{"event_type": "price_change", "event_ts": "2026-01-15T15:33:20.721542", "ingestion_ts": "2026-01-15T15:34:23.851219", "market_id": "0xcab7ba4a9133cfd407d7e73e5757e5abbace413b59421527a31113406c97815c", "raw": {"market": "0xcab7ba4a9133cfd407d7e73e5757e5abbace413b59421527a31113406c97815c", "asset_id": "96361925776989336186111887920533578209326565663637092688733016597062311745569", "price": "0.011", "size": "131", "side": "SELL", "timestamp": "1768491200740", "received_at": "2026-01-15T15:33:20.721542"}}
{"event_type": "price_change", "event_ts": "2026-01-15T15:33:20.721542", "ingestion_ts": "2026-01-15T15:34:23.851219", "market_id": "0xcab7ba4a9133cfd407d7e73e5757e5abbace413b59421527a31113406c97815c", "raw": {"market": "0xcab7ba4a9133cfd407d7e73e5757e5abbace413b59421527a31113406c97815c", "asset_id": "20002636398944597965698652220992177552927816915094913583821579024925426590022", "price": "0.989", "size": "131", "side": "BUY", "timestamp": "1768491200740", "received_at": "2026-01-15T15:33:20.721542"}}
{"event_type": "price_change", "event_ts": "2026-01-15T15:33:23.790543", "ingestion_ts": "2026-01-15T15:34:23.851219", "market_id": "0xae5584fbb57f23c1c608d544b656f23d8bf12340cef70811cf31bb0cb4fc2115", "raw": {"market": "0xae5584fbb57f23c1c608d544b656f23d8bf12340cef70811cf31bb0cb4fc2115", "asset_id": "42278252558046940014991595990628759801692726198478046188873057685686228021663", "price": "0.99", "size": "543.4", "side": "SELL", "timestamp": "1768491203820", "received_at": "2026-01-15T15:33:23.790543"}}
{"event_type": "price_change", "event_ts": "2026-01-15T15:33:23.790543", "ingestion_ts": "2026-01-15T15:34:23.851219", "market_id": "0xae5584fbb57f23c1c608d544b656f23d8bf12340cef70811cf31bb0cb4fc2115", "raw": {"market": "0xae5584fbb57f23c1c608d544b656f23d8bf12340cef70811cf31bb0cb4fc2115", "asset_id": "28946595841244317705636126646676849578876740730186646421280828201004700559420", "price": "0.01", "size": "543.4", "side": "BUY", "timestamp": "1768491203820", "received_at": "2026-01-15T15:33:23.790543"}}
{"event_type": "price_change", "event_ts": "2026-01-15T15:33:23.863069", "ingestion_ts": "2026-01-15T15:34:23.851219", "market_id": "0xae5584fbb57f23c1c608d544b656f23d8bf12340cef70811cf31bb0cb4fc2115", "raw": {"market": "0xae5584fbb57f23c1c608d544b656f23d8bf12340cef70811cf31bb0cb4fc2115", "asset_id": "28946595841244317705636126646676849578876740730186646421280828201004700559420", "price": "0.01", "size": "591.2", "side": "BUY", "timestamp": "1768491203904", "received_at": "2026-01-15T15:33:23.863069"}}
{"event_type": "price_change", "event_ts": "2026-01-15T15:33:23.863069", "ingestion_ts": "2026-01-15T15:34:23.851219", "market_id": "0xae5584fbb57f23c1c608d544b656f23d8bf12340cef70811cf31bb0cb4fc2115", "raw": {"market": "0xae5584fbb57f23c1c608d544b656f23d8bf12340cef70811cf31bb0cb4fc2115", "asset_id": "42278252558046940014991595990628759801692726198478046188873057685686228021663", "price": "0.99", "size": "591.2", "side": "SELL", "timestamp": "1768491203904", "received_at": "2026-01-15T15:33:23.863069"}}
{"event_type": "price_change", "event_ts": "2026-01-15T15:33:41.068326", "ingestion_ts": "2026-01-15T15:34:23.851219", "market_id": "0xc55db914f0fd1fee18997706712c0dfd8d0369cdbef93a9fef12bd001914ca77", "raw": {"market": "0xc55db914f0fd1fee18997706712c0dfd8d0369cdbef93a9fef12bd001914ca77", "asset_id": "114600293444080540179603459515770723592661967180480327891296353898330242622833", "price": "0.883", "size": "0", "side": "BUY", "timestamp": "1768491220904", "received_at": "2026-01-15T15:33:41.068326"}}
{"event_type": "price_change", "event_ts": "2026-01-15T15:33:41.068326", "ingestion_ts": "2026-01-15T15:34:23.851219", "market_id": "0xc55db914f0fd1fee18997706712c0dfd8d0369cdbef93a9fef12bd001914ca77", "raw": {"market": "0xc55db914f0fd1fee18997706712c0dfd8d0369cdbef93a9fef12bd001914ca77", "asset_id": "72354723612769247426741660426331235762851940382312402276325808095604519806766", "price": "0.117", "size": "0", "side": "SELL", "timestamp": "1768491220904", "received_at": "2026-01-15T15:33:41.068326"}}
{"event_type": "price_change", "event_ts": "2026-01-15T15:33:41.112649", "ingestion_ts": "2026-01-15T15:34:23.851219", "market_id": "0x50c669f178da4e5bbea7f1be25041fd278914712fa87a6a6f8e57d5923d88dee", "raw": {"market": "0x50c669f178da4e5bbea7f1be25041fd278914712fa87a6a6f8e57d5923d88dee", "asset_id": "74040420326294854165772767082819937451857852955603897473157746262672057685461", "price": "0.882", "size": "0", "side": "BUY", "timestamp": "1768491220901", "received_at": "2026-01-15T15:33:41.112649"}}
{"event_type": "price_change", "event_ts": "2026-01-15T15:33:41.112649", "ingestion_ts": "2026-01-15T15:34:23.851219", "market_id": "0x50c669f178da4e5bbea7f1be25041fd278914712fa87a6a6f8e57d5923d88dee", "raw": {"market": "0x50c669f178da4e5bbea7f1be25041fd278914712fa87a6a6f8e57d5923d88dee", "asset_id": "24682525479474221428144937281315825971983904267399062415430320764754931667953", "price": "0.118", "size": "0", "side": "SELL", "timestamp": "1768491220901", "received_at": "2026-01-15T15:33:41.112649"}}
{"event_type": "price_change", "event_ts": "2026-01-15T15:33:41.145049", "ingestion_ts": "2026-01-15T15:34:23.851219", "market_id": "0x2393ed0b0fdc450054c7b9071907eca75cf4fc36e385adf4a0a5f99ee62243e8", "raw": {"market": "0x2393ed0b0fdc450054c7b9071907eca75cf4fc36e385adf4a0a5f99ee62243e8", "asset_id": "32769749367306925959219403371425714180265458150646381231272229429098460625924", "price": "0.879", "size": "30", "side": "BUY", "timestamp": "1768491220906", "received_at": "2026-01-15T15:33:41.145049"}}
{"event_type": "price_change", "event_ts": "2026-01-15T15:33:41.145049", "ingestion_ts": "2026-01-15T15:34:23.851219", "market_id": "0x2393ed0b0fdc450054c7b9071907eca75cf4fc36e385adf4a0a5f99ee62243e8", "raw": {"market": "0x2393ed0b0fdc450054c7b9071907eca75cf4fc36e385adf4a0a5f99ee62243e8", "asset_id": "100074770378634056601572485653252702850363676459996771990439989989293515601975", "price": "0.121", "size": "30", "side": "SELL", "timestamp": "1768491220906", "received_at": "2026-01-15T15:33:41.145049"}}
{"event_type": "price_change", "event_ts": "2026-01-15T15:33:41.223038", "ingestion_ts": "2026-01-15T15:34:23.851219", "market_id": "0x49a20c7523c271099008f3ef9a31521263b24d637959852a391e6b4697b1a437", "raw": {"market": "0x49a20c7523c271099008f3ef9a31521263b24d637959852a391e6b4697b1a437", "asset_id": "55881023621710858558280545117465775643848233756850602339827152783696837905531", "price": "0.882", "size": "0", "side": "BUY", "timestamp": "1768491220908", "received_at": "2026-01-15T15:33:41.223038"}}
{"event_type": "price_change", "event_ts": "2026-01-15T15:33:41.223038", "ingestion_ts": "2026-01-15T15:34:23.851219", "market_id": "0x49a20c7523c271099008f3ef9a31521263b24d637959852a391e6b4697b1a437", "raw": {"market": "0x49a20c7523c271099008f3ef9a31521263b24d637959852a391e6b4697b1a437", "asset_id": "13018971792603393862521629014128024641178044618205296260525674415067194037856", "price": "0.118", "size": "0", "side": "SELL", "timestamp": "1768491220908", "received_at": "2026-01-15T15:33:41.223038"}}
{"event_type": "price_change", "event_ts": "2026-01-15T15:33:41.265252", "ingestion_ts": "2026-01-15T15:34:23.851219", "market_id": "0xc0e6b917320a47228fb96e3b5ae0e5c93773a5ae2662ae4e1f37807cfe47ce98", "raw": {"market": "0xc0e6b917320a47228fb96e3b5ae0e5c93773a5ae2662ae4e1f37807cfe47ce98", "asset_id": "58656358377246279051017109359677190749228949103591068167284263961542487110215", "price": "0.001", "size": "416.09", "side": "BUY", "timestamp": "1768491220915", "received_at": "2026-01-15T15:33:41.265252"}}
{"event_type": "price_change", "event_ts": "2026-01-15T15:33:41.265252", "ingestion_ts": "2026-01-15T15:34:23.851219", "market_id": "0xc0e6b917320a47228fb96e3b5ae0e5c93773a5ae2662ae4e1f37807cfe47ce98", "raw": {"market": "0xc0e6b917320a47228fb96e3b5ae0e5c93773a5ae2662ae4e1f37807cfe47ce98", "asset_id": "81647294538046680798858716589766492074338758116170717123345952330712416337530", "price": "0.999", "size": "416.09", "side": "SELL", "timestamp": "1768491220915", "received_at": "2026-01-15T15:33:41.265252"}}
{"event_type": "price_change", "event_ts": "2026-01-15T15:33:41.304422", "ingestion_ts": "2026-01-15T15:34:23.851219", "market_id": "0x44f08744458b8896620cd3330bc5e1ea69df4199b02d4fc583b3fc96e5d314ce", "raw": {"market": "0x44f08744458b8896620cd3330bc5e1ea69df4199b02d4fc583b3fc96e5d314ce", "asset_id": "72327831507226612545928776794104143393438710920370371172884559893525100761096", "price": "0.881", "size": "0", "side": "BUY", "timestamp": "1768491220917", "received_at": "2026-01-15T15:33:41.304422"}}
{"event_type": "price_change", "event_ts": "2026-01-15T15:33:41.304422", "ingestion_ts": "2026-01-15T15:34:23.851219", "market_id": "0x44f08744458b8896620cd3330bc5e1ea69df4199b02d4fc583b3fc96e5d314ce", "raw": {"market": "0x44f08744458b8896620cd3330bc5e1ea69df4199b02d4fc583b3fc96e5d314ce", "asset_id": "49194009556504828848509244326501559253829462790583873936160989575507522044057", "price": "0.119", "size": "0", "side": "SELL", "timestamp": "1768491220917", "received_at": "2026-01-15T15:33:41.304422"}}
{"event_type": "price_change", "event_ts": "2026-01-15T15:33:41.309896", "ingestion_ts": "2026-01-15T15:34:23.851219", "market_id": "0x9472be65457510b7fc3477b20ba90910e99d92eac8421a14bf4b7b7a08ef31dc", "raw": {"market": "0x9472be65457510b7fc3477b20ba90910e99d92eac8421a14bf4b7b7a08ef31dc", "asset_id": "43311793366960417907757893276427136943959788721376762326430771171648759300146", "price": "0.882", "size": "0", "side": "BUY", "timestamp": "1768491220922", "received_at": "2026-01-15T15:33:41.309896"}}
{"event_type": "price_change", "event_ts": "2026-01-15T15:33:41.309896", "ingestion_ts": "2026-01-15T15:34:23.851219", "market_id": "0x9472be65457510b7fc3477b20ba90910e99d92eac8421a14bf4b7b7a08ef31dc", "raw": {"market": "0x9472be65457510b7fc3477b20ba90910e99d92eac8421a14bf4b7b7a08ef31dc", "asset_id": "73414222381656326204771753454630063673548497164758947581648273905027617570612", "price": "0.118", "size": "0", "side": "SELL", "timestamp": "1768491220922", "received_at": "2026-01-15T15:33:41.309896"}}
{"event_type": "price_change", "event_ts": "2026-01-15T15:33:41.406215", "ingestion_ts": "2026-01-15T15:34:23.851219", "market_id": "0x49686d26fb712515cd5e12c23f0a1c7e10214c7faa3cb0a730aabe0c33694082", "raw": {"market": "0x49686d26fb712515cd5e12c23f0a1c7e10214c7faa3cb0a730aabe0c33694082", "asset_id": "30442780799048074404860985387051749017905070253466005720364298335239299761065", "price": "0.033", "size": "0", "side": "BUY", "timestamp": "1768491220927", "received_at": "2026-01-15T15:33:41.406215"}}
{"event_type": "price_change", "event_ts": "2026-01-15T15:33:41.406215", "ingestion_ts": "2026-01-15T15:34:23.851219", "market_id": "0x49686d26fb712515cd5e12c23f0a1c7e10214c7faa3cb0a730aabe0c33694082", "raw": {"market": "0x49686d26fb712515cd5e12c23f0a1c7e10214c7faa3cb0a730aabe0c33694082", "asset_id": "13244681086321087932946246027856416106585284024824496763706748621681543444582", "price": "0.967", "size": "0", "side": "SELL", "timestamp": "1768491220927", "received_at": "2026-01-15T15:33:41.406215"}}
{"event_type": "price_change", "event_ts": "2026-01-15T15:33:41.840956", "ingestion_ts": "2026-01-15T15:34:23.851219", "market_id": "0xea644975be7b2ad32b536a94ae21b707ecb2f84290225b24e60ca46dd77903dd", "raw": {"market": "0xea644975be7b2ad32b536a94ae21b707ecb2f84290225b24e60ca46dd77903dd", "asset_id": "19255594762111702415265750364124818677094538461124581923455280001407159960455", "price": "0.802", "size": "0", "side": "BUY", "timestamp": "1768491221464", "received_at": "2026-01-15T15:33:41.840956"}}
{"event_type": "price_change", "event_ts": "2026-01-15T15:33:41.840956", "ingestion_ts": "2026-01-15T15:34:23.851219", "market_id": "0xea644975be7b2ad32b536a94ae21b707ecb2f84290225b24e60ca46dd77903dd", "raw": {"market": "0xea644975be7b2ad32b536a94ae21b707ecb2f84290225b24e60ca46dd77903dd", "asset_id": "110044455628775971785618539427229099821815416148768008176051068105157446559241", "price": "0.198", "size": "0", "side": "SELL", "timestamp": "1768491221464", "received_at": "2026-01-15T15:33:41.840956"}}
{"event_type": "price_change", "event_ts": "2026-01-15T15:33:41.941129", "ingestion_ts": "2026-01-15T15:34:23.851219", "market_id": "0x5533fb9ab797777a243c75b1bf3882c54b1ee91f794730c090bf701598993529", "raw": {"market": "0x5533fb9ab797777a243c75b1bf3882c54b1ee91f794730c090bf701598993529", "asset_id": "99478074208094578615268494931219682040135218828258512927013036335093067688695", "price": "0.801", "size": "0", "side": "BUY", "timestamp": "1768491221474", "received_at": "2026-01-15T15:33:41.941129"}}
{"event_type": "price_change", "event_ts": "2026-01-15T15:33:41.941129", "ingestion_ts": "2026-01-15T15:34:23.851219", "market_id": "0x5533fb9ab797777a243c75b1bf3882c54b1ee91f794730c090bf701598993529", "raw": {"market": "0x5533fb9ab797777a243c75b1bf3882c54b1ee91f794730c090bf701598993529", "asset_id": "22532055631814907447535815649879981046415248231878961745474659705989546420934", "price": "0.199", "size": "0", "side": "SELL", "timestamp": "1768491221474", "received_at": "2026-01-15T15:33:41.941129"}}
{"event_type": "price_change", "event_ts": "2026-01-15T15:33:42.012298", "ingestion_ts": "2026-01-15T15:34:23.851219", "market_id": "0xb9bbdd34304344dcc45803780a34c97d73a00133a5ecf70f63e1008b8abb2fca", "raw": {"market": "0xb9bbdd34304344dcc45803780a34c97d73a00133a5ecf70f63e1008b8abb2fca", "asset_id": "8682484153073832526711485265636767086525069344085206423986003504588877767339", "price": "0.881", "size": "0", "side": "BUY", "timestamp": "1768491221465", "received_at": "2026-01-15T15:33:42.012298"}}
{"event_type": "price_change", "event_ts": "2026-01-15T15:33:42.012298", "ingestion_ts": "2026-01-15T15:34:23.851219", "market_id": "0xb9bbdd34304344dcc45803780a34c97d73a00133a5ecf70f63e1008b8abb2fca", "raw": {"market": "0xb9bbdd34304344dcc45803780a34c97d73a00133a5ecf70f63e1008b8abb2fca", "asset_id": "72012724360700510767037780555710363830014634797787940282136454146828040926557", "price": "0.119", "size": "0", "side": "SELL", "timestamp": "1768491221465", "received_at": "2026-01-15T15:33:42.012298"}}
{"event_type": "price_change", "event_ts": "2026-01-15T15:33:42.013983", "ingestion_ts": "2026-01-15T15:34:23.851219", "market_id": "0x44f08744458b8896620cd3330bc5e1ea69df4199b02d4fc583b3fc96e5d314ce", "raw": {"market": "0x44f08744458b8896620cd3330bc5e1ea69df4199b02d4fc583b3fc96e5d314ce", "asset_id": "72327831507226612545928776794104143393438710920370371172884559893525100761096", "price": "0.835", "size": "0", "side": "BUY", "timestamp": "1768491221480", "received_at": "2026-01-15T15:33:42.013983"}}
{"event_type": "price_change", "event_ts": "2026-01-15T15:33:42.013983", "ingestion_ts": "2026-01-15T15:34:23.851219", "market_id": "0x44f08744458b8896620cd3330bc5e1ea69df4199b02d4fc583b3fc96e5d314ce", "raw": {"market": "0x44f08744458b8896620cd3330bc5e1ea69df4199b02d4fc583b3fc96e5d314ce", "asset_id": "49194009556504828848509244326501559253829462790583873936160989575507522044057", "price": "0.165", "size": "0", "side": "SELL", "timestamp": "1768491221480", "received_at": "2026-01-15T15:33:42.013983"}}
{"event_type": "price_change", "event_ts": "2026-01-15T15:33:42.052424", "ingestion_ts": "2026-01-15T15:34:23.851219", "market_id": "0x50e477f0b316a3d97d60486479657c63be0763834d0e2e8a30b1b86dc3c1c001", "raw": {"market": "0x50e477f0b316a3d97d60486479657c63be0763834d0e2e8a30b1b86dc3c1c001", "asset_id": "39981134260608444876865205057565852475343967395624370698967311821208058420507", "price": "0.801", "size": "0", "side": "BUY", "timestamp": "1768491221468", "received_at": "2026-01-15T15:33:42.052424"}}
{"event_type": "price_change", "event_ts": "2026-01-15T15:33:42.052424", "ingestion_ts": "2026-01-15T15:34:23.851219", "market_id": "0x50e477f0b316a3d97d60486479657c63be0763834d0e2e8a30b1b86dc3c1c001", "raw": {"market": "0x50e477f0b316a3d97d60486479657c63be0763834d0e2e8a30b1b86dc3c1c001", "asset_id": "60573178197991590327120832143415406583517170365625050489007297367895074266641", "price": "0.199", "size": "0", "side": "SELL", "timestamp": "1768491221468", "received_at": "2026-01-15T15:33:42.052424"}}
{"event_type": "price_change", "event_ts": "2026-01-15T15:33:42.069444", "ingestion_ts": "2026-01-15T15:34:23.851219", "market_id": "0xaf9d0e448129a9f657f851d49495ba4742055d80e0ef1166ba0ee81d4d594214", "raw": {"market": "0xaf9d0e448129a9f657f851d49495ba4742055d80e0ef1166ba0ee81d4d594214", "asset_id": "4153292802911610701832309484716814274802943278345248636922528170020319407796", "price": "0.867", "size": "0", "side": "BUY", "timestamp": "1768491221468", "received_at": "2026-01-15T15:33:42.069444"}}
{"event_type": "price_change", "event_ts": "2026-01-15T15:33:42.069444", "ingestion_ts": "2026-01-15T15:34:23.851219", "market_id": "0xaf9d0e448129a9f657f851d49495ba4742055d80e0ef1166ba0ee81d4d594214", "raw": {"market": "0xaf9d0e448129a9f657f851d49495ba4742055d80e0ef1166ba0ee81d4d594214", "asset_id": "101676997363687199724245607342877036148401850938023978421879460310389391082353", "price": "0.133", "size": "0", "side": "SELL", "timestamp": "1768491221468", "received_at": "2026-01-15T15:33:42.069444"}}
{"event_type": "price_change", "event_ts": "2026-01-15T15:33:42.100026", "ingestion_ts": "2026-01-15T15:34:23.851219", "market_id": "0x9d24d9f9b5995949cb158d943793dea20bd448e1b3971cb6f7418bb15e719661", "raw": {"market": "0x9d24d9f9b5995949cb158d943793dea20bd448e1b3971cb6f7418bb15e719661", "asset_id": "79516121807256184736227920754945730465880754940725759201193439378549308939672", "price": "0.802", "size": "0", "side": "BUY", "timestamp": "1768491221469", "received_at": "2026-01-15T15:33:42.100026"}}
{"event_type": "price_change", "event_ts": "2026-01-15T15:33:42.100026", "ingestion_ts": "2026-01-15T15:34:23.851219", "market_id": "0x9d24d9f9b5995949cb158d943793dea20bd448e1b3971cb6f7418bb15e719661", "raw": {"market": "0x9d24d9f9b5995949cb158d943793dea20bd448e1b3971cb6f7418bb15e719661", "asset_id": "70512916946285526357165287373537570327431985324385225788636160168740471920430", "price": "0.198", "size": "0", "side": "SELL", "timestamp": "1768491221469", "received_at": "2026-01-15T15:33:42.100026"}}
{"event_type": "price_change", "event_ts": "2026-01-15T15:33:42.192896", "ingestion_ts": "2026-01-15T15:34:23.851219", "market_id": "0xe68594f1350f5535532b24979b5b5c1948432cbfc0c363802c32a8f9ab4e6509", "raw": {"market": "0xe68594f1350f5535532b24979b5b5c1948432cbfc0c363802c32a8f9ab4e6509", "asset_id": "3074032031589250926591186368301243337494992039402397918135503567058257050088", "price": "0.801", "size": "0", "side": "BUY", "timestamp": "1768491221468", "received_at": "2026-01-15T15:33:42.192896"}}
{"event_type": "price_change", "event_ts": "2026-01-15T15:33:42.192896", "ingestion_ts": "2026-01-15T15:34:23.851219", "market_id": "0xe68594f1350f5535532b24979b5b5c1948432cbfc0c363802c32a8f9ab4e6509", "raw": {"market": "0xe68594f1350f5535532b24979b5b5c1948432cbfc0c363802c32a8f9ab4e6509", "asset_id": "47459180813047899567328389455747872955901265556145057896316155826890276004242", "price": "0.199", "size": "0", "side": "SELL", "timestamp": "1768491221468", "received_at": "2026-01-15T15:33:42.192896"}}
{"event_type": "price_change", "event_ts": "2026-01-15T15:33:42.629777", "ingestion_ts": "2026-01-15T15:34:23.851219", "market_id": "0xaf9d0e448129a9f657f851d49495ba4742055d80e0ef1166ba0ee81d4d594214", "raw": {"market": "0xaf9d0e448129a9f657f851d49495ba4742055d80e0ef1166ba0ee81d4d594214", "asset_id": "101676997363687199724245607342877036148401850938023978421879460310389391082353", "price": "0.065", "size": "0", "side": "SELL", "timestamp": "1768491221968", "received_at": "2026-01-15T15:33:42.629777"}}
{"event_type": "price_change", "event_ts": "2026-01-15T15:33:42.629777", "ingestion_ts": "2026-01-15T15:34:23.851219", "market_id": "0xaf9d0e448129a9f657f851d49495ba4742055d80e0ef1166ba0ee81d4d594214", "raw": {"market": "0xaf9d0e448129a9f657f851d49495ba4742055d80e0ef1166ba0ee81d4d594214", "asset_id": "4153292802911610701832309484716814274802943278345248636922528170020319407796", "price": "0.935", "size": "0", "side": "BUY", "timestamp": "1768491221968", "received_at": "2026-01-15T15:33:42.629777"}}
{"event_type": "price_change", "event_ts": "2026-01-15T15:33:42.696192", "ingestion_ts": "2026-01-15T15:34:23.851219", "market_id": "0xaf9d0e448129a9f657f851d49495ba4742055d80e0ef1166ba0ee81d4d594214", "raw": {"market": "0xaf9d0e448129a9f657f851d49495ba4742055d80e0ef1166ba0ee81d4d594214", "asset_id": "101676997363687199724245607342877036148401850938023978421879460310389391082353", "price": "0.071", "size": "159", "side": "SELL", "timestamp": "1768491222008", "received_at": "2026-01-15T15:33:42.696192"}}
{"event_type": "price_change", "event_ts": "2026-01-15T15:33:42.696192", "ingestion_ts": "2026-01-15T15:34:23.851219", "market_id": "0xaf9d0e448129a9f657f851d49495ba4742055d80e0ef1166ba0ee81d4d594214", "raw": {"market": "0xaf9d0e448129a9f657f851d49495ba4742055d80e0ef1166ba0ee81d4d594214", "asset_id": "4153292802911610701832309484716814274802943278345248636922528170020319407796", "price": "0.929", "size": "159", "side": "BUY", "timestamp": "1768491222008", "received_at": "2026-01-15T15:33:42.696192"}}
{"event_type": "price_change", "event_ts": "2026-01-15T15:33:42.799925", "ingestion_ts": "2026-01-15T15:34:23.851219", "market_id": "0xaf9d0e448129a9f657f851d49495ba4742055d80e0ef1166ba0ee81d4d594214", "raw": {"market": "0xaf9d0e448129a9f657f851d49495ba4742055d80e0ef1166ba0ee81d4d594214", "asset_id": "4153292802911610701832309484716814274802943278345248636922528170020319407796", "price": "0.697", "size": "300", "side": "BUY", "timestamp": "1768491222117", "received_at": "2026-01-15T15:33:42.799925"}}
{"event_type": "price_change", "event_ts": "2026-01-15T15:33:42.799925", "ingestion_ts": "2026-01-15T15:34:23.851219", "market_id": "0xaf9d0e448129a9f657f851d49495ba4742055d80e0ef1166ba0ee81d4d594214", "raw": {"market": "0xaf9d0e448129a9f657f851d49495ba4742055d80e0ef1166ba0ee81d4d594214", "asset_id": "101676997363687199724245607342877036148401850938023978421879460310389391082353", "price": "0.303", "size": "300", "side": "SELL", "timestamp": "1768491222117", "received_at": "2026-01-15T15:33:42.799925"}}
{"event_type": "price_change", "event_ts": "2026-01-15T15:33:43.128825", "ingestion_ts": "2026-01-15T15:34:23.851219", "market_id": "0xaf9d0e448129a9f657f851d49495ba4742055d80e0ef1166ba0ee81d4d594214", "raw": {"market": "0xaf9d0e448129a9f657f851d49495ba4742055d80e0ef1166ba0ee81d4d594214", "asset_id": "4153292802911610701832309484716814274802943278345248636922528170020319407796", "price": "0.869", "size": "30", "side": "BUY", "timestamp": "1768491222596", "received_at": "2026-01-15T15:33:43.128825"}}
{"event_type": "price_change", "event_ts": "2026-01-15T15:33:43.128825", "ingestion_ts": "2026-01-15T15:34:23.851219", "market_id": "0xaf9d0e448129a9f657f851d49495ba4742055d80e0ef1166ba0ee81d4d594214", "raw": {"market": "0xaf9d0e448129a9f657f851d49495ba4742055d80e0ef1166ba0ee81d4d594214", "asset_id": "101676997363687199724245607342877036148401850938023978421879460310389391082353", "price": "0.131", "size": "30", "side": "SELL", "timestamp": "1768491222596", "received_at": "2026-01-15T15:33:43.128825"}}
{"event_type": "price_change", "event_ts": "2026-01-15T15:33:43.128876", "ingestion_ts": "2026-01-15T15:34:23.851219", "market_id": "0xaf9d0e448129a9f657f851d49495ba4742055d80e0ef1166ba0ee81d4d594214", "raw": {"market": "0xaf9d0e448129a9f657f851d49495ba4742055d80e0ef1166ba0ee81d4d594214", "asset_id": "4153292802911610701832309484716814274802943278345248636922528170020319407796", "price": "0.701", "size": "361", "side": "BUY", "timestamp": "1768491222597", "received_at": "2026-01-15T15:33:43.128876"}}
{"event_type": "price_change", "event_ts": "2026-01-15T15:33:43.128876", "ingestion_ts": "2026-01-15T15:34:23.851219", "market_id": "0xaf9d0e448129a9f657f851d49495ba4742055d80e0ef1166ba0ee81d4d594214", "raw": {"market": "0xaf9d0e448129a9f657f851d49495ba4742055d80e0ef1166ba0ee81d4d594214", "asset_id": "101676997363687199724245607342877036148401850938023978421879460310389391082353", "price": "0.299", "size": "361", "side": "SELL", "timestamp": "1768491222597", "received_at": "2026-01-15T15:33:43.128876"}}
{"event_type": "price_change", "event_ts": "2026-01-15T15:33:43.385688", "ingestion_ts": "2026-01-15T15:34:23.851219", "market_id": "0xaf9d0e448129a9f657f851d49495ba4742055d80e0ef1166ba0ee81d4d594214", "raw": {"market": "0xaf9d0e448129a9f657f851d49495ba4742055d80e0ef1166ba0ee81d4d594214", "asset_id": "4153292802911610701832309484716814274802943278345248636922528170020319407796", "price": "0.929", "size": "189", "side": "BUY", "timestamp": "1768491223040", "received_at": "2026-01-15T15:33:43.385688"}}
{"event_type": "price_change", "event_ts": "2026-01-15T15:33:43.385688", "ingestion_ts": "2026-01-15T15:34:23.851219", "market_id": "0xaf9d0e448129a9f657f851d49495ba4742055d80e0ef1166ba0ee81d4d594214", "raw": {"market": "0xaf9d0e448129a9f657f851d49495ba4742055d80e0ef1166ba0ee81d4d594214", "asset_id": "101676997363687199724245607342877036148401850938023978421879460310389391082353", "price": "0.071", "size": "189", "side": "SELL", "timestamp": "1768491223040", "received_at": "2026-01-15T15:33:43.385688"}}
{"event_type": "price_change", "event_ts": "2026-01-15T15:33:44.708123", "ingestion_ts": "2026-01-15T15:34:23.851219", "market_id": "0x50c669f178da4e5bbea7f1be25041fd278914712fa87a6a6f8e57d5923d88dee", "raw": {"market": "0x50c669f178da4e5bbea7f1be25041fd278914712fa87a6a6f8e57d5923d88dee", "asset_id": "74040420326294854165772767082819937451857852955603897473157746262672057685461", "price": "0.883", "size": "0", "side": "BUY", "timestamp": "1768491224746", "received_at": "2026-01-15T15:33:44.708123"}}
{"event_type": "price_change", "event_ts": "2026-01-15T15:33:44.708123", "ingestion_ts": "2026-01-15T15:34:23.851219", "market_id": "0x50c669f178da4e5bbea7f1be25041fd278914712fa87a6a6f8e57d5923d88dee", "raw": {"market": "0x50c669f178da4e5bbea7f1be25041fd278914712fa87a6a6f8e57d5923d88dee", "asset_id": "24682525479474221428144937281315825971983904267399062415430320764754931667953", "price": "0.117", "size": "0", "side": "SELL", "timestamp": "1768491224746", "received_at": "2026-01-15T15:33:44.708123"}}
{"event_type": "price_change", "event_ts": "2026-01-15T15:33:44.708208", "ingestion_ts": "2026-01-15T15:34:23.851219", "market_id": "0x49686d26fb712515cd5e12c23f0a1c7e10214c7faa3cb0a730aabe0c33694082", "raw": {"market": "0x49686d26fb712515cd5e12c23f0a1c7e10214c7faa3cb0a730aabe0c33694082", "asset_id": "30442780799048074404860985387051749017905070253466005720364298335239299761065", "price": "0.034", "size": "0", "side": "BUY", "timestamp": "1768491224746", "received_at": "2026-01-15T15:33:44.708208"}}
{"event_type": "price_change", "event_ts": "2026-01-15T15:33:44.708208", "ingestion_ts": "2026-01-15T15:34:23.851219", "market_id": "0x49686d26fb712515cd5e12c23f0a1c7e10214c7faa3cb0a730aabe0c33694082", "raw": {"market": "0x49686d26fb712515cd5e12c23f0a1c7e10214c7faa3cb0a730aabe0c33694082", "asset_id": "13244681086321087932946246027856416106585284024824496763706748621681543444582", "price": "0.966", "size": "0", "side": "SELL", "timestamp": "1768491224746", "received_at": "2026-01-15T15:33:44.708208"}}
{"event_type": "price_change", "event_ts": "2026-01-15T15:33:44.708252", "ingestion_ts": "2026-01-15T15:34:23.851219", "market_id": "0xaf9d0e448129a9f657f851d49495ba4742055d80e0ef1166ba0ee81d4d594214", "raw": {"market": "0xaf9d0e448129a9f657f851d49495ba4742055d80e0ef1166ba0ee81d4d594214", "asset_id": "4153292802911610701832309484716814274802943278345248636922528170020319407796", "price": "0.701", "size": "356", "side": "BUY", "timestamp": "1768491224746", "received_at": "2026-01-15T15:33:44.708252"}}
{"event_type": "price_change", "event_ts": "2026-01-15T15:33:44.708252", "ingestion_ts": "2026-01-15T15:34:23.851219", "market_id": "0xaf9d0e448129a9f657f851d49495ba4742055d80e0ef1166ba0ee81d4d594214", "raw": {"market": "0xaf9d0e448129a9f657f851d49495ba4742055d80e0ef1166ba0ee81d4d594214", "asset_id": "101676997363687199724245607342877036148401850938023978421879460310389391082353", "price": "0.299", "size": "356", "side": "SELL", "timestamp": "1768491224746", "received_at": "2026-01-15T15:33:44.708252"}}
{"event_type": "price_change", "event_ts": "2026-01-15T15:33:44.752617", "ingestion_ts": "2026-01-15T15:34:23.851219", "market_id": "0xaf9d0e448129a9f657f851d49495ba4742055d80e0ef1166ba0ee81d4d594214", "raw": {"market": "0xaf9d0e448129a9f657f851d49495ba4742055d80e0ef1166ba0ee81d4d594214", "asset_id": "4153292802911610701832309484716814274802943278345248636922528170020319407796", "price": "0.702", "size": "5", "side": "BUY", "timestamp": "1768491224791", "received_at": "2026-01-15T15:33:44.752617"}}
{"event_type": "price_change", "event_ts": "2026-01-15T15:33:44.752617", "ingestion_ts": "2026-01-15T15:34:23.851219", "market_id": "0xaf9d0e448129a9f657f851d49495ba4742055d80e0ef1166ba0ee81d4d594214", "raw": {"market": "0xaf9d0e448129a9f657f851d49495ba4742055d80e0ef1166ba0ee81d4d594214", "asset_id": "101676997363687199724245607342877036148401850938023978421879460310389391082353", "price": "0.298", "size": "5", "side": "SELL", "timestamp": "1768491224791", "received_at": "2026-01-15T15:33:44.752617"}}
{"event_type": "price_change", "event_ts": "2026-01-15T15:33:44.752702", "ingestion_ts": "2026-01-15T15:34:23.851219", "market_id": "0x50c669f178da4e5bbea7f1be25041fd278914712fa87a6a6f8e57d5923d88dee", "raw": {"market": "0x50c669f178da4e5bbea7f1be25041fd278914712fa87a6a6f8e57d5923d88dee", "asset_id": "74040420326294854165772767082819937451857852955603897473157746262672057685461", "price": "0.825", "size": "5", "side": "BUY", "timestamp": "1768491224791", "received_at": "2026-01-15T15:33:44.752702"}}
{"event_type": "price_change", "event_ts": "2026-01-15T15:33:44.752702", "ingestion_ts": "2026-01-15T15:34:23.851219", "market_id": "0x50c669f178da4e5bbea7f1be25041fd278914712fa87a6a6f8e57d5923d88dee", "raw": {"market": "0x50c669f178da4e5bbea7f1be25041fd278914712fa87a6a6f8e57d5923d88dee", "asset_id": "24682525479474221428144937281315825971983904267399062415430320764754931667953", "price": "0.175", "size": "5", "side": "SELL", "timestamp": "1768491224791", "received_at": "2026-01-15T15:33:44.752702"}}
{"event_type": "price_change", "event_ts": "2026-01-15T15:33:44.752744", "ingestion_ts": "2026-01-15T15:34:23.851219", "market_id": "0x49686d26fb712515cd5e12c23f0a1c7e10214c7faa3cb0a730aabe0c33694082", "raw": {"market": "0x49686d26fb712515cd5e12c23f0a1c7e10214c7faa3cb0a730aabe0c33694082", "asset_id": "30442780799048074404860985387051749017905070253466005720364298335239299761065", "price": "0.023", "size": "5", "side": "BUY", "timestamp": "1768491224791", "received_at": "2026-01-15T15:33:44.752744"}}
{"event_type": "price_change", "event_ts": "2026-01-15T15:33:44.752744", "ingestion_ts": "2026-01-15T15:34:23.851219", "market_id": "0x49686d26fb712515cd5e12c23f0a1c7e10214c7faa3cb0a730aabe0c33694082", "raw": {"market": "0x49686d26fb712515cd5e12c23f0a1c7e10214c7faa3cb0a730aabe0c33694082", "asset_id": "13244681086321087932946246027856416106585284024824496763706748621681543444582", "price": "0.977", "size": "5", "side": "SELL", "timestamp": "1768491224791", "received_at": "2026-01-15T15:33:44.752744"}}
{"event_type": "price_change", "event_ts": "2026-01-15T15:33:47.319500", "ingestion_ts": "2026-01-15T15:34:23.851219", "market_id": "0xae5584fbb57f23c1c608d544b656f23d8bf12340cef70811cf31bb0cb4fc2115", "raw": {"market": "0xae5584fbb57f23c1c608d544b656f23d8bf12340cef70811cf31bb0cb4fc2115", "asset_id": "42278252558046940014991595990628759801692726198478046188873057685686228021663", "price": "0.99", "size": "489", "side": "SELL", "timestamp": "1768491227358", "received_at": "2026-01-15T15:33:47.319500"}}
{"event_type": "price_change", "event_ts": "2026-01-15T15:33:47.319500", "ingestion_ts": "2026-01-15T15:34:23.851219", "market_id": "0xae5584fbb57f23c1c608d544b656f23d8bf12340cef70811cf31bb0cb4fc2115", "raw": {"market": "0xae5584fbb57f23c1c608d544b656f23d8bf12340cef70811cf31bb0cb4fc2115", "asset_id": "28946595841244317705636126646676849578876740730186646421280828201004700559420", "price": "0.01", "size": "489", "side": "BUY", "timestamp": "1768491227358", "received_at": "2026-01-15T15:33:47.319500"}}
{"event_type": "price_change", "event_ts": "2026-01-15T15:33:47.435887", "ingestion_ts": "2026-01-15T15:34:23.851219", "market_id": "0xae5584fbb57f23c1c608d544b656f23d8bf12340cef70811cf31bb0cb4fc2115", "raw": {"market": "0xae5584fbb57f23c1c608d544b656f23d8bf12340cef70811cf31bb0cb4fc2115", "asset_id": "28946595841244317705636126646676849578876740730186646421280828201004700559420", "price": "0.01", "size": "441.2", "side": "BUY", "timestamp": "1768491227462", "received_at": "2026-01-15T15:33:47.435887"}}
{"event_type": "price_change", "event_ts": "2026-01-15T15:33:47.435887", "ingestion_ts": "2026-01-15T15:34:23.851219", "market_id": "0xae5584fbb57f23c1c608d544b656f23d8bf12340cef70811cf31bb0cb4fc2115", "raw": {"market": "0xae5584fbb57f23c1c608d544b656f23d8bf12340cef70811cf31bb0cb4fc2115", "asset_id": "42278252558046940014991595990628759801692726198478046188873057685686228021663", "price": "0.99", "size": "441.2", "side": "SELL", "timestamp": "1768491227462", "received_at": "2026-01-15T15:33:47.435887"}}
{"event_type": "price_change", "event_ts": "2026-01-15T15:33:50.785341", "ingestion_ts": "2026-01-15T15:34:23.851219", "market_id": "0x44f08744458b8896620cd3330bc5e1ea69df4199b02d4fc583b3fc96e5d314ce", "raw": {"market": "0x44f08744458b8896620cd3330bc5e1ea69df4199b02d4fc583b3fc96e5d314ce", "asset_id": "72327831507226612545928776794104143393438710920370371172884559893525100761096", "price": "0.402", "size": "0", "side": "BUY", "timestamp": "1768491230825", "received_at": "2026-01-15T15:33:50.785341"}}
{"event_type": "price_change", "event_ts": "2026-01-15T15:33:50.785341", "ingestion_ts": "2026-01-15T15:34:23.851219", "market_id": "0x44f08744458b8896620cd3330bc5e1ea69df4199b02d4fc583b3fc96e5d314ce", "raw": {"market": "0x44f08744458b8896620cd3330bc5e1ea69df4199b02d4fc583b3fc96e5d314ce", "asset_id": "49194009556504828848509244326501559253829462790583873936160989575507522044057", "price": "0.598", "size": "0", "side": "SELL", "timestamp": "1768491230825", "received_at": "2026-01-15T15:33:50.785341"}}
{"event_type": "price_change", "event_ts": "2026-01-15T15:33:50.840663", "ingestion_ts": "2026-01-15T15:34:23.851219", "market_id": "0x44f08744458b8896620cd3330bc5e1ea69df4199b02d4fc583b3fc96e5d314ce", "raw": {"market": "0x44f08744458b8896620cd3330bc5e1ea69df4199b02d4fc583b3fc96e5d314ce", "asset_id": "72327831507226612545928776794104143393438710920370371172884559893525100761096", "price": "0.402", "size": "5", "side": "BUY", "timestamp": "1768491230882", "received_at": "2026-01-15T15:33:50.840663"}}
{"event_type": "price_change", "event_ts": "2026-01-15T15:33:50.840663", "ingestion_ts": "2026-01-15T15:34:23.851219", "market_id": "0x44f08744458b8896620cd3330bc5e1ea69df4199b02d4fc583b3fc96e5d314ce", "raw": {"market": "0x44f08744458b8896620cd3330bc5e1ea69df4199b02d4fc583b3fc96e5d314ce", "asset_id": "49194009556504828848509244326501559253829462790583873936160989575507522044057", "price": "0.598", "size": "5", "side": "SELL", "timestamp": "1768491230882", "received_at": "2026-01-15T15:33:50.840663"}}
{"event_type": "price_change", "event_ts": "2026-01-15T15:33:53.826174", "ingestion_ts": "2026-01-15T15:34:23.851219", "market_id": "0xae5584fbb57f23c1c608d544b656f23d8bf12340cef70811cf31bb0cb4fc2115", "raw": {"market": "0xae5584fbb57f23c1c608d544b656f23d8bf12340cef70811cf31bb0cb4fc2115", "asset_id": "42278252558046940014991595990628759801692726198478046188873057685686228021663", "price": "0.99", "size": "543.4", "side": "SELL", "timestamp": "1768491233858", "received_at": "2026-01-15T15:33:53.826174"}}
{"event_type": "price_change", "event_ts": "2026-01-15T15:33:53.826174", "ingestion_ts": "2026-01-15T15:34:23.851219", "market_id": "0xae5584fbb57f23c1c608d544b656f23d8bf12340cef70811cf31bb0cb4fc2115", "raw": {"market": "0xae5584fbb57f23c1c608d544b656f23d8bf12340cef70811cf31bb0cb4fc2115", "asset_id": "28946595841244317705636126646676849578876740730186646421280828201004700559420", "price": "0.01", "size": "543.4", "side": "BUY", "timestamp": "1768491233858", "received_at": "2026-01-15T15:33:53.826174"}}
{"event_type": "price_change", "event_ts": "2026-01-15T15:33:53.904390", "ingestion_ts": "2026-01-15T15:34:23.851219", "market_id": "0xae5584fbb57f23c1c608d544b656f23d8bf12340cef70811cf31bb0cb4fc2115", "raw": {"market": "0xae5584fbb57f23c1c608d544b656f23d8bf12340cef70811cf31bb0cb4fc2115", "asset_id": "28946595841244317705636126646676849578876740730186646421280828201004700559420", "price": "0.01", "size": "591.2", "side": "BUY", "timestamp": "1768491233941", "received_at": "2026-01-15T15:33:53.904390"}}
{"event_type": "price_change", "event_ts": "2026-01-15T15:33:53.904390", "ingestion_ts": "2026-01-15T15:34:23.851219", "market_id": "0xae5584fbb57f23c1c608d544b656f23d8bf12340cef70811cf31bb0cb4fc2115", "raw": {"market": "0xae5584fbb57f23c1c608d544b656f23d8bf12340cef70811cf31bb0cb4fc2115", "asset_id": "42278252558046940014991595990628759801692726198478046188873057685686228021663", "price": "0.99", "size": "591.2", "side": "SELL", "timestamp": "1768491233941", "received_at": "2026-01-15T15:33:53.904390"}}
{"event_type": "price_change", "event_ts": "2026-01-15T15:34:15.554303", "ingestion_ts": "2026-01-15T15:34:23.851219", "market_id": "0xae5584fbb57f23c1c608d544b656f23d8bf12340cef70811cf31bb0cb4fc2115", "raw": {"market": "0xae5584fbb57f23c1c608d544b656f23d8bf12340cef70811cf31bb0cb4fc2115", "asset_id": "28946595841244317705636126646676849578876740730186646421280828201004700559420", "price": "0.008", "size": "15625.11", "side": "BUY", "timestamp": "1768491255526", "received_at": "2026-01-15T15:34:15.554303"}}
{"event_type": "price_change", "event_ts": "2026-01-15T15:34:15.554303", "ingestion_ts": "2026-01-15T15:34:23.851219", "market_id": "0xae5584fbb57f23c1c608d544b656f23d8bf12340cef70811cf31bb0cb4fc2115", "raw": {"market": "0xae5584fbb57f23c1c608d544b656f23d8bf12340cef70811cf31bb0cb4fc2115", "asset_id": "42278252558046940014991595990628759801692726198478046188873057685686228021663", "price": "0.992", "size": "15625.11", "side": "SELL", "timestamp": "1768491255526", "received_at": "2026-01-15T15:34:15.554303"}}
{"event_type": "price_change", "event_ts": "2026-01-15T15:34:15.556869", "ingestion_ts": "2026-01-15T15:34:23.851219", "market_id": "0xae5584fbb57f23c1c608d544b656f23d8bf12340cef70811cf31bb0cb4fc2115", "raw": {"market": "0xae5584fbb57f23c1c608d544b656f23d8bf12340cef70811cf31bb0cb4fc2115", "asset_id": "28946595841244317705636126646676849578876740730186646421280828201004700559420", "price": "0.004", "size": "12750", "side": "BUY", "timestamp": "1768491255527", "received_at": "2026-01-15T15:34:15.556869"}}
{"event_type": "price_change", "event_ts": "2026-01-15T15:34:15.556869", "ingestion_ts": "2026-01-15T15:34:23.851219", "market_id": "0xae5584fbb57f23c1c608d544b656f23d8bf12340cef70811cf31bb0cb4fc2115", "raw": {"market": "0xae5584fbb57f23c1c608d544b656f23d8bf12340cef70811cf31bb0cb4fc2115", "asset_id": "42278252558046940014991595990628759801692726198478046188873057685686228021663", "price": "0.996", "size": "12750", "side": "SELL", "timestamp": "1768491255527", "received_at": "2026-01-15T15:34:15.556869"}}
{"event_type": "price_change", "event_ts": "2026-01-15T15:34:16.802674", "ingestion_ts": "2026-01-15T15:34:23.851219", "market_id": "0x2393ed0b0fdc450054c7b9071907eca75cf4fc36e385adf4a0a5f99ee62243e8", "raw": {"market": "0x2393ed0b0fdc450054c7b9071907eca75cf4fc36e385adf4a0a5f99ee62243e8", "asset_id": "32769749367306925959219403371425714180265458150646381231272229429098460625924", "price": "0.917", "size": "0", "side": "BUY", "timestamp": "1768491256806", "received_at": "2026-01-15T15:34:16.802674"}}
{"event_type": "price_change", "event_ts": "2026-01-15T15:34:16.802674", "ingestion_ts": "2026-01-15T15:34:23.851219", "market_id": "0x2393ed0b0fdc450054c7b9071907eca75cf4fc36e385adf4a0a5f99ee62243e8", "raw": {"market": "0x2393ed0b0fdc450054c7b9071907eca75cf4fc36e385adf4a0a5f99ee62243e8", "asset_id": "100074770378634056601572485653252702850363676459996771990439989989293515601975", "price": "0.083", "size": "0", "side": "SELL", "timestamp": "1768491256806", "received_at": "2026-01-15T15:34:16.802674"}}
{"event_type": "price_change", "event_ts": "2026-01-15T15:34:16.890365", "ingestion_ts": "2026-01-15T15:34:23.851219", "market_id": "0x49686d26fb712515cd5e12c23f0a1c7e10214c7faa3cb0a730aabe0c33694082", "raw": {"market": "0x49686d26fb712515cd5e12c23f0a1c7e10214c7faa3cb0a730aabe0c33694082", "asset_id": "30442780799048074404860985387051749017905070253466005720364298335239299761065", "price": "0.062", "size": "5", "side": "BUY", "timestamp": "1768491256923", "received_at": "2026-01-15T15:34:16.890365"}}
{"event_type": "price_change", "event_ts": "2026-01-15T15:34:16.890365", "ingestion_ts": "2026-01-15T15:34:23.851219", "market_id": "0x49686d26fb712515cd5e12c23f0a1c7e10214c7faa3cb0a730aabe0c33694082", "raw": {"market": "0x49686d26fb712515cd5e12c23f0a1c7e10214c7faa3cb0a730aabe0c33694082", "asset_id": "13244681086321087932946246027856416106585284024824496763706748621681543444582", "price": "0.938", "size": "5", "side": "SELL", "timestamp": "1768491256923", "received_at": "2026-01-15T15:34:16.890365"}}
{"event_type": "price_change", "event_ts": "2026-01-15T15:34:16.931746", "ingestion_ts": "2026-01-15T15:34:23.851219", "market_id": "0x49686d26fb712515cd5e12c23f0a1c7e10214c7faa3cb0a730aabe0c33694082", "raw": {"market": "0x49686d26fb712515cd5e12c23f0a1c7e10214c7faa3cb0a730aabe0c33694082", "asset_id": "30442780799048074404860985387051749017905070253466005720364298335239299761065", "price": "0.064", "size": "25", "side": "BUY", "timestamp": "1768491256969", "received_at": "2026-01-15T15:34:16.931746"}}
{"event_type": "price_change", "event_ts": "2026-01-15T15:34:16.931746", "ingestion_ts": "2026-01-15T15:34:23.851219", "market_id": "0x49686d26fb712515cd5e12c23f0a1c7e10214c7faa3cb0a730aabe0c33694082", "raw": {"market": "0x49686d26fb712515cd5e12c23f0a1c7e10214c7faa3cb0a730aabe0c33694082", "asset_id": "13244681086321087932946246027856416106585284024824496763706748621681543444582", "price": "0.936", "size": "25", "side": "SELL", "timestamp": "1768491256969", "received_at": "2026-01-15T15:34:16.931746"}}
{"event_type": "price_change", "event_ts": "2026-01-15T15:34:17.015773", "ingestion_ts": "2026-01-15T15:34:23.851219", "market_id": "0x50c669f178da4e5bbea7f1be25041fd278914712fa87a6a6f8e57d5923d88dee", "raw": {"market": "0x50c669f178da4e5bbea7f1be25041fd278914712fa87a6a6f8e57d5923d88dee", "asset_id": "74040420326294854165772767082819937451857852955603897473157746262672057685461", "price": "0.902", "size": "0", "side": "BUY", "timestamp": "1768491257025", "received_at": "2026-01-15T15:34:17.015773"}}
{"event_type": "price_change", "event_ts": "2026-01-15T15:34:17.015773", "ingestion_ts": "2026-01-15T15:34:23.851219", "market_id": "0x50c669f178da4e5bbea7f1be25041fd278914712fa87a6a6f8e57d5923d88dee", "raw": {"market": "0x50c669f178da4e5bbea7f1be25041fd278914712fa87a6a6f8e57d5923d88dee", "asset_id": "24682525479474221428144937281315825971983904267399062415430320764754931667953", "price": "0.098", "size": "0", "side": "SELL", "timestamp": "1768491257025", "received_at": "2026-01-15T15:34:17.015773"}}
{"event_type": "price_change", "event_ts": "2026-01-15T15:34:17.016849", "ingestion_ts": "2026-01-15T15:34:23.851219", "market_id": "0x49686d26fb712515cd5e12c23f0a1c7e10214c7faa3cb0a730aabe0c33694082", "raw": {"market": "0x49686d26fb712515cd5e12c23f0a1c7e10214c7faa3cb0a730aabe0c33694082", "asset_id": "30442780799048074404860985387051749017905070253466005720364298335239299761065", "price": "0.042", "size": "0", "side": "BUY", "timestamp": "1768491257025", "received_at": "2026-01-15T15:34:17.016849"}}
{"event_type": "price_change", "event_ts": "2026-01-15T15:34:17.016849", "ingestion_ts": "2026-01-15T15:34:23.851219", "market_id": "0x49686d26fb712515cd5e12c23f0a1c7e10214c7faa3cb0a730aabe0c33694082", "raw": {"market": "0x49686d26fb712515cd5e12c23f0a1c7e10214c7faa3cb0a730aabe0c33694082", "asset_id": "13244681086321087932946246027856416106585284024824496763706748621681543444582", "price": "0.958", "size": "0", "side": "SELL", "timestamp": "1768491257025", "received_at": "2026-01-15T15:34:17.016849"}}
{"event_type": "price_change", "event_ts": "2026-01-15T15:34:17.016903", "ingestion_ts": "2026-01-15T15:34:23.851219", "market_id": "0x49a20c7523c271099008f3ef9a31521263b24d637959852a391e6b4697b1a437", "raw": {"market": "0x49a20c7523c271099008f3ef9a31521263b24d637959852a391e6b4697b1a437", "asset_id": "55881023621710858558280545117465775643848233756850602339827152783696837905531", "price": "0.892", "size": "0", "side": "BUY", "timestamp": "1768491257025", "received_at": "2026-01-15T15:34:17.016903"}}
{"event_type": "price_change", "event_ts": "2026-01-15T15:34:17.016903", "ingestion_ts": "2026-01-15T15:34:23.851219", "market_id": "0x49a20c7523c271099008f3ef9a31521263b24d637959852a391e6b4697b1a437", "raw": {"market": "0x49a20c7523c271099008f3ef9a31521263b24d637959852a391e6b4697b1a437", "asset_id": "13018971792603393862521629014128024641178044618205296260525674415067194037856", "price": "0.108", "size": "0", "side": "SELL", "timestamp": "1768491257025", "received_at": "2026-01-15T15:34:17.016903"}}
{"event_type": "price_change", "event_ts": "2026-01-15T15:34:17.140877", "ingestion_ts": "2026-01-15T15:34:23.851219", "market_id": "0x50c669f178da4e5bbea7f1be25041fd278914712fa87a6a6f8e57d5923d88dee", "raw": {"market": "0x50c669f178da4e5bbea7f1be25041fd278914712fa87a6a6f8e57d5923d88dee", "asset_id": "74040420326294854165772767082819937451857852955603897473157746262672057685461", "price": "0.904", "size": "30", "side": "BUY", "timestamp": "1768491257164", "received_at": "2026-01-15T15:34:17.140877"}}
{"event_type": "price_change", "event_ts": "2026-01-15T15:34:17.140877", "ingestion_ts": "2026-01-15T15:34:23.851219", "market_id": "0x50c669f178da4e5bbea7f1be25041fd278914712fa87a6a6f8e57d5923d88dee", "raw": {"market": "0x50c669f178da4e5bbea7f1be25041fd278914712fa87a6a6f8e57d5923d88dee", "asset_id": "24682525479474221428144937281315825971983904267399062415430320764754931667953", "price": "0.096", "size": "30", "side": "SELL", "timestamp": "1768491257164", "received_at": "2026-01-15T15:34:17.140877"}}
{"event_type": "price_change", "event_ts": "2026-01-15T15:34:17.140915", "ingestion_ts": "2026-01-15T15:34:23.851219", "market_id": "0x49a20c7523c271099008f3ef9a31521263b24d637959852a391e6b4697b1a437", "raw": {"market": "0x49a20c7523c271099008f3ef9a31521263b24d637959852a391e6b4697b1a437", "asset_id": "55881023621710858558280545117465775643848233756850602339827152783696837905531", "price": "0.895", "size": "30", "side": "BUY", "timestamp": "1768491257164", "received_at": "2026-01-15T15:34:17.140915"}}
{"event_type": "price_change", "event_ts": "2026-01-15T15:34:17.140915", "ingestion_ts": "2026-01-15T15:34:23.851219", "market_id": "0x49a20c7523c271099008f3ef9a31521263b24d637959852a391e6b4697b1a437", "raw": {"market": "0x49a20c7523c271099008f3ef9a31521263b24d637959852a391e6b4697b1a437", "asset_id": "13018971792603393862521629014128024641178044618205296260525674415067194037856", "price": "0.105", "size": "30", "side": "SELL", "timestamp": "1768491257164", "received_at": "2026-01-15T15:34:17.140915"}}
{"event_type": "price_change", "event_ts": "2026-01-15T15:34:17.140930", "ingestion_ts": "2026-01-15T15:34:23.851219", "market_id": "0x49686d26fb712515cd5e12c23f0a1c7e10214c7faa3cb0a730aabe0c33694082", "raw": {"market": "0x49686d26fb712515cd5e12c23f0a1c7e10214c7faa3cb0a730aabe0c33694082", "asset_id": "30442780799048074404860985387051749017905070253466005720364298335239299761065", "price": "0.043", "size": "30", "side": "BUY", "timestamp": "1768491257164", "received_at": "2026-01-15T15:34:17.140930"}}
{"event_type": "price_change", "event_ts": "2026-01-15T15:34:17.140930", "ingestion_ts": "2026-01-15T15:34:23.851219", "market_id": "0x49686d26fb712515cd5e12c23f0a1c7e10214c7faa3cb0a730aabe0c33694082", "raw": {"market": "0x49686d26fb712515cd5e12c23f0a1c7e10214c7faa3cb0a730aabe0c33694082", "asset_id": "13244681086321087932946246027856416106585284024824496763706748621681543444582", "price": "0.957", "size": "30", "side": "SELL", "timestamp": "1768491257164", "received_at": "2026-01-15T15:34:17.140930"}}
{"event_type": "price_change", "event_ts": "2026-01-15T15:34:17.140942", "ingestion_ts": "2026-01-15T15:34:23.851219", "market_id": "0x49686d26fb712515cd5e12c23f0a1c7e10214c7faa3cb0a730aabe0c33694082", "raw": {"market": "0x49686d26fb712515cd5e12c23f0a1c7e10214c7faa3cb0a730aabe0c33694082", "asset_id": "30442780799048074404860985387051749017905070253466005720364298335239299761065", "price": "0.021", "size": "700", "side": "BUY", "timestamp": "1768491257165", "received_at": "2026-01-15T15:34:17.140942"}}
{"event_type": "price_change", "event_ts": "2026-01-15T15:34:17.140942", "ingestion_ts": "2026-01-15T15:34:23.851219", "market_id": "0x49686d26fb712515cd5e12c23f0a1c7e10214c7faa3cb0a730aabe0c33694082", "raw": {"market": "0x49686d26fb712515cd5e12c23f0a1c7e10214c7faa3cb0a730aabe0c33694082", "asset_id": "13244681086321087932946246027856416106585284024824496763706748621681543444582", "price": "0.979", "size": "700", "side": "SELL", "timestamp": "1768491257165", "received_at": "2026-01-15T15:34:17.140942"}}
{"event_type": "price_change", "event_ts": "2026-01-15T15:34:17.240023", "ingestion_ts": "2026-01-15T15:34:23.851219", "market_id": "0x49a20c7523c271099008f3ef9a31521263b24d637959852a391e6b4697b1a437", "raw": {"market": "0x49a20c7523c271099008f3ef9a31521263b24d637959852a391e6b4697b1a437", "asset_id": "55881023621710858558280545117465775643848233756850602339827152783696837905531", "price": "0.893", "size": "0", "side": "BUY", "timestamp": "1768491257262", "received_at": "2026-01-15T15:34:17.240023"}}
{"event_type": "price_change", "event_ts": "2026-01-15T15:34:17.240023", "ingestion_ts": "2026-01-15T15:34:23.851219", "market_id": "0x49a20c7523c271099008f3ef9a31521263b24d637959852a391e6b4697b1a437", "raw": {"market": "0x49a20c7523c271099008f3ef9a31521263b24d637959852a391e6b4697b1a437", "asset_id": "13018971792603393862521629014128024641178044618205296260525674415067194037856", "price": "0.107", "size": "0", "side": "SELL", "timestamp": "1768491257262", "received_at": "2026-01-15T15:34:17.240023"}}
{"event_type": "price_change", "event_ts": "2026-01-15T15:34:17.240065", "ingestion_ts": "2026-01-15T15:34:23.851219", "market_id": "0x2393ed0b0fdc450054c7b9071907eca75cf4fc36e385adf4a0a5f99ee62243e8", "raw": {"market": "0x2393ed0b0fdc450054c7b9071907eca75cf4fc36e385adf4a0a5f99ee62243e8", "asset_id": "32769749367306925959219403371425714180265458150646381231272229429098460625924", "price": "0.824", "size": "0", "side": "BUY", "timestamp": "1768491257262", "received_at": "2026-01-15T15:34:17.240065"}}
{"event_type": "price_change", "event_ts": "2026-01-15T15:34:17.240065", "ingestion_ts": "2026-01-15T15:34:23.851219", "market_id": "0x2393ed0b0fdc450054c7b9071907eca75cf4fc36e385adf4a0a5f99ee62243e8", "raw": {"market": "0x2393ed0b0fdc450054c7b9071907eca75cf4fc36e385adf4a0a5f99ee62243e8", "asset_id": "100074770378634056601572485653252702850363676459996771990439989989293515601975", "price": "0.176", "size": "0", "side": "SELL", "timestamp": "1768491257262", "received_at": "2026-01-15T15:34:17.240065"}}
{"event_type": "price_change", "event_ts": "2026-01-15T15:34:17.292011", "ingestion_ts": "2026-01-15T15:34:23.851219", "market_id": "0xae5584fbb57f23c1c608d544b656f23d8bf12340cef70811cf31bb0cb4fc2115", "raw": {"market": "0xae5584fbb57f23c1c608d544b656f23d8bf12340cef70811cf31bb0cb4fc2115", "asset_id": "42278252558046940014991595990628759801692726198478046188873057685686228021663", "price": "0.99", "size": "489", "side": "SELL", "timestamp": "1768491257317", "received_at": "2026-01-15T15:34:17.292011"}}
{"event_type": "price_change", "event_ts": "2026-01-15T15:34:17.292011", "ingestion_ts": "2026-01-15T15:34:23.851219", "market_id": "0xae5584fbb57f23c1c608d544b656f23d8bf12340cef70811cf31bb0cb4fc2115", "raw": {"market": "0xae5584fbb57f23c1c608d544b656f23d8bf12340cef70811cf31bb0cb4fc2115", "asset_id": "28946595841244317705636126646676849578876740730186646421280828201004700559420", "price": "0.01", "size": "489", "side": "BUY", "timestamp": "1768491257317", "received_at": "2026-01-15T15:34:17.292011"}}
{"event_type": "price_change", "event_ts": "2026-01-15T15:34:17.371741", "ingestion_ts": "2026-01-15T15:34:23.851219", "market_id": "0xae5584fbb57f23c1c608d544b656f23d8bf12340cef70811cf31bb0cb4fc2115", "raw": {"market": "0xae5584fbb57f23c1c608d544b656f23d8bf12340cef70811cf31bb0cb4fc2115", "asset_id": "28946595841244317705636126646676849578876740730186646421280828201004700559420", "price": "0.01", "size": "441.2", "side": "BUY", "timestamp": "1768491257412", "received_at": "2026-01-15T15:34:17.371741"}}
{"event_type": "price_change", "event_ts": "2026-01-15T15:34:17.371741", "ingestion_ts": "2026-01-15T15:34:23.851219", "market_id": "0xae5584fbb57f23c1c608d544b656f23d8bf12340cef70811cf31bb0cb4fc2115", "raw": {"market": "0xae5584fbb57f23c1c608d544b656f23d8bf12340cef70811cf31bb0cb4fc2115", "asset_id": "42278252558046940014991595990628759801692726198478046188873057685686228021663", "price": "0.99", "size": "441.2", "side": "SELL", "timestamp": "1768491257412", "received_at": "2026-01-15T15:34:17.371741"}}
{"event_type": "price_change", "event_ts": "2026-01-15T15:34:17.389851", "ingestion_ts": "2026-01-15T15:34:23.851219", "market_id": "0x2393ed0b0fdc450054c7b9071907eca75cf4fc36e385adf4a0a5f99ee62243e8", "raw": {"market": "0x2393ed0b0fdc450054c7b9071907eca75cf4fc36e385adf4a0a5f99ee62243e8", "asset_id": "32769749367306925959219403371425714180265458150646381231272229429098460625924", "price": "0.88", "size": "25", "side": "BUY", "timestamp": "1768491257429", "received_at": "2026-01-15T15:34:17.389851"}}
{"event_type": "price_change", "event_ts": "2026-01-15T15:34:17.389851", "ingestion_ts": "2026-01-15T15:34:23.851219", "market_id": "0x2393ed0b0fdc450054c7b9071907eca75cf4fc36e385adf4a0a5f99ee62243e8", "raw": {"market": "0x2393ed0b0fdc450054c7b9071907eca75cf4fc36e385adf4a0a5f99ee62243e8", "asset_id": "100074770378634056601572485653252702850363676459996771990439989989293515601975", "price": "0.12", "size": "25", "side": "SELL", "timestamp": "1768491257429", "received_at": "2026-01-15T15:34:17.389851"}}
{"event_type": "price_change", "event_ts": "2026-01-15T15:34:17.389887", "ingestion_ts": "2026-01-15T15:34:23.851219", "market_id": "0x49a20c7523c271099008f3ef9a31521263b24d637959852a391e6b4697b1a437", "raw": {"market": "0x49a20c7523c271099008f3ef9a31521263b24d637959852a391e6b4697b1a437", "asset_id": "55881023621710858558280545117465775643848233756850602339827152783696837905531", "price": "0.825", "size": "25", "side": "BUY", "timestamp": "1768491257429", "received_at": "2026-01-15T15:34:17.389887"}}
{"event_type": "price_change", "event_ts": "2026-01-15T15:34:17.389887", "ingestion_ts": "2026-01-15T15:34:23.851219", "market_id": "0x49a20c7523c271099008f3ef9a31521263b24d637959852a391e6b4697b1a437", "raw": {"market": "0x49a20c7523c271099008f3ef9a31521263b24d637959852a391e6b4697b1a437", "asset_id": "13018971792603393862521629014128024641178044618205296260525674415067194037856", "price": "0.175", "size": "25", "side": "SELL", "timestamp": "1768491257429", "received_at": "2026-01-15T15:34:17.389887"}}
{"event_type": "price_change", "event_ts": "2026-01-15T15:34:23.812927", "ingestion_ts": "2026-01-15T15:34:23.851219", "market_id": "0xae5584fbb57f23c1c608d544b656f23d8bf12340cef70811cf31bb0cb4fc2115", "raw": {"market": "0xae5584fbb57f23c1c608d544b656f23d8bf12340cef70811cf31bb0cb4fc2115", "asset_id": "42278252558046940014991595990628759801692726198478046188873057685686228021663", "price": "0.99", "size": "543.4", "side": "SELL", "timestamp": "1768491263848", "received_at": "2026-01-15T15:34:23.812927"}}
{"event_type": "price_change", "event_ts": "2026-01-15T15:34:23.812927", "ingestion_ts": "2026-01-15T15:34:23.851219", "market_id": "0xae5584fbb57f23c1c608d544b656f23d8bf12340cef70811cf31bb0cb4fc2115", "raw": {"market": "0xae5584fbb57f23c1c608d544b656f23d8bf12340cef70811cf31bb0cb4fc2115", "asset_id": "28946595841244317705636126646676849578876740730186646421280828201004700559420", "price": "0.01", "size": "543.4", "side": "BUY", "timestamp": "1768491263848", "received_at": "2026-01-15T15:34:23.812927"}}
