{"event_type": "price_change", "event_ts": "2026-01-16T14:35:49.766455", "ingestion_ts": "2026-01-16T14:36:49.604167", "market_id": "0xc0e6b917320a47228fb96e3b5ae0e5c93773a5ae2662ae4e1f37807cfe47ce98", "raw": {"market": "0xc0e6b917320a47228fb96e3b5ae0e5c93773a5ae2662ae4e1f37807cfe47ce98", "asset_id": "58656358377246279051017109359677190749228949103591068167284263961542487110215", "price": "0.002", "size": "3279.99", "side": "BUY", "timestamp": "1768574149724", "received_at": "2026-01-16T14:35:49.766455"}}
{"event_type": "price_change", "event_ts": "2026-01-16T14:35:49.766455", "ingestion_ts": "2026-01-16T14:36:49.604167", "market_id": "0xc0e6b917320a47228fb96e3b5ae0e5c93773a5ae2662ae4e1f37807cfe47ce98", "raw": {"market": "0xc0e6b917320a47228fb96e3b5ae0e5c93773a5ae2662ae4e1f37807cfe47ce98", "asset_id": "81647294538046680798858716589766492074338758116170717123345952330712416337530", "price": "0.998", "size": "3279.99", "side": "SELL", "timestamp": "1768574149724", "received_at": "2026-01-16T14:35:49.766455"}}
{"event_type": "price_change", "event_ts": "2026-01-16T14:35:50.270012", "ingestion_ts": "2026-01-16T14:36:49.604167", "market_id": "0xc55db914f0fd1fee18997706712c0dfd8d0369cdbef93a9fef12bd001914ca77", "raw": {"market": "0xc55db914f0fd1fee18997706712c0dfd8d0369cdbef93a9fef12bd001914ca77", "asset_id": "114600293444080540179603459515770723592661967180480327891296353898330242622833", "price": "0.857", "size": "233", "side": "BUY", "timestamp": "1768574150230", "received_at": "2026-01-16T14:35:50.270012"}}
{"event_type": "price_change", "event_ts": "2026-01-16T14:35:50.270012", "ingestion_ts": "2026-01-16T14:36:49.604167", "market_id": "0xc55db914f0fd1fee18997706712c0dfd8d0369cdbef93a9fef12bd001914ca77", "raw": {"market": "0xc55db914f0fd1fee18997706712c0dfd8d0369cdbef93a9fef12bd001914ca77", "asset_id": "72354723612769247426741660426331235762851940382312402276325808095604519806766", "price": "0.143", "size": "233", "side": "SELL", "timestamp": "1768574150230", "received_at": "2026-01-16T14:35:50.270012"}}
{"event_type": "price_change", "event_ts": "2026-01-16T14:35:50.270054", "ingestion_ts": "2026-01-16T14:36:49.604167", "market_id": "0x44f08744458b8896620cd3330bc5e1ea69df4199b02d4fc583b3fc96e5d314ce", "raw": {"market": "0x44f08744458b8896620cd3330bc5e1ea69df4199b02d4fc583b3fc96e5d314ce", "asset_id": "72327831507226612545928776794104143393438710920370371172884559893525100761096", "price": "0.853", "size": "234", "side": "BUY", "timestamp": "1768574150230", "received_at": "2026-01-16T14:35:50.270054"}}
{"event_type": "price_change", "event_ts": "2026-01-16T14:35:50.270054", "ingestion_ts": "2026-01-16T14:36:49.604167", "market_id": "0x44f08744458b8896620cd3330bc5e1ea69df4199b02d4fc583b3fc96e5d314ce", "raw": {"market": "0x44f08744458b8896620cd3330bc5e1ea69df4199b02d4fc583b3fc96e5d314ce", "asset_id": "49194009556504828848509244326501559253829462790583873936160989575507522044057", "price": "0.147", "size": "234", "side": "SELL", "timestamp": "1768574150230", "received_at": "2026-01-16T14:35:50.270054"}}
{"event_type": "price_change", "event_ts": "2026-01-16T14:35:50.270070", "ingestion_ts": "2026-01-16T14:36:49.604167", "market_id": "0x50c669f178da4e5bbea7f1be25041fd278914712fa87a6a6f8e57d5923d88dee", "raw": {"market": "0x50c669f178da4e5bbea7f1be25041fd278914712fa87a6a6f8e57d5923d88dee", "asset_id": "74040420326294854165772767082819937451857852955603897473157746262672057685461", "price": "0.855", "size": "584", "side": "BUY", "timestamp": "1768574150230", "received_at": "2026-01-16T14:35:50.270070"}}
{"event_type": "price_change", "event_ts": "2026-01-16T14:35:50.270070", "ingestion_ts": "2026-01-16T14:36:49.604167", "market_id": "0x50c669f178da4e5bbea7f1be25041fd278914712fa87a6a6f8e57d5923d88dee", "raw": {"market": "0x50c669f178da4e5bbea7f1be25041fd278914712fa87a6a6f8e57d5923d88dee", "asset_id": "24682525479474221428144937281315825971983904267399062415430320764754931667953", "price": "0.145", "size": "584", "side": "SELL", "timestamp": "1768574150230", "received_at": "2026-01-16T14:35:50.270070"}}
{"event_type": "price_change", "event_ts": "2026-01-16T14:35:50.270083", "ingestion_ts": "2026-01-16T14:36:49.604167", "market_id": "0x49686d26fb712515cd5e12c23f0a1c7e10214c7faa3cb0a730aabe0c33694082", "raw": {"market": "0x49686d26fb712515cd5e12c23f0a1c7e10214c7faa3cb0a730aabe0c33694082", "asset_id": "30442780799048074404860985387051749017905070253466005720364298335239299761065", "price": "0.004", "size": "0", "side": "BUY", "timestamp": "1768574150230", "received_at": "2026-01-16T14:35:50.270083"}}
{"event_type": "price_change", "event_ts": "2026-01-16T14:35:50.270083", "ingestion_ts": "2026-01-16T14:36:49.604167", "market_id": "0x49686d26fb712515cd5e12c23f0a1c7e10214c7faa3cb0a730aabe0c33694082", "raw": {"market": "0x49686d26fb712515cd5e12c23f0a1c7e10214c7faa3cb0a730aabe0c33694082", "asset_id": "13244681086321087932946246027856416106585284024824496763706748621681543444582", "price": "0.996", "size": "0", "side": "SELL", "timestamp": "1768574150230", "received_at": "2026-01-16T14:35:50.270083"}}
{"event_type": "price_change", "event_ts": "2026-01-16T14:35:50.270095", "ingestion_ts": "2026-01-16T14:36:49.604167", "market_id": "0x49a20c7523c271099008f3ef9a31521263b24d637959852a391e6b4697b1a437", "raw": {"market": "0x49a20c7523c271099008f3ef9a31521263b24d637959852a391e6b4697b1a437", "asset_id": "55881023621710858558280545117465775643848233756850602339827152783696837905531", "price": "0.855", "size": "292", "side": "BUY", "timestamp": "1768574150230", "received_at": "2026-01-16T14:35:50.270095"}}
{"event_type": "price_change", "event_ts": "2026-01-16T14:35:50.270095", "ingestion_ts": "2026-01-16T14:36:49.604167", "market_id": "0x49a20c7523c271099008f3ef9a31521263b24d637959852a391e6b4697b1a437", "raw": {"market": "0x49a20c7523c271099008f3ef9a31521263b24d637959852a391e6b4697b1a437", "asset_id": "13018971792603393862521629014128024641178044618205296260525674415067194037856", "price": "0.145", "size": "292", "side": "SELL", "timestamp": "1768574150230", "received_at": "2026-01-16T14:35:50.270095"}}
{"event_type": "price_change", "event_ts": "2026-01-16T14:35:50.299401", "ingestion_ts": "2026-01-16T14:36:49.604167", "market_id": "0x50c669f178da4e5bbea7f1be25041fd278914712fa87a6a6f8e57d5923d88dee", "raw": {"market": "0x50c669f178da4e5bbea7f1be25041fd278914712fa87a6a6f8e57d5923d88dee", "asset_id": "74040420326294854165772767082819937451857852955603897473157746262672057685461", "price": "0.856", "size": "10", "side": "BUY", "timestamp": "1768574150262", "received_at": "2026-01-16T14:35:50.299401"}}
{"event_type": "price_change", "event_ts": "2026-01-16T14:35:50.299401", "ingestion_ts": "2026-01-16T14:36:49.604167", "market_id": "0x50c669f178da4e5bbea7f1be25041fd278914712fa87a6a6f8e57d5923d88dee", "raw": {"market": "0x50c669f178da4e5bbea7f1be25041fd278914712fa87a6a6f8e57d5923d88dee", "asset_id": "24682525479474221428144937281315825971983904267399062415430320764754931667953", "price": "0.144", "size": "10", "side": "SELL", "timestamp": "1768574150262", "received_at": "2026-01-16T14:35:50.299401"}}
{"event_type": "price_change", "event_ts": "2026-01-16T14:35:50.299461", "ingestion_ts": "2026-01-16T14:36:49.604167", "market_id": "0xc55db914f0fd1fee18997706712c0dfd8d0369cdbef93a9fef12bd001914ca77", "raw": {"market": "0xc55db914f0fd1fee18997706712c0dfd8d0369cdbef93a9fef12bd001914ca77", "asset_id": "114600293444080540179603459515770723592661967180480327891296353898330242622833", "price": "0.858", "size": "10", "side": "BUY", "timestamp": "1768574150262", "received_at": "2026-01-16T14:35:50.299461"}}
{"event_type": "price_change", "event_ts": "2026-01-16T14:35:50.299461", "ingestion_ts": "2026-01-16T14:36:49.604167", "market_id": "0xc55db914f0fd1fee18997706712c0dfd8d0369cdbef93a9fef12bd001914ca77", "raw": {"market": "0xc55db914f0fd1fee18997706712c0dfd8d0369cdbef93a9fef12bd001914ca77", "asset_id": "72354723612769247426741660426331235762851940382312402276325808095604519806766", "price": "0.142", "size": "10", "side": "SELL", "timestamp": "1768574150262", "received_at": "2026-01-16T14:35:50.299461"}}
{"event_type": "price_change", "event_ts": "2026-01-16T14:35:50.299478", "ingestion_ts": "2026-01-16T14:36:49.604167", "market_id": "0x49a20c7523c271099008f3ef9a31521263b24d637959852a391e6b4697b1a437", "raw": {"market": "0x49a20c7523c271099008f3ef9a31521263b24d637959852a391e6b4697b1a437", "asset_id": "55881023621710858558280545117465775643848233756850602339827152783696837905531", "price": "0.856", "size": "40", "side": "BUY", "timestamp": "1768574150262", "received_at": "2026-01-16T14:35:50.299478"}}
{"event_type": "price_change", "event_ts": "2026-01-16T14:35:50.299478", "ingestion_ts": "2026-01-16T14:36:49.604167", "market_id": "0x49a20c7523c271099008f3ef9a31521263b24d637959852a391e6b4697b1a437", "raw": {"market": "0x49a20c7523c271099008f3ef9a31521263b24d637959852a391e6b4697b1a437", "asset_id": "13018971792603393862521629014128024641178044618205296260525674415067194037856", "price": "0.144", "size": "40", "side": "SELL", "timestamp": "1768574150262", "received_at": "2026-01-16T14:35:50.299478"}}
{"event_type": "price_change", "event_ts": "2026-01-16T14:35:50.300080", "ingestion_ts": "2026-01-16T14:36:49.604167", "market_id": "0x49686d26fb712515cd5e12c23f0a1c7e10214c7faa3cb0a730aabe0c33694082", "raw": {"market": "0x49686d26fb712515cd5e12c23f0a1c7e10214c7faa3cb0a730aabe0c33694082", "asset_id": "30442780799048074404860985387051749017905070253466005720364298335239299761065", "price": "0.005", "size": "109.51", "side": "BUY", "timestamp": "1768574150262", "received_at": "2026-01-16T14:35:50.300080"}}
{"event_type": "price_change", "event_ts": "2026-01-16T14:35:50.300080", "ingestion_ts": "2026-01-16T14:36:49.604167", "market_id": "0x49686d26fb712515cd5e12c23f0a1c7e10214c7faa3cb0a730aabe0c33694082", "raw": {"market": "0x49686d26fb712515cd5e12c23f0a1c7e10214c7faa3cb0a730aabe0c33694082", "asset_id": "13244681086321087932946246027856416106585284024824496763706748621681543444582", "price": "0.995", "size": "109.51", "side": "SELL", "timestamp": "1768574150262", "received_at": "2026-01-16T14:35:50.300080"}}
{"event_type": "price_change", "event_ts": "2026-01-16T14:35:50.300123", "ingestion_ts": "2026-01-16T14:36:49.604167", "market_id": "0x44f08744458b8896620cd3330bc5e1ea69df4199b02d4fc583b3fc96e5d314ce", "raw": {"market": "0x44f08744458b8896620cd3330bc5e1ea69df4199b02d4fc583b3fc96e5d314ce", "asset_id": "72327831507226612545928776794104143393438710920370371172884559893525100761096", "price": "0.854", "size": "10", "side": "BUY", "timestamp": "1768574150262", "received_at": "2026-01-16T14:35:50.300123"}}
{"event_type": "price_change", "event_ts": "2026-01-16T14:35:50.300123", "ingestion_ts": "2026-01-16T14:36:49.604167", "market_id": "0x44f08744458b8896620cd3330bc5e1ea69df4199b02d4fc583b3fc96e5d314ce", "raw": {"market": "0x44f08744458b8896620cd3330bc5e1ea69df4199b02d4fc583b3fc96e5d314ce", "asset_id": "49194009556504828848509244326501559253829462790583873936160989575507522044057", "price": "0.146", "size": "10", "side": "SELL", "timestamp": "1768574150262", "received_at": "2026-01-16T14:35:50.300123"}}
{"event_type": "price_change", "event_ts": "2026-01-16T14:35:50.338154", "ingestion_ts": "2026-01-16T14:36:49.604167", "market_id": "0xaf9d0e448129a9f657f851d49495ba4742055d80e0ef1166ba0ee81d4d594214", "raw": {"market": "0xaf9d0e448129a9f657f851d49495ba4742055d80e0ef1166ba0ee81d4d594214", "asset_id": "4153292802911610701832309484716814274802943278345248636922528170020319407796", "price": "0.989", "size": "0", "side": "SELL", "timestamp": "1768574150302", "received_at": "2026-01-16T14:35:50.338154"}}
{"event_type": "price_change", "event_ts": "2026-01-16T14:35:50.338154", "ingestion_ts": "2026-01-16T14:36:49.604167", "market_id": "0xaf9d0e448129a9f657f851d49495ba4742055d80e0ef1166ba0ee81d4d594214", "raw": {"market": "0xaf9d0e448129a9f657f851d49495ba4742055d80e0ef1166ba0ee81d4d594214", "asset_id": "101676997363687199724245607342877036148401850938023978421879460310389391082353", "price": "0.011", "size": "0", "side": "BUY", "timestamp": "1768574150302", "received_at": "2026-01-16T14:35:50.338154"}}
{"event_type": "price_change", "event_ts": "2026-01-16T14:35:50.504865", "ingestion_ts": "2026-01-16T14:36:49.604167", "market_id": "0xc0e6b917320a47228fb96e3b5ae0e5c93773a5ae2662ae4e1f37807cfe47ce98", "raw": {"market": "0xc0e6b917320a47228fb96e3b5ae0e5c93773a5ae2662ae4e1f37807cfe47ce98", "asset_id": "58656358377246279051017109359677190749228949103591068167284263961542487110215", "price": "0.002", "size": "3287.1", "side": "BUY", "timestamp": "1768574150468", "received_at": "2026-01-16T14:35:50.504865"}}
{"event_type": "price_change", "event_ts": "2026-01-16T14:35:50.504865", "ingestion_ts": "2026-01-16T14:36:49.604167", "market_id": "0xc0e6b917320a47228fb96e3b5ae0e5c93773a5ae2662ae4e1f37807cfe47ce98", "raw": {"market": "0xc0e6b917320a47228fb96e3b5ae0e5c93773a5ae2662ae4e1f37807cfe47ce98", "asset_id": "81647294538046680798858716589766492074338758116170717123345952330712416337530", "price": "0.998", "size": "3287.1", "side": "SELL", "timestamp": "1768574150468", "received_at": "2026-01-16T14:35:50.504865"}}
{"event_type": "price_change", "event_ts": "2026-01-16T14:35:50.508412", "ingestion_ts": "2026-01-16T14:36:49.604167", "market_id": "0xc0e6b917320a47228fb96e3b5ae0e5c93773a5ae2662ae4e1f37807cfe47ce98", "raw": {"market": "0xc0e6b917320a47228fb96e3b5ae0e5c93773a5ae2662ae4e1f37807cfe47ce98", "asset_id": "58656358377246279051017109359677190749228949103591068167284263961542487110215", "price": "0.002", "size": "3294.21", "side": "BUY", "timestamp": "1768574150469", "received_at": "2026-01-16T14:35:50.508412"}}
{"event_type": "price_change", "event_ts": "2026-01-16T14:35:50.508412", "ingestion_ts": "2026-01-16T14:36:49.604167", "market_id": "0xc0e6b917320a47228fb96e3b5ae0e5c93773a5ae2662ae4e1f37807cfe47ce98", "raw": {"market": "0xc0e6b917320a47228fb96e3b5ae0e5c93773a5ae2662ae4e1f37807cfe47ce98", "asset_id": "81647294538046680798858716589766492074338758116170717123345952330712416337530", "price": "0.998", "size": "3294.21", "side": "SELL", "timestamp": "1768574150469", "received_at": "2026-01-16T14:35:50.508412"}}
{"event_type": "price_change", "event_ts": "2026-01-16T14:35:50.691362", "ingestion_ts": "2026-01-16T14:36:49.604167", "market_id": "0xaf9d0e448129a9f657f851d49495ba4742055d80e0ef1166ba0ee81d4d594214", "raw": {"market": "0xaf9d0e448129a9f657f851d49495ba4742055d80e0ef1166ba0ee81d4d594214", "asset_id": "4153292802911610701832309484716814274802943278345248636922528170020319407796", "price": "0.978", "size": "20.5", "side": "SELL", "timestamp": "1768574150623", "received_at": "2026-01-16T14:35:50.691362"}}
{"event_type": "price_change", "event_ts": "2026-01-16T14:35:50.691362", "ingestion_ts": "2026-01-16T14:36:49.604167", "market_id": "0xaf9d0e448129a9f657f851d49495ba4742055d80e0ef1166ba0ee81d4d594214", "raw": {"market": "0xaf9d0e448129a9f657f851d49495ba4742055d80e0ef1166ba0ee81d4d594214", "asset_id": "101676997363687199724245607342877036148401850938023978421879460310389391082353", "price": "0.022", "size": "20.5", "side": "BUY", "timestamp": "1768574150623", "received_at": "2026-01-16T14:35:50.691362"}}
{"event_type": "price_change", "event_ts": "2026-01-16T14:35:51.323037", "ingestion_ts": "2026-01-16T14:36:49.604167", "market_id": "0x49a20c7523c271099008f3ef9a31521263b24d637959852a391e6b4697b1a437", "raw": {"market": "0x49a20c7523c271099008f3ef9a31521263b24d637959852a391e6b4697b1a437", "asset_id": "55881023621710858558280545117465775643848233756850602339827152783696837905531", "price": "0.856", "size": "30", "side": "BUY", "timestamp": "1768574151280", "received_at": "2026-01-16T14:35:51.323037"}}
{"event_type": "price_change", "event_ts": "2026-01-16T14:35:51.323037", "ingestion_ts": "2026-01-16T14:36:49.604167", "market_id": "0x49a20c7523c271099008f3ef9a31521263b24d637959852a391e6b4697b1a437", "raw": {"market": "0x49a20c7523c271099008f3ef9a31521263b24d637959852a391e6b4697b1a437", "asset_id": "13018971792603393862521629014128024641178044618205296260525674415067194037856", "price": "0.144", "size": "30", "side": "SELL", "timestamp": "1768574151280", "received_at": "2026-01-16T14:35:51.323037"}}
{"event_type": "price_change", "event_ts": "2026-01-16T14:35:51.323081", "ingestion_ts": "2026-01-16T14:36:49.604167", "market_id": "0x50c669f178da4e5bbea7f1be25041fd278914712fa87a6a6f8e57d5923d88dee", "raw": {"market": "0x50c669f178da4e5bbea7f1be25041fd278914712fa87a6a6f8e57d5923d88dee", "asset_id": "74040420326294854165772767082819937451857852955603897473157746262672057685461", "price": "0.856", "size": "0", "side": "BUY", "timestamp": "1768574151280", "received_at": "2026-01-16T14:35:51.323081"}}
{"event_type": "price_change", "event_ts": "2026-01-16T14:35:51.323081", "ingestion_ts": "2026-01-16T14:36:49.604167", "market_id": "0x50c669f178da4e5bbea7f1be25041fd278914712fa87a6a6f8e57d5923d88dee", "raw": {"market": "0x50c669f178da4e5bbea7f1be25041fd278914712fa87a6a6f8e57d5923d88dee", "asset_id": "24682525479474221428144937281315825971983904267399062415430320764754931667953", "price": "0.144", "size": "0", "side": "SELL", "timestamp": "1768574151280", "received_at": "2026-01-16T14:35:51.323081"}}
{"event_type": "price_change", "event_ts": "2026-01-16T14:35:51.323108", "ingestion_ts": "2026-01-16T14:36:49.604167", "market_id": "0x2393ed0b0fdc450054c7b9071907eca75cf4fc36e385adf4a0a5f99ee62243e8", "raw": {"market": "0x2393ed0b0fdc450054c7b9071907eca75cf4fc36e385adf4a0a5f99ee62243e8", "asset_id": "32769749367306925959219403371425714180265458150646381231272229429098460625924", "price": "0.811", "size": "0", "side": "BUY", "timestamp": "1768574151280", "received_at": "2026-01-16T14:35:51.323108"}}
{"event_type": "price_change", "event_ts": "2026-01-16T14:35:51.323108", "ingestion_ts": "2026-01-16T14:36:49.604167", "market_id": "0x2393ed0b0fdc450054c7b9071907eca75cf4fc36e385adf4a0a5f99ee62243e8", "raw": {"market": "0x2393ed0b0fdc450054c7b9071907eca75cf4fc36e385adf4a0a5f99ee62243e8", "asset_id": "100074770378634056601572485653252702850363676459996771990439989989293515601975", "price": "0.189", "size": "0", "side": "SELL", "timestamp": "1768574151280", "received_at": "2026-01-16T14:35:51.323108"}}
{"event_type": "price_change", "event_ts": "2026-01-16T14:35:51.323121", "ingestion_ts": "2026-01-16T14:36:49.604167", "market_id": "0x9472be65457510b7fc3477b20ba90910e99d92eac8421a14bf4b7b7a08ef31dc", "raw": {"market": "0x9472be65457510b7fc3477b20ba90910e99d92eac8421a14bf4b7b7a08ef31dc", "asset_id": "43311793366960417907757893276427136943959788721376762326430771171648759300146", "price": "0.856", "size": "0", "side": "BUY", "timestamp": "1768574151280", "received_at": "2026-01-16T14:35:51.323121"}}
{"event_type": "price_change", "event_ts": "2026-01-16T14:35:51.323121", "ingestion_ts": "2026-01-16T14:36:49.604167", "market_id": "0x9472be65457510b7fc3477b20ba90910e99d92eac8421a14bf4b7b7a08ef31dc", "raw": {"market": "0x9472be65457510b7fc3477b20ba90910e99d92eac8421a14bf4b7b7a08ef31dc", "asset_id": "73414222381656326204771753454630063673548497164758947581648273905027617570612", "price": "0.144", "size": "0", "side": "SELL", "timestamp": "1768574151280", "received_at": "2026-01-16T14:35:51.323121"}}
{"event_type": "price_change", "event_ts": "2026-01-16T14:35:51.323134", "ingestion_ts": "2026-01-16T14:36:49.604167", "market_id": "0xc55db914f0fd1fee18997706712c0dfd8d0369cdbef93a9fef12bd001914ca77", "raw": {"market": "0xc55db914f0fd1fee18997706712c0dfd8d0369cdbef93a9fef12bd001914ca77", "asset_id": "114600293444080540179603459515770723592661967180480327891296353898330242622833", "price": "0.858", "size": "0", "side": "BUY", "timestamp": "1768574151280", "received_at": "2026-01-16T14:35:51.323134"}}
{"event_type": "price_change", "event_ts": "2026-01-16T14:35:51.323134", "ingestion_ts": "2026-01-16T14:36:49.604167", "market_id": "0xc55db914f0fd1fee18997706712c0dfd8d0369cdbef93a9fef12bd001914ca77", "raw": {"market": "0xc55db914f0fd1fee18997706712c0dfd8d0369cdbef93a9fef12bd001914ca77", "asset_id": "72354723612769247426741660426331235762851940382312402276325808095604519806766", "price": "0.142", "size": "0", "side": "SELL", "timestamp": "1768574151280", "received_at": "2026-01-16T14:35:51.323134"}}
{"event_type": "price_change", "event_ts": "2026-01-16T14:35:51.323146", "ingestion_ts": "2026-01-16T14:36:49.604167", "market_id": "0x49686d26fb712515cd5e12c23f0a1c7e10214c7faa3cb0a730aabe0c33694082", "raw": {"market": "0x49686d26fb712515cd5e12c23f0a1c7e10214c7faa3cb0a730aabe0c33694082", "asset_id": "30442780799048074404860985387051749017905070253466005720364298335239299761065", "price": "0.005", "size": "99.51", "side": "BUY", "timestamp": "1768574151280", "received_at": "2026-01-16T14:35:51.323146"}}
{"event_type": "price_change", "event_ts": "2026-01-16T14:35:51.323146", "ingestion_ts": "2026-01-16T14:36:49.604167", "market_id": "0x49686d26fb712515cd5e12c23f0a1c7e10214c7faa3cb0a730aabe0c33694082", "raw": {"market": "0x49686d26fb712515cd5e12c23f0a1c7e10214c7faa3cb0a730aabe0c33694082", "asset_id": "13244681086321087932946246027856416106585284024824496763706748621681543444582", "price": "0.995", "size": "99.51", "side": "SELL", "timestamp": "1768574151280", "received_at": "2026-01-16T14:35:51.323146"}}
{"event_type": "price_change", "event_ts": "2026-01-16T14:35:51.357350", "ingestion_ts": "2026-01-16T14:36:49.604167", "market_id": "0x50c669f178da4e5bbea7f1be25041fd278914712fa87a6a6f8e57d5923d88dee", "raw": {"market": "0x50c669f178da4e5bbea7f1be25041fd278914712fa87a6a6f8e57d5923d88dee", "asset_id": "74040420326294854165772767082819937451857852955603897473157746262672057685461", "price": "0.857", "size": "35", "side": "BUY", "timestamp": "1768574151312", "received_at": "2026-01-16T14:35:51.357350"}}
{"event_type": "price_change", "event_ts": "2026-01-16T14:35:51.357350", "ingestion_ts": "2026-01-16T14:36:49.604167", "market_id": "0x50c669f178da4e5bbea7f1be25041fd278914712fa87a6a6f8e57d5923d88dee", "raw": {"market": "0x50c669f178da4e5bbea7f1be25041fd278914712fa87a6a6f8e57d5923d88dee", "asset_id": "24682525479474221428144937281315825971983904267399062415430320764754931667953", "price": "0.143", "size": "35", "side": "SELL", "timestamp": "1768574151312", "received_at": "2026-01-16T14:35:51.357350"}}
{"event_type": "price_change", "event_ts": "2026-01-16T14:35:51.357412", "ingestion_ts": "2026-01-16T14:36:49.604167", "market_id": "0x9472be65457510b7fc3477b20ba90910e99d92eac8421a14bf4b7b7a08ef31dc", "raw": {"market": "0x9472be65457510b7fc3477b20ba90910e99d92eac8421a14bf4b7b7a08ef31dc", "asset_id": "43311793366960417907757893276427136943959788721376762326430771171648759300146", "price": "0.858", "size": "243", "side": "BUY", "timestamp": "1768574151312", "received_at": "2026-01-16T14:35:51.357412"}}
{"event_type": "price_change", "event_ts": "2026-01-16T14:35:51.357412", "ingestion_ts": "2026-01-16T14:36:49.604167", "market_id": "0x9472be65457510b7fc3477b20ba90910e99d92eac8421a14bf4b7b7a08ef31dc", "raw": {"market": "0x9472be65457510b7fc3477b20ba90910e99d92eac8421a14bf4b7b7a08ef31dc", "asset_id": "73414222381656326204771753454630063673548497164758947581648273905027617570612", "price": "0.142", "size": "243", "side": "SELL", "timestamp": "1768574151312", "received_at": "2026-01-16T14:35:51.357412"}}
{"event_type": "price_change", "event_ts": "2026-01-16T14:35:51.357429", "ingestion_ts": "2026-01-16T14:36:49.604167", "market_id": "0x2393ed0b0fdc450054c7b9071907eca75cf4fc36e385adf4a0a5f99ee62243e8", "raw": {"market": "0x2393ed0b0fdc450054c7b9071907eca75cf4fc36e385adf4a0a5f99ee62243e8", "asset_id": "32769749367306925959219403371425714180265458150646381231272229429098460625924", "price": "0.849", "size": "304", "side": "BUY", "timestamp": "1768574151312", "received_at": "2026-01-16T14:35:51.357429"}}
{"event_type": "price_change", "event_ts": "2026-01-16T14:35:51.357429", "ingestion_ts": "2026-01-16T14:36:49.604167", "market_id": "0x2393ed0b0fdc450054c7b9071907eca75cf4fc36e385adf4a0a5f99ee62243e8", "raw": {"market": "0x2393ed0b0fdc450054c7b9071907eca75cf4fc36e385adf4a0a5f99ee62243e8", "asset_id": "100074770378634056601572485653252702850363676459996771990439989989293515601975", "price": "0.151", "size": "304", "side": "SELL", "timestamp": "1768574151312", "received_at": "2026-01-16T14:35:51.357429"}}
{"event_type": "price_change", "event_ts": "2026-01-16T14:35:51.357451", "ingestion_ts": "2026-01-16T14:36:49.604167", "market_id": "0xc55db914f0fd1fee18997706712c0dfd8d0369cdbef93a9fef12bd001914ca77", "raw": {"market": "0xc55db914f0fd1fee18997706712c0dfd8d0369cdbef93a9fef12bd001914ca77", "asset_id": "114600293444080540179603459515770723592661967180480327891296353898330242622833", "price": "0.859", "size": "40", "side": "BUY", "timestamp": "1768574151312", "received_at": "2026-01-16T14:35:51.357451"}}
{"event_type": "price_change", "event_ts": "2026-01-16T14:35:51.357451", "ingestion_ts": "2026-01-16T14:36:49.604167", "market_id": "0xc55db914f0fd1fee18997706712c0dfd8d0369cdbef93a9fef12bd001914ca77", "raw": {"market": "0xc55db914f0fd1fee18997706712c0dfd8d0369cdbef93a9fef12bd001914ca77", "asset_id": "72354723612769247426741660426331235762851940382312402276325808095604519806766", "price": "0.141", "size": "40", "side": "SELL", "timestamp": "1768574151312", "received_at": "2026-01-16T14:35:51.357451"}}
{"event_type": "price_change", "event_ts": "2026-01-16T14:35:51.357462", "ingestion_ts": "2026-01-16T14:36:49.604167", "market_id": "0x49686d26fb712515cd5e12c23f0a1c7e10214c7faa3cb0a730aabe0c33694082", "raw": {"market": "0x49686d26fb712515cd5e12c23f0a1c7e10214c7faa3cb0a730aabe0c33694082", "asset_id": "30442780799048074404860985387051749017905070253466005720364298335239299761065", "price": "0.006", "size": "20.08", "side": "BUY", "timestamp": "1768574151312", "received_at": "2026-01-16T14:35:51.357462"}}
{"event_type": "price_change", "event_ts": "2026-01-16T14:35:51.357462", "ingestion_ts": "2026-01-16T14:36:49.604167", "market_id": "0x49686d26fb712515cd5e12c23f0a1c7e10214c7faa3cb0a730aabe0c33694082", "raw": {"market": "0x49686d26fb712515cd5e12c23f0a1c7e10214c7faa3cb0a730aabe0c33694082", "asset_id": "13244681086321087932946246027856416106585284024824496763706748621681543444582", "price": "0.994", "size": "20.08", "side": "SELL", "timestamp": "1768574151312", "received_at": "2026-01-16T14:35:51.357462"}}
{"event_type": "price_change", "event_ts": "2026-01-16T14:35:51.357473", "ingestion_ts": "2026-01-16T14:36:49.604167", "market_id": "0x49a20c7523c271099008f3ef9a31521263b24d637959852a391e6b4697b1a437", "raw": {"market": "0x49a20c7523c271099008f3ef9a31521263b24d637959852a391e6b4697b1a437", "asset_id": "55881023621710858558280545117465775643848233756850602339827152783696837905531", "price": "0.857", "size": "10", "side": "BUY", "timestamp": "1768574151312", "received_at": "2026-01-16T14:35:51.357473"}}
{"event_type": "price_change", "event_ts": "2026-01-16T14:35:51.357473", "ingestion_ts": "2026-01-16T14:36:49.604167", "market_id": "0x49a20c7523c271099008f3ef9a31521263b24d637959852a391e6b4697b1a437", "raw": {"market": "0x49a20c7523c271099008f3ef9a31521263b24d637959852a391e6b4697b1a437", "asset_id": "13018971792603393862521629014128024641178044618205296260525674415067194037856", "price": "0.143", "size": "10", "side": "SELL", "timestamp": "1768574151312", "received_at": "2026-01-16T14:35:51.357473"}}
{"event_type": "price_change", "event_ts": "2026-01-16T14:35:51.605089", "ingestion_ts": "2026-01-16T14:36:49.604167", "market_id": "0x49686d26fb712515cd5e12c23f0a1c7e10214c7faa3cb0a730aabe0c33694082", "raw": {"market": "0x49686d26fb712515cd5e12c23f0a1c7e10214c7faa3cb0a730aabe0c33694082", "asset_id": "30442780799048074404860985387051749017905070253466005720364298335239299761065", "price": "0.011", "size": "0", "side": "BUY", "timestamp": "1768574151562", "received_at": "2026-01-16T14:35:51.605089"}}
{"event_type": "price_change", "event_ts": "2026-01-16T14:35:51.605089", "ingestion_ts": "2026-01-16T14:36:49.604167", "market_id": "0x49686d26fb712515cd5e12c23f0a1c7e10214c7faa3cb0a730aabe0c33694082", "raw": {"market": "0x49686d26fb712515cd5e12c23f0a1c7e10214c7faa3cb0a730aabe0c33694082", "asset_id": "13244681086321087932946246027856416106585284024824496763706748621681543444582", "price": "0.989", "size": "0", "side": "SELL", "timestamp": "1768574151562", "received_at": "2026-01-16T14:35:51.605089"}}
{"event_type": "price_change", "event_ts": "2026-01-16T14:35:52.000895", "ingestion_ts": "2026-01-16T14:36:49.604167", "market_id": "0x49686d26fb712515cd5e12c23f0a1c7e10214c7faa3cb0a730aabe0c33694082", "raw": {"market": "0x49686d26fb712515cd5e12c23f0a1c7e10214c7faa3cb0a730aabe0c33694082", "asset_id": "30442780799048074404860985387051749017905070253466005720364298335239299761065", "price": "0.012", "size": "12.61", "side": "BUY", "timestamp": "1768574151957", "received_at": "2026-01-16T14:35:52.000895"}}
{"event_type": "price_change", "event_ts": "2026-01-16T14:35:52.000895", "ingestion_ts": "2026-01-16T14:36:49.604167", "market_id": "0x49686d26fb712515cd5e12c23f0a1c7e10214c7faa3cb0a730aabe0c33694082", "raw": {"market": "0x49686d26fb712515cd5e12c23f0a1c7e10214c7faa3cb0a730aabe0c33694082", "asset_id": "13244681086321087932946246027856416106585284024824496763706748621681543444582", "price": "0.988", "size": "12.61", "side": "SELL", "timestamp": "1768574151957", "received_at": "2026-01-16T14:35:52.000895"}}
{"event_type": "price_change", "event_ts": "2026-01-16T14:35:52.002128", "ingestion_ts": "2026-01-16T14:36:49.604167", "market_id": "0x49686d26fb712515cd5e12c23f0a1c7e10214c7faa3cb0a730aabe0c33694082", "raw": {"market": "0x49686d26fb712515cd5e12c23f0a1c7e10214c7faa3cb0a730aabe0c33694082", "asset_id": "30442780799048074404860985387051749017905070253466005720364298335239299761065", "price": "0.008", "size": "15.58", "side": "BUY", "timestamp": "1768574151958", "received_at": "2026-01-16T14:35:52.002128"}}
{"event_type": "price_change", "event_ts": "2026-01-16T14:35:52.002128", "ingestion_ts": "2026-01-16T14:36:49.604167", "market_id": "0x49686d26fb712515cd5e12c23f0a1c7e10214c7faa3cb0a730aabe0c33694082", "raw": {"market": "0x49686d26fb712515cd5e12c23f0a1c7e10214c7faa3cb0a730aabe0c33694082", "asset_id": "13244681086321087932946246027856416106585284024824496763706748621681543444582", "price": "0.992", "size": "15.58", "side": "SELL", "timestamp": "1768574151958", "received_at": "2026-01-16T14:35:52.002128"}}
{"event_type": "price_change", "event_ts": "2026-01-16T14:35:52.547645", "ingestion_ts": "2026-01-16T14:36:49.604167", "market_id": "0xc0e6b917320a47228fb96e3b5ae0e5c93773a5ae2662ae4e1f37807cfe47ce98", "raw": {"market": "0xc0e6b917320a47228fb96e3b5ae0e5c93773a5ae2662ae4e1f37807cfe47ce98", "asset_id": "58656358377246279051017109359677190749228949103591068167284263961542487110215", "price": "0.002", "size": "3287.1", "side": "BUY", "timestamp": "1768574152511", "received_at": "2026-01-16T14:35:52.547645"}}
{"event_type": "price_change", "event_ts": "2026-01-16T14:35:52.547645", "ingestion_ts": "2026-01-16T14:36:49.604167", "market_id": "0xc0e6b917320a47228fb96e3b5ae0e5c93773a5ae2662ae4e1f37807cfe47ce98", "raw": {"market": "0xc0e6b917320a47228fb96e3b5ae0e5c93773a5ae2662ae4e1f37807cfe47ce98", "asset_id": "81647294538046680798858716589766492074338758116170717123345952330712416337530", "price": "0.998", "size": "3287.1", "side": "SELL", "timestamp": "1768574152511", "received_at": "2026-01-16T14:35:52.547645"}}
{"event_type": "price_change", "event_ts": "2026-01-16T14:35:52.715312", "ingestion_ts": "2026-01-16T14:36:49.604167", "market_id": "0x49686d26fb712515cd5e12c23f0a1c7e10214c7faa3cb0a730aabe0c33694082", "raw": {"market": "0x49686d26fb712515cd5e12c23f0a1c7e10214c7faa3cb0a730aabe0c33694082", "asset_id": "13244681086321087932946246027856416106585284024824496763706748621681543444582", "price": "0.854", "size": "0", "side": "BUY", "timestamp": "1768574152670", "received_at": "2026-01-16T14:35:52.715312"}}
{"event_type": "price_change", "event_ts": "2026-01-16T14:35:52.715312", "ingestion_ts": "2026-01-16T14:36:49.604167", "market_id": "0x49686d26fb712515cd5e12c23f0a1c7e10214c7faa3cb0a730aabe0c33694082", "raw": {"market": "0x49686d26fb712515cd5e12c23f0a1c7e10214c7faa3cb0a730aabe0c33694082", "asset_id": "30442780799048074404860985387051749017905070253466005720364298335239299761065", "price": "0.146", "size": "0", "side": "SELL", "timestamp": "1768574152670", "received_at": "2026-01-16T14:35:52.715312"}}
{"event_type": "price_change", "event_ts": "2026-01-16T14:35:52.758560", "ingestion_ts": "2026-01-16T14:36:49.604167", "market_id": "0x49686d26fb712515cd5e12c23f0a1c7e10214c7faa3cb0a730aabe0c33694082", "raw": {"market": "0x49686d26fb712515cd5e12c23f0a1c7e10214c7faa3cb0a730aabe0c33694082", "asset_id": "13244681086321087932946246027856416106585284024824496763706748621681543444582", "price": "0.911", "size": "134.98", "side": "SELL", "timestamp": "1768574152717", "received_at": "2026-01-16T14:35:52.758560"}}
{"event_type": "price_change", "event_ts": "2026-01-16T14:35:52.758560", "ingestion_ts": "2026-01-16T14:36:49.604167", "market_id": "0x49686d26fb712515cd5e12c23f0a1c7e10214c7faa3cb0a730aabe0c33694082", "raw": {"market": "0x49686d26fb712515cd5e12c23f0a1c7e10214c7faa3cb0a730aabe0c33694082", "asset_id": "30442780799048074404860985387051749017905070253466005720364298335239299761065", "price": "0.089", "size": "134.98", "side": "BUY", "timestamp": "1768574152717", "received_at": "2026-01-16T14:35:52.758560"}}
{"event_type": "price_change", "event_ts": "2026-01-16T14:35:53.234418", "ingestion_ts": "2026-01-16T14:36:49.604167", "market_id": "0x9472be65457510b7fc3477b20ba90910e99d92eac8421a14bf4b7b7a08ef31dc", "raw": {"market": "0x9472be65457510b7fc3477b20ba90910e99d92eac8421a14bf4b7b7a08ef31dc", "asset_id": "43311793366960417907757893276427136943959788721376762326430771171648759300146", "price": "0.858", "size": "233", "side": "BUY", "timestamp": "1768574153198", "received_at": "2026-01-16T14:35:53.234418"}}
{"event_type": "price_change", "event_ts": "2026-01-16T14:35:53.234418", "ingestion_ts": "2026-01-16T14:36:49.604167", "market_id": "0x9472be65457510b7fc3477b20ba90910e99d92eac8421a14bf4b7b7a08ef31dc", "raw": {"market": "0x9472be65457510b7fc3477b20ba90910e99d92eac8421a14bf4b7b7a08ef31dc", "asset_id": "73414222381656326204771753454630063673548497164758947581648273905027617570612", "price": "0.142", "size": "233", "side": "SELL", "timestamp": "1768574153198", "received_at": "2026-01-16T14:35:53.234418"}}
{"event_type": "price_change", "event_ts": "2026-01-16T14:35:53.234572", "ingestion_ts": "2026-01-16T14:36:49.604167", "market_id": "0xc55db914f0fd1fee18997706712c0dfd8d0369cdbef93a9fef12bd001914ca77", "raw": {"market": "0xc55db914f0fd1fee18997706712c0dfd8d0369cdbef93a9fef12bd001914ca77", "asset_id": "114600293444080540179603459515770723592661967180480327891296353898330242622833", "price": "0.859", "size": "30", "side": "BUY", "timestamp": "1768574153198", "received_at": "2026-01-16T14:35:53.234572"}}
{"event_type": "price_change", "event_ts": "2026-01-16T14:35:53.234572", "ingestion_ts": "2026-01-16T14:36:49.604167", "market_id": "0xc55db914f0fd1fee18997706712c0dfd8d0369cdbef93a9fef12bd001914ca77", "raw": {"market": "0xc55db914f0fd1fee18997706712c0dfd8d0369cdbef93a9fef12bd001914ca77", "asset_id": "72354723612769247426741660426331235762851940382312402276325808095604519806766", "price": "0.141", "size": "30", "side": "SELL", "timestamp": "1768574153198", "received_at": "2026-01-16T14:35:53.234572"}}
{"event_type": "price_change", "event_ts": "2026-01-16T14:35:53.234590", "ingestion_ts": "2026-01-16T14:36:49.604167", "market_id": "0x50c669f178da4e5bbea7f1be25041fd278914712fa87a6a6f8e57d5923d88dee", "raw": {"market": "0x50c669f178da4e5bbea7f1be25041fd278914712fa87a6a6f8e57d5923d88dee", "asset_id": "74040420326294854165772767082819937451857852955603897473157746262672057685461", "price": "0.857", "size": "25", "side": "BUY", "timestamp": "1768574153198", "received_at": "2026-01-16T14:35:53.234590"}}
{"event_type": "price_change", "event_ts": "2026-01-16T14:35:53.234590", "ingestion_ts": "2026-01-16T14:36:49.604167", "market_id": "0x50c669f178da4e5bbea7f1be25041fd278914712fa87a6a6f8e57d5923d88dee", "raw": {"market": "0x50c669f178da4e5bbea7f1be25041fd278914712fa87a6a6f8e57d5923d88dee", "asset_id": "24682525479474221428144937281315825971983904267399062415430320764754931667953", "price": "0.143", "size": "25", "side": "SELL", "timestamp": "1768574153198", "received_at": "2026-01-16T14:35:53.234590"}}
{"event_type": "price_change", "event_ts": "2026-01-16T14:35:53.234604", "ingestion_ts": "2026-01-16T14:36:49.604167", "market_id": "0x49a20c7523c271099008f3ef9a31521263b24d637959852a391e6b4697b1a437", "raw": {"market": "0x49a20c7523c271099008f3ef9a31521263b24d637959852a391e6b4697b1a437", "asset_id": "55881023621710858558280545117465775643848233756850602339827152783696837905531", "price": "0.857", "size": "0", "side": "BUY", "timestamp": "1768574153198", "received_at": "2026-01-16T14:35:53.234604"}}
{"event_type": "price_change", "event_ts": "2026-01-16T14:35:53.234604", "ingestion_ts": "2026-01-16T14:36:49.604167", "market_id": "0x49a20c7523c271099008f3ef9a31521263b24d637959852a391e6b4697b1a437", "raw": {"market": "0x49a20c7523c271099008f3ef9a31521263b24d637959852a391e6b4697b1a437", "asset_id": "13018971792603393862521629014128024641178044618205296260525674415067194037856", "price": "0.143", "size": "0", "side": "SELL", "timestamp": "1768574153198", "received_at": "2026-01-16T14:35:53.234604"}}
{"event_type": "price_change", "event_ts": "2026-01-16T14:35:53.235646", "ingestion_ts": "2026-01-16T14:36:49.604167", "market_id": "0x2393ed0b0fdc450054c7b9071907eca75cf4fc36e385adf4a0a5f99ee62243e8", "raw": {"market": "0x2393ed0b0fdc450054c7b9071907eca75cf4fc36e385adf4a0a5f99ee62243e8", "asset_id": "32769749367306925959219403371425714180265458150646381231272229429098460625924", "price": "0.849", "size": "294", "side": "BUY", "timestamp": "1768574153198", "received_at": "2026-01-16T14:35:53.235646"}}
{"event_type": "price_change", "event_ts": "2026-01-16T14:35:53.235646", "ingestion_ts": "2026-01-16T14:36:49.604167", "market_id": "0x2393ed0b0fdc450054c7b9071907eca75cf4fc36e385adf4a0a5f99ee62243e8", "raw": {"market": "0x2393ed0b0fdc450054c7b9071907eca75cf4fc36e385adf4a0a5f99ee62243e8", "asset_id": "100074770378634056601572485653252702850363676459996771990439989989293515601975", "price": "0.151", "size": "294", "side": "SELL", "timestamp": "1768574153198", "received_at": "2026-01-16T14:35:53.235646"}}
{"event_type": "price_change", "event_ts": "2026-01-16T14:35:53.290052", "ingestion_ts": "2026-01-16T14:36:49.604167", "market_id": "0x9472be65457510b7fc3477b20ba90910e99d92eac8421a14bf4b7b7a08ef31dc", "raw": {"market": "0x9472be65457510b7fc3477b20ba90910e99d92eac8421a14bf4b7b7a08ef31dc", "asset_id": "43311793366960417907757893276427136943959788721376762326430771171648759300146", "price": "0.856", "size": "10", "side": "BUY", "timestamp": "1768574153251", "received_at": "2026-01-16T14:35:53.290052"}}
{"event_type": "price_change", "event_ts": "2026-01-16T14:35:53.290052", "ingestion_ts": "2026-01-16T14:36:49.604167", "market_id": "0x9472be65457510b7fc3477b20ba90910e99d92eac8421a14bf4b7b7a08ef31dc", "raw": {"market": "0x9472be65457510b7fc3477b20ba90910e99d92eac8421a14bf4b7b7a08ef31dc", "asset_id": "73414222381656326204771753454630063673548497164758947581648273905027617570612", "price": "0.144", "size": "10", "side": "SELL", "timestamp": "1768574153251", "received_at": "2026-01-16T14:35:53.290052"}}
{"event_type": "price_change", "event_ts": "2026-01-16T14:35:53.290096", "ingestion_ts": "2026-01-16T14:36:49.604167", "market_id": "0x50c669f178da4e5bbea7f1be25041fd278914712fa87a6a6f8e57d5923d88dee", "raw": {"market": "0x50c669f178da4e5bbea7f1be25041fd278914712fa87a6a6f8e57d5923d88dee", "asset_id": "74040420326294854165772767082819937451857852955603897473157746262672057685461", "price": "0.856", "size": "10", "side": "BUY", "timestamp": "1768574153251", "received_at": "2026-01-16T14:35:53.290096"}}
{"event_type": "price_change", "event_ts": "2026-01-16T14:35:53.290096", "ingestion_ts": "2026-01-16T14:36:49.604167", "market_id": "0x50c669f178da4e5bbea7f1be25041fd278914712fa87a6a6f8e57d5923d88dee", "raw": {"market": "0x50c669f178da4e5bbea7f1be25041fd278914712fa87a6a6f8e57d5923d88dee", "asset_id": "24682525479474221428144937281315825971983904267399062415430320764754931667953", "price": "0.144", "size": "10", "side": "SELL", "timestamp": "1768574153251", "received_at": "2026-01-16T14:35:53.290096"}}
{"event_type": "price_change", "event_ts": "2026-01-16T14:35:53.290110", "ingestion_ts": "2026-01-16T14:36:49.604167", "market_id": "0xc55db914f0fd1fee18997706712c0dfd8d0369cdbef93a9fef12bd001914ca77", "raw": {"market": "0xc55db914f0fd1fee18997706712c0dfd8d0369cdbef93a9fef12bd001914ca77", "asset_id": "114600293444080540179603459515770723592661967180480327891296353898330242622833", "price": "0.858", "size": "10", "side": "BUY", "timestamp": "1768574153251", "received_at": "2026-01-16T14:35:53.290110"}}
{"event_type": "price_change", "event_ts": "2026-01-16T14:35:53.290110", "ingestion_ts": "2026-01-16T14:36:49.604167", "market_id": "0xc55db914f0fd1fee18997706712c0dfd8d0369cdbef93a9fef12bd001914ca77", "raw": {"market": "0xc55db914f0fd1fee18997706712c0dfd8d0369cdbef93a9fef12bd001914ca77", "asset_id": "72354723612769247426741660426331235762851940382312402276325808095604519806766", "price": "0.142", "size": "10", "side": "SELL", "timestamp": "1768574153251", "received_at": "2026-01-16T14:35:53.290110"}}
{"event_type": "price_change", "event_ts": "2026-01-16T14:35:53.295681", "ingestion_ts": "2026-01-16T14:36:49.604167", "market_id": "0x49a20c7523c271099008f3ef9a31521263b24d637959852a391e6b4697b1a437", "raw": {"market": "0x49a20c7523c271099008f3ef9a31521263b24d637959852a391e6b4697b1a437", "asset_id": "55881023621710858558280545117465775643848233756850602339827152783696837905531", "price": "0.856", "size": "40", "side": "BUY", "timestamp": "1768574153251", "received_at": "2026-01-16T14:35:53.295681"}}
{"event_type": "price_change", "event_ts": "2026-01-16T14:35:53.295681", "ingestion_ts": "2026-01-16T14:36:49.604167", "market_id": "0x49a20c7523c271099008f3ef9a31521263b24d637959852a391e6b4697b1a437", "raw": {"market": "0x49a20c7523c271099008f3ef9a31521263b24d637959852a391e6b4697b1a437", "asset_id": "13018971792603393862521629014128024641178044618205296260525674415067194037856", "price": "0.144", "size": "40", "side": "SELL", "timestamp": "1768574153251", "received_at": "2026-01-16T14:35:53.295681"}}
{"event_type": "price_change", "event_ts": "2026-01-16T14:35:53.295730", "ingestion_ts": "2026-01-16T14:36:49.604167", "market_id": "0x2393ed0b0fdc450054c7b9071907eca75cf4fc36e385adf4a0a5f99ee62243e8", "raw": {"market": "0x2393ed0b0fdc450054c7b9071907eca75cf4fc36e385adf4a0a5f99ee62243e8", "asset_id": "32769749367306925959219403371425714180265458150646381231272229429098460625924", "price": "0.811", "size": "10", "side": "BUY", "timestamp": "1768574153251", "received_at": "2026-01-16T14:35:53.295730"}}
{"event_type": "price_change", "event_ts": "2026-01-16T14:35:53.295730", "ingestion_ts": "2026-01-16T14:36:49.604167", "market_id": "0x2393ed0b0fdc450054c7b9071907eca75cf4fc36e385adf4a0a5f99ee62243e8", "raw": {"market": "0x2393ed0b0fdc450054c7b9071907eca75cf4fc36e385adf4a0a5f99ee62243e8", "asset_id": "100074770378634056601572485653252702850363676459996771990439989989293515601975", "price": "0.189", "size": "10", "side": "SELL", "timestamp": "1768574153251", "received_at": "2026-01-16T14:35:53.295730"}}
{"event_type": "price_change", "event_ts": "2026-01-16T14:35:53.592096", "ingestion_ts": "2026-01-16T14:36:49.604167", "market_id": "0xae5584fbb57f23c1c608d544b656f23d8bf12340cef70811cf31bb0cb4fc2115", "raw": {"market": "0xae5584fbb57f23c1c608d544b656f23d8bf12340cef70811cf31bb0cb4fc2115", "asset_id": "42278252558046940014991595990628759801692726198478046188873057685686228021663", "price": "0.99", "size": "8138.8", "side": "SELL", "timestamp": "1768574153555", "received_at": "2026-01-16T14:35:53.592096"}}
{"event_type": "price_change", "event_ts": "2026-01-16T14:35:53.592096", "ingestion_ts": "2026-01-16T14:36:49.604167", "market_id": "0xae5584fbb57f23c1c608d544b656f23d8bf12340cef70811cf31bb0cb4fc2115", "raw": {"market": "0xae5584fbb57f23c1c608d544b656f23d8bf12340cef70811cf31bb0cb4fc2115", "asset_id": "28946595841244317705636126646676849578876740730186646421280828201004700559420", "price": "0.01", "size": "8138.8", "side": "BUY", "timestamp": "1768574153555", "received_at": "2026-01-16T14:35:53.592096"}}
{"event_type": "price_change", "event_ts": "2026-01-16T14:35:53.701179", "ingestion_ts": "2026-01-16T14:36:49.604167", "market_id": "0xae5584fbb57f23c1c608d544b656f23d8bf12340cef70811cf31bb0cb4fc2115", "raw": {"market": "0xae5584fbb57f23c1c608d544b656f23d8bf12340cef70811cf31bb0cb4fc2115", "asset_id": "28946595841244317705636126646676849578876740730186646421280828201004700559420", "price": "0.01", "size": "8091", "side": "BUY", "timestamp": "1768574153664", "received_at": "2026-01-16T14:35:53.701179"}}
{"event_type": "price_change", "event_ts": "2026-01-16T14:35:53.701179", "ingestion_ts": "2026-01-16T14:36:49.604167", "market_id": "0xae5584fbb57f23c1c608d544b656f23d8bf12340cef70811cf31bb0cb4fc2115", "raw": {"market": "0xae5584fbb57f23c1c608d544b656f23d8bf12340cef70811cf31bb0cb4fc2115", "asset_id": "42278252558046940014991595990628759801692726198478046188873057685686228021663", "price": "0.99", "size": "8091", "side": "SELL", "timestamp": "1768574153664", "received_at": "2026-01-16T14:35:53.701179"}}
{"event_type": "price_change", "event_ts": "2026-01-16T14:35:53.867736", "ingestion_ts": "2026-01-16T14:36:49.604167", "market_id": "0xc0e6b917320a47228fb96e3b5ae0e5c93773a5ae2662ae4e1f37807cfe47ce98", "raw": {"market": "0xc0e6b917320a47228fb96e3b5ae0e5c93773a5ae2662ae4e1f37807cfe47ce98", "asset_id": "58656358377246279051017109359677190749228949103591068167284263961542487110215", "price": "0.002", "size": "3279.99", "side": "BUY", "timestamp": "1768574153830", "received_at": "2026-01-16T14:35:53.867736"}}
{"event_type": "price_change", "event_ts": "2026-01-16T14:35:53.867736", "ingestion_ts": "2026-01-16T14:36:49.604167", "market_id": "0xc0e6b917320a47228fb96e3b5ae0e5c93773a5ae2662ae4e1f37807cfe47ce98", "raw": {"market": "0xc0e6b917320a47228fb96e3b5ae0e5c93773a5ae2662ae4e1f37807cfe47ce98", "asset_id": "81647294538046680798858716589766492074338758116170717123345952330712416337530", "price": "0.998", "size": "3279.99", "side": "SELL", "timestamp": "1768574153830", "received_at": "2026-01-16T14:35:53.867736"}}
{"event_type": "price_change", "event_ts": "2026-01-16T14:35:54.655905", "ingestion_ts": "2026-01-16T14:36:49.604167", "market_id": "0xc0e6b917320a47228fb96e3b5ae0e5c93773a5ae2662ae4e1f37807cfe47ce98", "raw": {"market": "0xc0e6b917320a47228fb96e3b5ae0e5c93773a5ae2662ae4e1f37807cfe47ce98", "asset_id": "58656358377246279051017109359677190749228949103591068167284263961542487110215", "price": "0.002", "size": "3287.1", "side": "BUY", "timestamp": "1768574154595", "received_at": "2026-01-16T14:35:54.655905"}}
{"event_type": "price_change", "event_ts": "2026-01-16T14:35:54.655905", "ingestion_ts": "2026-01-16T14:36:49.604167", "market_id": "0xc0e6b917320a47228fb96e3b5ae0e5c93773a5ae2662ae4e1f37807cfe47ce98", "raw": {"market": "0xc0e6b917320a47228fb96e3b5ae0e5c93773a5ae2662ae4e1f37807cfe47ce98", "asset_id": "81647294538046680798858716589766492074338758116170717123345952330712416337530", "price": "0.998", "size": "3287.1", "side": "SELL", "timestamp": "1768574154595", "received_at": "2026-01-16T14:35:54.655905"}}
{"event_type": "price_change", "event_ts": "2026-01-16T14:35:54.660749", "ingestion_ts": "2026-01-16T14:36:49.604167", "market_id": "0xc0e6b917320a47228fb96e3b5ae0e5c93773a5ae2662ae4e1f37807cfe47ce98", "raw": {"market": "0xc0e6b917320a47228fb96e3b5ae0e5c93773a5ae2662ae4e1f37807cfe47ce98", "asset_id": "58656358377246279051017109359677190749228949103591068167284263961542487110215", "price": "0.002", "size": "3294.21", "side": "BUY", "timestamp": "1768574154596", "received_at": "2026-01-16T14:35:54.660749"}}
{"event_type": "price_change", "event_ts": "2026-01-16T14:35:54.660749", "ingestion_ts": "2026-01-16T14:36:49.604167", "market_id": "0xc0e6b917320a47228fb96e3b5ae0e5c93773a5ae2662ae4e1f37807cfe47ce98", "raw": {"market": "0xc0e6b917320a47228fb96e3b5ae0e5c93773a5ae2662ae4e1f37807cfe47ce98", "asset_id": "81647294538046680798858716589766492074338758116170717123345952330712416337530", "price": "0.998", "size": "3294.21", "side": "SELL", "timestamp": "1768574154596", "received_at": "2026-01-16T14:35:54.660749"}}
{"event_type": "price_change", "event_ts": "2026-01-16T14:35:54.835718", "ingestion_ts": "2026-01-16T14:36:49.604167", "market_id": "0xaf9d0e448129a9f657f851d49495ba4742055d80e0ef1166ba0ee81d4d594214", "raw": {"market": "0xaf9d0e448129a9f657f851d49495ba4742055d80e0ef1166ba0ee81d4d594214", "asset_id": "4153292802911610701832309484716814274802943278345248636922528170020319407796", "price": "0.979", "size": "0", "side": "SELL", "timestamp": "1768574154743", "received_at": "2026-01-16T14:35:54.835718"}}
{"event_type": "price_change", "event_ts": "2026-01-16T14:35:54.835718", "ingestion_ts": "2026-01-16T14:36:49.604167", "market_id": "0xaf9d0e448129a9f657f851d49495ba4742055d80e0ef1166ba0ee81d4d594214", "raw": {"market": "0xaf9d0e448129a9f657f851d49495ba4742055d80e0ef1166ba0ee81d4d594214", "asset_id": "101676997363687199724245607342877036148401850938023978421879460310389391082353", "price": "0.021", "size": "0", "side": "BUY", "timestamp": "1768574154743", "received_at": "2026-01-16T14:35:54.835718"}}
{"event_type": "price_change", "event_ts": "2026-01-16T14:35:55.211941", "ingestion_ts": "2026-01-16T14:36:49.604167", "market_id": "0x2393ed0b0fdc450054c7b9071907eca75cf4fc36e385adf4a0a5f99ee62243e8", "raw": {"market": "0x2393ed0b0fdc450054c7b9071907eca75cf4fc36e385adf4a0a5f99ee62243e8", "asset_id": "32769749367306925959219403371425714180265458150646381231272229429098460625924", "price": "0.948", "size": "50", "side": "BUY", "timestamp": "1768574155125", "received_at": "2026-01-16T14:35:55.211941"}}
{"event_type": "price_change", "event_ts": "2026-01-16T14:35:55.211941", "ingestion_ts": "2026-01-16T14:36:49.604167", "market_id": "0x2393ed0b0fdc450054c7b9071907eca75cf4fc36e385adf4a0a5f99ee62243e8", "raw": {"market": "0x2393ed0b0fdc450054c7b9071907eca75cf4fc36e385adf4a0a5f99ee62243e8", "asset_id": "100074770378634056601572485653252702850363676459996771990439989989293515601975", "price": "0.052", "size": "50", "side": "SELL", "timestamp": "1768574155125", "received_at": "2026-01-16T14:35:55.211941"}}
{"event_type": "price_change", "event_ts": "2026-01-16T14:35:55.227403", "ingestion_ts": "2026-01-16T14:36:49.604167", "market_id": "0x2393ed0b0fdc450054c7b9071907eca75cf4fc36e385adf4a0a5f99ee62243e8", "raw": {"market": "0x2393ed0b0fdc450054c7b9071907eca75cf4fc36e385adf4a0a5f99ee62243e8", "asset_id": "100074770378634056601572485653252702850363676459996771990439989989293515601975", "price": "0.053", "size": "0", "side": "SELL", "timestamp": "1768574155158", "received_at": "2026-01-16T14:35:55.227403"}}
{"event_type": "price_change", "event_ts": "2026-01-16T14:35:55.227403", "ingestion_ts": "2026-01-16T14:36:49.604167", "market_id": "0x2393ed0b0fdc450054c7b9071907eca75cf4fc36e385adf4a0a5f99ee62243e8", "raw": {"market": "0x2393ed0b0fdc450054c7b9071907eca75cf4fc36e385adf4a0a5f99ee62243e8", "asset_id": "32769749367306925959219403371425714180265458150646381231272229429098460625924", "price": "0.947", "size": "0", "side": "BUY", "timestamp": "1768574155158", "received_at": "2026-01-16T14:35:55.227403"}}
{"event_type": "price_change", "event_ts": "2026-01-16T14:35:55.250158", "ingestion_ts": "2026-01-16T14:36:49.604167", "market_id": "0x2393ed0b0fdc450054c7b9071907eca75cf4fc36e385adf4a0a5f99ee62243e8", "raw": {"market": "0x2393ed0b0fdc450054c7b9071907eca75cf4fc36e385adf4a0a5f99ee62243e8", "asset_id": "100074770378634056601572485653252702850363676459996771990439989989293515601975", "price": "0.051", "size": "198", "side": "SELL", "timestamp": "1768574155187", "received_at": "2026-01-16T14:35:55.250158"}}
{"event_type": "price_change", "event_ts": "2026-01-16T14:35:55.250158", "ingestion_ts": "2026-01-16T14:36:49.604167", "market_id": "0x2393ed0b0fdc450054c7b9071907eca75cf4fc36e385adf4a0a5f99ee62243e8", "raw": {"market": "0x2393ed0b0fdc450054c7b9071907eca75cf4fc36e385adf4a0a5f99ee62243e8", "asset_id": "32769749367306925959219403371425714180265458150646381231272229429098460625924", "price": "0.949", "size": "198", "side": "BUY", "timestamp": "1768574155187", "received_at": "2026-01-16T14:35:55.250158"}}
{"event_type": "price_change", "event_ts": "2026-01-16T14:35:55.366732", "ingestion_ts": "2026-01-16T14:36:49.604167", "market_id": "0xaf9d0e448129a9f657f851d49495ba4742055d80e0ef1166ba0ee81d4d594214", "raw": {"market": "0xaf9d0e448129a9f657f851d49495ba4742055d80e0ef1166ba0ee81d4d594214", "asset_id": "4153292802911610701832309484716814274802943278345248636922528170020319407796", "price": "0.978", "size": "0", "side": "SELL", "timestamp": "1768574155303", "received_at": "2026-01-16T14:35:55.366732"}}
{"event_type": "price_change", "event_ts": "2026-01-16T14:35:55.366732", "ingestion_ts": "2026-01-16T14:36:49.604167", "market_id": "0xaf9d0e448129a9f657f851d49495ba4742055d80e0ef1166ba0ee81d4d594214", "raw": {"market": "0xaf9d0e448129a9f657f851d49495ba4742055d80e0ef1166ba0ee81d4d594214", "asset_id": "101676997363687199724245607342877036148401850938023978421879460310389391082353", "price": "0.022", "size": "0", "side": "BUY", "timestamp": "1768574155303", "received_at": "2026-01-16T14:35:55.366732"}}
{"event_type": "price_change", "event_ts": "2026-01-16T14:35:55.476027", "ingestion_ts": "2026-01-16T14:36:49.604167", "market_id": "0x49686d26fb712515cd5e12c23f0a1c7e10214c7faa3cb0a730aabe0c33694082", "raw": {"market": "0x49686d26fb712515cd5e12c23f0a1c7e10214c7faa3cb0a730aabe0c33694082", "asset_id": "30442780799048074404860985387051749017905070253466005720364298335239299761065", "price": "0.006", "size": "10.08", "side": "BUY", "timestamp": "1768574155435", "received_at": "2026-01-16T14:35:55.476027"}}
{"event_type": "price_change", "event_ts": "2026-01-16T14:35:55.476027", "ingestion_ts": "2026-01-16T14:36:49.604167", "market_id": "0x49686d26fb712515cd5e12c23f0a1c7e10214c7faa3cb0a730aabe0c33694082", "raw": {"market": "0x49686d26fb712515cd5e12c23f0a1c7e10214c7faa3cb0a730aabe0c33694082", "asset_id": "13244681086321087932946246027856416106585284024824496763706748621681543444582", "price": "0.994", "size": "10.08", "side": "SELL", "timestamp": "1768574155435", "received_at": "2026-01-16T14:35:55.476027"}}
{"event_type": "price_change", "event_ts": "2026-01-16T14:35:55.476066", "ingestion_ts": "2026-01-16T14:36:49.604167", "market_id": "0x9472be65457510b7fc3477b20ba90910e99d92eac8421a14bf4b7b7a08ef31dc", "raw": {"market": "0x9472be65457510b7fc3477b20ba90910e99d92eac8421a14bf4b7b7a08ef31dc", "asset_id": "43311793366960417907757893276427136943959788721376762326430771171648759300146", "price": "0.856", "size": "0", "side": "BUY", "timestamp": "1768574155435", "received_at": "2026-01-16T14:35:55.476066"}}
{"event_type": "price_change", "event_ts": "2026-01-16T14:35:55.476066", "ingestion_ts": "2026-01-16T14:36:49.604167", "market_id": "0x9472be65457510b7fc3477b20ba90910e99d92eac8421a14bf4b7b7a08ef31dc", "raw": {"market": "0x9472be65457510b7fc3477b20ba90910e99d92eac8421a14bf4b7b7a08ef31dc", "asset_id": "73414222381656326204771753454630063673548497164758947581648273905027617570612", "price": "0.144", "size": "0", "side": "SELL", "timestamp": "1768574155435", "received_at": "2026-01-16T14:35:55.476066"}}
{"event_type": "price_change", "event_ts": "2026-01-16T14:35:55.476080", "ingestion_ts": "2026-01-16T14:36:49.604167", "market_id": "0x49a20c7523c271099008f3ef9a31521263b24d637959852a391e6b4697b1a437", "raw": {"market": "0x49a20c7523c271099008f3ef9a31521263b24d637959852a391e6b4697b1a437", "asset_id": "55881023621710858558280545117465775643848233756850602339827152783696837905531", "price": "0.856", "size": "30", "side": "BUY", "timestamp": "1768574155435", "received_at": "2026-01-16T14:35:55.476080"}}
{"event_type": "price_change", "event_ts": "2026-01-16T14:35:55.476080", "ingestion_ts": "2026-01-16T14:36:49.604167", "market_id": "0x49a20c7523c271099008f3ef9a31521263b24d637959852a391e6b4697b1a437", "raw": {"market": "0x49a20c7523c271099008f3ef9a31521263b24d637959852a391e6b4697b1a437", "asset_id": "13018971792603393862521629014128024641178044618205296260525674415067194037856", "price": "0.144", "size": "30", "side": "SELL", "timestamp": "1768574155435", "received_at": "2026-01-16T14:35:55.476080"}}
{"event_type": "price_change", "event_ts": "2026-01-16T14:35:55.476092", "ingestion_ts": "2026-01-16T14:36:49.604167", "market_id": "0x44f08744458b8896620cd3330bc5e1ea69df4199b02d4fc583b3fc96e5d314ce", "raw": {"market": "0x44f08744458b8896620cd3330bc5e1ea69df4199b02d4fc583b3fc96e5d314ce", "asset_id": "72327831507226612545928776794104143393438710920370371172884559893525100761096", "price": "0.854", "size": "0", "side": "BUY", "timestamp": "1768574155435", "received_at": "2026-01-16T14:35:55.476092"}}
{"event_type": "price_change", "event_ts": "2026-01-16T14:35:55.476092", "ingestion_ts": "2026-01-16T14:36:49.604167", "market_id": "0x44f08744458b8896620cd3330bc5e1ea69df4199b02d4fc583b3fc96e5d314ce", "raw": {"market": "0x44f08744458b8896620cd3330bc5e1ea69df4199b02d4fc583b3fc96e5d314ce", "asset_id": "49194009556504828848509244326501559253829462790583873936160989575507522044057", "price": "0.146", "size": "0", "side": "SELL", "timestamp": "1768574155435", "received_at": "2026-01-16T14:35:55.476092"}}
{"event_type": "price_change", "event_ts": "2026-01-16T14:35:55.476103", "ingestion_ts": "2026-01-16T14:36:49.604167", "market_id": "0x50c669f178da4e5bbea7f1be25041fd278914712fa87a6a6f8e57d5923d88dee", "raw": {"market": "0x50c669f178da4e5bbea7f1be25041fd278914712fa87a6a6f8e57d5923d88dee", "asset_id": "74040420326294854165772767082819937451857852955603897473157746262672057685461", "price": "0.856", "size": "0", "side": "BUY", "timestamp": "1768574155435", "received_at": "2026-01-16T14:35:55.476103"}}
{"event_type": "price_change", "event_ts": "2026-01-16T14:35:55.476103", "ingestion_ts": "2026-01-16T14:36:49.604167", "market_id": "0x50c669f178da4e5bbea7f1be25041fd278914712fa87a6a6f8e57d5923d88dee", "raw": {"market": "0x50c669f178da4e5bbea7f1be25041fd278914712fa87a6a6f8e57d5923d88dee", "asset_id": "24682525479474221428144937281315825971983904267399062415430320764754931667953", "price": "0.144", "size": "0", "side": "SELL", "timestamp": "1768574155435", "received_at": "2026-01-16T14:35:55.476103"}}
{"event_type": "price_change", "event_ts": "2026-01-16T14:35:55.476113", "ingestion_ts": "2026-01-16T14:36:49.604167", "market_id": "0xc55db914f0fd1fee18997706712c0dfd8d0369cdbef93a9fef12bd001914ca77", "raw": {"market": "0xc55db914f0fd1fee18997706712c0dfd8d0369cdbef93a9fef12bd001914ca77", "asset_id": "114600293444080540179603459515770723592661967180480327891296353898330242622833", "price": "0.858", "size": "0", "side": "BUY", "timestamp": "1768574155435", "received_at": "2026-01-16T14:35:55.476113"}}
{"event_type": "price_change", "event_ts": "2026-01-16T14:35:55.476113", "ingestion_ts": "2026-01-16T14:36:49.604167", "market_id": "0xc55db914f0fd1fee18997706712c0dfd8d0369cdbef93a9fef12bd001914ca77", "raw": {"market": "0xc55db914f0fd1fee18997706712c0dfd8d0369cdbef93a9fef12bd001914ca77", "asset_id": "72354723612769247426741660426331235762851940382312402276325808095604519806766", "price": "0.142", "size": "0", "side": "SELL", "timestamp": "1768574155435", "received_at": "2026-01-16T14:35:55.476113"}}
{"event_type": "price_change", "event_ts": "2026-01-16T14:35:55.493197", "ingestion_ts": "2026-01-16T14:36:49.604167", "market_id": "0xaf9d0e448129a9f657f851d49495ba4742055d80e0ef1166ba0ee81d4d594214", "raw": {"market": "0xaf9d0e448129a9f657f851d49495ba4742055d80e0ef1166ba0ee81d4d594214", "asset_id": "4153292802911610701832309484716814274802943278345248636922528170020319407796", "price": "0.989", "size": "20.5", "side": "SELL", "timestamp": "1768574155450", "received_at": "2026-01-16T14:35:55.493197"}}
{"event_type": "price_change", "event_ts": "2026-01-16T14:35:55.493197", "ingestion_ts": "2026-01-16T14:36:49.604167", "market_id": "0xaf9d0e448129a9f657f851d49495ba4742055d80e0ef1166ba0ee81d4d594214", "raw": {"market": "0xaf9d0e448129a9f657f851d49495ba4742055d80e0ef1166ba0ee81d4d594214", "asset_id": "101676997363687199724245607342877036148401850938023978421879460310389391082353", "price": "0.011", "size": "20.5", "side": "BUY", "timestamp": "1768574155450", "received_at": "2026-01-16T14:35:55.493197"}}
{"event_type": "price_change", "event_ts": "2026-01-16T14:35:55.502560", "ingestion_ts": "2026-01-16T14:36:49.604167", "market_id": "0x9472be65457510b7fc3477b20ba90910e99d92eac8421a14bf4b7b7a08ef31dc", "raw": {"market": "0x9472be65457510b7fc3477b20ba90910e99d92eac8421a14bf4b7b7a08ef31dc", "asset_id": "43311793366960417907757893276427136943959788721376762326430771171648759300146", "price": "0.824", "size": "10", "side": "BUY", "timestamp": "1768574155467", "received_at": "2026-01-16T14:35:55.502560"}}
{"event_type": "price_change", "event_ts": "2026-01-16T14:35:55.502560", "ingestion_ts": "2026-01-16T14:36:49.604167", "market_id": "0x9472be65457510b7fc3477b20ba90910e99d92eac8421a14bf4b7b7a08ef31dc", "raw": {"market": "0x9472be65457510b7fc3477b20ba90910e99d92eac8421a14bf4b7b7a08ef31dc", "asset_id": "73414222381656326204771753454630063673548497164758947581648273905027617570612", "price": "0.176", "size": "10", "side": "SELL", "timestamp": "1768574155467", "received_at": "2026-01-16T14:35:55.502560"}}
{"event_type": "price_change", "event_ts": "2026-01-16T14:35:55.503470", "ingestion_ts": "2026-01-16T14:36:49.604167", "market_id": "0x49a20c7523c271099008f3ef9a31521263b24d637959852a391e6b4697b1a437", "raw": {"market": "0x49a20c7523c271099008f3ef9a31521263b24d637959852a391e6b4697b1a437", "asset_id": "55881023621710858558280545117465775643848233756850602339827152783696837905531", "price": "0.847", "size": "10", "side": "BUY", "timestamp": "1768574155467", "received_at": "2026-01-16T14:35:55.503470"}}
{"event_type": "price_change", "event_ts": "2026-01-16T14:35:55.503470", "ingestion_ts": "2026-01-16T14:36:49.604167", "market_id": "0x49a20c7523c271099008f3ef9a31521263b24d637959852a391e6b4697b1a437", "raw": {"market": "0x49a20c7523c271099008f3ef9a31521263b24d637959852a391e6b4697b1a437", "asset_id": "13018971792603393862521629014128024641178044618205296260525674415067194037856", "price": "0.153", "size": "10", "side": "SELL", "timestamp": "1768574155467", "received_at": "2026-01-16T14:35:55.503470"}}
{"event_type": "price_change", "event_ts": "2026-01-16T14:35:55.503502", "ingestion_ts": "2026-01-16T14:36:49.604167", "market_id": "0x49686d26fb712515cd5e12c23f0a1c7e10214c7faa3cb0a730aabe0c33694082", "raw": {"market": "0x49686d26fb712515cd5e12c23f0a1c7e10214c7faa3cb0a730aabe0c33694082", "asset_id": "30442780799048074404860985387051749017905070253466005720364298335239299761065", "price": "0.002", "size": "672.74", "side": "BUY", "timestamp": "1768574155467", "received_at": "2026-01-16T14:35:55.503502"}}
{"event_type": "price_change", "event_ts": "2026-01-16T14:35:55.503502", "ingestion_ts": "2026-01-16T14:36:49.604167", "market_id": "0x49686d26fb712515cd5e12c23f0a1c7e10214c7faa3cb0a730aabe0c33694082", "raw": {"market": "0x49686d26fb712515cd5e12c23f0a1c7e10214c7faa3cb0a730aabe0c33694082", "asset_id": "13244681086321087932946246027856416106585284024824496763706748621681543444582", "price": "0.998", "size": "672.74", "side": "SELL", "timestamp": "1768574155467", "received_at": "2026-01-16T14:35:55.503502"}}
{"event_type": "price_change", "event_ts": "2026-01-16T14:35:55.503516", "ingestion_ts": "2026-01-16T14:36:49.604167", "market_id": "0xc55db914f0fd1fee18997706712c0dfd8d0369cdbef93a9fef12bd001914ca77", "raw": {"market": "0xc55db914f0fd1fee18997706712c0dfd8d0369cdbef93a9fef12bd001914ca77", "asset_id": "114600293444080540179603459515770723592661967180480327891296353898330242622833", "price": "0.837", "size": "10", "side": "BUY", "timestamp": "1768574155467", "received_at": "2026-01-16T14:35:55.503516"}}
{"event_type": "price_change", "event_ts": "2026-01-16T14:35:55.503516", "ingestion_ts": "2026-01-16T14:36:49.604167", "market_id": "0xc55db914f0fd1fee18997706712c0dfd8d0369cdbef93a9fef12bd001914ca77", "raw": {"market": "0xc55db914f0fd1fee18997706712c0dfd8d0369cdbef93a9fef12bd001914ca77", "asset_id": "72354723612769247426741660426331235762851940382312402276325808095604519806766", "price": "0.163", "size": "10", "side": "SELL", "timestamp": "1768574155467", "received_at": "2026-01-16T14:35:55.503516"}}
{"event_type": "price_change", "event_ts": "2026-01-16T14:35:55.504102", "ingestion_ts": "2026-01-16T14:36:49.604167", "market_id": "0x50c669f178da4e5bbea7f1be25041fd278914712fa87a6a6f8e57d5923d88dee", "raw": {"market": "0x50c669f178da4e5bbea7f1be25041fd278914712fa87a6a6f8e57d5923d88dee", "asset_id": "74040420326294854165772767082819937451857852955603897473157746262672057685461", "price": "0.825", "size": "10", "side": "BUY", "timestamp": "1768574155467", "received_at": "2026-01-16T14:35:55.504102"}}
{"event_type": "price_change", "event_ts": "2026-01-16T14:35:55.504102", "ingestion_ts": "2026-01-16T14:36:49.604167", "market_id": "0x50c669f178da4e5bbea7f1be25041fd278914712fa87a6a6f8e57d5923d88dee", "raw": {"market": "0x50c669f178da4e5bbea7f1be25041fd278914712fa87a6a6f8e57d5923d88dee", "asset_id": "24682525479474221428144937281315825971983904267399062415430320764754931667953", "price": "0.175", "size": "10", "side": "SELL", "timestamp": "1768574155467", "received_at": "2026-01-16T14:35:55.504102"}}
{"event_type": "price_change", "event_ts": "2026-01-16T14:35:55.504131", "ingestion_ts": "2026-01-16T14:36:49.604167", "market_id": "0x44f08744458b8896620cd3330bc5e1ea69df4199b02d4fc583b3fc96e5d314ce", "raw": {"market": "0x44f08744458b8896620cd3330bc5e1ea69df4199b02d4fc583b3fc96e5d314ce", "asset_id": "72327831507226612545928776794104143393438710920370371172884559893525100761096", "price": "0.831", "size": "10", "side": "BUY", "timestamp": "1768574155467", "received_at": "2026-01-16T14:35:55.504131"}}
{"event_type": "price_change", "event_ts": "2026-01-16T14:35:55.504131", "ingestion_ts": "2026-01-16T14:36:49.604167", "market_id": "0x44f08744458b8896620cd3330bc5e1ea69df4199b02d4fc583b3fc96e5d314ce", "raw": {"market": "0x44f08744458b8896620cd3330bc5e1ea69df4199b02d4fc583b3fc96e5d314ce", "asset_id": "49194009556504828848509244326501559253829462790583873936160989575507522044057", "price": "0.169", "size": "10", "side": "SELL", "timestamp": "1768574155467", "received_at": "2026-01-16T14:35:55.504131"}}
{"event_type": "price_change", "event_ts": "2026-01-16T14:35:55.624460", "ingestion_ts": "2026-01-16T14:36:49.604167", "market_id": "0x2393ed0b0fdc450054c7b9071907eca75cf4fc36e385adf4a0a5f99ee62243e8", "raw": {"market": "0x2393ed0b0fdc450054c7b9071907eca75cf4fc36e385adf4a0a5f99ee62243e8", "asset_id": "32769749367306925959219403371425714180265458150646381231272229429098460625924", "price": "0.946", "size": "0", "side": "BUY", "timestamp": "1768574155582", "received_at": "2026-01-16T14:35:55.624460"}}
{"event_type": "price_change", "event_ts": "2026-01-16T14:35:55.624460", "ingestion_ts": "2026-01-16T14:36:49.604167", "market_id": "0x2393ed0b0fdc450054c7b9071907eca75cf4fc36e385adf4a0a5f99ee62243e8", "raw": {"market": "0x2393ed0b0fdc450054c7b9071907eca75cf4fc36e385adf4a0a5f99ee62243e8", "asset_id": "100074770378634056601572485653252702850363676459996771990439989989293515601975", "price": "0.054", "size": "0", "side": "SELL", "timestamp": "1768574155582", "received_at": "2026-01-16T14:35:55.624460"}}
{"event_type": "price_change", "event_ts": "2026-01-16T14:35:56.690783", "ingestion_ts": "2026-01-16T14:36:49.604167", "market_id": "0x49686d26fb712515cd5e12c23f0a1c7e10214c7faa3cb0a730aabe0c33694082", "raw": {"market": "0x49686d26fb712515cd5e12c23f0a1c7e10214c7faa3cb0a730aabe0c33694082", "asset_id": "30442780799048074404860985387051749017905070253466005720364298335239299761065", "price": "0.008", "size": "5.94", "side": "BUY", "timestamp": "1768574156484", "received_at": "2026-01-16T14:35:56.690783"}}
{"event_type": "price_change", "event_ts": "2026-01-16T14:35:56.690783", "ingestion_ts": "2026-01-16T14:36:49.604167", "market_id": "0x49686d26fb712515cd5e12c23f0a1c7e10214c7faa3cb0a730aabe0c33694082", "raw": {"market": "0x49686d26fb712515cd5e12c23f0a1c7e10214c7faa3cb0a730aabe0c33694082", "asset_id": "13244681086321087932946246027856416106585284024824496763706748621681543444582", "price": "0.992", "size": "5.94", "side": "SELL", "timestamp": "1768574156484", "received_at": "2026-01-16T14:35:56.690783"}}
{"event_type": "price_change", "event_ts": "2026-01-16T14:35:56.690821", "ingestion_ts": "2026-01-16T14:36:49.604167", "market_id": "0x49686d26fb712515cd5e12c23f0a1c7e10214c7faa3cb0a730aabe0c33694082", "raw": {"market": "0x49686d26fb712515cd5e12c23f0a1c7e10214c7faa3cb0a730aabe0c33694082", "asset_id": "30442780799048074404860985387051749017905070253466005720364298335239299761065", "price": "0.012", "size": "0", "side": "BUY", "timestamp": "1768574156484", "received_at": "2026-01-16T14:35:56.690821"}}
{"event_type": "price_change", "event_ts": "2026-01-16T14:35:56.690821", "ingestion_ts": "2026-01-16T14:36:49.604167", "market_id": "0x49686d26fb712515cd5e12c23f0a1c7e10214c7faa3cb0a730aabe0c33694082", "raw": {"market": "0x49686d26fb712515cd5e12c23f0a1c7e10214c7faa3cb0a730aabe0c33694082", "asset_id": "13244681086321087932946246027856416106585284024824496763706748621681543444582", "price": "0.988", "size": "0", "side": "SELL", "timestamp": "1768574156484", "received_at": "2026-01-16T14:35:56.690821"}}
{"event_type": "price_change", "event_ts": "2026-01-16T14:35:57.244911", "ingestion_ts": "2026-01-16T14:36:49.604167", "market_id": "0x49686d26fb712515cd5e12c23f0a1c7e10214c7faa3cb0a730aabe0c33694082", "raw": {"market": "0x49686d26fb712515cd5e12c23f0a1c7e10214c7faa3cb0a730aabe0c33694082", "asset_id": "30442780799048074404860985387051749017905070253466005720364298335239299761065", "price": "0.013", "size": "8.44", "side": "BUY", "timestamp": "1768574157069", "received_at": "2026-01-16T14:35:57.244911"}}
{"event_type": "price_change", "event_ts": "2026-01-16T14:35:57.244911", "ingestion_ts": "2026-01-16T14:36:49.604167", "market_id": "0x49686d26fb712515cd5e12c23f0a1c7e10214c7faa3cb0a730aabe0c33694082", "raw": {"market": "0x49686d26fb712515cd5e12c23f0a1c7e10214c7faa3cb0a730aabe0c33694082", "asset_id": "13244681086321087932946246027856416106585284024824496763706748621681543444582", "price": "0.987", "size": "8.44", "side": "SELL", "timestamp": "1768574157069", "received_at": "2026-01-16T14:35:57.244911"}}
{"event_type": "price_change", "event_ts": "2026-01-16T14:35:57.247615", "ingestion_ts": "2026-01-16T14:36:49.604167", "market_id": "0x49686d26fb712515cd5e12c23f0a1c7e10214c7faa3cb0a730aabe0c33694082", "raw": {"market": "0x49686d26fb712515cd5e12c23f0a1c7e10214c7faa3cb0a730aabe0c33694082", "asset_id": "30442780799048074404860985387051749017905070253466005720364298335239299761065", "price": "0.009", "size": "13.18", "side": "BUY", "timestamp": "1768574157072", "received_at": "2026-01-16T14:35:57.247615"}}
{"event_type": "price_change", "event_ts": "2026-01-16T14:35:57.247615", "ingestion_ts": "2026-01-16T14:36:49.604167", "market_id": "0x49686d26fb712515cd5e12c23f0a1c7e10214c7faa3cb0a730aabe0c33694082", "raw": {"market": "0x49686d26fb712515cd5e12c23f0a1c7e10214c7faa3cb0a730aabe0c33694082", "asset_id": "13244681086321087932946246027856416106585284024824496763706748621681543444582", "price": "0.991", "size": "13.18", "side": "SELL", "timestamp": "1768574157072", "received_at": "2026-01-16T14:35:57.247615"}}
{"event_type": "price_change", "event_ts": "2026-01-16T14:35:57.822784", "ingestion_ts": "2026-01-16T14:36:49.604167", "market_id": "0xc0e6b917320a47228fb96e3b5ae0e5c93773a5ae2662ae4e1f37807cfe47ce98", "raw": {"market": "0xc0e6b917320a47228fb96e3b5ae0e5c93773a5ae2662ae4e1f37807cfe47ce98", "asset_id": "58656358377246279051017109359677190749228949103591068167284263961542487110215", "price": "0.002", "size": "3287.1", "side": "BUY", "timestamp": "1768574157672", "received_at": "2026-01-16T14:35:57.822784"}}
{"event_type": "price_change", "event_ts": "2026-01-16T14:35:57.822784", "ingestion_ts": "2026-01-16T14:36:49.604167", "market_id": "0xc0e6b917320a47228fb96e3b5ae0e5c93773a5ae2662ae4e1f37807cfe47ce98", "raw": {"market": "0xc0e6b917320a47228fb96e3b5ae0e5c93773a5ae2662ae4e1f37807cfe47ce98", "asset_id": "81647294538046680798858716589766492074338758116170717123345952330712416337530", "price": "0.998", "size": "3287.1", "side": "SELL", "timestamp": "1768574157672", "received_at": "2026-01-16T14:35:57.822784"}}
{"event_type": "price_change", "event_ts": "2026-01-16T14:35:58.897229", "ingestion_ts": "2026-01-16T14:36:49.604167", "market_id": "0x49686d26fb712515cd5e12c23f0a1c7e10214c7faa3cb0a730aabe0c33694082", "raw": {"market": "0x49686d26fb712515cd5e12c23f0a1c7e10214c7faa3cb0a730aabe0c33694082", "asset_id": "13244681086321087932946246027856416106585284024824496763706748621681543444582", "price": "0.853", "size": "50.86", "side": "BUY", "timestamp": "1768574158826", "received_at": "2026-01-16T14:35:58.897229"}}
{"event_type": "price_change", "event_ts": "2026-01-16T14:35:58.897229", "ingestion_ts": "2026-01-16T14:36:49.604167", "market_id": "0x49686d26fb712515cd5e12c23f0a1c7e10214c7faa3cb0a730aabe0c33694082", "raw": {"market": "0x49686d26fb712515cd5e12c23f0a1c7e10214c7faa3cb0a730aabe0c33694082", "asset_id": "30442780799048074404860985387051749017905070253466005720364298335239299761065", "price": "0.147", "size": "50.86", "side": "SELL", "timestamp": "1768574158826", "received_at": "2026-01-16T14:35:58.897229"}}
{"event_type": "price_change", "event_ts": "2026-01-16T14:35:59.404041", "ingestion_ts": "2026-01-16T14:36:49.604167", "market_id": "0xc0e6b917320a47228fb96e3b5ae0e5c93773a5ae2662ae4e1f37807cfe47ce98", "raw": {"market": "0xc0e6b917320a47228fb96e3b5ae0e5c93773a5ae2662ae4e1f37807cfe47ce98", "asset_id": "58656358377246279051017109359677190749228949103591068167284263961542487110215", "price": "0.002", "size": "3279.99", "side": "BUY", "timestamp": "1768574159357", "received_at": "2026-01-16T14:35:59.404041"}}
{"event_type": "price_change", "event_ts": "2026-01-16T14:35:59.404041", "ingestion_ts": "2026-01-16T14:36:49.604167", "market_id": "0xc0e6b917320a47228fb96e3b5ae0e5c93773a5ae2662ae4e1f37807cfe47ce98", "raw": {"market": "0xc0e6b917320a47228fb96e3b5ae0e5c93773a5ae2662ae4e1f37807cfe47ce98", "asset_id": "81647294538046680798858716589766492074338758116170717123345952330712416337530", "price": "0.998", "size": "3279.99", "side": "SELL", "timestamp": "1768574159357", "received_at": "2026-01-16T14:35:59.404041"}}
{"event_type": "price_change", "event_ts": "2026-01-16T14:35:59.557741", "ingestion_ts": "2026-01-16T14:36:49.604167", "market_id": "0x49686d26fb712515cd5e12c23f0a1c7e10214c7faa3cb0a730aabe0c33694082", "raw": {"market": "0x49686d26fb712515cd5e12c23f0a1c7e10214c7faa3cb0a730aabe0c33694082", "asset_id": "30442780799048074404860985387051749017905070253466005720364298335239299761065", "price": "0.148", "size": "0", "side": "SELL", "timestamp": "1768574159519", "received_at": "2026-01-16T14:35:59.557741"}}
{"event_type": "price_change", "event_ts": "2026-01-16T14:35:59.557741", "ingestion_ts": "2026-01-16T14:36:49.604167", "market_id": "0x49686d26fb712515cd5e12c23f0a1c7e10214c7faa3cb0a730aabe0c33694082", "raw": {"market": "0x49686d26fb712515cd5e12c23f0a1c7e10214c7faa3cb0a730aabe0c33694082", "asset_id": "13244681086321087932946246027856416106585284024824496763706748621681543444582", "price": "0.852", "size": "0", "side": "BUY", "timestamp": "1768574159519", "received_at": "2026-01-16T14:35:59.557741"}}
{"event_type": "price_change", "event_ts": "2026-01-16T14:35:59.616021", "ingestion_ts": "2026-01-16T14:36:49.604167", "market_id": "0x49686d26fb712515cd5e12c23f0a1c7e10214c7faa3cb0a730aabe0c33694082", "raw": {"market": "0x49686d26fb712515cd5e12c23f0a1c7e10214c7faa3cb0a730aabe0c33694082", "asset_id": "30442780799048074404860985387051749017905070253466005720364298335239299761065", "price": "0.146", "size": "17.5", "side": "SELL", "timestamp": "1768574159570", "received_at": "2026-01-16T14:35:59.616021"}}
{"event_type": "price_change", "event_ts": "2026-01-16T14:35:59.616021", "ingestion_ts": "2026-01-16T14:36:49.604167", "market_id": "0x49686d26fb712515cd5e12c23f0a1c7e10214c7faa3cb0a730aabe0c33694082", "raw": {"market": "0x49686d26fb712515cd5e12c23f0a1c7e10214c7faa3cb0a730aabe0c33694082", "asset_id": "13244681086321087932946246027856416106585284024824496763706748621681543444582", "price": "0.854", "size": "17.5", "side": "BUY", "timestamp": "1768574159570", "received_at": "2026-01-16T14:35:59.616021"}}
{"event_type": "price_change", "event_ts": "2026-01-16T14:35:59.657047", "ingestion_ts": "2026-01-16T14:36:49.604167", "market_id": "0x49686d26fb712515cd5e12c23f0a1c7e10214c7faa3cb0a730aabe0c33694082", "raw": {"market": "0x49686d26fb712515cd5e12c23f0a1c7e10214c7faa3cb0a730aabe0c33694082", "asset_id": "13244681086321087932946246027856416106585284024824496763706748621681543444582", "price": "0.911", "size": "14.98", "side": "SELL", "timestamp": "1768574159603", "received_at": "2026-01-16T14:35:59.657047"}}
{"event_type": "price_change", "event_ts": "2026-01-16T14:35:59.657047", "ingestion_ts": "2026-01-16T14:36:49.604167", "market_id": "0x49686d26fb712515cd5e12c23f0a1c7e10214c7faa3cb0a730aabe0c33694082", "raw": {"market": "0x49686d26fb712515cd5e12c23f0a1c7e10214c7faa3cb0a730aabe0c33694082", "asset_id": "30442780799048074404860985387051749017905070253466005720364298335239299761065", "price": "0.089", "size": "14.98", "side": "BUY", "timestamp": "1768574159603", "received_at": "2026-01-16T14:35:59.657047"}}
{"event_type": "price_change", "event_ts": "2026-01-16T14:35:59.986008", "ingestion_ts": "2026-01-16T14:36:49.604167", "market_id": "0xae5584fbb57f23c1c608d544b656f23d8bf12340cef70811cf31bb0cb4fc2115", "raw": {"market": "0xae5584fbb57f23c1c608d544b656f23d8bf12340cef70811cf31bb0cb4fc2115", "asset_id": "42278252558046940014991595990628759801692726198478046188873057685686228021663", "price": "0.99", "size": "8193.2", "side": "SELL", "timestamp": "1768574159949", "received_at": "2026-01-16T14:35:59.986008"}}
{"event_type": "price_change", "event_ts": "2026-01-16T14:35:59.986008", "ingestion_ts": "2026-01-16T14:36:49.604167", "market_id": "0xae5584fbb57f23c1c608d544b656f23d8bf12340cef70811cf31bb0cb4fc2115", "raw": {"market": "0xae5584fbb57f23c1c608d544b656f23d8bf12340cef70811cf31bb0cb4fc2115", "asset_id": "28946595841244317705636126646676849578876740730186646421280828201004700559420", "price": "0.01", "size": "8193.2", "side": "BUY", "timestamp": "1768574159949", "received_at": "2026-01-16T14:35:59.986008"}}
{"event_type": "price_change", "event_ts": "2026-01-16T14:36:00.027725", "ingestion_ts": "2026-01-16T14:36:49.604167", "market_id": "0xc0e6b917320a47228fb96e3b5ae0e5c93773a5ae2662ae4e1f37807cfe47ce98", "raw": {"market": "0xc0e6b917320a47228fb96e3b5ae0e5c93773a5ae2662ae4e1f37807cfe47ce98", "asset_id": "58656358377246279051017109359677190749228949103591068167284263961542487110215", "price": "0.002", "size": "3287.1", "side": "BUY", "timestamp": "1768574159975", "received_at": "2026-01-16T14:36:00.027725"}}
{"event_type": "price_change", "event_ts": "2026-01-16T14:36:00.027725", "ingestion_ts": "2026-01-16T14:36:49.604167", "market_id": "0xc0e6b917320a47228fb96e3b5ae0e5c93773a5ae2662ae4e1f37807cfe47ce98", "raw": {"market": "0xc0e6b917320a47228fb96e3b5ae0e5c93773a5ae2662ae4e1f37807cfe47ce98", "asset_id": "81647294538046680798858716589766492074338758116170717123345952330712416337530", "price": "0.998", "size": "3287.1", "side": "SELL", "timestamp": "1768574159975", "received_at": "2026-01-16T14:36:00.027725"}}
{"event_type": "price_change", "event_ts": "2026-01-16T14:36:00.027763", "ingestion_ts": "2026-01-16T14:36:49.604167", "market_id": "0xc0e6b917320a47228fb96e3b5ae0e5c93773a5ae2662ae4e1f37807cfe47ce98", "raw": {"market": "0xc0e6b917320a47228fb96e3b5ae0e5c93773a5ae2662ae4e1f37807cfe47ce98", "asset_id": "58656358377246279051017109359677190749228949103591068167284263961542487110215", "price": "0.002", "size": "3294.21", "side": "BUY", "timestamp": "1768574159976", "received_at": "2026-01-16T14:36:00.027763"}}
{"event_type": "price_change", "event_ts": "2026-01-16T14:36:00.027763", "ingestion_ts": "2026-01-16T14:36:49.604167", "market_id": "0xc0e6b917320a47228fb96e3b5ae0e5c93773a5ae2662ae4e1f37807cfe47ce98", "raw": {"market": "0xc0e6b917320a47228fb96e3b5ae0e5c93773a5ae2662ae4e1f37807cfe47ce98", "asset_id": "81647294538046680798858716589766492074338758116170717123345952330712416337530", "price": "0.998", "size": "3294.21", "side": "SELL", "timestamp": "1768574159976", "received_at": "2026-01-16T14:36:00.027763"}}
{"event_type": "price_change", "event_ts": "2026-01-16T14:36:00.139877", "ingestion_ts": "2026-01-16T14:36:49.604167", "market_id": "0xae5584fbb57f23c1c608d544b656f23d8bf12340cef70811cf31bb0cb4fc2115", "raw": {"market": "0xae5584fbb57f23c1c608d544b656f23d8bf12340cef70811cf31bb0cb4fc2115", "asset_id": "28946595841244317705636126646676849578876740730186646421280828201004700559420", "price": "0.01", "size": "8241", "side": "BUY", "timestamp": "1768574160076", "received_at": "2026-01-16T14:36:00.139877"}}
{"event_type": "price_change", "event_ts": "2026-01-16T14:36:00.139877", "ingestion_ts": "2026-01-16T14:36:49.604167", "market_id": "0xae5584fbb57f23c1c608d544b656f23d8bf12340cef70811cf31bb0cb4fc2115", "raw": {"market": "0xae5584fbb57f23c1c608d544b656f23d8bf12340cef70811cf31bb0cb4fc2115", "asset_id": "42278252558046940014991595990628759801692726198478046188873057685686228021663", "price": "0.99", "size": "8241", "side": "SELL", "timestamp": "1768574160076", "received_at": "2026-01-16T14:36:00.139877"}}
{"event_type": "price_change", "event_ts": "2026-01-16T14:36:01.013726", "ingestion_ts": "2026-01-16T14:36:49.604167", "market_id": "0xaf9d0e448129a9f657f851d49495ba4742055d80e0ef1166ba0ee81d4d594214", "raw": {"market": "0xaf9d0e448129a9f657f851d49495ba4742055d80e0ef1166ba0ee81d4d594214", "asset_id": "4153292802911610701832309484716814274802943278345248636922528170020319407796", "price": "0.981", "size": "140.01", "side": "SELL", "timestamp": "1768574160889", "received_at": "2026-01-16T14:36:01.013726"}}
{"event_type": "price_change", "event_ts": "2026-01-16T14:36:01.013726", "ingestion_ts": "2026-01-16T14:36:49.604167", "market_id": "0xaf9d0e448129a9f657f851d49495ba4742055d80e0ef1166ba0ee81d4d594214", "raw": {"market": "0xaf9d0e448129a9f657f851d49495ba4742055d80e0ef1166ba0ee81d4d594214", "asset_id": "101676997363687199724245607342877036148401850938023978421879460310389391082353", "price": "0.019", "size": "140.01", "side": "BUY", "timestamp": "1768574160889", "received_at": "2026-01-16T14:36:01.013726"}}
{"event_type": "price_change", "event_ts": "2026-01-16T14:36:01.270569", "ingestion_ts": "2026-01-16T14:36:49.604167", "market_id": "0x2393ed0b0fdc450054c7b9071907eca75cf4fc36e385adf4a0a5f99ee62243e8", "raw": {"market": "0x2393ed0b0fdc450054c7b9071907eca75cf4fc36e385adf4a0a5f99ee62243e8", "asset_id": "32769749367306925959219403371425714180265458150646381231272229429098460625924", "price": "0.95", "size": "50", "side": "BUY", "timestamp": "1768574161227", "received_at": "2026-01-16T14:36:01.270569"}}
{"event_type": "price_change", "event_ts": "2026-01-16T14:36:01.270569", "ingestion_ts": "2026-01-16T14:36:49.604167", "market_id": "0x2393ed0b0fdc450054c7b9071907eca75cf4fc36e385adf4a0a5f99ee62243e8", "raw": {"market": "0x2393ed0b0fdc450054c7b9071907eca75cf4fc36e385adf4a0a5f99ee62243e8", "asset_id": "100074770378634056601572485653252702850363676459996771990439989989293515601975", "price": "0.05", "size": "50", "side": "SELL", "timestamp": "1768574161227", "received_at": "2026-01-16T14:36:01.270569"}}
{"event_type": "price_change", "event_ts": "2026-01-16T14:36:01.307182", "ingestion_ts": "2026-01-16T14:36:49.604167", "market_id": "0x2393ed0b0fdc450054c7b9071907eca75cf4fc36e385adf4a0a5f99ee62243e8", "raw": {"market": "0x2393ed0b0fdc450054c7b9071907eca75cf4fc36e385adf4a0a5f99ee62243e8", "asset_id": "100074770378634056601572485653252702850363676459996771990439989989293515601975", "price": "0.051", "size": "0", "side": "SELL", "timestamp": "1768574161256", "received_at": "2026-01-16T14:36:01.307182"}}
{"event_type": "price_change", "event_ts": "2026-01-16T14:36:01.307182", "ingestion_ts": "2026-01-16T14:36:49.604167", "market_id": "0x2393ed0b0fdc450054c7b9071907eca75cf4fc36e385adf4a0a5f99ee62243e8", "raw": {"market": "0x2393ed0b0fdc450054c7b9071907eca75cf4fc36e385adf4a0a5f99ee62243e8", "asset_id": "32769749367306925959219403371425714180265458150646381231272229429098460625924", "price": "0.949", "size": "0", "side": "BUY", "timestamp": "1768574161256", "received_at": "2026-01-16T14:36:01.307182"}}
{"event_type": "price_change", "event_ts": "2026-01-16T14:36:01.327207", "ingestion_ts": "2026-01-16T14:36:49.604167", "market_id": "0x2393ed0b0fdc450054c7b9071907eca75cf4fc36e385adf4a0a5f99ee62243e8", "raw": {"market": "0x2393ed0b0fdc450054c7b9071907eca75cf4fc36e385adf4a0a5f99ee62243e8", "asset_id": "100074770378634056601572485653252702850363676459996771990439989989293515601975", "price": "0.049", "size": "198", "side": "SELL", "timestamp": "1768574161284", "received_at": "2026-01-16T14:36:01.327207"}}
{"event_type": "price_change", "event_ts": "2026-01-16T14:36:01.327207", "ingestion_ts": "2026-01-16T14:36:49.604167", "market_id": "0x2393ed0b0fdc450054c7b9071907eca75cf4fc36e385adf4a0a5f99ee62243e8", "raw": {"market": "0x2393ed0b0fdc450054c7b9071907eca75cf4fc36e385adf4a0a5f99ee62243e8", "asset_id": "32769749367306925959219403371425714180265458150646381231272229429098460625924", "price": "0.951", "size": "198", "side": "BUY", "timestamp": "1768574161284", "received_at": "2026-01-16T14:36:01.327207"}}
{"event_type": "price_change", "event_ts": "2026-01-16T14:36:01.352290", "ingestion_ts": "2026-01-16T14:36:49.604167", "market_id": "0x49686d26fb712515cd5e12c23f0a1c7e10214c7faa3cb0a730aabe0c33694082", "raw": {"market": "0x49686d26fb712515cd5e12c23f0a1c7e10214c7faa3cb0a730aabe0c33694082", "asset_id": "30442780799048074404860985387051749017905070253466005720364298335239299761065", "price": "0.009", "size": "0", "side": "BUY", "timestamp": "1768574161304", "received_at": "2026-01-16T14:36:01.352290"}}
{"event_type": "price_change", "event_ts": "2026-01-16T14:36:01.352290", "ingestion_ts": "2026-01-16T14:36:49.604167", "market_id": "0x49686d26fb712515cd5e12c23f0a1c7e10214c7faa3cb0a730aabe0c33694082", "raw": {"market": "0x49686d26fb712515cd5e12c23f0a1c7e10214c7faa3cb0a730aabe0c33694082", "asset_id": "13244681086321087932946246027856416106585284024824496763706748621681543444582", "price": "0.991", "size": "0", "side": "SELL", "timestamp": "1768574161304", "received_at": "2026-01-16T14:36:01.352290"}}
{"event_type": "price_change", "event_ts": "2026-01-16T14:36:01.352331", "ingestion_ts": "2026-01-16T14:36:49.604167", "market_id": "0x49686d26fb712515cd5e12c23f0a1c7e10214c7faa3cb0a730aabe0c33694082", "raw": {"market": "0x49686d26fb712515cd5e12c23f0a1c7e10214c7faa3cb0a730aabe0c33694082", "asset_id": "30442780799048074404860985387051749017905070253466005720364298335239299761065", "price": "0.013", "size": "0", "side": "BUY", "timestamp": "1768574161304", "received_at": "2026-01-16T14:36:01.352331"}}
{"event_type": "price_change", "event_ts": "2026-01-16T14:36:01.352331", "ingestion_ts": "2026-01-16T14:36:49.604167", "market_id": "0x49686d26fb712515cd5e12c23f0a1c7e10214c7faa3cb0a730aabe0c33694082", "raw": {"market": "0x49686d26fb712515cd5e12c23f0a1c7e10214c7faa3cb0a730aabe0c33694082", "asset_id": "13244681086321087932946246027856416106585284024824496763706748621681543444582", "price": "0.987", "size": "0", "side": "SELL", "timestamp": "1768574161304", "received_at": "2026-01-16T14:36:01.352331"}}
{"event_type": "price_change", "event_ts": "2026-01-16T14:36:01.659475", "ingestion_ts": "2026-01-16T14:36:49.604167", "market_id": "0x2393ed0b0fdc450054c7b9071907eca75cf4fc36e385adf4a0a5f99ee62243e8", "raw": {"market": "0x2393ed0b0fdc450054c7b9071907eca75cf4fc36e385adf4a0a5f99ee62243e8", "asset_id": "32769749367306925959219403371425714180265458150646381231272229429098460625924", "price": "0.948", "size": "0", "side": "BUY", "timestamp": "1768574161615", "received_at": "2026-01-16T14:36:01.659475"}}
{"event_type": "price_change", "event_ts": "2026-01-16T14:36:01.659475", "ingestion_ts": "2026-01-16T14:36:49.604167", "market_id": "0x2393ed0b0fdc450054c7b9071907eca75cf4fc36e385adf4a0a5f99ee62243e8", "raw": {"market": "0x2393ed0b0fdc450054c7b9071907eca75cf4fc36e385adf4a0a5f99ee62243e8", "asset_id": "100074770378634056601572485653252702850363676459996771990439989989293515601975", "price": "0.052", "size": "0", "side": "SELL", "timestamp": "1768574161615", "received_at": "2026-01-16T14:36:01.659475"}}
{"event_type": "price_change", "event_ts": "2026-01-16T14:36:01.879990", "ingestion_ts": "2026-01-16T14:36:49.604167", "market_id": "0xc55db914f0fd1fee18997706712c0dfd8d0369cdbef93a9fef12bd001914ca77", "raw": {"market": "0xc55db914f0fd1fee18997706712c0dfd8d0369cdbef93a9fef12bd001914ca77", "asset_id": "114600293444080540179603459515770723592661967180480327891296353898330242622833", "price": "0.837", "size": "0", "side": "BUY", "timestamp": "1768574161843", "received_at": "2026-01-16T14:36:01.879990"}}
{"event_type": "price_change", "event_ts": "2026-01-16T14:36:01.879990", "ingestion_ts": "2026-01-16T14:36:49.604167", "market_id": "0xc55db914f0fd1fee18997706712c0dfd8d0369cdbef93a9fef12bd001914ca77", "raw": {"market": "0xc55db914f0fd1fee18997706712c0dfd8d0369cdbef93a9fef12bd001914ca77", "asset_id": "72354723612769247426741660426331235762851940382312402276325808095604519806766", "price": "0.163", "size": "0", "side": "SELL", "timestamp": "1768574161843", "received_at": "2026-01-16T14:36:01.879990"}}
{"event_type": "price_change", "event_ts": "2026-01-16T14:36:01.880029", "ingestion_ts": "2026-01-16T14:36:49.604167", "market_id": "0x9472be65457510b7fc3477b20ba90910e99d92eac8421a14bf4b7b7a08ef31dc", "raw": {"market": "0x9472be65457510b7fc3477b20ba90910e99d92eac8421a14bf4b7b7a08ef31dc", "asset_id": "43311793366960417907757893276427136943959788721376762326430771171648759300146", "price": "0.824", "size": "0", "side": "BUY", "timestamp": "1768574161843", "received_at": "2026-01-16T14:36:01.880029"}}
{"event_type": "price_change", "event_ts": "2026-01-16T14:36:01.880029", "ingestion_ts": "2026-01-16T14:36:49.604167", "market_id": "0x9472be65457510b7fc3477b20ba90910e99d92eac8421a14bf4b7b7a08ef31dc", "raw": {"market": "0x9472be65457510b7fc3477b20ba90910e99d92eac8421a14bf4b7b7a08ef31dc", "asset_id": "73414222381656326204771753454630063673548497164758947581648273905027617570612", "price": "0.176", "size": "0", "side": "SELL", "timestamp": "1768574161843", "received_at": "2026-01-16T14:36:01.880029"}}
{"event_type": "price_change", "event_ts": "2026-01-16T14:36:01.880043", "ingestion_ts": "2026-01-16T14:36:49.604167", "market_id": "0x49686d26fb712515cd5e12c23f0a1c7e10214c7faa3cb0a730aabe0c33694082", "raw": {"market": "0x49686d26fb712515cd5e12c23f0a1c7e10214c7faa3cb0a730aabe0c33694082", "asset_id": "30442780799048074404860985387051749017905070253466005720364298335239299761065", "price": "0.002", "size": "662.74", "side": "BUY", "timestamp": "1768574161843", "received_at": "2026-01-16T14:36:01.880043"}}
{"event_type": "price_change", "event_ts": "2026-01-16T14:36:01.880043", "ingestion_ts": "2026-01-16T14:36:49.604167", "market_id": "0x49686d26fb712515cd5e12c23f0a1c7e10214c7faa3cb0a730aabe0c33694082", "raw": {"market": "0x49686d26fb712515cd5e12c23f0a1c7e10214c7faa3cb0a730aabe0c33694082", "asset_id": "13244681086321087932946246027856416106585284024824496763706748621681543444582", "price": "0.998", "size": "662.74", "side": "SELL", "timestamp": "1768574161843", "received_at": "2026-01-16T14:36:01.880043"}}
{"event_type": "price_change", "event_ts": "2026-01-16T14:36:01.920106", "ingestion_ts": "2026-01-16T14:36:49.604167", "market_id": "0x9472be65457510b7fc3477b20ba90910e99d92eac8421a14bf4b7b7a08ef31dc", "raw": {"market": "0x9472be65457510b7fc3477b20ba90910e99d92eac8421a14bf4b7b7a08ef31dc", "asset_id": "43311793366960417907757893276427136943959788721376762326430771171648759300146", "price": "0.855", "size": "302", "side": "BUY", "timestamp": "1768574161872", "received_at": "2026-01-16T14:36:01.920106"}}
{"event_type": "price_change", "event_ts": "2026-01-16T14:36:01.920106", "ingestion_ts": "2026-01-16T14:36:49.604167", "market_id": "0x9472be65457510b7fc3477b20ba90910e99d92eac8421a14bf4b7b7a08ef31dc", "raw": {"market": "0x9472be65457510b7fc3477b20ba90910e99d92eac8421a14bf4b7b7a08ef31dc", "asset_id": "73414222381656326204771753454630063673548497164758947581648273905027617570612", "price": "0.145", "size": "302", "side": "SELL", "timestamp": "1768574161872", "received_at": "2026-01-16T14:36:01.920106"}}
{"event_type": "price_change", "event_ts": "2026-01-16T14:36:01.920146", "ingestion_ts": "2026-01-16T14:36:49.604167", "market_id": "0xc55db914f0fd1fee18997706712c0dfd8d0369cdbef93a9fef12bd001914ca77", "raw": {"market": "0xc55db914f0fd1fee18997706712c0dfd8d0369cdbef93a9fef12bd001914ca77", "asset_id": "114600293444080540179603459515770723592661967180480327891296353898330242622833", "price": "0.856", "size": "10", "side": "BUY", "timestamp": "1768574161872", "received_at": "2026-01-16T14:36:01.920146"}}
{"event_type": "price_change", "event_ts": "2026-01-16T14:36:01.920146", "ingestion_ts": "2026-01-16T14:36:49.604167", "market_id": "0xc55db914f0fd1fee18997706712c0dfd8d0369cdbef93a9fef12bd001914ca77", "raw": {"market": "0xc55db914f0fd1fee18997706712c0dfd8d0369cdbef93a9fef12bd001914ca77", "asset_id": "72354723612769247426741660426331235762851940382312402276325808095604519806766", "price": "0.144", "size": "10", "side": "SELL", "timestamp": "1768574161872", "received_at": "2026-01-16T14:36:01.920146"}}
{"event_type": "price_change", "event_ts": "2026-01-16T14:36:01.920166", "ingestion_ts": "2026-01-16T14:36:49.604167", "market_id": "0x49686d26fb712515cd5e12c23f0a1c7e10214c7faa3cb0a730aabe0c33694082", "raw": {"market": "0x49686d26fb712515cd5e12c23f0a1c7e10214c7faa3cb0a730aabe0c33694082", "asset_id": "30442780799048074404860985387051749017905070253466005720364298335239299761065", "price": "0.003", "size": "36.81", "side": "BUY", "timestamp": "1768574161872", "received_at": "2026-01-16T14:36:01.920166"}}
{"event_type": "price_change", "event_ts": "2026-01-16T14:36:01.920166", "ingestion_ts": "2026-01-16T14:36:49.604167", "market_id": "0x49686d26fb712515cd5e12c23f0a1c7e10214c7faa3cb0a730aabe0c33694082", "raw": {"market": "0x49686d26fb712515cd5e12c23f0a1c7e10214c7faa3cb0a730aabe0c33694082", "asset_id": "13244681086321087932946246027856416106585284024824496763706748621681543444582", "price": "0.997", "size": "36.81", "side": "SELL", "timestamp": "1768574161872", "received_at": "2026-01-16T14:36:01.920166"}}
{"event_type": "price_change", "event_ts": "2026-01-16T14:36:02.232223", "ingestion_ts": "2026-01-16T14:36:49.604167", "market_id": "0x49686d26fb712515cd5e12c23f0a1c7e10214c7faa3cb0a730aabe0c33694082", "raw": {"market": "0x49686d26fb712515cd5e12c23f0a1c7e10214c7faa3cb0a730aabe0c33694082", "asset_id": "13244681086321087932946246027856416106585284024824496763706748621681543444582", "price": "0.853", "size": "45", "side": "BUY", "timestamp": "1768574162183", "received_at": "2026-01-16T14:36:02.232223"}}
{"event_type": "price_change", "event_ts": "2026-01-16T14:36:02.232223", "ingestion_ts": "2026-01-16T14:36:49.604167", "market_id": "0x49686d26fb712515cd5e12c23f0a1c7e10214c7faa3cb0a730aabe0c33694082", "raw": {"market": "0x49686d26fb712515cd5e12c23f0a1c7e10214c7faa3cb0a730aabe0c33694082", "asset_id": "30442780799048074404860985387051749017905070253466005720364298335239299761065", "price": "0.147", "size": "45", "side": "SELL", "timestamp": "1768574162183", "received_at": "2026-01-16T14:36:02.232223"}}
{"event_type": "price_change", "event_ts": "2026-01-16T14:36:02.241013", "ingestion_ts": "2026-01-16T14:36:49.604167", "market_id": "0x49686d26fb712515cd5e12c23f0a1c7e10214c7faa3cb0a730aabe0c33694082", "raw": {"market": "0x49686d26fb712515cd5e12c23f0a1c7e10214c7faa3cb0a730aabe0c33694082", "asset_id": "30442780799048074404860985387051749017905070253466005720364298335239299761065", "price": "0.011", "size": "20.77", "side": "BUY", "timestamp": "1768574162185", "received_at": "2026-01-16T14:36:02.241013"}}
{"event_type": "price_change", "event_ts": "2026-01-16T14:36:02.241013", "ingestion_ts": "2026-01-16T14:36:49.604167", "market_id": "0x49686d26fb712515cd5e12c23f0a1c7e10214c7faa3cb0a730aabe0c33694082", "raw": {"market": "0x49686d26fb712515cd5e12c23f0a1c7e10214c7faa3cb0a730aabe0c33694082", "asset_id": "13244681086321087932946246027856416106585284024824496763706748621681543444582", "price": "0.989", "size": "20.77", "side": "SELL", "timestamp": "1768574162185", "received_at": "2026-01-16T14:36:02.241013"}}
{"event_type": "price_change", "event_ts": "2026-01-16T14:36:02.310772", "ingestion_ts": "2026-01-16T14:36:49.604167", "market_id": "0x49686d26fb712515cd5e12c23f0a1c7e10214c7faa3cb0a730aabe0c33694082", "raw": {"market": "0x49686d26fb712515cd5e12c23f0a1c7e10214c7faa3cb0a730aabe0c33694082", "asset_id": "13244681086321087932946246027856416106585284024824496763706748621681543444582", "price": "0.854", "size": "23.35", "side": "BUY", "timestamp": "1768574162222", "received_at": "2026-01-16T14:36:02.310772"}}
{"event_type": "price_change", "event_ts": "2026-01-16T14:36:02.310772", "ingestion_ts": "2026-01-16T14:36:49.604167", "market_id": "0x49686d26fb712515cd5e12c23f0a1c7e10214c7faa3cb0a730aabe0c33694082", "raw": {"market": "0x49686d26fb712515cd5e12c23f0a1c7e10214c7faa3cb0a730aabe0c33694082", "asset_id": "30442780799048074404860985387051749017905070253466005720364298335239299761065", "price": "0.146", "size": "23.35", "side": "SELL", "timestamp": "1768574162222", "received_at": "2026-01-16T14:36:02.310772"}}
{"event_type": "price_change", "event_ts": "2026-01-16T14:36:02.425265", "ingestion_ts": "2026-01-16T14:36:49.604167", "market_id": "0xaf9d0e448129a9f657f851d49495ba4742055d80e0ef1166ba0ee81d4d594214", "raw": {"market": "0xaf9d0e448129a9f657f851d49495ba4742055d80e0ef1166ba0ee81d4d594214", "asset_id": "4153292802911610701832309484716814274802943278345248636922528170020319407796", "price": "0.98", "size": "20.5", "side": "SELL", "timestamp": "1768574162377", "received_at": "2026-01-16T14:36:02.425265"}}
{"event_type": "price_change", "event_ts": "2026-01-16T14:36:02.425265", "ingestion_ts": "2026-01-16T14:36:49.604167", "market_id": "0xaf9d0e448129a9f657f851d49495ba4742055d80e0ef1166ba0ee81d4d594214", "raw": {"market": "0xaf9d0e448129a9f657f851d49495ba4742055d80e0ef1166ba0ee81d4d594214", "asset_id": "101676997363687199724245607342877036148401850938023978421879460310389391082353", "price": "0.02", "size": "20.5", "side": "BUY", "timestamp": "1768574162377", "received_at": "2026-01-16T14:36:02.425265"}}
{"event_type": "price_change", "event_ts": "2026-01-16T14:36:02.489202", "ingestion_ts": "2026-01-16T14:36:49.604167", "market_id": "0xaf9d0e448129a9f657f851d49495ba4742055d80e0ef1166ba0ee81d4d594214", "raw": {"market": "0xaf9d0e448129a9f657f851d49495ba4742055d80e0ef1166ba0ee81d4d594214", "asset_id": "4153292802911610701832309484716814274802943278345248636922528170020319407796", "price": "0.989", "size": "0", "side": "SELL", "timestamp": "1768574162452", "received_at": "2026-01-16T14:36:02.489202"}}
{"event_type": "price_change", "event_ts": "2026-01-16T14:36:02.489202", "ingestion_ts": "2026-01-16T14:36:49.604167", "market_id": "0xaf9d0e448129a9f657f851d49495ba4742055d80e0ef1166ba0ee81d4d594214", "raw": {"market": "0xaf9d0e448129a9f657f851d49495ba4742055d80e0ef1166ba0ee81d4d594214", "asset_id": "101676997363687199724245607342877036148401850938023978421879460310389391082353", "price": "0.011", "size": "0", "side": "BUY", "timestamp": "1768574162452", "received_at": "2026-01-16T14:36:02.489202"}}
{"event_type": "price_change", "event_ts": "2026-01-16T14:36:02.697527", "ingestion_ts": "2026-01-16T14:36:49.604167", "market_id": "0x49686d26fb712515cd5e12c23f0a1c7e10214c7faa3cb0a730aabe0c33694082", "raw": {"market": "0x49686d26fb712515cd5e12c23f0a1c7e10214c7faa3cb0a730aabe0c33694082", "asset_id": "30442780799048074404860985387051749017905070253466005720364298335239299761065", "price": "0.003", "size": "26.81", "side": "BUY", "timestamp": "1768574162640", "received_at": "2026-01-16T14:36:02.697527"}}
{"event_type": "price_change", "event_ts": "2026-01-16T14:36:02.697527", "ingestion_ts": "2026-01-16T14:36:49.604167", "market_id": "0x49686d26fb712515cd5e12c23f0a1c7e10214c7faa3cb0a730aabe0c33694082", "raw": {"market": "0x49686d26fb712515cd5e12c23f0a1c7e10214c7faa3cb0a730aabe0c33694082", "asset_id": "13244681086321087932946246027856416106585284024824496763706748621681543444582", "price": "0.997", "size": "26.81", "side": "SELL", "timestamp": "1768574162640", "received_at": "2026-01-16T14:36:02.697527"}}
{"event_type": "price_change", "event_ts": "2026-01-16T14:36:02.697565", "ingestion_ts": "2026-01-16T14:36:49.604167", "market_id": "0xc55db914f0fd1fee18997706712c0dfd8d0369cdbef93a9fef12bd001914ca77", "raw": {"market": "0xc55db914f0fd1fee18997706712c0dfd8d0369cdbef93a9fef12bd001914ca77", "asset_id": "114600293444080540179603459515770723592661967180480327891296353898330242622833", "price": "0.856", "size": "0", "side": "BUY", "timestamp": "1768574162640", "received_at": "2026-01-16T14:36:02.697565"}}
{"event_type": "price_change", "event_ts": "2026-01-16T14:36:02.697565", "ingestion_ts": "2026-01-16T14:36:49.604167", "market_id": "0xc55db914f0fd1fee18997706712c0dfd8d0369cdbef93a9fef12bd001914ca77", "raw": {"market": "0xc55db914f0fd1fee18997706712c0dfd8d0369cdbef93a9fef12bd001914ca77", "asset_id": "72354723612769247426741660426331235762851940382312402276325808095604519806766", "price": "0.144", "size": "0", "side": "SELL", "timestamp": "1768574162640", "received_at": "2026-01-16T14:36:02.697565"}}
{"event_type": "price_change", "event_ts": "2026-01-16T14:36:02.697579", "ingestion_ts": "2026-01-16T14:36:49.604167", "market_id": "0x50c669f178da4e5bbea7f1be25041fd278914712fa87a6a6f8e57d5923d88dee", "raw": {"market": "0x50c669f178da4e5bbea7f1be25041fd278914712fa87a6a6f8e57d5923d88dee", "asset_id": "74040420326294854165772767082819937451857852955603897473157746262672057685461", "price": "0.825", "size": "0", "side": "BUY", "timestamp": "1768574162640", "received_at": "2026-01-16T14:36:02.697579"}}
{"event_type": "price_change", "event_ts": "2026-01-16T14:36:02.697579", "ingestion_ts": "2026-01-16T14:36:49.604167", "market_id": "0x50c669f178da4e5bbea7f1be25041fd278914712fa87a6a6f8e57d5923d88dee", "raw": {"market": "0x50c669f178da4e5bbea7f1be25041fd278914712fa87a6a6f8e57d5923d88dee", "asset_id": "24682525479474221428144937281315825971983904267399062415430320764754931667953", "price": "0.175", "size": "0", "side": "SELL", "timestamp": "1768574162640", "received_at": "2026-01-16T14:36:02.697579"}}
{"event_type": "price_change", "event_ts": "2026-01-16T14:36:02.697590", "ingestion_ts": "2026-01-16T14:36:49.604167", "market_id": "0x9472be65457510b7fc3477b20ba90910e99d92eac8421a14bf4b7b7a08ef31dc", "raw": {"market": "0x9472be65457510b7fc3477b20ba90910e99d92eac8421a14bf4b7b7a08ef31dc", "asset_id": "43311793366960417907757893276427136943959788721376762326430771171648759300146", "price": "0.855", "size": "292", "side": "BUY", "timestamp": "1768574162640", "received_at": "2026-01-16T14:36:02.697590"}}
{"event_type": "price_change", "event_ts": "2026-01-16T14:36:02.697590", "ingestion_ts": "2026-01-16T14:36:49.604167", "market_id": "0x9472be65457510b7fc3477b20ba90910e99d92eac8421a14bf4b7b7a08ef31dc", "raw": {"market": "0x9472be65457510b7fc3477b20ba90910e99d92eac8421a14bf4b7b7a08ef31dc", "asset_id": "73414222381656326204771753454630063673548497164758947581648273905027617570612", "price": "0.145", "size": "292", "side": "SELL", "timestamp": "1768574162640", "received_at": "2026-01-16T14:36:02.697590"}}
{"event_type": "price_change", "event_ts": "2026-01-16T14:36:02.697602", "ingestion_ts": "2026-01-16T14:36:49.604167", "market_id": "0x49a20c7523c271099008f3ef9a31521263b24d637959852a391e6b4697b1a437", "raw": {"market": "0x49a20c7523c271099008f3ef9a31521263b24d637959852a391e6b4697b1a437", "asset_id": "55881023621710858558280545117465775643848233756850602339827152783696837905531", "price": "0.847", "size": "0", "side": "BUY", "timestamp": "1768574162640", "received_at": "2026-01-16T14:36:02.697602"}}
{"event_type": "price_change", "event_ts": "2026-01-16T14:36:02.697602", "ingestion_ts": "2026-01-16T14:36:49.604167", "market_id": "0x49a20c7523c271099008f3ef9a31521263b24d637959852a391e6b4697b1a437", "raw": {"market": "0x49a20c7523c271099008f3ef9a31521263b24d637959852a391e6b4697b1a437", "asset_id": "13018971792603393862521629014128024641178044618205296260525674415067194037856", "price": "0.153", "size": "0", "side": "SELL", "timestamp": "1768574162640", "received_at": "2026-01-16T14:36:02.697602"}}
{"event_type": "price_change", "event_ts": "2026-01-16T14:36:02.697613", "ingestion_ts": "2026-01-16T14:36:49.604167", "market_id": "0x44f08744458b8896620cd3330bc5e1ea69df4199b02d4fc583b3fc96e5d314ce", "raw": {"market": "0x44f08744458b8896620cd3330bc5e1ea69df4199b02d4fc583b3fc96e5d314ce", "asset_id": "72327831507226612545928776794104143393438710920370371172884559893525100761096", "price": "0.831", "size": "0", "side": "BUY", "timestamp": "1768574162640", "received_at": "2026-01-16T14:36:02.697613"}}
{"event_type": "price_change", "event_ts": "2026-01-16T14:36:02.697613", "ingestion_ts": "2026-01-16T14:36:49.604167", "market_id": "0x44f08744458b8896620cd3330bc5e1ea69df4199b02d4fc583b3fc96e5d314ce", "raw": {"market": "0x44f08744458b8896620cd3330bc5e1ea69df4199b02d4fc583b3fc96e5d314ce", "asset_id": "49194009556504828848509244326501559253829462790583873936160989575507522044057", "price": "0.169", "size": "0", "side": "SELL", "timestamp": "1768574162640", "received_at": "2026-01-16T14:36:02.697613"}}
{"event_type": "price_change", "event_ts": "2026-01-16T14:36:02.719228", "ingestion_ts": "2026-01-16T14:36:49.604167", "market_id": "0x9472be65457510b7fc3477b20ba90910e99d92eac8421a14bf4b7b7a08ef31dc", "raw": {"market": "0x9472be65457510b7fc3477b20ba90910e99d92eac8421a14bf4b7b7a08ef31dc", "asset_id": "43311793366960417907757893276427136943959788721376762326430771171648759300146", "price": "0.856", "size": "10", "side": "BUY", "timestamp": "1768574162681", "received_at": "2026-01-16T14:36:02.719228"}}
{"event_type": "price_change", "event_ts": "2026-01-16T14:36:02.719228", "ingestion_ts": "2026-01-16T14:36:49.604167", "market_id": "0x9472be65457510b7fc3477b20ba90910e99d92eac8421a14bf4b7b7a08ef31dc", "raw": {"market": "0x9472be65457510b7fc3477b20ba90910e99d92eac8421a14bf4b7b7a08ef31dc", "asset_id": "73414222381656326204771753454630063673548497164758947581648273905027617570612", "price": "0.144", "size": "10", "side": "SELL", "timestamp": "1768574162681", "received_at": "2026-01-16T14:36:02.719228"}}
{"event_type": "price_change", "event_ts": "2026-01-16T14:36:02.719337", "ingestion_ts": "2026-01-16T14:36:49.604167", "market_id": "0x44f08744458b8896620cd3330bc5e1ea69df4199b02d4fc583b3fc96e5d314ce", "raw": {"market": "0x44f08744458b8896620cd3330bc5e1ea69df4199b02d4fc583b3fc96e5d314ce", "asset_id": "72327831507226612545928776794104143393438710920370371172884559893525100761096", "price": "0.853", "size": "244", "side": "BUY", "timestamp": "1768574162681", "received_at": "2026-01-16T14:36:02.719337"}}
{"event_type": "price_change", "event_ts": "2026-01-16T14:36:02.719337", "ingestion_ts": "2026-01-16T14:36:49.604167", "market_id": "0x44f08744458b8896620cd3330bc5e1ea69df4199b02d4fc583b3fc96e5d314ce", "raw": {"market": "0x44f08744458b8896620cd3330bc5e1ea69df4199b02d4fc583b3fc96e5d314ce", "asset_id": "49194009556504828848509244326501559253829462790583873936160989575507522044057", "price": "0.147", "size": "244", "side": "SELL", "timestamp": "1768574162681", "received_at": "2026-01-16T14:36:02.719337"}}
{"event_type": "price_change", "event_ts": "2026-01-16T14:36:02.719356", "ingestion_ts": "2026-01-16T14:36:49.604167", "market_id": "0x49686d26fb712515cd5e12c23f0a1c7e10214c7faa3cb0a730aabe0c33694082", "raw": {"market": "0x49686d26fb712515cd5e12c23f0a1c7e10214c7faa3cb0a730aabe0c33694082", "asset_id": "30442780799048074404860985387051749017905070253466005720364298335239299761065", "price": "0.004", "size": "10", "side": "BUY", "timestamp": "1768574162681", "received_at": "2026-01-16T14:36:02.719356"}}
{"event_type": "price_change", "event_ts": "2026-01-16T14:36:02.719356", "ingestion_ts": "2026-01-16T14:36:49.604167", "market_id": "0x49686d26fb712515cd5e12c23f0a1c7e10214c7faa3cb0a730aabe0c33694082", "raw": {"market": "0x49686d26fb712515cd5e12c23f0a1c7e10214c7faa3cb0a730aabe0c33694082", "asset_id": "13244681086321087932946246027856416106585284024824496763706748621681543444582", "price": "0.996", "size": "10", "side": "SELL", "timestamp": "1768574162681", "received_at": "2026-01-16T14:36:02.719356"}}
{"event_type": "price_change", "event_ts": "2026-01-16T14:36:02.719369", "ingestion_ts": "2026-01-16T14:36:49.604167", "market_id": "0x49a20c7523c271099008f3ef9a31521263b24d637959852a391e6b4697b1a437", "raw": {"market": "0x49a20c7523c271099008f3ef9a31521263b24d637959852a391e6b4697b1a437", "asset_id": "55881023621710858558280545117465775643848233756850602339827152783696837905531", "price": "0.855", "size": "302", "side": "BUY", "timestamp": "1768574162681", "received_at": "2026-01-16T14:36:02.719369"}}
{"event_type": "price_change", "event_ts": "2026-01-16T14:36:02.719369", "ingestion_ts": "2026-01-16T14:36:49.604167", "market_id": "0x49a20c7523c271099008f3ef9a31521263b24d637959852a391e6b4697b1a437", "raw": {"market": "0x49a20c7523c271099008f3ef9a31521263b24d637959852a391e6b4697b1a437", "asset_id": "13018971792603393862521629014128024641178044618205296260525674415067194037856", "price": "0.145", "size": "302", "side": "SELL", "timestamp": "1768574162681", "received_at": "2026-01-16T14:36:02.719369"}}
{"event_type": "price_change", "event_ts": "2026-01-16T14:36:02.721564", "ingestion_ts": "2026-01-16T14:36:49.604167", "market_id": "0xc55db914f0fd1fee18997706712c0dfd8d0369cdbef93a9fef12bd001914ca77", "raw": {"market": "0xc55db914f0fd1fee18997706712c0dfd8d0369cdbef93a9fef12bd001914ca77", "asset_id": "114600293444080540179603459515770723592661967180480327891296353898330242622833", "price": "0.857", "size": "243", "side": "BUY", "timestamp": "1768574162681", "received_at": "2026-01-16T14:36:02.721564"}}
{"event_type": "price_change", "event_ts": "2026-01-16T14:36:02.721564", "ingestion_ts": "2026-01-16T14:36:49.604167", "market_id": "0xc55db914f0fd1fee18997706712c0dfd8d0369cdbef93a9fef12bd001914ca77", "raw": {"market": "0xc55db914f0fd1fee18997706712c0dfd8d0369cdbef93a9fef12bd001914ca77", "asset_id": "72354723612769247426741660426331235762851940382312402276325808095604519806766", "price": "0.143", "size": "243", "side": "SELL", "timestamp": "1768574162681", "received_at": "2026-01-16T14:36:02.721564"}}
{"event_type": "price_change", "event_ts": "2026-01-16T14:36:02.721599", "ingestion_ts": "2026-01-16T14:36:49.604167", "market_id": "0x50c669f178da4e5bbea7f1be25041fd278914712fa87a6a6f8e57d5923d88dee", "raw": {"market": "0x50c669f178da4e5bbea7f1be25041fd278914712fa87a6a6f8e57d5923d88dee", "asset_id": "74040420326294854165772767082819937451857852955603897473157746262672057685461", "price": "0.856", "size": "10", "side": "BUY", "timestamp": "1768574162681", "received_at": "2026-01-16T14:36:02.721599"}}
{"event_type": "price_change", "event_ts": "2026-01-16T14:36:02.721599", "ingestion_ts": "2026-01-16T14:36:49.604167", "market_id": "0x50c669f178da4e5bbea7f1be25041fd278914712fa87a6a6f8e57d5923d88dee", "raw": {"market": "0x50c669f178da4e5bbea7f1be25041fd278914712fa87a6a6f8e57d5923d88dee", "asset_id": "24682525479474221428144937281315825971983904267399062415430320764754931667953", "price": "0.144", "size": "10", "side": "SELL", "timestamp": "1768574162681", "received_at": "2026-01-16T14:36:02.721599"}}
{"event_type": "price_change", "event_ts": "2026-01-16T14:36:03.354410", "ingestion_ts": "2026-01-16T14:36:49.604167", "market_id": "0xc0e6b917320a47228fb96e3b5ae0e5c93773a5ae2662ae4e1f37807cfe47ce98", "raw": {"market": "0xc0e6b917320a47228fb96e3b5ae0e5c93773a5ae2662ae4e1f37807cfe47ce98", "asset_id": "58656358377246279051017109359677190749228949103591068167284263961542487110215", "price": "0.002", "size": "3287.1", "side": "BUY", "timestamp": "1768574163184", "received_at": "2026-01-16T14:36:03.354410"}}
{"event_type": "price_change", "event_ts": "2026-01-16T14:36:03.354410", "ingestion_ts": "2026-01-16T14:36:49.604167", "market_id": "0xc0e6b917320a47228fb96e3b5ae0e5c93773a5ae2662ae4e1f37807cfe47ce98", "raw": {"market": "0xc0e6b917320a47228fb96e3b5ae0e5c93773a5ae2662ae4e1f37807cfe47ce98", "asset_id": "81647294538046680798858716589766492074338758116170717123345952330712416337530", "price": "0.998", "size": "3287.1", "side": "SELL", "timestamp": "1768574163184", "received_at": "2026-01-16T14:36:03.354410"}}
{"event_type": "price_change", "event_ts": "2026-01-16T14:36:03.478328", "ingestion_ts": "2026-01-16T14:36:49.604167", "market_id": "0x49686d26fb712515cd5e12c23f0a1c7e10214c7faa3cb0a730aabe0c33694082", "raw": {"market": "0x49686d26fb712515cd5e12c23f0a1c7e10214c7faa3cb0a730aabe0c33694082", "asset_id": "30442780799048074404860985387051749017905070253466005720364298335239299761065", "price": "0.146", "size": "5.85", "side": "SELL", "timestamp": "1768574163351", "received_at": "2026-01-16T14:36:03.478328"}}
{"event_type": "price_change", "event_ts": "2026-01-16T14:36:03.478328", "ingestion_ts": "2026-01-16T14:36:49.604167", "market_id": "0x49686d26fb712515cd5e12c23f0a1c7e10214c7faa3cb0a730aabe0c33694082", "raw": {"market": "0x49686d26fb712515cd5e12c23f0a1c7e10214c7faa3cb0a730aabe0c33694082", "asset_id": "13244681086321087932946246027856416106585284024824496763706748621681543444582", "price": "0.854", "size": "5.85", "side": "BUY", "timestamp": "1768574163351", "received_at": "2026-01-16T14:36:03.478328"}}
{"event_type": "price_change", "event_ts": "2026-01-16T14:36:03.525630", "ingestion_ts": "2026-01-16T14:36:49.604167", "market_id": "0x49686d26fb712515cd5e12c23f0a1c7e10214c7faa3cb0a730aabe0c33694082", "raw": {"market": "0x49686d26fb712515cd5e12c23f0a1c7e10214c7faa3cb0a730aabe0c33694082", "asset_id": "30442780799048074404860985387051749017905070253466005720364298335239299761065", "price": "0.148", "size": "17.5", "side": "SELL", "timestamp": "1768574163429", "received_at": "2026-01-16T14:36:03.525630"}}
{"event_type": "price_change", "event_ts": "2026-01-16T14:36:03.525630", "ingestion_ts": "2026-01-16T14:36:49.604167", "market_id": "0x49686d26fb712515cd5e12c23f0a1c7e10214c7faa3cb0a730aabe0c33694082", "raw": {"market": "0x49686d26fb712515cd5e12c23f0a1c7e10214c7faa3cb0a730aabe0c33694082", "asset_id": "13244681086321087932946246027856416106585284024824496763706748621681543444582", "price": "0.852", "size": "17.5", "side": "BUY", "timestamp": "1768574163429", "received_at": "2026-01-16T14:36:03.525630"}}
{"event_type": "price_change", "event_ts": "2026-01-16T14:36:04.343694", "ingestion_ts": "2026-01-16T14:36:49.604167", "market_id": "0x50c669f178da4e5bbea7f1be25041fd278914712fa87a6a6f8e57d5923d88dee", "raw": {"market": "0x50c669f178da4e5bbea7f1be25041fd278914712fa87a6a6f8e57d5923d88dee", "asset_id": "74040420326294854165772767082819937451857852955603897473157746262672057685461", "price": "0.856", "size": "0", "side": "BUY", "timestamp": "1768574164307", "received_at": "2026-01-16T14:36:04.343694"}}
{"event_type": "price_change", "event_ts": "2026-01-16T14:36:04.343694", "ingestion_ts": "2026-01-16T14:36:49.604167", "market_id": "0x50c669f178da4e5bbea7f1be25041fd278914712fa87a6a6f8e57d5923d88dee", "raw": {"market": "0x50c669f178da4e5bbea7f1be25041fd278914712fa87a6a6f8e57d5923d88dee", "asset_id": "24682525479474221428144937281315825971983904267399062415430320764754931667953", "price": "0.144", "size": "0", "side": "SELL", "timestamp": "1768574164307", "received_at": "2026-01-16T14:36:04.343694"}}
{"event_type": "price_change", "event_ts": "2026-01-16T14:36:04.372569", "ingestion_ts": "2026-01-16T14:36:49.604167", "market_id": "0x50c669f178da4e5bbea7f1be25041fd278914712fa87a6a6f8e57d5923d88dee", "raw": {"market": "0x50c669f178da4e5bbea7f1be25041fd278914712fa87a6a6f8e57d5923d88dee", "asset_id": "74040420326294854165772767082819937451857852955603897473157746262672057685461", "price": "0.855", "size": "594", "side": "BUY", "timestamp": "1768574164334", "received_at": "2026-01-16T14:36:04.372569"}}
{"event_type": "price_change", "event_ts": "2026-01-16T14:36:04.372569", "ingestion_ts": "2026-01-16T14:36:49.604167", "market_id": "0x50c669f178da4e5bbea7f1be25041fd278914712fa87a6a6f8e57d5923d88dee", "raw": {"market": "0x50c669f178da4e5bbea7f1be25041fd278914712fa87a6a6f8e57d5923d88dee", "asset_id": "24682525479474221428144937281315825971983904267399062415430320764754931667953", "price": "0.145", "size": "594", "side": "SELL", "timestamp": "1768574164334", "received_at": "2026-01-16T14:36:04.372569"}}
{"event_type": "price_change", "event_ts": "2026-01-16T14:36:04.426824", "ingestion_ts": "2026-01-16T14:36:49.604167", "market_id": "0xc0e6b917320a47228fb96e3b5ae0e5c93773a5ae2662ae4e1f37807cfe47ce98", "raw": {"market": "0xc0e6b917320a47228fb96e3b5ae0e5c93773a5ae2662ae4e1f37807cfe47ce98", "asset_id": "58656358377246279051017109359677190749228949103591068167284263961542487110215", "price": "0.002", "size": "3279.99", "side": "BUY", "timestamp": "1768574164389", "received_at": "2026-01-16T14:36:04.426824"}}
{"event_type": "price_change", "event_ts": "2026-01-16T14:36:04.426824", "ingestion_ts": "2026-01-16T14:36:49.604167", "market_id": "0xc0e6b917320a47228fb96e3b5ae0e5c93773a5ae2662ae4e1f37807cfe47ce98", "raw": {"market": "0xc0e6b917320a47228fb96e3b5ae0e5c93773a5ae2662ae4e1f37807cfe47ce98", "asset_id": "81647294538046680798858716589766492074338758116170717123345952330712416337530", "price": "0.998", "size": "3279.99", "side": "SELL", "timestamp": "1768574164389", "received_at": "2026-01-16T14:36:04.426824"}}
{"event_type": "price_change", "event_ts": "2026-01-16T14:36:04.923679", "ingestion_ts": "2026-01-16T14:36:49.604167", "market_id": "0xc0e6b917320a47228fb96e3b5ae0e5c93773a5ae2662ae4e1f37807cfe47ce98", "raw": {"market": "0xc0e6b917320a47228fb96e3b5ae0e5c93773a5ae2662ae4e1f37807cfe47ce98", "asset_id": "58656358377246279051017109359677190749228949103591068167284263961542487110215", "price": "0.002", "size": "3287.1", "side": "BUY", "timestamp": "1768574164888", "received_at": "2026-01-16T14:36:04.923679"}}
{"event_type": "price_change", "event_ts": "2026-01-16T14:36:04.923679", "ingestion_ts": "2026-01-16T14:36:49.604167", "market_id": "0xc0e6b917320a47228fb96e3b5ae0e5c93773a5ae2662ae4e1f37807cfe47ce98", "raw": {"market": "0xc0e6b917320a47228fb96e3b5ae0e5c93773a5ae2662ae4e1f37807cfe47ce98", "asset_id": "81647294538046680798858716589766492074338758116170717123345952330712416337530", "price": "0.998", "size": "3287.1", "side": "SELL", "timestamp": "1768574164888", "received_at": "2026-01-16T14:36:04.923679"}}
{"event_type": "price_change", "event_ts": "2026-01-16T14:36:04.925409", "ingestion_ts": "2026-01-16T14:36:49.604167", "market_id": "0xc0e6b917320a47228fb96e3b5ae0e5c93773a5ae2662ae4e1f37807cfe47ce98", "raw": {"market": "0xc0e6b917320a47228fb96e3b5ae0e5c93773a5ae2662ae4e1f37807cfe47ce98", "asset_id": "58656358377246279051017109359677190749228949103591068167284263961542487110215", "price": "0.002", "size": "3294.21", "side": "BUY", "timestamp": "1768574164889", "received_at": "2026-01-16T14:36:04.925409"}}
{"event_type": "price_change", "event_ts": "2026-01-16T14:36:04.925409", "ingestion_ts": "2026-01-16T14:36:49.604167", "market_id": "0xc0e6b917320a47228fb96e3b5ae0e5c93773a5ae2662ae4e1f37807cfe47ce98", "raw": {"market": "0xc0e6b917320a47228fb96e3b5ae0e5c93773a5ae2662ae4e1f37807cfe47ce98", "asset_id": "81647294538046680798858716589766492074338758116170717123345952330712416337530", "price": "0.998", "size": "3294.21", "side": "SELL", "timestamp": "1768574164889", "received_at": "2026-01-16T14:36:04.925409"}}
{"event_type": "price_change", "event_ts": "2026-01-16T14:36:06.985278", "ingestion_ts": "2026-01-16T14:36:49.604167", "market_id": "0xaf9d0e448129a9f657f851d49495ba4742055d80e0ef1166ba0ee81d4d594214", "raw": {"market": "0xaf9d0e448129a9f657f851d49495ba4742055d80e0ef1166ba0ee81d4d594214", "asset_id": "4153292802911610701832309484716814274802943278345248636922528170020319407796", "price": "0.981", "size": "0", "side": "SELL", "timestamp": "1768574166947", "received_at": "2026-01-16T14:36:06.985278"}}
{"event_type": "price_change", "event_ts": "2026-01-16T14:36:06.985278", "ingestion_ts": "2026-01-16T14:36:49.604167", "market_id": "0xaf9d0e448129a9f657f851d49495ba4742055d80e0ef1166ba0ee81d4d594214", "raw": {"market": "0xaf9d0e448129a9f657f851d49495ba4742055d80e0ef1166ba0ee81d4d594214", "asset_id": "101676997363687199724245607342877036148401850938023978421879460310389391082353", "price": "0.019", "size": "0", "side": "BUY", "timestamp": "1768574166947", "received_at": "2026-01-16T14:36:06.985278"}}
{"event_type": "price_change", "event_ts": "2026-01-16T14:36:07.056874", "ingestion_ts": "2026-01-16T14:36:49.604167", "market_id": "0xae5584fbb57f23c1c608d544b656f23d8bf12340cef70811cf31bb0cb4fc2115", "raw": {"market": "0xae5584fbb57f23c1c608d544b656f23d8bf12340cef70811cf31bb0cb4fc2115", "asset_id": "28946595841244317705636126646676849578876740730186646421280828201004700559420", "price": "0.01", "size": "7742", "side": "BUY", "timestamp": "1768574167004", "received_at": "2026-01-16T14:36:07.056874"}}
{"event_type": "price_change", "event_ts": "2026-01-16T14:36:07.056874", "ingestion_ts": "2026-01-16T14:36:49.604167", "market_id": "0xae5584fbb57f23c1c608d544b656f23d8bf12340cef70811cf31bb0cb4fc2115", "raw": {"market": "0xae5584fbb57f23c1c608d544b656f23d8bf12340cef70811cf31bb0cb4fc2115", "asset_id": "42278252558046940014991595990628759801692726198478046188873057685686228021663", "price": "0.99", "size": "7742", "side": "SELL", "timestamp": "1768574167004", "received_at": "2026-01-16T14:36:07.056874"}}
{"event_type": "price_change", "event_ts": "2026-01-16T14:36:07.402010", "ingestion_ts": "2026-01-16T14:36:49.604167", "market_id": "0xaf9d0e448129a9f657f851d49495ba4742055d80e0ef1166ba0ee81d4d594214", "raw": {"market": "0xaf9d0e448129a9f657f851d49495ba4742055d80e0ef1166ba0ee81d4d594214", "asset_id": "4153292802911610701832309484716814274802943278345248636922528170020319407796", "price": "0.979", "size": "140.01", "side": "SELL", "timestamp": "1768574167332", "received_at": "2026-01-16T14:36:07.402010"}}
{"event_type": "price_change", "event_ts": "2026-01-16T14:36:07.402010", "ingestion_ts": "2026-01-16T14:36:49.604167", "market_id": "0xaf9d0e448129a9f657f851d49495ba4742055d80e0ef1166ba0ee81d4d594214", "raw": {"market": "0xaf9d0e448129a9f657f851d49495ba4742055d80e0ef1166ba0ee81d4d594214", "asset_id": "101676997363687199724245607342877036148401850938023978421879460310389391082353", "price": "0.021", "size": "140.01", "side": "BUY", "timestamp": "1768574167332", "received_at": "2026-01-16T14:36:07.402010"}}
{"event_type": "price_change", "event_ts": "2026-01-16T14:36:07.629566", "ingestion_ts": "2026-01-16T14:36:49.604167", "market_id": "0x2393ed0b0fdc450054c7b9071907eca75cf4fc36e385adf4a0a5f99ee62243e8", "raw": {"market": "0x2393ed0b0fdc450054c7b9071907eca75cf4fc36e385adf4a0a5f99ee62243e8", "asset_id": "32769749367306925959219403371425714180265458150646381231272229429098460625924", "price": "0.95", "size": "0", "side": "BUY", "timestamp": "1768574167585", "received_at": "2026-01-16T14:36:07.629566"}}
{"event_type": "price_change", "event_ts": "2026-01-16T14:36:07.629566", "ingestion_ts": "2026-01-16T14:36:49.604167", "market_id": "0x2393ed0b0fdc450054c7b9071907eca75cf4fc36e385adf4a0a5f99ee62243e8", "raw": {"market": "0x2393ed0b0fdc450054c7b9071907eca75cf4fc36e385adf4a0a5f99ee62243e8", "asset_id": "100074770378634056601572485653252702850363676459996771990439989989293515601975", "price": "0.05", "size": "0", "side": "SELL", "timestamp": "1768574167585", "received_at": "2026-01-16T14:36:07.629566"}}
{"event_type": "price_change", "event_ts": "2026-01-16T14:36:07.700998", "ingestion_ts": "2026-01-16T14:36:49.604167", "market_id": "0xc0e6b917320a47228fb96e3b5ae0e5c93773a5ae2662ae4e1f37807cfe47ce98", "raw": {"market": "0xc0e6b917320a47228fb96e3b5ae0e5c93773a5ae2662ae4e1f37807cfe47ce98", "asset_id": "58656358377246279051017109359677190749228949103591068167284263961542487110215", "price": "0.002", "size": "3287.1", "side": "BUY", "timestamp": "1768574167663", "received_at": "2026-01-16T14:36:07.700998"}}
{"event_type": "price_change", "event_ts": "2026-01-16T14:36:07.700998", "ingestion_ts": "2026-01-16T14:36:49.604167", "market_id": "0xc0e6b917320a47228fb96e3b5ae0e5c93773a5ae2662ae4e1f37807cfe47ce98", "raw": {"market": "0xc0e6b917320a47228fb96e3b5ae0e5c93773a5ae2662ae4e1f37807cfe47ce98", "asset_id": "81647294538046680798858716589766492074338758116170717123345952330712416337530", "price": "0.998", "size": "3287.1", "side": "SELL", "timestamp": "1768574167663", "received_at": "2026-01-16T14:36:07.700998"}}
{"event_type": "price_change", "event_ts": "2026-01-16T14:36:08.144790", "ingestion_ts": "2026-01-16T14:36:49.604167", "market_id": "0xaf9d0e448129a9f657f851d49495ba4742055d80e0ef1166ba0ee81d4d594214", "raw": {"market": "0xaf9d0e448129a9f657f851d49495ba4742055d80e0ef1166ba0ee81d4d594214", "asset_id": "4153292802911610701832309484716814274802943278345248636922528170020319407796", "price": "0.98", "size": "0", "side": "SELL", "timestamp": "1768574168094", "received_at": "2026-01-16T14:36:08.144790"}}
{"event_type": "price_change", "event_ts": "2026-01-16T14:36:08.144790", "ingestion_ts": "2026-01-16T14:36:49.604167", "market_id": "0xaf9d0e448129a9f657f851d49495ba4742055d80e0ef1166ba0ee81d4d594214", "raw": {"market": "0xaf9d0e448129a9f657f851d49495ba4742055d80e0ef1166ba0ee81d4d594214", "asset_id": "101676997363687199724245607342877036148401850938023978421879460310389391082353", "price": "0.02", "size": "0", "side": "BUY", "timestamp": "1768574168094", "received_at": "2026-01-16T14:36:08.144790"}}
{"event_type": "price_change", "event_ts": "2026-01-16T14:36:08.204960", "ingestion_ts": "2026-01-16T14:36:49.604167", "market_id": "0xaf9d0e448129a9f657f851d49495ba4742055d80e0ef1166ba0ee81d4d594214", "raw": {"market": "0xaf9d0e448129a9f657f851d49495ba4742055d80e0ef1166ba0ee81d4d594214", "asset_id": "4153292802911610701832309484716814274802943278345248636922528170020319407796", "price": "0.978", "size": "20.5", "side": "SELL", "timestamp": "1768574168158", "received_at": "2026-01-16T14:36:08.204960"}}
{"event_type": "price_change", "event_ts": "2026-01-16T14:36:08.204960", "ingestion_ts": "2026-01-16T14:36:49.604167", "market_id": "0xaf9d0e448129a9f657f851d49495ba4742055d80e0ef1166ba0ee81d4d594214", "raw": {"market": "0xaf9d0e448129a9f657f851d49495ba4742055d80e0ef1166ba0ee81d4d594214", "asset_id": "101676997363687199724245607342877036148401850938023978421879460310389391082353", "price": "0.022", "size": "20.5", "side": "BUY", "timestamp": "1768574168158", "received_at": "2026-01-16T14:36:08.204960"}}
{"event_type": "price_change", "event_ts": "2026-01-16T14:36:08.536560", "ingestion_ts": "2026-01-16T14:36:49.604167", "market_id": "0x50c669f178da4e5bbea7f1be25041fd278914712fa87a6a6f8e57d5923d88dee", "raw": {"market": "0x50c669f178da4e5bbea7f1be25041fd278914712fa87a6a6f8e57d5923d88dee", "asset_id": "74040420326294854165772767082819937451857852955603897473157746262672057685461", "price": "0.855", "size": "584", "side": "BUY", "timestamp": "1768574168500", "received_at": "2026-01-16T14:36:08.536560"}}
{"event_type": "price_change", "event_ts": "2026-01-16T14:36:08.536560", "ingestion_ts": "2026-01-16T14:36:49.604167", "market_id": "0x50c669f178da4e5bbea7f1be25041fd278914712fa87a6a6f8e57d5923d88dee", "raw": {"market": "0x50c669f178da4e5bbea7f1be25041fd278914712fa87a6a6f8e57d5923d88dee", "asset_id": "24682525479474221428144937281315825971983904267399062415430320764754931667953", "price": "0.145", "size": "584", "side": "SELL", "timestamp": "1768574168500", "received_at": "2026-01-16T14:36:08.536560"}}
{"event_type": "price_change", "event_ts": "2026-01-16T14:36:08.536810", "ingestion_ts": "2026-01-16T14:36:49.604167", "market_id": "0x2393ed0b0fdc450054c7b9071907eca75cf4fc36e385adf4a0a5f99ee62243e8", "raw": {"market": "0x2393ed0b0fdc450054c7b9071907eca75cf4fc36e385adf4a0a5f99ee62243e8", "asset_id": "32769749367306925959219403371425714180265458150646381231272229429098460625924", "price": "0.811", "size": "0", "side": "BUY", "timestamp": "1768574168500", "received_at": "2026-01-16T14:36:08.536810"}}
{"event_type": "price_change", "event_ts": "2026-01-16T14:36:08.536810", "ingestion_ts": "2026-01-16T14:36:49.604167", "market_id": "0x2393ed0b0fdc450054c7b9071907eca75cf4fc36e385adf4a0a5f99ee62243e8", "raw": {"market": "0x2393ed0b0fdc450054c7b9071907eca75cf4fc36e385adf4a0a5f99ee62243e8", "asset_id": "100074770378634056601572485653252702850363676459996771990439989989293515601975", "price": "0.189", "size": "0", "side": "SELL", "timestamp": "1768574168500", "received_at": "2026-01-16T14:36:08.536810"}}
{"event_type": "price_change", "event_ts": "2026-01-16T14:36:08.536842", "ingestion_ts": "2026-01-16T14:36:49.604167", "market_id": "0x49686d26fb712515cd5e12c23f0a1c7e10214c7faa3cb0a730aabe0c33694082", "raw": {"market": "0x49686d26fb712515cd5e12c23f0a1c7e10214c7faa3cb0a730aabe0c33694082", "asset_id": "30442780799048074404860985387051749017905070253466005720364298335239299761065", "price": "0.004", "size": "0", "side": "BUY", "timestamp": "1768574168500", "received_at": "2026-01-16T14:36:08.536842"}}
{"event_type": "price_change", "event_ts": "2026-01-16T14:36:08.536842", "ingestion_ts": "2026-01-16T14:36:49.604167", "market_id": "0x49686d26fb712515cd5e12c23f0a1c7e10214c7faa3cb0a730aabe0c33694082", "raw": {"market": "0x49686d26fb712515cd5e12c23f0a1c7e10214c7faa3cb0a730aabe0c33694082", "asset_id": "13244681086321087932946246027856416106585284024824496763706748621681543444582", "price": "0.996", "size": "0", "side": "SELL", "timestamp": "1768574168500", "received_at": "2026-01-16T14:36:08.536842"}}
{"event_type": "price_change", "event_ts": "2026-01-16T14:36:08.538722", "ingestion_ts": "2026-01-16T14:36:49.604167", "market_id": "0xc55db914f0fd1fee18997706712c0dfd8d0369cdbef93a9fef12bd001914ca77", "raw": {"market": "0xc55db914f0fd1fee18997706712c0dfd8d0369cdbef93a9fef12bd001914ca77", "asset_id": "114600293444080540179603459515770723592661967180480327891296353898330242622833", "price": "0.857", "size": "233", "side": "BUY", "timestamp": "1768574168500", "received_at": "2026-01-16T14:36:08.538722"}}
{"event_type": "price_change", "event_ts": "2026-01-16T14:36:08.538722", "ingestion_ts": "2026-01-16T14:36:49.604167", "market_id": "0xc55db914f0fd1fee18997706712c0dfd8d0369cdbef93a9fef12bd001914ca77", "raw": {"market": "0xc55db914f0fd1fee18997706712c0dfd8d0369cdbef93a9fef12bd001914ca77", "asset_id": "72354723612769247426741660426331235762851940382312402276325808095604519806766", "price": "0.143", "size": "233", "side": "SELL", "timestamp": "1768574168500", "received_at": "2026-01-16T14:36:08.538722"}}
{"event_type": "price_change", "event_ts": "2026-01-16T14:36:08.538765", "ingestion_ts": "2026-01-16T14:36:49.604167", "market_id": "0x49a20c7523c271099008f3ef9a31521263b24d637959852a391e6b4697b1a437", "raw": {"market": "0x49a20c7523c271099008f3ef9a31521263b24d637959852a391e6b4697b1a437", "asset_id": "55881023621710858558280545117465775643848233756850602339827152783696837905531", "price": "0.855", "size": "292", "side": "BUY", "timestamp": "1768574168500", "received_at": "2026-01-16T14:36:08.538765"}}
{"event_type": "price_change", "event_ts": "2026-01-16T14:36:08.538765", "ingestion_ts": "2026-01-16T14:36:49.604167", "market_id": "0x49a20c7523c271099008f3ef9a31521263b24d637959852a391e6b4697b1a437", "raw": {"market": "0x49a20c7523c271099008f3ef9a31521263b24d637959852a391e6b4697b1a437", "asset_id": "13018971792603393862521629014128024641178044618205296260525674415067194037856", "price": "0.145", "size": "292", "side": "SELL", "timestamp": "1768574168500", "received_at": "2026-01-16T14:36:08.538765"}}
{"event_type": "price_change", "event_ts": "2026-01-16T14:36:08.538780", "ingestion_ts": "2026-01-16T14:36:49.604167", "market_id": "0x9472be65457510b7fc3477b20ba90910e99d92eac8421a14bf4b7b7a08ef31dc", "raw": {"market": "0x9472be65457510b7fc3477b20ba90910e99d92eac8421a14bf4b7b7a08ef31dc", "asset_id": "43311793366960417907757893276427136943959788721376762326430771171648759300146", "price": "0.856", "size": "0", "side": "BUY", "timestamp": "1768574168500", "received_at": "2026-01-16T14:36:08.538780"}}
{"event_type": "price_change", "event_ts": "2026-01-16T14:36:08.538780", "ingestion_ts": "2026-01-16T14:36:49.604167", "market_id": "0x9472be65457510b7fc3477b20ba90910e99d92eac8421a14bf4b7b7a08ef31dc", "raw": {"market": "0x9472be65457510b7fc3477b20ba90910e99d92eac8421a14bf4b7b7a08ef31dc", "asset_id": "73414222381656326204771753454630063673548497164758947581648273905027617570612", "price": "0.144", "size": "0", "side": "SELL", "timestamp": "1768574168500", "received_at": "2026-01-16T14:36:08.538780"}}
{"event_type": "price_change", "event_ts": "2026-01-16T14:36:08.543071", "ingestion_ts": "2026-01-16T14:36:49.604167", "market_id": "0x44f08744458b8896620cd3330bc5e1ea69df4199b02d4fc583b3fc96e5d314ce", "raw": {"market": "0x44f08744458b8896620cd3330bc5e1ea69df4199b02d4fc583b3fc96e5d314ce", "asset_id": "72327831507226612545928776794104143393438710920370371172884559893525100761096", "price": "0.853", "size": "234", "side": "BUY", "timestamp": "1768574168500", "received_at": "2026-01-16T14:36:08.543071"}}
{"event_type": "price_change", "event_ts": "2026-01-16T14:36:08.543071", "ingestion_ts": "2026-01-16T14:36:49.604167", "market_id": "0x44f08744458b8896620cd3330bc5e1ea69df4199b02d4fc583b3fc96e5d314ce", "raw": {"market": "0x44f08744458b8896620cd3330bc5e1ea69df4199b02d4fc583b3fc96e5d314ce", "asset_id": "49194009556504828848509244326501559253829462790583873936160989575507522044057", "price": "0.147", "size": "234", "side": "SELL", "timestamp": "1768574168500", "received_at": "2026-01-16T14:36:08.543071"}}
{"event_type": "price_change", "event_ts": "2026-01-16T14:36:08.578575", "ingestion_ts": "2026-01-16T14:36:49.604167", "market_id": "0x9472be65457510b7fc3477b20ba90910e99d92eac8421a14bf4b7b7a08ef31dc", "raw": {"market": "0x9472be65457510b7fc3477b20ba90910e99d92eac8421a14bf4b7b7a08ef31dc", "asset_id": "43311793366960417907757893276427136943959788721376762326430771171648759300146", "price": "0.858", "size": "243", "side": "BUY", "timestamp": "1768574168542", "received_at": "2026-01-16T14:36:08.578575"}}
{"event_type": "price_change", "event_ts": "2026-01-16T14:36:08.578575", "ingestion_ts": "2026-01-16T14:36:49.604167", "market_id": "0x9472be65457510b7fc3477b20ba90910e99d92eac8421a14bf4b7b7a08ef31dc", "raw": {"market": "0x9472be65457510b7fc3477b20ba90910e99d92eac8421a14bf4b7b7a08ef31dc", "asset_id": "73414222381656326204771753454630063673548497164758947581648273905027617570612", "price": "0.142", "size": "243", "side": "SELL", "timestamp": "1768574168542", "received_at": "2026-01-16T14:36:08.578575"}}
{"event_type": "price_change", "event_ts": "2026-01-16T14:36:08.578618", "ingestion_ts": "2026-01-16T14:36:49.604167", "market_id": "0x2393ed0b0fdc450054c7b9071907eca75cf4fc36e385adf4a0a5f99ee62243e8", "raw": {"market": "0x2393ed0b0fdc450054c7b9071907eca75cf4fc36e385adf4a0a5f99ee62243e8", "asset_id": "32769749367306925959219403371425714180265458150646381231272229429098460625924", "price": "0.849", "size": "304", "side": "BUY", "timestamp": "1768574168542", "received_at": "2026-01-16T14:36:08.578618"}}
{"event_type": "price_change", "event_ts": "2026-01-16T14:36:08.578618", "ingestion_ts": "2026-01-16T14:36:49.604167", "market_id": "0x2393ed0b0fdc450054c7b9071907eca75cf4fc36e385adf4a0a5f99ee62243e8", "raw": {"market": "0x2393ed0b0fdc450054c7b9071907eca75cf4fc36e385adf4a0a5f99ee62243e8", "asset_id": "100074770378634056601572485653252702850363676459996771990439989989293515601975", "price": "0.151", "size": "304", "side": "SELL", "timestamp": "1768574168542", "received_at": "2026-01-16T14:36:08.578618"}}
{"event_type": "price_change", "event_ts": "2026-01-16T14:36:08.578632", "ingestion_ts": "2026-01-16T14:36:49.604167", "market_id": "0x50c669f178da4e5bbea7f1be25041fd278914712fa87a6a6f8e57d5923d88dee", "raw": {"market": "0x50c669f178da4e5bbea7f1be25041fd278914712fa87a6a6f8e57d5923d88dee", "asset_id": "74040420326294854165772767082819937451857852955603897473157746262672057685461", "price": "0.857", "size": "35", "side": "BUY", "timestamp": "1768574168542", "received_at": "2026-01-16T14:36:08.578632"}}
{"event_type": "price_change", "event_ts": "2026-01-16T14:36:08.578632", "ingestion_ts": "2026-01-16T14:36:49.604167", "market_id": "0x50c669f178da4e5bbea7f1be25041fd278914712fa87a6a6f8e57d5923d88dee", "raw": {"market": "0x50c669f178da4e5bbea7f1be25041fd278914712fa87a6a6f8e57d5923d88dee", "asset_id": "24682525479474221428144937281315825971983904267399062415430320764754931667953", "price": "0.143", "size": "35", "side": "SELL", "timestamp": "1768574168542", "received_at": "2026-01-16T14:36:08.578632"}}
{"event_type": "price_change", "event_ts": "2026-01-16T14:36:08.579093", "ingestion_ts": "2026-01-16T14:36:49.604167", "market_id": "0x49a20c7523c271099008f3ef9a31521263b24d637959852a391e6b4697b1a437", "raw": {"market": "0x49a20c7523c271099008f3ef9a31521263b24d637959852a391e6b4697b1a437", "asset_id": "55881023621710858558280545117465775643848233756850602339827152783696837905531", "price": "0.857", "size": "10", "side": "BUY", "timestamp": "1768574168542", "received_at": "2026-01-16T14:36:08.579093"}}
{"event_type": "price_change", "event_ts": "2026-01-16T14:36:08.579093", "ingestion_ts": "2026-01-16T14:36:49.604167", "market_id": "0x49a20c7523c271099008f3ef9a31521263b24d637959852a391e6b4697b1a437", "raw": {"market": "0x49a20c7523c271099008f3ef9a31521263b24d637959852a391e6b4697b1a437", "asset_id": "13018971792603393862521629014128024641178044618205296260525674415067194037856", "price": "0.143", "size": "10", "side": "SELL", "timestamp": "1768574168542", "received_at": "2026-01-16T14:36:08.579093"}}
{"event_type": "price_change", "event_ts": "2026-01-16T14:36:08.579116", "ingestion_ts": "2026-01-16T14:36:49.604167", "market_id": "0xc55db914f0fd1fee18997706712c0dfd8d0369cdbef93a9fef12bd001914ca77", "raw": {"market": "0xc55db914f0fd1fee18997706712c0dfd8d0369cdbef93a9fef12bd001914ca77", "asset_id": "114600293444080540179603459515770723592661967180480327891296353898330242622833", "price": "0.859", "size": "40", "side": "BUY", "timestamp": "1768574168542", "received_at": "2026-01-16T14:36:08.579116"}}
{"event_type": "price_change", "event_ts": "2026-01-16T14:36:08.579116", "ingestion_ts": "2026-01-16T14:36:49.604167", "market_id": "0xc55db914f0fd1fee18997706712c0dfd8d0369cdbef93a9fef12bd001914ca77", "raw": {"market": "0xc55db914f0fd1fee18997706712c0dfd8d0369cdbef93a9fef12bd001914ca77", "asset_id": "72354723612769247426741660426331235762851940382312402276325808095604519806766", "price": "0.141", "size": "40", "side": "SELL", "timestamp": "1768574168542", "received_at": "2026-01-16T14:36:08.579116"}}
{"event_type": "price_change", "event_ts": "2026-01-16T14:36:08.579129", "ingestion_ts": "2026-01-16T14:36:49.604167", "market_id": "0x44f08744458b8896620cd3330bc5e1ea69df4199b02d4fc583b3fc96e5d314ce", "raw": {"market": "0x44f08744458b8896620cd3330bc5e1ea69df4199b02d4fc583b3fc96e5d314ce", "asset_id": "72327831507226612545928776794104143393438710920370371172884559893525100761096", "price": "0.854", "size": "10", "side": "BUY", "timestamp": "1768574168542", "received_at": "2026-01-16T14:36:08.579129"}}
{"event_type": "price_change", "event_ts": "2026-01-16T14:36:08.579129", "ingestion_ts": "2026-01-16T14:36:49.604167", "market_id": "0x44f08744458b8896620cd3330bc5e1ea69df4199b02d4fc583b3fc96e5d314ce", "raw": {"market": "0x44f08744458b8896620cd3330bc5e1ea69df4199b02d4fc583b3fc96e5d314ce", "asset_id": "49194009556504828848509244326501559253829462790583873936160989575507522044057", "price": "0.146", "size": "10", "side": "SELL", "timestamp": "1768574168542", "received_at": "2026-01-16T14:36:08.579129"}}
{"event_type": "price_change", "event_ts": "2026-01-16T14:36:08.579793", "ingestion_ts": "2026-01-16T14:36:49.604167", "market_id": "0x49686d26fb712515cd5e12c23f0a1c7e10214c7faa3cb0a730aabe0c33694082", "raw": {"market": "0x49686d26fb712515cd5e12c23f0a1c7e10214c7faa3cb0a730aabe0c33694082", "asset_id": "30442780799048074404860985387051749017905070253466005720364298335239299761065", "price": "0.006", "size": "20.08", "side": "BUY", "timestamp": "1768574168543", "received_at": "2026-01-16T14:36:08.579793"}}
{"event_type": "price_change", "event_ts": "2026-01-16T14:36:08.579793", "ingestion_ts": "2026-01-16T14:36:49.604167", "market_id": "0x49686d26fb712515cd5e12c23f0a1c7e10214c7faa3cb0a730aabe0c33694082", "raw": {"market": "0x49686d26fb712515cd5e12c23f0a1c7e10214c7faa3cb0a730aabe0c33694082", "asset_id": "13244681086321087932946246027856416106585284024824496763706748621681543444582", "price": "0.994", "size": "20.08", "side": "SELL", "timestamp": "1768574168543", "received_at": "2026-01-16T14:36:08.579793"}}
{"event_type": "price_change", "event_ts": "2026-01-16T14:36:09.073083", "ingestion_ts": "2026-01-16T14:36:49.604167", "market_id": "0x49686d26fb712515cd5e12c23f0a1c7e10214c7faa3cb0a730aabe0c33694082", "raw": {"market": "0x49686d26fb712515cd5e12c23f0a1c7e10214c7faa3cb0a730aabe0c33694082", "asset_id": "30442780799048074404860985387051749017905070253466005720364298335239299761065", "price": "0.011", "size": "0", "side": "BUY", "timestamp": "1768574169013", "received_at": "2026-01-16T14:36:09.073083"}}
{"event_type": "price_change", "event_ts": "2026-01-16T14:36:09.073083", "ingestion_ts": "2026-01-16T14:36:49.604167", "market_id": "0x49686d26fb712515cd5e12c23f0a1c7e10214c7faa3cb0a730aabe0c33694082", "raw": {"market": "0x49686d26fb712515cd5e12c23f0a1c7e10214c7faa3cb0a730aabe0c33694082", "asset_id": "13244681086321087932946246027856416106585284024824496763706748621681543444582", "price": "0.989", "size": "0", "side": "SELL", "timestamp": "1768574169013", "received_at": "2026-01-16T14:36:09.073083"}}
{"event_type": "price_change", "event_ts": "2026-01-16T14:36:09.150667", "ingestion_ts": "2026-01-16T14:36:49.604167", "market_id": "0xae5584fbb57f23c1c608d544b656f23d8bf12340cef70811cf31bb0cb4fc2115", "raw": {"market": "0xae5584fbb57f23c1c608d544b656f23d8bf12340cef70811cf31bb0cb4fc2115", "asset_id": "28946595841244317705636126646676849578876740730186646421280828201004700559420", "price": "0.01", "size": "8241", "side": "BUY", "timestamp": "1768574169111", "received_at": "2026-01-16T14:36:09.150667"}}
{"event_type": "price_change", "event_ts": "2026-01-16T14:36:09.150667", "ingestion_ts": "2026-01-16T14:36:49.604167", "market_id": "0xae5584fbb57f23c1c608d544b656f23d8bf12340cef70811cf31bb0cb4fc2115", "raw": {"market": "0xae5584fbb57f23c1c608d544b656f23d8bf12340cef70811cf31bb0cb4fc2115", "asset_id": "42278252558046940014991595990628759801692726198478046188873057685686228021663", "price": "0.99", "size": "8241", "side": "SELL", "timestamp": "1768574169111", "received_at": "2026-01-16T14:36:09.150667"}}
{"event_type": "price_change", "event_ts": "2026-01-16T14:36:09.834216", "ingestion_ts": "2026-01-16T14:36:49.604167", "market_id": "0x49686d26fb712515cd5e12c23f0a1c7e10214c7faa3cb0a730aabe0c33694082", "raw": {"market": "0x49686d26fb712515cd5e12c23f0a1c7e10214c7faa3cb0a730aabe0c33694082", "asset_id": "30442780799048074404860985387051749017905070253466005720364298335239299761065", "price": "0.012", "size": "12.61", "side": "BUY", "timestamp": "1768574169792", "received_at": "2026-01-16T14:36:09.834216"}}
{"event_type": "price_change", "event_ts": "2026-01-16T14:36:09.834216", "ingestion_ts": "2026-01-16T14:36:49.604167", "market_id": "0x49686d26fb712515cd5e12c23f0a1c7e10214c7faa3cb0a730aabe0c33694082", "raw": {"market": "0x49686d26fb712515cd5e12c23f0a1c7e10214c7faa3cb0a730aabe0c33694082", "asset_id": "13244681086321087932946246027856416106585284024824496763706748621681543444582", "price": "0.988", "size": "12.61", "side": "SELL", "timestamp": "1768574169792", "received_at": "2026-01-16T14:36:09.834216"}}
{"event_type": "price_change", "event_ts": "2026-01-16T14:36:09.835312", "ingestion_ts": "2026-01-16T14:36:49.604167", "market_id": "0x49686d26fb712515cd5e12c23f0a1c7e10214c7faa3cb0a730aabe0c33694082", "raw": {"market": "0x49686d26fb712515cd5e12c23f0a1c7e10214c7faa3cb0a730aabe0c33694082", "asset_id": "30442780799048074404860985387051749017905070253466005720364298335239299761065", "price": "0.008", "size": "15.58", "side": "BUY", "timestamp": "1768574169793", "received_at": "2026-01-16T14:36:09.835312"}}
{"event_type": "price_change", "event_ts": "2026-01-16T14:36:09.835312", "ingestion_ts": "2026-01-16T14:36:49.604167", "market_id": "0x49686d26fb712515cd5e12c23f0a1c7e10214c7faa3cb0a730aabe0c33694082", "raw": {"market": "0x49686d26fb712515cd5e12c23f0a1c7e10214c7faa3cb0a730aabe0c33694082", "asset_id": "13244681086321087932946246027856416106585284024824496763706748621681543444582", "price": "0.992", "size": "15.58", "side": "SELL", "timestamp": "1768574169793", "received_at": "2026-01-16T14:36:09.835312"}}
{"event_type": "price_change", "event_ts": "2026-01-16T14:36:10.663125", "ingestion_ts": "2026-01-16T14:36:49.604167", "market_id": "0x49686d26fb712515cd5e12c23f0a1c7e10214c7faa3cb0a730aabe0c33694082", "raw": {"market": "0x49686d26fb712515cd5e12c23f0a1c7e10214c7faa3cb0a730aabe0c33694082", "asset_id": "13244681086321087932946246027856416106585284024824496763706748621681543444582", "price": "0.854", "size": "0", "side": "BUY", "timestamp": "1768574170627", "received_at": "2026-01-16T14:36:10.663125"}}
{"event_type": "price_change", "event_ts": "2026-01-16T14:36:10.663125", "ingestion_ts": "2026-01-16T14:36:49.604167", "market_id": "0x49686d26fb712515cd5e12c23f0a1c7e10214c7faa3cb0a730aabe0c33694082", "raw": {"market": "0x49686d26fb712515cd5e12c23f0a1c7e10214c7faa3cb0a730aabe0c33694082", "asset_id": "30442780799048074404860985387051749017905070253466005720364298335239299761065", "price": "0.146", "size": "0", "side": "SELL", "timestamp": "1768574170627", "received_at": "2026-01-16T14:36:10.663125"}}
{"event_type": "price_change", "event_ts": "2026-01-16T14:36:10.693136", "ingestion_ts": "2026-01-16T14:36:49.604167", "market_id": "0x49686d26fb712515cd5e12c23f0a1c7e10214c7faa3cb0a730aabe0c33694082", "raw": {"market": "0x49686d26fb712515cd5e12c23f0a1c7e10214c7faa3cb0a730aabe0c33694082", "asset_id": "13244681086321087932946246027856416106585284024824496763706748621681543444582", "price": "0.911", "size": "134.98", "side": "SELL", "timestamp": "1768574170657", "received_at": "2026-01-16T14:36:10.693136"}}
{"event_type": "price_change", "event_ts": "2026-01-16T14:36:10.693136", "ingestion_ts": "2026-01-16T14:36:49.604167", "market_id": "0x49686d26fb712515cd5e12c23f0a1c7e10214c7faa3cb0a730aabe0c33694082", "raw": {"market": "0x49686d26fb712515cd5e12c23f0a1c7e10214c7faa3cb0a730aabe0c33694082", "asset_id": "30442780799048074404860985387051749017905070253466005720364298335239299761065", "price": "0.089", "size": "134.98", "side": "BUY", "timestamp": "1768574170657", "received_at": "2026-01-16T14:36:10.693136"}}
{"event_type": "price_change", "event_ts": "2026-01-16T14:36:11.473607", "ingestion_ts": "2026-01-16T14:36:49.604167", "market_id": "0xc0e6b917320a47228fb96e3b5ae0e5c93773a5ae2662ae4e1f37807cfe47ce98", "raw": {"market": "0xc0e6b917320a47228fb96e3b5ae0e5c93773a5ae2662ae4e1f37807cfe47ce98", "asset_id": "58656358377246279051017109359677190749228949103591068167284263961542487110215", "price": "0.002", "size": "3279.99", "side": "BUY", "timestamp": "1768574171437", "received_at": "2026-01-16T14:36:11.473607"}}
{"event_type": "price_change", "event_ts": "2026-01-16T14:36:11.473607", "ingestion_ts": "2026-01-16T14:36:49.604167", "market_id": "0xc0e6b917320a47228fb96e3b5ae0e5c93773a5ae2662ae4e1f37807cfe47ce98", "raw": {"market": "0xc0e6b917320a47228fb96e3b5ae0e5c93773a5ae2662ae4e1f37807cfe47ce98", "asset_id": "81647294538046680798858716589766492074338758116170717123345952330712416337530", "price": "0.998", "size": "3279.99", "side": "SELL", "timestamp": "1768574171437", "received_at": "2026-01-16T14:36:11.473607"}}
{"event_type": "price_change", "event_ts": "2026-01-16T14:36:11.547412", "ingestion_ts": "2026-01-16T14:36:49.604167", "market_id": "0x50c669f178da4e5bbea7f1be25041fd278914712fa87a6a6f8e57d5923d88dee", "raw": {"market": "0x50c669f178da4e5bbea7f1be25041fd278914712fa87a6a6f8e57d5923d88dee", "asset_id": "74040420326294854165772767082819937451857852955603897473157746262672057685461", "price": "0.857", "size": "25", "side": "BUY", "timestamp": "1768574171511", "received_at": "2026-01-16T14:36:11.547412"}}
{"event_type": "price_change", "event_ts": "2026-01-16T14:36:11.547412", "ingestion_ts": "2026-01-16T14:36:49.604167", "market_id": "0x50c669f178da4e5bbea7f1be25041fd278914712fa87a6a6f8e57d5923d88dee", "raw": {"market": "0x50c669f178da4e5bbea7f1be25041fd278914712fa87a6a6f8e57d5923d88dee", "asset_id": "24682525479474221428144937281315825971983904267399062415430320764754931667953", "price": "0.143", "size": "25", "side": "SELL", "timestamp": "1768574171511", "received_at": "2026-01-16T14:36:11.547412"}}
{"event_type": "price_change", "event_ts": "2026-01-16T14:36:11.547764", "ingestion_ts": "2026-01-16T14:36:49.604167", "market_id": "0xc55db914f0fd1fee18997706712c0dfd8d0369cdbef93a9fef12bd001914ca77", "raw": {"market": "0xc55db914f0fd1fee18997706712c0dfd8d0369cdbef93a9fef12bd001914ca77", "asset_id": "114600293444080540179603459515770723592661967180480327891296353898330242622833", "price": "0.859", "size": "30", "side": "BUY", "timestamp": "1768574171511", "received_at": "2026-01-16T14:36:11.547764"}}
{"event_type": "price_change", "event_ts": "2026-01-16T14:36:11.547764", "ingestion_ts": "2026-01-16T14:36:49.604167", "market_id": "0xc55db914f0fd1fee18997706712c0dfd8d0369cdbef93a9fef12bd001914ca77", "raw": {"market": "0xc55db914f0fd1fee18997706712c0dfd8d0369cdbef93a9fef12bd001914ca77", "asset_id": "72354723612769247426741660426331235762851940382312402276325808095604519806766", "price": "0.141", "size": "30", "side": "SELL", "timestamp": "1768574171511", "received_at": "2026-01-16T14:36:11.547764"}}
{"event_type": "price_change", "event_ts": "2026-01-16T14:36:11.547801", "ingestion_ts": "2026-01-16T14:36:49.604167", "market_id": "0x9472be65457510b7fc3477b20ba90910e99d92eac8421a14bf4b7b7a08ef31dc", "raw": {"market": "0x9472be65457510b7fc3477b20ba90910e99d92eac8421a14bf4b7b7a08ef31dc", "asset_id": "43311793366960417907757893276427136943959788721376762326430771171648759300146", "price": "0.858", "size": "233", "side": "BUY", "timestamp": "1768574171511", "received_at": "2026-01-16T14:36:11.547801"}}
{"event_type": "price_change", "event_ts": "2026-01-16T14:36:11.547801", "ingestion_ts": "2026-01-16T14:36:49.604167", "market_id": "0x9472be65457510b7fc3477b20ba90910e99d92eac8421a14bf4b7b7a08ef31dc", "raw": {"market": "0x9472be65457510b7fc3477b20ba90910e99d92eac8421a14bf4b7b7a08ef31dc", "asset_id": "73414222381656326204771753454630063673548497164758947581648273905027617570612", "price": "0.142", "size": "233", "side": "SELL", "timestamp": "1768574171511", "received_at": "2026-01-16T14:36:11.547801"}}
{"event_type": "price_change", "event_ts": "2026-01-16T14:36:11.547815", "ingestion_ts": "2026-01-16T14:36:49.604167", "market_id": "0x49a20c7523c271099008f3ef9a31521263b24d637959852a391e6b4697b1a437", "raw": {"market": "0x49a20c7523c271099008f3ef9a31521263b24d637959852a391e6b4697b1a437", "asset_id": "55881023621710858558280545117465775643848233756850602339827152783696837905531", "price": "0.857", "size": "0", "side": "BUY", "timestamp": "1768574171511", "received_at": "2026-01-16T14:36:11.547815"}}
{"event_type": "price_change", "event_ts": "2026-01-16T14:36:11.547815", "ingestion_ts": "2026-01-16T14:36:49.604167", "market_id": "0x49a20c7523c271099008f3ef9a31521263b24d637959852a391e6b4697b1a437", "raw": {"market": "0x49a20c7523c271099008f3ef9a31521263b24d637959852a391e6b4697b1a437", "asset_id": "13018971792603393862521629014128024641178044618205296260525674415067194037856", "price": "0.143", "size": "0", "side": "SELL", "timestamp": "1768574171511", "received_at": "2026-01-16T14:36:11.547815"}}
{"event_type": "price_change", "event_ts": "2026-01-16T14:36:11.547837", "ingestion_ts": "2026-01-16T14:36:49.604167", "market_id": "0x2393ed0b0fdc450054c7b9071907eca75cf4fc36e385adf4a0a5f99ee62243e8", "raw": {"market": "0x2393ed0b0fdc450054c7b9071907eca75cf4fc36e385adf4a0a5f99ee62243e8", "asset_id": "32769749367306925959219403371425714180265458150646381231272229429098460625924", "price": "0.849", "size": "294", "side": "BUY", "timestamp": "1768574171511", "received_at": "2026-01-16T14:36:11.547837"}}
{"event_type": "price_change", "event_ts": "2026-01-16T14:36:11.547837", "ingestion_ts": "2026-01-16T14:36:49.604167", "market_id": "0x2393ed0b0fdc450054c7b9071907eca75cf4fc36e385adf4a0a5f99ee62243e8", "raw": {"market": "0x2393ed0b0fdc450054c7b9071907eca75cf4fc36e385adf4a0a5f99ee62243e8", "asset_id": "100074770378634056601572485653252702850363676459996771990439989989293515601975", "price": "0.151", "size": "294", "side": "SELL", "timestamp": "1768574171511", "received_at": "2026-01-16T14:36:11.547837"}}
{"event_type": "price_change", "event_ts": "2026-01-16T14:36:11.591221", "ingestion_ts": "2026-01-16T14:36:49.604167", "market_id": "0x9472be65457510b7fc3477b20ba90910e99d92eac8421a14bf4b7b7a08ef31dc", "raw": {"market": "0x9472be65457510b7fc3477b20ba90910e99d92eac8421a14bf4b7b7a08ef31dc", "asset_id": "43311793366960417907757893276427136943959788721376762326430771171648759300146", "price": "0.856", "size": "10", "side": "BUY", "timestamp": "1768574171546", "received_at": "2026-01-16T14:36:11.591221"}}
{"event_type": "price_change", "event_ts": "2026-01-16T14:36:11.591221", "ingestion_ts": "2026-01-16T14:36:49.604167", "market_id": "0x9472be65457510b7fc3477b20ba90910e99d92eac8421a14bf4b7b7a08ef31dc", "raw": {"market": "0x9472be65457510b7fc3477b20ba90910e99d92eac8421a14bf4b7b7a08ef31dc", "asset_id": "73414222381656326204771753454630063673548497164758947581648273905027617570612", "price": "0.144", "size": "10", "side": "SELL", "timestamp": "1768574171546", "received_at": "2026-01-16T14:36:11.591221"}}
{"event_type": "price_change", "event_ts": "2026-01-16T14:36:11.591303", "ingestion_ts": "2026-01-16T14:36:49.604167", "market_id": "0x2393ed0b0fdc450054c7b9071907eca75cf4fc36e385adf4a0a5f99ee62243e8", "raw": {"market": "0x2393ed0b0fdc450054c7b9071907eca75cf4fc36e385adf4a0a5f99ee62243e8", "asset_id": "32769749367306925959219403371425714180265458150646381231272229429098460625924", "price": "0.811", "size": "10", "side": "BUY", "timestamp": "1768574171546", "received_at": "2026-01-16T14:36:11.591303"}}
{"event_type": "price_change", "event_ts": "2026-01-16T14:36:11.591303", "ingestion_ts": "2026-01-16T14:36:49.604167", "market_id": "0x2393ed0b0fdc450054c7b9071907eca75cf4fc36e385adf4a0a5f99ee62243e8", "raw": {"market": "0x2393ed0b0fdc450054c7b9071907eca75cf4fc36e385adf4a0a5f99ee62243e8", "asset_id": "100074770378634056601572485653252702850363676459996771990439989989293515601975", "price": "0.189", "size": "10", "side": "SELL", "timestamp": "1768574171546", "received_at": "2026-01-16T14:36:11.591303"}}
{"event_type": "price_change", "event_ts": "2026-01-16T14:36:11.591321", "ingestion_ts": "2026-01-16T14:36:49.604167", "market_id": "0x49a20c7523c271099008f3ef9a31521263b24d637959852a391e6b4697b1a437", "raw": {"market": "0x49a20c7523c271099008f3ef9a31521263b24d637959852a391e6b4697b1a437", "asset_id": "55881023621710858558280545117465775643848233756850602339827152783696837905531", "price": "0.856", "size": "40", "side": "BUY", "timestamp": "1768574171546", "received_at": "2026-01-16T14:36:11.591321"}}
{"event_type": "price_change", "event_ts": "2026-01-16T14:36:11.591321", "ingestion_ts": "2026-01-16T14:36:49.604167", "market_id": "0x49a20c7523c271099008f3ef9a31521263b24d637959852a391e6b4697b1a437", "raw": {"market": "0x49a20c7523c271099008f3ef9a31521263b24d637959852a391e6b4697b1a437", "asset_id": "13018971792603393862521629014128024641178044618205296260525674415067194037856", "price": "0.144", "size": "40", "side": "SELL", "timestamp": "1768574171546", "received_at": "2026-01-16T14:36:11.591321"}}
{"event_type": "price_change", "event_ts": "2026-01-16T14:36:11.591335", "ingestion_ts": "2026-01-16T14:36:49.604167", "market_id": "0x50c669f178da4e5bbea7f1be25041fd278914712fa87a6a6f8e57d5923d88dee", "raw": {"market": "0x50c669f178da4e5bbea7f1be25041fd278914712fa87a6a6f8e57d5923d88dee", "asset_id": "74040420326294854165772767082819937451857852955603897473157746262672057685461", "price": "0.856", "size": "10", "side": "BUY", "timestamp": "1768574171546", "received_at": "2026-01-16T14:36:11.591335"}}
{"event_type": "price_change", "event_ts": "2026-01-16T14:36:11.591335", "ingestion_ts": "2026-01-16T14:36:49.604167", "market_id": "0x50c669f178da4e5bbea7f1be25041fd278914712fa87a6a6f8e57d5923d88dee", "raw": {"market": "0x50c669f178da4e5bbea7f1be25041fd278914712fa87a6a6f8e57d5923d88dee", "asset_id": "24682525479474221428144937281315825971983904267399062415430320764754931667953", "price": "0.144", "size": "10", "side": "SELL", "timestamp": "1768574171546", "received_at": "2026-01-16T14:36:11.591335"}}
{"event_type": "price_change", "event_ts": "2026-01-16T14:36:11.591347", "ingestion_ts": "2026-01-16T14:36:49.604167", "market_id": "0xc55db914f0fd1fee18997706712c0dfd8d0369cdbef93a9fef12bd001914ca77", "raw": {"market": "0xc55db914f0fd1fee18997706712c0dfd8d0369cdbef93a9fef12bd001914ca77", "asset_id": "114600293444080540179603459515770723592661967180480327891296353898330242622833", "price": "0.858", "size": "10", "side": "BUY", "timestamp": "1768574171546", "received_at": "2026-01-16T14:36:11.591347"}}
{"event_type": "price_change", "event_ts": "2026-01-16T14:36:11.591347", "ingestion_ts": "2026-01-16T14:36:49.604167", "market_id": "0xc55db914f0fd1fee18997706712c0dfd8d0369cdbef93a9fef12bd001914ca77", "raw": {"market": "0xc55db914f0fd1fee18997706712c0dfd8d0369cdbef93a9fef12bd001914ca77", "asset_id": "72354723612769247426741660426331235762851940382312402276325808095604519806766", "price": "0.142", "size": "10", "side": "SELL", "timestamp": "1768574171546", "received_at": "2026-01-16T14:36:11.591347"}}
{"event_type": "price_change", "event_ts": "2026-01-16T14:36:11.601064", "ingestion_ts": "2026-01-16T14:36:49.604167", "market_id": "0x2393ed0b0fdc450054c7b9071907eca75cf4fc36e385adf4a0a5f99ee62243e8", "raw": {"market": "0x2393ed0b0fdc450054c7b9071907eca75cf4fc36e385adf4a0a5f99ee62243e8", "asset_id": "100074770378634056601572485653252702850363676459996771990439989989293515601975", "price": "0.049", "size": "0", "side": "SELL", "timestamp": "1768574171550", "received_at": "2026-01-16T14:36:11.601064"}}
{"event_type": "price_change", "event_ts": "2026-01-16T14:36:11.601064", "ingestion_ts": "2026-01-16T14:36:49.604167", "market_id": "0x2393ed0b0fdc450054c7b9071907eca75cf4fc36e385adf4a0a5f99ee62243e8", "raw": {"market": "0x2393ed0b0fdc450054c7b9071907eca75cf4fc36e385adf4a0a5f99ee62243e8", "asset_id": "32769749367306925959219403371425714180265458150646381231272229429098460625924", "price": "0.951", "size": "0", "side": "BUY", "timestamp": "1768574171550", "received_at": "2026-01-16T14:36:11.601064"}}
{"event_type": "price_change", "event_ts": "2026-01-16T14:36:11.633242", "ingestion_ts": "2026-01-16T14:36:49.604167", "market_id": "0x2393ed0b0fdc450054c7b9071907eca75cf4fc36e385adf4a0a5f99ee62243e8", "raw": {"market": "0x2393ed0b0fdc450054c7b9071907eca75cf4fc36e385adf4a0a5f99ee62243e8", "asset_id": "100074770378634056601572485653252702850363676459996771990439989989293515601975", "price": "0.061", "size": "204", "side": "SELL", "timestamp": "1768574171579", "received_at": "2026-01-16T14:36:11.633242"}}
{"event_type": "price_change", "event_ts": "2026-01-16T14:36:11.633242", "ingestion_ts": "2026-01-16T14:36:49.604167", "market_id": "0x2393ed0b0fdc450054c7b9071907eca75cf4fc36e385adf4a0a5f99ee62243e8", "raw": {"market": "0x2393ed0b0fdc450054c7b9071907eca75cf4fc36e385adf4a0a5f99ee62243e8", "asset_id": "32769749367306925959219403371425714180265458150646381231272229429098460625924", "price": "0.939", "size": "204", "side": "BUY", "timestamp": "1768574171579", "received_at": "2026-01-16T14:36:11.633242"}}
{"event_type": "price_change", "event_ts": "2026-01-16T14:36:12.198382", "ingestion_ts": "2026-01-16T14:36:49.604167", "market_id": "0xc0e6b917320a47228fb96e3b5ae0e5c93773a5ae2662ae4e1f37807cfe47ce98", "raw": {"market": "0xc0e6b917320a47228fb96e3b5ae0e5c93773a5ae2662ae4e1f37807cfe47ce98", "asset_id": "58656358377246279051017109359677190749228949103591068167284263961542487110215", "price": "0.002", "size": "3287.1", "side": "BUY", "timestamp": "1768574172133", "received_at": "2026-01-16T14:36:12.198382"}}
{"event_type": "price_change", "event_ts": "2026-01-16T14:36:12.198382", "ingestion_ts": "2026-01-16T14:36:49.604167", "market_id": "0xc0e6b917320a47228fb96e3b5ae0e5c93773a5ae2662ae4e1f37807cfe47ce98", "raw": {"market": "0xc0e6b917320a47228fb96e3b5ae0e5c93773a5ae2662ae4e1f37807cfe47ce98", "asset_id": "81647294538046680798858716589766492074338758116170717123345952330712416337530", "price": "0.998", "size": "3287.1", "side": "SELL", "timestamp": "1768574172133", "received_at": "2026-01-16T14:36:12.198382"}}
{"event_type": "price_change", "event_ts": "2026-01-16T14:36:12.204494", "ingestion_ts": "2026-01-16T14:36:49.604167", "market_id": "0xc0e6b917320a47228fb96e3b5ae0e5c93773a5ae2662ae4e1f37807cfe47ce98", "raw": {"market": "0xc0e6b917320a47228fb96e3b5ae0e5c93773a5ae2662ae4e1f37807cfe47ce98", "asset_id": "58656358377246279051017109359677190749228949103591068167284263961542487110215", "price": "0.002", "size": "3294.21", "side": "BUY", "timestamp": "1768574172134", "received_at": "2026-01-16T14:36:12.204494"}}
{"event_type": "price_change", "event_ts": "2026-01-16T14:36:12.204494", "ingestion_ts": "2026-01-16T14:36:49.604167", "market_id": "0xc0e6b917320a47228fb96e3b5ae0e5c93773a5ae2662ae4e1f37807cfe47ce98", "raw": {"market": "0xc0e6b917320a47228fb96e3b5ae0e5c93773a5ae2662ae4e1f37807cfe47ce98", "asset_id": "81647294538046680798858716589766492074338758116170717123345952330712416337530", "price": "0.998", "size": "3294.21", "side": "SELL", "timestamp": "1768574172134", "received_at": "2026-01-16T14:36:12.204494"}}
{"event_type": "price_change", "event_ts": "2026-01-16T14:36:12.972491", "ingestion_ts": "2026-01-16T14:36:49.604167", "market_id": "0xaf9d0e448129a9f657f851d49495ba4742055d80e0ef1166ba0ee81d4d594214", "raw": {"market": "0xaf9d0e448129a9f657f851d49495ba4742055d80e0ef1166ba0ee81d4d594214", "asset_id": "4153292802911610701832309484716814274802943278345248636922528170020319407796", "price": "0.979", "size": "0", "side": "SELL", "timestamp": "1768574172923", "received_at": "2026-01-16T14:36:12.972491"}}
{"event_type": "price_change", "event_ts": "2026-01-16T14:36:12.972491", "ingestion_ts": "2026-01-16T14:36:49.604167", "market_id": "0xaf9d0e448129a9f657f851d49495ba4742055d80e0ef1166ba0ee81d4d594214", "raw": {"market": "0xaf9d0e448129a9f657f851d49495ba4742055d80e0ef1166ba0ee81d4d594214", "asset_id": "101676997363687199724245607342877036148401850938023978421879460310389391082353", "price": "0.021", "size": "0", "side": "BUY", "timestamp": "1768574172923", "received_at": "2026-01-16T14:36:12.972491"}}
{"event_type": "price_change", "event_ts": "2026-01-16T14:36:13.274006", "ingestion_ts": "2026-01-16T14:36:49.604167", "market_id": "0x2393ed0b0fdc450054c7b9071907eca75cf4fc36e385adf4a0a5f99ee62243e8", "raw": {"market": "0x2393ed0b0fdc450054c7b9071907eca75cf4fc36e385adf4a0a5f99ee62243e8", "asset_id": "32769749367306925959219403371425714180265458150646381231272229429098460625924", "price": "0.94", "size": "50", "side": "BUY", "timestamp": "1768574173238", "received_at": "2026-01-16T14:36:13.274006"}}
{"event_type": "price_change", "event_ts": "2026-01-16T14:36:13.274006", "ingestion_ts": "2026-01-16T14:36:49.604167", "market_id": "0x2393ed0b0fdc450054c7b9071907eca75cf4fc36e385adf4a0a5f99ee62243e8", "raw": {"market": "0x2393ed0b0fdc450054c7b9071907eca75cf4fc36e385adf4a0a5f99ee62243e8", "asset_id": "100074770378634056601572485653252702850363676459996771990439989989293515601975", "price": "0.06", "size": "50", "side": "SELL", "timestamp": "1768574173238", "received_at": "2026-01-16T14:36:13.274006"}}
{"event_type": "price_change", "event_ts": "2026-01-16T14:36:13.296815", "ingestion_ts": "2026-01-16T14:36:49.604167", "market_id": "0x2393ed0b0fdc450054c7b9071907eca75cf4fc36e385adf4a0a5f99ee62243e8", "raw": {"market": "0x2393ed0b0fdc450054c7b9071907eca75cf4fc36e385adf4a0a5f99ee62243e8", "asset_id": "100074770378634056601572485653252702850363676459996771990439989989293515601975", "price": "0.061", "size": "0", "side": "SELL", "timestamp": "1768574173261", "received_at": "2026-01-16T14:36:13.296815"}}
{"event_type": "price_change", "event_ts": "2026-01-16T14:36:13.296815", "ingestion_ts": "2026-01-16T14:36:49.604167", "market_id": "0x2393ed0b0fdc450054c7b9071907eca75cf4fc36e385adf4a0a5f99ee62243e8", "raw": {"market": "0x2393ed0b0fdc450054c7b9071907eca75cf4fc36e385adf4a0a5f99ee62243e8", "asset_id": "32769749367306925959219403371425714180265458150646381231272229429098460625924", "price": "0.939", "size": "0", "side": "BUY", "timestamp": "1768574173261", "received_at": "2026-01-16T14:36:13.296815"}}
{"event_type": "price_change", "event_ts": "2026-01-16T14:36:13.324096", "ingestion_ts": "2026-01-16T14:36:49.604167", "market_id": "0x2393ed0b0fdc450054c7b9071907eca75cf4fc36e385adf4a0a5f99ee62243e8", "raw": {"market": "0x2393ed0b0fdc450054c7b9071907eca75cf4fc36e385adf4a0a5f99ee62243e8", "asset_id": "100074770378634056601572485653252702850363676459996771990439989989293515601975", "price": "0.059", "size": "204", "side": "SELL", "timestamp": "1768574173289", "received_at": "2026-01-16T14:36:13.324096"}}
{"event_type": "price_change", "event_ts": "2026-01-16T14:36:13.324096", "ingestion_ts": "2026-01-16T14:36:49.604167", "market_id": "0x2393ed0b0fdc450054c7b9071907eca75cf4fc36e385adf4a0a5f99ee62243e8", "raw": {"market": "0x2393ed0b0fdc450054c7b9071907eca75cf4fc36e385adf4a0a5f99ee62243e8", "asset_id": "32769749367306925959219403371425714180265458150646381231272229429098460625924", "price": "0.941", "size": "204", "side": "BUY", "timestamp": "1768574173289", "received_at": "2026-01-16T14:36:13.324096"}}
{"event_type": "price_change", "event_ts": "2026-01-16T14:36:14.240730", "ingestion_ts": "2026-01-16T14:36:49.604167", "market_id": "0xaf9d0e448129a9f657f851d49495ba4742055d80e0ef1166ba0ee81d4d594214", "raw": {"market": "0xaf9d0e448129a9f657f851d49495ba4742055d80e0ef1166ba0ee81d4d594214", "asset_id": "4153292802911610701832309484716814274802943278345248636922528170020319407796", "price": "0.978", "size": "0", "side": "SELL", "timestamp": "1768574174170", "received_at": "2026-01-16T14:36:14.240730"}}
{"event_type": "price_change", "event_ts": "2026-01-16T14:36:14.240730", "ingestion_ts": "2026-01-16T14:36:49.604167", "market_id": "0xaf9d0e448129a9f657f851d49495ba4742055d80e0ef1166ba0ee81d4d594214", "raw": {"market": "0xaf9d0e448129a9f657f851d49495ba4742055d80e0ef1166ba0ee81d4d594214", "asset_id": "101676997363687199724245607342877036148401850938023978421879460310389391082353", "price": "0.022", "size": "0", "side": "BUY", "timestamp": "1768574174170", "received_at": "2026-01-16T14:36:14.240730"}}
{"event_type": "price_change", "event_ts": "2026-01-16T14:36:14.240745", "ingestion_ts": "2026-01-16T14:36:49.604167", "market_id": "0x49686d26fb712515cd5e12c23f0a1c7e10214c7faa3cb0a730aabe0c33694082", "raw": {"market": "0x49686d26fb712515cd5e12c23f0a1c7e10214c7faa3cb0a730aabe0c33694082", "asset_id": "30442780799048074404860985387051749017905070253466005720364298335239299761065", "price": "0.008", "size": "5.94", "side": "BUY", "timestamp": "1768574174179", "received_at": "2026-01-16T14:36:14.240745"}}
{"event_type": "price_change", "event_ts": "2026-01-16T14:36:14.240745", "ingestion_ts": "2026-01-16T14:36:49.604167", "market_id": "0x49686d26fb712515cd5e12c23f0a1c7e10214c7faa3cb0a730aabe0c33694082", "raw": {"market": "0x49686d26fb712515cd5e12c23f0a1c7e10214c7faa3cb0a730aabe0c33694082", "asset_id": "13244681086321087932946246027856416106585284024824496763706748621681543444582", "price": "0.992", "size": "5.94", "side": "SELL", "timestamp": "1768574174179", "received_at": "2026-01-16T14:36:14.240745"}}
{"event_type": "price_change", "event_ts": "2026-01-16T14:36:14.240757", "ingestion_ts": "2026-01-16T14:36:49.604167", "market_id": "0x49686d26fb712515cd5e12c23f0a1c7e10214c7faa3cb0a730aabe0c33694082", "raw": {"market": "0x49686d26fb712515cd5e12c23f0a1c7e10214c7faa3cb0a730aabe0c33694082", "asset_id": "30442780799048074404860985387051749017905070253466005720364298335239299761065", "price": "0.012", "size": "0", "side": "BUY", "timestamp": "1768574174179", "received_at": "2026-01-16T14:36:14.240757"}}
{"event_type": "price_change", "event_ts": "2026-01-16T14:36:14.240757", "ingestion_ts": "2026-01-16T14:36:49.604167", "market_id": "0x49686d26fb712515cd5e12c23f0a1c7e10214c7faa3cb0a730aabe0c33694082", "raw": {"market": "0x49686d26fb712515cd5e12c23f0a1c7e10214c7faa3cb0a730aabe0c33694082", "asset_id": "13244681086321087932946246027856416106585284024824496763706748621681543444582", "price": "0.988", "size": "0", "side": "SELL", "timestamp": "1768574174179", "received_at": "2026-01-16T14:36:14.240757"}}
{"event_type": "price_change", "event_ts": "2026-01-16T14:36:14.412383", "ingestion_ts": "2026-01-16T14:36:49.604167", "market_id": "0xaf9d0e448129a9f657f851d49495ba4742055d80e0ef1166ba0ee81d4d594214", "raw": {"market": "0xaf9d0e448129a9f657f851d49495ba4742055d80e0ef1166ba0ee81d4d594214", "asset_id": "4153292802911610701832309484716814274802943278345248636922528170020319407796", "price": "0.989", "size": "20.5", "side": "SELL", "timestamp": "1768574174371", "received_at": "2026-01-16T14:36:14.412383"}}
{"event_type": "price_change", "event_ts": "2026-01-16T14:36:14.412383", "ingestion_ts": "2026-01-16T14:36:49.604167", "market_id": "0xaf9d0e448129a9f657f851d49495ba4742055d80e0ef1166ba0ee81d4d594214", "raw": {"market": "0xaf9d0e448129a9f657f851d49495ba4742055d80e0ef1166ba0ee81d4d594214", "asset_id": "101676997363687199724245607342877036148401850938023978421879460310389391082353", "price": "0.011", "size": "20.5", "side": "BUY", "timestamp": "1768574174371", "received_at": "2026-01-16T14:36:14.412383"}}
{"event_type": "price_change", "event_ts": "2026-01-16T14:36:14.658595", "ingestion_ts": "2026-01-16T14:36:49.604167", "market_id": "0x44f08744458b8896620cd3330bc5e1ea69df4199b02d4fc583b3fc96e5d314ce", "raw": {"market": "0x44f08744458b8896620cd3330bc5e1ea69df4199b02d4fc583b3fc96e5d314ce", "asset_id": "72327831507226612545928776794104143393438710920370371172884559893525100761096", "price": "0.854", "size": "0", "side": "BUY", "timestamp": "1768574174613", "received_at": "2026-01-16T14:36:14.658595"}}
{"event_type": "price_change", "event_ts": "2026-01-16T14:36:14.658595", "ingestion_ts": "2026-01-16T14:36:49.604167", "market_id": "0x44f08744458b8896620cd3330bc5e1ea69df4199b02d4fc583b3fc96e5d314ce", "raw": {"market": "0x44f08744458b8896620cd3330bc5e1ea69df4199b02d4fc583b3fc96e5d314ce", "asset_id": "49194009556504828848509244326501559253829462790583873936160989575507522044057", "price": "0.146", "size": "0", "side": "SELL", "timestamp": "1768574174613", "received_at": "2026-01-16T14:36:14.658595"}}
{"event_type": "price_change", "event_ts": "2026-01-16T14:36:14.658647", "ingestion_ts": "2026-01-16T14:36:49.604167", "market_id": "0x9472be65457510b7fc3477b20ba90910e99d92eac8421a14bf4b7b7a08ef31dc", "raw": {"market": "0x9472be65457510b7fc3477b20ba90910e99d92eac8421a14bf4b7b7a08ef31dc", "asset_id": "43311793366960417907757893276427136943959788721376762326430771171648759300146", "price": "0.856", "size": "0", "side": "BUY", "timestamp": "1768574174613", "received_at": "2026-01-16T14:36:14.658647"}}
{"event_type": "price_change", "event_ts": "2026-01-16T14:36:14.658647", "ingestion_ts": "2026-01-16T14:36:49.604167", "market_id": "0x9472be65457510b7fc3477b20ba90910e99d92eac8421a14bf4b7b7a08ef31dc", "raw": {"market": "0x9472be65457510b7fc3477b20ba90910e99d92eac8421a14bf4b7b7a08ef31dc", "asset_id": "73414222381656326204771753454630063673548497164758947581648273905027617570612", "price": "0.144", "size": "0", "side": "SELL", "timestamp": "1768574174613", "received_at": "2026-01-16T14:36:14.658647"}}
{"event_type": "price_change", "event_ts": "2026-01-16T14:36:14.658674", "ingestion_ts": "2026-01-16T14:36:49.604167", "market_id": "0x49a20c7523c271099008f3ef9a31521263b24d637959852a391e6b4697b1a437", "raw": {"market": "0x49a20c7523c271099008f3ef9a31521263b24d637959852a391e6b4697b1a437", "asset_id": "55881023621710858558280545117465775643848233756850602339827152783696837905531", "price": "0.856", "size": "30", "side": "BUY", "timestamp": "1768574174613", "received_at": "2026-01-16T14:36:14.658674"}}
{"event_type": "price_change", "event_ts": "2026-01-16T14:36:14.658674", "ingestion_ts": "2026-01-16T14:36:49.604167", "market_id": "0x49a20c7523c271099008f3ef9a31521263b24d637959852a391e6b4697b1a437", "raw": {"market": "0x49a20c7523c271099008f3ef9a31521263b24d637959852a391e6b4697b1a437", "asset_id": "13018971792603393862521629014128024641178044618205296260525674415067194037856", "price": "0.144", "size": "30", "side": "SELL", "timestamp": "1768574174613", "received_at": "2026-01-16T14:36:14.658674"}}
{"event_type": "price_change", "event_ts": "2026-01-16T14:36:14.658686", "ingestion_ts": "2026-01-16T14:36:49.604167", "market_id": "0x50c669f178da4e5bbea7f1be25041fd278914712fa87a6a6f8e57d5923d88dee", "raw": {"market": "0x50c669f178da4e5bbea7f1be25041fd278914712fa87a6a6f8e57d5923d88dee", "asset_id": "74040420326294854165772767082819937451857852955603897473157746262672057685461", "price": "0.856", "size": "0", "side": "BUY", "timestamp": "1768574174613", "received_at": "2026-01-16T14:36:14.658686"}}
{"event_type": "price_change", "event_ts": "2026-01-16T14:36:14.658686", "ingestion_ts": "2026-01-16T14:36:49.604167", "market_id": "0x50c669f178da4e5bbea7f1be25041fd278914712fa87a6a6f8e57d5923d88dee", "raw": {"market": "0x50c669f178da4e5bbea7f1be25041fd278914712fa87a6a6f8e57d5923d88dee", "asset_id": "24682525479474221428144937281315825971983904267399062415430320764754931667953", "price": "0.144", "size": "0", "side": "SELL", "timestamp": "1768574174613", "received_at": "2026-01-16T14:36:14.658686"}}
{"event_type": "price_change", "event_ts": "2026-01-16T14:36:14.658697", "ingestion_ts": "2026-01-16T14:36:49.604167", "market_id": "0x49686d26fb712515cd5e12c23f0a1c7e10214c7faa3cb0a730aabe0c33694082", "raw": {"market": "0x49686d26fb712515cd5e12c23f0a1c7e10214c7faa3cb0a730aabe0c33694082", "asset_id": "30442780799048074404860985387051749017905070253466005720364298335239299761065", "price": "0.006", "size": "10.08", "side": "BUY", "timestamp": "1768574174613", "received_at": "2026-01-16T14:36:14.658697"}}
{"event_type": "price_change", "event_ts": "2026-01-16T14:36:14.658697", "ingestion_ts": "2026-01-16T14:36:49.604167", "market_id": "0x49686d26fb712515cd5e12c23f0a1c7e10214c7faa3cb0a730aabe0c33694082", "raw": {"market": "0x49686d26fb712515cd5e12c23f0a1c7e10214c7faa3cb0a730aabe0c33694082", "asset_id": "13244681086321087932946246027856416106585284024824496763706748621681543444582", "price": "0.994", "size": "10.08", "side": "SELL", "timestamp": "1768574174613", "received_at": "2026-01-16T14:36:14.658697"}}
{"event_type": "price_change", "event_ts": "2026-01-16T14:36:14.658707", "ingestion_ts": "2026-01-16T14:36:49.604167", "market_id": "0xc55db914f0fd1fee18997706712c0dfd8d0369cdbef93a9fef12bd001914ca77", "raw": {"market": "0xc55db914f0fd1fee18997706712c0dfd8d0369cdbef93a9fef12bd001914ca77", "asset_id": "114600293444080540179603459515770723592661967180480327891296353898330242622833", "price": "0.858", "size": "0", "side": "BUY", "timestamp": "1768574174613", "received_at": "2026-01-16T14:36:14.658707"}}
{"event_type": "price_change", "event_ts": "2026-01-16T14:36:14.658707", "ingestion_ts": "2026-01-16T14:36:49.604167", "market_id": "0xc55db914f0fd1fee18997706712c0dfd8d0369cdbef93a9fef12bd001914ca77", "raw": {"market": "0xc55db914f0fd1fee18997706712c0dfd8d0369cdbef93a9fef12bd001914ca77", "asset_id": "72354723612769247426741660426331235762851940382312402276325808095604519806766", "price": "0.142", "size": "0", "side": "SELL", "timestamp": "1768574174613", "received_at": "2026-01-16T14:36:14.658707"}}
{"event_type": "price_change", "event_ts": "2026-01-16T14:36:14.689816", "ingestion_ts": "2026-01-16T14:36:49.604167", "market_id": "0x9472be65457510b7fc3477b20ba90910e99d92eac8421a14bf4b7b7a08ef31dc", "raw": {"market": "0x9472be65457510b7fc3477b20ba90910e99d92eac8421a14bf4b7b7a08ef31dc", "asset_id": "43311793366960417907757893276427136943959788721376762326430771171648759300146", "price": "0.824", "size": "10", "side": "BUY", "timestamp": "1768574174653", "received_at": "2026-01-16T14:36:14.689816"}}
{"event_type": "price_change", "event_ts": "2026-01-16T14:36:14.689816", "ingestion_ts": "2026-01-16T14:36:49.604167", "market_id": "0x9472be65457510b7fc3477b20ba90910e99d92eac8421a14bf4b7b7a08ef31dc", "raw": {"market": "0x9472be65457510b7fc3477b20ba90910e99d92eac8421a14bf4b7b7a08ef31dc", "asset_id": "73414222381656326204771753454630063673548497164758947581648273905027617570612", "price": "0.176", "size": "10", "side": "SELL", "timestamp": "1768574174653", "received_at": "2026-01-16T14:36:14.689816"}}
{"event_type": "price_change", "event_ts": "2026-01-16T14:36:14.689855", "ingestion_ts": "2026-01-16T14:36:49.604167", "market_id": "0x49a20c7523c271099008f3ef9a31521263b24d637959852a391e6b4697b1a437", "raw": {"market": "0x49a20c7523c271099008f3ef9a31521263b24d637959852a391e6b4697b1a437", "asset_id": "55881023621710858558280545117465775643848233756850602339827152783696837905531", "price": "0.847", "size": "10", "side": "BUY", "timestamp": "1768574174653", "received_at": "2026-01-16T14:36:14.689855"}}
{"event_type": "price_change", "event_ts": "2026-01-16T14:36:14.689855", "ingestion_ts": "2026-01-16T14:36:49.604167", "market_id": "0x49a20c7523c271099008f3ef9a31521263b24d637959852a391e6b4697b1a437", "raw": {"market": "0x49a20c7523c271099008f3ef9a31521263b24d637959852a391e6b4697b1a437", "asset_id": "13018971792603393862521629014128024641178044618205296260525674415067194037856", "price": "0.153", "size": "10", "side": "SELL", "timestamp": "1768574174653", "received_at": "2026-01-16T14:36:14.689855"}}
{"event_type": "price_change", "event_ts": "2026-01-16T14:36:14.689871", "ingestion_ts": "2026-01-16T14:36:49.604167", "market_id": "0x50c669f178da4e5bbea7f1be25041fd278914712fa87a6a6f8e57d5923d88dee", "raw": {"market": "0x50c669f178da4e5bbea7f1be25041fd278914712fa87a6a6f8e57d5923d88dee", "asset_id": "74040420326294854165772767082819937451857852955603897473157746262672057685461", "price": "0.825", "size": "10", "side": "BUY", "timestamp": "1768574174653", "received_at": "2026-01-16T14:36:14.689871"}}
{"event_type": "price_change", "event_ts": "2026-01-16T14:36:14.689871", "ingestion_ts": "2026-01-16T14:36:49.604167", "market_id": "0x50c669f178da4e5bbea7f1be25041fd278914712fa87a6a6f8e57d5923d88dee", "raw": {"market": "0x50c669f178da4e5bbea7f1be25041fd278914712fa87a6a6f8e57d5923d88dee", "asset_id": "24682525479474221428144937281315825971983904267399062415430320764754931667953", "price": "0.175", "size": "10", "side": "SELL", "timestamp": "1768574174653", "received_at": "2026-01-16T14:36:14.689871"}}
{"event_type": "price_change", "event_ts": "2026-01-16T14:36:14.689883", "ingestion_ts": "2026-01-16T14:36:49.604167", "market_id": "0xc55db914f0fd1fee18997706712c0dfd8d0369cdbef93a9fef12bd001914ca77", "raw": {"market": "0xc55db914f0fd1fee18997706712c0dfd8d0369cdbef93a9fef12bd001914ca77", "asset_id": "114600293444080540179603459515770723592661967180480327891296353898330242622833", "price": "0.837", "size": "10", "side": "BUY", "timestamp": "1768574174653", "received_at": "2026-01-16T14:36:14.689883"}}
{"event_type": "price_change", "event_ts": "2026-01-16T14:36:14.689883", "ingestion_ts": "2026-01-16T14:36:49.604167", "market_id": "0xc55db914f0fd1fee18997706712c0dfd8d0369cdbef93a9fef12bd001914ca77", "raw": {"market": "0xc55db914f0fd1fee18997706712c0dfd8d0369cdbef93a9fef12bd001914ca77", "asset_id": "72354723612769247426741660426331235762851940382312402276325808095604519806766", "price": "0.163", "size": "10", "side": "SELL", "timestamp": "1768574174653", "received_at": "2026-01-16T14:36:14.689883"}}
{"event_type": "price_change", "event_ts": "2026-01-16T14:36:14.689894", "ingestion_ts": "2026-01-16T14:36:49.604167", "market_id": "0x44f08744458b8896620cd3330bc5e1ea69df4199b02d4fc583b3fc96e5d314ce", "raw": {"market": "0x44f08744458b8896620cd3330bc5e1ea69df4199b02d4fc583b3fc96e5d314ce", "asset_id": "72327831507226612545928776794104143393438710920370371172884559893525100761096", "price": "0.831", "size": "10", "side": "BUY", "timestamp": "1768574174653", "received_at": "2026-01-16T14:36:14.689894"}}
{"event_type": "price_change", "event_ts": "2026-01-16T14:36:14.689894", "ingestion_ts": "2026-01-16T14:36:49.604167", "market_id": "0x44f08744458b8896620cd3330bc5e1ea69df4199b02d4fc583b3fc96e5d314ce", "raw": {"market": "0x44f08744458b8896620cd3330bc5e1ea69df4199b02d4fc583b3fc96e5d314ce", "asset_id": "49194009556504828848509244326501559253829462790583873936160989575507522044057", "price": "0.169", "size": "10", "side": "SELL", "timestamp": "1768574174653", "received_at": "2026-01-16T14:36:14.689894"}}
{"event_type": "price_change", "event_ts": "2026-01-16T14:36:14.689905", "ingestion_ts": "2026-01-16T14:36:49.604167", "market_id": "0x49686d26fb712515cd5e12c23f0a1c7e10214c7faa3cb0a730aabe0c33694082", "raw": {"market": "0x49686d26fb712515cd5e12c23f0a1c7e10214c7faa3cb0a730aabe0c33694082", "asset_id": "30442780799048074404860985387051749017905070253466005720364298335239299761065", "price": "0.002", "size": "672.74", "side": "BUY", "timestamp": "1768574174653", "received_at": "2026-01-16T14:36:14.689905"}}
{"event_type": "price_change", "event_ts": "2026-01-16T14:36:14.689905", "ingestion_ts": "2026-01-16T14:36:49.604167", "market_id": "0x49686d26fb712515cd5e12c23f0a1c7e10214c7faa3cb0a730aabe0c33694082", "raw": {"market": "0x49686d26fb712515cd5e12c23f0a1c7e10214c7faa3cb0a730aabe0c33694082", "asset_id": "13244681086321087932946246027856416106585284024824496763706748621681543444582", "price": "0.998", "size": "672.74", "side": "SELL", "timestamp": "1768574174653", "received_at": "2026-01-16T14:36:14.689905"}}
{"event_type": "price_change", "event_ts": "2026-01-16T14:36:14.720120", "ingestion_ts": "2026-01-16T14:36:49.604167", "market_id": "0x49686d26fb712515cd5e12c23f0a1c7e10214c7faa3cb0a730aabe0c33694082", "raw": {"market": "0x49686d26fb712515cd5e12c23f0a1c7e10214c7faa3cb0a730aabe0c33694082", "asset_id": "30442780799048074404860985387051749017905070253466005720364298335239299761065", "price": "0.009", "size": "13.18", "side": "BUY", "timestamp": "1768574174679", "received_at": "2026-01-16T14:36:14.720120"}}
{"event_type": "price_change", "event_ts": "2026-01-16T14:36:14.720120", "ingestion_ts": "2026-01-16T14:36:49.604167", "market_id": "0x49686d26fb712515cd5e12c23f0a1c7e10214c7faa3cb0a730aabe0c33694082", "raw": {"market": "0x49686d26fb712515cd5e12c23f0a1c7e10214c7faa3cb0a730aabe0c33694082", "asset_id": "13244681086321087932946246027856416106585284024824496763706748621681543444582", "price": "0.991", "size": "13.18", "side": "SELL", "timestamp": "1768574174679", "received_at": "2026-01-16T14:36:14.720120"}}
{"event_type": "price_change", "event_ts": "2026-01-16T14:36:14.721325", "ingestion_ts": "2026-01-16T14:36:49.604167", "market_id": "0x49686d26fb712515cd5e12c23f0a1c7e10214c7faa3cb0a730aabe0c33694082", "raw": {"market": "0x49686d26fb712515cd5e12c23f0a1c7e10214c7faa3cb0a730aabe0c33694082", "asset_id": "30442780799048074404860985387051749017905070253466005720364298335239299761065", "price": "0.013", "size": "8.44", "side": "BUY", "timestamp": "1768574174680", "received_at": "2026-01-16T14:36:14.721325"}}
{"event_type": "price_change", "event_ts": "2026-01-16T14:36:14.721325", "ingestion_ts": "2026-01-16T14:36:49.604167", "market_id": "0x49686d26fb712515cd5e12c23f0a1c7e10214c7faa3cb0a730aabe0c33694082", "raw": {"market": "0x49686d26fb712515cd5e12c23f0a1c7e10214c7faa3cb0a730aabe0c33694082", "asset_id": "13244681086321087932946246027856416106585284024824496763706748621681543444582", "price": "0.987", "size": "8.44", "side": "SELL", "timestamp": "1768574174680", "received_at": "2026-01-16T14:36:14.721325"}}
{"event_type": "price_change", "event_ts": "2026-01-16T14:36:15.312251", "ingestion_ts": "2026-01-16T14:36:49.604167", "market_id": "0xc0e6b917320a47228fb96e3b5ae0e5c93773a5ae2662ae4e1f37807cfe47ce98", "raw": {"market": "0xc0e6b917320a47228fb96e3b5ae0e5c93773a5ae2662ae4e1f37807cfe47ce98", "asset_id": "58656358377246279051017109359677190749228949103591068167284263961542487110215", "price": "0.002", "size": "3287.1", "side": "BUY", "timestamp": "1768574175275", "received_at": "2026-01-16T14:36:15.312251"}}
{"event_type": "price_change", "event_ts": "2026-01-16T14:36:15.312251", "ingestion_ts": "2026-01-16T14:36:49.604167", "market_id": "0xc0e6b917320a47228fb96e3b5ae0e5c93773a5ae2662ae4e1f37807cfe47ce98", "raw": {"market": "0xc0e6b917320a47228fb96e3b5ae0e5c93773a5ae2662ae4e1f37807cfe47ce98", "asset_id": "81647294538046680798858716589766492074338758116170717123345952330712416337530", "price": "0.998", "size": "3287.1", "side": "SELL", "timestamp": "1768574175275", "received_at": "2026-01-16T14:36:15.312251"}}
{"event_type": "price_change", "event_ts": "2026-01-16T14:36:16.469249", "ingestion_ts": "2026-01-16T14:36:49.604167", "market_id": "0xc0e6b917320a47228fb96e3b5ae0e5c93773a5ae2662ae4e1f37807cfe47ce98", "raw": {"market": "0xc0e6b917320a47228fb96e3b5ae0e5c93773a5ae2662ae4e1f37807cfe47ce98", "asset_id": "58656358377246279051017109359677190749228949103591068167284263961542487110215", "price": "0.002", "size": "3279.99", "side": "BUY", "timestamp": "1768574176389", "received_at": "2026-01-16T14:36:16.469249"}}
{"event_type": "price_change", "event_ts": "2026-01-16T14:36:16.469249", "ingestion_ts": "2026-01-16T14:36:49.604167", "market_id": "0xc0e6b917320a47228fb96e3b5ae0e5c93773a5ae2662ae4e1f37807cfe47ce98", "raw": {"market": "0xc0e6b917320a47228fb96e3b5ae0e5c93773a5ae2662ae4e1f37807cfe47ce98", "asset_id": "81647294538046680798858716589766492074338758116170717123345952330712416337530", "price": "0.998", "size": "3279.99", "side": "SELL", "timestamp": "1768574176389", "received_at": "2026-01-16T14:36:16.469249"}}
{"event_type": "price_change", "event_ts": "2026-01-16T14:36:16.884959", "ingestion_ts": "2026-01-16T14:36:49.604167", "market_id": "0xc0e6b917320a47228fb96e3b5ae0e5c93773a5ae2662ae4e1f37807cfe47ce98", "raw": {"market": "0xc0e6b917320a47228fb96e3b5ae0e5c93773a5ae2662ae4e1f37807cfe47ce98", "asset_id": "58656358377246279051017109359677190749228949103591068167284263961542487110215", "price": "0.002", "size": "3287.1", "side": "BUY", "timestamp": "1768574176834", "received_at": "2026-01-16T14:36:16.884959"}}
{"event_type": "price_change", "event_ts": "2026-01-16T14:36:16.884959", "ingestion_ts": "2026-01-16T14:36:49.604167", "market_id": "0xc0e6b917320a47228fb96e3b5ae0e5c93773a5ae2662ae4e1f37807cfe47ce98", "raw": {"market": "0xc0e6b917320a47228fb96e3b5ae0e5c93773a5ae2662ae4e1f37807cfe47ce98", "asset_id": "81647294538046680798858716589766492074338758116170717123345952330712416337530", "price": "0.998", "size": "3287.1", "side": "SELL", "timestamp": "1768574176834", "received_at": "2026-01-16T14:36:16.884959"}}
{"event_type": "price_change", "event_ts": "2026-01-16T14:36:16.885112", "ingestion_ts": "2026-01-16T14:36:49.604167", "market_id": "0xc0e6b917320a47228fb96e3b5ae0e5c93773a5ae2662ae4e1f37807cfe47ce98", "raw": {"market": "0xc0e6b917320a47228fb96e3b5ae0e5c93773a5ae2662ae4e1f37807cfe47ce98", "asset_id": "58656358377246279051017109359677190749228949103591068167284263961542487110215", "price": "0.002", "size": "3294.21", "side": "BUY", "timestamp": "1768574176838", "received_at": "2026-01-16T14:36:16.885112"}}
{"event_type": "price_change", "event_ts": "2026-01-16T14:36:16.885112", "ingestion_ts": "2026-01-16T14:36:49.604167", "market_id": "0xc0e6b917320a47228fb96e3b5ae0e5c93773a5ae2662ae4e1f37807cfe47ce98", "raw": {"market": "0xc0e6b917320a47228fb96e3b5ae0e5c93773a5ae2662ae4e1f37807cfe47ce98", "asset_id": "81647294538046680798858716589766492074338758116170717123345952330712416337530", "price": "0.998", "size": "3294.21", "side": "SELL", "timestamp": "1768574176838", "received_at": "2026-01-16T14:36:16.885112"}}
{"event_type": "price_change", "event_ts": "2026-01-16T14:36:17.606823", "ingestion_ts": "2026-01-16T14:36:49.604167", "market_id": "0x49686d26fb712515cd5e12c23f0a1c7e10214c7faa3cb0a730aabe0c33694082", "raw": {"market": "0x49686d26fb712515cd5e12c23f0a1c7e10214c7faa3cb0a730aabe0c33694082", "asset_id": "13244681086321087932946246027856416106585284024824496763706748621681543444582", "price": "0.853", "size": "50.86", "side": "BUY", "timestamp": "1768574177564", "received_at": "2026-01-16T14:36:17.606823"}}
{"event_type": "price_change", "event_ts": "2026-01-16T14:36:17.606823", "ingestion_ts": "2026-01-16T14:36:49.604167", "market_id": "0x49686d26fb712515cd5e12c23f0a1c7e10214c7faa3cb0a730aabe0c33694082", "raw": {"market": "0x49686d26fb712515cd5e12c23f0a1c7e10214c7faa3cb0a730aabe0c33694082", "asset_id": "30442780799048074404860985387051749017905070253466005720364298335239299761065", "price": "0.147", "size": "50.86", "side": "SELL", "timestamp": "1768574177564", "received_at": "2026-01-16T14:36:17.606823"}}
{"event_type": "price_change", "event_ts": "2026-01-16T14:36:18.805386", "ingestion_ts": "2026-01-16T14:36:49.604167", "market_id": "0x49686d26fb712515cd5e12c23f0a1c7e10214c7faa3cb0a730aabe0c33694082", "raw": {"market": "0x49686d26fb712515cd5e12c23f0a1c7e10214c7faa3cb0a730aabe0c33694082", "asset_id": "30442780799048074404860985387051749017905070253466005720364298335239299761065", "price": "0.009", "size": "0", "side": "BUY", "timestamp": "1768574178746", "received_at": "2026-01-16T14:36:18.805386"}}
{"event_type": "price_change", "event_ts": "2026-01-16T14:36:18.805386", "ingestion_ts": "2026-01-16T14:36:49.604167", "market_id": "0x49686d26fb712515cd5e12c23f0a1c7e10214c7faa3cb0a730aabe0c33694082", "raw": {"market": "0x49686d26fb712515cd5e12c23f0a1c7e10214c7faa3cb0a730aabe0c33694082", "asset_id": "13244681086321087932946246027856416106585284024824496763706748621681543444582", "price": "0.991", "size": "0", "side": "SELL", "timestamp": "1768574178746", "received_at": "2026-01-16T14:36:18.805386"}}
{"event_type": "price_change", "event_ts": "2026-01-16T14:36:18.805427", "ingestion_ts": "2026-01-16T14:36:49.604167", "market_id": "0x49686d26fb712515cd5e12c23f0a1c7e10214c7faa3cb0a730aabe0c33694082", "raw": {"market": "0x49686d26fb712515cd5e12c23f0a1c7e10214c7faa3cb0a730aabe0c33694082", "asset_id": "30442780799048074404860985387051749017905070253466005720364298335239299761065", "price": "0.013", "size": "0", "side": "BUY", "timestamp": "1768574178746", "received_at": "2026-01-16T14:36:18.805427"}}
{"event_type": "price_change", "event_ts": "2026-01-16T14:36:18.805427", "ingestion_ts": "2026-01-16T14:36:49.604167", "market_id": "0x49686d26fb712515cd5e12c23f0a1c7e10214c7faa3cb0a730aabe0c33694082", "raw": {"market": "0x49686d26fb712515cd5e12c23f0a1c7e10214c7faa3cb0a730aabe0c33694082", "asset_id": "13244681086321087932946246027856416106585284024824496763706748621681543444582", "price": "0.987", "size": "0", "side": "SELL", "timestamp": "1768574178746", "received_at": "2026-01-16T14:36:18.805427"}}
{"event_type": "price_change", "event_ts": "2026-01-16T14:36:18.970320", "ingestion_ts": "2026-01-16T14:36:49.604167", "market_id": "0xaf9d0e448129a9f657f851d49495ba4742055d80e0ef1166ba0ee81d4d594214", "raw": {"market": "0xaf9d0e448129a9f657f851d49495ba4742055d80e0ef1166ba0ee81d4d594214", "asset_id": "4153292802911610701832309484716814274802943278345248636922528170020319407796", "price": "0.981", "size": "140.01", "side": "SELL", "timestamp": "1768574178932", "received_at": "2026-01-16T14:36:18.970320"}}
{"event_type": "price_change", "event_ts": "2026-01-16T14:36:18.970320", "ingestion_ts": "2026-01-16T14:36:49.604167", "market_id": "0xaf9d0e448129a9f657f851d49495ba4742055d80e0ef1166ba0ee81d4d594214", "raw": {"market": "0xaf9d0e448129a9f657f851d49495ba4742055d80e0ef1166ba0ee81d4d594214", "asset_id": "101676997363687199724245607342877036148401850938023978421879460310389391082353", "price": "0.019", "size": "140.01", "side": "BUY", "timestamp": "1768574178932", "received_at": "2026-01-16T14:36:18.970320"}}
{"event_type": "price_change", "event_ts": "2026-01-16T14:36:19.120472", "ingestion_ts": "2026-01-16T14:36:49.604167", "market_id": "0x49686d26fb712515cd5e12c23f0a1c7e10214c7faa3cb0a730aabe0c33694082", "raw": {"market": "0x49686d26fb712515cd5e12c23f0a1c7e10214c7faa3cb0a730aabe0c33694082", "asset_id": "30442780799048074404860985387051749017905070253466005720364298335239299761065", "price": "0.148", "size": "0", "side": "SELL", "timestamp": "1768574179073", "received_at": "2026-01-16T14:36:19.120472"}}
{"event_type": "price_change", "event_ts": "2026-01-16T14:36:19.120472", "ingestion_ts": "2026-01-16T14:36:49.604167", "market_id": "0x49686d26fb712515cd5e12c23f0a1c7e10214c7faa3cb0a730aabe0c33694082", "raw": {"market": "0x49686d26fb712515cd5e12c23f0a1c7e10214c7faa3cb0a730aabe0c33694082", "asset_id": "13244681086321087932946246027856416106585284024824496763706748621681543444582", "price": "0.852", "size": "0", "side": "BUY", "timestamp": "1768574179073", "received_at": "2026-01-16T14:36:19.120472"}}
{"event_type": "price_change", "event_ts": "2026-01-16T14:36:19.149371", "ingestion_ts": "2026-01-16T14:36:49.604167", "market_id": "0x49686d26fb712515cd5e12c23f0a1c7e10214c7faa3cb0a730aabe0c33694082", "raw": {"market": "0x49686d26fb712515cd5e12c23f0a1c7e10214c7faa3cb0a730aabe0c33694082", "asset_id": "30442780799048074404860985387051749017905070253466005720364298335239299761065", "price": "0.011", "size": "20.77", "side": "BUY", "timestamp": "1768574179104", "received_at": "2026-01-16T14:36:19.149371"}}
{"event_type": "price_change", "event_ts": "2026-01-16T14:36:19.149371", "ingestion_ts": "2026-01-16T14:36:49.604167", "market_id": "0x49686d26fb712515cd5e12c23f0a1c7e10214c7faa3cb0a730aabe0c33694082", "raw": {"market": "0x49686d26fb712515cd5e12c23f0a1c7e10214c7faa3cb0a730aabe0c33694082", "asset_id": "13244681086321087932946246027856416106585284024824496763706748621681543444582", "price": "0.989", "size": "20.77", "side": "SELL", "timestamp": "1768574179104", "received_at": "2026-01-16T14:36:19.149371"}}
{"event_type": "price_change", "event_ts": "2026-01-16T14:36:19.288992", "ingestion_ts": "2026-01-16T14:36:49.604167", "market_id": "0x49686d26fb712515cd5e12c23f0a1c7e10214c7faa3cb0a730aabe0c33694082", "raw": {"market": "0x49686d26fb712515cd5e12c23f0a1c7e10214c7faa3cb0a730aabe0c33694082", "asset_id": "30442780799048074404860985387051749017905070253466005720364298335239299761065", "price": "0.146", "size": "17.5", "side": "SELL", "timestamp": "1768574179217", "received_at": "2026-01-16T14:36:19.288992"}}
{"event_type": "price_change", "event_ts": "2026-01-16T14:36:19.288992", "ingestion_ts": "2026-01-16T14:36:49.604167", "market_id": "0x49686d26fb712515cd5e12c23f0a1c7e10214c7faa3cb0a730aabe0c33694082", "raw": {"market": "0x49686d26fb712515cd5e12c23f0a1c7e10214c7faa3cb0a730aabe0c33694082", "asset_id": "13244681086321087932946246027856416106585284024824496763706748621681543444582", "price": "0.854", "size": "17.5", "side": "BUY", "timestamp": "1768574179217", "received_at": "2026-01-16T14:36:19.288992"}}
{"event_type": "price_change", "event_ts": "2026-01-16T14:36:19.325033", "ingestion_ts": "2026-01-16T14:36:49.604167", "market_id": "0x49686d26fb712515cd5e12c23f0a1c7e10214c7faa3cb0a730aabe0c33694082", "raw": {"market": "0x49686d26fb712515cd5e12c23f0a1c7e10214c7faa3cb0a730aabe0c33694082", "asset_id": "13244681086321087932946246027856416106585284024824496763706748621681543444582", "price": "0.911", "size": "14.98", "side": "SELL", "timestamp": "1768574179267", "received_at": "2026-01-16T14:36:19.325033"}}
{"event_type": "price_change", "event_ts": "2026-01-16T14:36:19.325033", "ingestion_ts": "2026-01-16T14:36:49.604167", "market_id": "0x49686d26fb712515cd5e12c23f0a1c7e10214c7faa3cb0a730aabe0c33694082", "raw": {"market": "0x49686d26fb712515cd5e12c23f0a1c7e10214c7faa3cb0a730aabe0c33694082", "asset_id": "30442780799048074404860985387051749017905070253466005720364298335239299761065", "price": "0.089", "size": "14.98", "side": "BUY", "timestamp": "1768574179267", "received_at": "2026-01-16T14:36:19.325033"}}
{"event_type": "price_change", "event_ts": "2026-01-16T14:36:19.708064", "ingestion_ts": "2026-01-16T14:36:49.604167", "market_id": "0xc0e6b917320a47228fb96e3b5ae0e5c93773a5ae2662ae4e1f37807cfe47ce98", "raw": {"market": "0xc0e6b917320a47228fb96e3b5ae0e5c93773a5ae2662ae4e1f37807cfe47ce98", "asset_id": "58656358377246279051017109359677190749228949103591068167284263961542487110215", "price": "0.002", "size": "3287.1", "side": "BUY", "timestamp": "1768574179637", "received_at": "2026-01-16T14:36:19.708064"}}
{"event_type": "price_change", "event_ts": "2026-01-16T14:36:19.708064", "ingestion_ts": "2026-01-16T14:36:49.604167", "market_id": "0xc0e6b917320a47228fb96e3b5ae0e5c93773a5ae2662ae4e1f37807cfe47ce98", "raw": {"market": "0xc0e6b917320a47228fb96e3b5ae0e5c93773a5ae2662ae4e1f37807cfe47ce98", "asset_id": "81647294538046680798858716589766492074338758116170717123345952330712416337530", "price": "0.998", "size": "3287.1", "side": "SELL", "timestamp": "1768574179637", "received_at": "2026-01-16T14:36:19.708064"}}
{"event_type": "price_change", "event_ts": "2026-01-16T14:36:19.837719", "ingestion_ts": "2026-01-16T14:36:49.604167", "market_id": "0x2393ed0b0fdc450054c7b9071907eca75cf4fc36e385adf4a0a5f99ee62243e8", "raw": {"market": "0x2393ed0b0fdc450054c7b9071907eca75cf4fc36e385adf4a0a5f99ee62243e8", "asset_id": "32769749367306925959219403371425714180265458150646381231272229429098460625924", "price": "0.94", "size": "0", "side": "BUY", "timestamp": "1768574179766", "received_at": "2026-01-16T14:36:19.837719"}}
