{"event_type": "price_change", "event_ts": "2026-01-16T14:36:19.837719", "ingestion_ts": "2026-01-16T14:36:49.604167", "market_id": "0x2393ed0b0fdc450054c7b9071907eca75cf4fc36e385adf4a0a5f99ee62243e8", "raw": {"market": "0x2393ed0b0fdc450054c7b9071907eca75cf4fc36e385adf4a0a5f99ee62243e8", "asset_id": "100074770378634056601572485653252702850363676459996771990439989989293515601975", "price": "0.06", "size": "0", "side": "SELL", "timestamp": "1768574179766", "received_at": "2026-01-16T14:36:19.837719"}}
{"event_type": "price_change", "event_ts": "2026-01-16T14:36:20.213316", "ingestion_ts": "2026-01-16T14:36:49.604167", "market_id": "0xaf9d0e448129a9f657f851d49495ba4742055d80e0ef1166ba0ee81d4d594214", "raw": {"market": "0xaf9d0e448129a9f657f851d49495ba4742055d80e0ef1166ba0ee81d4d594214", "asset_id": "4153292802911610701832309484716814274802943278345248636922528170020319407796", "price": "0.989", "size": "0", "side": "SELL", "timestamp": "1768574180176", "received_at": "2026-01-16T14:36:20.213316"}}
{"event_type": "price_change", "event_ts": "2026-01-16T14:36:20.213316", "ingestion_ts": "2026-01-16T14:36:49.604167", "market_id": "0xaf9d0e448129a9f657f851d49495ba4742055d80e0ef1166ba0ee81d4d594214", "raw": {"market": "0xaf9d0e448129a9f657f851d49495ba4742055d80e0ef1166ba0ee81d4d594214", "asset_id": "101676997363687199724245607342877036148401850938023978421879460310389391082353", "price": "0.011", "size": "0", "side": "BUY", "timestamp": "1768574180176", "received_at": "2026-01-16T14:36:20.213316"}}
{"event_type": "price_change", "event_ts": "2026-01-16T14:36:20.326225", "ingestion_ts": "2026-01-16T14:36:49.604167", "market_id": "0x49686d26fb712515cd5e12c23f0a1c7e10214c7faa3cb0a730aabe0c33694082", "raw": {"market": "0x49686d26fb712515cd5e12c23f0a1c7e10214c7faa3cb0a730aabe0c33694082", "asset_id": "30442780799048074404860985387051749017905070253466005720364298335239299761065", "price": "0.002", "size": "662.74", "side": "BUY", "timestamp": "1768574180290", "received_at": "2026-01-16T14:36:20.326225"}}
{"event_type": "price_change", "event_ts": "2026-01-16T14:36:20.326225", "ingestion_ts": "2026-01-16T14:36:49.604167", "market_id": "0x49686d26fb712515cd5e12c23f0a1c7e10214c7faa3cb0a730aabe0c33694082", "raw": {"market": "0x49686d26fb712515cd5e12c23f0a1c7e10214c7faa3cb0a730aabe0c33694082", "asset_id": "13244681086321087932946246027856416106585284024824496763706748621681543444582", "price": "0.998", "size": "662.74", "side": "SELL", "timestamp": "1768574180290", "received_at": "2026-01-16T14:36:20.326225"}}
{"event_type": "price_change", "event_ts": "2026-01-16T14:36:20.326266", "ingestion_ts": "2026-01-16T14:36:49.604167", "market_id": "0xc55db914f0fd1fee18997706712c0dfd8d0369cdbef93a9fef12bd001914ca77", "raw": {"market": "0xc55db914f0fd1fee18997706712c0dfd8d0369cdbef93a9fef12bd001914ca77", "asset_id": "114600293444080540179603459515770723592661967180480327891296353898330242622833", "price": "0.837", "size": "0", "side": "BUY", "timestamp": "1768574180290", "received_at": "2026-01-16T14:36:20.326266"}}
{"event_type": "price_change", "event_ts": "2026-01-16T14:36:20.326266", "ingestion_ts": "2026-01-16T14:36:49.604167", "market_id": "0xc55db914f0fd1fee18997706712c0dfd8d0369cdbef93a9fef12bd001914ca77", "raw": {"market": "0xc55db914f0fd1fee18997706712c0dfd8d0369cdbef93a9fef12bd001914ca77", "asset_id": "72354723612769247426741660426331235762851940382312402276325808095604519806766", "price": "0.163", "size": "0", "side": "SELL", "timestamp": "1768574180290", "received_at": "2026-01-16T14:36:20.326266"}}
{"event_type": "price_change", "event_ts": "2026-01-16T14:36:20.327133", "ingestion_ts": "2026-01-16T14:36:49.604167", "market_id": "0x9472be65457510b7fc3477b20ba90910e99d92eac8421a14bf4b7b7a08ef31dc", "raw": {"market": "0x9472be65457510b7fc3477b20ba90910e99d92eac8421a14bf4b7b7a08ef31dc", "asset_id": "43311793366960417907757893276427136943959788721376762326430771171648759300146", "price": "0.824", "size": "0", "side": "BUY", "timestamp": "1768574180290", "received_at": "2026-01-16T14:36:20.327133"}}
{"event_type": "price_change", "event_ts": "2026-01-16T14:36:20.327133", "ingestion_ts": "2026-01-16T14:36:49.604167", "market_id": "0x9472be65457510b7fc3477b20ba90910e99d92eac8421a14bf4b7b7a08ef31dc", "raw": {"market": "0x9472be65457510b7fc3477b20ba90910e99d92eac8421a14bf4b7b7a08ef31dc", "asset_id": "73414222381656326204771753454630063673548497164758947581648273905027617570612", "price": "0.176", "size": "0", "side": "SELL", "timestamp": "1768574180290", "received_at": "2026-01-16T14:36:20.327133"}}
{"event_type": "price_change", "event_ts": "2026-01-16T14:36:20.360069", "ingestion_ts": "2026-01-16T14:36:49.604167", "market_id": "0x49686d26fb712515cd5e12c23f0a1c7e10214c7faa3cb0a730aabe0c33694082", "raw": {"market": "0x49686d26fb712515cd5e12c23f0a1c7e10214c7faa3cb0a730aabe0c33694082", "asset_id": "30442780799048074404860985387051749017905070253466005720364298335239299761065", "price": "0.003", "size": "36.81", "side": "BUY", "timestamp": "1768574180322", "received_at": "2026-01-16T14:36:20.360069"}}
{"event_type": "price_change", "event_ts": "2026-01-16T14:36:20.360069", "ingestion_ts": "2026-01-16T14:36:49.604167", "market_id": "0x49686d26fb712515cd5e12c23f0a1c7e10214c7faa3cb0a730aabe0c33694082", "raw": {"market": "0x49686d26fb712515cd5e12c23f0a1c7e10214c7faa3cb0a730aabe0c33694082", "asset_id": "13244681086321087932946246027856416106585284024824496763706748621681543444582", "price": "0.997", "size": "36.81", "side": "SELL", "timestamp": "1768574180322", "received_at": "2026-01-16T14:36:20.360069"}}
{"event_type": "price_change", "event_ts": "2026-01-16T14:36:20.361875", "ingestion_ts": "2026-01-16T14:36:49.604167", "market_id": "0x9472be65457510b7fc3477b20ba90910e99d92eac8421a14bf4b7b7a08ef31dc", "raw": {"market": "0x9472be65457510b7fc3477b20ba90910e99d92eac8421a14bf4b7b7a08ef31dc", "asset_id": "43311793366960417907757893276427136943959788721376762326430771171648759300146", "price": "0.855", "size": "302", "side": "BUY", "timestamp": "1768574180322", "received_at": "2026-01-16T14:36:20.361875"}}
{"event_type": "price_change", "event_ts": "2026-01-16T14:36:20.361875", "ingestion_ts": "2026-01-16T14:36:49.604167", "market_id": "0x9472be65457510b7fc3477b20ba90910e99d92eac8421a14bf4b7b7a08ef31dc", "raw": {"market": "0x9472be65457510b7fc3477b20ba90910e99d92eac8421a14bf4b7b7a08ef31dc", "asset_id": "73414222381656326204771753454630063673548497164758947581648273905027617570612", "price": "0.145", "size": "302", "side": "SELL", "timestamp": "1768574180322", "received_at": "2026-01-16T14:36:20.361875"}}
{"event_type": "price_change", "event_ts": "2026-01-16T14:36:20.361898", "ingestion_ts": "2026-01-16T14:36:49.604167", "market_id": "0xc55db914f0fd1fee18997706712c0dfd8d0369cdbef93a9fef12bd001914ca77", "raw": {"market": "0xc55db914f0fd1fee18997706712c0dfd8d0369cdbef93a9fef12bd001914ca77", "asset_id": "114600293444080540179603459515770723592661967180480327891296353898330242622833", "price": "0.856", "size": "10", "side": "BUY", "timestamp": "1768574180322", "received_at": "2026-01-16T14:36:20.361898"}}
{"event_type": "price_change", "event_ts": "2026-01-16T14:36:20.361898", "ingestion_ts": "2026-01-16T14:36:49.604167", "market_id": "0xc55db914f0fd1fee18997706712c0dfd8d0369cdbef93a9fef12bd001914ca77", "raw": {"market": "0xc55db914f0fd1fee18997706712c0dfd8d0369cdbef93a9fef12bd001914ca77", "asset_id": "72354723612769247426741660426331235762851940382312402276325808095604519806766", "price": "0.144", "size": "10", "side": "SELL", "timestamp": "1768574180322", "received_at": "2026-01-16T14:36:20.361898"}}
{"event_type": "price_change", "event_ts": "2026-01-16T14:36:20.437643", "ingestion_ts": "2026-01-16T14:36:49.604167", "market_id": "0xaf9d0e448129a9f657f851d49495ba4742055d80e0ef1166ba0ee81d4d594214", "raw": {"market": "0xaf9d0e448129a9f657f851d49495ba4742055d80e0ef1166ba0ee81d4d594214", "asset_id": "4153292802911610701832309484716814274802943278345248636922528170020319407796", "price": "0.98", "size": "20.5", "side": "SELL", "timestamp": "1768574180366", "received_at": "2026-01-16T14:36:20.437643"}}
{"event_type": "price_change", "event_ts": "2026-01-16T14:36:20.437643", "ingestion_ts": "2026-01-16T14:36:49.604167", "market_id": "0xaf9d0e448129a9f657f851d49495ba4742055d80e0ef1166ba0ee81d4d594214", "raw": {"market": "0xaf9d0e448129a9f657f851d49495ba4742055d80e0ef1166ba0ee81d4d594214", "asset_id": "101676997363687199724245607342877036148401850938023978421879460310389391082353", "price": "0.02", "size": "20.5", "side": "BUY", "timestamp": "1768574180366", "received_at": "2026-01-16T14:36:20.437643"}}
{"event_type": "price_change", "event_ts": "2026-01-16T14:36:20.590680", "ingestion_ts": "2026-01-16T14:36:49.604167", "market_id": "0xc0e6b917320a47228fb96e3b5ae0e5c93773a5ae2662ae4e1f37807cfe47ce98", "raw": {"market": "0xc0e6b917320a47228fb96e3b5ae0e5c93773a5ae2662ae4e1f37807cfe47ce98", "asset_id": "58656358377246279051017109359677190749228949103591068167284263961542487110215", "price": "0.002", "size": "3279.99", "side": "BUY", "timestamp": "1768574180524", "received_at": "2026-01-16T14:36:20.590680"}}
{"event_type": "price_change", "event_ts": "2026-01-16T14:36:20.590680", "ingestion_ts": "2026-01-16T14:36:49.604167", "market_id": "0xc0e6b917320a47228fb96e3b5ae0e5c93773a5ae2662ae4e1f37807cfe47ce98", "raw": {"market": "0xc0e6b917320a47228fb96e3b5ae0e5c93773a5ae2662ae4e1f37807cfe47ce98", "asset_id": "81647294538046680798858716589766492074338758116170717123345952330712416337530", "price": "0.998", "size": "3279.99", "side": "SELL", "timestamp": "1768574180524", "received_at": "2026-01-16T14:36:20.590680"}}
{"event_type": "price_change", "event_ts": "2026-01-16T14:36:21.059587", "ingestion_ts": "2026-01-16T14:36:49.604167", "market_id": "0xc0e6b917320a47228fb96e3b5ae0e5c93773a5ae2662ae4e1f37807cfe47ce98", "raw": {"market": "0xc0e6b917320a47228fb96e3b5ae0e5c93773a5ae2662ae4e1f37807cfe47ce98", "asset_id": "58656358377246279051017109359677190749228949103591068167284263961542487110215", "price": "0.002", "size": "3287.1", "side": "BUY", "timestamp": "1768574180953", "received_at": "2026-01-16T14:36:21.059587"}}
{"event_type": "price_change", "event_ts": "2026-01-16T14:36:21.059587", "ingestion_ts": "2026-01-16T14:36:49.604167", "market_id": "0xc0e6b917320a47228fb96e3b5ae0e5c93773a5ae2662ae4e1f37807cfe47ce98", "raw": {"market": "0xc0e6b917320a47228fb96e3b5ae0e5c93773a5ae2662ae4e1f37807cfe47ce98", "asset_id": "81647294538046680798858716589766492074338758116170717123345952330712416337530", "price": "0.998", "size": "3287.1", "side": "SELL", "timestamp": "1768574180953", "received_at": "2026-01-16T14:36:21.059587"}}
{"event_type": "price_change", "event_ts": "2026-01-16T14:36:21.059626", "ingestion_ts": "2026-01-16T14:36:49.604167", "market_id": "0xc0e6b917320a47228fb96e3b5ae0e5c93773a5ae2662ae4e1f37807cfe47ce98", "raw": {"market": "0xc0e6b917320a47228fb96e3b5ae0e5c93773a5ae2662ae4e1f37807cfe47ce98", "asset_id": "58656358377246279051017109359677190749228949103591068167284263961542487110215", "price": "0.002", "size": "3294.21", "side": "BUY", "timestamp": "1768574180954", "received_at": "2026-01-16T14:36:21.059626"}}
{"event_type": "price_change", "event_ts": "2026-01-16T14:36:21.059626", "ingestion_ts": "2026-01-16T14:36:49.604167", "market_id": "0xc0e6b917320a47228fb96e3b5ae0e5c93773a5ae2662ae4e1f37807cfe47ce98", "raw": {"market": "0xc0e6b917320a47228fb96e3b5ae0e5c93773a5ae2662ae4e1f37807cfe47ce98", "asset_id": "81647294538046680798858716589766492074338758116170717123345952330712416337530", "price": "0.998", "size": "3294.21", "side": "SELL", "timestamp": "1768574180954", "received_at": "2026-01-16T14:36:21.059626"}}
{"event_type": "price_change", "event_ts": "2026-01-16T14:36:21.113777", "ingestion_ts": "2026-01-16T14:36:49.604167", "market_id": "0xc55db914f0fd1fee18997706712c0dfd8d0369cdbef93a9fef12bd001914ca77", "raw": {"market": "0xc55db914f0fd1fee18997706712c0dfd8d0369cdbef93a9fef12bd001914ca77", "asset_id": "114600293444080540179603459515770723592661967180480327891296353898330242622833", "price": "0.856", "size": "0", "side": "BUY", "timestamp": "1768574181023", "received_at": "2026-01-16T14:36:21.113777"}}
{"event_type": "price_change", "event_ts": "2026-01-16T14:36:21.113777", "ingestion_ts": "2026-01-16T14:36:49.604167", "market_id": "0xc55db914f0fd1fee18997706712c0dfd8d0369cdbef93a9fef12bd001914ca77", "raw": {"market": "0xc55db914f0fd1fee18997706712c0dfd8d0369cdbef93a9fef12bd001914ca77", "asset_id": "72354723612769247426741660426331235762851940382312402276325808095604519806766", "price": "0.144", "size": "0", "side": "SELL", "timestamp": "1768574181023", "received_at": "2026-01-16T14:36:21.113777"}}
{"event_type": "price_change", "event_ts": "2026-01-16T14:36:21.113817", "ingestion_ts": "2026-01-16T14:36:49.604167", "market_id": "0x49686d26fb712515cd5e12c23f0a1c7e10214c7faa3cb0a730aabe0c33694082", "raw": {"market": "0x49686d26fb712515cd5e12c23f0a1c7e10214c7faa3cb0a730aabe0c33694082", "asset_id": "30442780799048074404860985387051749017905070253466005720364298335239299761065", "price": "0.003", "size": "26.81", "side": "BUY", "timestamp": "1768574181023", "received_at": "2026-01-16T14:36:21.113817"}}
{"event_type": "price_change", "event_ts": "2026-01-16T14:36:21.113817", "ingestion_ts": "2026-01-16T14:36:49.604167", "market_id": "0x49686d26fb712515cd5e12c23f0a1c7e10214c7faa3cb0a730aabe0c33694082", "raw": {"market": "0x49686d26fb712515cd5e12c23f0a1c7e10214c7faa3cb0a730aabe0c33694082", "asset_id": "13244681086321087932946246027856416106585284024824496763706748621681543444582", "price": "0.997", "size": "26.81", "side": "SELL", "timestamp": "1768574181023", "received_at": "2026-01-16T14:36:21.113817"}}
{"event_type": "price_change", "event_ts": "2026-01-16T14:36:21.113898", "ingestion_ts": "2026-01-16T14:36:49.604167", "market_id": "0x49a20c7523c271099008f3ef9a31521263b24d637959852a391e6b4697b1a437", "raw": {"market": "0x49a20c7523c271099008f3ef9a31521263b24d637959852a391e6b4697b1a437", "asset_id": "55881023621710858558280545117465775643848233756850602339827152783696837905531", "price": "0.847", "size": "0", "side": "BUY", "timestamp": "1768574181023", "received_at": "2026-01-16T14:36:21.113898"}}
{"event_type": "price_change", "event_ts": "2026-01-16T14:36:21.113898", "ingestion_ts": "2026-01-16T14:36:49.604167", "market_id": "0x49a20c7523c271099008f3ef9a31521263b24d637959852a391e6b4697b1a437", "raw": {"market": "0x49a20c7523c271099008f3ef9a31521263b24d637959852a391e6b4697b1a437", "asset_id": "13018971792603393862521629014128024641178044618205296260525674415067194037856", "price": "0.153", "size": "0", "side": "SELL", "timestamp": "1768574181023", "received_at": "2026-01-16T14:36:21.113898"}}
{"event_type": "price_change", "event_ts": "2026-01-16T14:36:21.113913", "ingestion_ts": "2026-01-16T14:36:49.604167", "market_id": "0x50c669f178da4e5bbea7f1be25041fd278914712fa87a6a6f8e57d5923d88dee", "raw": {"market": "0x50c669f178da4e5bbea7f1be25041fd278914712fa87a6a6f8e57d5923d88dee", "asset_id": "74040420326294854165772767082819937451857852955603897473157746262672057685461", "price": "0.825", "size": "0", "side": "BUY", "timestamp": "1768574181023", "received_at": "2026-01-16T14:36:21.113913"}}
{"event_type": "price_change", "event_ts": "2026-01-16T14:36:21.113913", "ingestion_ts": "2026-01-16T14:36:49.604167", "market_id": "0x50c669f178da4e5bbea7f1be25041fd278914712fa87a6a6f8e57d5923d88dee", "raw": {"market": "0x50c669f178da4e5bbea7f1be25041fd278914712fa87a6a6f8e57d5923d88dee", "asset_id": "24682525479474221428144937281315825971983904267399062415430320764754931667953", "price": "0.175", "size": "0", "side": "SELL", "timestamp": "1768574181023", "received_at": "2026-01-16T14:36:21.113913"}}
{"event_type": "price_change", "event_ts": "2026-01-16T14:36:21.113925", "ingestion_ts": "2026-01-16T14:36:49.604167", "market_id": "0x9472be65457510b7fc3477b20ba90910e99d92eac8421a14bf4b7b7a08ef31dc", "raw": {"market": "0x9472be65457510b7fc3477b20ba90910e99d92eac8421a14bf4b7b7a08ef31dc", "asset_id": "43311793366960417907757893276427136943959788721376762326430771171648759300146", "price": "0.855", "size": "292", "side": "BUY", "timestamp": "1768574181023", "received_at": "2026-01-16T14:36:21.113925"}}
{"event_type": "price_change", "event_ts": "2026-01-16T14:36:21.113925", "ingestion_ts": "2026-01-16T14:36:49.604167", "market_id": "0x9472be65457510b7fc3477b20ba90910e99d92eac8421a14bf4b7b7a08ef31dc", "raw": {"market": "0x9472be65457510b7fc3477b20ba90910e99d92eac8421a14bf4b7b7a08ef31dc", "asset_id": "73414222381656326204771753454630063673548497164758947581648273905027617570612", "price": "0.145", "size": "292", "side": "SELL", "timestamp": "1768574181023", "received_at": "2026-01-16T14:36:21.113925"}}
{"event_type": "price_change", "event_ts": "2026-01-16T14:36:21.113936", "ingestion_ts": "2026-01-16T14:36:49.604167", "market_id": "0x44f08744458b8896620cd3330bc5e1ea69df4199b02d4fc583b3fc96e5d314ce", "raw": {"market": "0x44f08744458b8896620cd3330bc5e1ea69df4199b02d4fc583b3fc96e5d314ce", "asset_id": "72327831507226612545928776794104143393438710920370371172884559893525100761096", "price": "0.831", "size": "0", "side": "BUY", "timestamp": "1768574181023", "received_at": "2026-01-16T14:36:21.113936"}}
{"event_type": "price_change", "event_ts": "2026-01-16T14:36:21.113936", "ingestion_ts": "2026-01-16T14:36:49.604167", "market_id": "0x44f08744458b8896620cd3330bc5e1ea69df4199b02d4fc583b3fc96e5d314ce", "raw": {"market": "0x44f08744458b8896620cd3330bc5e1ea69df4199b02d4fc583b3fc96e5d314ce", "asset_id": "49194009556504828848509244326501559253829462790583873936160989575507522044057", "price": "0.169", "size": "0", "side": "SELL", "timestamp": "1768574181023", "received_at": "2026-01-16T14:36:21.113936"}}
{"event_type": "price_change", "event_ts": "2026-01-16T14:36:21.159414", "ingestion_ts": "2026-01-16T14:36:49.604167", "market_id": "0x49686d26fb712515cd5e12c23f0a1c7e10214c7faa3cb0a730aabe0c33694082", "raw": {"market": "0x49686d26fb712515cd5e12c23f0a1c7e10214c7faa3cb0a730aabe0c33694082", "asset_id": "30442780799048074404860985387051749017905070253466005720364298335239299761065", "price": "0.004", "size": "10", "side": "BUY", "timestamp": "1768574181058", "received_at": "2026-01-16T14:36:21.159414"}}
{"event_type": "price_change", "event_ts": "2026-01-16T14:36:21.159414", "ingestion_ts": "2026-01-16T14:36:49.604167", "market_id": "0x49686d26fb712515cd5e12c23f0a1c7e10214c7faa3cb0a730aabe0c33694082", "raw": {"market": "0x49686d26fb712515cd5e12c23f0a1c7e10214c7faa3cb0a730aabe0c33694082", "asset_id": "13244681086321087932946246027856416106585284024824496763706748621681543444582", "price": "0.996", "size": "10", "side": "SELL", "timestamp": "1768574181058", "received_at": "2026-01-16T14:36:21.159414"}}
{"event_type": "price_change", "event_ts": "2026-01-16T14:36:21.159455", "ingestion_ts": "2026-01-16T14:36:49.604167", "market_id": "0x49a20c7523c271099008f3ef9a31521263b24d637959852a391e6b4697b1a437", "raw": {"market": "0x49a20c7523c271099008f3ef9a31521263b24d637959852a391e6b4697b1a437", "asset_id": "55881023621710858558280545117465775643848233756850602339827152783696837905531", "price": "0.855", "size": "302", "side": "BUY", "timestamp": "1768574181058", "received_at": "2026-01-16T14:36:21.159455"}}
{"event_type": "price_change", "event_ts": "2026-01-16T14:36:21.159455", "ingestion_ts": "2026-01-16T14:36:49.604167", "market_id": "0x49a20c7523c271099008f3ef9a31521263b24d637959852a391e6b4697b1a437", "raw": {"market": "0x49a20c7523c271099008f3ef9a31521263b24d637959852a391e6b4697b1a437", "asset_id": "13018971792603393862521629014128024641178044618205296260525674415067194037856", "price": "0.145", "size": "302", "side": "SELL", "timestamp": "1768574181058", "received_at": "2026-01-16T14:36:21.159455"}}
{"event_type": "price_change", "event_ts": "2026-01-16T14:36:21.159469", "ingestion_ts": "2026-01-16T14:36:49.604167", "market_id": "0x9472be65457510b7fc3477b20ba90910e99d92eac8421a14bf4b7b7a08ef31dc", "raw": {"market": "0x9472be65457510b7fc3477b20ba90910e99d92eac8421a14bf4b7b7a08ef31dc", "asset_id": "43311793366960417907757893276427136943959788721376762326430771171648759300146", "price": "0.856", "size": "10", "side": "BUY", "timestamp": "1768574181058", "received_at": "2026-01-16T14:36:21.159469"}}
{"event_type": "price_change", "event_ts": "2026-01-16T14:36:21.159469", "ingestion_ts": "2026-01-16T14:36:49.604167", "market_id": "0x9472be65457510b7fc3477b20ba90910e99d92eac8421a14bf4b7b7a08ef31dc", "raw": {"market": "0x9472be65457510b7fc3477b20ba90910e99d92eac8421a14bf4b7b7a08ef31dc", "asset_id": "73414222381656326204771753454630063673548497164758947581648273905027617570612", "price": "0.144", "size": "10", "side": "SELL", "timestamp": "1768574181058", "received_at": "2026-01-16T14:36:21.159469"}}
{"event_type": "price_change", "event_ts": "2026-01-16T14:36:21.159481", "ingestion_ts": "2026-01-16T14:36:49.604167", "market_id": "0x44f08744458b8896620cd3330bc5e1ea69df4199b02d4fc583b3fc96e5d314ce", "raw": {"market": "0x44f08744458b8896620cd3330bc5e1ea69df4199b02d4fc583b3fc96e5d314ce", "asset_id": "72327831507226612545928776794104143393438710920370371172884559893525100761096", "price": "0.853", "size": "244", "side": "BUY", "timestamp": "1768574181058", "received_at": "2026-01-16T14:36:21.159481"}}
{"event_type": "price_change", "event_ts": "2026-01-16T14:36:21.159481", "ingestion_ts": "2026-01-16T14:36:49.604167", "market_id": "0x44f08744458b8896620cd3330bc5e1ea69df4199b02d4fc583b3fc96e5d314ce", "raw": {"market": "0x44f08744458b8896620cd3330bc5e1ea69df4199b02d4fc583b3fc96e5d314ce", "asset_id": "49194009556504828848509244326501559253829462790583873936160989575507522044057", "price": "0.147", "size": "244", "side": "SELL", "timestamp": "1768574181058", "received_at": "2026-01-16T14:36:21.159481"}}
{"event_type": "price_change", "event_ts": "2026-01-16T14:36:21.159493", "ingestion_ts": "2026-01-16T14:36:49.604167", "market_id": "0x50c669f178da4e5bbea7f1be25041fd278914712fa87a6a6f8e57d5923d88dee", "raw": {"market": "0x50c669f178da4e5bbea7f1be25041fd278914712fa87a6a6f8e57d5923d88dee", "asset_id": "74040420326294854165772767082819937451857852955603897473157746262672057685461", "price": "0.856", "size": "10", "side": "BUY", "timestamp": "1768574181058", "received_at": "2026-01-16T14:36:21.159493"}}
{"event_type": "price_change", "event_ts": "2026-01-16T14:36:21.159493", "ingestion_ts": "2026-01-16T14:36:49.604167", "market_id": "0x50c669f178da4e5bbea7f1be25041fd278914712fa87a6a6f8e57d5923d88dee", "raw": {"market": "0x50c669f178da4e5bbea7f1be25041fd278914712fa87a6a6f8e57d5923d88dee", "asset_id": "24682525479474221428144937281315825971983904267399062415430320764754931667953", "price": "0.144", "size": "10", "side": "SELL", "timestamp": "1768574181058", "received_at": "2026-01-16T14:36:21.159493"}}
{"event_type": "price_change", "event_ts": "2026-01-16T14:36:21.159504", "ingestion_ts": "2026-01-16T14:36:49.604167", "market_id": "0xc55db914f0fd1fee18997706712c0dfd8d0369cdbef93a9fef12bd001914ca77", "raw": {"market": "0xc55db914f0fd1fee18997706712c0dfd8d0369cdbef93a9fef12bd001914ca77", "asset_id": "114600293444080540179603459515770723592661967180480327891296353898330242622833", "price": "0.857", "size": "243", "side": "BUY", "timestamp": "1768574181058", "received_at": "2026-01-16T14:36:21.159504"}}
{"event_type": "price_change", "event_ts": "2026-01-16T14:36:21.159504", "ingestion_ts": "2026-01-16T14:36:49.604167", "market_id": "0xc55db914f0fd1fee18997706712c0dfd8d0369cdbef93a9fef12bd001914ca77", "raw": {"market": "0xc55db914f0fd1fee18997706712c0dfd8d0369cdbef93a9fef12bd001914ca77", "asset_id": "72354723612769247426741660426331235762851940382312402276325808095604519806766", "price": "0.143", "size": "243", "side": "SELL", "timestamp": "1768574181058", "received_at": "2026-01-16T14:36:21.159504"}}
{"event_type": "price_change", "event_ts": "2026-01-16T14:36:21.450684", "ingestion_ts": "2026-01-16T14:36:49.604167", "market_id": "0x49686d26fb712515cd5e12c23f0a1c7e10214c7faa3cb0a730aabe0c33694082", "raw": {"market": "0x49686d26fb712515cd5e12c23f0a1c7e10214c7faa3cb0a730aabe0c33694082", "asset_id": "30442780799048074404860985387051749017905070253466005720364298335239299761065", "price": "0.003", "size": "15.78", "side": "BUY", "timestamp": "1768574181411", "received_at": "2026-01-16T14:36:21.450684"}}
{"event_type": "price_change", "event_ts": "2026-01-16T14:36:21.450684", "ingestion_ts": "2026-01-16T14:36:49.604167", "market_id": "0x49686d26fb712515cd5e12c23f0a1c7e10214c7faa3cb0a730aabe0c33694082", "raw": {"market": "0x49686d26fb712515cd5e12c23f0a1c7e10214c7faa3cb0a730aabe0c33694082", "asset_id": "13244681086321087932946246027856416106585284024824496763706748621681543444582", "price": "0.997", "size": "15.78", "side": "SELL", "timestamp": "1768574181411", "received_at": "2026-01-16T14:36:21.450684"}}
{"event_type": "price_change", "event_ts": "2026-01-16T14:36:21.450797", "ingestion_ts": "2026-01-16T14:36:49.604167", "market_id": "0x49686d26fb712515cd5e12c23f0a1c7e10214c7faa3cb0a730aabe0c33694082", "raw": {"market": "0x49686d26fb712515cd5e12c23f0a1c7e10214c7faa3cb0a730aabe0c33694082", "asset_id": "30442780799048074404860985387051749017905070253466005720364298335239299761065", "price": "0.011", "size": "0", "side": "BUY", "timestamp": "1768574181411", "received_at": "2026-01-16T14:36:21.450797"}}
{"event_type": "price_change", "event_ts": "2026-01-16T14:36:21.450797", "ingestion_ts": "2026-01-16T14:36:49.604167", "market_id": "0x49686d26fb712515cd5e12c23f0a1c7e10214c7faa3cb0a730aabe0c33694082", "raw": {"market": "0x49686d26fb712515cd5e12c23f0a1c7e10214c7faa3cb0a730aabe0c33694082", "asset_id": "13244681086321087932946246027856416106585284024824496763706748621681543444582", "price": "0.989", "size": "0", "side": "SELL", "timestamp": "1768574181411", "received_at": "2026-01-16T14:36:21.450797"}}
{"event_type": "price_change", "event_ts": "2026-01-16T14:36:21.571663", "ingestion_ts": "2026-01-16T14:36:49.604167", "market_id": "0x49686d26fb712515cd5e12c23f0a1c7e10214c7faa3cb0a730aabe0c33694082", "raw": {"market": "0x49686d26fb712515cd5e12c23f0a1c7e10214c7faa3cb0a730aabe0c33694082", "asset_id": "13244681086321087932946246027856416106585284024824496763706748621681543444582", "price": "0.853", "size": "45", "side": "BUY", "timestamp": "1768574181533", "received_at": "2026-01-16T14:36:21.571663"}}
{"event_type": "price_change", "event_ts": "2026-01-16T14:36:21.571663", "ingestion_ts": "2026-01-16T14:36:49.604167", "market_id": "0x49686d26fb712515cd5e12c23f0a1c7e10214c7faa3cb0a730aabe0c33694082", "raw": {"market": "0x49686d26fb712515cd5e12c23f0a1c7e10214c7faa3cb0a730aabe0c33694082", "asset_id": "30442780799048074404860985387051749017905070253466005720364298335239299761065", "price": "0.147", "size": "45", "side": "SELL", "timestamp": "1768574181533", "received_at": "2026-01-16T14:36:21.571663"}}
{"event_type": "price_change", "event_ts": "2026-01-16T14:36:21.629524", "ingestion_ts": "2026-01-16T14:36:49.604167", "market_id": "0x49686d26fb712515cd5e12c23f0a1c7e10214c7faa3cb0a730aabe0c33694082", "raw": {"market": "0x49686d26fb712515cd5e12c23f0a1c7e10214c7faa3cb0a730aabe0c33694082", "asset_id": "13244681086321087932946246027856416106585284024824496763706748621681543444582", "price": "0.854", "size": "23.35", "side": "BUY", "timestamp": "1768574181594", "received_at": "2026-01-16T14:36:21.629524"}}
{"event_type": "price_change", "event_ts": "2026-01-16T14:36:21.629524", "ingestion_ts": "2026-01-16T14:36:49.604167", "market_id": "0x49686d26fb712515cd5e12c23f0a1c7e10214c7faa3cb0a730aabe0c33694082", "raw": {"market": "0x49686d26fb712515cd5e12c23f0a1c7e10214c7faa3cb0a730aabe0c33694082", "asset_id": "30442780799048074404860985387051749017905070253466005720364298335239299761065", "price": "0.146", "size": "23.35", "side": "SELL", "timestamp": "1768574181594", "received_at": "2026-01-16T14:36:21.629524"}}
{"event_type": "price_change", "event_ts": "2026-01-16T14:36:21.912011", "ingestion_ts": "2026-01-16T14:36:49.604167", "market_id": "0x49686d26fb712515cd5e12c23f0a1c7e10214c7faa3cb0a730aabe0c33694082", "raw": {"market": "0x49686d26fb712515cd5e12c23f0a1c7e10214c7faa3cb0a730aabe0c33694082", "asset_id": "30442780799048074404860985387051749017905070253466005720364298335239299761065", "price": "0.011", "size": "19.57", "side": "BUY", "timestamp": "1768574181868", "received_at": "2026-01-16T14:36:21.912011"}}
{"event_type": "price_change", "event_ts": "2026-01-16T14:36:21.912011", "ingestion_ts": "2026-01-16T14:36:49.604167", "market_id": "0x49686d26fb712515cd5e12c23f0a1c7e10214c7faa3cb0a730aabe0c33694082", "raw": {"market": "0x49686d26fb712515cd5e12c23f0a1c7e10214c7faa3cb0a730aabe0c33694082", "asset_id": "13244681086321087932946246027856416106585284024824496763706748621681543444582", "price": "0.989", "size": "19.57", "side": "SELL", "timestamp": "1768574181868", "received_at": "2026-01-16T14:36:21.912011"}}
{"event_type": "price_change", "event_ts": "2026-01-16T14:36:21.916445", "ingestion_ts": "2026-01-16T14:36:49.604167", "market_id": "0x49686d26fb712515cd5e12c23f0a1c7e10214c7faa3cb0a730aabe0c33694082", "raw": {"market": "0x49686d26fb712515cd5e12c23f0a1c7e10214c7faa3cb0a730aabe0c33694082", "asset_id": "30442780799048074404860985387051749017905070253466005720364298335239299761065", "price": "0.003", "size": "31.2", "side": "BUY", "timestamp": "1768574181869", "received_at": "2026-01-16T14:36:21.916445"}}
{"event_type": "price_change", "event_ts": "2026-01-16T14:36:21.916445", "ingestion_ts": "2026-01-16T14:36:49.604167", "market_id": "0x49686d26fb712515cd5e12c23f0a1c7e10214c7faa3cb0a730aabe0c33694082", "raw": {"market": "0x49686d26fb712515cd5e12c23f0a1c7e10214c7faa3cb0a730aabe0c33694082", "asset_id": "13244681086321087932946246027856416106585284024824496763706748621681543444582", "price": "0.997", "size": "31.2", "side": "SELL", "timestamp": "1768574181869", "received_at": "2026-01-16T14:36:21.916445"}}
{"event_type": "price_change", "event_ts": "2026-01-16T14:36:22.829444", "ingestion_ts": "2026-01-16T14:36:49.604167", "market_id": "0xc0e6b917320a47228fb96e3b5ae0e5c93773a5ae2662ae4e1f37807cfe47ce98", "raw": {"market": "0xc0e6b917320a47228fb96e3b5ae0e5c93773a5ae2662ae4e1f37807cfe47ce98", "asset_id": "58656358377246279051017109359677190749228949103591068167284263961542487110215", "price": "0.002", "size": "3287.1", "side": "BUY", "timestamp": "1768574182782", "received_at": "2026-01-16T14:36:22.829444"}}
{"event_type": "price_change", "event_ts": "2026-01-16T14:36:22.829444", "ingestion_ts": "2026-01-16T14:36:49.604167", "market_id": "0xc0e6b917320a47228fb96e3b5ae0e5c93773a5ae2662ae4e1f37807cfe47ce98", "raw": {"market": "0xc0e6b917320a47228fb96e3b5ae0e5c93773a5ae2662ae4e1f37807cfe47ce98", "asset_id": "81647294538046680798858716589766492074338758116170717123345952330712416337530", "price": "0.998", "size": "3287.1", "side": "SELL", "timestamp": "1768574182782", "received_at": "2026-01-16T14:36:22.829444"}}
{"event_type": "price_change", "event_ts": "2026-01-16T14:36:22.913659", "ingestion_ts": "2026-01-16T14:36:49.604167", "market_id": "0x49686d26fb712515cd5e12c23f0a1c7e10214c7faa3cb0a730aabe0c33694082", "raw": {"market": "0x49686d26fb712515cd5e12c23f0a1c7e10214c7faa3cb0a730aabe0c33694082", "asset_id": "30442780799048074404860985387051749017905070253466005720364298335239299761065", "price": "0.146", "size": "5.85", "side": "SELL", "timestamp": "1768574182837", "received_at": "2026-01-16T14:36:22.913659"}}
{"event_type": "price_change", "event_ts": "2026-01-16T14:36:22.913659", "ingestion_ts": "2026-01-16T14:36:49.604167", "market_id": "0x49686d26fb712515cd5e12c23f0a1c7e10214c7faa3cb0a730aabe0c33694082", "raw": {"market": "0x49686d26fb712515cd5e12c23f0a1c7e10214c7faa3cb0a730aabe0c33694082", "asset_id": "13244681086321087932946246027856416106585284024824496763706748621681543444582", "price": "0.854", "size": "5.85", "side": "BUY", "timestamp": "1768574182837", "received_at": "2026-01-16T14:36:22.913659"}}
{"event_type": "price_change", "event_ts": "2026-01-16T14:36:22.959623", "ingestion_ts": "2026-01-16T14:36:49.604167", "market_id": "0x49686d26fb712515cd5e12c23f0a1c7e10214c7faa3cb0a730aabe0c33694082", "raw": {"market": "0x49686d26fb712515cd5e12c23f0a1c7e10214c7faa3cb0a730aabe0c33694082", "asset_id": "30442780799048074404860985387051749017905070253466005720364298335239299761065", "price": "0.148", "size": "17.5", "side": "SELL", "timestamp": "1768574182879", "received_at": "2026-01-16T14:36:22.959623"}}
{"event_type": "price_change", "event_ts": "2026-01-16T14:36:22.959623", "ingestion_ts": "2026-01-16T14:36:49.604167", "market_id": "0x49686d26fb712515cd5e12c23f0a1c7e10214c7faa3cb0a730aabe0c33694082", "raw": {"market": "0x49686d26fb712515cd5e12c23f0a1c7e10214c7faa3cb0a730aabe0c33694082", "asset_id": "13244681086321087932946246027856416106585284024824496763706748621681543444582", "price": "0.852", "size": "17.5", "side": "BUY", "timestamp": "1768574182879", "received_at": "2026-01-16T14:36:22.959623"}}
{"event_type": "price_change", "event_ts": "2026-01-16T14:36:23.610174", "ingestion_ts": "2026-01-16T14:36:49.604167", "market_id": "0xae5584fbb57f23c1c608d544b656f23d8bf12340cef70811cf31bb0cb4fc2115", "raw": {"market": "0xae5584fbb57f23c1c608d544b656f23d8bf12340cef70811cf31bb0cb4fc2115", "asset_id": "42278252558046940014991595990628759801692726198478046188873057685686228021663", "price": "0.99", "size": "8138.8", "side": "SELL", "timestamp": "1768574183569", "received_at": "2026-01-16T14:36:23.610174"}}
{"event_type": "price_change", "event_ts": "2026-01-16T14:36:23.610174", "ingestion_ts": "2026-01-16T14:36:49.604167", "market_id": "0xae5584fbb57f23c1c608d544b656f23d8bf12340cef70811cf31bb0cb4fc2115", "raw": {"market": "0xae5584fbb57f23c1c608d544b656f23d8bf12340cef70811cf31bb0cb4fc2115", "asset_id": "28946595841244317705636126646676849578876740730186646421280828201004700559420", "price": "0.01", "size": "8138.8", "side": "BUY", "timestamp": "1768574183569", "received_at": "2026-01-16T14:36:23.610174"}}
{"event_type": "price_change", "event_ts": "2026-01-16T14:36:23.708093", "ingestion_ts": "2026-01-16T14:36:49.604167", "market_id": "0xae5584fbb57f23c1c608d544b656f23d8bf12340cef70811cf31bb0cb4fc2115", "raw": {"market": "0xae5584fbb57f23c1c608d544b656f23d8bf12340cef70811cf31bb0cb4fc2115", "asset_id": "28946595841244317705636126646676849578876740730186646421280828201004700559420", "price": "0.01", "size": "8091", "side": "BUY", "timestamp": "1768574183668", "received_at": "2026-01-16T14:36:23.708093"}}
{"event_type": "price_change", "event_ts": "2026-01-16T14:36:23.708093", "ingestion_ts": "2026-01-16T14:36:49.604167", "market_id": "0xae5584fbb57f23c1c608d544b656f23d8bf12340cef70811cf31bb0cb4fc2115", "raw": {"market": "0xae5584fbb57f23c1c608d544b656f23d8bf12340cef70811cf31bb0cb4fc2115", "asset_id": "42278252558046940014991595990628759801692726198478046188873057685686228021663", "price": "0.99", "size": "8091", "side": "SELL", "timestamp": "1768574183668", "received_at": "2026-01-16T14:36:23.708093"}}
{"event_type": "price_change", "event_ts": "2026-01-16T14:36:23.760997", "ingestion_ts": "2026-01-16T14:36:49.604167", "market_id": "0xc0e6b917320a47228fb96e3b5ae0e5c93773a5ae2662ae4e1f37807cfe47ce98", "raw": {"market": "0xc0e6b917320a47228fb96e3b5ae0e5c93773a5ae2662ae4e1f37807cfe47ce98", "asset_id": "58656358377246279051017109359677190749228949103591068167284263961542487110215", "price": "0.002", "size": "3279.99", "side": "BUY", "timestamp": "1768574183721", "received_at": "2026-01-16T14:36:23.760997"}}
{"event_type": "price_change", "event_ts": "2026-01-16T14:36:23.760997", "ingestion_ts": "2026-01-16T14:36:49.604167", "market_id": "0xc0e6b917320a47228fb96e3b5ae0e5c93773a5ae2662ae4e1f37807cfe47ce98", "raw": {"market": "0xc0e6b917320a47228fb96e3b5ae0e5c93773a5ae2662ae4e1f37807cfe47ce98", "asset_id": "81647294538046680798858716589766492074338758116170717123345952330712416337530", "price": "0.998", "size": "3279.99", "side": "SELL", "timestamp": "1768574183721", "received_at": "2026-01-16T14:36:23.760997"}}
{"event_type": "price_change", "event_ts": "2026-01-16T14:36:24.019142", "ingestion_ts": "2026-01-16T14:36:49.604167", "market_id": "0x50c669f178da4e5bbea7f1be25041fd278914712fa87a6a6f8e57d5923d88dee", "raw": {"market": "0x50c669f178da4e5bbea7f1be25041fd278914712fa87a6a6f8e57d5923d88dee", "asset_id": "74040420326294854165772767082819937451857852955603897473157746262672057685461", "price": "0.856", "size": "0", "side": "BUY", "timestamp": "1768574183980", "received_at": "2026-01-16T14:36:24.019142"}}
{"event_type": "price_change", "event_ts": "2026-01-16T14:36:24.019142", "ingestion_ts": "2026-01-16T14:36:49.604167", "market_id": "0x50c669f178da4e5bbea7f1be25041fd278914712fa87a6a6f8e57d5923d88dee", "raw": {"market": "0x50c669f178da4e5bbea7f1be25041fd278914712fa87a6a6f8e57d5923d88dee", "asset_id": "24682525479474221428144937281315825971983904267399062415430320764754931667953", "price": "0.144", "size": "0", "side": "SELL", "timestamp": "1768574183980", "received_at": "2026-01-16T14:36:24.019142"}}
{"event_type": "price_change", "event_ts": "2026-01-16T14:36:24.053439", "ingestion_ts": "2026-01-16T14:36:49.604167", "market_id": "0x50c669f178da4e5bbea7f1be25041fd278914712fa87a6a6f8e57d5923d88dee", "raw": {"market": "0x50c669f178da4e5bbea7f1be25041fd278914712fa87a6a6f8e57d5923d88dee", "asset_id": "74040420326294854165772767082819937451857852955603897473157746262672057685461", "price": "0.855", "size": "594", "side": "BUY", "timestamp": "1768574184014", "received_at": "2026-01-16T14:36:24.053439"}}
{"event_type": "price_change", "event_ts": "2026-01-16T14:36:24.053439", "ingestion_ts": "2026-01-16T14:36:49.604167", "market_id": "0x50c669f178da4e5bbea7f1be25041fd278914712fa87a6a6f8e57d5923d88dee", "raw": {"market": "0x50c669f178da4e5bbea7f1be25041fd278914712fa87a6a6f8e57d5923d88dee", "asset_id": "24682525479474221428144937281315825971983904267399062415430320764754931667953", "price": "0.145", "size": "594", "side": "SELL", "timestamp": "1768574184014", "received_at": "2026-01-16T14:36:24.053439"}}
{"event_type": "price_change", "event_ts": "2026-01-16T14:36:24.256718", "ingestion_ts": "2026-01-16T14:36:49.604167", "market_id": "0xc0e6b917320a47228fb96e3b5ae0e5c93773a5ae2662ae4e1f37807cfe47ce98", "raw": {"market": "0xc0e6b917320a47228fb96e3b5ae0e5c93773a5ae2662ae4e1f37807cfe47ce98", "asset_id": "58656358377246279051017109359677190749228949103591068167284263961542487110215", "price": "0.002", "size": "3287.1", "side": "BUY", "timestamp": "1768574184216", "received_at": "2026-01-16T14:36:24.256718"}}
{"event_type": "price_change", "event_ts": "2026-01-16T14:36:24.256718", "ingestion_ts": "2026-01-16T14:36:49.604167", "market_id": "0xc0e6b917320a47228fb96e3b5ae0e5c93773a5ae2662ae4e1f37807cfe47ce98", "raw": {"market": "0xc0e6b917320a47228fb96e3b5ae0e5c93773a5ae2662ae4e1f37807cfe47ce98", "asset_id": "81647294538046680798858716589766492074338758116170717123345952330712416337530", "price": "0.998", "size": "3287.1", "side": "SELL", "timestamp": "1768574184216", "received_at": "2026-01-16T14:36:24.256718"}}
{"event_type": "price_change", "event_ts": "2026-01-16T14:36:24.257064", "ingestion_ts": "2026-01-16T14:36:49.604167", "market_id": "0xc0e6b917320a47228fb96e3b5ae0e5c93773a5ae2662ae4e1f37807cfe47ce98", "raw": {"market": "0xc0e6b917320a47228fb96e3b5ae0e5c93773a5ae2662ae4e1f37807cfe47ce98", "asset_id": "58656358377246279051017109359677190749228949103591068167284263961542487110215", "price": "0.002", "size": "3294.21", "side": "BUY", "timestamp": "1768574184219", "received_at": "2026-01-16T14:36:24.257064"}}
{"event_type": "price_change", "event_ts": "2026-01-16T14:36:24.257064", "ingestion_ts": "2026-01-16T14:36:49.604167", "market_id": "0xc0e6b917320a47228fb96e3b5ae0e5c93773a5ae2662ae4e1f37807cfe47ce98", "raw": {"market": "0xc0e6b917320a47228fb96e3b5ae0e5c93773a5ae2662ae4e1f37807cfe47ce98", "asset_id": "81647294538046680798858716589766492074338758116170717123345952330712416337530", "price": "0.998", "size": "3294.21", "side": "SELL", "timestamp": "1768574184219", "received_at": "2026-01-16T14:36:24.257064"}}
{"event_type": "price_change", "event_ts": "2026-01-16T14:36:25.174498", "ingestion_ts": "2026-01-16T14:36:49.604167", "market_id": "0x49686d26fb712515cd5e12c23f0a1c7e10214c7faa3cb0a730aabe0c33694082", "raw": {"market": "0x49686d26fb712515cd5e12c23f0a1c7e10214c7faa3cb0a730aabe0c33694082", "asset_id": "30442780799048074404860985387051749017905070253466005720364298335239299761065", "price": "0.003", "size": "15.78", "side": "BUY", "timestamp": "1768574185113", "received_at": "2026-01-16T14:36:25.174498"}}
{"event_type": "price_change", "event_ts": "2026-01-16T14:36:25.174498", "ingestion_ts": "2026-01-16T14:36:49.604167", "market_id": "0x49686d26fb712515cd5e12c23f0a1c7e10214c7faa3cb0a730aabe0c33694082", "raw": {"market": "0x49686d26fb712515cd5e12c23f0a1c7e10214c7faa3cb0a730aabe0c33694082", "asset_id": "13244681086321087932946246027856416106585284024824496763706748621681543444582", "price": "0.997", "size": "15.78", "side": "SELL", "timestamp": "1768574185113", "received_at": "2026-01-16T14:36:25.174498"}}
{"event_type": "price_change", "event_ts": "2026-01-16T14:36:25.174542", "ingestion_ts": "2026-01-16T14:36:49.604167", "market_id": "0x49686d26fb712515cd5e12c23f0a1c7e10214c7faa3cb0a730aabe0c33694082", "raw": {"market": "0x49686d26fb712515cd5e12c23f0a1c7e10214c7faa3cb0a730aabe0c33694082", "asset_id": "30442780799048074404860985387051749017905070253466005720364298335239299761065", "price": "0.011", "size": "0", "side": "BUY", "timestamp": "1768574185113", "received_at": "2026-01-16T14:36:25.174542"}}
{"event_type": "price_change", "event_ts": "2026-01-16T14:36:25.174542", "ingestion_ts": "2026-01-16T14:36:49.604167", "market_id": "0x49686d26fb712515cd5e12c23f0a1c7e10214c7faa3cb0a730aabe0c33694082", "raw": {"market": "0x49686d26fb712515cd5e12c23f0a1c7e10214c7faa3cb0a730aabe0c33694082", "asset_id": "13244681086321087932946246027856416106585284024824496763706748621681543444582", "price": "0.989", "size": "0", "side": "SELL", "timestamp": "1768574185113", "received_at": "2026-01-16T14:36:25.174542"}}
{"event_type": "price_change", "event_ts": "2026-01-16T14:36:25.174556", "ingestion_ts": "2026-01-16T14:36:49.604167", "market_id": "0xaf9d0e448129a9f657f851d49495ba4742055d80e0ef1166ba0ee81d4d594214", "raw": {"market": "0xaf9d0e448129a9f657f851d49495ba4742055d80e0ef1166ba0ee81d4d594214", "asset_id": "4153292802911610701832309484716814274802943278345248636922528170020319407796", "price": "0.981", "size": "0", "side": "SELL", "timestamp": "1768574185137", "received_at": "2026-01-16T14:36:25.174556"}}
{"event_type": "price_change", "event_ts": "2026-01-16T14:36:25.174556", "ingestion_ts": "2026-01-16T14:36:49.604167", "market_id": "0xaf9d0e448129a9f657f851d49495ba4742055d80e0ef1166ba0ee81d4d594214", "raw": {"market": "0xaf9d0e448129a9f657f851d49495ba4742055d80e0ef1166ba0ee81d4d594214", "asset_id": "101676997363687199724245607342877036148401850938023978421879460310389391082353", "price": "0.019", "size": "0", "side": "BUY", "timestamp": "1768574185137", "received_at": "2026-01-16T14:36:25.174556"}}
{"event_type": "price_change", "event_ts": "2026-01-16T14:36:25.513370", "ingestion_ts": "2026-01-16T14:36:49.604167", "market_id": "0x2393ed0b0fdc450054c7b9071907eca75cf4fc36e385adf4a0a5f99ee62243e8", "raw": {"market": "0x2393ed0b0fdc450054c7b9071907eca75cf4fc36e385adf4a0a5f99ee62243e8", "asset_id": "32769749367306925959219403371425714180265458150646381231272229429098460625924", "price": "0.942", "size": "50", "side": "BUY", "timestamp": "1768574185454", "received_at": "2026-01-16T14:36:25.513370"}}
{"event_type": "price_change", "event_ts": "2026-01-16T14:36:25.513370", "ingestion_ts": "2026-01-16T14:36:49.604167", "market_id": "0x2393ed0b0fdc450054c7b9071907eca75cf4fc36e385adf4a0a5f99ee62243e8", "raw": {"market": "0x2393ed0b0fdc450054c7b9071907eca75cf4fc36e385adf4a0a5f99ee62243e8", "asset_id": "100074770378634056601572485653252702850363676459996771990439989989293515601975", "price": "0.058", "size": "50", "side": "SELL", "timestamp": "1768574185454", "received_at": "2026-01-16T14:36:25.513370"}}
{"event_type": "price_change", "event_ts": "2026-01-16T14:36:25.593846", "ingestion_ts": "2026-01-16T14:36:49.604167", "market_id": "0x2393ed0b0fdc450054c7b9071907eca75cf4fc36e385adf4a0a5f99ee62243e8", "raw": {"market": "0x2393ed0b0fdc450054c7b9071907eca75cf4fc36e385adf4a0a5f99ee62243e8", "asset_id": "100074770378634056601572485653252702850363676459996771990439989989293515601975", "price": "0.059", "size": "0", "side": "SELL", "timestamp": "1768574185503", "received_at": "2026-01-16T14:36:25.593846"}}
{"event_type": "price_change", "event_ts": "2026-01-16T14:36:25.593846", "ingestion_ts": "2026-01-16T14:36:49.604167", "market_id": "0x2393ed0b0fdc450054c7b9071907eca75cf4fc36e385adf4a0a5f99ee62243e8", "raw": {"market": "0x2393ed0b0fdc450054c7b9071907eca75cf4fc36e385adf4a0a5f99ee62243e8", "asset_id": "32769749367306925959219403371425714180265458150646381231272229429098460625924", "price": "0.941", "size": "0", "side": "BUY", "timestamp": "1768574185503", "received_at": "2026-01-16T14:36:25.593846"}}
{"event_type": "price_change", "event_ts": "2026-01-16T14:36:25.593884", "ingestion_ts": "2026-01-16T14:36:49.604167", "market_id": "0x2393ed0b0fdc450054c7b9071907eca75cf4fc36e385adf4a0a5f99ee62243e8", "raw": {"market": "0x2393ed0b0fdc450054c7b9071907eca75cf4fc36e385adf4a0a5f99ee62243e8", "asset_id": "100074770378634056601572485653252702850363676459996771990439989989293515601975", "price": "0.057", "size": "204", "side": "SELL", "timestamp": "1768574185530", "received_at": "2026-01-16T14:36:25.593884"}}
{"event_type": "price_change", "event_ts": "2026-01-16T14:36:25.593884", "ingestion_ts": "2026-01-16T14:36:49.604167", "market_id": "0x2393ed0b0fdc450054c7b9071907eca75cf4fc36e385adf4a0a5f99ee62243e8", "raw": {"market": "0x2393ed0b0fdc450054c7b9071907eca75cf4fc36e385adf4a0a5f99ee62243e8", "asset_id": "32769749367306925959219403371425714180265458150646381231272229429098460625924", "price": "0.943", "size": "204", "side": "BUY", "timestamp": "1768574185530", "received_at": "2026-01-16T14:36:25.593884"}}
{"event_type": "price_change", "event_ts": "2026-01-16T14:36:25.602806", "ingestion_ts": "2026-01-16T14:36:49.604167", "market_id": "0xaf9d0e448129a9f657f851d49495ba4742055d80e0ef1166ba0ee81d4d594214", "raw": {"market": "0xaf9d0e448129a9f657f851d49495ba4742055d80e0ef1166ba0ee81d4d594214", "asset_id": "4153292802911610701832309484716814274802943278345248636922528170020319407796", "price": "0.979", "size": "140.01", "side": "SELL", "timestamp": "1768574185567", "received_at": "2026-01-16T14:36:25.602806"}}
{"event_type": "price_change", "event_ts": "2026-01-16T14:36:25.602806", "ingestion_ts": "2026-01-16T14:36:49.604167", "market_id": "0xaf9d0e448129a9f657f851d49495ba4742055d80e0ef1166ba0ee81d4d594214", "raw": {"market": "0xaf9d0e448129a9f657f851d49495ba4742055d80e0ef1166ba0ee81d4d594214", "asset_id": "101676997363687199724245607342877036148401850938023978421879460310389391082353", "price": "0.021", "size": "140.01", "side": "BUY", "timestamp": "1768574185567", "received_at": "2026-01-16T14:36:25.602806"}}
{"event_type": "price_change", "event_ts": "2026-01-16T14:36:25.775780", "ingestion_ts": "2026-01-16T14:36:49.604167", "market_id": "0x49686d26fb712515cd5e12c23f0a1c7e10214c7faa3cb0a730aabe0c33694082", "raw": {"market": "0x49686d26fb712515cd5e12c23f0a1c7e10214c7faa3cb0a730aabe0c33694082", "asset_id": "30442780799048074404860985387051749017905070253466005720364298335239299761065", "price": "0.003", "size": "31.2", "side": "BUY", "timestamp": "1768574185738", "received_at": "2026-01-16T14:36:25.775780"}}
{"event_type": "price_change", "event_ts": "2026-01-16T14:36:25.775780", "ingestion_ts": "2026-01-16T14:36:49.604167", "market_id": "0x49686d26fb712515cd5e12c23f0a1c7e10214c7faa3cb0a730aabe0c33694082", "raw": {"market": "0x49686d26fb712515cd5e12c23f0a1c7e10214c7faa3cb0a730aabe0c33694082", "asset_id": "13244681086321087932946246027856416106585284024824496763706748621681543444582", "price": "0.997", "size": "31.2", "side": "SELL", "timestamp": "1768574185738", "received_at": "2026-01-16T14:36:25.775780"}}
{"event_type": "price_change", "event_ts": "2026-01-16T14:36:25.780623", "ingestion_ts": "2026-01-16T14:36:49.604167", "market_id": "0x49686d26fb712515cd5e12c23f0a1c7e10214c7faa3cb0a730aabe0c33694082", "raw": {"market": "0x49686d26fb712515cd5e12c23f0a1c7e10214c7faa3cb0a730aabe0c33694082", "asset_id": "30442780799048074404860985387051749017905070253466005720364298335239299761065", "price": "0.011", "size": "19.57", "side": "BUY", "timestamp": "1768574185739", "received_at": "2026-01-16T14:36:25.780623"}}
{"event_type": "price_change", "event_ts": "2026-01-16T14:36:25.780623", "ingestion_ts": "2026-01-16T14:36:49.604167", "market_id": "0x49686d26fb712515cd5e12c23f0a1c7e10214c7faa3cb0a730aabe0c33694082", "raw": {"market": "0x49686d26fb712515cd5e12c23f0a1c7e10214c7faa3cb0a730aabe0c33694082", "asset_id": "13244681086321087932946246027856416106585284024824496763706748621681543444582", "price": "0.989", "size": "19.57", "side": "SELL", "timestamp": "1768574185739", "received_at": "2026-01-16T14:36:25.780623"}}
{"event_type": "price_change", "event_ts": "2026-01-16T14:36:26.266040", "ingestion_ts": "2026-01-16T14:36:49.604167", "market_id": "0xaf9d0e448129a9f657f851d49495ba4742055d80e0ef1166ba0ee81d4d594214", "raw": {"market": "0xaf9d0e448129a9f657f851d49495ba4742055d80e0ef1166ba0ee81d4d594214", "asset_id": "4153292802911610701832309484716814274802943278345248636922528170020319407796", "price": "0.98", "size": "0", "side": "SELL", "timestamp": "1768574186221", "received_at": "2026-01-16T14:36:26.266040"}}
{"event_type": "price_change", "event_ts": "2026-01-16T14:36:26.266040", "ingestion_ts": "2026-01-16T14:36:49.604167", "market_id": "0xaf9d0e448129a9f657f851d49495ba4742055d80e0ef1166ba0ee81d4d594214", "raw": {"market": "0xaf9d0e448129a9f657f851d49495ba4742055d80e0ef1166ba0ee81d4d594214", "asset_id": "101676997363687199724245607342877036148401850938023978421879460310389391082353", "price": "0.02", "size": "0", "side": "BUY", "timestamp": "1768574186221", "received_at": "2026-01-16T14:36:26.266040"}}
{"event_type": "price_change", "event_ts": "2026-01-16T14:36:26.299082", "ingestion_ts": "2026-01-16T14:36:49.604167", "market_id": "0xaf9d0e448129a9f657f851d49495ba4742055d80e0ef1166ba0ee81d4d594214", "raw": {"market": "0xaf9d0e448129a9f657f851d49495ba4742055d80e0ef1166ba0ee81d4d594214", "asset_id": "4153292802911610701832309484716814274802943278345248636922528170020319407796", "price": "0.989", "size": "20.5", "side": "SELL", "timestamp": "1768574186261", "received_at": "2026-01-16T14:36:26.299082"}}
{"event_type": "price_change", "event_ts": "2026-01-16T14:36:26.299082", "ingestion_ts": "2026-01-16T14:36:49.604167", "market_id": "0xaf9d0e448129a9f657f851d49495ba4742055d80e0ef1166ba0ee81d4d594214", "raw": {"market": "0xaf9d0e448129a9f657f851d49495ba4742055d80e0ef1166ba0ee81d4d594214", "asset_id": "101676997363687199724245607342877036148401850938023978421879460310389391082353", "price": "0.011", "size": "20.5", "side": "BUY", "timestamp": "1768574186261", "received_at": "2026-01-16T14:36:26.299082"}}
{"event_type": "price_change", "event_ts": "2026-01-16T14:36:26.366337", "ingestion_ts": "2026-01-16T14:36:49.604167", "market_id": "0xc0e6b917320a47228fb96e3b5ae0e5c93773a5ae2662ae4e1f37807cfe47ce98", "raw": {"market": "0xc0e6b917320a47228fb96e3b5ae0e5c93773a5ae2662ae4e1f37807cfe47ce98", "asset_id": "58656358377246279051017109359677190749228949103591068167284263961542487110215", "price": "0.002", "size": "3287.1", "side": "BUY", "timestamp": "1768574186327", "received_at": "2026-01-16T14:36:26.366337"}}
{"event_type": "price_change", "event_ts": "2026-01-16T14:36:26.366337", "ingestion_ts": "2026-01-16T14:36:49.604167", "market_id": "0xc0e6b917320a47228fb96e3b5ae0e5c93773a5ae2662ae4e1f37807cfe47ce98", "raw": {"market": "0xc0e6b917320a47228fb96e3b5ae0e5c93773a5ae2662ae4e1f37807cfe47ce98", "asset_id": "81647294538046680798858716589766492074338758116170717123345952330712416337530", "price": "0.998", "size": "3287.1", "side": "SELL", "timestamp": "1768574186327", "received_at": "2026-01-16T14:36:26.366337"}}
{"event_type": "price_change", "event_ts": "2026-01-16T14:36:27.245249", "ingestion_ts": "2026-01-16T14:36:49.604167", "market_id": "0xc0e6b917320a47228fb96e3b5ae0e5c93773a5ae2662ae4e1f37807cfe47ce98", "raw": {"market": "0xc0e6b917320a47228fb96e3b5ae0e5c93773a5ae2662ae4e1f37807cfe47ce98", "asset_id": "58656358377246279051017109359677190749228949103591068167284263961542487110215", "price": "0.002", "size": "3279.99", "side": "BUY", "timestamp": "1768574187209", "received_at": "2026-01-16T14:36:27.245249"}}
{"event_type": "price_change", "event_ts": "2026-01-16T14:36:27.245249", "ingestion_ts": "2026-01-16T14:36:49.604167", "market_id": "0xc0e6b917320a47228fb96e3b5ae0e5c93773a5ae2662ae4e1f37807cfe47ce98", "raw": {"market": "0xc0e6b917320a47228fb96e3b5ae0e5c93773a5ae2662ae4e1f37807cfe47ce98", "asset_id": "81647294538046680798858716589766492074338758116170717123345952330712416337530", "price": "0.998", "size": "3279.99", "side": "SELL", "timestamp": "1768574187209", "received_at": "2026-01-16T14:36:27.245249"}}
{"event_type": "price_change", "event_ts": "2026-01-16T14:36:27.463092", "ingestion_ts": "2026-01-16T14:36:49.604167", "market_id": "0xaf9d0e448129a9f657f851d49495ba4742055d80e0ef1166ba0ee81d4d594214", "raw": {"market": "0xaf9d0e448129a9f657f851d49495ba4742055d80e0ef1166ba0ee81d4d594214", "asset_id": "4153292802911610701832309484716814274802943278345248636922528170020319407796", "price": "0.989", "size": "0", "side": "SELL", "timestamp": "1768574187416", "received_at": "2026-01-16T14:36:27.463092"}}
{"event_type": "price_change", "event_ts": "2026-01-16T14:36:27.463092", "ingestion_ts": "2026-01-16T14:36:49.604167", "market_id": "0xaf9d0e448129a9f657f851d49495ba4742055d80e0ef1166ba0ee81d4d594214", "raw": {"market": "0xaf9d0e448129a9f657f851d49495ba4742055d80e0ef1166ba0ee81d4d594214", "asset_id": "101676997363687199724245607342877036148401850938023978421879460310389391082353", "price": "0.011", "size": "0", "side": "BUY", "timestamp": "1768574187416", "received_at": "2026-01-16T14:36:27.463092"}}
{"event_type": "price_change", "event_ts": "2026-01-16T14:36:27.518024", "ingestion_ts": "2026-01-16T14:36:49.604167", "market_id": "0xaf9d0e448129a9f657f851d49495ba4742055d80e0ef1166ba0ee81d4d594214", "raw": {"market": "0xaf9d0e448129a9f657f851d49495ba4742055d80e0ef1166ba0ee81d4d594214", "asset_id": "4153292802911610701832309484716814274802943278345248636922528170020319407796", "price": "0.978", "size": "20.5", "side": "SELL", "timestamp": "1768574187467", "received_at": "2026-01-16T14:36:27.518024"}}
{"event_type": "price_change", "event_ts": "2026-01-16T14:36:27.518024", "ingestion_ts": "2026-01-16T14:36:49.604167", "market_id": "0xaf9d0e448129a9f657f851d49495ba4742055d80e0ef1166ba0ee81d4d594214", "raw": {"market": "0xaf9d0e448129a9f657f851d49495ba4742055d80e0ef1166ba0ee81d4d594214", "asset_id": "101676997363687199724245607342877036148401850938023978421879460310389391082353", "price": "0.022", "size": "20.5", "side": "BUY", "timestamp": "1768574187467", "received_at": "2026-01-16T14:36:27.518024"}}
{"event_type": "price_change", "event_ts": "2026-01-16T14:36:27.554492", "ingestion_ts": "2026-01-16T14:36:49.604167", "market_id": "0x49686d26fb712515cd5e12c23f0a1c7e10214c7faa3cb0a730aabe0c33694082", "raw": {"market": "0x49686d26fb712515cd5e12c23f0a1c7e10214c7faa3cb0a730aabe0c33694082", "asset_id": "30442780799048074404860985387051749017905070253466005720364298335239299761065", "price": "0.004", "size": "0", "side": "BUY", "timestamp": "1768574187514", "received_at": "2026-01-16T14:36:27.554492"}}
{"event_type": "price_change", "event_ts": "2026-01-16T14:36:27.554492", "ingestion_ts": "2026-01-16T14:36:49.604167", "market_id": "0x49686d26fb712515cd5e12c23f0a1c7e10214c7faa3cb0a730aabe0c33694082", "raw": {"market": "0x49686d26fb712515cd5e12c23f0a1c7e10214c7faa3cb0a730aabe0c33694082", "asset_id": "13244681086321087932946246027856416106585284024824496763706748621681543444582", "price": "0.996", "size": "0", "side": "SELL", "timestamp": "1768574187514", "received_at": "2026-01-16T14:36:27.554492"}}
{"event_type": "price_change", "event_ts": "2026-01-16T14:36:27.554562", "ingestion_ts": "2026-01-16T14:36:49.604167", "market_id": "0x44f08744458b8896620cd3330bc5e1ea69df4199b02d4fc583b3fc96e5d314ce", "raw": {"market": "0x44f08744458b8896620cd3330bc5e1ea69df4199b02d4fc583b3fc96e5d314ce", "asset_id": "72327831507226612545928776794104143393438710920370371172884559893525100761096", "price": "0.853", "size": "234", "side": "BUY", "timestamp": "1768574187514", "received_at": "2026-01-16T14:36:27.554562"}}
{"event_type": "price_change", "event_ts": "2026-01-16T14:36:27.554562", "ingestion_ts": "2026-01-16T14:36:49.604167", "market_id": "0x44f08744458b8896620cd3330bc5e1ea69df4199b02d4fc583b3fc96e5d314ce", "raw": {"market": "0x44f08744458b8896620cd3330bc5e1ea69df4199b02d4fc583b3fc96e5d314ce", "asset_id": "49194009556504828848509244326501559253829462790583873936160989575507522044057", "price": "0.147", "size": "234", "side": "SELL", "timestamp": "1768574187514", "received_at": "2026-01-16T14:36:27.554562"}}
{"event_type": "price_change", "event_ts": "2026-01-16T14:36:27.554589", "ingestion_ts": "2026-01-16T14:36:49.604167", "market_id": "0xc55db914f0fd1fee18997706712c0dfd8d0369cdbef93a9fef12bd001914ca77", "raw": {"market": "0xc55db914f0fd1fee18997706712c0dfd8d0369cdbef93a9fef12bd001914ca77", "asset_id": "114600293444080540179603459515770723592661967180480327891296353898330242622833", "price": "0.857", "size": "233", "side": "BUY", "timestamp": "1768574187514", "received_at": "2026-01-16T14:36:27.554589"}}
{"event_type": "price_change", "event_ts": "2026-01-16T14:36:27.554589", "ingestion_ts": "2026-01-16T14:36:49.604167", "market_id": "0xc55db914f0fd1fee18997706712c0dfd8d0369cdbef93a9fef12bd001914ca77", "raw": {"market": "0xc55db914f0fd1fee18997706712c0dfd8d0369cdbef93a9fef12bd001914ca77", "asset_id": "72354723612769247426741660426331235762851940382312402276325808095604519806766", "price": "0.143", "size": "233", "side": "SELL", "timestamp": "1768574187514", "received_at": "2026-01-16T14:36:27.554589"}}
{"event_type": "price_change", "event_ts": "2026-01-16T14:36:27.554608", "ingestion_ts": "2026-01-16T14:36:49.604167", "market_id": "0x50c669f178da4e5bbea7f1be25041fd278914712fa87a6a6f8e57d5923d88dee", "raw": {"market": "0x50c669f178da4e5bbea7f1be25041fd278914712fa87a6a6f8e57d5923d88dee", "asset_id": "74040420326294854165772767082819937451857852955603897473157746262672057685461", "price": "0.855", "size": "584", "side": "BUY", "timestamp": "1768574187514", "received_at": "2026-01-16T14:36:27.554608"}}
{"event_type": "price_change", "event_ts": "2026-01-16T14:36:27.554608", "ingestion_ts": "2026-01-16T14:36:49.604167", "market_id": "0x50c669f178da4e5bbea7f1be25041fd278914712fa87a6a6f8e57d5923d88dee", "raw": {"market": "0x50c669f178da4e5bbea7f1be25041fd278914712fa87a6a6f8e57d5923d88dee", "asset_id": "24682525479474221428144937281315825971983904267399062415430320764754931667953", "price": "0.145", "size": "584", "side": "SELL", "timestamp": "1768574187514", "received_at": "2026-01-16T14:36:27.554608"}}
{"event_type": "price_change", "event_ts": "2026-01-16T14:36:27.554622", "ingestion_ts": "2026-01-16T14:36:49.604167", "market_id": "0x49a20c7523c271099008f3ef9a31521263b24d637959852a391e6b4697b1a437", "raw": {"market": "0x49a20c7523c271099008f3ef9a31521263b24d637959852a391e6b4697b1a437", "asset_id": "55881023621710858558280545117465775643848233756850602339827152783696837905531", "price": "0.855", "size": "292", "side": "BUY", "timestamp": "1768574187514", "received_at": "2026-01-16T14:36:27.554622"}}
{"event_type": "price_change", "event_ts": "2026-01-16T14:36:27.554622", "ingestion_ts": "2026-01-16T14:36:49.604167", "market_id": "0x49a20c7523c271099008f3ef9a31521263b24d637959852a391e6b4697b1a437", "raw": {"market": "0x49a20c7523c271099008f3ef9a31521263b24d637959852a391e6b4697b1a437", "asset_id": "13018971792603393862521629014128024641178044618205296260525674415067194037856", "price": "0.145", "size": "292", "side": "SELL", "timestamp": "1768574187514", "received_at": "2026-01-16T14:36:27.554622"}}
{"event_type": "price_change", "event_ts": "2026-01-16T14:36:27.593218", "ingestion_ts": "2026-01-16T14:36:49.604167", "market_id": "0x49686d26fb712515cd5e12c23f0a1c7e10214c7faa3cb0a730aabe0c33694082", "raw": {"market": "0x49686d26fb712515cd5e12c23f0a1c7e10214c7faa3cb0a730aabe0c33694082", "asset_id": "30442780799048074404860985387051749017905070253466005720364298335239299761065", "price": "0.005", "size": "109.51", "side": "BUY", "timestamp": "1768574187553", "received_at": "2026-01-16T14:36:27.593218"}}
{"event_type": "price_change", "event_ts": "2026-01-16T14:36:27.593218", "ingestion_ts": "2026-01-16T14:36:49.604167", "market_id": "0x49686d26fb712515cd5e12c23f0a1c7e10214c7faa3cb0a730aabe0c33694082", "raw": {"market": "0x49686d26fb712515cd5e12c23f0a1c7e10214c7faa3cb0a730aabe0c33694082", "asset_id": "13244681086321087932946246027856416106585284024824496763706748621681543444582", "price": "0.995", "size": "109.51", "side": "SELL", "timestamp": "1768574187553", "received_at": "2026-01-16T14:36:27.593218"}}
{"event_type": "price_change", "event_ts": "2026-01-16T14:36:27.593307", "ingestion_ts": "2026-01-16T14:36:49.604167", "market_id": "0x50c669f178da4e5bbea7f1be25041fd278914712fa87a6a6f8e57d5923d88dee", "raw": {"market": "0x50c669f178da4e5bbea7f1be25041fd278914712fa87a6a6f8e57d5923d88dee", "asset_id": "74040420326294854165772767082819937451857852955603897473157746262672057685461", "price": "0.856", "size": "10", "side": "BUY", "timestamp": "1768574187553", "received_at": "2026-01-16T14:36:27.593307"}}
{"event_type": "price_change", "event_ts": "2026-01-16T14:36:27.593307", "ingestion_ts": "2026-01-16T14:36:49.604167", "market_id": "0x50c669f178da4e5bbea7f1be25041fd278914712fa87a6a6f8e57d5923d88dee", "raw": {"market": "0x50c669f178da4e5bbea7f1be25041fd278914712fa87a6a6f8e57d5923d88dee", "asset_id": "24682525479474221428144937281315825971983904267399062415430320764754931667953", "price": "0.144", "size": "10", "side": "SELL", "timestamp": "1768574187553", "received_at": "2026-01-16T14:36:27.593307"}}
{"event_type": "price_change", "event_ts": "2026-01-16T14:36:27.593331", "ingestion_ts": "2026-01-16T14:36:49.604167", "market_id": "0xc55db914f0fd1fee18997706712c0dfd8d0369cdbef93a9fef12bd001914ca77", "raw": {"market": "0xc55db914f0fd1fee18997706712c0dfd8d0369cdbef93a9fef12bd001914ca77", "asset_id": "114600293444080540179603459515770723592661967180480327891296353898330242622833", "price": "0.858", "size": "10", "side": "BUY", "timestamp": "1768574187553", "received_at": "2026-01-16T14:36:27.593331"}}
{"event_type": "price_change", "event_ts": "2026-01-16T14:36:27.593331", "ingestion_ts": "2026-01-16T14:36:49.604167", "market_id": "0xc55db914f0fd1fee18997706712c0dfd8d0369cdbef93a9fef12bd001914ca77", "raw": {"market": "0xc55db914f0fd1fee18997706712c0dfd8d0369cdbef93a9fef12bd001914ca77", "asset_id": "72354723612769247426741660426331235762851940382312402276325808095604519806766", "price": "0.142", "size": "10", "side": "SELL", "timestamp": "1768574187553", "received_at": "2026-01-16T14:36:27.593331"}}
{"event_type": "price_change", "event_ts": "2026-01-16T14:36:27.593348", "ingestion_ts": "2026-01-16T14:36:49.604167", "market_id": "0x49a20c7523c271099008f3ef9a31521263b24d637959852a391e6b4697b1a437", "raw": {"market": "0x49a20c7523c271099008f3ef9a31521263b24d637959852a391e6b4697b1a437", "asset_id": "55881023621710858558280545117465775643848233756850602339827152783696837905531", "price": "0.856", "size": "40", "side": "BUY", "timestamp": "1768574187553", "received_at": "2026-01-16T14:36:27.593348"}}
{"event_type": "price_change", "event_ts": "2026-01-16T14:36:27.593348", "ingestion_ts": "2026-01-16T14:36:49.604167", "market_id": "0x49a20c7523c271099008f3ef9a31521263b24d637959852a391e6b4697b1a437", "raw": {"market": "0x49a20c7523c271099008f3ef9a31521263b24d637959852a391e6b4697b1a437", "asset_id": "13018971792603393862521629014128024641178044618205296260525674415067194037856", "price": "0.144", "size": "40", "side": "SELL", "timestamp": "1768574187553", "received_at": "2026-01-16T14:36:27.593348"}}
{"event_type": "price_change", "event_ts": "2026-01-16T14:36:27.593364", "ingestion_ts": "2026-01-16T14:36:49.604167", "market_id": "0x44f08744458b8896620cd3330bc5e1ea69df4199b02d4fc583b3fc96e5d314ce", "raw": {"market": "0x44f08744458b8896620cd3330bc5e1ea69df4199b02d4fc583b3fc96e5d314ce", "asset_id": "72327831507226612545928776794104143393438710920370371172884559893525100761096", "price": "0.854", "size": "10", "side": "BUY", "timestamp": "1768574187553", "received_at": "2026-01-16T14:36:27.593364"}}
{"event_type": "price_change", "event_ts": "2026-01-16T14:36:27.593364", "ingestion_ts": "2026-01-16T14:36:49.604167", "market_id": "0x44f08744458b8896620cd3330bc5e1ea69df4199b02d4fc583b3fc96e5d314ce", "raw": {"market": "0x44f08744458b8896620cd3330bc5e1ea69df4199b02d4fc583b3fc96e5d314ce", "asset_id": "49194009556504828848509244326501559253829462790583873936160989575507522044057", "price": "0.146", "size": "10", "side": "SELL", "timestamp": "1768574187553", "received_at": "2026-01-16T14:36:27.593364"}}
{"event_type": "price_change", "event_ts": "2026-01-16T14:36:28.146271", "ingestion_ts": "2026-01-16T14:36:49.604167", "market_id": "0x9472be65457510b7fc3477b20ba90910e99d92eac8421a14bf4b7b7a08ef31dc", "raw": {"market": "0x9472be65457510b7fc3477b20ba90910e99d92eac8421a14bf4b7b7a08ef31dc", "asset_id": "43311793366960417907757893276427136943959788721376762326430771171648759300146", "price": "0.856", "size": "0", "side": "BUY", "timestamp": "1768574188104", "received_at": "2026-01-16T14:36:28.146271"}}
{"event_type": "price_change", "event_ts": "2026-01-16T14:36:28.146271", "ingestion_ts": "2026-01-16T14:36:49.604167", "market_id": "0x9472be65457510b7fc3477b20ba90910e99d92eac8421a14bf4b7b7a08ef31dc", "raw": {"market": "0x9472be65457510b7fc3477b20ba90910e99d92eac8421a14bf4b7b7a08ef31dc", "asset_id": "73414222381656326204771753454630063673548497164758947581648273905027617570612", "price": "0.144", "size": "0", "side": "SELL", "timestamp": "1768574188104", "received_at": "2026-01-16T14:36:28.146271"}}
{"event_type": "price_change", "event_ts": "2026-01-16T14:36:28.146343", "ingestion_ts": "2026-01-16T14:36:49.604167", "market_id": "0x50c669f178da4e5bbea7f1be25041fd278914712fa87a6a6f8e57d5923d88dee", "raw": {"market": "0x50c669f178da4e5bbea7f1be25041fd278914712fa87a6a6f8e57d5923d88dee", "asset_id": "74040420326294854165772767082819937451857852955603897473157746262672057685461", "price": "0.856", "size": "0", "side": "BUY", "timestamp": "1768574188104", "received_at": "2026-01-16T14:36:28.146343"}}
{"event_type": "price_change", "event_ts": "2026-01-16T14:36:28.146343", "ingestion_ts": "2026-01-16T14:36:49.604167", "market_id": "0x50c669f178da4e5bbea7f1be25041fd278914712fa87a6a6f8e57d5923d88dee", "raw": {"market": "0x50c669f178da4e5bbea7f1be25041fd278914712fa87a6a6f8e57d5923d88dee", "asset_id": "24682525479474221428144937281315825971983904267399062415430320764754931667953", "price": "0.144", "size": "0", "side": "SELL", "timestamp": "1768574188104", "received_at": "2026-01-16T14:36:28.146343"}}
{"event_type": "price_change", "event_ts": "2026-01-16T14:36:28.146367", "ingestion_ts": "2026-01-16T14:36:49.604167", "market_id": "0x2393ed0b0fdc450054c7b9071907eca75cf4fc36e385adf4a0a5f99ee62243e8", "raw": {"market": "0x2393ed0b0fdc450054c7b9071907eca75cf4fc36e385adf4a0a5f99ee62243e8", "asset_id": "32769749367306925959219403371425714180265458150646381231272229429098460625924", "price": "0.811", "size": "0", "side": "BUY", "timestamp": "1768574188104", "received_at": "2026-01-16T14:36:28.146367"}}
{"event_type": "price_change", "event_ts": "2026-01-16T14:36:28.146367", "ingestion_ts": "2026-01-16T14:36:49.604167", "market_id": "0x2393ed0b0fdc450054c7b9071907eca75cf4fc36e385adf4a0a5f99ee62243e8", "raw": {"market": "0x2393ed0b0fdc450054c7b9071907eca75cf4fc36e385adf4a0a5f99ee62243e8", "asset_id": "100074770378634056601572485653252702850363676459996771990439989989293515601975", "price": "0.189", "size": "0", "side": "SELL", "timestamp": "1768574188104", "received_at": "2026-01-16T14:36:28.146367"}}
{"event_type": "price_change", "event_ts": "2026-01-16T14:36:28.146391", "ingestion_ts": "2026-01-16T14:36:49.604167", "market_id": "0x49a20c7523c271099008f3ef9a31521263b24d637959852a391e6b4697b1a437", "raw": {"market": "0x49a20c7523c271099008f3ef9a31521263b24d637959852a391e6b4697b1a437", "asset_id": "55881023621710858558280545117465775643848233756850602339827152783696837905531", "price": "0.856", "size": "30", "side": "BUY", "timestamp": "1768574188104", "received_at": "2026-01-16T14:36:28.146391"}}
{"event_type": "price_change", "event_ts": "2026-01-16T14:36:28.146391", "ingestion_ts": "2026-01-16T14:36:49.604167", "market_id": "0x49a20c7523c271099008f3ef9a31521263b24d637959852a391e6b4697b1a437", "raw": {"market": "0x49a20c7523c271099008f3ef9a31521263b24d637959852a391e6b4697b1a437", "asset_id": "13018971792603393862521629014128024641178044618205296260525674415067194037856", "price": "0.144", "size": "30", "side": "SELL", "timestamp": "1768574188104", "received_at": "2026-01-16T14:36:28.146391"}}
{"event_type": "price_change", "event_ts": "2026-01-16T14:36:28.146413", "ingestion_ts": "2026-01-16T14:36:49.604167", "market_id": "0x49686d26fb712515cd5e12c23f0a1c7e10214c7faa3cb0a730aabe0c33694082", "raw": {"market": "0x49686d26fb712515cd5e12c23f0a1c7e10214c7faa3cb0a730aabe0c33694082", "asset_id": "30442780799048074404860985387051749017905070253466005720364298335239299761065", "price": "0.005", "size": "99.51", "side": "BUY", "timestamp": "1768574188104", "received_at": "2026-01-16T14:36:28.146413"}}
{"event_type": "price_change", "event_ts": "2026-01-16T14:36:28.146413", "ingestion_ts": "2026-01-16T14:36:49.604167", "market_id": "0x49686d26fb712515cd5e12c23f0a1c7e10214c7faa3cb0a730aabe0c33694082", "raw": {"market": "0x49686d26fb712515cd5e12c23f0a1c7e10214c7faa3cb0a730aabe0c33694082", "asset_id": "13244681086321087932946246027856416106585284024824496763706748621681543444582", "price": "0.995", "size": "99.51", "side": "SELL", "timestamp": "1768574188104", "received_at": "2026-01-16T14:36:28.146413"}}
{"event_type": "price_change", "event_ts": "2026-01-16T14:36:28.146435", "ingestion_ts": "2026-01-16T14:36:49.604167", "market_id": "0xc55db914f0fd1fee18997706712c0dfd8d0369cdbef93a9fef12bd001914ca77", "raw": {"market": "0xc55db914f0fd1fee18997706712c0dfd8d0369cdbef93a9fef12bd001914ca77", "asset_id": "114600293444080540179603459515770723592661967180480327891296353898330242622833", "price": "0.858", "size": "0", "side": "BUY", "timestamp": "1768574188104", "received_at": "2026-01-16T14:36:28.146435"}}
{"event_type": "price_change", "event_ts": "2026-01-16T14:36:28.146435", "ingestion_ts": "2026-01-16T14:36:49.604167", "market_id": "0xc55db914f0fd1fee18997706712c0dfd8d0369cdbef93a9fef12bd001914ca77", "raw": {"market": "0xc55db914f0fd1fee18997706712c0dfd8d0369cdbef93a9fef12bd001914ca77", "asset_id": "72354723612769247426741660426331235762851940382312402276325808095604519806766", "price": "0.142", "size": "0", "side": "SELL", "timestamp": "1768574188104", "received_at": "2026-01-16T14:36:28.146435"}}
{"event_type": "price_change", "event_ts": "2026-01-16T14:36:28.183024", "ingestion_ts": "2026-01-16T14:36:49.604167", "market_id": "0x50c669f178da4e5bbea7f1be25041fd278914712fa87a6a6f8e57d5923d88dee", "raw": {"market": "0x50c669f178da4e5bbea7f1be25041fd278914712fa87a6a6f8e57d5923d88dee", "asset_id": "74040420326294854165772767082819937451857852955603897473157746262672057685461", "price": "0.857", "size": "35", "side": "BUY", "timestamp": "1768574188146", "received_at": "2026-01-16T14:36:28.183024"}}
{"event_type": "price_change", "event_ts": "2026-01-16T14:36:28.183024", "ingestion_ts": "2026-01-16T14:36:49.604167", "market_id": "0x50c669f178da4e5bbea7f1be25041fd278914712fa87a6a6f8e57d5923d88dee", "raw": {"market": "0x50c669f178da4e5bbea7f1be25041fd278914712fa87a6a6f8e57d5923d88dee", "asset_id": "24682525479474221428144937281315825971983904267399062415430320764754931667953", "price": "0.143", "size": "35", "side": "SELL", "timestamp": "1768574188146", "received_at": "2026-01-16T14:36:28.183024"}}
{"event_type": "price_change", "event_ts": "2026-01-16T14:36:28.183107", "ingestion_ts": "2026-01-16T14:36:49.604167", "market_id": "0xc55db914f0fd1fee18997706712c0dfd8d0369cdbef93a9fef12bd001914ca77", "raw": {"market": "0xc55db914f0fd1fee18997706712c0dfd8d0369cdbef93a9fef12bd001914ca77", "asset_id": "114600293444080540179603459515770723592661967180480327891296353898330242622833", "price": "0.859", "size": "40", "side": "BUY", "timestamp": "1768574188146", "received_at": "2026-01-16T14:36:28.183107"}}
{"event_type": "price_change", "event_ts": "2026-01-16T14:36:28.183107", "ingestion_ts": "2026-01-16T14:36:49.604167", "market_id": "0xc55db914f0fd1fee18997706712c0dfd8d0369cdbef93a9fef12bd001914ca77", "raw": {"market": "0xc55db914f0fd1fee18997706712c0dfd8d0369cdbef93a9fef12bd001914ca77", "asset_id": "72354723612769247426741660426331235762851940382312402276325808095604519806766", "price": "0.141", "size": "40", "side": "SELL", "timestamp": "1768574188146", "received_at": "2026-01-16T14:36:28.183107"}}
{"event_type": "price_change", "event_ts": "2026-01-16T14:36:28.183137", "ingestion_ts": "2026-01-16T14:36:49.604167", "market_id": "0x49a20c7523c271099008f3ef9a31521263b24d637959852a391e6b4697b1a437", "raw": {"market": "0x49a20c7523c271099008f3ef9a31521263b24d637959852a391e6b4697b1a437", "asset_id": "55881023621710858558280545117465775643848233756850602339827152783696837905531", "price": "0.857", "size": "10", "side": "BUY", "timestamp": "1768574188146", "received_at": "2026-01-16T14:36:28.183137"}}
{"event_type": "price_change", "event_ts": "2026-01-16T14:36:28.183137", "ingestion_ts": "2026-01-16T14:36:49.604167", "market_id": "0x49a20c7523c271099008f3ef9a31521263b24d637959852a391e6b4697b1a437", "raw": {"market": "0x49a20c7523c271099008f3ef9a31521263b24d637959852a391e6b4697b1a437", "asset_id": "13018971792603393862521629014128024641178044618205296260525674415067194037856", "price": "0.143", "size": "10", "side": "SELL", "timestamp": "1768574188146", "received_at": "2026-01-16T14:36:28.183137"}}
{"event_type": "price_change", "event_ts": "2026-01-16T14:36:28.183390", "ingestion_ts": "2026-01-16T14:36:49.604167", "market_id": "0x9472be65457510b7fc3477b20ba90910e99d92eac8421a14bf4b7b7a08ef31dc", "raw": {"market": "0x9472be65457510b7fc3477b20ba90910e99d92eac8421a14bf4b7b7a08ef31dc", "asset_id": "43311793366960417907757893276427136943959788721376762326430771171648759300146", "price": "0.858", "size": "243", "side": "BUY", "timestamp": "1768574188146", "received_at": "2026-01-16T14:36:28.183390"}}
{"event_type": "price_change", "event_ts": "2026-01-16T14:36:28.183390", "ingestion_ts": "2026-01-16T14:36:49.604167", "market_id": "0x9472be65457510b7fc3477b20ba90910e99d92eac8421a14bf4b7b7a08ef31dc", "raw": {"market": "0x9472be65457510b7fc3477b20ba90910e99d92eac8421a14bf4b7b7a08ef31dc", "asset_id": "73414222381656326204771753454630063673548497164758947581648273905027617570612", "price": "0.142", "size": "243", "side": "SELL", "timestamp": "1768574188146", "received_at": "2026-01-16T14:36:28.183390"}}
{"event_type": "price_change", "event_ts": "2026-01-16T14:36:28.183423", "ingestion_ts": "2026-01-16T14:36:49.604167", "market_id": "0x2393ed0b0fdc450054c7b9071907eca75cf4fc36e385adf4a0a5f99ee62243e8", "raw": {"market": "0x2393ed0b0fdc450054c7b9071907eca75cf4fc36e385adf4a0a5f99ee62243e8", "asset_id": "32769749367306925959219403371425714180265458150646381231272229429098460625924", "price": "0.849", "size": "304", "side": "BUY", "timestamp": "1768574188146", "received_at": "2026-01-16T14:36:28.183423"}}
{"event_type": "price_change", "event_ts": "2026-01-16T14:36:28.183423", "ingestion_ts": "2026-01-16T14:36:49.604167", "market_id": "0x2393ed0b0fdc450054c7b9071907eca75cf4fc36e385adf4a0a5f99ee62243e8", "raw": {"market": "0x2393ed0b0fdc450054c7b9071907eca75cf4fc36e385adf4a0a5f99ee62243e8", "asset_id": "100074770378634056601572485653252702850363676459996771990439989989293515601975", "price": "0.151", "size": "304", "side": "SELL", "timestamp": "1768574188146", "received_at": "2026-01-16T14:36:28.183423"}}
{"event_type": "price_change", "event_ts": "2026-01-16T14:36:28.183447", "ingestion_ts": "2026-01-16T14:36:49.604167", "market_id": "0x49686d26fb712515cd5e12c23f0a1c7e10214c7faa3cb0a730aabe0c33694082", "raw": {"market": "0x49686d26fb712515cd5e12c23f0a1c7e10214c7faa3cb0a730aabe0c33694082", "asset_id": "30442780799048074404860985387051749017905070253466005720364298335239299761065", "price": "0.006", "size": "20.08", "side": "BUY", "timestamp": "1768574188146", "received_at": "2026-01-16T14:36:28.183447"}}
{"event_type": "price_change", "event_ts": "2026-01-16T14:36:28.183447", "ingestion_ts": "2026-01-16T14:36:49.604167", "market_id": "0x49686d26fb712515cd5e12c23f0a1c7e10214c7faa3cb0a730aabe0c33694082", "raw": {"market": "0x49686d26fb712515cd5e12c23f0a1c7e10214c7faa3cb0a730aabe0c33694082", "asset_id": "13244681086321087932946246027856416106585284024824496763706748621681543444582", "price": "0.994", "size": "20.08", "side": "SELL", "timestamp": "1768574188146", "received_at": "2026-01-16T14:36:28.183447"}}
{"event_type": "price_change", "event_ts": "2026-01-16T14:36:28.303217", "ingestion_ts": "2026-01-16T14:36:49.604167", "market_id": "0xc0e6b917320a47228fb96e3b5ae0e5c93773a5ae2662ae4e1f37807cfe47ce98", "raw": {"market": "0xc0e6b917320a47228fb96e3b5ae0e5c93773a5ae2662ae4e1f37807cfe47ce98", "asset_id": "58656358377246279051017109359677190749228949103591068167284263961542487110215", "price": "0.002", "size": "3287.1", "side": "BUY", "timestamp": "1768574188267", "received_at": "2026-01-16T14:36:28.303217"}}
{"event_type": "price_change", "event_ts": "2026-01-16T14:36:28.303217", "ingestion_ts": "2026-01-16T14:36:49.604167", "market_id": "0xc0e6b917320a47228fb96e3b5ae0e5c93773a5ae2662ae4e1f37807cfe47ce98", "raw": {"market": "0xc0e6b917320a47228fb96e3b5ae0e5c93773a5ae2662ae4e1f37807cfe47ce98", "asset_id": "81647294538046680798858716589766492074338758116170717123345952330712416337530", "price": "0.998", "size": "3287.1", "side": "SELL", "timestamp": "1768574188267", "received_at": "2026-01-16T14:36:28.303217"}}
{"event_type": "price_change", "event_ts": "2026-01-16T14:36:28.306254", "ingestion_ts": "2026-01-16T14:36:49.604167", "market_id": "0xc0e6b917320a47228fb96e3b5ae0e5c93773a5ae2662ae4e1f37807cfe47ce98", "raw": {"market": "0xc0e6b917320a47228fb96e3b5ae0e5c93773a5ae2662ae4e1f37807cfe47ce98", "asset_id": "58656358377246279051017109359677190749228949103591068167284263961542487110215", "price": "0.002", "size": "3294.21", "side": "BUY", "timestamp": "1768574188268", "received_at": "2026-01-16T14:36:28.306254"}}
{"event_type": "price_change", "event_ts": "2026-01-16T14:36:28.306254", "ingestion_ts": "2026-01-16T14:36:49.604167", "market_id": "0xc0e6b917320a47228fb96e3b5ae0e5c93773a5ae2662ae4e1f37807cfe47ce98", "raw": {"market": "0xc0e6b917320a47228fb96e3b5ae0e5c93773a5ae2662ae4e1f37807cfe47ce98", "asset_id": "81647294538046680798858716589766492074338758116170717123345952330712416337530", "price": "0.998", "size": "3294.21", "side": "SELL", "timestamp": "1768574188268", "received_at": "2026-01-16T14:36:28.306254"}}
{"event_type": "price_change", "event_ts": "2026-01-16T14:36:29.655106", "ingestion_ts": "2026-01-16T14:36:49.604167", "market_id": "0x49686d26fb712515cd5e12c23f0a1c7e10214c7faa3cb0a730aabe0c33694082", "raw": {"market": "0x49686d26fb712515cd5e12c23f0a1c7e10214c7faa3cb0a730aabe0c33694082", "asset_id": "30442780799048074404860985387051749017905070253466005720364298335239299761065", "price": "0.003", "size": "15.78", "side": "BUY", "timestamp": "1768574189617", "received_at": "2026-01-16T14:36:29.655106"}}
{"event_type": "price_change", "event_ts": "2026-01-16T14:36:29.655106", "ingestion_ts": "2026-01-16T14:36:49.604167", "market_id": "0x49686d26fb712515cd5e12c23f0a1c7e10214c7faa3cb0a730aabe0c33694082", "raw": {"market": "0x49686d26fb712515cd5e12c23f0a1c7e10214c7faa3cb0a730aabe0c33694082", "asset_id": "13244681086321087932946246027856416106585284024824496763706748621681543444582", "price": "0.997", "size": "15.78", "side": "SELL", "timestamp": "1768574189617", "received_at": "2026-01-16T14:36:29.655106"}}
{"event_type": "price_change", "event_ts": "2026-01-16T14:36:29.656118", "ingestion_ts": "2026-01-16T14:36:49.604167", "market_id": "0x49686d26fb712515cd5e12c23f0a1c7e10214c7faa3cb0a730aabe0c33694082", "raw": {"market": "0x49686d26fb712515cd5e12c23f0a1c7e10214c7faa3cb0a730aabe0c33694082", "asset_id": "30442780799048074404860985387051749017905070253466005720364298335239299761065", "price": "0.011", "size": "0", "side": "BUY", "timestamp": "1768574189617", "received_at": "2026-01-16T14:36:29.656118"}}
{"event_type": "price_change", "event_ts": "2026-01-16T14:36:29.656118", "ingestion_ts": "2026-01-16T14:36:49.604167", "market_id": "0x49686d26fb712515cd5e12c23f0a1c7e10214c7faa3cb0a730aabe0c33694082", "raw": {"market": "0x49686d26fb712515cd5e12c23f0a1c7e10214c7faa3cb0a730aabe0c33694082", "asset_id": "13244681086321087932946246027856416106585284024824496763706748621681543444582", "price": "0.989", "size": "0", "side": "SELL", "timestamp": "1768574189617", "received_at": "2026-01-16T14:36:29.656118"}}
{"event_type": "price_change", "event_ts": "2026-01-16T14:36:29.936086", "ingestion_ts": "2026-01-16T14:36:49.604167", "market_id": "0x49686d26fb712515cd5e12c23f0a1c7e10214c7faa3cb0a730aabe0c33694082", "raw": {"market": "0x49686d26fb712515cd5e12c23f0a1c7e10214c7faa3cb0a730aabe0c33694082", "asset_id": "13244681086321087932946246027856416106585284024824496763706748621681543444582", "price": "0.854", "size": "0", "side": "BUY", "timestamp": "1768574189899", "received_at": "2026-01-16T14:36:29.936086"}}
{"event_type": "price_change", "event_ts": "2026-01-16T14:36:29.936086", "ingestion_ts": "2026-01-16T14:36:49.604167", "market_id": "0x49686d26fb712515cd5e12c23f0a1c7e10214c7faa3cb0a730aabe0c33694082", "raw": {"market": "0x49686d26fb712515cd5e12c23f0a1c7e10214c7faa3cb0a730aabe0c33694082", "asset_id": "30442780799048074404860985387051749017905070253466005720364298335239299761065", "price": "0.146", "size": "0", "side": "SELL", "timestamp": "1768574189899", "received_at": "2026-01-16T14:36:29.936086"}}
{"event_type": "price_change", "event_ts": "2026-01-16T14:36:29.965868", "ingestion_ts": "2026-01-16T14:36:49.604167", "market_id": "0x49686d26fb712515cd5e12c23f0a1c7e10214c7faa3cb0a730aabe0c33694082", "raw": {"market": "0x49686d26fb712515cd5e12c23f0a1c7e10214c7faa3cb0a730aabe0c33694082", "asset_id": "13244681086321087932946246027856416106585284024824496763706748621681543444582", "price": "0.911", "size": "134.98", "side": "SELL", "timestamp": "1768574189927", "received_at": "2026-01-16T14:36:29.965868"}}
{"event_type": "price_change", "event_ts": "2026-01-16T14:36:29.965868", "ingestion_ts": "2026-01-16T14:36:49.604167", "market_id": "0x49686d26fb712515cd5e12c23f0a1c7e10214c7faa3cb0a730aabe0c33694082", "raw": {"market": "0x49686d26fb712515cd5e12c23f0a1c7e10214c7faa3cb0a730aabe0c33694082", "asset_id": "30442780799048074404860985387051749017905070253466005720364298335239299761065", "price": "0.089", "size": "134.98", "side": "BUY", "timestamp": "1768574189927", "received_at": "2026-01-16T14:36:29.965868"}}
{"event_type": "price_change", "event_ts": "2026-01-16T14:36:29.993099", "ingestion_ts": "2026-01-16T14:36:49.604167", "market_id": "0xae5584fbb57f23c1c608d544b656f23d8bf12340cef70811cf31bb0cb4fc2115", "raw": {"market": "0xae5584fbb57f23c1c608d544b656f23d8bf12340cef70811cf31bb0cb4fc2115", "asset_id": "42278252558046940014991595990628759801692726198478046188873057685686228021663", "price": "0.99", "size": "8193.2", "side": "SELL", "timestamp": "1768574189957", "received_at": "2026-01-16T14:36:29.993099"}}
{"event_type": "price_change", "event_ts": "2026-01-16T14:36:29.993099", "ingestion_ts": "2026-01-16T14:36:49.604167", "market_id": "0xae5584fbb57f23c1c608d544b656f23d8bf12340cef70811cf31bb0cb4fc2115", "raw": {"market": "0xae5584fbb57f23c1c608d544b656f23d8bf12340cef70811cf31bb0cb4fc2115", "asset_id": "28946595841244317705636126646676849578876740730186646421280828201004700559420", "price": "0.01", "size": "8193.2", "side": "BUY", "timestamp": "1768574189957", "received_at": "2026-01-16T14:36:29.993099"}}
{"event_type": "price_change", "event_ts": "2026-01-16T14:36:30.128378", "ingestion_ts": "2026-01-16T14:36:49.604167", "market_id": "0xae5584fbb57f23c1c608d544b656f23d8bf12340cef70811cf31bb0cb4fc2115", "raw": {"market": "0xae5584fbb57f23c1c608d544b656f23d8bf12340cef70811cf31bb0cb4fc2115", "asset_id": "28946595841244317705636126646676849578876740730186646421280828201004700559420", "price": "0.01", "size": "8241", "side": "BUY", "timestamp": "1768574190059", "received_at": "2026-01-16T14:36:30.128378"}}
{"event_type": "price_change", "event_ts": "2026-01-16T14:36:30.128378", "ingestion_ts": "2026-01-16T14:36:49.604167", "market_id": "0xae5584fbb57f23c1c608d544b656f23d8bf12340cef70811cf31bb0cb4fc2115", "raw": {"market": "0xae5584fbb57f23c1c608d544b656f23d8bf12340cef70811cf31bb0cb4fc2115", "asset_id": "42278252558046940014991595990628759801692726198478046188873057685686228021663", "price": "0.99", "size": "8241", "side": "SELL", "timestamp": "1768574190059", "received_at": "2026-01-16T14:36:30.128378"}}
{"event_type": "price_change", "event_ts": "2026-01-16T14:36:30.133184", "ingestion_ts": "2026-01-16T14:36:49.604167", "market_id": "0x49686d26fb712515cd5e12c23f0a1c7e10214c7faa3cb0a730aabe0c33694082", "raw": {"market": "0x49686d26fb712515cd5e12c23f0a1c7e10214c7faa3cb0a730aabe0c33694082", "asset_id": "30442780799048074404860985387051749017905070253466005720364298335239299761065", "price": "0.011", "size": "19.57", "side": "BUY", "timestamp": "1768574190066", "received_at": "2026-01-16T14:36:30.133184"}}
{"event_type": "price_change", "event_ts": "2026-01-16T14:36:30.133184", "ingestion_ts": "2026-01-16T14:36:49.604167", "market_id": "0x49686d26fb712515cd5e12c23f0a1c7e10214c7faa3cb0a730aabe0c33694082", "raw": {"market": "0x49686d26fb712515cd5e12c23f0a1c7e10214c7faa3cb0a730aabe0c33694082", "asset_id": "13244681086321087932946246027856416106585284024824496763706748621681543444582", "price": "0.989", "size": "19.57", "side": "SELL", "timestamp": "1768574190066", "received_at": "2026-01-16T14:36:30.133184"}}
{"event_type": "price_change", "event_ts": "2026-01-16T14:36:30.133952", "ingestion_ts": "2026-01-16T14:36:49.604167", "market_id": "0x49686d26fb712515cd5e12c23f0a1c7e10214c7faa3cb0a730aabe0c33694082", "raw": {"market": "0x49686d26fb712515cd5e12c23f0a1c7e10214c7faa3cb0a730aabe0c33694082", "asset_id": "30442780799048074404860985387051749017905070253466005720364298335239299761065", "price": "0.003", "size": "31.2", "side": "BUY", "timestamp": "1768574190068", "received_at": "2026-01-16T14:36:30.133952"}}
{"event_type": "price_change", "event_ts": "2026-01-16T14:36:30.133952", "ingestion_ts": "2026-01-16T14:36:49.604167", "market_id": "0x49686d26fb712515cd5e12c23f0a1c7e10214c7faa3cb0a730aabe0c33694082", "raw": {"market": "0x49686d26fb712515cd5e12c23f0a1c7e10214c7faa3cb0a730aabe0c33694082", "asset_id": "13244681086321087932946246027856416106585284024824496763706748621681543444582", "price": "0.997", "size": "31.2", "side": "SELL", "timestamp": "1768574190068", "received_at": "2026-01-16T14:36:30.133952"}}
{"event_type": "price_change", "event_ts": "2026-01-16T14:36:30.643990", "ingestion_ts": "2026-01-16T14:36:49.604167", "market_id": "0xc0e6b917320a47228fb96e3b5ae0e5c93773a5ae2662ae4e1f37807cfe47ce98", "raw": {"market": "0xc0e6b917320a47228fb96e3b5ae0e5c93773a5ae2662ae4e1f37807cfe47ce98", "asset_id": "58656358377246279051017109359677190749228949103591068167284263961542487110215", "price": "0.002", "size": "3287.1", "side": "BUY", "timestamp": "1768574190586", "received_at": "2026-01-16T14:36:30.643990"}}
{"event_type": "price_change", "event_ts": "2026-01-16T14:36:30.643990", "ingestion_ts": "2026-01-16T14:36:49.604167", "market_id": "0xc0e6b917320a47228fb96e3b5ae0e5c93773a5ae2662ae4e1f37807cfe47ce98", "raw": {"market": "0xc0e6b917320a47228fb96e3b5ae0e5c93773a5ae2662ae4e1f37807cfe47ce98", "asset_id": "81647294538046680798858716589766492074338758116170717123345952330712416337530", "price": "0.998", "size": "3287.1", "side": "SELL", "timestamp": "1768574190586", "received_at": "2026-01-16T14:36:30.643990"}}
{"event_type": "price_change", "event_ts": "2026-01-16T14:36:31.126741", "ingestion_ts": "2026-01-16T14:36:49.604167", "market_id": "0x50c669f178da4e5bbea7f1be25041fd278914712fa87a6a6f8e57d5923d88dee", "raw": {"market": "0x50c669f178da4e5bbea7f1be25041fd278914712fa87a6a6f8e57d5923d88dee", "asset_id": "74040420326294854165772767082819937451857852955603897473157746262672057685461", "price": "0.857", "size": "25", "side": "BUY", "timestamp": "1768574191085", "received_at": "2026-01-16T14:36:31.126741"}}
{"event_type": "price_change", "event_ts": "2026-01-16T14:36:31.126741", "ingestion_ts": "2026-01-16T14:36:49.604167", "market_id": "0x50c669f178da4e5bbea7f1be25041fd278914712fa87a6a6f8e57d5923d88dee", "raw": {"market": "0x50c669f178da4e5bbea7f1be25041fd278914712fa87a6a6f8e57d5923d88dee", "asset_id": "24682525479474221428144937281315825971983904267399062415430320764754931667953", "price": "0.143", "size": "25", "side": "SELL", "timestamp": "1768574191085", "received_at": "2026-01-16T14:36:31.126741"}}
{"event_type": "price_change", "event_ts": "2026-01-16T14:36:31.126783", "ingestion_ts": "2026-01-16T14:36:49.604167", "market_id": "0x9472be65457510b7fc3477b20ba90910e99d92eac8421a14bf4b7b7a08ef31dc", "raw": {"market": "0x9472be65457510b7fc3477b20ba90910e99d92eac8421a14bf4b7b7a08ef31dc", "asset_id": "43311793366960417907757893276427136943959788721376762326430771171648759300146", "price": "0.858", "size": "233", "side": "BUY", "timestamp": "1768574191085", "received_at": "2026-01-16T14:36:31.126783"}}
{"event_type": "price_change", "event_ts": "2026-01-16T14:36:31.126783", "ingestion_ts": "2026-01-16T14:36:49.604167", "market_id": "0x9472be65457510b7fc3477b20ba90910e99d92eac8421a14bf4b7b7a08ef31dc", "raw": {"market": "0x9472be65457510b7fc3477b20ba90910e99d92eac8421a14bf4b7b7a08ef31dc", "asset_id": "73414222381656326204771753454630063673548497164758947581648273905027617570612", "price": "0.142", "size": "233", "side": "SELL", "timestamp": "1768574191085", "received_at": "2026-01-16T14:36:31.126783"}}
{"event_type": "price_change", "event_ts": "2026-01-16T14:36:31.126797", "ingestion_ts": "2026-01-16T14:36:49.604167", "market_id": "0x49a20c7523c271099008f3ef9a31521263b24d637959852a391e6b4697b1a437", "raw": {"market": "0x49a20c7523c271099008f3ef9a31521263b24d637959852a391e6b4697b1a437", "asset_id": "55881023621710858558280545117465775643848233756850602339827152783696837905531", "price": "0.857", "size": "0", "side": "BUY", "timestamp": "1768574191085", "received_at": "2026-01-16T14:36:31.126797"}}
{"event_type": "price_change", "event_ts": "2026-01-16T14:36:31.126797", "ingestion_ts": "2026-01-16T14:36:49.604167", "market_id": "0x49a20c7523c271099008f3ef9a31521263b24d637959852a391e6b4697b1a437", "raw": {"market": "0x49a20c7523c271099008f3ef9a31521263b24d637959852a391e6b4697b1a437", "asset_id": "13018971792603393862521629014128024641178044618205296260525674415067194037856", "price": "0.143", "size": "0", "side": "SELL", "timestamp": "1768574191085", "received_at": "2026-01-16T14:36:31.126797"}}
{"event_type": "price_change", "event_ts": "2026-01-16T14:36:31.126811", "ingestion_ts": "2026-01-16T14:36:49.604167", "market_id": "0x2393ed0b0fdc450054c7b9071907eca75cf4fc36e385adf4a0a5f99ee62243e8", "raw": {"market": "0x2393ed0b0fdc450054c7b9071907eca75cf4fc36e385adf4a0a5f99ee62243e8", "asset_id": "32769749367306925959219403371425714180265458150646381231272229429098460625924", "price": "0.849", "size": "294", "side": "BUY", "timestamp": "1768574191085", "received_at": "2026-01-16T14:36:31.126811"}}
{"event_type": "price_change", "event_ts": "2026-01-16T14:36:31.126811", "ingestion_ts": "2026-01-16T14:36:49.604167", "market_id": "0x2393ed0b0fdc450054c7b9071907eca75cf4fc36e385adf4a0a5f99ee62243e8", "raw": {"market": "0x2393ed0b0fdc450054c7b9071907eca75cf4fc36e385adf4a0a5f99ee62243e8", "asset_id": "100074770378634056601572485653252702850363676459996771990439989989293515601975", "price": "0.151", "size": "294", "side": "SELL", "timestamp": "1768574191085", "received_at": "2026-01-16T14:36:31.126811"}}
{"event_type": "price_change", "event_ts": "2026-01-16T14:36:31.126823", "ingestion_ts": "2026-01-16T14:36:49.604167", "market_id": "0xc55db914f0fd1fee18997706712c0dfd8d0369cdbef93a9fef12bd001914ca77", "raw": {"market": "0xc55db914f0fd1fee18997706712c0dfd8d0369cdbef93a9fef12bd001914ca77", "asset_id": "114600293444080540179603459515770723592661967180480327891296353898330242622833", "price": "0.859", "size": "30", "side": "BUY", "timestamp": "1768574191085", "received_at": "2026-01-16T14:36:31.126823"}}
{"event_type": "price_change", "event_ts": "2026-01-16T14:36:31.126823", "ingestion_ts": "2026-01-16T14:36:49.604167", "market_id": "0xc55db914f0fd1fee18997706712c0dfd8d0369cdbef93a9fef12bd001914ca77", "raw": {"market": "0xc55db914f0fd1fee18997706712c0dfd8d0369cdbef93a9fef12bd001914ca77", "asset_id": "72354723612769247426741660426331235762851940382312402276325808095604519806766", "price": "0.141", "size": "30", "side": "SELL", "timestamp": "1768574191085", "received_at": "2026-01-16T14:36:31.126823"}}
{"event_type": "price_change", "event_ts": "2026-01-16T14:36:31.162909", "ingestion_ts": "2026-01-16T14:36:49.604167", "market_id": "0x2393ed0b0fdc450054c7b9071907eca75cf4fc36e385adf4a0a5f99ee62243e8", "raw": {"market": "0x2393ed0b0fdc450054c7b9071907eca75cf4fc36e385adf4a0a5f99ee62243e8", "asset_id": "32769749367306925959219403371425714180265458150646381231272229429098460625924", "price": "0.811", "size": "10", "side": "BUY", "timestamp": "1768574191124", "received_at": "2026-01-16T14:36:31.162909"}}
{"event_type": "price_change", "event_ts": "2026-01-16T14:36:31.162909", "ingestion_ts": "2026-01-16T14:36:49.604167", "market_id": "0x2393ed0b0fdc450054c7b9071907eca75cf4fc36e385adf4a0a5f99ee62243e8", "raw": {"market": "0x2393ed0b0fdc450054c7b9071907eca75cf4fc36e385adf4a0a5f99ee62243e8", "asset_id": "100074770378634056601572485653252702850363676459996771990439989989293515601975", "price": "0.189", "size": "10", "side": "SELL", "timestamp": "1768574191124", "received_at": "2026-01-16T14:36:31.162909"}}
{"event_type": "price_change", "event_ts": "2026-01-16T14:36:31.162950", "ingestion_ts": "2026-01-16T14:36:49.604167", "market_id": "0x9472be65457510b7fc3477b20ba90910e99d92eac8421a14bf4b7b7a08ef31dc", "raw": {"market": "0x9472be65457510b7fc3477b20ba90910e99d92eac8421a14bf4b7b7a08ef31dc", "asset_id": "43311793366960417907757893276427136943959788721376762326430771171648759300146", "price": "0.856", "size": "10", "side": "BUY", "timestamp": "1768574191124", "received_at": "2026-01-16T14:36:31.162950"}}
{"event_type": "price_change", "event_ts": "2026-01-16T14:36:31.162950", "ingestion_ts": "2026-01-16T14:36:49.604167", "market_id": "0x9472be65457510b7fc3477b20ba90910e99d92eac8421a14bf4b7b7a08ef31dc", "raw": {"market": "0x9472be65457510b7fc3477b20ba90910e99d92eac8421a14bf4b7b7a08ef31dc", "asset_id": "73414222381656326204771753454630063673548497164758947581648273905027617570612", "price": "0.144", "size": "10", "side": "SELL", "timestamp": "1768574191124", "received_at": "2026-01-16T14:36:31.162950"}}
{"event_type": "price_change", "event_ts": "2026-01-16T14:36:31.162966", "ingestion_ts": "2026-01-16T14:36:49.604167", "market_id": "0xc55db914f0fd1fee18997706712c0dfd8d0369cdbef93a9fef12bd001914ca77", "raw": {"market": "0xc55db914f0fd1fee18997706712c0dfd8d0369cdbef93a9fef12bd001914ca77", "asset_id": "114600293444080540179603459515770723592661967180480327891296353898330242622833", "price": "0.858", "size": "10", "side": "BUY", "timestamp": "1768574191124", "received_at": "2026-01-16T14:36:31.162966"}}
{"event_type": "price_change", "event_ts": "2026-01-16T14:36:31.162966", "ingestion_ts": "2026-01-16T14:36:49.604167", "market_id": "0xc55db914f0fd1fee18997706712c0dfd8d0369cdbef93a9fef12bd001914ca77", "raw": {"market": "0xc55db914f0fd1fee18997706712c0dfd8d0369cdbef93a9fef12bd001914ca77", "asset_id": "72354723612769247426741660426331235762851940382312402276325808095604519806766", "price": "0.142", "size": "10", "side": "SELL", "timestamp": "1768574191124", "received_at": "2026-01-16T14:36:31.162966"}}
{"event_type": "price_change", "event_ts": "2026-01-16T14:36:31.162979", "ingestion_ts": "2026-01-16T14:36:49.604167", "market_id": "0x50c669f178da4e5bbea7f1be25041fd278914712fa87a6a6f8e57d5923d88dee", "raw": {"market": "0x50c669f178da4e5bbea7f1be25041fd278914712fa87a6a6f8e57d5923d88dee", "asset_id": "74040420326294854165772767082819937451857852955603897473157746262672057685461", "price": "0.856", "size": "10", "side": "BUY", "timestamp": "1768574191124", "received_at": "2026-01-16T14:36:31.162979"}}
{"event_type": "price_change", "event_ts": "2026-01-16T14:36:31.162979", "ingestion_ts": "2026-01-16T14:36:49.604167", "market_id": "0x50c669f178da4e5bbea7f1be25041fd278914712fa87a6a6f8e57d5923d88dee", "raw": {"market": "0x50c669f178da4e5bbea7f1be25041fd278914712fa87a6a6f8e57d5923d88dee", "asset_id": "24682525479474221428144937281315825971983904267399062415430320764754931667953", "price": "0.144", "size": "10", "side": "SELL", "timestamp": "1768574191124", "received_at": "2026-01-16T14:36:31.162979"}}
{"event_type": "price_change", "event_ts": "2026-01-16T14:36:31.162990", "ingestion_ts": "2026-01-16T14:36:49.604167", "market_id": "0x49a20c7523c271099008f3ef9a31521263b24d637959852a391e6b4697b1a437", "raw": {"market": "0x49a20c7523c271099008f3ef9a31521263b24d637959852a391e6b4697b1a437", "asset_id": "55881023621710858558280545117465775643848233756850602339827152783696837905531", "price": "0.856", "size": "40", "side": "BUY", "timestamp": "1768574191124", "received_at": "2026-01-16T14:36:31.162990"}}
{"event_type": "price_change", "event_ts": "2026-01-16T14:36:31.162990", "ingestion_ts": "2026-01-16T14:36:49.604167", "market_id": "0x49a20c7523c271099008f3ef9a31521263b24d637959852a391e6b4697b1a437", "raw": {"market": "0x49a20c7523c271099008f3ef9a31521263b24d637959852a391e6b4697b1a437", "asset_id": "13018971792603393862521629014128024641178044618205296260525674415067194037856", "price": "0.144", "size": "40", "side": "SELL", "timestamp": "1768574191124", "received_at": "2026-01-16T14:36:31.162990"}}
{"event_type": "price_change", "event_ts": "2026-01-16T14:36:31.212144", "ingestion_ts": "2026-01-16T14:36:49.604167", "market_id": "0xaf9d0e448129a9f657f851d49495ba4742055d80e0ef1166ba0ee81d4d594214", "raw": {"market": "0xaf9d0e448129a9f657f851d49495ba4742055d80e0ef1166ba0ee81d4d594214", "asset_id": "4153292802911610701832309484716814274802943278345248636922528170020319407796", "price": "0.979", "size": "0", "side": "SELL", "timestamp": "1768574191172", "received_at": "2026-01-16T14:36:31.212144"}}
{"event_type": "price_change", "event_ts": "2026-01-16T14:36:31.212144", "ingestion_ts": "2026-01-16T14:36:49.604167", "market_id": "0xaf9d0e448129a9f657f851d49495ba4742055d80e0ef1166ba0ee81d4d594214", "raw": {"market": "0xaf9d0e448129a9f657f851d49495ba4742055d80e0ef1166ba0ee81d4d594214", "asset_id": "101676997363687199724245607342877036148401850938023978421879460310389391082353", "price": "0.021", "size": "0", "side": "BUY", "timestamp": "1768574191172", "received_at": "2026-01-16T14:36:31.212144"}}
{"event_type": "price_change", "event_ts": "2026-01-16T14:36:31.446129", "ingestion_ts": "2026-01-16T14:36:49.604167", "market_id": "0x2393ed0b0fdc450054c7b9071907eca75cf4fc36e385adf4a0a5f99ee62243e8", "raw": {"market": "0x2393ed0b0fdc450054c7b9071907eca75cf4fc36e385adf4a0a5f99ee62243e8", "asset_id": "32769749367306925959219403371425714180265458150646381231272229429098460625924", "price": "0.944", "size": "50", "side": "BUY", "timestamp": "1768574191407", "received_at": "2026-01-16T14:36:31.446129"}}
{"event_type": "price_change", "event_ts": "2026-01-16T14:36:31.446129", "ingestion_ts": "2026-01-16T14:36:49.604167", "market_id": "0x2393ed0b0fdc450054c7b9071907eca75cf4fc36e385adf4a0a5f99ee62243e8", "raw": {"market": "0x2393ed0b0fdc450054c7b9071907eca75cf4fc36e385adf4a0a5f99ee62243e8", "asset_id": "100074770378634056601572485653252702850363676459996771990439989989293515601975", "price": "0.056", "size": "50", "side": "SELL", "timestamp": "1768574191407", "received_at": "2026-01-16T14:36:31.446129"}}
{"event_type": "price_change", "event_ts": "2026-01-16T14:36:31.470775", "ingestion_ts": "2026-01-16T14:36:49.604167", "market_id": "0x2393ed0b0fdc450054c7b9071907eca75cf4fc36e385adf4a0a5f99ee62243e8", "raw": {"market": "0x2393ed0b0fdc450054c7b9071907eca75cf4fc36e385adf4a0a5f99ee62243e8", "asset_id": "100074770378634056601572485653252702850363676459996771990439989989293515601975", "price": "0.057", "size": "0", "side": "SELL", "timestamp": "1768574191434", "received_at": "2026-01-16T14:36:31.470775"}}
{"event_type": "price_change", "event_ts": "2026-01-16T14:36:31.470775", "ingestion_ts": "2026-01-16T14:36:49.604167", "market_id": "0x2393ed0b0fdc450054c7b9071907eca75cf4fc36e385adf4a0a5f99ee62243e8", "raw": {"market": "0x2393ed0b0fdc450054c7b9071907eca75cf4fc36e385adf4a0a5f99ee62243e8", "asset_id": "32769749367306925959219403371425714180265458150646381231272229429098460625924", "price": "0.943", "size": "0", "side": "BUY", "timestamp": "1768574191434", "received_at": "2026-01-16T14:36:31.470775"}}
{"event_type": "price_change", "event_ts": "2026-01-16T14:36:31.515110", "ingestion_ts": "2026-01-16T14:36:49.604167", "market_id": "0x2393ed0b0fdc450054c7b9071907eca75cf4fc36e385adf4a0a5f99ee62243e8", "raw": {"market": "0x2393ed0b0fdc450054c7b9071907eca75cf4fc36e385adf4a0a5f99ee62243e8", "asset_id": "100074770378634056601572485653252702850363676459996771990439989989293515601975", "price": "0.055", "size": "198", "side": "SELL", "timestamp": "1768574191478", "received_at": "2026-01-16T14:36:31.515110"}}
{"event_type": "price_change", "event_ts": "2026-01-16T14:36:31.515110", "ingestion_ts": "2026-01-16T14:36:49.604167", "market_id": "0x2393ed0b0fdc450054c7b9071907eca75cf4fc36e385adf4a0a5f99ee62243e8", "raw": {"market": "0x2393ed0b0fdc450054c7b9071907eca75cf4fc36e385adf4a0a5f99ee62243e8", "asset_id": "32769749367306925959219403371425714180265458150646381231272229429098460625924", "price": "0.945", "size": "198", "side": "BUY", "timestamp": "1768574191478", "received_at": "2026-01-16T14:36:31.515110"}}
{"event_type": "price_change", "event_ts": "2026-01-16T14:36:31.812279", "ingestion_ts": "2026-01-16T14:36:49.604167", "market_id": "0x2393ed0b0fdc450054c7b9071907eca75cf4fc36e385adf4a0a5f99ee62243e8", "raw": {"market": "0x2393ed0b0fdc450054c7b9071907eca75cf4fc36e385adf4a0a5f99ee62243e8", "asset_id": "32769749367306925959219403371425714180265458150646381231272229429098460625924", "price": "0.942", "size": "0", "side": "BUY", "timestamp": "1768574191768", "received_at": "2026-01-16T14:36:31.812279"}}
{"event_type": "price_change", "event_ts": "2026-01-16T14:36:31.812279", "ingestion_ts": "2026-01-16T14:36:49.604167", "market_id": "0x2393ed0b0fdc450054c7b9071907eca75cf4fc36e385adf4a0a5f99ee62243e8", "raw": {"market": "0x2393ed0b0fdc450054c7b9071907eca75cf4fc36e385adf4a0a5f99ee62243e8", "asset_id": "100074770378634056601572485653252702850363676459996771990439989989293515601975", "price": "0.058", "size": "0", "side": "SELL", "timestamp": "1768574191768", "received_at": "2026-01-16T14:36:31.812279"}}
{"event_type": "price_change", "event_ts": "2026-01-16T14:36:31.953850", "ingestion_ts": "2026-01-16T14:36:49.604167", "market_id": "0xc0e6b917320a47228fb96e3b5ae0e5c93773a5ae2662ae4e1f37807cfe47ce98", "raw": {"market": "0xc0e6b917320a47228fb96e3b5ae0e5c93773a5ae2662ae4e1f37807cfe47ce98", "asset_id": "58656358377246279051017109359677190749228949103591068167284263961542487110215", "price": "0.002", "size": "3279.99", "side": "BUY", "timestamp": "1768574191911", "received_at": "2026-01-16T14:36:31.953850"}}
{"event_type": "price_change", "event_ts": "2026-01-16T14:36:31.953850", "ingestion_ts": "2026-01-16T14:36:49.604167", "market_id": "0xc0e6b917320a47228fb96e3b5ae0e5c93773a5ae2662ae4e1f37807cfe47ce98", "raw": {"market": "0xc0e6b917320a47228fb96e3b5ae0e5c93773a5ae2662ae4e1f37807cfe47ce98", "asset_id": "81647294538046680798858716589766492074338758116170717123345952330712416337530", "price": "0.998", "size": "3279.99", "side": "SELL", "timestamp": "1768574191911", "received_at": "2026-01-16T14:36:31.953850"}}
{"event_type": "price_change", "event_ts": "2026-01-16T14:36:32.052137", "ingestion_ts": "2026-01-16T14:36:49.604167", "market_id": "0xaf9d0e448129a9f657f851d49495ba4742055d80e0ef1166ba0ee81d4d594214", "raw": {"market": "0xaf9d0e448129a9f657f851d49495ba4742055d80e0ef1166ba0ee81d4d594214", "asset_id": "4153292802911610701832309484716814274802943278345248636922528170020319407796", "price": "0.978", "size": "0", "side": "SELL", "timestamp": "1768574191998", "received_at": "2026-01-16T14:36:32.052137"}}
{"event_type": "price_change", "event_ts": "2026-01-16T14:36:32.052137", "ingestion_ts": "2026-01-16T14:36:49.604167", "market_id": "0xaf9d0e448129a9f657f851d49495ba4742055d80e0ef1166ba0ee81d4d594214", "raw": {"market": "0xaf9d0e448129a9f657f851d49495ba4742055d80e0ef1166ba0ee81d4d594214", "asset_id": "101676997363687199724245607342877036148401850938023978421879460310389391082353", "price": "0.022", "size": "0", "side": "BUY", "timestamp": "1768574191998", "received_at": "2026-01-16T14:36:32.052137"}}
{"event_type": "price_change", "event_ts": "2026-01-16T14:36:32.179514", "ingestion_ts": "2026-01-16T14:36:49.604167", "market_id": "0xaf9d0e448129a9f657f851d49495ba4742055d80e0ef1166ba0ee81d4d594214", "raw": {"market": "0xaf9d0e448129a9f657f851d49495ba4742055d80e0ef1166ba0ee81d4d594214", "asset_id": "4153292802911610701832309484716814274802943278345248636922528170020319407796", "price": "0.989", "size": "20.5", "side": "SELL", "timestamp": "1768574192109", "received_at": "2026-01-16T14:36:32.179514"}}
{"event_type": "price_change", "event_ts": "2026-01-16T14:36:32.179514", "ingestion_ts": "2026-01-16T14:36:49.604167", "market_id": "0xaf9d0e448129a9f657f851d49495ba4742055d80e0ef1166ba0ee81d4d594214", "raw": {"market": "0xaf9d0e448129a9f657f851d49495ba4742055d80e0ef1166ba0ee81d4d594214", "asset_id": "101676997363687199724245607342877036148401850938023978421879460310389391082353", "price": "0.011", "size": "20.5", "side": "BUY", "timestamp": "1768574192109", "received_at": "2026-01-16T14:36:32.179514"}}
{"event_type": "price_change", "event_ts": "2026-01-16T14:36:32.772282", "ingestion_ts": "2026-01-16T14:36:49.604167", "market_id": "0xc0e6b917320a47228fb96e3b5ae0e5c93773a5ae2662ae4e1f37807cfe47ce98", "raw": {"market": "0xc0e6b917320a47228fb96e3b5ae0e5c93773a5ae2662ae4e1f37807cfe47ce98", "asset_id": "58656358377246279051017109359677190749228949103591068167284263961542487110215", "price": "0.002", "size": "3287.1", "side": "BUY", "timestamp": "1768574192731", "received_at": "2026-01-16T14:36:32.772282"}}
{"event_type": "price_change", "event_ts": "2026-01-16T14:36:32.772282", "ingestion_ts": "2026-01-16T14:36:49.604167", "market_id": "0xc0e6b917320a47228fb96e3b5ae0e5c93773a5ae2662ae4e1f37807cfe47ce98", "raw": {"market": "0xc0e6b917320a47228fb96e3b5ae0e5c93773a5ae2662ae4e1f37807cfe47ce98", "asset_id": "81647294538046680798858716589766492074338758116170717123345952330712416337530", "price": "0.998", "size": "3287.1", "side": "SELL", "timestamp": "1768574192731", "received_at": "2026-01-16T14:36:32.772282"}}
{"event_type": "price_change", "event_ts": "2026-01-16T14:36:32.772323", "ingestion_ts": "2026-01-16T14:36:49.604167", "market_id": "0xc0e6b917320a47228fb96e3b5ae0e5c93773a5ae2662ae4e1f37807cfe47ce98", "raw": {"market": "0xc0e6b917320a47228fb96e3b5ae0e5c93773a5ae2662ae4e1f37807cfe47ce98", "asset_id": "58656358377246279051017109359677190749228949103591068167284263961542487110215", "price": "0.002", "size": "3294.21", "side": "BUY", "timestamp": "1768574192731", "received_at": "2026-01-16T14:36:32.772323"}}
{"event_type": "price_change", "event_ts": "2026-01-16T14:36:32.772323", "ingestion_ts": "2026-01-16T14:36:49.604167", "market_id": "0xc0e6b917320a47228fb96e3b5ae0e5c93773a5ae2662ae4e1f37807cfe47ce98", "raw": {"market": "0xc0e6b917320a47228fb96e3b5ae0e5c93773a5ae2662ae4e1f37807cfe47ce98", "asset_id": "81647294538046680798858716589766492074338758116170717123345952330712416337530", "price": "0.998", "size": "3294.21", "side": "SELL", "timestamp": "1768574192731", "received_at": "2026-01-16T14:36:32.772323"}}
{"event_type": "price_change", "event_ts": "2026-01-16T14:36:33.503648", "ingestion_ts": "2026-01-16T14:36:49.604167", "market_id": "0x49a20c7523c271099008f3ef9a31521263b24d637959852a391e6b4697b1a437", "raw": {"market": "0x49a20c7523c271099008f3ef9a31521263b24d637959852a391e6b4697b1a437", "asset_id": "55881023621710858558280545117465775643848233756850602339827152783696837905531", "price": "0.856", "size": "30", "side": "BUY", "timestamp": "1768574193443", "received_at": "2026-01-16T14:36:33.503648"}}
{"event_type": "price_change", "event_ts": "2026-01-16T14:36:33.503648", "ingestion_ts": "2026-01-16T14:36:49.604167", "market_id": "0x49a20c7523c271099008f3ef9a31521263b24d637959852a391e6b4697b1a437", "raw": {"market": "0x49a20c7523c271099008f3ef9a31521263b24d637959852a391e6b4697b1a437", "asset_id": "13018971792603393862521629014128024641178044618205296260525674415067194037856", "price": "0.144", "size": "30", "side": "SELL", "timestamp": "1768574193443", "received_at": "2026-01-16T14:36:33.503648"}}
{"event_type": "price_change", "event_ts": "2026-01-16T14:36:33.503685", "ingestion_ts": "2026-01-16T14:36:49.604167", "market_id": "0x49686d26fb712515cd5e12c23f0a1c7e10214c7faa3cb0a730aabe0c33694082", "raw": {"market": "0x49686d26fb712515cd5e12c23f0a1c7e10214c7faa3cb0a730aabe0c33694082", "asset_id": "30442780799048074404860985387051749017905070253466005720364298335239299761065", "price": "0.006", "size": "10.08", "side": "BUY", "timestamp": "1768574193443", "received_at": "2026-01-16T14:36:33.503685"}}
{"event_type": "price_change", "event_ts": "2026-01-16T14:36:33.503685", "ingestion_ts": "2026-01-16T14:36:49.604167", "market_id": "0x49686d26fb712515cd5e12c23f0a1c7e10214c7faa3cb0a730aabe0c33694082", "raw": {"market": "0x49686d26fb712515cd5e12c23f0a1c7e10214c7faa3cb0a730aabe0c33694082", "asset_id": "13244681086321087932946246027856416106585284024824496763706748621681543444582", "price": "0.994", "size": "10.08", "side": "SELL", "timestamp": "1768574193443", "received_at": "2026-01-16T14:36:33.503685"}}
{"event_type": "price_change", "event_ts": "2026-01-16T14:36:33.503700", "ingestion_ts": "2026-01-16T14:36:49.604167", "market_id": "0x44f08744458b8896620cd3330bc5e1ea69df4199b02d4fc583b3fc96e5d314ce", "raw": {"market": "0x44f08744458b8896620cd3330bc5e1ea69df4199b02d4fc583b3fc96e5d314ce", "asset_id": "72327831507226612545928776794104143393438710920370371172884559893525100761096", "price": "0.854", "size": "0", "side": "BUY", "timestamp": "1768574193443", "received_at": "2026-01-16T14:36:33.503700"}}
{"event_type": "price_change", "event_ts": "2026-01-16T14:36:33.503700", "ingestion_ts": "2026-01-16T14:36:49.604167", "market_id": "0x44f08744458b8896620cd3330bc5e1ea69df4199b02d4fc583b3fc96e5d314ce", "raw": {"market": "0x44f08744458b8896620cd3330bc5e1ea69df4199b02d4fc583b3fc96e5d314ce", "asset_id": "49194009556504828848509244326501559253829462790583873936160989575507522044057", "price": "0.146", "size": "0", "side": "SELL", "timestamp": "1768574193443", "received_at": "2026-01-16T14:36:33.503700"}}
{"event_type": "price_change", "event_ts": "2026-01-16T14:36:33.503713", "ingestion_ts": "2026-01-16T14:36:49.604167", "market_id": "0x9472be65457510b7fc3477b20ba90910e99d92eac8421a14bf4b7b7a08ef31dc", "raw": {"market": "0x9472be65457510b7fc3477b20ba90910e99d92eac8421a14bf4b7b7a08ef31dc", "asset_id": "43311793366960417907757893276427136943959788721376762326430771171648759300146", "price": "0.856", "size": "0", "side": "BUY", "timestamp": "1768574193443", "received_at": "2026-01-16T14:36:33.503713"}}
{"event_type": "price_change", "event_ts": "2026-01-16T14:36:33.503713", "ingestion_ts": "2026-01-16T14:36:49.604167", "market_id": "0x9472be65457510b7fc3477b20ba90910e99d92eac8421a14bf4b7b7a08ef31dc", "raw": {"market": "0x9472be65457510b7fc3477b20ba90910e99d92eac8421a14bf4b7b7a08ef31dc", "asset_id": "73414222381656326204771753454630063673548497164758947581648273905027617570612", "price": "0.144", "size": "0", "side": "SELL", "timestamp": "1768574193443", "received_at": "2026-01-16T14:36:33.503713"}}
{"event_type": "price_change", "event_ts": "2026-01-16T14:36:33.503724", "ingestion_ts": "2026-01-16T14:36:49.604167", "market_id": "0xc55db914f0fd1fee18997706712c0dfd8d0369cdbef93a9fef12bd001914ca77", "raw": {"market": "0xc55db914f0fd1fee18997706712c0dfd8d0369cdbef93a9fef12bd001914ca77", "asset_id": "114600293444080540179603459515770723592661967180480327891296353898330242622833", "price": "0.858", "size": "0", "side": "BUY", "timestamp": "1768574193443", "received_at": "2026-01-16T14:36:33.503724"}}
{"event_type": "price_change", "event_ts": "2026-01-16T14:36:33.503724", "ingestion_ts": "2026-01-16T14:36:49.604167", "market_id": "0xc55db914f0fd1fee18997706712c0dfd8d0369cdbef93a9fef12bd001914ca77", "raw": {"market": "0xc55db914f0fd1fee18997706712c0dfd8d0369cdbef93a9fef12bd001914ca77", "asset_id": "72354723612769247426741660426331235762851940382312402276325808095604519806766", "price": "0.142", "size": "0", "side": "SELL", "timestamp": "1768574193443", "received_at": "2026-01-16T14:36:33.503724"}}
{"event_type": "price_change", "event_ts": "2026-01-16T14:36:33.503734", "ingestion_ts": "2026-01-16T14:36:49.604167", "market_id": "0x50c669f178da4e5bbea7f1be25041fd278914712fa87a6a6f8e57d5923d88dee", "raw": {"market": "0x50c669f178da4e5bbea7f1be25041fd278914712fa87a6a6f8e57d5923d88dee", "asset_id": "74040420326294854165772767082819937451857852955603897473157746262672057685461", "price": "0.856", "size": "0", "side": "BUY", "timestamp": "1768574193443", "received_at": "2026-01-16T14:36:33.503734"}}
{"event_type": "price_change", "event_ts": "2026-01-16T14:36:33.503734", "ingestion_ts": "2026-01-16T14:36:49.604167", "market_id": "0x50c669f178da4e5bbea7f1be25041fd278914712fa87a6a6f8e57d5923d88dee", "raw": {"market": "0x50c669f178da4e5bbea7f1be25041fd278914712fa87a6a6f8e57d5923d88dee", "asset_id": "24682525479474221428144937281315825971983904267399062415430320764754931667953", "price": "0.144", "size": "0", "side": "SELL", "timestamp": "1768574193443", "received_at": "2026-01-16T14:36:33.503734"}}
{"event_type": "price_change", "event_ts": "2026-01-16T14:36:33.545608", "ingestion_ts": "2026-01-16T14:36:49.604167", "market_id": "0x9472be65457510b7fc3477b20ba90910e99d92eac8421a14bf4b7b7a08ef31dc", "raw": {"market": "0x9472be65457510b7fc3477b20ba90910e99d92eac8421a14bf4b7b7a08ef31dc", "asset_id": "43311793366960417907757893276427136943959788721376762326430771171648759300146", "price": "0.824", "size": "10", "side": "BUY", "timestamp": "1768574193485", "received_at": "2026-01-16T14:36:33.545608"}}
{"event_type": "price_change", "event_ts": "2026-01-16T14:36:33.545608", "ingestion_ts": "2026-01-16T14:36:49.604167", "market_id": "0x9472be65457510b7fc3477b20ba90910e99d92eac8421a14bf4b7b7a08ef31dc", "raw": {"market": "0x9472be65457510b7fc3477b20ba90910e99d92eac8421a14bf4b7b7a08ef31dc", "asset_id": "73414222381656326204771753454630063673548497164758947581648273905027617570612", "price": "0.176", "size": "10", "side": "SELL", "timestamp": "1768574193485", "received_at": "2026-01-16T14:36:33.545608"}}
{"event_type": "price_change", "event_ts": "2026-01-16T14:36:33.545647", "ingestion_ts": "2026-01-16T14:36:49.604167", "market_id": "0x44f08744458b8896620cd3330bc5e1ea69df4199b02d4fc583b3fc96e5d314ce", "raw": {"market": "0x44f08744458b8896620cd3330bc5e1ea69df4199b02d4fc583b3fc96e5d314ce", "asset_id": "72327831507226612545928776794104143393438710920370371172884559893525100761096", "price": "0.831", "size": "10", "side": "BUY", "timestamp": "1768574193485", "received_at": "2026-01-16T14:36:33.545647"}}
{"event_type": "price_change", "event_ts": "2026-01-16T14:36:33.545647", "ingestion_ts": "2026-01-16T14:36:49.604167", "market_id": "0x44f08744458b8896620cd3330bc5e1ea69df4199b02d4fc583b3fc96e5d314ce", "raw": {"market": "0x44f08744458b8896620cd3330bc5e1ea69df4199b02d4fc583b3fc96e5d314ce", "asset_id": "49194009556504828848509244326501559253829462790583873936160989575507522044057", "price": "0.169", "size": "10", "side": "SELL", "timestamp": "1768574193485", "received_at": "2026-01-16T14:36:33.545647"}}
{"event_type": "price_change", "event_ts": "2026-01-16T14:36:33.545661", "ingestion_ts": "2026-01-16T14:36:49.604167", "market_id": "0xc55db914f0fd1fee18997706712c0dfd8d0369cdbef93a9fef12bd001914ca77", "raw": {"market": "0xc55db914f0fd1fee18997706712c0dfd8d0369cdbef93a9fef12bd001914ca77", "asset_id": "114600293444080540179603459515770723592661967180480327891296353898330242622833", "price": "0.837", "size": "10", "side": "BUY", "timestamp": "1768574193485", "received_at": "2026-01-16T14:36:33.545661"}}
{"event_type": "price_change", "event_ts": "2026-01-16T14:36:33.545661", "ingestion_ts": "2026-01-16T14:36:49.604167", "market_id": "0xc55db914f0fd1fee18997706712c0dfd8d0369cdbef93a9fef12bd001914ca77", "raw": {"market": "0xc55db914f0fd1fee18997706712c0dfd8d0369cdbef93a9fef12bd001914ca77", "asset_id": "72354723612769247426741660426331235762851940382312402276325808095604519806766", "price": "0.163", "size": "10", "side": "SELL", "timestamp": "1768574193485", "received_at": "2026-01-16T14:36:33.545661"}}
{"event_type": "price_change", "event_ts": "2026-01-16T14:36:33.545673", "ingestion_ts": "2026-01-16T14:36:49.604167", "market_id": "0x49a20c7523c271099008f3ef9a31521263b24d637959852a391e6b4697b1a437", "raw": {"market": "0x49a20c7523c271099008f3ef9a31521263b24d637959852a391e6b4697b1a437", "asset_id": "55881023621710858558280545117465775643848233756850602339827152783696837905531", "price": "0.847", "size": "10", "side": "BUY", "timestamp": "1768574193485", "received_at": "2026-01-16T14:36:33.545673"}}
{"event_type": "price_change", "event_ts": "2026-01-16T14:36:33.545673", "ingestion_ts": "2026-01-16T14:36:49.604167", "market_id": "0x49a20c7523c271099008f3ef9a31521263b24d637959852a391e6b4697b1a437", "raw": {"market": "0x49a20c7523c271099008f3ef9a31521263b24d637959852a391e6b4697b1a437", "asset_id": "13018971792603393862521629014128024641178044618205296260525674415067194037856", "price": "0.153", "size": "10", "side": "SELL", "timestamp": "1768574193485", "received_at": "2026-01-16T14:36:33.545673"}}
{"event_type": "price_change", "event_ts": "2026-01-16T14:36:33.545685", "ingestion_ts": "2026-01-16T14:36:49.604167", "market_id": "0x50c669f178da4e5bbea7f1be25041fd278914712fa87a6a6f8e57d5923d88dee", "raw": {"market": "0x50c669f178da4e5bbea7f1be25041fd278914712fa87a6a6f8e57d5923d88dee", "asset_id": "74040420326294854165772767082819937451857852955603897473157746262672057685461", "price": "0.825", "size": "10", "side": "BUY", "timestamp": "1768574193485", "received_at": "2026-01-16T14:36:33.545685"}}
{"event_type": "price_change", "event_ts": "2026-01-16T14:36:33.545685", "ingestion_ts": "2026-01-16T14:36:49.604167", "market_id": "0x50c669f178da4e5bbea7f1be25041fd278914712fa87a6a6f8e57d5923d88dee", "raw": {"market": "0x50c669f178da4e5bbea7f1be25041fd278914712fa87a6a6f8e57d5923d88dee", "asset_id": "24682525479474221428144937281315825971983904267399062415430320764754931667953", "price": "0.175", "size": "10", "side": "SELL", "timestamp": "1768574193485", "received_at": "2026-01-16T14:36:33.545685"}}
{"event_type": "price_change", "event_ts": "2026-01-16T14:36:33.545695", "ingestion_ts": "2026-01-16T14:36:49.604167", "market_id": "0x49686d26fb712515cd5e12c23f0a1c7e10214c7faa3cb0a730aabe0c33694082", "raw": {"market": "0x49686d26fb712515cd5e12c23f0a1c7e10214c7faa3cb0a730aabe0c33694082", "asset_id": "30442780799048074404860985387051749017905070253466005720364298335239299761065", "price": "0.002", "size": "672.74", "side": "BUY", "timestamp": "1768574193485", "received_at": "2026-01-16T14:36:33.545695"}}
{"event_type": "price_change", "event_ts": "2026-01-16T14:36:33.545695", "ingestion_ts": "2026-01-16T14:36:49.604167", "market_id": "0x49686d26fb712515cd5e12c23f0a1c7e10214c7faa3cb0a730aabe0c33694082", "raw": {"market": "0x49686d26fb712515cd5e12c23f0a1c7e10214c7faa3cb0a730aabe0c33694082", "asset_id": "13244681086321087932946246027856416106585284024824496763706748621681543444582", "price": "0.998", "size": "672.74", "side": "SELL", "timestamp": "1768574193485", "received_at": "2026-01-16T14:36:33.545695"}}
{"event_type": "price_change", "event_ts": "2026-01-16T14:36:33.820657", "ingestion_ts": "2026-01-16T14:36:49.604167", "market_id": "0x49686d26fb712515cd5e12c23f0a1c7e10214c7faa3cb0a730aabe0c33694082", "raw": {"market": "0x49686d26fb712515cd5e12c23f0a1c7e10214c7faa3cb0a730aabe0c33694082", "asset_id": "30442780799048074404860985387051749017905070253466005720364298335239299761065", "price": "0.003", "size": "15.78", "side": "BUY", "timestamp": "1768574193742", "received_at": "2026-01-16T14:36:33.820657"}}
{"event_type": "price_change", "event_ts": "2026-01-16T14:36:33.820657", "ingestion_ts": "2026-01-16T14:36:49.604167", "market_id": "0x49686d26fb712515cd5e12c23f0a1c7e10214c7faa3cb0a730aabe0c33694082", "raw": {"market": "0x49686d26fb712515cd5e12c23f0a1c7e10214c7faa3cb0a730aabe0c33694082", "asset_id": "13244681086321087932946246027856416106585284024824496763706748621681543444582", "price": "0.997", "size": "15.78", "side": "SELL", "timestamp": "1768574193742", "received_at": "2026-01-16T14:36:33.820657"}}
{"event_type": "price_change", "event_ts": "2026-01-16T14:36:33.820698", "ingestion_ts": "2026-01-16T14:36:49.604167", "market_id": "0x49686d26fb712515cd5e12c23f0a1c7e10214c7faa3cb0a730aabe0c33694082", "raw": {"market": "0x49686d26fb712515cd5e12c23f0a1c7e10214c7faa3cb0a730aabe0c33694082", "asset_id": "30442780799048074404860985387051749017905070253466005720364298335239299761065", "price": "0.011", "size": "0", "side": "BUY", "timestamp": "1768574193742", "received_at": "2026-01-16T14:36:33.820698"}}
{"event_type": "price_change", "event_ts": "2026-01-16T14:36:33.820698", "ingestion_ts": "2026-01-16T14:36:49.604167", "market_id": "0x49686d26fb712515cd5e12c23f0a1c7e10214c7faa3cb0a730aabe0c33694082", "raw": {"market": "0x49686d26fb712515cd5e12c23f0a1c7e10214c7faa3cb0a730aabe0c33694082", "asset_id": "13244681086321087932946246027856416106585284024824496763706748621681543444582", "price": "0.989", "size": "0", "side": "SELL", "timestamp": "1768574193742", "received_at": "2026-01-16T14:36:33.820698"}}
{"event_type": "price_change", "event_ts": "2026-01-16T14:36:34.204902", "ingestion_ts": "2026-01-16T14:36:49.604167", "market_id": "0x49686d26fb712515cd5e12c23f0a1c7e10214c7faa3cb0a730aabe0c33694082", "raw": {"market": "0x49686d26fb712515cd5e12c23f0a1c7e10214c7faa3cb0a730aabe0c33694082", "asset_id": "13244681086321087932946246027856416106585284024824496763706748621681543444582", "price": "0.853", "size": "0", "side": "BUY", "timestamp": "1768574194130", "received_at": "2026-01-16T14:36:34.204902"}}
{"event_type": "price_change", "event_ts": "2026-01-16T14:36:34.204902", "ingestion_ts": "2026-01-16T14:36:49.604167", "market_id": "0x49686d26fb712515cd5e12c23f0a1c7e10214c7faa3cb0a730aabe0c33694082", "raw": {"market": "0x49686d26fb712515cd5e12c23f0a1c7e10214c7faa3cb0a730aabe0c33694082", "asset_id": "30442780799048074404860985387051749017905070253466005720364298335239299761065", "price": "0.147", "size": "0", "side": "SELL", "timestamp": "1768574194130", "received_at": "2026-01-16T14:36:34.204902"}}
{"event_type": "price_change", "event_ts": "2026-01-16T14:36:34.211354", "ingestion_ts": "2026-01-16T14:36:49.604167", "market_id": "0xc0e6b917320a47228fb96e3b5ae0e5c93773a5ae2662ae4e1f37807cfe47ce98", "raw": {"market": "0xc0e6b917320a47228fb96e3b5ae0e5c93773a5ae2662ae4e1f37807cfe47ce98", "asset_id": "81647294538046680798858716589766492074338758116170717123345952330712416337530", "price": "0.925", "size": "0", "side": "BUY", "timestamp": "1768574194130", "received_at": "2026-01-16T14:36:34.211354"}}
{"event_type": "price_change", "event_ts": "2026-01-16T14:36:34.211354", "ingestion_ts": "2026-01-16T14:36:49.604167", "market_id": "0xc0e6b917320a47228fb96e3b5ae0e5c93773a5ae2662ae4e1f37807cfe47ce98", "raw": {"market": "0xc0e6b917320a47228fb96e3b5ae0e5c93773a5ae2662ae4e1f37807cfe47ce98", "asset_id": "58656358377246279051017109359677190749228949103591068167284263961542487110215", "price": "0.075", "size": "0", "side": "SELL", "timestamp": "1768574194130", "received_at": "2026-01-16T14:36:34.211354"}}
{"event_type": "price_change", "event_ts": "2026-01-16T14:36:34.211424", "ingestion_ts": "2026-01-16T14:36:49.604167", "market_id": "0xc0e6b917320a47228fb96e3b5ae0e5c93773a5ae2662ae4e1f37807cfe47ce98", "raw": {"market": "0xc0e6b917320a47228fb96e3b5ae0e5c93773a5ae2662ae4e1f37807cfe47ce98", "asset_id": "81647294538046680798858716589766492074338758116170717123345952330712416337530", "price": "0.993", "size": "0", "side": "SELL", "timestamp": "1768574194130", "received_at": "2026-01-16T14:36:34.211424"}}
{"event_type": "price_change", "event_ts": "2026-01-16T14:36:34.211424", "ingestion_ts": "2026-01-16T14:36:49.604167", "market_id": "0xc0e6b917320a47228fb96e3b5ae0e5c93773a5ae2662ae4e1f37807cfe47ce98", "raw": {"market": "0xc0e6b917320a47228fb96e3b5ae0e5c93773a5ae2662ae4e1f37807cfe47ce98", "asset_id": "58656358377246279051017109359677190749228949103591068167284263961542487110215", "price": "0.007", "size": "0", "side": "BUY", "timestamp": "1768574194130", "received_at": "2026-01-16T14:36:34.211424"}}
{"event_type": "price_change", "event_ts": "2026-01-16T14:36:34.480633", "ingestion_ts": "2026-01-16T14:36:49.604167", "market_id": "0x49686d26fb712515cd5e12c23f0a1c7e10214c7faa3cb0a730aabe0c33694082", "raw": {"market": "0x49686d26fb712515cd5e12c23f0a1c7e10214c7faa3cb0a730aabe0c33694082", "asset_id": "30442780799048074404860985387051749017905070253466005720364298335239299761065", "price": "0.012", "size": "10.92", "side": "BUY", "timestamp": "1768574194188", "received_at": "2026-01-16T14:36:34.480633"}}
{"event_type": "price_change", "event_ts": "2026-01-16T14:36:34.480633", "ingestion_ts": "2026-01-16T14:36:49.604167", "market_id": "0x49686d26fb712515cd5e12c23f0a1c7e10214c7faa3cb0a730aabe0c33694082", "raw": {"market": "0x49686d26fb712515cd5e12c23f0a1c7e10214c7faa3cb0a730aabe0c33694082", "asset_id": "13244681086321087932946246027856416106585284024824496763706748621681543444582", "price": "0.988", "size": "10.92", "side": "SELL", "timestamp": "1768574194188", "received_at": "2026-01-16T14:36:34.480633"}}
{"event_type": "price_change", "event_ts": "2026-01-16T14:36:34.482806", "ingestion_ts": "2026-01-16T14:36:49.604167", "market_id": "0x49686d26fb712515cd5e12c23f0a1c7e10214c7faa3cb0a730aabe0c33694082", "raw": {"market": "0x49686d26fb712515cd5e12c23f0a1c7e10214c7faa3cb0a730aabe0c33694082", "asset_id": "30442780799048074404860985387051749017905070253466005720364298335239299761065", "price": "0.008", "size": "14.29", "side": "BUY", "timestamp": "1768574194190", "received_at": "2026-01-16T14:36:34.482806"}}
{"event_type": "price_change", "event_ts": "2026-01-16T14:36:34.482806", "ingestion_ts": "2026-01-16T14:36:49.604167", "market_id": "0x49686d26fb712515cd5e12c23f0a1c7e10214c7faa3cb0a730aabe0c33694082", "raw": {"market": "0x49686d26fb712515cd5e12c23f0a1c7e10214c7faa3cb0a730aabe0c33694082", "asset_id": "13244681086321087932946246027856416106585284024824496763706748621681543444582", "price": "0.992", "size": "14.29", "side": "SELL", "timestamp": "1768574194190", "received_at": "2026-01-16T14:36:34.482806"}}
{"event_type": "price_change", "event_ts": "2026-01-16T14:36:34.487927", "ingestion_ts": "2026-01-16T14:36:49.604167", "market_id": "0x49686d26fb712515cd5e12c23f0a1c7e10214c7faa3cb0a730aabe0c33694082", "raw": {"market": "0x49686d26fb712515cd5e12c23f0a1c7e10214c7faa3cb0a730aabe0c33694082", "asset_id": "30442780799048074404860985387051749017905070253466005720364298335239299761065", "price": "0.004", "size": "15.91", "side": "BUY", "timestamp": "1768574194191", "received_at": "2026-01-16T14:36:34.487927"}}
{"event_type": "price_change", "event_ts": "2026-01-16T14:36:34.487927", "ingestion_ts": "2026-01-16T14:36:49.604167", "market_id": "0x49686d26fb712515cd5e12c23f0a1c7e10214c7faa3cb0a730aabe0c33694082", "raw": {"market": "0x49686d26fb712515cd5e12c23f0a1c7e10214c7faa3cb0a730aabe0c33694082", "asset_id": "13244681086321087932946246027856416106585284024824496763706748621681543444582", "price": "0.996", "size": "15.91", "side": "SELL", "timestamp": "1768574194191", "received_at": "2026-01-16T14:36:34.487927"}}
{"event_type": "price_change", "event_ts": "2026-01-16T14:36:34.916382", "ingestion_ts": "2026-01-16T14:36:49.604167", "market_id": "0xc0e6b917320a47228fb96e3b5ae0e5c93773a5ae2662ae4e1f37807cfe47ce98", "raw": {"market": "0xc0e6b917320a47228fb96e3b5ae0e5c93773a5ae2662ae4e1f37807cfe47ce98", "asset_id": "58656358377246279051017109359677190749228949103591068167284263961542487110215", "price": "0.002", "size": "3287.1", "side": "BUY", "timestamp": "1768574194785", "received_at": "2026-01-16T14:36:34.916382"}}
{"event_type": "price_change", "event_ts": "2026-01-16T14:36:34.916382", "ingestion_ts": "2026-01-16T14:36:49.604167", "market_id": "0xc0e6b917320a47228fb96e3b5ae0e5c93773a5ae2662ae4e1f37807cfe47ce98", "raw": {"market": "0xc0e6b917320a47228fb96e3b5ae0e5c93773a5ae2662ae4e1f37807cfe47ce98", "asset_id": "81647294538046680798858716589766492074338758116170717123345952330712416337530", "price": "0.998", "size": "3287.1", "side": "SELL", "timestamp": "1768574194785", "received_at": "2026-01-16T14:36:34.916382"}}
{"event_type": "price_change", "event_ts": "2026-01-16T14:36:34.916423", "ingestion_ts": "2026-01-16T14:36:49.604167", "market_id": "0xc0e6b917320a47228fb96e3b5ae0e5c93773a5ae2662ae4e1f37807cfe47ce98", "raw": {"market": "0xc0e6b917320a47228fb96e3b5ae0e5c93773a5ae2662ae4e1f37807cfe47ce98", "asset_id": "58656358377246279051017109359677190749228949103591068167284263961542487110215", "price": "0.008", "size": "5.87", "side": "BUY", "timestamp": "1768574194785", "received_at": "2026-01-16T14:36:34.916423"}}
{"event_type": "price_change", "event_ts": "2026-01-16T14:36:34.916423", "ingestion_ts": "2026-01-16T14:36:49.604167", "market_id": "0xc0e6b917320a47228fb96e3b5ae0e5c93773a5ae2662ae4e1f37807cfe47ce98", "raw": {"market": "0xc0e6b917320a47228fb96e3b5ae0e5c93773a5ae2662ae4e1f37807cfe47ce98", "asset_id": "81647294538046680798858716589766492074338758116170717123345952330712416337530", "price": "0.992", "size": "5.87", "side": "SELL", "timestamp": "1768574194785", "received_at": "2026-01-16T14:36:34.916423"}}
{"event_type": "price_change", "event_ts": "2026-01-16T14:36:36.290390", "ingestion_ts": "2026-01-16T14:36:49.604167", "market_id": "0xc0e6b917320a47228fb96e3b5ae0e5c93773a5ae2662ae4e1f37807cfe47ce98", "raw": {"market": "0xc0e6b917320a47228fb96e3b5ae0e5c93773a5ae2662ae4e1f37807cfe47ce98", "asset_id": "58656358377246279051017109359677190749228949103591068167284263961542487110215", "price": "0.004", "size": "66.47", "side": "BUY", "timestamp": "1768574196250", "received_at": "2026-01-16T14:36:36.290390"}}
{"event_type": "price_change", "event_ts": "2026-01-16T14:36:36.290390", "ingestion_ts": "2026-01-16T14:36:49.604167", "market_id": "0xc0e6b917320a47228fb96e3b5ae0e5c93773a5ae2662ae4e1f37807cfe47ce98", "raw": {"market": "0xc0e6b917320a47228fb96e3b5ae0e5c93773a5ae2662ae4e1f37807cfe47ce98", "asset_id": "81647294538046680798858716589766492074338758116170717123345952330712416337530", "price": "0.996", "size": "66.47", "side": "SELL", "timestamp": "1768574196250", "received_at": "2026-01-16T14:36:36.290390"}}
{"event_type": "price_change", "event_ts": "2026-01-16T14:36:36.290435", "ingestion_ts": "2026-01-16T14:36:49.604167", "market_id": "0xc0e6b917320a47228fb96e3b5ae0e5c93773a5ae2662ae4e1f37807cfe47ce98", "raw": {"market": "0xc0e6b917320a47228fb96e3b5ae0e5c93773a5ae2662ae4e1f37807cfe47ce98", "asset_id": "58656358377246279051017109359677190749228949103591068167284263961542487110215", "price": "0.009", "size": "11.62", "side": "BUY", "timestamp": "1768574196251", "received_at": "2026-01-16T14:36:36.290435"}}
{"event_type": "price_change", "event_ts": "2026-01-16T14:36:36.290435", "ingestion_ts": "2026-01-16T14:36:49.604167", "market_id": "0xc0e6b917320a47228fb96e3b5ae0e5c93773a5ae2662ae4e1f37807cfe47ce98", "raw": {"market": "0xc0e6b917320a47228fb96e3b5ae0e5c93773a5ae2662ae4e1f37807cfe47ce98", "asset_id": "81647294538046680798858716589766492074338758116170717123345952330712416337530", "price": "0.991", "size": "11.62", "side": "SELL", "timestamp": "1768574196251", "received_at": "2026-01-16T14:36:36.290435"}}
{"event_type": "price_change", "event_ts": "2026-01-16T14:36:36.291184", "ingestion_ts": "2026-01-16T14:36:49.604167", "market_id": "0xc0e6b917320a47228fb96e3b5ae0e5c93773a5ae2662ae4e1f37807cfe47ce98", "raw": {"market": "0xc0e6b917320a47228fb96e3b5ae0e5c93773a5ae2662ae4e1f37807cfe47ce98", "asset_id": "58656358377246279051017109359677190749228949103591068167284263961542487110215", "price": "0.009", "size": "23.24", "side": "BUY", "timestamp": "1768574196252", "received_at": "2026-01-16T14:36:36.291184"}}
{"event_type": "price_change", "event_ts": "2026-01-16T14:36:36.291184", "ingestion_ts": "2026-01-16T14:36:49.604167", "market_id": "0xc0e6b917320a47228fb96e3b5ae0e5c93773a5ae2662ae4e1f37807cfe47ce98", "raw": {"market": "0xc0e6b917320a47228fb96e3b5ae0e5c93773a5ae2662ae4e1f37807cfe47ce98", "asset_id": "81647294538046680798858716589766492074338758116170717123345952330712416337530", "price": "0.991", "size": "23.24", "side": "SELL", "timestamp": "1768574196252", "received_at": "2026-01-16T14:36:36.291184"}}
{"event_type": "price_change", "event_ts": "2026-01-16T14:36:36.293335", "ingestion_ts": "2026-01-16T14:36:49.604167", "market_id": "0xc0e6b917320a47228fb96e3b5ae0e5c93773a5ae2662ae4e1f37807cfe47ce98", "raw": {"market": "0xc0e6b917320a47228fb96e3b5ae0e5c93773a5ae2662ae4e1f37807cfe47ce98", "asset_id": "58656358377246279051017109359677190749228949103591068167284263961542487110215", "price": "0.004", "size": "72.81", "side": "BUY", "timestamp": "1768574196253", "received_at": "2026-01-16T14:36:36.293335"}}
{"event_type": "price_change", "event_ts": "2026-01-16T14:36:36.293335", "ingestion_ts": "2026-01-16T14:36:49.604167", "market_id": "0xc0e6b917320a47228fb96e3b5ae0e5c93773a5ae2662ae4e1f37807cfe47ce98", "raw": {"market": "0xc0e6b917320a47228fb96e3b5ae0e5c93773a5ae2662ae4e1f37807cfe47ce98", "asset_id": "81647294538046680798858716589766492074338758116170717123345952330712416337530", "price": "0.996", "size": "72.81", "side": "SELL", "timestamp": "1768574196253", "received_at": "2026-01-16T14:36:36.293335"}}
{"event_type": "price_change", "event_ts": "2026-01-16T14:36:36.928733", "ingestion_ts": "2026-01-16T14:36:49.604167", "market_id": "0xc0e6b917320a47228fb96e3b5ae0e5c93773a5ae2662ae4e1f37807cfe47ce98", "raw": {"market": "0xc0e6b917320a47228fb96e3b5ae0e5c93773a5ae2662ae4e1f37807cfe47ce98", "asset_id": "58656358377246279051017109359677190749228949103591068167284263961542487110215", "price": "0.074", "size": "5.64", "side": "SELL", "timestamp": "1768574196889", "received_at": "2026-01-16T14:36:36.928733"}}
{"event_type": "price_change", "event_ts": "2026-01-16T14:36:36.928733", "ingestion_ts": "2026-01-16T14:36:49.604167", "market_id": "0xc0e6b917320a47228fb96e3b5ae0e5c93773a5ae2662ae4e1f37807cfe47ce98", "raw": {"market": "0xc0e6b917320a47228fb96e3b5ae0e5c93773a5ae2662ae4e1f37807cfe47ce98", "asset_id": "81647294538046680798858716589766492074338758116170717123345952330712416337530", "price": "0.926", "size": "5.64", "side": "BUY", "timestamp": "1768574196889", "received_at": "2026-01-16T14:36:36.928733"}}
{"event_type": "price_change", "event_ts": "2026-01-16T14:36:37.072791", "ingestion_ts": "2026-01-16T14:36:49.604167", "market_id": "0xaf9d0e448129a9f657f851d49495ba4742055d80e0ef1166ba0ee81d4d594214", "raw": {"market": "0xaf9d0e448129a9f657f851d49495ba4742055d80e0ef1166ba0ee81d4d594214", "asset_id": "4153292802911610701832309484716814274802943278345248636922528170020319407796", "price": "0.981", "size": "140.01", "side": "SELL", "timestamp": "1768574197037", "received_at": "2026-01-16T14:36:37.072791"}}
{"event_type": "price_change", "event_ts": "2026-01-16T14:36:37.072791", "ingestion_ts": "2026-01-16T14:36:49.604167", "market_id": "0xaf9d0e448129a9f657f851d49495ba4742055d80e0ef1166ba0ee81d4d594214", "raw": {"market": "0xaf9d0e448129a9f657f851d49495ba4742055d80e0ef1166ba0ee81d4d594214", "asset_id": "101676997363687199724245607342877036148401850938023978421879460310389391082353", "price": "0.019", "size": "140.01", "side": "BUY", "timestamp": "1768574197037", "received_at": "2026-01-16T14:36:37.072791"}}
{"event_type": "price_change", "event_ts": "2026-01-16T14:36:37.430634", "ingestion_ts": "2026-01-16T14:36:49.604167", "market_id": "0x49686d26fb712515cd5e12c23f0a1c7e10214c7faa3cb0a730aabe0c33694082", "raw": {"market": "0x49686d26fb712515cd5e12c23f0a1c7e10214c7faa3cb0a730aabe0c33694082", "asset_id": "13244681086321087932946246027856416106585284024824496763706748621681543444582", "price": "0.852", "size": "23.36", "side": "BUY", "timestamp": "1768574197378", "received_at": "2026-01-16T14:36:37.430634"}}
{"event_type": "price_change", "event_ts": "2026-01-16T14:36:37.430634", "ingestion_ts": "2026-01-16T14:36:49.604167", "market_id": "0x49686d26fb712515cd5e12c23f0a1c7e10214c7faa3cb0a730aabe0c33694082", "raw": {"market": "0x49686d26fb712515cd5e12c23f0a1c7e10214c7faa3cb0a730aabe0c33694082", "asset_id": "30442780799048074404860985387051749017905070253466005720364298335239299761065", "price": "0.148", "size": "23.36", "side": "SELL", "timestamp": "1768574197378", "received_at": "2026-01-16T14:36:37.430634"}}
{"event_type": "price_change", "event_ts": "2026-01-16T14:36:37.489748", "ingestion_ts": "2026-01-16T14:36:49.604167", "market_id": "0x49686d26fb712515cd5e12c23f0a1c7e10214c7faa3cb0a730aabe0c33694082", "raw": {"market": "0x49686d26fb712515cd5e12c23f0a1c7e10214c7faa3cb0a730aabe0c33694082", "asset_id": "30442780799048074404860985387051749017905070253466005720364298335239299761065", "price": "0.002", "size": "662.74", "side": "BUY", "timestamp": "1768574197417", "received_at": "2026-01-16T14:36:37.489748"}}
{"event_type": "price_change", "event_ts": "2026-01-16T14:36:37.489748", "ingestion_ts": "2026-01-16T14:36:49.604167", "market_id": "0x49686d26fb712515cd5e12c23f0a1c7e10214c7faa3cb0a730aabe0c33694082", "raw": {"market": "0x49686d26fb712515cd5e12c23f0a1c7e10214c7faa3cb0a730aabe0c33694082", "asset_id": "13244681086321087932946246027856416106585284024824496763706748621681543444582", "price": "0.998", "size": "662.74", "side": "SELL", "timestamp": "1768574197417", "received_at": "2026-01-16T14:36:37.489748"}}
{"event_type": "price_change", "event_ts": "2026-01-16T14:36:37.523830", "ingestion_ts": "2026-01-16T14:36:49.604167", "market_id": "0x49686d26fb712515cd5e12c23f0a1c7e10214c7faa3cb0a730aabe0c33694082", "raw": {"market": "0x49686d26fb712515cd5e12c23f0a1c7e10214c7faa3cb0a730aabe0c33694082", "asset_id": "30442780799048074404860985387051749017905070253466005720364298335239299761065", "price": "0.003", "size": "25.78", "side": "BUY", "timestamp": "1768574197449", "received_at": "2026-01-16T14:36:37.523830"}}
{"event_type": "price_change", "event_ts": "2026-01-16T14:36:37.523830", "ingestion_ts": "2026-01-16T14:36:49.604167", "market_id": "0x49686d26fb712515cd5e12c23f0a1c7e10214c7faa3cb0a730aabe0c33694082", "raw": {"market": "0x49686d26fb712515cd5e12c23f0a1c7e10214c7faa3cb0a730aabe0c33694082", "asset_id": "13244681086321087932946246027856416106585284024824496763706748621681543444582", "price": "0.997", "size": "25.78", "side": "SELL", "timestamp": "1768574197449", "received_at": "2026-01-16T14:36:37.523830"}}
{"event_type": "price_change", "event_ts": "2026-01-16T14:36:37.551910", "ingestion_ts": "2026-01-16T14:36:49.604167", "market_id": "0xc0e6b917320a47228fb96e3b5ae0e5c93773a5ae2662ae4e1f37807cfe47ce98", "raw": {"market": "0xc0e6b917320a47228fb96e3b5ae0e5c93773a5ae2662ae4e1f37807cfe47ce98", "asset_id": "58656358377246279051017109359677190749228949103591068167284263961542487110215", "price": "0.073", "size": "27.33", "side": "SELL", "timestamp": "1768574197465", "received_at": "2026-01-16T14:36:37.551910"}}
{"event_type": "price_change", "event_ts": "2026-01-16T14:36:37.551910", "ingestion_ts": "2026-01-16T14:36:49.604167", "market_id": "0xc0e6b917320a47228fb96e3b5ae0e5c93773a5ae2662ae4e1f37807cfe47ce98", "raw": {"market": "0xc0e6b917320a47228fb96e3b5ae0e5c93773a5ae2662ae4e1f37807cfe47ce98", "asset_id": "81647294538046680798858716589766492074338758116170717123345952330712416337530", "price": "0.927", "size": "27.33", "side": "BUY", "timestamp": "1768574197465", "received_at": "2026-01-16T14:36:37.551910"}}
{"event_type": "price_change", "event_ts": "2026-01-16T14:36:37.551931", "ingestion_ts": "2026-01-16T14:36:49.604167", "market_id": "0xc0e6b917320a47228fb96e3b5ae0e5c93773a5ae2662ae4e1f37807cfe47ce98", "raw": {"market": "0xc0e6b917320a47228fb96e3b5ae0e5c93773a5ae2662ae4e1f37807cfe47ce98", "asset_id": "58656358377246279051017109359677190749228949103591068167284263961542487110215", "price": "0.073", "size": "54.66", "side": "SELL", "timestamp": "1768574197466", "received_at": "2026-01-16T14:36:37.551931"}}
{"event_type": "price_change", "event_ts": "2026-01-16T14:36:37.551931", "ingestion_ts": "2026-01-16T14:36:49.604167", "market_id": "0xc0e6b917320a47228fb96e3b5ae0e5c93773a5ae2662ae4e1f37807cfe47ce98", "raw": {"market": "0xc0e6b917320a47228fb96e3b5ae0e5c93773a5ae2662ae4e1f37807cfe47ce98", "asset_id": "81647294538046680798858716589766492074338758116170717123345952330712416337530", "price": "0.927", "size": "54.66", "side": "BUY", "timestamp": "1768574197466", "received_at": "2026-01-16T14:36:37.551931"}}
{"event_type": "price_change", "event_ts": "2026-01-16T14:36:37.674112", "ingestion_ts": "2026-01-16T14:36:49.604167", "market_id": "0x2393ed0b0fdc450054c7b9071907eca75cf4fc36e385adf4a0a5f99ee62243e8", "raw": {"market": "0x2393ed0b0fdc450054c7b9071907eca75cf4fc36e385adf4a0a5f99ee62243e8", "asset_id": "32769749367306925959219403371425714180265458150646381231272229429098460625924", "price": "0.946", "size": "50", "side": "BUY", "timestamp": "1768574197552", "received_at": "2026-01-16T14:36:37.674112"}}
{"event_type": "price_change", "event_ts": "2026-01-16T14:36:37.674112", "ingestion_ts": "2026-01-16T14:36:49.604167", "market_id": "0x2393ed0b0fdc450054c7b9071907eca75cf4fc36e385adf4a0a5f99ee62243e8", "raw": {"market": "0x2393ed0b0fdc450054c7b9071907eca75cf4fc36e385adf4a0a5f99ee62243e8", "asset_id": "100074770378634056601572485653252702850363676459996771990439989989293515601975", "price": "0.054", "size": "50", "side": "SELL", "timestamp": "1768574197552", "received_at": "2026-01-16T14:36:37.674112"}}
{"event_type": "price_change", "event_ts": "2026-01-16T14:36:37.777329", "ingestion_ts": "2026-01-16T14:36:49.604167", "market_id": "0x2393ed0b0fdc450054c7b9071907eca75cf4fc36e385adf4a0a5f99ee62243e8", "raw": {"market": "0x2393ed0b0fdc450054c7b9071907eca75cf4fc36e385adf4a0a5f99ee62243e8", "asset_id": "100074770378634056601572485653252702850363676459996771990439989989293515601975", "price": "0.055", "size": "0", "side": "SELL", "timestamp": "1768574197653", "received_at": "2026-01-16T14:36:37.777329"}}
{"event_type": "price_change", "event_ts": "2026-01-16T14:36:37.777329", "ingestion_ts": "2026-01-16T14:36:49.604167", "market_id": "0x2393ed0b0fdc450054c7b9071907eca75cf4fc36e385adf4a0a5f99ee62243e8", "raw": {"market": "0x2393ed0b0fdc450054c7b9071907eca75cf4fc36e385adf4a0a5f99ee62243e8", "asset_id": "32769749367306925959219403371425714180265458150646381231272229429098460625924", "price": "0.945", "size": "0", "side": "BUY", "timestamp": "1768574197653", "received_at": "2026-01-16T14:36:37.777329"}}
{"event_type": "price_change", "event_ts": "2026-01-16T14:36:37.810432", "ingestion_ts": "2026-01-16T14:36:49.604167", "market_id": "0x2393ed0b0fdc450054c7b9071907eca75cf4fc36e385adf4a0a5f99ee62243e8", "raw": {"market": "0x2393ed0b0fdc450054c7b9071907eca75cf4fc36e385adf4a0a5f99ee62243e8", "asset_id": "100074770378634056601572485653252702850363676459996771990439989989293515601975", "price": "0.053", "size": "198", "side": "SELL", "timestamp": "1768574197681", "received_at": "2026-01-16T14:36:37.810432"}}
{"event_type": "price_change", "event_ts": "2026-01-16T14:36:37.810432", "ingestion_ts": "2026-01-16T14:36:49.604167", "market_id": "0x2393ed0b0fdc450054c7b9071907eca75cf4fc36e385adf4a0a5f99ee62243e8", "raw": {"market": "0x2393ed0b0fdc450054c7b9071907eca75cf4fc36e385adf4a0a5f99ee62243e8", "asset_id": "32769749367306925959219403371425714180265458150646381231272229429098460625924", "price": "0.947", "size": "198", "side": "BUY", "timestamp": "1768574197681", "received_at": "2026-01-16T14:36:37.810432"}}
{"event_type": "price_change", "event_ts": "2026-01-16T14:36:37.895800", "ingestion_ts": "2026-01-16T14:36:49.604167", "market_id": "0xaf9d0e448129a9f657f851d49495ba4742055d80e0ef1166ba0ee81d4d594214", "raw": {"market": "0xaf9d0e448129a9f657f851d49495ba4742055d80e0ef1166ba0ee81d4d594214", "asset_id": "4153292802911610701832309484716814274802943278345248636922528170020319407796", "price": "0.989", "size": "0", "side": "SELL", "timestamp": "1768574197859", "received_at": "2026-01-16T14:36:37.895800"}}
{"event_type": "price_change", "event_ts": "2026-01-16T14:36:37.895800", "ingestion_ts": "2026-01-16T14:36:49.604167", "market_id": "0xaf9d0e448129a9f657f851d49495ba4742055d80e0ef1166ba0ee81d4d594214", "raw": {"market": "0xaf9d0e448129a9f657f851d49495ba4742055d80e0ef1166ba0ee81d4d594214", "asset_id": "101676997363687199724245607342877036148401850938023978421879460310389391082353", "price": "0.011", "size": "0", "side": "BUY", "timestamp": "1768574197859", "received_at": "2026-01-16T14:36:37.895800"}}
{"event_type": "price_change", "event_ts": "2026-01-16T14:36:37.945615", "ingestion_ts": "2026-01-16T14:36:49.604167", "market_id": "0xaf9d0e448129a9f657f851d49495ba4742055d80e0ef1166ba0ee81d4d594214", "raw": {"market": "0xaf9d0e448129a9f657f851d49495ba4742055d80e0ef1166ba0ee81d4d594214", "asset_id": "4153292802911610701832309484716814274802943278345248636922528170020319407796", "price": "0.98", "size": "20.5", "side": "SELL", "timestamp": "1768574197910", "received_at": "2026-01-16T14:36:37.945615"}}
{"event_type": "price_change", "event_ts": "2026-01-16T14:36:37.945615", "ingestion_ts": "2026-01-16T14:36:49.604167", "market_id": "0xaf9d0e448129a9f657f851d49495ba4742055d80e0ef1166ba0ee81d4d594214", "raw": {"market": "0xaf9d0e448129a9f657f851d49495ba4742055d80e0ef1166ba0ee81d4d594214", "asset_id": "101676997363687199724245607342877036148401850938023978421879460310389391082353", "price": "0.02", "size": "20.5", "side": "BUY", "timestamp": "1768574197910", "received_at": "2026-01-16T14:36:37.945615"}}
{"event_type": "price_change", "event_ts": "2026-01-16T14:36:38.088372", "ingestion_ts": "2026-01-16T14:36:49.604167", "market_id": "0x2393ed0b0fdc450054c7b9071907eca75cf4fc36e385adf4a0a5f99ee62243e8", "raw": {"market": "0x2393ed0b0fdc450054c7b9071907eca75cf4fc36e385adf4a0a5f99ee62243e8", "asset_id": "32769749367306925959219403371425714180265458150646381231272229429098460625924", "price": "0.944", "size": "0", "side": "BUY", "timestamp": "1768574198036", "received_at": "2026-01-16T14:36:38.088372"}}
{"event_type": "price_change", "event_ts": "2026-01-16T14:36:38.088372", "ingestion_ts": "2026-01-16T14:36:49.604167", "market_id": "0x2393ed0b0fdc450054c7b9071907eca75cf4fc36e385adf4a0a5f99ee62243e8", "raw": {"market": "0x2393ed0b0fdc450054c7b9071907eca75cf4fc36e385adf4a0a5f99ee62243e8", "asset_id": "100074770378634056601572485653252702850363676459996771990439989989293515601975", "price": "0.056", "size": "0", "side": "SELL", "timestamp": "1768574198036", "received_at": "2026-01-16T14:36:38.088372"}}
{"event_type": "price_change", "event_ts": "2026-01-16T14:36:39.062126", "ingestion_ts": "2026-01-16T14:36:49.604167", "market_id": "0xc0e6b917320a47228fb96e3b5ae0e5c93773a5ae2662ae4e1f37807cfe47ce98", "raw": {"market": "0xc0e6b917320a47228fb96e3b5ae0e5c93773a5ae2662ae4e1f37807cfe47ce98", "asset_id": "58656358377246279051017109359677190749228949103591068167284263961542487110215", "price": "0.002", "size": "3279.99", "side": "BUY", "timestamp": "1768574199021", "received_at": "2026-01-16T14:36:39.062126"}}
{"event_type": "price_change", "event_ts": "2026-01-16T14:36:39.062126", "ingestion_ts": "2026-01-16T14:36:49.604167", "market_id": "0xc0e6b917320a47228fb96e3b5ae0e5c93773a5ae2662ae4e1f37807cfe47ce98", "raw": {"market": "0xc0e6b917320a47228fb96e3b5ae0e5c93773a5ae2662ae4e1f37807cfe47ce98", "asset_id": "81647294538046680798858716589766492074338758116170717123345952330712416337530", "price": "0.998", "size": "3279.99", "side": "SELL", "timestamp": "1768574199021", "received_at": "2026-01-16T14:36:39.062126"}}
{"event_type": "price_change", "event_ts": "2026-01-16T14:36:39.062166", "ingestion_ts": "2026-01-16T14:36:49.604167", "market_id": "0xc0e6b917320a47228fb96e3b5ae0e5c93773a5ae2662ae4e1f37807cfe47ce98", "raw": {"market": "0xc0e6b917320a47228fb96e3b5ae0e5c93773a5ae2662ae4e1f37807cfe47ce98", "asset_id": "58656358377246279051017109359677190749228949103591068167284263961542487110215", "price": "0.008", "size": "0", "side": "BUY", "timestamp": "1768574199021", "received_at": "2026-01-16T14:36:39.062166"}}
{"event_type": "price_change", "event_ts": "2026-01-16T14:36:39.062166", "ingestion_ts": "2026-01-16T14:36:49.604167", "market_id": "0xc0e6b917320a47228fb96e3b5ae0e5c93773a5ae2662ae4e1f37807cfe47ce98", "raw": {"market": "0xc0e6b917320a47228fb96e3b5ae0e5c93773a5ae2662ae4e1f37807cfe47ce98", "asset_id": "81647294538046680798858716589766492074338758116170717123345952330712416337530", "price": "0.992", "size": "0", "side": "SELL", "timestamp": "1768574199021", "received_at": "2026-01-16T14:36:39.062166"}}
{"event_type": "price_change", "event_ts": "2026-01-16T14:36:39.062193", "ingestion_ts": "2026-01-16T14:36:49.604167", "market_id": "0xc0e6b917320a47228fb96e3b5ae0e5c93773a5ae2662ae4e1f37807cfe47ce98", "raw": {"market": "0xc0e6b917320a47228fb96e3b5ae0e5c93773a5ae2662ae4e1f37807cfe47ce98", "asset_id": "58656358377246279051017109359677190749228949103591068167284263961542487110215", "price": "0.009", "size": "11.62", "side": "BUY", "timestamp": "1768574199021", "received_at": "2026-01-16T14:36:39.062193"}}
{"event_type": "price_change", "event_ts": "2026-01-16T14:36:39.062193", "ingestion_ts": "2026-01-16T14:36:49.604167", "market_id": "0xc0e6b917320a47228fb96e3b5ae0e5c93773a5ae2662ae4e1f37807cfe47ce98", "raw": {"market": "0xc0e6b917320a47228fb96e3b5ae0e5c93773a5ae2662ae4e1f37807cfe47ce98", "asset_id": "81647294538046680798858716589766492074338758116170717123345952330712416337530", "price": "0.991", "size": "11.62", "side": "SELL", "timestamp": "1768574199021", "received_at": "2026-01-16T14:36:39.062193"}}
{"event_type": "price_change", "event_ts": "2026-01-16T14:36:39.063639", "ingestion_ts": "2026-01-16T14:36:49.604167", "market_id": "0x49686d26fb712515cd5e12c23f0a1c7e10214c7faa3cb0a730aabe0c33694082", "raw": {"market": "0x49686d26fb712515cd5e12c23f0a1c7e10214c7faa3cb0a730aabe0c33694082", "asset_id": "30442780799048074404860985387051749017905070253466005720364298335239299761065", "price": "0.004", "size": "0", "side": "BUY", "timestamp": "1768574199021", "received_at": "2026-01-16T14:36:39.063639"}}
{"event_type": "price_change", "event_ts": "2026-01-16T14:36:39.063639", "ingestion_ts": "2026-01-16T14:36:49.604167", "market_id": "0x49686d26fb712515cd5e12c23f0a1c7e10214c7faa3cb0a730aabe0c33694082", "raw": {"market": "0x49686d26fb712515cd5e12c23f0a1c7e10214c7faa3cb0a730aabe0c33694082", "asset_id": "13244681086321087932946246027856416106585284024824496763706748621681543444582", "price": "0.996", "size": "0", "side": "SELL", "timestamp": "1768574199021", "received_at": "2026-01-16T14:36:39.063639"}}
{"event_type": "price_change", "event_ts": "2026-01-16T14:36:39.063664", "ingestion_ts": "2026-01-16T14:36:49.604167", "market_id": "0x49686d26fb712515cd5e12c23f0a1c7e10214c7faa3cb0a730aabe0c33694082", "raw": {"market": "0x49686d26fb712515cd5e12c23f0a1c7e10214c7faa3cb0a730aabe0c33694082", "asset_id": "30442780799048074404860985387051749017905070253466005720364298335239299761065", "price": "0.008", "size": "5.94", "side": "BUY", "timestamp": "1768574199021", "received_at": "2026-01-16T14:36:39.063664"}}
{"event_type": "price_change", "event_ts": "2026-01-16T14:36:39.063664", "ingestion_ts": "2026-01-16T14:36:49.604167", "market_id": "0x49686d26fb712515cd5e12c23f0a1c7e10214c7faa3cb0a730aabe0c33694082", "raw": {"market": "0x49686d26fb712515cd5e12c23f0a1c7e10214c7faa3cb0a730aabe0c33694082", "asset_id": "13244681086321087932946246027856416106585284024824496763706748621681543444582", "price": "0.992", "size": "5.94", "side": "SELL", "timestamp": "1768574199021", "received_at": "2026-01-16T14:36:39.063664"}}
{"event_type": "price_change", "event_ts": "2026-01-16T14:36:39.063679", "ingestion_ts": "2026-01-16T14:36:49.604167", "market_id": "0x49686d26fb712515cd5e12c23f0a1c7e10214c7faa3cb0a730aabe0c33694082", "raw": {"market": "0x49686d26fb712515cd5e12c23f0a1c7e10214c7faa3cb0a730aabe0c33694082", "asset_id": "30442780799048074404860985387051749017905070253466005720364298335239299761065", "price": "0.012", "size": "0", "side": "BUY", "timestamp": "1768574199021", "received_at": "2026-01-16T14:36:39.063679"}}
{"event_type": "price_change", "event_ts": "2026-01-16T14:36:39.063679", "ingestion_ts": "2026-01-16T14:36:49.604167", "market_id": "0x49686d26fb712515cd5e12c23f0a1c7e10214c7faa3cb0a730aabe0c33694082", "raw": {"market": "0x49686d26fb712515cd5e12c23f0a1c7e10214c7faa3cb0a730aabe0c33694082", "asset_id": "13244681086321087932946246027856416106585284024824496763706748621681543444582", "price": "0.988", "size": "0", "side": "SELL", "timestamp": "1768574199021", "received_at": "2026-01-16T14:36:39.063679"}}
{"event_type": "price_change", "event_ts": "2026-01-16T14:36:39.771847", "ingestion_ts": "2026-01-16T14:36:49.604167", "market_id": "0x49686d26fb712515cd5e12c23f0a1c7e10214c7faa3cb0a730aabe0c33694082", "raw": {"market": "0x49686d26fb712515cd5e12c23f0a1c7e10214c7faa3cb0a730aabe0c33694082", "asset_id": "30442780799048074404860985387051749017905070253466005720364298335239299761065", "price": "0.003", "size": "15.78", "side": "BUY", "timestamp": "1768574199658", "received_at": "2026-01-16T14:36:39.771847"}}
{"event_type": "price_change", "event_ts": "2026-01-16T14:36:39.771847", "ingestion_ts": "2026-01-16T14:36:49.604167", "market_id": "0x49686d26fb712515cd5e12c23f0a1c7e10214c7faa3cb0a730aabe0c33694082", "raw": {"market": "0x49686d26fb712515cd5e12c23f0a1c7e10214c7faa3cb0a730aabe0c33694082", "asset_id": "13244681086321087932946246027856416106585284024824496763706748621681543444582", "price": "0.997", "size": "15.78", "side": "SELL", "timestamp": "1768574199658", "received_at": "2026-01-16T14:36:39.771847"}}
{"event_type": "price_change", "event_ts": "2026-01-16T14:36:39.771902", "ingestion_ts": "2026-01-16T14:36:49.604167", "market_id": "0xc55db914f0fd1fee18997706712c0dfd8d0369cdbef93a9fef12bd001914ca77", "raw": {"market": "0xc55db914f0fd1fee18997706712c0dfd8d0369cdbef93a9fef12bd001914ca77", "asset_id": "114600293444080540179603459515770723592661967180480327891296353898330242622833", "price": "0.837", "size": "0", "side": "BUY", "timestamp": "1768574199658", "received_at": "2026-01-16T14:36:39.771902"}}
{"event_type": "price_change", "event_ts": "2026-01-16T14:36:39.771902", "ingestion_ts": "2026-01-16T14:36:49.604167", "market_id": "0xc55db914f0fd1fee18997706712c0dfd8d0369cdbef93a9fef12bd001914ca77", "raw": {"market": "0xc55db914f0fd1fee18997706712c0dfd8d0369cdbef93a9fef12bd001914ca77", "asset_id": "72354723612769247426741660426331235762851940382312402276325808095604519806766", "price": "0.163", "size": "0", "side": "SELL", "timestamp": "1768574199658", "received_at": "2026-01-16T14:36:39.771902"}}
{"event_type": "price_change", "event_ts": "2026-01-16T14:36:39.806658", "ingestion_ts": "2026-01-16T14:36:49.604167", "market_id": "0xc55db914f0fd1fee18997706712c0dfd8d0369cdbef93a9fef12bd001914ca77", "raw": {"market": "0xc55db914f0fd1fee18997706712c0dfd8d0369cdbef93a9fef12bd001914ca77", "asset_id": "114600293444080540179603459515770723592661967180480327891296353898330242622833", "price": "0.855", "size": "302", "side": "BUY", "timestamp": "1768574199707", "received_at": "2026-01-16T14:36:39.806658"}}
{"event_type": "price_change", "event_ts": "2026-01-16T14:36:39.806658", "ingestion_ts": "2026-01-16T14:36:49.604167", "market_id": "0xc55db914f0fd1fee18997706712c0dfd8d0369cdbef93a9fef12bd001914ca77", "raw": {"market": "0xc55db914f0fd1fee18997706712c0dfd8d0369cdbef93a9fef12bd001914ca77", "asset_id": "72354723612769247426741660426331235762851940382312402276325808095604519806766", "price": "0.145", "size": "302", "side": "SELL", "timestamp": "1768574199707", "received_at": "2026-01-16T14:36:39.806658"}}
{"event_type": "price_change", "event_ts": "2026-01-16T14:36:39.806729", "ingestion_ts": "2026-01-16T14:36:49.604167", "market_id": "0x49686d26fb712515cd5e12c23f0a1c7e10214c7faa3cb0a730aabe0c33694082", "raw": {"market": "0x49686d26fb712515cd5e12c23f0a1c7e10214c7faa3cb0a730aabe0c33694082", "asset_id": "30442780799048074404860985387051749017905070253466005720364298335239299761065", "price": "0.004", "size": "10", "side": "BUY", "timestamp": "1768574199708", "received_at": "2026-01-16T14:36:39.806729"}}
{"event_type": "price_change", "event_ts": "2026-01-16T14:36:39.806729", "ingestion_ts": "2026-01-16T14:36:49.604167", "market_id": "0x49686d26fb712515cd5e12c23f0a1c7e10214c7faa3cb0a730aabe0c33694082", "raw": {"market": "0x49686d26fb712515cd5e12c23f0a1c7e10214c7faa3cb0a730aabe0c33694082", "asset_id": "13244681086321087932946246027856416106585284024824496763706748621681543444582", "price": "0.996", "size": "10", "side": "SELL", "timestamp": "1768574199708", "received_at": "2026-01-16T14:36:39.806729"}}
{"event_type": "price_change", "event_ts": "2026-01-16T14:36:39.961315", "ingestion_ts": "2026-01-16T14:36:49.604167", "market_id": "0xc0e6b917320a47228fb96e3b5ae0e5c93773a5ae2662ae4e1f37807cfe47ce98", "raw": {"market": "0xc0e6b917320a47228fb96e3b5ae0e5c93773a5ae2662ae4e1f37807cfe47ce98", "asset_id": "58656358377246279051017109359677190749228949103591068167284263961542487110215", "price": "0.004", "size": "93.55", "side": "BUY", "timestamp": "1768574199904", "received_at": "2026-01-16T14:36:39.961315"}}
{"event_type": "price_change", "event_ts": "2026-01-16T14:36:39.961315", "ingestion_ts": "2026-01-16T14:36:49.604167", "market_id": "0xc0e6b917320a47228fb96e3b5ae0e5c93773a5ae2662ae4e1f37807cfe47ce98", "raw": {"market": "0xc0e6b917320a47228fb96e3b5ae0e5c93773a5ae2662ae4e1f37807cfe47ce98", "asset_id": "81647294538046680798858716589766492074338758116170717123345952330712416337530", "price": "0.996", "size": "93.55", "side": "SELL", "timestamp": "1768574199904", "received_at": "2026-01-16T14:36:39.961315"}}
{"event_type": "price_change", "event_ts": "2026-01-16T14:36:39.961384", "ingestion_ts": "2026-01-16T14:36:49.604167", "market_id": "0x49686d26fb712515cd5e12c23f0a1c7e10214c7faa3cb0a730aabe0c33694082", "raw": {"market": "0x49686d26fb712515cd5e12c23f0a1c7e10214c7faa3cb0a730aabe0c33694082", "asset_id": "30442780799048074404860985387051749017905070253466005720364298335239299761065", "price": "0.004", "size": "23.15", "side": "BUY", "timestamp": "1768574199904", "received_at": "2026-01-16T14:36:39.961384"}}
{"event_type": "price_change", "event_ts": "2026-01-16T14:36:39.961384", "ingestion_ts": "2026-01-16T14:36:49.604167", "market_id": "0x49686d26fb712515cd5e12c23f0a1c7e10214c7faa3cb0a730aabe0c33694082", "raw": {"market": "0x49686d26fb712515cd5e12c23f0a1c7e10214c7faa3cb0a730aabe0c33694082", "asset_id": "13244681086321087932946246027856416106585284024824496763706748621681543444582", "price": "0.996", "size": "23.15", "side": "SELL", "timestamp": "1768574199904", "received_at": "2026-01-16T14:36:39.961384"}}
{"event_type": "price_change", "event_ts": "2026-01-16T14:36:39.961398", "ingestion_ts": "2026-01-16T14:36:49.604167", "market_id": "0x49686d26fb712515cd5e12c23f0a1c7e10214c7faa3cb0a730aabe0c33694082", "raw": {"market": "0x49686d26fb712515cd5e12c23f0a1c7e10214c7faa3cb0a730aabe0c33694082", "asset_id": "30442780799048074404860985387051749017905070253466005720364298335239299761065", "price": "0.011", "size": "19", "side": "BUY", "timestamp": "1768574199906", "received_at": "2026-01-16T14:36:39.961398"}}
{"event_type": "price_change", "event_ts": "2026-01-16T14:36:39.961398", "ingestion_ts": "2026-01-16T14:36:49.604167", "market_id": "0x49686d26fb712515cd5e12c23f0a1c7e10214c7faa3cb0a730aabe0c33694082", "raw": {"market": "0x49686d26fb712515cd5e12c23f0a1c7e10214c7faa3cb0a730aabe0c33694082", "asset_id": "13244681086321087932946246027856416106585284024824496763706748621681543444582", "price": "0.989", "size": "19", "side": "SELL", "timestamp": "1768574199906", "received_at": "2026-01-16T14:36:39.961398"}}
{"event_type": "price_change", "event_ts": "2026-01-16T14:36:39.961409", "ingestion_ts": "2026-01-16T14:36:49.604167", "market_id": "0xc0e6b917320a47228fb96e3b5ae0e5c93773a5ae2662ae4e1f37807cfe47ce98", "raw": {"market": "0xc0e6b917320a47228fb96e3b5ae0e5c93773a5ae2662ae4e1f37807cfe47ce98", "asset_id": "58656358377246279051017109359677190749228949103591068167284263961542487110215", "price": "0.004", "size": "114.29", "side": "BUY", "timestamp": "1768574199906", "received_at": "2026-01-16T14:36:39.961409"}}
{"event_type": "price_change", "event_ts": "2026-01-16T14:36:39.961409", "ingestion_ts": "2026-01-16T14:36:49.604167", "market_id": "0xc0e6b917320a47228fb96e3b5ae0e5c93773a5ae2662ae4e1f37807cfe47ce98", "raw": {"market": "0xc0e6b917320a47228fb96e3b5ae0e5c93773a5ae2662ae4e1f37807cfe47ce98", "asset_id": "81647294538046680798858716589766492074338758116170717123345952330712416337530", "price": "0.996", "size": "114.29", "side": "SELL", "timestamp": "1768574199906", "received_at": "2026-01-16T14:36:39.961409"}}
{"event_type": "price_change", "event_ts": "2026-01-16T14:36:40.555679", "ingestion_ts": "2026-01-16T14:36:49.604167", "market_id": "0xc0e6b917320a47228fb96e3b5ae0e5c93773a5ae2662ae4e1f37807cfe47ce98", "raw": {"market": "0xc0e6b917320a47228fb96e3b5ae0e5c93773a5ae2662ae4e1f37807cfe47ce98", "asset_id": "58656358377246279051017109359677190749228949103591068167284263961542487110215", "price": "0.073", "size": "27.33", "side": "SELL", "timestamp": "1768574200425", "received_at": "2026-01-16T14:36:40.555679"}}
{"event_type": "price_change", "event_ts": "2026-01-16T14:36:40.555679", "ingestion_ts": "2026-01-16T14:36:49.604167", "market_id": "0xc0e6b917320a47228fb96e3b5ae0e5c93773a5ae2662ae4e1f37807cfe47ce98", "raw": {"market": "0xc0e6b917320a47228fb96e3b5ae0e5c93773a5ae2662ae4e1f37807cfe47ce98", "asset_id": "81647294538046680798858716589766492074338758116170717123345952330712416337530", "price": "0.927", "size": "27.33", "side": "BUY", "timestamp": "1768574200425", "received_at": "2026-01-16T14:36:40.555679"}}
{"event_type": "price_change", "event_ts": "2026-01-16T14:36:40.555720", "ingestion_ts": "2026-01-16T14:36:49.604167", "market_id": "0xc0e6b917320a47228fb96e3b5ae0e5c93773a5ae2662ae4e1f37807cfe47ce98", "raw": {"market": "0xc0e6b917320a47228fb96e3b5ae0e5c93773a5ae2662ae4e1f37807cfe47ce98", "asset_id": "58656358377246279051017109359677190749228949103591068167284263961542487110215", "price": "0.074", "size": "0", "side": "SELL", "timestamp": "1768574200425", "received_at": "2026-01-16T14:36:40.555720"}}
{"event_type": "price_change", "event_ts": "2026-01-16T14:36:40.555720", "ingestion_ts": "2026-01-16T14:36:49.604167", "market_id": "0xc0e6b917320a47228fb96e3b5ae0e5c93773a5ae2662ae4e1f37807cfe47ce98", "raw": {"market": "0xc0e6b917320a47228fb96e3b5ae0e5c93773a5ae2662ae4e1f37807cfe47ce98", "asset_id": "81647294538046680798858716589766492074338758116170717123345952330712416337530", "price": "0.926", "size": "0", "side": "BUY", "timestamp": "1768574200425", "received_at": "2026-01-16T14:36:40.555720"}}
{"event_type": "price_change", "event_ts": "2026-01-16T14:36:41.245869", "ingestion_ts": "2026-01-16T14:36:49.604167", "market_id": "0xc0e6b917320a47228fb96e3b5ae0e5c93773a5ae2662ae4e1f37807cfe47ce98", "raw": {"market": "0xc0e6b917320a47228fb96e3b5ae0e5c93773a5ae2662ae4e1f37807cfe47ce98", "asset_id": "58656358377246279051017109359677190749228949103591068167284263961542487110215", "price": "0.072", "size": "13.03", "side": "SELL", "timestamp": "1768574201196", "received_at": "2026-01-16T14:36:41.245869"}}
{"event_type": "price_change", "event_ts": "2026-01-16T14:36:41.245869", "ingestion_ts": "2026-01-16T14:36:49.604167", "market_id": "0xc0e6b917320a47228fb96e3b5ae0e5c93773a5ae2662ae4e1f37807cfe47ce98", "raw": {"market": "0xc0e6b917320a47228fb96e3b5ae0e5c93773a5ae2662ae4e1f37807cfe47ce98", "asset_id": "81647294538046680798858716589766492074338758116170717123345952330712416337530", "price": "0.928", "size": "13.03", "side": "BUY", "timestamp": "1768574201196", "received_at": "2026-01-16T14:36:41.245869"}}
{"event_type": "price_change", "event_ts": "2026-01-16T14:36:41.245903", "ingestion_ts": "2026-01-16T14:36:49.604167", "market_id": "0xc0e6b917320a47228fb96e3b5ae0e5c93773a5ae2662ae4e1f37807cfe47ce98", "raw": {"market": "0xc0e6b917320a47228fb96e3b5ae0e5c93773a5ae2662ae4e1f37807cfe47ce98", "asset_id": "58656358377246279051017109359677190749228949103591068167284263961542487110215", "price": "0.076", "size": "6.9", "side": "SELL", "timestamp": "1768574201197", "received_at": "2026-01-16T14:36:41.245903"}}
{"event_type": "price_change", "event_ts": "2026-01-16T14:36:41.245903", "ingestion_ts": "2026-01-16T14:36:49.604167", "market_id": "0xc0e6b917320a47228fb96e3b5ae0e5c93773a5ae2662ae4e1f37807cfe47ce98", "raw": {"market": "0xc0e6b917320a47228fb96e3b5ae0e5c93773a5ae2662ae4e1f37807cfe47ce98", "asset_id": "81647294538046680798858716589766492074338758116170717123345952330712416337530", "price": "0.924", "size": "6.9", "side": "BUY", "timestamp": "1768574201197", "received_at": "2026-01-16T14:36:41.245903"}}
{"event_type": "price_change", "event_ts": "2026-01-16T14:36:41.245916", "ingestion_ts": "2026-01-16T14:36:49.604167", "market_id": "0xc0e6b917320a47228fb96e3b5ae0e5c93773a5ae2662ae4e1f37807cfe47ce98", "raw": {"market": "0xc0e6b917320a47228fb96e3b5ae0e5c93773a5ae2662ae4e1f37807cfe47ce98", "asset_id": "58656358377246279051017109359677190749228949103591068167284263961542487110215", "price": "0.072", "size": "26.06", "side": "SELL", "timestamp": "1768574201198", "received_at": "2026-01-16T14:36:41.245916"}}
{"event_type": "price_change", "event_ts": "2026-01-16T14:36:41.245916", "ingestion_ts": "2026-01-16T14:36:49.604167", "market_id": "0xc0e6b917320a47228fb96e3b5ae0e5c93773a5ae2662ae4e1f37807cfe47ce98", "raw": {"market": "0xc0e6b917320a47228fb96e3b5ae0e5c93773a5ae2662ae4e1f37807cfe47ce98", "asset_id": "81647294538046680798858716589766492074338758116170717123345952330712416337530", "price": "0.928", "size": "26.06", "side": "BUY", "timestamp": "1768574201198", "received_at": "2026-01-16T14:36:41.245916"}}
{"event_type": "price_change", "event_ts": "2026-01-16T14:36:43.515941", "ingestion_ts": "2026-01-16T14:36:49.604167", "market_id": "0xaf9d0e448129a9f657f851d49495ba4742055d80e0ef1166ba0ee81d4d594214", "raw": {"market": "0xaf9d0e448129a9f657f851d49495ba4742055d80e0ef1166ba0ee81d4d594214", "asset_id": "4153292802911610701832309484716814274802943278345248636922528170020319407796", "price": "0.981", "size": "0", "side": "SELL", "timestamp": "1768574203479", "received_at": "2026-01-16T14:36:43.515941"}}
{"event_type": "price_change", "event_ts": "2026-01-16T14:36:43.515941", "ingestion_ts": "2026-01-16T14:36:49.604167", "market_id": "0xaf9d0e448129a9f657f851d49495ba4742055d80e0ef1166ba0ee81d4d594214", "raw": {"market": "0xaf9d0e448129a9f657f851d49495ba4742055d80e0ef1166ba0ee81d4d594214", "asset_id": "101676997363687199724245607342877036148401850938023978421879460310389391082353", "price": "0.019", "size": "0", "side": "BUY", "timestamp": "1768574203479", "received_at": "2026-01-16T14:36:43.515941"}}
{"event_type": "price_change", "event_ts": "2026-01-16T14:36:43.560341", "ingestion_ts": "2026-01-16T14:36:49.604167", "market_id": "0x49686d26fb712515cd5e12c23f0a1c7e10214c7faa3cb0a730aabe0c33694082", "raw": {"market": "0x49686d26fb712515cd5e12c23f0a1c7e10214c7faa3cb0a730aabe0c33694082", "asset_id": "30442780799048074404860985387051749017905070253466005720364298335239299761065", "price": "0.004", "size": "10", "side": "BUY", "timestamp": "1768574203523", "received_at": "2026-01-16T14:36:43.560341"}}
{"event_type": "price_change", "event_ts": "2026-01-16T14:36:43.560341", "ingestion_ts": "2026-01-16T14:36:49.604167", "market_id": "0x49686d26fb712515cd5e12c23f0a1c7e10214c7faa3cb0a730aabe0c33694082", "raw": {"market": "0x49686d26fb712515cd5e12c23f0a1c7e10214c7faa3cb0a730aabe0c33694082", "asset_id": "13244681086321087932946246027856416106585284024824496763706748621681543444582", "price": "0.996", "size": "10", "side": "SELL", "timestamp": "1768574203523", "received_at": "2026-01-16T14:36:43.560341"}}
{"event_type": "price_change", "event_ts": "2026-01-16T14:36:43.560381", "ingestion_ts": "2026-01-16T14:36:49.604167", "market_id": "0x49686d26fb712515cd5e12c23f0a1c7e10214c7faa3cb0a730aabe0c33694082", "raw": {"market": "0x49686d26fb712515cd5e12c23f0a1c7e10214c7faa3cb0a730aabe0c33694082", "asset_id": "30442780799048074404860985387051749017905070253466005720364298335239299761065", "price": "0.011", "size": "0", "side": "BUY", "timestamp": "1768574203523", "received_at": "2026-01-16T14:36:43.560381"}}
{"event_type": "price_change", "event_ts": "2026-01-16T14:36:43.560381", "ingestion_ts": "2026-01-16T14:36:49.604167", "market_id": "0x49686d26fb712515cd5e12c23f0a1c7e10214c7faa3cb0a730aabe0c33694082", "raw": {"market": "0x49686d26fb712515cd5e12c23f0a1c7e10214c7faa3cb0a730aabe0c33694082", "asset_id": "13244681086321087932946246027856416106585284024824496763706748621681543444582", "price": "0.989", "size": "0", "side": "SELL", "timestamp": "1768574203523", "received_at": "2026-01-16T14:36:43.560381"}}
{"event_type": "price_change", "event_ts": "2026-01-16T14:36:43.911222", "ingestion_ts": "2026-01-16T14:36:49.604167", "market_id": "0x49686d26fb712515cd5e12c23f0a1c7e10214c7faa3cb0a730aabe0c33694082", "raw": {"market": "0x49686d26fb712515cd5e12c23f0a1c7e10214c7faa3cb0a730aabe0c33694082", "asset_id": "30442780799048074404860985387051749017905070253466005720364298335239299761065", "price": "0.003", "size": "28.96", "side": "BUY", "timestamp": "1768574203873", "received_at": "2026-01-16T14:36:43.911222"}}
{"event_type": "price_change", "event_ts": "2026-01-16T14:36:43.911222", "ingestion_ts": "2026-01-16T14:36:49.604167", "market_id": "0x49686d26fb712515cd5e12c23f0a1c7e10214c7faa3cb0a730aabe0c33694082", "raw": {"market": "0x49686d26fb712515cd5e12c23f0a1c7e10214c7faa3cb0a730aabe0c33694082", "asset_id": "13244681086321087932946246027856416106585284024824496763706748621681543444582", "price": "0.997", "size": "28.96", "side": "SELL", "timestamp": "1768574203873", "received_at": "2026-01-16T14:36:43.911222"}}
{"event_type": "price_change", "event_ts": "2026-01-16T14:36:43.911258", "ingestion_ts": "2026-01-16T14:36:49.604167", "market_id": "0x49686d26fb712515cd5e12c23f0a1c7e10214c7faa3cb0a730aabe0c33694082", "raw": {"market": "0x49686d26fb712515cd5e12c23f0a1c7e10214c7faa3cb0a730aabe0c33694082", "asset_id": "30442780799048074404860985387051749017905070253466005720364298335239299761065", "price": "0.012", "size": "12.25", "side": "BUY", "timestamp": "1768574203874", "received_at": "2026-01-16T14:36:43.911258"}}
{"event_type": "price_change", "event_ts": "2026-01-16T14:36:43.911258", "ingestion_ts": "2026-01-16T14:36:49.604167", "market_id": "0x49686d26fb712515cd5e12c23f0a1c7e10214c7faa3cb0a730aabe0c33694082", "raw": {"market": "0x49686d26fb712515cd5e12c23f0a1c7e10214c7faa3cb0a730aabe0c33694082", "asset_id": "13244681086321087932946246027856416106585284024824496763706748621681543444582", "price": "0.988", "size": "12.25", "side": "SELL", "timestamp": "1768574203874", "received_at": "2026-01-16T14:36:43.911258"}}
{"event_type": "price_change", "event_ts": "2026-01-16T14:36:43.913783", "ingestion_ts": "2026-01-16T14:36:49.604167", "market_id": "0x49686d26fb712515cd5e12c23f0a1c7e10214c7faa3cb0a730aabe0c33694082", "raw": {"market": "0x49686d26fb712515cd5e12c23f0a1c7e10214c7faa3cb0a730aabe0c33694082", "asset_id": "30442780799048074404860985387051749017905070253466005720364298335239299761065", "price": "0.008", "size": "15.31", "side": "BUY", "timestamp": "1768574203875", "received_at": "2026-01-16T14:36:43.913783"}}
{"event_type": "price_change", "event_ts": "2026-01-16T14:36:43.913783", "ingestion_ts": "2026-01-16T14:36:49.604167", "market_id": "0x49686d26fb712515cd5e12c23f0a1c7e10214c7faa3cb0a730aabe0c33694082", "raw": {"market": "0x49686d26fb712515cd5e12c23f0a1c7e10214c7faa3cb0a730aabe0c33694082", "asset_id": "13244681086321087932946246027856416106585284024824496763706748621681543444582", "price": "0.992", "size": "15.31", "side": "SELL", "timestamp": "1768574203875", "received_at": "2026-01-16T14:36:43.913783"}}
{"event_type": "price_change", "event_ts": "2026-01-16T14:36:44.018287", "ingestion_ts": "2026-01-16T14:36:49.604167", "market_id": "0xc0e6b917320a47228fb96e3b5ae0e5c93773a5ae2662ae4e1f37807cfe47ce98", "raw": {"market": "0xc0e6b917320a47228fb96e3b5ae0e5c93773a5ae2662ae4e1f37807cfe47ce98", "asset_id": "58656358377246279051017109359677190749228949103591068167284263961542487110215", "price": "0.009", "size": "0", "side": "BUY", "timestamp": "1768574203973", "received_at": "2026-01-16T14:36:44.018287"}}
{"event_type": "price_change", "event_ts": "2026-01-16T14:36:44.018287", "ingestion_ts": "2026-01-16T14:36:49.604167", "market_id": "0xc0e6b917320a47228fb96e3b5ae0e5c93773a5ae2662ae4e1f37807cfe47ce98", "raw": {"market": "0xc0e6b917320a47228fb96e3b5ae0e5c93773a5ae2662ae4e1f37807cfe47ce98", "asset_id": "81647294538046680798858716589766492074338758116170717123345952330712416337530", "price": "0.991", "size": "0", "side": "SELL", "timestamp": "1768574203973", "received_at": "2026-01-16T14:36:44.018287"}}
{"event_type": "price_change", "event_ts": "2026-01-16T14:36:44.060080", "ingestion_ts": "2026-01-16T14:36:49.604167", "market_id": "0x2393ed0b0fdc450054c7b9071907eca75cf4fc36e385adf4a0a5f99ee62243e8", "raw": {"market": "0x2393ed0b0fdc450054c7b9071907eca75cf4fc36e385adf4a0a5f99ee62243e8", "asset_id": "32769749367306925959219403371425714180265458150646381231272229429098460625924", "price": "0.948", "size": "50", "side": "BUY", "timestamp": "1768574204014", "received_at": "2026-01-16T14:36:44.060080"}}
{"event_type": "price_change", "event_ts": "2026-01-16T14:36:44.060080", "ingestion_ts": "2026-01-16T14:36:49.604167", "market_id": "0x2393ed0b0fdc450054c7b9071907eca75cf4fc36e385adf4a0a5f99ee62243e8", "raw": {"market": "0x2393ed0b0fdc450054c7b9071907eca75cf4fc36e385adf4a0a5f99ee62243e8", "asset_id": "100074770378634056601572485653252702850363676459996771990439989989293515601975", "price": "0.052", "size": "50", "side": "SELL", "timestamp": "1768574204014", "received_at": "2026-01-16T14:36:44.060080"}}
{"event_type": "price_change", "event_ts": "2026-01-16T14:36:44.121356", "ingestion_ts": "2026-01-16T14:36:49.604167", "market_id": "0x2393ed0b0fdc450054c7b9071907eca75cf4fc36e385adf4a0a5f99ee62243e8", "raw": {"market": "0x2393ed0b0fdc450054c7b9071907eca75cf4fc36e385adf4a0a5f99ee62243e8", "asset_id": "100074770378634056601572485653252702850363676459996771990439989989293515601975", "price": "0.053", "size": "0", "side": "SELL", "timestamp": "1768574204053", "received_at": "2026-01-16T14:36:44.121356"}}
{"event_type": "price_change", "event_ts": "2026-01-16T14:36:44.121356", "ingestion_ts": "2026-01-16T14:36:49.604167", "market_id": "0x2393ed0b0fdc450054c7b9071907eca75cf4fc36e385adf4a0a5f99ee62243e8", "raw": {"market": "0x2393ed0b0fdc450054c7b9071907eca75cf4fc36e385adf4a0a5f99ee62243e8", "asset_id": "32769749367306925959219403371425714180265458150646381231272229429098460625924", "price": "0.947", "size": "0", "side": "BUY", "timestamp": "1768574204053", "received_at": "2026-01-16T14:36:44.121356"}}
{"event_type": "price_change", "event_ts": "2026-01-16T14:36:44.147245", "ingestion_ts": "2026-01-16T14:36:49.604167", "market_id": "0x2393ed0b0fdc450054c7b9071907eca75cf4fc36e385adf4a0a5f99ee62243e8", "raw": {"market": "0x2393ed0b0fdc450054c7b9071907eca75cf4fc36e385adf4a0a5f99ee62243e8", "asset_id": "100074770378634056601572485653252702850363676459996771990439989989293515601975", "price": "0.051", "size": "198", "side": "SELL", "timestamp": "1768574204083", "received_at": "2026-01-16T14:36:44.147245"}}
{"event_type": "price_change", "event_ts": "2026-01-16T14:36:44.147245", "ingestion_ts": "2026-01-16T14:36:49.604167", "market_id": "0x2393ed0b0fdc450054c7b9071907eca75cf4fc36e385adf4a0a5f99ee62243e8", "raw": {"market": "0x2393ed0b0fdc450054c7b9071907eca75cf4fc36e385adf4a0a5f99ee62243e8", "asset_id": "32769749367306925959219403371425714180265458150646381231272229429098460625924", "price": "0.949", "size": "198", "side": "BUY", "timestamp": "1768574204083", "received_at": "2026-01-16T14:36:44.147245"}}
{"event_type": "price_change", "event_ts": "2026-01-16T14:36:44.195745", "ingestion_ts": "2026-01-16T14:36:49.604167", "market_id": "0xaf9d0e448129a9f657f851d49495ba4742055d80e0ef1166ba0ee81d4d594214", "raw": {"market": "0xaf9d0e448129a9f657f851d49495ba4742055d80e0ef1166ba0ee81d4d594214", "asset_id": "4153292802911610701832309484716814274802943278345248636922528170020319407796", "price": "0.979", "size": "140.01", "side": "SELL", "timestamp": "1768574204129", "received_at": "2026-01-16T14:36:44.195745"}}
{"event_type": "price_change", "event_ts": "2026-01-16T14:36:44.195745", "ingestion_ts": "2026-01-16T14:36:49.604167", "market_id": "0xaf9d0e448129a9f657f851d49495ba4742055d80e0ef1166ba0ee81d4d594214", "raw": {"market": "0xaf9d0e448129a9f657f851d49495ba4742055d80e0ef1166ba0ee81d4d594214", "asset_id": "101676997363687199724245607342877036148401850938023978421879460310389391082353", "price": "0.021", "size": "140.01", "side": "BUY", "timestamp": "1768574204129", "received_at": "2026-01-16T14:36:44.195745"}}
{"event_type": "price_change", "event_ts": "2026-01-16T14:36:44.600906", "ingestion_ts": "2026-01-16T14:36:49.604167", "market_id": "0xc0e6b917320a47228fb96e3b5ae0e5c93773a5ae2662ae4e1f37807cfe47ce98", "raw": {"market": "0xc0e6b917320a47228fb96e3b5ae0e5c93773a5ae2662ae4e1f37807cfe47ce98", "asset_id": "58656358377246279051017109359677190749228949103591068167284263961542487110215", "price": "0.004", "size": "127.36", "side": "BUY", "timestamp": "1768574204546", "received_at": "2026-01-16T14:36:44.600906"}}
{"event_type": "price_change", "event_ts": "2026-01-16T14:36:44.600906", "ingestion_ts": "2026-01-16T14:36:49.604167", "market_id": "0xc0e6b917320a47228fb96e3b5ae0e5c93773a5ae2662ae4e1f37807cfe47ce98", "raw": {"market": "0xc0e6b917320a47228fb96e3b5ae0e5c93773a5ae2662ae4e1f37807cfe47ce98", "asset_id": "81647294538046680798858716589766492074338758116170717123345952330712416337530", "price": "0.996", "size": "127.36", "side": "SELL", "timestamp": "1768574204546", "received_at": "2026-01-16T14:36:44.600906"}}
{"event_type": "price_change", "event_ts": "2026-01-16T14:36:44.619561", "ingestion_ts": "2026-01-16T14:36:49.604167", "market_id": "0xc0e6b917320a47228fb96e3b5ae0e5c93773a5ae2662ae4e1f37807cfe47ce98", "raw": {"market": "0xc0e6b917320a47228fb96e3b5ae0e5c93773a5ae2662ae4e1f37807cfe47ce98", "asset_id": "58656358377246279051017109359677190749228949103591068167284263961542487110215", "price": "0.004", "size": "140.43", "side": "BUY", "timestamp": "1768574204558", "received_at": "2026-01-16T14:36:44.619561"}}
{"event_type": "price_change", "event_ts": "2026-01-16T14:36:44.619561", "ingestion_ts": "2026-01-16T14:36:49.604167", "market_id": "0xc0e6b917320a47228fb96e3b5ae0e5c93773a5ae2662ae4e1f37807cfe47ce98", "raw": {"market": "0xc0e6b917320a47228fb96e3b5ae0e5c93773a5ae2662ae4e1f37807cfe47ce98", "asset_id": "81647294538046680798858716589766492074338758116170717123345952330712416337530", "price": "0.996", "size": "140.43", "side": "SELL", "timestamp": "1768574204558", "received_at": "2026-01-16T14:36:44.619561"}}
{"event_type": "price_change", "event_ts": "2026-01-16T14:36:44.622830", "ingestion_ts": "2026-01-16T14:36:49.604167", "market_id": "0x2393ed0b0fdc450054c7b9071907eca75cf4fc36e385adf4a0a5f99ee62243e8", "raw": {"market": "0x2393ed0b0fdc450054c7b9071907eca75cf4fc36e385adf4a0a5f99ee62243e8", "asset_id": "32769749367306925959219403371425714180265458150646381231272229429098460625924", "price": "0.946", "size": "0", "side": "BUY", "timestamp": "1768574204563", "received_at": "2026-01-16T14:36:44.622830"}}
{"event_type": "price_change", "event_ts": "2026-01-16T14:36:44.622830", "ingestion_ts": "2026-01-16T14:36:49.604167", "market_id": "0x2393ed0b0fdc450054c7b9071907eca75cf4fc36e385adf4a0a5f99ee62243e8", "raw": {"market": "0x2393ed0b0fdc450054c7b9071907eca75cf4fc36e385adf4a0a5f99ee62243e8", "asset_id": "100074770378634056601572485653252702850363676459996771990439989989293515601975", "price": "0.054", "size": "0", "side": "SELL", "timestamp": "1768574204563", "received_at": "2026-01-16T14:36:44.622830"}}
{"event_type": "price_change", "event_ts": "2026-01-16T14:36:44.729468", "ingestion_ts": "2026-01-16T14:36:49.604167", "market_id": "0xaf9d0e448129a9f657f851d49495ba4742055d80e0ef1166ba0ee81d4d594214", "raw": {"market": "0xaf9d0e448129a9f657f851d49495ba4742055d80e0ef1166ba0ee81d4d594214", "asset_id": "4153292802911610701832309484716814274802943278345248636922528170020319407796", "price": "0.98", "size": "0", "side": "SELL", "timestamp": "1768574204673", "received_at": "2026-01-16T14:36:44.729468"}}
{"event_type": "price_change", "event_ts": "2026-01-16T14:36:44.729468", "ingestion_ts": "2026-01-16T14:36:49.604167", "market_id": "0xaf9d0e448129a9f657f851d49495ba4742055d80e0ef1166ba0ee81d4d594214", "raw": {"market": "0xaf9d0e448129a9f657f851d49495ba4742055d80e0ef1166ba0ee81d4d594214", "asset_id": "101676997363687199724245607342877036148401850938023978421879460310389391082353", "price": "0.02", "size": "0", "side": "BUY", "timestamp": "1768574204673", "received_at": "2026-01-16T14:36:44.729468"}}
{"event_type": "price_change", "event_ts": "2026-01-16T14:36:44.933588", "ingestion_ts": "2026-01-16T14:36:49.604167", "market_id": "0x49686d26fb712515cd5e12c23f0a1c7e10214c7faa3cb0a730aabe0c33694082", "raw": {"market": "0x49686d26fb712515cd5e12c23f0a1c7e10214c7faa3cb0a730aabe0c33694082", "asset_id": "30442780799048074404860985387051749017905070253466005720364298335239299761065", "price": "0.004", "size": "0", "side": "BUY", "timestamp": "1768574204869", "received_at": "2026-01-16T14:36:44.933588"}}
{"event_type": "price_change", "event_ts": "2026-01-16T14:36:44.933588", "ingestion_ts": "2026-01-16T14:36:49.604167", "market_id": "0x49686d26fb712515cd5e12c23f0a1c7e10214c7faa3cb0a730aabe0c33694082", "raw": {"market": "0x49686d26fb712515cd5e12c23f0a1c7e10214c7faa3cb0a730aabe0c33694082", "asset_id": "13244681086321087932946246027856416106585284024824496763706748621681543444582", "price": "0.996", "size": "0", "side": "SELL", "timestamp": "1768574204869", "received_at": "2026-01-16T14:36:44.933588"}}
{"event_type": "price_change", "event_ts": "2026-01-16T14:36:44.934092", "ingestion_ts": "2026-01-16T14:36:49.604167", "market_id": "0x9472be65457510b7fc3477b20ba90910e99d92eac8421a14bf4b7b7a08ef31dc", "raw": {"market": "0x9472be65457510b7fc3477b20ba90910e99d92eac8421a14bf4b7b7a08ef31dc", "asset_id": "43311793366960417907757893276427136943959788721376762326430771171648759300146", "price": "0.824", "size": "0", "side": "BUY", "timestamp": "1768574204869", "received_at": "2026-01-16T14:36:44.934092"}}
{"event_type": "price_change", "event_ts": "2026-01-16T14:36:44.934092", "ingestion_ts": "2026-01-16T14:36:49.604167", "market_id": "0x9472be65457510b7fc3477b20ba90910e99d92eac8421a14bf4b7b7a08ef31dc", "raw": {"market": "0x9472be65457510b7fc3477b20ba90910e99d92eac8421a14bf4b7b7a08ef31dc", "asset_id": "73414222381656326204771753454630063673548497164758947581648273905027617570612", "price": "0.176", "size": "0", "side": "SELL", "timestamp": "1768574204869", "received_at": "2026-01-16T14:36:44.934092"}}
{"event_type": "price_change", "event_ts": "2026-01-16T14:36:44.934118", "ingestion_ts": "2026-01-16T14:36:49.604167", "market_id": "0xc55db914f0fd1fee18997706712c0dfd8d0369cdbef93a9fef12bd001914ca77", "raw": {"market": "0xc55db914f0fd1fee18997706712c0dfd8d0369cdbef93a9fef12bd001914ca77", "asset_id": "114600293444080540179603459515770723592661967180480327891296353898330242622833", "price": "0.855", "size": "292", "side": "BUY", "timestamp": "1768574204869", "received_at": "2026-01-16T14:36:44.934118"}}
{"event_type": "price_change", "event_ts": "2026-01-16T14:36:44.934118", "ingestion_ts": "2026-01-16T14:36:49.604167", "market_id": "0xc55db914f0fd1fee18997706712c0dfd8d0369cdbef93a9fef12bd001914ca77", "raw": {"market": "0xc55db914f0fd1fee18997706712c0dfd8d0369cdbef93a9fef12bd001914ca77", "asset_id": "72354723612769247426741660426331235762851940382312402276325808095604519806766", "price": "0.145", "size": "292", "side": "SELL", "timestamp": "1768574204869", "received_at": "2026-01-16T14:36:44.934118"}}
{"event_type": "price_change", "event_ts": "2026-01-16T14:36:44.963724", "ingestion_ts": "2026-01-16T14:36:49.604167", "market_id": "0x49686d26fb712515cd5e12c23f0a1c7e10214c7faa3cb0a730aabe0c33694082", "raw": {"market": "0x49686d26fb712515cd5e12c23f0a1c7e10214c7faa3cb0a730aabe0c33694082", "asset_id": "30442780799048074404860985387051749017905070253466005720364298335239299761065", "price": "0.005", "size": "109.51", "side": "BUY", "timestamp": "1768574204904", "received_at": "2026-01-16T14:36:44.963724"}}
{"event_type": "price_change", "event_ts": "2026-01-16T14:36:44.963724", "ingestion_ts": "2026-01-16T14:36:49.604167", "market_id": "0x49686d26fb712515cd5e12c23f0a1c7e10214c7faa3cb0a730aabe0c33694082", "raw": {"market": "0x49686d26fb712515cd5e12c23f0a1c7e10214c7faa3cb0a730aabe0c33694082", "asset_id": "13244681086321087932946246027856416106585284024824496763706748621681543444582", "price": "0.995", "size": "109.51", "side": "SELL", "timestamp": "1768574204904", "received_at": "2026-01-16T14:36:44.963724"}}
{"event_type": "price_change", "event_ts": "2026-01-16T14:36:44.965017", "ingestion_ts": "2026-01-16T14:36:49.604167", "market_id": "0xc55db914f0fd1fee18997706712c0dfd8d0369cdbef93a9fef12bd001914ca77", "raw": {"market": "0xc55db914f0fd1fee18997706712c0dfd8d0369cdbef93a9fef12bd001914ca77", "asset_id": "114600293444080540179603459515770723592661967180480327891296353898330242622833", "price": "0.856", "size": "10", "side": "BUY", "timestamp": "1768574204904", "received_at": "2026-01-16T14:36:44.965017"}}
{"event_type": "price_change", "event_ts": "2026-01-16T14:36:44.965017", "ingestion_ts": "2026-01-16T14:36:49.604167", "market_id": "0xc55db914f0fd1fee18997706712c0dfd8d0369cdbef93a9fef12bd001914ca77", "raw": {"market": "0xc55db914f0fd1fee18997706712c0dfd8d0369cdbef93a9fef12bd001914ca77", "asset_id": "72354723612769247426741660426331235762851940382312402276325808095604519806766", "price": "0.144", "size": "10", "side": "SELL", "timestamp": "1768574204904", "received_at": "2026-01-16T14:36:44.965017"}}
{"event_type": "price_change", "event_ts": "2026-01-16T14:36:44.965054", "ingestion_ts": "2026-01-16T14:36:49.604167", "market_id": "0x9472be65457510b7fc3477b20ba90910e99d92eac8421a14bf4b7b7a08ef31dc", "raw": {"market": "0x9472be65457510b7fc3477b20ba90910e99d92eac8421a14bf4b7b7a08ef31dc", "asset_id": "43311793366960417907757893276427136943959788721376762326430771171648759300146", "price": "0.855", "size": "302", "side": "BUY", "timestamp": "1768574204904", "received_at": "2026-01-16T14:36:44.965054"}}
{"event_type": "price_change", "event_ts": "2026-01-16T14:36:44.965054", "ingestion_ts": "2026-01-16T14:36:49.604167", "market_id": "0x9472be65457510b7fc3477b20ba90910e99d92eac8421a14bf4b7b7a08ef31dc", "raw": {"market": "0x9472be65457510b7fc3477b20ba90910e99d92eac8421a14bf4b7b7a08ef31dc", "asset_id": "73414222381656326204771753454630063673548497164758947581648273905027617570612", "price": "0.145", "size": "302", "side": "SELL", "timestamp": "1768574204904", "received_at": "2026-01-16T14:36:44.965054"}}
{"event_type": "price_change", "event_ts": "2026-01-16T14:36:45.012406", "ingestion_ts": "2026-01-16T14:36:49.604167", "market_id": "0xaf9d0e448129a9f657f851d49495ba4742055d80e0ef1166ba0ee81d4d594214", "raw": {"market": "0xaf9d0e448129a9f657f851d49495ba4742055d80e0ef1166ba0ee81d4d594214", "asset_id": "4153292802911610701832309484716814274802943278345248636922528170020319407796", "price": "0.989", "size": "20.5", "side": "SELL", "timestamp": "1768574204970", "received_at": "2026-01-16T14:36:45.012406"}}
{"event_type": "price_change", "event_ts": "2026-01-16T14:36:45.012406", "ingestion_ts": "2026-01-16T14:36:49.604167", "market_id": "0xaf9d0e448129a9f657f851d49495ba4742055d80e0ef1166ba0ee81d4d594214", "raw": {"market": "0xaf9d0e448129a9f657f851d49495ba4742055d80e0ef1166ba0ee81d4d594214", "asset_id": "101676997363687199724245607342877036148401850938023978421879460310389391082353", "price": "0.011", "size": "20.5", "side": "BUY", "timestamp": "1768574204970", "received_at": "2026-01-16T14:36:45.012406"}}
{"event_type": "price_change", "event_ts": "2026-01-16T14:36:45.200735", "ingestion_ts": "2026-01-16T14:36:49.604167", "market_id": "0xc0e6b917320a47228fb96e3b5ae0e5c93773a5ae2662ae4e1f37807cfe47ce98", "raw": {"market": "0xc0e6b917320a47228fb96e3b5ae0e5c93773a5ae2662ae4e1f37807cfe47ce98", "asset_id": "58656358377246279051017109359677190749228949103591068167284263961542487110215", "price": "0.072", "size": "13.03", "side": "SELL", "timestamp": "1768574205144", "received_at": "2026-01-16T14:36:45.200735"}}
{"event_type": "price_change", "event_ts": "2026-01-16T14:36:45.200735", "ingestion_ts": "2026-01-16T14:36:49.604167", "market_id": "0xc0e6b917320a47228fb96e3b5ae0e5c93773a5ae2662ae4e1f37807cfe47ce98", "raw": {"market": "0xc0e6b917320a47228fb96e3b5ae0e5c93773a5ae2662ae4e1f37807cfe47ce98", "asset_id": "81647294538046680798858716589766492074338758116170717123345952330712416337530", "price": "0.928", "size": "13.03", "side": "BUY", "timestamp": "1768574205144", "received_at": "2026-01-16T14:36:45.200735"}}
{"event_type": "price_change", "event_ts": "2026-01-16T14:36:45.200783", "ingestion_ts": "2026-01-16T14:36:49.604167", "market_id": "0xc0e6b917320a47228fb96e3b5ae0e5c93773a5ae2662ae4e1f37807cfe47ce98", "raw": {"market": "0xc0e6b917320a47228fb96e3b5ae0e5c93773a5ae2662ae4e1f37807cfe47ce98", "asset_id": "58656358377246279051017109359677190749228949103591068167284263961542487110215", "price": "0.073", "size": "0", "side": "SELL", "timestamp": "1768574205144", "received_at": "2026-01-16T14:36:45.200783"}}
{"event_type": "price_change", "event_ts": "2026-01-16T14:36:45.200783", "ingestion_ts": "2026-01-16T14:36:49.604167", "market_id": "0xc0e6b917320a47228fb96e3b5ae0e5c93773a5ae2662ae4e1f37807cfe47ce98", "raw": {"market": "0xc0e6b917320a47228fb96e3b5ae0e5c93773a5ae2662ae4e1f37807cfe47ce98", "asset_id": "81647294538046680798858716589766492074338758116170717123345952330712416337530", "price": "0.927", "size": "0", "side": "BUY", "timestamp": "1768574205144", "received_at": "2026-01-16T14:36:45.200783"}}
{"event_type": "price_change", "event_ts": "2026-01-16T14:36:45.828117", "ingestion_ts": "2026-01-16T14:36:49.604167", "market_id": "0xc0e6b917320a47228fb96e3b5ae0e5c93773a5ae2662ae4e1f37807cfe47ce98", "raw": {"market": "0xc0e6b917320a47228fb96e3b5ae0e5c93773a5ae2662ae4e1f37807cfe47ce98", "asset_id": "58656358377246279051017109359677190749228949103591068167284263961542487110215", "price": "0.071", "size": "8.34", "side": "SELL", "timestamp": "1768574205791", "received_at": "2026-01-16T14:36:45.828117"}}
{"event_type": "price_change", "event_ts": "2026-01-16T14:36:45.828117", "ingestion_ts": "2026-01-16T14:36:49.604167", "market_id": "0xc0e6b917320a47228fb96e3b5ae0e5c93773a5ae2662ae4e1f37807cfe47ce98", "raw": {"market": "0xc0e6b917320a47228fb96e3b5ae0e5c93773a5ae2662ae4e1f37807cfe47ce98", "asset_id": "81647294538046680798858716589766492074338758116170717123345952330712416337530", "price": "0.929", "size": "8.34", "side": "BUY", "timestamp": "1768574205791", "received_at": "2026-01-16T14:36:45.828117"}}
{"event_type": "price_change", "event_ts": "2026-01-16T14:36:45.832409", "ingestion_ts": "2026-01-16T14:36:49.604167", "market_id": "0xc0e6b917320a47228fb96e3b5ae0e5c93773a5ae2662ae4e1f37807cfe47ce98", "raw": {"market": "0xc0e6b917320a47228fb96e3b5ae0e5c93773a5ae2662ae4e1f37807cfe47ce98", "asset_id": "58656358377246279051017109359677190749228949103591068167284263961542487110215", "price": "0.072", "size": "24.87", "side": "SELL", "timestamp": "1768574205795", "received_at": "2026-01-16T14:36:45.832409"}}
{"event_type": "price_change", "event_ts": "2026-01-16T14:36:45.832409", "ingestion_ts": "2026-01-16T14:36:49.604167", "market_id": "0xc0e6b917320a47228fb96e3b5ae0e5c93773a5ae2662ae4e1f37807cfe47ce98", "raw": {"market": "0xc0e6b917320a47228fb96e3b5ae0e5c93773a5ae2662ae4e1f37807cfe47ce98", "asset_id": "81647294538046680798858716589766492074338758116170717123345952330712416337530", "price": "0.928", "size": "24.87", "side": "BUY", "timestamp": "1768574205795", "received_at": "2026-01-16T14:36:45.832409"}}
{"event_type": "price_change", "event_ts": "2026-01-16T14:36:45.835946", "ingestion_ts": "2026-01-16T14:36:49.604167", "market_id": "0xc0e6b917320a47228fb96e3b5ae0e5c93773a5ae2662ae4e1f37807cfe47ce98", "raw": {"market": "0xc0e6b917320a47228fb96e3b5ae0e5c93773a5ae2662ae4e1f37807cfe47ce98", "asset_id": "58656358377246279051017109359677190749228949103591068167284263961542487110215", "price": "0.072", "size": "36.71", "side": "SELL", "timestamp": "1768574205797", "received_at": "2026-01-16T14:36:45.835946"}}
{"event_type": "price_change", "event_ts": "2026-01-16T14:36:45.835946", "ingestion_ts": "2026-01-16T14:36:49.604167", "market_id": "0xc0e6b917320a47228fb96e3b5ae0e5c93773a5ae2662ae4e1f37807cfe47ce98", "raw": {"market": "0xc0e6b917320a47228fb96e3b5ae0e5c93773a5ae2662ae4e1f37807cfe47ce98", "asset_id": "81647294538046680798858716589766492074338758116170717123345952330712416337530", "price": "0.928", "size": "36.71", "side": "BUY", "timestamp": "1768574205797", "received_at": "2026-01-16T14:36:45.835946"}}
{"event_type": "price_change", "event_ts": "2026-01-16T14:36:45.835986", "ingestion_ts": "2026-01-16T14:36:49.604167", "market_id": "0xc0e6b917320a47228fb96e3b5ae0e5c93773a5ae2662ae4e1f37807cfe47ce98", "raw": {"market": "0xc0e6b917320a47228fb96e3b5ae0e5c93773a5ae2662ae4e1f37807cfe47ce98", "asset_id": "58656358377246279051017109359677190749228949103591068167284263961542487110215", "price": "0.071", "size": "16.68", "side": "SELL", "timestamp": "1768574205801", "received_at": "2026-01-16T14:36:45.835986"}}
{"event_type": "price_change", "event_ts": "2026-01-16T14:36:45.835986", "ingestion_ts": "2026-01-16T14:36:49.604167", "market_id": "0xc0e6b917320a47228fb96e3b5ae0e5c93773a5ae2662ae4e1f37807cfe47ce98", "raw": {"market": "0xc0e6b917320a47228fb96e3b5ae0e5c93773a5ae2662ae4e1f37807cfe47ce98", "asset_id": "81647294538046680798858716589766492074338758116170717123345952330712416337530", "price": "0.929", "size": "16.68", "side": "BUY", "timestamp": "1768574205801", "received_at": "2026-01-16T14:36:45.835986"}}
{"event_type": "price_change", "event_ts": "2026-01-16T14:36:46.280329", "ingestion_ts": "2026-01-16T14:36:49.604167", "market_id": "0xaf9d0e448129a9f657f851d49495ba4742055d80e0ef1166ba0ee81d4d594214", "raw": {"market": "0xaf9d0e448129a9f657f851d49495ba4742055d80e0ef1166ba0ee81d4d594214", "asset_id": "4153292802911610701832309484716814274802943278345248636922528170020319407796", "price": "0.989", "size": "0", "side": "SELL", "timestamp": "1768574206244", "received_at": "2026-01-16T14:36:46.280329"}}
{"event_type": "price_change", "event_ts": "2026-01-16T14:36:46.280329", "ingestion_ts": "2026-01-16T14:36:49.604167", "market_id": "0xaf9d0e448129a9f657f851d49495ba4742055d80e0ef1166ba0ee81d4d594214", "raw": {"market": "0xaf9d0e448129a9f657f851d49495ba4742055d80e0ef1166ba0ee81d4d594214", "asset_id": "101676997363687199724245607342877036148401850938023978421879460310389391082353", "price": "0.011", "size": "0", "side": "BUY", "timestamp": "1768574206244", "received_at": "2026-01-16T14:36:46.280329"}}
{"event_type": "price_change", "event_ts": "2026-01-16T14:36:46.354297", "ingestion_ts": "2026-01-16T14:36:49.604167", "market_id": "0xaf9d0e448129a9f657f851d49495ba4742055d80e0ef1166ba0ee81d4d594214", "raw": {"market": "0xaf9d0e448129a9f657f851d49495ba4742055d80e0ef1166ba0ee81d4d594214", "asset_id": "4153292802911610701832309484716814274802943278345248636922528170020319407796", "price": "0.978", "size": "20.5", "side": "SELL", "timestamp": "1768574206317", "received_at": "2026-01-16T14:36:46.354297"}}
{"event_type": "price_change", "event_ts": "2026-01-16T14:36:46.354297", "ingestion_ts": "2026-01-16T14:36:49.604167", "market_id": "0xaf9d0e448129a9f657f851d49495ba4742055d80e0ef1166ba0ee81d4d594214", "raw": {"market": "0xaf9d0e448129a9f657f851d49495ba4742055d80e0ef1166ba0ee81d4d594214", "asset_id": "101676997363687199724245607342877036148401850938023978421879460310389391082353", "price": "0.022", "size": "20.5", "side": "BUY", "timestamp": "1768574206317", "received_at": "2026-01-16T14:36:46.354297"}}
{"event_type": "price_change", "event_ts": "2026-01-16T14:36:46.416794", "ingestion_ts": "2026-01-16T14:36:49.604167", "market_id": "0xc0e6b917320a47228fb96e3b5ae0e5c93773a5ae2662ae4e1f37807cfe47ce98", "raw": {"market": "0xc0e6b917320a47228fb96e3b5ae0e5c93773a5ae2662ae4e1f37807cfe47ce98", "asset_id": "58656358377246279051017109359677190749228949103591068167284263961542487110215", "price": "0.004", "size": "119.69", "side": "BUY", "timestamp": "1768574206373", "received_at": "2026-01-16T14:36:46.416794"}}
{"event_type": "price_change", "event_ts": "2026-01-16T14:36:46.416794", "ingestion_ts": "2026-01-16T14:36:49.604167", "market_id": "0xc0e6b917320a47228fb96e3b5ae0e5c93773a5ae2662ae4e1f37807cfe47ce98", "raw": {"market": "0xc0e6b917320a47228fb96e3b5ae0e5c93773a5ae2662ae4e1f37807cfe47ce98", "asset_id": "81647294538046680798858716589766492074338758116170717123345952330712416337530", "price": "0.996", "size": "119.69", "side": "SELL", "timestamp": "1768574206373", "received_at": "2026-01-16T14:36:46.416794"}}
