{"event_type": "price_change", "event_ts": "2026-01-16T14:26:52.861851", "ingestion_ts": "2026-01-16T14:27:04.418606", "market_id": "0x49686d26fb712515cd5e12c23f0a1c7e10214c7faa3cb0a730aabe0c33694082", "raw": {"market": "0x49686d26fb712515cd5e12c23f0a1c7e10214c7faa3cb0a730aabe0c33694082", "asset_id": "13244681086321087932946246027856416106585284024824496763706748621681543444582", "price": "0.994", "size": "10.08", "side": "SELL", "timestamp": "1768573612812", "received_at": "2026-01-16T14:26:52.861851"}}
{"event_type": "price_change", "event_ts": "2026-01-16T14:26:52.861863", "ingestion_ts": "2026-01-16T14:27:04.418606", "market_id": "0x50c669f178da4e5bbea7f1be25041fd278914712fa87a6a6f8e57d5923d88dee", "raw": {"market": "0x50c669f178da4e5bbea7f1be25041fd278914712fa87a6a6f8e57d5923d88dee", "asset_id": "74040420326294854165772767082819937451857852955603897473157746262672057685461", "price": "0.855", "size": "0", "side": "BUY", "timestamp": "1768573612812", "received_at": "2026-01-16T14:26:52.861863"}}
{"event_type": "price_change", "event_ts": "2026-01-16T14:26:52.861863", "ingestion_ts": "2026-01-16T14:27:04.418606", "market_id": "0x50c669f178da4e5bbea7f1be25041fd278914712fa87a6a6f8e57d5923d88dee", "raw": {"market": "0x50c669f178da4e5bbea7f1be25041fd278914712fa87a6a6f8e57d5923d88dee", "asset_id": "24682525479474221428144937281315825971983904267399062415430320764754931667953", "price": "0.145", "size": "0", "side": "SELL", "timestamp": "1768573612812", "received_at": "2026-01-16T14:26:52.861863"}}
{"event_type": "price_change", "event_ts": "2026-01-16T14:26:52.861874", "ingestion_ts": "2026-01-16T14:27:04.418606", "market_id": "0x9472be65457510b7fc3477b20ba90910e99d92eac8421a14bf4b7b7a08ef31dc", "raw": {"market": "0x9472be65457510b7fc3477b20ba90910e99d92eac8421a14bf4b7b7a08ef31dc", "asset_id": "43311793366960417907757893276427136943959788721376762326430771171648759300146", "price": "0.856", "size": "0", "side": "BUY", "timestamp": "1768573612812", "received_at": "2026-01-16T14:26:52.861874"}}
{"event_type": "price_change", "event_ts": "2026-01-16T14:26:52.861874", "ingestion_ts": "2026-01-16T14:27:04.418606", "market_id": "0x9472be65457510b7fc3477b20ba90910e99d92eac8421a14bf4b7b7a08ef31dc", "raw": {"market": "0x9472be65457510b7fc3477b20ba90910e99d92eac8421a14bf4b7b7a08ef31dc", "asset_id": "73414222381656326204771753454630063673548497164758947581648273905027617570612", "price": "0.144", "size": "0", "side": "SELL", "timestamp": "1768573612812", "received_at": "2026-01-16T14:26:52.861874"}}
{"event_type": "price_change", "event_ts": "2026-01-16T14:26:52.861884", "ingestion_ts": "2026-01-16T14:27:04.418606", "market_id": "0x44f08744458b8896620cd3330bc5e1ea69df4199b02d4fc583b3fc96e5d314ce", "raw": {"market": "0x44f08744458b8896620cd3330bc5e1ea69df4199b02d4fc583b3fc96e5d314ce", "asset_id": "72327831507226612545928776794104143393438710920370371172884559893525100761096", "price": "0.853", "size": "234", "side": "BUY", "timestamp": "1768573612812", "received_at": "2026-01-16T14:26:52.861884"}}
{"event_type": "price_change", "event_ts": "2026-01-16T14:26:52.861884", "ingestion_ts": "2026-01-16T14:27:04.418606", "market_id": "0x44f08744458b8896620cd3330bc5e1ea69df4199b02d4fc583b3fc96e5d314ce", "raw": {"market": "0x44f08744458b8896620cd3330bc5e1ea69df4199b02d4fc583b3fc96e5d314ce", "asset_id": "49194009556504828848509244326501559253829462790583873936160989575507522044057", "price": "0.147", "size": "234", "side": "SELL", "timestamp": "1768573612812", "received_at": "2026-01-16T14:26:52.861884"}}
{"event_type": "price_change", "event_ts": "2026-01-16T14:26:52.861895", "ingestion_ts": "2026-01-16T14:27:04.418606", "market_id": "0xc55db914f0fd1fee18997706712c0dfd8d0369cdbef93a9fef12bd001914ca77", "raw": {"market": "0xc55db914f0fd1fee18997706712c0dfd8d0369cdbef93a9fef12bd001914ca77", "asset_id": "114600293444080540179603459515770723592661967180480327891296353898330242622833", "price": "0.857", "size": "233", "side": "BUY", "timestamp": "1768573612813", "received_at": "2026-01-16T14:26:52.861895"}}
{"event_type": "price_change", "event_ts": "2026-01-16T14:26:52.861895", "ingestion_ts": "2026-01-16T14:27:04.418606", "market_id": "0xc55db914f0fd1fee18997706712c0dfd8d0369cdbef93a9fef12bd001914ca77", "raw": {"market": "0xc55db914f0fd1fee18997706712c0dfd8d0369cdbef93a9fef12bd001914ca77", "asset_id": "72354723612769247426741660426331235762851940382312402276325808095604519806766", "price": "0.143", "size": "233", "side": "SELL", "timestamp": "1768573612813", "received_at": "2026-01-16T14:26:52.861895"}}
{"event_type": "price_change", "event_ts": "2026-01-16T14:26:52.889423", "ingestion_ts": "2026-01-16T14:27:04.418606", "market_id": "0xb9bbdd34304344dcc45803780a34c97d73a00133a5ecf70f63e1008b8abb2fca", "raw": {"market": "0xb9bbdd34304344dcc45803780a34c97d73a00133a5ecf70f63e1008b8abb2fca", "asset_id": "8682484153073832526711485265636767086525069344085206423986003504588877767339", "price": "0.838", "size": "158.24", "side": "BUY", "timestamp": "1768573612846", "received_at": "2026-01-16T14:26:52.889423"}}
{"event_type": "price_change", "event_ts": "2026-01-16T14:26:52.889423", "ingestion_ts": "2026-01-16T14:27:04.418606", "market_id": "0xb9bbdd34304344dcc45803780a34c97d73a00133a5ecf70f63e1008b8abb2fca", "raw": {"market": "0xb9bbdd34304344dcc45803780a34c97d73a00133a5ecf70f63e1008b8abb2fca", "asset_id": "72012724360700510767037780555710363830014634797787940282136454146828040926557", "price": "0.162", "size": "158.24", "side": "SELL", "timestamp": "1768573612846", "received_at": "2026-01-16T14:26:52.889423"}}
{"event_type": "price_change", "event_ts": "2026-01-16T14:26:52.889505", "ingestion_ts": "2026-01-16T14:27:04.418606", "market_id": "0xc55db914f0fd1fee18997706712c0dfd8d0369cdbef93a9fef12bd001914ca77", "raw": {"market": "0xc55db914f0fd1fee18997706712c0dfd8d0369cdbef93a9fef12bd001914ca77", "asset_id": "114600293444080540179603459515770723592661967180480327891296353898330242622833", "price": "0.837", "size": "10", "side": "BUY", "timestamp": "1768573612847", "received_at": "2026-01-16T14:26:52.889505"}}
{"event_type": "price_change", "event_ts": "2026-01-16T14:26:52.889505", "ingestion_ts": "2026-01-16T14:27:04.418606", "market_id": "0xc55db914f0fd1fee18997706712c0dfd8d0369cdbef93a9fef12bd001914ca77", "raw": {"market": "0xc55db914f0fd1fee18997706712c0dfd8d0369cdbef93a9fef12bd001914ca77", "asset_id": "72354723612769247426741660426331235762851940382312402276325808095604519806766", "price": "0.163", "size": "10", "side": "SELL", "timestamp": "1768573612847", "received_at": "2026-01-16T14:26:52.889505"}}
{"event_type": "price_change", "event_ts": "2026-01-16T14:26:52.889522", "ingestion_ts": "2026-01-16T14:27:04.418606", "market_id": "0x9472be65457510b7fc3477b20ba90910e99d92eac8421a14bf4b7b7a08ef31dc", "raw": {"market": "0x9472be65457510b7fc3477b20ba90910e99d92eac8421a14bf4b7b7a08ef31dc", "asset_id": "43311793366960417907757893276427136943959788721376762326430771171648759300146", "price": "0.824", "size": "10", "side": "BUY", "timestamp": "1768573612847", "received_at": "2026-01-16T14:26:52.889522"}}
{"event_type": "price_change", "event_ts": "2026-01-16T14:26:52.889522", "ingestion_ts": "2026-01-16T14:27:04.418606", "market_id": "0x9472be65457510b7fc3477b20ba90910e99d92eac8421a14bf4b7b7a08ef31dc", "raw": {"market": "0x9472be65457510b7fc3477b20ba90910e99d92eac8421a14bf4b7b7a08ef31dc", "asset_id": "73414222381656326204771753454630063673548497164758947581648273905027617570612", "price": "0.176", "size": "10", "side": "SELL", "timestamp": "1768573612847", "received_at": "2026-01-16T14:26:52.889522"}}
{"event_type": "price_change", "event_ts": "2026-01-16T14:26:52.889535", "ingestion_ts": "2026-01-16T14:27:04.418606", "market_id": "0x50c669f178da4e5bbea7f1be25041fd278914712fa87a6a6f8e57d5923d88dee", "raw": {"market": "0x50c669f178da4e5bbea7f1be25041fd278914712fa87a6a6f8e57d5923d88dee", "asset_id": "74040420326294854165772767082819937451857852955603897473157746262672057685461", "price": "0.824", "size": "10", "side": "BUY", "timestamp": "1768573612847", "received_at": "2026-01-16T14:26:52.889535"}}
{"event_type": "price_change", "event_ts": "2026-01-16T14:26:52.889535", "ingestion_ts": "2026-01-16T14:27:04.418606", "market_id": "0x50c669f178da4e5bbea7f1be25041fd278914712fa87a6a6f8e57d5923d88dee", "raw": {"market": "0x50c669f178da4e5bbea7f1be25041fd278914712fa87a6a6f8e57d5923d88dee", "asset_id": "24682525479474221428144937281315825971983904267399062415430320764754931667953", "price": "0.176", "size": "10", "side": "SELL", "timestamp": "1768573612847", "received_at": "2026-01-16T14:26:52.889535"}}
{"event_type": "price_change", "event_ts": "2026-01-16T14:26:52.889547", "ingestion_ts": "2026-01-16T14:27:04.418606", "market_id": "0x49a20c7523c271099008f3ef9a31521263b24d637959852a391e6b4697b1a437", "raw": {"market": "0x49a20c7523c271099008f3ef9a31521263b24d637959852a391e6b4697b1a437", "asset_id": "55881023621710858558280545117465775643848233756850602339827152783696837905531", "price": "0.824", "size": "10", "side": "BUY", "timestamp": "1768573612847", "received_at": "2026-01-16T14:26:52.889547"}}
{"event_type": "price_change", "event_ts": "2026-01-16T14:26:52.889547", "ingestion_ts": "2026-01-16T14:27:04.418606", "market_id": "0x49a20c7523c271099008f3ef9a31521263b24d637959852a391e6b4697b1a437", "raw": {"market": "0x49a20c7523c271099008f3ef9a31521263b24d637959852a391e6b4697b1a437", "asset_id": "13018971792603393862521629014128024641178044618205296260525674415067194037856", "price": "0.176", "size": "10", "side": "SELL", "timestamp": "1768573612847", "received_at": "2026-01-16T14:26:52.889547"}}
{"event_type": "price_change", "event_ts": "2026-01-16T14:26:52.889558", "ingestion_ts": "2026-01-16T14:27:04.418606", "market_id": "0x44f08744458b8896620cd3330bc5e1ea69df4199b02d4fc583b3fc96e5d314ce", "raw": {"market": "0x44f08744458b8896620cd3330bc5e1ea69df4199b02d4fc583b3fc96e5d314ce", "asset_id": "72327831507226612545928776794104143393438710920370371172884559893525100761096", "price": "0.831", "size": "10", "side": "BUY", "timestamp": "1768573612847", "received_at": "2026-01-16T14:26:52.889558"}}
{"event_type": "price_change", "event_ts": "2026-01-16T14:26:52.889558", "ingestion_ts": "2026-01-16T14:27:04.418606", "market_id": "0x44f08744458b8896620cd3330bc5e1ea69df4199b02d4fc583b3fc96e5d314ce", "raw": {"market": "0x44f08744458b8896620cd3330bc5e1ea69df4199b02d4fc583b3fc96e5d314ce", "asset_id": "49194009556504828848509244326501559253829462790583873936160989575507522044057", "price": "0.169", "size": "10", "side": "SELL", "timestamp": "1768573612847", "received_at": "2026-01-16T14:26:52.889558"}}
{"event_type": "price_change", "event_ts": "2026-01-16T14:26:52.905820", "ingestion_ts": "2026-01-16T14:27:04.418606", "market_id": "0xc0e6b917320a47228fb96e3b5ae0e5c93773a5ae2662ae4e1f37807cfe47ce98", "raw": {"market": "0xc0e6b917320a47228fb96e3b5ae0e5c93773a5ae2662ae4e1f37807cfe47ce98", "asset_id": "58656358377246279051017109359677190749228949103591068167284263961542487110215", "price": "0.004", "size": "133.1", "side": "BUY", "timestamp": "1768573612862", "received_at": "2026-01-16T14:26:52.905820"}}
{"event_type": "price_change", "event_ts": "2026-01-16T14:26:52.905820", "ingestion_ts": "2026-01-16T14:27:04.418606", "market_id": "0xc0e6b917320a47228fb96e3b5ae0e5c93773a5ae2662ae4e1f37807cfe47ce98", "raw": {"market": "0xc0e6b917320a47228fb96e3b5ae0e5c93773a5ae2662ae4e1f37807cfe47ce98", "asset_id": "81647294538046680798858716589766492074338758116170717123345952330712416337530", "price": "0.996", "size": "133.1", "side": "SELL", "timestamp": "1768573612862", "received_at": "2026-01-16T14:26:52.905820"}}
{"event_type": "price_change", "event_ts": "2026-01-16T14:26:52.906386", "ingestion_ts": "2026-01-16T14:27:04.418606", "market_id": "0xc0e6b917320a47228fb96e3b5ae0e5c93773a5ae2662ae4e1f37807cfe47ce98", "raw": {"market": "0xc0e6b917320a47228fb96e3b5ae0e5c93773a5ae2662ae4e1f37807cfe47ce98", "asset_id": "58656358377246279051017109359677190749228949103591068167284263961542487110215", "price": "0.004", "size": "142.91", "side": "BUY", "timestamp": "1768573612863", "received_at": "2026-01-16T14:26:52.906386"}}
{"event_type": "price_change", "event_ts": "2026-01-16T14:26:52.906386", "ingestion_ts": "2026-01-16T14:27:04.418606", "market_id": "0xc0e6b917320a47228fb96e3b5ae0e5c93773a5ae2662ae4e1f37807cfe47ce98", "raw": {"market": "0xc0e6b917320a47228fb96e3b5ae0e5c93773a5ae2662ae4e1f37807cfe47ce98", "asset_id": "81647294538046680798858716589766492074338758116170717123345952330712416337530", "price": "0.996", "size": "142.91", "side": "SELL", "timestamp": "1768573612863", "received_at": "2026-01-16T14:26:52.906386"}}
{"event_type": "price_change", "event_ts": "2026-01-16T14:26:53.566617", "ingestion_ts": "2026-01-16T14:27:04.418606", "market_id": "0xae5584fbb57f23c1c608d544b656f23d8bf12340cef70811cf31bb0cb4fc2115", "raw": {"market": "0xae5584fbb57f23c1c608d544b656f23d8bf12340cef70811cf31bb0cb4fc2115", "asset_id": "42278252558046940014991595990628759801692726198478046188873057685686228021663", "price": "0.99", "size": "8145.4", "side": "SELL", "timestamp": "1768573613521", "received_at": "2026-01-16T14:26:53.566617"}}
{"event_type": "price_change", "event_ts": "2026-01-16T14:26:53.566617", "ingestion_ts": "2026-01-16T14:27:04.418606", "market_id": "0xae5584fbb57f23c1c608d544b656f23d8bf12340cef70811cf31bb0cb4fc2115", "raw": {"market": "0xae5584fbb57f23c1c608d544b656f23d8bf12340cef70811cf31bb0cb4fc2115", "asset_id": "28946595841244317705636126646676849578876740730186646421280828201004700559420", "price": "0.01", "size": "8145.4", "side": "BUY", "timestamp": "1768573613521", "received_at": "2026-01-16T14:26:53.566617"}}
{"event_type": "price_change", "event_ts": "2026-01-16T14:26:53.662086", "ingestion_ts": "2026-01-16T14:27:04.418606", "market_id": "0xae5584fbb57f23c1c608d544b656f23d8bf12340cef70811cf31bb0cb4fc2115", "raw": {"market": "0xae5584fbb57f23c1c608d544b656f23d8bf12340cef70811cf31bb0cb4fc2115", "asset_id": "28946595841244317705636126646676849578876740730186646421280828201004700559420", "price": "0.01", "size": "8097.6", "side": "BUY", "timestamp": "1768573613623", "received_at": "2026-01-16T14:26:53.662086"}}
{"event_type": "price_change", "event_ts": "2026-01-16T14:26:53.662086", "ingestion_ts": "2026-01-16T14:27:04.418606", "market_id": "0xae5584fbb57f23c1c608d544b656f23d8bf12340cef70811cf31bb0cb4fc2115", "raw": {"market": "0xae5584fbb57f23c1c608d544b656f23d8bf12340cef70811cf31bb0cb4fc2115", "asset_id": "42278252558046940014991595990628759801692726198478046188873057685686228021663", "price": "0.99", "size": "8097.6", "side": "SELL", "timestamp": "1768573613623", "received_at": "2026-01-16T14:26:53.662086"}}
{"event_type": "price_change", "event_ts": "2026-01-16T14:26:54.585766", "ingestion_ts": "2026-01-16T14:27:04.418606", "market_id": "0x22ac5f75af18fdb453497fbf7ac0606a09a6fd55b78b2d08aace6b946ad62038", "raw": {"market": "0x22ac5f75af18fdb453497fbf7ac0606a09a6fd55b78b2d08aace6b946ad62038", "asset_id": "59259495934562596318644973716893809974860301509869285036503555129962149752635", "price": "0.241", "size": "0", "side": "BUY", "timestamp": "1768573614543", "received_at": "2026-01-16T14:26:54.585766"}}
{"event_type": "price_change", "event_ts": "2026-01-16T14:26:54.585766", "ingestion_ts": "2026-01-16T14:27:04.418606", "market_id": "0x22ac5f75af18fdb453497fbf7ac0606a09a6fd55b78b2d08aace6b946ad62038", "raw": {"market": "0x22ac5f75af18fdb453497fbf7ac0606a09a6fd55b78b2d08aace6b946ad62038", "asset_id": "97449340182256366014320155718265676486703217567849039806162053075113517266910", "price": "0.759", "size": "0", "side": "SELL", "timestamp": "1768573614543", "received_at": "2026-01-16T14:26:54.585766"}}
{"event_type": "price_change", "event_ts": "2026-01-16T14:26:54.639261", "ingestion_ts": "2026-01-16T14:27:04.418606", "market_id": "0x22ac5f75af18fdb453497fbf7ac0606a09a6fd55b78b2d08aace6b946ad62038", "raw": {"market": "0x22ac5f75af18fdb453497fbf7ac0606a09a6fd55b78b2d08aace6b946ad62038", "asset_id": "59259495934562596318644973716893809974860301509869285036503555129962149752635", "price": "0.241", "size": "8", "side": "BUY", "timestamp": "1768573614599", "received_at": "2026-01-16T14:26:54.639261"}}
{"event_type": "price_change", "event_ts": "2026-01-16T14:26:54.639261", "ingestion_ts": "2026-01-16T14:27:04.418606", "market_id": "0x22ac5f75af18fdb453497fbf7ac0606a09a6fd55b78b2d08aace6b946ad62038", "raw": {"market": "0x22ac5f75af18fdb453497fbf7ac0606a09a6fd55b78b2d08aace6b946ad62038", "asset_id": "97449340182256366014320155718265676486703217567849039806162053075113517266910", "price": "0.759", "size": "8", "side": "SELL", "timestamp": "1768573614599", "received_at": "2026-01-16T14:26:54.639261"}}
{"event_type": "price_change", "event_ts": "2026-01-16T14:26:55.593761", "ingestion_ts": "2026-01-16T14:27:04.418606", "market_id": "0xc0e6b917320a47228fb96e3b5ae0e5c93773a5ae2662ae4e1f37807cfe47ce98", "raw": {"market": "0xc0e6b917320a47228fb96e3b5ae0e5c93773a5ae2662ae4e1f37807cfe47ce98", "asset_id": "58656358377246279051017109359677190749228949103591068167284263961542487110215", "price": "0.001", "size": "485.47", "side": "BUY", "timestamp": "1768573615551", "received_at": "2026-01-16T14:26:55.593761"}}
{"event_type": "price_change", "event_ts": "2026-01-16T14:26:55.593761", "ingestion_ts": "2026-01-16T14:27:04.418606", "market_id": "0xc0e6b917320a47228fb96e3b5ae0e5c93773a5ae2662ae4e1f37807cfe47ce98", "raw": {"market": "0xc0e6b917320a47228fb96e3b5ae0e5c93773a5ae2662ae4e1f37807cfe47ce98", "asset_id": "81647294538046680798858716589766492074338758116170717123345952330712416337530", "price": "0.999", "size": "485.47", "side": "SELL", "timestamp": "1768573615551", "received_at": "2026-01-16T14:26:55.593761"}}
{"event_type": "price_change", "event_ts": "2026-01-16T14:26:56.092152", "ingestion_ts": "2026-01-16T14:27:04.418606", "market_id": "0xc0e6b917320a47228fb96e3b5ae0e5c93773a5ae2662ae4e1f37807cfe47ce98", "raw": {"market": "0xc0e6b917320a47228fb96e3b5ae0e5c93773a5ae2662ae4e1f37807cfe47ce98", "asset_id": "58656358377246279051017109359677190749228949103591068167284263961542487110215", "price": "0.004", "size": "123.29", "side": "BUY", "timestamp": "1768573616052", "received_at": "2026-01-16T14:26:56.092152"}}
{"event_type": "price_change", "event_ts": "2026-01-16T14:26:56.092152", "ingestion_ts": "2026-01-16T14:27:04.418606", "market_id": "0xc0e6b917320a47228fb96e3b5ae0e5c93773a5ae2662ae4e1f37807cfe47ce98", "raw": {"market": "0xc0e6b917320a47228fb96e3b5ae0e5c93773a5ae2662ae4e1f37807cfe47ce98", "asset_id": "81647294538046680798858716589766492074338758116170717123345952330712416337530", "price": "0.996", "size": "123.29", "side": "SELL", "timestamp": "1768573616052", "received_at": "2026-01-16T14:26:56.092152"}}
{"event_type": "price_change", "event_ts": "2026-01-16T14:26:56.331058", "ingestion_ts": "2026-01-16T14:27:04.418606", "market_id": "0xc0e6b917320a47228fb96e3b5ae0e5c93773a5ae2662ae4e1f37807cfe47ce98", "raw": {"market": "0xc0e6b917320a47228fb96e3b5ae0e5c93773a5ae2662ae4e1f37807cfe47ce98", "asset_id": "58656358377246279051017109359677190749228949103591068167284263961542487110215", "price": "0.004", "size": "133.1", "side": "BUY", "timestamp": "1768573616291", "received_at": "2026-01-16T14:26:56.331058"}}
{"event_type": "price_change", "event_ts": "2026-01-16T14:26:56.331058", "ingestion_ts": "2026-01-16T14:27:04.418606", "market_id": "0xc0e6b917320a47228fb96e3b5ae0e5c93773a5ae2662ae4e1f37807cfe47ce98", "raw": {"market": "0xc0e6b917320a47228fb96e3b5ae0e5c93773a5ae2662ae4e1f37807cfe47ce98", "asset_id": "81647294538046680798858716589766492074338758116170717123345952330712416337530", "price": "0.996", "size": "133.1", "side": "SELL", "timestamp": "1768573616291", "received_at": "2026-01-16T14:26:56.331058"}}
{"event_type": "price_change", "event_ts": "2026-01-16T14:26:56.331108", "ingestion_ts": "2026-01-16T14:27:04.418606", "market_id": "0xc0e6b917320a47228fb96e3b5ae0e5c93773a5ae2662ae4e1f37807cfe47ce98", "raw": {"market": "0xc0e6b917320a47228fb96e3b5ae0e5c93773a5ae2662ae4e1f37807cfe47ce98", "asset_id": "58656358377246279051017109359677190749228949103591068167284263961542487110215", "price": "0.004", "size": "142.91", "side": "BUY", "timestamp": "1768573616291", "received_at": "2026-01-16T14:26:56.331108"}}
{"event_type": "price_change", "event_ts": "2026-01-16T14:26:56.331108", "ingestion_ts": "2026-01-16T14:27:04.418606", "market_id": "0xc0e6b917320a47228fb96e3b5ae0e5c93773a5ae2662ae4e1f37807cfe47ce98", "raw": {"market": "0xc0e6b917320a47228fb96e3b5ae0e5c93773a5ae2662ae4e1f37807cfe47ce98", "asset_id": "81647294538046680798858716589766492074338758116170717123345952330712416337530", "price": "0.996", "size": "142.91", "side": "SELL", "timestamp": "1768573616291", "received_at": "2026-01-16T14:26:56.331108"}}
{"event_type": "price_change", "event_ts": "2026-01-16T14:26:56.686468", "ingestion_ts": "2026-01-16T14:27:04.418606", "market_id": "0xea644975be7b2ad32b536a94ae21b707ecb2f84290225b24e60ca46dd77903dd", "raw": {"market": "0xea644975be7b2ad32b536a94ae21b707ecb2f84290225b24e60ca46dd77903dd", "asset_id": "19255594762111702415265750364124818677094538461124581923455280001407159960455", "price": "0.252", "size": "0", "side": "BUY", "timestamp": "1768573616618", "received_at": "2026-01-16T14:26:56.686468"}}
{"event_type": "price_change", "event_ts": "2026-01-16T14:26:56.686468", "ingestion_ts": "2026-01-16T14:27:04.418606", "market_id": "0xea644975be7b2ad32b536a94ae21b707ecb2f84290225b24e60ca46dd77903dd", "raw": {"market": "0xea644975be7b2ad32b536a94ae21b707ecb2f84290225b24e60ca46dd77903dd", "asset_id": "110044455628775971785618539427229099821815416148768008176051068105157446559241", "price": "0.748", "size": "0", "side": "SELL", "timestamp": "1768573616618", "received_at": "2026-01-16T14:26:56.686468"}}
{"event_type": "price_change", "event_ts": "2026-01-16T14:26:56.702398", "ingestion_ts": "2026-01-16T14:27:04.418606", "market_id": "0xc0e6b917320a47228fb96e3b5ae0e5c93773a5ae2662ae4e1f37807cfe47ce98", "raw": {"market": "0xc0e6b917320a47228fb96e3b5ae0e5c93773a5ae2662ae4e1f37807cfe47ce98", "asset_id": "81647294538046680798858716589766492074338758116170717123345952330712416337530", "price": "0.932", "size": "0", "side": "BUY", "timestamp": "1768573616619", "received_at": "2026-01-16T14:26:56.702398"}}
{"event_type": "price_change", "event_ts": "2026-01-16T14:26:56.702398", "ingestion_ts": "2026-01-16T14:27:04.418606", "market_id": "0xc0e6b917320a47228fb96e3b5ae0e5c93773a5ae2662ae4e1f37807cfe47ce98", "raw": {"market": "0xc0e6b917320a47228fb96e3b5ae0e5c93773a5ae2662ae4e1f37807cfe47ce98", "asset_id": "58656358377246279051017109359677190749228949103591068167284263961542487110215", "price": "0.068", "size": "0", "side": "SELL", "timestamp": "1768573616619", "received_at": "2026-01-16T14:26:56.702398"}}
{"event_type": "price_change", "event_ts": "2026-01-16T14:26:56.702438", "ingestion_ts": "2026-01-16T14:27:04.418606", "market_id": "0x22ac5f75af18fdb453497fbf7ac0606a09a6fd55b78b2d08aace6b946ad62038", "raw": {"market": "0x22ac5f75af18fdb453497fbf7ac0606a09a6fd55b78b2d08aace6b946ad62038", "asset_id": "59259495934562596318644973716893809974860301509869285036503555129962149752635", "price": "0.946", "size": "0", "side": "BUY", "timestamp": "1768573616621", "received_at": "2026-01-16T14:26:56.702438"}}
{"event_type": "price_change", "event_ts": "2026-01-16T14:26:56.702438", "ingestion_ts": "2026-01-16T14:27:04.418606", "market_id": "0x22ac5f75af18fdb453497fbf7ac0606a09a6fd55b78b2d08aace6b946ad62038", "raw": {"market": "0x22ac5f75af18fdb453497fbf7ac0606a09a6fd55b78b2d08aace6b946ad62038", "asset_id": "97449340182256366014320155718265676486703217567849039806162053075113517266910", "price": "0.054", "size": "0", "side": "SELL", "timestamp": "1768573616621", "received_at": "2026-01-16T14:26:56.702438"}}
{"event_type": "price_change", "event_ts": "2026-01-16T14:26:56.718236", "ingestion_ts": "2026-01-16T14:27:04.418606", "market_id": "0x5533fb9ab797777a243c75b1bf3882c54b1ee91f794730c090bf701598993529", "raw": {"market": "0x5533fb9ab797777a243c75b1bf3882c54b1ee91f794730c090bf701598993529", "asset_id": "99478074208094578615268494931219682040135218828258512927013036335093067688695", "price": "0.987", "size": "0", "side": "BUY", "timestamp": "1768573616622", "received_at": "2026-01-16T14:26:56.718236"}}
{"event_type": "price_change", "event_ts": "2026-01-16T14:26:56.718236", "ingestion_ts": "2026-01-16T14:27:04.418606", "market_id": "0x5533fb9ab797777a243c75b1bf3882c54b1ee91f794730c090bf701598993529", "raw": {"market": "0x5533fb9ab797777a243c75b1bf3882c54b1ee91f794730c090bf701598993529", "asset_id": "22532055631814907447535815649879981046415248231878961745474659705989546420934", "price": "0.013", "size": "0", "side": "SELL", "timestamp": "1768573616622", "received_at": "2026-01-16T14:26:56.718236"}}
{"event_type": "price_change", "event_ts": "2026-01-16T14:26:56.741490", "ingestion_ts": "2026-01-16T14:27:04.418606", "market_id": "0xaf9d0e448129a9f657f851d49495ba4742055d80e0ef1166ba0ee81d4d594214", "raw": {"market": "0xaf9d0e448129a9f657f851d49495ba4742055d80e0ef1166ba0ee81d4d594214", "asset_id": "4153292802911610701832309484716814274802943278345248636922528170020319407796", "price": "0.988", "size": "0", "side": "SELL", "timestamp": "1768573616619", "received_at": "2026-01-16T14:26:56.741490"}}
{"event_type": "price_change", "event_ts": "2026-01-16T14:26:56.741490", "ingestion_ts": "2026-01-16T14:27:04.418606", "market_id": "0xaf9d0e448129a9f657f851d49495ba4742055d80e0ef1166ba0ee81d4d594214", "raw": {"market": "0xaf9d0e448129a9f657f851d49495ba4742055d80e0ef1166ba0ee81d4d594214", "asset_id": "101676997363687199724245607342877036148401850938023978421879460310389391082353", "price": "0.012", "size": "0", "side": "BUY", "timestamp": "1768573616619", "received_at": "2026-01-16T14:26:56.741490"}}
{"event_type": "price_change", "event_ts": "2026-01-16T14:26:56.741506", "ingestion_ts": "2026-01-16T14:27:04.418606", "market_id": "0xaf9d0e448129a9f657f851d49495ba4742055d80e0ef1166ba0ee81d4d594214", "raw": {"market": "0xaf9d0e448129a9f657f851d49495ba4742055d80e0ef1166ba0ee81d4d594214", "asset_id": "4153292802911610701832309484716814274802943278345248636922528170020319407796", "price": "0.953", "size": "0", "side": "BUY", "timestamp": "1768573616619", "received_at": "2026-01-16T14:26:56.741506"}}
{"event_type": "price_change", "event_ts": "2026-01-16T14:26:56.741506", "ingestion_ts": "2026-01-16T14:27:04.418606", "market_id": "0xaf9d0e448129a9f657f851d49495ba4742055d80e0ef1166ba0ee81d4d594214", "raw": {"market": "0xaf9d0e448129a9f657f851d49495ba4742055d80e0ef1166ba0ee81d4d594214", "asset_id": "101676997363687199724245607342877036148401850938023978421879460310389391082353", "price": "0.047", "size": "0", "side": "SELL", "timestamp": "1768573616619", "received_at": "2026-01-16T14:26:56.741506"}}
{"event_type": "price_change", "event_ts": "2026-01-16T14:26:56.745881", "ingestion_ts": "2026-01-16T14:27:04.418606", "market_id": "0x9d24d9f9b5995949cb158d943793dea20bd448e1b3971cb6f7418bb15e719661", "raw": {"market": "0x9d24d9f9b5995949cb158d943793dea20bd448e1b3971cb6f7418bb15e719661", "asset_id": "79516121807256184736227920754945730465880754940725759201193439378549308939672", "price": "0.997", "size": "0", "side": "SELL", "timestamp": "1768573616624", "received_at": "2026-01-16T14:26:56.745881"}}
{"event_type": "price_change", "event_ts": "2026-01-16T14:26:56.745881", "ingestion_ts": "2026-01-16T14:27:04.418606", "market_id": "0x9d24d9f9b5995949cb158d943793dea20bd448e1b3971cb6f7418bb15e719661", "raw": {"market": "0x9d24d9f9b5995949cb158d943793dea20bd448e1b3971cb6f7418bb15e719661", "asset_id": "70512916946285526357165287373537570327431985324385225788636160168740471920430", "price": "0.003", "size": "0", "side": "BUY", "timestamp": "1768573616624", "received_at": "2026-01-16T14:26:56.745881"}}
{"event_type": "price_change", "event_ts": "2026-01-16T14:26:56.800751", "ingestion_ts": "2026-01-16T14:27:04.418606", "market_id": "0x44f08744458b8896620cd3330bc5e1ea69df4199b02d4fc583b3fc96e5d314ce", "raw": {"market": "0x44f08744458b8896620cd3330bc5e1ea69df4199b02d4fc583b3fc96e5d314ce", "asset_id": "72327831507226612545928776794104143393438710920370371172884559893525100761096", "price": "0.968", "size": "0", "side": "BUY", "timestamp": "1768573616618", "received_at": "2026-01-16T14:26:56.800751"}}
{"event_type": "price_change", "event_ts": "2026-01-16T14:26:56.800751", "ingestion_ts": "2026-01-16T14:27:04.418606", "market_id": "0x44f08744458b8896620cd3330bc5e1ea69df4199b02d4fc583b3fc96e5d314ce", "raw": {"market": "0x44f08744458b8896620cd3330bc5e1ea69df4199b02d4fc583b3fc96e5d314ce", "asset_id": "49194009556504828848509244326501559253829462790583873936160989575507522044057", "price": "0.032", "size": "0", "side": "SELL", "timestamp": "1768573616618", "received_at": "2026-01-16T14:26:56.800751"}}
{"event_type": "price_change", "event_ts": "2026-01-16T14:26:56.800791", "ingestion_ts": "2026-01-16T14:27:04.418606", "market_id": "0x2393ed0b0fdc450054c7b9071907eca75cf4fc36e385adf4a0a5f99ee62243e8", "raw": {"market": "0x2393ed0b0fdc450054c7b9071907eca75cf4fc36e385adf4a0a5f99ee62243e8", "asset_id": "32769749367306925959219403371425714180265458150646381231272229429098460625924", "price": "0.952", "size": "0", "side": "BUY", "timestamp": "1768573616626", "received_at": "2026-01-16T14:26:56.800791"}}
{"event_type": "price_change", "event_ts": "2026-01-16T14:26:56.800791", "ingestion_ts": "2026-01-16T14:27:04.418606", "market_id": "0x2393ed0b0fdc450054c7b9071907eca75cf4fc36e385adf4a0a5f99ee62243e8", "raw": {"market": "0x2393ed0b0fdc450054c7b9071907eca75cf4fc36e385adf4a0a5f99ee62243e8", "asset_id": "100074770378634056601572485653252702850363676459996771990439989989293515601975", "price": "0.048", "size": "0", "side": "SELL", "timestamp": "1768573616626", "received_at": "2026-01-16T14:26:56.800791"}}
{"event_type": "price_change", "event_ts": "2026-01-16T14:26:56.918733", "ingestion_ts": "2026-01-16T14:27:04.418606", "market_id": "0xaf9d0e448129a9f657f851d49495ba4742055d80e0ef1166ba0ee81d4d594214", "raw": {"market": "0xaf9d0e448129a9f657f851d49495ba4742055d80e0ef1166ba0ee81d4d594214", "asset_id": "4153292802911610701832309484716814274802943278345248636922528170020319407796", "price": "0.987", "size": "140.01", "side": "SELL", "timestamp": "1768573616783", "received_at": "2026-01-16T14:26:56.918733"}}
{"event_type": "price_change", "event_ts": "2026-01-16T14:26:56.918733", "ingestion_ts": "2026-01-16T14:27:04.418606", "market_id": "0xaf9d0e448129a9f657f851d49495ba4742055d80e0ef1166ba0ee81d4d594214", "raw": {"market": "0xaf9d0e448129a9f657f851d49495ba4742055d80e0ef1166ba0ee81d4d594214", "asset_id": "101676997363687199724245607342877036148401850938023978421879460310389391082353", "price": "0.013", "size": "140.01", "side": "BUY", "timestamp": "1768573616783", "received_at": "2026-01-16T14:26:56.918733"}}
{"event_type": "price_change", "event_ts": "2026-01-16T14:26:57.093352", "ingestion_ts": "2026-01-16T14:27:04.418606", "market_id": "0x49686d26fb712515cd5e12c23f0a1c7e10214c7faa3cb0a730aabe0c33694082", "raw": {"market": "0x49686d26fb712515cd5e12c23f0a1c7e10214c7faa3cb0a730aabe0c33694082", "asset_id": "13244681086321087932946246027856416106585284024824496763706748621681543444582", "price": "0.852", "size": "17.5", "side": "BUY", "timestamp": "1768573616985", "received_at": "2026-01-16T14:26:57.093352"}}
{"event_type": "price_change", "event_ts": "2026-01-16T14:26:57.093352", "ingestion_ts": "2026-01-16T14:27:04.418606", "market_id": "0x49686d26fb712515cd5e12c23f0a1c7e10214c7faa3cb0a730aabe0c33694082", "raw": {"market": "0x49686d26fb712515cd5e12c23f0a1c7e10214c7faa3cb0a730aabe0c33694082", "asset_id": "30442780799048074404860985387051749017905070253466005720364298335239299761065", "price": "0.148", "size": "17.5", "side": "SELL", "timestamp": "1768573616985", "received_at": "2026-01-16T14:26:57.093352"}}
{"event_type": "price_change", "event_ts": "2026-01-16T14:26:57.643425", "ingestion_ts": "2026-01-16T14:27:04.418606", "market_id": "0xaf9d0e448129a9f657f851d49495ba4742055d80e0ef1166ba0ee81d4d594214", "raw": {"market": "0xaf9d0e448129a9f657f851d49495ba4742055d80e0ef1166ba0ee81d4d594214", "asset_id": "4153292802911610701832309484716814274802943278345248636922528170020319407796", "price": "0.989", "size": "0", "side": "SELL", "timestamp": "1768573617585", "received_at": "2026-01-16T14:26:57.643425"}}
{"event_type": "price_change", "event_ts": "2026-01-16T14:26:57.643425", "ingestion_ts": "2026-01-16T14:27:04.418606", "market_id": "0xaf9d0e448129a9f657f851d49495ba4742055d80e0ef1166ba0ee81d4d594214", "raw": {"market": "0xaf9d0e448129a9f657f851d49495ba4742055d80e0ef1166ba0ee81d4d594214", "asset_id": "101676997363687199724245607342877036148401850938023978421879460310389391082353", "price": "0.011", "size": "0", "side": "BUY", "timestamp": "1768573617585", "received_at": "2026-01-16T14:26:57.643425"}}
{"event_type": "price_change", "event_ts": "2026-01-16T14:26:57.692095", "ingestion_ts": "2026-01-16T14:27:04.418606", "market_id": "0xaf9d0e448129a9f657f851d49495ba4742055d80e0ef1166ba0ee81d4d594214", "raw": {"market": "0xaf9d0e448129a9f657f851d49495ba4742055d80e0ef1166ba0ee81d4d594214", "asset_id": "4153292802911610701832309484716814274802943278345248636922528170020319407796", "price": "0.986", "size": "20.5", "side": "SELL", "timestamp": "1768573617644", "received_at": "2026-01-16T14:26:57.692095"}}
{"event_type": "price_change", "event_ts": "2026-01-16T14:26:57.692095", "ingestion_ts": "2026-01-16T14:27:04.418606", "market_id": "0xaf9d0e448129a9f657f851d49495ba4742055d80e0ef1166ba0ee81d4d594214", "raw": {"market": "0xaf9d0e448129a9f657f851d49495ba4742055d80e0ef1166ba0ee81d4d594214", "asset_id": "101676997363687199724245607342877036148401850938023978421879460310389391082353", "price": "0.014", "size": "20.5", "side": "BUY", "timestamp": "1768573617644", "received_at": "2026-01-16T14:26:57.692095"}}
{"event_type": "price_change", "event_ts": "2026-01-16T14:26:57.738316", "ingestion_ts": "2026-01-16T14:27:04.418606", "market_id": "0xaf9d0e448129a9f657f851d49495ba4742055d80e0ef1166ba0ee81d4d594214", "raw": {"market": "0xaf9d0e448129a9f657f851d49495ba4742055d80e0ef1166ba0ee81d4d594214", "asset_id": "4153292802911610701832309484716814274802943278345248636922528170020319407796", "price": "0.952", "size": "9", "side": "BUY", "timestamp": "1768573617668", "received_at": "2026-01-16T14:26:57.738316"}}
{"event_type": "price_change", "event_ts": "2026-01-16T14:26:57.738316", "ingestion_ts": "2026-01-16T14:27:04.418606", "market_id": "0xaf9d0e448129a9f657f851d49495ba4742055d80e0ef1166ba0ee81d4d594214", "raw": {"market": "0xaf9d0e448129a9f657f851d49495ba4742055d80e0ef1166ba0ee81d4d594214", "asset_id": "101676997363687199724245607342877036148401850938023978421879460310389391082353", "price": "0.048", "size": "9", "side": "SELL", "timestamp": "1768573617668", "received_at": "2026-01-16T14:26:57.738316"}}
{"event_type": "price_change", "event_ts": "2026-01-16T14:26:57.738379", "ingestion_ts": "2026-01-16T14:27:04.418606", "market_id": "0x44f08744458b8896620cd3330bc5e1ea69df4199b02d4fc583b3fc96e5d314ce", "raw": {"market": "0x44f08744458b8896620cd3330bc5e1ea69df4199b02d4fc583b3fc96e5d314ce", "asset_id": "72327831507226612545928776794104143393438710920370371172884559893525100761096", "price": "0.968", "size": "50", "side": "BUY", "timestamp": "1768573617675", "received_at": "2026-01-16T14:26:57.738379"}}
{"event_type": "price_change", "event_ts": "2026-01-16T14:26:57.738379", "ingestion_ts": "2026-01-16T14:27:04.418606", "market_id": "0x44f08744458b8896620cd3330bc5e1ea69df4199b02d4fc583b3fc96e5d314ce", "raw": {"market": "0x44f08744458b8896620cd3330bc5e1ea69df4199b02d4fc583b3fc96e5d314ce", "asset_id": "49194009556504828848509244326501559253829462790583873936160989575507522044057", "price": "0.032", "size": "50", "side": "SELL", "timestamp": "1768573617675", "received_at": "2026-01-16T14:26:57.738379"}}
{"event_type": "price_change", "event_ts": "2026-01-16T14:26:57.990420", "ingestion_ts": "2026-01-16T14:27:04.418606", "market_id": "0xb9bbdd34304344dcc45803780a34c97d73a00133a5ecf70f63e1008b8abb2fca", "raw": {"market": "0xb9bbdd34304344dcc45803780a34c97d73a00133a5ecf70f63e1008b8abb2fca", "asset_id": "8682484153073832526711485265636767086525069344085206423986003504588877767339", "price": "0.838", "size": "148.24", "side": "BUY", "timestamp": "1768573617952", "received_at": "2026-01-16T14:26:57.990420"}}
{"event_type": "price_change", "event_ts": "2026-01-16T14:26:57.990420", "ingestion_ts": "2026-01-16T14:27:04.418606", "market_id": "0xb9bbdd34304344dcc45803780a34c97d73a00133a5ecf70f63e1008b8abb2fca", "raw": {"market": "0xb9bbdd34304344dcc45803780a34c97d73a00133a5ecf70f63e1008b8abb2fca", "asset_id": "72012724360700510767037780555710363830014634797787940282136454146828040926557", "price": "0.162", "size": "148.24", "side": "SELL", "timestamp": "1768573617952", "received_at": "2026-01-16T14:26:57.990420"}}
{"event_type": "price_change", "event_ts": "2026-01-16T14:26:57.990495", "ingestion_ts": "2026-01-16T14:27:04.418606", "market_id": "0x49a20c7523c271099008f3ef9a31521263b24d637959852a391e6b4697b1a437", "raw": {"market": "0x49a20c7523c271099008f3ef9a31521263b24d637959852a391e6b4697b1a437", "asset_id": "55881023621710858558280545117465775643848233756850602339827152783696837905531", "price": "0.824", "size": "0", "side": "BUY", "timestamp": "1768573617952", "received_at": "2026-01-16T14:26:57.990495"}}
{"event_type": "price_change", "event_ts": "2026-01-16T14:26:57.990495", "ingestion_ts": "2026-01-16T14:27:04.418606", "market_id": "0x49a20c7523c271099008f3ef9a31521263b24d637959852a391e6b4697b1a437", "raw": {"market": "0x49a20c7523c271099008f3ef9a31521263b24d637959852a391e6b4697b1a437", "asset_id": "13018971792603393862521629014128024641178044618205296260525674415067194037856", "price": "0.176", "size": "0", "side": "SELL", "timestamp": "1768573617952", "received_at": "2026-01-16T14:26:57.990495"}}
{"event_type": "price_change", "event_ts": "2026-01-16T14:26:58.030534", "ingestion_ts": "2026-01-16T14:27:04.418606", "market_id": "0xb9bbdd34304344dcc45803780a34c97d73a00133a5ecf70f63e1008b8abb2fca", "raw": {"market": "0xb9bbdd34304344dcc45803780a34c97d73a00133a5ecf70f63e1008b8abb2fca", "asset_id": "8682484153073832526711485265636767086525069344085206423986003504588877767339", "price": "0.84", "size": "40", "side": "BUY", "timestamp": "1768573617987", "received_at": "2026-01-16T14:26:58.030534"}}
{"event_type": "price_change", "event_ts": "2026-01-16T14:26:58.030534", "ingestion_ts": "2026-01-16T14:27:04.418606", "market_id": "0xb9bbdd34304344dcc45803780a34c97d73a00133a5ecf70f63e1008b8abb2fca", "raw": {"market": "0xb9bbdd34304344dcc45803780a34c97d73a00133a5ecf70f63e1008b8abb2fca", "asset_id": "72012724360700510767037780555710363830014634797787940282136454146828040926557", "price": "0.16", "size": "40", "side": "SELL", "timestamp": "1768573617987", "received_at": "2026-01-16T14:26:58.030534"}}
{"event_type": "price_change", "event_ts": "2026-01-16T14:26:58.030602", "ingestion_ts": "2026-01-16T14:27:04.418606", "market_id": "0x49a20c7523c271099008f3ef9a31521263b24d637959852a391e6b4697b1a437", "raw": {"market": "0x49a20c7523c271099008f3ef9a31521263b24d637959852a391e6b4697b1a437", "asset_id": "55881023621710858558280545117465775643848233756850602339827152783696837905531", "price": "0.847", "size": "10", "side": "BUY", "timestamp": "1768573617987", "received_at": "2026-01-16T14:26:58.030602"}}
{"event_type": "price_change", "event_ts": "2026-01-16T14:26:58.030602", "ingestion_ts": "2026-01-16T14:27:04.418606", "market_id": "0x49a20c7523c271099008f3ef9a31521263b24d637959852a391e6b4697b1a437", "raw": {"market": "0x49a20c7523c271099008f3ef9a31521263b24d637959852a391e6b4697b1a437", "asset_id": "13018971792603393862521629014128024641178044618205296260525674415067194037856", "price": "0.153", "size": "10", "side": "SELL", "timestamp": "1768573617987", "received_at": "2026-01-16T14:26:58.030602"}}
{"event_type": "price_change", "event_ts": "2026-01-16T14:26:58.440108", "ingestion_ts": "2026-01-16T14:27:04.418606", "market_id": "0xaf9d0e448129a9f657f851d49495ba4742055d80e0ef1166ba0ee81d4d594214", "raw": {"market": "0xaf9d0e448129a9f657f851d49495ba4742055d80e0ef1166ba0ee81d4d594214", "asset_id": "4153292802911610701832309484716814274802943278345248636922528170020319407796", "price": "0.954", "size": "0", "side": "BUY", "timestamp": "1768573618384", "received_at": "2026-01-16T14:26:58.440108"}}
{"event_type": "price_change", "event_ts": "2026-01-16T14:26:58.440108", "ingestion_ts": "2026-01-16T14:27:04.418606", "market_id": "0xaf9d0e448129a9f657f851d49495ba4742055d80e0ef1166ba0ee81d4d594214", "raw": {"market": "0xaf9d0e448129a9f657f851d49495ba4742055d80e0ef1166ba0ee81d4d594214", "asset_id": "101676997363687199724245607342877036148401850938023978421879460310389391082353", "price": "0.046", "size": "0", "side": "SELL", "timestamp": "1768573618384", "received_at": "2026-01-16T14:26:58.440108"}}
{"event_type": "price_change", "event_ts": "2026-01-16T14:26:58.454769", "ingestion_ts": "2026-01-16T14:27:04.418606", "market_id": "0x44f08744458b8896620cd3330bc5e1ea69df4199b02d4fc583b3fc96e5d314ce", "raw": {"market": "0x44f08744458b8896620cd3330bc5e1ea69df4199b02d4fc583b3fc96e5d314ce", "asset_id": "72327831507226612545928776794104143393438710920370371172884559893525100761096", "price": "0.969", "size": "0", "side": "BUY", "timestamp": "1768573618388", "received_at": "2026-01-16T14:26:58.454769"}}
{"event_type": "price_change", "event_ts": "2026-01-16T14:26:58.454769", "ingestion_ts": "2026-01-16T14:27:04.418606", "market_id": "0x44f08744458b8896620cd3330bc5e1ea69df4199b02d4fc583b3fc96e5d314ce", "raw": {"market": "0x44f08744458b8896620cd3330bc5e1ea69df4199b02d4fc583b3fc96e5d314ce", "asset_id": "49194009556504828848509244326501559253829462790583873936160989575507522044057", "price": "0.031", "size": "0", "side": "SELL", "timestamp": "1768573618388", "received_at": "2026-01-16T14:26:58.454769"}}
{"event_type": "price_change", "event_ts": "2026-01-16T14:26:58.707846", "ingestion_ts": "2026-01-16T14:27:04.418606", "market_id": "0x44f08744458b8896620cd3330bc5e1ea69df4199b02d4fc583b3fc96e5d314ce", "raw": {"market": "0x44f08744458b8896620cd3330bc5e1ea69df4199b02d4fc583b3fc96e5d314ce", "asset_id": "72327831507226612545928776794104143393438710920370371172884559893525100761096", "price": "0.967", "size": "25", "side": "BUY", "timestamp": "1768573618666", "received_at": "2026-01-16T14:26:58.707846"}}
{"event_type": "price_change", "event_ts": "2026-01-16T14:26:58.707846", "ingestion_ts": "2026-01-16T14:27:04.418606", "market_id": "0x44f08744458b8896620cd3330bc5e1ea69df4199b02d4fc583b3fc96e5d314ce", "raw": {"market": "0x44f08744458b8896620cd3330bc5e1ea69df4199b02d4fc583b3fc96e5d314ce", "asset_id": "49194009556504828848509244326501559253829462790583873936160989575507522044057", "price": "0.033", "size": "25", "side": "SELL", "timestamp": "1768573618666", "received_at": "2026-01-16T14:26:58.707846"}}
{"event_type": "price_change", "event_ts": "2026-01-16T14:26:59.600275", "ingestion_ts": "2026-01-16T14:27:04.418606", "market_id": "0xc0e6b917320a47228fb96e3b5ae0e5c93773a5ae2662ae4e1f37807cfe47ce98", "raw": {"market": "0xc0e6b917320a47228fb96e3b5ae0e5c93773a5ae2662ae4e1f37807cfe47ce98", "asset_id": "81647294538046680798858716589766492074338758116170717123345952330712416337530", "price": "0.993", "size": "44.99", "side": "SELL", "timestamp": "1768573619551", "received_at": "2026-01-16T14:26:59.600275"}}
{"event_type": "price_change", "event_ts": "2026-01-16T14:26:59.600275", "ingestion_ts": "2026-01-16T14:27:04.418606", "market_id": "0xc0e6b917320a47228fb96e3b5ae0e5c93773a5ae2662ae4e1f37807cfe47ce98", "raw": {"market": "0xc0e6b917320a47228fb96e3b5ae0e5c93773a5ae2662ae4e1f37807cfe47ce98", "asset_id": "58656358377246279051017109359677190749228949103591068167284263961542487110215", "price": "0.007", "size": "44.99", "side": "BUY", "timestamp": "1768573619551", "received_at": "2026-01-16T14:26:59.600275"}}
{"event_type": "price_change", "event_ts": "2026-01-16T14:26:59.961516", "ingestion_ts": "2026-01-16T14:27:04.418606", "market_id": "0xae5584fbb57f23c1c608d544b656f23d8bf12340cef70811cf31bb0cb4fc2115", "raw": {"market": "0xae5584fbb57f23c1c608d544b656f23d8bf12340cef70811cf31bb0cb4fc2115", "asset_id": "42278252558046940014991595990628759801692726198478046188873057685686228021663", "price": "0.99", "size": "8199.8", "side": "SELL", "timestamp": "1768573619923", "received_at": "2026-01-16T14:26:59.961516"}}
{"event_type": "price_change", "event_ts": "2026-01-16T14:26:59.961516", "ingestion_ts": "2026-01-16T14:27:04.418606", "market_id": "0xae5584fbb57f23c1c608d544b656f23d8bf12340cef70811cf31bb0cb4fc2115", "raw": {"market": "0xae5584fbb57f23c1c608d544b656f23d8bf12340cef70811cf31bb0cb4fc2115", "asset_id": "28946595841244317705636126646676849578876740730186646421280828201004700559420", "price": "0.01", "size": "8199.8", "side": "BUY", "timestamp": "1768573619923", "received_at": "2026-01-16T14:26:59.961516"}}
{"event_type": "price_change", "event_ts": "2026-01-16T14:27:00.083727", "ingestion_ts": "2026-01-16T14:27:04.418606", "market_id": "0xae5584fbb57f23c1c608d544b656f23d8bf12340cef70811cf31bb0cb4fc2115", "raw": {"market": "0xae5584fbb57f23c1c608d544b656f23d8bf12340cef70811cf31bb0cb4fc2115", "asset_id": "28946595841244317705636126646676849578876740730186646421280828201004700559420", "price": "0.01", "size": "8247.6", "side": "BUY", "timestamp": "1768573620042", "received_at": "2026-01-16T14:27:00.083727"}}
{"event_type": "price_change", "event_ts": "2026-01-16T14:27:00.083727", "ingestion_ts": "2026-01-16T14:27:04.418606", "market_id": "0xae5584fbb57f23c1c608d544b656f23d8bf12340cef70811cf31bb0cb4fc2115", "raw": {"market": "0xae5584fbb57f23c1c608d544b656f23d8bf12340cef70811cf31bb0cb4fc2115", "asset_id": "42278252558046940014991595990628759801692726198478046188873057685686228021663", "price": "0.99", "size": "8247.6", "side": "SELL", "timestamp": "1768573620042", "received_at": "2026-01-16T14:27:00.083727"}}
{"event_type": "price_change", "event_ts": "2026-01-16T14:27:00.696258", "ingestion_ts": "2026-01-16T14:27:04.418606", "market_id": "0xc0e6b917320a47228fb96e3b5ae0e5c93773a5ae2662ae4e1f37807cfe47ce98", "raw": {"market": "0xc0e6b917320a47228fb96e3b5ae0e5c93773a5ae2662ae4e1f37807cfe47ce98", "asset_id": "58656358377246279051017109359677190749228949103591068167284263961542487110215", "price": "0.004", "size": "67.02", "side": "BUY", "timestamp": "1768573620656", "received_at": "2026-01-16T14:27:00.696258"}}
{"event_type": "price_change", "event_ts": "2026-01-16T14:27:00.696258", "ingestion_ts": "2026-01-16T14:27:04.418606", "market_id": "0xc0e6b917320a47228fb96e3b5ae0e5c93773a5ae2662ae4e1f37807cfe47ce98", "raw": {"market": "0xc0e6b917320a47228fb96e3b5ae0e5c93773a5ae2662ae4e1f37807cfe47ce98", "asset_id": "81647294538046680798858716589766492074338758116170717123345952330712416337530", "price": "0.996", "size": "67.02", "side": "SELL", "timestamp": "1768573620656", "received_at": "2026-01-16T14:27:00.696258"}}
{"event_type": "price_change", "event_ts": "2026-01-16T14:27:00.921171", "ingestion_ts": "2026-01-16T14:27:04.418606", "market_id": "0xc0e6b917320a47228fb96e3b5ae0e5c93773a5ae2662ae4e1f37807cfe47ce98", "raw": {"market": "0xc0e6b917320a47228fb96e3b5ae0e5c93773a5ae2662ae4e1f37807cfe47ce98", "asset_id": "58656358377246279051017109359677190749228949103591068167284263961542487110215", "price": "0.008", "size": "18.97", "side": "BUY", "timestamp": "1768573620882", "received_at": "2026-01-16T14:27:00.921171"}}
{"event_type": "price_change", "event_ts": "2026-01-16T14:27:00.921171", "ingestion_ts": "2026-01-16T14:27:04.418606", "market_id": "0xc0e6b917320a47228fb96e3b5ae0e5c93773a5ae2662ae4e1f37807cfe47ce98", "raw": {"market": "0xc0e6b917320a47228fb96e3b5ae0e5c93773a5ae2662ae4e1f37807cfe47ce98", "asset_id": "81647294538046680798858716589766492074338758116170717123345952330712416337530", "price": "0.992", "size": "18.97", "side": "SELL", "timestamp": "1768573620882", "received_at": "2026-01-16T14:27:00.921171"}}
{"event_type": "price_change", "event_ts": "2026-01-16T14:27:00.921217", "ingestion_ts": "2026-01-16T14:27:04.418606", "market_id": "0xc0e6b917320a47228fb96e3b5ae0e5c93773a5ae2662ae4e1f37807cfe47ce98", "raw": {"market": "0xc0e6b917320a47228fb96e3b5ae0e5c93773a5ae2662ae4e1f37807cfe47ce98", "asset_id": "58656358377246279051017109359677190749228949103591068167284263961542487110215", "price": "0.008", "size": "37.94", "side": "BUY", "timestamp": "1768573620883", "received_at": "2026-01-16T14:27:00.921217"}}
{"event_type": "price_change", "event_ts": "2026-01-16T14:27:00.921217", "ingestion_ts": "2026-01-16T14:27:04.418606", "market_id": "0xc0e6b917320a47228fb96e3b5ae0e5c93773a5ae2662ae4e1f37807cfe47ce98", "raw": {"market": "0xc0e6b917320a47228fb96e3b5ae0e5c93773a5ae2662ae4e1f37807cfe47ce98", "asset_id": "81647294538046680798858716589766492074338758116170717123345952330712416337530", "price": "0.992", "size": "37.94", "side": "SELL", "timestamp": "1768573620883", "received_at": "2026-01-16T14:27:00.921217"}}
{"event_type": "price_change", "event_ts": "2026-01-16T14:27:01.186594", "ingestion_ts": "2026-01-16T14:27:04.418606", "market_id": "0xc0e6b917320a47228fb96e3b5ae0e5c93773a5ae2662ae4e1f37807cfe47ce98", "raw": {"market": "0xc0e6b917320a47228fb96e3b5ae0e5c93773a5ae2662ae4e1f37807cfe47ce98", "asset_id": "58656358377246279051017109359677190749228949103591068167284263961542487110215", "price": "0.067", "size": "0", "side": "SELL", "timestamp": "1768573621082", "received_at": "2026-01-16T14:27:01.186594"}}
{"event_type": "price_change", "event_ts": "2026-01-16T14:27:01.186594", "ingestion_ts": "2026-01-16T14:27:04.418606", "market_id": "0xc0e6b917320a47228fb96e3b5ae0e5c93773a5ae2662ae4e1f37807cfe47ce98", "raw": {"market": "0xc0e6b917320a47228fb96e3b5ae0e5c93773a5ae2662ae4e1f37807cfe47ce98", "asset_id": "81647294538046680798858716589766492074338758116170717123345952330712416337530", "price": "0.933", "size": "0", "side": "BUY", "timestamp": "1768573621082", "received_at": "2026-01-16T14:27:01.186594"}}
{"event_type": "price_change", "event_ts": "2026-01-16T14:27:01.371634", "ingestion_ts": "2026-01-16T14:27:04.418606", "market_id": "0xc0e6b917320a47228fb96e3b5ae0e5c93773a5ae2662ae4e1f37807cfe47ce98", "raw": {"market": "0xc0e6b917320a47228fb96e3b5ae0e5c93773a5ae2662ae4e1f37807cfe47ce98", "asset_id": "58656358377246279051017109359677190749228949103591068167284263961542487110215", "price": "0.066", "size": "7.5", "side": "SELL", "timestamp": "1768573621328", "received_at": "2026-01-16T14:27:01.371634"}}
{"event_type": "price_change", "event_ts": "2026-01-16T14:27:01.371634", "ingestion_ts": "2026-01-16T14:27:04.418606", "market_id": "0xc0e6b917320a47228fb96e3b5ae0e5c93773a5ae2662ae4e1f37807cfe47ce98", "raw": {"market": "0xc0e6b917320a47228fb96e3b5ae0e5c93773a5ae2662ae4e1f37807cfe47ce98", "asset_id": "81647294538046680798858716589766492074338758116170717123345952330712416337530", "price": "0.934", "size": "7.5", "side": "BUY", "timestamp": "1768573621328", "received_at": "2026-01-16T14:27:01.371634"}}
{"event_type": "price_change", "event_ts": "2026-01-16T14:27:02.839949", "ingestion_ts": "2026-01-16T14:27:04.418606", "market_id": "0xc0e6b917320a47228fb96e3b5ae0e5c93773a5ae2662ae4e1f37807cfe47ce98", "raw": {"market": "0xc0e6b917320a47228fb96e3b5ae0e5c93773a5ae2662ae4e1f37807cfe47ce98", "asset_id": "58656358377246279051017109359677190749228949103591068167284263961542487110215", "price": "0.004", "size": "57.21", "side": "BUY", "timestamp": "1768573622798", "received_at": "2026-01-16T14:27:02.839949"}}
{"event_type": "price_change", "event_ts": "2026-01-16T14:27:02.839949", "ingestion_ts": "2026-01-16T14:27:04.418606", "market_id": "0xc0e6b917320a47228fb96e3b5ae0e5c93773a5ae2662ae4e1f37807cfe47ce98", "raw": {"market": "0xc0e6b917320a47228fb96e3b5ae0e5c93773a5ae2662ae4e1f37807cfe47ce98", "asset_id": "81647294538046680798858716589766492074338758116170717123345952330712416337530", "price": "0.996", "size": "57.21", "side": "SELL", "timestamp": "1768573622798", "received_at": "2026-01-16T14:27:02.839949"}}
{"event_type": "price_change", "event_ts": "2026-01-16T14:27:03.207296", "ingestion_ts": "2026-01-16T14:27:04.418606", "market_id": "0xc0e6b917320a47228fb96e3b5ae0e5c93773a5ae2662ae4e1f37807cfe47ce98", "raw": {"market": "0xc0e6b917320a47228fb96e3b5ae0e5c93773a5ae2662ae4e1f37807cfe47ce98", "asset_id": "58656358377246279051017109359677190749228949103591068167284263961542487110215", "price": "0.002", "size": "3275.86", "side": "BUY", "timestamp": "1768573623169", "received_at": "2026-01-16T14:27:03.207296"}}
{"event_type": "price_change", "event_ts": "2026-01-16T14:27:03.207296", "ingestion_ts": "2026-01-16T14:27:04.418606", "market_id": "0xc0e6b917320a47228fb96e3b5ae0e5c93773a5ae2662ae4e1f37807cfe47ce98", "raw": {"market": "0xc0e6b917320a47228fb96e3b5ae0e5c93773a5ae2662ae4e1f37807cfe47ce98", "asset_id": "81647294538046680798858716589766492074338758116170717123345952330712416337530", "price": "0.998", "size": "3275.86", "side": "SELL", "timestamp": "1768573623169", "received_at": "2026-01-16T14:27:03.207296"}}
{"event_type": "price_change", "event_ts": "2026-01-16T14:27:03.208575", "ingestion_ts": "2026-01-16T14:27:04.418606", "market_id": "0xc0e6b917320a47228fb96e3b5ae0e5c93773a5ae2662ae4e1f37807cfe47ce98", "raw": {"market": "0xc0e6b917320a47228fb96e3b5ae0e5c93773a5ae2662ae4e1f37807cfe47ce98", "asset_id": "58656358377246279051017109359677190749228949103591068167284263961542487110215", "price": "0.002", "size": "3285.69", "side": "BUY", "timestamp": "1768573623170", "received_at": "2026-01-16T14:27:03.208575"}}
{"event_type": "price_change", "event_ts": "2026-01-16T14:27:03.208575", "ingestion_ts": "2026-01-16T14:27:04.418606", "market_id": "0xc0e6b917320a47228fb96e3b5ae0e5c93773a5ae2662ae4e1f37807cfe47ce98", "raw": {"market": "0xc0e6b917320a47228fb96e3b5ae0e5c93773a5ae2662ae4e1f37807cfe47ce98", "asset_id": "81647294538046680798858716589766492074338758116170717123345952330712416337530", "price": "0.998", "size": "3285.69", "side": "SELL", "timestamp": "1768573623170", "received_at": "2026-01-16T14:27:03.208575"}}
{"event_type": "price_change", "event_ts": "2026-01-16T14:27:03.485990", "ingestion_ts": "2026-01-16T14:27:04.418606", "market_id": "0x49686d26fb712515cd5e12c23f0a1c7e10214c7faa3cb0a730aabe0c33694082", "raw": {"market": "0x49686d26fb712515cd5e12c23f0a1c7e10214c7faa3cb0a730aabe0c33694082", "asset_id": "13244681086321087932946246027856416106585284024824496763706748621681543444582", "price": "0.852", "size": "23.36", "side": "BUY", "timestamp": "1768573623440", "received_at": "2026-01-16T14:27:03.485990"}}
{"event_type": "price_change", "event_ts": "2026-01-16T14:27:03.485990", "ingestion_ts": "2026-01-16T14:27:04.418606", "market_id": "0x49686d26fb712515cd5e12c23f0a1c7e10214c7faa3cb0a730aabe0c33694082", "raw": {"market": "0x49686d26fb712515cd5e12c23f0a1c7e10214c7faa3cb0a730aabe0c33694082", "asset_id": "30442780799048074404860985387051749017905070253466005720364298335239299761065", "price": "0.148", "size": "23.36", "side": "SELL", "timestamp": "1768573623440", "received_at": "2026-01-16T14:27:03.485990"}}
{"event_type": "price_change", "event_ts": "2026-01-16T14:27:03.712725", "ingestion_ts": "2026-01-16T14:27:04.418606", "market_id": "0xc0e6b917320a47228fb96e3b5ae0e5c93773a5ae2662ae4e1f37807cfe47ce98", "raw": {"market": "0xc0e6b917320a47228fb96e3b5ae0e5c93773a5ae2662ae4e1f37807cfe47ce98", "asset_id": "58656358377246279051017109359677190749228949103591068167284263961542487110215", "price": "0.066", "size": "0", "side": "SELL", "timestamp": "1768573623665", "received_at": "2026-01-16T14:27:03.712725"}}
{"event_type": "price_change", "event_ts": "2026-01-16T14:27:03.712725", "ingestion_ts": "2026-01-16T14:27:04.418606", "market_id": "0xc0e6b917320a47228fb96e3b5ae0e5c93773a5ae2662ae4e1f37807cfe47ce98", "raw": {"market": "0xc0e6b917320a47228fb96e3b5ae0e5c93773a5ae2662ae4e1f37807cfe47ce98", "asset_id": "81647294538046680798858716589766492074338758116170717123345952330712416337530", "price": "0.934", "size": "0", "side": "BUY", "timestamp": "1768573623665", "received_at": "2026-01-16T14:27:03.712725"}}
{"event_type": "price_change", "event_ts": "2026-01-16T14:27:03.811604", "ingestion_ts": "2026-01-16T14:27:04.418606", "market_id": "0xaf9d0e448129a9f657f851d49495ba4742055d80e0ef1166ba0ee81d4d594214", "raw": {"market": "0xaf9d0e448129a9f657f851d49495ba4742055d80e0ef1166ba0ee81d4d594214", "asset_id": "4153292802911610701832309484716814274802943278345248636922528170020319407796", "price": "0.987", "size": "0", "side": "SELL", "timestamp": "1768573623769", "received_at": "2026-01-16T14:27:03.811604"}}
{"event_type": "price_change", "event_ts": "2026-01-16T14:27:03.811604", "ingestion_ts": "2026-01-16T14:27:04.418606", "market_id": "0xaf9d0e448129a9f657f851d49495ba4742055d80e0ef1166ba0ee81d4d594214", "raw": {"market": "0xaf9d0e448129a9f657f851d49495ba4742055d80e0ef1166ba0ee81d4d594214", "asset_id": "101676997363687199724245607342877036148401850938023978421879460310389391082353", "price": "0.013", "size": "0", "side": "BUY", "timestamp": "1768573623769", "received_at": "2026-01-16T14:27:03.811604"}}
{"event_type": "price_change", "event_ts": "2026-01-16T14:27:04.020844", "ingestion_ts": "2026-01-16T14:27:04.418606", "market_id": "0x49686d26fb712515cd5e12c23f0a1c7e10214c7faa3cb0a730aabe0c33694082", "raw": {"market": "0x49686d26fb712515cd5e12c23f0a1c7e10214c7faa3cb0a730aabe0c33694082", "asset_id": "13244681086321087932946246027856416106585284024824496763706748621681543444582", "price": "0.853", "size": "45", "side": "BUY", "timestamp": "1768573623966", "received_at": "2026-01-16T14:27:04.020844"}}
{"event_type": "price_change", "event_ts": "2026-01-16T14:27:04.020844", "ingestion_ts": "2026-01-16T14:27:04.418606", "market_id": "0x49686d26fb712515cd5e12c23f0a1c7e10214c7faa3cb0a730aabe0c33694082", "raw": {"market": "0x49686d26fb712515cd5e12c23f0a1c7e10214c7faa3cb0a730aabe0c33694082", "asset_id": "30442780799048074404860985387051749017905070253466005720364298335239299761065", "price": "0.147", "size": "45", "side": "SELL", "timestamp": "1768573623966", "received_at": "2026-01-16T14:27:04.020844"}}
{"event_type": "price_change", "event_ts": "2026-01-16T14:27:04.035180", "ingestion_ts": "2026-01-16T14:27:04.418606", "market_id": "0xc0e6b917320a47228fb96e3b5ae0e5c93773a5ae2662ae4e1f37807cfe47ce98", "raw": {"market": "0xc0e6b917320a47228fb96e3b5ae0e5c93773a5ae2662ae4e1f37807cfe47ce98", "asset_id": "58656358377246279051017109359677190749228949103591068167284263961542487110215", "price": "0.076", "size": "60.3", "side": "SELL", "timestamp": "1768573623973", "received_at": "2026-01-16T14:27:04.035180"}}
{"event_type": "price_change", "event_ts": "2026-01-16T14:27:04.035180", "ingestion_ts": "2026-01-16T14:27:04.418606", "market_id": "0xc0e6b917320a47228fb96e3b5ae0e5c93773a5ae2662ae4e1f37807cfe47ce98", "raw": {"market": "0xc0e6b917320a47228fb96e3b5ae0e5c93773a5ae2662ae4e1f37807cfe47ce98", "asset_id": "81647294538046680798858716589766492074338758116170717123345952330712416337530", "price": "0.924", "size": "60.3", "side": "BUY", "timestamp": "1768573623973", "received_at": "2026-01-16T14:27:04.035180"}}
{"event_type": "price_change", "event_ts": "2026-01-16T14:27:04.386121", "ingestion_ts": "2026-01-16T14:27:04.418606", "market_id": "0x44f08744458b8896620cd3330bc5e1ea69df4199b02d4fc583b3fc96e5d314ce", "raw": {"market": "0x44f08744458b8896620cd3330bc5e1ea69df4199b02d4fc583b3fc96e5d314ce", "asset_id": "72327831507226612545928776794104143393438710920370371172884559893525100761096", "price": "0.967", "size": "75", "side": "BUY", "timestamp": "1768573624336", "received_at": "2026-01-16T14:27:04.386121"}}
{"event_type": "price_change", "event_ts": "2026-01-16T14:27:04.386121", "ingestion_ts": "2026-01-16T14:27:04.418606", "market_id": "0x44f08744458b8896620cd3330bc5e1ea69df4199b02d4fc583b3fc96e5d314ce", "raw": {"market": "0x44f08744458b8896620cd3330bc5e1ea69df4199b02d4fc583b3fc96e5d314ce", "asset_id": "49194009556504828848509244326501559253829462790583873936160989575507522044057", "price": "0.033", "size": "75", "side": "SELL", "timestamp": "1768573624336", "received_at": "2026-01-16T14:27:04.386121"}}
