{"event_type": "price_change", "event_ts": "2026-01-16T14:26:04.961788", "ingestion_ts": "2026-01-16T14:27:04.418606", "market_id": "0xaf9d0e448129a9f657f851d49495ba4742055d80e0ef1166ba0ee81d4d594214", "raw": {"market": "0xaf9d0e448129a9f657f851d49495ba4742055d80e0ef1166ba0ee81d4d594214", "asset_id": "4153292802911610701832309484716814274802943278345248636922528170020319407796", "price": "0.989", "size": "0", "side": "SELL", "timestamp": "1768573564923", "received_at": "2026-01-16T14:26:04.961788"}}
{"event_type": "price_change", "event_ts": "2026-01-16T14:26:04.961788", "ingestion_ts": "2026-01-16T14:27:04.418606", "market_id": "0xaf9d0e448129a9f657f851d49495ba4742055d80e0ef1166ba0ee81d4d594214", "raw": {"market": "0xaf9d0e448129a9f657f851d49495ba4742055d80e0ef1166ba0ee81d4d594214", "asset_id": "101676997363687199724245607342877036148401850938023978421879460310389391082353", "price": "0.011", "size": "0", "side": "BUY", "timestamp": "1768573564923", "received_at": "2026-01-16T14:26:04.961788"}}
{"event_type": "price_change", "event_ts": "2026-01-16T14:26:05.010464", "ingestion_ts": "2026-01-16T14:27:04.418606", "market_id": "0xaf9d0e448129a9f657f851d49495ba4742055d80e0ef1166ba0ee81d4d594214", "raw": {"market": "0xaf9d0e448129a9f657f851d49495ba4742055d80e0ef1166ba0ee81d4d594214", "asset_id": "4153292802911610701832309484716814274802943278345248636922528170020319407796", "price": "0.98", "size": "20.5", "side": "SELL", "timestamp": "1768573564966", "received_at": "2026-01-16T14:26:05.010464"}}
{"event_type": "price_change", "event_ts": "2026-01-16T14:26:05.010464", "ingestion_ts": "2026-01-16T14:27:04.418606", "market_id": "0xaf9d0e448129a9f657f851d49495ba4742055d80e0ef1166ba0ee81d4d594214", "raw": {"market": "0xaf9d0e448129a9f657f851d49495ba4742055d80e0ef1166ba0ee81d4d594214", "asset_id": "101676997363687199724245607342877036148401850938023978421879460310389391082353", "price": "0.02", "size": "20.5", "side": "BUY", "timestamp": "1768573564966", "received_at": "2026-01-16T14:26:05.010464"}}
{"event_type": "price_change", "event_ts": "2026-01-16T14:26:05.815237", "ingestion_ts": "2026-01-16T14:27:04.418606", "market_id": "0x9472be65457510b7fc3477b20ba90910e99d92eac8421a14bf4b7b7a08ef31dc", "raw": {"market": "0x9472be65457510b7fc3477b20ba90910e99d92eac8421a14bf4b7b7a08ef31dc", "asset_id": "43311793366960417907757893276427136943959788721376762326430771171648759300146", "price": "0.824", "size": "0", "side": "BUY", "timestamp": "1768573565776", "received_at": "2026-01-16T14:26:05.815237"}}
{"event_type": "price_change", "event_ts": "2026-01-16T14:26:05.815237", "ingestion_ts": "2026-01-16T14:27:04.418606", "market_id": "0x9472be65457510b7fc3477b20ba90910e99d92eac8421a14bf4b7b7a08ef31dc", "raw": {"market": "0x9472be65457510b7fc3477b20ba90910e99d92eac8421a14bf4b7b7a08ef31dc", "asset_id": "73414222381656326204771753454630063673548497164758947581648273905027617570612", "price": "0.176", "size": "0", "side": "SELL", "timestamp": "1768573565776", "received_at": "2026-01-16T14:26:05.815237"}}
{"event_type": "price_change", "event_ts": "2026-01-16T14:26:05.819115", "ingestion_ts": "2026-01-16T14:27:04.418606", "market_id": "0xc55db914f0fd1fee18997706712c0dfd8d0369cdbef93a9fef12bd001914ca77", "raw": {"market": "0xc55db914f0fd1fee18997706712c0dfd8d0369cdbef93a9fef12bd001914ca77", "asset_id": "114600293444080540179603459515770723592661967180480327891296353898330242622833", "price": "0.855", "size": "292", "side": "BUY", "timestamp": "1768573565776", "received_at": "2026-01-16T14:26:05.819115"}}
{"event_type": "price_change", "event_ts": "2026-01-16T14:26:05.819115", "ingestion_ts": "2026-01-16T14:27:04.418606", "market_id": "0xc55db914f0fd1fee18997706712c0dfd8d0369cdbef93a9fef12bd001914ca77", "raw": {"market": "0xc55db914f0fd1fee18997706712c0dfd8d0369cdbef93a9fef12bd001914ca77", "asset_id": "72354723612769247426741660426331235762851940382312402276325808095604519806766", "price": "0.145", "size": "292", "side": "SELL", "timestamp": "1768573565776", "received_at": "2026-01-16T14:26:05.819115"}}
{"event_type": "price_change", "event_ts": "2026-01-16T14:26:05.819156", "ingestion_ts": "2026-01-16T14:27:04.418606", "market_id": "0x49686d26fb712515cd5e12c23f0a1c7e10214c7faa3cb0a730aabe0c33694082", "raw": {"market": "0x49686d26fb712515cd5e12c23f0a1c7e10214c7faa3cb0a730aabe0c33694082", "asset_id": "30442780799048074404860985387051749017905070253466005720364298335239299761065", "price": "0.003", "size": "26.81", "side": "BUY", "timestamp": "1768573565776", "received_at": "2026-01-16T14:26:05.819156"}}
{"event_type": "price_change", "event_ts": "2026-01-16T14:26:05.819156", "ingestion_ts": "2026-01-16T14:27:04.418606", "market_id": "0x49686d26fb712515cd5e12c23f0a1c7e10214c7faa3cb0a730aabe0c33694082", "raw": {"market": "0x49686d26fb712515cd5e12c23f0a1c7e10214c7faa3cb0a730aabe0c33694082", "asset_id": "13244681086321087932946246027856416106585284024824496763706748621681543444582", "price": "0.997", "size": "26.81", "side": "SELL", "timestamp": "1768573565776", "received_at": "2026-01-16T14:26:05.819156"}}
{"event_type": "price_change", "event_ts": "2026-01-16T14:26:05.819171", "ingestion_ts": "2026-01-16T14:27:04.418606", "market_id": "0x50c669f178da4e5bbea7f1be25041fd278914712fa87a6a6f8e57d5923d88dee", "raw": {"market": "0x50c669f178da4e5bbea7f1be25041fd278914712fa87a6a6f8e57d5923d88dee", "asset_id": "74040420326294854165772767082819937451857852955603897473157746262672057685461", "price": "0.854", "size": "30", "side": "BUY", "timestamp": "1768573565776", "received_at": "2026-01-16T14:26:05.819171"}}
{"event_type": "price_change", "event_ts": "2026-01-16T14:26:05.819171", "ingestion_ts": "2026-01-16T14:27:04.418606", "market_id": "0x50c669f178da4e5bbea7f1be25041fd278914712fa87a6a6f8e57d5923d88dee", "raw": {"market": "0x50c669f178da4e5bbea7f1be25041fd278914712fa87a6a6f8e57d5923d88dee", "asset_id": "24682525479474221428144937281315825971983904267399062415430320764754931667953", "price": "0.146", "size": "30", "side": "SELL", "timestamp": "1768573565776", "received_at": "2026-01-16T14:26:05.819171"}}
{"event_type": "price_change", "event_ts": "2026-01-16T14:26:05.819525", "ingestion_ts": "2026-01-16T14:27:04.418606", "market_id": "0x44f08744458b8896620cd3330bc5e1ea69df4199b02d4fc583b3fc96e5d314ce", "raw": {"market": "0x44f08744458b8896620cd3330bc5e1ea69df4199b02d4fc583b3fc96e5d314ce", "asset_id": "72327831507226612545928776794104143393438710920370371172884559893525100761096", "price": "0.851", "size": "293", "side": "BUY", "timestamp": "1768573565776", "received_at": "2026-01-16T14:26:05.819525"}}
{"event_type": "price_change", "event_ts": "2026-01-16T14:26:05.819525", "ingestion_ts": "2026-01-16T14:27:04.418606", "market_id": "0x44f08744458b8896620cd3330bc5e1ea69df4199b02d4fc583b3fc96e5d314ce", "raw": {"market": "0x44f08744458b8896620cd3330bc5e1ea69df4199b02d4fc583b3fc96e5d314ce", "asset_id": "49194009556504828848509244326501559253829462790583873936160989575507522044057", "price": "0.149", "size": "293", "side": "SELL", "timestamp": "1768573565776", "received_at": "2026-01-16T14:26:05.819525"}}
{"event_type": "price_change", "event_ts": "2026-01-16T14:26:05.819557", "ingestion_ts": "2026-01-16T14:27:04.418606", "market_id": "0x49a20c7523c271099008f3ef9a31521263b24d637959852a391e6b4697b1a437", "raw": {"market": "0x49a20c7523c271099008f3ef9a31521263b24d637959852a391e6b4697b1a437", "asset_id": "55881023621710858558280545117465775643848233756850602339827152783696837905531", "price": "0.853", "size": "527", "side": "BUY", "timestamp": "1768573565776", "received_at": "2026-01-16T14:26:05.819557"}}
{"event_type": "price_change", "event_ts": "2026-01-16T14:26:05.819557", "ingestion_ts": "2026-01-16T14:27:04.418606", "market_id": "0x49a20c7523c271099008f3ef9a31521263b24d637959852a391e6b4697b1a437", "raw": {"market": "0x49a20c7523c271099008f3ef9a31521263b24d637959852a391e6b4697b1a437", "asset_id": "13018971792603393862521629014128024641178044618205296260525674415067194037856", "price": "0.147", "size": "527", "side": "SELL", "timestamp": "1768573565776", "received_at": "2026-01-16T14:26:05.819557"}}
{"event_type": "price_change", "event_ts": "2026-01-16T14:26:05.862907", "ingestion_ts": "2026-01-16T14:27:04.418606", "market_id": "0x49a20c7523c271099008f3ef9a31521263b24d637959852a391e6b4697b1a437", "raw": {"market": "0x49a20c7523c271099008f3ef9a31521263b24d637959852a391e6b4697b1a437", "asset_id": "55881023621710858558280545117465775643848233756850602339827152783696837905531", "price": "0.854", "size": "10", "side": "BUY", "timestamp": "1768573565810", "received_at": "2026-01-16T14:26:05.862907"}}
{"event_type": "price_change", "event_ts": "2026-01-16T14:26:05.862907", "ingestion_ts": "2026-01-16T14:27:04.418606", "market_id": "0x49a20c7523c271099008f3ef9a31521263b24d637959852a391e6b4697b1a437", "raw": {"market": "0x49a20c7523c271099008f3ef9a31521263b24d637959852a391e6b4697b1a437", "asset_id": "13018971792603393862521629014128024641178044618205296260525674415067194037856", "price": "0.146", "size": "10", "side": "SELL", "timestamp": "1768573565810", "received_at": "2026-01-16T14:26:05.862907"}}
{"event_type": "price_change", "event_ts": "2026-01-16T14:26:05.862949", "ingestion_ts": "2026-01-16T14:27:04.418606", "market_id": "0x49686d26fb712515cd5e12c23f0a1c7e10214c7faa3cb0a730aabe0c33694082", "raw": {"market": "0x49686d26fb712515cd5e12c23f0a1c7e10214c7faa3cb0a730aabe0c33694082", "asset_id": "30442780799048074404860985387051749017905070253466005720364298335239299761065", "price": "0.004", "size": "10", "side": "BUY", "timestamp": "1768573565810", "received_at": "2026-01-16T14:26:05.862949"}}
{"event_type": "price_change", "event_ts": "2026-01-16T14:26:05.862949", "ingestion_ts": "2026-01-16T14:27:04.418606", "market_id": "0x49686d26fb712515cd5e12c23f0a1c7e10214c7faa3cb0a730aabe0c33694082", "raw": {"market": "0x49686d26fb712515cd5e12c23f0a1c7e10214c7faa3cb0a730aabe0c33694082", "asset_id": "13244681086321087932946246027856416106585284024824496763706748621681543444582", "price": "0.996", "size": "10", "side": "SELL", "timestamp": "1768573565810", "received_at": "2026-01-16T14:26:05.862949"}}
{"event_type": "price_change", "event_ts": "2026-01-16T14:26:05.862963", "ingestion_ts": "2026-01-16T14:27:04.418606", "market_id": "0x9472be65457510b7fc3477b20ba90910e99d92eac8421a14bf4b7b7a08ef31dc", "raw": {"market": "0x9472be65457510b7fc3477b20ba90910e99d92eac8421a14bf4b7b7a08ef31dc", "asset_id": "43311793366960417907757893276427136943959788721376762326430771171648759300146", "price": "0.855", "size": "302", "side": "BUY", "timestamp": "1768573565810", "received_at": "2026-01-16T14:26:05.862963"}}
{"event_type": "price_change", "event_ts": "2026-01-16T14:26:05.862963", "ingestion_ts": "2026-01-16T14:27:04.418606", "market_id": "0x9472be65457510b7fc3477b20ba90910e99d92eac8421a14bf4b7b7a08ef31dc", "raw": {"market": "0x9472be65457510b7fc3477b20ba90910e99d92eac8421a14bf4b7b7a08ef31dc", "asset_id": "73414222381656326204771753454630063673548497164758947581648273905027617570612", "price": "0.145", "size": "302", "side": "SELL", "timestamp": "1768573565810", "received_at": "2026-01-16T14:26:05.862963"}}
{"event_type": "price_change", "event_ts": "2026-01-16T14:26:05.862976", "ingestion_ts": "2026-01-16T14:27:04.418606", "market_id": "0xc55db914f0fd1fee18997706712c0dfd8d0369cdbef93a9fef12bd001914ca77", "raw": {"market": "0xc55db914f0fd1fee18997706712c0dfd8d0369cdbef93a9fef12bd001914ca77", "asset_id": "114600293444080540179603459515770723592661967180480327891296353898330242622833", "price": "0.856", "size": "10", "side": "BUY", "timestamp": "1768573565810", "received_at": "2026-01-16T14:26:05.862976"}}
{"event_type": "price_change", "event_ts": "2026-01-16T14:26:05.862976", "ingestion_ts": "2026-01-16T14:27:04.418606", "market_id": "0xc55db914f0fd1fee18997706712c0dfd8d0369cdbef93a9fef12bd001914ca77", "raw": {"market": "0xc55db914f0fd1fee18997706712c0dfd8d0369cdbef93a9fef12bd001914ca77", "asset_id": "72354723612769247426741660426331235762851940382312402276325808095604519806766", "price": "0.144", "size": "10", "side": "SELL", "timestamp": "1768573565810", "received_at": "2026-01-16T14:26:05.862976"}}
{"event_type": "price_change", "event_ts": "2026-01-16T14:26:05.862987", "ingestion_ts": "2026-01-16T14:27:04.418606", "market_id": "0x44f08744458b8896620cd3330bc5e1ea69df4199b02d4fc583b3fc96e5d314ce", "raw": {"market": "0x44f08744458b8896620cd3330bc5e1ea69df4199b02d4fc583b3fc96e5d314ce", "asset_id": "72327831507226612545928776794104143393438710920370371172884559893525100761096", "price": "0.852", "size": "10", "side": "BUY", "timestamp": "1768573565810", "received_at": "2026-01-16T14:26:05.862987"}}
{"event_type": "price_change", "event_ts": "2026-01-16T14:26:05.862987", "ingestion_ts": "2026-01-16T14:27:04.418606", "market_id": "0x44f08744458b8896620cd3330bc5e1ea69df4199b02d4fc583b3fc96e5d314ce", "raw": {"market": "0x44f08744458b8896620cd3330bc5e1ea69df4199b02d4fc583b3fc96e5d314ce", "asset_id": "49194009556504828848509244326501559253829462790583873936160989575507522044057", "price": "0.148", "size": "10", "side": "SELL", "timestamp": "1768573565810", "received_at": "2026-01-16T14:26:05.862987"}}
{"event_type": "price_change", "event_ts": "2026-01-16T14:26:05.862998", "ingestion_ts": "2026-01-16T14:27:04.418606", "market_id": "0x50c669f178da4e5bbea7f1be25041fd278914712fa87a6a6f8e57d5923d88dee", "raw": {"market": "0x50c669f178da4e5bbea7f1be25041fd278914712fa87a6a6f8e57d5923d88dee", "asset_id": "74040420326294854165772767082819937451857852955603897473157746262672057685461", "price": "0.855", "size": "10", "side": "BUY", "timestamp": "1768573565810", "received_at": "2026-01-16T14:26:05.862998"}}
{"event_type": "price_change", "event_ts": "2026-01-16T14:26:05.862998", "ingestion_ts": "2026-01-16T14:27:04.418606", "market_id": "0x50c669f178da4e5bbea7f1be25041fd278914712fa87a6a6f8e57d5923d88dee", "raw": {"market": "0x50c669f178da4e5bbea7f1be25041fd278914712fa87a6a6f8e57d5923d88dee", "asset_id": "24682525479474221428144937281315825971983904267399062415430320764754931667953", "price": "0.145", "size": "10", "side": "SELL", "timestamp": "1768573565810", "received_at": "2026-01-16T14:26:05.862998"}}
{"event_type": "price_change", "event_ts": "2026-01-16T14:26:06.107728", "ingestion_ts": "2026-01-16T14:27:04.418606", "market_id": "0xc0e6b917320a47228fb96e3b5ae0e5c93773a5ae2662ae4e1f37807cfe47ce98", "raw": {"market": "0xc0e6b917320a47228fb96e3b5ae0e5c93773a5ae2662ae4e1f37807cfe47ce98", "asset_id": "58656358377246279051017109359677190749228949103591068167284263961542487110215", "price": "0.002", "size": "3273.26", "side": "BUY", "timestamp": "1768573566070", "received_at": "2026-01-16T14:26:06.107728"}}
{"event_type": "price_change", "event_ts": "2026-01-16T14:26:06.107728", "ingestion_ts": "2026-01-16T14:27:04.418606", "market_id": "0xc0e6b917320a47228fb96e3b5ae0e5c93773a5ae2662ae4e1f37807cfe47ce98", "raw": {"market": "0xc0e6b917320a47228fb96e3b5ae0e5c93773a5ae2662ae4e1f37807cfe47ce98", "asset_id": "81647294538046680798858716589766492074338758116170717123345952330712416337530", "price": "0.998", "size": "3273.26", "side": "SELL", "timestamp": "1768573566070", "received_at": "2026-01-16T14:26:06.107728"}}
{"event_type": "price_change", "event_ts": "2026-01-16T14:26:07.537781", "ingestion_ts": "2026-01-16T14:27:04.418606", "market_id": "0xaf9d0e448129a9f657f851d49495ba4742055d80e0ef1166ba0ee81d4d594214", "raw": {"market": "0xaf9d0e448129a9f657f851d49495ba4742055d80e0ef1166ba0ee81d4d594214", "asset_id": "4153292802911610701832309484716814274802943278345248636922528170020319407796", "price": "0.981", "size": "0", "side": "SELL", "timestamp": "1768573567493", "received_at": "2026-01-16T14:26:07.537781"}}
{"event_type": "price_change", "event_ts": "2026-01-16T14:26:07.537781", "ingestion_ts": "2026-01-16T14:27:04.418606", "market_id": "0xaf9d0e448129a9f657f851d49495ba4742055d80e0ef1166ba0ee81d4d594214", "raw": {"market": "0xaf9d0e448129a9f657f851d49495ba4742055d80e0ef1166ba0ee81d4d594214", "asset_id": "101676997363687199724245607342877036148401850938023978421879460310389391082353", "price": "0.019", "size": "0", "side": "BUY", "timestamp": "1768573567493", "received_at": "2026-01-16T14:26:07.537781"}}
{"event_type": "price_change", "event_ts": "2026-01-16T14:26:07.870065", "ingestion_ts": "2026-01-16T14:27:04.418606", "market_id": "0xc0e6b917320a47228fb96e3b5ae0e5c93773a5ae2662ae4e1f37807cfe47ce98", "raw": {"market": "0xc0e6b917320a47228fb96e3b5ae0e5c93773a5ae2662ae4e1f37807cfe47ce98", "asset_id": "58656358377246279051017109359677190749228949103591068167284263961542487110215", "price": "0.002", "size": "3266.03", "side": "BUY", "timestamp": "1768573567787", "received_at": "2026-01-16T14:26:07.870065"}}
{"event_type": "price_change", "event_ts": "2026-01-16T14:26:07.870065", "ingestion_ts": "2026-01-16T14:27:04.418606", "market_id": "0xc0e6b917320a47228fb96e3b5ae0e5c93773a5ae2662ae4e1f37807cfe47ce98", "raw": {"market": "0xc0e6b917320a47228fb96e3b5ae0e5c93773a5ae2662ae4e1f37807cfe47ce98", "asset_id": "81647294538046680798858716589766492074338758116170717123345952330712416337530", "price": "0.998", "size": "3266.03", "side": "SELL", "timestamp": "1768573567787", "received_at": "2026-01-16T14:26:07.870065"}}
{"event_type": "price_change", "event_ts": "2026-01-16T14:26:07.870289", "ingestion_ts": "2026-01-16T14:27:04.418606", "market_id": "0xaf9d0e448129a9f657f851d49495ba4742055d80e0ef1166ba0ee81d4d594214", "raw": {"market": "0xaf9d0e448129a9f657f851d49495ba4742055d80e0ef1166ba0ee81d4d594214", "asset_id": "4153292802911610701832309484716814274802943278345248636922528170020319407796", "price": "0.979", "size": "140.01", "side": "SELL", "timestamp": "1768573567827", "received_at": "2026-01-16T14:26:07.870289"}}
{"event_type": "price_change", "event_ts": "2026-01-16T14:26:07.870289", "ingestion_ts": "2026-01-16T14:27:04.418606", "market_id": "0xaf9d0e448129a9f657f851d49495ba4742055d80e0ef1166ba0ee81d4d594214", "raw": {"market": "0xaf9d0e448129a9f657f851d49495ba4742055d80e0ef1166ba0ee81d4d594214", "asset_id": "101676997363687199724245607342877036148401850938023978421879460310389391082353", "price": "0.021", "size": "140.01", "side": "BUY", "timestamp": "1768573567827", "received_at": "2026-01-16T14:26:07.870289"}}
{"event_type": "price_change", "event_ts": "2026-01-16T14:26:08.076684", "ingestion_ts": "2026-01-16T14:27:04.418606", "market_id": "0xc0e6b917320a47228fb96e3b5ae0e5c93773a5ae2662ae4e1f37807cfe47ce98", "raw": {"market": "0xc0e6b917320a47228fb96e3b5ae0e5c93773a5ae2662ae4e1f37807cfe47ce98", "asset_id": "58656358377246279051017109359677190749228949103591068167284263961542487110215", "price": "0.002", "size": "3273.26", "side": "BUY", "timestamp": "1768573568032", "received_at": "2026-01-16T14:26:08.076684"}}
{"event_type": "price_change", "event_ts": "2026-01-16T14:26:08.076684", "ingestion_ts": "2026-01-16T14:27:04.418606", "market_id": "0xc0e6b917320a47228fb96e3b5ae0e5c93773a5ae2662ae4e1f37807cfe47ce98", "raw": {"market": "0xc0e6b917320a47228fb96e3b5ae0e5c93773a5ae2662ae4e1f37807cfe47ce98", "asset_id": "81647294538046680798858716589766492074338758116170717123345952330712416337530", "price": "0.998", "size": "3273.26", "side": "SELL", "timestamp": "1768573568032", "received_at": "2026-01-16T14:26:08.076684"}}
{"event_type": "price_change", "event_ts": "2026-01-16T14:26:08.076728", "ingestion_ts": "2026-01-16T14:27:04.418606", "market_id": "0xc0e6b917320a47228fb96e3b5ae0e5c93773a5ae2662ae4e1f37807cfe47ce98", "raw": {"market": "0xc0e6b917320a47228fb96e3b5ae0e5c93773a5ae2662ae4e1f37807cfe47ce98", "asset_id": "58656358377246279051017109359677190749228949103591068167284263961542487110215", "price": "0.002", "size": "3280.49", "side": "BUY", "timestamp": "1768573568033", "received_at": "2026-01-16T14:26:08.076728"}}
{"event_type": "price_change", "event_ts": "2026-01-16T14:26:08.076728", "ingestion_ts": "2026-01-16T14:27:04.418606", "market_id": "0xc0e6b917320a47228fb96e3b5ae0e5c93773a5ae2662ae4e1f37807cfe47ce98", "raw": {"market": "0xc0e6b917320a47228fb96e3b5ae0e5c93773a5ae2662ae4e1f37807cfe47ce98", "asset_id": "81647294538046680798858716589766492074338758116170717123345952330712416337530", "price": "0.998", "size": "3280.49", "side": "SELL", "timestamp": "1768573568033", "received_at": "2026-01-16T14:26:08.076728"}}
{"event_type": "price_change", "event_ts": "2026-01-16T14:26:08.733070", "ingestion_ts": "2026-01-16T14:27:04.418606", "market_id": "0xc55db914f0fd1fee18997706712c0dfd8d0369cdbef93a9fef12bd001914ca77", "raw": {"market": "0xc55db914f0fd1fee18997706712c0dfd8d0369cdbef93a9fef12bd001914ca77", "asset_id": "114600293444080540179603459515770723592661967180480327891296353898330242622833", "price": "0.856", "size": "0", "side": "BUY", "timestamp": "1768573568681", "received_at": "2026-01-16T14:26:08.733070"}}
{"event_type": "price_change", "event_ts": "2026-01-16T14:26:08.733070", "ingestion_ts": "2026-01-16T14:27:04.418606", "market_id": "0xc55db914f0fd1fee18997706712c0dfd8d0369cdbef93a9fef12bd001914ca77", "raw": {"market": "0xc55db914f0fd1fee18997706712c0dfd8d0369cdbef93a9fef12bd001914ca77", "asset_id": "72354723612769247426741660426331235762851940382312402276325808095604519806766", "price": "0.144", "size": "0", "side": "SELL", "timestamp": "1768573568681", "received_at": "2026-01-16T14:26:08.733070"}}
{"event_type": "price_change", "event_ts": "2026-01-16T14:26:08.733519", "ingestion_ts": "2026-01-16T14:27:04.418606", "market_id": "0x9472be65457510b7fc3477b20ba90910e99d92eac8421a14bf4b7b7a08ef31dc", "raw": {"market": "0x9472be65457510b7fc3477b20ba90910e99d92eac8421a14bf4b7b7a08ef31dc", "asset_id": "43311793366960417907757893276427136943959788721376762326430771171648759300146", "price": "0.855", "size": "292", "side": "BUY", "timestamp": "1768573568681", "received_at": "2026-01-16T14:26:08.733519"}}
{"event_type": "price_change", "event_ts": "2026-01-16T14:26:08.733519", "ingestion_ts": "2026-01-16T14:27:04.418606", "market_id": "0x9472be65457510b7fc3477b20ba90910e99d92eac8421a14bf4b7b7a08ef31dc", "raw": {"market": "0x9472be65457510b7fc3477b20ba90910e99d92eac8421a14bf4b7b7a08ef31dc", "asset_id": "73414222381656326204771753454630063673548497164758947581648273905027617570612", "price": "0.145", "size": "292", "side": "SELL", "timestamp": "1768573568681", "received_at": "2026-01-16T14:26:08.733519"}}
{"event_type": "price_change", "event_ts": "2026-01-16T14:26:08.733583", "ingestion_ts": "2026-01-16T14:27:04.418606", "market_id": "0x49686d26fb712515cd5e12c23f0a1c7e10214c7faa3cb0a730aabe0c33694082", "raw": {"market": "0x49686d26fb712515cd5e12c23f0a1c7e10214c7faa3cb0a730aabe0c33694082", "asset_id": "30442780799048074404860985387051749017905070253466005720364298335239299761065", "price": "0.004", "size": "0", "side": "BUY", "timestamp": "1768573568681", "received_at": "2026-01-16T14:26:08.733583"}}
{"event_type": "price_change", "event_ts": "2026-01-16T14:26:08.733583", "ingestion_ts": "2026-01-16T14:27:04.418606", "market_id": "0x49686d26fb712515cd5e12c23f0a1c7e10214c7faa3cb0a730aabe0c33694082", "raw": {"market": "0x49686d26fb712515cd5e12c23f0a1c7e10214c7faa3cb0a730aabe0c33694082", "asset_id": "13244681086321087932946246027856416106585284024824496763706748621681543444582", "price": "0.996", "size": "0", "side": "SELL", "timestamp": "1768573568681", "received_at": "2026-01-16T14:26:08.733583"}}
{"event_type": "price_change", "event_ts": "2026-01-16T14:26:08.733611", "ingestion_ts": "2026-01-16T14:27:04.418606", "market_id": "0x44f08744458b8896620cd3330bc5e1ea69df4199b02d4fc583b3fc96e5d314ce", "raw": {"market": "0x44f08744458b8896620cd3330bc5e1ea69df4199b02d4fc583b3fc96e5d314ce", "asset_id": "72327831507226612545928776794104143393438710920370371172884559893525100761096", "price": "0.852", "size": "0", "side": "BUY", "timestamp": "1768573568681", "received_at": "2026-01-16T14:26:08.733611"}}
{"event_type": "price_change", "event_ts": "2026-01-16T14:26:08.733611", "ingestion_ts": "2026-01-16T14:27:04.418606", "market_id": "0x44f08744458b8896620cd3330bc5e1ea69df4199b02d4fc583b3fc96e5d314ce", "raw": {"market": "0x44f08744458b8896620cd3330bc5e1ea69df4199b02d4fc583b3fc96e5d314ce", "asset_id": "49194009556504828848509244326501559253829462790583873936160989575507522044057", "price": "0.148", "size": "0", "side": "SELL", "timestamp": "1768573568681", "received_at": "2026-01-16T14:26:08.733611"}}
{"event_type": "price_change", "event_ts": "2026-01-16T14:26:08.739601", "ingestion_ts": "2026-01-16T14:27:04.418606", "market_id": "0xaf9d0e448129a9f657f851d49495ba4742055d80e0ef1166ba0ee81d4d594214", "raw": {"market": "0xaf9d0e448129a9f657f851d49495ba4742055d80e0ef1166ba0ee81d4d594214", "asset_id": "4153292802911610701832309484716814274802943278345248636922528170020319407796", "price": "0.98", "size": "0", "side": "SELL", "timestamp": "1768573568702", "received_at": "2026-01-16T14:26:08.739601"}}
{"event_type": "price_change", "event_ts": "2026-01-16T14:26:08.739601", "ingestion_ts": "2026-01-16T14:27:04.418606", "market_id": "0xaf9d0e448129a9f657f851d49495ba4742055d80e0ef1166ba0ee81d4d594214", "raw": {"market": "0xaf9d0e448129a9f657f851d49495ba4742055d80e0ef1166ba0ee81d4d594214", "asset_id": "101676997363687199724245607342877036148401850938023978421879460310389391082353", "price": "0.02", "size": "0", "side": "BUY", "timestamp": "1768573568702", "received_at": "2026-01-16T14:26:08.739601"}}
{"event_type": "price_change", "event_ts": "2026-01-16T14:26:08.753864", "ingestion_ts": "2026-01-16T14:27:04.418606", "market_id": "0x44f08744458b8896620cd3330bc5e1ea69df4199b02d4fc583b3fc96e5d314ce", "raw": {"market": "0x44f08744458b8896620cd3330bc5e1ea69df4199b02d4fc583b3fc96e5d314ce", "asset_id": "72327831507226612545928776794104143393438710920370371172884559893525100761096", "price": "0.853", "size": "244", "side": "BUY", "timestamp": "1768573568714", "received_at": "2026-01-16T14:26:08.753864"}}
{"event_type": "price_change", "event_ts": "2026-01-16T14:26:08.753864", "ingestion_ts": "2026-01-16T14:27:04.418606", "market_id": "0x44f08744458b8896620cd3330bc5e1ea69df4199b02d4fc583b3fc96e5d314ce", "raw": {"market": "0x44f08744458b8896620cd3330bc5e1ea69df4199b02d4fc583b3fc96e5d314ce", "asset_id": "49194009556504828848509244326501559253829462790583873936160989575507522044057", "price": "0.147", "size": "244", "side": "SELL", "timestamp": "1768573568714", "received_at": "2026-01-16T14:26:08.753864"}}
{"event_type": "price_change", "event_ts": "2026-01-16T14:26:08.756511", "ingestion_ts": "2026-01-16T14:27:04.418606", "market_id": "0xc55db914f0fd1fee18997706712c0dfd8d0369cdbef93a9fef12bd001914ca77", "raw": {"market": "0xc55db914f0fd1fee18997706712c0dfd8d0369cdbef93a9fef12bd001914ca77", "asset_id": "114600293444080540179603459515770723592661967180480327891296353898330242622833", "price": "0.857", "size": "243", "side": "BUY", "timestamp": "1768573568714", "received_at": "2026-01-16T14:26:08.756511"}}
{"event_type": "price_change", "event_ts": "2026-01-16T14:26:08.756511", "ingestion_ts": "2026-01-16T14:27:04.418606", "market_id": "0xc55db914f0fd1fee18997706712c0dfd8d0369cdbef93a9fef12bd001914ca77", "raw": {"market": "0xc55db914f0fd1fee18997706712c0dfd8d0369cdbef93a9fef12bd001914ca77", "asset_id": "72354723612769247426741660426331235762851940382312402276325808095604519806766", "price": "0.143", "size": "243", "side": "SELL", "timestamp": "1768573568714", "received_at": "2026-01-16T14:26:08.756511"}}
{"event_type": "price_change", "event_ts": "2026-01-16T14:26:08.756557", "ingestion_ts": "2026-01-16T14:27:04.418606", "market_id": "0x9472be65457510b7fc3477b20ba90910e99d92eac8421a14bf4b7b7a08ef31dc", "raw": {"market": "0x9472be65457510b7fc3477b20ba90910e99d92eac8421a14bf4b7b7a08ef31dc", "asset_id": "43311793366960417907757893276427136943959788721376762326430771171648759300146", "price": "0.856", "size": "10", "side": "BUY", "timestamp": "1768573568714", "received_at": "2026-01-16T14:26:08.756557"}}
{"event_type": "price_change", "event_ts": "2026-01-16T14:26:08.756557", "ingestion_ts": "2026-01-16T14:27:04.418606", "market_id": "0x9472be65457510b7fc3477b20ba90910e99d92eac8421a14bf4b7b7a08ef31dc", "raw": {"market": "0x9472be65457510b7fc3477b20ba90910e99d92eac8421a14bf4b7b7a08ef31dc", "asset_id": "73414222381656326204771753454630063673548497164758947581648273905027617570612", "price": "0.144", "size": "10", "side": "SELL", "timestamp": "1768573568714", "received_at": "2026-01-16T14:26:08.756557"}}
{"event_type": "price_change", "event_ts": "2026-01-16T14:26:08.756670", "ingestion_ts": "2026-01-16T14:27:04.418606", "market_id": "0x49686d26fb712515cd5e12c23f0a1c7e10214c7faa3cb0a730aabe0c33694082", "raw": {"market": "0x49686d26fb712515cd5e12c23f0a1c7e10214c7faa3cb0a730aabe0c33694082", "asset_id": "30442780799048074404860985387051749017905070253466005720364298335239299761065", "price": "0.005", "size": "109.51", "side": "BUY", "timestamp": "1768573568714", "received_at": "2026-01-16T14:26:08.756670"}}
{"event_type": "price_change", "event_ts": "2026-01-16T14:26:08.756670", "ingestion_ts": "2026-01-16T14:27:04.418606", "market_id": "0x49686d26fb712515cd5e12c23f0a1c7e10214c7faa3cb0a730aabe0c33694082", "raw": {"market": "0x49686d26fb712515cd5e12c23f0a1c7e10214c7faa3cb0a730aabe0c33694082", "asset_id": "13244681086321087932946246027856416106585284024824496763706748621681543444582", "price": "0.995", "size": "109.51", "side": "SELL", "timestamp": "1768573568714", "received_at": "2026-01-16T14:26:08.756670"}}
{"event_type": "price_change", "event_ts": "2026-01-16T14:26:09.017758", "ingestion_ts": "2026-01-16T14:27:04.418606", "market_id": "0xaf9d0e448129a9f657f851d49495ba4742055d80e0ef1166ba0ee81d4d594214", "raw": {"market": "0xaf9d0e448129a9f657f851d49495ba4742055d80e0ef1166ba0ee81d4d594214", "asset_id": "4153292802911610701832309484716814274802943278345248636922528170020319407796", "price": "0.978", "size": "20.5", "side": "SELL", "timestamp": "1768573568935", "received_at": "2026-01-16T14:26:09.017758"}}
{"event_type": "price_change", "event_ts": "2026-01-16T14:26:09.017758", "ingestion_ts": "2026-01-16T14:27:04.418606", "market_id": "0xaf9d0e448129a9f657f851d49495ba4742055d80e0ef1166ba0ee81d4d594214", "raw": {"market": "0xaf9d0e448129a9f657f851d49495ba4742055d80e0ef1166ba0ee81d4d594214", "asset_id": "101676997363687199724245607342877036148401850938023978421879460310389391082353", "price": "0.022", "size": "20.5", "side": "BUY", "timestamp": "1768573568935", "received_at": "2026-01-16T14:26:09.017758"}}
{"event_type": "price_change", "event_ts": "2026-01-16T14:26:09.677276", "ingestion_ts": "2026-01-16T14:27:04.418606", "market_id": "0x49686d26fb712515cd5e12c23f0a1c7e10214c7faa3cb0a730aabe0c33694082", "raw": {"market": "0x49686d26fb712515cd5e12c23f0a1c7e10214c7faa3cb0a730aabe0c33694082", "asset_id": "13244681086321087932946246027856416106585284024824496763706748621681543444582", "price": "0.853", "size": "50.86", "side": "BUY", "timestamp": "1768573569624", "received_at": "2026-01-16T14:26:09.677276"}}
{"event_type": "price_change", "event_ts": "2026-01-16T14:26:09.677276", "ingestion_ts": "2026-01-16T14:27:04.418606", "market_id": "0x49686d26fb712515cd5e12c23f0a1c7e10214c7faa3cb0a730aabe0c33694082", "raw": {"market": "0x49686d26fb712515cd5e12c23f0a1c7e10214c7faa3cb0a730aabe0c33694082", "asset_id": "30442780799048074404860985387051749017905070253466005720364298335239299761065", "price": "0.147", "size": "50.86", "side": "SELL", "timestamp": "1768573569624", "received_at": "2026-01-16T14:26:09.677276"}}
{"event_type": "price_change", "event_ts": "2026-01-16T14:26:10.185539", "ingestion_ts": "2026-01-16T14:27:04.418606", "market_id": "0x49686d26fb712515cd5e12c23f0a1c7e10214c7faa3cb0a730aabe0c33694082", "raw": {"market": "0x49686d26fb712515cd5e12c23f0a1c7e10214c7faa3cb0a730aabe0c33694082", "asset_id": "30442780799048074404860985387051749017905070253466005720364298335239299761065", "price": "0.148", "size": "0", "side": "SELL", "timestamp": "1768573570117", "received_at": "2026-01-16T14:26:10.185539"}}
{"event_type": "price_change", "event_ts": "2026-01-16T14:26:10.185539", "ingestion_ts": "2026-01-16T14:27:04.418606", "market_id": "0x49686d26fb712515cd5e12c23f0a1c7e10214c7faa3cb0a730aabe0c33694082", "raw": {"market": "0x49686d26fb712515cd5e12c23f0a1c7e10214c7faa3cb0a730aabe0c33694082", "asset_id": "13244681086321087932946246027856416106585284024824496763706748621681543444582", "price": "0.852", "size": "0", "side": "BUY", "timestamp": "1768573570117", "received_at": "2026-01-16T14:26:10.185539"}}
{"event_type": "price_change", "event_ts": "2026-01-16T14:26:10.269853", "ingestion_ts": "2026-01-16T14:27:04.418606", "market_id": "0x49686d26fb712515cd5e12c23f0a1c7e10214c7faa3cb0a730aabe0c33694082", "raw": {"market": "0x49686d26fb712515cd5e12c23f0a1c7e10214c7faa3cb0a730aabe0c33694082", "asset_id": "30442780799048074404860985387051749017905070253466005720364298335239299761065", "price": "0.146", "size": "17.5", "side": "SELL", "timestamp": "1768573570175", "received_at": "2026-01-16T14:26:10.269853"}}
{"event_type": "price_change", "event_ts": "2026-01-16T14:26:10.269853", "ingestion_ts": "2026-01-16T14:27:04.418606", "market_id": "0x49686d26fb712515cd5e12c23f0a1c7e10214c7faa3cb0a730aabe0c33694082", "raw": {"market": "0x49686d26fb712515cd5e12c23f0a1c7e10214c7faa3cb0a730aabe0c33694082", "asset_id": "13244681086321087932946246027856416106585284024824496763706748621681543444582", "price": "0.854", "size": "17.5", "side": "BUY", "timestamp": "1768573570175", "received_at": "2026-01-16T14:26:10.269853"}}
{"event_type": "price_change", "event_ts": "2026-01-16T14:26:10.327691", "ingestion_ts": "2026-01-16T14:27:04.418606", "market_id": "0x49686d26fb712515cd5e12c23f0a1c7e10214c7faa3cb0a730aabe0c33694082", "raw": {"market": "0x49686d26fb712515cd5e12c23f0a1c7e10214c7faa3cb0a730aabe0c33694082", "asset_id": "13244681086321087932946246027856416106585284024824496763706748621681543444582", "price": "0.911", "size": "14.98", "side": "SELL", "timestamp": "1768573570208", "received_at": "2026-01-16T14:26:10.327691"}}
{"event_type": "price_change", "event_ts": "2026-01-16T14:26:10.327691", "ingestion_ts": "2026-01-16T14:27:04.418606", "market_id": "0x49686d26fb712515cd5e12c23f0a1c7e10214c7faa3cb0a730aabe0c33694082", "raw": {"market": "0x49686d26fb712515cd5e12c23f0a1c7e10214c7faa3cb0a730aabe0c33694082", "asset_id": "30442780799048074404860985387051749017905070253466005720364298335239299761065", "price": "0.089", "size": "14.98", "side": "BUY", "timestamp": "1768573570208", "received_at": "2026-01-16T14:26:10.327691"}}
{"event_type": "price_change", "event_ts": "2026-01-16T14:26:11.401418", "ingestion_ts": "2026-01-16T14:27:04.418606", "market_id": "0x50c669f178da4e5bbea7f1be25041fd278914712fa87a6a6f8e57d5923d88dee", "raw": {"market": "0x50c669f178da4e5bbea7f1be25041fd278914712fa87a6a6f8e57d5923d88dee", "asset_id": "74040420326294854165772767082819937451857852955603897473157746262672057685461", "price": "0.855", "size": "0", "side": "BUY", "timestamp": "1768573571303", "received_at": "2026-01-16T14:26:11.401418"}}
{"event_type": "price_change", "event_ts": "2026-01-16T14:26:11.401418", "ingestion_ts": "2026-01-16T14:27:04.418606", "market_id": "0x50c669f178da4e5bbea7f1be25041fd278914712fa87a6a6f8e57d5923d88dee", "raw": {"market": "0x50c669f178da4e5bbea7f1be25041fd278914712fa87a6a6f8e57d5923d88dee", "asset_id": "24682525479474221428144937281315825971983904267399062415430320764754931667953", "price": "0.145", "size": "0", "side": "SELL", "timestamp": "1768573571303", "received_at": "2026-01-16T14:26:11.401418"}}
{"event_type": "price_change", "event_ts": "2026-01-16T14:26:11.401495", "ingestion_ts": "2026-01-16T14:27:04.418606", "market_id": "0x49a20c7523c271099008f3ef9a31521263b24d637959852a391e6b4697b1a437", "raw": {"market": "0x49a20c7523c271099008f3ef9a31521263b24d637959852a391e6b4697b1a437", "asset_id": "55881023621710858558280545117465775643848233756850602339827152783696837905531", "price": "0.854", "size": "0", "side": "BUY", "timestamp": "1768573571303", "received_at": "2026-01-16T14:26:11.401495"}}
{"event_type": "price_change", "event_ts": "2026-01-16T14:26:11.401495", "ingestion_ts": "2026-01-16T14:27:04.418606", "market_id": "0x49a20c7523c271099008f3ef9a31521263b24d637959852a391e6b4697b1a437", "raw": {"market": "0x49a20c7523c271099008f3ef9a31521263b24d637959852a391e6b4697b1a437", "asset_id": "13018971792603393862521629014128024641178044618205296260525674415067194037856", "price": "0.146", "size": "0", "side": "SELL", "timestamp": "1768573571303", "received_at": "2026-01-16T14:26:11.401495"}}
{"event_type": "price_change", "event_ts": "2026-01-16T14:26:11.401523", "ingestion_ts": "2026-01-16T14:27:04.418606", "market_id": "0x49686d26fb712515cd5e12c23f0a1c7e10214c7faa3cb0a730aabe0c33694082", "raw": {"market": "0x49686d26fb712515cd5e12c23f0a1c7e10214c7faa3cb0a730aabe0c33694082", "asset_id": "30442780799048074404860985387051749017905070253466005720364298335239299761065", "price": "0.005", "size": "99.51", "side": "BUY", "timestamp": "1768573571303", "received_at": "2026-01-16T14:26:11.401523"}}
{"event_type": "price_change", "event_ts": "2026-01-16T14:26:11.401523", "ingestion_ts": "2026-01-16T14:27:04.418606", "market_id": "0x49686d26fb712515cd5e12c23f0a1c7e10214c7faa3cb0a730aabe0c33694082", "raw": {"market": "0x49686d26fb712515cd5e12c23f0a1c7e10214c7faa3cb0a730aabe0c33694082", "asset_id": "13244681086321087932946246027856416106585284024824496763706748621681543444582", "price": "0.995", "size": "99.51", "side": "SELL", "timestamp": "1768573571303", "received_at": "2026-01-16T14:26:11.401523"}}
{"event_type": "price_change", "event_ts": "2026-01-16T14:26:11.439542", "ingestion_ts": "2026-01-16T14:27:04.418606", "market_id": "0xc55db914f0fd1fee18997706712c0dfd8d0369cdbef93a9fef12bd001914ca77", "raw": {"market": "0xc55db914f0fd1fee18997706712c0dfd8d0369cdbef93a9fef12bd001914ca77", "asset_id": "114600293444080540179603459515770723592661967180480327891296353898330242622833", "price": "0.857", "size": "233", "side": "BUY", "timestamp": "1768573571303", "received_at": "2026-01-16T14:26:11.439542"}}
{"event_type": "price_change", "event_ts": "2026-01-16T14:26:11.439542", "ingestion_ts": "2026-01-16T14:27:04.418606", "market_id": "0xc55db914f0fd1fee18997706712c0dfd8d0369cdbef93a9fef12bd001914ca77", "raw": {"market": "0xc55db914f0fd1fee18997706712c0dfd8d0369cdbef93a9fef12bd001914ca77", "asset_id": "72354723612769247426741660426331235762851940382312402276325808095604519806766", "price": "0.143", "size": "233", "side": "SELL", "timestamp": "1768573571303", "received_at": "2026-01-16T14:26:11.439542"}}
{"event_type": "price_change", "event_ts": "2026-01-16T14:26:11.439589", "ingestion_ts": "2026-01-16T14:27:04.418606", "market_id": "0x44f08744458b8896620cd3330bc5e1ea69df4199b02d4fc583b3fc96e5d314ce", "raw": {"market": "0x44f08744458b8896620cd3330bc5e1ea69df4199b02d4fc583b3fc96e5d314ce", "asset_id": "72327831507226612545928776794104143393438710920370371172884559893525100761096", "price": "0.853", "size": "234", "side": "BUY", "timestamp": "1768573571303", "received_at": "2026-01-16T14:26:11.439589"}}
{"event_type": "price_change", "event_ts": "2026-01-16T14:26:11.439589", "ingestion_ts": "2026-01-16T14:27:04.418606", "market_id": "0x44f08744458b8896620cd3330bc5e1ea69df4199b02d4fc583b3fc96e5d314ce", "raw": {"market": "0x44f08744458b8896620cd3330bc5e1ea69df4199b02d4fc583b3fc96e5d314ce", "asset_id": "49194009556504828848509244326501559253829462790583873936160989575507522044057", "price": "0.147", "size": "234", "side": "SELL", "timestamp": "1768573571303", "received_at": "2026-01-16T14:26:11.439589"}}
{"event_type": "price_change", "event_ts": "2026-01-16T14:26:11.439604", "ingestion_ts": "2026-01-16T14:27:04.418606", "market_id": "0x9472be65457510b7fc3477b20ba90910e99d92eac8421a14bf4b7b7a08ef31dc", "raw": {"market": "0x9472be65457510b7fc3477b20ba90910e99d92eac8421a14bf4b7b7a08ef31dc", "asset_id": "43311793366960417907757893276427136943959788721376762326430771171648759300146", "price": "0.856", "size": "0", "side": "BUY", "timestamp": "1768573571303", "received_at": "2026-01-16T14:26:11.439604"}}
{"event_type": "price_change", "event_ts": "2026-01-16T14:26:11.439604", "ingestion_ts": "2026-01-16T14:27:04.418606", "market_id": "0x9472be65457510b7fc3477b20ba90910e99d92eac8421a14bf4b7b7a08ef31dc", "raw": {"market": "0x9472be65457510b7fc3477b20ba90910e99d92eac8421a14bf4b7b7a08ef31dc", "asset_id": "73414222381656326204771753454630063673548497164758947581648273905027617570612", "price": "0.144", "size": "0", "side": "SELL", "timestamp": "1768573571303", "received_at": "2026-01-16T14:26:11.439604"}}
{"event_type": "price_change", "event_ts": "2026-01-16T14:26:11.439918", "ingestion_ts": "2026-01-16T14:27:04.418606", "market_id": "0x2393ed0b0fdc450054c7b9071907eca75cf4fc36e385adf4a0a5f99ee62243e8", "raw": {"market": "0x2393ed0b0fdc450054c7b9071907eca75cf4fc36e385adf4a0a5f99ee62243e8", "asset_id": "32769749367306925959219403371425714180265458150646381231272229429098460625924", "price": "0.811", "size": "0", "side": "BUY", "timestamp": "1768573571303", "received_at": "2026-01-16T14:26:11.439918"}}
{"event_type": "price_change", "event_ts": "2026-01-16T14:26:11.439918", "ingestion_ts": "2026-01-16T14:27:04.418606", "market_id": "0x2393ed0b0fdc450054c7b9071907eca75cf4fc36e385adf4a0a5f99ee62243e8", "raw": {"market": "0x2393ed0b0fdc450054c7b9071907eca75cf4fc36e385adf4a0a5f99ee62243e8", "asset_id": "100074770378634056601572485653252702850363676459996771990439989989293515601975", "price": "0.189", "size": "0", "side": "SELL", "timestamp": "1768573571303", "received_at": "2026-01-16T14:26:11.439918"}}
{"event_type": "price_change", "event_ts": "2026-01-16T14:26:11.466138", "ingestion_ts": "2026-01-16T14:27:04.418606", "market_id": "0xc55db914f0fd1fee18997706712c0dfd8d0369cdbef93a9fef12bd001914ca77", "raw": {"market": "0xc55db914f0fd1fee18997706712c0dfd8d0369cdbef93a9fef12bd001914ca77", "asset_id": "114600293444080540179603459515770723592661967180480327891296353898330242622833", "price": "0.859", "size": "40", "side": "BUY", "timestamp": "1768573571346", "received_at": "2026-01-16T14:26:11.466138"}}
{"event_type": "price_change", "event_ts": "2026-01-16T14:26:11.466138", "ingestion_ts": "2026-01-16T14:27:04.418606", "market_id": "0xc55db914f0fd1fee18997706712c0dfd8d0369cdbef93a9fef12bd001914ca77", "raw": {"market": "0xc55db914f0fd1fee18997706712c0dfd8d0369cdbef93a9fef12bd001914ca77", "asset_id": "72354723612769247426741660426331235762851940382312402276325808095604519806766", "price": "0.141", "size": "40", "side": "SELL", "timestamp": "1768573571346", "received_at": "2026-01-16T14:26:11.466138"}}
{"event_type": "price_change", "event_ts": "2026-01-16T14:26:11.466330", "ingestion_ts": "2026-01-16T14:27:04.418606", "market_id": "0x2393ed0b0fdc450054c7b9071907eca75cf4fc36e385adf4a0a5f99ee62243e8", "raw": {"market": "0x2393ed0b0fdc450054c7b9071907eca75cf4fc36e385adf4a0a5f99ee62243e8", "asset_id": "32769749367306925959219403371425714180265458150646381231272229429098460625924", "price": "0.849", "size": "304", "side": "BUY", "timestamp": "1768573571346", "received_at": "2026-01-16T14:26:11.466330"}}
{"event_type": "price_change", "event_ts": "2026-01-16T14:26:11.466330", "ingestion_ts": "2026-01-16T14:27:04.418606", "market_id": "0x2393ed0b0fdc450054c7b9071907eca75cf4fc36e385adf4a0a5f99ee62243e8", "raw": {"market": "0x2393ed0b0fdc450054c7b9071907eca75cf4fc36e385adf4a0a5f99ee62243e8", "asset_id": "100074770378634056601572485653252702850363676459996771990439989989293515601975", "price": "0.151", "size": "304", "side": "SELL", "timestamp": "1768573571346", "received_at": "2026-01-16T14:26:11.466330"}}
{"event_type": "price_change", "event_ts": "2026-01-16T14:26:11.466686", "ingestion_ts": "2026-01-16T14:27:04.418606", "market_id": "0x49686d26fb712515cd5e12c23f0a1c7e10214c7faa3cb0a730aabe0c33694082", "raw": {"market": "0x49686d26fb712515cd5e12c23f0a1c7e10214c7faa3cb0a730aabe0c33694082", "asset_id": "30442780799048074404860985387051749017905070253466005720364298335239299761065", "price": "0.006", "size": "20.08", "side": "BUY", "timestamp": "1768573571346", "received_at": "2026-01-16T14:26:11.466686"}}
{"event_type": "price_change", "event_ts": "2026-01-16T14:26:11.466686", "ingestion_ts": "2026-01-16T14:27:04.418606", "market_id": "0x49686d26fb712515cd5e12c23f0a1c7e10214c7faa3cb0a730aabe0c33694082", "raw": {"market": "0x49686d26fb712515cd5e12c23f0a1c7e10214c7faa3cb0a730aabe0c33694082", "asset_id": "13244681086321087932946246027856416106585284024824496763706748621681543444582", "price": "0.994", "size": "20.08", "side": "SELL", "timestamp": "1768573571346", "received_at": "2026-01-16T14:26:11.466686"}}
{"event_type": "price_change", "event_ts": "2026-01-16T14:26:11.466829", "ingestion_ts": "2026-01-16T14:27:04.418606", "market_id": "0x49a20c7523c271099008f3ef9a31521263b24d637959852a391e6b4697b1a437", "raw": {"market": "0x49a20c7523c271099008f3ef9a31521263b24d637959852a391e6b4697b1a437", "asset_id": "55881023621710858558280545117465775643848233756850602339827152783696837905531", "price": "0.857", "size": "40", "side": "BUY", "timestamp": "1768573571346", "received_at": "2026-01-16T14:26:11.466829"}}
{"event_type": "price_change", "event_ts": "2026-01-16T14:26:11.466829", "ingestion_ts": "2026-01-16T14:27:04.418606", "market_id": "0x49a20c7523c271099008f3ef9a31521263b24d637959852a391e6b4697b1a437", "raw": {"market": "0x49a20c7523c271099008f3ef9a31521263b24d637959852a391e6b4697b1a437", "asset_id": "13018971792603393862521629014128024641178044618205296260525674415067194037856", "price": "0.143", "size": "40", "side": "SELL", "timestamp": "1768573571346", "received_at": "2026-01-16T14:26:11.466829"}}
{"event_type": "price_change", "event_ts": "2026-01-16T14:26:11.466870", "ingestion_ts": "2026-01-16T14:27:04.418606", "market_id": "0x9472be65457510b7fc3477b20ba90910e99d92eac8421a14bf4b7b7a08ef31dc", "raw": {"market": "0x9472be65457510b7fc3477b20ba90910e99d92eac8421a14bf4b7b7a08ef31dc", "asset_id": "43311793366960417907757893276427136943959788721376762326430771171648759300146", "price": "0.858", "size": "243", "side": "BUY", "timestamp": "1768573571346", "received_at": "2026-01-16T14:26:11.466870"}}
{"event_type": "price_change", "event_ts": "2026-01-16T14:26:11.466870", "ingestion_ts": "2026-01-16T14:27:04.418606", "market_id": "0x9472be65457510b7fc3477b20ba90910e99d92eac8421a14bf4b7b7a08ef31dc", "raw": {"market": "0x9472be65457510b7fc3477b20ba90910e99d92eac8421a14bf4b7b7a08ef31dc", "asset_id": "73414222381656326204771753454630063673548497164758947581648273905027617570612", "price": "0.142", "size": "243", "side": "SELL", "timestamp": "1768573571346", "received_at": "2026-01-16T14:26:11.466870"}}
{"event_type": "price_change", "event_ts": "2026-01-16T14:26:11.468445", "ingestion_ts": "2026-01-16T14:27:04.418606", "market_id": "0x44f08744458b8896620cd3330bc5e1ea69df4199b02d4fc583b3fc96e5d314ce", "raw": {"market": "0x44f08744458b8896620cd3330bc5e1ea69df4199b02d4fc583b3fc96e5d314ce", "asset_id": "72327831507226612545928776794104143393438710920370371172884559893525100761096", "price": "0.854", "size": "10", "side": "BUY", "timestamp": "1768573571346", "received_at": "2026-01-16T14:26:11.468445"}}
{"event_type": "price_change", "event_ts": "2026-01-16T14:26:11.468445", "ingestion_ts": "2026-01-16T14:27:04.418606", "market_id": "0x44f08744458b8896620cd3330bc5e1ea69df4199b02d4fc583b3fc96e5d314ce", "raw": {"market": "0x44f08744458b8896620cd3330bc5e1ea69df4199b02d4fc583b3fc96e5d314ce", "asset_id": "49194009556504828848509244326501559253829462790583873936160989575507522044057", "price": "0.146", "size": "10", "side": "SELL", "timestamp": "1768573571346", "received_at": "2026-01-16T14:26:11.468445"}}
{"event_type": "price_change", "event_ts": "2026-01-16T14:26:11.468496", "ingestion_ts": "2026-01-16T14:27:04.418606", "market_id": "0x50c669f178da4e5bbea7f1be25041fd278914712fa87a6a6f8e57d5923d88dee", "raw": {"market": "0x50c669f178da4e5bbea7f1be25041fd278914712fa87a6a6f8e57d5923d88dee", "asset_id": "74040420326294854165772767082819937451857852955603897473157746262672057685461", "price": "0.857", "size": "10", "side": "BUY", "timestamp": "1768573571346", "received_at": "2026-01-16T14:26:11.468496"}}
{"event_type": "price_change", "event_ts": "2026-01-16T14:26:11.468496", "ingestion_ts": "2026-01-16T14:27:04.418606", "market_id": "0x50c669f178da4e5bbea7f1be25041fd278914712fa87a6a6f8e57d5923d88dee", "raw": {"market": "0x50c669f178da4e5bbea7f1be25041fd278914712fa87a6a6f8e57d5923d88dee", "asset_id": "24682525479474221428144937281315825971983904267399062415430320764754931667953", "price": "0.143", "size": "10", "side": "SELL", "timestamp": "1768573571346", "received_at": "2026-01-16T14:26:11.468496"}}
{"event_type": "price_change", "event_ts": "2026-01-16T14:26:13.000978", "ingestion_ts": "2026-01-16T14:27:04.418606", "market_id": "0x49686d26fb712515cd5e12c23f0a1c7e10214c7faa3cb0a730aabe0c33694082", "raw": {"market": "0x49686d26fb712515cd5e12c23f0a1c7e10214c7faa3cb0a730aabe0c33694082", "asset_id": "13244681086321087932946246027856416106585284024824496763706748621681543444582", "price": "0.853", "size": "45", "side": "BUY", "timestamp": "1768573572959", "received_at": "2026-01-16T14:26:13.000978"}}
{"event_type": "price_change", "event_ts": "2026-01-16T14:26:13.000978", "ingestion_ts": "2026-01-16T14:27:04.418606", "market_id": "0x49686d26fb712515cd5e12c23f0a1c7e10214c7faa3cb0a730aabe0c33694082", "raw": {"market": "0x49686d26fb712515cd5e12c23f0a1c7e10214c7faa3cb0a730aabe0c33694082", "asset_id": "30442780799048074404860985387051749017905070253466005720364298335239299761065", "price": "0.147", "size": "45", "side": "SELL", "timestamp": "1768573572959", "received_at": "2026-01-16T14:26:13.000978"}}
{"event_type": "price_change", "event_ts": "2026-01-16T14:26:13.043120", "ingestion_ts": "2026-01-16T14:27:04.418606", "market_id": "0x44f08744458b8896620cd3330bc5e1ea69df4199b02d4fc583b3fc96e5d314ce", "raw": {"market": "0x44f08744458b8896620cd3330bc5e1ea69df4199b02d4fc583b3fc96e5d314ce", "asset_id": "72327831507226612545928776794104143393438710920370371172884559893525100761096", "price": "0.899", "size": "0", "side": "BUY", "timestamp": "1768573573000", "received_at": "2026-01-16T14:26:13.043120"}}
{"event_type": "price_change", "event_ts": "2026-01-16T14:26:13.043120", "ingestion_ts": "2026-01-16T14:27:04.418606", "market_id": "0x44f08744458b8896620cd3330bc5e1ea69df4199b02d4fc583b3fc96e5d314ce", "raw": {"market": "0x44f08744458b8896620cd3330bc5e1ea69df4199b02d4fc583b3fc96e5d314ce", "asset_id": "49194009556504828848509244326501559253829462790583873936160989575507522044057", "price": "0.101", "size": "0", "side": "SELL", "timestamp": "1768573573000", "received_at": "2026-01-16T14:26:13.043120"}}
{"event_type": "price_change", "event_ts": "2026-01-16T14:26:13.043182", "ingestion_ts": "2026-01-16T14:27:04.418606", "market_id": "0x49686d26fb712515cd5e12c23f0a1c7e10214c7faa3cb0a730aabe0c33694082", "raw": {"market": "0x49686d26fb712515cd5e12c23f0a1c7e10214c7faa3cb0a730aabe0c33694082", "asset_id": "30442780799048074404860985387051749017905070253466005720364298335239299761065", "price": "0.049", "size": "0", "side": "BUY", "timestamp": "1768573573000", "received_at": "2026-01-16T14:26:13.043182"}}
{"event_type": "price_change", "event_ts": "2026-01-16T14:26:13.043182", "ingestion_ts": "2026-01-16T14:27:04.418606", "market_id": "0x49686d26fb712515cd5e12c23f0a1c7e10214c7faa3cb0a730aabe0c33694082", "raw": {"market": "0x49686d26fb712515cd5e12c23f0a1c7e10214c7faa3cb0a730aabe0c33694082", "asset_id": "13244681086321087932946246027856416106585284024824496763706748621681543444582", "price": "0.951", "size": "0", "side": "SELL", "timestamp": "1768573573000", "received_at": "2026-01-16T14:26:13.043182"}}
{"event_type": "price_change", "event_ts": "2026-01-16T14:26:13.043208", "ingestion_ts": "2026-01-16T14:27:04.418606", "market_id": "0xc55db914f0fd1fee18997706712c0dfd8d0369cdbef93a9fef12bd001914ca77", "raw": {"market": "0xc55db914f0fd1fee18997706712c0dfd8d0369cdbef93a9fef12bd001914ca77", "asset_id": "114600293444080540179603459515770723592661967180480327891296353898330242622833", "price": "0.902", "size": "0", "side": "BUY", "timestamp": "1768573573000", "received_at": "2026-01-16T14:26:13.043208"}}
{"event_type": "price_change", "event_ts": "2026-01-16T14:26:13.043208", "ingestion_ts": "2026-01-16T14:27:04.418606", "market_id": "0xc55db914f0fd1fee18997706712c0dfd8d0369cdbef93a9fef12bd001914ca77", "raw": {"market": "0xc55db914f0fd1fee18997706712c0dfd8d0369cdbef93a9fef12bd001914ca77", "asset_id": "72354723612769247426741660426331235762851940382312402276325808095604519806766", "price": "0.098", "size": "0", "side": "SELL", "timestamp": "1768573573000", "received_at": "2026-01-16T14:26:13.043208"}}
{"event_type": "price_change", "event_ts": "2026-01-16T14:26:13.044380", "ingestion_ts": "2026-01-16T14:27:04.418606", "market_id": "0x2393ed0b0fdc450054c7b9071907eca75cf4fc36e385adf4a0a5f99ee62243e8", "raw": {"market": "0x2393ed0b0fdc450054c7b9071907eca75cf4fc36e385adf4a0a5f99ee62243e8", "asset_id": "32769749367306925959219403371425714180265458150646381231272229429098460625924", "price": "0.892", "size": "0", "side": "BUY", "timestamp": "1768573573002", "received_at": "2026-01-16T14:26:13.044380"}}
{"event_type": "price_change", "event_ts": "2026-01-16T14:26:13.044380", "ingestion_ts": "2026-01-16T14:27:04.418606", "market_id": "0x2393ed0b0fdc450054c7b9071907eca75cf4fc36e385adf4a0a5f99ee62243e8", "raw": {"market": "0x2393ed0b0fdc450054c7b9071907eca75cf4fc36e385adf4a0a5f99ee62243e8", "asset_id": "100074770378634056601572485653252702850363676459996771990439989989293515601975", "price": "0.108", "size": "0", "side": "SELL", "timestamp": "1768573573002", "received_at": "2026-01-16T14:26:13.044380"}}
{"event_type": "price_change", "event_ts": "2026-01-16T14:26:13.061199", "ingestion_ts": "2026-01-16T14:27:04.418606", "market_id": "0x49686d26fb712515cd5e12c23f0a1c7e10214c7faa3cb0a730aabe0c33694082", "raw": {"market": "0x49686d26fb712515cd5e12c23f0a1c7e10214c7faa3cb0a730aabe0c33694082", "asset_id": "13244681086321087932946246027856416106585284024824496763706748621681543444582", "price": "0.854", "size": "23.35", "side": "BUY", "timestamp": "1768573573022", "received_at": "2026-01-16T14:26:13.061199"}}
{"event_type": "price_change", "event_ts": "2026-01-16T14:26:13.061199", "ingestion_ts": "2026-01-16T14:27:04.418606", "market_id": "0x49686d26fb712515cd5e12c23f0a1c7e10214c7faa3cb0a730aabe0c33694082", "raw": {"market": "0x49686d26fb712515cd5e12c23f0a1c7e10214c7faa3cb0a730aabe0c33694082", "asset_id": "30442780799048074404860985387051749017905070253466005720364298335239299761065", "price": "0.146", "size": "23.35", "side": "SELL", "timestamp": "1768573573022", "received_at": "2026-01-16T14:26:13.061199"}}
{"event_type": "price_change", "event_ts": "2026-01-16T14:26:13.078313", "ingestion_ts": "2026-01-16T14:27:04.418606", "market_id": "0x2393ed0b0fdc450054c7b9071907eca75cf4fc36e385adf4a0a5f99ee62243e8", "raw": {"market": "0x2393ed0b0fdc450054c7b9071907eca75cf4fc36e385adf4a0a5f99ee62243e8", "asset_id": "32769749367306925959219403371425714180265458150646381231272229429098460625924", "price": "0.897", "size": "7.37", "side": "BUY", "timestamp": "1768573573041", "received_at": "2026-01-16T14:26:13.078313"}}
{"event_type": "price_change", "event_ts": "2026-01-16T14:26:13.078313", "ingestion_ts": "2026-01-16T14:27:04.418606", "market_id": "0x2393ed0b0fdc450054c7b9071907eca75cf4fc36e385adf4a0a5f99ee62243e8", "raw": {"market": "0x2393ed0b0fdc450054c7b9071907eca75cf4fc36e385adf4a0a5f99ee62243e8", "asset_id": "100074770378634056601572485653252702850363676459996771990439989989293515601975", "price": "0.103", "size": "7.37", "side": "SELL", "timestamp": "1768573573041", "received_at": "2026-01-16T14:26:13.078313"}}
{"event_type": "price_change", "event_ts": "2026-01-16T14:26:13.078998", "ingestion_ts": "2026-01-16T14:27:04.418606", "market_id": "0x49686d26fb712515cd5e12c23f0a1c7e10214c7faa3cb0a730aabe0c33694082", "raw": {"market": "0x49686d26fb712515cd5e12c23f0a1c7e10214c7faa3cb0a730aabe0c33694082", "asset_id": "30442780799048074404860985387051749017905070253466005720364298335239299761065", "price": "0.054", "size": "7.37", "side": "BUY", "timestamp": "1768573573041", "received_at": "2026-01-16T14:26:13.078998"}}
{"event_type": "price_change", "event_ts": "2026-01-16T14:26:13.078998", "ingestion_ts": "2026-01-16T14:27:04.418606", "market_id": "0x49686d26fb712515cd5e12c23f0a1c7e10214c7faa3cb0a730aabe0c33694082", "raw": {"market": "0x49686d26fb712515cd5e12c23f0a1c7e10214c7faa3cb0a730aabe0c33694082", "asset_id": "13244681086321087932946246027856416106585284024824496763706748621681543444582", "price": "0.946", "size": "7.37", "side": "SELL", "timestamp": "1768573573041", "received_at": "2026-01-16T14:26:13.078998"}}
{"event_type": "price_change", "event_ts": "2026-01-16T14:26:13.079032", "ingestion_ts": "2026-01-16T14:27:04.418606", "market_id": "0xc55db914f0fd1fee18997706712c0dfd8d0369cdbef93a9fef12bd001914ca77", "raw": {"market": "0xc55db914f0fd1fee18997706712c0dfd8d0369cdbef93a9fef12bd001914ca77", "asset_id": "114600293444080540179603459515770723592661967180480327891296353898330242622833", "price": "0.907", "size": "7.37", "side": "BUY", "timestamp": "1768573573041", "received_at": "2026-01-16T14:26:13.079032"}}
{"event_type": "price_change", "event_ts": "2026-01-16T14:26:13.079032", "ingestion_ts": "2026-01-16T14:27:04.418606", "market_id": "0xc55db914f0fd1fee18997706712c0dfd8d0369cdbef93a9fef12bd001914ca77", "raw": {"market": "0xc55db914f0fd1fee18997706712c0dfd8d0369cdbef93a9fef12bd001914ca77", "asset_id": "72354723612769247426741660426331235762851940382312402276325808095604519806766", "price": "0.093", "size": "7.37", "side": "SELL", "timestamp": "1768573573041", "received_at": "2026-01-16T14:26:13.079032"}}
{"event_type": "price_change", "event_ts": "2026-01-16T14:26:13.079100", "ingestion_ts": "2026-01-16T14:27:04.418606", "market_id": "0x44f08744458b8896620cd3330bc5e1ea69df4199b02d4fc583b3fc96e5d314ce", "raw": {"market": "0x44f08744458b8896620cd3330bc5e1ea69df4199b02d4fc583b3fc96e5d314ce", "asset_id": "72327831507226612545928776794104143393438710920370371172884559893525100761096", "price": "0.903", "size": "7.37", "side": "BUY", "timestamp": "1768573573041", "received_at": "2026-01-16T14:26:13.079100"}}
{"event_type": "price_change", "event_ts": "2026-01-16T14:26:13.079100", "ingestion_ts": "2026-01-16T14:27:04.418606", "market_id": "0x44f08744458b8896620cd3330bc5e1ea69df4199b02d4fc583b3fc96e5d314ce", "raw": {"market": "0x44f08744458b8896620cd3330bc5e1ea69df4199b02d4fc583b3fc96e5d314ce", "asset_id": "49194009556504828848509244326501559253829462790583873936160989575507522044057", "price": "0.097", "size": "7.37", "side": "SELL", "timestamp": "1768573573041", "received_at": "2026-01-16T14:26:13.079100"}}
{"event_type": "price_change", "event_ts": "2026-01-16T14:26:13.086083", "ingestion_ts": "2026-01-16T14:27:04.418606", "market_id": "0x2393ed0b0fdc450054c7b9071907eca75cf4fc36e385adf4a0a5f99ee62243e8", "raw": {"market": "0x2393ed0b0fdc450054c7b9071907eca75cf4fc36e385adf4a0a5f99ee62243e8", "asset_id": "100074770378634056601572485653252702850363676459996771990439989989293515601975", "price": "0.047", "size": "0", "side": "SELL", "timestamp": "1768573573046", "received_at": "2026-01-16T14:26:13.086083"}}
{"event_type": "price_change", "event_ts": "2026-01-16T14:26:13.086083", "ingestion_ts": "2026-01-16T14:27:04.418606", "market_id": "0x2393ed0b0fdc450054c7b9071907eca75cf4fc36e385adf4a0a5f99ee62243e8", "raw": {"market": "0x2393ed0b0fdc450054c7b9071907eca75cf4fc36e385adf4a0a5f99ee62243e8", "asset_id": "32769749367306925959219403371425714180265458150646381231272229429098460625924", "price": "0.953", "size": "0", "side": "BUY", "timestamp": "1768573573046", "received_at": "2026-01-16T14:26:13.086083"}}
{"event_type": "price_change", "event_ts": "2026-01-16T14:26:13.117709", "ingestion_ts": "2026-01-16T14:27:04.418606", "market_id": "0x2393ed0b0fdc450054c7b9071907eca75cf4fc36e385adf4a0a5f99ee62243e8", "raw": {"market": "0x2393ed0b0fdc450054c7b9071907eca75cf4fc36e385adf4a0a5f99ee62243e8", "asset_id": "100074770378634056601572485653252702850363676459996771990439989989293515601975", "price": "0.061", "size": "195", "side": "SELL", "timestamp": "1768573573079", "received_at": "2026-01-16T14:26:13.117709"}}
{"event_type": "price_change", "event_ts": "2026-01-16T14:26:13.117709", "ingestion_ts": "2026-01-16T14:27:04.418606", "market_id": "0x2393ed0b0fdc450054c7b9071907eca75cf4fc36e385adf4a0a5f99ee62243e8", "raw": {"market": "0x2393ed0b0fdc450054c7b9071907eca75cf4fc36e385adf4a0a5f99ee62243e8", "asset_id": "32769749367306925959219403371425714180265458150646381231272229429098460625924", "price": "0.939", "size": "195", "side": "BUY", "timestamp": "1768573573079", "received_at": "2026-01-16T14:26:13.117709"}}
{"event_type": "price_change", "event_ts": "2026-01-16T14:26:13.542715", "ingestion_ts": "2026-01-16T14:27:04.418606", "market_id": "0xaf9d0e448129a9f657f851d49495ba4742055d80e0ef1166ba0ee81d4d594214", "raw": {"market": "0xaf9d0e448129a9f657f851d49495ba4742055d80e0ef1166ba0ee81d4d594214", "asset_id": "4153292802911610701832309484716814274802943278345248636922528170020319407796", "price": "0.979", "size": "0", "side": "SELL", "timestamp": "1768573573492", "received_at": "2026-01-16T14:26:13.542715"}}
{"event_type": "price_change", "event_ts": "2026-01-16T14:26:13.542715", "ingestion_ts": "2026-01-16T14:27:04.418606", "market_id": "0xaf9d0e448129a9f657f851d49495ba4742055d80e0ef1166ba0ee81d4d594214", "raw": {"market": "0xaf9d0e448129a9f657f851d49495ba4742055d80e0ef1166ba0ee81d4d594214", "asset_id": "101676997363687199724245607342877036148401850938023978421879460310389391082353", "price": "0.021", "size": "0", "side": "BUY", "timestamp": "1768573573492", "received_at": "2026-01-16T14:26:13.542715"}}
{"event_type": "price_change", "event_ts": "2026-01-16T14:26:13.585816", "ingestion_ts": "2026-01-16T14:27:04.418606", "market_id": "0xc0e6b917320a47228fb96e3b5ae0e5c93773a5ae2662ae4e1f37807cfe47ce98", "raw": {"market": "0xc0e6b917320a47228fb96e3b5ae0e5c93773a5ae2662ae4e1f37807cfe47ce98", "asset_id": "58656358377246279051017109359677190749228949103591068167284263961542487110215", "price": "0.002", "size": "3273.26", "side": "BUY", "timestamp": "1768573573535", "received_at": "2026-01-16T14:26:13.585816"}}
{"event_type": "price_change", "event_ts": "2026-01-16T14:26:13.585816", "ingestion_ts": "2026-01-16T14:27:04.418606", "market_id": "0xc0e6b917320a47228fb96e3b5ae0e5c93773a5ae2662ae4e1f37807cfe47ce98", "raw": {"market": "0xc0e6b917320a47228fb96e3b5ae0e5c93773a5ae2662ae4e1f37807cfe47ce98", "asset_id": "81647294538046680798858716589766492074338758116170717123345952330712416337530", "price": "0.998", "size": "3273.26", "side": "SELL", "timestamp": "1768573573535", "received_at": "2026-01-16T14:26:13.585816"}}
{"event_type": "price_change", "event_ts": "2026-01-16T14:26:13.782721", "ingestion_ts": "2026-01-16T14:27:04.418606", "market_id": "0x2393ed0b0fdc450054c7b9071907eca75cf4fc36e385adf4a0a5f99ee62243e8", "raw": {"market": "0x2393ed0b0fdc450054c7b9071907eca75cf4fc36e385adf4a0a5f99ee62243e8", "asset_id": "32769749367306925959219403371425714180265458150646381231272229429098460625924", "price": "0.953", "size": "50", "side": "BUY", "timestamp": "1768573573744", "received_at": "2026-01-16T14:26:13.782721"}}
{"event_type": "price_change", "event_ts": "2026-01-16T14:26:13.782721", "ingestion_ts": "2026-01-16T14:27:04.418606", "market_id": "0x2393ed0b0fdc450054c7b9071907eca75cf4fc36e385adf4a0a5f99ee62243e8", "raw": {"market": "0x2393ed0b0fdc450054c7b9071907eca75cf4fc36e385adf4a0a5f99ee62243e8", "asset_id": "100074770378634056601572485653252702850363676459996771990439989989293515601975", "price": "0.047", "size": "50", "side": "SELL", "timestamp": "1768573573744", "received_at": "2026-01-16T14:26:13.782721"}}
{"event_type": "price_change", "event_ts": "2026-01-16T14:26:14.110666", "ingestion_ts": "2026-01-16T14:27:04.418606", "market_id": "0x2393ed0b0fdc450054c7b9071907eca75cf4fc36e385adf4a0a5f99ee62243e8", "raw": {"market": "0x2393ed0b0fdc450054c7b9071907eca75cf4fc36e385adf4a0a5f99ee62243e8", "asset_id": "32769749367306925959219403371425714180265458150646381231272229429098460625924", "price": "0.954", "size": "0", "side": "BUY", "timestamp": "1768573574062", "received_at": "2026-01-16T14:26:14.110666"}}
{"event_type": "price_change", "event_ts": "2026-01-16T14:26:14.110666", "ingestion_ts": "2026-01-16T14:27:04.418606", "market_id": "0x2393ed0b0fdc450054c7b9071907eca75cf4fc36e385adf4a0a5f99ee62243e8", "raw": {"market": "0x2393ed0b0fdc450054c7b9071907eca75cf4fc36e385adf4a0a5f99ee62243e8", "asset_id": "100074770378634056601572485653252702850363676459996771990439989989293515601975", "price": "0.046", "size": "0", "side": "SELL", "timestamp": "1768573574062", "received_at": "2026-01-16T14:26:14.110666"}}
{"event_type": "price_change", "event_ts": "2026-01-16T14:26:14.358367", "ingestion_ts": "2026-01-16T14:27:04.418606", "market_id": "0x49686d26fb712515cd5e12c23f0a1c7e10214c7faa3cb0a730aabe0c33694082", "raw": {"market": "0x49686d26fb712515cd5e12c23f0a1c7e10214c7faa3cb0a730aabe0c33694082", "asset_id": "30442780799048074404860985387051749017905070253466005720364298335239299761065", "price": "0.146", "size": "5.85", "side": "SELL", "timestamp": "1768573574320", "received_at": "2026-01-16T14:26:14.358367"}}
{"event_type": "price_change", "event_ts": "2026-01-16T14:26:14.358367", "ingestion_ts": "2026-01-16T14:27:04.418606", "market_id": "0x49686d26fb712515cd5e12c23f0a1c7e10214c7faa3cb0a730aabe0c33694082", "raw": {"market": "0x49686d26fb712515cd5e12c23f0a1c7e10214c7faa3cb0a730aabe0c33694082", "asset_id": "13244681086321087932946246027856416106585284024824496763706748621681543444582", "price": "0.854", "size": "5.85", "side": "BUY", "timestamp": "1768573574320", "received_at": "2026-01-16T14:26:14.358367"}}
{"event_type": "price_change", "event_ts": "2026-01-16T14:26:14.485878", "ingestion_ts": "2026-01-16T14:27:04.418606", "market_id": "0x49686d26fb712515cd5e12c23f0a1c7e10214c7faa3cb0a730aabe0c33694082", "raw": {"market": "0x49686d26fb712515cd5e12c23f0a1c7e10214c7faa3cb0a730aabe0c33694082", "asset_id": "30442780799048074404860985387051749017905070253466005720364298335239299761065", "price": "0.148", "size": "17.5", "side": "SELL", "timestamp": "1768573574448", "received_at": "2026-01-16T14:26:14.485878"}}
{"event_type": "price_change", "event_ts": "2026-01-16T14:26:14.485878", "ingestion_ts": "2026-01-16T14:27:04.418606", "market_id": "0x49686d26fb712515cd5e12c23f0a1c7e10214c7faa3cb0a730aabe0c33694082", "raw": {"market": "0x49686d26fb712515cd5e12c23f0a1c7e10214c7faa3cb0a730aabe0c33694082", "asset_id": "13244681086321087932946246027856416106585284024824496763706748621681543444582", "price": "0.852", "size": "17.5", "side": "BUY", "timestamp": "1768573574448", "received_at": "2026-01-16T14:26:14.485878"}}
{"event_type": "price_change", "event_ts": "2026-01-16T14:26:15.312015", "ingestion_ts": "2026-01-16T14:27:04.418606", "market_id": "0x44f08744458b8896620cd3330bc5e1ea69df4199b02d4fc583b3fc96e5d314ce", "raw": {"market": "0x44f08744458b8896620cd3330bc5e1ea69df4199b02d4fc583b3fc96e5d314ce", "asset_id": "72327831507226612545928776794104143393438710920370371172884559893525100761096", "price": "0.402", "size": "0", "side": "BUY", "timestamp": "1768573575265", "received_at": "2026-01-16T14:26:15.312015"}}
{"event_type": "price_change", "event_ts": "2026-01-16T14:26:15.312015", "ingestion_ts": "2026-01-16T14:27:04.418606", "market_id": "0x44f08744458b8896620cd3330bc5e1ea69df4199b02d4fc583b3fc96e5d314ce", "raw": {"market": "0x44f08744458b8896620cd3330bc5e1ea69df4199b02d4fc583b3fc96e5d314ce", "asset_id": "49194009556504828848509244326501559253829462790583873936160989575507522044057", "price": "0.598", "size": "0", "side": "SELL", "timestamp": "1768573575265", "received_at": "2026-01-16T14:26:15.312015"}}
{"event_type": "price_change", "event_ts": "2026-01-16T14:26:15.358915", "ingestion_ts": "2026-01-16T14:27:04.418606", "market_id": "0x44f08744458b8896620cd3330bc5e1ea69df4199b02d4fc583b3fc96e5d314ce", "raw": {"market": "0x44f08744458b8896620cd3330bc5e1ea69df4199b02d4fc583b3fc96e5d314ce", "asset_id": "72327831507226612545928776794104143393438710920370371172884559893525100761096", "price": "0.402", "size": "5", "side": "BUY", "timestamp": "1768573575312", "received_at": "2026-01-16T14:26:15.358915"}}
{"event_type": "price_change", "event_ts": "2026-01-16T14:26:15.358915", "ingestion_ts": "2026-01-16T14:27:04.418606", "market_id": "0x44f08744458b8896620cd3330bc5e1ea69df4199b02d4fc583b3fc96e5d314ce", "raw": {"market": "0x44f08744458b8896620cd3330bc5e1ea69df4199b02d4fc583b3fc96e5d314ce", "asset_id": "49194009556504828848509244326501559253829462790583873936160989575507522044057", "price": "0.598", "size": "5", "side": "SELL", "timestamp": "1768573575312", "received_at": "2026-01-16T14:26:15.358915"}}
{"event_type": "price_change", "event_ts": "2026-01-16T14:26:15.583022", "ingestion_ts": "2026-01-16T14:27:04.418606", "market_id": "0xc0e6b917320a47228fb96e3b5ae0e5c93773a5ae2662ae4e1f37807cfe47ce98", "raw": {"market": "0xc0e6b917320a47228fb96e3b5ae0e5c93773a5ae2662ae4e1f37807cfe47ce98", "asset_id": "58656358377246279051017109359677190749228949103591068167284263961542487110215", "price": "0.002", "size": "3266.03", "side": "BUY", "timestamp": "1768573575540", "received_at": "2026-01-16T14:26:15.583022"}}
{"event_type": "price_change", "event_ts": "2026-01-16T14:26:15.583022", "ingestion_ts": "2026-01-16T14:27:04.418606", "market_id": "0xc0e6b917320a47228fb96e3b5ae0e5c93773a5ae2662ae4e1f37807cfe47ce98", "raw": {"market": "0xc0e6b917320a47228fb96e3b5ae0e5c93773a5ae2662ae4e1f37807cfe47ce98", "asset_id": "81647294538046680798858716589766492074338758116170717123345952330712416337530", "price": "0.998", "size": "3266.03", "side": "SELL", "timestamp": "1768573575540", "received_at": "2026-01-16T14:26:15.583022"}}
{"event_type": "price_change", "event_ts": "2026-01-16T14:26:15.712069", "ingestion_ts": "2026-01-16T14:27:04.418606", "market_id": "0xaf9d0e448129a9f657f851d49495ba4742055d80e0ef1166ba0ee81d4d594214", "raw": {"market": "0xaf9d0e448129a9f657f851d49495ba4742055d80e0ef1166ba0ee81d4d594214", "asset_id": "4153292802911610701832309484716814274802943278345248636922528170020319407796", "price": "0.978", "size": "0", "side": "SELL", "timestamp": "1768573575664", "received_at": "2026-01-16T14:26:15.712069"}}
{"event_type": "price_change", "event_ts": "2026-01-16T14:26:15.712069", "ingestion_ts": "2026-01-16T14:27:04.418606", "market_id": "0xaf9d0e448129a9f657f851d49495ba4742055d80e0ef1166ba0ee81d4d594214", "raw": {"market": "0xaf9d0e448129a9f657f851d49495ba4742055d80e0ef1166ba0ee81d4d594214", "asset_id": "101676997363687199724245607342877036148401850938023978421879460310389391082353", "price": "0.022", "size": "0", "side": "BUY", "timestamp": "1768573575664", "received_at": "2026-01-16T14:26:15.712069"}}
{"event_type": "price_change", "event_ts": "2026-01-16T14:26:15.788235", "ingestion_ts": "2026-01-16T14:27:04.418606", "market_id": "0xaf9d0e448129a9f657f851d49495ba4742055d80e0ef1166ba0ee81d4d594214", "raw": {"market": "0xaf9d0e448129a9f657f851d49495ba4742055d80e0ef1166ba0ee81d4d594214", "asset_id": "4153292802911610701832309484716814274802943278345248636922528170020319407796", "price": "0.989", "size": "20.5", "side": "SELL", "timestamp": "1768573575732", "received_at": "2026-01-16T14:26:15.788235"}}
{"event_type": "price_change", "event_ts": "2026-01-16T14:26:15.788235", "ingestion_ts": "2026-01-16T14:27:04.418606", "market_id": "0xaf9d0e448129a9f657f851d49495ba4742055d80e0ef1166ba0ee81d4d594214", "raw": {"market": "0xaf9d0e448129a9f657f851d49495ba4742055d80e0ef1166ba0ee81d4d594214", "asset_id": "101676997363687199724245607342877036148401850938023978421879460310389391082353", "price": "0.011", "size": "20.5", "side": "BUY", "timestamp": "1768573575732", "received_at": "2026-01-16T14:26:15.788235"}}
{"event_type": "price_change", "event_ts": "2026-01-16T14:26:15.893536", "ingestion_ts": "2026-01-16T14:27:04.418606", "market_id": "0xc0e6b917320a47228fb96e3b5ae0e5c93773a5ae2662ae4e1f37807cfe47ce98", "raw": {"market": "0xc0e6b917320a47228fb96e3b5ae0e5c93773a5ae2662ae4e1f37807cfe47ce98", "asset_id": "58656358377246279051017109359677190749228949103591068167284263961542487110215", "price": "0.002", "size": "3273.26", "side": "BUY", "timestamp": "1768573575856", "received_at": "2026-01-16T14:26:15.893536"}}
{"event_type": "price_change", "event_ts": "2026-01-16T14:26:15.893536", "ingestion_ts": "2026-01-16T14:27:04.418606", "market_id": "0xc0e6b917320a47228fb96e3b5ae0e5c93773a5ae2662ae4e1f37807cfe47ce98", "raw": {"market": "0xc0e6b917320a47228fb96e3b5ae0e5c93773a5ae2662ae4e1f37807cfe47ce98", "asset_id": "81647294538046680798858716589766492074338758116170717123345952330712416337530", "price": "0.998", "size": "3273.26", "side": "SELL", "timestamp": "1768573575856", "received_at": "2026-01-16T14:26:15.893536"}}
{"event_type": "price_change", "event_ts": "2026-01-16T14:26:15.895187", "ingestion_ts": "2026-01-16T14:27:04.418606", "market_id": "0xc0e6b917320a47228fb96e3b5ae0e5c93773a5ae2662ae4e1f37807cfe47ce98", "raw": {"market": "0xc0e6b917320a47228fb96e3b5ae0e5c93773a5ae2662ae4e1f37807cfe47ce98", "asset_id": "58656358377246279051017109359677190749228949103591068167284263961542487110215", "price": "0.002", "size": "3280.49", "side": "BUY", "timestamp": "1768573575857", "received_at": "2026-01-16T14:26:15.895187"}}
{"event_type": "price_change", "event_ts": "2026-01-16T14:26:15.895187", "ingestion_ts": "2026-01-16T14:27:04.418606", "market_id": "0xc0e6b917320a47228fb96e3b5ae0e5c93773a5ae2662ae4e1f37807cfe47ce98", "raw": {"market": "0xc0e6b917320a47228fb96e3b5ae0e5c93773a5ae2662ae4e1f37807cfe47ce98", "asset_id": "81647294538046680798858716589766492074338758116170717123345952330712416337530", "price": "0.998", "size": "3280.49", "side": "SELL", "timestamp": "1768573575857", "received_at": "2026-01-16T14:26:15.895187"}}
{"event_type": "price_change", "event_ts": "2026-01-16T14:26:15.923744", "ingestion_ts": "2026-01-16T14:27:04.418606", "market_id": "0x9472be65457510b7fc3477b20ba90910e99d92eac8421a14bf4b7b7a08ef31dc", "raw": {"market": "0x9472be65457510b7fc3477b20ba90910e99d92eac8421a14bf4b7b7a08ef31dc", "asset_id": "43311793366960417907757893276427136943959788721376762326430771171648759300146", "price": "0.858", "size": "233", "side": "BUY", "timestamp": "1768573575883", "received_at": "2026-01-16T14:26:15.923744"}}
{"event_type": "price_change", "event_ts": "2026-01-16T14:26:15.923744", "ingestion_ts": "2026-01-16T14:27:04.418606", "market_id": "0x9472be65457510b7fc3477b20ba90910e99d92eac8421a14bf4b7b7a08ef31dc", "raw": {"market": "0x9472be65457510b7fc3477b20ba90910e99d92eac8421a14bf4b7b7a08ef31dc", "asset_id": "73414222381656326204771753454630063673548497164758947581648273905027617570612", "price": "0.142", "size": "233", "side": "SELL", "timestamp": "1768573575883", "received_at": "2026-01-16T14:26:15.923744"}}
{"event_type": "price_change", "event_ts": "2026-01-16T14:26:15.923782", "ingestion_ts": "2026-01-16T14:27:04.418606", "market_id": "0x49a20c7523c271099008f3ef9a31521263b24d637959852a391e6b4697b1a437", "raw": {"market": "0x49a20c7523c271099008f3ef9a31521263b24d637959852a391e6b4697b1a437", "asset_id": "55881023621710858558280545117465775643848233756850602339827152783696837905531", "price": "0.857", "size": "30", "side": "BUY", "timestamp": "1768573575883", "received_at": "2026-01-16T14:26:15.923782"}}
{"event_type": "price_change", "event_ts": "2026-01-16T14:26:15.923782", "ingestion_ts": "2026-01-16T14:27:04.418606", "market_id": "0x49a20c7523c271099008f3ef9a31521263b24d637959852a391e6b4697b1a437", "raw": {"market": "0x49a20c7523c271099008f3ef9a31521263b24d637959852a391e6b4697b1a437", "asset_id": "13018971792603393862521629014128024641178044618205296260525674415067194037856", "price": "0.143", "size": "30", "side": "SELL", "timestamp": "1768573575883", "received_at": "2026-01-16T14:26:15.923782"}}
{"event_type": "price_change", "event_ts": "2026-01-16T14:26:15.923796", "ingestion_ts": "2026-01-16T14:27:04.418606", "market_id": "0x50c669f178da4e5bbea7f1be25041fd278914712fa87a6a6f8e57d5923d88dee", "raw": {"market": "0x50c669f178da4e5bbea7f1be25041fd278914712fa87a6a6f8e57d5923d88dee", "asset_id": "74040420326294854165772767082819937451857852955603897473157746262672057685461", "price": "0.857", "size": "0", "side": "BUY", "timestamp": "1768573575883", "received_at": "2026-01-16T14:26:15.923796"}}
{"event_type": "price_change", "event_ts": "2026-01-16T14:26:15.923796", "ingestion_ts": "2026-01-16T14:27:04.418606", "market_id": "0x50c669f178da4e5bbea7f1be25041fd278914712fa87a6a6f8e57d5923d88dee", "raw": {"market": "0x50c669f178da4e5bbea7f1be25041fd278914712fa87a6a6f8e57d5923d88dee", "asset_id": "24682525479474221428144937281315825971983904267399062415430320764754931667953", "price": "0.143", "size": "0", "side": "SELL", "timestamp": "1768573575883", "received_at": "2026-01-16T14:26:15.923796"}}
{"event_type": "price_change", "event_ts": "2026-01-16T14:26:15.923808", "ingestion_ts": "2026-01-16T14:27:04.418606", "market_id": "0x2393ed0b0fdc450054c7b9071907eca75cf4fc36e385adf4a0a5f99ee62243e8", "raw": {"market": "0x2393ed0b0fdc450054c7b9071907eca75cf4fc36e385adf4a0a5f99ee62243e8", "asset_id": "32769749367306925959219403371425714180265458150646381231272229429098460625924", "price": "0.849", "size": "294", "side": "BUY", "timestamp": "1768573575883", "received_at": "2026-01-16T14:26:15.923808"}}
{"event_type": "price_change", "event_ts": "2026-01-16T14:26:15.923808", "ingestion_ts": "2026-01-16T14:27:04.418606", "market_id": "0x2393ed0b0fdc450054c7b9071907eca75cf4fc36e385adf4a0a5f99ee62243e8", "raw": {"market": "0x2393ed0b0fdc450054c7b9071907eca75cf4fc36e385adf4a0a5f99ee62243e8", "asset_id": "100074770378634056601572485653252702850363676459996771990439989989293515601975", "price": "0.151", "size": "294", "side": "SELL", "timestamp": "1768573575883", "received_at": "2026-01-16T14:26:15.923808"}}
{"event_type": "price_change", "event_ts": "2026-01-16T14:26:15.923819", "ingestion_ts": "2026-01-16T14:27:04.418606", "market_id": "0x49686d26fb712515cd5e12c23f0a1c7e10214c7faa3cb0a730aabe0c33694082", "raw": {"market": "0x49686d26fb712515cd5e12c23f0a1c7e10214c7faa3cb0a730aabe0c33694082", "asset_id": "30442780799048074404860985387051749017905070253466005720364298335239299761065", "price": "0.006", "size": "10.08", "side": "BUY", "timestamp": "1768573575883", "received_at": "2026-01-16T14:26:15.923819"}}
{"event_type": "price_change", "event_ts": "2026-01-16T14:26:15.923819", "ingestion_ts": "2026-01-16T14:27:04.418606", "market_id": "0x49686d26fb712515cd5e12c23f0a1c7e10214c7faa3cb0a730aabe0c33694082", "raw": {"market": "0x49686d26fb712515cd5e12c23f0a1c7e10214c7faa3cb0a730aabe0c33694082", "asset_id": "13244681086321087932946246027856416106585284024824496763706748621681543444582", "price": "0.994", "size": "10.08", "side": "SELL", "timestamp": "1768573575883", "received_at": "2026-01-16T14:26:15.923819"}}
{"event_type": "price_change", "event_ts": "2026-01-16T14:26:15.923830", "ingestion_ts": "2026-01-16T14:27:04.418606", "market_id": "0xc55db914f0fd1fee18997706712c0dfd8d0369cdbef93a9fef12bd001914ca77", "raw": {"market": "0xc55db914f0fd1fee18997706712c0dfd8d0369cdbef93a9fef12bd001914ca77", "asset_id": "114600293444080540179603459515770723592661967180480327891296353898330242622833", "price": "0.859", "size": "30", "side": "BUY", "timestamp": "1768573575883", "received_at": "2026-01-16T14:26:15.923830"}}
{"event_type": "price_change", "event_ts": "2026-01-16T14:26:15.923830", "ingestion_ts": "2026-01-16T14:27:04.418606", "market_id": "0xc55db914f0fd1fee18997706712c0dfd8d0369cdbef93a9fef12bd001914ca77", "raw": {"market": "0xc55db914f0fd1fee18997706712c0dfd8d0369cdbef93a9fef12bd001914ca77", "asset_id": "72354723612769247426741660426331235762851940382312402276325808095604519806766", "price": "0.141", "size": "30", "side": "SELL", "timestamp": "1768573575883", "received_at": "2026-01-16T14:26:15.923830"}}
{"event_type": "price_change", "event_ts": "2026-01-16T14:26:15.923840", "ingestion_ts": "2026-01-16T14:27:04.418606", "market_id": "0x44f08744458b8896620cd3330bc5e1ea69df4199b02d4fc583b3fc96e5d314ce", "raw": {"market": "0x44f08744458b8896620cd3330bc5e1ea69df4199b02d4fc583b3fc96e5d314ce", "asset_id": "72327831507226612545928776794104143393438710920370371172884559893525100761096", "price": "0.854", "size": "0", "side": "BUY", "timestamp": "1768573575883", "received_at": "2026-01-16T14:26:15.923840"}}
{"event_type": "price_change", "event_ts": "2026-01-16T14:26:15.923840", "ingestion_ts": "2026-01-16T14:27:04.418606", "market_id": "0x44f08744458b8896620cd3330bc5e1ea69df4199b02d4fc583b3fc96e5d314ce", "raw": {"market": "0x44f08744458b8896620cd3330bc5e1ea69df4199b02d4fc583b3fc96e5d314ce", "asset_id": "49194009556504828848509244326501559253829462790583873936160989575507522044057", "price": "0.146", "size": "0", "side": "SELL", "timestamp": "1768573575883", "received_at": "2026-01-16T14:26:15.923840"}}
{"event_type": "price_change", "event_ts": "2026-01-16T14:26:15.949952", "ingestion_ts": "2026-01-16T14:27:04.418606", "market_id": "0x2393ed0b0fdc450054c7b9071907eca75cf4fc36e385adf4a0a5f99ee62243e8", "raw": {"market": "0x2393ed0b0fdc450054c7b9071907eca75cf4fc36e385adf4a0a5f99ee62243e8", "asset_id": "32769749367306925959219403371425714180265458150646381231272229429098460625924", "price": "0.811", "size": "10", "side": "BUY", "timestamp": "1768573575912", "received_at": "2026-01-16T14:26:15.949952"}}
{"event_type": "price_change", "event_ts": "2026-01-16T14:26:15.949952", "ingestion_ts": "2026-01-16T14:27:04.418606", "market_id": "0x2393ed0b0fdc450054c7b9071907eca75cf4fc36e385adf4a0a5f99ee62243e8", "raw": {"market": "0x2393ed0b0fdc450054c7b9071907eca75cf4fc36e385adf4a0a5f99ee62243e8", "asset_id": "100074770378634056601572485653252702850363676459996771990439989989293515601975", "price": "0.189", "size": "10", "side": "SELL", "timestamp": "1768573575912", "received_at": "2026-01-16T14:26:15.949952"}}
{"event_type": "price_change", "event_ts": "2026-01-16T14:26:15.950671", "ingestion_ts": "2026-01-16T14:27:04.418606", "market_id": "0x50c669f178da4e5bbea7f1be25041fd278914712fa87a6a6f8e57d5923d88dee", "raw": {"market": "0x50c669f178da4e5bbea7f1be25041fd278914712fa87a6a6f8e57d5923d88dee", "asset_id": "74040420326294854165772767082819937451857852955603897473157746262672057685461", "price": "0.824", "size": "10", "side": "BUY", "timestamp": "1768573575912", "received_at": "2026-01-16T14:26:15.950671"}}
{"event_type": "price_change", "event_ts": "2026-01-16T14:26:15.950671", "ingestion_ts": "2026-01-16T14:27:04.418606", "market_id": "0x50c669f178da4e5bbea7f1be25041fd278914712fa87a6a6f8e57d5923d88dee", "raw": {"market": "0x50c669f178da4e5bbea7f1be25041fd278914712fa87a6a6f8e57d5923d88dee", "asset_id": "24682525479474221428144937281315825971983904267399062415430320764754931667953", "price": "0.176", "size": "10", "side": "SELL", "timestamp": "1768573575912", "received_at": "2026-01-16T14:26:15.950671"}}
{"event_type": "price_change", "event_ts": "2026-01-16T14:26:15.951315", "ingestion_ts": "2026-01-16T14:27:04.418606", "market_id": "0x44f08744458b8896620cd3330bc5e1ea69df4199b02d4fc583b3fc96e5d314ce", "raw": {"market": "0x44f08744458b8896620cd3330bc5e1ea69df4199b02d4fc583b3fc96e5d314ce", "asset_id": "72327831507226612545928776794104143393438710920370371172884559893525100761096", "price": "0.831", "size": "10", "side": "BUY", "timestamp": "1768573575912", "received_at": "2026-01-16T14:26:15.951315"}}
{"event_type": "price_change", "event_ts": "2026-01-16T14:26:15.951315", "ingestion_ts": "2026-01-16T14:27:04.418606", "market_id": "0x44f08744458b8896620cd3330bc5e1ea69df4199b02d4fc583b3fc96e5d314ce", "raw": {"market": "0x44f08744458b8896620cd3330bc5e1ea69df4199b02d4fc583b3fc96e5d314ce", "asset_id": "49194009556504828848509244326501559253829462790583873936160989575507522044057", "price": "0.169", "size": "10", "side": "SELL", "timestamp": "1768573575912", "received_at": "2026-01-16T14:26:15.951315"}}
{"event_type": "price_change", "event_ts": "2026-01-16T14:26:15.951347", "ingestion_ts": "2026-01-16T14:27:04.418606", "market_id": "0x9472be65457510b7fc3477b20ba90910e99d92eac8421a14bf4b7b7a08ef31dc", "raw": {"market": "0x9472be65457510b7fc3477b20ba90910e99d92eac8421a14bf4b7b7a08ef31dc", "asset_id": "43311793366960417907757893276427136943959788721376762326430771171648759300146", "price": "0.824", "size": "10", "side": "BUY", "timestamp": "1768573575913", "received_at": "2026-01-16T14:26:15.951347"}}
{"event_type": "price_change", "event_ts": "2026-01-16T14:26:15.951347", "ingestion_ts": "2026-01-16T14:27:04.418606", "market_id": "0x9472be65457510b7fc3477b20ba90910e99d92eac8421a14bf4b7b7a08ef31dc", "raw": {"market": "0x9472be65457510b7fc3477b20ba90910e99d92eac8421a14bf4b7b7a08ef31dc", "asset_id": "73414222381656326204771753454630063673548497164758947581648273905027617570612", "price": "0.176", "size": "10", "side": "SELL", "timestamp": "1768573575913", "received_at": "2026-01-16T14:26:15.951347"}}
{"event_type": "price_change", "event_ts": "2026-01-16T14:26:15.952078", "ingestion_ts": "2026-01-16T14:27:04.418606", "market_id": "0x49a20c7523c271099008f3ef9a31521263b24d637959852a391e6b4697b1a437", "raw": {"market": "0x49a20c7523c271099008f3ef9a31521263b24d637959852a391e6b4697b1a437", "asset_id": "55881023621710858558280545117465775643848233756850602339827152783696837905531", "price": "0.847", "size": "10", "side": "BUY", "timestamp": "1768573575912", "received_at": "2026-01-16T14:26:15.952078"}}
{"event_type": "price_change", "event_ts": "2026-01-16T14:26:15.952078", "ingestion_ts": "2026-01-16T14:27:04.418606", "market_id": "0x49a20c7523c271099008f3ef9a31521263b24d637959852a391e6b4697b1a437", "raw": {"market": "0x49a20c7523c271099008f3ef9a31521263b24d637959852a391e6b4697b1a437", "asset_id": "13018971792603393862521629014128024641178044618205296260525674415067194037856", "price": "0.153", "size": "10", "side": "SELL", "timestamp": "1768573575912", "received_at": "2026-01-16T14:26:15.952078"}}
{"event_type": "price_change", "event_ts": "2026-01-16T14:26:15.952473", "ingestion_ts": "2026-01-16T14:27:04.418606", "market_id": "0xc55db914f0fd1fee18997706712c0dfd8d0369cdbef93a9fef12bd001914ca77", "raw": {"market": "0xc55db914f0fd1fee18997706712c0dfd8d0369cdbef93a9fef12bd001914ca77", "asset_id": "114600293444080540179603459515770723592661967180480327891296353898330242622833", "price": "0.837", "size": "10", "side": "BUY", "timestamp": "1768573575913", "received_at": "2026-01-16T14:26:15.952473"}}
{"event_type": "price_change", "event_ts": "2026-01-16T14:26:15.952473", "ingestion_ts": "2026-01-16T14:27:04.418606", "market_id": "0xc55db914f0fd1fee18997706712c0dfd8d0369cdbef93a9fef12bd001914ca77", "raw": {"market": "0xc55db914f0fd1fee18997706712c0dfd8d0369cdbef93a9fef12bd001914ca77", "asset_id": "72354723612769247426741660426331235762851940382312402276325808095604519806766", "price": "0.163", "size": "10", "side": "SELL", "timestamp": "1768573575913", "received_at": "2026-01-16T14:26:15.952473"}}
{"event_type": "price_change", "event_ts": "2026-01-16T14:26:19.417722", "ingestion_ts": "2026-01-16T14:27:04.418606", "market_id": "0xaf9d0e448129a9f657f851d49495ba4742055d80e0ef1166ba0ee81d4d594214", "raw": {"market": "0xaf9d0e448129a9f657f851d49495ba4742055d80e0ef1166ba0ee81d4d594214", "asset_id": "4153292802911610701832309484716814274802943278345248636922528170020319407796", "price": "0.987", "size": "140.01", "side": "SELL", "timestamp": "1768573579377", "received_at": "2026-01-16T14:26:19.417722"}}
{"event_type": "price_change", "event_ts": "2026-01-16T14:26:19.417722", "ingestion_ts": "2026-01-16T14:27:04.418606", "market_id": "0xaf9d0e448129a9f657f851d49495ba4742055d80e0ef1166ba0ee81d4d594214", "raw": {"market": "0xaf9d0e448129a9f657f851d49495ba4742055d80e0ef1166ba0ee81d4d594214", "asset_id": "101676997363687199724245607342877036148401850938023978421879460310389391082353", "price": "0.013", "size": "140.01", "side": "BUY", "timestamp": "1768573579377", "received_at": "2026-01-16T14:26:19.417722"}}
{"event_type": "price_change", "event_ts": "2026-01-16T14:26:20.626801", "ingestion_ts": "2026-01-16T14:27:04.418606", "market_id": "0xaf9d0e448129a9f657f851d49495ba4742055d80e0ef1166ba0ee81d4d594214", "raw": {"market": "0xaf9d0e448129a9f657f851d49495ba4742055d80e0ef1166ba0ee81d4d594214", "asset_id": "4153292802911610701832309484716814274802943278345248636922528170020319407796", "price": "0.989", "size": "0", "side": "SELL", "timestamp": "1768573580588", "received_at": "2026-01-16T14:26:20.626801"}}
{"event_type": "price_change", "event_ts": "2026-01-16T14:26:20.626801", "ingestion_ts": "2026-01-16T14:27:04.418606", "market_id": "0xaf9d0e448129a9f657f851d49495ba4742055d80e0ef1166ba0ee81d4d594214", "raw": {"market": "0xaf9d0e448129a9f657f851d49495ba4742055d80e0ef1166ba0ee81d4d594214", "asset_id": "101676997363687199724245607342877036148401850938023978421879460310389391082353", "price": "0.011", "size": "0", "side": "BUY", "timestamp": "1768573580588", "received_at": "2026-01-16T14:26:20.626801"}}
{"event_type": "price_change", "event_ts": "2026-01-16T14:26:20.676724", "ingestion_ts": "2026-01-16T14:27:04.418606", "market_id": "0xaf9d0e448129a9f657f851d49495ba4742055d80e0ef1166ba0ee81d4d594214", "raw": {"market": "0xaf9d0e448129a9f657f851d49495ba4742055d80e0ef1166ba0ee81d4d594214", "asset_id": "4153292802911610701832309484716814274802943278345248636922528170020319407796", "price": "0.986", "size": "20.5", "side": "SELL", "timestamp": "1768573580631", "received_at": "2026-01-16T14:26:20.676724"}}
{"event_type": "price_change", "event_ts": "2026-01-16T14:26:20.676724", "ingestion_ts": "2026-01-16T14:27:04.418606", "market_id": "0xaf9d0e448129a9f657f851d49495ba4742055d80e0ef1166ba0ee81d4d594214", "raw": {"market": "0xaf9d0e448129a9f657f851d49495ba4742055d80e0ef1166ba0ee81d4d594214", "asset_id": "101676997363687199724245607342877036148401850938023978421879460310389391082353", "price": "0.014", "size": "20.5", "side": "BUY", "timestamp": "1768573580631", "received_at": "2026-01-16T14:26:20.676724"}}
{"event_type": "price_change", "event_ts": "2026-01-16T14:26:21.314441", "ingestion_ts": "2026-01-16T14:27:04.418606", "market_id": "0x49686d26fb712515cd5e12c23f0a1c7e10214c7faa3cb0a730aabe0c33694082", "raw": {"market": "0x49686d26fb712515cd5e12c23f0a1c7e10214c7faa3cb0a730aabe0c33694082", "asset_id": "13244681086321087932946246027856416106585284024824496763706748621681543444582", "price": "0.854", "size": "0", "side": "BUY", "timestamp": "1768573581273", "received_at": "2026-01-16T14:26:21.314441"}}
{"event_type": "price_change", "event_ts": "2026-01-16T14:26:21.314441", "ingestion_ts": "2026-01-16T14:27:04.418606", "market_id": "0x49686d26fb712515cd5e12c23f0a1c7e10214c7faa3cb0a730aabe0c33694082", "raw": {"market": "0x49686d26fb712515cd5e12c23f0a1c7e10214c7faa3cb0a730aabe0c33694082", "asset_id": "30442780799048074404860985387051749017905070253466005720364298335239299761065", "price": "0.146", "size": "0", "side": "SELL", "timestamp": "1768573581273", "received_at": "2026-01-16T14:26:21.314441"}}
{"event_type": "price_change", "event_ts": "2026-01-16T14:26:21.339473", "ingestion_ts": "2026-01-16T14:27:04.418606", "market_id": "0x49686d26fb712515cd5e12c23f0a1c7e10214c7faa3cb0a730aabe0c33694082", "raw": {"market": "0x49686d26fb712515cd5e12c23f0a1c7e10214c7faa3cb0a730aabe0c33694082", "asset_id": "13244681086321087932946246027856416106585284024824496763706748621681543444582", "price": "0.911", "size": "132.98", "side": "SELL", "timestamp": "1768573581301", "received_at": "2026-01-16T14:26:21.339473"}}
{"event_type": "price_change", "event_ts": "2026-01-16T14:26:21.339473", "ingestion_ts": "2026-01-16T14:27:04.418606", "market_id": "0x49686d26fb712515cd5e12c23f0a1c7e10214c7faa3cb0a730aabe0c33694082", "raw": {"market": "0x49686d26fb712515cd5e12c23f0a1c7e10214c7faa3cb0a730aabe0c33694082", "asset_id": "30442780799048074404860985387051749017905070253466005720364298335239299761065", "price": "0.089", "size": "132.98", "side": "BUY", "timestamp": "1768573581301", "received_at": "2026-01-16T14:26:21.339473"}}
{"event_type": "price_change", "event_ts": "2026-01-16T14:26:21.834223", "ingestion_ts": "2026-01-16T14:27:04.418606", "market_id": "0xc0e6b917320a47228fb96e3b5ae0e5c93773a5ae2662ae4e1f37807cfe47ce98", "raw": {"market": "0xc0e6b917320a47228fb96e3b5ae0e5c93773a5ae2662ae4e1f37807cfe47ce98", "asset_id": "58656358377246279051017109359677190749228949103591068167284263961542487110215", "price": "0.002", "size": "3273.26", "side": "BUY", "timestamp": "1768573581796", "received_at": "2026-01-16T14:26:21.834223"}}
{"event_type": "price_change", "event_ts": "2026-01-16T14:26:21.834223", "ingestion_ts": "2026-01-16T14:27:04.418606", "market_id": "0xc0e6b917320a47228fb96e3b5ae0e5c93773a5ae2662ae4e1f37807cfe47ce98", "raw": {"market": "0xc0e6b917320a47228fb96e3b5ae0e5c93773a5ae2662ae4e1f37807cfe47ce98", "asset_id": "81647294538046680798858716589766492074338758116170717123345952330712416337530", "price": "0.998", "size": "3273.26", "side": "SELL", "timestamp": "1768573581796", "received_at": "2026-01-16T14:26:21.834223"}}
{"event_type": "price_change", "event_ts": "2026-01-16T14:26:23.095432", "ingestion_ts": "2026-01-16T14:27:04.418606", "market_id": "0xc0e6b917320a47228fb96e3b5ae0e5c93773a5ae2662ae4e1f37807cfe47ce98", "raw": {"market": "0xc0e6b917320a47228fb96e3b5ae0e5c93773a5ae2662ae4e1f37807cfe47ce98", "asset_id": "58656358377246279051017109359677190749228949103591068167284263961542487110215", "price": "0.002", "size": "3266.03", "side": "BUY", "timestamp": "1768573583057", "received_at": "2026-01-16T14:26:23.095432"}}
{"event_type": "price_change", "event_ts": "2026-01-16T14:26:23.095432", "ingestion_ts": "2026-01-16T14:27:04.418606", "market_id": "0xc0e6b917320a47228fb96e3b5ae0e5c93773a5ae2662ae4e1f37807cfe47ce98", "raw": {"market": "0xc0e6b917320a47228fb96e3b5ae0e5c93773a5ae2662ae4e1f37807cfe47ce98", "asset_id": "81647294538046680798858716589766492074338758116170717123345952330712416337530", "price": "0.998", "size": "3266.03", "side": "SELL", "timestamp": "1768573583057", "received_at": "2026-01-16T14:26:23.095432"}}
{"event_type": "price_change", "event_ts": "2026-01-16T14:26:23.360516", "ingestion_ts": "2026-01-16T14:27:04.418606", "market_id": "0xc0e6b917320a47228fb96e3b5ae0e5c93773a5ae2662ae4e1f37807cfe47ce98", "raw": {"market": "0xc0e6b917320a47228fb96e3b5ae0e5c93773a5ae2662ae4e1f37807cfe47ce98", "asset_id": "58656358377246279051017109359677190749228949103591068167284263961542487110215", "price": "0.002", "size": "3273.26", "side": "BUY", "timestamp": "1768573583321", "received_at": "2026-01-16T14:26:23.360516"}}
{"event_type": "price_change", "event_ts": "2026-01-16T14:26:23.360516", "ingestion_ts": "2026-01-16T14:27:04.418606", "market_id": "0xc0e6b917320a47228fb96e3b5ae0e5c93773a5ae2662ae4e1f37807cfe47ce98", "raw": {"market": "0xc0e6b917320a47228fb96e3b5ae0e5c93773a5ae2662ae4e1f37807cfe47ce98", "asset_id": "81647294538046680798858716589766492074338758116170717123345952330712416337530", "price": "0.998", "size": "3273.26", "side": "SELL", "timestamp": "1768573583321", "received_at": "2026-01-16T14:26:23.360516"}}
{"event_type": "price_change", "event_ts": "2026-01-16T14:26:23.361050", "ingestion_ts": "2026-01-16T14:27:04.418606", "market_id": "0xc0e6b917320a47228fb96e3b5ae0e5c93773a5ae2662ae4e1f37807cfe47ce98", "raw": {"market": "0xc0e6b917320a47228fb96e3b5ae0e5c93773a5ae2662ae4e1f37807cfe47ce98", "asset_id": "58656358377246279051017109359677190749228949103591068167284263961542487110215", "price": "0.002", "size": "3280.49", "side": "BUY", "timestamp": "1768573583322", "received_at": "2026-01-16T14:26:23.361050"}}
{"event_type": "price_change", "event_ts": "2026-01-16T14:26:23.361050", "ingestion_ts": "2026-01-16T14:27:04.418606", "market_id": "0xc0e6b917320a47228fb96e3b5ae0e5c93773a5ae2662ae4e1f37807cfe47ce98", "raw": {"market": "0xc0e6b917320a47228fb96e3b5ae0e5c93773a5ae2662ae4e1f37807cfe47ce98", "asset_id": "81647294538046680798858716589766492074338758116170717123345952330712416337530", "price": "0.998", "size": "3280.49", "side": "SELL", "timestamp": "1768573583322", "received_at": "2026-01-16T14:26:23.361050"}}
{"event_type": "price_change", "event_ts": "2026-01-16T14:26:23.607205", "ingestion_ts": "2026-01-16T14:27:04.418606", "market_id": "0xae5584fbb57f23c1c608d544b656f23d8bf12340cef70811cf31bb0cb4fc2115", "raw": {"market": "0xae5584fbb57f23c1c608d544b656f23d8bf12340cef70811cf31bb0cb4fc2115", "asset_id": "28946595841244317705636126646676849578876740730186646421280828201004700559420", "price": "0.01", "size": "8193.2", "side": "BUY", "timestamp": "1768573583510", "received_at": "2026-01-16T14:26:23.607205"}}
{"event_type": "price_change", "event_ts": "2026-01-16T14:26:23.607205", "ingestion_ts": "2026-01-16T14:27:04.418606", "market_id": "0xae5584fbb57f23c1c608d544b656f23d8bf12340cef70811cf31bb0cb4fc2115", "raw": {"market": "0xae5584fbb57f23c1c608d544b656f23d8bf12340cef70811cf31bb0cb4fc2115", "asset_id": "42278252558046940014991595990628759801692726198478046188873057685686228021663", "price": "0.99", "size": "8193.2", "side": "SELL", "timestamp": "1768573583510", "received_at": "2026-01-16T14:26:23.607205"}}
{"event_type": "price_change", "event_ts": "2026-01-16T14:26:23.677116", "ingestion_ts": "2026-01-16T14:27:04.418606", "market_id": "0xae5584fbb57f23c1c608d544b656f23d8bf12340cef70811cf31bb0cb4fc2115", "raw": {"market": "0xae5584fbb57f23c1c608d544b656f23d8bf12340cef70811cf31bb0cb4fc2115", "asset_id": "28946595841244317705636126646676849578876740730186646421280828201004700559420", "price": "0.01", "size": "8145.4", "side": "BUY", "timestamp": "1768573583620", "received_at": "2026-01-16T14:26:23.677116"}}
{"event_type": "price_change", "event_ts": "2026-01-16T14:26:23.677116", "ingestion_ts": "2026-01-16T14:27:04.418606", "market_id": "0xae5584fbb57f23c1c608d544b656f23d8bf12340cef70811cf31bb0cb4fc2115", "raw": {"market": "0xae5584fbb57f23c1c608d544b656f23d8bf12340cef70811cf31bb0cb4fc2115", "asset_id": "42278252558046940014991595990628759801692726198478046188873057685686228021663", "price": "0.99", "size": "8145.4", "side": "SELL", "timestamp": "1768573583620", "received_at": "2026-01-16T14:26:23.677116"}}
{"event_type": "price_change", "event_ts": "2026-01-16T14:26:23.764153", "ingestion_ts": "2026-01-16T14:27:04.418606", "market_id": "0xae5584fbb57f23c1c608d544b656f23d8bf12340cef70811cf31bb0cb4fc2115", "raw": {"market": "0xae5584fbb57f23c1c608d544b656f23d8bf12340cef70811cf31bb0cb4fc2115", "asset_id": "28946595841244317705636126646676849578876740730186646421280828201004700559420", "price": "0.01", "size": "8097.6", "side": "BUY", "timestamp": "1768573583723", "received_at": "2026-01-16T14:26:23.764153"}}
{"event_type": "price_change", "event_ts": "2026-01-16T14:26:23.764153", "ingestion_ts": "2026-01-16T14:27:04.418606", "market_id": "0xae5584fbb57f23c1c608d544b656f23d8bf12340cef70811cf31bb0cb4fc2115", "raw": {"market": "0xae5584fbb57f23c1c608d544b656f23d8bf12340cef70811cf31bb0cb4fc2115", "asset_id": "42278252558046940014991595990628759801692726198478046188873057685686228021663", "price": "0.99", "size": "8097.6", "side": "SELL", "timestamp": "1768573583723", "received_at": "2026-01-16T14:26:23.764153"}}
{"event_type": "price_change", "event_ts": "2026-01-16T14:26:25.400387", "ingestion_ts": "2026-01-16T14:27:04.418606", "market_id": "0xaf9d0e448129a9f657f851d49495ba4742055d80e0ef1166ba0ee81d4d594214", "raw": {"market": "0xaf9d0e448129a9f657f851d49495ba4742055d80e0ef1166ba0ee81d4d594214", "asset_id": "4153292802911610701832309484716814274802943278345248636922528170020319407796", "price": "0.987", "size": "0", "side": "SELL", "timestamp": "1768573585359", "received_at": "2026-01-16T14:26:25.400387"}}
{"event_type": "price_change", "event_ts": "2026-01-16T14:26:25.400387", "ingestion_ts": "2026-01-16T14:27:04.418606", "market_id": "0xaf9d0e448129a9f657f851d49495ba4742055d80e0ef1166ba0ee81d4d594214", "raw": {"market": "0xaf9d0e448129a9f657f851d49495ba4742055d80e0ef1166ba0ee81d4d594214", "asset_id": "101676997363687199724245607342877036148401850938023978421879460310389391082353", "price": "0.013", "size": "0", "side": "BUY", "timestamp": "1768573585359", "received_at": "2026-01-16T14:26:25.400387"}}
{"event_type": "price_change", "event_ts": "2026-01-16T14:26:25.733497", "ingestion_ts": "2026-01-16T14:27:04.418606", "market_id": "0xaf9d0e448129a9f657f851d49495ba4742055d80e0ef1166ba0ee81d4d594214", "raw": {"market": "0xaf9d0e448129a9f657f851d49495ba4742055d80e0ef1166ba0ee81d4d594214", "asset_id": "4153292802911610701832309484716814274802943278345248636922528170020319407796", "price": "0.985", "size": "140.01", "side": "SELL", "timestamp": "1768573585693", "received_at": "2026-01-16T14:26:25.733497"}}
{"event_type": "price_change", "event_ts": "2026-01-16T14:26:25.733497", "ingestion_ts": "2026-01-16T14:27:04.418606", "market_id": "0xaf9d0e448129a9f657f851d49495ba4742055d80e0ef1166ba0ee81d4d594214", "raw": {"market": "0xaf9d0e448129a9f657f851d49495ba4742055d80e0ef1166ba0ee81d4d594214", "asset_id": "101676997363687199724245607342877036148401850938023978421879460310389391082353", "price": "0.015", "size": "140.01", "side": "BUY", "timestamp": "1768573585693", "received_at": "2026-01-16T14:26:25.733497"}}
{"event_type": "price_change", "event_ts": "2026-01-16T14:26:28.289225", "ingestion_ts": "2026-01-16T14:27:04.418606", "market_id": "0xaf9d0e448129a9f657f851d49495ba4742055d80e0ef1166ba0ee81d4d594214", "raw": {"market": "0xaf9d0e448129a9f657f851d49495ba4742055d80e0ef1166ba0ee81d4d594214", "asset_id": "4153292802911610701832309484716814274802943278345248636922528170020319407796", "price": "0.986", "size": "0", "side": "SELL", "timestamp": "1768573588250", "received_at": "2026-01-16T14:26:28.289225"}}
{"event_type": "price_change", "event_ts": "2026-01-16T14:26:28.289225", "ingestion_ts": "2026-01-16T14:27:04.418606", "market_id": "0xaf9d0e448129a9f657f851d49495ba4742055d80e0ef1166ba0ee81d4d594214", "raw": {"market": "0xaf9d0e448129a9f657f851d49495ba4742055d80e0ef1166ba0ee81d4d594214", "asset_id": "101676997363687199724245607342877036148401850938023978421879460310389391082353", "price": "0.014", "size": "0", "side": "BUY", "timestamp": "1768573588250", "received_at": "2026-01-16T14:26:28.289225"}}
{"event_type": "price_change", "event_ts": "2026-01-16T14:26:28.495451", "ingestion_ts": "2026-01-16T14:27:04.418606", "market_id": "0xaf9d0e448129a9f657f851d49495ba4742055d80e0ef1166ba0ee81d4d594214", "raw": {"market": "0xaf9d0e448129a9f657f851d49495ba4742055d80e0ef1166ba0ee81d4d594214", "asset_id": "4153292802911610701832309484716814274802943278345248636922528170020319407796", "price": "0.984", "size": "20.5", "side": "SELL", "timestamp": "1768573588442", "received_at": "2026-01-16T14:26:28.495451"}}
{"event_type": "price_change", "event_ts": "2026-01-16T14:26:28.495451", "ingestion_ts": "2026-01-16T14:27:04.418606", "market_id": "0xaf9d0e448129a9f657f851d49495ba4742055d80e0ef1166ba0ee81d4d594214", "raw": {"market": "0xaf9d0e448129a9f657f851d49495ba4742055d80e0ef1166ba0ee81d4d594214", "asset_id": "101676997363687199724245607342877036148401850938023978421879460310389391082353", "price": "0.016", "size": "20.5", "side": "BUY", "timestamp": "1768573588442", "received_at": "2026-01-16T14:26:28.495451"}}
{"event_type": "price_change", "event_ts": "2026-01-16T14:26:28.505568", "ingestion_ts": "2026-01-16T14:27:04.418606", "market_id": "0x49686d26fb712515cd5e12c23f0a1c7e10214c7faa3cb0a730aabe0c33694082", "raw": {"market": "0x49686d26fb712515cd5e12c23f0a1c7e10214c7faa3cb0a730aabe0c33694082", "asset_id": "13244681086321087932946246027856416106585284024824496763706748621681543444582", "price": "0.853", "size": "50.86", "side": "BUY", "timestamp": "1768573588454", "received_at": "2026-01-16T14:26:28.505568"}}
{"event_type": "price_change", "event_ts": "2026-01-16T14:26:28.505568", "ingestion_ts": "2026-01-16T14:27:04.418606", "market_id": "0x49686d26fb712515cd5e12c23f0a1c7e10214c7faa3cb0a730aabe0c33694082", "raw": {"market": "0x49686d26fb712515cd5e12c23f0a1c7e10214c7faa3cb0a730aabe0c33694082", "asset_id": "30442780799048074404860985387051749017905070253466005720364298335239299761065", "price": "0.147", "size": "50.86", "side": "SELL", "timestamp": "1768573588454", "received_at": "2026-01-16T14:26:28.505568"}}
{"event_type": "price_change", "event_ts": "2026-01-16T14:26:29.406581", "ingestion_ts": "2026-01-16T14:27:04.418606", "market_id": "0x49686d26fb712515cd5e12c23f0a1c7e10214c7faa3cb0a730aabe0c33694082", "raw": {"market": "0x49686d26fb712515cd5e12c23f0a1c7e10214c7faa3cb0a730aabe0c33694082", "asset_id": "30442780799048074404860985387051749017905070253466005720364298335239299761065", "price": "0.148", "size": "0", "side": "SELL", "timestamp": "1768573589366", "received_at": "2026-01-16T14:26:29.406581"}}
{"event_type": "price_change", "event_ts": "2026-01-16T14:26:29.406581", "ingestion_ts": "2026-01-16T14:27:04.418606", "market_id": "0x49686d26fb712515cd5e12c23f0a1c7e10214c7faa3cb0a730aabe0c33694082", "raw": {"market": "0x49686d26fb712515cd5e12c23f0a1c7e10214c7faa3cb0a730aabe0c33694082", "asset_id": "13244681086321087932946246027856416106585284024824496763706748621681543444582", "price": "0.852", "size": "0", "side": "BUY", "timestamp": "1768573589366", "received_at": "2026-01-16T14:26:29.406581"}}
{"event_type": "price_change", "event_ts": "2026-01-16T14:26:29.458562", "ingestion_ts": "2026-01-16T14:27:04.418606", "market_id": "0x49686d26fb712515cd5e12c23f0a1c7e10214c7faa3cb0a730aabe0c33694082", "raw": {"market": "0x49686d26fb712515cd5e12c23f0a1c7e10214c7faa3cb0a730aabe0c33694082", "asset_id": "30442780799048074404860985387051749017905070253466005720364298335239299761065", "price": "0.146", "size": "17.5", "side": "SELL", "timestamp": "1768573589410", "received_at": "2026-01-16T14:26:29.458562"}}
{"event_type": "price_change", "event_ts": "2026-01-16T14:26:29.458562", "ingestion_ts": "2026-01-16T14:27:04.418606", "market_id": "0x49686d26fb712515cd5e12c23f0a1c7e10214c7faa3cb0a730aabe0c33694082", "raw": {"market": "0x49686d26fb712515cd5e12c23f0a1c7e10214c7faa3cb0a730aabe0c33694082", "asset_id": "13244681086321087932946246027856416106585284024824496763706748621681543444582", "price": "0.854", "size": "17.5", "side": "BUY", "timestamp": "1768573589410", "received_at": "2026-01-16T14:26:29.458562"}}
{"event_type": "price_change", "event_ts": "2026-01-16T14:26:29.481838", "ingestion_ts": "2026-01-16T14:27:04.418606", "market_id": "0x49686d26fb712515cd5e12c23f0a1c7e10214c7faa3cb0a730aabe0c33694082", "raw": {"market": "0x49686d26fb712515cd5e12c23f0a1c7e10214c7faa3cb0a730aabe0c33694082", "asset_id": "13244681086321087932946246027856416106585284024824496763706748621681543444582", "price": "0.911", "size": "14.98", "side": "SELL", "timestamp": "1768573589440", "received_at": "2026-01-16T14:26:29.481838"}}
{"event_type": "price_change", "event_ts": "2026-01-16T14:26:29.481838", "ingestion_ts": "2026-01-16T14:27:04.418606", "market_id": "0x49686d26fb712515cd5e12c23f0a1c7e10214c7faa3cb0a730aabe0c33694082", "raw": {"market": "0x49686d26fb712515cd5e12c23f0a1c7e10214c7faa3cb0a730aabe0c33694082", "asset_id": "30442780799048074404860985387051749017905070253466005720364298335239299761065", "price": "0.089", "size": "14.98", "side": "BUY", "timestamp": "1768573589440", "received_at": "2026-01-16T14:26:29.481838"}}
{"event_type": "price_change", "event_ts": "2026-01-16T14:26:29.805951", "ingestion_ts": "2026-01-16T14:27:04.418606", "market_id": "0xc0e6b917320a47228fb96e3b5ae0e5c93773a5ae2662ae4e1f37807cfe47ce98", "raw": {"market": "0xc0e6b917320a47228fb96e3b5ae0e5c93773a5ae2662ae4e1f37807cfe47ce98", "asset_id": "81647294538046680798858716589766492074338758116170717123345952330712416337530", "price": "0.993", "size": "0", "side": "SELL", "timestamp": "1768573589758", "received_at": "2026-01-16T14:26:29.805951"}}
{"event_type": "price_change", "event_ts": "2026-01-16T14:26:29.805951", "ingestion_ts": "2026-01-16T14:27:04.418606", "market_id": "0xc0e6b917320a47228fb96e3b5ae0e5c93773a5ae2662ae4e1f37807cfe47ce98", "raw": {"market": "0xc0e6b917320a47228fb96e3b5ae0e5c93773a5ae2662ae4e1f37807cfe47ce98", "asset_id": "58656358377246279051017109359677190749228949103591068167284263961542487110215", "price": "0.007", "size": "0", "side": "BUY", "timestamp": "1768573589758", "received_at": "2026-01-16T14:26:29.805951"}}
{"event_type": "price_change", "event_ts": "2026-01-16T14:26:29.805996", "ingestion_ts": "2026-01-16T14:27:04.418606", "market_id": "0xc0e6b917320a47228fb96e3b5ae0e5c93773a5ae2662ae4e1f37807cfe47ce98", "raw": {"market": "0xc0e6b917320a47228fb96e3b5ae0e5c93773a5ae2662ae4e1f37807cfe47ce98", "asset_id": "81647294538046680798858716589766492074338758116170717123345952330712416337530", "price": "0.93", "size": "0", "side": "BUY", "timestamp": "1768573589758", "received_at": "2026-01-16T14:26:29.805996"}}
{"event_type": "price_change", "event_ts": "2026-01-16T14:26:29.805996", "ingestion_ts": "2026-01-16T14:27:04.418606", "market_id": "0xc0e6b917320a47228fb96e3b5ae0e5c93773a5ae2662ae4e1f37807cfe47ce98", "raw": {"market": "0xc0e6b917320a47228fb96e3b5ae0e5c93773a5ae2662ae4e1f37807cfe47ce98", "asset_id": "58656358377246279051017109359677190749228949103591068167284263961542487110215", "price": "0.07", "size": "0", "side": "SELL", "timestamp": "1768573589758", "received_at": "2026-01-16T14:26:29.805996"}}
{"event_type": "price_change", "event_ts": "2026-01-16T14:26:29.876383", "ingestion_ts": "2026-01-16T14:27:04.418606", "market_id": "0x49686d26fb712515cd5e12c23f0a1c7e10214c7faa3cb0a730aabe0c33694082", "raw": {"market": "0x49686d26fb712515cd5e12c23f0a1c7e10214c7faa3cb0a730aabe0c33694082", "asset_id": "13244681086321087932946246027856416106585284024824496763706748621681543444582", "price": "0.853", "size": "5.86", "side": "BUY", "timestamp": "1768573589760", "received_at": "2026-01-16T14:26:29.876383"}}
{"event_type": "price_change", "event_ts": "2026-01-16T14:26:29.876383", "ingestion_ts": "2026-01-16T14:27:04.418606", "market_id": "0x49686d26fb712515cd5e12c23f0a1c7e10214c7faa3cb0a730aabe0c33694082", "raw": {"market": "0x49686d26fb712515cd5e12c23f0a1c7e10214c7faa3cb0a730aabe0c33694082", "asset_id": "30442780799048074404860985387051749017905070253466005720364298335239299761065", "price": "0.147", "size": "5.86", "side": "SELL", "timestamp": "1768573589760", "received_at": "2026-01-16T14:26:29.876383"}}
{"event_type": "price_change", "event_ts": "2026-01-16T14:26:30.052256", "ingestion_ts": "2026-01-16T14:27:04.418606", "market_id": "0xae5584fbb57f23c1c608d544b656f23d8bf12340cef70811cf31bb0cb4fc2115", "raw": {"market": "0xae5584fbb57f23c1c608d544b656f23d8bf12340cef70811cf31bb0cb4fc2115", "asset_id": "42278252558046940014991595990628759801692726198478046188873057685686228021663", "price": "0.99", "size": "8199.8", "side": "SELL", "timestamp": "1768573589910", "received_at": "2026-01-16T14:26:30.052256"}}
{"event_type": "price_change", "event_ts": "2026-01-16T14:26:30.052256", "ingestion_ts": "2026-01-16T14:27:04.418606", "market_id": "0xae5584fbb57f23c1c608d544b656f23d8bf12340cef70811cf31bb0cb4fc2115", "raw": {"market": "0xae5584fbb57f23c1c608d544b656f23d8bf12340cef70811cf31bb0cb4fc2115", "asset_id": "28946595841244317705636126646676849578876740730186646421280828201004700559420", "price": "0.01", "size": "8199.8", "side": "BUY", "timestamp": "1768573589910", "received_at": "2026-01-16T14:26:30.052256"}}
{"event_type": "price_change", "event_ts": "2026-01-16T14:26:30.105390", "ingestion_ts": "2026-01-16T14:27:04.418606", "market_id": "0xc0e6b917320a47228fb96e3b5ae0e5c93773a5ae2662ae4e1f37807cfe47ce98", "raw": {"market": "0xc0e6b917320a47228fb96e3b5ae0e5c93773a5ae2662ae4e1f37807cfe47ce98", "asset_id": "58656358377246279051017109359677190749228949103591068167284263961542487110215", "price": "0.002", "size": "3273.26", "side": "BUY", "timestamp": "1768573589986", "received_at": "2026-01-16T14:26:30.105390"}}
{"event_type": "price_change", "event_ts": "2026-01-16T14:26:30.105390", "ingestion_ts": "2026-01-16T14:27:04.418606", "market_id": "0xc0e6b917320a47228fb96e3b5ae0e5c93773a5ae2662ae4e1f37807cfe47ce98", "raw": {"market": "0xc0e6b917320a47228fb96e3b5ae0e5c93773a5ae2662ae4e1f37807cfe47ce98", "asset_id": "81647294538046680798858716589766492074338758116170717123345952330712416337530", "price": "0.998", "size": "3273.26", "side": "SELL", "timestamp": "1768573589986", "received_at": "2026-01-16T14:26:30.105390"}}
{"event_type": "price_change", "event_ts": "2026-01-16T14:26:30.122496", "ingestion_ts": "2026-01-16T14:27:04.418606", "market_id": "0xae5584fbb57f23c1c608d544b656f23d8bf12340cef70811cf31bb0cb4fc2115", "raw": {"market": "0xae5584fbb57f23c1c608d544b656f23d8bf12340cef70811cf31bb0cb4fc2115", "asset_id": "28946595841244317705636126646676849578876740730186646421280828201004700559420", "price": "0.01", "size": "8247.6", "side": "BUY", "timestamp": "1768573590005", "received_at": "2026-01-16T14:26:30.122496"}}
{"event_type": "price_change", "event_ts": "2026-01-16T14:26:30.122496", "ingestion_ts": "2026-01-16T14:27:04.418606", "market_id": "0xae5584fbb57f23c1c608d544b656f23d8bf12340cef70811cf31bb0cb4fc2115", "raw": {"market": "0xae5584fbb57f23c1c608d544b656f23d8bf12340cef70811cf31bb0cb4fc2115", "asset_id": "42278252558046940014991595990628759801692726198478046188873057685686228021663", "price": "0.99", "size": "8247.6", "side": "SELL", "timestamp": "1768573590005", "received_at": "2026-01-16T14:26:30.122496"}}
{"event_type": "price_change", "event_ts": "2026-01-16T14:26:30.466314", "ingestion_ts": "2026-01-16T14:27:04.418606", "market_id": "0xc0e6b917320a47228fb96e3b5ae0e5c93773a5ae2662ae4e1f37807cfe47ce98", "raw": {"market": "0xc0e6b917320a47228fb96e3b5ae0e5c93773a5ae2662ae4e1f37807cfe47ce98", "asset_id": "58656358377246279051017109359677190749228949103591068167284263961542487110215", "price": "0.069", "size": "5.11", "side": "SELL", "timestamp": "1768573590424", "received_at": "2026-01-16T14:26:30.466314"}}
{"event_type": "price_change", "event_ts": "2026-01-16T14:26:30.466314", "ingestion_ts": "2026-01-16T14:27:04.418606", "market_id": "0xc0e6b917320a47228fb96e3b5ae0e5c93773a5ae2662ae4e1f37807cfe47ce98", "raw": {"market": "0xc0e6b917320a47228fb96e3b5ae0e5c93773a5ae2662ae4e1f37807cfe47ce98", "asset_id": "81647294538046680798858716589766492074338758116170717123345952330712416337530", "price": "0.931", "size": "5.11", "side": "BUY", "timestamp": "1768573590424", "received_at": "2026-01-16T14:26:30.466314"}}
{"event_type": "price_change", "event_ts": "2026-01-16T14:26:30.598973", "ingestion_ts": "2026-01-16T14:27:04.418606", "market_id": "0x49686d26fb712515cd5e12c23f0a1c7e10214c7faa3cb0a730aabe0c33694082", "raw": {"market": "0x49686d26fb712515cd5e12c23f0a1c7e10214c7faa3cb0a730aabe0c33694082", "asset_id": "30442780799048074404860985387051749017905070253466005720364298335239299761065", "price": "0.146", "size": "0", "side": "SELL", "timestamp": "1768573590543", "received_at": "2026-01-16T14:26:30.598973"}}
{"event_type": "price_change", "event_ts": "2026-01-16T14:26:30.598973", "ingestion_ts": "2026-01-16T14:27:04.418606", "market_id": "0x49686d26fb712515cd5e12c23f0a1c7e10214c7faa3cb0a730aabe0c33694082", "raw": {"market": "0x49686d26fb712515cd5e12c23f0a1c7e10214c7faa3cb0a730aabe0c33694082", "asset_id": "13244681086321087932946246027856416106585284024824496763706748621681543444582", "price": "0.854", "size": "0", "side": "BUY", "timestamp": "1768573590543", "received_at": "2026-01-16T14:26:30.598973"}}
{"event_type": "price_change", "event_ts": "2026-01-16T14:26:30.655461", "ingestion_ts": "2026-01-16T14:27:04.418606", "market_id": "0x49686d26fb712515cd5e12c23f0a1c7e10214c7faa3cb0a730aabe0c33694082", "raw": {"market": "0x49686d26fb712515cd5e12c23f0a1c7e10214c7faa3cb0a730aabe0c33694082", "asset_id": "13244681086321087932946246027856416106585284024824496763706748621681543444582", "price": "0.911", "size": "143.98", "side": "SELL", "timestamp": "1768573590576", "received_at": "2026-01-16T14:26:30.655461"}}
{"event_type": "price_change", "event_ts": "2026-01-16T14:26:30.655461", "ingestion_ts": "2026-01-16T14:27:04.418606", "market_id": "0x49686d26fb712515cd5e12c23f0a1c7e10214c7faa3cb0a730aabe0c33694082", "raw": {"market": "0x49686d26fb712515cd5e12c23f0a1c7e10214c7faa3cb0a730aabe0c33694082", "asset_id": "30442780799048074404860985387051749017905070253466005720364298335239299761065", "price": "0.089", "size": "143.98", "side": "BUY", "timestamp": "1768573590576", "received_at": "2026-01-16T14:26:30.655461"}}
{"event_type": "price_change", "event_ts": "2026-01-16T14:26:30.662546", "ingestion_ts": "2026-01-16T14:27:04.418606", "market_id": "0x49686d26fb712515cd5e12c23f0a1c7e10214c7faa3cb0a730aabe0c33694082", "raw": {"market": "0x49686d26fb712515cd5e12c23f0a1c7e10214c7faa3cb0a730aabe0c33694082", "asset_id": "30442780799048074404860985387051749017905070253466005720364298335239299761065", "price": "0.148", "size": "17.5", "side": "SELL", "timestamp": "1768573590590", "received_at": "2026-01-16T14:26:30.662546"}}
{"event_type": "price_change", "event_ts": "2026-01-16T14:26:30.662546", "ingestion_ts": "2026-01-16T14:27:04.418606", "market_id": "0x49686d26fb712515cd5e12c23f0a1c7e10214c7faa3cb0a730aabe0c33694082", "raw": {"market": "0x49686d26fb712515cd5e12c23f0a1c7e10214c7faa3cb0a730aabe0c33694082", "asset_id": "13244681086321087932946246027856416106585284024824496763706748621681543444582", "price": "0.852", "size": "17.5", "side": "BUY", "timestamp": "1768573590590", "received_at": "2026-01-16T14:26:30.662546"}}
{"event_type": "price_change", "event_ts": "2026-01-16T14:26:30.744225", "ingestion_ts": "2026-01-16T14:27:04.418606", "market_id": "0xb9bbdd34304344dcc45803780a34c97d73a00133a5ecf70f63e1008b8abb2fca", "raw": {"market": "0xb9bbdd34304344dcc45803780a34c97d73a00133a5ecf70f63e1008b8abb2fca", "asset_id": "8682484153073832526711485265636767086525069344085206423986003504588877767339", "price": "0.852", "size": "0", "side": "BUY", "timestamp": "1768573590706", "received_at": "2026-01-16T14:26:30.744225"}}
{"event_type": "price_change", "event_ts": "2026-01-16T14:26:30.744225", "ingestion_ts": "2026-01-16T14:27:04.418606", "market_id": "0xb9bbdd34304344dcc45803780a34c97d73a00133a5ecf70f63e1008b8abb2fca", "raw": {"market": "0xb9bbdd34304344dcc45803780a34c97d73a00133a5ecf70f63e1008b8abb2fca", "asset_id": "72012724360700510767037780555710363830014634797787940282136454146828040926557", "price": "0.148", "size": "0", "side": "SELL", "timestamp": "1768573590706", "received_at": "2026-01-16T14:26:30.744225"}}
{"event_type": "price_change", "event_ts": "2026-01-16T14:26:30.871073", "ingestion_ts": "2026-01-16T14:27:04.418606", "market_id": "0xb9bbdd34304344dcc45803780a34c97d73a00133a5ecf70f63e1008b8abb2fca", "raw": {"market": "0xb9bbdd34304344dcc45803780a34c97d73a00133a5ecf70f63e1008b8abb2fca", "asset_id": "8682484153073832526711485265636767086525069344085206423986003504588877767339", "price": "0.852", "size": "30", "side": "BUY", "timestamp": "1768573590808", "received_at": "2026-01-16T14:26:30.871073"}}
{"event_type": "price_change", "event_ts": "2026-01-16T14:26:30.871073", "ingestion_ts": "2026-01-16T14:27:04.418606", "market_id": "0xb9bbdd34304344dcc45803780a34c97d73a00133a5ecf70f63e1008b8abb2fca", "raw": {"market": "0xb9bbdd34304344dcc45803780a34c97d73a00133a5ecf70f63e1008b8abb2fca", "asset_id": "72012724360700510767037780555710363830014634797787940282136454146828040926557", "price": "0.148", "size": "30", "side": "SELL", "timestamp": "1768573590808", "received_at": "2026-01-16T14:26:30.871073"}}
{"event_type": "price_change", "event_ts": "2026-01-16T14:26:30.930283", "ingestion_ts": "2026-01-16T14:27:04.418606", "market_id": "0xc0e6b917320a47228fb96e3b5ae0e5c93773a5ae2662ae4e1f37807cfe47ce98", "raw": {"market": "0xc0e6b917320a47228fb96e3b5ae0e5c93773a5ae2662ae4e1f37807cfe47ce98", "asset_id": "58656358377246279051017109359677190749228949103591068167284263961542487110215", "price": "0.076", "size": "23.84", "side": "SELL", "timestamp": "1768573590878", "received_at": "2026-01-16T14:26:30.930283"}}
{"event_type": "price_change", "event_ts": "2026-01-16T14:26:30.930283", "ingestion_ts": "2026-01-16T14:27:04.418606", "market_id": "0xc0e6b917320a47228fb96e3b5ae0e5c93773a5ae2662ae4e1f37807cfe47ce98", "raw": {"market": "0xc0e6b917320a47228fb96e3b5ae0e5c93773a5ae2662ae4e1f37807cfe47ce98", "asset_id": "81647294538046680798858716589766492074338758116170717123345952330712416337530", "price": "0.924", "size": "23.84", "side": "BUY", "timestamp": "1768573590878", "received_at": "2026-01-16T14:26:30.930283"}}
{"event_type": "price_change", "event_ts": "2026-01-16T14:26:30.930344", "ingestion_ts": "2026-01-16T14:27:04.418606", "market_id": "0xc0e6b917320a47228fb96e3b5ae0e5c93773a5ae2662ae4e1f37807cfe47ce98", "raw": {"market": "0xc0e6b917320a47228fb96e3b5ae0e5c93773a5ae2662ae4e1f37807cfe47ce98", "asset_id": "58656358377246279051017109359677190749228949103591068167284263961542487110215", "price": "0.076", "size": "47.68", "side": "SELL", "timestamp": "1768573590878", "received_at": "2026-01-16T14:26:30.930344"}}
{"event_type": "price_change", "event_ts": "2026-01-16T14:26:30.930344", "ingestion_ts": "2026-01-16T14:27:04.418606", "market_id": "0xc0e6b917320a47228fb96e3b5ae0e5c93773a5ae2662ae4e1f37807cfe47ce98", "raw": {"market": "0xc0e6b917320a47228fb96e3b5ae0e5c93773a5ae2662ae4e1f37807cfe47ce98", "asset_id": "81647294538046680798858716589766492074338758116170717123345952330712416337530", "price": "0.924", "size": "47.68", "side": "BUY", "timestamp": "1768573590878", "received_at": "2026-01-16T14:26:30.930344"}}
{"event_type": "price_change", "event_ts": "2026-01-16T14:26:31.345902", "ingestion_ts": "2026-01-16T14:27:04.418606", "market_id": "0xaf9d0e448129a9f657f851d49495ba4742055d80e0ef1166ba0ee81d4d594214", "raw": {"market": "0xaf9d0e448129a9f657f851d49495ba4742055d80e0ef1166ba0ee81d4d594214", "asset_id": "4153292802911610701832309484716814274802943278345248636922528170020319407796", "price": "0.985", "size": "0", "side": "SELL", "timestamp": "1768573591292", "received_at": "2026-01-16T14:26:31.345902"}}
{"event_type": "price_change", "event_ts": "2026-01-16T14:26:31.345902", "ingestion_ts": "2026-01-16T14:27:04.418606", "market_id": "0xaf9d0e448129a9f657f851d49495ba4742055d80e0ef1166ba0ee81d4d594214", "raw": {"market": "0xaf9d0e448129a9f657f851d49495ba4742055d80e0ef1166ba0ee81d4d594214", "asset_id": "101676997363687199724245607342877036148401850938023978421879460310389391082353", "price": "0.015", "size": "0", "side": "BUY", "timestamp": "1768573591292", "received_at": "2026-01-16T14:26:31.345902"}}
{"event_type": "price_change", "event_ts": "2026-01-16T14:26:31.924559", "ingestion_ts": "2026-01-16T14:27:04.418606", "market_id": "0xaf9d0e448129a9f657f851d49495ba4742055d80e0ef1166ba0ee81d4d594214", "raw": {"market": "0xaf9d0e448129a9f657f851d49495ba4742055d80e0ef1166ba0ee81d4d594214", "asset_id": "4153292802911610701832309484716814274802943278345248636922528170020319407796", "price": "0.983", "size": "140.01", "side": "SELL", "timestamp": "1768573591881", "received_at": "2026-01-16T14:26:31.924559"}}
{"event_type": "price_change", "event_ts": "2026-01-16T14:26:31.924559", "ingestion_ts": "2026-01-16T14:27:04.418606", "market_id": "0xaf9d0e448129a9f657f851d49495ba4742055d80e0ef1166ba0ee81d4d594214", "raw": {"market": "0xaf9d0e448129a9f657f851d49495ba4742055d80e0ef1166ba0ee81d4d594214", "asset_id": "101676997363687199724245607342877036148401850938023978421879460310389391082353", "price": "0.017", "size": "140.01", "side": "BUY", "timestamp": "1768573591881", "received_at": "2026-01-16T14:26:31.924559"}}
{"event_type": "price_change", "event_ts": "2026-01-16T14:26:32.039228", "ingestion_ts": "2026-01-16T14:27:04.418606", "market_id": "0xaf9d0e448129a9f657f851d49495ba4742055d80e0ef1166ba0ee81d4d594214", "raw": {"market": "0xaf9d0e448129a9f657f851d49495ba4742055d80e0ef1166ba0ee81d4d594214", "asset_id": "4153292802911610701832309484716814274802943278345248636922528170020319407796", "price": "0.984", "size": "0", "side": "SELL", "timestamp": "1768573591992", "received_at": "2026-01-16T14:26:32.039228"}}
{"event_type": "price_change", "event_ts": "2026-01-16T14:26:32.039228", "ingestion_ts": "2026-01-16T14:27:04.418606", "market_id": "0xaf9d0e448129a9f657f851d49495ba4742055d80e0ef1166ba0ee81d4d594214", "raw": {"market": "0xaf9d0e448129a9f657f851d49495ba4742055d80e0ef1166ba0ee81d4d594214", "asset_id": "101676997363687199724245607342877036148401850938023978421879460310389391082353", "price": "0.016", "size": "0", "side": "BUY", "timestamp": "1768573591992", "received_at": "2026-01-16T14:26:32.039228"}}
{"event_type": "price_change", "event_ts": "2026-01-16T14:26:32.337319", "ingestion_ts": "2026-01-16T14:27:04.418606", "market_id": "0xaf9d0e448129a9f657f851d49495ba4742055d80e0ef1166ba0ee81d4d594214", "raw": {"market": "0xaf9d0e448129a9f657f851d49495ba4742055d80e0ef1166ba0ee81d4d594214", "asset_id": "4153292802911610701832309484716814274802943278345248636922528170020319407796", "price": "0.989", "size": "20.5", "side": "SELL", "timestamp": "1768573592278", "received_at": "2026-01-16T14:26:32.337319"}}
{"event_type": "price_change", "event_ts": "2026-01-16T14:26:32.337319", "ingestion_ts": "2026-01-16T14:27:04.418606", "market_id": "0xaf9d0e448129a9f657f851d49495ba4742055d80e0ef1166ba0ee81d4d594214", "raw": {"market": "0xaf9d0e448129a9f657f851d49495ba4742055d80e0ef1166ba0ee81d4d594214", "asset_id": "101676997363687199724245607342877036148401850938023978421879460310389391082353", "price": "0.011", "size": "20.5", "side": "BUY", "timestamp": "1768573592278", "received_at": "2026-01-16T14:26:32.337319"}}
{"event_type": "price_change", "event_ts": "2026-01-16T14:26:32.711290", "ingestion_ts": "2026-01-16T14:27:04.418606", "market_id": "0xc0e6b917320a47228fb96e3b5ae0e5c93773a5ae2662ae4e1f37807cfe47ce98", "raw": {"market": "0xc0e6b917320a47228fb96e3b5ae0e5c93773a5ae2662ae4e1f37807cfe47ce98", "asset_id": "58656358377246279051017109359677190749228949103591068167284263961542487110215", "price": "0.002", "size": "3266.03", "side": "BUY", "timestamp": "1768573592667", "received_at": "2026-01-16T14:26:32.711290"}}
{"event_type": "price_change", "event_ts": "2026-01-16T14:26:32.711290", "ingestion_ts": "2026-01-16T14:27:04.418606", "market_id": "0xc0e6b917320a47228fb96e3b5ae0e5c93773a5ae2662ae4e1f37807cfe47ce98", "raw": {"market": "0xc0e6b917320a47228fb96e3b5ae0e5c93773a5ae2662ae4e1f37807cfe47ce98", "asset_id": "81647294538046680798858716589766492074338758116170717123345952330712416337530", "price": "0.998", "size": "3266.03", "side": "SELL", "timestamp": "1768573592667", "received_at": "2026-01-16T14:26:32.711290"}}
{"event_type": "price_change", "event_ts": "2026-01-16T14:26:32.711339", "ingestion_ts": "2026-01-16T14:27:04.418606", "market_id": "0xc0e6b917320a47228fb96e3b5ae0e5c93773a5ae2662ae4e1f37807cfe47ce98", "raw": {"market": "0xc0e6b917320a47228fb96e3b5ae0e5c93773a5ae2662ae4e1f37807cfe47ce98", "asset_id": "58656358377246279051017109359677190749228949103591068167284263961542487110215", "price": "0.008", "size": "19.62", "side": "BUY", "timestamp": "1768573592667", "received_at": "2026-01-16T14:26:32.711339"}}
{"event_type": "price_change", "event_ts": "2026-01-16T14:26:32.711339", "ingestion_ts": "2026-01-16T14:27:04.418606", "market_id": "0xc0e6b917320a47228fb96e3b5ae0e5c93773a5ae2662ae4e1f37807cfe47ce98", "raw": {"market": "0xc0e6b917320a47228fb96e3b5ae0e5c93773a5ae2662ae4e1f37807cfe47ce98", "asset_id": "81647294538046680798858716589766492074338758116170717123345952330712416337530", "price": "0.992", "size": "19.62", "side": "SELL", "timestamp": "1768573592667", "received_at": "2026-01-16T14:26:32.711339"}}
{"event_type": "price_change", "event_ts": "2026-01-16T14:26:33.031531", "ingestion_ts": "2026-01-16T14:27:04.418606", "market_id": "0xc0e6b917320a47228fb96e3b5ae0e5c93773a5ae2662ae4e1f37807cfe47ce98", "raw": {"market": "0xc0e6b917320a47228fb96e3b5ae0e5c93773a5ae2662ae4e1f37807cfe47ce98", "asset_id": "58656358377246279051017109359677190749228949103591068167284263961542487110215", "price": "0.004", "size": "80.44", "side": "BUY", "timestamp": "1768573592985", "received_at": "2026-01-16T14:26:33.031531"}}
{"event_type": "price_change", "event_ts": "2026-01-16T14:26:33.031531", "ingestion_ts": "2026-01-16T14:27:04.418606", "market_id": "0xc0e6b917320a47228fb96e3b5ae0e5c93773a5ae2662ae4e1f37807cfe47ce98", "raw": {"market": "0xc0e6b917320a47228fb96e3b5ae0e5c93773a5ae2662ae4e1f37807cfe47ce98", "asset_id": "81647294538046680798858716589766492074338758116170717123345952330712416337530", "price": "0.996", "size": "80.44", "side": "SELL", "timestamp": "1768573592985", "received_at": "2026-01-16T14:26:33.031531"}}
{"event_type": "price_change", "event_ts": "2026-01-16T14:26:33.038748", "ingestion_ts": "2026-01-16T14:27:04.418606", "market_id": "0xc0e6b917320a47228fb96e3b5ae0e5c93773a5ae2662ae4e1f37807cfe47ce98", "raw": {"market": "0xc0e6b917320a47228fb96e3b5ae0e5c93773a5ae2662ae4e1f37807cfe47ce98", "asset_id": "58656358377246279051017109359677190749228949103591068167284263961542487110215", "price": "0.004", "size": "103.67", "side": "BUY", "timestamp": "1768573592988", "received_at": "2026-01-16T14:26:33.038748"}}
{"event_type": "price_change", "event_ts": "2026-01-16T14:26:33.038748", "ingestion_ts": "2026-01-16T14:27:04.418606", "market_id": "0xc0e6b917320a47228fb96e3b5ae0e5c93773a5ae2662ae4e1f37807cfe47ce98", "raw": {"market": "0xc0e6b917320a47228fb96e3b5ae0e5c93773a5ae2662ae4e1f37807cfe47ce98", "asset_id": "81647294538046680798858716589766492074338758116170717123345952330712416337530", "price": "0.996", "size": "103.67", "side": "SELL", "timestamp": "1768573592988", "received_at": "2026-01-16T14:26:33.038748"}}
{"event_type": "price_change", "event_ts": "2026-01-16T14:26:33.201740", "ingestion_ts": "2026-01-16T14:27:04.418606", "market_id": "0xaf9d0e448129a9f657f851d49495ba4742055d80e0ef1166ba0ee81d4d594214", "raw": {"market": "0xaf9d0e448129a9f657f851d49495ba4742055d80e0ef1166ba0ee81d4d594214", "asset_id": "4153292802911610701832309484716814274802943278345248636922528170020319407796", "price": "0.989", "size": "0", "side": "SELL", "timestamp": "1768573593146", "received_at": "2026-01-16T14:26:33.201740"}}
{"event_type": "price_change", "event_ts": "2026-01-16T14:26:33.201740", "ingestion_ts": "2026-01-16T14:27:04.418606", "market_id": "0xaf9d0e448129a9f657f851d49495ba4742055d80e0ef1166ba0ee81d4d594214", "raw": {"market": "0xaf9d0e448129a9f657f851d49495ba4742055d80e0ef1166ba0ee81d4d594214", "asset_id": "101676997363687199724245607342877036148401850938023978421879460310389391082353", "price": "0.011", "size": "0", "side": "BUY", "timestamp": "1768573593146", "received_at": "2026-01-16T14:26:33.201740"}}
{"event_type": "price_change", "event_ts": "2026-01-16T14:26:33.283906", "ingestion_ts": "2026-01-16T14:27:04.418606", "market_id": "0xaf9d0e448129a9f657f851d49495ba4742055d80e0ef1166ba0ee81d4d594214", "raw": {"market": "0xaf9d0e448129a9f657f851d49495ba4742055d80e0ef1166ba0ee81d4d594214", "asset_id": "4153292802911610701832309484716814274802943278345248636922528170020319407796", "price": "0.982", "size": "20.5", "side": "SELL", "timestamp": "1768573593185", "received_at": "2026-01-16T14:26:33.283906"}}
{"event_type": "price_change", "event_ts": "2026-01-16T14:26:33.283906", "ingestion_ts": "2026-01-16T14:27:04.418606", "market_id": "0xaf9d0e448129a9f657f851d49495ba4742055d80e0ef1166ba0ee81d4d594214", "raw": {"market": "0xaf9d0e448129a9f657f851d49495ba4742055d80e0ef1166ba0ee81d4d594214", "asset_id": "101676997363687199724245607342877036148401850938023978421879460310389391082353", "price": "0.018", "size": "20.5", "side": "BUY", "timestamp": "1768573593185", "received_at": "2026-01-16T14:26:33.283906"}}
{"event_type": "price_change", "event_ts": "2026-01-16T14:26:33.422769", "ingestion_ts": "2026-01-16T14:27:04.418606", "market_id": "0xc0e6b917320a47228fb96e3b5ae0e5c93773a5ae2662ae4e1f37807cfe47ce98", "raw": {"market": "0xc0e6b917320a47228fb96e3b5ae0e5c93773a5ae2662ae4e1f37807cfe47ce98", "asset_id": "58656358377246279051017109359677190749228949103591068167284263961542487110215", "price": "0.069", "size": "0", "side": "SELL", "timestamp": "1768573593381", "received_at": "2026-01-16T14:26:33.422769"}}
{"event_type": "price_change", "event_ts": "2026-01-16T14:26:33.422769", "ingestion_ts": "2026-01-16T14:27:04.418606", "market_id": "0xc0e6b917320a47228fb96e3b5ae0e5c93773a5ae2662ae4e1f37807cfe47ce98", "raw": {"market": "0xc0e6b917320a47228fb96e3b5ae0e5c93773a5ae2662ae4e1f37807cfe47ce98", "asset_id": "81647294538046680798858716589766492074338758116170717123345952330712416337530", "price": "0.931", "size": "0", "side": "BUY", "timestamp": "1768573593381", "received_at": "2026-01-16T14:26:33.422769"}}
{"event_type": "price_change", "event_ts": "2026-01-16T14:26:33.571315", "ingestion_ts": "2026-01-16T14:27:04.418606", "market_id": "0x49686d26fb712515cd5e12c23f0a1c7e10214c7faa3cb0a730aabe0c33694082", "raw": {"market": "0x49686d26fb712515cd5e12c23f0a1c7e10214c7faa3cb0a730aabe0c33694082", "asset_id": "30442780799048074404860985387051749017905070253466005720364298335239299761065", "price": "0.002", "size": "672.74", "side": "BUY", "timestamp": "1768573593533", "received_at": "2026-01-16T14:26:33.571315"}}
{"event_type": "price_change", "event_ts": "2026-01-16T14:26:33.571315", "ingestion_ts": "2026-01-16T14:27:04.418606", "market_id": "0x49686d26fb712515cd5e12c23f0a1c7e10214c7faa3cb0a730aabe0c33694082", "raw": {"market": "0x49686d26fb712515cd5e12c23f0a1c7e10214c7faa3cb0a730aabe0c33694082", "asset_id": "13244681086321087932946246027856416106585284024824496763706748621681543444582", "price": "0.998", "size": "672.74", "side": "SELL", "timestamp": "1768573593533", "received_at": "2026-01-16T14:26:33.571315"}}
{"event_type": "price_change", "event_ts": "2026-01-16T14:26:33.811891", "ingestion_ts": "2026-01-16T14:27:04.418606", "market_id": "0xc0e6b917320a47228fb96e3b5ae0e5c93773a5ae2662ae4e1f37807cfe47ce98", "raw": {"market": "0xc0e6b917320a47228fb96e3b5ae0e5c93773a5ae2662ae4e1f37807cfe47ce98", "asset_id": "58656358377246279051017109359677190749228949103591068167284263961542487110215", "price": "0.076", "size": "52.8", "side": "SELL", "timestamp": "1768573593772", "received_at": "2026-01-16T14:26:33.811891"}}
{"event_type": "price_change", "event_ts": "2026-01-16T14:26:33.811891", "ingestion_ts": "2026-01-16T14:27:04.418606", "market_id": "0xc0e6b917320a47228fb96e3b5ae0e5c93773a5ae2662ae4e1f37807cfe47ce98", "raw": {"market": "0xc0e6b917320a47228fb96e3b5ae0e5c93773a5ae2662ae4e1f37807cfe47ce98", "asset_id": "81647294538046680798858716589766492074338758116170717123345952330712416337530", "price": "0.924", "size": "52.8", "side": "BUY", "timestamp": "1768573593772", "received_at": "2026-01-16T14:26:33.811891"}}
{"event_type": "price_change", "event_ts": "2026-01-16T14:26:37.201026", "ingestion_ts": "2026-01-16T14:27:04.418606", "market_id": "0xc0e6b917320a47228fb96e3b5ae0e5c93773a5ae2662ae4e1f37807cfe47ce98", "raw": {"market": "0xc0e6b917320a47228fb96e3b5ae0e5c93773a5ae2662ae4e1f37807cfe47ce98", "asset_id": "58656358377246279051017109359677190749228949103591068167284263961542487110215", "price": "0.008", "size": "0", "side": "BUY", "timestamp": "1768573597149", "received_at": "2026-01-16T14:26:37.201026"}}
{"event_type": "price_change", "event_ts": "2026-01-16T14:26:37.201026", "ingestion_ts": "2026-01-16T14:27:04.418606", "market_id": "0xc0e6b917320a47228fb96e3b5ae0e5c93773a5ae2662ae4e1f37807cfe47ce98", "raw": {"market": "0xc0e6b917320a47228fb96e3b5ae0e5c93773a5ae2662ae4e1f37807cfe47ce98", "asset_id": "81647294538046680798858716589766492074338758116170717123345952330712416337530", "price": "0.992", "size": "0", "side": "SELL", "timestamp": "1768573597149", "received_at": "2026-01-16T14:26:37.201026"}}
{"event_type": "price_change", "event_ts": "2026-01-16T14:26:37.533627", "ingestion_ts": "2026-01-16T14:27:04.418606", "market_id": "0xc0e6b917320a47228fb96e3b5ae0e5c93773a5ae2662ae4e1f37807cfe47ce98", "raw": {"market": "0xc0e6b917320a47228fb96e3b5ae0e5c93773a5ae2662ae4e1f37807cfe47ce98", "asset_id": "58656358377246279051017109359677190749228949103591068167284263961542487110215", "price": "0.004", "size": "123.29", "side": "BUY", "timestamp": "1768573597495", "received_at": "2026-01-16T14:26:37.533627"}}
{"event_type": "price_change", "event_ts": "2026-01-16T14:26:37.533627", "ingestion_ts": "2026-01-16T14:27:04.418606", "market_id": "0xc0e6b917320a47228fb96e3b5ae0e5c93773a5ae2662ae4e1f37807cfe47ce98", "raw": {"market": "0xc0e6b917320a47228fb96e3b5ae0e5c93773a5ae2662ae4e1f37807cfe47ce98", "asset_id": "81647294538046680798858716589766492074338758116170717123345952330712416337530", "price": "0.996", "size": "123.29", "side": "SELL", "timestamp": "1768573597495", "received_at": "2026-01-16T14:26:37.533627"}}
{"event_type": "price_change", "event_ts": "2026-01-16T14:26:37.534854", "ingestion_ts": "2026-01-16T14:27:04.418606", "market_id": "0xc0e6b917320a47228fb96e3b5ae0e5c93773a5ae2662ae4e1f37807cfe47ce98", "raw": {"market": "0xc0e6b917320a47228fb96e3b5ae0e5c93773a5ae2662ae4e1f37807cfe47ce98", "asset_id": "58656358377246279051017109359677190749228949103591068167284263961542487110215", "price": "0.004", "size": "142.91", "side": "BUY", "timestamp": "1768573597496", "received_at": "2026-01-16T14:26:37.534854"}}
{"event_type": "price_change", "event_ts": "2026-01-16T14:26:37.534854", "ingestion_ts": "2026-01-16T14:27:04.418606", "market_id": "0xc0e6b917320a47228fb96e3b5ae0e5c93773a5ae2662ae4e1f37807cfe47ce98", "raw": {"market": "0xc0e6b917320a47228fb96e3b5ae0e5c93773a5ae2662ae4e1f37807cfe47ce98", "asset_id": "81647294538046680798858716589766492074338758116170717123345952330712416337530", "price": "0.996", "size": "142.91", "side": "SELL", "timestamp": "1768573597496", "received_at": "2026-01-16T14:26:37.534854"}}
{"event_type": "price_change", "event_ts": "2026-01-16T14:26:37.718094", "ingestion_ts": "2026-01-16T14:27:04.418606", "market_id": "0xaf9d0e448129a9f657f851d49495ba4742055d80e0ef1166ba0ee81d4d594214", "raw": {"market": "0xaf9d0e448129a9f657f851d49495ba4742055d80e0ef1166ba0ee81d4d594214", "asset_id": "4153292802911610701832309484716814274802943278345248636922528170020319407796", "price": "0.983", "size": "0", "side": "SELL", "timestamp": "1768573597674", "received_at": "2026-01-16T14:26:37.718094"}}
{"event_type": "price_change", "event_ts": "2026-01-16T14:26:37.718094", "ingestion_ts": "2026-01-16T14:27:04.418606", "market_id": "0xaf9d0e448129a9f657f851d49495ba4742055d80e0ef1166ba0ee81d4d594214", "raw": {"market": "0xaf9d0e448129a9f657f851d49495ba4742055d80e0ef1166ba0ee81d4d594214", "asset_id": "101676997363687199724245607342877036148401850938023978421879460310389391082353", "price": "0.017", "size": "0", "side": "BUY", "timestamp": "1768573597674", "received_at": "2026-01-16T14:26:37.718094"}}
{"event_type": "price_change", "event_ts": "2026-01-16T14:26:38.258176", "ingestion_ts": "2026-01-16T14:27:04.418606", "market_id": "0xaf9d0e448129a9f657f851d49495ba4742055d80e0ef1166ba0ee81d4d594214", "raw": {"market": "0xaf9d0e448129a9f657f851d49495ba4742055d80e0ef1166ba0ee81d4d594214", "asset_id": "4153292802911610701832309484716814274802943278345248636922528170020319407796", "price": "0.981", "size": "140.01", "side": "SELL", "timestamp": "1768573598217", "received_at": "2026-01-16T14:26:38.258176"}}
{"event_type": "price_change", "event_ts": "2026-01-16T14:26:38.258176", "ingestion_ts": "2026-01-16T14:27:04.418606", "market_id": "0xaf9d0e448129a9f657f851d49495ba4742055d80e0ef1166ba0ee81d4d594214", "raw": {"market": "0xaf9d0e448129a9f657f851d49495ba4742055d80e0ef1166ba0ee81d4d594214", "asset_id": "101676997363687199724245607342877036148401850938023978421879460310389391082353", "price": "0.019", "size": "140.01", "side": "BUY", "timestamp": "1768573598217", "received_at": "2026-01-16T14:26:38.258176"}}
{"event_type": "price_change", "event_ts": "2026-01-16T14:26:39.633093", "ingestion_ts": "2026-01-16T14:27:04.418606", "market_id": "0xaf9d0e448129a9f657f851d49495ba4742055d80e0ef1166ba0ee81d4d594214", "raw": {"market": "0xaf9d0e448129a9f657f851d49495ba4742055d80e0ef1166ba0ee81d4d594214", "asset_id": "4153292802911610701832309484716814274802943278345248636922528170020319407796", "price": "0.982", "size": "0", "side": "SELL", "timestamp": "1768573599590", "received_at": "2026-01-16T14:26:39.633093"}}
{"event_type": "price_change", "event_ts": "2026-01-16T14:26:39.633093", "ingestion_ts": "2026-01-16T14:27:04.418606", "market_id": "0xaf9d0e448129a9f657f851d49495ba4742055d80e0ef1166ba0ee81d4d594214", "raw": {"market": "0xaf9d0e448129a9f657f851d49495ba4742055d80e0ef1166ba0ee81d4d594214", "asset_id": "101676997363687199724245607342877036148401850938023978421879460310389391082353", "price": "0.018", "size": "0", "side": "BUY", "timestamp": "1768573599590", "received_at": "2026-01-16T14:26:39.633093"}}
{"event_type": "price_change", "event_ts": "2026-01-16T14:26:39.678430", "ingestion_ts": "2026-01-16T14:27:04.418606", "market_id": "0xaf9d0e448129a9f657f851d49495ba4742055d80e0ef1166ba0ee81d4d594214", "raw": {"market": "0xaf9d0e448129a9f657f851d49495ba4742055d80e0ef1166ba0ee81d4d594214", "asset_id": "4153292802911610701832309484716814274802943278345248636922528170020319407796", "price": "0.98", "size": "20.5", "side": "SELL", "timestamp": "1768573599634", "received_at": "2026-01-16T14:26:39.678430"}}
{"event_type": "price_change", "event_ts": "2026-01-16T14:26:39.678430", "ingestion_ts": "2026-01-16T14:27:04.418606", "market_id": "0xaf9d0e448129a9f657f851d49495ba4742055d80e0ef1166ba0ee81d4d594214", "raw": {"market": "0xaf9d0e448129a9f657f851d49495ba4742055d80e0ef1166ba0ee81d4d594214", "asset_id": "101676997363687199724245607342877036148401850938023978421879460310389391082353", "price": "0.02", "size": "20.5", "side": "BUY", "timestamp": "1768573599634", "received_at": "2026-01-16T14:26:39.678430"}}
{"event_type": "price_change", "event_ts": "2026-01-16T14:26:39.873966", "ingestion_ts": "2026-01-16T14:27:04.418606", "market_id": "0x49686d26fb712515cd5e12c23f0a1c7e10214c7faa3cb0a730aabe0c33694082", "raw": {"market": "0x49686d26fb712515cd5e12c23f0a1c7e10214c7faa3cb0a730aabe0c33694082", "asset_id": "30442780799048074404860985387051749017905070253466005720364298335239299761065", "price": "0.002", "size": "662.74", "side": "BUY", "timestamp": "1768573599829", "received_at": "2026-01-16T14:26:39.873966"}}
{"event_type": "price_change", "event_ts": "2026-01-16T14:26:39.873966", "ingestion_ts": "2026-01-16T14:27:04.418606", "market_id": "0x49686d26fb712515cd5e12c23f0a1c7e10214c7faa3cb0a730aabe0c33694082", "raw": {"market": "0x49686d26fb712515cd5e12c23f0a1c7e10214c7faa3cb0a730aabe0c33694082", "asset_id": "13244681086321087932946246027856416106585284024824496763706748621681543444582", "price": "0.998", "size": "662.74", "side": "SELL", "timestamp": "1768573599829", "received_at": "2026-01-16T14:26:39.873966"}}
{"event_type": "price_change", "event_ts": "2026-01-16T14:26:39.874024", "ingestion_ts": "2026-01-16T14:27:04.418606", "market_id": "0x49a20c7523c271099008f3ef9a31521263b24d637959852a391e6b4697b1a437", "raw": {"market": "0x49a20c7523c271099008f3ef9a31521263b24d637959852a391e6b4697b1a437", "asset_id": "55881023621710858558280545117465775643848233756850602339827152783696837905531", "price": "0.847", "size": "0", "side": "BUY", "timestamp": "1768573599829", "received_at": "2026-01-16T14:26:39.874024"}}
{"event_type": "price_change", "event_ts": "2026-01-16T14:26:39.874024", "ingestion_ts": "2026-01-16T14:27:04.418606", "market_id": "0x49a20c7523c271099008f3ef9a31521263b24d637959852a391e6b4697b1a437", "raw": {"market": "0x49a20c7523c271099008f3ef9a31521263b24d637959852a391e6b4697b1a437", "asset_id": "13018971792603393862521629014128024641178044618205296260525674415067194037856", "price": "0.153", "size": "0", "side": "SELL", "timestamp": "1768573599829", "received_at": "2026-01-16T14:26:39.874024"}}
{"event_type": "price_change", "event_ts": "2026-01-16T14:26:39.874045", "ingestion_ts": "2026-01-16T14:27:04.418606", "market_id": "0x9472be65457510b7fc3477b20ba90910e99d92eac8421a14bf4b7b7a08ef31dc", "raw": {"market": "0x9472be65457510b7fc3477b20ba90910e99d92eac8421a14bf4b7b7a08ef31dc", "asset_id": "43311793366960417907757893276427136943959788721376762326430771171648759300146", "price": "0.824", "size": "0", "side": "BUY", "timestamp": "1768573599829", "received_at": "2026-01-16T14:26:39.874045"}}
{"event_type": "price_change", "event_ts": "2026-01-16T14:26:39.874045", "ingestion_ts": "2026-01-16T14:27:04.418606", "market_id": "0x9472be65457510b7fc3477b20ba90910e99d92eac8421a14bf4b7b7a08ef31dc", "raw": {"market": "0x9472be65457510b7fc3477b20ba90910e99d92eac8421a14bf4b7b7a08ef31dc", "asset_id": "73414222381656326204771753454630063673548497164758947581648273905027617570612", "price": "0.176", "size": "0", "side": "SELL", "timestamp": "1768573599829", "received_at": "2026-01-16T14:26:39.874045"}}
{"event_type": "price_change", "event_ts": "2026-01-16T14:26:39.874060", "ingestion_ts": "2026-01-16T14:27:04.418606", "market_id": "0xc55db914f0fd1fee18997706712c0dfd8d0369cdbef93a9fef12bd001914ca77", "raw": {"market": "0xc55db914f0fd1fee18997706712c0dfd8d0369cdbef93a9fef12bd001914ca77", "asset_id": "114600293444080540179603459515770723592661967180480327891296353898330242622833", "price": "0.837", "size": "0", "side": "BUY", "timestamp": "1768573599829", "received_at": "2026-01-16T14:26:39.874060"}}
{"event_type": "price_change", "event_ts": "2026-01-16T14:26:39.874060", "ingestion_ts": "2026-01-16T14:27:04.418606", "market_id": "0xc55db914f0fd1fee18997706712c0dfd8d0369cdbef93a9fef12bd001914ca77", "raw": {"market": "0xc55db914f0fd1fee18997706712c0dfd8d0369cdbef93a9fef12bd001914ca77", "asset_id": "72354723612769247426741660426331235762851940382312402276325808095604519806766", "price": "0.163", "size": "0", "side": "SELL", "timestamp": "1768573599829", "received_at": "2026-01-16T14:26:39.874060"}}
{"event_type": "price_change", "event_ts": "2026-01-16T14:26:39.874072", "ingestion_ts": "2026-01-16T14:27:04.418606", "market_id": "0x50c669f178da4e5bbea7f1be25041fd278914712fa87a6a6f8e57d5923d88dee", "raw": {"market": "0x50c669f178da4e5bbea7f1be25041fd278914712fa87a6a6f8e57d5923d88dee", "asset_id": "74040420326294854165772767082819937451857852955603897473157746262672057685461", "price": "0.824", "size": "0", "side": "BUY", "timestamp": "1768573599829", "received_at": "2026-01-16T14:26:39.874072"}}
{"event_type": "price_change", "event_ts": "2026-01-16T14:26:39.874072", "ingestion_ts": "2026-01-16T14:27:04.418606", "market_id": "0x50c669f178da4e5bbea7f1be25041fd278914712fa87a6a6f8e57d5923d88dee", "raw": {"market": "0x50c669f178da4e5bbea7f1be25041fd278914712fa87a6a6f8e57d5923d88dee", "asset_id": "24682525479474221428144937281315825971983904267399062415430320764754931667953", "price": "0.176", "size": "0", "side": "SELL", "timestamp": "1768573599829", "received_at": "2026-01-16T14:26:39.874072"}}
{"event_type": "price_change", "event_ts": "2026-01-16T14:26:39.874083", "ingestion_ts": "2026-01-16T14:27:04.418606", "market_id": "0x44f08744458b8896620cd3330bc5e1ea69df4199b02d4fc583b3fc96e5d314ce", "raw": {"market": "0x44f08744458b8896620cd3330bc5e1ea69df4199b02d4fc583b3fc96e5d314ce", "asset_id": "72327831507226612545928776794104143393438710920370371172884559893525100761096", "price": "0.831", "size": "0", "side": "BUY", "timestamp": "1768573599829", "received_at": "2026-01-16T14:26:39.874083"}}
{"event_type": "price_change", "event_ts": "2026-01-16T14:26:39.874083", "ingestion_ts": "2026-01-16T14:27:04.418606", "market_id": "0x44f08744458b8896620cd3330bc5e1ea69df4199b02d4fc583b3fc96e5d314ce", "raw": {"market": "0x44f08744458b8896620cd3330bc5e1ea69df4199b02d4fc583b3fc96e5d314ce", "asset_id": "49194009556504828848509244326501559253829462790583873936160989575507522044057", "price": "0.169", "size": "0", "side": "SELL", "timestamp": "1768573599829", "received_at": "2026-01-16T14:26:39.874083"}}
{"event_type": "price_change", "event_ts": "2026-01-16T14:26:39.898972", "ingestion_ts": "2026-01-16T14:27:04.418606", "market_id": "0x9472be65457510b7fc3477b20ba90910e99d92eac8421a14bf4b7b7a08ef31dc", "raw": {"market": "0x9472be65457510b7fc3477b20ba90910e99d92eac8421a14bf4b7b7a08ef31dc", "asset_id": "43311793366960417907757893276427136943959788721376762326430771171648759300146", "price": "0.855", "size": "302", "side": "BUY", "timestamp": "1768573599860", "received_at": "2026-01-16T14:26:39.898972"}}
{"event_type": "price_change", "event_ts": "2026-01-16T14:26:39.898972", "ingestion_ts": "2026-01-16T14:27:04.418606", "market_id": "0x9472be65457510b7fc3477b20ba90910e99d92eac8421a14bf4b7b7a08ef31dc", "raw": {"market": "0x9472be65457510b7fc3477b20ba90910e99d92eac8421a14bf4b7b7a08ef31dc", "asset_id": "73414222381656326204771753454630063673548497164758947581648273905027617570612", "price": "0.145", "size": "302", "side": "SELL", "timestamp": "1768573599860", "received_at": "2026-01-16T14:26:39.898972"}}
{"event_type": "price_change", "event_ts": "2026-01-16T14:26:39.899012", "ingestion_ts": "2026-01-16T14:27:04.418606", "market_id": "0xc55db914f0fd1fee18997706712c0dfd8d0369cdbef93a9fef12bd001914ca77", "raw": {"market": "0xc55db914f0fd1fee18997706712c0dfd8d0369cdbef93a9fef12bd001914ca77", "asset_id": "114600293444080540179603459515770723592661967180480327891296353898330242622833", "price": "0.856", "size": "10", "side": "BUY", "timestamp": "1768573599860", "received_at": "2026-01-16T14:26:39.899012"}}
{"event_type": "price_change", "event_ts": "2026-01-16T14:26:39.899012", "ingestion_ts": "2026-01-16T14:27:04.418606", "market_id": "0xc55db914f0fd1fee18997706712c0dfd8d0369cdbef93a9fef12bd001914ca77", "raw": {"market": "0xc55db914f0fd1fee18997706712c0dfd8d0369cdbef93a9fef12bd001914ca77", "asset_id": "72354723612769247426741660426331235762851940382312402276325808095604519806766", "price": "0.144", "size": "10", "side": "SELL", "timestamp": "1768573599860", "received_at": "2026-01-16T14:26:39.899012"}}
{"event_type": "price_change", "event_ts": "2026-01-16T14:26:39.899782", "ingestion_ts": "2026-01-16T14:27:04.418606", "market_id": "0x49686d26fb712515cd5e12c23f0a1c7e10214c7faa3cb0a730aabe0c33694082", "raw": {"market": "0x49686d26fb712515cd5e12c23f0a1c7e10214c7faa3cb0a730aabe0c33694082", "asset_id": "30442780799048074404860985387051749017905070253466005720364298335239299761065", "price": "0.004", "size": "10", "side": "BUY", "timestamp": "1768573599860", "received_at": "2026-01-16T14:26:39.899782"}}
{"event_type": "price_change", "event_ts": "2026-01-16T14:26:39.899782", "ingestion_ts": "2026-01-16T14:27:04.418606", "market_id": "0x49686d26fb712515cd5e12c23f0a1c7e10214c7faa3cb0a730aabe0c33694082", "raw": {"market": "0x49686d26fb712515cd5e12c23f0a1c7e10214c7faa3cb0a730aabe0c33694082", "asset_id": "13244681086321087932946246027856416106585284024824496763706748621681543444582", "price": "0.996", "size": "10", "side": "SELL", "timestamp": "1768573599860", "received_at": "2026-01-16T14:26:39.899782"}}
{"event_type": "price_change", "event_ts": "2026-01-16T14:26:39.899817", "ingestion_ts": "2026-01-16T14:27:04.418606", "market_id": "0x49a20c7523c271099008f3ef9a31521263b24d637959852a391e6b4697b1a437", "raw": {"market": "0x49a20c7523c271099008f3ef9a31521263b24d637959852a391e6b4697b1a437", "asset_id": "55881023621710858558280545117465775643848233756850602339827152783696837905531", "price": "0.854", "size": "10", "side": "BUY", "timestamp": "1768573599860", "received_at": "2026-01-16T14:26:39.899817"}}
{"event_type": "price_change", "event_ts": "2026-01-16T14:26:39.899817", "ingestion_ts": "2026-01-16T14:27:04.418606", "market_id": "0x49a20c7523c271099008f3ef9a31521263b24d637959852a391e6b4697b1a437", "raw": {"market": "0x49a20c7523c271099008f3ef9a31521263b24d637959852a391e6b4697b1a437", "asset_id": "13018971792603393862521629014128024641178044618205296260525674415067194037856", "price": "0.146", "size": "10", "side": "SELL", "timestamp": "1768573599860", "received_at": "2026-01-16T14:26:39.899817"}}
{"event_type": "price_change", "event_ts": "2026-01-16T14:26:39.902594", "ingestion_ts": "2026-01-16T14:27:04.418606", "market_id": "0x50c669f178da4e5bbea7f1be25041fd278914712fa87a6a6f8e57d5923d88dee", "raw": {"market": "0x50c669f178da4e5bbea7f1be25041fd278914712fa87a6a6f8e57d5923d88dee", "asset_id": "74040420326294854165772767082819937451857852955603897473157746262672057685461", "price": "0.854", "size": "40", "side": "BUY", "timestamp": "1768573599860", "received_at": "2026-01-16T14:26:39.902594"}}
{"event_type": "price_change", "event_ts": "2026-01-16T14:26:39.902594", "ingestion_ts": "2026-01-16T14:27:04.418606", "market_id": "0x50c669f178da4e5bbea7f1be25041fd278914712fa87a6a6f8e57d5923d88dee", "raw": {"market": "0x50c669f178da4e5bbea7f1be25041fd278914712fa87a6a6f8e57d5923d88dee", "asset_id": "24682525479474221428144937281315825971983904267399062415430320764754931667953", "price": "0.146", "size": "40", "side": "SELL", "timestamp": "1768573599860", "received_at": "2026-01-16T14:26:39.902594"}}
{"event_type": "price_change", "event_ts": "2026-01-16T14:26:39.902664", "ingestion_ts": "2026-01-16T14:27:04.418606", "market_id": "0x44f08744458b8896620cd3330bc5e1ea69df4199b02d4fc583b3fc96e5d314ce", "raw": {"market": "0x44f08744458b8896620cd3330bc5e1ea69df4199b02d4fc583b3fc96e5d314ce", "asset_id": "72327831507226612545928776794104143393438710920370371172884559893525100761096", "price": "0.852", "size": "10", "side": "BUY", "timestamp": "1768573599860", "received_at": "2026-01-16T14:26:39.902664"}}
{"event_type": "price_change", "event_ts": "2026-01-16T14:26:39.902664", "ingestion_ts": "2026-01-16T14:27:04.418606", "market_id": "0x44f08744458b8896620cd3330bc5e1ea69df4199b02d4fc583b3fc96e5d314ce", "raw": {"market": "0x44f08744458b8896620cd3330bc5e1ea69df4199b02d4fc583b3fc96e5d314ce", "asset_id": "49194009556504828848509244326501559253829462790583873936160989575507522044057", "price": "0.148", "size": "10", "side": "SELL", "timestamp": "1768573599860", "received_at": "2026-01-16T14:26:39.902664"}}
{"event_type": "price_change", "event_ts": "2026-01-16T14:26:40.478357", "ingestion_ts": "2026-01-16T14:27:04.418606", "market_id": "0x49686d26fb712515cd5e12c23f0a1c7e10214c7faa3cb0a730aabe0c33694082", "raw": {"market": "0x49686d26fb712515cd5e12c23f0a1c7e10214c7faa3cb0a730aabe0c33694082", "asset_id": "13244681086321087932946246027856416106585284024824496763706748621681543444582", "price": "0.853", "size": "0", "side": "BUY", "timestamp": "1768573600438", "received_at": "2026-01-16T14:26:40.478357"}}
{"event_type": "price_change", "event_ts": "2026-01-16T14:26:40.478357", "ingestion_ts": "2026-01-16T14:27:04.418606", "market_id": "0x49686d26fb712515cd5e12c23f0a1c7e10214c7faa3cb0a730aabe0c33694082", "raw": {"market": "0x49686d26fb712515cd5e12c23f0a1c7e10214c7faa3cb0a730aabe0c33694082", "asset_id": "30442780799048074404860985387051749017905070253466005720364298335239299761065", "price": "0.147", "size": "0", "side": "SELL", "timestamp": "1768573600438", "received_at": "2026-01-16T14:26:40.478357"}}
{"event_type": "price_change", "event_ts": "2026-01-16T14:26:40.619934", "ingestion_ts": "2026-01-16T14:27:04.418606", "market_id": "0x9472be65457510b7fc3477b20ba90910e99d92eac8421a14bf4b7b7a08ef31dc", "raw": {"market": "0x9472be65457510b7fc3477b20ba90910e99d92eac8421a14bf4b7b7a08ef31dc", "asset_id": "43311793366960417907757893276427136943959788721376762326430771171648759300146", "price": "0.855", "size": "292", "side": "BUY", "timestamp": "1768573600539", "received_at": "2026-01-16T14:26:40.619934"}}
{"event_type": "price_change", "event_ts": "2026-01-16T14:26:40.619934", "ingestion_ts": "2026-01-16T14:27:04.418606", "market_id": "0x9472be65457510b7fc3477b20ba90910e99d92eac8421a14bf4b7b7a08ef31dc", "raw": {"market": "0x9472be65457510b7fc3477b20ba90910e99d92eac8421a14bf4b7b7a08ef31dc", "asset_id": "73414222381656326204771753454630063673548497164758947581648273905027617570612", "price": "0.145", "size": "292", "side": "SELL", "timestamp": "1768573600539", "received_at": "2026-01-16T14:26:40.619934"}}
{"event_type": "price_change", "event_ts": "2026-01-16T14:26:40.620001", "ingestion_ts": "2026-01-16T14:27:04.418606", "market_id": "0x49a20c7523c271099008f3ef9a31521263b24d637959852a391e6b4697b1a437", "raw": {"market": "0x49a20c7523c271099008f3ef9a31521263b24d637959852a391e6b4697b1a437", "asset_id": "55881023621710858558280545117465775643848233756850602339827152783696837905531", "price": "0.854", "size": "0", "side": "BUY", "timestamp": "1768573600539", "received_at": "2026-01-16T14:26:40.620001"}}
{"event_type": "price_change", "event_ts": "2026-01-16T14:26:40.620001", "ingestion_ts": "2026-01-16T14:27:04.418606", "market_id": "0x49a20c7523c271099008f3ef9a31521263b24d637959852a391e6b4697b1a437", "raw": {"market": "0x49a20c7523c271099008f3ef9a31521263b24d637959852a391e6b4697b1a437", "asset_id": "13018971792603393862521629014128024641178044618205296260525674415067194037856", "price": "0.146", "size": "0", "side": "SELL", "timestamp": "1768573600539", "received_at": "2026-01-16T14:26:40.620001"}}
{"event_type": "price_change", "event_ts": "2026-01-16T14:26:40.620034", "ingestion_ts": "2026-01-16T14:27:04.418606", "market_id": "0xc55db914f0fd1fee18997706712c0dfd8d0369cdbef93a9fef12bd001914ca77", "raw": {"market": "0xc55db914f0fd1fee18997706712c0dfd8d0369cdbef93a9fef12bd001914ca77", "asset_id": "114600293444080540179603459515770723592661967180480327891296353898330242622833", "price": "0.856", "size": "0", "side": "BUY", "timestamp": "1768573600539", "received_at": "2026-01-16T14:26:40.620034"}}
{"event_type": "price_change", "event_ts": "2026-01-16T14:26:40.620034", "ingestion_ts": "2026-01-16T14:27:04.418606", "market_id": "0xc55db914f0fd1fee18997706712c0dfd8d0369cdbef93a9fef12bd001914ca77", "raw": {"market": "0xc55db914f0fd1fee18997706712c0dfd8d0369cdbef93a9fef12bd001914ca77", "asset_id": "72354723612769247426741660426331235762851940382312402276325808095604519806766", "price": "0.144", "size": "0", "side": "SELL", "timestamp": "1768573600539", "received_at": "2026-01-16T14:26:40.620034"}}
{"event_type": "price_change", "event_ts": "2026-01-16T14:26:40.620066", "ingestion_ts": "2026-01-16T14:27:04.418606", "market_id": "0x44f08744458b8896620cd3330bc5e1ea69df4199b02d4fc583b3fc96e5d314ce", "raw": {"market": "0x44f08744458b8896620cd3330bc5e1ea69df4199b02d4fc583b3fc96e5d314ce", "asset_id": "72327831507226612545928776794104143393438710920370371172884559893525100761096", "price": "0.852", "size": "0", "side": "BUY", "timestamp": "1768573600539", "received_at": "2026-01-16T14:26:40.620066"}}
{"event_type": "price_change", "event_ts": "2026-01-16T14:26:40.620066", "ingestion_ts": "2026-01-16T14:27:04.418606", "market_id": "0x44f08744458b8896620cd3330bc5e1ea69df4199b02d4fc583b3fc96e5d314ce", "raw": {"market": "0x44f08744458b8896620cd3330bc5e1ea69df4199b02d4fc583b3fc96e5d314ce", "asset_id": "49194009556504828848509244326501559253829462790583873936160989575507522044057", "price": "0.148", "size": "0", "side": "SELL", "timestamp": "1768573600539", "received_at": "2026-01-16T14:26:40.620066"}}
{"event_type": "price_change", "event_ts": "2026-01-16T14:26:40.620088", "ingestion_ts": "2026-01-16T14:27:04.418606", "market_id": "0xc55db914f0fd1fee18997706712c0dfd8d0369cdbef93a9fef12bd001914ca77", "raw": {"market": "0xc55db914f0fd1fee18997706712c0dfd8d0369cdbef93a9fef12bd001914ca77", "asset_id": "114600293444080540179603459515770723592661967180480327891296353898330242622833", "price": "0.855", "size": "302", "side": "BUY", "timestamp": "1768573600570", "received_at": "2026-01-16T14:26:40.620088"}}
{"event_type": "price_change", "event_ts": "2026-01-16T14:26:40.620088", "ingestion_ts": "2026-01-16T14:27:04.418606", "market_id": "0xc55db914f0fd1fee18997706712c0dfd8d0369cdbef93a9fef12bd001914ca77", "raw": {"market": "0xc55db914f0fd1fee18997706712c0dfd8d0369cdbef93a9fef12bd001914ca77", "asset_id": "72354723612769247426741660426331235762851940382312402276325808095604519806766", "price": "0.145", "size": "302", "side": "SELL", "timestamp": "1768573600570", "received_at": "2026-01-16T14:26:40.620088"}}
{"event_type": "price_change", "event_ts": "2026-01-16T14:26:40.620109", "ingestion_ts": "2026-01-16T14:27:04.418606", "market_id": "0x9472be65457510b7fc3477b20ba90910e99d92eac8421a14bf4b7b7a08ef31dc", "raw": {"market": "0x9472be65457510b7fc3477b20ba90910e99d92eac8421a14bf4b7b7a08ef31dc", "asset_id": "43311793366960417907757893276427136943959788721376762326430771171648759300146", "price": "0.824", "size": "10", "side": "BUY", "timestamp": "1768573600570", "received_at": "2026-01-16T14:26:40.620109"}}
{"event_type": "price_change", "event_ts": "2026-01-16T14:26:40.620109", "ingestion_ts": "2026-01-16T14:27:04.418606", "market_id": "0x9472be65457510b7fc3477b20ba90910e99d92eac8421a14bf4b7b7a08ef31dc", "raw": {"market": "0x9472be65457510b7fc3477b20ba90910e99d92eac8421a14bf4b7b7a08ef31dc", "asset_id": "73414222381656326204771753454630063673548497164758947581648273905027617570612", "price": "0.176", "size": "10", "side": "SELL", "timestamp": "1768573600570", "received_at": "2026-01-16T14:26:40.620109"}}
{"event_type": "price_change", "event_ts": "2026-01-16T14:26:40.620129", "ingestion_ts": "2026-01-16T14:27:04.418606", "market_id": "0x49a20c7523c271099008f3ef9a31521263b24d637959852a391e6b4697b1a437", "raw": {"market": "0x49a20c7523c271099008f3ef9a31521263b24d637959852a391e6b4697b1a437", "asset_id": "55881023621710858558280545117465775643848233756850602339827152783696837905531", "price": "0.853", "size": "537", "side": "BUY", "timestamp": "1768573600570", "received_at": "2026-01-16T14:26:40.620129"}}
{"event_type": "price_change", "event_ts": "2026-01-16T14:26:40.620129", "ingestion_ts": "2026-01-16T14:27:04.418606", "market_id": "0x49a20c7523c271099008f3ef9a31521263b24d637959852a391e6b4697b1a437", "raw": {"market": "0x49a20c7523c271099008f3ef9a31521263b24d637959852a391e6b4697b1a437", "asset_id": "13018971792603393862521629014128024641178044618205296260525674415067194037856", "price": "0.147", "size": "537", "side": "SELL", "timestamp": "1768573600570", "received_at": "2026-01-16T14:26:40.620129"}}
{"event_type": "price_change", "event_ts": "2026-01-16T14:26:40.620147", "ingestion_ts": "2026-01-16T14:27:04.418606", "market_id": "0x44f08744458b8896620cd3330bc5e1ea69df4199b02d4fc583b3fc96e5d314ce", "raw": {"market": "0x44f08744458b8896620cd3330bc5e1ea69df4199b02d4fc583b3fc96e5d314ce", "asset_id": "72327831507226612545928776794104143393438710920370371172884559893525100761096", "price": "0.851", "size": "303", "side": "BUY", "timestamp": "1768573600570", "received_at": "2026-01-16T14:26:40.620147"}}
{"event_type": "price_change", "event_ts": "2026-01-16T14:26:40.620147", "ingestion_ts": "2026-01-16T14:27:04.418606", "market_id": "0x44f08744458b8896620cd3330bc5e1ea69df4199b02d4fc583b3fc96e5d314ce", "raw": {"market": "0x44f08744458b8896620cd3330bc5e1ea69df4199b02d4fc583b3fc96e5d314ce", "asset_id": "49194009556504828848509244326501559253829462790583873936160989575507522044057", "price": "0.149", "size": "303", "side": "SELL", "timestamp": "1768573600570", "received_at": "2026-01-16T14:26:40.620147"}}
{"event_type": "price_change", "event_ts": "2026-01-16T14:26:43.950590", "ingestion_ts": "2026-01-16T14:27:04.418606", "market_id": "0xc0e6b917320a47228fb96e3b5ae0e5c93773a5ae2662ae4e1f37807cfe47ce98", "raw": {"market": "0xc0e6b917320a47228fb96e3b5ae0e5c93773a5ae2662ae4e1f37807cfe47ce98", "asset_id": "58656358377246279051017109359677190749228949103591068167284263961542487110215", "price": "0.004", "size": "119.68", "side": "BUY", "timestamp": "1768573603912", "received_at": "2026-01-16T14:26:43.950590"}}
{"event_type": "price_change", "event_ts": "2026-01-16T14:26:43.950590", "ingestion_ts": "2026-01-16T14:27:04.418606", "market_id": "0xc0e6b917320a47228fb96e3b5ae0e5c93773a5ae2662ae4e1f37807cfe47ce98", "raw": {"market": "0xc0e6b917320a47228fb96e3b5ae0e5c93773a5ae2662ae4e1f37807cfe47ce98", "asset_id": "81647294538046680798858716589766492074338758116170717123345952330712416337530", "price": "0.996", "size": "119.68", "side": "SELL", "timestamp": "1768573603912", "received_at": "2026-01-16T14:26:43.950590"}}
{"event_type": "price_change", "event_ts": "2026-01-16T14:26:44.214263", "ingestion_ts": "2026-01-16T14:27:04.418606", "market_id": "0xc0e6b917320a47228fb96e3b5ae0e5c93773a5ae2662ae4e1f37807cfe47ce98", "raw": {"market": "0xc0e6b917320a47228fb96e3b5ae0e5c93773a5ae2662ae4e1f37807cfe47ce98", "asset_id": "58656358377246279051017109359677190749228949103591068167284263961542487110215", "price": "0.004", "size": "131.3", "side": "BUY", "timestamp": "1768573604167", "received_at": "2026-01-16T14:26:44.214263"}}
{"event_type": "price_change", "event_ts": "2026-01-16T14:26:44.214263", "ingestion_ts": "2026-01-16T14:27:04.418606", "market_id": "0xc0e6b917320a47228fb96e3b5ae0e5c93773a5ae2662ae4e1f37807cfe47ce98", "raw": {"market": "0xc0e6b917320a47228fb96e3b5ae0e5c93773a5ae2662ae4e1f37807cfe47ce98", "asset_id": "81647294538046680798858716589766492074338758116170717123345952330712416337530", "price": "0.996", "size": "131.3", "side": "SELL", "timestamp": "1768573604167", "received_at": "2026-01-16T14:26:44.214263"}}
{"event_type": "price_change", "event_ts": "2026-01-16T14:26:44.214316", "ingestion_ts": "2026-01-16T14:27:04.418606", "market_id": "0xc0e6b917320a47228fb96e3b5ae0e5c93773a5ae2662ae4e1f37807cfe47ce98", "raw": {"market": "0xc0e6b917320a47228fb96e3b5ae0e5c93773a5ae2662ae4e1f37807cfe47ce98", "asset_id": "58656358377246279051017109359677190749228949103591068167284263961542487110215", "price": "0.004", "size": "142.92", "side": "BUY", "timestamp": "1768573604170", "received_at": "2026-01-16T14:26:44.214316"}}
{"event_type": "price_change", "event_ts": "2026-01-16T14:26:44.214316", "ingestion_ts": "2026-01-16T14:27:04.418606", "market_id": "0xc0e6b917320a47228fb96e3b5ae0e5c93773a5ae2662ae4e1f37807cfe47ce98", "raw": {"market": "0xc0e6b917320a47228fb96e3b5ae0e5c93773a5ae2662ae4e1f37807cfe47ce98", "asset_id": "81647294538046680798858716589766492074338758116170717123345952330712416337530", "price": "0.996", "size": "142.92", "side": "SELL", "timestamp": "1768573604170", "received_at": "2026-01-16T14:26:44.214316"}}
{"event_type": "price_change", "event_ts": "2026-01-16T14:26:44.278271", "ingestion_ts": "2026-01-16T14:27:04.418606", "market_id": "0xaf9d0e448129a9f657f851d49495ba4742055d80e0ef1166ba0ee81d4d594214", "raw": {"market": "0xaf9d0e448129a9f657f851d49495ba4742055d80e0ef1166ba0ee81d4d594214", "asset_id": "4153292802911610701832309484716814274802943278345248636922528170020319407796", "price": "0.981", "size": "0", "side": "SELL", "timestamp": "1768573604239", "received_at": "2026-01-16T14:26:44.278271"}}
{"event_type": "price_change", "event_ts": "2026-01-16T14:26:44.278271", "ingestion_ts": "2026-01-16T14:27:04.418606", "market_id": "0xaf9d0e448129a9f657f851d49495ba4742055d80e0ef1166ba0ee81d4d594214", "raw": {"market": "0xaf9d0e448129a9f657f851d49495ba4742055d80e0ef1166ba0ee81d4d594214", "asset_id": "101676997363687199724245607342877036148401850938023978421879460310389391082353", "price": "0.019", "size": "0", "side": "BUY", "timestamp": "1768573604239", "received_at": "2026-01-16T14:26:44.278271"}}
{"event_type": "price_change", "event_ts": "2026-01-16T14:26:44.445619", "ingestion_ts": "2026-01-16T14:27:04.418606", "market_id": "0xb9bbdd34304344dcc45803780a34c97d73a00133a5ecf70f63e1008b8abb2fca", "raw": {"market": "0xb9bbdd34304344dcc45803780a34c97d73a00133a5ecf70f63e1008b8abb2fca", "asset_id": "8682484153073832526711485265636767086525069344085206423986003504588877767339", "price": "0.852", "size": "0", "side": "BUY", "timestamp": "1768573604375", "received_at": "2026-01-16T14:26:44.445619"}}
{"event_type": "price_change", "event_ts": "2026-01-16T14:26:44.445619", "ingestion_ts": "2026-01-16T14:27:04.418606", "market_id": "0xb9bbdd34304344dcc45803780a34c97d73a00133a5ecf70f63e1008b8abb2fca", "raw": {"market": "0xb9bbdd34304344dcc45803780a34c97d73a00133a5ecf70f63e1008b8abb2fca", "asset_id": "72012724360700510767037780555710363830014634797787940282136454146828040926557", "price": "0.148", "size": "0", "side": "SELL", "timestamp": "1768573604375", "received_at": "2026-01-16T14:26:44.445619"}}
{"event_type": "price_change", "event_ts": "2026-01-16T14:26:44.563837", "ingestion_ts": "2026-01-16T14:27:04.418606", "market_id": "0xb9bbdd34304344dcc45803780a34c97d73a00133a5ecf70f63e1008b8abb2fca", "raw": {"market": "0xb9bbdd34304344dcc45803780a34c97d73a00133a5ecf70f63e1008b8abb2fca", "asset_id": "8682484153073832526711485265636767086525069344085206423986003504588877767339", "price": "0.84", "size": "30", "side": "BUY", "timestamp": "1768573604507", "received_at": "2026-01-16T14:26:44.563837"}}
{"event_type": "price_change", "event_ts": "2026-01-16T14:26:44.563837", "ingestion_ts": "2026-01-16T14:27:04.418606", "market_id": "0xb9bbdd34304344dcc45803780a34c97d73a00133a5ecf70f63e1008b8abb2fca", "raw": {"market": "0xb9bbdd34304344dcc45803780a34c97d73a00133a5ecf70f63e1008b8abb2fca", "asset_id": "72012724360700510767037780555710363830014634797787940282136454146828040926557", "price": "0.16", "size": "30", "side": "SELL", "timestamp": "1768573604507", "received_at": "2026-01-16T14:26:44.563837"}}
{"event_type": "price_change", "event_ts": "2026-01-16T14:26:44.924857", "ingestion_ts": "2026-01-16T14:27:04.418606", "market_id": "0xaf9d0e448129a9f657f851d49495ba4742055d80e0ef1166ba0ee81d4d594214", "raw": {"market": "0xaf9d0e448129a9f657f851d49495ba4742055d80e0ef1166ba0ee81d4d594214", "asset_id": "4153292802911610701832309484716814274802943278345248636922528170020319407796", "price": "0.979", "size": "140.01", "side": "SELL", "timestamp": "1768573604886", "received_at": "2026-01-16T14:26:44.924857"}}
{"event_type": "price_change", "event_ts": "2026-01-16T14:26:44.924857", "ingestion_ts": "2026-01-16T14:27:04.418606", "market_id": "0xaf9d0e448129a9f657f851d49495ba4742055d80e0ef1166ba0ee81d4d594214", "raw": {"market": "0xaf9d0e448129a9f657f851d49495ba4742055d80e0ef1166ba0ee81d4d594214", "asset_id": "101676997363687199724245607342877036148401850938023978421879460310389391082353", "price": "0.021", "size": "140.01", "side": "BUY", "timestamp": "1768573604886", "received_at": "2026-01-16T14:26:44.924857"}}
{"event_type": "price_change", "event_ts": "2026-01-16T14:26:44.945973", "ingestion_ts": "2026-01-16T14:27:04.418606", "market_id": "0xaf9d0e448129a9f657f851d49495ba4742055d80e0ef1166ba0ee81d4d594214", "raw": {"market": "0xaf9d0e448129a9f657f851d49495ba4742055d80e0ef1166ba0ee81d4d594214", "asset_id": "4153292802911610701832309484716814274802943278345248636922528170020319407796", "price": "0.98", "size": "0", "side": "SELL", "timestamp": "1768573604908", "received_at": "2026-01-16T14:26:44.945973"}}
{"event_type": "price_change", "event_ts": "2026-01-16T14:26:44.945973", "ingestion_ts": "2026-01-16T14:27:04.418606", "market_id": "0xaf9d0e448129a9f657f851d49495ba4742055d80e0ef1166ba0ee81d4d594214", "raw": {"market": "0xaf9d0e448129a9f657f851d49495ba4742055d80e0ef1166ba0ee81d4d594214", "asset_id": "101676997363687199724245607342877036148401850938023978421879460310389391082353", "price": "0.02", "size": "0", "side": "BUY", "timestamp": "1768573604908", "received_at": "2026-01-16T14:26:44.945973"}}
{"event_type": "price_change", "event_ts": "2026-01-16T14:26:44.993714", "ingestion_ts": "2026-01-16T14:27:04.418606", "market_id": "0xaf9d0e448129a9f657f851d49495ba4742055d80e0ef1166ba0ee81d4d594214", "raw": {"market": "0xaf9d0e448129a9f657f851d49495ba4742055d80e0ef1166ba0ee81d4d594214", "asset_id": "4153292802911610701832309484716814274802943278345248636922528170020319407796", "price": "0.989", "size": "20.5", "side": "SELL", "timestamp": "1768573604954", "received_at": "2026-01-16T14:26:44.993714"}}
{"event_type": "price_change", "event_ts": "2026-01-16T14:26:44.993714", "ingestion_ts": "2026-01-16T14:27:04.418606", "market_id": "0xaf9d0e448129a9f657f851d49495ba4742055d80e0ef1166ba0ee81d4d594214", "raw": {"market": "0xaf9d0e448129a9f657f851d49495ba4742055d80e0ef1166ba0ee81d4d594214", "asset_id": "101676997363687199724245607342877036148401850938023978421879460310389391082353", "price": "0.011", "size": "20.5", "side": "BUY", "timestamp": "1768573604954", "received_at": "2026-01-16T14:26:44.993714"}}
{"event_type": "price_change", "event_ts": "2026-01-16T14:26:45.521933", "ingestion_ts": "2026-01-16T14:27:04.418606", "market_id": "0x49686d26fb712515cd5e12c23f0a1c7e10214c7faa3cb0a730aabe0c33694082", "raw": {"market": "0x49686d26fb712515cd5e12c23f0a1c7e10214c7faa3cb0a730aabe0c33694082", "asset_id": "13244681086321087932946246027856416106585284024824496763706748621681543444582", "price": "0.852", "size": "23.36", "side": "BUY", "timestamp": "1768573605476", "received_at": "2026-01-16T14:26:45.521933"}}
{"event_type": "price_change", "event_ts": "2026-01-16T14:26:45.521933", "ingestion_ts": "2026-01-16T14:27:04.418606", "market_id": "0x49686d26fb712515cd5e12c23f0a1c7e10214c7faa3cb0a730aabe0c33694082", "raw": {"market": "0x49686d26fb712515cd5e12c23f0a1c7e10214c7faa3cb0a730aabe0c33694082", "asset_id": "30442780799048074404860985387051749017905070253466005720364298335239299761065", "price": "0.148", "size": "23.36", "side": "SELL", "timestamp": "1768573605476", "received_at": "2026-01-16T14:26:45.521933"}}
{"event_type": "price_change", "event_ts": "2026-01-16T14:26:46.172928", "ingestion_ts": "2026-01-16T14:27:04.418606", "market_id": "0xaf9d0e448129a9f657f851d49495ba4742055d80e0ef1166ba0ee81d4d594214", "raw": {"market": "0xaf9d0e448129a9f657f851d49495ba4742055d80e0ef1166ba0ee81d4d594214", "asset_id": "4153292802911610701832309484716814274802943278345248636922528170020319407796", "price": "0.989", "size": "0", "side": "SELL", "timestamp": "1768573606134", "received_at": "2026-01-16T14:26:46.172928"}}
{"event_type": "price_change", "event_ts": "2026-01-16T14:26:46.172928", "ingestion_ts": "2026-01-16T14:27:04.418606", "market_id": "0xaf9d0e448129a9f657f851d49495ba4742055d80e0ef1166ba0ee81d4d594214", "raw": {"market": "0xaf9d0e448129a9f657f851d49495ba4742055d80e0ef1166ba0ee81d4d594214", "asset_id": "101676997363687199724245607342877036148401850938023978421879460310389391082353", "price": "0.011", "size": "0", "side": "BUY", "timestamp": "1768573606134", "received_at": "2026-01-16T14:26:46.172928"}}
{"event_type": "price_change", "event_ts": "2026-01-16T14:26:46.310853", "ingestion_ts": "2026-01-16T14:27:04.418606", "market_id": "0xaf9d0e448129a9f657f851d49495ba4742055d80e0ef1166ba0ee81d4d594214", "raw": {"market": "0xaf9d0e448129a9f657f851d49495ba4742055d80e0ef1166ba0ee81d4d594214", "asset_id": "4153292802911610701832309484716814274802943278345248636922528170020319407796", "price": "0.978", "size": "20.5", "side": "SELL", "timestamp": "1768573606207", "received_at": "2026-01-16T14:26:46.310853"}}
{"event_type": "price_change", "event_ts": "2026-01-16T14:26:46.310853", "ingestion_ts": "2026-01-16T14:27:04.418606", "market_id": "0xaf9d0e448129a9f657f851d49495ba4742055d80e0ef1166ba0ee81d4d594214", "raw": {"market": "0xaf9d0e448129a9f657f851d49495ba4742055d80e0ef1166ba0ee81d4d594214", "asset_id": "101676997363687199724245607342877036148401850938023978421879460310389391082353", "price": "0.022", "size": "20.5", "side": "BUY", "timestamp": "1768573606207", "received_at": "2026-01-16T14:26:46.310853"}}
{"event_type": "price_change", "event_ts": "2026-01-16T14:26:47.453422", "ingestion_ts": "2026-01-16T14:27:04.418606", "market_id": "0xc0e6b917320a47228fb96e3b5ae0e5c93773a5ae2662ae4e1f37807cfe47ce98", "raw": {"market": "0xc0e6b917320a47228fb96e3b5ae0e5c93773a5ae2662ae4e1f37807cfe47ce98", "asset_id": "58656358377246279051017109359677190749228949103591068167284263961542487110215", "price": "0.004", "size": "119.69", "side": "BUY", "timestamp": "1768573607404", "received_at": "2026-01-16T14:26:47.453422"}}
{"event_type": "price_change", "event_ts": "2026-01-16T14:26:47.453422", "ingestion_ts": "2026-01-16T14:27:04.418606", "market_id": "0xc0e6b917320a47228fb96e3b5ae0e5c93773a5ae2662ae4e1f37807cfe47ce98", "raw": {"market": "0xc0e6b917320a47228fb96e3b5ae0e5c93773a5ae2662ae4e1f37807cfe47ce98", "asset_id": "81647294538046680798858716589766492074338758116170717123345952330712416337530", "price": "0.996", "size": "119.69", "side": "SELL", "timestamp": "1768573607404", "received_at": "2026-01-16T14:26:47.453422"}}
{"event_type": "price_change", "event_ts": "2026-01-16T14:26:47.742947", "ingestion_ts": "2026-01-16T14:27:04.418606", "market_id": "0xc0e6b917320a47228fb96e3b5ae0e5c93773a5ae2662ae4e1f37807cfe47ce98", "raw": {"market": "0xc0e6b917320a47228fb96e3b5ae0e5c93773a5ae2662ae4e1f37807cfe47ce98", "asset_id": "58656358377246279051017109359677190749228949103591068167284263961542487110215", "price": "0.004", "size": "131.3", "side": "BUY", "timestamp": "1768573607703", "received_at": "2026-01-16T14:26:47.742947"}}
{"event_type": "price_change", "event_ts": "2026-01-16T14:26:47.742947", "ingestion_ts": "2026-01-16T14:27:04.418606", "market_id": "0xc0e6b917320a47228fb96e3b5ae0e5c93773a5ae2662ae4e1f37807cfe47ce98", "raw": {"market": "0xc0e6b917320a47228fb96e3b5ae0e5c93773a5ae2662ae4e1f37807cfe47ce98", "asset_id": "81647294538046680798858716589766492074338758116170717123345952330712416337530", "price": "0.996", "size": "131.3", "side": "SELL", "timestamp": "1768573607703", "received_at": "2026-01-16T14:26:47.742947"}}
{"event_type": "price_change", "event_ts": "2026-01-16T14:26:47.748905", "ingestion_ts": "2026-01-16T14:27:04.418606", "market_id": "0xc0e6b917320a47228fb96e3b5ae0e5c93773a5ae2662ae4e1f37807cfe47ce98", "raw": {"market": "0xc0e6b917320a47228fb96e3b5ae0e5c93773a5ae2662ae4e1f37807cfe47ce98", "asset_id": "58656358377246279051017109359677190749228949103591068167284263961542487110215", "price": "0.004", "size": "142.91", "side": "BUY", "timestamp": "1768573607704", "received_at": "2026-01-16T14:26:47.748905"}}
{"event_type": "price_change", "event_ts": "2026-01-16T14:26:47.748905", "ingestion_ts": "2026-01-16T14:27:04.418606", "market_id": "0xc0e6b917320a47228fb96e3b5ae0e5c93773a5ae2662ae4e1f37807cfe47ce98", "raw": {"market": "0xc0e6b917320a47228fb96e3b5ae0e5c93773a5ae2662ae4e1f37807cfe47ce98", "asset_id": "81647294538046680798858716589766492074338758116170717123345952330712416337530", "price": "0.996", "size": "142.91", "side": "SELL", "timestamp": "1768573607704", "received_at": "2026-01-16T14:26:47.748905"}}
{"event_type": "price_change", "event_ts": "2026-01-16T14:26:47.900176", "ingestion_ts": "2026-01-16T14:27:04.418606", "market_id": "0x49686d26fb712515cd5e12c23f0a1c7e10214c7faa3cb0a730aabe0c33694082", "raw": {"market": "0x49686d26fb712515cd5e12c23f0a1c7e10214c7faa3cb0a730aabe0c33694082", "asset_id": "30442780799048074404860985387051749017905070253466005720364298335239299761065", "price": "0.004", "size": "0", "side": "BUY", "timestamp": "1768573607857", "received_at": "2026-01-16T14:26:47.900176"}}
{"event_type": "price_change", "event_ts": "2026-01-16T14:26:47.900176", "ingestion_ts": "2026-01-16T14:27:04.418606", "market_id": "0x49686d26fb712515cd5e12c23f0a1c7e10214c7faa3cb0a730aabe0c33694082", "raw": {"market": "0x49686d26fb712515cd5e12c23f0a1c7e10214c7faa3cb0a730aabe0c33694082", "asset_id": "13244681086321087932946246027856416106585284024824496763706748621681543444582", "price": "0.996", "size": "0", "side": "SELL", "timestamp": "1768573607857", "received_at": "2026-01-16T14:26:47.900176"}}
{"event_type": "price_change", "event_ts": "2026-01-16T14:26:47.901118", "ingestion_ts": "2026-01-16T14:27:04.418606", "market_id": "0x50c669f178da4e5bbea7f1be25041fd278914712fa87a6a6f8e57d5923d88dee", "raw": {"market": "0x50c669f178da4e5bbea7f1be25041fd278914712fa87a6a6f8e57d5923d88dee", "asset_id": "74040420326294854165772767082819937451857852955603897473157746262672057685461", "price": "0.854", "size": "30", "side": "BUY", "timestamp": "1768573607857", "received_at": "2026-01-16T14:26:47.901118"}}
{"event_type": "price_change", "event_ts": "2026-01-16T14:26:47.901118", "ingestion_ts": "2026-01-16T14:27:04.418606", "market_id": "0x50c669f178da4e5bbea7f1be25041fd278914712fa87a6a6f8e57d5923d88dee", "raw": {"market": "0x50c669f178da4e5bbea7f1be25041fd278914712fa87a6a6f8e57d5923d88dee", "asset_id": "24682525479474221428144937281315825971983904267399062415430320764754931667953", "price": "0.146", "size": "30", "side": "SELL", "timestamp": "1768573607857", "received_at": "2026-01-16T14:26:47.901118"}}
{"event_type": "price_change", "event_ts": "2026-01-16T14:26:47.901164", "ingestion_ts": "2026-01-16T14:27:04.418606", "market_id": "0x9472be65457510b7fc3477b20ba90910e99d92eac8421a14bf4b7b7a08ef31dc", "raw": {"market": "0x9472be65457510b7fc3477b20ba90910e99d92eac8421a14bf4b7b7a08ef31dc", "asset_id": "43311793366960417907757893276427136943959788721376762326430771171648759300146", "price": "0.824", "size": "0", "side": "BUY", "timestamp": "1768573607857", "received_at": "2026-01-16T14:26:47.901164"}}
{"event_type": "price_change", "event_ts": "2026-01-16T14:26:47.901164", "ingestion_ts": "2026-01-16T14:27:04.418606", "market_id": "0x9472be65457510b7fc3477b20ba90910e99d92eac8421a14bf4b7b7a08ef31dc", "raw": {"market": "0x9472be65457510b7fc3477b20ba90910e99d92eac8421a14bf4b7b7a08ef31dc", "asset_id": "73414222381656326204771753454630063673548497164758947581648273905027617570612", "price": "0.176", "size": "0", "side": "SELL", "timestamp": "1768573607857", "received_at": "2026-01-16T14:26:47.901164"}}
{"event_type": "price_change", "event_ts": "2026-01-16T14:26:47.901189", "ingestion_ts": "2026-01-16T14:27:04.418606", "market_id": "0xc55db914f0fd1fee18997706712c0dfd8d0369cdbef93a9fef12bd001914ca77", "raw": {"market": "0xc55db914f0fd1fee18997706712c0dfd8d0369cdbef93a9fef12bd001914ca77", "asset_id": "114600293444080540179603459515770723592661967180480327891296353898330242622833", "price": "0.855", "size": "292", "side": "BUY", "timestamp": "1768573607857", "received_at": "2026-01-16T14:26:47.901189"}}
{"event_type": "price_change", "event_ts": "2026-01-16T14:26:47.901189", "ingestion_ts": "2026-01-16T14:27:04.418606", "market_id": "0xc55db914f0fd1fee18997706712c0dfd8d0369cdbef93a9fef12bd001914ca77", "raw": {"market": "0xc55db914f0fd1fee18997706712c0dfd8d0369cdbef93a9fef12bd001914ca77", "asset_id": "72354723612769247426741660426331235762851940382312402276325808095604519806766", "price": "0.145", "size": "292", "side": "SELL", "timestamp": "1768573607857", "received_at": "2026-01-16T14:26:47.901189"}}
{"event_type": "price_change", "event_ts": "2026-01-16T14:26:47.901208", "ingestion_ts": "2026-01-16T14:27:04.418606", "market_id": "0xb9bbdd34304344dcc45803780a34c97d73a00133a5ecf70f63e1008b8abb2fca", "raw": {"market": "0xb9bbdd34304344dcc45803780a34c97d73a00133a5ecf70f63e1008b8abb2fca", "asset_id": "8682484153073832526711485265636767086525069344085206423986003504588877767339", "price": "0.839", "size": "0", "side": "BUY", "timestamp": "1768573607857", "received_at": "2026-01-16T14:26:47.901208"}}
{"event_type": "price_change", "event_ts": "2026-01-16T14:26:47.901208", "ingestion_ts": "2026-01-16T14:27:04.418606", "market_id": "0xb9bbdd34304344dcc45803780a34c97d73a00133a5ecf70f63e1008b8abb2fca", "raw": {"market": "0xb9bbdd34304344dcc45803780a34c97d73a00133a5ecf70f63e1008b8abb2fca", "asset_id": "72012724360700510767037780555710363830014634797787940282136454146828040926557", "price": "0.161", "size": "0", "side": "SELL", "timestamp": "1768573607857", "received_at": "2026-01-16T14:26:47.901208"}}
{"event_type": "price_change", "event_ts": "2026-01-16T14:26:47.904371", "ingestion_ts": "2026-01-16T14:27:04.418606", "market_id": "0x49a20c7523c271099008f3ef9a31521263b24d637959852a391e6b4697b1a437", "raw": {"market": "0x49a20c7523c271099008f3ef9a31521263b24d637959852a391e6b4697b1a437", "asset_id": "55881023621710858558280545117465775643848233756850602339827152783696837905531", "price": "0.853", "size": "527", "side": "BUY", "timestamp": "1768573607857", "received_at": "2026-01-16T14:26:47.904371"}}
{"event_type": "price_change", "event_ts": "2026-01-16T14:26:47.904371", "ingestion_ts": "2026-01-16T14:27:04.418606", "market_id": "0x49a20c7523c271099008f3ef9a31521263b24d637959852a391e6b4697b1a437", "raw": {"market": "0x49a20c7523c271099008f3ef9a31521263b24d637959852a391e6b4697b1a437", "asset_id": "13018971792603393862521629014128024641178044618205296260525674415067194037856", "price": "0.147", "size": "527", "side": "SELL", "timestamp": "1768573607857", "received_at": "2026-01-16T14:26:47.904371"}}
{"event_type": "price_change", "event_ts": "2026-01-16T14:26:47.904443", "ingestion_ts": "2026-01-16T14:27:04.418606", "market_id": "0x44f08744458b8896620cd3330bc5e1ea69df4199b02d4fc583b3fc96e5d314ce", "raw": {"market": "0x44f08744458b8896620cd3330bc5e1ea69df4199b02d4fc583b3fc96e5d314ce", "asset_id": "72327831507226612545928776794104143393438710920370371172884559893525100761096", "price": "0.851", "size": "293", "side": "BUY", "timestamp": "1768573607857", "received_at": "2026-01-16T14:26:47.904443"}}
{"event_type": "price_change", "event_ts": "2026-01-16T14:26:47.904443", "ingestion_ts": "2026-01-16T14:27:04.418606", "market_id": "0x44f08744458b8896620cd3330bc5e1ea69df4199b02d4fc583b3fc96e5d314ce", "raw": {"market": "0x44f08744458b8896620cd3330bc5e1ea69df4199b02d4fc583b3fc96e5d314ce", "asset_id": "49194009556504828848509244326501559253829462790583873936160989575507522044057", "price": "0.149", "size": "293", "side": "SELL", "timestamp": "1768573607857", "received_at": "2026-01-16T14:26:47.904443"}}
{"event_type": "price_change", "event_ts": "2026-01-16T14:26:47.937470", "ingestion_ts": "2026-01-16T14:27:04.418606", "market_id": "0xb9bbdd34304344dcc45803780a34c97d73a00133a5ecf70f63e1008b8abb2fca", "raw": {"market": "0xb9bbdd34304344dcc45803780a34c97d73a00133a5ecf70f63e1008b8abb2fca", "asset_id": "8682484153073832526711485265636767086525069344085206423986003504588877767339", "price": "0.841", "size": "10", "side": "BUY", "timestamp": "1768573607900", "received_at": "2026-01-16T14:26:47.937470"}}
{"event_type": "price_change", "event_ts": "2026-01-16T14:26:47.937470", "ingestion_ts": "2026-01-16T14:27:04.418606", "market_id": "0xb9bbdd34304344dcc45803780a34c97d73a00133a5ecf70f63e1008b8abb2fca", "raw": {"market": "0xb9bbdd34304344dcc45803780a34c97d73a00133a5ecf70f63e1008b8abb2fca", "asset_id": "72012724360700510767037780555710363830014634797787940282136454146828040926557", "price": "0.159", "size": "10", "side": "SELL", "timestamp": "1768573607900", "received_at": "2026-01-16T14:26:47.937470"}}
{"event_type": "price_change", "event_ts": "2026-01-16T14:26:47.937950", "ingestion_ts": "2026-01-16T14:27:04.418606", "market_id": "0xc55db914f0fd1fee18997706712c0dfd8d0369cdbef93a9fef12bd001914ca77", "raw": {"market": "0xc55db914f0fd1fee18997706712c0dfd8d0369cdbef93a9fef12bd001914ca77", "asset_id": "114600293444080540179603459515770723592661967180480327891296353898330242622833", "price": "0.857", "size": "243", "side": "BUY", "timestamp": "1768573607900", "received_at": "2026-01-16T14:26:47.937950"}}
{"event_type": "price_change", "event_ts": "2026-01-16T14:26:47.937950", "ingestion_ts": "2026-01-16T14:27:04.418606", "market_id": "0xc55db914f0fd1fee18997706712c0dfd8d0369cdbef93a9fef12bd001914ca77", "raw": {"market": "0xc55db914f0fd1fee18997706712c0dfd8d0369cdbef93a9fef12bd001914ca77", "asset_id": "72354723612769247426741660426331235762851940382312402276325808095604519806766", "price": "0.143", "size": "243", "side": "SELL", "timestamp": "1768573607900", "received_at": "2026-01-16T14:26:47.937950"}}
{"event_type": "price_change", "event_ts": "2026-01-16T14:26:47.937988", "ingestion_ts": "2026-01-16T14:27:04.418606", "market_id": "0x9472be65457510b7fc3477b20ba90910e99d92eac8421a14bf4b7b7a08ef31dc", "raw": {"market": "0x9472be65457510b7fc3477b20ba90910e99d92eac8421a14bf4b7b7a08ef31dc", "asset_id": "43311793366960417907757893276427136943959788721376762326430771171648759300146", "price": "0.856", "size": "10", "side": "BUY", "timestamp": "1768573607900", "received_at": "2026-01-16T14:26:47.937988"}}
{"event_type": "price_change", "event_ts": "2026-01-16T14:26:47.937988", "ingestion_ts": "2026-01-16T14:27:04.418606", "market_id": "0x9472be65457510b7fc3477b20ba90910e99d92eac8421a14bf4b7b7a08ef31dc", "raw": {"market": "0x9472be65457510b7fc3477b20ba90910e99d92eac8421a14bf4b7b7a08ef31dc", "asset_id": "73414222381656326204771753454630063673548497164758947581648273905027617570612", "price": "0.144", "size": "10", "side": "SELL", "timestamp": "1768573607900", "received_at": "2026-01-16T14:26:47.937988"}}
{"event_type": "price_change", "event_ts": "2026-01-16T14:26:47.938006", "ingestion_ts": "2026-01-16T14:27:04.418606", "market_id": "0x49686d26fb712515cd5e12c23f0a1c7e10214c7faa3cb0a730aabe0c33694082", "raw": {"market": "0x49686d26fb712515cd5e12c23f0a1c7e10214c7faa3cb0a730aabe0c33694082", "asset_id": "30442780799048074404860985387051749017905070253466005720364298335239299761065", "price": "0.006", "size": "20.08", "side": "BUY", "timestamp": "1768573607900", "received_at": "2026-01-16T14:26:47.938006"}}
{"event_type": "price_change", "event_ts": "2026-01-16T14:26:47.938006", "ingestion_ts": "2026-01-16T14:27:04.418606", "market_id": "0x49686d26fb712515cd5e12c23f0a1c7e10214c7faa3cb0a730aabe0c33694082", "raw": {"market": "0x49686d26fb712515cd5e12c23f0a1c7e10214c7faa3cb0a730aabe0c33694082", "asset_id": "13244681086321087932946246027856416106585284024824496763706748621681543444582", "price": "0.994", "size": "20.08", "side": "SELL", "timestamp": "1768573607900", "received_at": "2026-01-16T14:26:47.938006"}}
{"event_type": "price_change", "event_ts": "2026-01-16T14:26:47.938551", "ingestion_ts": "2026-01-16T14:27:04.418606", "market_id": "0x50c669f178da4e5bbea7f1be25041fd278914712fa87a6a6f8e57d5923d88dee", "raw": {"market": "0x50c669f178da4e5bbea7f1be25041fd278914712fa87a6a6f8e57d5923d88dee", "asset_id": "74040420326294854165772767082819937451857852955603897473157746262672057685461", "price": "0.855", "size": "10", "side": "BUY", "timestamp": "1768573607900", "received_at": "2026-01-16T14:26:47.938551"}}
{"event_type": "price_change", "event_ts": "2026-01-16T14:26:47.938551", "ingestion_ts": "2026-01-16T14:27:04.418606", "market_id": "0x50c669f178da4e5bbea7f1be25041fd278914712fa87a6a6f8e57d5923d88dee", "raw": {"market": "0x50c669f178da4e5bbea7f1be25041fd278914712fa87a6a6f8e57d5923d88dee", "asset_id": "24682525479474221428144937281315825971983904267399062415430320764754931667953", "price": "0.145", "size": "10", "side": "SELL", "timestamp": "1768573607900", "received_at": "2026-01-16T14:26:47.938551"}}
{"event_type": "price_change", "event_ts": "2026-01-16T14:26:47.940194", "ingestion_ts": "2026-01-16T14:27:04.418606", "market_id": "0x44f08744458b8896620cd3330bc5e1ea69df4199b02d4fc583b3fc96e5d314ce", "raw": {"market": "0x44f08744458b8896620cd3330bc5e1ea69df4199b02d4fc583b3fc96e5d314ce", "asset_id": "72327831507226612545928776794104143393438710920370371172884559893525100761096", "price": "0.853", "size": "244", "side": "BUY", "timestamp": "1768573607900", "received_at": "2026-01-16T14:26:47.940194"}}
{"event_type": "price_change", "event_ts": "2026-01-16T14:26:47.940194", "ingestion_ts": "2026-01-16T14:27:04.418606", "market_id": "0x44f08744458b8896620cd3330bc5e1ea69df4199b02d4fc583b3fc96e5d314ce", "raw": {"market": "0x44f08744458b8896620cd3330bc5e1ea69df4199b02d4fc583b3fc96e5d314ce", "asset_id": "49194009556504828848509244326501559253829462790583873936160989575507522044057", "price": "0.147", "size": "244", "side": "SELL", "timestamp": "1768573607900", "received_at": "2026-01-16T14:26:47.940194"}}
{"event_type": "price_change", "event_ts": "2026-01-16T14:26:47.940224", "ingestion_ts": "2026-01-16T14:27:04.418606", "market_id": "0x49a20c7523c271099008f3ef9a31521263b24d637959852a391e6b4697b1a437", "raw": {"market": "0x49a20c7523c271099008f3ef9a31521263b24d637959852a391e6b4697b1a437", "asset_id": "55881023621710858558280545117465775643848233756850602339827152783696837905531", "price": "0.854", "size": "10", "side": "BUY", "timestamp": "1768573607900", "received_at": "2026-01-16T14:26:47.940224"}}
{"event_type": "price_change", "event_ts": "2026-01-16T14:26:47.940224", "ingestion_ts": "2026-01-16T14:27:04.418606", "market_id": "0x49a20c7523c271099008f3ef9a31521263b24d637959852a391e6b4697b1a437", "raw": {"market": "0x49a20c7523c271099008f3ef9a31521263b24d637959852a391e6b4697b1a437", "asset_id": "13018971792603393862521629014128024641178044618205296260525674415067194037856", "price": "0.146", "size": "10", "side": "SELL", "timestamp": "1768573607900", "received_at": "2026-01-16T14:26:47.940224"}}
{"event_type": "price_change", "event_ts": "2026-01-16T14:26:51.003097", "ingestion_ts": "2026-01-16T14:27:04.418606", "market_id": "0xaf9d0e448129a9f657f851d49495ba4742055d80e0ef1166ba0ee81d4d594214", "raw": {"market": "0xaf9d0e448129a9f657f851d49495ba4742055d80e0ef1166ba0ee81d4d594214", "asset_id": "4153292802911610701832309484716814274802943278345248636922528170020319407796", "price": "0.979", "size": "0", "side": "SELL", "timestamp": "1768573610954", "received_at": "2026-01-16T14:26:51.003097"}}
{"event_type": "price_change", "event_ts": "2026-01-16T14:26:51.003097", "ingestion_ts": "2026-01-16T14:27:04.418606", "market_id": "0xaf9d0e448129a9f657f851d49495ba4742055d80e0ef1166ba0ee81d4d594214", "raw": {"market": "0xaf9d0e448129a9f657f851d49495ba4742055d80e0ef1166ba0ee81d4d594214", "asset_id": "101676997363687199724245607342877036148401850938023978421879460310389391082353", "price": "0.021", "size": "0", "side": "BUY", "timestamp": "1768573610954", "received_at": "2026-01-16T14:26:51.003097"}}
{"event_type": "price_change", "event_ts": "2026-01-16T14:26:51.685550", "ingestion_ts": "2026-01-16T14:27:04.418606", "market_id": "0xaf9d0e448129a9f657f851d49495ba4742055d80e0ef1166ba0ee81d4d594214", "raw": {"market": "0xaf9d0e448129a9f657f851d49495ba4742055d80e0ef1166ba0ee81d4d594214", "asset_id": "4153292802911610701832309484716814274802943278345248636922528170020319407796", "price": "0.978", "size": "0", "side": "SELL", "timestamp": "1768573611624", "received_at": "2026-01-16T14:26:51.685550"}}
{"event_type": "price_change", "event_ts": "2026-01-16T14:26:51.685550", "ingestion_ts": "2026-01-16T14:27:04.418606", "market_id": "0xaf9d0e448129a9f657f851d49495ba4742055d80e0ef1166ba0ee81d4d594214", "raw": {"market": "0xaf9d0e448129a9f657f851d49495ba4742055d80e0ef1166ba0ee81d4d594214", "asset_id": "101676997363687199724245607342877036148401850938023978421879460310389391082353", "price": "0.022", "size": "0", "side": "BUY", "timestamp": "1768573611624", "received_at": "2026-01-16T14:26:51.685550"}}
{"event_type": "price_change", "event_ts": "2026-01-16T14:26:51.710950", "ingestion_ts": "2026-01-16T14:27:04.418606", "market_id": "0xaf9d0e448129a9f657f851d49495ba4742055d80e0ef1166ba0ee81d4d594214", "raw": {"market": "0xaf9d0e448129a9f657f851d49495ba4742055d80e0ef1166ba0ee81d4d594214", "asset_id": "4153292802911610701832309484716814274802943278345248636922528170020319407796", "price": "0.989", "size": "20.5", "side": "SELL", "timestamp": "1768573611670", "received_at": "2026-01-16T14:26:51.710950"}}
{"event_type": "price_change", "event_ts": "2026-01-16T14:26:51.710950", "ingestion_ts": "2026-01-16T14:27:04.418606", "market_id": "0xaf9d0e448129a9f657f851d49495ba4742055d80e0ef1166ba0ee81d4d594214", "raw": {"market": "0xaf9d0e448129a9f657f851d49495ba4742055d80e0ef1166ba0ee81d4d594214", "asset_id": "101676997363687199724245607342877036148401850938023978421879460310389391082353", "price": "0.011", "size": "20.5", "side": "BUY", "timestamp": "1768573611670", "received_at": "2026-01-16T14:26:51.710950"}}
{"event_type": "price_change", "event_ts": "2026-01-16T14:26:52.751965", "ingestion_ts": "2026-01-16T14:27:04.418606", "market_id": "0xc0e6b917320a47228fb96e3b5ae0e5c93773a5ae2662ae4e1f37807cfe47ce98", "raw": {"market": "0xc0e6b917320a47228fb96e3b5ae0e5c93773a5ae2662ae4e1f37807cfe47ce98", "asset_id": "58656358377246279051017109359677190749228949103591068167284263961542487110215", "price": "0.004", "size": "123.29", "side": "BUY", "timestamp": "1768573612570", "received_at": "2026-01-16T14:26:52.751965"}}
{"event_type": "price_change", "event_ts": "2026-01-16T14:26:52.751965", "ingestion_ts": "2026-01-16T14:27:04.418606", "market_id": "0xc0e6b917320a47228fb96e3b5ae0e5c93773a5ae2662ae4e1f37807cfe47ce98", "raw": {"market": "0xc0e6b917320a47228fb96e3b5ae0e5c93773a5ae2662ae4e1f37807cfe47ce98", "asset_id": "81647294538046680798858716589766492074338758116170717123345952330712416337530", "price": "0.996", "size": "123.29", "side": "SELL", "timestamp": "1768573612570", "received_at": "2026-01-16T14:26:52.751965"}}
{"event_type": "price_change", "event_ts": "2026-01-16T14:26:52.861798", "ingestion_ts": "2026-01-16T14:27:04.418606", "market_id": "0x49a20c7523c271099008f3ef9a31521263b24d637959852a391e6b4697b1a437", "raw": {"market": "0x49a20c7523c271099008f3ef9a31521263b24d637959852a391e6b4697b1a437", "asset_id": "55881023621710858558280545117465775643848233756850602339827152783696837905531", "price": "0.854", "size": "0", "side": "BUY", "timestamp": "1768573612812", "received_at": "2026-01-16T14:26:52.861798"}}
{"event_type": "price_change", "event_ts": "2026-01-16T14:26:52.861798", "ingestion_ts": "2026-01-16T14:27:04.418606", "market_id": "0x49a20c7523c271099008f3ef9a31521263b24d637959852a391e6b4697b1a437", "raw": {"market": "0x49a20c7523c271099008f3ef9a31521263b24d637959852a391e6b4697b1a437", "asset_id": "13018971792603393862521629014128024641178044618205296260525674415067194037856", "price": "0.146", "size": "0", "side": "SELL", "timestamp": "1768573612812", "received_at": "2026-01-16T14:26:52.861798"}}
{"event_type": "price_change", "event_ts": "2026-01-16T14:26:52.861837", "ingestion_ts": "2026-01-16T14:27:04.418606", "market_id": "0xb9bbdd34304344dcc45803780a34c97d73a00133a5ecf70f63e1008b8abb2fca", "raw": {"market": "0xb9bbdd34304344dcc45803780a34c97d73a00133a5ecf70f63e1008b8abb2fca", "asset_id": "8682484153073832526711485265636767086525069344085206423986003504588877767339", "price": "0.841", "size": "0", "side": "BUY", "timestamp": "1768573612812", "received_at": "2026-01-16T14:26:52.861837"}}
{"event_type": "price_change", "event_ts": "2026-01-16T14:26:52.861837", "ingestion_ts": "2026-01-16T14:27:04.418606", "market_id": "0xb9bbdd34304344dcc45803780a34c97d73a00133a5ecf70f63e1008b8abb2fca", "raw": {"market": "0xb9bbdd34304344dcc45803780a34c97d73a00133a5ecf70f63e1008b8abb2fca", "asset_id": "72012724360700510767037780555710363830014634797787940282136454146828040926557", "price": "0.159", "size": "0", "side": "SELL", "timestamp": "1768573612812", "received_at": "2026-01-16T14:26:52.861837"}}
{"event_type": "price_change", "event_ts": "2026-01-16T14:26:52.861851", "ingestion_ts": "2026-01-16T14:27:04.418606", "market_id": "0x49686d26fb712515cd5e12c23f0a1c7e10214c7faa3cb0a730aabe0c33694082", "raw": {"market": "0x49686d26fb712515cd5e12c23f0a1c7e10214c7faa3cb0a730aabe0c33694082", "asset_id": "30442780799048074404860985387051749017905070253466005720364298335239299761065", "price": "0.006", "size": "10.08", "side": "BUY", "timestamp": "1768573612812", "received_at": "2026-01-16T14:26:52.861851"}}
