{"event_type": "price_change", "event_ts": "2026-01-16T14:19:57.100705", "ingestion_ts": "2026-01-16T14:20:56.869125", "market_id": "0x2393ed0b0fdc450054c7b9071907eca75cf4fc36e385adf4a0a5f99ee62243e8", "raw": {"market": "0x2393ed0b0fdc450054c7b9071907eca75cf4fc36e385adf4a0a5f99ee62243e8", "asset_id": "32769749367306925959219403371425714180265458150646381231272229429098460625924", "price": "0.942", "size": "50", "side": "BUY", "timestamp": "1768573197027", "received_at": "2026-01-16T14:19:57.100705"}}
{"event_type": "price_change", "event_ts": "2026-01-16T14:19:57.100705", "ingestion_ts": "2026-01-16T14:20:56.869125", "market_id": "0x2393ed0b0fdc450054c7b9071907eca75cf4fc36e385adf4a0a5f99ee62243e8", "raw": {"market": "0x2393ed0b0fdc450054c7b9071907eca75cf4fc36e385adf4a0a5f99ee62243e8", "asset_id": "100074770378634056601572485653252702850363676459996771990439989989293515601975", "price": "0.058", "size": "50", "side": "SELL", "timestamp": "1768573197027", "received_at": "2026-01-16T14:19:57.100705"}}
{"event_type": "price_change", "event_ts": "2026-01-16T14:19:57.145369", "ingestion_ts": "2026-01-16T14:20:56.869125", "market_id": "0x2393ed0b0fdc450054c7b9071907eca75cf4fc36e385adf4a0a5f99ee62243e8", "raw": {"market": "0x2393ed0b0fdc450054c7b9071907eca75cf4fc36e385adf4a0a5f99ee62243e8", "asset_id": "100074770378634056601572485653252702850363676459996771990439989989293515601975", "price": "0.059", "size": "0", "side": "SELL", "timestamp": "1768573197097", "received_at": "2026-01-16T14:19:57.145369"}}
{"event_type": "price_change", "event_ts": "2026-01-16T14:19:57.145369", "ingestion_ts": "2026-01-16T14:20:56.869125", "market_id": "0x2393ed0b0fdc450054c7b9071907eca75cf4fc36e385adf4a0a5f99ee62243e8", "raw": {"market": "0x2393ed0b0fdc450054c7b9071907eca75cf4fc36e385adf4a0a5f99ee62243e8", "asset_id": "32769749367306925959219403371425714180265458150646381231272229429098460625924", "price": "0.941", "size": "0", "side": "BUY", "timestamp": "1768573197097", "received_at": "2026-01-16T14:19:57.145369"}}
{"event_type": "price_change", "event_ts": "2026-01-16T14:19:57.170075", "ingestion_ts": "2026-01-16T14:20:56.869125", "market_id": "0x427bc4b40c09b3dcbc973747f0e4b079bed91b3e5a0aed5c36edd0f7591485f4", "raw": {"market": "0x427bc4b40c09b3dcbc973747f0e4b079bed91b3e5a0aed5c36edd0f7591485f4", "asset_id": "115669573443672055876643967408433138119481486650803218131873713375232186497057", "price": "0.183", "size": "22.07", "side": "SELL", "timestamp": "1768573197128", "received_at": "2026-01-16T14:19:57.170075"}}
{"event_type": "price_change", "event_ts": "2026-01-16T14:19:57.170075", "ingestion_ts": "2026-01-16T14:20:56.869125", "market_id": "0x427bc4b40c09b3dcbc973747f0e4b079bed91b3e5a0aed5c36edd0f7591485f4", "raw": {"market": "0x427bc4b40c09b3dcbc973747f0e4b079bed91b3e5a0aed5c36edd0f7591485f4", "asset_id": "86130975769502911188457673769190265049139877688522439001984850068234616395137", "price": "0.817", "size": "22.07", "side": "BUY", "timestamp": "1768573197128", "received_at": "2026-01-16T14:19:57.170075"}}
{"event_type": "price_change", "event_ts": "2026-01-16T14:19:57.170135", "ingestion_ts": "2026-01-16T14:20:56.869125", "market_id": "0x2393ed0b0fdc450054c7b9071907eca75cf4fc36e385adf4a0a5f99ee62243e8", "raw": {"market": "0x2393ed0b0fdc450054c7b9071907eca75cf4fc36e385adf4a0a5f99ee62243e8", "asset_id": "100074770378634056601572485653252702850363676459996771990439989989293515601975", "price": "0.057", "size": "205", "side": "SELL", "timestamp": "1768573197128", "received_at": "2026-01-16T14:19:57.170135"}}
{"event_type": "price_change", "event_ts": "2026-01-16T14:19:57.170135", "ingestion_ts": "2026-01-16T14:20:56.869125", "market_id": "0x2393ed0b0fdc450054c7b9071907eca75cf4fc36e385adf4a0a5f99ee62243e8", "raw": {"market": "0x2393ed0b0fdc450054c7b9071907eca75cf4fc36e385adf4a0a5f99ee62243e8", "asset_id": "32769749367306925959219403371425714180265458150646381231272229429098460625924", "price": "0.943", "size": "205", "side": "BUY", "timestamp": "1768573197128", "received_at": "2026-01-16T14:19:57.170135"}}
{"event_type": "price_change", "event_ts": "2026-01-16T14:19:57.173842", "ingestion_ts": "2026-01-16T14:20:56.869125", "market_id": "0x427bc4b40c09b3dcbc973747f0e4b079bed91b3e5a0aed5c36edd0f7591485f4", "raw": {"market": "0x427bc4b40c09b3dcbc973747f0e4b079bed91b3e5a0aed5c36edd0f7591485f4", "asset_id": "115669573443672055876643967408433138119481486650803218131873713375232186497057", "price": "0.184", "size": "52.88", "side": "SELL", "timestamp": "1768573197134", "received_at": "2026-01-16T14:19:57.173842"}}
{"event_type": "price_change", "event_ts": "2026-01-16T14:19:57.173842", "ingestion_ts": "2026-01-16T14:20:56.869125", "market_id": "0x427bc4b40c09b3dcbc973747f0e4b079bed91b3e5a0aed5c36edd0f7591485f4", "raw": {"market": "0x427bc4b40c09b3dcbc973747f0e4b079bed91b3e5a0aed5c36edd0f7591485f4", "asset_id": "86130975769502911188457673769190265049139877688522439001984850068234616395137", "price": "0.816", "size": "52.88", "side": "BUY", "timestamp": "1768573197134", "received_at": "2026-01-16T14:19:57.173842"}}
{"event_type": "price_change", "event_ts": "2026-01-16T14:19:57.184967", "ingestion_ts": "2026-01-16T14:20:56.869125", "market_id": "0x427bc4b40c09b3dcbc973747f0e4b079bed91b3e5a0aed5c36edd0f7591485f4", "raw": {"market": "0x427bc4b40c09b3dcbc973747f0e4b079bed91b3e5a0aed5c36edd0f7591485f4", "asset_id": "115669573443672055876643967408433138119481486650803218131873713375232186497057", "price": "0.183", "size": "44.14", "side": "SELL", "timestamp": "1768573197137", "received_at": "2026-01-16T14:19:57.184967"}}
{"event_type": "price_change", "event_ts": "2026-01-16T14:19:57.184967", "ingestion_ts": "2026-01-16T14:20:56.869125", "market_id": "0x427bc4b40c09b3dcbc973747f0e4b079bed91b3e5a0aed5c36edd0f7591485f4", "raw": {"market": "0x427bc4b40c09b3dcbc973747f0e4b079bed91b3e5a0aed5c36edd0f7591485f4", "asset_id": "86130975769502911188457673769190265049139877688522439001984850068234616395137", "price": "0.817", "size": "44.14", "side": "BUY", "timestamp": "1768573197137", "received_at": "2026-01-16T14:19:57.184967"}}
{"event_type": "price_change", "event_ts": "2026-01-16T14:19:57.185013", "ingestion_ts": "2026-01-16T14:20:56.869125", "market_id": "0x427bc4b40c09b3dcbc973747f0e4b079bed91b3e5a0aed5c36edd0f7591485f4", "raw": {"market": "0x427bc4b40c09b3dcbc973747f0e4b079bed91b3e5a0aed5c36edd0f7591485f4", "asset_id": "115669573443672055876643967408433138119481486650803218131873713375232186497057", "price": "0.184", "size": "58.76", "side": "SELL", "timestamp": "1768573197141", "received_at": "2026-01-16T14:19:57.185013"}}
{"event_type": "price_change", "event_ts": "2026-01-16T14:19:57.185013", "ingestion_ts": "2026-01-16T14:20:56.869125", "market_id": "0x427bc4b40c09b3dcbc973747f0e4b079bed91b3e5a0aed5c36edd0f7591485f4", "raw": {"market": "0x427bc4b40c09b3dcbc973747f0e4b079bed91b3e5a0aed5c36edd0f7591485f4", "asset_id": "86130975769502911188457673769190265049139877688522439001984850068234616395137", "price": "0.816", "size": "58.76", "side": "BUY", "timestamp": "1768573197141", "received_at": "2026-01-16T14:19:57.185013"}}
{"event_type": "price_change", "event_ts": "2026-01-16T14:19:57.229110", "ingestion_ts": "2026-01-16T14:20:56.869125", "market_id": "0x427bc4b40c09b3dcbc973747f0e4b079bed91b3e5a0aed5c36edd0f7591485f4", "raw": {"market": "0x427bc4b40c09b3dcbc973747f0e4b079bed91b3e5a0aed5c36edd0f7591485f4", "asset_id": "86130975769502911188457673769190265049139877688522439001984850068234616395137", "price": "0.816", "size": "11.76", "side": "BUY", "timestamp": "1768573197161", "received_at": "2026-01-16T14:19:57.229110"}}
{"event_type": "price_change", "event_ts": "2026-01-16T14:19:57.229110", "ingestion_ts": "2026-01-16T14:20:56.869125", "market_id": "0x427bc4b40c09b3dcbc973747f0e4b079bed91b3e5a0aed5c36edd0f7591485f4", "raw": {"market": "0x427bc4b40c09b3dcbc973747f0e4b079bed91b3e5a0aed5c36edd0f7591485f4", "asset_id": "115669573443672055876643967408433138119481486650803218131873713375232186497057", "price": "0.184", "size": "11.76", "side": "SELL", "timestamp": "1768573197161", "received_at": "2026-01-16T14:19:57.229110"}}
{"event_type": "price_change", "event_ts": "2026-01-16T14:19:57.288002", "ingestion_ts": "2026-01-16T14:20:56.869125", "market_id": "0x427bc4b40c09b3dcbc973747f0e4b079bed91b3e5a0aed5c36edd0f7591485f4", "raw": {"market": "0x427bc4b40c09b3dcbc973747f0e4b079bed91b3e5a0aed5c36edd0f7591485f4", "asset_id": "86130975769502911188457673769190265049139877688522439001984850068234616395137", "price": "0.818", "size": "35", "side": "BUY", "timestamp": "1768573197200", "received_at": "2026-01-16T14:19:57.288002"}}
{"event_type": "price_change", "event_ts": "2026-01-16T14:19:57.288002", "ingestion_ts": "2026-01-16T14:20:56.869125", "market_id": "0x427bc4b40c09b3dcbc973747f0e4b079bed91b3e5a0aed5c36edd0f7591485f4", "raw": {"market": "0x427bc4b40c09b3dcbc973747f0e4b079bed91b3e5a0aed5c36edd0f7591485f4", "asset_id": "115669573443672055876643967408433138119481486650803218131873713375232186497057", "price": "0.182", "size": "35", "side": "SELL", "timestamp": "1768573197200", "received_at": "2026-01-16T14:19:57.288002"}}
{"event_type": "price_change", "event_ts": "2026-01-16T14:19:57.429511", "ingestion_ts": "2026-01-16T14:20:56.869125", "market_id": "0x2393ed0b0fdc450054c7b9071907eca75cf4fc36e385adf4a0a5f99ee62243e8", "raw": {"market": "0x2393ed0b0fdc450054c7b9071907eca75cf4fc36e385adf4a0a5f99ee62243e8", "asset_id": "32769749367306925959219403371425714180265458150646381231272229429098460625924", "price": "0.94", "size": "0", "side": "BUY", "timestamp": "1768573197327", "received_at": "2026-01-16T14:19:57.429511"}}
{"event_type": "price_change", "event_ts": "2026-01-16T14:19:57.429511", "ingestion_ts": "2026-01-16T14:20:56.869125", "market_id": "0x2393ed0b0fdc450054c7b9071907eca75cf4fc36e385adf4a0a5f99ee62243e8", "raw": {"market": "0x2393ed0b0fdc450054c7b9071907eca75cf4fc36e385adf4a0a5f99ee62243e8", "asset_id": "100074770378634056601572485653252702850363676459996771990439989989293515601975", "price": "0.06", "size": "0", "side": "SELL", "timestamp": "1768573197327", "received_at": "2026-01-16T14:19:57.429511"}}
{"event_type": "price_change", "event_ts": "2026-01-16T14:19:58.674349", "ingestion_ts": "2026-01-16T14:20:56.869125", "market_id": "0x49686d26fb712515cd5e12c23f0a1c7e10214c7faa3cb0a730aabe0c33694082", "raw": {"market": "0x49686d26fb712515cd5e12c23f0a1c7e10214c7faa3cb0a730aabe0c33694082", "asset_id": "13244681086321087932946246027856416106585284024824496763706748621681543444582", "price": "0.853", "size": "50.86", "side": "BUY", "timestamp": "1768573198590", "received_at": "2026-01-16T14:19:58.674349"}}
{"event_type": "price_change", "event_ts": "2026-01-16T14:19:58.674349", "ingestion_ts": "2026-01-16T14:20:56.869125", "market_id": "0x49686d26fb712515cd5e12c23f0a1c7e10214c7faa3cb0a730aabe0c33694082", "raw": {"market": "0x49686d26fb712515cd5e12c23f0a1c7e10214c7faa3cb0a730aabe0c33694082", "asset_id": "30442780799048074404860985387051749017905070253466005720364298335239299761065", "price": "0.147", "size": "50.86", "side": "SELL", "timestamp": "1768573198590", "received_at": "2026-01-16T14:19:58.674349"}}
{"event_type": "price_change", "event_ts": "2026-01-16T14:19:58.711344", "ingestion_ts": "2026-01-16T14:20:56.869125", "market_id": "0x427bc4b40c09b3dcbc973747f0e4b079bed91b3e5a0aed5c36edd0f7591485f4", "raw": {"market": "0x427bc4b40c09b3dcbc973747f0e4b079bed91b3e5a0aed5c36edd0f7591485f4", "asset_id": "115669573443672055876643967408433138119481486650803218131873713375232186497057", "price": "0.002", "size": "109.4", "side": "BUY", "timestamp": "1768573198665", "received_at": "2026-01-16T14:19:58.711344"}}
{"event_type": "price_change", "event_ts": "2026-01-16T14:19:58.711344", "ingestion_ts": "2026-01-16T14:20:56.869125", "market_id": "0x427bc4b40c09b3dcbc973747f0e4b079bed91b3e5a0aed5c36edd0f7591485f4", "raw": {"market": "0x427bc4b40c09b3dcbc973747f0e4b079bed91b3e5a0aed5c36edd0f7591485f4", "asset_id": "86130975769502911188457673769190265049139877688522439001984850068234616395137", "price": "0.998", "size": "109.4", "side": "SELL", "timestamp": "1768573198665", "received_at": "2026-01-16T14:19:58.711344"}}
{"event_type": "price_change", "event_ts": "2026-01-16T14:19:58.711407", "ingestion_ts": "2026-01-16T14:20:56.869125", "market_id": "0x427bc4b40c09b3dcbc973747f0e4b079bed91b3e5a0aed5c36edd0f7591485f4", "raw": {"market": "0x427bc4b40c09b3dcbc973747f0e4b079bed91b3e5a0aed5c36edd0f7591485f4", "asset_id": "115669573443672055876643967408433138119481486650803218131873713375232186497057", "price": "0.006", "size": "21.35", "side": "BUY", "timestamp": "1768573198665", "received_at": "2026-01-16T14:19:58.711407"}}
{"event_type": "price_change", "event_ts": "2026-01-16T14:19:58.711407", "ingestion_ts": "2026-01-16T14:20:56.869125", "market_id": "0x427bc4b40c09b3dcbc973747f0e4b079bed91b3e5a0aed5c36edd0f7591485f4", "raw": {"market": "0x427bc4b40c09b3dcbc973747f0e4b079bed91b3e5a0aed5c36edd0f7591485f4", "asset_id": "86130975769502911188457673769190265049139877688522439001984850068234616395137", "price": "0.994", "size": "21.35", "side": "SELL", "timestamp": "1768573198665", "received_at": "2026-01-16T14:19:58.711407"}}
{"event_type": "price_change", "event_ts": "2026-01-16T14:19:59.109750", "ingestion_ts": "2026-01-16T14:20:56.869125", "market_id": "0x427bc4b40c09b3dcbc973747f0e4b079bed91b3e5a0aed5c36edd0f7591485f4", "raw": {"market": "0x427bc4b40c09b3dcbc973747f0e4b079bed91b3e5a0aed5c36edd0f7591485f4", "asset_id": "115669573443672055876643967408433138119481486650803218131873713375232186497057", "price": "0.008", "size": "5.14", "side": "BUY", "timestamp": "1768573199067", "received_at": "2026-01-16T14:19:59.109750"}}
{"event_type": "price_change", "event_ts": "2026-01-16T14:19:59.109750", "ingestion_ts": "2026-01-16T14:20:56.869125", "market_id": "0x427bc4b40c09b3dcbc973747f0e4b079bed91b3e5a0aed5c36edd0f7591485f4", "raw": {"market": "0x427bc4b40c09b3dcbc973747f0e4b079bed91b3e5a0aed5c36edd0f7591485f4", "asset_id": "86130975769502911188457673769190265049139877688522439001984850068234616395137", "price": "0.992", "size": "5.14", "side": "SELL", "timestamp": "1768573199067", "received_at": "2026-01-16T14:19:59.109750"}}
{"event_type": "price_change", "event_ts": "2026-01-16T14:19:59.111336", "ingestion_ts": "2026-01-16T14:20:56.869125", "market_id": "0x427bc4b40c09b3dcbc973747f0e4b079bed91b3e5a0aed5c36edd0f7591485f4", "raw": {"market": "0x427bc4b40c09b3dcbc973747f0e4b079bed91b3e5a0aed5c36edd0f7591485f4", "asset_id": "115669573443672055876643967408433138119481486650803218131873713375232186497057", "price": "0.003", "size": "5.06", "side": "BUY", "timestamp": "1768573199068", "received_at": "2026-01-16T14:19:59.111336"}}
{"event_type": "price_change", "event_ts": "2026-01-16T14:19:59.111336", "ingestion_ts": "2026-01-16T14:20:56.869125", "market_id": "0x427bc4b40c09b3dcbc973747f0e4b079bed91b3e5a0aed5c36edd0f7591485f4", "raw": {"market": "0x427bc4b40c09b3dcbc973747f0e4b079bed91b3e5a0aed5c36edd0f7591485f4", "asset_id": "86130975769502911188457673769190265049139877688522439001984850068234616395137", "price": "0.997", "size": "5.06", "side": "SELL", "timestamp": "1768573199068", "received_at": "2026-01-16T14:19:59.111336"}}
{"event_type": "price_change", "event_ts": "2026-01-16T14:19:59.111379", "ingestion_ts": "2026-01-16T14:20:56.869125", "market_id": "0x427bc4b40c09b3dcbc973747f0e4b079bed91b3e5a0aed5c36edd0f7591485f4", "raw": {"market": "0x427bc4b40c09b3dcbc973747f0e4b079bed91b3e5a0aed5c36edd0f7591485f4", "asset_id": "115669573443672055876643967408433138119481486650803218131873713375232186497057", "price": "0.007", "size": "41.9", "side": "BUY", "timestamp": "1768573199069", "received_at": "2026-01-16T14:19:59.111379"}}
{"event_type": "price_change", "event_ts": "2026-01-16T14:19:59.111379", "ingestion_ts": "2026-01-16T14:20:56.869125", "market_id": "0x427bc4b40c09b3dcbc973747f0e4b079bed91b3e5a0aed5c36edd0f7591485f4", "raw": {"market": "0x427bc4b40c09b3dcbc973747f0e4b079bed91b3e5a0aed5c36edd0f7591485f4", "asset_id": "86130975769502911188457673769190265049139877688522439001984850068234616395137", "price": "0.993", "size": "41.9", "side": "SELL", "timestamp": "1768573199069", "received_at": "2026-01-16T14:19:59.111379"}}
{"event_type": "price_change", "event_ts": "2026-01-16T14:19:59.172997", "ingestion_ts": "2026-01-16T14:20:56.869125", "market_id": "0x427bc4b40c09b3dcbc973747f0e4b079bed91b3e5a0aed5c36edd0f7591485f4", "raw": {"market": "0x427bc4b40c09b3dcbc973747f0e4b079bed91b3e5a0aed5c36edd0f7591485f4", "asset_id": "86130975769502911188457673769190265049139877688522439001984850068234616395137", "price": "0.818", "size": "0", "side": "BUY", "timestamp": "1768573199098", "received_at": "2026-01-16T14:19:59.172997"}}
{"event_type": "price_change", "event_ts": "2026-01-16T14:19:59.172997", "ingestion_ts": "2026-01-16T14:20:56.869125", "market_id": "0x427bc4b40c09b3dcbc973747f0e4b079bed91b3e5a0aed5c36edd0f7591485f4", "raw": {"market": "0x427bc4b40c09b3dcbc973747f0e4b079bed91b3e5a0aed5c36edd0f7591485f4", "asset_id": "115669573443672055876643967408433138119481486650803218131873713375232186497057", "price": "0.182", "size": "0", "side": "SELL", "timestamp": "1768573199098", "received_at": "2026-01-16T14:19:59.172997"}}
{"event_type": "price_change", "event_ts": "2026-01-16T14:19:59.173039", "ingestion_ts": "2026-01-16T14:20:56.869125", "market_id": "0x427bc4b40c09b3dcbc973747f0e4b079bed91b3e5a0aed5c36edd0f7591485f4", "raw": {"market": "0x427bc4b40c09b3dcbc973747f0e4b079bed91b3e5a0aed5c36edd0f7591485f4", "asset_id": "86130975769502911188457673769190265049139877688522439001984850068234616395137", "price": "0.993", "size": "5.9", "side": "SELL", "timestamp": "1768573199098", "received_at": "2026-01-16T14:19:59.173039"}}
{"event_type": "price_change", "event_ts": "2026-01-16T14:19:59.173039", "ingestion_ts": "2026-01-16T14:20:56.869125", "market_id": "0x427bc4b40c09b3dcbc973747f0e4b079bed91b3e5a0aed5c36edd0f7591485f4", "raw": {"market": "0x427bc4b40c09b3dcbc973747f0e4b079bed91b3e5a0aed5c36edd0f7591485f4", "asset_id": "115669573443672055876643967408433138119481486650803218131873713375232186497057", "price": "0.007", "size": "5.9", "side": "BUY", "timestamp": "1768573199098", "received_at": "2026-01-16T14:19:59.173039"}}
{"event_type": "price_change", "event_ts": "2026-01-16T14:19:59.308275", "ingestion_ts": "2026-01-16T14:20:56.869125", "market_id": "0x49686d26fb712515cd5e12c23f0a1c7e10214c7faa3cb0a730aabe0c33694082", "raw": {"market": "0x49686d26fb712515cd5e12c23f0a1c7e10214c7faa3cb0a730aabe0c33694082", "asset_id": "30442780799048074404860985387051749017905070253466005720364298335239299761065", "price": "0.148", "size": "0", "side": "SELL", "timestamp": "1768573199217", "received_at": "2026-01-16T14:19:59.308275"}}
{"event_type": "price_change", "event_ts": "2026-01-16T14:19:59.308275", "ingestion_ts": "2026-01-16T14:20:56.869125", "market_id": "0x49686d26fb712515cd5e12c23f0a1c7e10214c7faa3cb0a730aabe0c33694082", "raw": {"market": "0x49686d26fb712515cd5e12c23f0a1c7e10214c7faa3cb0a730aabe0c33694082", "asset_id": "13244681086321087932946246027856416106585284024824496763706748621681543444582", "price": "0.852", "size": "0", "side": "BUY", "timestamp": "1768573199217", "received_at": "2026-01-16T14:19:59.308275"}}
{"event_type": "price_change", "event_ts": "2026-01-16T14:19:59.337930", "ingestion_ts": "2026-01-16T14:20:56.869125", "market_id": "0x49686d26fb712515cd5e12c23f0a1c7e10214c7faa3cb0a730aabe0c33694082", "raw": {"market": "0x49686d26fb712515cd5e12c23f0a1c7e10214c7faa3cb0a730aabe0c33694082", "asset_id": "30442780799048074404860985387051749017905070253466005720364298335239299761065", "price": "0.146", "size": "17.5", "side": "SELL", "timestamp": "1768573199280", "received_at": "2026-01-16T14:19:59.337930"}}
{"event_type": "price_change", "event_ts": "2026-01-16T14:19:59.337930", "ingestion_ts": "2026-01-16T14:20:56.869125", "market_id": "0x49686d26fb712515cd5e12c23f0a1c7e10214c7faa3cb0a730aabe0c33694082", "raw": {"market": "0x49686d26fb712515cd5e12c23f0a1c7e10214c7faa3cb0a730aabe0c33694082", "asset_id": "13244681086321087932946246027856416106585284024824496763706748621681543444582", "price": "0.854", "size": "17.5", "side": "BUY", "timestamp": "1768573199280", "received_at": "2026-01-16T14:19:59.337930"}}
{"event_type": "price_change", "event_ts": "2026-01-16T14:19:59.359276", "ingestion_ts": "2026-01-16T14:20:56.869125", "market_id": "0x49686d26fb712515cd5e12c23f0a1c7e10214c7faa3cb0a730aabe0c33694082", "raw": {"market": "0x49686d26fb712515cd5e12c23f0a1c7e10214c7faa3cb0a730aabe0c33694082", "asset_id": "13244681086321087932946246027856416106585284024824496763706748621681543444582", "price": "0.911", "size": "14.98", "side": "SELL", "timestamp": "1768573199308", "received_at": "2026-01-16T14:19:59.359276"}}
{"event_type": "price_change", "event_ts": "2026-01-16T14:19:59.359276", "ingestion_ts": "2026-01-16T14:20:56.869125", "market_id": "0x49686d26fb712515cd5e12c23f0a1c7e10214c7faa3cb0a730aabe0c33694082", "raw": {"market": "0x49686d26fb712515cd5e12c23f0a1c7e10214c7faa3cb0a730aabe0c33694082", "asset_id": "30442780799048074404860985387051749017905070253466005720364298335239299761065", "price": "0.089", "size": "14.98", "side": "BUY", "timestamp": "1768573199308", "received_at": "2026-01-16T14:19:59.359276"}}
{"event_type": "price_change", "event_ts": "2026-01-16T14:19:59.602850", "ingestion_ts": "2026-01-16T14:20:56.869125", "market_id": "0x427bc4b40c09b3dcbc973747f0e4b079bed91b3e5a0aed5c36edd0f7591485f4", "raw": {"market": "0x427bc4b40c09b3dcbc973747f0e4b079bed91b3e5a0aed5c36edd0f7591485f4", "asset_id": "115669573443672055876643967408433138119481486650803218131873713375232186497057", "price": "0.183", "size": "22.07", "side": "SELL", "timestamp": "1768573199563", "received_at": "2026-01-16T14:19:59.602850"}}
{"event_type": "price_change", "event_ts": "2026-01-16T14:19:59.602850", "ingestion_ts": "2026-01-16T14:20:56.869125", "market_id": "0x427bc4b40c09b3dcbc973747f0e4b079bed91b3e5a0aed5c36edd0f7591485f4", "raw": {"market": "0x427bc4b40c09b3dcbc973747f0e4b079bed91b3e5a0aed5c36edd0f7591485f4", "asset_id": "86130975769502911188457673769190265049139877688522439001984850068234616395137", "price": "0.817", "size": "22.07", "side": "BUY", "timestamp": "1768573199563", "received_at": "2026-01-16T14:19:59.602850"}}
{"event_type": "price_change", "event_ts": "2026-01-16T14:19:59.603191", "ingestion_ts": "2026-01-16T14:20:56.869125", "market_id": "0x427bc4b40c09b3dcbc973747f0e4b079bed91b3e5a0aed5c36edd0f7591485f4", "raw": {"market": "0x427bc4b40c09b3dcbc973747f0e4b079bed91b3e5a0aed5c36edd0f7591485f4", "asset_id": "115669573443672055876643967408433138119481486650803218131873713375232186497057", "price": "0.184", "size": "5.88", "side": "SELL", "timestamp": "1768573199563", "received_at": "2026-01-16T14:19:59.603191"}}
{"event_type": "price_change", "event_ts": "2026-01-16T14:19:59.603191", "ingestion_ts": "2026-01-16T14:20:56.869125", "market_id": "0x427bc4b40c09b3dcbc973747f0e4b079bed91b3e5a0aed5c36edd0f7591485f4", "raw": {"market": "0x427bc4b40c09b3dcbc973747f0e4b079bed91b3e5a0aed5c36edd0f7591485f4", "asset_id": "86130975769502911188457673769190265049139877688522439001984850068234616395137", "price": "0.816", "size": "5.88", "side": "BUY", "timestamp": "1768573199563", "received_at": "2026-01-16T14:19:59.603191"}}
{"event_type": "price_change", "event_ts": "2026-01-16T14:19:59.603221", "ingestion_ts": "2026-01-16T14:20:56.869125", "market_id": "0x427bc4b40c09b3dcbc973747f0e4b079bed91b3e5a0aed5c36edd0f7591485f4", "raw": {"market": "0x427bc4b40c09b3dcbc973747f0e4b079bed91b3e5a0aed5c36edd0f7591485f4", "asset_id": "115669573443672055876643967408433138119481486650803218131873713375232186497057", "price": "0.185", "size": "0", "side": "SELL", "timestamp": "1768573199563", "received_at": "2026-01-16T14:19:59.603221"}}
{"event_type": "price_change", "event_ts": "2026-01-16T14:19:59.603221", "ingestion_ts": "2026-01-16T14:20:56.869125", "market_id": "0x427bc4b40c09b3dcbc973747f0e4b079bed91b3e5a0aed5c36edd0f7591485f4", "raw": {"market": "0x427bc4b40c09b3dcbc973747f0e4b079bed91b3e5a0aed5c36edd0f7591485f4", "asset_id": "86130975769502911188457673769190265049139877688522439001984850068234616395137", "price": "0.815", "size": "0", "side": "BUY", "timestamp": "1768573199563", "received_at": "2026-01-16T14:19:59.603221"}}
{"event_type": "price_change", "event_ts": "2026-01-16T14:19:59.958178", "ingestion_ts": "2026-01-16T14:20:56.869125", "market_id": "0xae5584fbb57f23c1c608d544b656f23d8bf12340cef70811cf31bb0cb4fc2115", "raw": {"market": "0xae5584fbb57f23c1c608d544b656f23d8bf12340cef70811cf31bb0cb4fc2115", "asset_id": "42278252558046940014991595990628759801692726198478046188873057685686228021663", "price": "0.99", "size": "8199.8", "side": "SELL", "timestamp": "1768573199912", "received_at": "2026-01-16T14:19:59.958178"}}
{"event_type": "price_change", "event_ts": "2026-01-16T14:19:59.958178", "ingestion_ts": "2026-01-16T14:20:56.869125", "market_id": "0xae5584fbb57f23c1c608d544b656f23d8bf12340cef70811cf31bb0cb4fc2115", "raw": {"market": "0xae5584fbb57f23c1c608d544b656f23d8bf12340cef70811cf31bb0cb4fc2115", "asset_id": "28946595841244317705636126646676849578876740730186646421280828201004700559420", "price": "0.01", "size": "8199.8", "side": "BUY", "timestamp": "1768573199912", "received_at": "2026-01-16T14:19:59.958178"}}
{"event_type": "price_change", "event_ts": "2026-01-16T14:20:00.079695", "ingestion_ts": "2026-01-16T14:20:56.869125", "market_id": "0x427bc4b40c09b3dcbc973747f0e4b079bed91b3e5a0aed5c36edd0f7591485f4", "raw": {"market": "0x427bc4b40c09b3dcbc973747f0e4b079bed91b3e5a0aed5c36edd0f7591485f4", "asset_id": "115669573443672055876643967408433138119481486650803218131873713375232186497057", "price": "0.47", "size": "57.64", "side": "SELL", "timestamp": "1768573200010", "received_at": "2026-01-16T14:20:00.079695"}}
{"event_type": "price_change", "event_ts": "2026-01-16T14:20:00.079695", "ingestion_ts": "2026-01-16T14:20:56.869125", "market_id": "0x427bc4b40c09b3dcbc973747f0e4b079bed91b3e5a0aed5c36edd0f7591485f4", "raw": {"market": "0x427bc4b40c09b3dcbc973747f0e4b079bed91b3e5a0aed5c36edd0f7591485f4", "asset_id": "86130975769502911188457673769190265049139877688522439001984850068234616395137", "price": "0.53", "size": "57.64", "side": "BUY", "timestamp": "1768573200010", "received_at": "2026-01-16T14:20:00.079695"}}
{"event_type": "price_change", "event_ts": "2026-01-16T14:20:00.079741", "ingestion_ts": "2026-01-16T14:20:56.869125", "market_id": "0x427bc4b40c09b3dcbc973747f0e4b079bed91b3e5a0aed5c36edd0f7591485f4", "raw": {"market": "0x427bc4b40c09b3dcbc973747f0e4b079bed91b3e5a0aed5c36edd0f7591485f4", "asset_id": "115669573443672055876643967408433138119481486650803218131873713375232186497057", "price": "0.47", "size": "77.89", "side": "SELL", "timestamp": "1768573200011", "received_at": "2026-01-16T14:20:00.079741"}}
{"event_type": "price_change", "event_ts": "2026-01-16T14:20:00.079741", "ingestion_ts": "2026-01-16T14:20:56.869125", "market_id": "0x427bc4b40c09b3dcbc973747f0e4b079bed91b3e5a0aed5c36edd0f7591485f4", "raw": {"market": "0x427bc4b40c09b3dcbc973747f0e4b079bed91b3e5a0aed5c36edd0f7591485f4", "asset_id": "86130975769502911188457673769190265049139877688522439001984850068234616395137", "price": "0.53", "size": "77.89", "side": "BUY", "timestamp": "1768573200011", "received_at": "2026-01-16T14:20:00.079741"}}
{"event_type": "price_change", "event_ts": "2026-01-16T14:20:00.083175", "ingestion_ts": "2026-01-16T14:20:56.869125", "market_id": "0xae5584fbb57f23c1c608d544b656f23d8bf12340cef70811cf31bb0cb4fc2115", "raw": {"market": "0xae5584fbb57f23c1c608d544b656f23d8bf12340cef70811cf31bb0cb4fc2115", "asset_id": "28946595841244317705636126646676849578876740730186646421280828201004700559420", "price": "0.01", "size": "8247.6", "side": "BUY", "timestamp": "1768573200018", "received_at": "2026-01-16T14:20:00.083175"}}
{"event_type": "price_change", "event_ts": "2026-01-16T14:20:00.083175", "ingestion_ts": "2026-01-16T14:20:56.869125", "market_id": "0xae5584fbb57f23c1c608d544b656f23d8bf12340cef70811cf31bb0cb4fc2115", "raw": {"market": "0xae5584fbb57f23c1c608d544b656f23d8bf12340cef70811cf31bb0cb4fc2115", "asset_id": "42278252558046940014991595990628759801692726198478046188873057685686228021663", "price": "0.99", "size": "8247.6", "side": "SELL", "timestamp": "1768573200018", "received_at": "2026-01-16T14:20:00.083175"}}
{"event_type": "price_change", "event_ts": "2026-01-16T14:20:00.169836", "ingestion_ts": "2026-01-16T14:20:56.869125", "market_id": "0xc55db914f0fd1fee18997706712c0dfd8d0369cdbef93a9fef12bd001914ca77", "raw": {"market": "0xc55db914f0fd1fee18997706712c0dfd8d0369cdbef93a9fef12bd001914ca77", "asset_id": "114600293444080540179603459515770723592661967180480327891296353898330242622833", "price": "0.859", "size": "30", "side": "BUY", "timestamp": "1768573200114", "received_at": "2026-01-16T14:20:00.169836"}}
{"event_type": "price_change", "event_ts": "2026-01-16T14:20:00.169836", "ingestion_ts": "2026-01-16T14:20:56.869125", "market_id": "0xc55db914f0fd1fee18997706712c0dfd8d0369cdbef93a9fef12bd001914ca77", "raw": {"market": "0xc55db914f0fd1fee18997706712c0dfd8d0369cdbef93a9fef12bd001914ca77", "asset_id": "72354723612769247426741660426331235762851940382312402276325808095604519806766", "price": "0.141", "size": "30", "side": "SELL", "timestamp": "1768573200114", "received_at": "2026-01-16T14:20:00.169836"}}
{"event_type": "price_change", "event_ts": "2026-01-16T14:20:00.169898", "ingestion_ts": "2026-01-16T14:20:56.869125", "market_id": "0x9472be65457510b7fc3477b20ba90910e99d92eac8421a14bf4b7b7a08ef31dc", "raw": {"market": "0x9472be65457510b7fc3477b20ba90910e99d92eac8421a14bf4b7b7a08ef31dc", "asset_id": "43311793366960417907757893276427136943959788721376762326430771171648759300146", "price": "0.858", "size": "233", "side": "BUY", "timestamp": "1768573200114", "received_at": "2026-01-16T14:20:00.169898"}}
{"event_type": "price_change", "event_ts": "2026-01-16T14:20:00.169898", "ingestion_ts": "2026-01-16T14:20:56.869125", "market_id": "0x9472be65457510b7fc3477b20ba90910e99d92eac8421a14bf4b7b7a08ef31dc", "raw": {"market": "0x9472be65457510b7fc3477b20ba90910e99d92eac8421a14bf4b7b7a08ef31dc", "asset_id": "73414222381656326204771753454630063673548497164758947581648273905027617570612", "price": "0.142", "size": "233", "side": "SELL", "timestamp": "1768573200114", "received_at": "2026-01-16T14:20:00.169898"}}
{"event_type": "price_change", "event_ts": "2026-01-16T14:20:00.169914", "ingestion_ts": "2026-01-16T14:20:56.869125", "market_id": "0x2393ed0b0fdc450054c7b9071907eca75cf4fc36e385adf4a0a5f99ee62243e8", "raw": {"market": "0x2393ed0b0fdc450054c7b9071907eca75cf4fc36e385adf4a0a5f99ee62243e8", "asset_id": "32769749367306925959219403371425714180265458150646381231272229429098460625924", "price": "0.849", "size": "294", "side": "BUY", "timestamp": "1768573200114", "received_at": "2026-01-16T14:20:00.169914"}}
{"event_type": "price_change", "event_ts": "2026-01-16T14:20:00.169914", "ingestion_ts": "2026-01-16T14:20:56.869125", "market_id": "0x2393ed0b0fdc450054c7b9071907eca75cf4fc36e385adf4a0a5f99ee62243e8", "raw": {"market": "0x2393ed0b0fdc450054c7b9071907eca75cf4fc36e385adf4a0a5f99ee62243e8", "asset_id": "100074770378634056601572485653252702850363676459996771990439989989293515601975", "price": "0.151", "size": "294", "side": "SELL", "timestamp": "1768573200114", "received_at": "2026-01-16T14:20:00.169914"}}
{"event_type": "price_change", "event_ts": "2026-01-16T14:20:00.169931", "ingestion_ts": "2026-01-16T14:20:56.869125", "market_id": "0xb9bbdd34304344dcc45803780a34c97d73a00133a5ecf70f63e1008b8abb2fca", "raw": {"market": "0xb9bbdd34304344dcc45803780a34c97d73a00133a5ecf70f63e1008b8abb2fca", "asset_id": "8682484153073832526711485265636767086525069344085206423986003504588877767339", "price": "0.839", "size": "0", "side": "BUY", "timestamp": "1768573200114", "received_at": "2026-01-16T14:20:00.169931"}}
{"event_type": "price_change", "event_ts": "2026-01-16T14:20:00.169931", "ingestion_ts": "2026-01-16T14:20:56.869125", "market_id": "0xb9bbdd34304344dcc45803780a34c97d73a00133a5ecf70f63e1008b8abb2fca", "raw": {"market": "0xb9bbdd34304344dcc45803780a34c97d73a00133a5ecf70f63e1008b8abb2fca", "asset_id": "72012724360700510767037780555710363830014634797787940282136454146828040926557", "price": "0.161", "size": "0", "side": "SELL", "timestamp": "1768573200114", "received_at": "2026-01-16T14:20:00.169931"}}
{"event_type": "price_change", "event_ts": "2026-01-16T14:20:00.194413", "ingestion_ts": "2026-01-16T14:20:56.869125", "market_id": "0x9472be65457510b7fc3477b20ba90910e99d92eac8421a14bf4b7b7a08ef31dc", "raw": {"market": "0x9472be65457510b7fc3477b20ba90910e99d92eac8421a14bf4b7b7a08ef31dc", "asset_id": "43311793366960417907757893276427136943959788721376762326430771171648759300146", "price": "0.859", "size": "10", "side": "BUY", "timestamp": "1768573200144", "received_at": "2026-01-16T14:20:00.194413"}}
{"event_type": "price_change", "event_ts": "2026-01-16T14:20:00.194413", "ingestion_ts": "2026-01-16T14:20:56.869125", "market_id": "0x9472be65457510b7fc3477b20ba90910e99d92eac8421a14bf4b7b7a08ef31dc", "raw": {"market": "0x9472be65457510b7fc3477b20ba90910e99d92eac8421a14bf4b7b7a08ef31dc", "asset_id": "73414222381656326204771753454630063673548497164758947581648273905027617570612", "price": "0.141", "size": "10", "side": "SELL", "timestamp": "1768573200144", "received_at": "2026-01-16T14:20:00.194413"}}
{"event_type": "price_change", "event_ts": "2026-01-16T14:20:00.194455", "ingestion_ts": "2026-01-16T14:20:56.869125", "market_id": "0xb9bbdd34304344dcc45803780a34c97d73a00133a5ecf70f63e1008b8abb2fca", "raw": {"market": "0xb9bbdd34304344dcc45803780a34c97d73a00133a5ecf70f63e1008b8abb2fca", "asset_id": "8682484153073832526711485265636767086525069344085206423986003504588877767339", "price": "0.851", "size": "568", "side": "BUY", "timestamp": "1768573200144", "received_at": "2026-01-16T14:20:00.194455"}}
{"event_type": "price_change", "event_ts": "2026-01-16T14:20:00.194455", "ingestion_ts": "2026-01-16T14:20:56.869125", "market_id": "0xb9bbdd34304344dcc45803780a34c97d73a00133a5ecf70f63e1008b8abb2fca", "raw": {"market": "0xb9bbdd34304344dcc45803780a34c97d73a00133a5ecf70f63e1008b8abb2fca", "asset_id": "72012724360700510767037780555710363830014634797787940282136454146828040926557", "price": "0.149", "size": "568", "side": "SELL", "timestamp": "1768573200144", "received_at": "2026-01-16T14:20:00.194455"}}
{"event_type": "price_change", "event_ts": "2026-01-16T14:20:00.194470", "ingestion_ts": "2026-01-16T14:20:56.869125", "market_id": "0xc55db914f0fd1fee18997706712c0dfd8d0369cdbef93a9fef12bd001914ca77", "raw": {"market": "0xc55db914f0fd1fee18997706712c0dfd8d0369cdbef93a9fef12bd001914ca77", "asset_id": "114600293444080540179603459515770723592661967180480327891296353898330242622833", "price": "0.86", "size": "10", "side": "BUY", "timestamp": "1768573200144", "received_at": "2026-01-16T14:20:00.194470"}}
{"event_type": "price_change", "event_ts": "2026-01-16T14:20:00.194470", "ingestion_ts": "2026-01-16T14:20:56.869125", "market_id": "0xc55db914f0fd1fee18997706712c0dfd8d0369cdbef93a9fef12bd001914ca77", "raw": {"market": "0xc55db914f0fd1fee18997706712c0dfd8d0369cdbef93a9fef12bd001914ca77", "asset_id": "72354723612769247426741660426331235762851940382312402276325808095604519806766", "price": "0.14", "size": "10", "side": "SELL", "timestamp": "1768573200144", "received_at": "2026-01-16T14:20:00.194470"}}
{"event_type": "price_change", "event_ts": "2026-01-16T14:20:00.194482", "ingestion_ts": "2026-01-16T14:20:56.869125", "market_id": "0x2393ed0b0fdc450054c7b9071907eca75cf4fc36e385adf4a0a5f99ee62243e8", "raw": {"market": "0x2393ed0b0fdc450054c7b9071907eca75cf4fc36e385adf4a0a5f99ee62243e8", "asset_id": "32769749367306925959219403371425714180265458150646381231272229429098460625924", "price": "0.85", "size": "10", "side": "BUY", "timestamp": "1768573200144", "received_at": "2026-01-16T14:20:00.194482"}}
{"event_type": "price_change", "event_ts": "2026-01-16T14:20:00.194482", "ingestion_ts": "2026-01-16T14:20:56.869125", "market_id": "0x2393ed0b0fdc450054c7b9071907eca75cf4fc36e385adf4a0a5f99ee62243e8", "raw": {"market": "0x2393ed0b0fdc450054c7b9071907eca75cf4fc36e385adf4a0a5f99ee62243e8", "asset_id": "100074770378634056601572485653252702850363676459996771990439989989293515601975", "price": "0.15", "size": "10", "side": "SELL", "timestamp": "1768573200144", "received_at": "2026-01-16T14:20:00.194482"}}
{"event_type": "price_change", "event_ts": "2026-01-16T14:20:01.585651", "ingestion_ts": "2026-01-16T14:20:56.869125", "market_id": "0xcab7ba4a9133cfd407d7e73e5757e5abbace413b59421527a31113406c97815c", "raw": {"market": "0xcab7ba4a9133cfd407d7e73e5757e5abbace413b59421527a31113406c97815c", "asset_id": "96361925776989336186111887920533578209326565663637092688733016597062311745569", "price": "0.002", "size": "30", "side": "BUY", "timestamp": "1768573201446", "received_at": "2026-01-16T14:20:01.585651"}}
{"event_type": "price_change", "event_ts": "2026-01-16T14:20:01.585651", "ingestion_ts": "2026-01-16T14:20:56.869125", "market_id": "0xcab7ba4a9133cfd407d7e73e5757e5abbace413b59421527a31113406c97815c", "raw": {"market": "0xcab7ba4a9133cfd407d7e73e5757e5abbace413b59421527a31113406c97815c", "asset_id": "20002636398944597965698652220992177552927816915094913583821579024925426590022", "price": "0.998", "size": "30", "side": "SELL", "timestamp": "1768573201446", "received_at": "2026-01-16T14:20:01.585651"}}
{"event_type": "price_change", "event_ts": "2026-01-16T14:20:01.943589", "ingestion_ts": "2026-01-16T14:20:56.869125", "market_id": "0x427bc4b40c09b3dcbc973747f0e4b079bed91b3e5a0aed5c36edd0f7591485f4", "raw": {"market": "0x427bc4b40c09b3dcbc973747f0e4b079bed91b3e5a0aed5c36edd0f7591485f4", "asset_id": "115669573443672055876643967408433138119481486650803218131873713375232186497057", "price": "0.002", "size": "99.32", "side": "BUY", "timestamp": "1768573201785", "received_at": "2026-01-16T14:20:01.943589"}}
{"event_type": "price_change", "event_ts": "2026-01-16T14:20:01.943589", "ingestion_ts": "2026-01-16T14:20:56.869125", "market_id": "0x427bc4b40c09b3dcbc973747f0e4b079bed91b3e5a0aed5c36edd0f7591485f4", "raw": {"market": "0x427bc4b40c09b3dcbc973747f0e4b079bed91b3e5a0aed5c36edd0f7591485f4", "asset_id": "86130975769502911188457673769190265049139877688522439001984850068234616395137", "price": "0.998", "size": "99.32", "side": "SELL", "timestamp": "1768573201785", "received_at": "2026-01-16T14:20:01.943589"}}
{"event_type": "price_change", "event_ts": "2026-01-16T14:20:01.943606", "ingestion_ts": "2026-01-16T14:20:56.869125", "market_id": "0x427bc4b40c09b3dcbc973747f0e4b079bed91b3e5a0aed5c36edd0f7591485f4", "raw": {"market": "0x427bc4b40c09b3dcbc973747f0e4b079bed91b3e5a0aed5c36edd0f7591485f4", "asset_id": "115669573443672055876643967408433138119481486650803218131873713375232186497057", "price": "0.003", "size": "0", "side": "BUY", "timestamp": "1768573201785", "received_at": "2026-01-16T14:20:01.943606"}}
{"event_type": "price_change", "event_ts": "2026-01-16T14:20:01.943606", "ingestion_ts": "2026-01-16T14:20:56.869125", "market_id": "0x427bc4b40c09b3dcbc973747f0e4b079bed91b3e5a0aed5c36edd0f7591485f4", "raw": {"market": "0x427bc4b40c09b3dcbc973747f0e4b079bed91b3e5a0aed5c36edd0f7591485f4", "asset_id": "86130975769502911188457673769190265049139877688522439001984850068234616395137", "price": "0.997", "size": "0", "side": "SELL", "timestamp": "1768573201785", "received_at": "2026-01-16T14:20:01.943606"}}
{"event_type": "price_change", "event_ts": "2026-01-16T14:20:01.943619", "ingestion_ts": "2026-01-16T14:20:56.869125", "market_id": "0x427bc4b40c09b3dcbc973747f0e4b079bed91b3e5a0aed5c36edd0f7591485f4", "raw": {"market": "0x427bc4b40c09b3dcbc973747f0e4b079bed91b3e5a0aed5c36edd0f7591485f4", "asset_id": "115669573443672055876643967408433138119481486650803218131873713375232186497057", "price": "0.007", "size": "0", "side": "BUY", "timestamp": "1768573201785", "received_at": "2026-01-16T14:20:01.943619"}}
{"event_type": "price_change", "event_ts": "2026-01-16T14:20:01.943619", "ingestion_ts": "2026-01-16T14:20:56.869125", "market_id": "0x427bc4b40c09b3dcbc973747f0e4b079bed91b3e5a0aed5c36edd0f7591485f4", "raw": {"market": "0x427bc4b40c09b3dcbc973747f0e4b079bed91b3e5a0aed5c36edd0f7591485f4", "asset_id": "86130975769502911188457673769190265049139877688522439001984850068234616395137", "price": "0.993", "size": "0", "side": "SELL", "timestamp": "1768573201785", "received_at": "2026-01-16T14:20:01.943619"}}
{"event_type": "price_change", "event_ts": "2026-01-16T14:20:01.943630", "ingestion_ts": "2026-01-16T14:20:56.869125", "market_id": "0x427bc4b40c09b3dcbc973747f0e4b079bed91b3e5a0aed5c36edd0f7591485f4", "raw": {"market": "0x427bc4b40c09b3dcbc973747f0e4b079bed91b3e5a0aed5c36edd0f7591485f4", "asset_id": "115669573443672055876643967408433138119481486650803218131873713375232186497057", "price": "0.008", "size": "0", "side": "BUY", "timestamp": "1768573201785", "received_at": "2026-01-16T14:20:01.943630"}}
{"event_type": "price_change", "event_ts": "2026-01-16T14:20:01.943630", "ingestion_ts": "2026-01-16T14:20:56.869125", "market_id": "0x427bc4b40c09b3dcbc973747f0e4b079bed91b3e5a0aed5c36edd0f7591485f4", "raw": {"market": "0x427bc4b40c09b3dcbc973747f0e4b079bed91b3e5a0aed5c36edd0f7591485f4", "asset_id": "86130975769502911188457673769190265049139877688522439001984850068234616395137", "price": "0.992", "size": "0", "side": "SELL", "timestamp": "1768573201785", "received_at": "2026-01-16T14:20:01.943630"}}
{"event_type": "price_change", "event_ts": "2026-01-16T14:20:02.042704", "ingestion_ts": "2026-01-16T14:20:56.869125", "market_id": "0x427bc4b40c09b3dcbc973747f0e4b079bed91b3e5a0aed5c36edd0f7591485f4", "raw": {"market": "0x427bc4b40c09b3dcbc973747f0e4b079bed91b3e5a0aed5c36edd0f7591485f4", "asset_id": "86130975769502911188457673769190265049139877688522439001984850068234616395137", "price": "0.818", "size": "46", "side": "BUY", "timestamp": "1768573201886", "received_at": "2026-01-16T14:20:02.042704"}}
{"event_type": "price_change", "event_ts": "2026-01-16T14:20:02.042704", "ingestion_ts": "2026-01-16T14:20:56.869125", "market_id": "0x427bc4b40c09b3dcbc973747f0e4b079bed91b3e5a0aed5c36edd0f7591485f4", "raw": {"market": "0x427bc4b40c09b3dcbc973747f0e4b079bed91b3e5a0aed5c36edd0f7591485f4", "asset_id": "115669573443672055876643967408433138119481486650803218131873713375232186497057", "price": "0.182", "size": "46", "side": "SELL", "timestamp": "1768573201886", "received_at": "2026-01-16T14:20:02.042704"}}
{"event_type": "price_change", "event_ts": "2026-01-16T14:20:02.343367", "ingestion_ts": "2026-01-16T14:20:56.869125", "market_id": "0x49686d26fb712515cd5e12c23f0a1c7e10214c7faa3cb0a730aabe0c33694082", "raw": {"market": "0x49686d26fb712515cd5e12c23f0a1c7e10214c7faa3cb0a730aabe0c33694082", "asset_id": "13244681086321087932946246027856416106585284024824496763706748621681543444582", "price": "0.853", "size": "45", "side": "BUY", "timestamp": "1768573202209", "received_at": "2026-01-16T14:20:02.343367"}}
{"event_type": "price_change", "event_ts": "2026-01-16T14:20:02.343367", "ingestion_ts": "2026-01-16T14:20:56.869125", "market_id": "0x49686d26fb712515cd5e12c23f0a1c7e10214c7faa3cb0a730aabe0c33694082", "raw": {"market": "0x49686d26fb712515cd5e12c23f0a1c7e10214c7faa3cb0a730aabe0c33694082", "asset_id": "30442780799048074404860985387051749017905070253466005720364298335239299761065", "price": "0.147", "size": "45", "side": "SELL", "timestamp": "1768573202209", "received_at": "2026-01-16T14:20:02.343367"}}
{"event_type": "price_change", "event_ts": "2026-01-16T14:20:02.391596", "ingestion_ts": "2026-01-16T14:20:56.869125", "market_id": "0x427bc4b40c09b3dcbc973747f0e4b079bed91b3e5a0aed5c36edd0f7591485f4", "raw": {"market": "0x427bc4b40c09b3dcbc973747f0e4b079bed91b3e5a0aed5c36edd0f7591485f4", "asset_id": "115669573443672055876643967408433138119481486650803218131873713375232186497057", "price": "0.006", "size": "27.14", "side": "BUY", "timestamp": "1768573202237", "received_at": "2026-01-16T14:20:02.391596"}}
{"event_type": "price_change", "event_ts": "2026-01-16T14:20:02.391596", "ingestion_ts": "2026-01-16T14:20:56.869125", "market_id": "0x427bc4b40c09b3dcbc973747f0e4b079bed91b3e5a0aed5c36edd0f7591485f4", "raw": {"market": "0x427bc4b40c09b3dcbc973747f0e4b079bed91b3e5a0aed5c36edd0f7591485f4", "asset_id": "86130975769502911188457673769190265049139877688522439001984850068234616395137", "price": "0.994", "size": "27.14", "side": "SELL", "timestamp": "1768573202237", "received_at": "2026-01-16T14:20:02.391596"}}
{"event_type": "price_change", "event_ts": "2026-01-16T14:20:02.391642", "ingestion_ts": "2026-01-16T14:20:56.869125", "market_id": "0x427bc4b40c09b3dcbc973747f0e4b079bed91b3e5a0aed5c36edd0f7591485f4", "raw": {"market": "0x427bc4b40c09b3dcbc973747f0e4b079bed91b3e5a0aed5c36edd0f7591485f4", "asset_id": "115669573443672055876643967408433138119481486650803218131873713375232186497057", "price": "0.003", "size": "9.08", "side": "BUY", "timestamp": "1768573202238", "received_at": "2026-01-16T14:20:02.391642"}}
{"event_type": "price_change", "event_ts": "2026-01-16T14:20:02.391642", "ingestion_ts": "2026-01-16T14:20:56.869125", "market_id": "0x427bc4b40c09b3dcbc973747f0e4b079bed91b3e5a0aed5c36edd0f7591485f4", "raw": {"market": "0x427bc4b40c09b3dcbc973747f0e4b079bed91b3e5a0aed5c36edd0f7591485f4", "asset_id": "86130975769502911188457673769190265049139877688522439001984850068234616395137", "price": "0.997", "size": "9.08", "side": "SELL", "timestamp": "1768573202238", "received_at": "2026-01-16T14:20:02.391642"}}
{"event_type": "price_change", "event_ts": "2026-01-16T14:20:02.391687", "ingestion_ts": "2026-01-16T14:20:56.869125", "market_id": "0x427bc4b40c09b3dcbc973747f0e4b079bed91b3e5a0aed5c36edd0f7591485f4", "raw": {"market": "0x427bc4b40c09b3dcbc973747f0e4b079bed91b3e5a0aed5c36edd0f7591485f4", "asset_id": "115669573443672055876643967408433138119481486650803218131873713375232186497057", "price": "0.008", "size": "6.97", "side": "BUY", "timestamp": "1768573202239", "received_at": "2026-01-16T14:20:02.391687"}}
{"event_type": "price_change", "event_ts": "2026-01-16T14:20:02.391687", "ingestion_ts": "2026-01-16T14:20:56.869125", "market_id": "0x427bc4b40c09b3dcbc973747f0e4b079bed91b3e5a0aed5c36edd0f7591485f4", "raw": {"market": "0x427bc4b40c09b3dcbc973747f0e4b079bed91b3e5a0aed5c36edd0f7591485f4", "asset_id": "86130975769502911188457673769190265049139877688522439001984850068234616395137", "price": "0.992", "size": "6.97", "side": "SELL", "timestamp": "1768573202239", "received_at": "2026-01-16T14:20:02.391687"}}
{"event_type": "price_change", "event_ts": "2026-01-16T14:20:02.400843", "ingestion_ts": "2026-01-16T14:20:56.869125", "market_id": "0x49686d26fb712515cd5e12c23f0a1c7e10214c7faa3cb0a730aabe0c33694082", "raw": {"market": "0x49686d26fb712515cd5e12c23f0a1c7e10214c7faa3cb0a730aabe0c33694082", "asset_id": "13244681086321087932946246027856416106585284024824496763706748621681543444582", "price": "0.854", "size": "23.35", "side": "BUY", "timestamp": "1768573202254", "received_at": "2026-01-16T14:20:02.400843"}}
{"event_type": "price_change", "event_ts": "2026-01-16T14:20:02.400843", "ingestion_ts": "2026-01-16T14:20:56.869125", "market_id": "0x49686d26fb712515cd5e12c23f0a1c7e10214c7faa3cb0a730aabe0c33694082", "raw": {"market": "0x49686d26fb712515cd5e12c23f0a1c7e10214c7faa3cb0a730aabe0c33694082", "asset_id": "30442780799048074404860985387051749017905070253466005720364298335239299761065", "price": "0.146", "size": "23.35", "side": "SELL", "timestamp": "1768573202254", "received_at": "2026-01-16T14:20:02.400843"}}
{"event_type": "price_change", "event_ts": "2026-01-16T14:20:02.448004", "ingestion_ts": "2026-01-16T14:20:56.869125", "market_id": "0x427bc4b40c09b3dcbc973747f0e4b079bed91b3e5a0aed5c36edd0f7591485f4", "raw": {"market": "0x427bc4b40c09b3dcbc973747f0e4b079bed91b3e5a0aed5c36edd0f7591485f4", "asset_id": "86130975769502911188457673769190265049139877688522439001984850068234616395137", "price": "0.993", "size": "35", "side": "SELL", "timestamp": "1768573202294", "received_at": "2026-01-16T14:20:02.448004"}}
{"event_type": "price_change", "event_ts": "2026-01-16T14:20:02.448004", "ingestion_ts": "2026-01-16T14:20:56.869125", "market_id": "0x427bc4b40c09b3dcbc973747f0e4b079bed91b3e5a0aed5c36edd0f7591485f4", "raw": {"market": "0x427bc4b40c09b3dcbc973747f0e4b079bed91b3e5a0aed5c36edd0f7591485f4", "asset_id": "115669573443672055876643967408433138119481486650803218131873713375232186497057", "price": "0.007", "size": "35", "side": "BUY", "timestamp": "1768573202294", "received_at": "2026-01-16T14:20:02.448004"}}
{"event_type": "price_change", "event_ts": "2026-01-16T14:20:02.657181", "ingestion_ts": "2026-01-16T14:20:56.869125", "market_id": "0x44f08744458b8896620cd3330bc5e1ea69df4199b02d4fc583b3fc96e5d314ce", "raw": {"market": "0x44f08744458b8896620cd3330bc5e1ea69df4199b02d4fc583b3fc96e5d314ce", "asset_id": "72327831507226612545928776794104143393438710920370371172884559893525100761096", "price": "0.903", "size": "0", "side": "BUY", "timestamp": "1768573202541", "received_at": "2026-01-16T14:20:02.657181"}}
{"event_type": "price_change", "event_ts": "2026-01-16T14:20:02.657181", "ingestion_ts": "2026-01-16T14:20:56.869125", "market_id": "0x44f08744458b8896620cd3330bc5e1ea69df4199b02d4fc583b3fc96e5d314ce", "raw": {"market": "0x44f08744458b8896620cd3330bc5e1ea69df4199b02d4fc583b3fc96e5d314ce", "asset_id": "49194009556504828848509244326501559253829462790583873936160989575507522044057", "price": "0.097", "size": "0", "side": "SELL", "timestamp": "1768573202541", "received_at": "2026-01-16T14:20:02.657181"}}
{"event_type": "price_change", "event_ts": "2026-01-16T14:20:02.657234", "ingestion_ts": "2026-01-16T14:20:56.869125", "market_id": "0x2393ed0b0fdc450054c7b9071907eca75cf4fc36e385adf4a0a5f99ee62243e8", "raw": {"market": "0x2393ed0b0fdc450054c7b9071907eca75cf4fc36e385adf4a0a5f99ee62243e8", "asset_id": "32769749367306925959219403371425714180265458150646381231272229429098460625924", "price": "0.897", "size": "0", "side": "BUY", "timestamp": "1768573202541", "received_at": "2026-01-16T14:20:02.657234"}}
{"event_type": "price_change", "event_ts": "2026-01-16T14:20:02.657234", "ingestion_ts": "2026-01-16T14:20:56.869125", "market_id": "0x2393ed0b0fdc450054c7b9071907eca75cf4fc36e385adf4a0a5f99ee62243e8", "raw": {"market": "0x2393ed0b0fdc450054c7b9071907eca75cf4fc36e385adf4a0a5f99ee62243e8", "asset_id": "100074770378634056601572485653252702850363676459996771990439989989293515601975", "price": "0.103", "size": "0", "side": "SELL", "timestamp": "1768573202541", "received_at": "2026-01-16T14:20:02.657234"}}
{"event_type": "price_change", "event_ts": "2026-01-16T14:20:02.657249", "ingestion_ts": "2026-01-16T14:20:56.869125", "market_id": "0xc55db914f0fd1fee18997706712c0dfd8d0369cdbef93a9fef12bd001914ca77", "raw": {"market": "0xc55db914f0fd1fee18997706712c0dfd8d0369cdbef93a9fef12bd001914ca77", "asset_id": "114600293444080540179603459515770723592661967180480327891296353898330242622833", "price": "0.907", "size": "0", "side": "BUY", "timestamp": "1768573202541", "received_at": "2026-01-16T14:20:02.657249"}}
{"event_type": "price_change", "event_ts": "2026-01-16T14:20:02.657249", "ingestion_ts": "2026-01-16T14:20:56.869125", "market_id": "0xc55db914f0fd1fee18997706712c0dfd8d0369cdbef93a9fef12bd001914ca77", "raw": {"market": "0xc55db914f0fd1fee18997706712c0dfd8d0369cdbef93a9fef12bd001914ca77", "asset_id": "72354723612769247426741660426331235762851940382312402276325808095604519806766", "price": "0.093", "size": "0", "side": "SELL", "timestamp": "1768573202541", "received_at": "2026-01-16T14:20:02.657249"}}
{"event_type": "price_change", "event_ts": "2026-01-16T14:20:02.657261", "ingestion_ts": "2026-01-16T14:20:56.869125", "market_id": "0xaf9d0e448129a9f657f851d49495ba4742055d80e0ef1166ba0ee81d4d594214", "raw": {"market": "0xaf9d0e448129a9f657f851d49495ba4742055d80e0ef1166ba0ee81d4d594214", "asset_id": "4153292802911610701832309484716814274802943278345248636922528170020319407796", "price": "0.884", "size": "0", "side": "BUY", "timestamp": "1768573202541", "received_at": "2026-01-16T14:20:02.657261"}}
{"event_type": "price_change", "event_ts": "2026-01-16T14:20:02.657261", "ingestion_ts": "2026-01-16T14:20:56.869125", "market_id": "0xaf9d0e448129a9f657f851d49495ba4742055d80e0ef1166ba0ee81d4d594214", "raw": {"market": "0xaf9d0e448129a9f657f851d49495ba4742055d80e0ef1166ba0ee81d4d594214", "asset_id": "101676997363687199724245607342877036148401850938023978421879460310389391082353", "price": "0.116", "size": "0", "side": "SELL", "timestamp": "1768573202541", "received_at": "2026-01-16T14:20:02.657261"}}
{"event_type": "price_change", "event_ts": "2026-01-16T14:20:03.457560", "ingestion_ts": "2026-01-16T14:20:56.869125", "market_id": "0x49686d26fb712515cd5e12c23f0a1c7e10214c7faa3cb0a730aabe0c33694082", "raw": {"market": "0x49686d26fb712515cd5e12c23f0a1c7e10214c7faa3cb0a730aabe0c33694082", "asset_id": "13244681086321087932946246027856416106585284024824496763706748621681543444582", "price": "0.192", "size": "0", "side": "BUY", "timestamp": "1768573202742", "received_at": "2026-01-16T14:20:03.457560"}}
{"event_type": "price_change", "event_ts": "2026-01-16T14:20:03.457560", "ingestion_ts": "2026-01-16T14:20:56.869125", "market_id": "0x49686d26fb712515cd5e12c23f0a1c7e10214c7faa3cb0a730aabe0c33694082", "raw": {"market": "0x49686d26fb712515cd5e12c23f0a1c7e10214c7faa3cb0a730aabe0c33694082", "asset_id": "30442780799048074404860985387051749017905070253466005720364298335239299761065", "price": "0.808", "size": "0", "side": "SELL", "timestamp": "1768573202742", "received_at": "2026-01-16T14:20:03.457560"}}
{"event_type": "price_change", "event_ts": "2026-01-16T14:20:03.862158", "ingestion_ts": "2026-01-16T14:20:56.869125", "market_id": "0x427bc4b40c09b3dcbc973747f0e4b079bed91b3e5a0aed5c36edd0f7591485f4", "raw": {"market": "0x427bc4b40c09b3dcbc973747f0e4b079bed91b3e5a0aed5c36edd0f7591485f4", "asset_id": "115669573443672055876643967408433138119481486650803218131873713375232186497057", "price": "0.183", "size": "0", "side": "SELL", "timestamp": "1768573202829", "received_at": "2026-01-16T14:20:03.862158"}}
{"event_type": "price_change", "event_ts": "2026-01-16T14:20:03.862158", "ingestion_ts": "2026-01-16T14:20:56.869125", "market_id": "0x427bc4b40c09b3dcbc973747f0e4b079bed91b3e5a0aed5c36edd0f7591485f4", "raw": {"market": "0x427bc4b40c09b3dcbc973747f0e4b079bed91b3e5a0aed5c36edd0f7591485f4", "asset_id": "86130975769502911188457673769190265049139877688522439001984850068234616395137", "price": "0.817", "size": "0", "side": "BUY", "timestamp": "1768573202829", "received_at": "2026-01-16T14:20:03.862158"}}
{"event_type": "price_change", "event_ts": "2026-01-16T14:20:03.865224", "ingestion_ts": "2026-01-16T14:20:56.869125", "market_id": "0x427bc4b40c09b3dcbc973747f0e4b079bed91b3e5a0aed5c36edd0f7591485f4", "raw": {"market": "0x427bc4b40c09b3dcbc973747f0e4b079bed91b3e5a0aed5c36edd0f7591485f4", "asset_id": "115669573443672055876643967408433138119481486650803218131873713375232186497057", "price": "0.184", "size": "0", "side": "SELL", "timestamp": "1768573202829", "received_at": "2026-01-16T14:20:03.865224"}}
{"event_type": "price_change", "event_ts": "2026-01-16T14:20:03.865224", "ingestion_ts": "2026-01-16T14:20:56.869125", "market_id": "0x427bc4b40c09b3dcbc973747f0e4b079bed91b3e5a0aed5c36edd0f7591485f4", "raw": {"market": "0x427bc4b40c09b3dcbc973747f0e4b079bed91b3e5a0aed5c36edd0f7591485f4", "asset_id": "86130975769502911188457673769190265049139877688522439001984850068234616395137", "price": "0.816", "size": "0", "side": "BUY", "timestamp": "1768573202829", "received_at": "2026-01-16T14:20:03.865224"}}
{"event_type": "price_change", "event_ts": "2026-01-16T14:20:03.865263", "ingestion_ts": "2026-01-16T14:20:56.869125", "market_id": "0x427bc4b40c09b3dcbc973747f0e4b079bed91b3e5a0aed5c36edd0f7591485f4", "raw": {"market": "0x427bc4b40c09b3dcbc973747f0e4b079bed91b3e5a0aed5c36edd0f7591485f4", "asset_id": "115669573443672055876643967408433138119481486650803218131873713375232186497057", "price": "0.47", "size": "57.64", "side": "SELL", "timestamp": "1768573202829", "received_at": "2026-01-16T14:20:03.865263"}}
{"event_type": "price_change", "event_ts": "2026-01-16T14:20:03.865263", "ingestion_ts": "2026-01-16T14:20:56.869125", "market_id": "0x427bc4b40c09b3dcbc973747f0e4b079bed91b3e5a0aed5c36edd0f7591485f4", "raw": {"market": "0x427bc4b40c09b3dcbc973747f0e4b079bed91b3e5a0aed5c36edd0f7591485f4", "asset_id": "86130975769502911188457673769190265049139877688522439001984850068234616395137", "price": "0.53", "size": "57.64", "side": "BUY", "timestamp": "1768573202829", "received_at": "2026-01-16T14:20:03.865263"}}
{"event_type": "price_change", "event_ts": "2026-01-16T14:20:04.135296", "ingestion_ts": "2026-01-16T14:20:56.869125", "market_id": "0x427bc4b40c09b3dcbc973747f0e4b079bed91b3e5a0aed5c36edd0f7591485f4", "raw": {"market": "0x427bc4b40c09b3dcbc973747f0e4b079bed91b3e5a0aed5c36edd0f7591485f4", "asset_id": "86130975769502911188457673769190265049139877688522439001984850068234616395137", "price": "0.818", "size": "0", "side": "BUY", "timestamp": "1768573202972", "received_at": "2026-01-16T14:20:04.135296"}}
{"event_type": "price_change", "event_ts": "2026-01-16T14:20:04.135296", "ingestion_ts": "2026-01-16T14:20:56.869125", "market_id": "0x427bc4b40c09b3dcbc973747f0e4b079bed91b3e5a0aed5c36edd0f7591485f4", "raw": {"market": "0x427bc4b40c09b3dcbc973747f0e4b079bed91b3e5a0aed5c36edd0f7591485f4", "asset_id": "115669573443672055876643967408433138119481486650803218131873713375232186497057", "price": "0.182", "size": "0", "side": "SELL", "timestamp": "1768573202972", "received_at": "2026-01-16T14:20:04.135296"}}
{"event_type": "price_change", "event_ts": "2026-01-16T14:20:04.135979", "ingestion_ts": "2026-01-16T14:20:56.869125", "market_id": "0x49686d26fb712515cd5e12c23f0a1c7e10214c7faa3cb0a730aabe0c33694082", "raw": {"market": "0x49686d26fb712515cd5e12c23f0a1c7e10214c7faa3cb0a730aabe0c33694082", "asset_id": "13244681086321087932946246027856416106585284024824496763706748621681543444582", "price": "0.141", "size": "100", "side": "BUY", "timestamp": "1768573202954", "received_at": "2026-01-16T14:20:04.135979"}}
{"event_type": "price_change", "event_ts": "2026-01-16T14:20:04.135979", "ingestion_ts": "2026-01-16T14:20:56.869125", "market_id": "0x49686d26fb712515cd5e12c23f0a1c7e10214c7faa3cb0a730aabe0c33694082", "raw": {"market": "0x49686d26fb712515cd5e12c23f0a1c7e10214c7faa3cb0a730aabe0c33694082", "asset_id": "30442780799048074404860985387051749017905070253466005720364298335239299761065", "price": "0.859", "size": "100", "side": "SELL", "timestamp": "1768573202954", "received_at": "2026-01-16T14:20:04.135979"}}
{"event_type": "price_change", "event_ts": "2026-01-16T14:20:04.479092", "ingestion_ts": "2026-01-16T14:20:56.869125", "market_id": "0x2393ed0b0fdc450054c7b9071907eca75cf4fc36e385adf4a0a5f99ee62243e8", "raw": {"market": "0x2393ed0b0fdc450054c7b9071907eca75cf4fc36e385adf4a0a5f99ee62243e8", "asset_id": "32769749367306925959219403371425714180265458150646381231272229429098460625924", "price": "0.944", "size": "50", "side": "BUY", "timestamp": "1768573203044", "received_at": "2026-01-16T14:20:04.479092"}}
{"event_type": "price_change", "event_ts": "2026-01-16T14:20:04.479092", "ingestion_ts": "2026-01-16T14:20:56.869125", "market_id": "0x2393ed0b0fdc450054c7b9071907eca75cf4fc36e385adf4a0a5f99ee62243e8", "raw": {"market": "0x2393ed0b0fdc450054c7b9071907eca75cf4fc36e385adf4a0a5f99ee62243e8", "asset_id": "100074770378634056601572485653252702850363676459996771990439989989293515601975", "price": "0.056", "size": "50", "side": "SELL", "timestamp": "1768573203044", "received_at": "2026-01-16T14:20:04.479092"}}
{"event_type": "price_change", "event_ts": "2026-01-16T14:20:04.573448", "ingestion_ts": "2026-01-16T14:20:56.869125", "market_id": "0x49686d26fb712515cd5e12c23f0a1c7e10214c7faa3cb0a730aabe0c33694082", "raw": {"market": "0x49686d26fb712515cd5e12c23f0a1c7e10214c7faa3cb0a730aabe0c33694082", "asset_id": "13244681086321087932946246027856416106585284024824496763706748621681543444582", "price": "0.097", "size": "300", "side": "BUY", "timestamp": "1768573203075", "received_at": "2026-01-16T14:20:04.573448"}}
{"event_type": "price_change", "event_ts": "2026-01-16T14:20:04.573448", "ingestion_ts": "2026-01-16T14:20:56.869125", "market_id": "0x49686d26fb712515cd5e12c23f0a1c7e10214c7faa3cb0a730aabe0c33694082", "raw": {"market": "0x49686d26fb712515cd5e12c23f0a1c7e10214c7faa3cb0a730aabe0c33694082", "asset_id": "30442780799048074404860985387051749017905070253466005720364298335239299761065", "price": "0.903", "size": "300", "side": "SELL", "timestamp": "1768573203075", "received_at": "2026-01-16T14:20:04.573448"}}
{"event_type": "price_change", "event_ts": "2026-01-16T14:20:04.760204", "ingestion_ts": "2026-01-16T14:20:56.869125", "market_id": "0x2393ed0b0fdc450054c7b9071907eca75cf4fc36e385adf4a0a5f99ee62243e8", "raw": {"market": "0x2393ed0b0fdc450054c7b9071907eca75cf4fc36e385adf4a0a5f99ee62243e8", "asset_id": "32769749367306925959219403371425714180265458150646381231272229429098460625924", "price": "0.898", "size": "7.37", "side": "BUY", "timestamp": "1768573203103", "received_at": "2026-01-16T14:20:04.760204"}}
{"event_type": "price_change", "event_ts": "2026-01-16T14:20:04.760204", "ingestion_ts": "2026-01-16T14:20:56.869125", "market_id": "0x2393ed0b0fdc450054c7b9071907eca75cf4fc36e385adf4a0a5f99ee62243e8", "raw": {"market": "0x2393ed0b0fdc450054c7b9071907eca75cf4fc36e385adf4a0a5f99ee62243e8", "asset_id": "100074770378634056601572485653252702850363676459996771990439989989293515601975", "price": "0.102", "size": "7.37", "side": "SELL", "timestamp": "1768573203103", "received_at": "2026-01-16T14:20:04.760204"}}
{"event_type": "price_change", "event_ts": "2026-01-16T14:20:04.766788", "ingestion_ts": "2026-01-16T14:20:56.869125", "market_id": "0xaf9d0e448129a9f657f851d49495ba4742055d80e0ef1166ba0ee81d4d594214", "raw": {"market": "0xaf9d0e448129a9f657f851d49495ba4742055d80e0ef1166ba0ee81d4d594214", "asset_id": "4153292802911610701832309484716814274802943278345248636922528170020319407796", "price": "0.886", "size": "222.7", "side": "BUY", "timestamp": "1768573203103", "received_at": "2026-01-16T14:20:04.766788"}}
{"event_type": "price_change", "event_ts": "2026-01-16T14:20:04.766788", "ingestion_ts": "2026-01-16T14:20:56.869125", "market_id": "0xaf9d0e448129a9f657f851d49495ba4742055d80e0ef1166ba0ee81d4d594214", "raw": {"market": "0xaf9d0e448129a9f657f851d49495ba4742055d80e0ef1166ba0ee81d4d594214", "asset_id": "101676997363687199724245607342877036148401850938023978421879460310389391082353", "price": "0.114", "size": "222.7", "side": "SELL", "timestamp": "1768573203103", "received_at": "2026-01-16T14:20:04.766788"}}
{"event_type": "price_change", "event_ts": "2026-01-16T14:20:04.770421", "ingestion_ts": "2026-01-16T14:20:56.869125", "market_id": "0xc55db914f0fd1fee18997706712c0dfd8d0369cdbef93a9fef12bd001914ca77", "raw": {"market": "0xc55db914f0fd1fee18997706712c0dfd8d0369cdbef93a9fef12bd001914ca77", "asset_id": "114600293444080540179603459515770723592661967180480327891296353898330242622833", "price": "0.908", "size": "7.37", "side": "BUY", "timestamp": "1768573203104", "received_at": "2026-01-16T14:20:04.770421"}}
{"event_type": "price_change", "event_ts": "2026-01-16T14:20:04.770421", "ingestion_ts": "2026-01-16T14:20:56.869125", "market_id": "0xc55db914f0fd1fee18997706712c0dfd8d0369cdbef93a9fef12bd001914ca77", "raw": {"market": "0xc55db914f0fd1fee18997706712c0dfd8d0369cdbef93a9fef12bd001914ca77", "asset_id": "72354723612769247426741660426331235762851940382312402276325808095604519806766", "price": "0.092", "size": "7.37", "side": "SELL", "timestamp": "1768573203104", "received_at": "2026-01-16T14:20:04.770421"}}
{"event_type": "price_change", "event_ts": "2026-01-16T14:20:04.780193", "ingestion_ts": "2026-01-16T14:20:56.869125", "market_id": "0x44f08744458b8896620cd3330bc5e1ea69df4199b02d4fc583b3fc96e5d314ce", "raw": {"market": "0x44f08744458b8896620cd3330bc5e1ea69df4199b02d4fc583b3fc96e5d314ce", "asset_id": "72327831507226612545928776794104143393438710920370371172884559893525100761096", "price": "0.904", "size": "22.91", "side": "BUY", "timestamp": "1768573203104", "received_at": "2026-01-16T14:20:04.780193"}}
{"event_type": "price_change", "event_ts": "2026-01-16T14:20:04.780193", "ingestion_ts": "2026-01-16T14:20:56.869125", "market_id": "0x44f08744458b8896620cd3330bc5e1ea69df4199b02d4fc583b3fc96e5d314ce", "raw": {"market": "0x44f08744458b8896620cd3330bc5e1ea69df4199b02d4fc583b3fc96e5d314ce", "asset_id": "49194009556504828848509244326501559253829462790583873936160989575507522044057", "price": "0.096", "size": "22.91", "side": "SELL", "timestamp": "1768573203104", "received_at": "2026-01-16T14:20:04.780193"}}
{"event_type": "price_change", "event_ts": "2026-01-16T14:20:05.014773", "ingestion_ts": "2026-01-16T14:20:56.869125", "market_id": "0x2393ed0b0fdc450054c7b9071907eca75cf4fc36e385adf4a0a5f99ee62243e8", "raw": {"market": "0x2393ed0b0fdc450054c7b9071907eca75cf4fc36e385adf4a0a5f99ee62243e8", "asset_id": "32769749367306925959219403371425714180265458150646381231272229429098460625924", "price": "0.942", "size": "0", "side": "BUY", "timestamp": "1768573203375", "received_at": "2026-01-16T14:20:05.014773"}}
{"event_type": "price_change", "event_ts": "2026-01-16T14:20:05.014773", "ingestion_ts": "2026-01-16T14:20:56.869125", "market_id": "0x2393ed0b0fdc450054c7b9071907eca75cf4fc36e385adf4a0a5f99ee62243e8", "raw": {"market": "0x2393ed0b0fdc450054c7b9071907eca75cf4fc36e385adf4a0a5f99ee62243e8", "asset_id": "100074770378634056601572485653252702850363676459996771990439989989293515601975", "price": "0.058", "size": "0", "side": "SELL", "timestamp": "1768573203375", "received_at": "2026-01-16T14:20:05.014773"}}
{"event_type": "price_change", "event_ts": "2026-01-16T14:20:05.022585", "ingestion_ts": "2026-01-16T14:20:56.869125", "market_id": "0x427bc4b40c09b3dcbc973747f0e4b079bed91b3e5a0aed5c36edd0f7591485f4", "raw": {"market": "0x427bc4b40c09b3dcbc973747f0e4b079bed91b3e5a0aed5c36edd0f7591485f4", "asset_id": "115669573443672055876643967408433138119481486650803218131873713375232186497057", "price": "0.181", "size": "16.28", "side": "SELL", "timestamp": "1768573203392", "received_at": "2026-01-16T14:20:05.022585"}}
{"event_type": "price_change", "event_ts": "2026-01-16T14:20:05.022585", "ingestion_ts": "2026-01-16T14:20:56.869125", "market_id": "0x427bc4b40c09b3dcbc973747f0e4b079bed91b3e5a0aed5c36edd0f7591485f4", "raw": {"market": "0x427bc4b40c09b3dcbc973747f0e4b079bed91b3e5a0aed5c36edd0f7591485f4", "asset_id": "86130975769502911188457673769190265049139877688522439001984850068234616395137", "price": "0.819", "size": "16.28", "side": "BUY", "timestamp": "1768573203392", "received_at": "2026-01-16T14:20:05.022585"}}
{"event_type": "price_change", "event_ts": "2026-01-16T14:20:05.023795", "ingestion_ts": "2026-01-16T14:20:56.869125", "market_id": "0x427bc4b40c09b3dcbc973747f0e4b079bed91b3e5a0aed5c36edd0f7591485f4", "raw": {"market": "0x427bc4b40c09b3dcbc973747f0e4b079bed91b3e5a0aed5c36edd0f7591485f4", "asset_id": "115669573443672055876643967408433138119481486650803218131873713375232186497057", "price": "0.181", "size": "32.56", "side": "SELL", "timestamp": "1768573203394", "received_at": "2026-01-16T14:20:05.023795"}}
{"event_type": "price_change", "event_ts": "2026-01-16T14:20:05.023795", "ingestion_ts": "2026-01-16T14:20:56.869125", "market_id": "0x427bc4b40c09b3dcbc973747f0e4b079bed91b3e5a0aed5c36edd0f7591485f4", "raw": {"market": "0x427bc4b40c09b3dcbc973747f0e4b079bed91b3e5a0aed5c36edd0f7591485f4", "asset_id": "86130975769502911188457673769190265049139877688522439001984850068234616395137", "price": "0.819", "size": "32.56", "side": "BUY", "timestamp": "1768573203394", "received_at": "2026-01-16T14:20:05.023795"}}
{"event_type": "price_change", "event_ts": "2026-01-16T14:20:05.024128", "ingestion_ts": "2026-01-16T14:20:56.869125", "market_id": "0x427bc4b40c09b3dcbc973747f0e4b079bed91b3e5a0aed5c36edd0f7591485f4", "raw": {"market": "0x427bc4b40c09b3dcbc973747f0e4b079bed91b3e5a0aed5c36edd0f7591485f4", "asset_id": "115669573443672055876643967408433138119481486650803218131873713375232186497057", "price": "0.182", "size": "7.81", "side": "SELL", "timestamp": "1768573203395", "received_at": "2026-01-16T14:20:05.024128"}}
{"event_type": "price_change", "event_ts": "2026-01-16T14:20:05.024128", "ingestion_ts": "2026-01-16T14:20:56.869125", "market_id": "0x427bc4b40c09b3dcbc973747f0e4b079bed91b3e5a0aed5c36edd0f7591485f4", "raw": {"market": "0x427bc4b40c09b3dcbc973747f0e4b079bed91b3e5a0aed5c36edd0f7591485f4", "asset_id": "86130975769502911188457673769190265049139877688522439001984850068234616395137", "price": "0.818", "size": "7.81", "side": "BUY", "timestamp": "1768573203395", "received_at": "2026-01-16T14:20:05.024128"}}
{"event_type": "price_change", "event_ts": "2026-01-16T14:20:05.025862", "ingestion_ts": "2026-01-16T14:20:56.869125", "market_id": "0x427bc4b40c09b3dcbc973747f0e4b079bed91b3e5a0aed5c36edd0f7591485f4", "raw": {"market": "0x427bc4b40c09b3dcbc973747f0e4b079bed91b3e5a0aed5c36edd0f7591485f4", "asset_id": "115669573443672055876643967408433138119481486650803218131873713375232186497057", "price": "0.182", "size": "15.62", "side": "SELL", "timestamp": "1768573203396", "received_at": "2026-01-16T14:20:05.025862"}}
{"event_type": "price_change", "event_ts": "2026-01-16T14:20:05.025862", "ingestion_ts": "2026-01-16T14:20:56.869125", "market_id": "0x427bc4b40c09b3dcbc973747f0e4b079bed91b3e5a0aed5c36edd0f7591485f4", "raw": {"market": "0x427bc4b40c09b3dcbc973747f0e4b079bed91b3e5a0aed5c36edd0f7591485f4", "asset_id": "86130975769502911188457673769190265049139877688522439001984850068234616395137", "price": "0.818", "size": "15.62", "side": "BUY", "timestamp": "1768573203396", "received_at": "2026-01-16T14:20:05.025862"}}
{"event_type": "price_change", "event_ts": "2026-01-16T14:20:05.088245", "ingestion_ts": "2026-01-16T14:20:56.869125", "market_id": "0x427bc4b40c09b3dcbc973747f0e4b079bed91b3e5a0aed5c36edd0f7591485f4", "raw": {"market": "0x427bc4b40c09b3dcbc973747f0e4b079bed91b3e5a0aed5c36edd0f7591485f4", "asset_id": "86130975769502911188457673769190265049139877688522439001984850068234616395137", "price": "0.993", "size": "0", "side": "SELL", "timestamp": "1768573203461", "received_at": "2026-01-16T14:20:05.088245"}}
{"event_type": "price_change", "event_ts": "2026-01-16T14:20:05.088245", "ingestion_ts": "2026-01-16T14:20:56.869125", "market_id": "0x427bc4b40c09b3dcbc973747f0e4b079bed91b3e5a0aed5c36edd0f7591485f4", "raw": {"market": "0x427bc4b40c09b3dcbc973747f0e4b079bed91b3e5a0aed5c36edd0f7591485f4", "asset_id": "115669573443672055876643967408433138119481486650803218131873713375232186497057", "price": "0.007", "size": "0", "side": "BUY", "timestamp": "1768573203461", "received_at": "2026-01-16T14:20:05.088245"}}
{"event_type": "price_change", "event_ts": "2026-01-16T14:20:05.206435", "ingestion_ts": "2026-01-16T14:20:56.869125", "market_id": "0x49686d26fb712515cd5e12c23f0a1c7e10214c7faa3cb0a730aabe0c33694082", "raw": {"market": "0x49686d26fb712515cd5e12c23f0a1c7e10214c7faa3cb0a730aabe0c33694082", "asset_id": "30442780799048074404860985387051749017905070253466005720364298335239299761065", "price": "0.146", "size": "5.85", "side": "SELL", "timestamp": "1768573203682", "received_at": "2026-01-16T14:20:05.206435"}}
{"event_type": "price_change", "event_ts": "2026-01-16T14:20:05.206435", "ingestion_ts": "2026-01-16T14:20:56.869125", "market_id": "0x49686d26fb712515cd5e12c23f0a1c7e10214c7faa3cb0a730aabe0c33694082", "raw": {"market": "0x49686d26fb712515cd5e12c23f0a1c7e10214c7faa3cb0a730aabe0c33694082", "asset_id": "13244681086321087932946246027856416106585284024824496763706748621681543444582", "price": "0.854", "size": "5.85", "side": "BUY", "timestamp": "1768573203682", "received_at": "2026-01-16T14:20:05.206435"}}
{"event_type": "price_change", "event_ts": "2026-01-16T14:20:05.263910", "ingestion_ts": "2026-01-16T14:20:56.869125", "market_id": "0x49686d26fb712515cd5e12c23f0a1c7e10214c7faa3cb0a730aabe0c33694082", "raw": {"market": "0x49686d26fb712515cd5e12c23f0a1c7e10214c7faa3cb0a730aabe0c33694082", "asset_id": "30442780799048074404860985387051749017905070253466005720364298335239299761065", "price": "0.148", "size": "17.5", "side": "SELL", "timestamp": "1768573203773", "received_at": "2026-01-16T14:20:05.263910"}}
{"event_type": "price_change", "event_ts": "2026-01-16T14:20:05.263910", "ingestion_ts": "2026-01-16T14:20:56.869125", "market_id": "0x49686d26fb712515cd5e12c23f0a1c7e10214c7faa3cb0a730aabe0c33694082", "raw": {"market": "0x49686d26fb712515cd5e12c23f0a1c7e10214c7faa3cb0a730aabe0c33694082", "asset_id": "13244681086321087932946246027856416106585284024824496763706748621681543444582", "price": "0.852", "size": "17.5", "side": "BUY", "timestamp": "1768573203773", "received_at": "2026-01-16T14:20:05.263910"}}
{"event_type": "price_change", "event_ts": "2026-01-16T14:20:05.647265", "ingestion_ts": "2026-01-16T14:20:56.869125", "market_id": "0x2393ed0b0fdc450054c7b9071907eca75cf4fc36e385adf4a0a5f99ee62243e8", "raw": {"market": "0x2393ed0b0fdc450054c7b9071907eca75cf4fc36e385adf4a0a5f99ee62243e8", "asset_id": "100074770378634056601572485653252702850363676459996771990439989989293515601975", "price": "0.057", "size": "0", "side": "SELL", "timestamp": "1768573204338", "received_at": "2026-01-16T14:20:05.647265"}}
{"event_type": "price_change", "event_ts": "2026-01-16T14:20:05.647265", "ingestion_ts": "2026-01-16T14:20:56.869125", "market_id": "0x2393ed0b0fdc450054c7b9071907eca75cf4fc36e385adf4a0a5f99ee62243e8", "raw": {"market": "0x2393ed0b0fdc450054c7b9071907eca75cf4fc36e385adf4a0a5f99ee62243e8", "asset_id": "32769749367306925959219403371425714180265458150646381231272229429098460625924", "price": "0.943", "size": "0", "side": "BUY", "timestamp": "1768573204338", "received_at": "2026-01-16T14:20:05.647265"}}
{"event_type": "price_change", "event_ts": "2026-01-16T14:20:05.661424", "ingestion_ts": "2026-01-16T14:20:56.869125", "market_id": "0x2393ed0b0fdc450054c7b9071907eca75cf4fc36e385adf4a0a5f99ee62243e8", "raw": {"market": "0x2393ed0b0fdc450054c7b9071907eca75cf4fc36e385adf4a0a5f99ee62243e8", "asset_id": "100074770378634056601572485653252702850363676459996771990439989989293515601975", "price": "0.055", "size": "205", "side": "SELL", "timestamp": "1768573204366", "received_at": "2026-01-16T14:20:05.661424"}}
{"event_type": "price_change", "event_ts": "2026-01-16T14:20:05.661424", "ingestion_ts": "2026-01-16T14:20:56.869125", "market_id": "0x2393ed0b0fdc450054c7b9071907eca75cf4fc36e385adf4a0a5f99ee62243e8", "raw": {"market": "0x2393ed0b0fdc450054c7b9071907eca75cf4fc36e385adf4a0a5f99ee62243e8", "asset_id": "32769749367306925959219403371425714180265458150646381231272229429098460625924", "price": "0.945", "size": "205", "side": "BUY", "timestamp": "1768573204366", "received_at": "2026-01-16T14:20:05.661424"}}
{"event_type": "price_change", "event_ts": "2026-01-16T14:20:05.693006", "ingestion_ts": "2026-01-16T14:20:56.869125", "market_id": "0x427bc4b40c09b3dcbc973747f0e4b079bed91b3e5a0aed5c36edd0f7591485f4", "raw": {"market": "0x427bc4b40c09b3dcbc973747f0e4b079bed91b3e5a0aed5c36edd0f7591485f4", "asset_id": "115669573443672055876643967408433138119481486650803218131873713375232186497057", "price": "0.003", "size": "0", "side": "BUY", "timestamp": "1768573204396", "received_at": "2026-01-16T14:20:05.693006"}}
{"event_type": "price_change", "event_ts": "2026-01-16T14:20:05.693006", "ingestion_ts": "2026-01-16T14:20:56.869125", "market_id": "0x427bc4b40c09b3dcbc973747f0e4b079bed91b3e5a0aed5c36edd0f7591485f4", "raw": {"market": "0x427bc4b40c09b3dcbc973747f0e4b079bed91b3e5a0aed5c36edd0f7591485f4", "asset_id": "86130975769502911188457673769190265049139877688522439001984850068234616395137", "price": "0.997", "size": "0", "side": "SELL", "timestamp": "1768573204396", "received_at": "2026-01-16T14:20:05.693006"}}
{"event_type": "price_change", "event_ts": "2026-01-16T14:20:05.693044", "ingestion_ts": "2026-01-16T14:20:56.869125", "market_id": "0x427bc4b40c09b3dcbc973747f0e4b079bed91b3e5a0aed5c36edd0f7591485f4", "raw": {"market": "0x427bc4b40c09b3dcbc973747f0e4b079bed91b3e5a0aed5c36edd0f7591485f4", "asset_id": "115669573443672055876643967408433138119481486650803218131873713375232186497057", "price": "0.006", "size": "21.35", "side": "BUY", "timestamp": "1768573204396", "received_at": "2026-01-16T14:20:05.693044"}}
{"event_type": "price_change", "event_ts": "2026-01-16T14:20:05.693044", "ingestion_ts": "2026-01-16T14:20:56.869125", "market_id": "0x427bc4b40c09b3dcbc973747f0e4b079bed91b3e5a0aed5c36edd0f7591485f4", "raw": {"market": "0x427bc4b40c09b3dcbc973747f0e4b079bed91b3e5a0aed5c36edd0f7591485f4", "asset_id": "86130975769502911188457673769190265049139877688522439001984850068234616395137", "price": "0.994", "size": "21.35", "side": "SELL", "timestamp": "1768573204396", "received_at": "2026-01-16T14:20:05.693044"}}
{"event_type": "price_change", "event_ts": "2026-01-16T14:20:05.920598", "ingestion_ts": "2026-01-16T14:20:56.869125", "market_id": "0x427bc4b40c09b3dcbc973747f0e4b079bed91b3e5a0aed5c36edd0f7591485f4", "raw": {"market": "0x427bc4b40c09b3dcbc973747f0e4b079bed91b3e5a0aed5c36edd0f7591485f4", "asset_id": "115669573443672055876643967408433138119481486650803218131873713375232186497057", "price": "0.181", "size": "16.28", "side": "SELL", "timestamp": "1768573204843", "received_at": "2026-01-16T14:20:05.920598"}}
{"event_type": "price_change", "event_ts": "2026-01-16T14:20:05.920598", "ingestion_ts": "2026-01-16T14:20:56.869125", "market_id": "0x427bc4b40c09b3dcbc973747f0e4b079bed91b3e5a0aed5c36edd0f7591485f4", "raw": {"market": "0x427bc4b40c09b3dcbc973747f0e4b079bed91b3e5a0aed5c36edd0f7591485f4", "asset_id": "86130975769502911188457673769190265049139877688522439001984850068234616395137", "price": "0.819", "size": "16.28", "side": "BUY", "timestamp": "1768573204843", "received_at": "2026-01-16T14:20:05.920598"}}
{"event_type": "price_change", "event_ts": "2026-01-16T14:20:05.920637", "ingestion_ts": "2026-01-16T14:20:56.869125", "market_id": "0x427bc4b40c09b3dcbc973747f0e4b079bed91b3e5a0aed5c36edd0f7591485f4", "raw": {"market": "0x427bc4b40c09b3dcbc973747f0e4b079bed91b3e5a0aed5c36edd0f7591485f4", "asset_id": "115669573443672055876643967408433138119481486650803218131873713375232186497057", "price": "0.182", "size": "7.81", "side": "SELL", "timestamp": "1768573204843", "received_at": "2026-01-16T14:20:05.920637"}}
{"event_type": "price_change", "event_ts": "2026-01-16T14:20:05.920637", "ingestion_ts": "2026-01-16T14:20:56.869125", "market_id": "0x427bc4b40c09b3dcbc973747f0e4b079bed91b3e5a0aed5c36edd0f7591485f4", "raw": {"market": "0x427bc4b40c09b3dcbc973747f0e4b079bed91b3e5a0aed5c36edd0f7591485f4", "asset_id": "86130975769502911188457673769190265049139877688522439001984850068234616395137", "price": "0.818", "size": "7.81", "side": "BUY", "timestamp": "1768573204843", "received_at": "2026-01-16T14:20:05.920637"}}
{"event_type": "price_change", "event_ts": "2026-01-16T14:20:06.221802", "ingestion_ts": "2026-01-16T14:20:56.869125", "market_id": "0x427bc4b40c09b3dcbc973747f0e4b079bed91b3e5a0aed5c36edd0f7591485f4", "raw": {"market": "0x427bc4b40c09b3dcbc973747f0e4b079bed91b3e5a0aed5c36edd0f7591485f4", "asset_id": "115669573443672055876643967408433138119481486650803218131873713375232186497057", "price": "0.47", "size": "69.7", "side": "SELL", "timestamp": "1768573205301", "received_at": "2026-01-16T14:20:06.221802"}}
{"event_type": "price_change", "event_ts": "2026-01-16T14:20:06.221802", "ingestion_ts": "2026-01-16T14:20:56.869125", "market_id": "0x427bc4b40c09b3dcbc973747f0e4b079bed91b3e5a0aed5c36edd0f7591485f4", "raw": {"market": "0x427bc4b40c09b3dcbc973747f0e4b079bed91b3e5a0aed5c36edd0f7591485f4", "asset_id": "86130975769502911188457673769190265049139877688522439001984850068234616395137", "price": "0.53", "size": "69.7", "side": "BUY", "timestamp": "1768573205301", "received_at": "2026-01-16T14:20:06.221802"}}
{"event_type": "price_change", "event_ts": "2026-01-16T14:20:06.221842", "ingestion_ts": "2026-01-16T14:20:56.869125", "market_id": "0x427bc4b40c09b3dcbc973747f0e4b079bed91b3e5a0aed5c36edd0f7591485f4", "raw": {"market": "0x427bc4b40c09b3dcbc973747f0e4b079bed91b3e5a0aed5c36edd0f7591485f4", "asset_id": "115669573443672055876643967408433138119481486650803218131873713375232186497057", "price": "0.47", "size": "81.76", "side": "SELL", "timestamp": "1768573205303", "received_at": "2026-01-16T14:20:06.221842"}}
{"event_type": "price_change", "event_ts": "2026-01-16T14:20:06.221842", "ingestion_ts": "2026-01-16T14:20:56.869125", "market_id": "0x427bc4b40c09b3dcbc973747f0e4b079bed91b3e5a0aed5c36edd0f7591485f4", "raw": {"market": "0x427bc4b40c09b3dcbc973747f0e4b079bed91b3e5a0aed5c36edd0f7591485f4", "asset_id": "86130975769502911188457673769190265049139877688522439001984850068234616395137", "price": "0.53", "size": "81.76", "side": "BUY", "timestamp": "1768573205303", "received_at": "2026-01-16T14:20:06.221842"}}
{"event_type": "price_change", "event_ts": "2026-01-16T14:20:08.069095", "ingestion_ts": "2026-01-16T14:20:56.869125", "market_id": "0x427bc4b40c09b3dcbc973747f0e4b079bed91b3e5a0aed5c36edd0f7591485f4", "raw": {"market": "0x427bc4b40c09b3dcbc973747f0e4b079bed91b3e5a0aed5c36edd0f7591485f4", "asset_id": "115669573443672055876643967408433138119481486650803218131873713375232186497057", "price": "0.008", "size": "0", "side": "BUY", "timestamp": "1768573207594", "received_at": "2026-01-16T14:20:08.069095"}}
{"event_type": "price_change", "event_ts": "2026-01-16T14:20:08.069095", "ingestion_ts": "2026-01-16T14:20:56.869125", "market_id": "0x427bc4b40c09b3dcbc973747f0e4b079bed91b3e5a0aed5c36edd0f7591485f4", "raw": {"market": "0x427bc4b40c09b3dcbc973747f0e4b079bed91b3e5a0aed5c36edd0f7591485f4", "asset_id": "86130975769502911188457673769190265049139877688522439001984850068234616395137", "price": "0.992", "size": "0", "side": "SELL", "timestamp": "1768573207594", "received_at": "2026-01-16T14:20:08.069095"}}
{"event_type": "price_change", "event_ts": "2026-01-16T14:20:08.119475", "ingestion_ts": "2026-01-16T14:20:56.869125", "market_id": "0x427bc4b40c09b3dcbc973747f0e4b079bed91b3e5a0aed5c36edd0f7591485f4", "raw": {"market": "0x427bc4b40c09b3dcbc973747f0e4b079bed91b3e5a0aed5c36edd0f7591485f4", "asset_id": "86130975769502911188457673769190265049139877688522439001984850068234616395137", "price": "0.82", "size": "46", "side": "BUY", "timestamp": "1768573207635", "received_at": "2026-01-16T14:20:08.119475"}}
{"event_type": "price_change", "event_ts": "2026-01-16T14:20:08.119475", "ingestion_ts": "2026-01-16T14:20:56.869125", "market_id": "0x427bc4b40c09b3dcbc973747f0e4b079bed91b3e5a0aed5c36edd0f7591485f4", "raw": {"market": "0x427bc4b40c09b3dcbc973747f0e4b079bed91b3e5a0aed5c36edd0f7591485f4", "asset_id": "115669573443672055876643967408433138119481486650803218131873713375232186497057", "price": "0.18", "size": "46", "side": "SELL", "timestamp": "1768573207635", "received_at": "2026-01-16T14:20:08.119475"}}
{"event_type": "price_change", "event_ts": "2026-01-16T14:20:08.248001", "ingestion_ts": "2026-01-16T14:20:56.869125", "market_id": "0x427bc4b40c09b3dcbc973747f0e4b079bed91b3e5a0aed5c36edd0f7591485f4", "raw": {"market": "0x427bc4b40c09b3dcbc973747f0e4b079bed91b3e5a0aed5c36edd0f7591485f4", "asset_id": "115669573443672055876643967408433138119481486650803218131873713375232186497057", "price": "0.006", "size": "31.17", "side": "BUY", "timestamp": "1768573207807", "received_at": "2026-01-16T14:20:08.248001"}}
{"event_type": "price_change", "event_ts": "2026-01-16T14:20:08.248001", "ingestion_ts": "2026-01-16T14:20:56.869125", "market_id": "0x427bc4b40c09b3dcbc973747f0e4b079bed91b3e5a0aed5c36edd0f7591485f4", "raw": {"market": "0x427bc4b40c09b3dcbc973747f0e4b079bed91b3e5a0aed5c36edd0f7591485f4", "asset_id": "86130975769502911188457673769190265049139877688522439001984850068234616395137", "price": "0.994", "size": "31.17", "side": "SELL", "timestamp": "1768573207807", "received_at": "2026-01-16T14:20:08.248001"}}
{"event_type": "price_change", "event_ts": "2026-01-16T14:20:08.248066", "ingestion_ts": "2026-01-16T14:20:56.869125", "market_id": "0x427bc4b40c09b3dcbc973747f0e4b079bed91b3e5a0aed5c36edd0f7591485f4", "raw": {"market": "0x427bc4b40c09b3dcbc973747f0e4b079bed91b3e5a0aed5c36edd0f7591485f4", "asset_id": "115669573443672055876643967408433138119481486650803218131873713375232186497057", "price": "0.006", "size": "40.99", "side": "BUY", "timestamp": "1768573207813", "received_at": "2026-01-16T14:20:08.248066"}}
{"event_type": "price_change", "event_ts": "2026-01-16T14:20:08.248066", "ingestion_ts": "2026-01-16T14:20:56.869125", "market_id": "0x427bc4b40c09b3dcbc973747f0e4b079bed91b3e5a0aed5c36edd0f7591485f4", "raw": {"market": "0x427bc4b40c09b3dcbc973747f0e4b079bed91b3e5a0aed5c36edd0f7591485f4", "asset_id": "86130975769502911188457673769190265049139877688522439001984850068234616395137", "price": "0.994", "size": "40.99", "side": "SELL", "timestamp": "1768573207813", "received_at": "2026-01-16T14:20:08.248066"}}
{"event_type": "price_change", "event_ts": "2026-01-16T14:20:08.256281", "ingestion_ts": "2026-01-16T14:20:56.869125", "market_id": "0x427bc4b40c09b3dcbc973747f0e4b079bed91b3e5a0aed5c36edd0f7591485f4", "raw": {"market": "0x427bc4b40c09b3dcbc973747f0e4b079bed91b3e5a0aed5c36edd0f7591485f4", "asset_id": "86130975769502911188457673769190265049139877688522439001984850068234616395137", "price": "0.993", "size": "36", "side": "SELL", "timestamp": "1768573207840", "received_at": "2026-01-16T14:20:08.256281"}}
{"event_type": "price_change", "event_ts": "2026-01-16T14:20:08.256281", "ingestion_ts": "2026-01-16T14:20:56.869125", "market_id": "0x427bc4b40c09b3dcbc973747f0e4b079bed91b3e5a0aed5c36edd0f7591485f4", "raw": {"market": "0x427bc4b40c09b3dcbc973747f0e4b079bed91b3e5a0aed5c36edd0f7591485f4", "asset_id": "115669573443672055876643967408433138119481486650803218131873713375232186497057", "price": "0.007", "size": "36", "side": "BUY", "timestamp": "1768573207840", "received_at": "2026-01-16T14:20:08.256281"}}
{"event_type": "price_change", "event_ts": "2026-01-16T14:20:08.367634", "ingestion_ts": "2026-01-16T14:20:56.869125", "market_id": "0x427bc4b40c09b3dcbc973747f0e4b079bed91b3e5a0aed5c36edd0f7591485f4", "raw": {"market": "0x427bc4b40c09b3dcbc973747f0e4b079bed91b3e5a0aed5c36edd0f7591485f4", "asset_id": "115669573443672055876643967408433138119481486650803218131873713375232186497057", "price": "0.181", "size": "0", "side": "SELL", "timestamp": "1768573208044", "received_at": "2026-01-16T14:20:08.367634"}}
{"event_type": "price_change", "event_ts": "2026-01-16T14:20:08.367634", "ingestion_ts": "2026-01-16T14:20:56.869125", "market_id": "0x427bc4b40c09b3dcbc973747f0e4b079bed91b3e5a0aed5c36edd0f7591485f4", "raw": {"market": "0x427bc4b40c09b3dcbc973747f0e4b079bed91b3e5a0aed5c36edd0f7591485f4", "asset_id": "86130975769502911188457673769190265049139877688522439001984850068234616395137", "price": "0.819", "size": "0", "side": "BUY", "timestamp": "1768573208044", "received_at": "2026-01-16T14:20:08.367634"}}
{"event_type": "price_change", "event_ts": "2026-01-16T14:20:08.367687", "ingestion_ts": "2026-01-16T14:20:56.869125", "market_id": "0x427bc4b40c09b3dcbc973747f0e4b079bed91b3e5a0aed5c36edd0f7591485f4", "raw": {"market": "0x427bc4b40c09b3dcbc973747f0e4b079bed91b3e5a0aed5c36edd0f7591485f4", "asset_id": "115669573443672055876643967408433138119481486650803218131873713375232186497057", "price": "0.182", "size": "0", "side": "SELL", "timestamp": "1768573208044", "received_at": "2026-01-16T14:20:08.367687"}}
{"event_type": "price_change", "event_ts": "2026-01-16T14:20:08.367687", "ingestion_ts": "2026-01-16T14:20:56.869125", "market_id": "0x427bc4b40c09b3dcbc973747f0e4b079bed91b3e5a0aed5c36edd0f7591485f4", "raw": {"market": "0x427bc4b40c09b3dcbc973747f0e4b079bed91b3e5a0aed5c36edd0f7591485f4", "asset_id": "86130975769502911188457673769190265049139877688522439001984850068234616395137", "price": "0.818", "size": "0", "side": "BUY", "timestamp": "1768573208044", "received_at": "2026-01-16T14:20:08.367687"}}
{"event_type": "price_change", "event_ts": "2026-01-16T14:20:08.367710", "ingestion_ts": "2026-01-16T14:20:56.869125", "market_id": "0x427bc4b40c09b3dcbc973747f0e4b079bed91b3e5a0aed5c36edd0f7591485f4", "raw": {"market": "0x427bc4b40c09b3dcbc973747f0e4b079bed91b3e5a0aed5c36edd0f7591485f4", "asset_id": "115669573443672055876643967408433138119481486650803218131873713375232186497057", "price": "0.47", "size": "49.45", "side": "SELL", "timestamp": "1768573208044", "received_at": "2026-01-16T14:20:08.367710"}}
{"event_type": "price_change", "event_ts": "2026-01-16T14:20:08.367710", "ingestion_ts": "2026-01-16T14:20:56.869125", "market_id": "0x427bc4b40c09b3dcbc973747f0e4b079bed91b3e5a0aed5c36edd0f7591485f4", "raw": {"market": "0x427bc4b40c09b3dcbc973747f0e4b079bed91b3e5a0aed5c36edd0f7591485f4", "asset_id": "86130975769502911188457673769190265049139877688522439001984850068234616395137", "price": "0.53", "size": "49.45", "side": "BUY", "timestamp": "1768573208044", "received_at": "2026-01-16T14:20:08.367710"}}
{"event_type": "price_change", "event_ts": "2026-01-16T14:20:08.708602", "ingestion_ts": "2026-01-16T14:20:56.869125", "market_id": "0x427bc4b40c09b3dcbc973747f0e4b079bed91b3e5a0aed5c36edd0f7591485f4", "raw": {"market": "0x427bc4b40c09b3dcbc973747f0e4b079bed91b3e5a0aed5c36edd0f7591485f4", "asset_id": "115669573443672055876643967408433138119481486650803218131873713375232186497057", "price": "0.179", "size": "28.2", "side": "SELL", "timestamp": "1768573208492", "received_at": "2026-01-16T14:20:08.708602"}}
{"event_type": "price_change", "event_ts": "2026-01-16T14:20:08.708602", "ingestion_ts": "2026-01-16T14:20:56.869125", "market_id": "0x427bc4b40c09b3dcbc973747f0e4b079bed91b3e5a0aed5c36edd0f7591485f4", "raw": {"market": "0x427bc4b40c09b3dcbc973747f0e4b079bed91b3e5a0aed5c36edd0f7591485f4", "asset_id": "86130975769502911188457673769190265049139877688522439001984850068234616395137", "price": "0.821", "size": "28.2", "side": "BUY", "timestamp": "1768573208492", "received_at": "2026-01-16T14:20:08.708602"}}
{"event_type": "price_change", "event_ts": "2026-01-16T14:20:08.711582", "ingestion_ts": "2026-01-16T14:20:56.869125", "market_id": "0x427bc4b40c09b3dcbc973747f0e4b079bed91b3e5a0aed5c36edd0f7591485f4", "raw": {"market": "0x427bc4b40c09b3dcbc973747f0e4b079bed91b3e5a0aed5c36edd0f7591485f4", "asset_id": "115669573443672055876643967408433138119481486650803218131873713375232186497057", "price": "0.179", "size": "56.4", "side": "SELL", "timestamp": "1768573208496", "received_at": "2026-01-16T14:20:08.711582"}}
{"event_type": "price_change", "event_ts": "2026-01-16T14:20:08.711582", "ingestion_ts": "2026-01-16T14:20:56.869125", "market_id": "0x427bc4b40c09b3dcbc973747f0e4b079bed91b3e5a0aed5c36edd0f7591485f4", "raw": {"market": "0x427bc4b40c09b3dcbc973747f0e4b079bed91b3e5a0aed5c36edd0f7591485f4", "asset_id": "86130975769502911188457673769190265049139877688522439001984850068234616395137", "price": "0.821", "size": "56.4", "side": "BUY", "timestamp": "1768573208496", "received_at": "2026-01-16T14:20:08.711582"}}
{"event_type": "price_change", "event_ts": "2026-01-16T14:20:09.107582", "ingestion_ts": "2026-01-16T14:20:56.869125", "market_id": "0x427bc4b40c09b3dcbc973747f0e4b079bed91b3e5a0aed5c36edd0f7591485f4", "raw": {"market": "0x427bc4b40c09b3dcbc973747f0e4b079bed91b3e5a0aed5c36edd0f7591485f4", "asset_id": "86130975769502911188457673769190265049139877688522439001984850068234616395137", "price": "0.82", "size": "0", "side": "BUY", "timestamp": "1768573208968", "received_at": "2026-01-16T14:20:09.107582"}}
{"event_type": "price_change", "event_ts": "2026-01-16T14:20:09.107582", "ingestion_ts": "2026-01-16T14:20:56.869125", "market_id": "0x427bc4b40c09b3dcbc973747f0e4b079bed91b3e5a0aed5c36edd0f7591485f4", "raw": {"market": "0x427bc4b40c09b3dcbc973747f0e4b079bed91b3e5a0aed5c36edd0f7591485f4", "asset_id": "115669573443672055876643967408433138119481486650803218131873713375232186497057", "price": "0.18", "size": "0", "side": "SELL", "timestamp": "1768573208968", "received_at": "2026-01-16T14:20:09.107582"}}
{"event_type": "price_change", "event_ts": "2026-01-16T14:20:09.152867", "ingestion_ts": "2026-01-16T14:20:56.869125", "market_id": "0x427bc4b40c09b3dcbc973747f0e4b079bed91b3e5a0aed5c36edd0f7591485f4", "raw": {"market": "0x427bc4b40c09b3dcbc973747f0e4b079bed91b3e5a0aed5c36edd0f7591485f4", "asset_id": "86130975769502911188457673769190265049139877688522439001984850068234616395137", "price": "0.822", "size": "52", "side": "BUY", "timestamp": "1768573209008", "received_at": "2026-01-16T14:20:09.152867"}}
{"event_type": "price_change", "event_ts": "2026-01-16T14:20:09.152867", "ingestion_ts": "2026-01-16T14:20:56.869125", "market_id": "0x427bc4b40c09b3dcbc973747f0e4b079bed91b3e5a0aed5c36edd0f7591485f4", "raw": {"market": "0x427bc4b40c09b3dcbc973747f0e4b079bed91b3e5a0aed5c36edd0f7591485f4", "asset_id": "115669573443672055876643967408433138119481486650803218131873713375232186497057", "price": "0.178", "size": "52", "side": "SELL", "timestamp": "1768573209008", "received_at": "2026-01-16T14:20:09.152867"}}
{"event_type": "price_change", "event_ts": "2026-01-16T14:20:09.886735", "ingestion_ts": "2026-01-16T14:20:56.869125", "market_id": "0x427bc4b40c09b3dcbc973747f0e4b079bed91b3e5a0aed5c36edd0f7591485f4", "raw": {"market": "0x427bc4b40c09b3dcbc973747f0e4b079bed91b3e5a0aed5c36edd0f7591485f4", "asset_id": "115669573443672055876643967408433138119481486650803218131873713375232186497057", "price": "0.006", "size": "21.35", "side": "BUY", "timestamp": "1768573209842", "received_at": "2026-01-16T14:20:09.886735"}}
{"event_type": "price_change", "event_ts": "2026-01-16T14:20:09.886735", "ingestion_ts": "2026-01-16T14:20:56.869125", "market_id": "0x427bc4b40c09b3dcbc973747f0e4b079bed91b3e5a0aed5c36edd0f7591485f4", "raw": {"market": "0x427bc4b40c09b3dcbc973747f0e4b079bed91b3e5a0aed5c36edd0f7591485f4", "asset_id": "86130975769502911188457673769190265049139877688522439001984850068234616395137", "price": "0.994", "size": "21.35", "side": "SELL", "timestamp": "1768573209842", "received_at": "2026-01-16T14:20:09.886735"}}
{"event_type": "price_change", "event_ts": "2026-01-16T14:20:10.040941", "ingestion_ts": "2026-01-16T14:20:56.869125", "market_id": "0x49686d26fb712515cd5e12c23f0a1c7e10214c7faa3cb0a730aabe0c33694082", "raw": {"market": "0x49686d26fb712515cd5e12c23f0a1c7e10214c7faa3cb0a730aabe0c33694082", "asset_id": "13244681086321087932946246027856416106585284024824496763706748621681543444582", "price": "0.854", "size": "0", "side": "BUY", "timestamp": "1768573209971", "received_at": "2026-01-16T14:20:10.040941"}}
{"event_type": "price_change", "event_ts": "2026-01-16T14:20:10.040941", "ingestion_ts": "2026-01-16T14:20:56.869125", "market_id": "0x49686d26fb712515cd5e12c23f0a1c7e10214c7faa3cb0a730aabe0c33694082", "raw": {"market": "0x49686d26fb712515cd5e12c23f0a1c7e10214c7faa3cb0a730aabe0c33694082", "asset_id": "30442780799048074404860985387051749017905070253466005720364298335239299761065", "price": "0.146", "size": "0", "side": "SELL", "timestamp": "1768573209971", "received_at": "2026-01-16T14:20:10.040941"}}
{"event_type": "price_change", "event_ts": "2026-01-16T14:20:10.084061", "ingestion_ts": "2026-01-16T14:20:56.869125", "market_id": "0x49686d26fb712515cd5e12c23f0a1c7e10214c7faa3cb0a730aabe0c33694082", "raw": {"market": "0x49686d26fb712515cd5e12c23f0a1c7e10214c7faa3cb0a730aabe0c33694082", "asset_id": "13244681086321087932946246027856416106585284024824496763706748621681543444582", "price": "0.911", "size": "132.98", "side": "SELL", "timestamp": "1768573210006", "received_at": "2026-01-16T14:20:10.084061"}}
{"event_type": "price_change", "event_ts": "2026-01-16T14:20:10.084061", "ingestion_ts": "2026-01-16T14:20:56.869125", "market_id": "0x49686d26fb712515cd5e12c23f0a1c7e10214c7faa3cb0a730aabe0c33694082", "raw": {"market": "0x49686d26fb712515cd5e12c23f0a1c7e10214c7faa3cb0a730aabe0c33694082", "asset_id": "30442780799048074404860985387051749017905070253466005720364298335239299761065", "price": "0.089", "size": "132.98", "side": "BUY", "timestamp": "1768573210006", "received_at": "2026-01-16T14:20:10.084061"}}
{"event_type": "price_change", "event_ts": "2026-01-16T14:20:10.216074", "ingestion_ts": "2026-01-16T14:20:56.869125", "market_id": "0x427bc4b40c09b3dcbc973747f0e4b079bed91b3e5a0aed5c36edd0f7591485f4", "raw": {"market": "0x427bc4b40c09b3dcbc973747f0e4b079bed91b3e5a0aed5c36edd0f7591485f4", "asset_id": "115669573443672055876643967408433138119481486650803218131873713375232186497057", "price": "0.002", "size": "108.51", "side": "BUY", "timestamp": "1768573210167", "received_at": "2026-01-16T14:20:10.216074"}}
{"event_type": "price_change", "event_ts": "2026-01-16T14:20:10.216074", "ingestion_ts": "2026-01-16T14:20:56.869125", "market_id": "0x427bc4b40c09b3dcbc973747f0e4b079bed91b3e5a0aed5c36edd0f7591485f4", "raw": {"market": "0x427bc4b40c09b3dcbc973747f0e4b079bed91b3e5a0aed5c36edd0f7591485f4", "asset_id": "86130975769502911188457673769190265049139877688522439001984850068234616395137", "price": "0.998", "size": "108.51", "side": "SELL", "timestamp": "1768573210167", "received_at": "2026-01-16T14:20:10.216074"}}
{"event_type": "price_change", "event_ts": "2026-01-16T14:20:10.220729", "ingestion_ts": "2026-01-16T14:20:56.869125", "market_id": "0x427bc4b40c09b3dcbc973747f0e4b079bed91b3e5a0aed5c36edd0f7591485f4", "raw": {"market": "0x427bc4b40c09b3dcbc973747f0e4b079bed91b3e5a0aed5c36edd0f7591485f4", "asset_id": "115669573443672055876643967408433138119481486650803218131873713375232186497057", "price": "0.008", "size": "5.06", "side": "BUY", "timestamp": "1768573210168", "received_at": "2026-01-16T14:20:10.220729"}}
{"event_type": "price_change", "event_ts": "2026-01-16T14:20:10.220729", "ingestion_ts": "2026-01-16T14:20:56.869125", "market_id": "0x427bc4b40c09b3dcbc973747f0e4b079bed91b3e5a0aed5c36edd0f7591485f4", "raw": {"market": "0x427bc4b40c09b3dcbc973747f0e4b079bed91b3e5a0aed5c36edd0f7591485f4", "asset_id": "86130975769502911188457673769190265049139877688522439001984850068234616395137", "price": "0.992", "size": "5.06", "side": "SELL", "timestamp": "1768573210168", "received_at": "2026-01-16T14:20:10.220729"}}
{"event_type": "price_change", "event_ts": "2026-01-16T14:20:10.220745", "ingestion_ts": "2026-01-16T14:20:56.869125", "market_id": "0x427bc4b40c09b3dcbc973747f0e4b079bed91b3e5a0aed5c36edd0f7591485f4", "raw": {"market": "0x427bc4b40c09b3dcbc973747f0e4b079bed91b3e5a0aed5c36edd0f7591485f4", "asset_id": "115669573443672055876643967408433138119481486650803218131873713375232186497057", "price": "0.002", "size": "117.7", "side": "BUY", "timestamp": "1768573210169", "received_at": "2026-01-16T14:20:10.220745"}}
{"event_type": "price_change", "event_ts": "2026-01-16T14:20:10.220745", "ingestion_ts": "2026-01-16T14:20:56.869125", "market_id": "0x427bc4b40c09b3dcbc973747f0e4b079bed91b3e5a0aed5c36edd0f7591485f4", "raw": {"market": "0x427bc4b40c09b3dcbc973747f0e4b079bed91b3e5a0aed5c36edd0f7591485f4", "asset_id": "86130975769502911188457673769190265049139877688522439001984850068234616395137", "price": "0.998", "size": "117.7", "side": "SELL", "timestamp": "1768573210169", "received_at": "2026-01-16T14:20:10.220745"}}
{"event_type": "price_change", "event_ts": "2026-01-16T14:20:10.220756", "ingestion_ts": "2026-01-16T14:20:56.869125", "market_id": "0x427bc4b40c09b3dcbc973747f0e4b079bed91b3e5a0aed5c36edd0f7591485f4", "raw": {"market": "0x427bc4b40c09b3dcbc973747f0e4b079bed91b3e5a0aed5c36edd0f7591485f4", "asset_id": "115669573443672055876643967408433138119481486650803218131873713375232186497057", "price": "0.008", "size": "10.12", "side": "BUY", "timestamp": "1768573210170", "received_at": "2026-01-16T14:20:10.220756"}}
{"event_type": "price_change", "event_ts": "2026-01-16T14:20:10.220756", "ingestion_ts": "2026-01-16T14:20:56.869125", "market_id": "0x427bc4b40c09b3dcbc973747f0e4b079bed91b3e5a0aed5c36edd0f7591485f4", "raw": {"market": "0x427bc4b40c09b3dcbc973747f0e4b079bed91b3e5a0aed5c36edd0f7591485f4", "asset_id": "86130975769502911188457673769190265049139877688522439001984850068234616395137", "price": "0.992", "size": "10.12", "side": "SELL", "timestamp": "1768573210170", "received_at": "2026-01-16T14:20:10.220756"}}
{"event_type": "price_change", "event_ts": "2026-01-16T14:20:10.243935", "ingestion_ts": "2026-01-16T14:20:56.869125", "market_id": "0x427bc4b40c09b3dcbc973747f0e4b079bed91b3e5a0aed5c36edd0f7591485f4", "raw": {"market": "0x427bc4b40c09b3dcbc973747f0e4b079bed91b3e5a0aed5c36edd0f7591485f4", "asset_id": "86130975769502911188457673769190265049139877688522439001984850068234616395137", "price": "0.822", "size": "0", "side": "BUY", "timestamp": "1768573210205", "received_at": "2026-01-16T14:20:10.243935"}}
{"event_type": "price_change", "event_ts": "2026-01-16T14:20:10.243935", "ingestion_ts": "2026-01-16T14:20:56.869125", "market_id": "0x427bc4b40c09b3dcbc973747f0e4b079bed91b3e5a0aed5c36edd0f7591485f4", "raw": {"market": "0x427bc4b40c09b3dcbc973747f0e4b079bed91b3e5a0aed5c36edd0f7591485f4", "asset_id": "115669573443672055876643967408433138119481486650803218131873713375232186497057", "price": "0.178", "size": "0", "side": "SELL", "timestamp": "1768573210205", "received_at": "2026-01-16T14:20:10.243935"}}
{"event_type": "price_change", "event_ts": "2026-01-16T14:20:10.243976", "ingestion_ts": "2026-01-16T14:20:56.869125", "market_id": "0x427bc4b40c09b3dcbc973747f0e4b079bed91b3e5a0aed5c36edd0f7591485f4", "raw": {"market": "0x427bc4b40c09b3dcbc973747f0e4b079bed91b3e5a0aed5c36edd0f7591485f4", "asset_id": "86130975769502911188457673769190265049139877688522439001984850068234616395137", "price": "0.993", "size": "0", "side": "SELL", "timestamp": "1768573210205", "received_at": "2026-01-16T14:20:10.243976"}}
{"event_type": "price_change", "event_ts": "2026-01-16T14:20:10.243976", "ingestion_ts": "2026-01-16T14:20:56.869125", "market_id": "0x427bc4b40c09b3dcbc973747f0e4b079bed91b3e5a0aed5c36edd0f7591485f4", "raw": {"market": "0x427bc4b40c09b3dcbc973747f0e4b079bed91b3e5a0aed5c36edd0f7591485f4", "asset_id": "115669573443672055876643967408433138119481486650803218131873713375232186497057", "price": "0.007", "size": "0", "side": "BUY", "timestamp": "1768573210205", "received_at": "2026-01-16T14:20:10.243976"}}
{"event_type": "price_change", "event_ts": "2026-01-16T14:20:10.767892", "ingestion_ts": "2026-01-16T14:20:56.869125", "market_id": "0x427bc4b40c09b3dcbc973747f0e4b079bed91b3e5a0aed5c36edd0f7591485f4", "raw": {"market": "0x427bc4b40c09b3dcbc973747f0e4b079bed91b3e5a0aed5c36edd0f7591485f4", "asset_id": "115669573443672055876643967408433138119481486650803218131873713375232186497057", "price": "0.179", "size": "28.2", "side": "SELL", "timestamp": "1768573210727", "received_at": "2026-01-16T14:20:10.767892"}}
{"event_type": "price_change", "event_ts": "2026-01-16T14:20:10.767892", "ingestion_ts": "2026-01-16T14:20:56.869125", "market_id": "0x427bc4b40c09b3dcbc973747f0e4b079bed91b3e5a0aed5c36edd0f7591485f4", "raw": {"market": "0x427bc4b40c09b3dcbc973747f0e4b079bed91b3e5a0aed5c36edd0f7591485f4", "asset_id": "86130975769502911188457673769190265049139877688522439001984850068234616395137", "price": "0.821", "size": "28.2", "side": "BUY", "timestamp": "1768573210727", "received_at": "2026-01-16T14:20:10.767892"}}
{"event_type": "price_change", "event_ts": "2026-01-16T14:20:11.098377", "ingestion_ts": "2026-01-16T14:20:56.869125", "market_id": "0x427bc4b40c09b3dcbc973747f0e4b079bed91b3e5a0aed5c36edd0f7591485f4", "raw": {"market": "0x427bc4b40c09b3dcbc973747f0e4b079bed91b3e5a0aed5c36edd0f7591485f4", "asset_id": "115669573443672055876643967408433138119481486650803218131873713375232186497057", "price": "0.47", "size": "63.55", "side": "SELL", "timestamp": "1768573211044", "received_at": "2026-01-16T14:20:11.098377"}}
{"event_type": "price_change", "event_ts": "2026-01-16T14:20:11.098377", "ingestion_ts": "2026-01-16T14:20:56.869125", "market_id": "0x427bc4b40c09b3dcbc973747f0e4b079bed91b3e5a0aed5c36edd0f7591485f4", "raw": {"market": "0x427bc4b40c09b3dcbc973747f0e4b079bed91b3e5a0aed5c36edd0f7591485f4", "asset_id": "86130975769502911188457673769190265049139877688522439001984850068234616395137", "price": "0.53", "size": "63.55", "side": "BUY", "timestamp": "1768573211044", "received_at": "2026-01-16T14:20:11.098377"}}
{"event_type": "price_change", "event_ts": "2026-01-16T14:20:11.098433", "ingestion_ts": "2026-01-16T14:20:56.869125", "market_id": "0x427bc4b40c09b3dcbc973747f0e4b079bed91b3e5a0aed5c36edd0f7591485f4", "raw": {"market": "0x427bc4b40c09b3dcbc973747f0e4b079bed91b3e5a0aed5c36edd0f7591485f4", "asset_id": "115669573443672055876643967408433138119481486650803218131873713375232186497057", "price": "0.47", "size": "77.65", "side": "SELL", "timestamp": "1768573211046", "received_at": "2026-01-16T14:20:11.098433"}}
{"event_type": "price_change", "event_ts": "2026-01-16T14:20:11.098433", "ingestion_ts": "2026-01-16T14:20:56.869125", "market_id": "0x427bc4b40c09b3dcbc973747f0e4b079bed91b3e5a0aed5c36edd0f7591485f4", "raw": {"market": "0x427bc4b40c09b3dcbc973747f0e4b079bed91b3e5a0aed5c36edd0f7591485f4", "asset_id": "86130975769502911188457673769190265049139877688522439001984850068234616395137", "price": "0.53", "size": "77.65", "side": "BUY", "timestamp": "1768573211046", "received_at": "2026-01-16T14:20:11.098433"}}
{"event_type": "price_change", "event_ts": "2026-01-16T14:20:11.472577", "ingestion_ts": "2026-01-16T14:20:56.869125", "market_id": "0x9472be65457510b7fc3477b20ba90910e99d92eac8421a14bf4b7b7a08ef31dc", "raw": {"market": "0x9472be65457510b7fc3477b20ba90910e99d92eac8421a14bf4b7b7a08ef31dc", "asset_id": "43311793366960417907757893276427136943959788721376762326430771171648759300146", "price": "0.859", "size": "0", "side": "BUY", "timestamp": "1768573211405", "received_at": "2026-01-16T14:20:11.472577"}}
{"event_type": "price_change", "event_ts": "2026-01-16T14:20:11.472577", "ingestion_ts": "2026-01-16T14:20:56.869125", "market_id": "0x9472be65457510b7fc3477b20ba90910e99d92eac8421a14bf4b7b7a08ef31dc", "raw": {"market": "0x9472be65457510b7fc3477b20ba90910e99d92eac8421a14bf4b7b7a08ef31dc", "asset_id": "73414222381656326204771753454630063673548497164758947581648273905027617570612", "price": "0.141", "size": "0", "side": "SELL", "timestamp": "1768573211405", "received_at": "2026-01-16T14:20:11.472577"}}
{"event_type": "price_change", "event_ts": "2026-01-16T14:20:11.472614", "ingestion_ts": "2026-01-16T14:20:56.869125", "market_id": "0xc55db914f0fd1fee18997706712c0dfd8d0369cdbef93a9fef12bd001914ca77", "raw": {"market": "0xc55db914f0fd1fee18997706712c0dfd8d0369cdbef93a9fef12bd001914ca77", "asset_id": "114600293444080540179603459515770723592661967180480327891296353898330242622833", "price": "0.86", "size": "0", "side": "BUY", "timestamp": "1768573211405", "received_at": "2026-01-16T14:20:11.472614"}}
{"event_type": "price_change", "event_ts": "2026-01-16T14:20:11.472614", "ingestion_ts": "2026-01-16T14:20:56.869125", "market_id": "0xc55db914f0fd1fee18997706712c0dfd8d0369cdbef93a9fef12bd001914ca77", "raw": {"market": "0xc55db914f0fd1fee18997706712c0dfd8d0369cdbef93a9fef12bd001914ca77", "asset_id": "72354723612769247426741660426331235762851940382312402276325808095604519806766", "price": "0.14", "size": "0", "side": "SELL", "timestamp": "1768573211405", "received_at": "2026-01-16T14:20:11.472614"}}
{"event_type": "price_change", "event_ts": "2026-01-16T14:20:11.472627", "ingestion_ts": "2026-01-16T14:20:56.869125", "market_id": "0xb9bbdd34304344dcc45803780a34c97d73a00133a5ecf70f63e1008b8abb2fca", "raw": {"market": "0xb9bbdd34304344dcc45803780a34c97d73a00133a5ecf70f63e1008b8abb2fca", "asset_id": "8682484153073832526711485265636767086525069344085206423986003504588877767339", "price": "0.851", "size": "558", "side": "BUY", "timestamp": "1768573211405", "received_at": "2026-01-16T14:20:11.472627"}}
{"event_type": "price_change", "event_ts": "2026-01-16T14:20:11.472627", "ingestion_ts": "2026-01-16T14:20:56.869125", "market_id": "0xb9bbdd34304344dcc45803780a34c97d73a00133a5ecf70f63e1008b8abb2fca", "raw": {"market": "0xb9bbdd34304344dcc45803780a34c97d73a00133a5ecf70f63e1008b8abb2fca", "asset_id": "72012724360700510767037780555710363830014634797787940282136454146828040926557", "price": "0.149", "size": "558", "side": "SELL", "timestamp": "1768573211405", "received_at": "2026-01-16T14:20:11.472627"}}
{"event_type": "price_change", "event_ts": "2026-01-16T14:20:11.472639", "ingestion_ts": "2026-01-16T14:20:56.869125", "market_id": "0x2393ed0b0fdc450054c7b9071907eca75cf4fc36e385adf4a0a5f99ee62243e8", "raw": {"market": "0x2393ed0b0fdc450054c7b9071907eca75cf4fc36e385adf4a0a5f99ee62243e8", "asset_id": "32769749367306925959219403371425714180265458150646381231272229429098460625924", "price": "0.85", "size": "0", "side": "BUY", "timestamp": "1768573211405", "received_at": "2026-01-16T14:20:11.472639"}}
{"event_type": "price_change", "event_ts": "2026-01-16T14:20:11.472639", "ingestion_ts": "2026-01-16T14:20:56.869125", "market_id": "0x2393ed0b0fdc450054c7b9071907eca75cf4fc36e385adf4a0a5f99ee62243e8", "raw": {"market": "0x2393ed0b0fdc450054c7b9071907eca75cf4fc36e385adf4a0a5f99ee62243e8", "asset_id": "100074770378634056601572485653252702850363676459996771990439989989293515601975", "price": "0.15", "size": "0", "side": "SELL", "timestamp": "1768573211405", "received_at": "2026-01-16T14:20:11.472639"}}
{"event_type": "price_change", "event_ts": "2026-01-16T14:20:11.484202", "ingestion_ts": "2026-01-16T14:20:56.869125", "market_id": "0x2393ed0b0fdc450054c7b9071907eca75cf4fc36e385adf4a0a5f99ee62243e8", "raw": {"market": "0x2393ed0b0fdc450054c7b9071907eca75cf4fc36e385adf4a0a5f99ee62243e8", "asset_id": "32769749367306925959219403371425714180265458150646381231272229429098460625924", "price": "0.849", "size": "304", "side": "BUY", "timestamp": "1768573211437", "received_at": "2026-01-16T14:20:11.484202"}}
{"event_type": "price_change", "event_ts": "2026-01-16T14:20:11.484202", "ingestion_ts": "2026-01-16T14:20:56.869125", "market_id": "0x2393ed0b0fdc450054c7b9071907eca75cf4fc36e385adf4a0a5f99ee62243e8", "raw": {"market": "0x2393ed0b0fdc450054c7b9071907eca75cf4fc36e385adf4a0a5f99ee62243e8", "asset_id": "100074770378634056601572485653252702850363676459996771990439989989293515601975", "price": "0.151", "size": "304", "side": "SELL", "timestamp": "1768573211437", "received_at": "2026-01-16T14:20:11.484202"}}
{"event_type": "price_change", "event_ts": "2026-01-16T14:20:11.484239", "ingestion_ts": "2026-01-16T14:20:56.869125", "market_id": "0x9472be65457510b7fc3477b20ba90910e99d92eac8421a14bf4b7b7a08ef31dc", "raw": {"market": "0x9472be65457510b7fc3477b20ba90910e99d92eac8421a14bf4b7b7a08ef31dc", "asset_id": "43311793366960417907757893276427136943959788721376762326430771171648759300146", "price": "0.858", "size": "243", "side": "BUY", "timestamp": "1768573211437", "received_at": "2026-01-16T14:20:11.484239"}}
{"event_type": "price_change", "event_ts": "2026-01-16T14:20:11.484239", "ingestion_ts": "2026-01-16T14:20:56.869125", "market_id": "0x9472be65457510b7fc3477b20ba90910e99d92eac8421a14bf4b7b7a08ef31dc", "raw": {"market": "0x9472be65457510b7fc3477b20ba90910e99d92eac8421a14bf4b7b7a08ef31dc", "asset_id": "73414222381656326204771753454630063673548497164758947581648273905027617570612", "price": "0.142", "size": "243", "side": "SELL", "timestamp": "1768573211437", "received_at": "2026-01-16T14:20:11.484239"}}
{"event_type": "price_change", "event_ts": "2026-01-16T14:20:11.484261", "ingestion_ts": "2026-01-16T14:20:56.869125", "market_id": "0xb9bbdd34304344dcc45803780a34c97d73a00133a5ecf70f63e1008b8abb2fca", "raw": {"market": "0xb9bbdd34304344dcc45803780a34c97d73a00133a5ecf70f63e1008b8abb2fca", "asset_id": "8682484153073832526711485265636767086525069344085206423986003504588877767339", "price": "0.839", "size": "10", "side": "BUY", "timestamp": "1768573211437", "received_at": "2026-01-16T14:20:11.484261"}}
{"event_type": "price_change", "event_ts": "2026-01-16T14:20:11.484261", "ingestion_ts": "2026-01-16T14:20:56.869125", "market_id": "0xb9bbdd34304344dcc45803780a34c97d73a00133a5ecf70f63e1008b8abb2fca", "raw": {"market": "0xb9bbdd34304344dcc45803780a34c97d73a00133a5ecf70f63e1008b8abb2fca", "asset_id": "72012724360700510767037780555710363830014634797787940282136454146828040926557", "price": "0.161", "size": "10", "side": "SELL", "timestamp": "1768573211437", "received_at": "2026-01-16T14:20:11.484261"}}
{"event_type": "price_change", "event_ts": "2026-01-16T14:20:11.484272", "ingestion_ts": "2026-01-16T14:20:56.869125", "market_id": "0xc55db914f0fd1fee18997706712c0dfd8d0369cdbef93a9fef12bd001914ca77", "raw": {"market": "0xc55db914f0fd1fee18997706712c0dfd8d0369cdbef93a9fef12bd001914ca77", "asset_id": "114600293444080540179603459515770723592661967180480327891296353898330242622833", "price": "0.859", "size": "40", "side": "BUY", "timestamp": "1768573211437", "received_at": "2026-01-16T14:20:11.484272"}}
{"event_type": "price_change", "event_ts": "2026-01-16T14:20:11.484272", "ingestion_ts": "2026-01-16T14:20:56.869125", "market_id": "0xc55db914f0fd1fee18997706712c0dfd8d0369cdbef93a9fef12bd001914ca77", "raw": {"market": "0xc55db914f0fd1fee18997706712c0dfd8d0369cdbef93a9fef12bd001914ca77", "asset_id": "72354723612769247426741660426331235762851940382312402276325808095604519806766", "price": "0.141", "size": "40", "side": "SELL", "timestamp": "1768573211437", "received_at": "2026-01-16T14:20:11.484272"}}
{"event_type": "price_change", "event_ts": "2026-01-16T14:20:13.442291", "ingestion_ts": "2026-01-16T14:20:56.869125", "market_id": "0x427bc4b40c09b3dcbc973747f0e4b079bed91b3e5a0aed5c36edd0f7591485f4", "raw": {"market": "0x427bc4b40c09b3dcbc973747f0e4b079bed91b3e5a0aed5c36edd0f7591485f4", "asset_id": "115669573443672055876643967408433138119481486650803218131873713375232186497057", "price": "0.002", "size": "108.51", "side": "BUY", "timestamp": "1768573213404", "received_at": "2026-01-16T14:20:13.442291"}}
{"event_type": "price_change", "event_ts": "2026-01-16T14:20:13.442291", "ingestion_ts": "2026-01-16T14:20:56.869125", "market_id": "0x427bc4b40c09b3dcbc973747f0e4b079bed91b3e5a0aed5c36edd0f7591485f4", "raw": {"market": "0x427bc4b40c09b3dcbc973747f0e4b079bed91b3e5a0aed5c36edd0f7591485f4", "asset_id": "86130975769502911188457673769190265049139877688522439001984850068234616395137", "price": "0.998", "size": "108.51", "side": "SELL", "timestamp": "1768573213404", "received_at": "2026-01-16T14:20:13.442291"}}
{"event_type": "price_change", "event_ts": "2026-01-16T14:20:13.442412", "ingestion_ts": "2026-01-16T14:20:56.869125", "market_id": "0x427bc4b40c09b3dcbc973747f0e4b079bed91b3e5a0aed5c36edd0f7591485f4", "raw": {"market": "0x427bc4b40c09b3dcbc973747f0e4b079bed91b3e5a0aed5c36edd0f7591485f4", "asset_id": "115669573443672055876643967408433138119481486650803218131873713375232186497057", "price": "0.008", "size": "5.06", "side": "BUY", "timestamp": "1768573213404", "received_at": "2026-01-16T14:20:13.442412"}}
{"event_type": "price_change", "event_ts": "2026-01-16T14:20:13.442412", "ingestion_ts": "2026-01-16T14:20:56.869125", "market_id": "0x427bc4b40c09b3dcbc973747f0e4b079bed91b3e5a0aed5c36edd0f7591485f4", "raw": {"market": "0x427bc4b40c09b3dcbc973747f0e4b079bed91b3e5a0aed5c36edd0f7591485f4", "asset_id": "86130975769502911188457673769190265049139877688522439001984850068234616395137", "price": "0.992", "size": "5.06", "side": "SELL", "timestamp": "1768573213404", "received_at": "2026-01-16T14:20:13.442412"}}
{"event_type": "price_change", "event_ts": "2026-01-16T14:20:13.918950", "ingestion_ts": "2026-01-16T14:20:56.869125", "market_id": "0x427bc4b40c09b3dcbc973747f0e4b079bed91b3e5a0aed5c36edd0f7591485f4", "raw": {"market": "0x427bc4b40c09b3dcbc973747f0e4b079bed91b3e5a0aed5c36edd0f7591485f4", "asset_id": "115669573443672055876643967408433138119481486650803218131873713375232186497057", "price": "0.006", "size": "31.18", "side": "BUY", "timestamp": "1768573213880", "received_at": "2026-01-16T14:20:13.918950"}}
{"event_type": "price_change", "event_ts": "2026-01-16T14:20:13.918950", "ingestion_ts": "2026-01-16T14:20:56.869125", "market_id": "0x427bc4b40c09b3dcbc973747f0e4b079bed91b3e5a0aed5c36edd0f7591485f4", "raw": {"market": "0x427bc4b40c09b3dcbc973747f0e4b079bed91b3e5a0aed5c36edd0f7591485f4", "asset_id": "86130975769502911188457673769190265049139877688522439001984850068234616395137", "price": "0.994", "size": "31.18", "side": "SELL", "timestamp": "1768573213880", "received_at": "2026-01-16T14:20:13.918950"}}
{"event_type": "price_change", "event_ts": "2026-01-16T14:20:14.350352", "ingestion_ts": "2026-01-16T14:20:56.869125", "market_id": "0x427bc4b40c09b3dcbc973747f0e4b079bed91b3e5a0aed5c36edd0f7591485f4", "raw": {"market": "0x427bc4b40c09b3dcbc973747f0e4b079bed91b3e5a0aed5c36edd0f7591485f4", "asset_id": "115669573443672055876643967408433138119481486650803218131873713375232186497057", "price": "0.179", "size": "0", "side": "SELL", "timestamp": "1768573214310", "received_at": "2026-01-16T14:20:14.350352"}}
{"event_type": "price_change", "event_ts": "2026-01-16T14:20:14.350352", "ingestion_ts": "2026-01-16T14:20:56.869125", "market_id": "0x427bc4b40c09b3dcbc973747f0e4b079bed91b3e5a0aed5c36edd0f7591485f4", "raw": {"market": "0x427bc4b40c09b3dcbc973747f0e4b079bed91b3e5a0aed5c36edd0f7591485f4", "asset_id": "86130975769502911188457673769190265049139877688522439001984850068234616395137", "price": "0.821", "size": "0", "side": "BUY", "timestamp": "1768573214310", "received_at": "2026-01-16T14:20:14.350352"}}
{"event_type": "price_change", "event_ts": "2026-01-16T14:20:14.704454", "ingestion_ts": "2026-01-16T14:20:56.869125", "market_id": "0x427bc4b40c09b3dcbc973747f0e4b079bed91b3e5a0aed5c36edd0f7591485f4", "raw": {"market": "0x427bc4b40c09b3dcbc973747f0e4b079bed91b3e5a0aed5c36edd0f7591485f4", "asset_id": "115669573443672055876643967408433138119481486650803218131873713375232186497057", "price": "0.178", "size": "14.1", "side": "SELL", "timestamp": "1768573214660", "received_at": "2026-01-16T14:20:14.704454"}}
{"event_type": "price_change", "event_ts": "2026-01-16T14:20:14.704454", "ingestion_ts": "2026-01-16T14:20:56.869125", "market_id": "0x427bc4b40c09b3dcbc973747f0e4b079bed91b3e5a0aed5c36edd0f7591485f4", "raw": {"market": "0x427bc4b40c09b3dcbc973747f0e4b079bed91b3e5a0aed5c36edd0f7591485f4", "asset_id": "86130975769502911188457673769190265049139877688522439001984850068234616395137", "price": "0.822", "size": "14.1", "side": "BUY", "timestamp": "1768573214660", "received_at": "2026-01-16T14:20:14.704454"}}
{"event_type": "price_change", "event_ts": "2026-01-16T14:20:14.704753", "ingestion_ts": "2026-01-16T14:20:56.869125", "market_id": "0x427bc4b40c09b3dcbc973747f0e4b079bed91b3e5a0aed5c36edd0f7591485f4", "raw": {"market": "0x427bc4b40c09b3dcbc973747f0e4b079bed91b3e5a0aed5c36edd0f7591485f4", "asset_id": "115669573443672055876643967408433138119481486650803218131873713375232186497057", "price": "0.178", "size": "28.2", "side": "SELL", "timestamp": "1768573214662", "received_at": "2026-01-16T14:20:14.704753"}}
{"event_type": "price_change", "event_ts": "2026-01-16T14:20:14.704753", "ingestion_ts": "2026-01-16T14:20:56.869125", "market_id": "0x427bc4b40c09b3dcbc973747f0e4b079bed91b3e5a0aed5c36edd0f7591485f4", "raw": {"market": "0x427bc4b40c09b3dcbc973747f0e4b079bed91b3e5a0aed5c36edd0f7591485f4", "asset_id": "86130975769502911188457673769190265049139877688522439001984850068234616395137", "price": "0.822", "size": "28.2", "side": "BUY", "timestamp": "1768573214662", "received_at": "2026-01-16T14:20:14.704753"}}
{"event_type": "price_change", "event_ts": "2026-01-16T14:20:14.725478", "ingestion_ts": "2026-01-16T14:20:56.869125", "market_id": "0x2393ed0b0fdc450054c7b9071907eca75cf4fc36e385adf4a0a5f99ee62243e8", "raw": {"market": "0x2393ed0b0fdc450054c7b9071907eca75cf4fc36e385adf4a0a5f99ee62243e8", "asset_id": "32769749367306925959219403371425714180265458150646381231272229429098460625924", "price": "0.946", "size": "50", "side": "BUY", "timestamp": "1768573214677", "received_at": "2026-01-16T14:20:14.725478"}}
{"event_type": "price_change", "event_ts": "2026-01-16T14:20:14.725478", "ingestion_ts": "2026-01-16T14:20:56.869125", "market_id": "0x2393ed0b0fdc450054c7b9071907eca75cf4fc36e385adf4a0a5f99ee62243e8", "raw": {"market": "0x2393ed0b0fdc450054c7b9071907eca75cf4fc36e385adf4a0a5f99ee62243e8", "asset_id": "100074770378634056601572485653252702850363676459996771990439989989293515601975", "price": "0.054", "size": "50", "side": "SELL", "timestamp": "1768573214677", "received_at": "2026-01-16T14:20:14.725478"}}
{"event_type": "price_change", "event_ts": "2026-01-16T14:20:14.745637", "ingestion_ts": "2026-01-16T14:20:56.869125", "market_id": "0x2393ed0b0fdc450054c7b9071907eca75cf4fc36e385adf4a0a5f99ee62243e8", "raw": {"market": "0x2393ed0b0fdc450054c7b9071907eca75cf4fc36e385adf4a0a5f99ee62243e8", "asset_id": "100074770378634056601572485653252702850363676459996771990439989989293515601975", "price": "0.055", "size": "0", "side": "SELL", "timestamp": "1768573214708", "received_at": "2026-01-16T14:20:14.745637"}}
{"event_type": "price_change", "event_ts": "2026-01-16T14:20:14.745637", "ingestion_ts": "2026-01-16T14:20:56.869125", "market_id": "0x2393ed0b0fdc450054c7b9071907eca75cf4fc36e385adf4a0a5f99ee62243e8", "raw": {"market": "0x2393ed0b0fdc450054c7b9071907eca75cf4fc36e385adf4a0a5f99ee62243e8", "asset_id": "32769749367306925959219403371425714180265458150646381231272229429098460625924", "price": "0.945", "size": "0", "side": "BUY", "timestamp": "1768573214708", "received_at": "2026-01-16T14:20:14.745637"}}
{"event_type": "price_change", "event_ts": "2026-01-16T14:20:14.773783", "ingestion_ts": "2026-01-16T14:20:56.869125", "market_id": "0x2393ed0b0fdc450054c7b9071907eca75cf4fc36e385adf4a0a5f99ee62243e8", "raw": {"market": "0x2393ed0b0fdc450054c7b9071907eca75cf4fc36e385adf4a0a5f99ee62243e8", "asset_id": "100074770378634056601572485653252702850363676459996771990439989989293515601975", "price": "0.053", "size": "197", "side": "SELL", "timestamp": "1768573214736", "received_at": "2026-01-16T14:20:14.773783"}}
{"event_type": "price_change", "event_ts": "2026-01-16T14:20:14.773783", "ingestion_ts": "2026-01-16T14:20:56.869125", "market_id": "0x2393ed0b0fdc450054c7b9071907eca75cf4fc36e385adf4a0a5f99ee62243e8", "raw": {"market": "0x2393ed0b0fdc450054c7b9071907eca75cf4fc36e385adf4a0a5f99ee62243e8", "asset_id": "32769749367306925959219403371425714180265458150646381231272229429098460625924", "price": "0.947", "size": "197", "side": "BUY", "timestamp": "1768573214736", "received_at": "2026-01-16T14:20:14.773783"}}
{"event_type": "price_change", "event_ts": "2026-01-16T14:20:15.098634", "ingestion_ts": "2026-01-16T14:20:56.869125", "market_id": "0x2393ed0b0fdc450054c7b9071907eca75cf4fc36e385adf4a0a5f99ee62243e8", "raw": {"market": "0x2393ed0b0fdc450054c7b9071907eca75cf4fc36e385adf4a0a5f99ee62243e8", "asset_id": "32769749367306925959219403371425714180265458150646381231272229429098460625924", "price": "0.944", "size": "0", "side": "BUY", "timestamp": "1768573215038", "received_at": "2026-01-16T14:20:15.098634"}}
{"event_type": "price_change", "event_ts": "2026-01-16T14:20:15.098634", "ingestion_ts": "2026-01-16T14:20:56.869125", "market_id": "0x2393ed0b0fdc450054c7b9071907eca75cf4fc36e385adf4a0a5f99ee62243e8", "raw": {"market": "0x2393ed0b0fdc450054c7b9071907eca75cf4fc36e385adf4a0a5f99ee62243e8", "asset_id": "100074770378634056601572485653252702850363676459996771990439989989293515601975", "price": "0.056", "size": "0", "side": "SELL", "timestamp": "1768573215038", "received_at": "2026-01-16T14:20:15.098634"}}
{"event_type": "price_change", "event_ts": "2026-01-16T14:20:16.391754", "ingestion_ts": "2026-01-16T14:20:56.869125", "market_id": "0x49686d26fb712515cd5e12c23f0a1c7e10214c7faa3cb0a730aabe0c33694082", "raw": {"market": "0x49686d26fb712515cd5e12c23f0a1c7e10214c7faa3cb0a730aabe0c33694082", "asset_id": "13244681086321087932946246027856416106585284024824496763706748621681543444582", "price": "0.853", "size": "50.86", "side": "BUY", "timestamp": "1768573216344", "received_at": "2026-01-16T14:20:16.391754"}}
{"event_type": "price_change", "event_ts": "2026-01-16T14:20:16.391754", "ingestion_ts": "2026-01-16T14:20:56.869125", "market_id": "0x49686d26fb712515cd5e12c23f0a1c7e10214c7faa3cb0a730aabe0c33694082", "raw": {"market": "0x49686d26fb712515cd5e12c23f0a1c7e10214c7faa3cb0a730aabe0c33694082", "asset_id": "30442780799048074404860985387051749017905070253466005720364298335239299761065", "price": "0.147", "size": "50.86", "side": "SELL", "timestamp": "1768573216344", "received_at": "2026-01-16T14:20:16.391754"}}
{"event_type": "price_change", "event_ts": "2026-01-16T14:20:16.595453", "ingestion_ts": "2026-01-16T14:20:56.869125", "market_id": "0x427bc4b40c09b3dcbc973747f0e4b079bed91b3e5a0aed5c36edd0f7591485f4", "raw": {"market": "0x427bc4b40c09b3dcbc973747f0e4b079bed91b3e5a0aed5c36edd0f7591485f4", "asset_id": "115669573443672055876643967408433138119481486650803218131873713375232186497057", "price": "0.002", "size": "99.32", "side": "BUY", "timestamp": "1768573216549", "received_at": "2026-01-16T14:20:16.595453"}}
{"event_type": "price_change", "event_ts": "2026-01-16T14:20:16.595453", "ingestion_ts": "2026-01-16T14:20:56.869125", "market_id": "0x427bc4b40c09b3dcbc973747f0e4b079bed91b3e5a0aed5c36edd0f7591485f4", "raw": {"market": "0x427bc4b40c09b3dcbc973747f0e4b079bed91b3e5a0aed5c36edd0f7591485f4", "asset_id": "86130975769502911188457673769190265049139877688522439001984850068234616395137", "price": "0.998", "size": "99.32", "side": "SELL", "timestamp": "1768573216549", "received_at": "2026-01-16T14:20:16.595453"}}
{"event_type": "price_change", "event_ts": "2026-01-16T14:20:16.595469", "ingestion_ts": "2026-01-16T14:20:56.869125", "market_id": "0x427bc4b40c09b3dcbc973747f0e4b079bed91b3e5a0aed5c36edd0f7591485f4", "raw": {"market": "0x427bc4b40c09b3dcbc973747f0e4b079bed91b3e5a0aed5c36edd0f7591485f4", "asset_id": "115669573443672055876643967408433138119481486650803218131873713375232186497057", "price": "0.008", "size": "0", "side": "BUY", "timestamp": "1768573216549", "received_at": "2026-01-16T14:20:16.595469"}}
{"event_type": "price_change", "event_ts": "2026-01-16T14:20:16.595469", "ingestion_ts": "2026-01-16T14:20:56.869125", "market_id": "0x427bc4b40c09b3dcbc973747f0e4b079bed91b3e5a0aed5c36edd0f7591485f4", "raw": {"market": "0x427bc4b40c09b3dcbc973747f0e4b079bed91b3e5a0aed5c36edd0f7591485f4", "asset_id": "86130975769502911188457673769190265049139877688522439001984850068234616395137", "price": "0.992", "size": "0", "side": "SELL", "timestamp": "1768573216549", "received_at": "2026-01-16T14:20:16.595469"}}
{"event_type": "price_change", "event_ts": "2026-01-16T14:20:16.632627", "ingestion_ts": "2026-01-16T14:20:56.869125", "market_id": "0x427bc4b40c09b3dcbc973747f0e4b079bed91b3e5a0aed5c36edd0f7591485f4", "raw": {"market": "0x427bc4b40c09b3dcbc973747f0e4b079bed91b3e5a0aed5c36edd0f7591485f4", "asset_id": "86130975769502911188457673769190265049139877688522439001984850068234616395137", "price": "0.823", "size": "49", "side": "BUY", "timestamp": "1768573216594", "received_at": "2026-01-16T14:20:16.632627"}}
{"event_type": "price_change", "event_ts": "2026-01-16T14:20:16.632627", "ingestion_ts": "2026-01-16T14:20:56.869125", "market_id": "0x427bc4b40c09b3dcbc973747f0e4b079bed91b3e5a0aed5c36edd0f7591485f4", "raw": {"market": "0x427bc4b40c09b3dcbc973747f0e4b079bed91b3e5a0aed5c36edd0f7591485f4", "asset_id": "115669573443672055876643967408433138119481486650803218131873713375232186497057", "price": "0.177", "size": "49", "side": "SELL", "timestamp": "1768573216594", "received_at": "2026-01-16T14:20:16.632627"}}
{"event_type": "price_change", "event_ts": "2026-01-16T14:20:16.967727", "ingestion_ts": "2026-01-16T14:20:56.869125", "market_id": "0x427bc4b40c09b3dcbc973747f0e4b079bed91b3e5a0aed5c36edd0f7591485f4", "raw": {"market": "0x427bc4b40c09b3dcbc973747f0e4b079bed91b3e5a0aed5c36edd0f7591485f4", "asset_id": "115669573443672055876643967408433138119481486650803218131873713375232186497057", "price": "0.006", "size": "40.99", "side": "BUY", "timestamp": "1768573216929", "received_at": "2026-01-16T14:20:16.967727"}}
{"event_type": "price_change", "event_ts": "2026-01-16T14:20:16.967727", "ingestion_ts": "2026-01-16T14:20:56.869125", "market_id": "0x427bc4b40c09b3dcbc973747f0e4b079bed91b3e5a0aed5c36edd0f7591485f4", "raw": {"market": "0x427bc4b40c09b3dcbc973747f0e4b079bed91b3e5a0aed5c36edd0f7591485f4", "asset_id": "86130975769502911188457673769190265049139877688522439001984850068234616395137", "price": "0.994", "size": "40.99", "side": "SELL", "timestamp": "1768573216929", "received_at": "2026-01-16T14:20:16.967727"}}
{"event_type": "price_change", "event_ts": "2026-01-16T14:20:17.460988", "ingestion_ts": "2026-01-16T14:20:56.869125", "market_id": "0x427bc4b40c09b3dcbc973747f0e4b079bed91b3e5a0aed5c36edd0f7591485f4", "raw": {"market": "0x427bc4b40c09b3dcbc973747f0e4b079bed91b3e5a0aed5c36edd0f7591485f4", "asset_id": "115669573443672055876643967408433138119481486650803218131873713375232186497057", "price": "0.178", "size": "14.1", "side": "SELL", "timestamp": "1768573217418", "received_at": "2026-01-16T14:20:17.460988"}}
{"event_type": "price_change", "event_ts": "2026-01-16T14:20:17.460988", "ingestion_ts": "2026-01-16T14:20:56.869125", "market_id": "0x427bc4b40c09b3dcbc973747f0e4b079bed91b3e5a0aed5c36edd0f7591485f4", "raw": {"market": "0x427bc4b40c09b3dcbc973747f0e4b079bed91b3e5a0aed5c36edd0f7591485f4", "asset_id": "86130975769502911188457673769190265049139877688522439001984850068234616395137", "price": "0.822", "size": "14.1", "side": "BUY", "timestamp": "1768573217418", "received_at": "2026-01-16T14:20:17.460988"}}
{"event_type": "price_change", "event_ts": "2026-01-16T14:20:17.461028", "ingestion_ts": "2026-01-16T14:20:56.869125", "market_id": "0x427bc4b40c09b3dcbc973747f0e4b079bed91b3e5a0aed5c36edd0f7591485f4", "raw": {"market": "0x427bc4b40c09b3dcbc973747f0e4b079bed91b3e5a0aed5c36edd0f7591485f4", "asset_id": "115669573443672055876643967408433138119481486650803218131873713375232186497057", "price": "0.47", "size": "37.39", "side": "SELL", "timestamp": "1768573217418", "received_at": "2026-01-16T14:20:17.461028"}}
{"event_type": "price_change", "event_ts": "2026-01-16T14:20:17.461028", "ingestion_ts": "2026-01-16T14:20:56.869125", "market_id": "0x427bc4b40c09b3dcbc973747f0e4b079bed91b3e5a0aed5c36edd0f7591485f4", "raw": {"market": "0x427bc4b40c09b3dcbc973747f0e4b079bed91b3e5a0aed5c36edd0f7591485f4", "asset_id": "86130975769502911188457673769190265049139877688522439001984850068234616395137", "price": "0.53", "size": "37.39", "side": "BUY", "timestamp": "1768573217418", "received_at": "2026-01-16T14:20:17.461028"}}
{"event_type": "price_change", "event_ts": "2026-01-16T14:20:17.830704", "ingestion_ts": "2026-01-16T14:20:56.869125", "market_id": "0x427bc4b40c09b3dcbc973747f0e4b079bed91b3e5a0aed5c36edd0f7591485f4", "raw": {"market": "0x427bc4b40c09b3dcbc973747f0e4b079bed91b3e5a0aed5c36edd0f7591485f4", "asset_id": "115669573443672055876643967408433138119481486650803218131873713375232186497057", "price": "0.176", "size": "27.18", "side": "SELL", "timestamp": "1768573217787", "received_at": "2026-01-16T14:20:17.830704"}}
{"event_type": "price_change", "event_ts": "2026-01-16T14:20:17.830704", "ingestion_ts": "2026-01-16T14:20:56.869125", "market_id": "0x427bc4b40c09b3dcbc973747f0e4b079bed91b3e5a0aed5c36edd0f7591485f4", "raw": {"market": "0x427bc4b40c09b3dcbc973747f0e4b079bed91b3e5a0aed5c36edd0f7591485f4", "asset_id": "86130975769502911188457673769190265049139877688522439001984850068234616395137", "price": "0.824", "size": "27.18", "side": "BUY", "timestamp": "1768573217787", "received_at": "2026-01-16T14:20:17.830704"}}
{"event_type": "price_change", "event_ts": "2026-01-16T14:20:17.830805", "ingestion_ts": "2026-01-16T14:20:56.869125", "market_id": "0x427bc4b40c09b3dcbc973747f0e4b079bed91b3e5a0aed5c36edd0f7591485f4", "raw": {"market": "0x427bc4b40c09b3dcbc973747f0e4b079bed91b3e5a0aed5c36edd0f7591485f4", "asset_id": "115669573443672055876643967408433138119481486650803218131873713375232186497057", "price": "0.176", "size": "54.36", "side": "SELL", "timestamp": "1768573217788", "received_at": "2026-01-16T14:20:17.830805"}}
{"event_type": "price_change", "event_ts": "2026-01-16T14:20:17.830805", "ingestion_ts": "2026-01-16T14:20:56.869125", "market_id": "0x427bc4b40c09b3dcbc973747f0e4b079bed91b3e5a0aed5c36edd0f7591485f4", "raw": {"market": "0x427bc4b40c09b3dcbc973747f0e4b079bed91b3e5a0aed5c36edd0f7591485f4", "asset_id": "86130975769502911188457673769190265049139877688522439001984850068234616395137", "price": "0.824", "size": "54.36", "side": "BUY", "timestamp": "1768573217788", "received_at": "2026-01-16T14:20:17.830805"}}
{"event_type": "price_change", "event_ts": "2026-01-16T14:20:17.857812", "ingestion_ts": "2026-01-16T14:20:56.869125", "market_id": "0x427bc4b40c09b3dcbc973747f0e4b079bed91b3e5a0aed5c36edd0f7591485f4", "raw": {"market": "0x427bc4b40c09b3dcbc973747f0e4b079bed91b3e5a0aed5c36edd0f7591485f4", "asset_id": "86130975769502911188457673769190265049139877688522439001984850068234616395137", "price": "0.823", "size": "0", "side": "BUY", "timestamp": "1768573217817", "received_at": "2026-01-16T14:20:17.857812"}}
{"event_type": "price_change", "event_ts": "2026-01-16T14:20:17.857812", "ingestion_ts": "2026-01-16T14:20:56.869125", "market_id": "0x427bc4b40c09b3dcbc973747f0e4b079bed91b3e5a0aed5c36edd0f7591485f4", "raw": {"market": "0x427bc4b40c09b3dcbc973747f0e4b079bed91b3e5a0aed5c36edd0f7591485f4", "asset_id": "115669573443672055876643967408433138119481486650803218131873713375232186497057", "price": "0.177", "size": "0", "side": "SELL", "timestamp": "1768573217817", "received_at": "2026-01-16T14:20:17.857812"}}
{"event_type": "price_change", "event_ts": "2026-01-16T14:20:17.881154", "ingestion_ts": "2026-01-16T14:20:56.869125", "market_id": "0x427bc4b40c09b3dcbc973747f0e4b079bed91b3e5a0aed5c36edd0f7591485f4", "raw": {"market": "0x427bc4b40c09b3dcbc973747f0e4b079bed91b3e5a0aed5c36edd0f7591485f4", "asset_id": "86130975769502911188457673769190265049139877688522439001984850068234616395137", "price": "0.825", "size": "36", "side": "BUY", "timestamp": "1768573217844", "received_at": "2026-01-16T14:20:17.881154"}}
{"event_type": "price_change", "event_ts": "2026-01-16T14:20:17.881154", "ingestion_ts": "2026-01-16T14:20:56.869125", "market_id": "0x427bc4b40c09b3dcbc973747f0e4b079bed91b3e5a0aed5c36edd0f7591485f4", "raw": {"market": "0x427bc4b40c09b3dcbc973747f0e4b079bed91b3e5a0aed5c36edd0f7591485f4", "asset_id": "115669573443672055876643967408433138119481486650803218131873713375232186497057", "price": "0.175", "size": "36", "side": "SELL", "timestamp": "1768573217844", "received_at": "2026-01-16T14:20:17.881154"}}
{"event_type": "price_change", "event_ts": "2026-01-16T14:20:17.970749", "ingestion_ts": "2026-01-16T14:20:56.869125", "market_id": "0x49686d26fb712515cd5e12c23f0a1c7e10214c7faa3cb0a730aabe0c33694082", "raw": {"market": "0x49686d26fb712515cd5e12c23f0a1c7e10214c7faa3cb0a730aabe0c33694082", "asset_id": "30442780799048074404860985387051749017905070253466005720364298335239299761065", "price": "0.148", "size": "0", "side": "SELL", "timestamp": "1768573217933", "received_at": "2026-01-16T14:20:17.970749"}}
{"event_type": "price_change", "event_ts": "2026-01-16T14:20:17.970749", "ingestion_ts": "2026-01-16T14:20:56.869125", "market_id": "0x49686d26fb712515cd5e12c23f0a1c7e10214c7faa3cb0a730aabe0c33694082", "raw": {"market": "0x49686d26fb712515cd5e12c23f0a1c7e10214c7faa3cb0a730aabe0c33694082", "asset_id": "13244681086321087932946246027856416106585284024824496763706748621681543444582", "price": "0.852", "size": "0", "side": "BUY", "timestamp": "1768573217933", "received_at": "2026-01-16T14:20:17.970749"}}
{"event_type": "price_change", "event_ts": "2026-01-16T14:20:18.034679", "ingestion_ts": "2026-01-16T14:20:56.869125", "market_id": "0x49686d26fb712515cd5e12c23f0a1c7e10214c7faa3cb0a730aabe0c33694082", "raw": {"market": "0x49686d26fb712515cd5e12c23f0a1c7e10214c7faa3cb0a730aabe0c33694082", "asset_id": "30442780799048074404860985387051749017905070253466005720364298335239299761065", "price": "0.146", "size": "17.5", "side": "SELL", "timestamp": "1768573217986", "received_at": "2026-01-16T14:20:18.034679"}}
{"event_type": "price_change", "event_ts": "2026-01-16T14:20:18.034679", "ingestion_ts": "2026-01-16T14:20:56.869125", "market_id": "0x49686d26fb712515cd5e12c23f0a1c7e10214c7faa3cb0a730aabe0c33694082", "raw": {"market": "0x49686d26fb712515cd5e12c23f0a1c7e10214c7faa3cb0a730aabe0c33694082", "asset_id": "13244681086321087932946246027856416106585284024824496763706748621681543444582", "price": "0.854", "size": "17.5", "side": "BUY", "timestamp": "1768573217986", "received_at": "2026-01-16T14:20:18.034679"}}
{"event_type": "price_change", "event_ts": "2026-01-16T14:20:18.057647", "ingestion_ts": "2026-01-16T14:20:56.869125", "market_id": "0x49686d26fb712515cd5e12c23f0a1c7e10214c7faa3cb0a730aabe0c33694082", "raw": {"market": "0x49686d26fb712515cd5e12c23f0a1c7e10214c7faa3cb0a730aabe0c33694082", "asset_id": "13244681086321087932946246027856416106585284024824496763706748621681543444582", "price": "0.911", "size": "14.98", "side": "SELL", "timestamp": "1768573218013", "received_at": "2026-01-16T14:20:18.057647"}}
{"event_type": "price_change", "event_ts": "2026-01-16T14:20:18.057647", "ingestion_ts": "2026-01-16T14:20:56.869125", "market_id": "0x49686d26fb712515cd5e12c23f0a1c7e10214c7faa3cb0a730aabe0c33694082", "raw": {"market": "0x49686d26fb712515cd5e12c23f0a1c7e10214c7faa3cb0a730aabe0c33694082", "asset_id": "30442780799048074404860985387051749017905070253466005720364298335239299761065", "price": "0.089", "size": "14.98", "side": "BUY", "timestamp": "1768573218013", "received_at": "2026-01-16T14:20:18.057647"}}
{"event_type": "price_change", "event_ts": "2026-01-16T14:20:18.276897", "ingestion_ts": "2026-01-16T14:20:56.869125", "market_id": "0xc55db914f0fd1fee18997706712c0dfd8d0369cdbef93a9fef12bd001914ca77", "raw": {"market": "0xc55db914f0fd1fee18997706712c0dfd8d0369cdbef93a9fef12bd001914ca77", "asset_id": "114600293444080540179603459515770723592661967180480327891296353898330242622833", "price": "0.859", "size": "30", "side": "BUY", "timestamp": "1768573218237", "received_at": "2026-01-16T14:20:18.276897"}}
{"event_type": "price_change", "event_ts": "2026-01-16T14:20:18.276897", "ingestion_ts": "2026-01-16T14:20:56.869125", "market_id": "0xc55db914f0fd1fee18997706712c0dfd8d0369cdbef93a9fef12bd001914ca77", "raw": {"market": "0xc55db914f0fd1fee18997706712c0dfd8d0369cdbef93a9fef12bd001914ca77", "asset_id": "72354723612769247426741660426331235762851940382312402276325808095604519806766", "price": "0.141", "size": "30", "side": "SELL", "timestamp": "1768573218237", "received_at": "2026-01-16T14:20:18.276897"}}
{"event_type": "price_change", "event_ts": "2026-01-16T14:20:18.276940", "ingestion_ts": "2026-01-16T14:20:56.869125", "market_id": "0x9472be65457510b7fc3477b20ba90910e99d92eac8421a14bf4b7b7a08ef31dc", "raw": {"market": "0x9472be65457510b7fc3477b20ba90910e99d92eac8421a14bf4b7b7a08ef31dc", "asset_id": "43311793366960417907757893276427136943959788721376762326430771171648759300146", "price": "0.858", "size": "233", "side": "BUY", "timestamp": "1768573218237", "received_at": "2026-01-16T14:20:18.276940"}}
{"event_type": "price_change", "event_ts": "2026-01-16T14:20:18.276940", "ingestion_ts": "2026-01-16T14:20:56.869125", "market_id": "0x9472be65457510b7fc3477b20ba90910e99d92eac8421a14bf4b7b7a08ef31dc", "raw": {"market": "0x9472be65457510b7fc3477b20ba90910e99d92eac8421a14bf4b7b7a08ef31dc", "asset_id": "73414222381656326204771753454630063673548497164758947581648273905027617570612", "price": "0.142", "size": "233", "side": "SELL", "timestamp": "1768573218237", "received_at": "2026-01-16T14:20:18.276940"}}
{"event_type": "price_change", "event_ts": "2026-01-16T14:20:18.276965", "ingestion_ts": "2026-01-16T14:20:56.869125", "market_id": "0xb9bbdd34304344dcc45803780a34c97d73a00133a5ecf70f63e1008b8abb2fca", "raw": {"market": "0xb9bbdd34304344dcc45803780a34c97d73a00133a5ecf70f63e1008b8abb2fca", "asset_id": "8682484153073832526711485265636767086525069344085206423986003504588877767339", "price": "0.839", "size": "0", "side": "BUY", "timestamp": "1768573218237", "received_at": "2026-01-16T14:20:18.276965"}}
{"event_type": "price_change", "event_ts": "2026-01-16T14:20:18.276965", "ingestion_ts": "2026-01-16T14:20:56.869125", "market_id": "0xb9bbdd34304344dcc45803780a34c97d73a00133a5ecf70f63e1008b8abb2fca", "raw": {"market": "0xb9bbdd34304344dcc45803780a34c97d73a00133a5ecf70f63e1008b8abb2fca", "asset_id": "72012724360700510767037780555710363830014634797787940282136454146828040926557", "price": "0.161", "size": "0", "side": "SELL", "timestamp": "1768573218237", "received_at": "2026-01-16T14:20:18.276965"}}
{"event_type": "price_change", "event_ts": "2026-01-16T14:20:18.276978", "ingestion_ts": "2026-01-16T14:20:56.869125", "market_id": "0x2393ed0b0fdc450054c7b9071907eca75cf4fc36e385adf4a0a5f99ee62243e8", "raw": {"market": "0x2393ed0b0fdc450054c7b9071907eca75cf4fc36e385adf4a0a5f99ee62243e8", "asset_id": "32769749367306925959219403371425714180265458150646381231272229429098460625924", "price": "0.849", "size": "294", "side": "BUY", "timestamp": "1768573218237", "received_at": "2026-01-16T14:20:18.276978"}}
{"event_type": "price_change", "event_ts": "2026-01-16T14:20:18.276978", "ingestion_ts": "2026-01-16T14:20:56.869125", "market_id": "0x2393ed0b0fdc450054c7b9071907eca75cf4fc36e385adf4a0a5f99ee62243e8", "raw": {"market": "0x2393ed0b0fdc450054c7b9071907eca75cf4fc36e385adf4a0a5f99ee62243e8", "asset_id": "100074770378634056601572485653252702850363676459996771990439989989293515601975", "price": "0.151", "size": "294", "side": "SELL", "timestamp": "1768573218237", "received_at": "2026-01-16T14:20:18.276978"}}
{"event_type": "price_change", "event_ts": "2026-01-16T14:20:18.310050", "ingestion_ts": "2026-01-16T14:20:56.869125", "market_id": "0xb9bbdd34304344dcc45803780a34c97d73a00133a5ecf70f63e1008b8abb2fca", "raw": {"market": "0xb9bbdd34304344dcc45803780a34c97d73a00133a5ecf70f63e1008b8abb2fca", "asset_id": "8682484153073832526711485265636767086525069344085206423986003504588877767339", "price": "0.851", "size": "568", "side": "BUY", "timestamp": "1768573218271", "received_at": "2026-01-16T14:20:18.310050"}}
{"event_type": "price_change", "event_ts": "2026-01-16T14:20:18.310050", "ingestion_ts": "2026-01-16T14:20:56.869125", "market_id": "0xb9bbdd34304344dcc45803780a34c97d73a00133a5ecf70f63e1008b8abb2fca", "raw": {"market": "0xb9bbdd34304344dcc45803780a34c97d73a00133a5ecf70f63e1008b8abb2fca", "asset_id": "72012724360700510767037780555710363830014634797787940282136454146828040926557", "price": "0.149", "size": "568", "side": "SELL", "timestamp": "1768573218271", "received_at": "2026-01-16T14:20:18.310050"}}
{"event_type": "price_change", "event_ts": "2026-01-16T14:20:18.310109", "ingestion_ts": "2026-01-16T14:20:56.869125", "market_id": "0x9472be65457510b7fc3477b20ba90910e99d92eac8421a14bf4b7b7a08ef31dc", "raw": {"market": "0x9472be65457510b7fc3477b20ba90910e99d92eac8421a14bf4b7b7a08ef31dc", "asset_id": "43311793366960417907757893276427136943959788721376762326430771171648759300146", "price": "0.859", "size": "10", "side": "BUY", "timestamp": "1768573218271", "received_at": "2026-01-16T14:20:18.310109"}}
{"event_type": "price_change", "event_ts": "2026-01-16T14:20:18.310109", "ingestion_ts": "2026-01-16T14:20:56.869125", "market_id": "0x9472be65457510b7fc3477b20ba90910e99d92eac8421a14bf4b7b7a08ef31dc", "raw": {"market": "0x9472be65457510b7fc3477b20ba90910e99d92eac8421a14bf4b7b7a08ef31dc", "asset_id": "73414222381656326204771753454630063673548497164758947581648273905027617570612", "price": "0.141", "size": "10", "side": "SELL", "timestamp": "1768573218271", "received_at": "2026-01-16T14:20:18.310109"}}
{"event_type": "price_change", "event_ts": "2026-01-16T14:20:18.310139", "ingestion_ts": "2026-01-16T14:20:56.869125", "market_id": "0x2393ed0b0fdc450054c7b9071907eca75cf4fc36e385adf4a0a5f99ee62243e8", "raw": {"market": "0x2393ed0b0fdc450054c7b9071907eca75cf4fc36e385adf4a0a5f99ee62243e8", "asset_id": "32769749367306925959219403371425714180265458150646381231272229429098460625924", "price": "0.85", "size": "10", "side": "BUY", "timestamp": "1768573218271", "received_at": "2026-01-16T14:20:18.310139"}}
{"event_type": "price_change", "event_ts": "2026-01-16T14:20:18.310139", "ingestion_ts": "2026-01-16T14:20:56.869125", "market_id": "0x2393ed0b0fdc450054c7b9071907eca75cf4fc36e385adf4a0a5f99ee62243e8", "raw": {"market": "0x2393ed0b0fdc450054c7b9071907eca75cf4fc36e385adf4a0a5f99ee62243e8", "asset_id": "100074770378634056601572485653252702850363676459996771990439989989293515601975", "price": "0.15", "size": "10", "side": "SELL", "timestamp": "1768573218271", "received_at": "2026-01-16T14:20:18.310139"}}
{"event_type": "price_change", "event_ts": "2026-01-16T14:20:18.310153", "ingestion_ts": "2026-01-16T14:20:56.869125", "market_id": "0xc55db914f0fd1fee18997706712c0dfd8d0369cdbef93a9fef12bd001914ca77", "raw": {"market": "0xc55db914f0fd1fee18997706712c0dfd8d0369cdbef93a9fef12bd001914ca77", "asset_id": "114600293444080540179603459515770723592661967180480327891296353898330242622833", "price": "0.86", "size": "10", "side": "BUY", "timestamp": "1768573218271", "received_at": "2026-01-16T14:20:18.310153"}}
{"event_type": "price_change", "event_ts": "2026-01-16T14:20:18.310153", "ingestion_ts": "2026-01-16T14:20:56.869125", "market_id": "0xc55db914f0fd1fee18997706712c0dfd8d0369cdbef93a9fef12bd001914ca77", "raw": {"market": "0xc55db914f0fd1fee18997706712c0dfd8d0369cdbef93a9fef12bd001914ca77", "asset_id": "72354723612769247426741660426331235762851940382312402276325808095604519806766", "price": "0.14", "size": "10", "side": "SELL", "timestamp": "1768573218271", "received_at": "2026-01-16T14:20:18.310153"}}
{"event_type": "price_change", "event_ts": "2026-01-16T14:20:19.024278", "ingestion_ts": "2026-01-16T14:20:56.869125", "market_id": "0x49686d26fb712515cd5e12c23f0a1c7e10214c7faa3cb0a730aabe0c33694082", "raw": {"market": "0x49686d26fb712515cd5e12c23f0a1c7e10214c7faa3cb0a730aabe0c33694082", "asset_id": "13244681086321087932946246027856416106585284024824496763706748621681543444582", "price": "0.098", "size": "2448", "side": "BUY", "timestamp": "1768573218987", "received_at": "2026-01-16T14:20:19.024278"}}
{"event_type": "price_change", "event_ts": "2026-01-16T14:20:19.024278", "ingestion_ts": "2026-01-16T14:20:56.869125", "market_id": "0x49686d26fb712515cd5e12c23f0a1c7e10214c7faa3cb0a730aabe0c33694082", "raw": {"market": "0x49686d26fb712515cd5e12c23f0a1c7e10214c7faa3cb0a730aabe0c33694082", "asset_id": "30442780799048074404860985387051749017905070253466005720364298335239299761065", "price": "0.902", "size": "2448", "side": "SELL", "timestamp": "1768573218987", "received_at": "2026-01-16T14:20:19.024278"}}
{"event_type": "price_change", "event_ts": "2026-01-16T14:20:19.037976", "ingestion_ts": "2026-01-16T14:20:56.869125", "market_id": "0x22ac5f75af18fdb453497fbf7ac0606a09a6fd55b78b2d08aace6b946ad62038", "raw": {"market": "0x22ac5f75af18fdb453497fbf7ac0606a09a6fd55b78b2d08aace6b946ad62038", "asset_id": "97449340182256366014320155718265676486703217567849039806162053075113517266910", "price": "0.003", "size": "84.44", "side": "BUY", "timestamp": "1768573219000", "received_at": "2026-01-16T14:20:19.037976"}}
{"event_type": "price_change", "event_ts": "2026-01-16T14:20:19.037976", "ingestion_ts": "2026-01-16T14:20:56.869125", "market_id": "0x22ac5f75af18fdb453497fbf7ac0606a09a6fd55b78b2d08aace6b946ad62038", "raw": {"market": "0x22ac5f75af18fdb453497fbf7ac0606a09a6fd55b78b2d08aace6b946ad62038", "asset_id": "59259495934562596318644973716893809974860301509869285036503555129962149752635", "price": "0.997", "size": "84.44", "side": "SELL", "timestamp": "1768573219000", "received_at": "2026-01-16T14:20:19.037976"}}
{"event_type": "price_change", "event_ts": "2026-01-16T14:20:20.144245", "ingestion_ts": "2026-01-16T14:20:56.869125", "market_id": "0x49686d26fb712515cd5e12c23f0a1c7e10214c7faa3cb0a730aabe0c33694082", "raw": {"market": "0x49686d26fb712515cd5e12c23f0a1c7e10214c7faa3cb0a730aabe0c33694082", "asset_id": "13244681086321087932946246027856416106585284024824496763706748621681543444582", "price": "0.853", "size": "45", "side": "BUY", "timestamp": "1768573220040", "received_at": "2026-01-16T14:20:20.144245"}}
{"event_type": "price_change", "event_ts": "2026-01-16T14:20:20.144245", "ingestion_ts": "2026-01-16T14:20:56.869125", "market_id": "0x49686d26fb712515cd5e12c23f0a1c7e10214c7faa3cb0a730aabe0c33694082", "raw": {"market": "0x49686d26fb712515cd5e12c23f0a1c7e10214c7faa3cb0a730aabe0c33694082", "asset_id": "30442780799048074404860985387051749017905070253466005720364298335239299761065", "price": "0.147", "size": "45", "side": "SELL", "timestamp": "1768573220040", "received_at": "2026-01-16T14:20:20.144245"}}
{"event_type": "price_change", "event_ts": "2026-01-16T14:20:20.157869", "ingestion_ts": "2026-01-16T14:20:56.869125", "market_id": "0x427bc4b40c09b3dcbc973747f0e4b079bed91b3e5a0aed5c36edd0f7591485f4", "raw": {"market": "0x427bc4b40c09b3dcbc973747f0e4b079bed91b3e5a0aed5c36edd0f7591485f4", "asset_id": "115669573443672055876643967408433138119481486650803218131873713375232186497057", "price": "0.006", "size": "31.16", "side": "BUY", "timestamp": "1768573220059", "received_at": "2026-01-16T14:20:20.157869"}}
{"event_type": "price_change", "event_ts": "2026-01-16T14:20:20.157869", "ingestion_ts": "2026-01-16T14:20:56.869125", "market_id": "0x427bc4b40c09b3dcbc973747f0e4b079bed91b3e5a0aed5c36edd0f7591485f4", "raw": {"market": "0x427bc4b40c09b3dcbc973747f0e4b079bed91b3e5a0aed5c36edd0f7591485f4", "asset_id": "86130975769502911188457673769190265049139877688522439001984850068234616395137", "price": "0.994", "size": "31.16", "side": "SELL", "timestamp": "1768573220059", "received_at": "2026-01-16T14:20:20.157869"}}
{"event_type": "price_change", "event_ts": "2026-01-16T14:20:20.192728", "ingestion_ts": "2026-01-16T14:20:56.869125", "market_id": "0x49686d26fb712515cd5e12c23f0a1c7e10214c7faa3cb0a730aabe0c33694082", "raw": {"market": "0x49686d26fb712515cd5e12c23f0a1c7e10214c7faa3cb0a730aabe0c33694082", "asset_id": "13244681086321087932946246027856416106585284024824496763706748621681543444582", "price": "0.854", "size": "23.35", "side": "BUY", "timestamp": "1768573220108", "received_at": "2026-01-16T14:20:20.192728"}}
{"event_type": "price_change", "event_ts": "2026-01-16T14:20:20.192728", "ingestion_ts": "2026-01-16T14:20:56.869125", "market_id": "0x49686d26fb712515cd5e12c23f0a1c7e10214c7faa3cb0a730aabe0c33694082", "raw": {"market": "0x49686d26fb712515cd5e12c23f0a1c7e10214c7faa3cb0a730aabe0c33694082", "asset_id": "30442780799048074404860985387051749017905070253466005720364298335239299761065", "price": "0.146", "size": "23.35", "side": "SELL", "timestamp": "1768573220108", "received_at": "2026-01-16T14:20:20.192728"}}
{"event_type": "price_change", "event_ts": "2026-01-16T14:20:20.525005", "ingestion_ts": "2026-01-16T14:20:56.869125", "market_id": "0x427bc4b40c09b3dcbc973747f0e4b079bed91b3e5a0aed5c36edd0f7591485f4", "raw": {"market": "0x427bc4b40c09b3dcbc973747f0e4b079bed91b3e5a0aed5c36edd0f7591485f4", "asset_id": "115669573443672055876643967408433138119481486650803218131873713375232186497057", "price": "0.002", "size": "114.07", "side": "BUY", "timestamp": "1768573220483", "received_at": "2026-01-16T14:20:20.525005"}}
{"event_type": "price_change", "event_ts": "2026-01-16T14:20:20.525005", "ingestion_ts": "2026-01-16T14:20:56.869125", "market_id": "0x427bc4b40c09b3dcbc973747f0e4b079bed91b3e5a0aed5c36edd0f7591485f4", "raw": {"market": "0x427bc4b40c09b3dcbc973747f0e4b079bed91b3e5a0aed5c36edd0f7591485f4", "asset_id": "86130975769502911188457673769190265049139877688522439001984850068234616395137", "price": "0.998", "size": "114.07", "side": "SELL", "timestamp": "1768573220483", "received_at": "2026-01-16T14:20:20.525005"}}
{"event_type": "price_change", "event_ts": "2026-01-16T14:20:20.525738", "ingestion_ts": "2026-01-16T14:20:56.869125", "market_id": "0x427bc4b40c09b3dcbc973747f0e4b079bed91b3e5a0aed5c36edd0f7591485f4", "raw": {"market": "0x427bc4b40c09b3dcbc973747f0e4b079bed91b3e5a0aed5c36edd0f7591485f4", "asset_id": "115669573443672055876643967408433138119481486650803218131873713375232186497057", "price": "0.002", "size": "128.82", "side": "BUY", "timestamp": "1768573220485", "received_at": "2026-01-16T14:20:20.525738"}}
{"event_type": "price_change", "event_ts": "2026-01-16T14:20:20.525738", "ingestion_ts": "2026-01-16T14:20:56.869125", "market_id": "0x427bc4b40c09b3dcbc973747f0e4b079bed91b3e5a0aed5c36edd0f7591485f4", "raw": {"market": "0x427bc4b40c09b3dcbc973747f0e4b079bed91b3e5a0aed5c36edd0f7591485f4", "asset_id": "86130975769502911188457673769190265049139877688522439001984850068234616395137", "price": "0.998", "size": "128.82", "side": "SELL", "timestamp": "1768573220485", "received_at": "2026-01-16T14:20:20.525738"}}
{"event_type": "price_change", "event_ts": "2026-01-16T14:20:20.833698", "ingestion_ts": "2026-01-16T14:20:56.869125", "market_id": "0x2393ed0b0fdc450054c7b9071907eca75cf4fc36e385adf4a0a5f99ee62243e8", "raw": {"market": "0x2393ed0b0fdc450054c7b9071907eca75cf4fc36e385adf4a0a5f99ee62243e8", "asset_id": "32769749367306925959219403371425714180265458150646381231272229429098460625924", "price": "0.948", "size": "50", "side": "BUY", "timestamp": "1768573220792", "received_at": "2026-01-16T14:20:20.833698"}}
{"event_type": "price_change", "event_ts": "2026-01-16T14:20:20.833698", "ingestion_ts": "2026-01-16T14:20:56.869125", "market_id": "0x2393ed0b0fdc450054c7b9071907eca75cf4fc36e385adf4a0a5f99ee62243e8", "raw": {"market": "0x2393ed0b0fdc450054c7b9071907eca75cf4fc36e385adf4a0a5f99ee62243e8", "asset_id": "100074770378634056601572485653252702850363676459996771990439989989293515601975", "price": "0.052", "size": "50", "side": "SELL", "timestamp": "1768573220792", "received_at": "2026-01-16T14:20:20.833698"}}
{"event_type": "price_change", "event_ts": "2026-01-16T14:20:20.863905", "ingestion_ts": "2026-01-16T14:20:56.869125", "market_id": "0x2393ed0b0fdc450054c7b9071907eca75cf4fc36e385adf4a0a5f99ee62243e8", "raw": {"market": "0x2393ed0b0fdc450054c7b9071907eca75cf4fc36e385adf4a0a5f99ee62243e8", "asset_id": "100074770378634056601572485653252702850363676459996771990439989989293515601975", "price": "0.053", "size": "0", "side": "SELL", "timestamp": "1768573220822", "received_at": "2026-01-16T14:20:20.863905"}}
{"event_type": "price_change", "event_ts": "2026-01-16T14:20:20.863905", "ingestion_ts": "2026-01-16T14:20:56.869125", "market_id": "0x2393ed0b0fdc450054c7b9071907eca75cf4fc36e385adf4a0a5f99ee62243e8", "raw": {"market": "0x2393ed0b0fdc450054c7b9071907eca75cf4fc36e385adf4a0a5f99ee62243e8", "asset_id": "32769749367306925959219403371425714180265458150646381231272229429098460625924", "price": "0.947", "size": "0", "side": "BUY", "timestamp": "1768573220822", "received_at": "2026-01-16T14:20:20.863905"}}
{"event_type": "price_change", "event_ts": "2026-01-16T14:20:20.891202", "ingestion_ts": "2026-01-16T14:20:56.869125", "market_id": "0x2393ed0b0fdc450054c7b9071907eca75cf4fc36e385adf4a0a5f99ee62243e8", "raw": {"market": "0x2393ed0b0fdc450054c7b9071907eca75cf4fc36e385adf4a0a5f99ee62243e8", "asset_id": "100074770378634056601572485653252702850363676459996771990439989989293515601975", "price": "0.051", "size": "199", "side": "SELL", "timestamp": "1768573220851", "received_at": "2026-01-16T14:20:20.891202"}}
{"event_type": "price_change", "event_ts": "2026-01-16T14:20:20.891202", "ingestion_ts": "2026-01-16T14:20:56.869125", "market_id": "0x2393ed0b0fdc450054c7b9071907eca75cf4fc36e385adf4a0a5f99ee62243e8", "raw": {"market": "0x2393ed0b0fdc450054c7b9071907eca75cf4fc36e385adf4a0a5f99ee62243e8", "asset_id": "32769749367306925959219403371425714180265458150646381231272229429098460625924", "price": "0.949", "size": "199", "side": "BUY", "timestamp": "1768573220851", "received_at": "2026-01-16T14:20:20.891202"}}
{"event_type": "price_change", "event_ts": "2026-01-16T14:20:20.981564", "ingestion_ts": "2026-01-16T14:20:56.869125", "market_id": "0x427bc4b40c09b3dcbc973747f0e4b079bed91b3e5a0aed5c36edd0f7591485f4", "raw": {"market": "0x427bc4b40c09b3dcbc973747f0e4b079bed91b3e5a0aed5c36edd0f7591485f4", "asset_id": "115669573443672055876643967408433138119481486650803218131873713375232186497057", "price": "0.176", "size": "27.18", "side": "SELL", "timestamp": "1768573220940", "received_at": "2026-01-16T14:20:20.981564"}}
{"event_type": "price_change", "event_ts": "2026-01-16T14:20:20.981564", "ingestion_ts": "2026-01-16T14:20:56.869125", "market_id": "0x427bc4b40c09b3dcbc973747f0e4b079bed91b3e5a0aed5c36edd0f7591485f4", "raw": {"market": "0x427bc4b40c09b3dcbc973747f0e4b079bed91b3e5a0aed5c36edd0f7591485f4", "asset_id": "86130975769502911188457673769190265049139877688522439001984850068234616395137", "price": "0.824", "size": "27.18", "side": "BUY", "timestamp": "1768573220940", "received_at": "2026-01-16T14:20:20.981564"}}
{"event_type": "price_change", "event_ts": "2026-01-16T14:20:20.981608", "ingestion_ts": "2026-01-16T14:20:56.869125", "market_id": "0x427bc4b40c09b3dcbc973747f0e4b079bed91b3e5a0aed5c36edd0f7591485f4", "raw": {"market": "0x427bc4b40c09b3dcbc973747f0e4b079bed91b3e5a0aed5c36edd0f7591485f4", "asset_id": "115669573443672055876643967408433138119481486650803218131873713375232186497057", "price": "0.178", "size": "0", "side": "SELL", "timestamp": "1768573220940", "received_at": "2026-01-16T14:20:20.981608"}}
{"event_type": "price_change", "event_ts": "2026-01-16T14:20:20.981608", "ingestion_ts": "2026-01-16T14:20:56.869125", "market_id": "0x427bc4b40c09b3dcbc973747f0e4b079bed91b3e5a0aed5c36edd0f7591485f4", "raw": {"market": "0x427bc4b40c09b3dcbc973747f0e4b079bed91b3e5a0aed5c36edd0f7591485f4", "asset_id": "86130975769502911188457673769190265049139877688522439001984850068234616395137", "price": "0.822", "size": "0", "side": "BUY", "timestamp": "1768573220940", "received_at": "2026-01-16T14:20:20.981608"}}
{"event_type": "price_change", "event_ts": "2026-01-16T14:20:21.014845", "ingestion_ts": "2026-01-16T14:20:56.869125", "market_id": "0x427bc4b40c09b3dcbc973747f0e4b079bed91b3e5a0aed5c36edd0f7591485f4", "raw": {"market": "0x427bc4b40c09b3dcbc973747f0e4b079bed91b3e5a0aed5c36edd0f7591485f4", "asset_id": "86130975769502911188457673769190265049139877688522439001984850068234616395137", "price": "0.993", "size": "36", "side": "SELL", "timestamp": "1768573220974", "received_at": "2026-01-16T14:20:21.014845"}}
{"event_type": "price_change", "event_ts": "2026-01-16T14:20:21.014845", "ingestion_ts": "2026-01-16T14:20:56.869125", "market_id": "0x427bc4b40c09b3dcbc973747f0e4b079bed91b3e5a0aed5c36edd0f7591485f4", "raw": {"market": "0x427bc4b40c09b3dcbc973747f0e4b079bed91b3e5a0aed5c36edd0f7591485f4", "asset_id": "115669573443672055876643967408433138119481486650803218131873713375232186497057", "price": "0.007", "size": "36", "side": "BUY", "timestamp": "1768573220974", "received_at": "2026-01-16T14:20:21.014845"}}
{"event_type": "price_change", "event_ts": "2026-01-16T14:20:21.132827", "ingestion_ts": "2026-01-16T14:20:56.869125", "market_id": "0x49686d26fb712515cd5e12c23f0a1c7e10214c7faa3cb0a730aabe0c33694082", "raw": {"market": "0x49686d26fb712515cd5e12c23f0a1c7e10214c7faa3cb0a730aabe0c33694082", "asset_id": "30442780799048074404860985387051749017905070253466005720364298335239299761065", "price": "0.146", "size": "5.85", "side": "SELL", "timestamp": "1768573221044", "received_at": "2026-01-16T14:20:21.132827"}}
{"event_type": "price_change", "event_ts": "2026-01-16T14:20:21.132827", "ingestion_ts": "2026-01-16T14:20:56.869125", "market_id": "0x49686d26fb712515cd5e12c23f0a1c7e10214c7faa3cb0a730aabe0c33694082", "raw": {"market": "0x49686d26fb712515cd5e12c23f0a1c7e10214c7faa3cb0a730aabe0c33694082", "asset_id": "13244681086321087932946246027856416106585284024824496763706748621681543444582", "price": "0.854", "size": "5.85", "side": "BUY", "timestamp": "1768573221044", "received_at": "2026-01-16T14:20:21.132827"}}
{"event_type": "price_change", "event_ts": "2026-01-16T14:20:21.139600", "ingestion_ts": "2026-01-16T14:20:56.869125", "market_id": "0x49686d26fb712515cd5e12c23f0a1c7e10214c7faa3cb0a730aabe0c33694082", "raw": {"market": "0x49686d26fb712515cd5e12c23f0a1c7e10214c7faa3cb0a730aabe0c33694082", "asset_id": "30442780799048074404860985387051749017905070253466005720364298335239299761065", "price": "0.148", "size": "17.5", "side": "SELL", "timestamp": "1768573221093", "received_at": "2026-01-16T14:20:21.139600"}}
{"event_type": "price_change", "event_ts": "2026-01-16T14:20:21.139600", "ingestion_ts": "2026-01-16T14:20:56.869125", "market_id": "0x49686d26fb712515cd5e12c23f0a1c7e10214c7faa3cb0a730aabe0c33694082", "raw": {"market": "0x49686d26fb712515cd5e12c23f0a1c7e10214c7faa3cb0a730aabe0c33694082", "asset_id": "13244681086321087932946246027856416106585284024824496763706748621681543444582", "price": "0.852", "size": "17.5", "side": "BUY", "timestamp": "1768573221093", "received_at": "2026-01-16T14:20:21.139600"}}
{"event_type": "price_change", "event_ts": "2026-01-16T14:20:21.164749", "ingestion_ts": "2026-01-16T14:20:56.869125", "market_id": "0x2393ed0b0fdc450054c7b9071907eca75cf4fc36e385adf4a0a5f99ee62243e8", "raw": {"market": "0x2393ed0b0fdc450054c7b9071907eca75cf4fc36e385adf4a0a5f99ee62243e8", "asset_id": "32769749367306925959219403371425714180265458150646381231272229429098460625924", "price": "0.946", "size": "0", "side": "BUY", "timestamp": "1768573221123", "received_at": "2026-01-16T14:20:21.164749"}}
{"event_type": "price_change", "event_ts": "2026-01-16T14:20:21.164749", "ingestion_ts": "2026-01-16T14:20:56.869125", "market_id": "0x2393ed0b0fdc450054c7b9071907eca75cf4fc36e385adf4a0a5f99ee62243e8", "raw": {"market": "0x2393ed0b0fdc450054c7b9071907eca75cf4fc36e385adf4a0a5f99ee62243e8", "asset_id": "100074770378634056601572485653252702850363676459996771990439989989293515601975", "price": "0.054", "size": "0", "side": "SELL", "timestamp": "1768573221123", "received_at": "2026-01-16T14:20:21.164749"}}
{"event_type": "price_change", "event_ts": "2026-01-16T14:20:21.334008", "ingestion_ts": "2026-01-16T14:20:56.869125", "market_id": "0x427bc4b40c09b3dcbc973747f0e4b079bed91b3e5a0aed5c36edd0f7591485f4", "raw": {"market": "0x427bc4b40c09b3dcbc973747f0e4b079bed91b3e5a0aed5c36edd0f7591485f4", "asset_id": "115669573443672055876643967408433138119481486650803218131873713375232186497057", "price": "0.174", "size": "9.61", "side": "SELL", "timestamp": "1768573221287", "received_at": "2026-01-16T14:20:21.334008"}}
{"event_type": "price_change", "event_ts": "2026-01-16T14:20:21.334008", "ingestion_ts": "2026-01-16T14:20:56.869125", "market_id": "0x427bc4b40c09b3dcbc973747f0e4b079bed91b3e5a0aed5c36edd0f7591485f4", "raw": {"market": "0x427bc4b40c09b3dcbc973747f0e4b079bed91b3e5a0aed5c36edd0f7591485f4", "asset_id": "86130975769502911188457673769190265049139877688522439001984850068234616395137", "price": "0.826", "size": "9.61", "side": "BUY", "timestamp": "1768573221287", "received_at": "2026-01-16T14:20:21.334008"}}
{"event_type": "price_change", "event_ts": "2026-01-16T14:20:21.334051", "ingestion_ts": "2026-01-16T14:20:56.869125", "market_id": "0x427bc4b40c09b3dcbc973747f0e4b079bed91b3e5a0aed5c36edd0f7591485f4", "raw": {"market": "0x427bc4b40c09b3dcbc973747f0e4b079bed91b3e5a0aed5c36edd0f7591485f4", "asset_id": "115669573443672055876643967408433138119481486650803218131873713375232186497057", "price": "0.177", "size": "7.53", "side": "SELL", "timestamp": "1768573221289", "received_at": "2026-01-16T14:20:21.334051"}}
{"event_type": "price_change", "event_ts": "2026-01-16T14:20:21.334051", "ingestion_ts": "2026-01-16T14:20:56.869125", "market_id": "0x427bc4b40c09b3dcbc973747f0e4b079bed91b3e5a0aed5c36edd0f7591485f4", "raw": {"market": "0x427bc4b40c09b3dcbc973747f0e4b079bed91b3e5a0aed5c36edd0f7591485f4", "asset_id": "86130975769502911188457673769190265049139877688522439001984850068234616395137", "price": "0.823", "size": "7.53", "side": "BUY", "timestamp": "1768573221289", "received_at": "2026-01-16T14:20:21.334051"}}
{"event_type": "price_change", "event_ts": "2026-01-16T14:20:21.337273", "ingestion_ts": "2026-01-16T14:20:56.869125", "market_id": "0x427bc4b40c09b3dcbc973747f0e4b079bed91b3e5a0aed5c36edd0f7591485f4", "raw": {"market": "0x427bc4b40c09b3dcbc973747f0e4b079bed91b3e5a0aed5c36edd0f7591485f4", "asset_id": "115669573443672055876643967408433138119481486650803218131873713375232186497057", "price": "0.174", "size": "19.22", "side": "SELL", "timestamp": "1768573221290", "received_at": "2026-01-16T14:20:21.337273"}}
{"event_type": "price_change", "event_ts": "2026-01-16T14:20:21.337273", "ingestion_ts": "2026-01-16T14:20:56.869125", "market_id": "0x427bc4b40c09b3dcbc973747f0e4b079bed91b3e5a0aed5c36edd0f7591485f4", "raw": {"market": "0x427bc4b40c09b3dcbc973747f0e4b079bed91b3e5a0aed5c36edd0f7591485f4", "asset_id": "86130975769502911188457673769190265049139877688522439001984850068234616395137", "price": "0.826", "size": "19.22", "side": "BUY", "timestamp": "1768573221290", "received_at": "2026-01-16T14:20:21.337273"}}
{"event_type": "price_change", "event_ts": "2026-01-16T14:20:21.337312", "ingestion_ts": "2026-01-16T14:20:56.869125", "market_id": "0x427bc4b40c09b3dcbc973747f0e4b079bed91b3e5a0aed5c36edd0f7591485f4", "raw": {"market": "0x427bc4b40c09b3dcbc973747f0e4b079bed91b3e5a0aed5c36edd0f7591485f4", "asset_id": "115669573443672055876643967408433138119481486650803218131873713375232186497057", "price": "0.175", "size": "43.25", "side": "SELL", "timestamp": "1768573221291", "received_at": "2026-01-16T14:20:21.337312"}}
{"event_type": "price_change", "event_ts": "2026-01-16T14:20:21.337312", "ingestion_ts": "2026-01-16T14:20:56.869125", "market_id": "0x427bc4b40c09b3dcbc973747f0e4b079bed91b3e5a0aed5c36edd0f7591485f4", "raw": {"market": "0x427bc4b40c09b3dcbc973747f0e4b079bed91b3e5a0aed5c36edd0f7591485f4", "asset_id": "86130975769502911188457673769190265049139877688522439001984850068234616395137", "price": "0.825", "size": "43.25", "side": "BUY", "timestamp": "1768573221291", "received_at": "2026-01-16T14:20:21.337312"}}
{"event_type": "price_change", "event_ts": "2026-01-16T14:20:21.337326", "ingestion_ts": "2026-01-16T14:20:56.869125", "market_id": "0x427bc4b40c09b3dcbc973747f0e4b079bed91b3e5a0aed5c36edd0f7591485f4", "raw": {"market": "0x427bc4b40c09b3dcbc973747f0e4b079bed91b3e5a0aed5c36edd0f7591485f4", "asset_id": "115669573443672055876643967408433138119481486650803218131873713375232186497057", "price": "0.175", "size": "50.5", "side": "SELL", "timestamp": "1768573221292", "received_at": "2026-01-16T14:20:21.337326"}}
{"event_type": "price_change", "event_ts": "2026-01-16T14:20:21.337326", "ingestion_ts": "2026-01-16T14:20:56.869125", "market_id": "0x427bc4b40c09b3dcbc973747f0e4b079bed91b3e5a0aed5c36edd0f7591485f4", "raw": {"market": "0x427bc4b40c09b3dcbc973747f0e4b079bed91b3e5a0aed5c36edd0f7591485f4", "asset_id": "86130975769502911188457673769190265049139877688522439001984850068234616395137", "price": "0.825", "size": "50.5", "side": "BUY", "timestamp": "1768573221292", "received_at": "2026-01-16T14:20:21.337326"}}
{"event_type": "price_change", "event_ts": "2026-01-16T14:20:21.379020", "ingestion_ts": "2026-01-16T14:20:56.869125", "market_id": "0x427bc4b40c09b3dcbc973747f0e4b079bed91b3e5a0aed5c36edd0f7591485f4", "raw": {"market": "0x427bc4b40c09b3dcbc973747f0e4b079bed91b3e5a0aed5c36edd0f7591485f4", "asset_id": "86130975769502911188457673769190265049139877688522439001984850068234616395137", "price": "0.825", "size": "14.5", "side": "BUY", "timestamp": "1768573221331", "received_at": "2026-01-16T14:20:21.379020"}}
{"event_type": "price_change", "event_ts": "2026-01-16T14:20:21.379020", "ingestion_ts": "2026-01-16T14:20:56.869125", "market_id": "0x427bc4b40c09b3dcbc973747f0e4b079bed91b3e5a0aed5c36edd0f7591485f4", "raw": {"market": "0x427bc4b40c09b3dcbc973747f0e4b079bed91b3e5a0aed5c36edd0f7591485f4", "asset_id": "115669573443672055876643967408433138119481486650803218131873713375232186497057", "price": "0.175", "size": "14.5", "side": "SELL", "timestamp": "1768573221331", "received_at": "2026-01-16T14:20:21.379020"}}
{"event_type": "price_change", "event_ts": "2026-01-16T14:20:21.398817", "ingestion_ts": "2026-01-16T14:20:56.869125", "market_id": "0x427bc4b40c09b3dcbc973747f0e4b079bed91b3e5a0aed5c36edd0f7591485f4", "raw": {"market": "0x427bc4b40c09b3dcbc973747f0e4b079bed91b3e5a0aed5c36edd0f7591485f4", "asset_id": "86130975769502911188457673769190265049139877688522439001984850068234616395137", "price": "0.827", "size": "33", "side": "BUY", "timestamp": "1768573221359", "received_at": "2026-01-16T14:20:21.398817"}}
{"event_type": "price_change", "event_ts": "2026-01-16T14:20:21.398817", "ingestion_ts": "2026-01-16T14:20:56.869125", "market_id": "0x427bc4b40c09b3dcbc973747f0e4b079bed91b3e5a0aed5c36edd0f7591485f4", "raw": {"market": "0x427bc4b40c09b3dcbc973747f0e4b079bed91b3e5a0aed5c36edd0f7591485f4", "asset_id": "115669573443672055876643967408433138119481486650803218131873713375232186497057", "price": "0.173", "size": "33", "side": "SELL", "timestamp": "1768573221359", "received_at": "2026-01-16T14:20:21.398817"}}
{"event_type": "price_change", "event_ts": "2026-01-16T14:20:22.547822", "ingestion_ts": "2026-01-16T14:20:56.869125", "market_id": "0x427bc4b40c09b3dcbc973747f0e4b079bed91b3e5a0aed5c36edd0f7591485f4", "raw": {"market": "0x427bc4b40c09b3dcbc973747f0e4b079bed91b3e5a0aed5c36edd0f7591485f4", "asset_id": "115669573443672055876643967408433138119481486650803218131873713375232186497057", "price": "0.002", "size": "114.07", "side": "BUY", "timestamp": "1768573222469", "received_at": "2026-01-16T14:20:22.547822"}}
{"event_type": "price_change", "event_ts": "2026-01-16T14:20:22.547822", "ingestion_ts": "2026-01-16T14:20:56.869125", "market_id": "0x427bc4b40c09b3dcbc973747f0e4b079bed91b3e5a0aed5c36edd0f7591485f4", "raw": {"market": "0x427bc4b40c09b3dcbc973747f0e4b079bed91b3e5a0aed5c36edd0f7591485f4", "asset_id": "86130975769502911188457673769190265049139877688522439001984850068234616395137", "price": "0.998", "size": "114.07", "side": "SELL", "timestamp": "1768573222469", "received_at": "2026-01-16T14:20:22.547822"}}
{"event_type": "price_change", "event_ts": "2026-01-16T14:20:22.547862", "ingestion_ts": "2026-01-16T14:20:56.869125", "market_id": "0x427bc4b40c09b3dcbc973747f0e4b079bed91b3e5a0aed5c36edd0f7591485f4", "raw": {"market": "0x427bc4b40c09b3dcbc973747f0e4b079bed91b3e5a0aed5c36edd0f7591485f4", "asset_id": "115669573443672055876643967408433138119481486650803218131873713375232186497057", "price": "0.006", "size": "21.35", "side": "BUY", "timestamp": "1768573222469", "received_at": "2026-01-16T14:20:22.547862"}}
{"event_type": "price_change", "event_ts": "2026-01-16T14:20:22.547862", "ingestion_ts": "2026-01-16T14:20:56.869125", "market_id": "0x427bc4b40c09b3dcbc973747f0e4b079bed91b3e5a0aed5c36edd0f7591485f4", "raw": {"market": "0x427bc4b40c09b3dcbc973747f0e4b079bed91b3e5a0aed5c36edd0f7591485f4", "asset_id": "86130975769502911188457673769190265049139877688522439001984850068234616395137", "price": "0.994", "size": "21.35", "side": "SELL", "timestamp": "1768573222469", "received_at": "2026-01-16T14:20:22.547862"}}
{"event_type": "price_change", "event_ts": "2026-01-16T14:20:22.795995", "ingestion_ts": "2026-01-16T14:20:56.869125", "market_id": "0x427bc4b40c09b3dcbc973747f0e4b079bed91b3e5a0aed5c36edd0f7591485f4", "raw": {"market": "0x427bc4b40c09b3dcbc973747f0e4b079bed91b3e5a0aed5c36edd0f7591485f4", "asset_id": "115669573443672055876643967408433138119481486650803218131873713375232186497057", "price": "0.003", "size": "5.14", "side": "BUY", "timestamp": "1768573222758", "received_at": "2026-01-16T14:20:22.795995"}}
{"event_type": "price_change", "event_ts": "2026-01-16T14:20:22.795995", "ingestion_ts": "2026-01-16T14:20:56.869125", "market_id": "0x427bc4b40c09b3dcbc973747f0e4b079bed91b3e5a0aed5c36edd0f7591485f4", "raw": {"market": "0x427bc4b40c09b3dcbc973747f0e4b079bed91b3e5a0aed5c36edd0f7591485f4", "asset_id": "86130975769502911188457673769190265049139877688522439001984850068234616395137", "price": "0.997", "size": "5.14", "side": "SELL", "timestamp": "1768573222758", "received_at": "2026-01-16T14:20:22.795995"}}
{"event_type": "price_change", "event_ts": "2026-01-16T14:20:22.800541", "ingestion_ts": "2026-01-16T14:20:56.869125", "market_id": "0x427bc4b40c09b3dcbc973747f0e4b079bed91b3e5a0aed5c36edd0f7591485f4", "raw": {"market": "0x427bc4b40c09b3dcbc973747f0e4b079bed91b3e5a0aed5c36edd0f7591485f4", "asset_id": "115669573443672055876643967408433138119481486650803218131873713375232186497057", "price": "0.003", "size": "10.28", "side": "BUY", "timestamp": "1768573222763", "received_at": "2026-01-16T14:20:22.800541"}}
{"event_type": "price_change", "event_ts": "2026-01-16T14:20:22.800541", "ingestion_ts": "2026-01-16T14:20:56.869125", "market_id": "0x427bc4b40c09b3dcbc973747f0e4b079bed91b3e5a0aed5c36edd0f7591485f4", "raw": {"market": "0x427bc4b40c09b3dcbc973747f0e4b079bed91b3e5a0aed5c36edd0f7591485f4", "asset_id": "86130975769502911188457673769190265049139877688522439001984850068234616395137", "price": "0.997", "size": "10.28", "side": "SELL", "timestamp": "1768573222763", "received_at": "2026-01-16T14:20:22.800541"}}
{"event_type": "price_change", "event_ts": "2026-01-16T14:20:22.806440", "ingestion_ts": "2026-01-16T14:20:56.869125", "market_id": "0x427bc4b40c09b3dcbc973747f0e4b079bed91b3e5a0aed5c36edd0f7591485f4", "raw": {"market": "0x427bc4b40c09b3dcbc973747f0e4b079bed91b3e5a0aed5c36edd0f7591485f4", "asset_id": "115669573443672055876643967408433138119481486650803218131873713375232186497057", "price": "0.007", "size": "44.2", "side": "BUY", "timestamp": "1768573222767", "received_at": "2026-01-16T14:20:22.806440"}}
{"event_type": "price_change", "event_ts": "2026-01-16T14:20:22.806440", "ingestion_ts": "2026-01-16T14:20:56.869125", "market_id": "0x427bc4b40c09b3dcbc973747f0e4b079bed91b3e5a0aed5c36edd0f7591485f4", "raw": {"market": "0x427bc4b40c09b3dcbc973747f0e4b079bed91b3e5a0aed5c36edd0f7591485f4", "asset_id": "86130975769502911188457673769190265049139877688522439001984850068234616395137", "price": "0.993", "size": "44.2", "side": "SELL", "timestamp": "1768573222767", "received_at": "2026-01-16T14:20:22.806440"}}
{"event_type": "price_change", "event_ts": "2026-01-16T14:20:23.683117", "ingestion_ts": "2026-01-16T14:20:56.869125", "market_id": "0x427bc4b40c09b3dcbc973747f0e4b079bed91b3e5a0aed5c36edd0f7591485f4", "raw": {"market": "0x427bc4b40c09b3dcbc973747f0e4b079bed91b3e5a0aed5c36edd0f7591485f4", "asset_id": "115669573443672055876643967408433138119481486650803218131873713375232186497057", "price": "0.174", "size": "9.61", "side": "SELL", "timestamp": "1768573223355", "received_at": "2026-01-16T14:20:23.683117"}}
{"event_type": "price_change", "event_ts": "2026-01-16T14:20:23.683117", "ingestion_ts": "2026-01-16T14:20:56.869125", "market_id": "0x427bc4b40c09b3dcbc973747f0e4b079bed91b3e5a0aed5c36edd0f7591485f4", "raw": {"market": "0x427bc4b40c09b3dcbc973747f0e4b079bed91b3e5a0aed5c36edd0f7591485f4", "asset_id": "86130975769502911188457673769190265049139877688522439001984850068234616395137", "price": "0.826", "size": "9.61", "side": "BUY", "timestamp": "1768573223355", "received_at": "2026-01-16T14:20:23.683117"}}
{"event_type": "price_change", "event_ts": "2026-01-16T14:20:23.683159", "ingestion_ts": "2026-01-16T14:20:56.869125", "market_id": "0x427bc4b40c09b3dcbc973747f0e4b079bed91b3e5a0aed5c36edd0f7591485f4", "raw": {"market": "0x427bc4b40c09b3dcbc973747f0e4b079bed91b3e5a0aed5c36edd0f7591485f4", "asset_id": "115669573443672055876643967408433138119481486650803218131873713375232186497057", "price": "0.175", "size": "7.25", "side": "SELL", "timestamp": "1768573223355", "received_at": "2026-01-16T14:20:23.683159"}}
{"event_type": "price_change", "event_ts": "2026-01-16T14:20:23.683159", "ingestion_ts": "2026-01-16T14:20:56.869125", "market_id": "0x427bc4b40c09b3dcbc973747f0e4b079bed91b3e5a0aed5c36edd0f7591485f4", "raw": {"market": "0x427bc4b40c09b3dcbc973747f0e4b079bed91b3e5a0aed5c36edd0f7591485f4", "asset_id": "86130975769502911188457673769190265049139877688522439001984850068234616395137", "price": "0.825", "size": "7.25", "side": "BUY", "timestamp": "1768573223355", "received_at": "2026-01-16T14:20:23.683159"}}
{"event_type": "price_change", "event_ts": "2026-01-16T14:20:23.683175", "ingestion_ts": "2026-01-16T14:20:56.869125", "market_id": "0x427bc4b40c09b3dcbc973747f0e4b079bed91b3e5a0aed5c36edd0f7591485f4", "raw": {"market": "0x427bc4b40c09b3dcbc973747f0e4b079bed91b3e5a0aed5c36edd0f7591485f4", "asset_id": "115669573443672055876643967408433138119481486650803218131873713375232186497057", "price": "0.176", "size": "0", "side": "SELL", "timestamp": "1768573223355", "received_at": "2026-01-16T14:20:23.683175"}}
{"event_type": "price_change", "event_ts": "2026-01-16T14:20:23.683175", "ingestion_ts": "2026-01-16T14:20:56.869125", "market_id": "0x427bc4b40c09b3dcbc973747f0e4b079bed91b3e5a0aed5c36edd0f7591485f4", "raw": {"market": "0x427bc4b40c09b3dcbc973747f0e4b079bed91b3e5a0aed5c36edd0f7591485f4", "asset_id": "86130975769502911188457673769190265049139877688522439001984850068234616395137", "price": "0.824", "size": "0", "side": "BUY", "timestamp": "1768573223355", "received_at": "2026-01-16T14:20:23.683175"}}
{"event_type": "price_change", "event_ts": "2026-01-16T14:20:23.683249", "ingestion_ts": "2026-01-16T14:20:56.869125", "market_id": "0x427bc4b40c09b3dcbc973747f0e4b079bed91b3e5a0aed5c36edd0f7591485f4", "raw": {"market": "0x427bc4b40c09b3dcbc973747f0e4b079bed91b3e5a0aed5c36edd0f7591485f4", "asset_id": "115669573443672055876643967408433138119481486650803218131873713375232186497057", "price": "0.177", "size": "0", "side": "SELL", "timestamp": "1768573223355", "received_at": "2026-01-16T14:20:23.683249"}}
{"event_type": "price_change", "event_ts": "2026-01-16T14:20:23.683249", "ingestion_ts": "2026-01-16T14:20:56.869125", "market_id": "0x427bc4b40c09b3dcbc973747f0e4b079bed91b3e5a0aed5c36edd0f7591485f4", "raw": {"market": "0x427bc4b40c09b3dcbc973747f0e4b079bed91b3e5a0aed5c36edd0f7591485f4", "asset_id": "86130975769502911188457673769190265049139877688522439001984850068234616395137", "price": "0.823", "size": "0", "side": "BUY", "timestamp": "1768573223355", "received_at": "2026-01-16T14:20:23.683249"}}
{"event_type": "price_change", "event_ts": "2026-01-16T14:20:23.850476", "ingestion_ts": "2026-01-16T14:20:56.869125", "market_id": "0xae5584fbb57f23c1c608d544b656f23d8bf12340cef70811cf31bb0cb4fc2115", "raw": {"market": "0xae5584fbb57f23c1c608d544b656f23d8bf12340cef70811cf31bb0cb4fc2115", "asset_id": "42278252558046940014991595990628759801692726198478046188873057685686228021663", "price": "0.99", "size": "8145.4", "side": "SELL", "timestamp": "1768573223497", "received_at": "2026-01-16T14:20:23.850476"}}
{"event_type": "price_change", "event_ts": "2026-01-16T14:20:23.850476", "ingestion_ts": "2026-01-16T14:20:56.869125", "market_id": "0xae5584fbb57f23c1c608d544b656f23d8bf12340cef70811cf31bb0cb4fc2115", "raw": {"market": "0xae5584fbb57f23c1c608d544b656f23d8bf12340cef70811cf31bb0cb4fc2115", "asset_id": "28946595841244317705636126646676849578876740730186646421280828201004700559420", "price": "0.01", "size": "8145.4", "side": "BUY", "timestamp": "1768573223497", "received_at": "2026-01-16T14:20:23.850476"}}
{"event_type": "price_change", "event_ts": "2026-01-16T14:20:23.951470", "ingestion_ts": "2026-01-16T14:20:56.869125", "market_id": "0xae5584fbb57f23c1c608d544b656f23d8bf12340cef70811cf31bb0cb4fc2115", "raw": {"market": "0xae5584fbb57f23c1c608d544b656f23d8bf12340cef70811cf31bb0cb4fc2115", "asset_id": "28946595841244317705636126646676849578876740730186646421280828201004700559420", "price": "0.01", "size": "8097.6", "side": "BUY", "timestamp": "1768573223585", "received_at": "2026-01-16T14:20:23.951470"}}
{"event_type": "price_change", "event_ts": "2026-01-16T14:20:23.951470", "ingestion_ts": "2026-01-16T14:20:56.869125", "market_id": "0xae5584fbb57f23c1c608d544b656f23d8bf12340cef70811cf31bb0cb4fc2115", "raw": {"market": "0xae5584fbb57f23c1c608d544b656f23d8bf12340cef70811cf31bb0cb4fc2115", "asset_id": "42278252558046940014991595990628759801692726198478046188873057685686228021663", "price": "0.99", "size": "8097.6", "side": "SELL", "timestamp": "1768573223585", "received_at": "2026-01-16T14:20:23.951470"}}
{"event_type": "price_change", "event_ts": "2026-01-16T14:20:24.178486", "ingestion_ts": "2026-01-16T14:20:56.869125", "market_id": "0x427bc4b40c09b3dcbc973747f0e4b079bed91b3e5a0aed5c36edd0f7591485f4", "raw": {"market": "0x427bc4b40c09b3dcbc973747f0e4b079bed91b3e5a0aed5c36edd0f7591485f4", "asset_id": "115669573443672055876643967408433138119481486650803218131873713375232186497057", "price": "0.175", "size": "15.04", "side": "SELL", "timestamp": "1768573223821", "received_at": "2026-01-16T14:20:24.178486"}}
{"event_type": "price_change", "event_ts": "2026-01-16T14:20:24.178486", "ingestion_ts": "2026-01-16T14:20:56.869125", "market_id": "0x427bc4b40c09b3dcbc973747f0e4b079bed91b3e5a0aed5c36edd0f7591485f4", "raw": {"market": "0x427bc4b40c09b3dcbc973747f0e4b079bed91b3e5a0aed5c36edd0f7591485f4", "asset_id": "86130975769502911188457673769190265049139877688522439001984850068234616395137", "price": "0.825", "size": "15.04", "side": "BUY", "timestamp": "1768573223821", "received_at": "2026-01-16T14:20:24.178486"}}
{"event_type": "price_change", "event_ts": "2026-01-16T14:20:24.178528", "ingestion_ts": "2026-01-16T14:20:56.869125", "market_id": "0x427bc4b40c09b3dcbc973747f0e4b079bed91b3e5a0aed5c36edd0f7591485f4", "raw": {"market": "0x427bc4b40c09b3dcbc973747f0e4b079bed91b3e5a0aed5c36edd0f7591485f4", "asset_id": "115669573443672055876643967408433138119481486650803218131873713375232186497057", "price": "0.173", "size": "39.7", "side": "SELL", "timestamp": "1768573223822", "received_at": "2026-01-16T14:20:24.178528"}}
{"event_type": "price_change", "event_ts": "2026-01-16T14:20:24.178528", "ingestion_ts": "2026-01-16T14:20:56.869125", "market_id": "0x427bc4b40c09b3dcbc973747f0e4b079bed91b3e5a0aed5c36edd0f7591485f4", "raw": {"market": "0x427bc4b40c09b3dcbc973747f0e4b079bed91b3e5a0aed5c36edd0f7591485f4", "asset_id": "86130975769502911188457673769190265049139877688522439001984850068234616395137", "price": "0.827", "size": "39.7", "side": "BUY", "timestamp": "1768573223822", "received_at": "2026-01-16T14:20:24.178528"}}
{"event_type": "price_change", "event_ts": "2026-01-16T14:20:24.178542", "ingestion_ts": "2026-01-16T14:20:56.869125", "market_id": "0x427bc4b40c09b3dcbc973747f0e4b079bed91b3e5a0aed5c36edd0f7591485f4", "raw": {"market": "0x427bc4b40c09b3dcbc973747f0e4b079bed91b3e5a0aed5c36edd0f7591485f4", "asset_id": "115669573443672055876643967408433138119481486650803218131873713375232186497057", "price": "0.175", "size": "22.83", "side": "SELL", "timestamp": "1768573223823", "received_at": "2026-01-16T14:20:24.178542"}}
{"event_type": "price_change", "event_ts": "2026-01-16T14:20:24.178542", "ingestion_ts": "2026-01-16T14:20:56.869125", "market_id": "0x427bc4b40c09b3dcbc973747f0e4b079bed91b3e5a0aed5c36edd0f7591485f4", "raw": {"market": "0x427bc4b40c09b3dcbc973747f0e4b079bed91b3e5a0aed5c36edd0f7591485f4", "asset_id": "86130975769502911188457673769190265049139877688522439001984850068234616395137", "price": "0.825", "size": "22.83", "side": "BUY", "timestamp": "1768573223823", "received_at": "2026-01-16T14:20:24.178542"}}
{"event_type": "price_change", "event_ts": "2026-01-16T14:20:24.178554", "ingestion_ts": "2026-01-16T14:20:56.869125", "market_id": "0x427bc4b40c09b3dcbc973747f0e4b079bed91b3e5a0aed5c36edd0f7591485f4", "raw": {"market": "0x427bc4b40c09b3dcbc973747f0e4b079bed91b3e5a0aed5c36edd0f7591485f4", "asset_id": "115669573443672055876643967408433138119481486650803218131873713375232186497057", "price": "0.172", "size": "11.51", "side": "SELL", "timestamp": "1768573223824", "received_at": "2026-01-16T14:20:24.178554"}}
{"event_type": "price_change", "event_ts": "2026-01-16T14:20:24.178554", "ingestion_ts": "2026-01-16T14:20:56.869125", "market_id": "0x427bc4b40c09b3dcbc973747f0e4b079bed91b3e5a0aed5c36edd0f7591485f4", "raw": {"market": "0x427bc4b40c09b3dcbc973747f0e4b079bed91b3e5a0aed5c36edd0f7591485f4", "asset_id": "86130975769502911188457673769190265049139877688522439001984850068234616395137", "price": "0.828", "size": "11.51", "side": "BUY", "timestamp": "1768573223824", "received_at": "2026-01-16T14:20:24.178554"}}
{"event_type": "price_change", "event_ts": "2026-01-16T14:20:24.178565", "ingestion_ts": "2026-01-16T14:20:56.869125", "market_id": "0x427bc4b40c09b3dcbc973747f0e4b079bed91b3e5a0aed5c36edd0f7591485f4", "raw": {"market": "0x427bc4b40c09b3dcbc973747f0e4b079bed91b3e5a0aed5c36edd0f7591485f4", "asset_id": "115669573443672055876643967408433138119481486650803218131873713375232186497057", "price": "0.172", "size": "23.02", "side": "SELL", "timestamp": "1768573223825", "received_at": "2026-01-16T14:20:24.178565"}}
{"event_type": "price_change", "event_ts": "2026-01-16T14:20:24.178565", "ingestion_ts": "2026-01-16T14:20:56.869125", "market_id": "0x427bc4b40c09b3dcbc973747f0e4b079bed91b3e5a0aed5c36edd0f7591485f4", "raw": {"market": "0x427bc4b40c09b3dcbc973747f0e4b079bed91b3e5a0aed5c36edd0f7591485f4", "asset_id": "86130975769502911188457673769190265049139877688522439001984850068234616395137", "price": "0.828", "size": "23.02", "side": "BUY", "timestamp": "1768573223825", "received_at": "2026-01-16T14:20:24.178565"}}
{"event_type": "price_change", "event_ts": "2026-01-16T14:20:24.178575", "ingestion_ts": "2026-01-16T14:20:56.869125", "market_id": "0x427bc4b40c09b3dcbc973747f0e4b079bed91b3e5a0aed5c36edd0f7591485f4", "raw": {"market": "0x427bc4b40c09b3dcbc973747f0e4b079bed91b3e5a0aed5c36edd0f7591485f4", "asset_id": "115669573443672055876643967408433138119481486650803218131873713375232186497057", "price": "0.176", "size": "6.27", "side": "SELL", "timestamp": "1768573223826", "received_at": "2026-01-16T14:20:24.178575"}}
{"event_type": "price_change", "event_ts": "2026-01-16T14:20:24.178575", "ingestion_ts": "2026-01-16T14:20:56.869125", "market_id": "0x427bc4b40c09b3dcbc973747f0e4b079bed91b3e5a0aed5c36edd0f7591485f4", "raw": {"market": "0x427bc4b40c09b3dcbc973747f0e4b079bed91b3e5a0aed5c36edd0f7591485f4", "asset_id": "86130975769502911188457673769190265049139877688522439001984850068234616395137", "price": "0.824", "size": "6.27", "side": "BUY", "timestamp": "1768573223826", "received_at": "2026-01-16T14:20:24.178575"}}
{"event_type": "price_change", "event_ts": "2026-01-16T14:20:24.271530", "ingestion_ts": "2026-01-16T14:20:56.869125", "market_id": "0x427bc4b40c09b3dcbc973747f0e4b079bed91b3e5a0aed5c36edd0f7591485f4", "raw": {"market": "0x427bc4b40c09b3dcbc973747f0e4b079bed91b3e5a0aed5c36edd0f7591485f4", "asset_id": "86130975769502911188457673769190265049139877688522439001984850068234616395137", "price": "0.827", "size": "6.7", "side": "BUY", "timestamp": "1768573223920", "received_at": "2026-01-16T14:20:24.271530"}}
{"event_type": "price_change", "event_ts": "2026-01-16T14:20:24.271530", "ingestion_ts": "2026-01-16T14:20:56.869125", "market_id": "0x427bc4b40c09b3dcbc973747f0e4b079bed91b3e5a0aed5c36edd0f7591485f4", "raw": {"market": "0x427bc4b40c09b3dcbc973747f0e4b079bed91b3e5a0aed5c36edd0f7591485f4", "asset_id": "115669573443672055876643967408433138119481486650803218131873713375232186497057", "price": "0.173", "size": "6.7", "side": "SELL", "timestamp": "1768573223920", "received_at": "2026-01-16T14:20:24.271530"}}
{"event_type": "price_change", "event_ts": "2026-01-16T14:20:24.271590", "ingestion_ts": "2026-01-16T14:20:56.869125", "market_id": "0x427bc4b40c09b3dcbc973747f0e4b079bed91b3e5a0aed5c36edd0f7591485f4", "raw": {"market": "0x427bc4b40c09b3dcbc973747f0e4b079bed91b3e5a0aed5c36edd0f7591485f4", "asset_id": "86130975769502911188457673769190265049139877688522439001984850068234616395137", "price": "0.829", "size": "25", "side": "BUY", "timestamp": "1768573223949", "received_at": "2026-01-16T14:20:24.271590"}}
{"event_type": "price_change", "event_ts": "2026-01-16T14:20:24.271590", "ingestion_ts": "2026-01-16T14:20:56.869125", "market_id": "0x427bc4b40c09b3dcbc973747f0e4b079bed91b3e5a0aed5c36edd0f7591485f4", "raw": {"market": "0x427bc4b40c09b3dcbc973747f0e4b079bed91b3e5a0aed5c36edd0f7591485f4", "asset_id": "115669573443672055876643967408433138119481486650803218131873713375232186497057", "price": "0.171", "size": "25", "side": "SELL", "timestamp": "1768573223949", "received_at": "2026-01-16T14:20:24.271590"}}
{"event_type": "price_change", "event_ts": "2026-01-16T14:20:25.338738", "ingestion_ts": "2026-01-16T14:20:56.869125", "market_id": "0x427bc4b40c09b3dcbc973747f0e4b079bed91b3e5a0aed5c36edd0f7591485f4", "raw": {"market": "0x427bc4b40c09b3dcbc973747f0e4b079bed91b3e5a0aed5c36edd0f7591485f4", "asset_id": "115669573443672055876643967408433138119481486650803218131873713375232186497057", "price": "0.003", "size": "5.14", "side": "BUY", "timestamp": "1768573225107", "received_at": "2026-01-16T14:20:25.338738"}}
{"event_type": "price_change", "event_ts": "2026-01-16T14:20:25.338738", "ingestion_ts": "2026-01-16T14:20:56.869125", "market_id": "0x427bc4b40c09b3dcbc973747f0e4b079bed91b3e5a0aed5c36edd0f7591485f4", "raw": {"market": "0x427bc4b40c09b3dcbc973747f0e4b079bed91b3e5a0aed5c36edd0f7591485f4", "asset_id": "86130975769502911188457673769190265049139877688522439001984850068234616395137", "price": "0.997", "size": "5.14", "side": "SELL", "timestamp": "1768573225107", "received_at": "2026-01-16T14:20:25.338738"}}
{"event_type": "price_change", "event_ts": "2026-01-16T14:20:25.338795", "ingestion_ts": "2026-01-16T14:20:56.869125", "market_id": "0x427bc4b40c09b3dcbc973747f0e4b079bed91b3e5a0aed5c36edd0f7591485f4", "raw": {"market": "0x427bc4b40c09b3dcbc973747f0e4b079bed91b3e5a0aed5c36edd0f7591485f4", "asset_id": "115669573443672055876643967408433138119481486650803218131873713375232186497057", "price": "0.006", "size": "15.74", "side": "BUY", "timestamp": "1768573225107", "received_at": "2026-01-16T14:20:25.338795"}}
{"event_type": "price_change", "event_ts": "2026-01-16T14:20:25.338795", "ingestion_ts": "2026-01-16T14:20:56.869125", "market_id": "0x427bc4b40c09b3dcbc973747f0e4b079bed91b3e5a0aed5c36edd0f7591485f4", "raw": {"market": "0x427bc4b40c09b3dcbc973747f0e4b079bed91b3e5a0aed5c36edd0f7591485f4", "asset_id": "86130975769502911188457673769190265049139877688522439001984850068234616395137", "price": "0.994", "size": "15.74", "side": "SELL", "timestamp": "1768573225107", "received_at": "2026-01-16T14:20:25.338795"}}
{"event_type": "price_change", "event_ts": "2026-01-16T14:20:25.338814", "ingestion_ts": "2026-01-16T14:20:56.869125", "market_id": "0x427bc4b40c09b3dcbc973747f0e4b079bed91b3e5a0aed5c36edd0f7591485f4", "raw": {"market": "0x427bc4b40c09b3dcbc973747f0e4b079bed91b3e5a0aed5c36edd0f7591485f4", "asset_id": "115669573443672055876643967408433138119481486650803218131873713375232186497057", "price": "0.007", "size": "36", "side": "BUY", "timestamp": "1768573225107", "received_at": "2026-01-16T14:20:25.338814"}}
{"event_type": "price_change", "event_ts": "2026-01-16T14:20:25.338814", "ingestion_ts": "2026-01-16T14:20:56.869125", "market_id": "0x427bc4b40c09b3dcbc973747f0e4b079bed91b3e5a0aed5c36edd0f7591485f4", "raw": {"market": "0x427bc4b40c09b3dcbc973747f0e4b079bed91b3e5a0aed5c36edd0f7591485f4", "asset_id": "86130975769502911188457673769190265049139877688522439001984850068234616395137", "price": "0.993", "size": "36", "side": "SELL", "timestamp": "1768573225107", "received_at": "2026-01-16T14:20:25.338814"}}
{"event_type": "price_change", "event_ts": "2026-01-16T14:20:25.607505", "ingestion_ts": "2026-01-16T14:20:56.869125", "market_id": "0x427bc4b40c09b3dcbc973747f0e4b079bed91b3e5a0aed5c36edd0f7591485f4", "raw": {"market": "0x427bc4b40c09b3dcbc973747f0e4b079bed91b3e5a0aed5c36edd0f7591485f4", "asset_id": "115669573443672055876643967408433138119481486650803218131873713375232186497057", "price": "0.008", "size": "6.66", "side": "BUY", "timestamp": "1768573225417", "received_at": "2026-01-16T14:20:25.607505"}}
{"event_type": "price_change", "event_ts": "2026-01-16T14:20:25.607505", "ingestion_ts": "2026-01-16T14:20:56.869125", "market_id": "0x427bc4b40c09b3dcbc973747f0e4b079bed91b3e5a0aed5c36edd0f7591485f4", "raw": {"market": "0x427bc4b40c09b3dcbc973747f0e4b079bed91b3e5a0aed5c36edd0f7591485f4", "asset_id": "86130975769502911188457673769190265049139877688522439001984850068234616395137", "price": "0.992", "size": "6.66", "side": "SELL", "timestamp": "1768573225417", "received_at": "2026-01-16T14:20:25.607505"}}
{"event_type": "price_change", "event_ts": "2026-01-16T14:20:25.608976", "ingestion_ts": "2026-01-16T14:20:56.869125", "market_id": "0x427bc4b40c09b3dcbc973747f0e4b079bed91b3e5a0aed5c36edd0f7591485f4", "raw": {"market": "0x427bc4b40c09b3dcbc973747f0e4b079bed91b3e5a0aed5c36edd0f7591485f4", "asset_id": "115669573443672055876643967408433138119481486650803218131873713375232186497057", "price": "0.008", "size": "13.32", "side": "BUY", "timestamp": "1768573225419", "received_at": "2026-01-16T14:20:25.608976"}}
{"event_type": "price_change", "event_ts": "2026-01-16T14:20:25.608976", "ingestion_ts": "2026-01-16T14:20:56.869125", "market_id": "0x427bc4b40c09b3dcbc973747f0e4b079bed91b3e5a0aed5c36edd0f7591485f4", "raw": {"market": "0x427bc4b40c09b3dcbc973747f0e4b079bed91b3e5a0aed5c36edd0f7591485f4", "asset_id": "86130975769502911188457673769190265049139877688522439001984850068234616395137", "price": "0.992", "size": "13.32", "side": "SELL", "timestamp": "1768573225419", "received_at": "2026-01-16T14:20:25.608976"}}
{"event_type": "price_change", "event_ts": "2026-01-16T14:20:25.626090", "ingestion_ts": "2026-01-16T14:20:56.869125", "market_id": "0x427bc4b40c09b3dcbc973747f0e4b079bed91b3e5a0aed5c36edd0f7591485f4", "raw": {"market": "0x427bc4b40c09b3dcbc973747f0e4b079bed91b3e5a0aed5c36edd0f7591485f4", "asset_id": "86130975769502911188457673769190265049139877688522439001984850068234616395137", "price": "0.829", "size": "0", "side": "BUY", "timestamp": "1768573225451", "received_at": "2026-01-16T14:20:25.626090"}}
{"event_type": "price_change", "event_ts": "2026-01-16T14:20:25.626090", "ingestion_ts": "2026-01-16T14:20:56.869125", "market_id": "0x427bc4b40c09b3dcbc973747f0e4b079bed91b3e5a0aed5c36edd0f7591485f4", "raw": {"market": "0x427bc4b40c09b3dcbc973747f0e4b079bed91b3e5a0aed5c36edd0f7591485f4", "asset_id": "115669573443672055876643967408433138119481486650803218131873713375232186497057", "price": "0.171", "size": "0", "side": "SELL", "timestamp": "1768573225451", "received_at": "2026-01-16T14:20:25.626090"}}
{"event_type": "price_change", "event_ts": "2026-01-16T14:20:25.626127", "ingestion_ts": "2026-01-16T14:20:56.869125", "market_id": "0x427bc4b40c09b3dcbc973747f0e4b079bed91b3e5a0aed5c36edd0f7591485f4", "raw": {"market": "0x427bc4b40c09b3dcbc973747f0e4b079bed91b3e5a0aed5c36edd0f7591485f4", "asset_id": "86130975769502911188457673769190265049139877688522439001984850068234616395137", "price": "0.993", "size": "0", "side": "SELL", "timestamp": "1768573225451", "received_at": "2026-01-16T14:20:25.626127"}}
{"event_type": "price_change", "event_ts": "2026-01-16T14:20:25.626127", "ingestion_ts": "2026-01-16T14:20:56.869125", "market_id": "0x427bc4b40c09b3dcbc973747f0e4b079bed91b3e5a0aed5c36edd0f7591485f4", "raw": {"market": "0x427bc4b40c09b3dcbc973747f0e4b079bed91b3e5a0aed5c36edd0f7591485f4", "asset_id": "115669573443672055876643967408433138119481486650803218131873713375232186497057", "price": "0.007", "size": "0", "side": "BUY", "timestamp": "1768573225451", "received_at": "2026-01-16T14:20:25.626127"}}
{"event_type": "price_change", "event_ts": "2026-01-16T14:20:26.062660", "ingestion_ts": "2026-01-16T14:20:56.869125", "market_id": "0x427bc4b40c09b3dcbc973747f0e4b079bed91b3e5a0aed5c36edd0f7591485f4", "raw": {"market": "0x427bc4b40c09b3dcbc973747f0e4b079bed91b3e5a0aed5c36edd0f7591485f4", "asset_id": "115669573443672055876643967408433138119481486650803218131873713375232186497057", "price": "0.172", "size": "11.51", "side": "SELL", "timestamp": "1768573225997", "received_at": "2026-01-16T14:20:26.062660"}}
{"event_type": "price_change", "event_ts": "2026-01-16T14:20:26.062660", "ingestion_ts": "2026-01-16T14:20:56.869125", "market_id": "0x427bc4b40c09b3dcbc973747f0e4b079bed91b3e5a0aed5c36edd0f7591485f4", "raw": {"market": "0x427bc4b40c09b3dcbc973747f0e4b079bed91b3e5a0aed5c36edd0f7591485f4", "asset_id": "86130975769502911188457673769190265049139877688522439001984850068234616395137", "price": "0.828", "size": "11.51", "side": "BUY", "timestamp": "1768573225997", "received_at": "2026-01-16T14:20:26.062660"}}
{"event_type": "price_change", "event_ts": "2026-01-16T14:20:26.062699", "ingestion_ts": "2026-01-16T14:20:56.869125", "market_id": "0x427bc4b40c09b3dcbc973747f0e4b079bed91b3e5a0aed5c36edd0f7591485f4", "raw": {"market": "0x427bc4b40c09b3dcbc973747f0e4b079bed91b3e5a0aed5c36edd0f7591485f4", "asset_id": "115669573443672055876643967408433138119481486650803218131873713375232186497057", "price": "0.173", "size": "0", "side": "SELL", "timestamp": "1768573225997", "received_at": "2026-01-16T14:20:26.062699"}}
{"event_type": "price_change", "event_ts": "2026-01-16T14:20:26.062699", "ingestion_ts": "2026-01-16T14:20:56.869125", "market_id": "0x427bc4b40c09b3dcbc973747f0e4b079bed91b3e5a0aed5c36edd0f7591485f4", "raw": {"market": "0x427bc4b40c09b3dcbc973747f0e4b079bed91b3e5a0aed5c36edd0f7591485f4", "asset_id": "86130975769502911188457673769190265049139877688522439001984850068234616395137", "price": "0.827", "size": "0", "side": "BUY", "timestamp": "1768573225997", "received_at": "2026-01-16T14:20:26.062699"}}
{"event_type": "price_change", "event_ts": "2026-01-16T14:20:26.062712", "ingestion_ts": "2026-01-16T14:20:56.869125", "market_id": "0x427bc4b40c09b3dcbc973747f0e4b079bed91b3e5a0aed5c36edd0f7591485f4", "raw": {"market": "0x427bc4b40c09b3dcbc973747f0e4b079bed91b3e5a0aed5c36edd0f7591485f4", "asset_id": "115669573443672055876643967408433138119481486650803218131873713375232186497057", "price": "0.174", "size": "0", "side": "SELL", "timestamp": "1768573225997", "received_at": "2026-01-16T14:20:26.062712"}}
{"event_type": "price_change", "event_ts": "2026-01-16T14:20:26.062712", "ingestion_ts": "2026-01-16T14:20:56.869125", "market_id": "0x427bc4b40c09b3dcbc973747f0e4b079bed91b3e5a0aed5c36edd0f7591485f4", "raw": {"market": "0x427bc4b40c09b3dcbc973747f0e4b079bed91b3e5a0aed5c36edd0f7591485f4", "asset_id": "86130975769502911188457673769190265049139877688522439001984850068234616395137", "price": "0.826", "size": "0", "side": "BUY", "timestamp": "1768573225997", "received_at": "2026-01-16T14:20:26.062712"}}
{"event_type": "price_change", "event_ts": "2026-01-16T14:20:26.062724", "ingestion_ts": "2026-01-16T14:20:56.869125", "market_id": "0x427bc4b40c09b3dcbc973747f0e4b079bed91b3e5a0aed5c36edd0f7591485f4", "raw": {"market": "0x427bc4b40c09b3dcbc973747f0e4b079bed91b3e5a0aed5c36edd0f7591485f4", "asset_id": "115669573443672055876643967408433138119481486650803218131873713375232186497057", "price": "0.175", "size": "7.25", "side": "SELL", "timestamp": "1768573225997", "received_at": "2026-01-16T14:20:26.062724"}}
