{"event_type": "price_change", "event_ts": "2026-01-16T14:20:26.062724", "ingestion_ts": "2026-01-16T14:20:56.869125", "market_id": "0x427bc4b40c09b3dcbc973747f0e4b079bed91b3e5a0aed5c36edd0f7591485f4", "raw": {"market": "0x427bc4b40c09b3dcbc973747f0e4b079bed91b3e5a0aed5c36edd0f7591485f4", "asset_id": "86130975769502911188457673769190265049139877688522439001984850068234616395137", "price": "0.825", "size": "7.25", "side": "BUY", "timestamp": "1768573225997", "received_at": "2026-01-16T14:20:26.062724"}}
{"event_type": "price_change", "event_ts": "2026-01-16T14:20:26.062735", "ingestion_ts": "2026-01-16T14:20:56.869125", "market_id": "0x427bc4b40c09b3dcbc973747f0e4b079bed91b3e5a0aed5c36edd0f7591485f4", "raw": {"market": "0x427bc4b40c09b3dcbc973747f0e4b079bed91b3e5a0aed5c36edd0f7591485f4", "asset_id": "115669573443672055876643967408433138119481486650803218131873713375232186497057", "price": "0.176", "size": "0", "side": "SELL", "timestamp": "1768573225997", "received_at": "2026-01-16T14:20:26.062735"}}
{"event_type": "price_change", "event_ts": "2026-01-16T14:20:26.062735", "ingestion_ts": "2026-01-16T14:20:56.869125", "market_id": "0x427bc4b40c09b3dcbc973747f0e4b079bed91b3e5a0aed5c36edd0f7591485f4", "raw": {"market": "0x427bc4b40c09b3dcbc973747f0e4b079bed91b3e5a0aed5c36edd0f7591485f4", "asset_id": "86130975769502911188457673769190265049139877688522439001984850068234616395137", "price": "0.824", "size": "0", "side": "BUY", "timestamp": "1768573225997", "received_at": "2026-01-16T14:20:26.062735"}}
{"event_type": "price_change", "event_ts": "2026-01-16T14:20:26.540217", "ingestion_ts": "2026-01-16T14:20:56.869125", "market_id": "0x427bc4b40c09b3dcbc973747f0e4b079bed91b3e5a0aed5c36edd0f7591485f4", "raw": {"market": "0x427bc4b40c09b3dcbc973747f0e4b079bed91b3e5a0aed5c36edd0f7591485f4", "asset_id": "115669573443672055876643967408433138119481486650803218131873713375232186497057", "price": "0.47", "size": "62.24", "side": "SELL", "timestamp": "1768573226502", "received_at": "2026-01-16T14:20:26.540217"}}
{"event_type": "price_change", "event_ts": "2026-01-16T14:20:26.540217", "ingestion_ts": "2026-01-16T14:20:56.869125", "market_id": "0x427bc4b40c09b3dcbc973747f0e4b079bed91b3e5a0aed5c36edd0f7591485f4", "raw": {"market": "0x427bc4b40c09b3dcbc973747f0e4b079bed91b3e5a0aed5c36edd0f7591485f4", "asset_id": "86130975769502911188457673769190265049139877688522439001984850068234616395137", "price": "0.53", "size": "62.24", "side": "BUY", "timestamp": "1768573226502", "received_at": "2026-01-16T14:20:26.540217"}}
{"event_type": "price_change", "event_ts": "2026-01-16T14:20:26.540534", "ingestion_ts": "2026-01-16T14:20:56.869125", "market_id": "0x427bc4b40c09b3dcbc973747f0e4b079bed91b3e5a0aed5c36edd0f7591485f4", "raw": {"market": "0x427bc4b40c09b3dcbc973747f0e4b079bed91b3e5a0aed5c36edd0f7591485f4", "asset_id": "115669573443672055876643967408433138119481486650803218131873713375232186497057", "price": "0.47", "size": "87.09", "side": "SELL", "timestamp": "1768573226503", "received_at": "2026-01-16T14:20:26.540534"}}
{"event_type": "price_change", "event_ts": "2026-01-16T14:20:26.540534", "ingestion_ts": "2026-01-16T14:20:56.869125", "market_id": "0x427bc4b40c09b3dcbc973747f0e4b079bed91b3e5a0aed5c36edd0f7591485f4", "raw": {"market": "0x427bc4b40c09b3dcbc973747f0e4b079bed91b3e5a0aed5c36edd0f7591485f4", "asset_id": "86130975769502911188457673769190265049139877688522439001984850068234616395137", "price": "0.53", "size": "87.09", "side": "BUY", "timestamp": "1768573226503", "received_at": "2026-01-16T14:20:26.540534"}}
{"event_type": "price_change", "event_ts": "2026-01-16T14:20:26.827833", "ingestion_ts": "2026-01-16T14:20:56.869125", "market_id": "0x2393ed0b0fdc450054c7b9071907eca75cf4fc36e385adf4a0a5f99ee62243e8", "raw": {"market": "0x2393ed0b0fdc450054c7b9071907eca75cf4fc36e385adf4a0a5f99ee62243e8", "asset_id": "32769749367306925959219403371425714180265458150646381231272229429098460625924", "price": "0.95", "size": "50", "side": "BUY", "timestamp": "1768573226786", "received_at": "2026-01-16T14:20:26.827833"}}
{"event_type": "price_change", "event_ts": "2026-01-16T14:20:26.827833", "ingestion_ts": "2026-01-16T14:20:56.869125", "market_id": "0x2393ed0b0fdc450054c7b9071907eca75cf4fc36e385adf4a0a5f99ee62243e8", "raw": {"market": "0x2393ed0b0fdc450054c7b9071907eca75cf4fc36e385adf4a0a5f99ee62243e8", "asset_id": "100074770378634056601572485653252702850363676459996771990439989989293515601975", "price": "0.05", "size": "50", "side": "SELL", "timestamp": "1768573226786", "received_at": "2026-01-16T14:20:26.827833"}}
{"event_type": "price_change", "event_ts": "2026-01-16T14:20:26.865559", "ingestion_ts": "2026-01-16T14:20:56.869125", "market_id": "0x2393ed0b0fdc450054c7b9071907eca75cf4fc36e385adf4a0a5f99ee62243e8", "raw": {"market": "0x2393ed0b0fdc450054c7b9071907eca75cf4fc36e385adf4a0a5f99ee62243e8", "asset_id": "100074770378634056601572485653252702850363676459996771990439989989293515601975", "price": "0.051", "size": "0", "side": "SELL", "timestamp": "1768573226811", "received_at": "2026-01-16T14:20:26.865559"}}
{"event_type": "price_change", "event_ts": "2026-01-16T14:20:26.865559", "ingestion_ts": "2026-01-16T14:20:56.869125", "market_id": "0x2393ed0b0fdc450054c7b9071907eca75cf4fc36e385adf4a0a5f99ee62243e8", "raw": {"market": "0x2393ed0b0fdc450054c7b9071907eca75cf4fc36e385adf4a0a5f99ee62243e8", "asset_id": "32769749367306925959219403371425714180265458150646381231272229429098460625924", "price": "0.949", "size": "0", "side": "BUY", "timestamp": "1768573226811", "received_at": "2026-01-16T14:20:26.865559"}}
{"event_type": "price_change", "event_ts": "2026-01-16T14:20:26.890739", "ingestion_ts": "2026-01-16T14:20:56.869125", "market_id": "0x2393ed0b0fdc450054c7b9071907eca75cf4fc36e385adf4a0a5f99ee62243e8", "raw": {"market": "0x2393ed0b0fdc450054c7b9071907eca75cf4fc36e385adf4a0a5f99ee62243e8", "asset_id": "100074770378634056601572485653252702850363676459996771990439989989293515601975", "price": "0.049", "size": "199", "side": "SELL", "timestamp": "1768573226839", "received_at": "2026-01-16T14:20:26.890739"}}
{"event_type": "price_change", "event_ts": "2026-01-16T14:20:26.890739", "ingestion_ts": "2026-01-16T14:20:56.869125", "market_id": "0x2393ed0b0fdc450054c7b9071907eca75cf4fc36e385adf4a0a5f99ee62243e8", "raw": {"market": "0x2393ed0b0fdc450054c7b9071907eca75cf4fc36e385adf4a0a5f99ee62243e8", "asset_id": "32769749367306925959219403371425714180265458150646381231272229429098460625924", "price": "0.951", "size": "199", "side": "BUY", "timestamp": "1768573226839", "received_at": "2026-01-16T14:20:26.890739"}}
{"event_type": "price_change", "event_ts": "2026-01-16T14:20:26.933943", "ingestion_ts": "2026-01-16T14:20:56.869125", "market_id": "0x49a20c7523c271099008f3ef9a31521263b24d637959852a391e6b4697b1a437", "raw": {"market": "0x49a20c7523c271099008f3ef9a31521263b24d637959852a391e6b4697b1a437", "asset_id": "55881023621710858558280545117465775643848233756850602339827152783696837905531", "price": "0.855", "size": "0", "side": "BUY", "timestamp": "1768573226887", "received_at": "2026-01-16T14:20:26.933943"}}
{"event_type": "price_change", "event_ts": "2026-01-16T14:20:26.933943", "ingestion_ts": "2026-01-16T14:20:56.869125", "market_id": "0x49a20c7523c271099008f3ef9a31521263b24d637959852a391e6b4697b1a437", "raw": {"market": "0x49a20c7523c271099008f3ef9a31521263b24d637959852a391e6b4697b1a437", "asset_id": "13018971792603393862521629014128024641178044618205296260525674415067194037856", "price": "0.145", "size": "0", "side": "SELL", "timestamp": "1768573226887", "received_at": "2026-01-16T14:20:26.933943"}}
{"event_type": "price_change", "event_ts": "2026-01-16T14:20:26.980386", "ingestion_ts": "2026-01-16T14:20:56.869125", "market_id": "0x49686d26fb712515cd5e12c23f0a1c7e10214c7faa3cb0a730aabe0c33694082", "raw": {"market": "0x49686d26fb712515cd5e12c23f0a1c7e10214c7faa3cb0a730aabe0c33694082", "asset_id": "13244681086321087932946246027856416106585284024824496763706748621681543444582", "price": "0.854", "size": "0", "side": "BUY", "timestamp": "1768573226929", "received_at": "2026-01-16T14:20:26.980386"}}
{"event_type": "price_change", "event_ts": "2026-01-16T14:20:26.980386", "ingestion_ts": "2026-01-16T14:20:56.869125", "market_id": "0x49686d26fb712515cd5e12c23f0a1c7e10214c7faa3cb0a730aabe0c33694082", "raw": {"market": "0x49686d26fb712515cd5e12c23f0a1c7e10214c7faa3cb0a730aabe0c33694082", "asset_id": "30442780799048074404860985387051749017905070253466005720364298335239299761065", "price": "0.146", "size": "0", "side": "SELL", "timestamp": "1768573226929", "received_at": "2026-01-16T14:20:26.980386"}}
{"event_type": "price_change", "event_ts": "2026-01-16T14:20:26.997806", "ingestion_ts": "2026-01-16T14:20:56.869125", "market_id": "0x49686d26fb712515cd5e12c23f0a1c7e10214c7faa3cb0a730aabe0c33694082", "raw": {"market": "0x49686d26fb712515cd5e12c23f0a1c7e10214c7faa3cb0a730aabe0c33694082", "asset_id": "13244681086321087932946246027856416106585284024824496763706748621681543444582", "price": "0.911", "size": "132.98", "side": "SELL", "timestamp": "1768573226957", "received_at": "2026-01-16T14:20:26.997806"}}
{"event_type": "price_change", "event_ts": "2026-01-16T14:20:26.997806", "ingestion_ts": "2026-01-16T14:20:56.869125", "market_id": "0x49686d26fb712515cd5e12c23f0a1c7e10214c7faa3cb0a730aabe0c33694082", "raw": {"market": "0x49686d26fb712515cd5e12c23f0a1c7e10214c7faa3cb0a730aabe0c33694082", "asset_id": "30442780799048074404860985387051749017905070253466005720364298335239299761065", "price": "0.089", "size": "132.98", "side": "BUY", "timestamp": "1768573226957", "received_at": "2026-01-16T14:20:26.997806"}}
{"event_type": "price_change", "event_ts": "2026-01-16T14:20:27.084093", "ingestion_ts": "2026-01-16T14:20:56.869125", "market_id": "0x49a20c7523c271099008f3ef9a31521263b24d637959852a391e6b4697b1a437", "raw": {"market": "0x49a20c7523c271099008f3ef9a31521263b24d637959852a391e6b4697b1a437", "asset_id": "55881023621710858558280545117465775643848233756850602339827152783696837905531", "price": "0.857", "size": "30", "side": "BUY", "timestamp": "1768573227003", "received_at": "2026-01-16T14:20:27.084093"}}
{"event_type": "price_change", "event_ts": "2026-01-16T14:20:27.084093", "ingestion_ts": "2026-01-16T14:20:56.869125", "market_id": "0x49a20c7523c271099008f3ef9a31521263b24d637959852a391e6b4697b1a437", "raw": {"market": "0x49a20c7523c271099008f3ef9a31521263b24d637959852a391e6b4697b1a437", "asset_id": "13018971792603393862521629014128024641178044618205296260525674415067194037856", "price": "0.143", "size": "30", "side": "SELL", "timestamp": "1768573227003", "received_at": "2026-01-16T14:20:27.084093"}}
{"event_type": "price_change", "event_ts": "2026-01-16T14:20:27.178537", "ingestion_ts": "2026-01-16T14:20:56.869125", "market_id": "0x2393ed0b0fdc450054c7b9071907eca75cf4fc36e385adf4a0a5f99ee62243e8", "raw": {"market": "0x2393ed0b0fdc450054c7b9071907eca75cf4fc36e385adf4a0a5f99ee62243e8", "asset_id": "32769749367306925959219403371425714180265458150646381231272229429098460625924", "price": "0.948", "size": "0", "side": "BUY", "timestamp": "1768573227105", "received_at": "2026-01-16T14:20:27.178537"}}
{"event_type": "price_change", "event_ts": "2026-01-16T14:20:27.178537", "ingestion_ts": "2026-01-16T14:20:56.869125", "market_id": "0x2393ed0b0fdc450054c7b9071907eca75cf4fc36e385adf4a0a5f99ee62243e8", "raw": {"market": "0x2393ed0b0fdc450054c7b9071907eca75cf4fc36e385adf4a0a5f99ee62243e8", "asset_id": "100074770378634056601572485653252702850363676459996771990439989989293515601975", "price": "0.052", "size": "0", "side": "SELL", "timestamp": "1768573227105", "received_at": "2026-01-16T14:20:27.178537"}}
{"event_type": "price_change", "event_ts": "2026-01-16T14:20:27.512917", "ingestion_ts": "2026-01-16T14:20:56.869125", "market_id": "0x427bc4b40c09b3dcbc973747f0e4b079bed91b3e5a0aed5c36edd0f7591485f4", "raw": {"market": "0x427bc4b40c09b3dcbc973747f0e4b079bed91b3e5a0aed5c36edd0f7591485f4", "asset_id": "115669573443672055876643967408433138119481486650803218131873713375232186497057", "price": "0.002", "size": "99.32", "side": "BUY", "timestamp": "1768573227469", "received_at": "2026-01-16T14:20:27.512917"}}
{"event_type": "price_change", "event_ts": "2026-01-16T14:20:27.512917", "ingestion_ts": "2026-01-16T14:20:56.869125", "market_id": "0x427bc4b40c09b3dcbc973747f0e4b079bed91b3e5a0aed5c36edd0f7591485f4", "raw": {"market": "0x427bc4b40c09b3dcbc973747f0e4b079bed91b3e5a0aed5c36edd0f7591485f4", "asset_id": "86130975769502911188457673769190265049139877688522439001984850068234616395137", "price": "0.998", "size": "99.32", "side": "SELL", "timestamp": "1768573227469", "received_at": "2026-01-16T14:20:27.512917"}}
{"event_type": "price_change", "event_ts": "2026-01-16T14:20:27.512953", "ingestion_ts": "2026-01-16T14:20:56.869125", "market_id": "0x427bc4b40c09b3dcbc973747f0e4b079bed91b3e5a0aed5c36edd0f7591485f4", "raw": {"market": "0x427bc4b40c09b3dcbc973747f0e4b079bed91b3e5a0aed5c36edd0f7591485f4", "asset_id": "115669573443672055876643967408433138119481486650803218131873713375232186497057", "price": "0.003", "size": "0", "side": "BUY", "timestamp": "1768573227469", "received_at": "2026-01-16T14:20:27.512953"}}
{"event_type": "price_change", "event_ts": "2026-01-16T14:20:27.512953", "ingestion_ts": "2026-01-16T14:20:56.869125", "market_id": "0x427bc4b40c09b3dcbc973747f0e4b079bed91b3e5a0aed5c36edd0f7591485f4", "raw": {"market": "0x427bc4b40c09b3dcbc973747f0e4b079bed91b3e5a0aed5c36edd0f7591485f4", "asset_id": "86130975769502911188457673769190265049139877688522439001984850068234616395137", "price": "0.997", "size": "0", "side": "SELL", "timestamp": "1768573227469", "received_at": "2026-01-16T14:20:27.512953"}}
{"event_type": "price_change", "event_ts": "2026-01-16T14:20:27.512968", "ingestion_ts": "2026-01-16T14:20:56.869125", "market_id": "0x427bc4b40c09b3dcbc973747f0e4b079bed91b3e5a0aed5c36edd0f7591485f4", "raw": {"market": "0x427bc4b40c09b3dcbc973747f0e4b079bed91b3e5a0aed5c36edd0f7591485f4", "asset_id": "115669573443672055876643967408433138119481486650803218131873713375232186497057", "price": "0.008", "size": "6.66", "side": "BUY", "timestamp": "1768573227469", "received_at": "2026-01-16T14:20:27.512968"}}
{"event_type": "price_change", "event_ts": "2026-01-16T14:20:27.512968", "ingestion_ts": "2026-01-16T14:20:56.869125", "market_id": "0x427bc4b40c09b3dcbc973747f0e4b079bed91b3e5a0aed5c36edd0f7591485f4", "raw": {"market": "0x427bc4b40c09b3dcbc973747f0e4b079bed91b3e5a0aed5c36edd0f7591485f4", "asset_id": "86130975769502911188457673769190265049139877688522439001984850068234616395137", "price": "0.992", "size": "6.66", "side": "SELL", "timestamp": "1768573227469", "received_at": "2026-01-16T14:20:27.512968"}}
{"event_type": "price_change", "event_ts": "2026-01-16T14:20:27.739029", "ingestion_ts": "2026-01-16T14:20:56.869125", "market_id": "0x2393ed0b0fdc450054c7b9071907eca75cf4fc36e385adf4a0a5f99ee62243e8", "raw": {"market": "0x2393ed0b0fdc450054c7b9071907eca75cf4fc36e385adf4a0a5f99ee62243e8", "asset_id": "32769749367306925959219403371425714180265458150646381231272229429098460625924", "price": "0.85", "size": "0", "side": "BUY", "timestamp": "1768573227698", "received_at": "2026-01-16T14:20:27.739029"}}
{"event_type": "price_change", "event_ts": "2026-01-16T14:20:27.739029", "ingestion_ts": "2026-01-16T14:20:56.869125", "market_id": "0x2393ed0b0fdc450054c7b9071907eca75cf4fc36e385adf4a0a5f99ee62243e8", "raw": {"market": "0x2393ed0b0fdc450054c7b9071907eca75cf4fc36e385adf4a0a5f99ee62243e8", "asset_id": "100074770378634056601572485653252702850363676459996771990439989989293515601975", "price": "0.15", "size": "0", "side": "SELL", "timestamp": "1768573227698", "received_at": "2026-01-16T14:20:27.739029"}}
{"event_type": "price_change", "event_ts": "2026-01-16T14:20:27.739069", "ingestion_ts": "2026-01-16T14:20:56.869125", "market_id": "0x9472be65457510b7fc3477b20ba90910e99d92eac8421a14bf4b7b7a08ef31dc", "raw": {"market": "0x9472be65457510b7fc3477b20ba90910e99d92eac8421a14bf4b7b7a08ef31dc", "asset_id": "43311793366960417907757893276427136943959788721376762326430771171648759300146", "price": "0.859", "size": "0", "side": "BUY", "timestamp": "1768573227698", "received_at": "2026-01-16T14:20:27.739069"}}
{"event_type": "price_change", "event_ts": "2026-01-16T14:20:27.739069", "ingestion_ts": "2026-01-16T14:20:56.869125", "market_id": "0x9472be65457510b7fc3477b20ba90910e99d92eac8421a14bf4b7b7a08ef31dc", "raw": {"market": "0x9472be65457510b7fc3477b20ba90910e99d92eac8421a14bf4b7b7a08ef31dc", "asset_id": "73414222381656326204771753454630063673548497164758947581648273905027617570612", "price": "0.141", "size": "0", "side": "SELL", "timestamp": "1768573227698", "received_at": "2026-01-16T14:20:27.739069"}}
{"event_type": "price_change", "event_ts": "2026-01-16T14:20:27.739614", "ingestion_ts": "2026-01-16T14:20:56.869125", "market_id": "0xc55db914f0fd1fee18997706712c0dfd8d0369cdbef93a9fef12bd001914ca77", "raw": {"market": "0xc55db914f0fd1fee18997706712c0dfd8d0369cdbef93a9fef12bd001914ca77", "asset_id": "114600293444080540179603459515770723592661967180480327891296353898330242622833", "price": "0.86", "size": "0", "side": "BUY", "timestamp": "1768573227698", "received_at": "2026-01-16T14:20:27.739614"}}
{"event_type": "price_change", "event_ts": "2026-01-16T14:20:27.739614", "ingestion_ts": "2026-01-16T14:20:56.869125", "market_id": "0xc55db914f0fd1fee18997706712c0dfd8d0369cdbef93a9fef12bd001914ca77", "raw": {"market": "0xc55db914f0fd1fee18997706712c0dfd8d0369cdbef93a9fef12bd001914ca77", "asset_id": "72354723612769247426741660426331235762851940382312402276325808095604519806766", "price": "0.14", "size": "0", "side": "SELL", "timestamp": "1768573227698", "received_at": "2026-01-16T14:20:27.739614"}}
{"event_type": "price_change", "event_ts": "2026-01-16T14:20:27.739648", "ingestion_ts": "2026-01-16T14:20:56.869125", "market_id": "0xb9bbdd34304344dcc45803780a34c97d73a00133a5ecf70f63e1008b8abb2fca", "raw": {"market": "0xb9bbdd34304344dcc45803780a34c97d73a00133a5ecf70f63e1008b8abb2fca", "asset_id": "8682484153073832526711485265636767086525069344085206423986003504588877767339", "price": "0.851", "size": "558", "side": "BUY", "timestamp": "1768573227698", "received_at": "2026-01-16T14:20:27.739648"}}
{"event_type": "price_change", "event_ts": "2026-01-16T14:20:27.739648", "ingestion_ts": "2026-01-16T14:20:56.869125", "market_id": "0xb9bbdd34304344dcc45803780a34c97d73a00133a5ecf70f63e1008b8abb2fca", "raw": {"market": "0xb9bbdd34304344dcc45803780a34c97d73a00133a5ecf70f63e1008b8abb2fca", "asset_id": "72012724360700510767037780555710363830014634797787940282136454146828040926557", "price": "0.149", "size": "558", "side": "SELL", "timestamp": "1768573227698", "received_at": "2026-01-16T14:20:27.739648"}}
{"event_type": "price_change", "event_ts": "2026-01-16T14:20:27.739704", "ingestion_ts": "2026-01-16T14:20:56.869125", "market_id": "0x49a20c7523c271099008f3ef9a31521263b24d637959852a391e6b4697b1a437", "raw": {"market": "0x49a20c7523c271099008f3ef9a31521263b24d637959852a391e6b4697b1a437", "asset_id": "55881023621710858558280545117465775643848233756850602339827152783696837905531", "price": "0.856", "size": "0", "side": "BUY", "timestamp": "1768573227698", "received_at": "2026-01-16T14:20:27.739704"}}
{"event_type": "price_change", "event_ts": "2026-01-16T14:20:27.739704", "ingestion_ts": "2026-01-16T14:20:56.869125", "market_id": "0x49a20c7523c271099008f3ef9a31521263b24d637959852a391e6b4697b1a437", "raw": {"market": "0x49a20c7523c271099008f3ef9a31521263b24d637959852a391e6b4697b1a437", "asset_id": "13018971792603393862521629014128024641178044618205296260525674415067194037856", "price": "0.144", "size": "0", "side": "SELL", "timestamp": "1768573227698", "received_at": "2026-01-16T14:20:27.739704"}}
{"event_type": "price_change", "event_ts": "2026-01-16T14:20:27.784663", "ingestion_ts": "2026-01-16T14:20:56.869125", "market_id": "0x2393ed0b0fdc450054c7b9071907eca75cf4fc36e385adf4a0a5f99ee62243e8", "raw": {"market": "0x2393ed0b0fdc450054c7b9071907eca75cf4fc36e385adf4a0a5f99ee62243e8", "asset_id": "32769749367306925959219403371425714180265458150646381231272229429098460625924", "price": "0.849", "size": "304", "side": "BUY", "timestamp": "1768573227741", "received_at": "2026-01-16T14:20:27.784663"}}
{"event_type": "price_change", "event_ts": "2026-01-16T14:20:27.784663", "ingestion_ts": "2026-01-16T14:20:56.869125", "market_id": "0x2393ed0b0fdc450054c7b9071907eca75cf4fc36e385adf4a0a5f99ee62243e8", "raw": {"market": "0x2393ed0b0fdc450054c7b9071907eca75cf4fc36e385adf4a0a5f99ee62243e8", "asset_id": "100074770378634056601572485653252702850363676459996771990439989989293515601975", "price": "0.151", "size": "304", "side": "SELL", "timestamp": "1768573227741", "received_at": "2026-01-16T14:20:27.784663"}}
{"event_type": "price_change", "event_ts": "2026-01-16T14:20:27.784722", "ingestion_ts": "2026-01-16T14:20:56.869125", "market_id": "0xb9bbdd34304344dcc45803780a34c97d73a00133a5ecf70f63e1008b8abb2fca", "raw": {"market": "0xb9bbdd34304344dcc45803780a34c97d73a00133a5ecf70f63e1008b8abb2fca", "asset_id": "8682484153073832526711485265636767086525069344085206423986003504588877767339", "price": "0.839", "size": "10", "side": "BUY", "timestamp": "1768573227741", "received_at": "2026-01-16T14:20:27.784722"}}
{"event_type": "price_change", "event_ts": "2026-01-16T14:20:27.784722", "ingestion_ts": "2026-01-16T14:20:56.869125", "market_id": "0xb9bbdd34304344dcc45803780a34c97d73a00133a5ecf70f63e1008b8abb2fca", "raw": {"market": "0xb9bbdd34304344dcc45803780a34c97d73a00133a5ecf70f63e1008b8abb2fca", "asset_id": "72012724360700510767037780555710363830014634797787940282136454146828040926557", "price": "0.161", "size": "10", "side": "SELL", "timestamp": "1768573227741", "received_at": "2026-01-16T14:20:27.784722"}}
{"event_type": "price_change", "event_ts": "2026-01-16T14:20:27.784737", "ingestion_ts": "2026-01-16T14:20:56.869125", "market_id": "0x49a20c7523c271099008f3ef9a31521263b24d637959852a391e6b4697b1a437", "raw": {"market": "0x49a20c7523c271099008f3ef9a31521263b24d637959852a391e6b4697b1a437", "asset_id": "55881023621710858558280545117465775643848233756850602339827152783696837905531", "price": "0.857", "size": "40", "side": "BUY", "timestamp": "1768573227742", "received_at": "2026-01-16T14:20:27.784737"}}
{"event_type": "price_change", "event_ts": "2026-01-16T14:20:27.784737", "ingestion_ts": "2026-01-16T14:20:56.869125", "market_id": "0x49a20c7523c271099008f3ef9a31521263b24d637959852a391e6b4697b1a437", "raw": {"market": "0x49a20c7523c271099008f3ef9a31521263b24d637959852a391e6b4697b1a437", "asset_id": "13018971792603393862521629014128024641178044618205296260525674415067194037856", "price": "0.143", "size": "40", "side": "SELL", "timestamp": "1768573227742", "received_at": "2026-01-16T14:20:27.784737"}}
{"event_type": "price_change", "event_ts": "2026-01-16T14:20:27.784750", "ingestion_ts": "2026-01-16T14:20:56.869125", "market_id": "0xc55db914f0fd1fee18997706712c0dfd8d0369cdbef93a9fef12bd001914ca77", "raw": {"market": "0xc55db914f0fd1fee18997706712c0dfd8d0369cdbef93a9fef12bd001914ca77", "asset_id": "114600293444080540179603459515770723592661967180480327891296353898330242622833", "price": "0.859", "size": "40", "side": "BUY", "timestamp": "1768573227742", "received_at": "2026-01-16T14:20:27.784750"}}
{"event_type": "price_change", "event_ts": "2026-01-16T14:20:27.784750", "ingestion_ts": "2026-01-16T14:20:56.869125", "market_id": "0xc55db914f0fd1fee18997706712c0dfd8d0369cdbef93a9fef12bd001914ca77", "raw": {"market": "0xc55db914f0fd1fee18997706712c0dfd8d0369cdbef93a9fef12bd001914ca77", "asset_id": "72354723612769247426741660426331235762851940382312402276325808095604519806766", "price": "0.141", "size": "40", "side": "SELL", "timestamp": "1768573227742", "received_at": "2026-01-16T14:20:27.784750"}}
{"event_type": "price_change", "event_ts": "2026-01-16T14:20:27.784762", "ingestion_ts": "2026-01-16T14:20:56.869125", "market_id": "0x9472be65457510b7fc3477b20ba90910e99d92eac8421a14bf4b7b7a08ef31dc", "raw": {"market": "0x9472be65457510b7fc3477b20ba90910e99d92eac8421a14bf4b7b7a08ef31dc", "asset_id": "43311793366960417907757893276427136943959788721376762326430771171648759300146", "price": "0.858", "size": "243", "side": "BUY", "timestamp": "1768573227742", "received_at": "2026-01-16T14:20:27.784762"}}
{"event_type": "price_change", "event_ts": "2026-01-16T14:20:27.784762", "ingestion_ts": "2026-01-16T14:20:56.869125", "market_id": "0x9472be65457510b7fc3477b20ba90910e99d92eac8421a14bf4b7b7a08ef31dc", "raw": {"market": "0x9472be65457510b7fc3477b20ba90910e99d92eac8421a14bf4b7b7a08ef31dc", "asset_id": "73414222381656326204771753454630063673548497164758947581648273905027617570612", "price": "0.142", "size": "243", "side": "SELL", "timestamp": "1768573227742", "received_at": "2026-01-16T14:20:27.784762"}}
{"event_type": "price_change", "event_ts": "2026-01-16T14:20:27.927594", "ingestion_ts": "2026-01-16T14:20:56.869125", "market_id": "0x427bc4b40c09b3dcbc973747f0e4b079bed91b3e5a0aed5c36edd0f7591485f4", "raw": {"market": "0x427bc4b40c09b3dcbc973747f0e4b079bed91b3e5a0aed5c36edd0f7591485f4", "asset_id": "115669573443672055876643967408433138119481486650803218131873713375232186497057", "price": "0.006", "size": "20.97", "side": "BUY", "timestamp": "1768573227890", "received_at": "2026-01-16T14:20:27.927594"}}
{"event_type": "price_change", "event_ts": "2026-01-16T14:20:27.927594", "ingestion_ts": "2026-01-16T14:20:56.869125", "market_id": "0x427bc4b40c09b3dcbc973747f0e4b079bed91b3e5a0aed5c36edd0f7591485f4", "raw": {"market": "0x427bc4b40c09b3dcbc973747f0e4b079bed91b3e5a0aed5c36edd0f7591485f4", "asset_id": "86130975769502911188457673769190265049139877688522439001984850068234616395137", "price": "0.994", "size": "20.97", "side": "SELL", "timestamp": "1768573227890", "received_at": "2026-01-16T14:20:27.927594"}}
{"event_type": "price_change", "event_ts": "2026-01-16T14:20:27.928394", "ingestion_ts": "2026-01-16T14:20:56.869125", "market_id": "0x427bc4b40c09b3dcbc973747f0e4b079bed91b3e5a0aed5c36edd0f7591485f4", "raw": {"market": "0x427bc4b40c09b3dcbc973747f0e4b079bed91b3e5a0aed5c36edd0f7591485f4", "asset_id": "115669573443672055876643967408433138119481486650803218131873713375232186497057", "price": "0.006", "size": "26.2", "side": "BUY", "timestamp": "1768573227892", "received_at": "2026-01-16T14:20:27.928394"}}
{"event_type": "price_change", "event_ts": "2026-01-16T14:20:27.928394", "ingestion_ts": "2026-01-16T14:20:56.869125", "market_id": "0x427bc4b40c09b3dcbc973747f0e4b079bed91b3e5a0aed5c36edd0f7591485f4", "raw": {"market": "0x427bc4b40c09b3dcbc973747f0e4b079bed91b3e5a0aed5c36edd0f7591485f4", "asset_id": "86130975769502911188457673769190265049139877688522439001984850068234616395137", "price": "0.994", "size": "26.2", "side": "SELL", "timestamp": "1768573227892", "received_at": "2026-01-16T14:20:27.928394"}}
{"event_type": "price_change", "event_ts": "2026-01-16T14:20:27.930151", "ingestion_ts": "2026-01-16T14:20:56.869125", "market_id": "0x427bc4b40c09b3dcbc973747f0e4b079bed91b3e5a0aed5c36edd0f7591485f4", "raw": {"market": "0x427bc4b40c09b3dcbc973747f0e4b079bed91b3e5a0aed5c36edd0f7591485f4", "asset_id": "115669573443672055876643967408433138119481486650803218131873713375232186497057", "price": "0.003", "size": "5.9", "side": "BUY", "timestamp": "1768573227893", "received_at": "2026-01-16T14:20:27.930151"}}
{"event_type": "price_change", "event_ts": "2026-01-16T14:20:27.930151", "ingestion_ts": "2026-01-16T14:20:56.869125", "market_id": "0x427bc4b40c09b3dcbc973747f0e4b079bed91b3e5a0aed5c36edd0f7591485f4", "raw": {"market": "0x427bc4b40c09b3dcbc973747f0e4b079bed91b3e5a0aed5c36edd0f7591485f4", "asset_id": "86130975769502911188457673769190265049139877688522439001984850068234616395137", "price": "0.997", "size": "5.9", "side": "SELL", "timestamp": "1768573227893", "received_at": "2026-01-16T14:20:27.930151"}}
{"event_type": "price_change", "event_ts": "2026-01-16T14:20:27.930842", "ingestion_ts": "2026-01-16T14:20:56.869125", "market_id": "0x427bc4b40c09b3dcbc973747f0e4b079bed91b3e5a0aed5c36edd0f7591485f4", "raw": {"market": "0x427bc4b40c09b3dcbc973747f0e4b079bed91b3e5a0aed5c36edd0f7591485f4", "asset_id": "115669573443672055876643967408433138119481486650803218131873713375232186497057", "price": "0.003", "size": "11.8", "side": "BUY", "timestamp": "1768573227894", "received_at": "2026-01-16T14:20:27.930842"}}
{"event_type": "price_change", "event_ts": "2026-01-16T14:20:27.930842", "ingestion_ts": "2026-01-16T14:20:56.869125", "market_id": "0x427bc4b40c09b3dcbc973747f0e4b079bed91b3e5a0aed5c36edd0f7591485f4", "raw": {"market": "0x427bc4b40c09b3dcbc973747f0e4b079bed91b3e5a0aed5c36edd0f7591485f4", "asset_id": "86130975769502911188457673769190265049139877688522439001984850068234616395137", "price": "0.997", "size": "11.8", "side": "SELL", "timestamp": "1768573227894", "received_at": "2026-01-16T14:20:27.930842"}}
{"event_type": "price_change", "event_ts": "2026-01-16T14:20:28.502379", "ingestion_ts": "2026-01-16T14:20:56.869125", "market_id": "0x427bc4b40c09b3dcbc973747f0e4b079bed91b3e5a0aed5c36edd0f7591485f4", "raw": {"market": "0x427bc4b40c09b3dcbc973747f0e4b079bed91b3e5a0aed5c36edd0f7591485f4", "asset_id": "115669573443672055876643967408433138119481486650803218131873713375232186497057", "price": "0.172", "size": "0", "side": "SELL", "timestamp": "1768573228409", "received_at": "2026-01-16T14:20:28.502379"}}
{"event_type": "price_change", "event_ts": "2026-01-16T14:20:28.502379", "ingestion_ts": "2026-01-16T14:20:56.869125", "market_id": "0x427bc4b40c09b3dcbc973747f0e4b079bed91b3e5a0aed5c36edd0f7591485f4", "raw": {"market": "0x427bc4b40c09b3dcbc973747f0e4b079bed91b3e5a0aed5c36edd0f7591485f4", "asset_id": "86130975769502911188457673769190265049139877688522439001984850068234616395137", "price": "0.828", "size": "0", "side": "BUY", "timestamp": "1768573228409", "received_at": "2026-01-16T14:20:28.502379"}}
{"event_type": "price_change", "event_ts": "2026-01-16T14:20:28.502434", "ingestion_ts": "2026-01-16T14:20:56.869125", "market_id": "0x427bc4b40c09b3dcbc973747f0e4b079bed91b3e5a0aed5c36edd0f7591485f4", "raw": {"market": "0x427bc4b40c09b3dcbc973747f0e4b079bed91b3e5a0aed5c36edd0f7591485f4", "asset_id": "115669573443672055876643967408433138119481486650803218131873713375232186497057", "price": "0.175", "size": "0", "side": "SELL", "timestamp": "1768573228409", "received_at": "2026-01-16T14:20:28.502434"}}
{"event_type": "price_change", "event_ts": "2026-01-16T14:20:28.502434", "ingestion_ts": "2026-01-16T14:20:56.869125", "market_id": "0x427bc4b40c09b3dcbc973747f0e4b079bed91b3e5a0aed5c36edd0f7591485f4", "raw": {"market": "0x427bc4b40c09b3dcbc973747f0e4b079bed91b3e5a0aed5c36edd0f7591485f4", "asset_id": "86130975769502911188457673769190265049139877688522439001984850068234616395137", "price": "0.825", "size": "0", "side": "BUY", "timestamp": "1768573228409", "received_at": "2026-01-16T14:20:28.502434"}}
{"event_type": "price_change", "event_ts": "2026-01-16T14:20:28.711718", "ingestion_ts": "2026-01-16T14:20:56.869125", "market_id": "0x427bc4b40c09b3dcbc973747f0e4b079bed91b3e5a0aed5c36edd0f7591485f4", "raw": {"market": "0x427bc4b40c09b3dcbc973747f0e4b079bed91b3e5a0aed5c36edd0f7591485f4", "asset_id": "115669573443672055876643967408433138119481486650803218131873713375232186497057", "price": "0.174", "size": "7.25", "side": "SELL", "timestamp": "1768573228667", "received_at": "2026-01-16T14:20:28.711718"}}
{"event_type": "price_change", "event_ts": "2026-01-16T14:20:28.711718", "ingestion_ts": "2026-01-16T14:20:56.869125", "market_id": "0x427bc4b40c09b3dcbc973747f0e4b079bed91b3e5a0aed5c36edd0f7591485f4", "raw": {"market": "0x427bc4b40c09b3dcbc973747f0e4b079bed91b3e5a0aed5c36edd0f7591485f4", "asset_id": "86130975769502911188457673769190265049139877688522439001984850068234616395137", "price": "0.826", "size": "7.25", "side": "BUY", "timestamp": "1768573228667", "received_at": "2026-01-16T14:20:28.711718"}}
{"event_type": "price_change", "event_ts": "2026-01-16T14:20:28.712304", "ingestion_ts": "2026-01-16T14:20:56.869125", "market_id": "0x427bc4b40c09b3dcbc973747f0e4b079bed91b3e5a0aed5c36edd0f7591485f4", "raw": {"market": "0x427bc4b40c09b3dcbc973747f0e4b079bed91b3e5a0aed5c36edd0f7591485f4", "asset_id": "115669573443672055876643967408433138119481486650803218131873713375232186497057", "price": "0.171", "size": "5.75", "side": "SELL", "timestamp": "1768573228669", "received_at": "2026-01-16T14:20:28.712304"}}
{"event_type": "price_change", "event_ts": "2026-01-16T14:20:28.712304", "ingestion_ts": "2026-01-16T14:20:56.869125", "market_id": "0x427bc4b40c09b3dcbc973747f0e4b079bed91b3e5a0aed5c36edd0f7591485f4", "raw": {"market": "0x427bc4b40c09b3dcbc973747f0e4b079bed91b3e5a0aed5c36edd0f7591485f4", "asset_id": "86130975769502911188457673769190265049139877688522439001984850068234616395137", "price": "0.829", "size": "5.75", "side": "BUY", "timestamp": "1768573228669", "received_at": "2026-01-16T14:20:28.712304"}}
{"event_type": "price_change", "event_ts": "2026-01-16T14:20:28.719993", "ingestion_ts": "2026-01-16T14:20:56.869125", "market_id": "0x427bc4b40c09b3dcbc973747f0e4b079bed91b3e5a0aed5c36edd0f7591485f4", "raw": {"market": "0x427bc4b40c09b3dcbc973747f0e4b079bed91b3e5a0aed5c36edd0f7591485f4", "asset_id": "115669573443672055876643967408433138119481486650803218131873713375232186497057", "price": "0.171", "size": "11.5", "side": "SELL", "timestamp": "1768573228670", "received_at": "2026-01-16T14:20:28.719993"}}
{"event_type": "price_change", "event_ts": "2026-01-16T14:20:28.719993", "ingestion_ts": "2026-01-16T14:20:56.869125", "market_id": "0x427bc4b40c09b3dcbc973747f0e4b079bed91b3e5a0aed5c36edd0f7591485f4", "raw": {"market": "0x427bc4b40c09b3dcbc973747f0e4b079bed91b3e5a0aed5c36edd0f7591485f4", "asset_id": "86130975769502911188457673769190265049139877688522439001984850068234616395137", "price": "0.829", "size": "11.5", "side": "BUY", "timestamp": "1768573228670", "received_at": "2026-01-16T14:20:28.719993"}}
{"event_type": "price_change", "event_ts": "2026-01-16T14:20:29.779453", "ingestion_ts": "2026-01-16T14:20:56.869125", "market_id": "0x427bc4b40c09b3dcbc973747f0e4b079bed91b3e5a0aed5c36edd0f7591485f4", "raw": {"market": "0x427bc4b40c09b3dcbc973747f0e4b079bed91b3e5a0aed5c36edd0f7591485f4", "asset_id": "115669573443672055876643967408433138119481486650803218131873713375232186497057", "price": "0.003", "size": "5.9", "side": "BUY", "timestamp": "1768573229735", "received_at": "2026-01-16T14:20:29.779453"}}
{"event_type": "price_change", "event_ts": "2026-01-16T14:20:29.779453", "ingestion_ts": "2026-01-16T14:20:56.869125", "market_id": "0x427bc4b40c09b3dcbc973747f0e4b079bed91b3e5a0aed5c36edd0f7591485f4", "raw": {"market": "0x427bc4b40c09b3dcbc973747f0e4b079bed91b3e5a0aed5c36edd0f7591485f4", "asset_id": "86130975769502911188457673769190265049139877688522439001984850068234616395137", "price": "0.997", "size": "5.9", "side": "SELL", "timestamp": "1768573229735", "received_at": "2026-01-16T14:20:29.779453"}}
{"event_type": "price_change", "event_ts": "2026-01-16T14:20:29.779489", "ingestion_ts": "2026-01-16T14:20:56.869125", "market_id": "0x427bc4b40c09b3dcbc973747f0e4b079bed91b3e5a0aed5c36edd0f7591485f4", "raw": {"market": "0x427bc4b40c09b3dcbc973747f0e4b079bed91b3e5a0aed5c36edd0f7591485f4", "asset_id": "115669573443672055876643967408433138119481486650803218131873713375232186497057", "price": "0.008", "size": "0", "side": "BUY", "timestamp": "1768573229735", "received_at": "2026-01-16T14:20:29.779489"}}
{"event_type": "price_change", "event_ts": "2026-01-16T14:20:29.779489", "ingestion_ts": "2026-01-16T14:20:56.869125", "market_id": "0x427bc4b40c09b3dcbc973747f0e4b079bed91b3e5a0aed5c36edd0f7591485f4", "raw": {"market": "0x427bc4b40c09b3dcbc973747f0e4b079bed91b3e5a0aed5c36edd0f7591485f4", "asset_id": "86130975769502911188457673769190265049139877688522439001984850068234616395137", "price": "0.992", "size": "0", "side": "SELL", "timestamp": "1768573229735", "received_at": "2026-01-16T14:20:29.779489"}}
{"event_type": "price_change", "event_ts": "2026-01-16T14:20:29.813383", "ingestion_ts": "2026-01-16T14:20:56.869125", "market_id": "0x427bc4b40c09b3dcbc973747f0e4b079bed91b3e5a0aed5c36edd0f7591485f4", "raw": {"market": "0x427bc4b40c09b3dcbc973747f0e4b079bed91b3e5a0aed5c36edd0f7591485f4", "asset_id": "86130975769502911188457673769190265049139877688522439001984850068234616395137", "price": "0.83", "size": "44", "side": "BUY", "timestamp": "1768573229766", "received_at": "2026-01-16T14:20:29.813383"}}
{"event_type": "price_change", "event_ts": "2026-01-16T14:20:29.813383", "ingestion_ts": "2026-01-16T14:20:56.869125", "market_id": "0x427bc4b40c09b3dcbc973747f0e4b079bed91b3e5a0aed5c36edd0f7591485f4", "raw": {"market": "0x427bc4b40c09b3dcbc973747f0e4b079bed91b3e5a0aed5c36edd0f7591485f4", "asset_id": "115669573443672055876643967408433138119481486650803218131873713375232186497057", "price": "0.17", "size": "44", "side": "SELL", "timestamp": "1768573229766", "received_at": "2026-01-16T14:20:29.813383"}}
{"event_type": "price_change", "event_ts": "2026-01-16T14:20:29.815260", "ingestion_ts": "2026-01-16T14:20:56.869125", "market_id": "0x427bc4b40c09b3dcbc973747f0e4b079bed91b3e5a0aed5c36edd0f7591485f4", "raw": {"market": "0x427bc4b40c09b3dcbc973747f0e4b079bed91b3e5a0aed5c36edd0f7591485f4", "asset_id": "86130975769502911188457673769190265049139877688522439001984850068234616395137", "price": "0.993", "size": "44", "side": "SELL", "timestamp": "1768573229771", "received_at": "2026-01-16T14:20:29.815260"}}
{"event_type": "price_change", "event_ts": "2026-01-16T14:20:29.815260", "ingestion_ts": "2026-01-16T14:20:56.869125", "market_id": "0x427bc4b40c09b3dcbc973747f0e4b079bed91b3e5a0aed5c36edd0f7591485f4", "raw": {"market": "0x427bc4b40c09b3dcbc973747f0e4b079bed91b3e5a0aed5c36edd0f7591485f4", "asset_id": "115669573443672055876643967408433138119481486650803218131873713375232186497057", "price": "0.007", "size": "44", "side": "BUY", "timestamp": "1768573229771", "received_at": "2026-01-16T14:20:29.815260"}}
{"event_type": "price_change", "event_ts": "2026-01-16T14:20:29.949134", "ingestion_ts": "2026-01-16T14:20:56.869125", "market_id": "0xae5584fbb57f23c1c608d544b656f23d8bf12340cef70811cf31bb0cb4fc2115", "raw": {"market": "0xae5584fbb57f23c1c608d544b656f23d8bf12340cef70811cf31bb0cb4fc2115", "asset_id": "42278252558046940014991595990628759801692726198478046188873057685686228021663", "price": "0.99", "size": "8199.8", "side": "SELL", "timestamp": "1768573229902", "received_at": "2026-01-16T14:20:29.949134"}}
{"event_type": "price_change", "event_ts": "2026-01-16T14:20:29.949134", "ingestion_ts": "2026-01-16T14:20:56.869125", "market_id": "0xae5584fbb57f23c1c608d544b656f23d8bf12340cef70811cf31bb0cb4fc2115", "raw": {"market": "0xae5584fbb57f23c1c608d544b656f23d8bf12340cef70811cf31bb0cb4fc2115", "asset_id": "28946595841244317705636126646676849578876740730186646421280828201004700559420", "price": "0.01", "size": "8199.8", "side": "BUY", "timestamp": "1768573229902", "received_at": "2026-01-16T14:20:29.949134"}}
{"event_type": "price_change", "event_ts": "2026-01-16T14:20:30.049191", "ingestion_ts": "2026-01-16T14:20:56.869125", "market_id": "0xae5584fbb57f23c1c608d544b656f23d8bf12340cef70811cf31bb0cb4fc2115", "raw": {"market": "0xae5584fbb57f23c1c608d544b656f23d8bf12340cef70811cf31bb0cb4fc2115", "asset_id": "28946595841244317705636126646676849578876740730186646421280828201004700559420", "price": "0.01", "size": "8247.6", "side": "BUY", "timestamp": "1768573230001", "received_at": "2026-01-16T14:20:30.049191"}}
{"event_type": "price_change", "event_ts": "2026-01-16T14:20:30.049191", "ingestion_ts": "2026-01-16T14:20:56.869125", "market_id": "0xae5584fbb57f23c1c608d544b656f23d8bf12340cef70811cf31bb0cb4fc2115", "raw": {"market": "0xae5584fbb57f23c1c608d544b656f23d8bf12340cef70811cf31bb0cb4fc2115", "asset_id": "42278252558046940014991595990628759801692726198478046188873057685686228021663", "price": "0.99", "size": "8247.6", "side": "SELL", "timestamp": "1768573230001", "received_at": "2026-01-16T14:20:30.049191"}}
{"event_type": "price_change", "event_ts": "2026-01-16T14:20:30.634130", "ingestion_ts": "2026-01-16T14:20:56.869125", "market_id": "0x427bc4b40c09b3dcbc973747f0e4b079bed91b3e5a0aed5c36edd0f7591485f4", "raw": {"market": "0x427bc4b40c09b3dcbc973747f0e4b079bed91b3e5a0aed5c36edd0f7591485f4", "asset_id": "115669573443672055876643967408433138119481486650803218131873713375232186497057", "price": "0.171", "size": "5.75", "side": "SELL", "timestamp": "1768573230595", "received_at": "2026-01-16T14:20:30.634130"}}
{"event_type": "price_change", "event_ts": "2026-01-16T14:20:30.634130", "ingestion_ts": "2026-01-16T14:20:56.869125", "market_id": "0x427bc4b40c09b3dcbc973747f0e4b079bed91b3e5a0aed5c36edd0f7591485f4", "raw": {"market": "0x427bc4b40c09b3dcbc973747f0e4b079bed91b3e5a0aed5c36edd0f7591485f4", "asset_id": "86130975769502911188457673769190265049139877688522439001984850068234616395137", "price": "0.829", "size": "5.75", "side": "BUY", "timestamp": "1768573230595", "received_at": "2026-01-16T14:20:30.634130"}}
{"event_type": "price_change", "event_ts": "2026-01-16T14:20:30.637296", "ingestion_ts": "2026-01-16T14:20:56.869125", "market_id": "0x427bc4b40c09b3dcbc973747f0e4b079bed91b3e5a0aed5c36edd0f7591485f4", "raw": {"market": "0x427bc4b40c09b3dcbc973747f0e4b079bed91b3e5a0aed5c36edd0f7591485f4", "asset_id": "115669573443672055876643967408433138119481486650803218131873713375232186497057", "price": "0.174", "size": "0", "side": "SELL", "timestamp": "1768573230595", "received_at": "2026-01-16T14:20:30.637296"}}
{"event_type": "price_change", "event_ts": "2026-01-16T14:20:30.637296", "ingestion_ts": "2026-01-16T14:20:56.869125", "market_id": "0x427bc4b40c09b3dcbc973747f0e4b079bed91b3e5a0aed5c36edd0f7591485f4", "raw": {"market": "0x427bc4b40c09b3dcbc973747f0e4b079bed91b3e5a0aed5c36edd0f7591485f4", "asset_id": "86130975769502911188457673769190265049139877688522439001984850068234616395137", "price": "0.826", "size": "0", "side": "BUY", "timestamp": "1768573230595", "received_at": "2026-01-16T14:20:30.637296"}}
{"event_type": "price_change", "event_ts": "2026-01-16T14:20:30.637343", "ingestion_ts": "2026-01-16T14:20:56.869125", "market_id": "0x427bc4b40c09b3dcbc973747f0e4b079bed91b3e5a0aed5c36edd0f7591485f4", "raw": {"market": "0x427bc4b40c09b3dcbc973747f0e4b079bed91b3e5a0aed5c36edd0f7591485f4", "asset_id": "115669573443672055876643967408433138119481486650803218131873713375232186497057", "price": "0.47", "size": "62.24", "side": "SELL", "timestamp": "1768573230595", "received_at": "2026-01-16T14:20:30.637343"}}
{"event_type": "price_change", "event_ts": "2026-01-16T14:20:30.637343", "ingestion_ts": "2026-01-16T14:20:56.869125", "market_id": "0x427bc4b40c09b3dcbc973747f0e4b079bed91b3e5a0aed5c36edd0f7591485f4", "raw": {"market": "0x427bc4b40c09b3dcbc973747f0e4b079bed91b3e5a0aed5c36edd0f7591485f4", "asset_id": "86130975769502911188457673769190265049139877688522439001984850068234616395137", "price": "0.53", "size": "62.24", "side": "BUY", "timestamp": "1768573230595", "received_at": "2026-01-16T14:20:30.637343"}}
{"event_type": "price_change", "event_ts": "2026-01-16T14:20:30.975623", "ingestion_ts": "2026-01-16T14:20:56.869125", "market_id": "0x427bc4b40c09b3dcbc973747f0e4b079bed91b3e5a0aed5c36edd0f7591485f4", "raw": {"market": "0x427bc4b40c09b3dcbc973747f0e4b079bed91b3e5a0aed5c36edd0f7591485f4", "asset_id": "115669573443672055876643967408433138119481486650803218131873713375232186497057", "price": "0.169", "size": "18.93", "side": "SELL", "timestamp": "1768573230936", "received_at": "2026-01-16T14:20:30.975623"}}
{"event_type": "price_change", "event_ts": "2026-01-16T14:20:30.975623", "ingestion_ts": "2026-01-16T14:20:56.869125", "market_id": "0x427bc4b40c09b3dcbc973747f0e4b079bed91b3e5a0aed5c36edd0f7591485f4", "raw": {"market": "0x427bc4b40c09b3dcbc973747f0e4b079bed91b3e5a0aed5c36edd0f7591485f4", "asset_id": "86130975769502911188457673769190265049139877688522439001984850068234616395137", "price": "0.831", "size": "18.93", "side": "BUY", "timestamp": "1768573230936", "received_at": "2026-01-16T14:20:30.975623"}}
{"event_type": "price_change", "event_ts": "2026-01-16T14:20:30.976060", "ingestion_ts": "2026-01-16T14:20:56.869125", "market_id": "0x427bc4b40c09b3dcbc973747f0e4b079bed91b3e5a0aed5c36edd0f7591485f4", "raw": {"market": "0x427bc4b40c09b3dcbc973747f0e4b079bed91b3e5a0aed5c36edd0f7591485f4", "asset_id": "115669573443672055876643967408433138119481486650803218131873713375232186497057", "price": "0.169", "size": "37.86", "side": "SELL", "timestamp": "1768573230938", "received_at": "2026-01-16T14:20:30.976060"}}
{"event_type": "price_change", "event_ts": "2026-01-16T14:20:30.976060", "ingestion_ts": "2026-01-16T14:20:56.869125", "market_id": "0x427bc4b40c09b3dcbc973747f0e4b079bed91b3e5a0aed5c36edd0f7591485f4", "raw": {"market": "0x427bc4b40c09b3dcbc973747f0e4b079bed91b3e5a0aed5c36edd0f7591485f4", "asset_id": "86130975769502911188457673769190265049139877688522439001984850068234616395137", "price": "0.831", "size": "37.86", "side": "BUY", "timestamp": "1768573230938", "received_at": "2026-01-16T14:20:30.976060"}}
{"event_type": "price_change", "event_ts": "2026-01-16T14:20:31.008280", "ingestion_ts": "2026-01-16T14:20:56.869125", "market_id": "0x427bc4b40c09b3dcbc973747f0e4b079bed91b3e5a0aed5c36edd0f7591485f4", "raw": {"market": "0x427bc4b40c09b3dcbc973747f0e4b079bed91b3e5a0aed5c36edd0f7591485f4", "asset_id": "86130975769502911188457673769190265049139877688522439001984850068234616395137", "price": "0.83", "size": "0", "side": "BUY", "timestamp": "1768573230964", "received_at": "2026-01-16T14:20:31.008280"}}
{"event_type": "price_change", "event_ts": "2026-01-16T14:20:31.008280", "ingestion_ts": "2026-01-16T14:20:56.869125", "market_id": "0x427bc4b40c09b3dcbc973747f0e4b079bed91b3e5a0aed5c36edd0f7591485f4", "raw": {"market": "0x427bc4b40c09b3dcbc973747f0e4b079bed91b3e5a0aed5c36edd0f7591485f4", "asset_id": "115669573443672055876643967408433138119481486650803218131873713375232186497057", "price": "0.17", "size": "0", "side": "SELL", "timestamp": "1768573230964", "received_at": "2026-01-16T14:20:31.008280"}}
{"event_type": "price_change", "event_ts": "2026-01-16T14:20:31.062621", "ingestion_ts": "2026-01-16T14:20:56.869125", "market_id": "0x427bc4b40c09b3dcbc973747f0e4b079bed91b3e5a0aed5c36edd0f7591485f4", "raw": {"market": "0x427bc4b40c09b3dcbc973747f0e4b079bed91b3e5a0aed5c36edd0f7591485f4", "asset_id": "86130975769502911188457673769190265049139877688522439001984850068234616395137", "price": "0.832", "size": "35", "side": "BUY", "timestamp": "1768573231007", "received_at": "2026-01-16T14:20:31.062621"}}
{"event_type": "price_change", "event_ts": "2026-01-16T14:20:31.062621", "ingestion_ts": "2026-01-16T14:20:56.869125", "market_id": "0x427bc4b40c09b3dcbc973747f0e4b079bed91b3e5a0aed5c36edd0f7591485f4", "raw": {"market": "0x427bc4b40c09b3dcbc973747f0e4b079bed91b3e5a0aed5c36edd0f7591485f4", "asset_id": "115669573443672055876643967408433138119481486650803218131873713375232186497057", "price": "0.168", "size": "35", "side": "SELL", "timestamp": "1768573231007", "received_at": "2026-01-16T14:20:31.062621"}}
{"event_type": "price_change", "event_ts": "2026-01-16T14:20:31.512141", "ingestion_ts": "2026-01-16T14:20:56.869125", "market_id": "0x427bc4b40c09b3dcbc973747f0e4b079bed91b3e5a0aed5c36edd0f7591485f4", "raw": {"market": "0x427bc4b40c09b3dcbc973747f0e4b079bed91b3e5a0aed5c36edd0f7591485f4", "asset_id": "115669573443672055876643967408433138119481486650803218131873713375232186497057", "price": "0.003", "size": "0", "side": "BUY", "timestamp": "1768573231472", "received_at": "2026-01-16T14:20:31.512141"}}
{"event_type": "price_change", "event_ts": "2026-01-16T14:20:31.512141", "ingestion_ts": "2026-01-16T14:20:56.869125", "market_id": "0x427bc4b40c09b3dcbc973747f0e4b079bed91b3e5a0aed5c36edd0f7591485f4", "raw": {"market": "0x427bc4b40c09b3dcbc973747f0e4b079bed91b3e5a0aed5c36edd0f7591485f4", "asset_id": "86130975769502911188457673769190265049139877688522439001984850068234616395137", "price": "0.997", "size": "0", "side": "SELL", "timestamp": "1768573231472", "received_at": "2026-01-16T14:20:31.512141"}}
{"event_type": "price_change", "event_ts": "2026-01-16T14:20:31.512191", "ingestion_ts": "2026-01-16T14:20:56.869125", "market_id": "0x427bc4b40c09b3dcbc973747f0e4b079bed91b3e5a0aed5c36edd0f7591485f4", "raw": {"market": "0x427bc4b40c09b3dcbc973747f0e4b079bed91b3e5a0aed5c36edd0f7591485f4", "asset_id": "115669573443672055876643967408433138119481486650803218131873713375232186497057", "price": "0.006", "size": "20.8", "side": "BUY", "timestamp": "1768573231472", "received_at": "2026-01-16T14:20:31.512191"}}
{"event_type": "price_change", "event_ts": "2026-01-16T14:20:31.512191", "ingestion_ts": "2026-01-16T14:20:56.869125", "market_id": "0x427bc4b40c09b3dcbc973747f0e4b079bed91b3e5a0aed5c36edd0f7591485f4", "raw": {"market": "0x427bc4b40c09b3dcbc973747f0e4b079bed91b3e5a0aed5c36edd0f7591485f4", "asset_id": "86130975769502911188457673769190265049139877688522439001984850068234616395137", "price": "0.994", "size": "20.8", "side": "SELL", "timestamp": "1768573231472", "received_at": "2026-01-16T14:20:31.512191"}}
{"event_type": "price_change", "event_ts": "2026-01-16T14:20:31.861801", "ingestion_ts": "2026-01-16T14:20:56.869125", "market_id": "0x427bc4b40c09b3dcbc973747f0e4b079bed91b3e5a0aed5c36edd0f7591485f4", "raw": {"market": "0x427bc4b40c09b3dcbc973747f0e4b079bed91b3e5a0aed5c36edd0f7591485f4", "asset_id": "115669573443672055876643967408433138119481486650803218131873713375232186497057", "price": "0.008", "size": "5.2", "side": "BUY", "timestamp": "1768573231817", "received_at": "2026-01-16T14:20:31.861801"}}
{"event_type": "price_change", "event_ts": "2026-01-16T14:20:31.861801", "ingestion_ts": "2026-01-16T14:20:56.869125", "market_id": "0x427bc4b40c09b3dcbc973747f0e4b079bed91b3e5a0aed5c36edd0f7591485f4", "raw": {"market": "0x427bc4b40c09b3dcbc973747f0e4b079bed91b3e5a0aed5c36edd0f7591485f4", "asset_id": "86130975769502911188457673769190265049139877688522439001984850068234616395137", "price": "0.992", "size": "5.2", "side": "SELL", "timestamp": "1768573231817", "received_at": "2026-01-16T14:20:31.861801"}}
{"event_type": "price_change", "event_ts": "2026-01-16T14:20:31.861818", "ingestion_ts": "2026-01-16T14:20:56.869125", "market_id": "0x427bc4b40c09b3dcbc973747f0e4b079bed91b3e5a0aed5c36edd0f7591485f4", "raw": {"market": "0x427bc4b40c09b3dcbc973747f0e4b079bed91b3e5a0aed5c36edd0f7591485f4", "asset_id": "115669573443672055876643967408433138119481486650803218131873713375232186497057", "price": "0.002", "size": "108.77", "side": "BUY", "timestamp": "1768573231819", "received_at": "2026-01-16T14:20:31.861818"}}
{"event_type": "price_change", "event_ts": "2026-01-16T14:20:31.861818", "ingestion_ts": "2026-01-16T14:20:56.869125", "market_id": "0x427bc4b40c09b3dcbc973747f0e4b079bed91b3e5a0aed5c36edd0f7591485f4", "raw": {"market": "0x427bc4b40c09b3dcbc973747f0e4b079bed91b3e5a0aed5c36edd0f7591485f4", "asset_id": "86130975769502911188457673769190265049139877688522439001984850068234616395137", "price": "0.998", "size": "108.77", "side": "SELL", "timestamp": "1768573231819", "received_at": "2026-01-16T14:20:31.861818"}}
{"event_type": "price_change", "event_ts": "2026-01-16T14:20:31.862841", "ingestion_ts": "2026-01-16T14:20:56.869125", "market_id": "0x427bc4b40c09b3dcbc973747f0e4b079bed91b3e5a0aed5c36edd0f7591485f4", "raw": {"market": "0x427bc4b40c09b3dcbc973747f0e4b079bed91b3e5a0aed5c36edd0f7591485f4", "asset_id": "115669573443672055876643967408433138119481486650803218131873713375232186497057", "price": "0.008", "size": "10.4", "side": "BUY", "timestamp": "1768573231820", "received_at": "2026-01-16T14:20:31.862841"}}
{"event_type": "price_change", "event_ts": "2026-01-16T14:20:31.862841", "ingestion_ts": "2026-01-16T14:20:56.869125", "market_id": "0x427bc4b40c09b3dcbc973747f0e4b079bed91b3e5a0aed5c36edd0f7591485f4", "raw": {"market": "0x427bc4b40c09b3dcbc973747f0e4b079bed91b3e5a0aed5c36edd0f7591485f4", "asset_id": "86130975769502911188457673769190265049139877688522439001984850068234616395137", "price": "0.992", "size": "10.4", "side": "SELL", "timestamp": "1768573231820", "received_at": "2026-01-16T14:20:31.862841"}}
{"event_type": "price_change", "event_ts": "2026-01-16T14:20:31.862875", "ingestion_ts": "2026-01-16T14:20:56.869125", "market_id": "0x427bc4b40c09b3dcbc973747f0e4b079bed91b3e5a0aed5c36edd0f7591485f4", "raw": {"market": "0x427bc4b40c09b3dcbc973747f0e4b079bed91b3e5a0aed5c36edd0f7591485f4", "asset_id": "115669573443672055876643967408433138119481486650803218131873713375232186497057", "price": "0.002", "size": "118.22", "side": "BUY", "timestamp": "1768573231821", "received_at": "2026-01-16T14:20:31.862875"}}
{"event_type": "price_change", "event_ts": "2026-01-16T14:20:31.862875", "ingestion_ts": "2026-01-16T14:20:56.869125", "market_id": "0x427bc4b40c09b3dcbc973747f0e4b079bed91b3e5a0aed5c36edd0f7591485f4", "raw": {"market": "0x427bc4b40c09b3dcbc973747f0e4b079bed91b3e5a0aed5c36edd0f7591485f4", "asset_id": "86130975769502911188457673769190265049139877688522439001984850068234616395137", "price": "0.998", "size": "118.22", "side": "SELL", "timestamp": "1768573231821", "received_at": "2026-01-16T14:20:31.862875"}}
{"event_type": "price_change", "event_ts": "2026-01-16T14:20:31.899275", "ingestion_ts": "2026-01-16T14:20:56.869125", "market_id": "0x427bc4b40c09b3dcbc973747f0e4b079bed91b3e5a0aed5c36edd0f7591485f4", "raw": {"market": "0x427bc4b40c09b3dcbc973747f0e4b079bed91b3e5a0aed5c36edd0f7591485f4", "asset_id": "86130975769502911188457673769190265049139877688522439001984850068234616395137", "price": "0.993", "size": "0", "side": "SELL", "timestamp": "1768573231853", "received_at": "2026-01-16T14:20:31.899275"}}
{"event_type": "price_change", "event_ts": "2026-01-16T14:20:31.899275", "ingestion_ts": "2026-01-16T14:20:56.869125", "market_id": "0x427bc4b40c09b3dcbc973747f0e4b079bed91b3e5a0aed5c36edd0f7591485f4", "raw": {"market": "0x427bc4b40c09b3dcbc973747f0e4b079bed91b3e5a0aed5c36edd0f7591485f4", "asset_id": "115669573443672055876643967408433138119481486650803218131873713375232186497057", "price": "0.007", "size": "0", "side": "BUY", "timestamp": "1768573231853", "received_at": "2026-01-16T14:20:31.899275"}}
{"event_type": "price_change", "event_ts": "2026-01-16T14:20:32.109136", "ingestion_ts": "2026-01-16T14:20:56.869125", "market_id": "0x427bc4b40c09b3dcbc973747f0e4b079bed91b3e5a0aed5c36edd0f7591485f4", "raw": {"market": "0x427bc4b40c09b3dcbc973747f0e4b079bed91b3e5a0aed5c36edd0f7591485f4", "asset_id": "115669573443672055876643967408433138119481486650803218131873713375232186497057", "price": "0.169", "size": "18.93", "side": "SELL", "timestamp": "1768573232069", "received_at": "2026-01-16T14:20:32.109136"}}
{"event_type": "price_change", "event_ts": "2026-01-16T14:20:32.109136", "ingestion_ts": "2026-01-16T14:20:56.869125", "market_id": "0x427bc4b40c09b3dcbc973747f0e4b079bed91b3e5a0aed5c36edd0f7591485f4", "raw": {"market": "0x427bc4b40c09b3dcbc973747f0e4b079bed91b3e5a0aed5c36edd0f7591485f4", "asset_id": "86130975769502911188457673769190265049139877688522439001984850068234616395137", "price": "0.831", "size": "18.93", "side": "BUY", "timestamp": "1768573232069", "received_at": "2026-01-16T14:20:32.109136"}}
{"event_type": "price_change", "event_ts": "2026-01-16T14:20:32.109177", "ingestion_ts": "2026-01-16T14:20:56.869125", "market_id": "0x427bc4b40c09b3dcbc973747f0e4b079bed91b3e5a0aed5c36edd0f7591485f4", "raw": {"market": "0x427bc4b40c09b3dcbc973747f0e4b079bed91b3e5a0aed5c36edd0f7591485f4", "asset_id": "115669573443672055876643967408433138119481486650803218131873713375232186497057", "price": "0.171", "size": "0", "side": "SELL", "timestamp": "1768573232069", "received_at": "2026-01-16T14:20:32.109177"}}
{"event_type": "price_change", "event_ts": "2026-01-16T14:20:32.109177", "ingestion_ts": "2026-01-16T14:20:56.869125", "market_id": "0x427bc4b40c09b3dcbc973747f0e4b079bed91b3e5a0aed5c36edd0f7591485f4", "raw": {"market": "0x427bc4b40c09b3dcbc973747f0e4b079bed91b3e5a0aed5c36edd0f7591485f4", "asset_id": "86130975769502911188457673769190265049139877688522439001984850068234616395137", "price": "0.829", "size": "0", "side": "BUY", "timestamp": "1768573232069", "received_at": "2026-01-16T14:20:32.109177"}}
{"event_type": "price_change", "event_ts": "2026-01-16T14:20:32.109192", "ingestion_ts": "2026-01-16T14:20:56.869125", "market_id": "0x427bc4b40c09b3dcbc973747f0e4b079bed91b3e5a0aed5c36edd0f7591485f4", "raw": {"market": "0x427bc4b40c09b3dcbc973747f0e4b079bed91b3e5a0aed5c36edd0f7591485f4", "asset_id": "115669573443672055876643967408433138119481486650803218131873713375232186497057", "price": "0.47", "size": "37.39", "side": "SELL", "timestamp": "1768573232069", "received_at": "2026-01-16T14:20:32.109192"}}
{"event_type": "price_change", "event_ts": "2026-01-16T14:20:32.109192", "ingestion_ts": "2026-01-16T14:20:56.869125", "market_id": "0x427bc4b40c09b3dcbc973747f0e4b079bed91b3e5a0aed5c36edd0f7591485f4", "raw": {"market": "0x427bc4b40c09b3dcbc973747f0e4b079bed91b3e5a0aed5c36edd0f7591485f4", "asset_id": "86130975769502911188457673769190265049139877688522439001984850068234616395137", "price": "0.53", "size": "37.39", "side": "BUY", "timestamp": "1768573232069", "received_at": "2026-01-16T14:20:32.109192"}}
{"event_type": "price_change", "event_ts": "2026-01-16T14:20:32.135120", "ingestion_ts": "2026-01-16T14:20:56.869125", "market_id": "0x427bc4b40c09b3dcbc973747f0e4b079bed91b3e5a0aed5c36edd0f7591485f4", "raw": {"market": "0x427bc4b40c09b3dcbc973747f0e4b079bed91b3e5a0aed5c36edd0f7591485f4", "asset_id": "86130975769502911188457673769190265049139877688522439001984850068234616395137", "price": "0.832", "size": "0", "side": "BUY", "timestamp": "1768573232096", "received_at": "2026-01-16T14:20:32.135120"}}
{"event_type": "price_change", "event_ts": "2026-01-16T14:20:32.135120", "ingestion_ts": "2026-01-16T14:20:56.869125", "market_id": "0x427bc4b40c09b3dcbc973747f0e4b079bed91b3e5a0aed5c36edd0f7591485f4", "raw": {"market": "0x427bc4b40c09b3dcbc973747f0e4b079bed91b3e5a0aed5c36edd0f7591485f4", "asset_id": "115669573443672055876643967408433138119481486650803218131873713375232186497057", "price": "0.168", "size": "0", "side": "SELL", "timestamp": "1768573232096", "received_at": "2026-01-16T14:20:32.135120"}}
{"event_type": "price_change", "event_ts": "2026-01-16T14:20:32.318643", "ingestion_ts": "2026-01-16T14:20:56.869125", "market_id": "0x427bc4b40c09b3dcbc973747f0e4b079bed91b3e5a0aed5c36edd0f7591485f4", "raw": {"market": "0x427bc4b40c09b3dcbc973747f0e4b079bed91b3e5a0aed5c36edd0f7591485f4", "asset_id": "115669573443672055876643967408433138119481486650803218131873713375232186497057", "price": "0.47", "size": "62.15", "side": "SELL", "timestamp": "1768573232281", "received_at": "2026-01-16T14:20:32.318643"}}
{"event_type": "price_change", "event_ts": "2026-01-16T14:20:32.318643", "ingestion_ts": "2026-01-16T14:20:56.869125", "market_id": "0x427bc4b40c09b3dcbc973747f0e4b079bed91b3e5a0aed5c36edd0f7591485f4", "raw": {"market": "0x427bc4b40c09b3dcbc973747f0e4b079bed91b3e5a0aed5c36edd0f7591485f4", "asset_id": "86130975769502911188457673769190265049139877688522439001984850068234616395137", "price": "0.53", "size": "62.15", "side": "BUY", "timestamp": "1768573232281", "received_at": "2026-01-16T14:20:32.318643"}}
{"event_type": "price_change", "event_ts": "2026-01-16T14:20:32.320720", "ingestion_ts": "2026-01-16T14:20:56.869125", "market_id": "0x427bc4b40c09b3dcbc973747f0e4b079bed91b3e5a0aed5c36edd0f7591485f4", "raw": {"market": "0x427bc4b40c09b3dcbc973747f0e4b079bed91b3e5a0aed5c36edd0f7591485f4", "asset_id": "115669573443672055876643967408433138119481486650803218131873713375232186497057", "price": "0.47", "size": "86.91", "side": "SELL", "timestamp": "1768573232282", "received_at": "2026-01-16T14:20:32.320720"}}
{"event_type": "price_change", "event_ts": "2026-01-16T14:20:32.320720", "ingestion_ts": "2026-01-16T14:20:56.869125", "market_id": "0x427bc4b40c09b3dcbc973747f0e4b079bed91b3e5a0aed5c36edd0f7591485f4", "raw": {"market": "0x427bc4b40c09b3dcbc973747f0e4b079bed91b3e5a0aed5c36edd0f7591485f4", "asset_id": "86130975769502911188457673769190265049139877688522439001984850068234616395137", "price": "0.53", "size": "86.91", "side": "BUY", "timestamp": "1768573232282", "received_at": "2026-01-16T14:20:32.320720"}}
{"event_type": "price_change", "event_ts": "2026-01-16T14:20:32.965636", "ingestion_ts": "2026-01-16T14:20:56.869125", "market_id": "0x2393ed0b0fdc450054c7b9071907eca75cf4fc36e385adf4a0a5f99ee62243e8", "raw": {"market": "0x2393ed0b0fdc450054c7b9071907eca75cf4fc36e385adf4a0a5f99ee62243e8", "asset_id": "32769749367306925959219403371425714180265458150646381231272229429098460625924", "price": "0.952", "size": "50", "side": "BUY", "timestamp": "1768573232916", "received_at": "2026-01-16T14:20:32.965636"}}
{"event_type": "price_change", "event_ts": "2026-01-16T14:20:32.965636", "ingestion_ts": "2026-01-16T14:20:56.869125", "market_id": "0x2393ed0b0fdc450054c7b9071907eca75cf4fc36e385adf4a0a5f99ee62243e8", "raw": {"market": "0x2393ed0b0fdc450054c7b9071907eca75cf4fc36e385adf4a0a5f99ee62243e8", "asset_id": "100074770378634056601572485653252702850363676459996771990439989989293515601975", "price": "0.048", "size": "50", "side": "SELL", "timestamp": "1768573232916", "received_at": "2026-01-16T14:20:32.965636"}}
{"event_type": "price_change", "event_ts": "2026-01-16T14:20:32.995187", "ingestion_ts": "2026-01-16T14:20:56.869125", "market_id": "0x2393ed0b0fdc450054c7b9071907eca75cf4fc36e385adf4a0a5f99ee62243e8", "raw": {"market": "0x2393ed0b0fdc450054c7b9071907eca75cf4fc36e385adf4a0a5f99ee62243e8", "asset_id": "100074770378634056601572485653252702850363676459996771990439989989293515601975", "price": "0.049", "size": "0", "side": "SELL", "timestamp": "1768573232954", "received_at": "2026-01-16T14:20:32.995187"}}
{"event_type": "price_change", "event_ts": "2026-01-16T14:20:32.995187", "ingestion_ts": "2026-01-16T14:20:56.869125", "market_id": "0x2393ed0b0fdc450054c7b9071907eca75cf4fc36e385adf4a0a5f99ee62243e8", "raw": {"market": "0x2393ed0b0fdc450054c7b9071907eca75cf4fc36e385adf4a0a5f99ee62243e8", "asset_id": "32769749367306925959219403371425714180265458150646381231272229429098460625924", "price": "0.951", "size": "0", "side": "BUY", "timestamp": "1768573232954", "received_at": "2026-01-16T14:20:32.995187"}}
{"event_type": "price_change", "event_ts": "2026-01-16T14:20:33.027980", "ingestion_ts": "2026-01-16T14:20:56.869125", "market_id": "0x2393ed0b0fdc450054c7b9071907eca75cf4fc36e385adf4a0a5f99ee62243e8", "raw": {"market": "0x2393ed0b0fdc450054c7b9071907eca75cf4fc36e385adf4a0a5f99ee62243e8", "asset_id": "100074770378634056601572485653252702850363676459996771990439989989293515601975", "price": "0.047", "size": "197", "side": "SELL", "timestamp": "1768573232989", "received_at": "2026-01-16T14:20:33.027980"}}
{"event_type": "price_change", "event_ts": "2026-01-16T14:20:33.027980", "ingestion_ts": "2026-01-16T14:20:56.869125", "market_id": "0x2393ed0b0fdc450054c7b9071907eca75cf4fc36e385adf4a0a5f99ee62243e8", "raw": {"market": "0x2393ed0b0fdc450054c7b9071907eca75cf4fc36e385adf4a0a5f99ee62243e8", "asset_id": "32769749367306925959219403371425714180265458150646381231272229429098460625924", "price": "0.953", "size": "197", "side": "BUY", "timestamp": "1768573232989", "received_at": "2026-01-16T14:20:33.027980"}}
{"event_type": "price_change", "event_ts": "2026-01-16T14:20:33.494231", "ingestion_ts": "2026-01-16T14:20:56.869125", "market_id": "0x2393ed0b0fdc450054c7b9071907eca75cf4fc36e385adf4a0a5f99ee62243e8", "raw": {"market": "0x2393ed0b0fdc450054c7b9071907eca75cf4fc36e385adf4a0a5f99ee62243e8", "asset_id": "32769749367306925959219403371425714180265458150646381231272229429098460625924", "price": "0.95", "size": "0", "side": "BUY", "timestamp": "1768573233405", "received_at": "2026-01-16T14:20:33.494231"}}
{"event_type": "price_change", "event_ts": "2026-01-16T14:20:33.494231", "ingestion_ts": "2026-01-16T14:20:56.869125", "market_id": "0x2393ed0b0fdc450054c7b9071907eca75cf4fc36e385adf4a0a5f99ee62243e8", "raw": {"market": "0x2393ed0b0fdc450054c7b9071907eca75cf4fc36e385adf4a0a5f99ee62243e8", "asset_id": "100074770378634056601572485653252702850363676459996771990439989989293515601975", "price": "0.05", "size": "0", "side": "SELL", "timestamp": "1768573233405", "received_at": "2026-01-16T14:20:33.494231"}}
{"event_type": "price_change", "event_ts": "2026-01-16T14:20:34.434727", "ingestion_ts": "2026-01-16T14:20:56.869125", "market_id": "0x49686d26fb712515cd5e12c23f0a1c7e10214c7faa3cb0a730aabe0c33694082", "raw": {"market": "0x49686d26fb712515cd5e12c23f0a1c7e10214c7faa3cb0a730aabe0c33694082", "asset_id": "13244681086321087932946246027856416106585284024824496763706748621681543444582", "price": "0.853", "size": "50.86", "side": "BUY", "timestamp": "1768573234373", "received_at": "2026-01-16T14:20:34.434727"}}
{"event_type": "price_change", "event_ts": "2026-01-16T14:20:34.434727", "ingestion_ts": "2026-01-16T14:20:56.869125", "market_id": "0x49686d26fb712515cd5e12c23f0a1c7e10214c7faa3cb0a730aabe0c33694082", "raw": {"market": "0x49686d26fb712515cd5e12c23f0a1c7e10214c7faa3cb0a730aabe0c33694082", "asset_id": "30442780799048074404860985387051749017905070253466005720364298335239299761065", "price": "0.147", "size": "50.86", "side": "SELL", "timestamp": "1768573234373", "received_at": "2026-01-16T14:20:34.434727"}}
{"event_type": "price_change", "event_ts": "2026-01-16T14:20:35.105761", "ingestion_ts": "2026-01-16T14:20:56.869125", "market_id": "0x22ac5f75af18fdb453497fbf7ac0606a09a6fd55b78b2d08aace6b946ad62038", "raw": {"market": "0x22ac5f75af18fdb453497fbf7ac0606a09a6fd55b78b2d08aace6b946ad62038", "asset_id": "97449340182256366014320155718265676486703217567849039806162053075113517266910", "price": "0.003", "size": "57.73", "side": "BUY", "timestamp": "1768573235000", "received_at": "2026-01-16T14:20:35.105761"}}
{"event_type": "price_change", "event_ts": "2026-01-16T14:20:35.105761", "ingestion_ts": "2026-01-16T14:20:56.869125", "market_id": "0x22ac5f75af18fdb453497fbf7ac0606a09a6fd55b78b2d08aace6b946ad62038", "raw": {"market": "0x22ac5f75af18fdb453497fbf7ac0606a09a6fd55b78b2d08aace6b946ad62038", "asset_id": "59259495934562596318644973716893809974860301509869285036503555129962149752635", "price": "0.997", "size": "57.73", "side": "SELL", "timestamp": "1768573235000", "received_at": "2026-01-16T14:20:35.105761"}}
{"event_type": "price_change", "event_ts": "2026-01-16T14:20:35.105802", "ingestion_ts": "2026-01-16T14:20:56.869125", "market_id": "0x22ac5f75af18fdb453497fbf7ac0606a09a6fd55b78b2d08aace6b946ad62038", "raw": {"market": "0x22ac5f75af18fdb453497fbf7ac0606a09a6fd55b78b2d08aace6b946ad62038", "asset_id": "97449340182256366014320155718265676486703217567849039806162053075113517266910", "price": "0.002", "size": "144.41", "side": "BUY", "timestamp": "1768573235001", "received_at": "2026-01-16T14:20:35.105802"}}
{"event_type": "price_change", "event_ts": "2026-01-16T14:20:35.105802", "ingestion_ts": "2026-01-16T14:20:56.869125", "market_id": "0x22ac5f75af18fdb453497fbf7ac0606a09a6fd55b78b2d08aace6b946ad62038", "raw": {"market": "0x22ac5f75af18fdb453497fbf7ac0606a09a6fd55b78b2d08aace6b946ad62038", "asset_id": "59259495934562596318644973716893809974860301509869285036503555129962149752635", "price": "0.998", "size": "144.41", "side": "SELL", "timestamp": "1768573235001", "received_at": "2026-01-16T14:20:35.105802"}}
{"event_type": "price_change", "event_ts": "2026-01-16T14:20:35.316557", "ingestion_ts": "2026-01-16T14:20:56.869125", "market_id": "0x49686d26fb712515cd5e12c23f0a1c7e10214c7faa3cb0a730aabe0c33694082", "raw": {"market": "0x49686d26fb712515cd5e12c23f0a1c7e10214c7faa3cb0a730aabe0c33694082", "asset_id": "30442780799048074404860985387051749017905070253466005720364298335239299761065", "price": "0.148", "size": "0", "side": "SELL", "timestamp": "1768573235206", "received_at": "2026-01-16T14:20:35.316557"}}
{"event_type": "price_change", "event_ts": "2026-01-16T14:20:35.316557", "ingestion_ts": "2026-01-16T14:20:56.869125", "market_id": "0x49686d26fb712515cd5e12c23f0a1c7e10214c7faa3cb0a730aabe0c33694082", "raw": {"market": "0x49686d26fb712515cd5e12c23f0a1c7e10214c7faa3cb0a730aabe0c33694082", "asset_id": "13244681086321087932946246027856416106585284024824496763706748621681543444582", "price": "0.852", "size": "0", "side": "BUY", "timestamp": "1768573235206", "received_at": "2026-01-16T14:20:35.316557"}}
{"event_type": "price_change", "event_ts": "2026-01-16T14:20:35.351061", "ingestion_ts": "2026-01-16T14:20:56.869125", "market_id": "0x49686d26fb712515cd5e12c23f0a1c7e10214c7faa3cb0a730aabe0c33694082", "raw": {"market": "0x49686d26fb712515cd5e12c23f0a1c7e10214c7faa3cb0a730aabe0c33694082", "asset_id": "30442780799048074404860985387051749017905070253466005720364298335239299761065", "price": "0.146", "size": "17.5", "side": "SELL", "timestamp": "1768573235272", "received_at": "2026-01-16T14:20:35.351061"}}
{"event_type": "price_change", "event_ts": "2026-01-16T14:20:35.351061", "ingestion_ts": "2026-01-16T14:20:56.869125", "market_id": "0x49686d26fb712515cd5e12c23f0a1c7e10214c7faa3cb0a730aabe0c33694082", "raw": {"market": "0x49686d26fb712515cd5e12c23f0a1c7e10214c7faa3cb0a730aabe0c33694082", "asset_id": "13244681086321087932946246027856416106585284024824496763706748621681543444582", "price": "0.854", "size": "17.5", "side": "BUY", "timestamp": "1768573235272", "received_at": "2026-01-16T14:20:35.351061"}}
{"event_type": "price_change", "event_ts": "2026-01-16T14:20:35.364366", "ingestion_ts": "2026-01-16T14:20:56.869125", "market_id": "0x49686d26fb712515cd5e12c23f0a1c7e10214c7faa3cb0a730aabe0c33694082", "raw": {"market": "0x49686d26fb712515cd5e12c23f0a1c7e10214c7faa3cb0a730aabe0c33694082", "asset_id": "13244681086321087932946246027856416106585284024824496763706748621681543444582", "price": "0.911", "size": "14.98", "side": "SELL", "timestamp": "1768573235303", "received_at": "2026-01-16T14:20:35.364366"}}
{"event_type": "price_change", "event_ts": "2026-01-16T14:20:35.364366", "ingestion_ts": "2026-01-16T14:20:56.869125", "market_id": "0x49686d26fb712515cd5e12c23f0a1c7e10214c7faa3cb0a730aabe0c33694082", "raw": {"market": "0x49686d26fb712515cd5e12c23f0a1c7e10214c7faa3cb0a730aabe0c33694082", "asset_id": "30442780799048074404860985387051749017905070253466005720364298335239299761065", "price": "0.089", "size": "14.98", "side": "BUY", "timestamp": "1768573235303", "received_at": "2026-01-16T14:20:35.364366"}}
{"event_type": "price_change", "event_ts": "2026-01-16T14:20:35.701488", "ingestion_ts": "2026-01-16T14:20:56.869125", "market_id": "0x427bc4b40c09b3dcbc973747f0e4b079bed91b3e5a0aed5c36edd0f7591485f4", "raw": {"market": "0x427bc4b40c09b3dcbc973747f0e4b079bed91b3e5a0aed5c36edd0f7591485f4", "asset_id": "115669573443672055876643967408433138119481486650803218131873713375232186497057", "price": "0.002", "size": "108.77", "side": "BUY", "timestamp": "1768573235659", "received_at": "2026-01-16T14:20:35.701488"}}
{"event_type": "price_change", "event_ts": "2026-01-16T14:20:35.701488", "ingestion_ts": "2026-01-16T14:20:56.869125", "market_id": "0x427bc4b40c09b3dcbc973747f0e4b079bed91b3e5a0aed5c36edd0f7591485f4", "raw": {"market": "0x427bc4b40c09b3dcbc973747f0e4b079bed91b3e5a0aed5c36edd0f7591485f4", "asset_id": "86130975769502911188457673769190265049139877688522439001984850068234616395137", "price": "0.998", "size": "108.77", "side": "SELL", "timestamp": "1768573235659", "received_at": "2026-01-16T14:20:35.701488"}}
{"event_type": "price_change", "event_ts": "2026-01-16T14:20:35.701576", "ingestion_ts": "2026-01-16T14:20:56.869125", "market_id": "0x427bc4b40c09b3dcbc973747f0e4b079bed91b3e5a0aed5c36edd0f7591485f4", "raw": {"market": "0x427bc4b40c09b3dcbc973747f0e4b079bed91b3e5a0aed5c36edd0f7591485f4", "asset_id": "115669573443672055876643967408433138119481486650803218131873713375232186497057", "price": "0.008", "size": "5.2", "side": "BUY", "timestamp": "1768573235659", "received_at": "2026-01-16T14:20:35.701576"}}
{"event_type": "price_change", "event_ts": "2026-01-16T14:20:35.701576", "ingestion_ts": "2026-01-16T14:20:56.869125", "market_id": "0x427bc4b40c09b3dcbc973747f0e4b079bed91b3e5a0aed5c36edd0f7591485f4", "raw": {"market": "0x427bc4b40c09b3dcbc973747f0e4b079bed91b3e5a0aed5c36edd0f7591485f4", "asset_id": "86130975769502911188457673769190265049139877688522439001984850068234616395137", "price": "0.992", "size": "5.2", "side": "SELL", "timestamp": "1768573235659", "received_at": "2026-01-16T14:20:35.701576"}}
{"event_type": "price_change", "event_ts": "2026-01-16T14:20:36.100298", "ingestion_ts": "2026-01-16T14:20:56.869125", "market_id": "0x427bc4b40c09b3dcbc973747f0e4b079bed91b3e5a0aed5c36edd0f7591485f4", "raw": {"market": "0x427bc4b40c09b3dcbc973747f0e4b079bed91b3e5a0aed5c36edd0f7591485f4", "asset_id": "115669573443672055876643967408433138119481486650803218131873713375232186497057", "price": "0.169", "size": "0", "side": "SELL", "timestamp": "1768573236063", "received_at": "2026-01-16T14:20:36.100298"}}
{"event_type": "price_change", "event_ts": "2026-01-16T14:20:36.100298", "ingestion_ts": "2026-01-16T14:20:56.869125", "market_id": "0x427bc4b40c09b3dcbc973747f0e4b079bed91b3e5a0aed5c36edd0f7591485f4", "raw": {"market": "0x427bc4b40c09b3dcbc973747f0e4b079bed91b3e5a0aed5c36edd0f7591485f4", "asset_id": "86130975769502911188457673769190265049139877688522439001984850068234616395137", "price": "0.831", "size": "0", "side": "BUY", "timestamp": "1768573236063", "received_at": "2026-01-16T14:20:36.100298"}}
{"event_type": "price_change", "event_ts": "2026-01-16T14:20:36.360222", "ingestion_ts": "2026-01-16T14:20:56.869125", "market_id": "0x427bc4b40c09b3dcbc973747f0e4b079bed91b3e5a0aed5c36edd0f7591485f4", "raw": {"market": "0x427bc4b40c09b3dcbc973747f0e4b079bed91b3e5a0aed5c36edd0f7591485f4", "asset_id": "115669573443672055876643967408433138119481486650803218131873713375232186497057", "price": "0.47", "size": "96.38", "side": "SELL", "timestamp": "1768573236322", "received_at": "2026-01-16T14:20:36.360222"}}
{"event_type": "price_change", "event_ts": "2026-01-16T14:20:36.360222", "ingestion_ts": "2026-01-16T14:20:56.869125", "market_id": "0x427bc4b40c09b3dcbc973747f0e4b079bed91b3e5a0aed5c36edd0f7591485f4", "raw": {"market": "0x427bc4b40c09b3dcbc973747f0e4b079bed91b3e5a0aed5c36edd0f7591485f4", "asset_id": "86130975769502911188457673769190265049139877688522439001984850068234616395137", "price": "0.53", "size": "96.38", "side": "BUY", "timestamp": "1768573236322", "received_at": "2026-01-16T14:20:36.360222"}}
{"event_type": "price_change", "event_ts": "2026-01-16T14:20:36.360854", "ingestion_ts": "2026-01-16T14:20:56.869125", "market_id": "0x427bc4b40c09b3dcbc973747f0e4b079bed91b3e5a0aed5c36edd0f7591485f4", "raw": {"market": "0x427bc4b40c09b3dcbc973747f0e4b079bed91b3e5a0aed5c36edd0f7591485f4", "asset_id": "115669573443672055876643967408433138119481486650803218131873713375232186497057", "price": "0.47", "size": "105.85", "side": "SELL", "timestamp": "1768573236323", "received_at": "2026-01-16T14:20:36.360854"}}
{"event_type": "price_change", "event_ts": "2026-01-16T14:20:36.360854", "ingestion_ts": "2026-01-16T14:20:56.869125", "market_id": "0x427bc4b40c09b3dcbc973747f0e4b079bed91b3e5a0aed5c36edd0f7591485f4", "raw": {"market": "0x427bc4b40c09b3dcbc973747f0e4b079bed91b3e5a0aed5c36edd0f7591485f4", "asset_id": "86130975769502911188457673769190265049139877688522439001984850068234616395137", "price": "0.53", "size": "105.85", "side": "BUY", "timestamp": "1768573236323", "received_at": "2026-01-16T14:20:36.360854"}}
{"event_type": "price_change", "event_ts": "2026-01-16T14:20:36.600793", "ingestion_ts": "2026-01-16T14:20:56.869125", "market_id": "0x49a20c7523c271099008f3ef9a31521263b24d637959852a391e6b4697b1a437", "raw": {"market": "0x49a20c7523c271099008f3ef9a31521263b24d637959852a391e6b4697b1a437", "asset_id": "55881023621710858558280545117465775643848233756850602339827152783696837905531", "price": "0.857", "size": "30", "side": "BUY", "timestamp": "1768573236553", "received_at": "2026-01-16T14:20:36.600793"}}
{"event_type": "price_change", "event_ts": "2026-01-16T14:20:36.600793", "ingestion_ts": "2026-01-16T14:20:56.869125", "market_id": "0x49a20c7523c271099008f3ef9a31521263b24d637959852a391e6b4697b1a437", "raw": {"market": "0x49a20c7523c271099008f3ef9a31521263b24d637959852a391e6b4697b1a437", "asset_id": "13018971792603393862521629014128024641178044618205296260525674415067194037856", "price": "0.143", "size": "30", "side": "SELL", "timestamp": "1768573236553", "received_at": "2026-01-16T14:20:36.600793"}}
{"event_type": "price_change", "event_ts": "2026-01-16T14:20:36.600841", "ingestion_ts": "2026-01-16T14:20:56.869125", "market_id": "0xb9bbdd34304344dcc45803780a34c97d73a00133a5ecf70f63e1008b8abb2fca", "raw": {"market": "0xb9bbdd34304344dcc45803780a34c97d73a00133a5ecf70f63e1008b8abb2fca", "asset_id": "8682484153073832526711485265636767086525069344085206423986003504588877767339", "price": "0.839", "size": "0", "side": "BUY", "timestamp": "1768573236553", "received_at": "2026-01-16T14:20:36.600841"}}
{"event_type": "price_change", "event_ts": "2026-01-16T14:20:36.600841", "ingestion_ts": "2026-01-16T14:20:56.869125", "market_id": "0xb9bbdd34304344dcc45803780a34c97d73a00133a5ecf70f63e1008b8abb2fca", "raw": {"market": "0xb9bbdd34304344dcc45803780a34c97d73a00133a5ecf70f63e1008b8abb2fca", "asset_id": "72012724360700510767037780555710363830014634797787940282136454146828040926557", "price": "0.161", "size": "0", "side": "SELL", "timestamp": "1768573236553", "received_at": "2026-01-16T14:20:36.600841"}}
{"event_type": "price_change", "event_ts": "2026-01-16T14:20:36.600861", "ingestion_ts": "2026-01-16T14:20:56.869125", "market_id": "0x9472be65457510b7fc3477b20ba90910e99d92eac8421a14bf4b7b7a08ef31dc", "raw": {"market": "0x9472be65457510b7fc3477b20ba90910e99d92eac8421a14bf4b7b7a08ef31dc", "asset_id": "43311793366960417907757893276427136943959788721376762326430771171648759300146", "price": "0.858", "size": "233", "side": "BUY", "timestamp": "1768573236553", "received_at": "2026-01-16T14:20:36.600861"}}
{"event_type": "price_change", "event_ts": "2026-01-16T14:20:36.600861", "ingestion_ts": "2026-01-16T14:20:56.869125", "market_id": "0x9472be65457510b7fc3477b20ba90910e99d92eac8421a14bf4b7b7a08ef31dc", "raw": {"market": "0x9472be65457510b7fc3477b20ba90910e99d92eac8421a14bf4b7b7a08ef31dc", "asset_id": "73414222381656326204771753454630063673548497164758947581648273905027617570612", "price": "0.142", "size": "233", "side": "SELL", "timestamp": "1768573236553", "received_at": "2026-01-16T14:20:36.600861"}}
{"event_type": "price_change", "event_ts": "2026-01-16T14:20:36.600873", "ingestion_ts": "2026-01-16T14:20:56.869125", "market_id": "0x2393ed0b0fdc450054c7b9071907eca75cf4fc36e385adf4a0a5f99ee62243e8", "raw": {"market": "0x2393ed0b0fdc450054c7b9071907eca75cf4fc36e385adf4a0a5f99ee62243e8", "asset_id": "32769749367306925959219403371425714180265458150646381231272229429098460625924", "price": "0.849", "size": "294", "side": "BUY", "timestamp": "1768573236553", "received_at": "2026-01-16T14:20:36.600873"}}
{"event_type": "price_change", "event_ts": "2026-01-16T14:20:36.600873", "ingestion_ts": "2026-01-16T14:20:56.869125", "market_id": "0x2393ed0b0fdc450054c7b9071907eca75cf4fc36e385adf4a0a5f99ee62243e8", "raw": {"market": "0x2393ed0b0fdc450054c7b9071907eca75cf4fc36e385adf4a0a5f99ee62243e8", "asset_id": "100074770378634056601572485653252702850363676459996771990439989989293515601975", "price": "0.151", "size": "294", "side": "SELL", "timestamp": "1768573236553", "received_at": "2026-01-16T14:20:36.600873"}}
{"event_type": "price_change", "event_ts": "2026-01-16T14:20:36.600887", "ingestion_ts": "2026-01-16T14:20:56.869125", "market_id": "0xc55db914f0fd1fee18997706712c0dfd8d0369cdbef93a9fef12bd001914ca77", "raw": {"market": "0xc55db914f0fd1fee18997706712c0dfd8d0369cdbef93a9fef12bd001914ca77", "asset_id": "114600293444080540179603459515770723592661967180480327891296353898330242622833", "price": "0.859", "size": "30", "side": "BUY", "timestamp": "1768573236553", "received_at": "2026-01-16T14:20:36.600887"}}
{"event_type": "price_change", "event_ts": "2026-01-16T14:20:36.600887", "ingestion_ts": "2026-01-16T14:20:56.869125", "market_id": "0xc55db914f0fd1fee18997706712c0dfd8d0369cdbef93a9fef12bd001914ca77", "raw": {"market": "0xc55db914f0fd1fee18997706712c0dfd8d0369cdbef93a9fef12bd001914ca77", "asset_id": "72354723612769247426741660426331235762851940382312402276325808095604519806766", "price": "0.141", "size": "30", "side": "SELL", "timestamp": "1768573236553", "received_at": "2026-01-16T14:20:36.600887"}}
{"event_type": "price_change", "event_ts": "2026-01-16T14:20:36.631060", "ingestion_ts": "2026-01-16T14:20:56.869125", "market_id": "0xb9bbdd34304344dcc45803780a34c97d73a00133a5ecf70f63e1008b8abb2fca", "raw": {"market": "0xb9bbdd34304344dcc45803780a34c97d73a00133a5ecf70f63e1008b8abb2fca", "asset_id": "8682484153073832526711485265636767086525069344085206423986003504588877767339", "price": "0.851", "size": "568", "side": "BUY", "timestamp": "1768573236588", "received_at": "2026-01-16T14:20:36.631060"}}
{"event_type": "price_change", "event_ts": "2026-01-16T14:20:36.631060", "ingestion_ts": "2026-01-16T14:20:56.869125", "market_id": "0xb9bbdd34304344dcc45803780a34c97d73a00133a5ecf70f63e1008b8abb2fca", "raw": {"market": "0xb9bbdd34304344dcc45803780a34c97d73a00133a5ecf70f63e1008b8abb2fca", "asset_id": "72012724360700510767037780555710363830014634797787940282136454146828040926557", "price": "0.149", "size": "568", "side": "SELL", "timestamp": "1768573236588", "received_at": "2026-01-16T14:20:36.631060"}}
{"event_type": "price_change", "event_ts": "2026-01-16T14:20:36.631100", "ingestion_ts": "2026-01-16T14:20:56.869125", "market_id": "0xc55db914f0fd1fee18997706712c0dfd8d0369cdbef93a9fef12bd001914ca77", "raw": {"market": "0xc55db914f0fd1fee18997706712c0dfd8d0369cdbef93a9fef12bd001914ca77", "asset_id": "114600293444080540179603459515770723592661967180480327891296353898330242622833", "price": "0.86", "size": "10", "side": "BUY", "timestamp": "1768573236588", "received_at": "2026-01-16T14:20:36.631100"}}
{"event_type": "price_change", "event_ts": "2026-01-16T14:20:36.631100", "ingestion_ts": "2026-01-16T14:20:56.869125", "market_id": "0xc55db914f0fd1fee18997706712c0dfd8d0369cdbef93a9fef12bd001914ca77", "raw": {"market": "0xc55db914f0fd1fee18997706712c0dfd8d0369cdbef93a9fef12bd001914ca77", "asset_id": "72354723612769247426741660426331235762851940382312402276325808095604519806766", "price": "0.14", "size": "10", "side": "SELL", "timestamp": "1768573236588", "received_at": "2026-01-16T14:20:36.631100"}}
{"event_type": "price_change", "event_ts": "2026-01-16T14:20:36.631114", "ingestion_ts": "2026-01-16T14:20:56.869125", "market_id": "0x2393ed0b0fdc450054c7b9071907eca75cf4fc36e385adf4a0a5f99ee62243e8", "raw": {"market": "0x2393ed0b0fdc450054c7b9071907eca75cf4fc36e385adf4a0a5f99ee62243e8", "asset_id": "32769749367306925959219403371425714180265458150646381231272229429098460625924", "price": "0.85", "size": "10", "side": "BUY", "timestamp": "1768573236588", "received_at": "2026-01-16T14:20:36.631114"}}
{"event_type": "price_change", "event_ts": "2026-01-16T14:20:36.631114", "ingestion_ts": "2026-01-16T14:20:56.869125", "market_id": "0x2393ed0b0fdc450054c7b9071907eca75cf4fc36e385adf4a0a5f99ee62243e8", "raw": {"market": "0x2393ed0b0fdc450054c7b9071907eca75cf4fc36e385adf4a0a5f99ee62243e8", "asset_id": "100074770378634056601572485653252702850363676459996771990439989989293515601975", "price": "0.15", "size": "10", "side": "SELL", "timestamp": "1768573236588", "received_at": "2026-01-16T14:20:36.631114"}}
{"event_type": "price_change", "event_ts": "2026-01-16T14:20:36.631126", "ingestion_ts": "2026-01-16T14:20:56.869125", "market_id": "0x49a20c7523c271099008f3ef9a31521263b24d637959852a391e6b4697b1a437", "raw": {"market": "0x49a20c7523c271099008f3ef9a31521263b24d637959852a391e6b4697b1a437", "asset_id": "55881023621710858558280545117465775643848233756850602339827152783696837905531", "price": "0.858", "size": "10", "side": "BUY", "timestamp": "1768573236588", "received_at": "2026-01-16T14:20:36.631126"}}
{"event_type": "price_change", "event_ts": "2026-01-16T14:20:36.631126", "ingestion_ts": "2026-01-16T14:20:56.869125", "market_id": "0x49a20c7523c271099008f3ef9a31521263b24d637959852a391e6b4697b1a437", "raw": {"market": "0x49a20c7523c271099008f3ef9a31521263b24d637959852a391e6b4697b1a437", "asset_id": "13018971792603393862521629014128024641178044618205296260525674415067194037856", "price": "0.142", "size": "10", "side": "SELL", "timestamp": "1768573236588", "received_at": "2026-01-16T14:20:36.631126"}}
{"event_type": "price_change", "event_ts": "2026-01-16T14:20:36.631138", "ingestion_ts": "2026-01-16T14:20:56.869125", "market_id": "0x9472be65457510b7fc3477b20ba90910e99d92eac8421a14bf4b7b7a08ef31dc", "raw": {"market": "0x9472be65457510b7fc3477b20ba90910e99d92eac8421a14bf4b7b7a08ef31dc", "asset_id": "43311793366960417907757893276427136943959788721376762326430771171648759300146", "price": "0.859", "size": "10", "side": "BUY", "timestamp": "1768573236588", "received_at": "2026-01-16T14:20:36.631138"}}
{"event_type": "price_change", "event_ts": "2026-01-16T14:20:36.631138", "ingestion_ts": "2026-01-16T14:20:56.869125", "market_id": "0x9472be65457510b7fc3477b20ba90910e99d92eac8421a14bf4b7b7a08ef31dc", "raw": {"market": "0x9472be65457510b7fc3477b20ba90910e99d92eac8421a14bf4b7b7a08ef31dc", "asset_id": "73414222381656326204771753454630063673548497164758947581648273905027617570612", "price": "0.141", "size": "10", "side": "SELL", "timestamp": "1768573236588", "received_at": "2026-01-16T14:20:36.631138"}}
{"event_type": "price_change", "event_ts": "2026-01-16T14:20:36.963644", "ingestion_ts": "2026-01-16T14:20:56.869125", "market_id": "0x49686d26fb712515cd5e12c23f0a1c7e10214c7faa3cb0a730aabe0c33694082", "raw": {"market": "0x49686d26fb712515cd5e12c23f0a1c7e10214c7faa3cb0a730aabe0c33694082", "asset_id": "13244681086321087932946246027856416106585284024824496763706748621681543444582", "price": "0.142", "size": "1126", "side": "BUY", "timestamp": "1768573236917", "received_at": "2026-01-16T14:20:36.963644"}}
{"event_type": "price_change", "event_ts": "2026-01-16T14:20:36.963644", "ingestion_ts": "2026-01-16T14:20:56.869125", "market_id": "0x49686d26fb712515cd5e12c23f0a1c7e10214c7faa3cb0a730aabe0c33694082", "raw": {"market": "0x49686d26fb712515cd5e12c23f0a1c7e10214c7faa3cb0a730aabe0c33694082", "asset_id": "30442780799048074404860985387051749017905070253466005720364298335239299761065", "price": "0.858", "size": "1126", "side": "SELL", "timestamp": "1768573236917", "received_at": "2026-01-16T14:20:36.963644"}}
{"event_type": "price_change", "event_ts": "2026-01-16T14:20:37.073250", "ingestion_ts": "2026-01-16T14:20:56.869125", "market_id": "0x49686d26fb712515cd5e12c23f0a1c7e10214c7faa3cb0a730aabe0c33694082", "raw": {"market": "0x49686d26fb712515cd5e12c23f0a1c7e10214c7faa3cb0a730aabe0c33694082", "asset_id": "13244681086321087932946246027856416106585284024824496763706748621681543444582", "price": "0.853", "size": "45", "side": "BUY", "timestamp": "1768573237030", "received_at": "2026-01-16T14:20:37.073250"}}
{"event_type": "price_change", "event_ts": "2026-01-16T14:20:37.073250", "ingestion_ts": "2026-01-16T14:20:56.869125", "market_id": "0x49686d26fb712515cd5e12c23f0a1c7e10214c7faa3cb0a730aabe0c33694082", "raw": {"market": "0x49686d26fb712515cd5e12c23f0a1c7e10214c7faa3cb0a730aabe0c33694082", "asset_id": "30442780799048074404860985387051749017905070253466005720364298335239299761065", "price": "0.147", "size": "45", "side": "SELL", "timestamp": "1768573237030", "received_at": "2026-01-16T14:20:37.073250"}}
{"event_type": "price_change", "event_ts": "2026-01-16T14:20:37.119564", "ingestion_ts": "2026-01-16T14:20:56.869125", "market_id": "0x49686d26fb712515cd5e12c23f0a1c7e10214c7faa3cb0a730aabe0c33694082", "raw": {"market": "0x49686d26fb712515cd5e12c23f0a1c7e10214c7faa3cb0a730aabe0c33694082", "asset_id": "13244681086321087932946246027856416106585284024824496763706748621681543444582", "price": "0.854", "size": "23.35", "side": "BUY", "timestamp": "1768573237074", "received_at": "2026-01-16T14:20:37.119564"}}
{"event_type": "price_change", "event_ts": "2026-01-16T14:20:37.119564", "ingestion_ts": "2026-01-16T14:20:56.869125", "market_id": "0x49686d26fb712515cd5e12c23f0a1c7e10214c7faa3cb0a730aabe0c33694082", "raw": {"market": "0x49686d26fb712515cd5e12c23f0a1c7e10214c7faa3cb0a730aabe0c33694082", "asset_id": "30442780799048074404860985387051749017905070253466005720364298335239299761065", "price": "0.146", "size": "23.35", "side": "SELL", "timestamp": "1768573237074", "received_at": "2026-01-16T14:20:37.119564"}}
{"event_type": "price_change", "event_ts": "2026-01-16T14:20:38.729862", "ingestion_ts": "2026-01-16T14:20:56.869125", "market_id": "0x49686d26fb712515cd5e12c23f0a1c7e10214c7faa3cb0a730aabe0c33694082", "raw": {"market": "0x49686d26fb712515cd5e12c23f0a1c7e10214c7faa3cb0a730aabe0c33694082", "asset_id": "30442780799048074404860985387051749017905070253466005720364298335239299761065", "price": "0.146", "size": "5.85", "side": "SELL", "timestamp": "1768573238688", "received_at": "2026-01-16T14:20:38.729862"}}
{"event_type": "price_change", "event_ts": "2026-01-16T14:20:38.729862", "ingestion_ts": "2026-01-16T14:20:56.869125", "market_id": "0x49686d26fb712515cd5e12c23f0a1c7e10214c7faa3cb0a730aabe0c33694082", "raw": {"market": "0x49686d26fb712515cd5e12c23f0a1c7e10214c7faa3cb0a730aabe0c33694082", "asset_id": "13244681086321087932946246027856416106585284024824496763706748621681543444582", "price": "0.854", "size": "5.85", "side": "BUY", "timestamp": "1768573238688", "received_at": "2026-01-16T14:20:38.729862"}}
{"event_type": "price_change", "event_ts": "2026-01-16T14:20:38.806754", "ingestion_ts": "2026-01-16T14:20:56.869125", "market_id": "0x49686d26fb712515cd5e12c23f0a1c7e10214c7faa3cb0a730aabe0c33694082", "raw": {"market": "0x49686d26fb712515cd5e12c23f0a1c7e10214c7faa3cb0a730aabe0c33694082", "asset_id": "30442780799048074404860985387051749017905070253466005720364298335239299761065", "price": "0.148", "size": "17.5", "side": "SELL", "timestamp": "1768573238742", "received_at": "2026-01-16T14:20:38.806754"}}
{"event_type": "price_change", "event_ts": "2026-01-16T14:20:38.806754", "ingestion_ts": "2026-01-16T14:20:56.869125", "market_id": "0x49686d26fb712515cd5e12c23f0a1c7e10214c7faa3cb0a730aabe0c33694082", "raw": {"market": "0x49686d26fb712515cd5e12c23f0a1c7e10214c7faa3cb0a730aabe0c33694082", "asset_id": "13244681086321087932946246027856416106585284024824496763706748621681543444582", "price": "0.852", "size": "17.5", "side": "BUY", "timestamp": "1768573238742", "received_at": "2026-01-16T14:20:38.806754"}}
{"event_type": "price_change", "event_ts": "2026-01-16T14:20:39.179452", "ingestion_ts": "2026-01-16T14:20:56.869125", "market_id": "0x2393ed0b0fdc450054c7b9071907eca75cf4fc36e385adf4a0a5f99ee62243e8", "raw": {"market": "0x2393ed0b0fdc450054c7b9071907eca75cf4fc36e385adf4a0a5f99ee62243e8", "asset_id": "32769749367306925959219403371425714180265458150646381231272229429098460625924", "price": "0.954", "size": "50", "side": "BUY", "timestamp": "1768573239059", "received_at": "2026-01-16T14:20:39.179452"}}
{"event_type": "price_change", "event_ts": "2026-01-16T14:20:39.179452", "ingestion_ts": "2026-01-16T14:20:56.869125", "market_id": "0x2393ed0b0fdc450054c7b9071907eca75cf4fc36e385adf4a0a5f99ee62243e8", "raw": {"market": "0x2393ed0b0fdc450054c7b9071907eca75cf4fc36e385adf4a0a5f99ee62243e8", "asset_id": "100074770378634056601572485653252702850363676459996771990439989989293515601975", "price": "0.046", "size": "50", "side": "SELL", "timestamp": "1768573239059", "received_at": "2026-01-16T14:20:39.179452"}}
{"event_type": "price_change", "event_ts": "2026-01-16T14:20:39.694008", "ingestion_ts": "2026-01-16T14:20:56.869125", "market_id": "0x2393ed0b0fdc450054c7b9071907eca75cf4fc36e385adf4a0a5f99ee62243e8", "raw": {"market": "0x2393ed0b0fdc450054c7b9071907eca75cf4fc36e385adf4a0a5f99ee62243e8", "asset_id": "32769749367306925959219403371425714180265458150646381231272229429098460625924", "price": "0.952", "size": "0", "side": "BUY", "timestamp": "1768573239654", "received_at": "2026-01-16T14:20:39.694008"}}
{"event_type": "price_change", "event_ts": "2026-01-16T14:20:39.694008", "ingestion_ts": "2026-01-16T14:20:56.869125", "market_id": "0x2393ed0b0fdc450054c7b9071907eca75cf4fc36e385adf4a0a5f99ee62243e8", "raw": {"market": "0x2393ed0b0fdc450054c7b9071907eca75cf4fc36e385adf4a0a5f99ee62243e8", "asset_id": "100074770378634056601572485653252702850363676459996771990439989989293515601975", "price": "0.048", "size": "0", "side": "SELL", "timestamp": "1768573239654", "received_at": "2026-01-16T14:20:39.694008"}}
{"event_type": "price_change", "event_ts": "2026-01-16T14:20:42.996243", "ingestion_ts": "2026-01-16T14:20:56.869125", "market_id": "0x427bc4b40c09b3dcbc973747f0e4b079bed91b3e5a0aed5c36edd0f7591485f4", "raw": {"market": "0x427bc4b40c09b3dcbc973747f0e4b079bed91b3e5a0aed5c36edd0f7591485f4", "asset_id": "115669573443672055876643967408433138119481486650803218131873713375232186497057", "price": "0.002", "size": "99.32", "side": "BUY", "timestamp": "1768573242946", "received_at": "2026-01-16T14:20:42.996243"}}
{"event_type": "price_change", "event_ts": "2026-01-16T14:20:42.996243", "ingestion_ts": "2026-01-16T14:20:56.869125", "market_id": "0x427bc4b40c09b3dcbc973747f0e4b079bed91b3e5a0aed5c36edd0f7591485f4", "raw": {"market": "0x427bc4b40c09b3dcbc973747f0e4b079bed91b3e5a0aed5c36edd0f7591485f4", "asset_id": "86130975769502911188457673769190265049139877688522439001984850068234616395137", "price": "0.998", "size": "99.32", "side": "SELL", "timestamp": "1768573242946", "received_at": "2026-01-16T14:20:42.996243"}}
{"event_type": "price_change", "event_ts": "2026-01-16T14:20:42.996261", "ingestion_ts": "2026-01-16T14:20:56.869125", "market_id": "0x427bc4b40c09b3dcbc973747f0e4b079bed91b3e5a0aed5c36edd0f7591485f4", "raw": {"market": "0x427bc4b40c09b3dcbc973747f0e4b079bed91b3e5a0aed5c36edd0f7591485f4", "asset_id": "115669573443672055876643967408433138119481486650803218131873713375232186497057", "price": "0.008", "size": "0", "side": "BUY", "timestamp": "1768573242946", "received_at": "2026-01-16T14:20:42.996261"}}
{"event_type": "price_change", "event_ts": "2026-01-16T14:20:42.996261", "ingestion_ts": "2026-01-16T14:20:56.869125", "market_id": "0x427bc4b40c09b3dcbc973747f0e4b079bed91b3e5a0aed5c36edd0f7591485f4", "raw": {"market": "0x427bc4b40c09b3dcbc973747f0e4b079bed91b3e5a0aed5c36edd0f7591485f4", "asset_id": "86130975769502911188457673769190265049139877688522439001984850068234616395137", "price": "0.992", "size": "0", "side": "SELL", "timestamp": "1768573242946", "received_at": "2026-01-16T14:20:42.996261"}}
{"event_type": "price_change", "event_ts": "2026-01-16T14:20:43.021546", "ingestion_ts": "2026-01-16T14:20:56.869125", "market_id": "0x427bc4b40c09b3dcbc973747f0e4b079bed91b3e5a0aed5c36edd0f7591485f4", "raw": {"market": "0x427bc4b40c09b3dcbc973747f0e4b079bed91b3e5a0aed5c36edd0f7591485f4", "asset_id": "86130975769502911188457673769190265049139877688522439001984850068234616395137", "price": "0.802", "size": "50", "side": "BUY", "timestamp": "1768573242982", "received_at": "2026-01-16T14:20:43.021546"}}
{"event_type": "price_change", "event_ts": "2026-01-16T14:20:43.021546", "ingestion_ts": "2026-01-16T14:20:56.869125", "market_id": "0x427bc4b40c09b3dcbc973747f0e4b079bed91b3e5a0aed5c36edd0f7591485f4", "raw": {"market": "0x427bc4b40c09b3dcbc973747f0e4b079bed91b3e5a0aed5c36edd0f7591485f4", "asset_id": "115669573443672055876643967408433138119481486650803218131873713375232186497057", "price": "0.198", "size": "50", "side": "SELL", "timestamp": "1768573242982", "received_at": "2026-01-16T14:20:43.021546"}}
{"event_type": "price_change", "event_ts": "2026-01-16T14:20:43.679384", "ingestion_ts": "2026-01-16T14:20:56.869125", "market_id": "0x427bc4b40c09b3dcbc973747f0e4b079bed91b3e5a0aed5c36edd0f7591485f4", "raw": {"market": "0x427bc4b40c09b3dcbc973747f0e4b079bed91b3e5a0aed5c36edd0f7591485f4", "asset_id": "115669573443672055876643967408433138119481486650803218131873713375232186497057", "price": "0.006", "size": "28.75", "side": "BUY", "timestamp": "1768573243330", "received_at": "2026-01-16T14:20:43.679384"}}
{"event_type": "price_change", "event_ts": "2026-01-16T14:20:43.679384", "ingestion_ts": "2026-01-16T14:20:56.869125", "market_id": "0x427bc4b40c09b3dcbc973747f0e4b079bed91b3e5a0aed5c36edd0f7591485f4", "raw": {"market": "0x427bc4b40c09b3dcbc973747f0e4b079bed91b3e5a0aed5c36edd0f7591485f4", "asset_id": "86130975769502911188457673769190265049139877688522439001984850068234616395137", "price": "0.994", "size": "28.75", "side": "SELL", "timestamp": "1768573243330", "received_at": "2026-01-16T14:20:43.679384"}}
{"event_type": "price_change", "event_ts": "2026-01-16T14:20:43.680265", "ingestion_ts": "2026-01-16T14:20:56.869125", "market_id": "0x427bc4b40c09b3dcbc973747f0e4b079bed91b3e5a0aed5c36edd0f7591485f4", "raw": {"market": "0x427bc4b40c09b3dcbc973747f0e4b079bed91b3e5a0aed5c36edd0f7591485f4", "asset_id": "115669573443672055876643967408433138119481486650803218131873713375232186497057", "price": "0.003", "size": "8.55", "side": "BUY", "timestamp": "1768573243332", "received_at": "2026-01-16T14:20:43.680265"}}
{"event_type": "price_change", "event_ts": "2026-01-16T14:20:43.680265", "ingestion_ts": "2026-01-16T14:20:56.869125", "market_id": "0x427bc4b40c09b3dcbc973747f0e4b079bed91b3e5a0aed5c36edd0f7591485f4", "raw": {"market": "0x427bc4b40c09b3dcbc973747f0e4b079bed91b3e5a0aed5c36edd0f7591485f4", "asset_id": "86130975769502911188457673769190265049139877688522439001984850068234616395137", "price": "0.997", "size": "8.55", "side": "SELL", "timestamp": "1768573243332", "received_at": "2026-01-16T14:20:43.680265"}}
{"event_type": "price_change", "event_ts": "2026-01-16T14:20:43.683076", "ingestion_ts": "2026-01-16T14:20:56.869125", "market_id": "0x427bc4b40c09b3dcbc973747f0e4b079bed91b3e5a0aed5c36edd0f7591485f4", "raw": {"market": "0x427bc4b40c09b3dcbc973747f0e4b079bed91b3e5a0aed5c36edd0f7591485f4", "asset_id": "115669573443672055876643967408433138119481486650803218131873713375232186497057", "price": "0.006", "size": "36.7", "side": "BUY", "timestamp": "1768573243333", "received_at": "2026-01-16T14:20:43.683076"}}
{"event_type": "price_change", "event_ts": "2026-01-16T14:20:43.683076", "ingestion_ts": "2026-01-16T14:20:56.869125", "market_id": "0x427bc4b40c09b3dcbc973747f0e4b079bed91b3e5a0aed5c36edd0f7591485f4", "raw": {"market": "0x427bc4b40c09b3dcbc973747f0e4b079bed91b3e5a0aed5c36edd0f7591485f4", "asset_id": "86130975769502911188457673769190265049139877688522439001984850068234616395137", "price": "0.994", "size": "36.7", "side": "SELL", "timestamp": "1768573243333", "received_at": "2026-01-16T14:20:43.683076"}}
{"event_type": "price_change", "event_ts": "2026-01-16T14:20:43.970186", "ingestion_ts": "2026-01-16T14:20:56.869125", "market_id": "0x427bc4b40c09b3dcbc973747f0e4b079bed91b3e5a0aed5c36edd0f7591485f4", "raw": {"market": "0x427bc4b40c09b3dcbc973747f0e4b079bed91b3e5a0aed5c36edd0f7591485f4", "asset_id": "86130975769502911188457673769190265049139877688522439001984850068234616395137", "price": "0.993", "size": "52", "side": "SELL", "timestamp": "1768573243500", "received_at": "2026-01-16T14:20:43.970186"}}
{"event_type": "price_change", "event_ts": "2026-01-16T14:20:43.970186", "ingestion_ts": "2026-01-16T14:20:56.869125", "market_id": "0x427bc4b40c09b3dcbc973747f0e4b079bed91b3e5a0aed5c36edd0f7591485f4", "raw": {"market": "0x427bc4b40c09b3dcbc973747f0e4b079bed91b3e5a0aed5c36edd0f7591485f4", "asset_id": "115669573443672055876643967408433138119481486650803218131873713375232186497057", "price": "0.007", "size": "52", "side": "BUY", "timestamp": "1768573243500", "received_at": "2026-01-16T14:20:43.970186"}}
{"event_type": "price_change", "event_ts": "2026-01-16T14:20:44.283153", "ingestion_ts": "2026-01-16T14:20:56.869125", "market_id": "0x427bc4b40c09b3dcbc973747f0e4b079bed91b3e5a0aed5c36edd0f7591485f4", "raw": {"market": "0x427bc4b40c09b3dcbc973747f0e4b079bed91b3e5a0aed5c36edd0f7591485f4", "asset_id": "115669573443672055876643967408433138119481486650803218131873713375232186497057", "price": "0.47", "size": "37.39", "side": "SELL", "timestamp": "1768573243694", "received_at": "2026-01-16T14:20:44.283153"}}
{"event_type": "price_change", "event_ts": "2026-01-16T14:20:44.283153", "ingestion_ts": "2026-01-16T14:20:56.869125", "market_id": "0x427bc4b40c09b3dcbc973747f0e4b079bed91b3e5a0aed5c36edd0f7591485f4", "raw": {"market": "0x427bc4b40c09b3dcbc973747f0e4b079bed91b3e5a0aed5c36edd0f7591485f4", "asset_id": "86130975769502911188457673769190265049139877688522439001984850068234616395137", "price": "0.53", "size": "37.39", "side": "BUY", "timestamp": "1768573243694", "received_at": "2026-01-16T14:20:44.283153"}}
{"event_type": "price_change", "event_ts": "2026-01-16T14:20:44.571026", "ingestion_ts": "2026-01-16T14:20:56.869125", "market_id": "0x427bc4b40c09b3dcbc973747f0e4b079bed91b3e5a0aed5c36edd0f7591485f4", "raw": {"market": "0x427bc4b40c09b3dcbc973747f0e4b079bed91b3e5a0aed5c36edd0f7591485f4", "asset_id": "115669573443672055876643967408433138119481486650803218131873713375232186497057", "price": "0.469", "size": "10.13", "side": "SELL", "timestamp": "1768573244019", "received_at": "2026-01-16T14:20:44.571026"}}
{"event_type": "price_change", "event_ts": "2026-01-16T14:20:44.571026", "ingestion_ts": "2026-01-16T14:20:56.869125", "market_id": "0x427bc4b40c09b3dcbc973747f0e4b079bed91b3e5a0aed5c36edd0f7591485f4", "raw": {"market": "0x427bc4b40c09b3dcbc973747f0e4b079bed91b3e5a0aed5c36edd0f7591485f4", "asset_id": "86130975769502911188457673769190265049139877688522439001984850068234616395137", "price": "0.531", "size": "10.13", "side": "BUY", "timestamp": "1768573244019", "received_at": "2026-01-16T14:20:44.571026"}}
{"event_type": "price_change", "event_ts": "2026-01-16T14:20:44.580862", "ingestion_ts": "2026-01-16T14:20:56.869125", "market_id": "0x427bc4b40c09b3dcbc973747f0e4b079bed91b3e5a0aed5c36edd0f7591485f4", "raw": {"market": "0x427bc4b40c09b3dcbc973747f0e4b079bed91b3e5a0aed5c36edd0f7591485f4", "asset_id": "115669573443672055876643967408433138119481486650803218131873713375232186497057", "price": "0.197", "size": "24.09", "side": "SELL", "timestamp": "1768573244024", "received_at": "2026-01-16T14:20:44.580862"}}
{"event_type": "price_change", "event_ts": "2026-01-16T14:20:44.580862", "ingestion_ts": "2026-01-16T14:20:56.869125", "market_id": "0x427bc4b40c09b3dcbc973747f0e4b079bed91b3e5a0aed5c36edd0f7591485f4", "raw": {"market": "0x427bc4b40c09b3dcbc973747f0e4b079bed91b3e5a0aed5c36edd0f7591485f4", "asset_id": "86130975769502911188457673769190265049139877688522439001984850068234616395137", "price": "0.803", "size": "24.09", "side": "BUY", "timestamp": "1768573244024", "received_at": "2026-01-16T14:20:44.580862"}}
{"event_type": "price_change", "event_ts": "2026-01-16T14:20:44.588371", "ingestion_ts": "2026-01-16T14:20:56.869125", "market_id": "0x427bc4b40c09b3dcbc973747f0e4b079bed91b3e5a0aed5c36edd0f7591485f4", "raw": {"market": "0x427bc4b40c09b3dcbc973747f0e4b079bed91b3e5a0aed5c36edd0f7591485f4", "asset_id": "115669573443672055876643967408433138119481486650803218131873713375232186497057", "price": "0.469", "size": "20.26", "side": "SELL", "timestamp": "1768573244029", "received_at": "2026-01-16T14:20:44.588371"}}
{"event_type": "price_change", "event_ts": "2026-01-16T14:20:44.588371", "ingestion_ts": "2026-01-16T14:20:56.869125", "market_id": "0x427bc4b40c09b3dcbc973747f0e4b079bed91b3e5a0aed5c36edd0f7591485f4", "raw": {"market": "0x427bc4b40c09b3dcbc973747f0e4b079bed91b3e5a0aed5c36edd0f7591485f4", "asset_id": "86130975769502911188457673769190265049139877688522439001984850068234616395137", "price": "0.531", "size": "20.26", "side": "BUY", "timestamp": "1768573244029", "received_at": "2026-01-16T14:20:44.588371"}}
{"event_type": "price_change", "event_ts": "2026-01-16T14:20:44.594187", "ingestion_ts": "2026-01-16T14:20:56.869125", "market_id": "0x427bc4b40c09b3dcbc973747f0e4b079bed91b3e5a0aed5c36edd0f7591485f4", "raw": {"market": "0x427bc4b40c09b3dcbc973747f0e4b079bed91b3e5a0aed5c36edd0f7591485f4", "asset_id": "115669573443672055876643967408433138119481486650803218131873713375232186497057", "price": "0.197", "size": "48.18", "side": "SELL", "timestamp": "1768573244034", "received_at": "2026-01-16T14:20:44.594187"}}
{"event_type": "price_change", "event_ts": "2026-01-16T14:20:44.594187", "ingestion_ts": "2026-01-16T14:20:56.869125", "market_id": "0x427bc4b40c09b3dcbc973747f0e4b079bed91b3e5a0aed5c36edd0f7591485f4", "raw": {"market": "0x427bc4b40c09b3dcbc973747f0e4b079bed91b3e5a0aed5c36edd0f7591485f4", "asset_id": "86130975769502911188457673769190265049139877688522439001984850068234616395137", "price": "0.803", "size": "48.18", "side": "BUY", "timestamp": "1768573244034", "received_at": "2026-01-16T14:20:44.594187"}}
{"event_type": "price_change", "event_ts": "2026-01-16T14:20:44.819137", "ingestion_ts": "2026-01-16T14:20:56.869125", "market_id": "0x427bc4b40c09b3dcbc973747f0e4b079bed91b3e5a0aed5c36edd0f7591485f4", "raw": {"market": "0x427bc4b40c09b3dcbc973747f0e4b079bed91b3e5a0aed5c36edd0f7591485f4", "asset_id": "86130975769502911188457673769190265049139877688522439001984850068234616395137", "price": "0.802", "size": "0", "side": "BUY", "timestamp": "1768573244197", "received_at": "2026-01-16T14:20:44.819137"}}
{"event_type": "price_change", "event_ts": "2026-01-16T14:20:44.819137", "ingestion_ts": "2026-01-16T14:20:56.869125", "market_id": "0x427bc4b40c09b3dcbc973747f0e4b079bed91b3e5a0aed5c36edd0f7591485f4", "raw": {"market": "0x427bc4b40c09b3dcbc973747f0e4b079bed91b3e5a0aed5c36edd0f7591485f4", "asset_id": "115669573443672055876643967408433138119481486650803218131873713375232186497057", "price": "0.198", "size": "0", "side": "SELL", "timestamp": "1768573244197", "received_at": "2026-01-16T14:20:44.819137"}}
{"event_type": "price_change", "event_ts": "2026-01-16T14:20:44.860059", "ingestion_ts": "2026-01-16T14:20:56.869125", "market_id": "0x427bc4b40c09b3dcbc973747f0e4b079bed91b3e5a0aed5c36edd0f7591485f4", "raw": {"market": "0x427bc4b40c09b3dcbc973747f0e4b079bed91b3e5a0aed5c36edd0f7591485f4", "asset_id": "86130975769502911188457673769190265049139877688522439001984850068234616395137", "price": "0.804", "size": "35", "side": "BUY", "timestamp": "1768573244276", "received_at": "2026-01-16T14:20:44.860059"}}
{"event_type": "price_change", "event_ts": "2026-01-16T14:20:44.860059", "ingestion_ts": "2026-01-16T14:20:56.869125", "market_id": "0x427bc4b40c09b3dcbc973747f0e4b079bed91b3e5a0aed5c36edd0f7591485f4", "raw": {"market": "0x427bc4b40c09b3dcbc973747f0e4b079bed91b3e5a0aed5c36edd0f7591485f4", "asset_id": "115669573443672055876643967408433138119481486650803218131873713375232186497057", "price": "0.196", "size": "35", "side": "SELL", "timestamp": "1768573244276", "received_at": "2026-01-16T14:20:44.860059"}}
{"event_type": "price_change", "event_ts": "2026-01-16T14:20:45.424253", "ingestion_ts": "2026-01-16T14:20:56.869125", "market_id": "0x49686d26fb712515cd5e12c23f0a1c7e10214c7faa3cb0a730aabe0c33694082", "raw": {"market": "0x49686d26fb712515cd5e12c23f0a1c7e10214c7faa3cb0a730aabe0c33694082", "asset_id": "13244681086321087932946246027856416106585284024824496763706748621681543444582", "price": "0.854", "size": "0", "side": "BUY", "timestamp": "1768573244892", "received_at": "2026-01-16T14:20:45.424253"}}
{"event_type": "price_change", "event_ts": "2026-01-16T14:20:45.424253", "ingestion_ts": "2026-01-16T14:20:56.869125", "market_id": "0x49686d26fb712515cd5e12c23f0a1c7e10214c7faa3cb0a730aabe0c33694082", "raw": {"market": "0x49686d26fb712515cd5e12c23f0a1c7e10214c7faa3cb0a730aabe0c33694082", "asset_id": "30442780799048074404860985387051749017905070253466005720364298335239299761065", "price": "0.146", "size": "0", "side": "SELL", "timestamp": "1768573244892", "received_at": "2026-01-16T14:20:45.424253"}}
{"event_type": "price_change", "event_ts": "2026-01-16T14:20:45.559415", "ingestion_ts": "2026-01-16T14:20:56.869125", "market_id": "0x49686d26fb712515cd5e12c23f0a1c7e10214c7faa3cb0a730aabe0c33694082", "raw": {"market": "0x49686d26fb712515cd5e12c23f0a1c7e10214c7faa3cb0a730aabe0c33694082", "asset_id": "13244681086321087932946246027856416106585284024824496763706748621681543444582", "price": "0.911", "size": "132.98", "side": "SELL", "timestamp": "1768573245056", "received_at": "2026-01-16T14:20:45.559415"}}
{"event_type": "price_change", "event_ts": "2026-01-16T14:20:45.559415", "ingestion_ts": "2026-01-16T14:20:56.869125", "market_id": "0x49686d26fb712515cd5e12c23f0a1c7e10214c7faa3cb0a730aabe0c33694082", "raw": {"market": "0x49686d26fb712515cd5e12c23f0a1c7e10214c7faa3cb0a730aabe0c33694082", "asset_id": "30442780799048074404860985387051749017905070253466005720364298335239299761065", "price": "0.089", "size": "132.98", "side": "BUY", "timestamp": "1768573245056", "received_at": "2026-01-16T14:20:45.559415"}}
{"event_type": "price_change", "event_ts": "2026-01-16T14:20:46.693919", "ingestion_ts": "2026-01-16T14:20:56.869125", "market_id": "0xc55db914f0fd1fee18997706712c0dfd8d0369cdbef93a9fef12bd001914ca77", "raw": {"market": "0xc55db914f0fd1fee18997706712c0dfd8d0369cdbef93a9fef12bd001914ca77", "asset_id": "114600293444080540179603459515770723592661967180480327891296353898330242622833", "price": "0.86", "size": "0", "side": "BUY", "timestamp": "1768573246126", "received_at": "2026-01-16T14:20:46.693919"}}
{"event_type": "price_change", "event_ts": "2026-01-16T14:20:46.693919", "ingestion_ts": "2026-01-16T14:20:56.869125", "market_id": "0xc55db914f0fd1fee18997706712c0dfd8d0369cdbef93a9fef12bd001914ca77", "raw": {"market": "0xc55db914f0fd1fee18997706712c0dfd8d0369cdbef93a9fef12bd001914ca77", "asset_id": "72354723612769247426741660426331235762851940382312402276325808095604519806766", "price": "0.14", "size": "0", "side": "SELL", "timestamp": "1768573246126", "received_at": "2026-01-16T14:20:46.693919"}}
{"event_type": "price_change", "event_ts": "2026-01-16T14:20:46.693957", "ingestion_ts": "2026-01-16T14:20:56.869125", "market_id": "0xb9bbdd34304344dcc45803780a34c97d73a00133a5ecf70f63e1008b8abb2fca", "raw": {"market": "0xb9bbdd34304344dcc45803780a34c97d73a00133a5ecf70f63e1008b8abb2fca", "asset_id": "8682484153073832526711485265636767086525069344085206423986003504588877767339", "price": "0.851", "size": "558", "side": "BUY", "timestamp": "1768573246126", "received_at": "2026-01-16T14:20:46.693957"}}
{"event_type": "price_change", "event_ts": "2026-01-16T14:20:46.693957", "ingestion_ts": "2026-01-16T14:20:56.869125", "market_id": "0xb9bbdd34304344dcc45803780a34c97d73a00133a5ecf70f63e1008b8abb2fca", "raw": {"market": "0xb9bbdd34304344dcc45803780a34c97d73a00133a5ecf70f63e1008b8abb2fca", "asset_id": "72012724360700510767037780555710363830014634797787940282136454146828040926557", "price": "0.149", "size": "558", "side": "SELL", "timestamp": "1768573246126", "received_at": "2026-01-16T14:20:46.693957"}}
{"event_type": "price_change", "event_ts": "2026-01-16T14:20:46.697673", "ingestion_ts": "2026-01-16T14:20:56.869125", "market_id": "0x2393ed0b0fdc450054c7b9071907eca75cf4fc36e385adf4a0a5f99ee62243e8", "raw": {"market": "0x2393ed0b0fdc450054c7b9071907eca75cf4fc36e385adf4a0a5f99ee62243e8", "asset_id": "32769749367306925959219403371425714180265458150646381231272229429098460625924", "price": "0.85", "size": "0", "side": "BUY", "timestamp": "1768573246126", "received_at": "2026-01-16T14:20:46.697673"}}
{"event_type": "price_change", "event_ts": "2026-01-16T14:20:46.697673", "ingestion_ts": "2026-01-16T14:20:56.869125", "market_id": "0x2393ed0b0fdc450054c7b9071907eca75cf4fc36e385adf4a0a5f99ee62243e8", "raw": {"market": "0x2393ed0b0fdc450054c7b9071907eca75cf4fc36e385adf4a0a5f99ee62243e8", "asset_id": "100074770378634056601572485653252702850363676459996771990439989989293515601975", "price": "0.15", "size": "0", "side": "SELL", "timestamp": "1768573246126", "received_at": "2026-01-16T14:20:46.697673"}}
{"event_type": "price_change", "event_ts": "2026-01-16T14:20:46.697706", "ingestion_ts": "2026-01-16T14:20:56.869125", "market_id": "0x9472be65457510b7fc3477b20ba90910e99d92eac8421a14bf4b7b7a08ef31dc", "raw": {"market": "0x9472be65457510b7fc3477b20ba90910e99d92eac8421a14bf4b7b7a08ef31dc", "asset_id": "43311793366960417907757893276427136943959788721376762326430771171648759300146", "price": "0.859", "size": "0", "side": "BUY", "timestamp": "1768573246126", "received_at": "2026-01-16T14:20:46.697706"}}
{"event_type": "price_change", "event_ts": "2026-01-16T14:20:46.697706", "ingestion_ts": "2026-01-16T14:20:56.869125", "market_id": "0x9472be65457510b7fc3477b20ba90910e99d92eac8421a14bf4b7b7a08ef31dc", "raw": {"market": "0x9472be65457510b7fc3477b20ba90910e99d92eac8421a14bf4b7b7a08ef31dc", "asset_id": "73414222381656326204771753454630063673548497164758947581648273905027617570612", "price": "0.141", "size": "0", "side": "SELL", "timestamp": "1768573246126", "received_at": "2026-01-16T14:20:46.697706"}}
{"event_type": "price_change", "event_ts": "2026-01-16T14:20:46.697721", "ingestion_ts": "2026-01-16T14:20:56.869125", "market_id": "0x49a20c7523c271099008f3ef9a31521263b24d637959852a391e6b4697b1a437", "raw": {"market": "0x49a20c7523c271099008f3ef9a31521263b24d637959852a391e6b4697b1a437", "asset_id": "55881023621710858558280545117465775643848233756850602339827152783696837905531", "price": "0.858", "size": "0", "side": "BUY", "timestamp": "1768573246126", "received_at": "2026-01-16T14:20:46.697721"}}
{"event_type": "price_change", "event_ts": "2026-01-16T14:20:46.697721", "ingestion_ts": "2026-01-16T14:20:56.869125", "market_id": "0x49a20c7523c271099008f3ef9a31521263b24d637959852a391e6b4697b1a437", "raw": {"market": "0x49a20c7523c271099008f3ef9a31521263b24d637959852a391e6b4697b1a437", "asset_id": "13018971792603393862521629014128024641178044618205296260525674415067194037856", "price": "0.142", "size": "0", "side": "SELL", "timestamp": "1768573246126", "received_at": "2026-01-16T14:20:46.697721"}}
{"event_type": "price_change", "event_ts": "2026-01-16T14:20:46.762651", "ingestion_ts": "2026-01-16T14:20:56.869125", "market_id": "0xb9bbdd34304344dcc45803780a34c97d73a00133a5ecf70f63e1008b8abb2fca", "raw": {"market": "0xb9bbdd34304344dcc45803780a34c97d73a00133a5ecf70f63e1008b8abb2fca", "asset_id": "8682484153073832526711485265636767086525069344085206423986003504588877767339", "price": "0.839", "size": "10", "side": "BUY", "timestamp": "1768573246195", "received_at": "2026-01-16T14:20:46.762651"}}
{"event_type": "price_change", "event_ts": "2026-01-16T14:20:46.762651", "ingestion_ts": "2026-01-16T14:20:56.869125", "market_id": "0xb9bbdd34304344dcc45803780a34c97d73a00133a5ecf70f63e1008b8abb2fca", "raw": {"market": "0xb9bbdd34304344dcc45803780a34c97d73a00133a5ecf70f63e1008b8abb2fca", "asset_id": "72012724360700510767037780555710363830014634797787940282136454146828040926557", "price": "0.161", "size": "10", "side": "SELL", "timestamp": "1768573246195", "received_at": "2026-01-16T14:20:46.762651"}}
{"event_type": "price_change", "event_ts": "2026-01-16T14:20:46.762715", "ingestion_ts": "2026-01-16T14:20:56.869125", "market_id": "0x49a20c7523c271099008f3ef9a31521263b24d637959852a391e6b4697b1a437", "raw": {"market": "0x49a20c7523c271099008f3ef9a31521263b24d637959852a391e6b4697b1a437", "asset_id": "55881023621710858558280545117465775643848233756850602339827152783696837905531", "price": "0.857", "size": "40", "side": "BUY", "timestamp": "1768573246195", "received_at": "2026-01-16T14:20:46.762715"}}
{"event_type": "price_change", "event_ts": "2026-01-16T14:20:46.762715", "ingestion_ts": "2026-01-16T14:20:56.869125", "market_id": "0x49a20c7523c271099008f3ef9a31521263b24d637959852a391e6b4697b1a437", "raw": {"market": "0x49a20c7523c271099008f3ef9a31521263b24d637959852a391e6b4697b1a437", "asset_id": "13018971792603393862521629014128024641178044618205296260525674415067194037856", "price": "0.143", "size": "40", "side": "SELL", "timestamp": "1768573246195", "received_at": "2026-01-16T14:20:46.762715"}}
{"event_type": "price_change", "event_ts": "2026-01-16T14:20:46.762729", "ingestion_ts": "2026-01-16T14:20:56.869125", "market_id": "0xc55db914f0fd1fee18997706712c0dfd8d0369cdbef93a9fef12bd001914ca77", "raw": {"market": "0xc55db914f0fd1fee18997706712c0dfd8d0369cdbef93a9fef12bd001914ca77", "asset_id": "114600293444080540179603459515770723592661967180480327891296353898330242622833", "price": "0.859", "size": "40", "side": "BUY", "timestamp": "1768573246195", "received_at": "2026-01-16T14:20:46.762729"}}
{"event_type": "price_change", "event_ts": "2026-01-16T14:20:46.762729", "ingestion_ts": "2026-01-16T14:20:56.869125", "market_id": "0xc55db914f0fd1fee18997706712c0dfd8d0369cdbef93a9fef12bd001914ca77", "raw": {"market": "0xc55db914f0fd1fee18997706712c0dfd8d0369cdbef93a9fef12bd001914ca77", "asset_id": "72354723612769247426741660426331235762851940382312402276325808095604519806766", "price": "0.141", "size": "40", "side": "SELL", "timestamp": "1768573246195", "received_at": "2026-01-16T14:20:46.762729"}}
{"event_type": "price_change", "event_ts": "2026-01-16T14:20:46.762742", "ingestion_ts": "2026-01-16T14:20:56.869125", "market_id": "0x2393ed0b0fdc450054c7b9071907eca75cf4fc36e385adf4a0a5f99ee62243e8", "raw": {"market": "0x2393ed0b0fdc450054c7b9071907eca75cf4fc36e385adf4a0a5f99ee62243e8", "asset_id": "32769749367306925959219403371425714180265458150646381231272229429098460625924", "price": "0.849", "size": "304", "side": "BUY", "timestamp": "1768573246195", "received_at": "2026-01-16T14:20:46.762742"}}
{"event_type": "price_change", "event_ts": "2026-01-16T14:20:46.762742", "ingestion_ts": "2026-01-16T14:20:56.869125", "market_id": "0x2393ed0b0fdc450054c7b9071907eca75cf4fc36e385adf4a0a5f99ee62243e8", "raw": {"market": "0x2393ed0b0fdc450054c7b9071907eca75cf4fc36e385adf4a0a5f99ee62243e8", "asset_id": "100074770378634056601572485653252702850363676459996771990439989989293515601975", "price": "0.151", "size": "304", "side": "SELL", "timestamp": "1768573246195", "received_at": "2026-01-16T14:20:46.762742"}}
{"event_type": "price_change", "event_ts": "2026-01-16T14:20:46.762753", "ingestion_ts": "2026-01-16T14:20:56.869125", "market_id": "0x9472be65457510b7fc3477b20ba90910e99d92eac8421a14bf4b7b7a08ef31dc", "raw": {"market": "0x9472be65457510b7fc3477b20ba90910e99d92eac8421a14bf4b7b7a08ef31dc", "asset_id": "43311793366960417907757893276427136943959788721376762326430771171648759300146", "price": "0.858", "size": "243", "side": "BUY", "timestamp": "1768573246195", "received_at": "2026-01-16T14:20:46.762753"}}
{"event_type": "price_change", "event_ts": "2026-01-16T14:20:46.762753", "ingestion_ts": "2026-01-16T14:20:56.869125", "market_id": "0x9472be65457510b7fc3477b20ba90910e99d92eac8421a14bf4b7b7a08ef31dc", "raw": {"market": "0x9472be65457510b7fc3477b20ba90910e99d92eac8421a14bf4b7b7a08ef31dc", "asset_id": "73414222381656326204771753454630063673548497164758947581648273905027617570612", "price": "0.142", "size": "243", "side": "SELL", "timestamp": "1768573246195", "received_at": "2026-01-16T14:20:46.762753"}}
{"event_type": "price_change", "event_ts": "2026-01-16T14:20:46.788475", "ingestion_ts": "2026-01-16T14:20:56.869125", "market_id": "0x2393ed0b0fdc450054c7b9071907eca75cf4fc36e385adf4a0a5f99ee62243e8", "raw": {"market": "0x2393ed0b0fdc450054c7b9071907eca75cf4fc36e385adf4a0a5f99ee62243e8", "asset_id": "100074770378634056601572485653252702850363676459996771990439989989293515601975", "price": "0.047", "size": "0", "side": "SELL", "timestamp": "1768573246231", "received_at": "2026-01-16T14:20:46.788475"}}
{"event_type": "price_change", "event_ts": "2026-01-16T14:20:46.788475", "ingestion_ts": "2026-01-16T14:20:56.869125", "market_id": "0x2393ed0b0fdc450054c7b9071907eca75cf4fc36e385adf4a0a5f99ee62243e8", "raw": {"market": "0x2393ed0b0fdc450054c7b9071907eca75cf4fc36e385adf4a0a5f99ee62243e8", "asset_id": "32769749367306925959219403371425714180265458150646381231272229429098460625924", "price": "0.953", "size": "0", "side": "BUY", "timestamp": "1768573246231", "received_at": "2026-01-16T14:20:46.788475"}}
{"event_type": "price_change", "event_ts": "2026-01-16T14:20:46.823744", "ingestion_ts": "2026-01-16T14:20:56.869125", "market_id": "0x2393ed0b0fdc450054c7b9071907eca75cf4fc36e385adf4a0a5f99ee62243e8", "raw": {"market": "0x2393ed0b0fdc450054c7b9071907eca75cf4fc36e385adf4a0a5f99ee62243e8", "asset_id": "100074770378634056601572485653252702850363676459996771990439989989293515601975", "price": "0.061", "size": "205", "side": "SELL", "timestamp": "1768573246267", "received_at": "2026-01-16T14:20:46.823744"}}
{"event_type": "price_change", "event_ts": "2026-01-16T14:20:46.823744", "ingestion_ts": "2026-01-16T14:20:56.869125", "market_id": "0x2393ed0b0fdc450054c7b9071907eca75cf4fc36e385adf4a0a5f99ee62243e8", "raw": {"market": "0x2393ed0b0fdc450054c7b9071907eca75cf4fc36e385adf4a0a5f99ee62243e8", "asset_id": "32769749367306925959219403371425714180265458150646381231272229429098460625924", "price": "0.939", "size": "205", "side": "BUY", "timestamp": "1768573246267", "received_at": "2026-01-16T14:20:46.823744"}}
{"event_type": "price_change", "event_ts": "2026-01-16T14:20:48.064311", "ingestion_ts": "2026-01-16T14:20:56.869125", "market_id": "0x427bc4b40c09b3dcbc973747f0e4b079bed91b3e5a0aed5c36edd0f7591485f4", "raw": {"market": "0x427bc4b40c09b3dcbc973747f0e4b079bed91b3e5a0aed5c36edd0f7591485f4", "asset_id": "115669573443672055876643967408433138119481486650803218131873713375232186497057", "price": "0.003", "size": "0", "side": "BUY", "timestamp": "1768573247788", "received_at": "2026-01-16T14:20:48.064311"}}
{"event_type": "price_change", "event_ts": "2026-01-16T14:20:48.064311", "ingestion_ts": "2026-01-16T14:20:56.869125", "market_id": "0x427bc4b40c09b3dcbc973747f0e4b079bed91b3e5a0aed5c36edd0f7591485f4", "raw": {"market": "0x427bc4b40c09b3dcbc973747f0e4b079bed91b3e5a0aed5c36edd0f7591485f4", "asset_id": "86130975769502911188457673769190265049139877688522439001984850068234616395137", "price": "0.997", "size": "0", "side": "SELL", "timestamp": "1768573247788", "received_at": "2026-01-16T14:20:48.064311"}}
{"event_type": "price_change", "event_ts": "2026-01-16T14:20:48.064358", "ingestion_ts": "2026-01-16T14:20:56.869125", "market_id": "0x427bc4b40c09b3dcbc973747f0e4b079bed91b3e5a0aed5c36edd0f7591485f4", "raw": {"market": "0x427bc4b40c09b3dcbc973747f0e4b079bed91b3e5a0aed5c36edd0f7591485f4", "asset_id": "115669573443672055876643967408433138119481486650803218131873713375232186497057", "price": "0.006", "size": "28.75", "side": "BUY", "timestamp": "1768573247788", "received_at": "2026-01-16T14:20:48.064358"}}
{"event_type": "price_change", "event_ts": "2026-01-16T14:20:48.064358", "ingestion_ts": "2026-01-16T14:20:56.869125", "market_id": "0x427bc4b40c09b3dcbc973747f0e4b079bed91b3e5a0aed5c36edd0f7591485f4", "raw": {"market": "0x427bc4b40c09b3dcbc973747f0e4b079bed91b3e5a0aed5c36edd0f7591485f4", "asset_id": "86130975769502911188457673769190265049139877688522439001984850068234616395137", "price": "0.994", "size": "28.75", "side": "SELL", "timestamp": "1768573247788", "received_at": "2026-01-16T14:20:48.064358"}}
{"event_type": "price_change", "event_ts": "2026-01-16T14:20:48.387957", "ingestion_ts": "2026-01-16T14:20:56.869125", "market_id": "0x427bc4b40c09b3dcbc973747f0e4b079bed91b3e5a0aed5c36edd0f7591485f4", "raw": {"market": "0x427bc4b40c09b3dcbc973747f0e4b079bed91b3e5a0aed5c36edd0f7591485f4", "asset_id": "115669573443672055876643967408433138119481486650803218131873713375232186497057", "price": "0.002", "size": "105.04", "side": "BUY", "timestamp": "1768573248175", "received_at": "2026-01-16T14:20:48.387957"}}
{"event_type": "price_change", "event_ts": "2026-01-16T14:20:48.387957", "ingestion_ts": "2026-01-16T14:20:56.869125", "market_id": "0x427bc4b40c09b3dcbc973747f0e4b079bed91b3e5a0aed5c36edd0f7591485f4", "raw": {"market": "0x427bc4b40c09b3dcbc973747f0e4b079bed91b3e5a0aed5c36edd0f7591485f4", "asset_id": "86130975769502911188457673769190265049139877688522439001984850068234616395137", "price": "0.998", "size": "105.04", "side": "SELL", "timestamp": "1768573248175", "received_at": "2026-01-16T14:20:48.387957"}}
{"event_type": "price_change", "event_ts": "2026-01-16T14:20:48.388102", "ingestion_ts": "2026-01-16T14:20:56.869125", "market_id": "0x427bc4b40c09b3dcbc973747f0e4b079bed91b3e5a0aed5c36edd0f7591485f4", "raw": {"market": "0x427bc4b40c09b3dcbc973747f0e4b079bed91b3e5a0aed5c36edd0f7591485f4", "asset_id": "115669573443672055876643967408433138119481486650803218131873713375232186497057", "price": "0.008", "size": "6.31", "side": "BUY", "timestamp": "1768573248176", "received_at": "2026-01-16T14:20:48.388102"}}
{"event_type": "price_change", "event_ts": "2026-01-16T14:20:48.388102", "ingestion_ts": "2026-01-16T14:20:56.869125", "market_id": "0x427bc4b40c09b3dcbc973747f0e4b079bed91b3e5a0aed5c36edd0f7591485f4", "raw": {"market": "0x427bc4b40c09b3dcbc973747f0e4b079bed91b3e5a0aed5c36edd0f7591485f4", "asset_id": "86130975769502911188457673769190265049139877688522439001984850068234616395137", "price": "0.992", "size": "6.31", "side": "SELL", "timestamp": "1768573248176", "received_at": "2026-01-16T14:20:48.388102"}}
{"event_type": "price_change", "event_ts": "2026-01-16T14:20:48.388128", "ingestion_ts": "2026-01-16T14:20:56.869125", "market_id": "0x427bc4b40c09b3dcbc973747f0e4b079bed91b3e5a0aed5c36edd0f7591485f4", "raw": {"market": "0x427bc4b40c09b3dcbc973747f0e4b079bed91b3e5a0aed5c36edd0f7591485f4", "asset_id": "115669573443672055876643967408433138119481486650803218131873713375232186497057", "price": "0.002", "size": "110.76", "side": "BUY", "timestamp": "1768573248177", "received_at": "2026-01-16T14:20:48.388128"}}
{"event_type": "price_change", "event_ts": "2026-01-16T14:20:48.388128", "ingestion_ts": "2026-01-16T14:20:56.869125", "market_id": "0x427bc4b40c09b3dcbc973747f0e4b079bed91b3e5a0aed5c36edd0f7591485f4", "raw": {"market": "0x427bc4b40c09b3dcbc973747f0e4b079bed91b3e5a0aed5c36edd0f7591485f4", "asset_id": "86130975769502911188457673769190265049139877688522439001984850068234616395137", "price": "0.998", "size": "110.76", "side": "SELL", "timestamp": "1768573248177", "received_at": "2026-01-16T14:20:48.388128"}}
{"event_type": "price_change", "event_ts": "2026-01-16T14:20:48.398485", "ingestion_ts": "2026-01-16T14:20:56.869125", "market_id": "0x427bc4b40c09b3dcbc973747f0e4b079bed91b3e5a0aed5c36edd0f7591485f4", "raw": {"market": "0x427bc4b40c09b3dcbc973747f0e4b079bed91b3e5a0aed5c36edd0f7591485f4", "asset_id": "86130975769502911188457673769190265049139877688522439001984850068234616395137", "price": "0.804", "size": "0", "side": "BUY", "timestamp": "1768573248208", "received_at": "2026-01-16T14:20:48.398485"}}
{"event_type": "price_change", "event_ts": "2026-01-16T14:20:48.398485", "ingestion_ts": "2026-01-16T14:20:56.869125", "market_id": "0x427bc4b40c09b3dcbc973747f0e4b079bed91b3e5a0aed5c36edd0f7591485f4", "raw": {"market": "0x427bc4b40c09b3dcbc973747f0e4b079bed91b3e5a0aed5c36edd0f7591485f4", "asset_id": "115669573443672055876643967408433138119481486650803218131873713375232186497057", "price": "0.196", "size": "0", "side": "SELL", "timestamp": "1768573248208", "received_at": "2026-01-16T14:20:48.398485"}}
{"event_type": "price_change", "event_ts": "2026-01-16T14:20:48.398547", "ingestion_ts": "2026-01-16T14:20:56.869125", "market_id": "0x427bc4b40c09b3dcbc973747f0e4b079bed91b3e5a0aed5c36edd0f7591485f4", "raw": {"market": "0x427bc4b40c09b3dcbc973747f0e4b079bed91b3e5a0aed5c36edd0f7591485f4", "asset_id": "86130975769502911188457673769190265049139877688522439001984850068234616395137", "price": "0.993", "size": "0", "side": "SELL", "timestamp": "1768573248208", "received_at": "2026-01-16T14:20:48.398547"}}
{"event_type": "price_change", "event_ts": "2026-01-16T14:20:48.398547", "ingestion_ts": "2026-01-16T14:20:56.869125", "market_id": "0x427bc4b40c09b3dcbc973747f0e4b079bed91b3e5a0aed5c36edd0f7591485f4", "raw": {"market": "0x427bc4b40c09b3dcbc973747f0e4b079bed91b3e5a0aed5c36edd0f7591485f4", "asset_id": "115669573443672055876643967408433138119481486650803218131873713375232186497057", "price": "0.007", "size": "0", "side": "BUY", "timestamp": "1768573248208", "received_at": "2026-01-16T14:20:48.398547"}}
{"event_type": "price_change", "event_ts": "2026-01-16T14:20:48.766044", "ingestion_ts": "2026-01-16T14:20:56.869125", "market_id": "0x427bc4b40c09b3dcbc973747f0e4b079bed91b3e5a0aed5c36edd0f7591485f4", "raw": {"market": "0x427bc4b40c09b3dcbc973747f0e4b079bed91b3e5a0aed5c36edd0f7591485f4", "asset_id": "115669573443672055876643967408433138119481486650803218131873713375232186497057", "price": "0.197", "size": "24.09", "side": "SELL", "timestamp": "1768573248708", "received_at": "2026-01-16T14:20:48.766044"}}
{"event_type": "price_change", "event_ts": "2026-01-16T14:20:48.766044", "ingestion_ts": "2026-01-16T14:20:56.869125", "market_id": "0x427bc4b40c09b3dcbc973747f0e4b079bed91b3e5a0aed5c36edd0f7591485f4", "raw": {"market": "0x427bc4b40c09b3dcbc973747f0e4b079bed91b3e5a0aed5c36edd0f7591485f4", "asset_id": "86130975769502911188457673769190265049139877688522439001984850068234616395137", "price": "0.803", "size": "24.09", "side": "BUY", "timestamp": "1768573248708", "received_at": "2026-01-16T14:20:48.766044"}}
{"event_type": "price_change", "event_ts": "2026-01-16T14:20:48.766089", "ingestion_ts": "2026-01-16T14:20:56.869125", "market_id": "0x427bc4b40c09b3dcbc973747f0e4b079bed91b3e5a0aed5c36edd0f7591485f4", "raw": {"market": "0x427bc4b40c09b3dcbc973747f0e4b079bed91b3e5a0aed5c36edd0f7591485f4", "asset_id": "115669573443672055876643967408433138119481486650803218131873713375232186497057", "price": "0.469", "size": "10.13", "side": "SELL", "timestamp": "1768573248708", "received_at": "2026-01-16T14:20:48.766089"}}
{"event_type": "price_change", "event_ts": "2026-01-16T14:20:48.766089", "ingestion_ts": "2026-01-16T14:20:56.869125", "market_id": "0x427bc4b40c09b3dcbc973747f0e4b079bed91b3e5a0aed5c36edd0f7591485f4", "raw": {"market": "0x427bc4b40c09b3dcbc973747f0e4b079bed91b3e5a0aed5c36edd0f7591485f4", "asset_id": "86130975769502911188457673769190265049139877688522439001984850068234616395137", "price": "0.531", "size": "10.13", "side": "BUY", "timestamp": "1768573248708", "received_at": "2026-01-16T14:20:48.766089"}}
{"event_type": "price_change", "event_ts": "2026-01-16T14:20:48.964857", "ingestion_ts": "2026-01-16T14:20:56.869125", "market_id": "0x427bc4b40c09b3dcbc973747f0e4b079bed91b3e5a0aed5c36edd0f7591485f4", "raw": {"market": "0x427bc4b40c09b3dcbc973747f0e4b079bed91b3e5a0aed5c36edd0f7591485f4", "asset_id": "115669573443672055876643967408433138119481486650803218131873713375232186497057", "price": "0.47", "size": "54.51", "side": "SELL", "timestamp": "1768573248921", "received_at": "2026-01-16T14:20:48.964857"}}
{"event_type": "price_change", "event_ts": "2026-01-16T14:20:48.964857", "ingestion_ts": "2026-01-16T14:20:56.869125", "market_id": "0x427bc4b40c09b3dcbc973747f0e4b079bed91b3e5a0aed5c36edd0f7591485f4", "raw": {"market": "0x427bc4b40c09b3dcbc973747f0e4b079bed91b3e5a0aed5c36edd0f7591485f4", "asset_id": "86130975769502911188457673769190265049139877688522439001984850068234616395137", "price": "0.53", "size": "54.51", "side": "BUY", "timestamp": "1768573248921", "received_at": "2026-01-16T14:20:48.964857"}}
{"event_type": "price_change", "event_ts": "2026-01-16T14:20:48.964911", "ingestion_ts": "2026-01-16T14:20:56.869125", "market_id": "0x427bc4b40c09b3dcbc973747f0e4b079bed91b3e5a0aed5c36edd0f7591485f4", "raw": {"market": "0x427bc4b40c09b3dcbc973747f0e4b079bed91b3e5a0aed5c36edd0f7591485f4", "asset_id": "115669573443672055876643967408433138119481486650803218131873713375232186497057", "price": "0.47", "size": "71.63", "side": "SELL", "timestamp": "1768573248922", "received_at": "2026-01-16T14:20:48.964911"}}
{"event_type": "price_change", "event_ts": "2026-01-16T14:20:48.964911", "ingestion_ts": "2026-01-16T14:20:56.869125", "market_id": "0x427bc4b40c09b3dcbc973747f0e4b079bed91b3e5a0aed5c36edd0f7591485f4", "raw": {"market": "0x427bc4b40c09b3dcbc973747f0e4b079bed91b3e5a0aed5c36edd0f7591485f4", "asset_id": "86130975769502911188457673769190265049139877688522439001984850068234616395137", "price": "0.53", "size": "71.63", "side": "BUY", "timestamp": "1768573248922", "received_at": "2026-01-16T14:20:48.964911"}}
{"event_type": "price_change", "event_ts": "2026-01-16T14:20:51.280668", "ingestion_ts": "2026-01-16T14:20:56.869125", "market_id": "0x2393ed0b0fdc450054c7b9071907eca75cf4fc36e385adf4a0a5f99ee62243e8", "raw": {"market": "0x2393ed0b0fdc450054c7b9071907eca75cf4fc36e385adf4a0a5f99ee62243e8", "asset_id": "32769749367306925959219403371425714180265458150646381231272229429098460625924", "price": "0.94", "size": "50", "side": "BUY", "timestamp": "1768573251203", "received_at": "2026-01-16T14:20:51.280668"}}
{"event_type": "price_change", "event_ts": "2026-01-16T14:20:51.280668", "ingestion_ts": "2026-01-16T14:20:56.869125", "market_id": "0x2393ed0b0fdc450054c7b9071907eca75cf4fc36e385adf4a0a5f99ee62243e8", "raw": {"market": "0x2393ed0b0fdc450054c7b9071907eca75cf4fc36e385adf4a0a5f99ee62243e8", "asset_id": "100074770378634056601572485653252702850363676459996771990439989989293515601975", "price": "0.06", "size": "50", "side": "SELL", "timestamp": "1768573251203", "received_at": "2026-01-16T14:20:51.280668"}}
{"event_type": "price_change", "event_ts": "2026-01-16T14:20:51.347050", "ingestion_ts": "2026-01-16T14:20:56.869125", "market_id": "0x2393ed0b0fdc450054c7b9071907eca75cf4fc36e385adf4a0a5f99ee62243e8", "raw": {"market": "0x2393ed0b0fdc450054c7b9071907eca75cf4fc36e385adf4a0a5f99ee62243e8", "asset_id": "100074770378634056601572485653252702850363676459996771990439989989293515601975", "price": "0.061", "size": "0", "side": "SELL", "timestamp": "1768573251290", "received_at": "2026-01-16T14:20:51.347050"}}
{"event_type": "price_change", "event_ts": "2026-01-16T14:20:51.347050", "ingestion_ts": "2026-01-16T14:20:56.869125", "market_id": "0x2393ed0b0fdc450054c7b9071907eca75cf4fc36e385adf4a0a5f99ee62243e8", "raw": {"market": "0x2393ed0b0fdc450054c7b9071907eca75cf4fc36e385adf4a0a5f99ee62243e8", "asset_id": "32769749367306925959219403371425714180265458150646381231272229429098460625924", "price": "0.939", "size": "0", "side": "BUY", "timestamp": "1768573251290", "received_at": "2026-01-16T14:20:51.347050"}}
{"event_type": "price_change", "event_ts": "2026-01-16T14:20:51.371450", "ingestion_ts": "2026-01-16T14:20:56.869125", "market_id": "0x2393ed0b0fdc450054c7b9071907eca75cf4fc36e385adf4a0a5f99ee62243e8", "raw": {"market": "0x2393ed0b0fdc450054c7b9071907eca75cf4fc36e385adf4a0a5f99ee62243e8", "asset_id": "100074770378634056601572485653252702850363676459996771990439989989293515601975", "price": "0.059", "size": "197", "side": "SELL", "timestamp": "1768573251329", "received_at": "2026-01-16T14:20:51.371450"}}
{"event_type": "price_change", "event_ts": "2026-01-16T14:20:51.371450", "ingestion_ts": "2026-01-16T14:20:56.869125", "market_id": "0x2393ed0b0fdc450054c7b9071907eca75cf4fc36e385adf4a0a5f99ee62243e8", "raw": {"market": "0x2393ed0b0fdc450054c7b9071907eca75cf4fc36e385adf4a0a5f99ee62243e8", "asset_id": "32769749367306925959219403371425714180265458150646381231272229429098460625924", "price": "0.941", "size": "197", "side": "BUY", "timestamp": "1768573251329", "received_at": "2026-01-16T14:20:51.371450"}}
{"event_type": "price_change", "event_ts": "2026-01-16T14:20:51.435777", "ingestion_ts": "2026-01-16T14:20:56.869125", "market_id": "0x49686d26fb712515cd5e12c23f0a1c7e10214c7faa3cb0a730aabe0c33694082", "raw": {"market": "0x49686d26fb712515cd5e12c23f0a1c7e10214c7faa3cb0a730aabe0c33694082", "asset_id": "13244681086321087932946246027856416106585284024824496763706748621681543444582", "price": "0.853", "size": "50.86", "side": "BUY", "timestamp": "1768573251395", "received_at": "2026-01-16T14:20:51.435777"}}
{"event_type": "price_change", "event_ts": "2026-01-16T14:20:51.435777", "ingestion_ts": "2026-01-16T14:20:56.869125", "market_id": "0x49686d26fb712515cd5e12c23f0a1c7e10214c7faa3cb0a730aabe0c33694082", "raw": {"market": "0x49686d26fb712515cd5e12c23f0a1c7e10214c7faa3cb0a730aabe0c33694082", "asset_id": "30442780799048074404860985387051749017905070253466005720364298335239299761065", "price": "0.147", "size": "50.86", "side": "SELL", "timestamp": "1768573251395", "received_at": "2026-01-16T14:20:51.435777"}}
{"event_type": "price_change", "event_ts": "2026-01-16T14:20:51.558912", "ingestion_ts": "2026-01-16T14:20:56.869125", "market_id": "0x2393ed0b0fdc450054c7b9071907eca75cf4fc36e385adf4a0a5f99ee62243e8", "raw": {"market": "0x2393ed0b0fdc450054c7b9071907eca75cf4fc36e385adf4a0a5f99ee62243e8", "asset_id": "32769749367306925959219403371425714180265458150646381231272229429098460625924", "price": "0.954", "size": "0", "side": "BUY", "timestamp": "1768573251521", "received_at": "2026-01-16T14:20:51.558912"}}
{"event_type": "price_change", "event_ts": "2026-01-16T14:20:51.558912", "ingestion_ts": "2026-01-16T14:20:56.869125", "market_id": "0x2393ed0b0fdc450054c7b9071907eca75cf4fc36e385adf4a0a5f99ee62243e8", "raw": {"market": "0x2393ed0b0fdc450054c7b9071907eca75cf4fc36e385adf4a0a5f99ee62243e8", "asset_id": "100074770378634056601572485653252702850363676459996771990439989989293515601975", "price": "0.046", "size": "0", "side": "SELL", "timestamp": "1768573251521", "received_at": "2026-01-16T14:20:51.558912"}}
{"event_type": "price_change", "event_ts": "2026-01-16T14:20:53.538797", "ingestion_ts": "2026-01-16T14:20:56.869125", "market_id": "0xae5584fbb57f23c1c608d544b656f23d8bf12340cef70811cf31bb0cb4fc2115", "raw": {"market": "0xae5584fbb57f23c1c608d544b656f23d8bf12340cef70811cf31bb0cb4fc2115", "asset_id": "42278252558046940014991595990628759801692726198478046188873057685686228021663", "price": "0.99", "size": "8145.4", "side": "SELL", "timestamp": "1768573253498", "received_at": "2026-01-16T14:20:53.538797"}}
{"event_type": "price_change", "event_ts": "2026-01-16T14:20:53.538797", "ingestion_ts": "2026-01-16T14:20:56.869125", "market_id": "0xae5584fbb57f23c1c608d544b656f23d8bf12340cef70811cf31bb0cb4fc2115", "raw": {"market": "0xae5584fbb57f23c1c608d544b656f23d8bf12340cef70811cf31bb0cb4fc2115", "asset_id": "28946595841244317705636126646676849578876740730186646421280828201004700559420", "price": "0.01", "size": "8145.4", "side": "BUY", "timestamp": "1768573253498", "received_at": "2026-01-16T14:20:53.538797"}}
{"event_type": "price_change", "event_ts": "2026-01-16T14:20:53.651252", "ingestion_ts": "2026-01-16T14:20:56.869125", "market_id": "0xae5584fbb57f23c1c608d544b656f23d8bf12340cef70811cf31bb0cb4fc2115", "raw": {"market": "0xae5584fbb57f23c1c608d544b656f23d8bf12340cef70811cf31bb0cb4fc2115", "asset_id": "28946595841244317705636126646676849578876740730186646421280828201004700559420", "price": "0.01", "size": "8097.6", "side": "BUY", "timestamp": "1768573253609", "received_at": "2026-01-16T14:20:53.651252"}}
{"event_type": "price_change", "event_ts": "2026-01-16T14:20:53.651252", "ingestion_ts": "2026-01-16T14:20:56.869125", "market_id": "0xae5584fbb57f23c1c608d544b656f23d8bf12340cef70811cf31bb0cb4fc2115", "raw": {"market": "0xae5584fbb57f23c1c608d544b656f23d8bf12340cef70811cf31bb0cb4fc2115", "asset_id": "42278252558046940014991595990628759801692726198478046188873057685686228021663", "price": "0.99", "size": "8097.6", "side": "SELL", "timestamp": "1768573253609", "received_at": "2026-01-16T14:20:53.651252"}}
{"event_type": "price_change", "event_ts": "2026-01-16T14:20:53.730833", "ingestion_ts": "2026-01-16T14:20:56.869125", "market_id": "0x49686d26fb712515cd5e12c23f0a1c7e10214c7faa3cb0a730aabe0c33694082", "raw": {"market": "0x49686d26fb712515cd5e12c23f0a1c7e10214c7faa3cb0a730aabe0c33694082", "asset_id": "30442780799048074404860985387051749017905070253466005720364298335239299761065", "price": "0.148", "size": "0", "side": "SELL", "timestamp": "1768573253692", "received_at": "2026-01-16T14:20:53.730833"}}
{"event_type": "price_change", "event_ts": "2026-01-16T14:20:53.730833", "ingestion_ts": "2026-01-16T14:20:56.869125", "market_id": "0x49686d26fb712515cd5e12c23f0a1c7e10214c7faa3cb0a730aabe0c33694082", "raw": {"market": "0x49686d26fb712515cd5e12c23f0a1c7e10214c7faa3cb0a730aabe0c33694082", "asset_id": "13244681086321087932946246027856416106585284024824496763706748621681543444582", "price": "0.852", "size": "0", "side": "BUY", "timestamp": "1768573253692", "received_at": "2026-01-16T14:20:53.730833"}}
{"event_type": "price_change", "event_ts": "2026-01-16T14:20:55.950337", "ingestion_ts": "2026-01-16T14:20:56.869125", "market_id": "0x49686d26fb712515cd5e12c23f0a1c7e10214c7faa3cb0a730aabe0c33694082", "raw": {"market": "0x49686d26fb712515cd5e12c23f0a1c7e10214c7faa3cb0a730aabe0c33694082", "asset_id": "30442780799048074404860985387051749017905070253466005720364298335239299761065", "price": "0.146", "size": "17.5", "side": "SELL", "timestamp": "1768573255894", "received_at": "2026-01-16T14:20:55.950337"}}
{"event_type": "price_change", "event_ts": "2026-01-16T14:20:55.950337", "ingestion_ts": "2026-01-16T14:20:56.869125", "market_id": "0x49686d26fb712515cd5e12c23f0a1c7e10214c7faa3cb0a730aabe0c33694082", "raw": {"market": "0x49686d26fb712515cd5e12c23f0a1c7e10214c7faa3cb0a730aabe0c33694082", "asset_id": "13244681086321087932946246027856416106585284024824496763706748621681543444582", "price": "0.854", "size": "17.5", "side": "BUY", "timestamp": "1768573255894", "received_at": "2026-01-16T14:20:55.950337"}}
{"event_type": "price_change", "event_ts": "2026-01-16T14:20:55.961063", "ingestion_ts": "2026-01-16T14:20:56.869125", "market_id": "0x49686d26fb712515cd5e12c23f0a1c7e10214c7faa3cb0a730aabe0c33694082", "raw": {"market": "0x49686d26fb712515cd5e12c23f0a1c7e10214c7faa3cb0a730aabe0c33694082", "asset_id": "13244681086321087932946246027856416106585284024824496763706748621681543444582", "price": "0.911", "size": "14.98", "side": "SELL", "timestamp": "1768573255924", "received_at": "2026-01-16T14:20:55.961063"}}
{"event_type": "price_change", "event_ts": "2026-01-16T14:20:55.961063", "ingestion_ts": "2026-01-16T14:20:56.869125", "market_id": "0x49686d26fb712515cd5e12c23f0a1c7e10214c7faa3cb0a730aabe0c33694082", "raw": {"market": "0x49686d26fb712515cd5e12c23f0a1c7e10214c7faa3cb0a730aabe0c33694082", "asset_id": "30442780799048074404860985387051749017905070253466005720364298335239299761065", "price": "0.089", "size": "14.98", "side": "BUY", "timestamp": "1768573255924", "received_at": "2026-01-16T14:20:55.961063"}}
{"event_type": "price_change", "event_ts": "2026-01-16T14:20:56.154008", "ingestion_ts": "2026-01-16T14:20:56.869125", "market_id": "0x427bc4b40c09b3dcbc973747f0e4b079bed91b3e5a0aed5c36edd0f7591485f4", "raw": {"market": "0x427bc4b40c09b3dcbc973747f0e4b079bed91b3e5a0aed5c36edd0f7591485f4", "asset_id": "115669573443672055876643967408433138119481486650803218131873713375232186497057", "price": "0.002", "size": "103.44", "side": "BUY", "timestamp": "1768573256025", "received_at": "2026-01-16T14:20:56.154008"}}
{"event_type": "price_change", "event_ts": "2026-01-16T14:20:56.154008", "ingestion_ts": "2026-01-16T14:20:56.869125", "market_id": "0x427bc4b40c09b3dcbc973747f0e4b079bed91b3e5a0aed5c36edd0f7591485f4", "raw": {"market": "0x427bc4b40c09b3dcbc973747f0e4b079bed91b3e5a0aed5c36edd0f7591485f4", "asset_id": "86130975769502911188457673769190265049139877688522439001984850068234616395137", "price": "0.998", "size": "103.44", "side": "SELL", "timestamp": "1768573256025", "received_at": "2026-01-16T14:20:56.154008"}}
{"event_type": "price_change", "event_ts": "2026-01-16T14:20:56.154023", "ingestion_ts": "2026-01-16T14:20:56.869125", "market_id": "0x427bc4b40c09b3dcbc973747f0e4b079bed91b3e5a0aed5c36edd0f7591485f4", "raw": {"market": "0x427bc4b40c09b3dcbc973747f0e4b079bed91b3e5a0aed5c36edd0f7591485f4", "asset_id": "115669573443672055876643967408433138119481486650803218131873713375232186497057", "price": "0.008", "size": "0", "side": "BUY", "timestamp": "1768573256025", "received_at": "2026-01-16T14:20:56.154023"}}
{"event_type": "price_change", "event_ts": "2026-01-16T14:20:56.154023", "ingestion_ts": "2026-01-16T14:20:56.869125", "market_id": "0x427bc4b40c09b3dcbc973747f0e4b079bed91b3e5a0aed5c36edd0f7591485f4", "raw": {"market": "0x427bc4b40c09b3dcbc973747f0e4b079bed91b3e5a0aed5c36edd0f7591485f4", "asset_id": "86130975769502911188457673769190265049139877688522439001984850068234616395137", "price": "0.992", "size": "0", "side": "SELL", "timestamp": "1768573256025", "received_at": "2026-01-16T14:20:56.154023"}}
{"event_type": "price_change", "event_ts": "2026-01-16T14:20:56.243831", "ingestion_ts": "2026-01-16T14:20:56.869125", "market_id": "0x427bc4b40c09b3dcbc973747f0e4b079bed91b3e5a0aed5c36edd0f7591485f4", "raw": {"market": "0x427bc4b40c09b3dcbc973747f0e4b079bed91b3e5a0aed5c36edd0f7591485f4", "asset_id": "86130975769502911188457673769190265049139877688522439001984850068234616395137", "price": "0.804", "size": "47", "side": "BUY", "timestamp": "1768573256138", "received_at": "2026-01-16T14:20:56.243831"}}
{"event_type": "price_change", "event_ts": "2026-01-16T14:20:56.243831", "ingestion_ts": "2026-01-16T14:20:56.869125", "market_id": "0x427bc4b40c09b3dcbc973747f0e4b079bed91b3e5a0aed5c36edd0f7591485f4", "raw": {"market": "0x427bc4b40c09b3dcbc973747f0e4b079bed91b3e5a0aed5c36edd0f7591485f4", "asset_id": "115669573443672055876643967408433138119481486650803218131873713375232186497057", "price": "0.196", "size": "47", "side": "SELL", "timestamp": "1768573256138", "received_at": "2026-01-16T14:20:56.243831"}}
{"event_type": "price_change", "event_ts": "2026-01-16T14:20:56.288976", "ingestion_ts": "2026-01-16T14:20:56.869125", "market_id": "0x427bc4b40c09b3dcbc973747f0e4b079bed91b3e5a0aed5c36edd0f7591485f4", "raw": {"market": "0x427bc4b40c09b3dcbc973747f0e4b079bed91b3e5a0aed5c36edd0f7591485f4", "asset_id": "86130975769502911188457673769190265049139877688522439001984850068234616395137", "price": "0.993", "size": "36", "side": "SELL", "timestamp": "1768573256215", "received_at": "2026-01-16T14:20:56.288976"}}
{"event_type": "price_change", "event_ts": "2026-01-16T14:20:56.288976", "ingestion_ts": "2026-01-16T14:20:56.869125", "market_id": "0x427bc4b40c09b3dcbc973747f0e4b079bed91b3e5a0aed5c36edd0f7591485f4", "raw": {"market": "0x427bc4b40c09b3dcbc973747f0e4b079bed91b3e5a0aed5c36edd0f7591485f4", "asset_id": "115669573443672055876643967408433138119481486650803218131873713375232186497057", "price": "0.007", "size": "36", "side": "BUY", "timestamp": "1768573256215", "received_at": "2026-01-16T14:20:56.288976"}}
{"event_type": "price_change", "event_ts": "2026-01-16T14:20:56.444567", "ingestion_ts": "2026-01-16T14:20:56.869125", "market_id": "0x427bc4b40c09b3dcbc973747f0e4b079bed91b3e5a0aed5c36edd0f7591485f4", "raw": {"market": "0x427bc4b40c09b3dcbc973747f0e4b079bed91b3e5a0aed5c36edd0f7591485f4", "asset_id": "115669573443672055876643967408433138119481486650803218131873713375232186497057", "price": "0.006", "size": "34.18", "side": "BUY", "timestamp": "1768573256394", "received_at": "2026-01-16T14:20:56.444567"}}
{"event_type": "price_change", "event_ts": "2026-01-16T14:20:56.444567", "ingestion_ts": "2026-01-16T14:20:56.869125", "market_id": "0x427bc4b40c09b3dcbc973747f0e4b079bed91b3e5a0aed5c36edd0f7591485f4", "raw": {"market": "0x427bc4b40c09b3dcbc973747f0e4b079bed91b3e5a0aed5c36edd0f7591485f4", "asset_id": "86130975769502911188457673769190265049139877688522439001984850068234616395137", "price": "0.994", "size": "34.18", "side": "SELL", "timestamp": "1768573256394", "received_at": "2026-01-16T14:20:56.444567"}}
{"event_type": "price_change", "event_ts": "2026-01-16T14:20:56.444606", "ingestion_ts": "2026-01-16T14:20:56.869125", "market_id": "0x427bc4b40c09b3dcbc973747f0e4b079bed91b3e5a0aed5c36edd0f7591485f4", "raw": {"market": "0x427bc4b40c09b3dcbc973747f0e4b079bed91b3e5a0aed5c36edd0f7591485f4", "asset_id": "115669573443672055876643967408433138119481486650803218131873713375232186497057", "price": "0.006", "size": "39.61", "side": "BUY", "timestamp": "1768573256395", "received_at": "2026-01-16T14:20:56.444606"}}
{"event_type": "price_change", "event_ts": "2026-01-16T14:20:56.444606", "ingestion_ts": "2026-01-16T14:20:56.869125", "market_id": "0x427bc4b40c09b3dcbc973747f0e4b079bed91b3e5a0aed5c36edd0f7591485f4", "raw": {"market": "0x427bc4b40c09b3dcbc973747f0e4b079bed91b3e5a0aed5c36edd0f7591485f4", "asset_id": "86130975769502911188457673769190265049139877688522439001984850068234616395137", "price": "0.994", "size": "39.61", "side": "SELL", "timestamp": "1768573256395", "received_at": "2026-01-16T14:20:56.444606"}}
{"event_type": "price_change", "event_ts": "2026-01-16T14:20:56.838435", "ingestion_ts": "2026-01-16T14:20:56.869125", "market_id": "0x427bc4b40c09b3dcbc973747f0e4b079bed91b3e5a0aed5c36edd0f7591485f4", "raw": {"market": "0x427bc4b40c09b3dcbc973747f0e4b079bed91b3e5a0aed5c36edd0f7591485f4", "asset_id": "115669573443672055876643967408433138119481486650803218131873713375232186497057", "price": "0.197", "size": "0", "side": "SELL", "timestamp": "1768573256765", "received_at": "2026-01-16T14:20:56.838435"}}
{"event_type": "price_change", "event_ts": "2026-01-16T14:20:56.838435", "ingestion_ts": "2026-01-16T14:20:56.869125", "market_id": "0x427bc4b40c09b3dcbc973747f0e4b079bed91b3e5a0aed5c36edd0f7591485f4", "raw": {"market": "0x427bc4b40c09b3dcbc973747f0e4b079bed91b3e5a0aed5c36edd0f7591485f4", "asset_id": "86130975769502911188457673769190265049139877688522439001984850068234616395137", "price": "0.803", "size": "0", "side": "BUY", "timestamp": "1768573256765", "received_at": "2026-01-16T14:20:56.838435"}}
