{"event_type": "price_change", "event_ts": "2026-01-16T14:30:24.924880", "ingestion_ts": "2026-01-16T14:30:40.976502", "market_id": "0x2393ed0b0fdc450054c7b9071907eca75cf4fc36e385adf4a0a5f99ee62243e8", "raw": {"market": "0x2393ed0b0fdc450054c7b9071907eca75cf4fc36e385adf4a0a5f99ee62243e8", "asset_id": "100074770378634056601572485653252702850363676459996771990439989989293515601975", "price": "0.059", "size": "199", "side": "SELL", "timestamp": "1768573824659", "received_at": "2026-01-16T14:30:24.924880"}}
{"event_type": "price_change", "event_ts": "2026-01-16T14:30:24.924880", "ingestion_ts": "2026-01-16T14:30:40.976502", "market_id": "0x2393ed0b0fdc450054c7b9071907eca75cf4fc36e385adf4a0a5f99ee62243e8", "raw": {"market": "0x2393ed0b0fdc450054c7b9071907eca75cf4fc36e385adf4a0a5f99ee62243e8", "asset_id": "32769749367306925959219403371425714180265458150646381231272229429098460625924", "price": "0.941", "size": "199", "side": "BUY", "timestamp": "1768573824659", "received_at": "2026-01-16T14:30:24.924880"}}
{"event_type": "price_change", "event_ts": "2026-01-16T14:30:25.068256", "ingestion_ts": "2026-01-16T14:30:40.976502", "market_id": "0x2393ed0b0fdc450054c7b9071907eca75cf4fc36e385adf4a0a5f99ee62243e8", "raw": {"market": "0x2393ed0b0fdc450054c7b9071907eca75cf4fc36e385adf4a0a5f99ee62243e8", "asset_id": "32769749367306925959219403371425714180265458150646381231272229429098460625924", "price": "0.954", "size": "0", "side": "BUY", "timestamp": "1768573824926", "received_at": "2026-01-16T14:30:25.068256"}}
{"event_type": "price_change", "event_ts": "2026-01-16T14:30:25.068256", "ingestion_ts": "2026-01-16T14:30:40.976502", "market_id": "0x2393ed0b0fdc450054c7b9071907eca75cf4fc36e385adf4a0a5f99ee62243e8", "raw": {"market": "0x2393ed0b0fdc450054c7b9071907eca75cf4fc36e385adf4a0a5f99ee62243e8", "asset_id": "100074770378634056601572485653252702850363676459996771990439989989293515601975", "price": "0.046", "size": "0", "side": "SELL", "timestamp": "1768573824926", "received_at": "2026-01-16T14:30:25.068256"}}
{"event_type": "price_change", "event_ts": "2026-01-16T14:30:26.159254", "ingestion_ts": "2026-01-16T14:30:40.976502", "market_id": "0x49686d26fb712515cd5e12c23f0a1c7e10214c7faa3cb0a730aabe0c33694082", "raw": {"market": "0x49686d26fb712515cd5e12c23f0a1c7e10214c7faa3cb0a730aabe0c33694082", "asset_id": "13244681086321087932946246027856416106585284024824496763706748621681543444582", "price": "0.853", "size": "45", "side": "BUY", "timestamp": "1768573826117", "received_at": "2026-01-16T14:30:26.159254"}}
{"event_type": "price_change", "event_ts": "2026-01-16T14:30:26.159254", "ingestion_ts": "2026-01-16T14:30:40.976502", "market_id": "0x49686d26fb712515cd5e12c23f0a1c7e10214c7faa3cb0a730aabe0c33694082", "raw": {"market": "0x49686d26fb712515cd5e12c23f0a1c7e10214c7faa3cb0a730aabe0c33694082", "asset_id": "30442780799048074404860985387051749017905070253466005720364298335239299761065", "price": "0.147", "size": "45", "side": "SELL", "timestamp": "1768573826117", "received_at": "2026-01-16T14:30:26.159254"}}
{"event_type": "price_change", "event_ts": "2026-01-16T14:30:26.214710", "ingestion_ts": "2026-01-16T14:30:40.976502", "market_id": "0x49686d26fb712515cd5e12c23f0a1c7e10214c7faa3cb0a730aabe0c33694082", "raw": {"market": "0x49686d26fb712515cd5e12c23f0a1c7e10214c7faa3cb0a730aabe0c33694082", "asset_id": "13244681086321087932946246027856416106585284024824496763706748621681543444582", "price": "0.854", "size": "23.35", "side": "BUY", "timestamp": "1768573826179", "received_at": "2026-01-16T14:30:26.214710"}}
{"event_type": "price_change", "event_ts": "2026-01-16T14:30:26.214710", "ingestion_ts": "2026-01-16T14:30:40.976502", "market_id": "0x49686d26fb712515cd5e12c23f0a1c7e10214c7faa3cb0a730aabe0c33694082", "raw": {"market": "0x49686d26fb712515cd5e12c23f0a1c7e10214c7faa3cb0a730aabe0c33694082", "asset_id": "30442780799048074404860985387051749017905070253466005720364298335239299761065", "price": "0.146", "size": "23.35", "side": "SELL", "timestamp": "1768573826179", "received_at": "2026-01-16T14:30:26.214710"}}
{"event_type": "price_change", "event_ts": "2026-01-16T14:30:26.544789", "ingestion_ts": "2026-01-16T14:30:40.976502", "market_id": "0xaf9d0e448129a9f657f851d49495ba4742055d80e0ef1166ba0ee81d4d594214", "raw": {"market": "0xaf9d0e448129a9f657f851d49495ba4742055d80e0ef1166ba0ee81d4d594214", "asset_id": "4153292802911610701832309484716814274802943278345248636922528170020319407796", "price": "0.98", "size": "0", "side": "SELL", "timestamp": "1768573826504", "received_at": "2026-01-16T14:30:26.544789"}}
{"event_type": "price_change", "event_ts": "2026-01-16T14:30:26.544789", "ingestion_ts": "2026-01-16T14:30:40.976502", "market_id": "0xaf9d0e448129a9f657f851d49495ba4742055d80e0ef1166ba0ee81d4d594214", "raw": {"market": "0xaf9d0e448129a9f657f851d49495ba4742055d80e0ef1166ba0ee81d4d594214", "asset_id": "101676997363687199724245607342877036148401850938023978421879460310389391082353", "price": "0.02", "size": "0", "side": "BUY", "timestamp": "1768573826504", "received_at": "2026-01-16T14:30:26.544789"}}
{"event_type": "price_change", "event_ts": "2026-01-16T14:30:26.609972", "ingestion_ts": "2026-01-16T14:30:40.976502", "market_id": "0xaf9d0e448129a9f657f851d49495ba4742055d80e0ef1166ba0ee81d4d594214", "raw": {"market": "0xaf9d0e448129a9f657f851d49495ba4742055d80e0ef1166ba0ee81d4d594214", "asset_id": "4153292802911610701832309484716814274802943278345248636922528170020319407796", "price": "0.978", "size": "20.5", "side": "SELL", "timestamp": "1768573826567", "received_at": "2026-01-16T14:30:26.609972"}}
{"event_type": "price_change", "event_ts": "2026-01-16T14:30:26.609972", "ingestion_ts": "2026-01-16T14:30:40.976502", "market_id": "0xaf9d0e448129a9f657f851d49495ba4742055d80e0ef1166ba0ee81d4d594214", "raw": {"market": "0xaf9d0e448129a9f657f851d49495ba4742055d80e0ef1166ba0ee81d4d594214", "asset_id": "101676997363687199724245607342877036148401850938023978421879460310389391082353", "price": "0.022", "size": "20.5", "side": "BUY", "timestamp": "1768573826567", "received_at": "2026-01-16T14:30:26.609972"}}
{"event_type": "price_change", "event_ts": "2026-01-16T14:30:26.673771", "ingestion_ts": "2026-01-16T14:30:40.976502", "market_id": "0x9d24d9f9b5995949cb158d943793dea20bd448e1b3971cb6f7418bb15e719661", "raw": {"market": "0x9d24d9f9b5995949cb158d943793dea20bd448e1b3971cb6f7418bb15e719661", "asset_id": "79516121807256184736227920754945730465880754940725759201193439378549308939672", "price": "0.923", "size": "517.56", "side": "BUY", "timestamp": "1768573826635", "received_at": "2026-01-16T14:30:26.673771"}}
{"event_type": "price_change", "event_ts": "2026-01-16T14:30:26.673771", "ingestion_ts": "2026-01-16T14:30:40.976502", "market_id": "0x9d24d9f9b5995949cb158d943793dea20bd448e1b3971cb6f7418bb15e719661", "raw": {"market": "0x9d24d9f9b5995949cb158d943793dea20bd448e1b3971cb6f7418bb15e719661", "asset_id": "70512916946285526357165287373537570327431985324385225788636160168740471920430", "price": "0.077", "size": "517.56", "side": "SELL", "timestamp": "1768573826635", "received_at": "2026-01-16T14:30:26.673771"}}
{"event_type": "price_change", "event_ts": "2026-01-16T14:30:27.970424", "ingestion_ts": "2026-01-16T14:30:40.976502", "market_id": "0x49686d26fb712515cd5e12c23f0a1c7e10214c7faa3cb0a730aabe0c33694082", "raw": {"market": "0x49686d26fb712515cd5e12c23f0a1c7e10214c7faa3cb0a730aabe0c33694082", "asset_id": "30442780799048074404860985387051749017905070253466005720364298335239299761065", "price": "0.146", "size": "5.85", "side": "SELL", "timestamp": "1768573827576", "received_at": "2026-01-16T14:30:27.970424"}}
{"event_type": "price_change", "event_ts": "2026-01-16T14:30:27.970424", "ingestion_ts": "2026-01-16T14:30:40.976502", "market_id": "0x49686d26fb712515cd5e12c23f0a1c7e10214c7faa3cb0a730aabe0c33694082", "raw": {"market": "0x49686d26fb712515cd5e12c23f0a1c7e10214c7faa3cb0a730aabe0c33694082", "asset_id": "13244681086321087932946246027856416106585284024824496763706748621681543444582", "price": "0.854", "size": "5.85", "side": "BUY", "timestamp": "1768573827576", "received_at": "2026-01-16T14:30:27.970424"}}
{"event_type": "price_change", "event_ts": "2026-01-16T14:30:28.004018", "ingestion_ts": "2026-01-16T14:30:40.976502", "market_id": "0x49686d26fb712515cd5e12c23f0a1c7e10214c7faa3cb0a730aabe0c33694082", "raw": {"market": "0x49686d26fb712515cd5e12c23f0a1c7e10214c7faa3cb0a730aabe0c33694082", "asset_id": "30442780799048074404860985387051749017905070253466005720364298335239299761065", "price": "0.148", "size": "17.5", "side": "SELL", "timestamp": "1768573827632", "received_at": "2026-01-16T14:30:28.004018"}}
{"event_type": "price_change", "event_ts": "2026-01-16T14:30:28.004018", "ingestion_ts": "2026-01-16T14:30:40.976502", "market_id": "0x49686d26fb712515cd5e12c23f0a1c7e10214c7faa3cb0a730aabe0c33694082", "raw": {"market": "0x49686d26fb712515cd5e12c23f0a1c7e10214c7faa3cb0a730aabe0c33694082", "asset_id": "13244681086321087932946246027856416106585284024824496763706748621681543444582", "price": "0.852", "size": "17.5", "side": "BUY", "timestamp": "1768573827632", "received_at": "2026-01-16T14:30:28.004018"}}
{"event_type": "price_change", "event_ts": "2026-01-16T14:30:28.232792", "ingestion_ts": "2026-01-16T14:30:40.976502", "market_id": "0x49686d26fb712515cd5e12c23f0a1c7e10214c7faa3cb0a730aabe0c33694082", "raw": {"market": "0x49686d26fb712515cd5e12c23f0a1c7e10214c7faa3cb0a730aabe0c33694082", "asset_id": "30442780799048074404860985387051749017905070253466005720364298335239299761065", "price": "0.004", "size": "0", "side": "BUY", "timestamp": "1768573827981", "received_at": "2026-01-16T14:30:28.232792"}}
{"event_type": "price_change", "event_ts": "2026-01-16T14:30:28.232792", "ingestion_ts": "2026-01-16T14:30:40.976502", "market_id": "0x49686d26fb712515cd5e12c23f0a1c7e10214c7faa3cb0a730aabe0c33694082", "raw": {"market": "0x49686d26fb712515cd5e12c23f0a1c7e10214c7faa3cb0a730aabe0c33694082", "asset_id": "13244681086321087932946246027856416106585284024824496763706748621681543444582", "price": "0.996", "size": "0", "side": "SELL", "timestamp": "1768573827981", "received_at": "2026-01-16T14:30:28.232792"}}
{"event_type": "price_change", "event_ts": "2026-01-16T14:30:28.232831", "ingestion_ts": "2026-01-16T14:30:40.976502", "market_id": "0x49a20c7523c271099008f3ef9a31521263b24d637959852a391e6b4697b1a437", "raw": {"market": "0x49a20c7523c271099008f3ef9a31521263b24d637959852a391e6b4697b1a437", "asset_id": "55881023621710858558280545117465775643848233756850602339827152783696837905531", "price": "0.854", "size": "2058.31", "side": "BUY", "timestamp": "1768573827981", "received_at": "2026-01-16T14:30:28.232831"}}
{"event_type": "price_change", "event_ts": "2026-01-16T14:30:28.232831", "ingestion_ts": "2026-01-16T14:30:40.976502", "market_id": "0x49a20c7523c271099008f3ef9a31521263b24d637959852a391e6b4697b1a437", "raw": {"market": "0x49a20c7523c271099008f3ef9a31521263b24d637959852a391e6b4697b1a437", "asset_id": "13018971792603393862521629014128024641178044618205296260525674415067194037856", "price": "0.146", "size": "2058.31", "side": "SELL", "timestamp": "1768573827981", "received_at": "2026-01-16T14:30:28.232831"}}
{"event_type": "price_change", "event_ts": "2026-01-16T14:30:28.232844", "ingestion_ts": "2026-01-16T14:30:40.976502", "market_id": "0x44f08744458b8896620cd3330bc5e1ea69df4199b02d4fc583b3fc96e5d314ce", "raw": {"market": "0x44f08744458b8896620cd3330bc5e1ea69df4199b02d4fc583b3fc96e5d314ce", "asset_id": "72327831507226612545928776794104143393438710920370371172884559893525100761096", "price": "0.852", "size": "0", "side": "BUY", "timestamp": "1768573827981", "received_at": "2026-01-16T14:30:28.232844"}}
{"event_type": "price_change", "event_ts": "2026-01-16T14:30:28.232844", "ingestion_ts": "2026-01-16T14:30:40.976502", "market_id": "0x44f08744458b8896620cd3330bc5e1ea69df4199b02d4fc583b3fc96e5d314ce", "raw": {"market": "0x44f08744458b8896620cd3330bc5e1ea69df4199b02d4fc583b3fc96e5d314ce", "asset_id": "49194009556504828848509244326501559253829462790583873936160989575507522044057", "price": "0.148", "size": "0", "side": "SELL", "timestamp": "1768573827981", "received_at": "2026-01-16T14:30:28.232844"}}
{"event_type": "price_change", "event_ts": "2026-01-16T14:30:28.242214", "ingestion_ts": "2026-01-16T14:30:40.976502", "market_id": "0x2393ed0b0fdc450054c7b9071907eca75cf4fc36e385adf4a0a5f99ee62243e8", "raw": {"market": "0x2393ed0b0fdc450054c7b9071907eca75cf4fc36e385adf4a0a5f99ee62243e8", "asset_id": "32769749367306925959219403371425714180265458150646381231272229429098460625924", "price": "0.811", "size": "0", "side": "BUY", "timestamp": "1768573827981", "received_at": "2026-01-16T14:30:28.242214"}}
{"event_type": "price_change", "event_ts": "2026-01-16T14:30:28.242214", "ingestion_ts": "2026-01-16T14:30:40.976502", "market_id": "0x2393ed0b0fdc450054c7b9071907eca75cf4fc36e385adf4a0a5f99ee62243e8", "raw": {"market": "0x2393ed0b0fdc450054c7b9071907eca75cf4fc36e385adf4a0a5f99ee62243e8", "asset_id": "100074770378634056601572485653252702850363676459996771990439989989293515601975", "price": "0.189", "size": "0", "side": "SELL", "timestamp": "1768573827981", "received_at": "2026-01-16T14:30:28.242214"}}
{"event_type": "price_change", "event_ts": "2026-01-16T14:30:28.242269", "ingestion_ts": "2026-01-16T14:30:40.976502", "market_id": "0x9472be65457510b7fc3477b20ba90910e99d92eac8421a14bf4b7b7a08ef31dc", "raw": {"market": "0x9472be65457510b7fc3477b20ba90910e99d92eac8421a14bf4b7b7a08ef31dc", "asset_id": "43311793366960417907757893276427136943959788721376762326430771171648759300146", "price": "0.855", "size": "292", "side": "BUY", "timestamp": "1768573827981", "received_at": "2026-01-16T14:30:28.242269"}}
{"event_type": "price_change", "event_ts": "2026-01-16T14:30:28.242269", "ingestion_ts": "2026-01-16T14:30:40.976502", "market_id": "0x9472be65457510b7fc3477b20ba90910e99d92eac8421a14bf4b7b7a08ef31dc", "raw": {"market": "0x9472be65457510b7fc3477b20ba90910e99d92eac8421a14bf4b7b7a08ef31dc", "asset_id": "73414222381656326204771753454630063673548497164758947581648273905027617570612", "price": "0.145", "size": "292", "side": "SELL", "timestamp": "1768573827981", "received_at": "2026-01-16T14:30:28.242269"}}
{"event_type": "price_change", "event_ts": "2026-01-16T14:30:28.242283", "ingestion_ts": "2026-01-16T14:30:40.976502", "market_id": "0xc55db914f0fd1fee18997706712c0dfd8d0369cdbef93a9fef12bd001914ca77", "raw": {"market": "0xc55db914f0fd1fee18997706712c0dfd8d0369cdbef93a9fef12bd001914ca77", "asset_id": "114600293444080540179603459515770723592661967180480327891296353898330242622833", "price": "0.856", "size": "0", "side": "BUY", "timestamp": "1768573827981", "received_at": "2026-01-16T14:30:28.242283"}}
{"event_type": "price_change", "event_ts": "2026-01-16T14:30:28.242283", "ingestion_ts": "2026-01-16T14:30:40.976502", "market_id": "0xc55db914f0fd1fee18997706712c0dfd8d0369cdbef93a9fef12bd001914ca77", "raw": {"market": "0xc55db914f0fd1fee18997706712c0dfd8d0369cdbef93a9fef12bd001914ca77", "asset_id": "72354723612769247426741660426331235762851940382312402276325808095604519806766", "price": "0.144", "size": "0", "side": "SELL", "timestamp": "1768573827981", "received_at": "2026-01-16T14:30:28.242283"}}
{"event_type": "price_change", "event_ts": "2026-01-16T14:30:28.242295", "ingestion_ts": "2026-01-16T14:30:40.976502", "market_id": "0x50c669f178da4e5bbea7f1be25041fd278914712fa87a6a6f8e57d5923d88dee", "raw": {"market": "0x50c669f178da4e5bbea7f1be25041fd278914712fa87a6a6f8e57d5923d88dee", "asset_id": "74040420326294854165772767082819937451857852955603897473157746262672057685461", "price": "0.855", "size": "584", "side": "BUY", "timestamp": "1768573827981", "received_at": "2026-01-16T14:30:28.242295"}}
{"event_type": "price_change", "event_ts": "2026-01-16T14:30:28.242295", "ingestion_ts": "2026-01-16T14:30:40.976502", "market_id": "0x50c669f178da4e5bbea7f1be25041fd278914712fa87a6a6f8e57d5923d88dee", "raw": {"market": "0x50c669f178da4e5bbea7f1be25041fd278914712fa87a6a6f8e57d5923d88dee", "asset_id": "24682525479474221428144937281315825971983904267399062415430320764754931667953", "price": "0.145", "size": "584", "side": "SELL", "timestamp": "1768573827981", "received_at": "2026-01-16T14:30:28.242295"}}
{"event_type": "price_change", "event_ts": "2026-01-16T14:30:28.262656", "ingestion_ts": "2026-01-16T14:30:40.976502", "market_id": "0x9472be65457510b7fc3477b20ba90910e99d92eac8421a14bf4b7b7a08ef31dc", "raw": {"market": "0x9472be65457510b7fc3477b20ba90910e99d92eac8421a14bf4b7b7a08ef31dc", "asset_id": "43311793366960417907757893276427136943959788721376762326430771171648759300146", "price": "0.858", "size": "243", "side": "BUY", "timestamp": "1768573828016", "received_at": "2026-01-16T14:30:28.262656"}}
{"event_type": "price_change", "event_ts": "2026-01-16T14:30:28.262656", "ingestion_ts": "2026-01-16T14:30:40.976502", "market_id": "0x9472be65457510b7fc3477b20ba90910e99d92eac8421a14bf4b7b7a08ef31dc", "raw": {"market": "0x9472be65457510b7fc3477b20ba90910e99d92eac8421a14bf4b7b7a08ef31dc", "asset_id": "73414222381656326204771753454630063673548497164758947581648273905027617570612", "price": "0.142", "size": "243", "side": "SELL", "timestamp": "1768573828016", "received_at": "2026-01-16T14:30:28.262656"}}
{"event_type": "price_change", "event_ts": "2026-01-16T14:30:28.262697", "ingestion_ts": "2026-01-16T14:30:40.976502", "market_id": "0x49686d26fb712515cd5e12c23f0a1c7e10214c7faa3cb0a730aabe0c33694082", "raw": {"market": "0x49686d26fb712515cd5e12c23f0a1c7e10214c7faa3cb0a730aabe0c33694082", "asset_id": "30442780799048074404860985387051749017905070253466005720364298335239299761065", "price": "0.006", "size": "20.08", "side": "BUY", "timestamp": "1768573828016", "received_at": "2026-01-16T14:30:28.262697"}}
{"event_type": "price_change", "event_ts": "2026-01-16T14:30:28.262697", "ingestion_ts": "2026-01-16T14:30:40.976502", "market_id": "0x49686d26fb712515cd5e12c23f0a1c7e10214c7faa3cb0a730aabe0c33694082", "raw": {"market": "0x49686d26fb712515cd5e12c23f0a1c7e10214c7faa3cb0a730aabe0c33694082", "asset_id": "13244681086321087932946246027856416106585284024824496763706748621681543444582", "price": "0.994", "size": "20.08", "side": "SELL", "timestamp": "1768573828016", "received_at": "2026-01-16T14:30:28.262697"}}
{"event_type": "price_change", "event_ts": "2026-01-16T14:30:28.270293", "ingestion_ts": "2026-01-16T14:30:40.976502", "market_id": "0x44f08744458b8896620cd3330bc5e1ea69df4199b02d4fc583b3fc96e5d314ce", "raw": {"market": "0x44f08744458b8896620cd3330bc5e1ea69df4199b02d4fc583b3fc96e5d314ce", "asset_id": "72327831507226612545928776794104143393438710920370371172884559893525100761096", "price": "0.854", "size": "10", "side": "BUY", "timestamp": "1768573828016", "received_at": "2026-01-16T14:30:28.270293"}}
{"event_type": "price_change", "event_ts": "2026-01-16T14:30:28.270293", "ingestion_ts": "2026-01-16T14:30:40.976502", "market_id": "0x44f08744458b8896620cd3330bc5e1ea69df4199b02d4fc583b3fc96e5d314ce", "raw": {"market": "0x44f08744458b8896620cd3330bc5e1ea69df4199b02d4fc583b3fc96e5d314ce", "asset_id": "49194009556504828848509244326501559253829462790583873936160989575507522044057", "price": "0.146", "size": "10", "side": "SELL", "timestamp": "1768573828016", "received_at": "2026-01-16T14:30:28.270293"}}
{"event_type": "price_change", "event_ts": "2026-01-16T14:30:28.270331", "ingestion_ts": "2026-01-16T14:30:40.976502", "market_id": "0x50c669f178da4e5bbea7f1be25041fd278914712fa87a6a6f8e57d5923d88dee", "raw": {"market": "0x50c669f178da4e5bbea7f1be25041fd278914712fa87a6a6f8e57d5923d88dee", "asset_id": "74040420326294854165772767082819937451857852955603897473157746262672057685461", "price": "0.857", "size": "10", "side": "BUY", "timestamp": "1768573828016", "received_at": "2026-01-16T14:30:28.270331"}}
{"event_type": "price_change", "event_ts": "2026-01-16T14:30:28.270331", "ingestion_ts": "2026-01-16T14:30:40.976502", "market_id": "0x50c669f178da4e5bbea7f1be25041fd278914712fa87a6a6f8e57d5923d88dee", "raw": {"market": "0x50c669f178da4e5bbea7f1be25041fd278914712fa87a6a6f8e57d5923d88dee", "asset_id": "24682525479474221428144937281315825971983904267399062415430320764754931667953", "price": "0.143", "size": "10", "side": "SELL", "timestamp": "1768573828016", "received_at": "2026-01-16T14:30:28.270331"}}
{"event_type": "price_change", "event_ts": "2026-01-16T14:30:28.270344", "ingestion_ts": "2026-01-16T14:30:40.976502", "market_id": "0xc55db914f0fd1fee18997706712c0dfd8d0369cdbef93a9fef12bd001914ca77", "raw": {"market": "0xc55db914f0fd1fee18997706712c0dfd8d0369cdbef93a9fef12bd001914ca77", "asset_id": "114600293444080540179603459515770723592661967180480327891296353898330242622833", "price": "0.859", "size": "40", "side": "BUY", "timestamp": "1768573828016", "received_at": "2026-01-16T14:30:28.270344"}}
{"event_type": "price_change", "event_ts": "2026-01-16T14:30:28.270344", "ingestion_ts": "2026-01-16T14:30:40.976502", "market_id": "0xc55db914f0fd1fee18997706712c0dfd8d0369cdbef93a9fef12bd001914ca77", "raw": {"market": "0xc55db914f0fd1fee18997706712c0dfd8d0369cdbef93a9fef12bd001914ca77", "asset_id": "72354723612769247426741660426331235762851940382312402276325808095604519806766", "price": "0.141", "size": "40", "side": "SELL", "timestamp": "1768573828016", "received_at": "2026-01-16T14:30:28.270344"}}
{"event_type": "price_change", "event_ts": "2026-01-16T14:30:28.270356", "ingestion_ts": "2026-01-16T14:30:40.976502", "market_id": "0x2393ed0b0fdc450054c7b9071907eca75cf4fc36e385adf4a0a5f99ee62243e8", "raw": {"market": "0x2393ed0b0fdc450054c7b9071907eca75cf4fc36e385adf4a0a5f99ee62243e8", "asset_id": "32769749367306925959219403371425714180265458150646381231272229429098460625924", "price": "0.849", "size": "304", "side": "BUY", "timestamp": "1768573828016", "received_at": "2026-01-16T14:30:28.270356"}}
{"event_type": "price_change", "event_ts": "2026-01-16T14:30:28.270356", "ingestion_ts": "2026-01-16T14:30:40.976502", "market_id": "0x2393ed0b0fdc450054c7b9071907eca75cf4fc36e385adf4a0a5f99ee62243e8", "raw": {"market": "0x2393ed0b0fdc450054c7b9071907eca75cf4fc36e385adf4a0a5f99ee62243e8", "asset_id": "100074770378634056601572485653252702850363676459996771990439989989293515601975", "price": "0.151", "size": "304", "side": "SELL", "timestamp": "1768573828016", "received_at": "2026-01-16T14:30:28.270356"}}
{"event_type": "price_change", "event_ts": "2026-01-16T14:30:28.270367", "ingestion_ts": "2026-01-16T14:30:40.976502", "market_id": "0x49a20c7523c271099008f3ef9a31521263b24d637959852a391e6b4697b1a437", "raw": {"market": "0x49a20c7523c271099008f3ef9a31521263b24d637959852a391e6b4697b1a437", "asset_id": "55881023621710858558280545117465775643848233756850602339827152783696837905531", "price": "0.857", "size": "40", "side": "BUY", "timestamp": "1768573828016", "received_at": "2026-01-16T14:30:28.270367"}}
{"event_type": "price_change", "event_ts": "2026-01-16T14:30:28.270367", "ingestion_ts": "2026-01-16T14:30:40.976502", "market_id": "0x49a20c7523c271099008f3ef9a31521263b24d637959852a391e6b4697b1a437", "raw": {"market": "0x49a20c7523c271099008f3ef9a31521263b24d637959852a391e6b4697b1a437", "asset_id": "13018971792603393862521629014128024641178044618205296260525674415067194037856", "price": "0.143", "size": "40", "side": "SELL", "timestamp": "1768573828016", "received_at": "2026-01-16T14:30:28.270367"}}
{"event_type": "price_change", "event_ts": "2026-01-16T14:30:30.004353", "ingestion_ts": "2026-01-16T14:30:40.976502", "market_id": "0xae5584fbb57f23c1c608d544b656f23d8bf12340cef70811cf31bb0cb4fc2115", "raw": {"market": "0xae5584fbb57f23c1c608d544b656f23d8bf12340cef70811cf31bb0cb4fc2115", "asset_id": "42278252558046940014991595990628759801692726198478046188873057685686228021663", "price": "0.99", "size": "8193.2", "side": "SELL", "timestamp": "1768573829943", "received_at": "2026-01-16T14:30:30.004353"}}
{"event_type": "price_change", "event_ts": "2026-01-16T14:30:30.004353", "ingestion_ts": "2026-01-16T14:30:40.976502", "market_id": "0xae5584fbb57f23c1c608d544b656f23d8bf12340cef70811cf31bb0cb4fc2115", "raw": {"market": "0xae5584fbb57f23c1c608d544b656f23d8bf12340cef70811cf31bb0cb4fc2115", "asset_id": "28946595841244317705636126646676849578876740730186646421280828201004700559420", "price": "0.01", "size": "8193.2", "side": "BUY", "timestamp": "1768573829943", "received_at": "2026-01-16T14:30:30.004353"}}
{"event_type": "price_change", "event_ts": "2026-01-16T14:30:30.124593", "ingestion_ts": "2026-01-16T14:30:40.976502", "market_id": "0xae5584fbb57f23c1c608d544b656f23d8bf12340cef70811cf31bb0cb4fc2115", "raw": {"market": "0xae5584fbb57f23c1c608d544b656f23d8bf12340cef70811cf31bb0cb4fc2115", "asset_id": "28946595841244317705636126646676849578876740730186646421280828201004700559420", "price": "0.01", "size": "8241", "side": "BUY", "timestamp": "1768573830052", "received_at": "2026-01-16T14:30:30.124593"}}
{"event_type": "price_change", "event_ts": "2026-01-16T14:30:30.124593", "ingestion_ts": "2026-01-16T14:30:40.976502", "market_id": "0xae5584fbb57f23c1c608d544b656f23d8bf12340cef70811cf31bb0cb4fc2115", "raw": {"market": "0xae5584fbb57f23c1c608d544b656f23d8bf12340cef70811cf31bb0cb4fc2115", "asset_id": "42278252558046940014991595990628759801692726198478046188873057685686228021663", "price": "0.99", "size": "8241", "side": "SELL", "timestamp": "1768573830052", "received_at": "2026-01-16T14:30:30.124593"}}
{"event_type": "price_change", "event_ts": "2026-01-16T14:30:30.331031", "ingestion_ts": "2026-01-16T14:30:40.976502", "market_id": "0xaf9d0e448129a9f657f851d49495ba4742055d80e0ef1166ba0ee81d4d594214", "raw": {"market": "0xaf9d0e448129a9f657f851d49495ba4742055d80e0ef1166ba0ee81d4d594214", "asset_id": "4153292802911610701832309484716814274802943278345248636922528170020319407796", "price": "0.979", "size": "0", "side": "SELL", "timestamp": "1768573830224", "received_at": "2026-01-16T14:30:30.331031"}}
{"event_type": "price_change", "event_ts": "2026-01-16T14:30:30.331031", "ingestion_ts": "2026-01-16T14:30:40.976502", "market_id": "0xaf9d0e448129a9f657f851d49495ba4742055d80e0ef1166ba0ee81d4d594214", "raw": {"market": "0xaf9d0e448129a9f657f851d49495ba4742055d80e0ef1166ba0ee81d4d594214", "asset_id": "101676997363687199724245607342877036148401850938023978421879460310389391082353", "price": "0.021", "size": "0", "side": "BUY", "timestamp": "1768573830224", "received_at": "2026-01-16T14:30:30.331031"}}
{"event_type": "price_change", "event_ts": "2026-01-16T14:30:30.760950", "ingestion_ts": "2026-01-16T14:30:40.976502", "market_id": "0x2393ed0b0fdc450054c7b9071907eca75cf4fc36e385adf4a0a5f99ee62243e8", "raw": {"market": "0x2393ed0b0fdc450054c7b9071907eca75cf4fc36e385adf4a0a5f99ee62243e8", "asset_id": "32769749367306925959219403371425714180265458150646381231272229429098460625924", "price": "0.942", "size": "50", "side": "BUY", "timestamp": "1768573830619", "received_at": "2026-01-16T14:30:30.760950"}}
{"event_type": "price_change", "event_ts": "2026-01-16T14:30:30.760950", "ingestion_ts": "2026-01-16T14:30:40.976502", "market_id": "0x2393ed0b0fdc450054c7b9071907eca75cf4fc36e385adf4a0a5f99ee62243e8", "raw": {"market": "0x2393ed0b0fdc450054c7b9071907eca75cf4fc36e385adf4a0a5f99ee62243e8", "asset_id": "100074770378634056601572485653252702850363676459996771990439989989293515601975", "price": "0.058", "size": "50", "side": "SELL", "timestamp": "1768573830619", "received_at": "2026-01-16T14:30:30.760950"}}
{"event_type": "price_change", "event_ts": "2026-01-16T14:30:30.861564", "ingestion_ts": "2026-01-16T14:30:40.976502", "market_id": "0x2393ed0b0fdc450054c7b9071907eca75cf4fc36e385adf4a0a5f99ee62243e8", "raw": {"market": "0x2393ed0b0fdc450054c7b9071907eca75cf4fc36e385adf4a0a5f99ee62243e8", "asset_id": "100074770378634056601572485653252702850363676459996771990439989989293515601975", "price": "0.059", "size": "0", "side": "SELL", "timestamp": "1768573830724", "received_at": "2026-01-16T14:30:30.861564"}}
{"event_type": "price_change", "event_ts": "2026-01-16T14:30:30.861564", "ingestion_ts": "2026-01-16T14:30:40.976502", "market_id": "0x2393ed0b0fdc450054c7b9071907eca75cf4fc36e385adf4a0a5f99ee62243e8", "raw": {"market": "0x2393ed0b0fdc450054c7b9071907eca75cf4fc36e385adf4a0a5f99ee62243e8", "asset_id": "32769749367306925959219403371425714180265458150646381231272229429098460625924", "price": "0.941", "size": "0", "side": "BUY", "timestamp": "1768573830724", "received_at": "2026-01-16T14:30:30.861564"}}
{"event_type": "price_change", "event_ts": "2026-01-16T14:30:30.895665", "ingestion_ts": "2026-01-16T14:30:40.976502", "market_id": "0x2393ed0b0fdc450054c7b9071907eca75cf4fc36e385adf4a0a5f99ee62243e8", "raw": {"market": "0x2393ed0b0fdc450054c7b9071907eca75cf4fc36e385adf4a0a5f99ee62243e8", "asset_id": "100074770378634056601572485653252702850363676459996771990439989989293515601975", "price": "0.057", "size": "199", "side": "SELL", "timestamp": "1768573830756", "received_at": "2026-01-16T14:30:30.895665"}}
{"event_type": "price_change", "event_ts": "2026-01-16T14:30:30.895665", "ingestion_ts": "2026-01-16T14:30:40.976502", "market_id": "0x2393ed0b0fdc450054c7b9071907eca75cf4fc36e385adf4a0a5f99ee62243e8", "raw": {"market": "0x2393ed0b0fdc450054c7b9071907eca75cf4fc36e385adf4a0a5f99ee62243e8", "asset_id": "32769749367306925959219403371425714180265458150646381231272229429098460625924", "price": "0.943", "size": "199", "side": "BUY", "timestamp": "1768573830756", "received_at": "2026-01-16T14:30:30.895665"}}
{"event_type": "price_change", "event_ts": "2026-01-16T14:30:31.115191", "ingestion_ts": "2026-01-16T14:30:40.976502", "market_id": "0x2393ed0b0fdc450054c7b9071907eca75cf4fc36e385adf4a0a5f99ee62243e8", "raw": {"market": "0x2393ed0b0fdc450054c7b9071907eca75cf4fc36e385adf4a0a5f99ee62243e8", "asset_id": "32769749367306925959219403371425714180265458150646381231272229429098460625924", "price": "0.94", "size": "0", "side": "BUY", "timestamp": "1768573831001", "received_at": "2026-01-16T14:30:31.115191"}}
{"event_type": "price_change", "event_ts": "2026-01-16T14:30:31.115191", "ingestion_ts": "2026-01-16T14:30:40.976502", "market_id": "0x2393ed0b0fdc450054c7b9071907eca75cf4fc36e385adf4a0a5f99ee62243e8", "raw": {"market": "0x2393ed0b0fdc450054c7b9071907eca75cf4fc36e385adf4a0a5f99ee62243e8", "asset_id": "100074770378634056601572485653252702850363676459996771990439989989293515601975", "price": "0.06", "size": "0", "side": "SELL", "timestamp": "1768573831001", "received_at": "2026-01-16T14:30:31.115191"}}
{"event_type": "price_change", "event_ts": "2026-01-16T14:30:31.141942", "ingestion_ts": "2026-01-16T14:30:40.976502", "market_id": "0xaf9d0e448129a9f657f851d49495ba4742055d80e0ef1166ba0ee81d4d594214", "raw": {"market": "0xaf9d0e448129a9f657f851d49495ba4742055d80e0ef1166ba0ee81d4d594214", "asset_id": "4153292802911610701832309484716814274802943278345248636922528170020319407796", "price": "0.978", "size": "0", "side": "SELL", "timestamp": "1768573831028", "received_at": "2026-01-16T14:30:31.141942"}}
{"event_type": "price_change", "event_ts": "2026-01-16T14:30:31.141942", "ingestion_ts": "2026-01-16T14:30:40.976502", "market_id": "0xaf9d0e448129a9f657f851d49495ba4742055d80e0ef1166ba0ee81d4d594214", "raw": {"market": "0xaf9d0e448129a9f657f851d49495ba4742055d80e0ef1166ba0ee81d4d594214", "asset_id": "101676997363687199724245607342877036148401850938023978421879460310389391082353", "price": "0.022", "size": "0", "side": "BUY", "timestamp": "1768573831028", "received_at": "2026-01-16T14:30:31.141942"}}
{"event_type": "price_change", "event_ts": "2026-01-16T14:30:31.175969", "ingestion_ts": "2026-01-16T14:30:40.976502", "market_id": "0xaf9d0e448129a9f657f851d49495ba4742055d80e0ef1166ba0ee81d4d594214", "raw": {"market": "0xaf9d0e448129a9f657f851d49495ba4742055d80e0ef1166ba0ee81d4d594214", "asset_id": "4153292802911610701832309484716814274802943278345248636922528170020319407796", "price": "0.989", "size": "20.5", "side": "SELL", "timestamp": "1768573831080", "received_at": "2026-01-16T14:30:31.175969"}}
{"event_type": "price_change", "event_ts": "2026-01-16T14:30:31.175969", "ingestion_ts": "2026-01-16T14:30:40.976502", "market_id": "0xaf9d0e448129a9f657f851d49495ba4742055d80e0ef1166ba0ee81d4d594214", "raw": {"market": "0xaf9d0e448129a9f657f851d49495ba4742055d80e0ef1166ba0ee81d4d594214", "asset_id": "101676997363687199724245607342877036148401850938023978421879460310389391082353", "price": "0.011", "size": "20.5", "side": "BUY", "timestamp": "1768573831080", "received_at": "2026-01-16T14:30:31.175969"}}
{"event_type": "price_change", "event_ts": "2026-01-16T14:30:32.672734", "ingestion_ts": "2026-01-16T14:30:40.976502", "market_id": "0xc0e6b917320a47228fb96e3b5ae0e5c93773a5ae2662ae4e1f37807cfe47ce98", "raw": {"market": "0xc0e6b917320a47228fb96e3b5ae0e5c93773a5ae2662ae4e1f37807cfe47ce98", "asset_id": "58656358377246279051017109359677190749228949103591068167284263961542487110215", "price": "0.07", "size": "0", "side": "SELL", "timestamp": "1768573832564", "received_at": "2026-01-16T14:30:32.672734"}}
{"event_type": "price_change", "event_ts": "2026-01-16T14:30:32.672734", "ingestion_ts": "2026-01-16T14:30:40.976502", "market_id": "0xc0e6b917320a47228fb96e3b5ae0e5c93773a5ae2662ae4e1f37807cfe47ce98", "raw": {"market": "0xc0e6b917320a47228fb96e3b5ae0e5c93773a5ae2662ae4e1f37807cfe47ce98", "asset_id": "81647294538046680798858716589766492074338758116170717123345952330712416337530", "price": "0.93", "size": "0", "side": "BUY", "timestamp": "1768573832564", "received_at": "2026-01-16T14:30:32.672734"}}
{"event_type": "price_change", "event_ts": "2026-01-16T14:30:33.369192", "ingestion_ts": "2026-01-16T14:30:40.976502", "market_id": "0xc0e6b917320a47228fb96e3b5ae0e5c93773a5ae2662ae4e1f37807cfe47ce98", "raw": {"market": "0xc0e6b917320a47228fb96e3b5ae0e5c93773a5ae2662ae4e1f37807cfe47ce98", "asset_id": "58656358377246279051017109359677190749228949103591068167284263961542487110215", "price": "0.069", "size": "7.5", "side": "SELL", "timestamp": "1768573833329", "received_at": "2026-01-16T14:30:33.369192"}}
{"event_type": "price_change", "event_ts": "2026-01-16T14:30:33.369192", "ingestion_ts": "2026-01-16T14:30:40.976502", "market_id": "0xc0e6b917320a47228fb96e3b5ae0e5c93773a5ae2662ae4e1f37807cfe47ce98", "raw": {"market": "0xc0e6b917320a47228fb96e3b5ae0e5c93773a5ae2662ae4e1f37807cfe47ce98", "asset_id": "81647294538046680798858716589766492074338758116170717123345952330712416337530", "price": "0.931", "size": "7.5", "side": "BUY", "timestamp": "1768573833329", "received_at": "2026-01-16T14:30:33.369192"}}
{"event_type": "price_change", "event_ts": "2026-01-16T14:30:34.230590", "ingestion_ts": "2026-01-16T14:30:40.976502", "market_id": "0x49686d26fb712515cd5e12c23f0a1c7e10214c7faa3cb0a730aabe0c33694082", "raw": {"market": "0x49686d26fb712515cd5e12c23f0a1c7e10214c7faa3cb0a730aabe0c33694082", "asset_id": "13244681086321087932946246027856416106585284024824496763706748621681543444582", "price": "0.854", "size": "0", "side": "BUY", "timestamp": "1768573834187", "received_at": "2026-01-16T14:30:34.230590"}}
{"event_type": "price_change", "event_ts": "2026-01-16T14:30:34.230590", "ingestion_ts": "2026-01-16T14:30:40.976502", "market_id": "0x49686d26fb712515cd5e12c23f0a1c7e10214c7faa3cb0a730aabe0c33694082", "raw": {"market": "0x49686d26fb712515cd5e12c23f0a1c7e10214c7faa3cb0a730aabe0c33694082", "asset_id": "30442780799048074404860985387051749017905070253466005720364298335239299761065", "price": "0.146", "size": "0", "side": "SELL", "timestamp": "1768573834187", "received_at": "2026-01-16T14:30:34.230590"}}
{"event_type": "price_change", "event_ts": "2026-01-16T14:30:34.257595", "ingestion_ts": "2026-01-16T14:30:40.976502", "market_id": "0x49686d26fb712515cd5e12c23f0a1c7e10214c7faa3cb0a730aabe0c33694082", "raw": {"market": "0x49686d26fb712515cd5e12c23f0a1c7e10214c7faa3cb0a730aabe0c33694082", "asset_id": "13244681086321087932946246027856416106585284024824496763706748621681543444582", "price": "0.911", "size": "132.98", "side": "SELL", "timestamp": "1768573834220", "received_at": "2026-01-16T14:30:34.257595"}}
{"event_type": "price_change", "event_ts": "2026-01-16T14:30:34.257595", "ingestion_ts": "2026-01-16T14:30:40.976502", "market_id": "0x49686d26fb712515cd5e12c23f0a1c7e10214c7faa3cb0a730aabe0c33694082", "raw": {"market": "0x49686d26fb712515cd5e12c23f0a1c7e10214c7faa3cb0a730aabe0c33694082", "asset_id": "30442780799048074404860985387051749017905070253466005720364298335239299761065", "price": "0.089", "size": "132.98", "side": "BUY", "timestamp": "1768573834220", "received_at": "2026-01-16T14:30:34.257595"}}
{"event_type": "price_change", "event_ts": "2026-01-16T14:30:34.832836", "ingestion_ts": "2026-01-16T14:30:40.976502", "market_id": "0xb9bbdd34304344dcc45803780a34c97d73a00133a5ecf70f63e1008b8abb2fca", "raw": {"market": "0xb9bbdd34304344dcc45803780a34c97d73a00133a5ecf70f63e1008b8abb2fca", "asset_id": "8682484153073832526711485265636767086525069344085206423986003504588877767339", "price": "0.841", "size": "0", "side": "BUY", "timestamp": "1768573834780", "received_at": "2026-01-16T14:30:34.832836"}}
{"event_type": "price_change", "event_ts": "2026-01-16T14:30:34.832836", "ingestion_ts": "2026-01-16T14:30:40.976502", "market_id": "0xb9bbdd34304344dcc45803780a34c97d73a00133a5ecf70f63e1008b8abb2fca", "raw": {"market": "0xb9bbdd34304344dcc45803780a34c97d73a00133a5ecf70f63e1008b8abb2fca", "asset_id": "72012724360700510767037780555710363830014634797787940282136454146828040926557", "price": "0.159", "size": "0", "side": "SELL", "timestamp": "1768573834780", "received_at": "2026-01-16T14:30:34.832836"}}
{"event_type": "price_change", "event_ts": "2026-01-16T14:30:34.832881", "ingestion_ts": "2026-01-16T14:30:40.976502", "market_id": "0xc55db914f0fd1fee18997706712c0dfd8d0369cdbef93a9fef12bd001914ca77", "raw": {"market": "0xc55db914f0fd1fee18997706712c0dfd8d0369cdbef93a9fef12bd001914ca77", "asset_id": "114600293444080540179603459515770723592661967180480327891296353898330242622833", "price": "0.859", "size": "30", "side": "BUY", "timestamp": "1768573834780", "received_at": "2026-01-16T14:30:34.832881"}}
{"event_type": "price_change", "event_ts": "2026-01-16T14:30:34.832881", "ingestion_ts": "2026-01-16T14:30:40.976502", "market_id": "0xc55db914f0fd1fee18997706712c0dfd8d0369cdbef93a9fef12bd001914ca77", "raw": {"market": "0xc55db914f0fd1fee18997706712c0dfd8d0369cdbef93a9fef12bd001914ca77", "asset_id": "72354723612769247426741660426331235762851940382312402276325808095604519806766", "price": "0.141", "size": "30", "side": "SELL", "timestamp": "1768573834780", "received_at": "2026-01-16T14:30:34.832881"}}
{"event_type": "price_change", "event_ts": "2026-01-16T14:30:34.832902", "ingestion_ts": "2026-01-16T14:30:40.976502", "market_id": "0x2393ed0b0fdc450054c7b9071907eca75cf4fc36e385adf4a0a5f99ee62243e8", "raw": {"market": "0x2393ed0b0fdc450054c7b9071907eca75cf4fc36e385adf4a0a5f99ee62243e8", "asset_id": "32769749367306925959219403371425714180265458150646381231272229429098460625924", "price": "0.849", "size": "294", "side": "BUY", "timestamp": "1768573834780", "received_at": "2026-01-16T14:30:34.832902"}}
{"event_type": "price_change", "event_ts": "2026-01-16T14:30:34.832902", "ingestion_ts": "2026-01-16T14:30:40.976502", "market_id": "0x2393ed0b0fdc450054c7b9071907eca75cf4fc36e385adf4a0a5f99ee62243e8", "raw": {"market": "0x2393ed0b0fdc450054c7b9071907eca75cf4fc36e385adf4a0a5f99ee62243e8", "asset_id": "100074770378634056601572485653252702850363676459996771990439989989293515601975", "price": "0.151", "size": "294", "side": "SELL", "timestamp": "1768573834780", "received_at": "2026-01-16T14:30:34.832902"}}
{"event_type": "price_change", "event_ts": "2026-01-16T14:30:34.832915", "ingestion_ts": "2026-01-16T14:30:40.976502", "market_id": "0x44f08744458b8896620cd3330bc5e1ea69df4199b02d4fc583b3fc96e5d314ce", "raw": {"market": "0x44f08744458b8896620cd3330bc5e1ea69df4199b02d4fc583b3fc96e5d314ce", "asset_id": "72327831507226612545928776794104143393438710920370371172884559893525100761096", "price": "0.854", "size": "0", "side": "BUY", "timestamp": "1768573834780", "received_at": "2026-01-16T14:30:34.832915"}}
{"event_type": "price_change", "event_ts": "2026-01-16T14:30:34.832915", "ingestion_ts": "2026-01-16T14:30:40.976502", "market_id": "0x44f08744458b8896620cd3330bc5e1ea69df4199b02d4fc583b3fc96e5d314ce", "raw": {"market": "0x44f08744458b8896620cd3330bc5e1ea69df4199b02d4fc583b3fc96e5d314ce", "asset_id": "49194009556504828848509244326501559253829462790583873936160989575507522044057", "price": "0.146", "size": "0", "side": "SELL", "timestamp": "1768573834780", "received_at": "2026-01-16T14:30:34.832915"}}
{"event_type": "price_change", "event_ts": "2026-01-16T14:30:34.832929", "ingestion_ts": "2026-01-16T14:30:40.976502", "market_id": "0x50c669f178da4e5bbea7f1be25041fd278914712fa87a6a6f8e57d5923d88dee", "raw": {"market": "0x50c669f178da4e5bbea7f1be25041fd278914712fa87a6a6f8e57d5923d88dee", "asset_id": "74040420326294854165772767082819937451857852955603897473157746262672057685461", "price": "0.857", "size": "0", "side": "BUY", "timestamp": "1768573834780", "received_at": "2026-01-16T14:30:34.832929"}}
{"event_type": "price_change", "event_ts": "2026-01-16T14:30:34.832929", "ingestion_ts": "2026-01-16T14:30:40.976502", "market_id": "0x50c669f178da4e5bbea7f1be25041fd278914712fa87a6a6f8e57d5923d88dee", "raw": {"market": "0x50c669f178da4e5bbea7f1be25041fd278914712fa87a6a6f8e57d5923d88dee", "asset_id": "24682525479474221428144937281315825971983904267399062415430320764754931667953", "price": "0.143", "size": "0", "side": "SELL", "timestamp": "1768573834780", "received_at": "2026-01-16T14:30:34.832929"}}
{"event_type": "price_change", "event_ts": "2026-01-16T14:30:34.832957", "ingestion_ts": "2026-01-16T14:30:40.976502", "market_id": "0x49686d26fb712515cd5e12c23f0a1c7e10214c7faa3cb0a730aabe0c33694082", "raw": {"market": "0x49686d26fb712515cd5e12c23f0a1c7e10214c7faa3cb0a730aabe0c33694082", "asset_id": "30442780799048074404860985387051749017905070253466005720364298335239299761065", "price": "0.006", "size": "10.08", "side": "BUY", "timestamp": "1768573834780", "received_at": "2026-01-16T14:30:34.832957"}}
{"event_type": "price_change", "event_ts": "2026-01-16T14:30:34.832957", "ingestion_ts": "2026-01-16T14:30:40.976502", "market_id": "0x49686d26fb712515cd5e12c23f0a1c7e10214c7faa3cb0a730aabe0c33694082", "raw": {"market": "0x49686d26fb712515cd5e12c23f0a1c7e10214c7faa3cb0a730aabe0c33694082", "asset_id": "13244681086321087932946246027856416106585284024824496763706748621681543444582", "price": "0.994", "size": "10.08", "side": "SELL", "timestamp": "1768573834780", "received_at": "2026-01-16T14:30:34.832957"}}
{"event_type": "price_change", "event_ts": "2026-01-16T14:30:34.832971", "ingestion_ts": "2026-01-16T14:30:40.976502", "market_id": "0x9472be65457510b7fc3477b20ba90910e99d92eac8421a14bf4b7b7a08ef31dc", "raw": {"market": "0x9472be65457510b7fc3477b20ba90910e99d92eac8421a14bf4b7b7a08ef31dc", "asset_id": "43311793366960417907757893276427136943959788721376762326430771171648759300146", "price": "0.858", "size": "233", "side": "BUY", "timestamp": "1768573834780", "received_at": "2026-01-16T14:30:34.832971"}}
{"event_type": "price_change", "event_ts": "2026-01-16T14:30:34.832971", "ingestion_ts": "2026-01-16T14:30:40.976502", "market_id": "0x9472be65457510b7fc3477b20ba90910e99d92eac8421a14bf4b7b7a08ef31dc", "raw": {"market": "0x9472be65457510b7fc3477b20ba90910e99d92eac8421a14bf4b7b7a08ef31dc", "asset_id": "73414222381656326204771753454630063673548497164758947581648273905027617570612", "price": "0.142", "size": "233", "side": "SELL", "timestamp": "1768573834780", "received_at": "2026-01-16T14:30:34.832971"}}
{"event_type": "price_change", "event_ts": "2026-01-16T14:30:34.832983", "ingestion_ts": "2026-01-16T14:30:40.976502", "market_id": "0x49a20c7523c271099008f3ef9a31521263b24d637959852a391e6b4697b1a437", "raw": {"market": "0x49a20c7523c271099008f3ef9a31521263b24d637959852a391e6b4697b1a437", "asset_id": "55881023621710858558280545117465775643848233756850602339827152783696837905531", "price": "0.857", "size": "30", "side": "BUY", "timestamp": "1768573834780", "received_at": "2026-01-16T14:30:34.832983"}}
{"event_type": "price_change", "event_ts": "2026-01-16T14:30:34.832983", "ingestion_ts": "2026-01-16T14:30:40.976502", "market_id": "0x49a20c7523c271099008f3ef9a31521263b24d637959852a391e6b4697b1a437", "raw": {"market": "0x49a20c7523c271099008f3ef9a31521263b24d637959852a391e6b4697b1a437", "asset_id": "13018971792603393862521629014128024641178044618205296260525674415067194037856", "price": "0.143", "size": "30", "side": "SELL", "timestamp": "1768573834780", "received_at": "2026-01-16T14:30:34.832983"}}
{"event_type": "price_change", "event_ts": "2026-01-16T14:30:34.846007", "ingestion_ts": "2026-01-16T14:30:40.976502", "market_id": "0xb9bbdd34304344dcc45803780a34c97d73a00133a5ecf70f63e1008b8abb2fca", "raw": {"market": "0xb9bbdd34304344dcc45803780a34c97d73a00133a5ecf70f63e1008b8abb2fca", "asset_id": "8682484153073832526711485265636767086525069344085206423986003504588877767339", "price": "0.839", "size": "10", "side": "BUY", "timestamp": "1768573834810", "received_at": "2026-01-16T14:30:34.846007"}}
{"event_type": "price_change", "event_ts": "2026-01-16T14:30:34.846007", "ingestion_ts": "2026-01-16T14:30:40.976502", "market_id": "0xb9bbdd34304344dcc45803780a34c97d73a00133a5ecf70f63e1008b8abb2fca", "raw": {"market": "0xb9bbdd34304344dcc45803780a34c97d73a00133a5ecf70f63e1008b8abb2fca", "asset_id": "72012724360700510767037780555710363830014634797787940282136454146828040926557", "price": "0.161", "size": "10", "side": "SELL", "timestamp": "1768573834810", "received_at": "2026-01-16T14:30:34.846007"}}
{"event_type": "price_change", "event_ts": "2026-01-16T14:30:34.846665", "ingestion_ts": "2026-01-16T14:30:40.976502", "market_id": "0x2393ed0b0fdc450054c7b9071907eca75cf4fc36e385adf4a0a5f99ee62243e8", "raw": {"market": "0x2393ed0b0fdc450054c7b9071907eca75cf4fc36e385adf4a0a5f99ee62243e8", "asset_id": "32769749367306925959219403371425714180265458150646381231272229429098460625924", "price": "0.811", "size": "10", "side": "BUY", "timestamp": "1768573834810", "received_at": "2026-01-16T14:30:34.846665"}}
{"event_type": "price_change", "event_ts": "2026-01-16T14:30:34.846665", "ingestion_ts": "2026-01-16T14:30:40.976502", "market_id": "0x2393ed0b0fdc450054c7b9071907eca75cf4fc36e385adf4a0a5f99ee62243e8", "raw": {"market": "0x2393ed0b0fdc450054c7b9071907eca75cf4fc36e385adf4a0a5f99ee62243e8", "asset_id": "100074770378634056601572485653252702850363676459996771990439989989293515601975", "price": "0.189", "size": "10", "side": "SELL", "timestamp": "1768573834810", "received_at": "2026-01-16T14:30:34.846665"}}
{"event_type": "price_change", "event_ts": "2026-01-16T14:30:34.846699", "ingestion_ts": "2026-01-16T14:30:40.976502", "market_id": "0x9472be65457510b7fc3477b20ba90910e99d92eac8421a14bf4b7b7a08ef31dc", "raw": {"market": "0x9472be65457510b7fc3477b20ba90910e99d92eac8421a14bf4b7b7a08ef31dc", "asset_id": "43311793366960417907757893276427136943959788721376762326430771171648759300146", "price": "0.824", "size": "10", "side": "BUY", "timestamp": "1768573834811", "received_at": "2026-01-16T14:30:34.846699"}}
{"event_type": "price_change", "event_ts": "2026-01-16T14:30:34.846699", "ingestion_ts": "2026-01-16T14:30:40.976502", "market_id": "0x9472be65457510b7fc3477b20ba90910e99d92eac8421a14bf4b7b7a08ef31dc", "raw": {"market": "0x9472be65457510b7fc3477b20ba90910e99d92eac8421a14bf4b7b7a08ef31dc", "asset_id": "73414222381656326204771753454630063673548497164758947581648273905027617570612", "price": "0.176", "size": "10", "side": "SELL", "timestamp": "1768573834811", "received_at": "2026-01-16T14:30:34.846699"}}
{"event_type": "price_change", "event_ts": "2026-01-16T14:30:34.846714", "ingestion_ts": "2026-01-16T14:30:40.976502", "market_id": "0xc55db914f0fd1fee18997706712c0dfd8d0369cdbef93a9fef12bd001914ca77", "raw": {"market": "0xc55db914f0fd1fee18997706712c0dfd8d0369cdbef93a9fef12bd001914ca77", "asset_id": "114600293444080540179603459515770723592661967180480327891296353898330242622833", "price": "0.837", "size": "10", "side": "BUY", "timestamp": "1768573834810", "received_at": "2026-01-16T14:30:34.846714"}}
{"event_type": "price_change", "event_ts": "2026-01-16T14:30:34.846714", "ingestion_ts": "2026-01-16T14:30:40.976502", "market_id": "0xc55db914f0fd1fee18997706712c0dfd8d0369cdbef93a9fef12bd001914ca77", "raw": {"market": "0xc55db914f0fd1fee18997706712c0dfd8d0369cdbef93a9fef12bd001914ca77", "asset_id": "72354723612769247426741660426331235762851940382312402276325808095604519806766", "price": "0.163", "size": "10", "side": "SELL", "timestamp": "1768573834810", "received_at": "2026-01-16T14:30:34.846714"}}
{"event_type": "price_change", "event_ts": "2026-01-16T14:30:34.846768", "ingestion_ts": "2026-01-16T14:30:40.976502", "market_id": "0x44f08744458b8896620cd3330bc5e1ea69df4199b02d4fc583b3fc96e5d314ce", "raw": {"market": "0x44f08744458b8896620cd3330bc5e1ea69df4199b02d4fc583b3fc96e5d314ce", "asset_id": "72327831507226612545928776794104143393438710920370371172884559893525100761096", "price": "0.831", "size": "10", "side": "BUY", "timestamp": "1768573834811", "received_at": "2026-01-16T14:30:34.846768"}}
{"event_type": "price_change", "event_ts": "2026-01-16T14:30:34.846768", "ingestion_ts": "2026-01-16T14:30:40.976502", "market_id": "0x44f08744458b8896620cd3330bc5e1ea69df4199b02d4fc583b3fc96e5d314ce", "raw": {"market": "0x44f08744458b8896620cd3330bc5e1ea69df4199b02d4fc583b3fc96e5d314ce", "asset_id": "49194009556504828848509244326501559253829462790583873936160989575507522044057", "price": "0.169", "size": "10", "side": "SELL", "timestamp": "1768573834811", "received_at": "2026-01-16T14:30:34.846768"}}
{"event_type": "price_change", "event_ts": "2026-01-16T14:30:34.847191", "ingestion_ts": "2026-01-16T14:30:40.976502", "market_id": "0x50c669f178da4e5bbea7f1be25041fd278914712fa87a6a6f8e57d5923d88dee", "raw": {"market": "0x50c669f178da4e5bbea7f1be25041fd278914712fa87a6a6f8e57d5923d88dee", "asset_id": "74040420326294854165772767082819937451857852955603897473157746262672057685461", "price": "0.824", "size": "10", "side": "BUY", "timestamp": "1768573834811", "received_at": "2026-01-16T14:30:34.847191"}}
{"event_type": "price_change", "event_ts": "2026-01-16T14:30:34.847191", "ingestion_ts": "2026-01-16T14:30:40.976502", "market_id": "0x50c669f178da4e5bbea7f1be25041fd278914712fa87a6a6f8e57d5923d88dee", "raw": {"market": "0x50c669f178da4e5bbea7f1be25041fd278914712fa87a6a6f8e57d5923d88dee", "asset_id": "24682525479474221428144937281315825971983904267399062415430320764754931667953", "price": "0.176", "size": "10", "side": "SELL", "timestamp": "1768573834811", "received_at": "2026-01-16T14:30:34.847191"}}
{"event_type": "price_change", "event_ts": "2026-01-16T14:30:34.847224", "ingestion_ts": "2026-01-16T14:30:40.976502", "market_id": "0x49a20c7523c271099008f3ef9a31521263b24d637959852a391e6b4697b1a437", "raw": {"market": "0x49a20c7523c271099008f3ef9a31521263b24d637959852a391e6b4697b1a437", "asset_id": "55881023621710858558280545117465775643848233756850602339827152783696837905531", "price": "0.846", "size": "309.79", "side": "BUY", "timestamp": "1768573834811", "received_at": "2026-01-16T14:30:34.847224"}}
{"event_type": "price_change", "event_ts": "2026-01-16T14:30:34.847224", "ingestion_ts": "2026-01-16T14:30:40.976502", "market_id": "0x49a20c7523c271099008f3ef9a31521263b24d637959852a391e6b4697b1a437", "raw": {"market": "0x49a20c7523c271099008f3ef9a31521263b24d637959852a391e6b4697b1a437", "asset_id": "13018971792603393862521629014128024641178044618205296260525674415067194037856", "price": "0.154", "size": "309.79", "side": "SELL", "timestamp": "1768573834811", "received_at": "2026-01-16T14:30:34.847224"}}
{"event_type": "price_change", "event_ts": "2026-01-16T14:30:36.438174", "ingestion_ts": "2026-01-16T14:30:40.976502", "market_id": "0xaf9d0e448129a9f657f851d49495ba4742055d80e0ef1166ba0ee81d4d594214", "raw": {"market": "0xaf9d0e448129a9f657f851d49495ba4742055d80e0ef1166ba0ee81d4d594214", "asset_id": "4153292802911610701832309484716814274802943278345248636922528170020319407796", "price": "0.987", "size": "140.01", "side": "SELL", "timestamp": "1768573836311", "received_at": "2026-01-16T14:30:36.438174"}}
{"event_type": "price_change", "event_ts": "2026-01-16T14:30:36.438174", "ingestion_ts": "2026-01-16T14:30:40.976502", "market_id": "0xaf9d0e448129a9f657f851d49495ba4742055d80e0ef1166ba0ee81d4d594214", "raw": {"market": "0xaf9d0e448129a9f657f851d49495ba4742055d80e0ef1166ba0ee81d4d594214", "asset_id": "101676997363687199724245607342877036148401850938023978421879460310389391082353", "price": "0.013", "size": "140.01", "side": "BUY", "timestamp": "1768573836311", "received_at": "2026-01-16T14:30:36.438174"}}
{"event_type": "price_change", "event_ts": "2026-01-16T14:30:36.901701", "ingestion_ts": "2026-01-16T14:30:40.976502", "market_id": "0x2393ed0b0fdc450054c7b9071907eca75cf4fc36e385adf4a0a5f99ee62243e8", "raw": {"market": "0x2393ed0b0fdc450054c7b9071907eca75cf4fc36e385adf4a0a5f99ee62243e8", "asset_id": "32769749367306925959219403371425714180265458150646381231272229429098460625924", "price": "0.944", "size": "50", "side": "BUY", "timestamp": "1768573836754", "received_at": "2026-01-16T14:30:36.901701"}}
{"event_type": "price_change", "event_ts": "2026-01-16T14:30:36.901701", "ingestion_ts": "2026-01-16T14:30:40.976502", "market_id": "0x2393ed0b0fdc450054c7b9071907eca75cf4fc36e385adf4a0a5f99ee62243e8", "raw": {"market": "0x2393ed0b0fdc450054c7b9071907eca75cf4fc36e385adf4a0a5f99ee62243e8", "asset_id": "100074770378634056601572485653252702850363676459996771990439989989293515601975", "price": "0.056", "size": "50", "side": "SELL", "timestamp": "1768573836754", "received_at": "2026-01-16T14:30:36.901701"}}
{"event_type": "price_change", "event_ts": "2026-01-16T14:30:37.006465", "ingestion_ts": "2026-01-16T14:30:40.976502", "market_id": "0x2393ed0b0fdc450054c7b9071907eca75cf4fc36e385adf4a0a5f99ee62243e8", "raw": {"market": "0x2393ed0b0fdc450054c7b9071907eca75cf4fc36e385adf4a0a5f99ee62243e8", "asset_id": "100074770378634056601572485653252702850363676459996771990439989989293515601975", "price": "0.057", "size": "0", "side": "SELL", "timestamp": "1768573836878", "received_at": "2026-01-16T14:30:37.006465"}}
{"event_type": "price_change", "event_ts": "2026-01-16T14:30:37.006465", "ingestion_ts": "2026-01-16T14:30:40.976502", "market_id": "0x2393ed0b0fdc450054c7b9071907eca75cf4fc36e385adf4a0a5f99ee62243e8", "raw": {"market": "0x2393ed0b0fdc450054c7b9071907eca75cf4fc36e385adf4a0a5f99ee62243e8", "asset_id": "32769749367306925959219403371425714180265458150646381231272229429098460625924", "price": "0.943", "size": "0", "side": "BUY", "timestamp": "1768573836878", "received_at": "2026-01-16T14:30:37.006465"}}
{"event_type": "price_change", "event_ts": "2026-01-16T14:30:37.041945", "ingestion_ts": "2026-01-16T14:30:40.976502", "market_id": "0x2393ed0b0fdc450054c7b9071907eca75cf4fc36e385adf4a0a5f99ee62243e8", "raw": {"market": "0x2393ed0b0fdc450054c7b9071907eca75cf4fc36e385adf4a0a5f99ee62243e8", "asset_id": "100074770378634056601572485653252702850363676459996771990439989989293515601975", "price": "0.055", "size": "199", "side": "SELL", "timestamp": "1768573836914", "received_at": "2026-01-16T14:30:37.041945"}}
{"event_type": "price_change", "event_ts": "2026-01-16T14:30:37.041945", "ingestion_ts": "2026-01-16T14:30:40.976502", "market_id": "0x2393ed0b0fdc450054c7b9071907eca75cf4fc36e385adf4a0a5f99ee62243e8", "raw": {"market": "0x2393ed0b0fdc450054c7b9071907eca75cf4fc36e385adf4a0a5f99ee62243e8", "asset_id": "32769749367306925959219403371425714180265458150646381231272229429098460625924", "price": "0.945", "size": "199", "side": "BUY", "timestamp": "1768573836914", "received_at": "2026-01-16T14:30:37.041945"}}
{"event_type": "price_change", "event_ts": "2026-01-16T14:30:37.189075", "ingestion_ts": "2026-01-16T14:30:40.976502", "market_id": "0x2393ed0b0fdc450054c7b9071907eca75cf4fc36e385adf4a0a5f99ee62243e8", "raw": {"market": "0x2393ed0b0fdc450054c7b9071907eca75cf4fc36e385adf4a0a5f99ee62243e8", "asset_id": "32769749367306925959219403371425714180265458150646381231272229429098460625924", "price": "0.942", "size": "0", "side": "BUY", "timestamp": "1768573837112", "received_at": "2026-01-16T14:30:37.189075"}}
{"event_type": "price_change", "event_ts": "2026-01-16T14:30:37.189075", "ingestion_ts": "2026-01-16T14:30:40.976502", "market_id": "0x2393ed0b0fdc450054c7b9071907eca75cf4fc36e385adf4a0a5f99ee62243e8", "raw": {"market": "0x2393ed0b0fdc450054c7b9071907eca75cf4fc36e385adf4a0a5f99ee62243e8", "asset_id": "100074770378634056601572485653252702850363676459996771990439989989293515601975", "price": "0.058", "size": "0", "side": "SELL", "timestamp": "1768573837112", "received_at": "2026-01-16T14:30:37.189075"}}
{"event_type": "price_change", "event_ts": "2026-01-16T14:30:38.382257", "ingestion_ts": "2026-01-16T14:30:40.976502", "market_id": "0x44f08744458b8896620cd3330bc5e1ea69df4199b02d4fc583b3fc96e5d314ce", "raw": {"market": "0x44f08744458b8896620cd3330bc5e1ea69df4199b02d4fc583b3fc96e5d314ce", "asset_id": "72327831507226612545928776794104143393438710920370371172884559893525100761096", "price": "0.852", "size": "2052.46", "side": "BUY", "timestamp": "1768573838314", "received_at": "2026-01-16T14:30:38.382257"}}
{"event_type": "price_change", "event_ts": "2026-01-16T14:30:38.382257", "ingestion_ts": "2026-01-16T14:30:40.976502", "market_id": "0x44f08744458b8896620cd3330bc5e1ea69df4199b02d4fc583b3fc96e5d314ce", "raw": {"market": "0x44f08744458b8896620cd3330bc5e1ea69df4199b02d4fc583b3fc96e5d314ce", "asset_id": "49194009556504828848509244326501559253829462790583873936160989575507522044057", "price": "0.148", "size": "2052.46", "side": "SELL", "timestamp": "1768573838314", "received_at": "2026-01-16T14:30:38.382257"}}
{"event_type": "price_change", "event_ts": "2026-01-16T14:30:38.455384", "ingestion_ts": "2026-01-16T14:30:40.976502", "market_id": "0xaf9d0e448129a9f657f851d49495ba4742055d80e0ef1166ba0ee81d4d594214", "raw": {"market": "0xaf9d0e448129a9f657f851d49495ba4742055d80e0ef1166ba0ee81d4d594214", "asset_id": "4153292802911610701832309484716814274802943278345248636922528170020319407796", "price": "0.989", "size": "0", "side": "SELL", "timestamp": "1768573838374", "received_at": "2026-01-16T14:30:38.455384"}}
{"event_type": "price_change", "event_ts": "2026-01-16T14:30:38.455384", "ingestion_ts": "2026-01-16T14:30:40.976502", "market_id": "0xaf9d0e448129a9f657f851d49495ba4742055d80e0ef1166ba0ee81d4d594214", "raw": {"market": "0xaf9d0e448129a9f657f851d49495ba4742055d80e0ef1166ba0ee81d4d594214", "asset_id": "101676997363687199724245607342877036148401850938023978421879460310389391082353", "price": "0.011", "size": "0", "side": "BUY", "timestamp": "1768573838374", "received_at": "2026-01-16T14:30:38.455384"}}
{"event_type": "price_change", "event_ts": "2026-01-16T14:30:38.501377", "ingestion_ts": "2026-01-16T14:30:40.976502", "market_id": "0xaf9d0e448129a9f657f851d49495ba4742055d80e0ef1166ba0ee81d4d594214", "raw": {"market": "0xaf9d0e448129a9f657f851d49495ba4742055d80e0ef1166ba0ee81d4d594214", "asset_id": "4153292802911610701832309484716814274802943278345248636922528170020319407796", "price": "0.986", "size": "20.5", "side": "SELL", "timestamp": "1768573838434", "received_at": "2026-01-16T14:30:38.501377"}}
{"event_type": "price_change", "event_ts": "2026-01-16T14:30:38.501377", "ingestion_ts": "2026-01-16T14:30:40.976502", "market_id": "0xaf9d0e448129a9f657f851d49495ba4742055d80e0ef1166ba0ee81d4d594214", "raw": {"market": "0xaf9d0e448129a9f657f851d49495ba4742055d80e0ef1166ba0ee81d4d594214", "asset_id": "101676997363687199724245607342877036148401850938023978421879460310389391082353", "price": "0.014", "size": "20.5", "side": "BUY", "timestamp": "1768573838434", "received_at": "2026-01-16T14:30:38.501377"}}
{"event_type": "price_change", "event_ts": "2026-01-16T14:30:38.526562", "ingestion_ts": "2026-01-16T14:30:40.976502", "market_id": "0x44f08744458b8896620cd3330bc5e1ea69df4199b02d4fc583b3fc96e5d314ce", "raw": {"market": "0x44f08744458b8896620cd3330bc5e1ea69df4199b02d4fc583b3fc96e5d314ce", "asset_id": "72327831507226612545928776794104143393438710920370371172884559893525100761096", "price": "0.811", "size": "0", "side": "BUY", "timestamp": "1768573838462", "received_at": "2026-01-16T14:30:38.526562"}}
{"event_type": "price_change", "event_ts": "2026-01-16T14:30:38.526562", "ingestion_ts": "2026-01-16T14:30:40.976502", "market_id": "0x44f08744458b8896620cd3330bc5e1ea69df4199b02d4fc583b3fc96e5d314ce", "raw": {"market": "0x44f08744458b8896620cd3330bc5e1ea69df4199b02d4fc583b3fc96e5d314ce", "asset_id": "49194009556504828848509244326501559253829462790583873936160989575507522044057", "price": "0.189", "size": "0", "side": "SELL", "timestamp": "1768573838462", "received_at": "2026-01-16T14:30:38.526562"}}
{"event_type": "price_change", "event_ts": "2026-01-16T14:30:39.502198", "ingestion_ts": "2026-01-16T14:30:40.976502", "market_id": "0x49a20c7523c271099008f3ef9a31521263b24d637959852a391e6b4697b1a437", "raw": {"market": "0x49a20c7523c271099008f3ef9a31521263b24d637959852a391e6b4697b1a437", "asset_id": "55881023621710858558280545117465775643848233756850602339827152783696837905531", "price": "0.846", "size": "299.79", "side": "BUY", "timestamp": "1768573839464", "received_at": "2026-01-16T14:30:39.502198"}}
{"event_type": "price_change", "event_ts": "2026-01-16T14:30:39.502198", "ingestion_ts": "2026-01-16T14:30:40.976502", "market_id": "0x49a20c7523c271099008f3ef9a31521263b24d637959852a391e6b4697b1a437", "raw": {"market": "0x49a20c7523c271099008f3ef9a31521263b24d637959852a391e6b4697b1a437", "asset_id": "13018971792603393862521629014128024641178044618205296260525674415067194037856", "price": "0.154", "size": "299.79", "side": "SELL", "timestamp": "1768573839464", "received_at": "2026-01-16T14:30:39.502198"}}
{"event_type": "price_change", "event_ts": "2026-01-16T14:30:39.502234", "ingestion_ts": "2026-01-16T14:30:40.976502", "market_id": "0xb9bbdd34304344dcc45803780a34c97d73a00133a5ecf70f63e1008b8abb2fca", "raw": {"market": "0xb9bbdd34304344dcc45803780a34c97d73a00133a5ecf70f63e1008b8abb2fca", "asset_id": "8682484153073832526711485265636767086525069344085206423986003504588877767339", "price": "0.839", "size": "0", "side": "BUY", "timestamp": "1768573839464", "received_at": "2026-01-16T14:30:39.502234"}}
{"event_type": "price_change", "event_ts": "2026-01-16T14:30:39.502234", "ingestion_ts": "2026-01-16T14:30:40.976502", "market_id": "0xb9bbdd34304344dcc45803780a34c97d73a00133a5ecf70f63e1008b8abb2fca", "raw": {"market": "0xb9bbdd34304344dcc45803780a34c97d73a00133a5ecf70f63e1008b8abb2fca", "asset_id": "72012724360700510767037780555710363830014634797787940282136454146828040926557", "price": "0.161", "size": "0", "side": "SELL", "timestamp": "1768573839464", "received_at": "2026-01-16T14:30:39.502234"}}
{"event_type": "price_change", "event_ts": "2026-01-16T14:30:39.535484", "ingestion_ts": "2026-01-16T14:30:40.976502", "market_id": "0xb9bbdd34304344dcc45803780a34c97d73a00133a5ecf70f63e1008b8abb2fca", "raw": {"market": "0xb9bbdd34304344dcc45803780a34c97d73a00133a5ecf70f63e1008b8abb2fca", "asset_id": "8682484153073832526711485265636767086525069344085206423986003504588877767339", "price": "0.841", "size": "10", "side": "BUY", "timestamp": "1768573839497", "received_at": "2026-01-16T14:30:39.535484"}}
{"event_type": "price_change", "event_ts": "2026-01-16T14:30:39.535484", "ingestion_ts": "2026-01-16T14:30:40.976502", "market_id": "0xb9bbdd34304344dcc45803780a34c97d73a00133a5ecf70f63e1008b8abb2fca", "raw": {"market": "0xb9bbdd34304344dcc45803780a34c97d73a00133a5ecf70f63e1008b8abb2fca", "asset_id": "72012724360700510767037780555710363830014634797787940282136454146828040926557", "price": "0.159", "size": "10", "side": "SELL", "timestamp": "1768573839497", "received_at": "2026-01-16T14:30:39.535484"}}
{"event_type": "price_change", "event_ts": "2026-01-16T14:30:39.536001", "ingestion_ts": "2026-01-16T14:30:40.976502", "market_id": "0x49a20c7523c271099008f3ef9a31521263b24d637959852a391e6b4697b1a437", "raw": {"market": "0x49a20c7523c271099008f3ef9a31521263b24d637959852a391e6b4697b1a437", "asset_id": "55881023621710858558280545117465775643848233756850602339827152783696837905531", "price": "0.847", "size": "10", "side": "BUY", "timestamp": "1768573839499", "received_at": "2026-01-16T14:30:39.536001"}}
{"event_type": "price_change", "event_ts": "2026-01-16T14:30:39.536001", "ingestion_ts": "2026-01-16T14:30:40.976502", "market_id": "0x49a20c7523c271099008f3ef9a31521263b24d637959852a391e6b4697b1a437", "raw": {"market": "0x49a20c7523c271099008f3ef9a31521263b24d637959852a391e6b4697b1a437", "asset_id": "13018971792603393862521629014128024641178044618205296260525674415067194037856", "price": "0.153", "size": "10", "side": "SELL", "timestamp": "1768573839499", "received_at": "2026-01-16T14:30:39.536001"}}
{"event_type": "price_change", "event_ts": "2026-01-16T14:30:40.944280", "ingestion_ts": "2026-01-16T14:30:40.976502", "market_id": "0x49686d26fb712515cd5e12c23f0a1c7e10214c7faa3cb0a730aabe0c33694082", "raw": {"market": "0x49686d26fb712515cd5e12c23f0a1c7e10214c7faa3cb0a730aabe0c33694082", "asset_id": "13244681086321087932946246027856416106585284024824496763706748621681543444582", "price": "0.853", "size": "50.86", "side": "BUY", "timestamp": "1768573840869", "received_at": "2026-01-16T14:30:40.944280"}}
{"event_type": "price_change", "event_ts": "2026-01-16T14:30:40.944280", "ingestion_ts": "2026-01-16T14:30:40.976502", "market_id": "0x49686d26fb712515cd5e12c23f0a1c7e10214c7faa3cb0a730aabe0c33694082", "raw": {"market": "0x49686d26fb712515cd5e12c23f0a1c7e10214c7faa3cb0a730aabe0c33694082", "asset_id": "30442780799048074404860985387051749017905070253466005720364298335239299761065", "price": "0.147", "size": "50.86", "side": "SELL", "timestamp": "1768573840869", "received_at": "2026-01-16T14:30:40.944280"}}
