{"event_type": "price_change", "event_ts": "2026-01-16T14:36:46.918790", "ingestion_ts": "2026-01-16T14:36:49.604167", "market_id": "0xc0e6b917320a47228fb96e3b5ae0e5c93773a5ae2662ae4e1f37807cfe47ce98", "raw": {"market": "0xc0e6b917320a47228fb96e3b5ae0e5c93773a5ae2662ae4e1f37807cfe47ce98", "asset_id": "58656358377246279051017109359677190749228949103591068167284263961542487110215", "price": "0.004", "size": "130.06", "side": "BUY", "timestamp": "1768574206875", "received_at": "2026-01-16T14:36:46.918790"}}
{"event_type": "price_change", "event_ts": "2026-01-16T14:36:46.918790", "ingestion_ts": "2026-01-16T14:36:49.604167", "market_id": "0xc0e6b917320a47228fb96e3b5ae0e5c93773a5ae2662ae4e1f37807cfe47ce98", "raw": {"market": "0xc0e6b917320a47228fb96e3b5ae0e5c93773a5ae2662ae4e1f37807cfe47ce98", "asset_id": "81647294538046680798858716589766492074338758116170717123345952330712416337530", "price": "0.996", "size": "130.06", "side": "SELL", "timestamp": "1768574206875", "received_at": "2026-01-16T14:36:46.918790"}}
{"event_type": "price_change", "event_ts": "2026-01-16T14:36:46.944545", "ingestion_ts": "2026-01-16T14:36:49.604167", "market_id": "0xc0e6b917320a47228fb96e3b5ae0e5c93773a5ae2662ae4e1f37807cfe47ce98", "raw": {"market": "0xc0e6b917320a47228fb96e3b5ae0e5c93773a5ae2662ae4e1f37807cfe47ce98", "asset_id": "58656358377246279051017109359677190749228949103591068167284263961542487110215", "price": "0.004", "size": "140.43", "side": "BUY", "timestamp": "1768574206876", "received_at": "2026-01-16T14:36:46.944545"}}
{"event_type": "price_change", "event_ts": "2026-01-16T14:36:46.944545", "ingestion_ts": "2026-01-16T14:36:49.604167", "market_id": "0xc0e6b917320a47228fb96e3b5ae0e5c93773a5ae2662ae4e1f37807cfe47ce98", "raw": {"market": "0xc0e6b917320a47228fb96e3b5ae0e5c93773a5ae2662ae4e1f37807cfe47ce98", "asset_id": "81647294538046680798858716589766492074338758116170717123345952330712416337530", "price": "0.996", "size": "140.43", "side": "SELL", "timestamp": "1768574206876", "received_at": "2026-01-16T14:36:46.944545"}}
{"event_type": "price_change", "event_ts": "2026-01-16T14:36:47.276042", "ingestion_ts": "2026-01-16T14:36:49.604167", "market_id": "0xc55db914f0fd1fee18997706712c0dfd8d0369cdbef93a9fef12bd001914ca77", "raw": {"market": "0xc55db914f0fd1fee18997706712c0dfd8d0369cdbef93a9fef12bd001914ca77", "asset_id": "114600293444080540179603459515770723592661967180480327891296353898330242622833", "price": "0.856", "size": "0", "side": "BUY", "timestamp": "1768574207237", "received_at": "2026-01-16T14:36:47.276042"}}
{"event_type": "price_change", "event_ts": "2026-01-16T14:36:47.276042", "ingestion_ts": "2026-01-16T14:36:49.604167", "market_id": "0xc55db914f0fd1fee18997706712c0dfd8d0369cdbef93a9fef12bd001914ca77", "raw": {"market": "0xc55db914f0fd1fee18997706712c0dfd8d0369cdbef93a9fef12bd001914ca77", "asset_id": "72354723612769247426741660426331235762851940382312402276325808095604519806766", "price": "0.144", "size": "0", "side": "SELL", "timestamp": "1768574207237", "received_at": "2026-01-16T14:36:47.276042"}}
{"event_type": "price_change", "event_ts": "2026-01-16T14:36:47.276101", "ingestion_ts": "2026-01-16T14:36:49.604167", "market_id": "0x49a20c7523c271099008f3ef9a31521263b24d637959852a391e6b4697b1a437", "raw": {"market": "0x49a20c7523c271099008f3ef9a31521263b24d637959852a391e6b4697b1a437", "asset_id": "55881023621710858558280545117465775643848233756850602339827152783696837905531", "price": "0.847", "size": "0", "side": "BUY", "timestamp": "1768574207237", "received_at": "2026-01-16T14:36:47.276101"}}
{"event_type": "price_change", "event_ts": "2026-01-16T14:36:47.276101", "ingestion_ts": "2026-01-16T14:36:49.604167", "market_id": "0x49a20c7523c271099008f3ef9a31521263b24d637959852a391e6b4697b1a437", "raw": {"market": "0x49a20c7523c271099008f3ef9a31521263b24d637959852a391e6b4697b1a437", "asset_id": "13018971792603393862521629014128024641178044618205296260525674415067194037856", "price": "0.153", "size": "0", "side": "SELL", "timestamp": "1768574207237", "received_at": "2026-01-16T14:36:47.276101"}}
{"event_type": "price_change", "event_ts": "2026-01-16T14:36:47.276121", "ingestion_ts": "2026-01-16T14:36:49.604167", "market_id": "0x49686d26fb712515cd5e12c23f0a1c7e10214c7faa3cb0a730aabe0c33694082", "raw": {"market": "0x49686d26fb712515cd5e12c23f0a1c7e10214c7faa3cb0a730aabe0c33694082", "asset_id": "30442780799048074404860985387051749017905070253466005720364298335239299761065", "price": "0.005", "size": "99.51", "side": "BUY", "timestamp": "1768574207237", "received_at": "2026-01-16T14:36:47.276121"}}
{"event_type": "price_change", "event_ts": "2026-01-16T14:36:47.276121", "ingestion_ts": "2026-01-16T14:36:49.604167", "market_id": "0x49686d26fb712515cd5e12c23f0a1c7e10214c7faa3cb0a730aabe0c33694082", "raw": {"market": "0x49686d26fb712515cd5e12c23f0a1c7e10214c7faa3cb0a730aabe0c33694082", "asset_id": "13244681086321087932946246027856416106585284024824496763706748621681543444582", "price": "0.995", "size": "99.51", "side": "SELL", "timestamp": "1768574207237", "received_at": "2026-01-16T14:36:47.276121"}}
{"event_type": "price_change", "event_ts": "2026-01-16T14:36:47.276133", "ingestion_ts": "2026-01-16T14:36:49.604167", "market_id": "0x9472be65457510b7fc3477b20ba90910e99d92eac8421a14bf4b7b7a08ef31dc", "raw": {"market": "0x9472be65457510b7fc3477b20ba90910e99d92eac8421a14bf4b7b7a08ef31dc", "asset_id": "43311793366960417907757893276427136943959788721376762326430771171648759300146", "price": "0.855", "size": "292", "side": "BUY", "timestamp": "1768574207237", "received_at": "2026-01-16T14:36:47.276133"}}
{"event_type": "price_change", "event_ts": "2026-01-16T14:36:47.276133", "ingestion_ts": "2026-01-16T14:36:49.604167", "market_id": "0x9472be65457510b7fc3477b20ba90910e99d92eac8421a14bf4b7b7a08ef31dc", "raw": {"market": "0x9472be65457510b7fc3477b20ba90910e99d92eac8421a14bf4b7b7a08ef31dc", "asset_id": "73414222381656326204771753454630063673548497164758947581648273905027617570612", "price": "0.145", "size": "292", "side": "SELL", "timestamp": "1768574207237", "received_at": "2026-01-16T14:36:47.276133"}}
{"event_type": "price_change", "event_ts": "2026-01-16T14:36:47.276144", "ingestion_ts": "2026-01-16T14:36:49.604167", "market_id": "0x44f08744458b8896620cd3330bc5e1ea69df4199b02d4fc583b3fc96e5d314ce", "raw": {"market": "0x44f08744458b8896620cd3330bc5e1ea69df4199b02d4fc583b3fc96e5d314ce", "asset_id": "72327831507226612545928776794104143393438710920370371172884559893525100761096", "price": "0.831", "size": "0", "side": "BUY", "timestamp": "1768574207237", "received_at": "2026-01-16T14:36:47.276144"}}
{"event_type": "price_change", "event_ts": "2026-01-16T14:36:47.276144", "ingestion_ts": "2026-01-16T14:36:49.604167", "market_id": "0x44f08744458b8896620cd3330bc5e1ea69df4199b02d4fc583b3fc96e5d314ce", "raw": {"market": "0x44f08744458b8896620cd3330bc5e1ea69df4199b02d4fc583b3fc96e5d314ce", "asset_id": "49194009556504828848509244326501559253829462790583873936160989575507522044057", "price": "0.169", "size": "0", "side": "SELL", "timestamp": "1768574207237", "received_at": "2026-01-16T14:36:47.276144"}}
{"event_type": "price_change", "event_ts": "2026-01-16T14:36:47.278999", "ingestion_ts": "2026-01-16T14:36:49.604167", "market_id": "0x50c669f178da4e5bbea7f1be25041fd278914712fa87a6a6f8e57d5923d88dee", "raw": {"market": "0x50c669f178da4e5bbea7f1be25041fd278914712fa87a6a6f8e57d5923d88dee", "asset_id": "74040420326294854165772767082819937451857852955603897473157746262672057685461", "price": "0.825", "size": "0", "side": "BUY", "timestamp": "1768574207237", "received_at": "2026-01-16T14:36:47.278999"}}
{"event_type": "price_change", "event_ts": "2026-01-16T14:36:47.278999", "ingestion_ts": "2026-01-16T14:36:49.604167", "market_id": "0x50c669f178da4e5bbea7f1be25041fd278914712fa87a6a6f8e57d5923d88dee", "raw": {"market": "0x50c669f178da4e5bbea7f1be25041fd278914712fa87a6a6f8e57d5923d88dee", "asset_id": "24682525479474221428144937281315825971983904267399062415430320764754931667953", "price": "0.175", "size": "0", "side": "SELL", "timestamp": "1768574207237", "received_at": "2026-01-16T14:36:47.278999"}}
{"event_type": "price_change", "event_ts": "2026-01-16T14:36:47.319895", "ingestion_ts": "2026-01-16T14:36:49.604167", "market_id": "0x49686d26fb712515cd5e12c23f0a1c7e10214c7faa3cb0a730aabe0c33694082", "raw": {"market": "0x49686d26fb712515cd5e12c23f0a1c7e10214c7faa3cb0a730aabe0c33694082", "asset_id": "30442780799048074404860985387051749017905070253466005720364298335239299761065", "price": "0.006", "size": "20.08", "side": "BUY", "timestamp": "1768574207275", "received_at": "2026-01-16T14:36:47.319895"}}
{"event_type": "price_change", "event_ts": "2026-01-16T14:36:47.319895", "ingestion_ts": "2026-01-16T14:36:49.604167", "market_id": "0x49686d26fb712515cd5e12c23f0a1c7e10214c7faa3cb0a730aabe0c33694082", "raw": {"market": "0x49686d26fb712515cd5e12c23f0a1c7e10214c7faa3cb0a730aabe0c33694082", "asset_id": "13244681086321087932946246027856416106585284024824496763706748621681543444582", "price": "0.994", "size": "20.08", "side": "SELL", "timestamp": "1768574207275", "received_at": "2026-01-16T14:36:47.319895"}}
{"event_type": "price_change", "event_ts": "2026-01-16T14:36:47.319936", "ingestion_ts": "2026-01-16T14:36:49.604167", "market_id": "0x9472be65457510b7fc3477b20ba90910e99d92eac8421a14bf4b7b7a08ef31dc", "raw": {"market": "0x9472be65457510b7fc3477b20ba90910e99d92eac8421a14bf4b7b7a08ef31dc", "asset_id": "43311793366960417907757893276427136943959788721376762326430771171648759300146", "price": "0.856", "size": "10", "side": "BUY", "timestamp": "1768574207275", "received_at": "2026-01-16T14:36:47.319936"}}
{"event_type": "price_change", "event_ts": "2026-01-16T14:36:47.319936", "ingestion_ts": "2026-01-16T14:36:49.604167", "market_id": "0x9472be65457510b7fc3477b20ba90910e99d92eac8421a14bf4b7b7a08ef31dc", "raw": {"market": "0x9472be65457510b7fc3477b20ba90910e99d92eac8421a14bf4b7b7a08ef31dc", "asset_id": "73414222381656326204771753454630063673548497164758947581648273905027617570612", "price": "0.144", "size": "10", "side": "SELL", "timestamp": "1768574207275", "received_at": "2026-01-16T14:36:47.319936"}}
{"event_type": "price_change", "event_ts": "2026-01-16T14:36:47.319951", "ingestion_ts": "2026-01-16T14:36:49.604167", "market_id": "0xc55db914f0fd1fee18997706712c0dfd8d0369cdbef93a9fef12bd001914ca77", "raw": {"market": "0xc55db914f0fd1fee18997706712c0dfd8d0369cdbef93a9fef12bd001914ca77", "asset_id": "114600293444080540179603459515770723592661967180480327891296353898330242622833", "price": "0.857", "size": "243", "side": "BUY", "timestamp": "1768574207275", "received_at": "2026-01-16T14:36:47.319951"}}
{"event_type": "price_change", "event_ts": "2026-01-16T14:36:47.319951", "ingestion_ts": "2026-01-16T14:36:49.604167", "market_id": "0xc55db914f0fd1fee18997706712c0dfd8d0369cdbef93a9fef12bd001914ca77", "raw": {"market": "0xc55db914f0fd1fee18997706712c0dfd8d0369cdbef93a9fef12bd001914ca77", "asset_id": "72354723612769247426741660426331235762851940382312402276325808095604519806766", "price": "0.143", "size": "243", "side": "SELL", "timestamp": "1768574207275", "received_at": "2026-01-16T14:36:47.319951"}}
{"event_type": "price_change", "event_ts": "2026-01-16T14:36:47.319964", "ingestion_ts": "2026-01-16T14:36:49.604167", "market_id": "0x50c669f178da4e5bbea7f1be25041fd278914712fa87a6a6f8e57d5923d88dee", "raw": {"market": "0x50c669f178da4e5bbea7f1be25041fd278914712fa87a6a6f8e57d5923d88dee", "asset_id": "74040420326294854165772767082819937451857852955603897473157746262672057685461", "price": "0.856", "size": "10", "side": "BUY", "timestamp": "1768574207275", "received_at": "2026-01-16T14:36:47.319964"}}
{"event_type": "price_change", "event_ts": "2026-01-16T14:36:47.319964", "ingestion_ts": "2026-01-16T14:36:49.604167", "market_id": "0x50c669f178da4e5bbea7f1be25041fd278914712fa87a6a6f8e57d5923d88dee", "raw": {"market": "0x50c669f178da4e5bbea7f1be25041fd278914712fa87a6a6f8e57d5923d88dee", "asset_id": "24682525479474221428144937281315825971983904267399062415430320764754931667953", "price": "0.144", "size": "10", "side": "SELL", "timestamp": "1768574207275", "received_at": "2026-01-16T14:36:47.319964"}}
{"event_type": "price_change", "event_ts": "2026-01-16T14:36:47.320810", "ingestion_ts": "2026-01-16T14:36:49.604167", "market_id": "0x49a20c7523c271099008f3ef9a31521263b24d637959852a391e6b4697b1a437", "raw": {"market": "0x49a20c7523c271099008f3ef9a31521263b24d637959852a391e6b4697b1a437", "asset_id": "55881023621710858558280545117465775643848233756850602339827152783696837905531", "price": "0.855", "size": "302", "side": "BUY", "timestamp": "1768574207275", "received_at": "2026-01-16T14:36:47.320810"}}
{"event_type": "price_change", "event_ts": "2026-01-16T14:36:47.320810", "ingestion_ts": "2026-01-16T14:36:49.604167", "market_id": "0x49a20c7523c271099008f3ef9a31521263b24d637959852a391e6b4697b1a437", "raw": {"market": "0x49a20c7523c271099008f3ef9a31521263b24d637959852a391e6b4697b1a437", "asset_id": "13018971792603393862521629014128024641178044618205296260525674415067194037856", "price": "0.145", "size": "302", "side": "SELL", "timestamp": "1768574207275", "received_at": "2026-01-16T14:36:47.320810"}}
{"event_type": "price_change", "event_ts": "2026-01-16T14:36:47.325133", "ingestion_ts": "2026-01-16T14:36:49.604167", "market_id": "0x44f08744458b8896620cd3330bc5e1ea69df4199b02d4fc583b3fc96e5d314ce", "raw": {"market": "0x44f08744458b8896620cd3330bc5e1ea69df4199b02d4fc583b3fc96e5d314ce", "asset_id": "72327831507226612545928776794104143393438710920370371172884559893525100761096", "price": "0.853", "size": "244", "side": "BUY", "timestamp": "1768574207275", "received_at": "2026-01-16T14:36:47.325133"}}
{"event_type": "price_change", "event_ts": "2026-01-16T14:36:47.325133", "ingestion_ts": "2026-01-16T14:36:49.604167", "market_id": "0x44f08744458b8896620cd3330bc5e1ea69df4199b02d4fc583b3fc96e5d314ce", "raw": {"market": "0x44f08744458b8896620cd3330bc5e1ea69df4199b02d4fc583b3fc96e5d314ce", "asset_id": "49194009556504828848509244326501559253829462790583873936160989575507522044057", "price": "0.147", "size": "244", "side": "SELL", "timestamp": "1768574207275", "received_at": "2026-01-16T14:36:47.325133"}}
{"event_type": "price_change", "event_ts": "2026-01-16T14:36:47.446129", "ingestion_ts": "2026-01-16T14:36:49.604167", "market_id": "0xc0e6b917320a47228fb96e3b5ae0e5c93773a5ae2662ae4e1f37807cfe47ce98", "raw": {"market": "0xc0e6b917320a47228fb96e3b5ae0e5c93773a5ae2662ae4e1f37807cfe47ce98", "asset_id": "58656358377246279051017109359677190749228949103591068167284263961542487110215", "price": "0.071", "size": "8.34", "side": "SELL", "timestamp": "1768574207387", "received_at": "2026-01-16T14:36:47.446129"}}
{"event_type": "price_change", "event_ts": "2026-01-16T14:36:47.446129", "ingestion_ts": "2026-01-16T14:36:49.604167", "market_id": "0xc0e6b917320a47228fb96e3b5ae0e5c93773a5ae2662ae4e1f37807cfe47ce98", "raw": {"market": "0xc0e6b917320a47228fb96e3b5ae0e5c93773a5ae2662ae4e1f37807cfe47ce98", "asset_id": "81647294538046680798858716589766492074338758116170717123345952330712416337530", "price": "0.929", "size": "8.34", "side": "BUY", "timestamp": "1768574207387", "received_at": "2026-01-16T14:36:47.446129"}}
{"event_type": "price_change", "event_ts": "2026-01-16T14:36:47.446170", "ingestion_ts": "2026-01-16T14:36:49.604167", "market_id": "0xc0e6b917320a47228fb96e3b5ae0e5c93773a5ae2662ae4e1f37807cfe47ce98", "raw": {"market": "0xc0e6b917320a47228fb96e3b5ae0e5c93773a5ae2662ae4e1f37807cfe47ce98", "asset_id": "58656358377246279051017109359677190749228949103591068167284263961542487110215", "price": "0.072", "size": "11.84", "side": "SELL", "timestamp": "1768574207387", "received_at": "2026-01-16T14:36:47.446170"}}
{"event_type": "price_change", "event_ts": "2026-01-16T14:36:47.446170", "ingestion_ts": "2026-01-16T14:36:49.604167", "market_id": "0xc0e6b917320a47228fb96e3b5ae0e5c93773a5ae2662ae4e1f37807cfe47ce98", "raw": {"market": "0xc0e6b917320a47228fb96e3b5ae0e5c93773a5ae2662ae4e1f37807cfe47ce98", "asset_id": "81647294538046680798858716589766492074338758116170717123345952330712416337530", "price": "0.928", "size": "11.84", "side": "BUY", "timestamp": "1768574207387", "received_at": "2026-01-16T14:36:47.446170"}}
{"event_type": "price_change", "event_ts": "2026-01-16T14:36:48.068245", "ingestion_ts": "2026-01-16T14:36:49.604167", "market_id": "0xc0e6b917320a47228fb96e3b5ae0e5c93773a5ae2662ae4e1f37807cfe47ce98", "raw": {"market": "0xc0e6b917320a47228fb96e3b5ae0e5c93773a5ae2662ae4e1f37807cfe47ce98", "asset_id": "58656358377246279051017109359677190749228949103591068167284263961542487110215", "price": "0.071", "size": "19.94", "side": "SELL", "timestamp": "1768574208028", "received_at": "2026-01-16T14:36:48.068245"}}
{"event_type": "price_change", "event_ts": "2026-01-16T14:36:48.068245", "ingestion_ts": "2026-01-16T14:36:49.604167", "market_id": "0xc0e6b917320a47228fb96e3b5ae0e5c93773a5ae2662ae4e1f37807cfe47ce98", "raw": {"market": "0xc0e6b917320a47228fb96e3b5ae0e5c93773a5ae2662ae4e1f37807cfe47ce98", "asset_id": "81647294538046680798858716589766492074338758116170717123345952330712416337530", "price": "0.929", "size": "19.94", "side": "BUY", "timestamp": "1768574208028", "received_at": "2026-01-16T14:36:48.068245"}}
{"event_type": "price_change", "event_ts": "2026-01-16T14:36:48.068341", "ingestion_ts": "2026-01-16T14:36:49.604167", "market_id": "0xc0e6b917320a47228fb96e3b5ae0e5c93773a5ae2662ae4e1f37807cfe47ce98", "raw": {"market": "0xc0e6b917320a47228fb96e3b5ae0e5c93773a5ae2662ae4e1f37807cfe47ce98", "asset_id": "58656358377246279051017109359677190749228949103591068167284263961542487110215", "price": "0.07", "size": "5.01", "side": "SELL", "timestamp": "1768574208029", "received_at": "2026-01-16T14:36:48.068341"}}
{"event_type": "price_change", "event_ts": "2026-01-16T14:36:48.068341", "ingestion_ts": "2026-01-16T14:36:49.604167", "market_id": "0xc0e6b917320a47228fb96e3b5ae0e5c93773a5ae2662ae4e1f37807cfe47ce98", "raw": {"market": "0xc0e6b917320a47228fb96e3b5ae0e5c93773a5ae2662ae4e1f37807cfe47ce98", "asset_id": "81647294538046680798858716589766492074338758116170717123345952330712416337530", "price": "0.93", "size": "5.01", "side": "BUY", "timestamp": "1768574208029", "received_at": "2026-01-16T14:36:48.068341"}}
{"event_type": "price_change", "event_ts": "2026-01-16T14:36:48.068353", "ingestion_ts": "2026-01-16T14:36:49.604167", "market_id": "0xc0e6b917320a47228fb96e3b5ae0e5c93773a5ae2662ae4e1f37807cfe47ce98", "raw": {"market": "0xc0e6b917320a47228fb96e3b5ae0e5c93773a5ae2662ae4e1f37807cfe47ce98", "asset_id": "58656358377246279051017109359677190749228949103591068167284263961542487110215", "price": "0.071", "size": "31.54", "side": "SELL", "timestamp": "1768574208030", "received_at": "2026-01-16T14:36:48.068353"}}
{"event_type": "price_change", "event_ts": "2026-01-16T14:36:48.068353", "ingestion_ts": "2026-01-16T14:36:49.604167", "market_id": "0xc0e6b917320a47228fb96e3b5ae0e5c93773a5ae2662ae4e1f37807cfe47ce98", "raw": {"market": "0xc0e6b917320a47228fb96e3b5ae0e5c93773a5ae2662ae4e1f37807cfe47ce98", "asset_id": "81647294538046680798858716589766492074338758116170717123345952330712416337530", "price": "0.929", "size": "31.54", "side": "BUY", "timestamp": "1768574208030", "received_at": "2026-01-16T14:36:48.068353"}}
{"event_type": "price_change", "event_ts": "2026-01-16T14:36:48.068372", "ingestion_ts": "2026-01-16T14:36:49.604167", "market_id": "0xc0e6b917320a47228fb96e3b5ae0e5c93773a5ae2662ae4e1f37807cfe47ce98", "raw": {"market": "0xc0e6b917320a47228fb96e3b5ae0e5c93773a5ae2662ae4e1f37807cfe47ce98", "asset_id": "58656358377246279051017109359677190749228949103591068167284263961542487110215", "price": "0.07", "size": "10.02", "side": "SELL", "timestamp": "1768574208031", "received_at": "2026-01-16T14:36:48.068372"}}
{"event_type": "price_change", "event_ts": "2026-01-16T14:36:48.068372", "ingestion_ts": "2026-01-16T14:36:49.604167", "market_id": "0xc0e6b917320a47228fb96e3b5ae0e5c93773a5ae2662ae4e1f37807cfe47ce98", "raw": {"market": "0xc0e6b917320a47228fb96e3b5ae0e5c93773a5ae2662ae4e1f37807cfe47ce98", "asset_id": "81647294538046680798858716589766492074338758116170717123345952330712416337530", "price": "0.93", "size": "10.02", "side": "BUY", "timestamp": "1768574208031", "received_at": "2026-01-16T14:36:48.068372"}}
{"event_type": "price_change", "event_ts": "2026-01-16T14:36:48.156746", "ingestion_ts": "2026-01-16T14:36:49.604167", "market_id": "0xc0e6b917320a47228fb96e3b5ae0e5c93773a5ae2662ae4e1f37807cfe47ce98", "raw": {"market": "0xc0e6b917320a47228fb96e3b5ae0e5c93773a5ae2662ae4e1f37807cfe47ce98", "asset_id": "81647294538046680798858716589766492074338758116170717123345952330712416337530", "price": "0.924", "size": "36.9", "side": "BUY", "timestamp": "1768574208120", "received_at": "2026-01-16T14:36:48.156746"}}
{"event_type": "price_change", "event_ts": "2026-01-16T14:36:48.156746", "ingestion_ts": "2026-01-16T14:36:49.604167", "market_id": "0xc0e6b917320a47228fb96e3b5ae0e5c93773a5ae2662ae4e1f37807cfe47ce98", "raw": {"market": "0xc0e6b917320a47228fb96e3b5ae0e5c93773a5ae2662ae4e1f37807cfe47ce98", "asset_id": "58656358377246279051017109359677190749228949103591068167284263961542487110215", "price": "0.076", "size": "36.9", "side": "SELL", "timestamp": "1768574208120", "received_at": "2026-01-16T14:36:48.156746"}}
{"event_type": "price_change", "event_ts": "2026-01-16T14:36:48.568803", "ingestion_ts": "2026-01-16T14:36:49.604167", "market_id": "0x49686d26fb712515cd5e12c23f0a1c7e10214c7faa3cb0a730aabe0c33694082", "raw": {"market": "0x49686d26fb712515cd5e12c23f0a1c7e10214c7faa3cb0a730aabe0c33694082", "asset_id": "30442780799048074404860985387051749017905070253466005720364298335239299761065", "price": "0.003", "size": "15.78", "side": "BUY", "timestamp": "1768574208521", "received_at": "2026-01-16T14:36:48.568803"}}
{"event_type": "price_change", "event_ts": "2026-01-16T14:36:48.568803", "ingestion_ts": "2026-01-16T14:36:49.604167", "market_id": "0x49686d26fb712515cd5e12c23f0a1c7e10214c7faa3cb0a730aabe0c33694082", "raw": {"market": "0x49686d26fb712515cd5e12c23f0a1c7e10214c7faa3cb0a730aabe0c33694082", "asset_id": "13244681086321087932946246027856416106585284024824496763706748621681543444582", "price": "0.997", "size": "15.78", "side": "SELL", "timestamp": "1768574208521", "received_at": "2026-01-16T14:36:48.568803"}}
{"event_type": "price_change", "event_ts": "2026-01-16T14:36:48.568845", "ingestion_ts": "2026-01-16T14:36:49.604167", "market_id": "0x49686d26fb712515cd5e12c23f0a1c7e10214c7faa3cb0a730aabe0c33694082", "raw": {"market": "0x49686d26fb712515cd5e12c23f0a1c7e10214c7faa3cb0a730aabe0c33694082", "asset_id": "30442780799048074404860985387051749017905070253466005720364298335239299761065", "price": "0.008", "size": "5.94", "side": "BUY", "timestamp": "1768574208521", "received_at": "2026-01-16T14:36:48.568845"}}
{"event_type": "price_change", "event_ts": "2026-01-16T14:36:48.568845", "ingestion_ts": "2026-01-16T14:36:49.604167", "market_id": "0x49686d26fb712515cd5e12c23f0a1c7e10214c7faa3cb0a730aabe0c33694082", "raw": {"market": "0x49686d26fb712515cd5e12c23f0a1c7e10214c7faa3cb0a730aabe0c33694082", "asset_id": "13244681086321087932946246027856416106585284024824496763706748621681543444582", "price": "0.992", "size": "5.94", "side": "SELL", "timestamp": "1768574208521", "received_at": "2026-01-16T14:36:48.568845"}}
{"event_type": "price_change", "event_ts": "2026-01-16T14:36:48.568861", "ingestion_ts": "2026-01-16T14:36:49.604167", "market_id": "0x49686d26fb712515cd5e12c23f0a1c7e10214c7faa3cb0a730aabe0c33694082", "raw": {"market": "0x49686d26fb712515cd5e12c23f0a1c7e10214c7faa3cb0a730aabe0c33694082", "asset_id": "30442780799048074404860985387051749017905070253466005720364298335239299761065", "price": "0.012", "size": "0", "side": "BUY", "timestamp": "1768574208521", "received_at": "2026-01-16T14:36:48.568861"}}
{"event_type": "price_change", "event_ts": "2026-01-16T14:36:48.568861", "ingestion_ts": "2026-01-16T14:36:49.604167", "market_id": "0x49686d26fb712515cd5e12c23f0a1c7e10214c7faa3cb0a730aabe0c33694082", "raw": {"market": "0x49686d26fb712515cd5e12c23f0a1c7e10214c7faa3cb0a730aabe0c33694082", "asset_id": "13244681086321087932946246027856416106585284024824496763706748621681543444582", "price": "0.988", "size": "0", "side": "SELL", "timestamp": "1768574208521", "received_at": "2026-01-16T14:36:48.568861"}}
{"event_type": "price_change", "event_ts": "2026-01-16T14:36:49.048353", "ingestion_ts": "2026-01-16T14:36:49.604167", "market_id": "0xc0e6b917320a47228fb96e3b5ae0e5c93773a5ae2662ae4e1f37807cfe47ce98", "raw": {"market": "0xc0e6b917320a47228fb96e3b5ae0e5c93773a5ae2662ae4e1f37807cfe47ce98", "asset_id": "58656358377246279051017109359677190749228949103591068167284263961542487110215", "price": "0.004", "size": "119.69", "side": "BUY", "timestamp": "1768574209012", "received_at": "2026-01-16T14:36:49.048353"}}
{"event_type": "price_change", "event_ts": "2026-01-16T14:36:49.048353", "ingestion_ts": "2026-01-16T14:36:49.604167", "market_id": "0xc0e6b917320a47228fb96e3b5ae0e5c93773a5ae2662ae4e1f37807cfe47ce98", "raw": {"market": "0xc0e6b917320a47228fb96e3b5ae0e5c93773a5ae2662ae4e1f37807cfe47ce98", "asset_id": "81647294538046680798858716589766492074338758116170717123345952330712416337530", "price": "0.996", "size": "119.69", "side": "SELL", "timestamp": "1768574209012", "received_at": "2026-01-16T14:36:49.048353"}}
{"event_type": "price_change", "event_ts": "2026-01-16T14:36:49.157791", "ingestion_ts": "2026-01-16T14:36:49.604167", "market_id": "0x49686d26fb712515cd5e12c23f0a1c7e10214c7faa3cb0a730aabe0c33694082", "raw": {"market": "0x49686d26fb712515cd5e12c23f0a1c7e10214c7faa3cb0a730aabe0c33694082", "asset_id": "30442780799048074404860985387051749017905070253466005720364298335239299761065", "price": "0.013", "size": "7.72", "side": "BUY", "timestamp": "1768574209117", "received_at": "2026-01-16T14:36:49.157791"}}
{"event_type": "price_change", "event_ts": "2026-01-16T14:36:49.157791", "ingestion_ts": "2026-01-16T14:36:49.604167", "market_id": "0x49686d26fb712515cd5e12c23f0a1c7e10214c7faa3cb0a730aabe0c33694082", "raw": {"market": "0x49686d26fb712515cd5e12c23f0a1c7e10214c7faa3cb0a730aabe0c33694082", "asset_id": "13244681086321087932946246027856416106585284024824496763706748621681543444582", "price": "0.987", "size": "7.72", "side": "SELL", "timestamp": "1768574209117", "received_at": "2026-01-16T14:36:49.157791"}}
{"event_type": "price_change", "event_ts": "2026-01-16T14:36:49.158138", "ingestion_ts": "2026-01-16T14:36:49.604167", "market_id": "0x49686d26fb712515cd5e12c23f0a1c7e10214c7faa3cb0a730aabe0c33694082", "raw": {"market": "0x49686d26fb712515cd5e12c23f0a1c7e10214c7faa3cb0a730aabe0c33694082", "asset_id": "30442780799048074404860985387051749017905070253466005720364298335239299761065", "price": "0.009", "size": "11.72", "side": "BUY", "timestamp": "1768574209119", "received_at": "2026-01-16T14:36:49.158138"}}
{"event_type": "price_change", "event_ts": "2026-01-16T14:36:49.158138", "ingestion_ts": "2026-01-16T14:36:49.604167", "market_id": "0x49686d26fb712515cd5e12c23f0a1c7e10214c7faa3cb0a730aabe0c33694082", "raw": {"market": "0x49686d26fb712515cd5e12c23f0a1c7e10214c7faa3cb0a730aabe0c33694082", "asset_id": "13244681086321087932946246027856416106585284024824496763706748621681543444582", "price": "0.991", "size": "11.72", "side": "SELL", "timestamp": "1768574209119", "received_at": "2026-01-16T14:36:49.158138"}}
{"event_type": "price_change", "event_ts": "2026-01-16T14:36:49.159045", "ingestion_ts": "2026-01-16T14:36:49.604167", "market_id": "0x49686d26fb712515cd5e12c23f0a1c7e10214c7faa3cb0a730aabe0c33694082", "raw": {"market": "0x49686d26fb712515cd5e12c23f0a1c7e10214c7faa3cb0a730aabe0c33694082", "asset_id": "30442780799048074404860985387051749017905070253466005720364298335239299761065", "price": "0.004", "size": "13.91", "side": "BUY", "timestamp": "1768574209120", "received_at": "2026-01-16T14:36:49.159045"}}
{"event_type": "price_change", "event_ts": "2026-01-16T14:36:49.159045", "ingestion_ts": "2026-01-16T14:36:49.604167", "market_id": "0x49686d26fb712515cd5e12c23f0a1c7e10214c7faa3cb0a730aabe0c33694082", "raw": {"market": "0x49686d26fb712515cd5e12c23f0a1c7e10214c7faa3cb0a730aabe0c33694082", "asset_id": "13244681086321087932946246027856416106585284024824496763706748621681543444582", "price": "0.996", "size": "13.91", "side": "SELL", "timestamp": "1768574209120", "received_at": "2026-01-16T14:36:49.159045"}}
{"event_type": "price_change", "event_ts": "2026-01-16T14:36:49.571136", "ingestion_ts": "2026-01-16T14:36:49.604167", "market_id": "0xc0e6b917320a47228fb96e3b5ae0e5c93773a5ae2662ae4e1f37807cfe47ce98", "raw": {"market": "0xc0e6b917320a47228fb96e3b5ae0e5c93773a5ae2662ae4e1f37807cfe47ce98", "asset_id": "58656358377246279051017109359677190749228949103591068167284263961542487110215", "price": "0.004", "size": "130.06", "side": "BUY", "timestamp": "1768574209534", "received_at": "2026-01-16T14:36:49.571136"}}
{"event_type": "price_change", "event_ts": "2026-01-16T14:36:49.571136", "ingestion_ts": "2026-01-16T14:36:49.604167", "market_id": "0xc0e6b917320a47228fb96e3b5ae0e5c93773a5ae2662ae4e1f37807cfe47ce98", "raw": {"market": "0xc0e6b917320a47228fb96e3b5ae0e5c93773a5ae2662ae4e1f37807cfe47ce98", "asset_id": "81647294538046680798858716589766492074338758116170717123345952330712416337530", "price": "0.996", "size": "130.06", "side": "SELL", "timestamp": "1768574209534", "received_at": "2026-01-16T14:36:49.571136"}}
{"event_type": "new_market", "event_ts": "2026-01-16T14:36:14.833480", "ingestion_ts": "2026-01-16T14:36:49.604167", "market_id": "1198405", "raw": {"id": "1198405", "question": "Game Handicap: IC (-1.5) vs Power Rangers (+1.5)", "market": "0xd000edbaa96f174a0c0a7ea0cb4434b8a4fcd21fb76ab3d44c25f2f39d53e0ee", "slug": "dota2-pr1-ic-2026-01-16-game-handicap-home-1pt5", "description": "This market refers to the Dota 2 match between Power Rangers and Inner Circle in the ESL One Birmingham: Eastern Europe Closed Qualifier Playoffs, scheduled for January 16 at 9:00AM ET.\n\nThis market will resolve to \"Inner Circle\" if Inner Circle wins 2 or more games than Power Rangers in this match.\n\nOtherwise, this market will resolve to \"Power Rangers\".\n\nIf the match is canceled (not played at all), ends in a tie, or is delayed beyond 7 days from the scheduled date without a winner determined, this market will resolve to 50-50. \n\nIf the match begins but is not completed, and one team wins due to the opponent's forfeiture, disqualification, or walkover, this market will resolve to 50-50. \n\nIf the match ends in a forfeit, disqualification, or walkover (team withdraws before the start and the other wins automatically), this market will resolve to 50-50.", "assets_ids": ["73985368307547376027585254119083628214748326959711670087573813960776441826768", "53807275948052332613807513170387873949459891570425899564732667468286148029472"], "outcomes": ["Inner Circle", "Power Rangers"], "timestamp": "1768574174794", "received_at": "2026-01-16T14:36:14.833480"}}
{"event_type": "new_market", "event_ts": "2026-01-16T14:36:15.085825", "ingestion_ts": "2026-01-16T14:36:49.604167", "market_id": "1198406", "raw": {"id": "1198406", "question": "Game Handicap: LGD (-1.5) vs Wolves (+1.5)", "market": "0x2b15d6d1106a98969f3d04e3b42e35d4984287a77eebe48fcd90619de4b1a020", "slug": "hok-lgd-wol-2026-01-16-game-handicap-away-1pt5", "description": "This market refers to the Honor of Kings match between LGD NBW and Wolves in the King Pro League Stage 1 Group 2, scheduled for January 16 at 7:00AM ET.\n\nThis market will resolve to \"LGD NBW\" if LGD NBW wins 2 or more games than Wolves in this match.\n\nOtherwise, this market will resolve to \"Wolves\".\n\nIf the match is canceled (not played at all), ends in a tie, or is delayed beyond 7 days from the scheduled date without a winner determined, this market will resolve to 50-50. \n\nIf the match begins but is not completed, and one team wins due to the opponent's forfeiture, disqualification, or walkover, this market will resolve to 50-50. \n\nIf the match ends in a forfeit, disqualification, or walkover (team withdraws before the start and the other wins automatically), this market will resolve to 50-50.", "assets_ids": ["83888850197146292892613156594067631165103543331866613552549420000822561447489", "83122918624928720738816112233532388034549994564387152785876855637059481882478"], "outcomes": ["LGD NBW", "Wolves"], "timestamp": "1768574175049", "received_at": "2026-01-16T14:36:15.085825"}}
