{"event_type": "price_change", "event_ts": "2026-01-16T14:29:40.956064", "ingestion_ts": "2026-01-16T14:30:40.976502", "market_id": "0xaf9d0e448129a9f657f851d49495ba4742055d80e0ef1166ba0ee81d4d594214", "raw": {"market": "0xaf9d0e448129a9f657f851d49495ba4742055d80e0ef1166ba0ee81d4d594214", "asset_id": "4153292802911610701832309484716814274802943278345248636922528170020319407796", "price": "0.983", "size": "0", "side": "SELL", "timestamp": "1768573780916", "received_at": "2026-01-16T14:29:40.956064"}}
{"event_type": "price_change", "event_ts": "2026-01-16T14:29:40.956064", "ingestion_ts": "2026-01-16T14:30:40.976502", "market_id": "0xaf9d0e448129a9f657f851d49495ba4742055d80e0ef1166ba0ee81d4d594214", "raw": {"market": "0xaf9d0e448129a9f657f851d49495ba4742055d80e0ef1166ba0ee81d4d594214", "asset_id": "101676997363687199724245607342877036148401850938023978421879460310389391082353", "price": "0.017", "size": "0", "side": "BUY", "timestamp": "1768573780916", "received_at": "2026-01-16T14:29:40.956064"}}
{"event_type": "price_change", "event_ts": "2026-01-16T14:29:41.160338", "ingestion_ts": "2026-01-16T14:30:40.976502", "market_id": "0x2393ed0b0fdc450054c7b9071907eca75cf4fc36e385adf4a0a5f99ee62243e8", "raw": {"market": "0x2393ed0b0fdc450054c7b9071907eca75cf4fc36e385adf4a0a5f99ee62243e8", "asset_id": "32769749367306925959219403371425714180265458150646381231272229429098460625924", "price": "0.948", "size": "50", "side": "BUY", "timestamp": "1768573781123", "received_at": "2026-01-16T14:29:41.160338"}}
{"event_type": "price_change", "event_ts": "2026-01-16T14:29:41.160338", "ingestion_ts": "2026-01-16T14:30:40.976502", "market_id": "0x2393ed0b0fdc450054c7b9071907eca75cf4fc36e385adf4a0a5f99ee62243e8", "raw": {"market": "0x2393ed0b0fdc450054c7b9071907eca75cf4fc36e385adf4a0a5f99ee62243e8", "asset_id": "100074770378634056601572485653252702850363676459996771990439989989293515601975", "price": "0.052", "size": "50", "side": "SELL", "timestamp": "1768573781123", "received_at": "2026-01-16T14:29:41.160338"}}
{"event_type": "price_change", "event_ts": "2026-01-16T14:29:41.196418", "ingestion_ts": "2026-01-16T14:30:40.976502", "market_id": "0x2393ed0b0fdc450054c7b9071907eca75cf4fc36e385adf4a0a5f99ee62243e8", "raw": {"market": "0x2393ed0b0fdc450054c7b9071907eca75cf4fc36e385adf4a0a5f99ee62243e8", "asset_id": "100074770378634056601572485653252702850363676459996771990439989989293515601975", "price": "0.053", "size": "0", "side": "SELL", "timestamp": "1768573781151", "received_at": "2026-01-16T14:29:41.196418"}}
{"event_type": "price_change", "event_ts": "2026-01-16T14:29:41.196418", "ingestion_ts": "2026-01-16T14:30:40.976502", "market_id": "0x2393ed0b0fdc450054c7b9071907eca75cf4fc36e385adf4a0a5f99ee62243e8", "raw": {"market": "0x2393ed0b0fdc450054c7b9071907eca75cf4fc36e385adf4a0a5f99ee62243e8", "asset_id": "32769749367306925959219403371425714180265458150646381231272229429098460625924", "price": "0.947", "size": "0", "side": "BUY", "timestamp": "1768573781151", "received_at": "2026-01-16T14:29:41.196418"}}
{"event_type": "price_change", "event_ts": "2026-01-16T14:29:41.215605", "ingestion_ts": "2026-01-16T14:30:40.976502", "market_id": "0x2393ed0b0fdc450054c7b9071907eca75cf4fc36e385adf4a0a5f99ee62243e8", "raw": {"market": "0x2393ed0b0fdc450054c7b9071907eca75cf4fc36e385adf4a0a5f99ee62243e8", "asset_id": "100074770378634056601572485653252702850363676459996771990439989989293515601975", "price": "0.051", "size": "196", "side": "SELL", "timestamp": "1768573781179", "received_at": "2026-01-16T14:29:41.215605"}}
{"event_type": "price_change", "event_ts": "2026-01-16T14:29:41.215605", "ingestion_ts": "2026-01-16T14:30:40.976502", "market_id": "0x2393ed0b0fdc450054c7b9071907eca75cf4fc36e385adf4a0a5f99ee62243e8", "raw": {"market": "0x2393ed0b0fdc450054c7b9071907eca75cf4fc36e385adf4a0a5f99ee62243e8", "asset_id": "32769749367306925959219403371425714180265458150646381231272229429098460625924", "price": "0.949", "size": "196", "side": "BUY", "timestamp": "1768573781179", "received_at": "2026-01-16T14:29:41.215605"}}
{"event_type": "price_change", "event_ts": "2026-01-16T14:29:41.240793", "ingestion_ts": "2026-01-16T14:30:40.976502", "market_id": "0xaf9d0e448129a9f657f851d49495ba4742055d80e0ef1166ba0ee81d4d594214", "raw": {"market": "0xaf9d0e448129a9f657f851d49495ba4742055d80e0ef1166ba0ee81d4d594214", "asset_id": "4153292802911610701832309484716814274802943278345248636922528170020319407796", "price": "0.981", "size": "140.01", "side": "SELL", "timestamp": "1768573781199", "received_at": "2026-01-16T14:29:41.240793"}}
{"event_type": "price_change", "event_ts": "2026-01-16T14:29:41.240793", "ingestion_ts": "2026-01-16T14:30:40.976502", "market_id": "0xaf9d0e448129a9f657f851d49495ba4742055d80e0ef1166ba0ee81d4d594214", "raw": {"market": "0xaf9d0e448129a9f657f851d49495ba4742055d80e0ef1166ba0ee81d4d594214", "asset_id": "101676997363687199724245607342877036148401850938023978421879460310389391082353", "price": "0.019", "size": "140.01", "side": "BUY", "timestamp": "1768573781199", "received_at": "2026-01-16T14:29:41.240793"}}
{"event_type": "price_change", "event_ts": "2026-01-16T14:29:41.521008", "ingestion_ts": "2026-01-16T14:30:40.976502", "market_id": "0x2393ed0b0fdc450054c7b9071907eca75cf4fc36e385adf4a0a5f99ee62243e8", "raw": {"market": "0x2393ed0b0fdc450054c7b9071907eca75cf4fc36e385adf4a0a5f99ee62243e8", "asset_id": "32769749367306925959219403371425714180265458150646381231272229429098460625924", "price": "0.946", "size": "0", "side": "BUY", "timestamp": "1768573781480", "received_at": "2026-01-16T14:29:41.521008"}}
{"event_type": "price_change", "event_ts": "2026-01-16T14:29:41.521008", "ingestion_ts": "2026-01-16T14:30:40.976502", "market_id": "0x2393ed0b0fdc450054c7b9071907eca75cf4fc36e385adf4a0a5f99ee62243e8", "raw": {"market": "0x2393ed0b0fdc450054c7b9071907eca75cf4fc36e385adf4a0a5f99ee62243e8", "asset_id": "100074770378634056601572485653252702850363676459996771990439989989293515601975", "price": "0.054", "size": "0", "side": "SELL", "timestamp": "1768573781480", "received_at": "2026-01-16T14:29:41.521008"}}
{"event_type": "price_change", "event_ts": "2026-01-16T14:29:41.821263", "ingestion_ts": "2026-01-16T14:30:40.976502", "market_id": "0x49686d26fb712515cd5e12c23f0a1c7e10214c7faa3cb0a730aabe0c33694082", "raw": {"market": "0x49686d26fb712515cd5e12c23f0a1c7e10214c7faa3cb0a730aabe0c33694082", "asset_id": "30442780799048074404860985387051749017905070253466005720364298335239299761065", "price": "0.002", "size": "662.74", "side": "BUY", "timestamp": "1768573781781", "received_at": "2026-01-16T14:29:41.821263"}}
{"event_type": "price_change", "event_ts": "2026-01-16T14:29:41.821263", "ingestion_ts": "2026-01-16T14:30:40.976502", "market_id": "0x49686d26fb712515cd5e12c23f0a1c7e10214c7faa3cb0a730aabe0c33694082", "raw": {"market": "0x49686d26fb712515cd5e12c23f0a1c7e10214c7faa3cb0a730aabe0c33694082", "asset_id": "13244681086321087932946246027856416106585284024824496763706748621681543444582", "price": "0.998", "size": "662.74", "side": "SELL", "timestamp": "1768573781781", "received_at": "2026-01-16T14:29:41.821263"}}
{"event_type": "price_change", "event_ts": "2026-01-16T14:29:41.856145", "ingestion_ts": "2026-01-16T14:30:40.976502", "market_id": "0x49686d26fb712515cd5e12c23f0a1c7e10214c7faa3cb0a730aabe0c33694082", "raw": {"market": "0x49686d26fb712515cd5e12c23f0a1c7e10214c7faa3cb0a730aabe0c33694082", "asset_id": "30442780799048074404860985387051749017905070253466005720364298335239299761065", "price": "0.003", "size": "36.81", "side": "BUY", "timestamp": "1768573781819", "received_at": "2026-01-16T14:29:41.856145"}}
{"event_type": "price_change", "event_ts": "2026-01-16T14:29:41.856145", "ingestion_ts": "2026-01-16T14:30:40.976502", "market_id": "0x49686d26fb712515cd5e12c23f0a1c7e10214c7faa3cb0a730aabe0c33694082", "raw": {"market": "0x49686d26fb712515cd5e12c23f0a1c7e10214c7faa3cb0a730aabe0c33694082", "asset_id": "13244681086321087932946246027856416106585284024824496763706748621681543444582", "price": "0.997", "size": "36.81", "side": "SELL", "timestamp": "1768573781819", "received_at": "2026-01-16T14:29:41.856145"}}
{"event_type": "price_change", "event_ts": "2026-01-16T14:29:43.288985", "ingestion_ts": "2026-01-16T14:30:40.976502", "market_id": "0xaf9d0e448129a9f657f851d49495ba4742055d80e0ef1166ba0ee81d4d594214", "raw": {"market": "0xaf9d0e448129a9f657f851d49495ba4742055d80e0ef1166ba0ee81d4d594214", "asset_id": "4153292802911610701832309484716814274802943278345248636922528170020319407796", "price": "0.982", "size": "0", "side": "SELL", "timestamp": "1768573783251", "received_at": "2026-01-16T14:29:43.288985"}}
{"event_type": "price_change", "event_ts": "2026-01-16T14:29:43.288985", "ingestion_ts": "2026-01-16T14:30:40.976502", "market_id": "0xaf9d0e448129a9f657f851d49495ba4742055d80e0ef1166ba0ee81d4d594214", "raw": {"market": "0xaf9d0e448129a9f657f851d49495ba4742055d80e0ef1166ba0ee81d4d594214", "asset_id": "101676997363687199724245607342877036148401850938023978421879460310389391082353", "price": "0.018", "size": "0", "side": "BUY", "timestamp": "1768573783251", "received_at": "2026-01-16T14:29:43.288985"}}
{"event_type": "price_change", "event_ts": "2026-01-16T14:29:43.337430", "ingestion_ts": "2026-01-16T14:30:40.976502", "market_id": "0xaf9d0e448129a9f657f851d49495ba4742055d80e0ef1166ba0ee81d4d594214", "raw": {"market": "0xaf9d0e448129a9f657f851d49495ba4742055d80e0ef1166ba0ee81d4d594214", "asset_id": "4153292802911610701832309484716814274802943278345248636922528170020319407796", "price": "0.98", "size": "20.5", "side": "SELL", "timestamp": "1768573783298", "received_at": "2026-01-16T14:29:43.337430"}}
{"event_type": "price_change", "event_ts": "2026-01-16T14:29:43.337430", "ingestion_ts": "2026-01-16T14:30:40.976502", "market_id": "0xaf9d0e448129a9f657f851d49495ba4742055d80e0ef1166ba0ee81d4d594214", "raw": {"market": "0xaf9d0e448129a9f657f851d49495ba4742055d80e0ef1166ba0ee81d4d594214", "asset_id": "101676997363687199724245607342877036148401850938023978421879460310389391082353", "price": "0.02", "size": "20.5", "side": "BUY", "timestamp": "1768573783298", "received_at": "2026-01-16T14:29:43.337430"}}
{"event_type": "price_change", "event_ts": "2026-01-16T14:29:44.081244", "ingestion_ts": "2026-01-16T14:30:40.976502", "market_id": "0xc0e6b917320a47228fb96e3b5ae0e5c93773a5ae2662ae4e1f37807cfe47ce98", "raw": {"market": "0xc0e6b917320a47228fb96e3b5ae0e5c93773a5ae2662ae4e1f37807cfe47ce98", "asset_id": "58656358377246279051017109359677190749228949103591068167284263961542487110215", "price": "0.074", "size": "44.64", "side": "SELL", "timestamp": "1768573784042", "received_at": "2026-01-16T14:29:44.081244"}}
{"event_type": "price_change", "event_ts": "2026-01-16T14:29:44.081244", "ingestion_ts": "2026-01-16T14:30:40.976502", "market_id": "0xc0e6b917320a47228fb96e3b5ae0e5c93773a5ae2662ae4e1f37807cfe47ce98", "raw": {"market": "0xc0e6b917320a47228fb96e3b5ae0e5c93773a5ae2662ae4e1f37807cfe47ce98", "asset_id": "81647294538046680798858716589766492074338758116170717123345952330712416337530", "price": "0.926", "size": "44.64", "side": "BUY", "timestamp": "1768573784042", "received_at": "2026-01-16T14:29:44.081244"}}
{"event_type": "price_change", "event_ts": "2026-01-16T14:29:44.325842", "ingestion_ts": "2026-01-16T14:30:40.976502", "market_id": "0xc0e6b917320a47228fb96e3b5ae0e5c93773a5ae2662ae4e1f37807cfe47ce98", "raw": {"market": "0xc0e6b917320a47228fb96e3b5ae0e5c93773a5ae2662ae4e1f37807cfe47ce98", "asset_id": "58656358377246279051017109359677190749228949103591068167284263961542487110215", "price": "0.073", "size": "24.08", "side": "SELL", "timestamp": "1768573784286", "received_at": "2026-01-16T14:29:44.325842"}}
{"event_type": "price_change", "event_ts": "2026-01-16T14:29:44.325842", "ingestion_ts": "2026-01-16T14:30:40.976502", "market_id": "0xc0e6b917320a47228fb96e3b5ae0e5c93773a5ae2662ae4e1f37807cfe47ce98", "raw": {"market": "0xc0e6b917320a47228fb96e3b5ae0e5c93773a5ae2662ae4e1f37807cfe47ce98", "asset_id": "81647294538046680798858716589766492074338758116170717123345952330712416337530", "price": "0.927", "size": "24.08", "side": "BUY", "timestamp": "1768573784286", "received_at": "2026-01-16T14:29:44.325842"}}
{"event_type": "price_change", "event_ts": "2026-01-16T14:29:44.325886", "ingestion_ts": "2026-01-16T14:30:40.976502", "market_id": "0xc0e6b917320a47228fb96e3b5ae0e5c93773a5ae2662ae4e1f37807cfe47ce98", "raw": {"market": "0xc0e6b917320a47228fb96e3b5ae0e5c93773a5ae2662ae4e1f37807cfe47ce98", "asset_id": "58656358377246279051017109359677190749228949103591068167284263961542487110215", "price": "0.073", "size": "43.16", "side": "SELL", "timestamp": "1768573784287", "received_at": "2026-01-16T14:29:44.325886"}}
{"event_type": "price_change", "event_ts": "2026-01-16T14:29:44.325886", "ingestion_ts": "2026-01-16T14:30:40.976502", "market_id": "0xc0e6b917320a47228fb96e3b5ae0e5c93773a5ae2662ae4e1f37807cfe47ce98", "raw": {"market": "0xc0e6b917320a47228fb96e3b5ae0e5c93773a5ae2662ae4e1f37807cfe47ce98", "asset_id": "81647294538046680798858716589766492074338758116170717123345952330712416337530", "price": "0.927", "size": "43.16", "side": "BUY", "timestamp": "1768573784287", "received_at": "2026-01-16T14:29:44.325886"}}
{"event_type": "price_change", "event_ts": "2026-01-16T14:29:44.331747", "ingestion_ts": "2026-01-16T14:30:40.976502", "market_id": "0x49686d26fb712515cd5e12c23f0a1c7e10214c7faa3cb0a730aabe0c33694082", "raw": {"market": "0x49686d26fb712515cd5e12c23f0a1c7e10214c7faa3cb0a730aabe0c33694082", "asset_id": "30442780799048074404860985387051749017905070253466005720364298335239299761065", "price": "0.003", "size": "26.81", "side": "BUY", "timestamp": "1768573784295", "received_at": "2026-01-16T14:29:44.331747"}}
{"event_type": "price_change", "event_ts": "2026-01-16T14:29:44.331747", "ingestion_ts": "2026-01-16T14:30:40.976502", "market_id": "0x49686d26fb712515cd5e12c23f0a1c7e10214c7faa3cb0a730aabe0c33694082", "raw": {"market": "0x49686d26fb712515cd5e12c23f0a1c7e10214c7faa3cb0a730aabe0c33694082", "asset_id": "13244681086321087932946246027856416106585284024824496763706748621681543444582", "price": "0.997", "size": "26.81", "side": "SELL", "timestamp": "1768573784295", "received_at": "2026-01-16T14:29:44.331747"}}
{"event_type": "price_change", "event_ts": "2026-01-16T14:29:44.332135", "ingestion_ts": "2026-01-16T14:30:40.976502", "market_id": "0xc55db914f0fd1fee18997706712c0dfd8d0369cdbef93a9fef12bd001914ca77", "raw": {"market": "0xc55db914f0fd1fee18997706712c0dfd8d0369cdbef93a9fef12bd001914ca77", "asset_id": "114600293444080540179603459515770723592661967180480327891296353898330242622833", "price": "0.855", "size": "292", "side": "BUY", "timestamp": "1768573784295", "received_at": "2026-01-16T14:29:44.332135"}}
{"event_type": "price_change", "event_ts": "2026-01-16T14:29:44.332135", "ingestion_ts": "2026-01-16T14:30:40.976502", "market_id": "0xc55db914f0fd1fee18997706712c0dfd8d0369cdbef93a9fef12bd001914ca77", "raw": {"market": "0xc55db914f0fd1fee18997706712c0dfd8d0369cdbef93a9fef12bd001914ca77", "asset_id": "72354723612769247426741660426331235762851940382312402276325808095604519806766", "price": "0.145", "size": "292", "side": "SELL", "timestamp": "1768573784295", "received_at": "2026-01-16T14:29:44.332135"}}
{"event_type": "price_change", "event_ts": "2026-01-16T14:29:44.332168", "ingestion_ts": "2026-01-16T14:30:40.976502", "market_id": "0x9472be65457510b7fc3477b20ba90910e99d92eac8421a14bf4b7b7a08ef31dc", "raw": {"market": "0x9472be65457510b7fc3477b20ba90910e99d92eac8421a14bf4b7b7a08ef31dc", "asset_id": "43311793366960417907757893276427136943959788721376762326430771171648759300146", "price": "0.824", "size": "0", "side": "BUY", "timestamp": "1768573784295", "received_at": "2026-01-16T14:29:44.332168"}}
{"event_type": "price_change", "event_ts": "2026-01-16T14:29:44.332168", "ingestion_ts": "2026-01-16T14:30:40.976502", "market_id": "0x9472be65457510b7fc3477b20ba90910e99d92eac8421a14bf4b7b7a08ef31dc", "raw": {"market": "0x9472be65457510b7fc3477b20ba90910e99d92eac8421a14bf4b7b7a08ef31dc", "asset_id": "73414222381656326204771753454630063673548497164758947581648273905027617570612", "price": "0.176", "size": "0", "side": "SELL", "timestamp": "1768573784295", "received_at": "2026-01-16T14:29:44.332168"}}
{"event_type": "price_change", "event_ts": "2026-01-16T14:29:44.332801", "ingestion_ts": "2026-01-16T14:30:40.976502", "market_id": "0x49a20c7523c271099008f3ef9a31521263b24d637959852a391e6b4697b1a437", "raw": {"market": "0x49a20c7523c271099008f3ef9a31521263b24d637959852a391e6b4697b1a437", "asset_id": "55881023621710858558280545117465775643848233756850602339827152783696837905531", "price": "0.847", "size": "0", "side": "BUY", "timestamp": "1768573784295", "received_at": "2026-01-16T14:29:44.332801"}}
{"event_type": "price_change", "event_ts": "2026-01-16T14:29:44.332801", "ingestion_ts": "2026-01-16T14:30:40.976502", "market_id": "0x49a20c7523c271099008f3ef9a31521263b24d637959852a391e6b4697b1a437", "raw": {"market": "0x49a20c7523c271099008f3ef9a31521263b24d637959852a391e6b4697b1a437", "asset_id": "13018971792603393862521629014128024641178044618205296260525674415067194037856", "price": "0.153", "size": "0", "side": "SELL", "timestamp": "1768573784295", "received_at": "2026-01-16T14:29:44.332801"}}
{"event_type": "price_change", "event_ts": "2026-01-16T14:29:44.333554", "ingestion_ts": "2026-01-16T14:30:40.976502", "market_id": "0x50c669f178da4e5bbea7f1be25041fd278914712fa87a6a6f8e57d5923d88dee", "raw": {"market": "0x50c669f178da4e5bbea7f1be25041fd278914712fa87a6a6f8e57d5923d88dee", "asset_id": "74040420326294854165772767082819937451857852955603897473157746262672057685461", "price": "0.824", "size": "0", "side": "BUY", "timestamp": "1768573784295", "received_at": "2026-01-16T14:29:44.333554"}}
{"event_type": "price_change", "event_ts": "2026-01-16T14:29:44.333554", "ingestion_ts": "2026-01-16T14:30:40.976502", "market_id": "0x50c669f178da4e5bbea7f1be25041fd278914712fa87a6a6f8e57d5923d88dee", "raw": {"market": "0x50c669f178da4e5bbea7f1be25041fd278914712fa87a6a6f8e57d5923d88dee", "asset_id": "24682525479474221428144937281315825971983904267399062415430320764754931667953", "price": "0.176", "size": "0", "side": "SELL", "timestamp": "1768573784295", "received_at": "2026-01-16T14:29:44.333554"}}
{"event_type": "price_change", "event_ts": "2026-01-16T14:29:44.334533", "ingestion_ts": "2026-01-16T14:30:40.976502", "market_id": "0x44f08744458b8896620cd3330bc5e1ea69df4199b02d4fc583b3fc96e5d314ce", "raw": {"market": "0x44f08744458b8896620cd3330bc5e1ea69df4199b02d4fc583b3fc96e5d314ce", "asset_id": "72327831507226612545928776794104143393438710920370371172884559893525100761096", "price": "0.851", "size": "293", "side": "BUY", "timestamp": "1768573784295", "received_at": "2026-01-16T14:29:44.334533"}}
{"event_type": "price_change", "event_ts": "2026-01-16T14:29:44.334533", "ingestion_ts": "2026-01-16T14:30:40.976502", "market_id": "0x44f08744458b8896620cd3330bc5e1ea69df4199b02d4fc583b3fc96e5d314ce", "raw": {"market": "0x44f08744458b8896620cd3330bc5e1ea69df4199b02d4fc583b3fc96e5d314ce", "asset_id": "49194009556504828848509244326501559253829462790583873936160989575507522044057", "price": "0.149", "size": "293", "side": "SELL", "timestamp": "1768573784295", "received_at": "2026-01-16T14:29:44.334533"}}
{"event_type": "price_change", "event_ts": "2026-01-16T14:29:44.372507", "ingestion_ts": "2026-01-16T14:30:40.976502", "market_id": "0xc55db914f0fd1fee18997706712c0dfd8d0369cdbef93a9fef12bd001914ca77", "raw": {"market": "0xc55db914f0fd1fee18997706712c0dfd8d0369cdbef93a9fef12bd001914ca77", "asset_id": "114600293444080540179603459515770723592661967180480327891296353898330242622833", "price": "0.856", "size": "10", "side": "BUY", "timestamp": "1768573784333", "received_at": "2026-01-16T14:29:44.372507"}}
{"event_type": "price_change", "event_ts": "2026-01-16T14:29:44.372507", "ingestion_ts": "2026-01-16T14:30:40.976502", "market_id": "0xc55db914f0fd1fee18997706712c0dfd8d0369cdbef93a9fef12bd001914ca77", "raw": {"market": "0xc55db914f0fd1fee18997706712c0dfd8d0369cdbef93a9fef12bd001914ca77", "asset_id": "72354723612769247426741660426331235762851940382312402276325808095604519806766", "price": "0.144", "size": "10", "side": "SELL", "timestamp": "1768573784333", "received_at": "2026-01-16T14:29:44.372507"}}
{"event_type": "price_change", "event_ts": "2026-01-16T14:29:44.372554", "ingestion_ts": "2026-01-16T14:30:40.976502", "market_id": "0x49686d26fb712515cd5e12c23f0a1c7e10214c7faa3cb0a730aabe0c33694082", "raw": {"market": "0x49686d26fb712515cd5e12c23f0a1c7e10214c7faa3cb0a730aabe0c33694082", "asset_id": "30442780799048074404860985387051749017905070253466005720364298335239299761065", "price": "0.004", "size": "10", "side": "BUY", "timestamp": "1768573784333", "received_at": "2026-01-16T14:29:44.372554"}}
{"event_type": "price_change", "event_ts": "2026-01-16T14:29:44.372554", "ingestion_ts": "2026-01-16T14:30:40.976502", "market_id": "0x49686d26fb712515cd5e12c23f0a1c7e10214c7faa3cb0a730aabe0c33694082", "raw": {"market": "0x49686d26fb712515cd5e12c23f0a1c7e10214c7faa3cb0a730aabe0c33694082", "asset_id": "13244681086321087932946246027856416106585284024824496763706748621681543444582", "price": "0.996", "size": "10", "side": "SELL", "timestamp": "1768573784333", "received_at": "2026-01-16T14:29:44.372554"}}
{"event_type": "price_change", "event_ts": "2026-01-16T14:29:44.372580", "ingestion_ts": "2026-01-16T14:30:40.976502", "market_id": "0x9472be65457510b7fc3477b20ba90910e99d92eac8421a14bf4b7b7a08ef31dc", "raw": {"market": "0x9472be65457510b7fc3477b20ba90910e99d92eac8421a14bf4b7b7a08ef31dc", "asset_id": "43311793366960417907757893276427136943959788721376762326430771171648759300146", "price": "0.855", "size": "302", "side": "BUY", "timestamp": "1768573784333", "received_at": "2026-01-16T14:29:44.372580"}}
{"event_type": "price_change", "event_ts": "2026-01-16T14:29:44.372580", "ingestion_ts": "2026-01-16T14:30:40.976502", "market_id": "0x9472be65457510b7fc3477b20ba90910e99d92eac8421a14bf4b7b7a08ef31dc", "raw": {"market": "0x9472be65457510b7fc3477b20ba90910e99d92eac8421a14bf4b7b7a08ef31dc", "asset_id": "73414222381656326204771753454630063673548497164758947581648273905027617570612", "price": "0.145", "size": "302", "side": "SELL", "timestamp": "1768573784333", "received_at": "2026-01-16T14:29:44.372580"}}
{"event_type": "price_change", "event_ts": "2026-01-16T14:29:44.372593", "ingestion_ts": "2026-01-16T14:30:40.976502", "market_id": "0x44f08744458b8896620cd3330bc5e1ea69df4199b02d4fc583b3fc96e5d314ce", "raw": {"market": "0x44f08744458b8896620cd3330bc5e1ea69df4199b02d4fc583b3fc96e5d314ce", "asset_id": "72327831507226612545928776794104143393438710920370371172884559893525100761096", "price": "0.852", "size": "10", "side": "BUY", "timestamp": "1768573784333", "received_at": "2026-01-16T14:29:44.372593"}}
{"event_type": "price_change", "event_ts": "2026-01-16T14:29:44.372593", "ingestion_ts": "2026-01-16T14:30:40.976502", "market_id": "0x44f08744458b8896620cd3330bc5e1ea69df4199b02d4fc583b3fc96e5d314ce", "raw": {"market": "0x44f08744458b8896620cd3330bc5e1ea69df4199b02d4fc583b3fc96e5d314ce", "asset_id": "49194009556504828848509244326501559253829462790583873936160989575507522044057", "price": "0.148", "size": "10", "side": "SELL", "timestamp": "1768573784333", "received_at": "2026-01-16T14:29:44.372593"}}
{"event_type": "price_change", "event_ts": "2026-01-16T14:29:44.372605", "ingestion_ts": "2026-01-16T14:30:40.976502", "market_id": "0x49a20c7523c271099008f3ef9a31521263b24d637959852a391e6b4697b1a437", "raw": {"market": "0x49a20c7523c271099008f3ef9a31521263b24d637959852a391e6b4697b1a437", "asset_id": "55881023621710858558280545117465775643848233756850602339827152783696837905531", "price": "0.854", "size": "2068.31", "side": "BUY", "timestamp": "1768573784333", "received_at": "2026-01-16T14:29:44.372605"}}
{"event_type": "price_change", "event_ts": "2026-01-16T14:29:44.372605", "ingestion_ts": "2026-01-16T14:30:40.976502", "market_id": "0x49a20c7523c271099008f3ef9a31521263b24d637959852a391e6b4697b1a437", "raw": {"market": "0x49a20c7523c271099008f3ef9a31521263b24d637959852a391e6b4697b1a437", "asset_id": "13018971792603393862521629014128024641178044618205296260525674415067194037856", "price": "0.146", "size": "2068.31", "side": "SELL", "timestamp": "1768573784333", "received_at": "2026-01-16T14:29:44.372605"}}
{"event_type": "price_change", "event_ts": "2026-01-16T14:29:44.372616", "ingestion_ts": "2026-01-16T14:30:40.976502", "market_id": "0x50c669f178da4e5bbea7f1be25041fd278914712fa87a6a6f8e57d5923d88dee", "raw": {"market": "0x50c669f178da4e5bbea7f1be25041fd278914712fa87a6a6f8e57d5923d88dee", "asset_id": "74040420326294854165772767082819937451857852955603897473157746262672057685461", "price": "0.855", "size": "594", "side": "BUY", "timestamp": "1768573784333", "received_at": "2026-01-16T14:29:44.372616"}}
{"event_type": "price_change", "event_ts": "2026-01-16T14:29:44.372616", "ingestion_ts": "2026-01-16T14:30:40.976502", "market_id": "0x50c669f178da4e5bbea7f1be25041fd278914712fa87a6a6f8e57d5923d88dee", "raw": {"market": "0x50c669f178da4e5bbea7f1be25041fd278914712fa87a6a6f8e57d5923d88dee", "asset_id": "24682525479474221428144937281315825971983904267399062415430320764754931667953", "price": "0.145", "size": "594", "side": "SELL", "timestamp": "1768573784333", "received_at": "2026-01-16T14:29:44.372616"}}
{"event_type": "price_change", "event_ts": "2026-01-16T14:29:44.709236", "ingestion_ts": "2026-01-16T14:30:40.976502", "market_id": "0xc0e6b917320a47228fb96e3b5ae0e5c93773a5ae2662ae4e1f37807cfe47ce98", "raw": {"market": "0xc0e6b917320a47228fb96e3b5ae0e5c93773a5ae2662ae4e1f37807cfe47ce98", "asset_id": "81647294538046680798858716589766492074338758116170717123345952330712416337530", "price": "0.926", "size": "14.64", "side": "BUY", "timestamp": "1768573784665", "received_at": "2026-01-16T14:29:44.709236"}}
{"event_type": "price_change", "event_ts": "2026-01-16T14:29:44.709236", "ingestion_ts": "2026-01-16T14:30:40.976502", "market_id": "0xc0e6b917320a47228fb96e3b5ae0e5c93773a5ae2662ae4e1f37807cfe47ce98", "raw": {"market": "0xc0e6b917320a47228fb96e3b5ae0e5c93773a5ae2662ae4e1f37807cfe47ce98", "asset_id": "58656358377246279051017109359677190749228949103591068167284263961542487110215", "price": "0.074", "size": "14.64", "side": "SELL", "timestamp": "1768573784665", "received_at": "2026-01-16T14:29:44.709236"}}
{"event_type": "price_change", "event_ts": "2026-01-16T14:29:44.752081", "ingestion_ts": "2026-01-16T14:30:40.976502", "market_id": "0xc0e6b917320a47228fb96e3b5ae0e5c93773a5ae2662ae4e1f37807cfe47ce98", "raw": {"market": "0xc0e6b917320a47228fb96e3b5ae0e5c93773a5ae2662ae4e1f37807cfe47ce98", "asset_id": "81647294538046680798858716589766492074338758116170717123345952330712416337530", "price": "0.924", "size": "30", "side": "BUY", "timestamp": "1768573784715", "received_at": "2026-01-16T14:29:44.752081"}}
{"event_type": "price_change", "event_ts": "2026-01-16T14:29:44.752081", "ingestion_ts": "2026-01-16T14:30:40.976502", "market_id": "0xc0e6b917320a47228fb96e3b5ae0e5c93773a5ae2662ae4e1f37807cfe47ce98", "raw": {"market": "0xc0e6b917320a47228fb96e3b5ae0e5c93773a5ae2662ae4e1f37807cfe47ce98", "asset_id": "58656358377246279051017109359677190749228949103591068167284263961542487110215", "price": "0.076", "size": "30", "side": "SELL", "timestamp": "1768573784715", "received_at": "2026-01-16T14:29:44.752081"}}
{"event_type": "price_change", "event_ts": "2026-01-16T14:29:46.336777", "ingestion_ts": "2026-01-16T14:30:40.976502", "market_id": "0x49686d26fb712515cd5e12c23f0a1c7e10214c7faa3cb0a730aabe0c33694082", "raw": {"market": "0x49686d26fb712515cd5e12c23f0a1c7e10214c7faa3cb0a730aabe0c33694082", "asset_id": "13244681086321087932946246027856416106585284024824496763706748621681543444582", "price": "0.853", "size": "50.86", "side": "BUY", "timestamp": "1768573786295", "received_at": "2026-01-16T14:29:46.336777"}}
{"event_type": "price_change", "event_ts": "2026-01-16T14:29:46.336777", "ingestion_ts": "2026-01-16T14:30:40.976502", "market_id": "0x49686d26fb712515cd5e12c23f0a1c7e10214c7faa3cb0a730aabe0c33694082", "raw": {"market": "0x49686d26fb712515cd5e12c23f0a1c7e10214c7faa3cb0a730aabe0c33694082", "asset_id": "30442780799048074404860985387051749017905070253466005720364298335239299761065", "price": "0.147", "size": "50.86", "side": "SELL", "timestamp": "1768573786295", "received_at": "2026-01-16T14:29:46.336777"}}
{"event_type": "price_change", "event_ts": "2026-01-16T14:29:46.821708", "ingestion_ts": "2026-01-16T14:30:40.976502", "market_id": "0xaf9d0e448129a9f657f851d49495ba4742055d80e0ef1166ba0ee81d4d594214", "raw": {"market": "0xaf9d0e448129a9f657f851d49495ba4742055d80e0ef1166ba0ee81d4d594214", "asset_id": "4153292802911610701832309484716814274802943278345248636922528170020319407796", "price": "0.981", "size": "0", "side": "SELL", "timestamp": "1768573786785", "received_at": "2026-01-16T14:29:46.821708"}}
{"event_type": "price_change", "event_ts": "2026-01-16T14:29:46.821708", "ingestion_ts": "2026-01-16T14:30:40.976502", "market_id": "0xaf9d0e448129a9f657f851d49495ba4742055d80e0ef1166ba0ee81d4d594214", "raw": {"market": "0xaf9d0e448129a9f657f851d49495ba4742055d80e0ef1166ba0ee81d4d594214", "asset_id": "101676997363687199724245607342877036148401850938023978421879460310389391082353", "price": "0.019", "size": "0", "side": "BUY", "timestamp": "1768573786785", "received_at": "2026-01-16T14:29:46.821708"}}
{"event_type": "price_change", "event_ts": "2026-01-16T14:29:47.108819", "ingestion_ts": "2026-01-16T14:30:40.976502", "market_id": "0xc0e6b917320a47228fb96e3b5ae0e5c93773a5ae2662ae4e1f37807cfe47ce98", "raw": {"market": "0xc0e6b917320a47228fb96e3b5ae0e5c93773a5ae2662ae4e1f37807cfe47ce98", "asset_id": "58656358377246279051017109359677190749228949103591068167284263961542487110215", "price": "0.073", "size": "24.08", "side": "SELL", "timestamp": "1768573787071", "received_at": "2026-01-16T14:29:47.108819"}}
{"event_type": "price_change", "event_ts": "2026-01-16T14:29:47.108819", "ingestion_ts": "2026-01-16T14:30:40.976502", "market_id": "0xc0e6b917320a47228fb96e3b5ae0e5c93773a5ae2662ae4e1f37807cfe47ce98", "raw": {"market": "0xc0e6b917320a47228fb96e3b5ae0e5c93773a5ae2662ae4e1f37807cfe47ce98", "asset_id": "81647294538046680798858716589766492074338758116170717123345952330712416337530", "price": "0.927", "size": "24.08", "side": "BUY", "timestamp": "1768573787071", "received_at": "2026-01-16T14:29:47.108819"}}
{"event_type": "price_change", "event_ts": "2026-01-16T14:29:47.138631", "ingestion_ts": "2026-01-16T14:30:40.976502", "market_id": "0x2393ed0b0fdc450054c7b9071907eca75cf4fc36e385adf4a0a5f99ee62243e8", "raw": {"market": "0x2393ed0b0fdc450054c7b9071907eca75cf4fc36e385adf4a0a5f99ee62243e8", "asset_id": "32769749367306925959219403371425714180265458150646381231272229429098460625924", "price": "0.95", "size": "50", "side": "BUY", "timestamp": "1768573787100", "received_at": "2026-01-16T14:29:47.138631"}}
{"event_type": "price_change", "event_ts": "2026-01-16T14:29:47.138631", "ingestion_ts": "2026-01-16T14:30:40.976502", "market_id": "0x2393ed0b0fdc450054c7b9071907eca75cf4fc36e385adf4a0a5f99ee62243e8", "raw": {"market": "0x2393ed0b0fdc450054c7b9071907eca75cf4fc36e385adf4a0a5f99ee62243e8", "asset_id": "100074770378634056601572485653252702850363676459996771990439989989293515601975", "price": "0.05", "size": "50", "side": "SELL", "timestamp": "1768573787100", "received_at": "2026-01-16T14:29:47.138631"}}
{"event_type": "price_change", "event_ts": "2026-01-16T14:29:47.167957", "ingestion_ts": "2026-01-16T14:30:40.976502", "market_id": "0x2393ed0b0fdc450054c7b9071907eca75cf4fc36e385adf4a0a5f99ee62243e8", "raw": {"market": "0x2393ed0b0fdc450054c7b9071907eca75cf4fc36e385adf4a0a5f99ee62243e8", "asset_id": "100074770378634056601572485653252702850363676459996771990439989989293515601975", "price": "0.051", "size": "0", "side": "SELL", "timestamp": "1768573787127", "received_at": "2026-01-16T14:29:47.167957"}}
{"event_type": "price_change", "event_ts": "2026-01-16T14:29:47.167957", "ingestion_ts": "2026-01-16T14:30:40.976502", "market_id": "0x2393ed0b0fdc450054c7b9071907eca75cf4fc36e385adf4a0a5f99ee62243e8", "raw": {"market": "0x2393ed0b0fdc450054c7b9071907eca75cf4fc36e385adf4a0a5f99ee62243e8", "asset_id": "32769749367306925959219403371425714180265458150646381231272229429098460625924", "price": "0.949", "size": "0", "side": "BUY", "timestamp": "1768573787127", "received_at": "2026-01-16T14:29:47.167957"}}
{"event_type": "price_change", "event_ts": "2026-01-16T14:29:47.194614", "ingestion_ts": "2026-01-16T14:30:40.976502", "market_id": "0x2393ed0b0fdc450054c7b9071907eca75cf4fc36e385adf4a0a5f99ee62243e8", "raw": {"market": "0x2393ed0b0fdc450054c7b9071907eca75cf4fc36e385adf4a0a5f99ee62243e8", "asset_id": "100074770378634056601572485653252702850363676459996771990439989989293515601975", "price": "0.049", "size": "205", "side": "SELL", "timestamp": "1768573787158", "received_at": "2026-01-16T14:29:47.194614"}}
{"event_type": "price_change", "event_ts": "2026-01-16T14:29:47.194614", "ingestion_ts": "2026-01-16T14:30:40.976502", "market_id": "0x2393ed0b0fdc450054c7b9071907eca75cf4fc36e385adf4a0a5f99ee62243e8", "raw": {"market": "0x2393ed0b0fdc450054c7b9071907eca75cf4fc36e385adf4a0a5f99ee62243e8", "asset_id": "32769749367306925959219403371425714180265458150646381231272229429098460625924", "price": "0.951", "size": "205", "side": "BUY", "timestamp": "1768573787158", "received_at": "2026-01-16T14:29:47.194614"}}
{"event_type": "price_change", "event_ts": "2026-01-16T14:29:47.207141", "ingestion_ts": "2026-01-16T14:30:40.976502", "market_id": "0xaf9d0e448129a9f657f851d49495ba4742055d80e0ef1166ba0ee81d4d594214", "raw": {"market": "0xaf9d0e448129a9f657f851d49495ba4742055d80e0ef1166ba0ee81d4d594214", "asset_id": "4153292802911610701832309484716814274802943278345248636922528170020319407796", "price": "0.979", "size": "140.01", "side": "SELL", "timestamp": "1768573787170", "received_at": "2026-01-16T14:29:47.207141"}}
{"event_type": "price_change", "event_ts": "2026-01-16T14:29:47.207141", "ingestion_ts": "2026-01-16T14:30:40.976502", "market_id": "0xaf9d0e448129a9f657f851d49495ba4742055d80e0ef1166ba0ee81d4d594214", "raw": {"market": "0xaf9d0e448129a9f657f851d49495ba4742055d80e0ef1166ba0ee81d4d594214", "asset_id": "101676997363687199724245607342877036148401850938023978421879460310389391082353", "price": "0.021", "size": "140.01", "side": "BUY", "timestamp": "1768573787170", "received_at": "2026-01-16T14:29:47.207141"}}
{"event_type": "price_change", "event_ts": "2026-01-16T14:29:47.477665", "ingestion_ts": "2026-01-16T14:30:40.976502", "market_id": "0x2393ed0b0fdc450054c7b9071907eca75cf4fc36e385adf4a0a5f99ee62243e8", "raw": {"market": "0x2393ed0b0fdc450054c7b9071907eca75cf4fc36e385adf4a0a5f99ee62243e8", "asset_id": "32769749367306925959219403371425714180265458150646381231272229429098460625924", "price": "0.948", "size": "0", "side": "BUY", "timestamp": "1768573787436", "received_at": "2026-01-16T14:29:47.477665"}}
{"event_type": "price_change", "event_ts": "2026-01-16T14:29:47.477665", "ingestion_ts": "2026-01-16T14:30:40.976502", "market_id": "0x2393ed0b0fdc450054c7b9071907eca75cf4fc36e385adf4a0a5f99ee62243e8", "raw": {"market": "0x2393ed0b0fdc450054c7b9071907eca75cf4fc36e385adf4a0a5f99ee62243e8", "asset_id": "100074770378634056601572485653252702850363676459996771990439989989293515601975", "price": "0.052", "size": "0", "side": "SELL", "timestamp": "1768573787436", "received_at": "2026-01-16T14:29:47.477665"}}
{"event_type": "price_change", "event_ts": "2026-01-16T14:29:47.560401", "ingestion_ts": "2026-01-16T14:30:40.976502", "market_id": "0xc0e6b917320a47228fb96e3b5ae0e5c93773a5ae2662ae4e1f37807cfe47ce98", "raw": {"market": "0xc0e6b917320a47228fb96e3b5ae0e5c93773a5ae2662ae4e1f37807cfe47ce98", "asset_id": "58656358377246279051017109359677190749228949103591068167284263961542487110215", "price": "0.074", "size": "24.18", "side": "SELL", "timestamp": "1768573787519", "received_at": "2026-01-16T14:29:47.560401"}}
{"event_type": "price_change", "event_ts": "2026-01-16T14:29:47.560401", "ingestion_ts": "2026-01-16T14:30:40.976502", "market_id": "0xc0e6b917320a47228fb96e3b5ae0e5c93773a5ae2662ae4e1f37807cfe47ce98", "raw": {"market": "0xc0e6b917320a47228fb96e3b5ae0e5c93773a5ae2662ae4e1f37807cfe47ce98", "asset_id": "81647294538046680798858716589766492074338758116170717123345952330712416337530", "price": "0.926", "size": "24.18", "side": "BUY", "timestamp": "1768573787519", "received_at": "2026-01-16T14:29:47.560401"}}
{"event_type": "price_change", "event_ts": "2026-01-16T14:29:47.564405", "ingestion_ts": "2026-01-16T14:30:40.976502", "market_id": "0xc0e6b917320a47228fb96e3b5ae0e5c93773a5ae2662ae4e1f37807cfe47ce98", "raw": {"market": "0xc0e6b917320a47228fb96e3b5ae0e5c93773a5ae2662ae4e1f37807cfe47ce98", "asset_id": "58656358377246279051017109359677190749228949103591068167284263961542487110215", "price": "0.074", "size": "33.72", "side": "SELL", "timestamp": "1768573787520", "received_at": "2026-01-16T14:29:47.564405"}}
{"event_type": "price_change", "event_ts": "2026-01-16T14:29:47.564405", "ingestion_ts": "2026-01-16T14:30:40.976502", "market_id": "0xc0e6b917320a47228fb96e3b5ae0e5c93773a5ae2662ae4e1f37807cfe47ce98", "raw": {"market": "0xc0e6b917320a47228fb96e3b5ae0e5c93773a5ae2662ae4e1f37807cfe47ce98", "asset_id": "81647294538046680798858716589766492074338758116170717123345952330712416337530", "price": "0.926", "size": "33.72", "side": "BUY", "timestamp": "1768573787520", "received_at": "2026-01-16T14:29:47.564405"}}
{"event_type": "price_change", "event_ts": "2026-01-16T14:29:47.715871", "ingestion_ts": "2026-01-16T14:30:40.976502", "market_id": "0xaf9d0e448129a9f657f851d49495ba4742055d80e0ef1166ba0ee81d4d594214", "raw": {"market": "0xaf9d0e448129a9f657f851d49495ba4742055d80e0ef1166ba0ee81d4d594214", "asset_id": "4153292802911610701832309484716814274802943278345248636922528170020319407796", "price": "0.98", "size": "0", "side": "SELL", "timestamp": "1768573787677", "received_at": "2026-01-16T14:29:47.715871"}}
{"event_type": "price_change", "event_ts": "2026-01-16T14:29:47.715871", "ingestion_ts": "2026-01-16T14:30:40.976502", "market_id": "0xaf9d0e448129a9f657f851d49495ba4742055d80e0ef1166ba0ee81d4d594214", "raw": {"market": "0xaf9d0e448129a9f657f851d49495ba4742055d80e0ef1166ba0ee81d4d594214", "asset_id": "101676997363687199724245607342877036148401850938023978421879460310389391082353", "price": "0.02", "size": "0", "side": "BUY", "timestamp": "1768573787677", "received_at": "2026-01-16T14:29:47.715871"}}
{"event_type": "price_change", "event_ts": "2026-01-16T14:29:47.782356", "ingestion_ts": "2026-01-16T14:30:40.976502", "market_id": "0xaf9d0e448129a9f657f851d49495ba4742055d80e0ef1166ba0ee81d4d594214", "raw": {"market": "0xaf9d0e448129a9f657f851d49495ba4742055d80e0ef1166ba0ee81d4d594214", "asset_id": "4153292802911610701832309484716814274802943278345248636922528170020319407796", "price": "0.978", "size": "20.5", "side": "SELL", "timestamp": "1768573787724", "received_at": "2026-01-16T14:29:47.782356"}}
{"event_type": "price_change", "event_ts": "2026-01-16T14:29:47.782356", "ingestion_ts": "2026-01-16T14:30:40.976502", "market_id": "0xaf9d0e448129a9f657f851d49495ba4742055d80e0ef1166ba0ee81d4d594214", "raw": {"market": "0xaf9d0e448129a9f657f851d49495ba4742055d80e0ef1166ba0ee81d4d594214", "asset_id": "101676997363687199724245607342877036148401850938023978421879460310389391082353", "price": "0.022", "size": "20.5", "side": "BUY", "timestamp": "1768573787724", "received_at": "2026-01-16T14:29:47.782356"}}
{"event_type": "price_change", "event_ts": "2026-01-16T14:29:48.053139", "ingestion_ts": "2026-01-16T14:30:40.976502", "market_id": "0x49686d26fb712515cd5e12c23f0a1c7e10214c7faa3cb0a730aabe0c33694082", "raw": {"market": "0x49686d26fb712515cd5e12c23f0a1c7e10214c7faa3cb0a730aabe0c33694082", "asset_id": "30442780799048074404860985387051749017905070253466005720364298335239299761065", "price": "0.148", "size": "0", "side": "SELL", "timestamp": "1768573788003", "received_at": "2026-01-16T14:29:48.053139"}}
{"event_type": "price_change", "event_ts": "2026-01-16T14:29:48.053139", "ingestion_ts": "2026-01-16T14:30:40.976502", "market_id": "0x49686d26fb712515cd5e12c23f0a1c7e10214c7faa3cb0a730aabe0c33694082", "raw": {"market": "0x49686d26fb712515cd5e12c23f0a1c7e10214c7faa3cb0a730aabe0c33694082", "asset_id": "13244681086321087932946246027856416106585284024824496763706748621681543444582", "price": "0.852", "size": "0", "side": "BUY", "timestamp": "1768573788003", "received_at": "2026-01-16T14:29:48.053139"}}
{"event_type": "price_change", "event_ts": "2026-01-16T14:29:48.108690", "ingestion_ts": "2026-01-16T14:30:40.976502", "market_id": "0x49686d26fb712515cd5e12c23f0a1c7e10214c7faa3cb0a730aabe0c33694082", "raw": {"market": "0x49686d26fb712515cd5e12c23f0a1c7e10214c7faa3cb0a730aabe0c33694082", "asset_id": "30442780799048074404860985387051749017905070253466005720364298335239299761065", "price": "0.146", "size": "17.5", "side": "SELL", "timestamp": "1768573788057", "received_at": "2026-01-16T14:29:48.108690"}}
{"event_type": "price_change", "event_ts": "2026-01-16T14:29:48.108690", "ingestion_ts": "2026-01-16T14:30:40.976502", "market_id": "0x49686d26fb712515cd5e12c23f0a1c7e10214c7faa3cb0a730aabe0c33694082", "raw": {"market": "0x49686d26fb712515cd5e12c23f0a1c7e10214c7faa3cb0a730aabe0c33694082", "asset_id": "13244681086321087932946246027856416106585284024824496763706748621681543444582", "price": "0.854", "size": "17.5", "side": "BUY", "timestamp": "1768573788057", "received_at": "2026-01-16T14:29:48.108690"}}
{"event_type": "price_change", "event_ts": "2026-01-16T14:29:48.132790", "ingestion_ts": "2026-01-16T14:30:40.976502", "market_id": "0x49686d26fb712515cd5e12c23f0a1c7e10214c7faa3cb0a730aabe0c33694082", "raw": {"market": "0x49686d26fb712515cd5e12c23f0a1c7e10214c7faa3cb0a730aabe0c33694082", "asset_id": "13244681086321087932946246027856416106585284024824496763706748621681543444582", "price": "0.911", "size": "14.98", "side": "SELL", "timestamp": "1768573788091", "received_at": "2026-01-16T14:29:48.132790"}}
{"event_type": "price_change", "event_ts": "2026-01-16T14:29:48.132790", "ingestion_ts": "2026-01-16T14:30:40.976502", "market_id": "0x49686d26fb712515cd5e12c23f0a1c7e10214c7faa3cb0a730aabe0c33694082", "raw": {"market": "0x49686d26fb712515cd5e12c23f0a1c7e10214c7faa3cb0a730aabe0c33694082", "asset_id": "30442780799048074404860985387051749017905070253466005720364298335239299761065", "price": "0.089", "size": "14.98", "side": "BUY", "timestamp": "1768573788091", "received_at": "2026-01-16T14:29:48.132790"}}
{"event_type": "price_change", "event_ts": "2026-01-16T14:29:48.528729", "ingestion_ts": "2026-01-16T14:30:40.976502", "market_id": "0x50c669f178da4e5bbea7f1be25041fd278914712fa87a6a6f8e57d5923d88dee", "raw": {"market": "0x50c669f178da4e5bbea7f1be25041fd278914712fa87a6a6f8e57d5923d88dee", "asset_id": "74040420326294854165772767082819937451857852955603897473157746262672057685461", "price": "0.855", "size": "584", "side": "BUY", "timestamp": "1768573788490", "received_at": "2026-01-16T14:29:48.528729"}}
{"event_type": "price_change", "event_ts": "2026-01-16T14:29:48.528729", "ingestion_ts": "2026-01-16T14:30:40.976502", "market_id": "0x50c669f178da4e5bbea7f1be25041fd278914712fa87a6a6f8e57d5923d88dee", "raw": {"market": "0x50c669f178da4e5bbea7f1be25041fd278914712fa87a6a6f8e57d5923d88dee", "asset_id": "24682525479474221428144937281315825971983904267399062415430320764754931667953", "price": "0.145", "size": "584", "side": "SELL", "timestamp": "1768573788490", "received_at": "2026-01-16T14:29:48.528729"}}
{"event_type": "price_change", "event_ts": "2026-01-16T14:29:48.528768", "ingestion_ts": "2026-01-16T14:30:40.976502", "market_id": "0x49686d26fb712515cd5e12c23f0a1c7e10214c7faa3cb0a730aabe0c33694082", "raw": {"market": "0x49686d26fb712515cd5e12c23f0a1c7e10214c7faa3cb0a730aabe0c33694082", "asset_id": "30442780799048074404860985387051749017905070253466005720364298335239299761065", "price": "0.004", "size": "0", "side": "BUY", "timestamp": "1768573788490", "received_at": "2026-01-16T14:29:48.528768"}}
{"event_type": "price_change", "event_ts": "2026-01-16T14:29:48.528768", "ingestion_ts": "2026-01-16T14:30:40.976502", "market_id": "0x49686d26fb712515cd5e12c23f0a1c7e10214c7faa3cb0a730aabe0c33694082", "raw": {"market": "0x49686d26fb712515cd5e12c23f0a1c7e10214c7faa3cb0a730aabe0c33694082", "asset_id": "13244681086321087932946246027856416106585284024824496763706748621681543444582", "price": "0.996", "size": "0", "side": "SELL", "timestamp": "1768573788490", "received_at": "2026-01-16T14:29:48.528768"}}
{"event_type": "price_change", "event_ts": "2026-01-16T14:29:48.528783", "ingestion_ts": "2026-01-16T14:30:40.976502", "market_id": "0x9472be65457510b7fc3477b20ba90910e99d92eac8421a14bf4b7b7a08ef31dc", "raw": {"market": "0x9472be65457510b7fc3477b20ba90910e99d92eac8421a14bf4b7b7a08ef31dc", "asset_id": "43311793366960417907757893276427136943959788721376762326430771171648759300146", "price": "0.855", "size": "292", "side": "BUY", "timestamp": "1768573788490", "received_at": "2026-01-16T14:29:48.528783"}}
{"event_type": "price_change", "event_ts": "2026-01-16T14:29:48.528783", "ingestion_ts": "2026-01-16T14:30:40.976502", "market_id": "0x9472be65457510b7fc3477b20ba90910e99d92eac8421a14bf4b7b7a08ef31dc", "raw": {"market": "0x9472be65457510b7fc3477b20ba90910e99d92eac8421a14bf4b7b7a08ef31dc", "asset_id": "73414222381656326204771753454630063673548497164758947581648273905027617570612", "price": "0.145", "size": "292", "side": "SELL", "timestamp": "1768573788490", "received_at": "2026-01-16T14:29:48.528783"}}
{"event_type": "price_change", "event_ts": "2026-01-16T14:29:48.528795", "ingestion_ts": "2026-01-16T14:30:40.976502", "market_id": "0xc55db914f0fd1fee18997706712c0dfd8d0369cdbef93a9fef12bd001914ca77", "raw": {"market": "0xc55db914f0fd1fee18997706712c0dfd8d0369cdbef93a9fef12bd001914ca77", "asset_id": "114600293444080540179603459515770723592661967180480327891296353898330242622833", "price": "0.856", "size": "0", "side": "BUY", "timestamp": "1768573788490", "received_at": "2026-01-16T14:29:48.528795"}}
{"event_type": "price_change", "event_ts": "2026-01-16T14:29:48.528795", "ingestion_ts": "2026-01-16T14:30:40.976502", "market_id": "0xc55db914f0fd1fee18997706712c0dfd8d0369cdbef93a9fef12bd001914ca77", "raw": {"market": "0xc55db914f0fd1fee18997706712c0dfd8d0369cdbef93a9fef12bd001914ca77", "asset_id": "72354723612769247426741660426331235762851940382312402276325808095604519806766", "price": "0.144", "size": "0", "side": "SELL", "timestamp": "1768573788490", "received_at": "2026-01-16T14:29:48.528795"}}
{"event_type": "price_change", "event_ts": "2026-01-16T14:29:48.528807", "ingestion_ts": "2026-01-16T14:30:40.976502", "market_id": "0x49a20c7523c271099008f3ef9a31521263b24d637959852a391e6b4697b1a437", "raw": {"market": "0x49a20c7523c271099008f3ef9a31521263b24d637959852a391e6b4697b1a437", "asset_id": "55881023621710858558280545117465775643848233756850602339827152783696837905531", "price": "0.854", "size": "2058.31", "side": "BUY", "timestamp": "1768573788490", "received_at": "2026-01-16T14:29:48.528807"}}
{"event_type": "price_change", "event_ts": "2026-01-16T14:29:48.528807", "ingestion_ts": "2026-01-16T14:30:40.976502", "market_id": "0x49a20c7523c271099008f3ef9a31521263b24d637959852a391e6b4697b1a437", "raw": {"market": "0x49a20c7523c271099008f3ef9a31521263b24d637959852a391e6b4697b1a437", "asset_id": "13018971792603393862521629014128024641178044618205296260525674415067194037856", "price": "0.146", "size": "2058.31", "side": "SELL", "timestamp": "1768573788490", "received_at": "2026-01-16T14:29:48.528807"}}
{"event_type": "price_change", "event_ts": "2026-01-16T14:29:48.528818", "ingestion_ts": "2026-01-16T14:30:40.976502", "market_id": "0x44f08744458b8896620cd3330bc5e1ea69df4199b02d4fc583b3fc96e5d314ce", "raw": {"market": "0x44f08744458b8896620cd3330bc5e1ea69df4199b02d4fc583b3fc96e5d314ce", "asset_id": "72327831507226612545928776794104143393438710920370371172884559893525100761096", "price": "0.852", "size": "0", "side": "BUY", "timestamp": "1768573788490", "received_at": "2026-01-16T14:29:48.528818"}}
{"event_type": "price_change", "event_ts": "2026-01-16T14:29:48.528818", "ingestion_ts": "2026-01-16T14:30:40.976502", "market_id": "0x44f08744458b8896620cd3330bc5e1ea69df4199b02d4fc583b3fc96e5d314ce", "raw": {"market": "0x44f08744458b8896620cd3330bc5e1ea69df4199b02d4fc583b3fc96e5d314ce", "asset_id": "49194009556504828848509244326501559253829462790583873936160989575507522044057", "price": "0.148", "size": "0", "side": "SELL", "timestamp": "1768573788490", "received_at": "2026-01-16T14:29:48.528818"}}
{"event_type": "price_change", "event_ts": "2026-01-16T14:29:48.528828", "ingestion_ts": "2026-01-16T14:30:40.976502", "market_id": "0x2393ed0b0fdc450054c7b9071907eca75cf4fc36e385adf4a0a5f99ee62243e8", "raw": {"market": "0x2393ed0b0fdc450054c7b9071907eca75cf4fc36e385adf4a0a5f99ee62243e8", "asset_id": "32769749367306925959219403371425714180265458150646381231272229429098460625924", "price": "0.811", "size": "0", "side": "BUY", "timestamp": "1768573788490", "received_at": "2026-01-16T14:29:48.528828"}}
{"event_type": "price_change", "event_ts": "2026-01-16T14:29:48.528828", "ingestion_ts": "2026-01-16T14:30:40.976502", "market_id": "0x2393ed0b0fdc450054c7b9071907eca75cf4fc36e385adf4a0a5f99ee62243e8", "raw": {"market": "0x2393ed0b0fdc450054c7b9071907eca75cf4fc36e385adf4a0a5f99ee62243e8", "asset_id": "100074770378634056601572485653252702850363676459996771990439989989293515601975", "price": "0.189", "size": "0", "side": "SELL", "timestamp": "1768573788490", "received_at": "2026-01-16T14:29:48.528828"}}
{"event_type": "price_change", "event_ts": "2026-01-16T14:29:48.560378", "ingestion_ts": "2026-01-16T14:30:40.976502", "market_id": "0x9472be65457510b7fc3477b20ba90910e99d92eac8421a14bf4b7b7a08ef31dc", "raw": {"market": "0x9472be65457510b7fc3477b20ba90910e99d92eac8421a14bf4b7b7a08ef31dc", "asset_id": "43311793366960417907757893276427136943959788721376762326430771171648759300146", "price": "0.858", "size": "243", "side": "BUY", "timestamp": "1768573788524", "received_at": "2026-01-16T14:29:48.560378"}}
{"event_type": "price_change", "event_ts": "2026-01-16T14:29:48.560378", "ingestion_ts": "2026-01-16T14:30:40.976502", "market_id": "0x9472be65457510b7fc3477b20ba90910e99d92eac8421a14bf4b7b7a08ef31dc", "raw": {"market": "0x9472be65457510b7fc3477b20ba90910e99d92eac8421a14bf4b7b7a08ef31dc", "asset_id": "73414222381656326204771753454630063673548497164758947581648273905027617570612", "price": "0.142", "size": "243", "side": "SELL", "timestamp": "1768573788524", "received_at": "2026-01-16T14:29:48.560378"}}
{"event_type": "price_change", "event_ts": "2026-01-16T14:29:48.561013", "ingestion_ts": "2026-01-16T14:30:40.976502", "market_id": "0x49a20c7523c271099008f3ef9a31521263b24d637959852a391e6b4697b1a437", "raw": {"market": "0x49a20c7523c271099008f3ef9a31521263b24d637959852a391e6b4697b1a437", "asset_id": "55881023621710858558280545117465775643848233756850602339827152783696837905531", "price": "0.857", "size": "40", "side": "BUY", "timestamp": "1768573788524", "received_at": "2026-01-16T14:29:48.561013"}}
{"event_type": "price_change", "event_ts": "2026-01-16T14:29:48.561013", "ingestion_ts": "2026-01-16T14:30:40.976502", "market_id": "0x49a20c7523c271099008f3ef9a31521263b24d637959852a391e6b4697b1a437", "raw": {"market": "0x49a20c7523c271099008f3ef9a31521263b24d637959852a391e6b4697b1a437", "asset_id": "13018971792603393862521629014128024641178044618205296260525674415067194037856", "price": "0.143", "size": "40", "side": "SELL", "timestamp": "1768573788524", "received_at": "2026-01-16T14:29:48.561013"}}
{"event_type": "price_change", "event_ts": "2026-01-16T14:29:48.561041", "ingestion_ts": "2026-01-16T14:30:40.976502", "market_id": "0xc55db914f0fd1fee18997706712c0dfd8d0369cdbef93a9fef12bd001914ca77", "raw": {"market": "0xc55db914f0fd1fee18997706712c0dfd8d0369cdbef93a9fef12bd001914ca77", "asset_id": "114600293444080540179603459515770723592661967180480327891296353898330242622833", "price": "0.859", "size": "40", "side": "BUY", "timestamp": "1768573788524", "received_at": "2026-01-16T14:29:48.561041"}}
{"event_type": "price_change", "event_ts": "2026-01-16T14:29:48.561041", "ingestion_ts": "2026-01-16T14:30:40.976502", "market_id": "0xc55db914f0fd1fee18997706712c0dfd8d0369cdbef93a9fef12bd001914ca77", "raw": {"market": "0xc55db914f0fd1fee18997706712c0dfd8d0369cdbef93a9fef12bd001914ca77", "asset_id": "72354723612769247426741660426331235762851940382312402276325808095604519806766", "price": "0.141", "size": "40", "side": "SELL", "timestamp": "1768573788524", "received_at": "2026-01-16T14:29:48.561041"}}
{"event_type": "price_change", "event_ts": "2026-01-16T14:29:48.561101", "ingestion_ts": "2026-01-16T14:30:40.976502", "market_id": "0x49686d26fb712515cd5e12c23f0a1c7e10214c7faa3cb0a730aabe0c33694082", "raw": {"market": "0x49686d26fb712515cd5e12c23f0a1c7e10214c7faa3cb0a730aabe0c33694082", "asset_id": "30442780799048074404860985387051749017905070253466005720364298335239299761065", "price": "0.006", "size": "20.08", "side": "BUY", "timestamp": "1768573788524", "received_at": "2026-01-16T14:29:48.561101"}}
{"event_type": "price_change", "event_ts": "2026-01-16T14:29:48.561101", "ingestion_ts": "2026-01-16T14:30:40.976502", "market_id": "0x49686d26fb712515cd5e12c23f0a1c7e10214c7faa3cb0a730aabe0c33694082", "raw": {"market": "0x49686d26fb712515cd5e12c23f0a1c7e10214c7faa3cb0a730aabe0c33694082", "asset_id": "13244681086321087932946246027856416106585284024824496763706748621681543444582", "price": "0.994", "size": "20.08", "side": "SELL", "timestamp": "1768573788524", "received_at": "2026-01-16T14:29:48.561101"}}
{"event_type": "price_change", "event_ts": "2026-01-16T14:29:48.561975", "ingestion_ts": "2026-01-16T14:30:40.976502", "market_id": "0x50c669f178da4e5bbea7f1be25041fd278914712fa87a6a6f8e57d5923d88dee", "raw": {"market": "0x50c669f178da4e5bbea7f1be25041fd278914712fa87a6a6f8e57d5923d88dee", "asset_id": "74040420326294854165772767082819937451857852955603897473157746262672057685461", "price": "0.857", "size": "10", "side": "BUY", "timestamp": "1768573788524", "received_at": "2026-01-16T14:29:48.561975"}}
{"event_type": "price_change", "event_ts": "2026-01-16T14:29:48.561975", "ingestion_ts": "2026-01-16T14:30:40.976502", "market_id": "0x50c669f178da4e5bbea7f1be25041fd278914712fa87a6a6f8e57d5923d88dee", "raw": {"market": "0x50c669f178da4e5bbea7f1be25041fd278914712fa87a6a6f8e57d5923d88dee", "asset_id": "24682525479474221428144937281315825971983904267399062415430320764754931667953", "price": "0.143", "size": "10", "side": "SELL", "timestamp": "1768573788524", "received_at": "2026-01-16T14:29:48.561975"}}
{"event_type": "price_change", "event_ts": "2026-01-16T14:29:48.562001", "ingestion_ts": "2026-01-16T14:30:40.976502", "market_id": "0x2393ed0b0fdc450054c7b9071907eca75cf4fc36e385adf4a0a5f99ee62243e8", "raw": {"market": "0x2393ed0b0fdc450054c7b9071907eca75cf4fc36e385adf4a0a5f99ee62243e8", "asset_id": "32769749367306925959219403371425714180265458150646381231272229429098460625924", "price": "0.849", "size": "304", "side": "BUY", "timestamp": "1768573788524", "received_at": "2026-01-16T14:29:48.562001"}}
{"event_type": "price_change", "event_ts": "2026-01-16T14:29:48.562001", "ingestion_ts": "2026-01-16T14:30:40.976502", "market_id": "0x2393ed0b0fdc450054c7b9071907eca75cf4fc36e385adf4a0a5f99ee62243e8", "raw": {"market": "0x2393ed0b0fdc450054c7b9071907eca75cf4fc36e385adf4a0a5f99ee62243e8", "asset_id": "100074770378634056601572485653252702850363676459996771990439989989293515601975", "price": "0.151", "size": "304", "side": "SELL", "timestamp": "1768573788524", "received_at": "2026-01-16T14:29:48.562001"}}
{"event_type": "price_change", "event_ts": "2026-01-16T14:29:48.562015", "ingestion_ts": "2026-01-16T14:30:40.976502", "market_id": "0x44f08744458b8896620cd3330bc5e1ea69df4199b02d4fc583b3fc96e5d314ce", "raw": {"market": "0x44f08744458b8896620cd3330bc5e1ea69df4199b02d4fc583b3fc96e5d314ce", "asset_id": "72327831507226612545928776794104143393438710920370371172884559893525100761096", "price": "0.854", "size": "10", "side": "BUY", "timestamp": "1768573788524", "received_at": "2026-01-16T14:29:48.562015"}}
{"event_type": "price_change", "event_ts": "2026-01-16T14:29:48.562015", "ingestion_ts": "2026-01-16T14:30:40.976502", "market_id": "0x44f08744458b8896620cd3330bc5e1ea69df4199b02d4fc583b3fc96e5d314ce", "raw": {"market": "0x44f08744458b8896620cd3330bc5e1ea69df4199b02d4fc583b3fc96e5d314ce", "asset_id": "49194009556504828848509244326501559253829462790583873936160989575507522044057", "price": "0.146", "size": "10", "side": "SELL", "timestamp": "1768573788524", "received_at": "2026-01-16T14:29:48.562015"}}
{"event_type": "price_change", "event_ts": "2026-01-16T14:29:48.872023", "ingestion_ts": "2026-01-16T14:30:40.976502", "market_id": "0x5533fb9ab797777a243c75b1bf3882c54b1ee91f794730c090bf701598993529", "raw": {"market": "0x5533fb9ab797777a243c75b1bf3882c54b1ee91f794730c090bf701598993529", "asset_id": "99478074208094578615268494931219682040135218828258512927013036335093067688695", "price": "0.987", "size": "0", "side": "BUY", "timestamp": "1768573788811", "received_at": "2026-01-16T14:29:48.872023"}}
{"event_type": "price_change", "event_ts": "2026-01-16T14:29:48.872023", "ingestion_ts": "2026-01-16T14:30:40.976502", "market_id": "0x5533fb9ab797777a243c75b1bf3882c54b1ee91f794730c090bf701598993529", "raw": {"market": "0x5533fb9ab797777a243c75b1bf3882c54b1ee91f794730c090bf701598993529", "asset_id": "22532055631814907447535815649879981046415248231878961745474659705989546420934", "price": "0.013", "size": "0", "side": "SELL", "timestamp": "1768573788811", "received_at": "2026-01-16T14:29:48.872023"}}
{"event_type": "price_change", "event_ts": "2026-01-16T14:29:48.906317", "ingestion_ts": "2026-01-16T14:30:40.976502", "market_id": "0x22ac5f75af18fdb453497fbf7ac0606a09a6fd55b78b2d08aace6b946ad62038", "raw": {"market": "0x22ac5f75af18fdb453497fbf7ac0606a09a6fd55b78b2d08aace6b946ad62038", "asset_id": "59259495934562596318644973716893809974860301509869285036503555129962149752635", "price": "0.948", "size": "0", "side": "BUY", "timestamp": "1768573788811", "received_at": "2026-01-16T14:29:48.906317"}}
{"event_type": "price_change", "event_ts": "2026-01-16T14:29:48.906317", "ingestion_ts": "2026-01-16T14:30:40.976502", "market_id": "0x22ac5f75af18fdb453497fbf7ac0606a09a6fd55b78b2d08aace6b946ad62038", "raw": {"market": "0x22ac5f75af18fdb453497fbf7ac0606a09a6fd55b78b2d08aace6b946ad62038", "asset_id": "97449340182256366014320155718265676486703217567849039806162053075113517266910", "price": "0.052", "size": "0", "side": "SELL", "timestamp": "1768573788811", "received_at": "2026-01-16T14:29:48.906317"}}
{"event_type": "price_change", "event_ts": "2026-01-16T14:29:48.917766", "ingestion_ts": "2026-01-16T14:30:40.976502", "market_id": "0xaf9d0e448129a9f657f851d49495ba4742055d80e0ef1166ba0ee81d4d594214", "raw": {"market": "0xaf9d0e448129a9f657f851d49495ba4742055d80e0ef1166ba0ee81d4d594214", "asset_id": "4153292802911610701832309484716814274802943278345248636922528170020319407796", "price": "0.953", "size": "0", "side": "BUY", "timestamp": "1768573788813", "received_at": "2026-01-16T14:29:48.917766"}}
{"event_type": "price_change", "event_ts": "2026-01-16T14:29:48.917766", "ingestion_ts": "2026-01-16T14:30:40.976502", "market_id": "0xaf9d0e448129a9f657f851d49495ba4742055d80e0ef1166ba0ee81d4d594214", "raw": {"market": "0xaf9d0e448129a9f657f851d49495ba4742055d80e0ef1166ba0ee81d4d594214", "asset_id": "101676997363687199724245607342877036148401850938023978421879460310389391082353", "price": "0.047", "size": "0", "side": "SELL", "timestamp": "1768573788813", "received_at": "2026-01-16T14:29:48.917766"}}
{"event_type": "price_change", "event_ts": "2026-01-16T14:29:48.928494", "ingestion_ts": "2026-01-16T14:30:40.976502", "market_id": "0x44f08744458b8896620cd3330bc5e1ea69df4199b02d4fc583b3fc96e5d314ce", "raw": {"market": "0x44f08744458b8896620cd3330bc5e1ea69df4199b02d4fc583b3fc96e5d314ce", "asset_id": "72327831507226612545928776794104143393438710920370371172884559893525100761096", "price": "0.968", "size": "0", "side": "BUY", "timestamp": "1768573788815", "received_at": "2026-01-16T14:29:48.928494"}}
{"event_type": "price_change", "event_ts": "2026-01-16T14:29:48.928494", "ingestion_ts": "2026-01-16T14:30:40.976502", "market_id": "0x44f08744458b8896620cd3330bc5e1ea69df4199b02d4fc583b3fc96e5d314ce", "raw": {"market": "0x44f08744458b8896620cd3330bc5e1ea69df4199b02d4fc583b3fc96e5d314ce", "asset_id": "49194009556504828848509244326501559253829462790583873936160989575507522044057", "price": "0.032", "size": "0", "side": "SELL", "timestamp": "1768573788815", "received_at": "2026-01-16T14:29:48.928494"}}
{"event_type": "price_change", "event_ts": "2026-01-16T14:29:49.468737", "ingestion_ts": "2026-01-16T14:30:40.976502", "market_id": "0x44f08744458b8896620cd3330bc5e1ea69df4199b02d4fc583b3fc96e5d314ce", "raw": {"market": "0x44f08744458b8896620cd3330bc5e1ea69df4199b02d4fc583b3fc96e5d314ce", "asset_id": "72327831507226612545928776794104143393438710920370371172884559893525100761096", "price": "0.967", "size": "25", "side": "BUY", "timestamp": "1768573789419", "received_at": "2026-01-16T14:29:49.468737"}}
{"event_type": "price_change", "event_ts": "2026-01-16T14:29:49.468737", "ingestion_ts": "2026-01-16T14:30:40.976502", "market_id": "0x44f08744458b8896620cd3330bc5e1ea69df4199b02d4fc583b3fc96e5d314ce", "raw": {"market": "0x44f08744458b8896620cd3330bc5e1ea69df4199b02d4fc583b3fc96e5d314ce", "asset_id": "49194009556504828848509244326501559253829462790583873936160989575507522044057", "price": "0.033", "size": "25", "side": "SELL", "timestamp": "1768573789419", "received_at": "2026-01-16T14:29:49.468737"}}
{"event_type": "price_change", "event_ts": "2026-01-16T14:29:49.508353", "ingestion_ts": "2026-01-16T14:30:40.976502", "market_id": "0x49686d26fb712515cd5e12c23f0a1c7e10214c7faa3cb0a730aabe0c33694082", "raw": {"market": "0x49686d26fb712515cd5e12c23f0a1c7e10214c7faa3cb0a730aabe0c33694082", "asset_id": "13244681086321087932946246027856416106585284024824496763706748621681543444582", "price": "0.853", "size": "45", "side": "BUY", "timestamp": "1768573789472", "received_at": "2026-01-16T14:29:49.508353"}}
{"event_type": "price_change", "event_ts": "2026-01-16T14:29:49.508353", "ingestion_ts": "2026-01-16T14:30:40.976502", "market_id": "0x49686d26fb712515cd5e12c23f0a1c7e10214c7faa3cb0a730aabe0c33694082", "raw": {"market": "0x49686d26fb712515cd5e12c23f0a1c7e10214c7faa3cb0a730aabe0c33694082", "asset_id": "30442780799048074404860985387051749017905070253466005720364298335239299761065", "price": "0.147", "size": "45", "side": "SELL", "timestamp": "1768573789472", "received_at": "2026-01-16T14:29:49.508353"}}
{"event_type": "price_change", "event_ts": "2026-01-16T14:29:49.547815", "ingestion_ts": "2026-01-16T14:30:40.976502", "market_id": "0x49686d26fb712515cd5e12c23f0a1c7e10214c7faa3cb0a730aabe0c33694082", "raw": {"market": "0x49686d26fb712515cd5e12c23f0a1c7e10214c7faa3cb0a730aabe0c33694082", "asset_id": "13244681086321087932946246027856416106585284024824496763706748621681543444582", "price": "0.854", "size": "23.35", "side": "BUY", "timestamp": "1768573789512", "received_at": "2026-01-16T14:29:49.547815"}}
{"event_type": "price_change", "event_ts": "2026-01-16T14:29:49.547815", "ingestion_ts": "2026-01-16T14:30:40.976502", "market_id": "0x49686d26fb712515cd5e12c23f0a1c7e10214c7faa3cb0a730aabe0c33694082", "raw": {"market": "0x49686d26fb712515cd5e12c23f0a1c7e10214c7faa3cb0a730aabe0c33694082", "asset_id": "30442780799048074404860985387051749017905070253466005720364298335239299761065", "price": "0.146", "size": "23.35", "side": "SELL", "timestamp": "1768573789512", "received_at": "2026-01-16T14:29:49.547815"}}
{"event_type": "price_change", "event_ts": "2026-01-16T14:29:50.203897", "ingestion_ts": "2026-01-16T14:30:40.976502", "market_id": "0x49686d26fb712515cd5e12c23f0a1c7e10214c7faa3cb0a730aabe0c33694082", "raw": {"market": "0x49686d26fb712515cd5e12c23f0a1c7e10214c7faa3cb0a730aabe0c33694082", "asset_id": "30442780799048074404860985387051749017905070253466005720364298335239299761065", "price": "0.146", "size": "5.85", "side": "SELL", "timestamp": "1768573790168", "received_at": "2026-01-16T14:29:50.203897"}}
{"event_type": "price_change", "event_ts": "2026-01-16T14:29:50.203897", "ingestion_ts": "2026-01-16T14:30:40.976502", "market_id": "0x49686d26fb712515cd5e12c23f0a1c7e10214c7faa3cb0a730aabe0c33694082", "raw": {"market": "0x49686d26fb712515cd5e12c23f0a1c7e10214c7faa3cb0a730aabe0c33694082", "asset_id": "13244681086321087932946246027856416106585284024824496763706748621681543444582", "price": "0.854", "size": "5.85", "side": "BUY", "timestamp": "1768573790168", "received_at": "2026-01-16T14:29:50.203897"}}
{"event_type": "price_change", "event_ts": "2026-01-16T14:29:50.245557", "ingestion_ts": "2026-01-16T14:30:40.976502", "market_id": "0x49686d26fb712515cd5e12c23f0a1c7e10214c7faa3cb0a730aabe0c33694082", "raw": {"market": "0x49686d26fb712515cd5e12c23f0a1c7e10214c7faa3cb0a730aabe0c33694082", "asset_id": "30442780799048074404860985387051749017905070253466005720364298335239299761065", "price": "0.148", "size": "17.5", "side": "SELL", "timestamp": "1768573790209", "received_at": "2026-01-16T14:29:50.245557"}}
{"event_type": "price_change", "event_ts": "2026-01-16T14:29:50.245557", "ingestion_ts": "2026-01-16T14:30:40.976502", "market_id": "0x49686d26fb712515cd5e12c23f0a1c7e10214c7faa3cb0a730aabe0c33694082", "raw": {"market": "0x49686d26fb712515cd5e12c23f0a1c7e10214c7faa3cb0a730aabe0c33694082", "asset_id": "13244681086321087932946246027856416106585284024824496763706748621681543444582", "price": "0.852", "size": "17.5", "side": "BUY", "timestamp": "1768573790209", "received_at": "2026-01-16T14:29:50.245557"}}
{"event_type": "price_change", "event_ts": "2026-01-16T14:29:52.609769", "ingestion_ts": "2026-01-16T14:30:40.976502", "market_id": "0xc0e6b917320a47228fb96e3b5ae0e5c93773a5ae2662ae4e1f37807cfe47ce98", "raw": {"market": "0xc0e6b917320a47228fb96e3b5ae0e5c93773a5ae2662ae4e1f37807cfe47ce98", "asset_id": "58656358377246279051017109359677190749228949103591068167284263961542487110215", "price": "0.073", "size": "5", "side": "SELL", "timestamp": "1768573792568", "received_at": "2026-01-16T14:29:52.609769"}}
{"event_type": "price_change", "event_ts": "2026-01-16T14:29:52.609769", "ingestion_ts": "2026-01-16T14:30:40.976502", "market_id": "0xc0e6b917320a47228fb96e3b5ae0e5c93773a5ae2662ae4e1f37807cfe47ce98", "raw": {"market": "0xc0e6b917320a47228fb96e3b5ae0e5c93773a5ae2662ae4e1f37807cfe47ce98", "asset_id": "81647294538046680798858716589766492074338758116170717123345952330712416337530", "price": "0.927", "size": "5", "side": "BUY", "timestamp": "1768573792568", "received_at": "2026-01-16T14:29:52.609769"}}
{"event_type": "price_change", "event_ts": "2026-01-16T14:29:52.831144", "ingestion_ts": "2026-01-16T14:30:40.976502", "market_id": "0xaf9d0e448129a9f657f851d49495ba4742055d80e0ef1166ba0ee81d4d594214", "raw": {"market": "0xaf9d0e448129a9f657f851d49495ba4742055d80e0ef1166ba0ee81d4d594214", "asset_id": "4153292802911610701832309484716814274802943278345248636922528170020319407796", "price": "0.979", "size": "0", "side": "SELL", "timestamp": "1768573792791", "received_at": "2026-01-16T14:29:52.831144"}}
{"event_type": "price_change", "event_ts": "2026-01-16T14:29:52.831144", "ingestion_ts": "2026-01-16T14:30:40.976502", "market_id": "0xaf9d0e448129a9f657f851d49495ba4742055d80e0ef1166ba0ee81d4d594214", "raw": {"market": "0xaf9d0e448129a9f657f851d49495ba4742055d80e0ef1166ba0ee81d4d594214", "asset_id": "101676997363687199724245607342877036148401850938023978421879460310389391082353", "price": "0.021", "size": "0", "side": "BUY", "timestamp": "1768573792791", "received_at": "2026-01-16T14:29:52.831144"}}
{"event_type": "price_change", "event_ts": "2026-01-16T14:29:53.109730", "ingestion_ts": "2026-01-16T14:30:40.976502", "market_id": "0xc0e6b917320a47228fb96e3b5ae0e5c93773a5ae2662ae4e1f37807cfe47ce98", "raw": {"market": "0xc0e6b917320a47228fb96e3b5ae0e5c93773a5ae2662ae4e1f37807cfe47ce98", "asset_id": "58656358377246279051017109359677190749228949103591068167284263961542487110215", "price": "0.074", "size": "43.26", "side": "SELL", "timestamp": "1768573793014", "received_at": "2026-01-16T14:29:53.109730"}}
{"event_type": "price_change", "event_ts": "2026-01-16T14:29:53.109730", "ingestion_ts": "2026-01-16T14:30:40.976502", "market_id": "0xc0e6b917320a47228fb96e3b5ae0e5c93773a5ae2662ae4e1f37807cfe47ce98", "raw": {"market": "0xc0e6b917320a47228fb96e3b5ae0e5c93773a5ae2662ae4e1f37807cfe47ce98", "asset_id": "81647294538046680798858716589766492074338758116170717123345952330712416337530", "price": "0.926", "size": "43.26", "side": "BUY", "timestamp": "1768573793014", "received_at": "2026-01-16T14:29:53.109730"}}
{"event_type": "price_change", "event_ts": "2026-01-16T14:29:53.109775", "ingestion_ts": "2026-01-16T14:30:40.976502", "market_id": "0xc0e6b917320a47228fb96e3b5ae0e5c93773a5ae2662ae4e1f37807cfe47ce98", "raw": {"market": "0xc0e6b917320a47228fb96e3b5ae0e5c93773a5ae2662ae4e1f37807cfe47ce98", "asset_id": "58656358377246279051017109359677190749228949103591068167284263961542487110215", "price": "0.074", "size": "52.8", "side": "SELL", "timestamp": "1768573793015", "received_at": "2026-01-16T14:29:53.109775"}}
{"event_type": "price_change", "event_ts": "2026-01-16T14:29:53.109775", "ingestion_ts": "2026-01-16T14:30:40.976502", "market_id": "0xc0e6b917320a47228fb96e3b5ae0e5c93773a5ae2662ae4e1f37807cfe47ce98", "raw": {"market": "0xc0e6b917320a47228fb96e3b5ae0e5c93773a5ae2662ae4e1f37807cfe47ce98", "asset_id": "81647294538046680798858716589766492074338758116170717123345952330712416337530", "price": "0.926", "size": "52.8", "side": "BUY", "timestamp": "1768573793015", "received_at": "2026-01-16T14:29:53.109775"}}
{"event_type": "price_change", "event_ts": "2026-01-16T14:29:53.148912", "ingestion_ts": "2026-01-16T14:30:40.976502", "market_id": "0xaf9d0e448129a9f657f851d49495ba4742055d80e0ef1166ba0ee81d4d594214", "raw": {"market": "0xaf9d0e448129a9f657f851d49495ba4742055d80e0ef1166ba0ee81d4d594214", "asset_id": "4153292802911610701832309484716814274802943278345248636922528170020319407796", "price": "0.954", "size": "26.19", "side": "BUY", "timestamp": "1768573793109", "received_at": "2026-01-16T14:29:53.148912"}}
{"event_type": "price_change", "event_ts": "2026-01-16T14:29:53.148912", "ingestion_ts": "2026-01-16T14:30:40.976502", "market_id": "0xaf9d0e448129a9f657f851d49495ba4742055d80e0ef1166ba0ee81d4d594214", "raw": {"market": "0xaf9d0e448129a9f657f851d49495ba4742055d80e0ef1166ba0ee81d4d594214", "asset_id": "101676997363687199724245607342877036148401850938023978421879460310389391082353", "price": "0.046", "size": "26.19", "side": "SELL", "timestamp": "1768573793109", "received_at": "2026-01-16T14:29:53.148912"}}
{"event_type": "price_change", "event_ts": "2026-01-16T14:29:53.475238", "ingestion_ts": "2026-01-16T14:30:40.976502", "market_id": "0x22ac5f75af18fdb453497fbf7ac0606a09a6fd55b78b2d08aace6b946ad62038", "raw": {"market": "0x22ac5f75af18fdb453497fbf7ac0606a09a6fd55b78b2d08aace6b946ad62038", "asset_id": "59259495934562596318644973716893809974860301509869285036503555129962149752635", "price": "0.949", "size": "27", "side": "BUY", "timestamp": "1768573793434", "received_at": "2026-01-16T14:29:53.475238"}}
{"event_type": "price_change", "event_ts": "2026-01-16T14:29:53.475238", "ingestion_ts": "2026-01-16T14:30:40.976502", "market_id": "0x22ac5f75af18fdb453497fbf7ac0606a09a6fd55b78b2d08aace6b946ad62038", "raw": {"market": "0x22ac5f75af18fdb453497fbf7ac0606a09a6fd55b78b2d08aace6b946ad62038", "asset_id": "97449340182256366014320155718265676486703217567849039806162053075113517266910", "price": "0.051", "size": "27", "side": "SELL", "timestamp": "1768573793434", "received_at": "2026-01-16T14:29:53.475238"}}
{"event_type": "price_change", "event_ts": "2026-01-16T14:29:53.528570", "ingestion_ts": "2026-01-16T14:30:40.976502", "market_id": "0x44f08744458b8896620cd3330bc5e1ea69df4199b02d4fc583b3fc96e5d314ce", "raw": {"market": "0x44f08744458b8896620cd3330bc5e1ea69df4199b02d4fc583b3fc96e5d314ce", "asset_id": "72327831507226612545928776794104143393438710920370371172884559893525100761096", "price": "0.968", "size": "17.19", "side": "BUY", "timestamp": "1768573793485", "received_at": "2026-01-16T14:29:53.528570"}}
{"event_type": "price_change", "event_ts": "2026-01-16T14:29:53.528570", "ingestion_ts": "2026-01-16T14:30:40.976502", "market_id": "0x44f08744458b8896620cd3330bc5e1ea69df4199b02d4fc583b3fc96e5d314ce", "raw": {"market": "0x44f08744458b8896620cd3330bc5e1ea69df4199b02d4fc583b3fc96e5d314ce", "asset_id": "49194009556504828848509244326501559253829462790583873936160989575507522044057", "price": "0.032", "size": "17.19", "side": "SELL", "timestamp": "1768573793485", "received_at": "2026-01-16T14:29:53.528570"}}
{"event_type": "price_change", "event_ts": "2026-01-16T14:29:53.627846", "ingestion_ts": "2026-01-16T14:30:40.976502", "market_id": "0xae5584fbb57f23c1c608d544b656f23d8bf12340cef70811cf31bb0cb4fc2115", "raw": {"market": "0xae5584fbb57f23c1c608d544b656f23d8bf12340cef70811cf31bb0cb4fc2115", "asset_id": "42278252558046940014991595990628759801692726198478046188873057685686228021663", "price": "0.99", "size": "8145.4", "side": "SELL", "timestamp": "1768573793557", "received_at": "2026-01-16T14:29:53.627846"}}
{"event_type": "price_change", "event_ts": "2026-01-16T14:29:53.627846", "ingestion_ts": "2026-01-16T14:30:40.976502", "market_id": "0xae5584fbb57f23c1c608d544b656f23d8bf12340cef70811cf31bb0cb4fc2115", "raw": {"market": "0xae5584fbb57f23c1c608d544b656f23d8bf12340cef70811cf31bb0cb4fc2115", "asset_id": "28946595841244317705636126646676849578876740730186646421280828201004700559420", "price": "0.01", "size": "8145.4", "side": "BUY", "timestamp": "1768573793557", "received_at": "2026-01-16T14:29:53.627846"}}
{"event_type": "price_change", "event_ts": "2026-01-16T14:29:53.695993", "ingestion_ts": "2026-01-16T14:30:40.976502", "market_id": "0xae5584fbb57f23c1c608d544b656f23d8bf12340cef70811cf31bb0cb4fc2115", "raw": {"market": "0xae5584fbb57f23c1c608d544b656f23d8bf12340cef70811cf31bb0cb4fc2115", "asset_id": "28946595841244317705636126646676849578876740730186646421280828201004700559420", "price": "0.01", "size": "8091", "side": "BUY", "timestamp": "1768573793657", "received_at": "2026-01-16T14:29:53.695993"}}
{"event_type": "price_change", "event_ts": "2026-01-16T14:29:53.695993", "ingestion_ts": "2026-01-16T14:30:40.976502", "market_id": "0xae5584fbb57f23c1c608d544b656f23d8bf12340cef70811cf31bb0cb4fc2115", "raw": {"market": "0xae5584fbb57f23c1c608d544b656f23d8bf12340cef70811cf31bb0cb4fc2115", "asset_id": "42278252558046940014991595990628759801692726198478046188873057685686228021663", "price": "0.99", "size": "8091", "side": "SELL", "timestamp": "1768573793657", "received_at": "2026-01-16T14:29:53.695993"}}
{"event_type": "price_change", "event_ts": "2026-01-16T14:29:53.732937", "ingestion_ts": "2026-01-16T14:30:40.976502", "market_id": "0x44f08744458b8896620cd3330bc5e1ea69df4199b02d4fc583b3fc96e5d314ce", "raw": {"market": "0x44f08744458b8896620cd3330bc5e1ea69df4199b02d4fc583b3fc96e5d314ce", "asset_id": "72327831507226612545928776794104143393438710920370371172884559893525100761096", "price": "0.967", "size": "75", "side": "BUY", "timestamp": "1768573793689", "received_at": "2026-01-16T14:29:53.732937"}}
{"event_type": "price_change", "event_ts": "2026-01-16T14:29:53.732937", "ingestion_ts": "2026-01-16T14:30:40.976502", "market_id": "0x44f08744458b8896620cd3330bc5e1ea69df4199b02d4fc583b3fc96e5d314ce", "raw": {"market": "0x44f08744458b8896620cd3330bc5e1ea69df4199b02d4fc583b3fc96e5d314ce", "asset_id": "49194009556504828848509244326501559253829462790583873936160989575507522044057", "price": "0.033", "size": "75", "side": "SELL", "timestamp": "1768573793689", "received_at": "2026-01-16T14:29:53.732937"}}
{"event_type": "price_change", "event_ts": "2026-01-16T14:29:53.762531", "ingestion_ts": "2026-01-16T14:30:40.976502", "market_id": "0x5533fb9ab797777a243c75b1bf3882c54b1ee91f794730c090bf701598993529", "raw": {"market": "0x5533fb9ab797777a243c75b1bf3882c54b1ee91f794730c090bf701598993529", "asset_id": "99478074208094578615268494931219682040135218828258512927013036335093067688695", "price": "0.987", "size": "17.19", "side": "BUY", "timestamp": "1768573793709", "received_at": "2026-01-16T14:29:53.762531"}}
{"event_type": "price_change", "event_ts": "2026-01-16T14:29:53.762531", "ingestion_ts": "2026-01-16T14:30:40.976502", "market_id": "0x5533fb9ab797777a243c75b1bf3882c54b1ee91f794730c090bf701598993529", "raw": {"market": "0x5533fb9ab797777a243c75b1bf3882c54b1ee91f794730c090bf701598993529", "asset_id": "22532055631814907447535815649879981046415248231878961745474659705989546420934", "price": "0.013", "size": "17.19", "side": "SELL", "timestamp": "1768573793709", "received_at": "2026-01-16T14:29:53.762531"}}
{"event_type": "price_change", "event_ts": "2026-01-16T14:29:53.785412", "ingestion_ts": "2026-01-16T14:30:40.976502", "market_id": "0xc0e6b917320a47228fb96e3b5ae0e5c93773a5ae2662ae4e1f37807cfe47ce98", "raw": {"market": "0xc0e6b917320a47228fb96e3b5ae0e5c93773a5ae2662ae4e1f37807cfe47ce98", "asset_id": "81647294538046680798858716589766492074338758116170717123345952330712416337530", "price": "0.924", "size": "0", "side": "BUY", "timestamp": "1768573793719", "received_at": "2026-01-16T14:29:53.785412"}}
{"event_type": "price_change", "event_ts": "2026-01-16T14:29:53.785412", "ingestion_ts": "2026-01-16T14:30:40.976502", "market_id": "0xc0e6b917320a47228fb96e3b5ae0e5c93773a5ae2662ae4e1f37807cfe47ce98", "raw": {"market": "0xc0e6b917320a47228fb96e3b5ae0e5c93773a5ae2662ae4e1f37807cfe47ce98", "asset_id": "58656358377246279051017109359677190749228949103591068167284263961542487110215", "price": "0.076", "size": "0", "side": "SELL", "timestamp": "1768573793719", "received_at": "2026-01-16T14:29:53.785412"}}
{"event_type": "price_change", "event_ts": "2026-01-16T14:29:53.845620", "ingestion_ts": "2026-01-16T14:30:40.976502", "market_id": "0xc0e6b917320a47228fb96e3b5ae0e5c93773a5ae2662ae4e1f37807cfe47ce98", "raw": {"market": "0xc0e6b917320a47228fb96e3b5ae0e5c93773a5ae2662ae4e1f37807cfe47ce98", "asset_id": "81647294538046680798858716589766492074338758116170717123345952330712416337530", "price": "0.926", "size": "82.8", "side": "BUY", "timestamp": "1768573793799", "received_at": "2026-01-16T14:29:53.845620"}}
{"event_type": "price_change", "event_ts": "2026-01-16T14:29:53.845620", "ingestion_ts": "2026-01-16T14:30:40.976502", "market_id": "0xc0e6b917320a47228fb96e3b5ae0e5c93773a5ae2662ae4e1f37807cfe47ce98", "raw": {"market": "0xc0e6b917320a47228fb96e3b5ae0e5c93773a5ae2662ae4e1f37807cfe47ce98", "asset_id": "58656358377246279051017109359677190749228949103591068167284263961542487110215", "price": "0.074", "size": "82.8", "side": "SELL", "timestamp": "1768573793799", "received_at": "2026-01-16T14:29:53.845620"}}
{"event_type": "price_change", "event_ts": "2026-01-16T14:29:53.855869", "ingestion_ts": "2026-01-16T14:30:40.976502", "market_id": "0x44f08744458b8896620cd3330bc5e1ea69df4199b02d4fc583b3fc96e5d314ce", "raw": {"market": "0x44f08744458b8896620cd3330bc5e1ea69df4199b02d4fc583b3fc96e5d314ce", "asset_id": "72327831507226612545928776794104143393438710920370371172884559893525100761096", "price": "0.967", "size": "105", "side": "BUY", "timestamp": "1768573793813", "received_at": "2026-01-16T14:29:53.855869"}}
{"event_type": "price_change", "event_ts": "2026-01-16T14:29:53.855869", "ingestion_ts": "2026-01-16T14:30:40.976502", "market_id": "0x44f08744458b8896620cd3330bc5e1ea69df4199b02d4fc583b3fc96e5d314ce", "raw": {"market": "0x44f08744458b8896620cd3330bc5e1ea69df4199b02d4fc583b3fc96e5d314ce", "asset_id": "49194009556504828848509244326501559253829462790583873936160989575507522044057", "price": "0.033", "size": "105", "side": "SELL", "timestamp": "1768573793813", "received_at": "2026-01-16T14:29:53.855869"}}
{"event_type": "price_change", "event_ts": "2026-01-16T14:29:53.888040", "ingestion_ts": "2026-01-16T14:30:40.976502", "market_id": "0xaf9d0e448129a9f657f851d49495ba4742055d80e0ef1166ba0ee81d4d594214", "raw": {"market": "0xaf9d0e448129a9f657f851d49495ba4742055d80e0ef1166ba0ee81d4d594214", "asset_id": "4153292802911610701832309484716814274802943278345248636922528170020319407796", "price": "0.978", "size": "0", "side": "SELL", "timestamp": "1768573793838", "received_at": "2026-01-16T14:29:53.888040"}}
{"event_type": "price_change", "event_ts": "2026-01-16T14:29:53.888040", "ingestion_ts": "2026-01-16T14:30:40.976502", "market_id": "0xaf9d0e448129a9f657f851d49495ba4742055d80e0ef1166ba0ee81d4d594214", "raw": {"market": "0xaf9d0e448129a9f657f851d49495ba4742055d80e0ef1166ba0ee81d4d594214", "asset_id": "101676997363687199724245607342877036148401850938023978421879460310389391082353", "price": "0.022", "size": "0", "side": "BUY", "timestamp": "1768573793838", "received_at": "2026-01-16T14:29:53.888040"}}
{"event_type": "price_change", "event_ts": "2026-01-16T14:29:53.932425", "ingestion_ts": "2026-01-16T14:30:40.976502", "market_id": "0xaf9d0e448129a9f657f851d49495ba4742055d80e0ef1166ba0ee81d4d594214", "raw": {"market": "0xaf9d0e448129a9f657f851d49495ba4742055d80e0ef1166ba0ee81d4d594214", "asset_id": "4153292802911610701832309484716814274802943278345248636922528170020319407796", "price": "0.989", "size": "20.5", "side": "SELL", "timestamp": "1768573793889", "received_at": "2026-01-16T14:29:53.932425"}}
{"event_type": "price_change", "event_ts": "2026-01-16T14:29:53.932425", "ingestion_ts": "2026-01-16T14:30:40.976502", "market_id": "0xaf9d0e448129a9f657f851d49495ba4742055d80e0ef1166ba0ee81d4d594214", "raw": {"market": "0xaf9d0e448129a9f657f851d49495ba4742055d80e0ef1166ba0ee81d4d594214", "asset_id": "101676997363687199724245607342877036148401850938023978421879460310389391082353", "price": "0.011", "size": "20.5", "side": "BUY", "timestamp": "1768573793889", "received_at": "2026-01-16T14:29:53.932425"}}
{"event_type": "price_change", "event_ts": "2026-01-16T14:29:54.049269", "ingestion_ts": "2026-01-16T14:30:40.976502", "market_id": "0xaf9d0e448129a9f657f851d49495ba4742055d80e0ef1166ba0ee81d4d594214", "raw": {"market": "0xaf9d0e448129a9f657f851d49495ba4742055d80e0ef1166ba0ee81d4d594214", "asset_id": "4153292802911610701832309484716814274802943278345248636922528170020319407796", "price": "0.952", "size": "9", "side": "BUY", "timestamp": "1768573793980", "received_at": "2026-01-16T14:29:54.049269"}}
{"event_type": "price_change", "event_ts": "2026-01-16T14:29:54.049269", "ingestion_ts": "2026-01-16T14:30:40.976502", "market_id": "0xaf9d0e448129a9f657f851d49495ba4742055d80e0ef1166ba0ee81d4d594214", "raw": {"market": "0xaf9d0e448129a9f657f851d49495ba4742055d80e0ef1166ba0ee81d4d594214", "asset_id": "101676997363687199724245607342877036148401850938023978421879460310389391082353", "price": "0.048", "size": "9", "side": "SELL", "timestamp": "1768573793980", "received_at": "2026-01-16T14:29:54.049269"}}
{"event_type": "price_change", "event_ts": "2026-01-16T14:29:54.164832", "ingestion_ts": "2026-01-16T14:30:40.976502", "market_id": "0x2393ed0b0fdc450054c7b9071907eca75cf4fc36e385adf4a0a5f99ee62243e8", "raw": {"market": "0x2393ed0b0fdc450054c7b9071907eca75cf4fc36e385adf4a0a5f99ee62243e8", "asset_id": "32769749367306925959219403371425714180265458150646381231272229429098460625924", "price": "0.952", "size": "50", "side": "BUY", "timestamp": "1768573794096", "received_at": "2026-01-16T14:29:54.164832"}}
{"event_type": "price_change", "event_ts": "2026-01-16T14:29:54.164832", "ingestion_ts": "2026-01-16T14:30:40.976502", "market_id": "0x2393ed0b0fdc450054c7b9071907eca75cf4fc36e385adf4a0a5f99ee62243e8", "raw": {"market": "0x2393ed0b0fdc450054c7b9071907eca75cf4fc36e385adf4a0a5f99ee62243e8", "asset_id": "100074770378634056601572485653252702850363676459996771990439989989293515601975", "price": "0.048", "size": "50", "side": "SELL", "timestamp": "1768573794096", "received_at": "2026-01-16T14:29:54.164832"}}
{"event_type": "price_change", "event_ts": "2026-01-16T14:29:54.229681", "ingestion_ts": "2026-01-16T14:30:40.976502", "market_id": "0x2393ed0b0fdc450054c7b9071907eca75cf4fc36e385adf4a0a5f99ee62243e8", "raw": {"market": "0x2393ed0b0fdc450054c7b9071907eca75cf4fc36e385adf4a0a5f99ee62243e8", "asset_id": "100074770378634056601572485653252702850363676459996771990439989989293515601975", "price": "0.049", "size": "0", "side": "SELL", "timestamp": "1768573794163", "received_at": "2026-01-16T14:29:54.229681"}}
{"event_type": "price_change", "event_ts": "2026-01-16T14:29:54.229681", "ingestion_ts": "2026-01-16T14:30:40.976502", "market_id": "0x2393ed0b0fdc450054c7b9071907eca75cf4fc36e385adf4a0a5f99ee62243e8", "raw": {"market": "0x2393ed0b0fdc450054c7b9071907eca75cf4fc36e385adf4a0a5f99ee62243e8", "asset_id": "32769749367306925959219403371425714180265458150646381231272229429098460625924", "price": "0.951", "size": "0", "side": "BUY", "timestamp": "1768573794163", "received_at": "2026-01-16T14:29:54.229681"}}
{"event_type": "price_change", "event_ts": "2026-01-16T14:29:54.248240", "ingestion_ts": "2026-01-16T14:30:40.976502", "market_id": "0x49a20c7523c271099008f3ef9a31521263b24d637959852a391e6b4697b1a437", "raw": {"market": "0x49a20c7523c271099008f3ef9a31521263b24d637959852a391e6b4697b1a437", "asset_id": "55881023621710858558280545117465775643848233756850602339827152783696837905531", "price": "0.857", "size": "30", "side": "BUY", "timestamp": "1768573794183", "received_at": "2026-01-16T14:29:54.248240"}}
{"event_type": "price_change", "event_ts": "2026-01-16T14:29:54.248240", "ingestion_ts": "2026-01-16T14:30:40.976502", "market_id": "0x49a20c7523c271099008f3ef9a31521263b24d637959852a391e6b4697b1a437", "raw": {"market": "0x49a20c7523c271099008f3ef9a31521263b24d637959852a391e6b4697b1a437", "asset_id": "13018971792603393862521629014128024641178044618205296260525674415067194037856", "price": "0.143", "size": "30", "side": "SELL", "timestamp": "1768573794183", "received_at": "2026-01-16T14:29:54.248240"}}
{"event_type": "price_change", "event_ts": "2026-01-16T14:29:54.248293", "ingestion_ts": "2026-01-16T14:30:40.976502", "market_id": "0x50c669f178da4e5bbea7f1be25041fd278914712fa87a6a6f8e57d5923d88dee", "raw": {"market": "0x50c669f178da4e5bbea7f1be25041fd278914712fa87a6a6f8e57d5923d88dee", "asset_id": "74040420326294854165772767082819937451857852955603897473157746262672057685461", "price": "0.857", "size": "0", "side": "BUY", "timestamp": "1768573794183", "received_at": "2026-01-16T14:29:54.248293"}}
{"event_type": "price_change", "event_ts": "2026-01-16T14:29:54.248293", "ingestion_ts": "2026-01-16T14:30:40.976502", "market_id": "0x50c669f178da4e5bbea7f1be25041fd278914712fa87a6a6f8e57d5923d88dee", "raw": {"market": "0x50c669f178da4e5bbea7f1be25041fd278914712fa87a6a6f8e57d5923d88dee", "asset_id": "24682525479474221428144937281315825971983904267399062415430320764754931667953", "price": "0.143", "size": "0", "side": "SELL", "timestamp": "1768573794183", "received_at": "2026-01-16T14:29:54.248293"}}
{"event_type": "price_change", "event_ts": "2026-01-16T14:29:54.248312", "ingestion_ts": "2026-01-16T14:30:40.976502", "market_id": "0xc55db914f0fd1fee18997706712c0dfd8d0369cdbef93a9fef12bd001914ca77", "raw": {"market": "0xc55db914f0fd1fee18997706712c0dfd8d0369cdbef93a9fef12bd001914ca77", "asset_id": "114600293444080540179603459515770723592661967180480327891296353898330242622833", "price": "0.859", "size": "30", "side": "BUY", "timestamp": "1768573794183", "received_at": "2026-01-16T14:29:54.248312"}}
{"event_type": "price_change", "event_ts": "2026-01-16T14:29:54.248312", "ingestion_ts": "2026-01-16T14:30:40.976502", "market_id": "0xc55db914f0fd1fee18997706712c0dfd8d0369cdbef93a9fef12bd001914ca77", "raw": {"market": "0xc55db914f0fd1fee18997706712c0dfd8d0369cdbef93a9fef12bd001914ca77", "asset_id": "72354723612769247426741660426331235762851940382312402276325808095604519806766", "price": "0.141", "size": "30", "side": "SELL", "timestamp": "1768573794183", "received_at": "2026-01-16T14:29:54.248312"}}
{"event_type": "price_change", "event_ts": "2026-01-16T14:29:54.248329", "ingestion_ts": "2026-01-16T14:30:40.976502", "market_id": "0x49686d26fb712515cd5e12c23f0a1c7e10214c7faa3cb0a730aabe0c33694082", "raw": {"market": "0x49686d26fb712515cd5e12c23f0a1c7e10214c7faa3cb0a730aabe0c33694082", "asset_id": "30442780799048074404860985387051749017905070253466005720364298335239299761065", "price": "0.006", "size": "10.08", "side": "BUY", "timestamp": "1768573794183", "received_at": "2026-01-16T14:29:54.248329"}}
{"event_type": "price_change", "event_ts": "2026-01-16T14:29:54.248329", "ingestion_ts": "2026-01-16T14:30:40.976502", "market_id": "0x49686d26fb712515cd5e12c23f0a1c7e10214c7faa3cb0a730aabe0c33694082", "raw": {"market": "0x49686d26fb712515cd5e12c23f0a1c7e10214c7faa3cb0a730aabe0c33694082", "asset_id": "13244681086321087932946246027856416106585284024824496763706748621681543444582", "price": "0.994", "size": "10.08", "side": "SELL", "timestamp": "1768573794183", "received_at": "2026-01-16T14:29:54.248329"}}
{"event_type": "price_change", "event_ts": "2026-01-16T14:29:54.248346", "ingestion_ts": "2026-01-16T14:30:40.976502", "market_id": "0x9472be65457510b7fc3477b20ba90910e99d92eac8421a14bf4b7b7a08ef31dc", "raw": {"market": "0x9472be65457510b7fc3477b20ba90910e99d92eac8421a14bf4b7b7a08ef31dc", "asset_id": "43311793366960417907757893276427136943959788721376762326430771171648759300146", "price": "0.858", "size": "233", "side": "BUY", "timestamp": "1768573794183", "received_at": "2026-01-16T14:29:54.248346"}}
{"event_type": "price_change", "event_ts": "2026-01-16T14:29:54.248346", "ingestion_ts": "2026-01-16T14:30:40.976502", "market_id": "0x9472be65457510b7fc3477b20ba90910e99d92eac8421a14bf4b7b7a08ef31dc", "raw": {"market": "0x9472be65457510b7fc3477b20ba90910e99d92eac8421a14bf4b7b7a08ef31dc", "asset_id": "73414222381656326204771753454630063673548497164758947581648273905027617570612", "price": "0.142", "size": "233", "side": "SELL", "timestamp": "1768573794183", "received_at": "2026-01-16T14:29:54.248346"}}
{"event_type": "price_change", "event_ts": "2026-01-16T14:29:54.249105", "ingestion_ts": "2026-01-16T14:30:40.976502", "market_id": "0xb9bbdd34304344dcc45803780a34c97d73a00133a5ecf70f63e1008b8abb2fca", "raw": {"market": "0xb9bbdd34304344dcc45803780a34c97d73a00133a5ecf70f63e1008b8abb2fca", "asset_id": "8682484153073832526711485265636767086525069344085206423986003504588877767339", "price": "0.841", "size": "0", "side": "BUY", "timestamp": "1768573794183", "received_at": "2026-01-16T14:29:54.249105"}}
{"event_type": "price_change", "event_ts": "2026-01-16T14:29:54.249105", "ingestion_ts": "2026-01-16T14:30:40.976502", "market_id": "0xb9bbdd34304344dcc45803780a34c97d73a00133a5ecf70f63e1008b8abb2fca", "raw": {"market": "0xb9bbdd34304344dcc45803780a34c97d73a00133a5ecf70f63e1008b8abb2fca", "asset_id": "72012724360700510767037780555710363830014634797787940282136454146828040926557", "price": "0.159", "size": "0", "side": "SELL", "timestamp": "1768573794183", "received_at": "2026-01-16T14:29:54.249105"}}
{"event_type": "price_change", "event_ts": "2026-01-16T14:29:54.249134", "ingestion_ts": "2026-01-16T14:30:40.976502", "market_id": "0x2393ed0b0fdc450054c7b9071907eca75cf4fc36e385adf4a0a5f99ee62243e8", "raw": {"market": "0x2393ed0b0fdc450054c7b9071907eca75cf4fc36e385adf4a0a5f99ee62243e8", "asset_id": "32769749367306925959219403371425714180265458150646381231272229429098460625924", "price": "0.849", "size": "294", "side": "BUY", "timestamp": "1768573794183", "received_at": "2026-01-16T14:29:54.249134"}}
{"event_type": "price_change", "event_ts": "2026-01-16T14:29:54.249134", "ingestion_ts": "2026-01-16T14:30:40.976502", "market_id": "0x2393ed0b0fdc450054c7b9071907eca75cf4fc36e385adf4a0a5f99ee62243e8", "raw": {"market": "0x2393ed0b0fdc450054c7b9071907eca75cf4fc36e385adf4a0a5f99ee62243e8", "asset_id": "100074770378634056601572485653252702850363676459996771990439989989293515601975", "price": "0.151", "size": "294", "side": "SELL", "timestamp": "1768573794183", "received_at": "2026-01-16T14:29:54.249134"}}
{"event_type": "price_change", "event_ts": "2026-01-16T14:29:54.249147", "ingestion_ts": "2026-01-16T14:30:40.976502", "market_id": "0x44f08744458b8896620cd3330bc5e1ea69df4199b02d4fc583b3fc96e5d314ce", "raw": {"market": "0x44f08744458b8896620cd3330bc5e1ea69df4199b02d4fc583b3fc96e5d314ce", "asset_id": "72327831507226612545928776794104143393438710920370371172884559893525100761096", "price": "0.854", "size": "0", "side": "BUY", "timestamp": "1768573794183", "received_at": "2026-01-16T14:29:54.249147"}}
{"event_type": "price_change", "event_ts": "2026-01-16T14:29:54.249147", "ingestion_ts": "2026-01-16T14:30:40.976502", "market_id": "0x44f08744458b8896620cd3330bc5e1ea69df4199b02d4fc583b3fc96e5d314ce", "raw": {"market": "0x44f08744458b8896620cd3330bc5e1ea69df4199b02d4fc583b3fc96e5d314ce", "asset_id": "49194009556504828848509244326501559253829462790583873936160989575507522044057", "price": "0.146", "size": "0", "side": "SELL", "timestamp": "1768573794183", "received_at": "2026-01-16T14:29:54.249147"}}
{"event_type": "price_change", "event_ts": "2026-01-16T14:29:54.261542", "ingestion_ts": "2026-01-16T14:30:40.976502", "market_id": "0x2393ed0b0fdc450054c7b9071907eca75cf4fc36e385adf4a0a5f99ee62243e8", "raw": {"market": "0x2393ed0b0fdc450054c7b9071907eca75cf4fc36e385adf4a0a5f99ee62243e8", "asset_id": "100074770378634056601572485653252702850363676459996771990439989989293515601975", "price": "0.047", "size": "205", "side": "SELL", "timestamp": "1768573794191", "received_at": "2026-01-16T14:29:54.261542"}}
{"event_type": "price_change", "event_ts": "2026-01-16T14:29:54.261542", "ingestion_ts": "2026-01-16T14:30:40.976502", "market_id": "0x2393ed0b0fdc450054c7b9071907eca75cf4fc36e385adf4a0a5f99ee62243e8", "raw": {"market": "0x2393ed0b0fdc450054c7b9071907eca75cf4fc36e385adf4a0a5f99ee62243e8", "asset_id": "32769749367306925959219403371425714180265458150646381231272229429098460625924", "price": "0.953", "size": "205", "side": "BUY", "timestamp": "1768573794191", "received_at": "2026-01-16T14:29:54.261542"}}
{"event_type": "price_change", "event_ts": "2026-01-16T14:29:54.276407", "ingestion_ts": "2026-01-16T14:30:40.976502", "market_id": "0x2393ed0b0fdc450054c7b9071907eca75cf4fc36e385adf4a0a5f99ee62243e8", "raw": {"market": "0x2393ed0b0fdc450054c7b9071907eca75cf4fc36e385adf4a0a5f99ee62243e8", "asset_id": "32769749367306925959219403371425714180265458150646381231272229429098460625924", "price": "0.811", "size": "10", "side": "BUY", "timestamp": "1768573794226", "received_at": "2026-01-16T14:29:54.276407"}}
{"event_type": "price_change", "event_ts": "2026-01-16T14:29:54.276407", "ingestion_ts": "2026-01-16T14:30:40.976502", "market_id": "0x2393ed0b0fdc450054c7b9071907eca75cf4fc36e385adf4a0a5f99ee62243e8", "raw": {"market": "0x2393ed0b0fdc450054c7b9071907eca75cf4fc36e385adf4a0a5f99ee62243e8", "asset_id": "100074770378634056601572485653252702850363676459996771990439989989293515601975", "price": "0.189", "size": "10", "side": "SELL", "timestamp": "1768573794226", "received_at": "2026-01-16T14:29:54.276407"}}
{"event_type": "price_change", "event_ts": "2026-01-16T14:29:54.276475", "ingestion_ts": "2026-01-16T14:30:40.976502", "market_id": "0x50c669f178da4e5bbea7f1be25041fd278914712fa87a6a6f8e57d5923d88dee", "raw": {"market": "0x50c669f178da4e5bbea7f1be25041fd278914712fa87a6a6f8e57d5923d88dee", "asset_id": "74040420326294854165772767082819937451857852955603897473157746262672057685461", "price": "0.824", "size": "10", "side": "BUY", "timestamp": "1768573794226", "received_at": "2026-01-16T14:29:54.276475"}}
{"event_type": "price_change", "event_ts": "2026-01-16T14:29:54.276475", "ingestion_ts": "2026-01-16T14:30:40.976502", "market_id": "0x50c669f178da4e5bbea7f1be25041fd278914712fa87a6a6f8e57d5923d88dee", "raw": {"market": "0x50c669f178da4e5bbea7f1be25041fd278914712fa87a6a6f8e57d5923d88dee", "asset_id": "24682525479474221428144937281315825971983904267399062415430320764754931667953", "price": "0.176", "size": "10", "side": "SELL", "timestamp": "1768573794226", "received_at": "2026-01-16T14:29:54.276475"}}
{"event_type": "price_change", "event_ts": "2026-01-16T14:29:54.276488", "ingestion_ts": "2026-01-16T14:30:40.976502", "market_id": "0x44f08744458b8896620cd3330bc5e1ea69df4199b02d4fc583b3fc96e5d314ce", "raw": {"market": "0x44f08744458b8896620cd3330bc5e1ea69df4199b02d4fc583b3fc96e5d314ce", "asset_id": "72327831507226612545928776794104143393438710920370371172884559893525100761096", "price": "0.831", "size": "10", "side": "BUY", "timestamp": "1768573794226", "received_at": "2026-01-16T14:29:54.276488"}}
{"event_type": "price_change", "event_ts": "2026-01-16T14:29:54.276488", "ingestion_ts": "2026-01-16T14:30:40.976502", "market_id": "0x44f08744458b8896620cd3330bc5e1ea69df4199b02d4fc583b3fc96e5d314ce", "raw": {"market": "0x44f08744458b8896620cd3330bc5e1ea69df4199b02d4fc583b3fc96e5d314ce", "asset_id": "49194009556504828848509244326501559253829462790583873936160989575507522044057", "price": "0.169", "size": "10", "side": "SELL", "timestamp": "1768573794226", "received_at": "2026-01-16T14:29:54.276488"}}
{"event_type": "price_change", "event_ts": "2026-01-16T14:29:54.276501", "ingestion_ts": "2026-01-16T14:30:40.976502", "market_id": "0x49a20c7523c271099008f3ef9a31521263b24d637959852a391e6b4697b1a437", "raw": {"market": "0x49a20c7523c271099008f3ef9a31521263b24d637959852a391e6b4697b1a437", "asset_id": "55881023621710858558280545117465775643848233756850602339827152783696837905531", "price": "0.847", "size": "10", "side": "BUY", "timestamp": "1768573794226", "received_at": "2026-01-16T14:29:54.276501"}}
{"event_type": "price_change", "event_ts": "2026-01-16T14:29:54.276501", "ingestion_ts": "2026-01-16T14:30:40.976502", "market_id": "0x49a20c7523c271099008f3ef9a31521263b24d637959852a391e6b4697b1a437", "raw": {"market": "0x49a20c7523c271099008f3ef9a31521263b24d637959852a391e6b4697b1a437", "asset_id": "13018971792603393862521629014128024641178044618205296260525674415067194037856", "price": "0.153", "size": "10", "side": "SELL", "timestamp": "1768573794226", "received_at": "2026-01-16T14:29:54.276501"}}
{"event_type": "price_change", "event_ts": "2026-01-16T14:29:54.276512", "ingestion_ts": "2026-01-16T14:30:40.976502", "market_id": "0x9472be65457510b7fc3477b20ba90910e99d92eac8421a14bf4b7b7a08ef31dc", "raw": {"market": "0x9472be65457510b7fc3477b20ba90910e99d92eac8421a14bf4b7b7a08ef31dc", "asset_id": "43311793366960417907757893276427136943959788721376762326430771171648759300146", "price": "0.824", "size": "10", "side": "BUY", "timestamp": "1768573794226", "received_at": "2026-01-16T14:29:54.276512"}}
{"event_type": "price_change", "event_ts": "2026-01-16T14:29:54.276512", "ingestion_ts": "2026-01-16T14:30:40.976502", "market_id": "0x9472be65457510b7fc3477b20ba90910e99d92eac8421a14bf4b7b7a08ef31dc", "raw": {"market": "0x9472be65457510b7fc3477b20ba90910e99d92eac8421a14bf4b7b7a08ef31dc", "asset_id": "73414222381656326204771753454630063673548497164758947581648273905027617570612", "price": "0.176", "size": "10", "side": "SELL", "timestamp": "1768573794226", "received_at": "2026-01-16T14:29:54.276512"}}
{"event_type": "price_change", "event_ts": "2026-01-16T14:29:54.276523", "ingestion_ts": "2026-01-16T14:30:40.976502", "market_id": "0xb9bbdd34304344dcc45803780a34c97d73a00133a5ecf70f63e1008b8abb2fca", "raw": {"market": "0xb9bbdd34304344dcc45803780a34c97d73a00133a5ecf70f63e1008b8abb2fca", "asset_id": "8682484153073832526711485265636767086525069344085206423986003504588877767339", "price": "0.84", "size": "40", "side": "BUY", "timestamp": "1768573794226", "received_at": "2026-01-16T14:29:54.276523"}}
{"event_type": "price_change", "event_ts": "2026-01-16T14:29:54.276523", "ingestion_ts": "2026-01-16T14:30:40.976502", "market_id": "0xb9bbdd34304344dcc45803780a34c97d73a00133a5ecf70f63e1008b8abb2fca", "raw": {"market": "0xb9bbdd34304344dcc45803780a34c97d73a00133a5ecf70f63e1008b8abb2fca", "asset_id": "72012724360700510767037780555710363830014634797787940282136454146828040926557", "price": "0.16", "size": "40", "side": "SELL", "timestamp": "1768573794226", "received_at": "2026-01-16T14:29:54.276523"}}
{"event_type": "price_change", "event_ts": "2026-01-16T14:29:54.276533", "ingestion_ts": "2026-01-16T14:30:40.976502", "market_id": "0xc55db914f0fd1fee18997706712c0dfd8d0369cdbef93a9fef12bd001914ca77", "raw": {"market": "0xc55db914f0fd1fee18997706712c0dfd8d0369cdbef93a9fef12bd001914ca77", "asset_id": "114600293444080540179603459515770723592661967180480327891296353898330242622833", "price": "0.837", "size": "10", "side": "BUY", "timestamp": "1768573794226", "received_at": "2026-01-16T14:29:54.276533"}}
{"event_type": "price_change", "event_ts": "2026-01-16T14:29:54.276533", "ingestion_ts": "2026-01-16T14:30:40.976502", "market_id": "0xc55db914f0fd1fee18997706712c0dfd8d0369cdbef93a9fef12bd001914ca77", "raw": {"market": "0xc55db914f0fd1fee18997706712c0dfd8d0369cdbef93a9fef12bd001914ca77", "asset_id": "72354723612769247426741660426331235762851940382312402276325808095604519806766", "price": "0.163", "size": "10", "side": "SELL", "timestamp": "1768573794226", "received_at": "2026-01-16T14:29:54.276533"}}
{"event_type": "price_change", "event_ts": "2026-01-16T14:29:54.454725", "ingestion_ts": "2026-01-16T14:30:40.976502", "market_id": "0x44f08744458b8896620cd3330bc5e1ea69df4199b02d4fc583b3fc96e5d314ce", "raw": {"market": "0x44f08744458b8896620cd3330bc5e1ea69df4199b02d4fc583b3fc96e5d314ce", "asset_id": "72327831507226612545928776794104143393438710920370371172884559893525100761096", "price": "0.969", "size": "0", "side": "BUY", "timestamp": "1768573794413", "received_at": "2026-01-16T14:29:54.454725"}}
{"event_type": "price_change", "event_ts": "2026-01-16T14:29:54.454725", "ingestion_ts": "2026-01-16T14:30:40.976502", "market_id": "0x44f08744458b8896620cd3330bc5e1ea69df4199b02d4fc583b3fc96e5d314ce", "raw": {"market": "0x44f08744458b8896620cd3330bc5e1ea69df4199b02d4fc583b3fc96e5d314ce", "asset_id": "49194009556504828848509244326501559253829462790583873936160989575507522044057", "price": "0.031", "size": "0", "side": "SELL", "timestamp": "1768573794413", "received_at": "2026-01-16T14:29:54.454725"}}
{"event_type": "price_change", "event_ts": "2026-01-16T14:29:54.493481", "ingestion_ts": "2026-01-16T14:30:40.976502", "market_id": "0x2393ed0b0fdc450054c7b9071907eca75cf4fc36e385adf4a0a5f99ee62243e8", "raw": {"market": "0x2393ed0b0fdc450054c7b9071907eca75cf4fc36e385adf4a0a5f99ee62243e8", "asset_id": "32769749367306925959219403371425714180265458150646381231272229429098460625924", "price": "0.95", "size": "0", "side": "BUY", "timestamp": "1768573794452", "received_at": "2026-01-16T14:29:54.493481"}}
{"event_type": "price_change", "event_ts": "2026-01-16T14:29:54.493481", "ingestion_ts": "2026-01-16T14:30:40.976502", "market_id": "0x2393ed0b0fdc450054c7b9071907eca75cf4fc36e385adf4a0a5f99ee62243e8", "raw": {"market": "0x2393ed0b0fdc450054c7b9071907eca75cf4fc36e385adf4a0a5f99ee62243e8", "asset_id": "100074770378634056601572485653252702850363676459996771990439989989293515601975", "price": "0.05", "size": "0", "side": "SELL", "timestamp": "1768573794452", "received_at": "2026-01-16T14:29:54.493481"}}
{"event_type": "price_change", "event_ts": "2026-01-16T14:29:54.496532", "ingestion_ts": "2026-01-16T14:30:40.976502", "market_id": "0xaf9d0e448129a9f657f851d49495ba4742055d80e0ef1166ba0ee81d4d594214", "raw": {"market": "0xaf9d0e448129a9f657f851d49495ba4742055d80e0ef1166ba0ee81d4d594214", "asset_id": "4153292802911610701832309484716814274802943278345248636922528170020319407796", "price": "0.954", "size": "17.19", "side": "BUY", "timestamp": "1768573794452", "received_at": "2026-01-16T14:29:54.496532"}}
{"event_type": "price_change", "event_ts": "2026-01-16T14:29:54.496532", "ingestion_ts": "2026-01-16T14:30:40.976502", "market_id": "0xaf9d0e448129a9f657f851d49495ba4742055d80e0ef1166ba0ee81d4d594214", "raw": {"market": "0xaf9d0e448129a9f657f851d49495ba4742055d80e0ef1166ba0ee81d4d594214", "asset_id": "101676997363687199724245607342877036148401850938023978421879460310389391082353", "price": "0.046", "size": "17.19", "side": "SELL", "timestamp": "1768573794452", "received_at": "2026-01-16T14:29:54.496532"}}
{"event_type": "price_change", "event_ts": "2026-01-16T14:29:55.481543", "ingestion_ts": "2026-01-16T14:30:40.976502", "market_id": "0x44f08744458b8896620cd3330bc5e1ea69df4199b02d4fc583b3fc96e5d314ce", "raw": {"market": "0x44f08744458b8896620cd3330bc5e1ea69df4199b02d4fc583b3fc96e5d314ce", "asset_id": "72327831507226612545928776794104143393438710920370371172884559893525100761096", "price": "0.967", "size": "75", "side": "BUY", "timestamp": "1768573795417", "received_at": "2026-01-16T14:29:55.481543"}}
{"event_type": "price_change", "event_ts": "2026-01-16T14:29:55.481543", "ingestion_ts": "2026-01-16T14:30:40.976502", "market_id": "0x44f08744458b8896620cd3330bc5e1ea69df4199b02d4fc583b3fc96e5d314ce", "raw": {"market": "0x44f08744458b8896620cd3330bc5e1ea69df4199b02d4fc583b3fc96e5d314ce", "asset_id": "49194009556504828848509244326501559253829462790583873936160989575507522044057", "price": "0.033", "size": "75", "side": "SELL", "timestamp": "1768573795417", "received_at": "2026-01-16T14:29:55.481543"}}
{"event_type": "price_change", "event_ts": "2026-01-16T14:29:57.362429", "ingestion_ts": "2026-01-16T14:30:40.976502", "market_id": "0x49686d26fb712515cd5e12c23f0a1c7e10214c7faa3cb0a730aabe0c33694082", "raw": {"market": "0x49686d26fb712515cd5e12c23f0a1c7e10214c7faa3cb0a730aabe0c33694082", "asset_id": "13244681086321087932946246027856416106585284024824496763706748621681543444582", "price": "0.854", "size": "0", "side": "BUY", "timestamp": "1768573797326", "received_at": "2026-01-16T14:29:57.362429"}}
{"event_type": "price_change", "event_ts": "2026-01-16T14:29:57.362429", "ingestion_ts": "2026-01-16T14:30:40.976502", "market_id": "0x49686d26fb712515cd5e12c23f0a1c7e10214c7faa3cb0a730aabe0c33694082", "raw": {"market": "0x49686d26fb712515cd5e12c23f0a1c7e10214c7faa3cb0a730aabe0c33694082", "asset_id": "30442780799048074404860985387051749017905070253466005720364298335239299761065", "price": "0.146", "size": "0", "side": "SELL", "timestamp": "1768573797326", "received_at": "2026-01-16T14:29:57.362429"}}
{"event_type": "price_change", "event_ts": "2026-01-16T14:29:57.398080", "ingestion_ts": "2026-01-16T14:30:40.976502", "market_id": "0x49686d26fb712515cd5e12c23f0a1c7e10214c7faa3cb0a730aabe0c33694082", "raw": {"market": "0x49686d26fb712515cd5e12c23f0a1c7e10214c7faa3cb0a730aabe0c33694082", "asset_id": "13244681086321087932946246027856416106585284024824496763706748621681543444582", "price": "0.911", "size": "134.98", "side": "SELL", "timestamp": "1768573797354", "received_at": "2026-01-16T14:29:57.398080"}}
{"event_type": "price_change", "event_ts": "2026-01-16T14:29:57.398080", "ingestion_ts": "2026-01-16T14:30:40.976502", "market_id": "0x49686d26fb712515cd5e12c23f0a1c7e10214c7faa3cb0a730aabe0c33694082", "raw": {"market": "0x49686d26fb712515cd5e12c23f0a1c7e10214c7faa3cb0a730aabe0c33694082", "asset_id": "30442780799048074404860985387051749017905070253466005720364298335239299761065", "price": "0.089", "size": "134.98", "side": "BUY", "timestamp": "1768573797354", "received_at": "2026-01-16T14:29:57.398080"}}
{"event_type": "price_change", "event_ts": "2026-01-16T14:29:58.469412", "ingestion_ts": "2026-01-16T14:30:40.976502", "market_id": "0xb9bbdd34304344dcc45803780a34c97d73a00133a5ecf70f63e1008b8abb2fca", "raw": {"market": "0xb9bbdd34304344dcc45803780a34c97d73a00133a5ecf70f63e1008b8abb2fca", "asset_id": "8682484153073832526711485265636767086525069344085206423986003504588877767339", "price": "0.84", "size": "30", "side": "BUY", "timestamp": "1768573798433", "received_at": "2026-01-16T14:29:58.469412"}}
{"event_type": "price_change", "event_ts": "2026-01-16T14:29:58.469412", "ingestion_ts": "2026-01-16T14:30:40.976502", "market_id": "0xb9bbdd34304344dcc45803780a34c97d73a00133a5ecf70f63e1008b8abb2fca", "raw": {"market": "0xb9bbdd34304344dcc45803780a34c97d73a00133a5ecf70f63e1008b8abb2fca", "asset_id": "72012724360700510767037780555710363830014634797787940282136454146828040926557", "price": "0.16", "size": "30", "side": "SELL", "timestamp": "1768573798433", "received_at": "2026-01-16T14:29:58.469412"}}
{"event_type": "price_change", "event_ts": "2026-01-16T14:29:58.471287", "ingestion_ts": "2026-01-16T14:30:40.976502", "market_id": "0x49a20c7523c271099008f3ef9a31521263b24d637959852a391e6b4697b1a437", "raw": {"market": "0x49a20c7523c271099008f3ef9a31521263b24d637959852a391e6b4697b1a437", "asset_id": "55881023621710858558280545117465775643848233756850602339827152783696837905531", "price": "0.847", "size": "0", "side": "BUY", "timestamp": "1768573798433", "received_at": "2026-01-16T14:29:58.471287"}}
{"event_type": "price_change", "event_ts": "2026-01-16T14:29:58.471287", "ingestion_ts": "2026-01-16T14:30:40.976502", "market_id": "0x49a20c7523c271099008f3ef9a31521263b24d637959852a391e6b4697b1a437", "raw": {"market": "0x49a20c7523c271099008f3ef9a31521263b24d637959852a391e6b4697b1a437", "asset_id": "13018971792603393862521629014128024641178044618205296260525674415067194037856", "price": "0.153", "size": "0", "side": "SELL", "timestamp": "1768573798433", "received_at": "2026-01-16T14:29:58.471287"}}
{"event_type": "price_change", "event_ts": "2026-01-16T14:29:58.533378", "ingestion_ts": "2026-01-16T14:30:40.976502", "market_id": "0xb9bbdd34304344dcc45803780a34c97d73a00133a5ecf70f63e1008b8abb2fca", "raw": {"market": "0xb9bbdd34304344dcc45803780a34c97d73a00133a5ecf70f63e1008b8abb2fca", "asset_id": "8682484153073832526711485265636767086525069344085206423986003504588877767339", "price": "0.839", "size": "10", "side": "BUY", "timestamp": "1768573798488", "received_at": "2026-01-16T14:29:58.533378"}}
{"event_type": "price_change", "event_ts": "2026-01-16T14:29:58.533378", "ingestion_ts": "2026-01-16T14:30:40.976502", "market_id": "0xb9bbdd34304344dcc45803780a34c97d73a00133a5ecf70f63e1008b8abb2fca", "raw": {"market": "0xb9bbdd34304344dcc45803780a34c97d73a00133a5ecf70f63e1008b8abb2fca", "asset_id": "72012724360700510767037780555710363830014634797787940282136454146828040926557", "price": "0.161", "size": "10", "side": "SELL", "timestamp": "1768573798488", "received_at": "2026-01-16T14:29:58.533378"}}
{"event_type": "price_change", "event_ts": "2026-01-16T14:29:58.533415", "ingestion_ts": "2026-01-16T14:30:40.976502", "market_id": "0x49a20c7523c271099008f3ef9a31521263b24d637959852a391e6b4697b1a437", "raw": {"market": "0x49a20c7523c271099008f3ef9a31521263b24d637959852a391e6b4697b1a437", "asset_id": "55881023621710858558280545117465775643848233756850602339827152783696837905531", "price": "0.846", "size": "309.79", "side": "BUY", "timestamp": "1768573798488", "received_at": "2026-01-16T14:29:58.533415"}}
{"event_type": "price_change", "event_ts": "2026-01-16T14:29:58.533415", "ingestion_ts": "2026-01-16T14:30:40.976502", "market_id": "0x49a20c7523c271099008f3ef9a31521263b24d637959852a391e6b4697b1a437", "raw": {"market": "0x49a20c7523c271099008f3ef9a31521263b24d637959852a391e6b4697b1a437", "asset_id": "13018971792603393862521629014128024641178044618205296260525674415067194037856", "price": "0.154", "size": "309.79", "side": "SELL", "timestamp": "1768573798488", "received_at": "2026-01-16T14:29:58.533415"}}
{"event_type": "price_change", "event_ts": "2026-01-16T14:29:59.976410", "ingestion_ts": "2026-01-16T14:30:40.976502", "market_id": "0xea644975be7b2ad32b536a94ae21b707ecb2f84290225b24e60ca46dd77903dd", "raw": {"market": "0xea644975be7b2ad32b536a94ae21b707ecb2f84290225b24e60ca46dd77903dd", "asset_id": "19255594762111702415265750364124818677094538461124581923455280001407159960455", "price": "0.252", "size": "0", "side": "BUY", "timestamp": "1768573799127", "received_at": "2026-01-16T14:29:59.976410"}}
{"event_type": "price_change", "event_ts": "2026-01-16T14:29:59.976410", "ingestion_ts": "2026-01-16T14:30:40.976502", "market_id": "0xea644975be7b2ad32b536a94ae21b707ecb2f84290225b24e60ca46dd77903dd", "raw": {"market": "0xea644975be7b2ad32b536a94ae21b707ecb2f84290225b24e60ca46dd77903dd", "asset_id": "110044455628775971785618539427229099821815416148768008176051068105157446559241", "price": "0.748", "size": "0", "side": "SELL", "timestamp": "1768573799127", "received_at": "2026-01-16T14:29:59.976410"}}
{"event_type": "price_change", "event_ts": "2026-01-16T14:29:59.980251", "ingestion_ts": "2026-01-16T14:30:40.976502", "market_id": "0x44f08744458b8896620cd3330bc5e1ea69df4199b02d4fc583b3fc96e5d314ce", "raw": {"market": "0x44f08744458b8896620cd3330bc5e1ea69df4199b02d4fc583b3fc96e5d314ce", "asset_id": "72327831507226612545928776794104143393438710920370371172884559893525100761096", "price": "0.968", "size": "0", "side": "BUY", "timestamp": "1768573799127", "received_at": "2026-01-16T14:29:59.980251"}}
{"event_type": "price_change", "event_ts": "2026-01-16T14:29:59.980251", "ingestion_ts": "2026-01-16T14:30:40.976502", "market_id": "0x44f08744458b8896620cd3330bc5e1ea69df4199b02d4fc583b3fc96e5d314ce", "raw": {"market": "0x44f08744458b8896620cd3330bc5e1ea69df4199b02d4fc583b3fc96e5d314ce", "asset_id": "49194009556504828848509244326501559253829462790583873936160989575507522044057", "price": "0.032", "size": "0", "side": "SELL", "timestamp": "1768573799127", "received_at": "2026-01-16T14:29:59.980251"}}
{"event_type": "price_change", "event_ts": "2026-01-16T14:29:59.980689", "ingestion_ts": "2026-01-16T14:30:40.976502", "market_id": "0x5533fb9ab797777a243c75b1bf3882c54b1ee91f794730c090bf701598993529", "raw": {"market": "0x5533fb9ab797777a243c75b1bf3882c54b1ee91f794730c090bf701598993529", "asset_id": "99478074208094578615268494931219682040135218828258512927013036335093067688695", "price": "0.987", "size": "0", "side": "BUY", "timestamp": "1768573799128", "received_at": "2026-01-16T14:29:59.980689"}}
{"event_type": "price_change", "event_ts": "2026-01-16T14:29:59.980689", "ingestion_ts": "2026-01-16T14:30:40.976502", "market_id": "0x5533fb9ab797777a243c75b1bf3882c54b1ee91f794730c090bf701598993529", "raw": {"market": "0x5533fb9ab797777a243c75b1bf3882c54b1ee91f794730c090bf701598993529", "asset_id": "22532055631814907447535815649879981046415248231878961745474659705989546420934", "price": "0.013", "size": "0", "side": "SELL", "timestamp": "1768573799128", "received_at": "2026-01-16T14:29:59.980689"}}
{"event_type": "price_change", "event_ts": "2026-01-16T14:29:59.997768", "ingestion_ts": "2026-01-16T14:30:40.976502", "market_id": "0xc0e6b917320a47228fb96e3b5ae0e5c93773a5ae2662ae4e1f37807cfe47ce98", "raw": {"market": "0xc0e6b917320a47228fb96e3b5ae0e5c93773a5ae2662ae4e1f37807cfe47ce98", "asset_id": "81647294538046680798858716589766492074338758116170717123345952330712416337530", "price": "0.927", "size": "0", "side": "BUY", "timestamp": "1768573799130", "received_at": "2026-01-16T14:29:59.997768"}}
{"event_type": "price_change", "event_ts": "2026-01-16T14:29:59.997768", "ingestion_ts": "2026-01-16T14:30:40.976502", "market_id": "0xc0e6b917320a47228fb96e3b5ae0e5c93773a5ae2662ae4e1f37807cfe47ce98", "raw": {"market": "0xc0e6b917320a47228fb96e3b5ae0e5c93773a5ae2662ae4e1f37807cfe47ce98", "asset_id": "58656358377246279051017109359677190749228949103591068167284263961542487110215", "price": "0.073", "size": "0", "side": "SELL", "timestamp": "1768573799130", "received_at": "2026-01-16T14:29:59.997768"}}
{"event_type": "price_change", "event_ts": "2026-01-16T14:30:00.016502", "ingestion_ts": "2026-01-16T14:30:40.976502", "market_id": "0xaf9d0e448129a9f657f851d49495ba4742055d80e0ef1166ba0ee81d4d594214", "raw": {"market": "0xaf9d0e448129a9f657f851d49495ba4742055d80e0ef1166ba0ee81d4d594214", "asset_id": "4153292802911610701832309484716814274802943278345248636922528170020319407796", "price": "0.954", "size": "0", "side": "BUY", "timestamp": "1768573799128", "received_at": "2026-01-16T14:30:00.016502"}}
{"event_type": "price_change", "event_ts": "2026-01-16T14:30:00.016502", "ingestion_ts": "2026-01-16T14:30:40.976502", "market_id": "0xaf9d0e448129a9f657f851d49495ba4742055d80e0ef1166ba0ee81d4d594214", "raw": {"market": "0xaf9d0e448129a9f657f851d49495ba4742055d80e0ef1166ba0ee81d4d594214", "asset_id": "101676997363687199724245607342877036148401850938023978421879460310389391082353", "price": "0.046", "size": "0", "side": "SELL", "timestamp": "1768573799128", "received_at": "2026-01-16T14:30:00.016502"}}
{"event_type": "price_change", "event_ts": "2026-01-16T14:30:00.036132", "ingestion_ts": "2026-01-16T14:30:40.976502", "market_id": "0x22ac5f75af18fdb453497fbf7ac0606a09a6fd55b78b2d08aace6b946ad62038", "raw": {"market": "0x22ac5f75af18fdb453497fbf7ac0606a09a6fd55b78b2d08aace6b946ad62038", "asset_id": "59259495934562596318644973716893809974860301509869285036503555129962149752635", "price": "0.949", "size": "9.81", "side": "BUY", "timestamp": "1768573799129", "received_at": "2026-01-16T14:30:00.036132"}}
{"event_type": "price_change", "event_ts": "2026-01-16T14:30:00.036132", "ingestion_ts": "2026-01-16T14:30:40.976502", "market_id": "0x22ac5f75af18fdb453497fbf7ac0606a09a6fd55b78b2d08aace6b946ad62038", "raw": {"market": "0x22ac5f75af18fdb453497fbf7ac0606a09a6fd55b78b2d08aace6b946ad62038", "asset_id": "97449340182256366014320155718265676486703217567849039806162053075113517266910", "price": "0.051", "size": "9.81", "side": "SELL", "timestamp": "1768573799129", "received_at": "2026-01-16T14:30:00.036132"}}
{"event_type": "price_change", "event_ts": "2026-01-16T14:30:00.417118", "ingestion_ts": "2026-01-16T14:30:40.976502", "market_id": "0xaf9d0e448129a9f657f851d49495ba4742055d80e0ef1166ba0ee81d4d594214", "raw": {"market": "0xaf9d0e448129a9f657f851d49495ba4742055d80e0ef1166ba0ee81d4d594214", "asset_id": "4153292802911610701832309484716814274802943278345248636922528170020319407796", "price": "0.987", "size": "140.01", "side": "SELL", "timestamp": "1768573799877", "received_at": "2026-01-16T14:30:00.417118"}}
{"event_type": "price_change", "event_ts": "2026-01-16T14:30:00.417118", "ingestion_ts": "2026-01-16T14:30:40.976502", "market_id": "0xaf9d0e448129a9f657f851d49495ba4742055d80e0ef1166ba0ee81d4d594214", "raw": {"market": "0xaf9d0e448129a9f657f851d49495ba4742055d80e0ef1166ba0ee81d4d594214", "asset_id": "101676997363687199724245607342877036148401850938023978421879460310389391082353", "price": "0.013", "size": "140.01", "side": "BUY", "timestamp": "1768573799877", "received_at": "2026-01-16T14:30:00.417118"}}
{"event_type": "price_change", "event_ts": "2026-01-16T14:30:00.509410", "ingestion_ts": "2026-01-16T14:30:40.976502", "market_id": "0xae5584fbb57f23c1c608d544b656f23d8bf12340cef70811cf31bb0cb4fc2115", "raw": {"market": "0xae5584fbb57f23c1c608d544b656f23d8bf12340cef70811cf31bb0cb4fc2115", "asset_id": "42278252558046940014991595990628759801692726198478046188873057685686228021663", "price": "0.99", "size": "8193.2", "side": "SELL", "timestamp": "1768573799948", "received_at": "2026-01-16T14:30:00.509410"}}
{"event_type": "price_change", "event_ts": "2026-01-16T14:30:00.509410", "ingestion_ts": "2026-01-16T14:30:40.976502", "market_id": "0xae5584fbb57f23c1c608d544b656f23d8bf12340cef70811cf31bb0cb4fc2115", "raw": {"market": "0xae5584fbb57f23c1c608d544b656f23d8bf12340cef70811cf31bb0cb4fc2115", "asset_id": "28946595841244317705636126646676849578876740730186646421280828201004700559420", "price": "0.01", "size": "8193.2", "side": "BUY", "timestamp": "1768573799948", "received_at": "2026-01-16T14:30:00.509410"}}
{"event_type": "price_change", "event_ts": "2026-01-16T14:30:00.627993", "ingestion_ts": "2026-01-16T14:30:40.976502", "market_id": "0xae5584fbb57f23c1c608d544b656f23d8bf12340cef70811cf31bb0cb4fc2115", "raw": {"market": "0xae5584fbb57f23c1c608d544b656f23d8bf12340cef70811cf31bb0cb4fc2115", "asset_id": "28946595841244317705636126646676849578876740730186646421280828201004700559420", "price": "0.01", "size": "8241", "side": "BUY", "timestamp": "1768573800068", "received_at": "2026-01-16T14:30:00.627993"}}
{"event_type": "price_change", "event_ts": "2026-01-16T14:30:00.627993", "ingestion_ts": "2026-01-16T14:30:40.976502", "market_id": "0xae5584fbb57f23c1c608d544b656f23d8bf12340cef70811cf31bb0cb4fc2115", "raw": {"market": "0xae5584fbb57f23c1c608d544b656f23d8bf12340cef70811cf31bb0cb4fc2115", "asset_id": "42278252558046940014991595990628759801692726198478046188873057685686228021663", "price": "0.99", "size": "8241", "side": "SELL", "timestamp": "1768573800068", "received_at": "2026-01-16T14:30:00.627993"}}
{"event_type": "price_change", "event_ts": "2026-01-16T14:30:01.597412", "ingestion_ts": "2026-01-16T14:30:40.976502", "market_id": "0x2393ed0b0fdc450054c7b9071907eca75cf4fc36e385adf4a0a5f99ee62243e8", "raw": {"market": "0x2393ed0b0fdc450054c7b9071907eca75cf4fc36e385adf4a0a5f99ee62243e8", "asset_id": "32769749367306925959219403371425714180265458150646381231272229429098460625924", "price": "0.954", "size": "50", "side": "BUY", "timestamp": "1768573800293", "received_at": "2026-01-16T14:30:01.597412"}}
{"event_type": "price_change", "event_ts": "2026-01-16T14:30:01.597412", "ingestion_ts": "2026-01-16T14:30:40.976502", "market_id": "0x2393ed0b0fdc450054c7b9071907eca75cf4fc36e385adf4a0a5f99ee62243e8", "raw": {"market": "0x2393ed0b0fdc450054c7b9071907eca75cf4fc36e385adf4a0a5f99ee62243e8", "asset_id": "100074770378634056601572485653252702850363676459996771990439989989293515601975", "price": "0.046", "size": "50", "side": "SELL", "timestamp": "1768573800293", "received_at": "2026-01-16T14:30:01.597412"}}
{"event_type": "price_change", "event_ts": "2026-01-16T14:30:01.856108", "ingestion_ts": "2026-01-16T14:30:40.976502", "market_id": "0x2393ed0b0fdc450054c7b9071907eca75cf4fc36e385adf4a0a5f99ee62243e8", "raw": {"market": "0x2393ed0b0fdc450054c7b9071907eca75cf4fc36e385adf4a0a5f99ee62243e8", "asset_id": "32769749367306925959219403371425714180265458150646381231272229429098460625924", "price": "0.952", "size": "0", "side": "BUY", "timestamp": "1768573800619", "received_at": "2026-01-16T14:30:01.856108"}}
{"event_type": "price_change", "event_ts": "2026-01-16T14:30:01.856108", "ingestion_ts": "2026-01-16T14:30:40.976502", "market_id": "0x2393ed0b0fdc450054c7b9071907eca75cf4fc36e385adf4a0a5f99ee62243e8", "raw": {"market": "0x2393ed0b0fdc450054c7b9071907eca75cf4fc36e385adf4a0a5f99ee62243e8", "asset_id": "100074770378634056601572485653252702850363676459996771990439989989293515601975", "price": "0.048", "size": "0", "side": "SELL", "timestamp": "1768573800619", "received_at": "2026-01-16T14:30:01.856108"}}
{"event_type": "price_change", "event_ts": "2026-01-16T14:30:01.913271", "ingestion_ts": "2026-01-16T14:30:40.976502", "market_id": "0xb9bbdd34304344dcc45803780a34c97d73a00133a5ecf70f63e1008b8abb2fca", "raw": {"market": "0xb9bbdd34304344dcc45803780a34c97d73a00133a5ecf70f63e1008b8abb2fca", "asset_id": "8682484153073832526711485265636767086525069344085206423986003504588877767339", "price": "0.839", "size": "0", "side": "BUY", "timestamp": "1768573800698", "received_at": "2026-01-16T14:30:01.913271"}}
{"event_type": "price_change", "event_ts": "2026-01-16T14:30:01.913271", "ingestion_ts": "2026-01-16T14:30:40.976502", "market_id": "0xb9bbdd34304344dcc45803780a34c97d73a00133a5ecf70f63e1008b8abb2fca", "raw": {"market": "0xb9bbdd34304344dcc45803780a34c97d73a00133a5ecf70f63e1008b8abb2fca", "asset_id": "72012724360700510767037780555710363830014634797787940282136454146828040926557", "price": "0.161", "size": "0", "side": "SELL", "timestamp": "1768573800698", "received_at": "2026-01-16T14:30:01.913271"}}
{"event_type": "price_change", "event_ts": "2026-01-16T14:30:01.913310", "ingestion_ts": "2026-01-16T14:30:40.976502", "market_id": "0x49a20c7523c271099008f3ef9a31521263b24d637959852a391e6b4697b1a437", "raw": {"market": "0x49a20c7523c271099008f3ef9a31521263b24d637959852a391e6b4697b1a437", "asset_id": "55881023621710858558280545117465775643848233756850602339827152783696837905531", "price": "0.846", "size": "299.79", "side": "BUY", "timestamp": "1768573800699", "received_at": "2026-01-16T14:30:01.913310"}}
{"event_type": "price_change", "event_ts": "2026-01-16T14:30:01.913310", "ingestion_ts": "2026-01-16T14:30:40.976502", "market_id": "0x49a20c7523c271099008f3ef9a31521263b24d637959852a391e6b4697b1a437", "raw": {"market": "0x49a20c7523c271099008f3ef9a31521263b24d637959852a391e6b4697b1a437", "asset_id": "13018971792603393862521629014128024641178044618205296260525674415067194037856", "price": "0.154", "size": "299.79", "side": "SELL", "timestamp": "1768573800699", "received_at": "2026-01-16T14:30:01.913310"}}
{"event_type": "price_change", "event_ts": "2026-01-16T14:30:01.918786", "ingestion_ts": "2026-01-16T14:30:40.976502", "market_id": "0xb9bbdd34304344dcc45803780a34c97d73a00133a5ecf70f63e1008b8abb2fca", "raw": {"market": "0xb9bbdd34304344dcc45803780a34c97d73a00133a5ecf70f63e1008b8abb2fca", "asset_id": "8682484153073832526711485265636767086525069344085206423986003504588877767339", "price": "0.84", "size": "40", "side": "BUY", "timestamp": "1768573800737", "received_at": "2026-01-16T14:30:01.918786"}}
{"event_type": "price_change", "event_ts": "2026-01-16T14:30:01.918786", "ingestion_ts": "2026-01-16T14:30:40.976502", "market_id": "0xb9bbdd34304344dcc45803780a34c97d73a00133a5ecf70f63e1008b8abb2fca", "raw": {"market": "0xb9bbdd34304344dcc45803780a34c97d73a00133a5ecf70f63e1008b8abb2fca", "asset_id": "72012724360700510767037780555710363830014634797787940282136454146828040926557", "price": "0.16", "size": "40", "side": "SELL", "timestamp": "1768573800737", "received_at": "2026-01-16T14:30:01.918786"}}
{"event_type": "price_change", "event_ts": "2026-01-16T14:30:01.918828", "ingestion_ts": "2026-01-16T14:30:40.976502", "market_id": "0x49a20c7523c271099008f3ef9a31521263b24d637959852a391e6b4697b1a437", "raw": {"market": "0x49a20c7523c271099008f3ef9a31521263b24d637959852a391e6b4697b1a437", "asset_id": "55881023621710858558280545117465775643848233756850602339827152783696837905531", "price": "0.847", "size": "10", "side": "BUY", "timestamp": "1768573800737", "received_at": "2026-01-16T14:30:01.918828"}}
{"event_type": "price_change", "event_ts": "2026-01-16T14:30:01.918828", "ingestion_ts": "2026-01-16T14:30:40.976502", "market_id": "0x49a20c7523c271099008f3ef9a31521263b24d637959852a391e6b4697b1a437", "raw": {"market": "0x49a20c7523c271099008f3ef9a31521263b24d637959852a391e6b4697b1a437", "asset_id": "13018971792603393862521629014128024641178044618205296260525674415067194037856", "price": "0.153", "size": "10", "side": "SELL", "timestamp": "1768573800737", "received_at": "2026-01-16T14:30:01.918828"}}
{"event_type": "price_change", "event_ts": "2026-01-16T14:30:01.927053", "ingestion_ts": "2026-01-16T14:30:40.976502", "market_id": "0xc0e6b917320a47228fb96e3b5ae0e5c93773a5ae2662ae4e1f37807cfe47ce98", "raw": {"market": "0xc0e6b917320a47228fb96e3b5ae0e5c93773a5ae2662ae4e1f37807cfe47ce98", "asset_id": "81647294538046680798858716589766492074338758116170717123345952330712416337530", "price": "0.926", "size": "52.8", "side": "BUY", "timestamp": "1768573800743", "received_at": "2026-01-16T14:30:01.927053"}}
{"event_type": "price_change", "event_ts": "2026-01-16T14:30:01.927053", "ingestion_ts": "2026-01-16T14:30:40.976502", "market_id": "0xc0e6b917320a47228fb96e3b5ae0e5c93773a5ae2662ae4e1f37807cfe47ce98", "raw": {"market": "0xc0e6b917320a47228fb96e3b5ae0e5c93773a5ae2662ae4e1f37807cfe47ce98", "asset_id": "58656358377246279051017109359677190749228949103591068167284263961542487110215", "price": "0.074", "size": "52.8", "side": "SELL", "timestamp": "1768573800743", "received_at": "2026-01-16T14:30:01.927053"}}
{"event_type": "price_change", "event_ts": "2026-01-16T14:30:03.221760", "ingestion_ts": "2026-01-16T14:30:40.976502", "market_id": "0xaf9d0e448129a9f657f851d49495ba4742055d80e0ef1166ba0ee81d4d594214", "raw": {"market": "0xaf9d0e448129a9f657f851d49495ba4742055d80e0ef1166ba0ee81d4d594214", "asset_id": "4153292802911610701832309484716814274802943278345248636922528170020319407796", "price": "0.989", "size": "0", "side": "SELL", "timestamp": "1768573801480", "received_at": "2026-01-16T14:30:03.221760"}}
{"event_type": "price_change", "event_ts": "2026-01-16T14:30:03.221760", "ingestion_ts": "2026-01-16T14:30:40.976502", "market_id": "0xaf9d0e448129a9f657f851d49495ba4742055d80e0ef1166ba0ee81d4d594214", "raw": {"market": "0xaf9d0e448129a9f657f851d49495ba4742055d80e0ef1166ba0ee81d4d594214", "asset_id": "101676997363687199724245607342877036148401850938023978421879460310389391082353", "price": "0.011", "size": "0", "side": "BUY", "timestamp": "1768573801480", "received_at": "2026-01-16T14:30:03.221760"}}
{"event_type": "price_change", "event_ts": "2026-01-16T14:30:03.379294", "ingestion_ts": "2026-01-16T14:30:40.976502", "market_id": "0xaf9d0e448129a9f657f851d49495ba4742055d80e0ef1166ba0ee81d4d594214", "raw": {"market": "0xaf9d0e448129a9f657f851d49495ba4742055d80e0ef1166ba0ee81d4d594214", "asset_id": "4153292802911610701832309484716814274802943278345248636922528170020319407796", "price": "0.986", "size": "20.5", "side": "SELL", "timestamp": "1768573801677", "received_at": "2026-01-16T14:30:03.379294"}}
{"event_type": "price_change", "event_ts": "2026-01-16T14:30:03.379294", "ingestion_ts": "2026-01-16T14:30:40.976502", "market_id": "0xaf9d0e448129a9f657f851d49495ba4742055d80e0ef1166ba0ee81d4d594214", "raw": {"market": "0xaf9d0e448129a9f657f851d49495ba4742055d80e0ef1166ba0ee81d4d594214", "asset_id": "101676997363687199724245607342877036148401850938023978421879460310389391082353", "price": "0.014", "size": "20.5", "side": "BUY", "timestamp": "1768573801677", "received_at": "2026-01-16T14:30:03.379294"}}
{"event_type": "price_change", "event_ts": "2026-01-16T14:30:05.638942", "ingestion_ts": "2026-01-16T14:30:40.976502", "market_id": "0x49686d26fb712515cd5e12c23f0a1c7e10214c7faa3cb0a730aabe0c33694082", "raw": {"market": "0x49686d26fb712515cd5e12c23f0a1c7e10214c7faa3cb0a730aabe0c33694082", "asset_id": "13244681086321087932946246027856416106585284024824496763706748621681543444582", "price": "0.853", "size": "50.86", "side": "BUY", "timestamp": "1768573803434", "received_at": "2026-01-16T14:30:05.638942"}}
{"event_type": "price_change", "event_ts": "2026-01-16T14:30:05.638942", "ingestion_ts": "2026-01-16T14:30:40.976502", "market_id": "0x49686d26fb712515cd5e12c23f0a1c7e10214c7faa3cb0a730aabe0c33694082", "raw": {"market": "0x49686d26fb712515cd5e12c23f0a1c7e10214c7faa3cb0a730aabe0c33694082", "asset_id": "30442780799048074404860985387051749017905070253466005720364298335239299761065", "price": "0.147", "size": "50.86", "side": "SELL", "timestamp": "1768573803434", "received_at": "2026-01-16T14:30:05.638942"}}
{"event_type": "price_change", "event_ts": "2026-01-16T14:30:07.137986", "ingestion_ts": "2026-01-16T14:30:40.976502", "market_id": "0xb9bbdd34304344dcc45803780a34c97d73a00133a5ecf70f63e1008b8abb2fca", "raw": {"market": "0xb9bbdd34304344dcc45803780a34c97d73a00133a5ecf70f63e1008b8abb2fca", "asset_id": "8682484153073832526711485265636767086525069344085206423986003504588877767339", "price": "0.84", "size": "30", "side": "BUY", "timestamp": "1768573804254", "received_at": "2026-01-16T14:30:07.137986"}}
{"event_type": "price_change", "event_ts": "2026-01-16T14:30:07.137986", "ingestion_ts": "2026-01-16T14:30:40.976502", "market_id": "0xb9bbdd34304344dcc45803780a34c97d73a00133a5ecf70f63e1008b8abb2fca", "raw": {"market": "0xb9bbdd34304344dcc45803780a34c97d73a00133a5ecf70f63e1008b8abb2fca", "asset_id": "72012724360700510767037780555710363830014634797787940282136454146828040926557", "price": "0.16", "size": "30", "side": "SELL", "timestamp": "1768573804254", "received_at": "2026-01-16T14:30:07.137986"}}
{"event_type": "price_change", "event_ts": "2026-01-16T14:30:07.138025", "ingestion_ts": "2026-01-16T14:30:40.976502", "market_id": "0xb9bbdd34304344dcc45803780a34c97d73a00133a5ecf70f63e1008b8abb2fca", "raw": {"market": "0xb9bbdd34304344dcc45803780a34c97d73a00133a5ecf70f63e1008b8abb2fca", "asset_id": "8682484153073832526711485265636767086525069344085206423986003504588877767339", "price": "0.841", "size": "10", "side": "BUY", "timestamp": "1768573804288", "received_at": "2026-01-16T14:30:07.138025"}}
{"event_type": "price_change", "event_ts": "2026-01-16T14:30:07.138025", "ingestion_ts": "2026-01-16T14:30:40.976502", "market_id": "0xb9bbdd34304344dcc45803780a34c97d73a00133a5ecf70f63e1008b8abb2fca", "raw": {"market": "0xb9bbdd34304344dcc45803780a34c97d73a00133a5ecf70f63e1008b8abb2fca", "asset_id": "72012724360700510767037780555710363830014634797787940282136454146828040926557", "price": "0.159", "size": "10", "side": "SELL", "timestamp": "1768573804288", "received_at": "2026-01-16T14:30:07.138025"}}
{"event_type": "price_change", "event_ts": "2026-01-16T14:30:07.519069", "ingestion_ts": "2026-01-16T14:30:40.976502", "market_id": "0x49686d26fb712515cd5e12c23f0a1c7e10214c7faa3cb0a730aabe0c33694082", "raw": {"market": "0x49686d26fb712515cd5e12c23f0a1c7e10214c7faa3cb0a730aabe0c33694082", "asset_id": "30442780799048074404860985387051749017905070253466005720364298335239299761065", "price": "0.148", "size": "0", "side": "SELL", "timestamp": "1768573804735", "received_at": "2026-01-16T14:30:07.519069"}}
{"event_type": "price_change", "event_ts": "2026-01-16T14:30:07.519069", "ingestion_ts": "2026-01-16T14:30:40.976502", "market_id": "0x49686d26fb712515cd5e12c23f0a1c7e10214c7faa3cb0a730aabe0c33694082", "raw": {"market": "0x49686d26fb712515cd5e12c23f0a1c7e10214c7faa3cb0a730aabe0c33694082", "asset_id": "13244681086321087932946246027856416106585284024824496763706748621681543444582", "price": "0.852", "size": "0", "side": "BUY", "timestamp": "1768573804735", "received_at": "2026-01-16T14:30:07.519069"}}
{"event_type": "price_change", "event_ts": "2026-01-16T14:30:08.291561", "ingestion_ts": "2026-01-16T14:30:40.976502", "market_id": "0x49686d26fb712515cd5e12c23f0a1c7e10214c7faa3cb0a730aabe0c33694082", "raw": {"market": "0x49686d26fb712515cd5e12c23f0a1c7e10214c7faa3cb0a730aabe0c33694082", "asset_id": "30442780799048074404860985387051749017905070253466005720364298335239299761065", "price": "0.146", "size": "17.5", "side": "SELL", "timestamp": "1768573805613", "received_at": "2026-01-16T14:30:08.291561"}}
{"event_type": "price_change", "event_ts": "2026-01-16T14:30:08.291561", "ingestion_ts": "2026-01-16T14:30:40.976502", "market_id": "0x49686d26fb712515cd5e12c23f0a1c7e10214c7faa3cb0a730aabe0c33694082", "raw": {"market": "0x49686d26fb712515cd5e12c23f0a1c7e10214c7faa3cb0a730aabe0c33694082", "asset_id": "13244681086321087932946246027856416106585284024824496763706748621681543444582", "price": "0.854", "size": "17.5", "side": "BUY", "timestamp": "1768573805613", "received_at": "2026-01-16T14:30:08.291561"}}
{"event_type": "price_change", "event_ts": "2026-01-16T14:30:08.645922", "ingestion_ts": "2026-01-16T14:30:40.976502", "market_id": "0xaf9d0e448129a9f657f851d49495ba4742055d80e0ef1166ba0ee81d4d594214", "raw": {"market": "0xaf9d0e448129a9f657f851d49495ba4742055d80e0ef1166ba0ee81d4d594214", "asset_id": "4153292802911610701832309484716814274802943278345248636922528170020319407796", "price": "0.987", "size": "0", "side": "SELL", "timestamp": "1768573806005", "received_at": "2026-01-16T14:30:08.645922"}}
{"event_type": "price_change", "event_ts": "2026-01-16T14:30:08.645922", "ingestion_ts": "2026-01-16T14:30:40.976502", "market_id": "0xaf9d0e448129a9f657f851d49495ba4742055d80e0ef1166ba0ee81d4d594214", "raw": {"market": "0xaf9d0e448129a9f657f851d49495ba4742055d80e0ef1166ba0ee81d4d594214", "asset_id": "101676997363687199724245607342877036148401850938023978421879460310389391082353", "price": "0.013", "size": "0", "side": "BUY", "timestamp": "1768573806005", "received_at": "2026-01-16T14:30:08.645922"}}
{"event_type": "price_change", "event_ts": "2026-01-16T14:30:08.996524", "ingestion_ts": "2026-01-16T14:30:40.976502", "market_id": "0xaf9d0e448129a9f657f851d49495ba4742055d80e0ef1166ba0ee81d4d594214", "raw": {"market": "0xaf9d0e448129a9f657f851d49495ba4742055d80e0ef1166ba0ee81d4d594214", "asset_id": "4153292802911610701832309484716814274802943278345248636922528170020319407796", "price": "0.985", "size": "140.01", "side": "SELL", "timestamp": "1768573806503", "received_at": "2026-01-16T14:30:08.996524"}}
{"event_type": "price_change", "event_ts": "2026-01-16T14:30:08.996524", "ingestion_ts": "2026-01-16T14:30:40.976502", "market_id": "0xaf9d0e448129a9f657f851d49495ba4742055d80e0ef1166ba0ee81d4d594214", "raw": {"market": "0xaf9d0e448129a9f657f851d49495ba4742055d80e0ef1166ba0ee81d4d594214", "asset_id": "101676997363687199724245607342877036148401850938023978421879460310389391082353", "price": "0.015", "size": "140.01", "side": "BUY", "timestamp": "1768573806503", "received_at": "2026-01-16T14:30:08.996524"}}
{"event_type": "price_change", "event_ts": "2026-01-16T14:30:09.419189", "ingestion_ts": "2026-01-16T14:30:40.976502", "market_id": "0xe9c127a8c35f045d37b5344b0a36711084fa20c2fc1618bf178a5386f90610be", "raw": {"market": "0xe9c127a8c35f045d37b5344b0a36711084fa20c2fc1618bf178a5386f90610be", "asset_id": "107000426448217931795450451304515386602910396776318075817601265223856116134349", "price": "0.992", "size": "40.05", "side": "SELL", "timestamp": "1768573806928", "received_at": "2026-01-16T14:30:09.419189"}}
{"event_type": "price_change", "event_ts": "2026-01-16T14:30:09.419189", "ingestion_ts": "2026-01-16T14:30:40.976502", "market_id": "0xe9c127a8c35f045d37b5344b0a36711084fa20c2fc1618bf178a5386f90610be", "raw": {"market": "0xe9c127a8c35f045d37b5344b0a36711084fa20c2fc1618bf178a5386f90610be", "asset_id": "80230236018433940569996058935444651347308266584430516013229815570706872276819", "price": "0.008", "size": "40.05", "side": "BUY", "timestamp": "1768573806928", "received_at": "2026-01-16T14:30:09.419189"}}
{"event_type": "price_change", "event_ts": "2026-01-16T14:30:09.419207", "ingestion_ts": "2026-01-16T14:30:40.976502", "market_id": "0xe9c127a8c35f045d37b5344b0a36711084fa20c2fc1618bf178a5386f90610be", "raw": {"market": "0xe9c127a8c35f045d37b5344b0a36711084fa20c2fc1618bf178a5386f90610be", "asset_id": "107000426448217931795450451304515386602910396776318075817601265223856116134349", "price": "0.991", "size": "0", "side": "SELL", "timestamp": "1768573806928", "received_at": "2026-01-16T14:30:09.419207"}}
{"event_type": "price_change", "event_ts": "2026-01-16T14:30:09.419207", "ingestion_ts": "2026-01-16T14:30:40.976502", "market_id": "0xe9c127a8c35f045d37b5344b0a36711084fa20c2fc1618bf178a5386f90610be", "raw": {"market": "0xe9c127a8c35f045d37b5344b0a36711084fa20c2fc1618bf178a5386f90610be", "asset_id": "80230236018433940569996058935444651347308266584430516013229815570706872276819", "price": "0.009", "size": "0", "side": "BUY", "timestamp": "1768573806928", "received_at": "2026-01-16T14:30:09.419207"}}
{"event_type": "price_change", "event_ts": "2026-01-16T14:30:09.748117", "ingestion_ts": "2026-01-16T14:30:40.976502", "market_id": "0xaf9d0e448129a9f657f851d49495ba4742055d80e0ef1166ba0ee81d4d594214", "raw": {"market": "0xaf9d0e448129a9f657f851d49495ba4742055d80e0ef1166ba0ee81d4d594214", "asset_id": "4153292802911610701832309484716814274802943278345248636922528170020319407796", "price": "0.986", "size": "0", "side": "SELL", "timestamp": "1768573807193", "received_at": "2026-01-16T14:30:09.748117"}}
{"event_type": "price_change", "event_ts": "2026-01-16T14:30:09.748117", "ingestion_ts": "2026-01-16T14:30:40.976502", "market_id": "0xaf9d0e448129a9f657f851d49495ba4742055d80e0ef1166ba0ee81d4d594214", "raw": {"market": "0xaf9d0e448129a9f657f851d49495ba4742055d80e0ef1166ba0ee81d4d594214", "asset_id": "101676997363687199724245607342877036148401850938023978421879460310389391082353", "price": "0.014", "size": "0", "side": "BUY", "timestamp": "1768573807193", "received_at": "2026-01-16T14:30:09.748117"}}
{"event_type": "price_change", "event_ts": "2026-01-16T14:30:09.748210", "ingestion_ts": "2026-01-16T14:30:40.976502", "market_id": "0xaf9d0e448129a9f657f851d49495ba4742055d80e0ef1166ba0ee81d4d594214", "raw": {"market": "0xaf9d0e448129a9f657f851d49495ba4742055d80e0ef1166ba0ee81d4d594214", "asset_id": "4153292802911610701832309484716814274802943278345248636922528170020319407796", "price": "0.984", "size": "20.5", "side": "SELL", "timestamp": "1768573807252", "received_at": "2026-01-16T14:30:09.748210"}}
{"event_type": "price_change", "event_ts": "2026-01-16T14:30:09.748210", "ingestion_ts": "2026-01-16T14:30:40.976502", "market_id": "0xaf9d0e448129a9f657f851d49495ba4742055d80e0ef1166ba0ee81d4d594214", "raw": {"market": "0xaf9d0e448129a9f657f851d49495ba4742055d80e0ef1166ba0ee81d4d594214", "asset_id": "101676997363687199724245607342877036148401850938023978421879460310389391082353", "price": "0.016", "size": "20.5", "side": "BUY", "timestamp": "1768573807252", "received_at": "2026-01-16T14:30:09.748210"}}
{"event_type": "price_change", "event_ts": "2026-01-16T14:30:09.793309", "ingestion_ts": "2026-01-16T14:30:40.976502", "market_id": "0xe9c127a8c35f045d37b5344b0a36711084fa20c2fc1618bf178a5386f90610be", "raw": {"market": "0xe9c127a8c35f045d37b5344b0a36711084fa20c2fc1618bf178a5386f90610be", "asset_id": "107000426448217931795450451304515386602910396776318075817601265223856116134349", "price": "0.992", "size": "56.05", "side": "SELL", "timestamp": "1768573807301", "received_at": "2026-01-16T14:30:09.793309"}}
{"event_type": "price_change", "event_ts": "2026-01-16T14:30:09.793309", "ingestion_ts": "2026-01-16T14:30:40.976502", "market_id": "0xe9c127a8c35f045d37b5344b0a36711084fa20c2fc1618bf178a5386f90610be", "raw": {"market": "0xe9c127a8c35f045d37b5344b0a36711084fa20c2fc1618bf178a5386f90610be", "asset_id": "80230236018433940569996058935444651347308266584430516013229815570706872276819", "price": "0.008", "size": "56.05", "side": "BUY", "timestamp": "1768573807301", "received_at": "2026-01-16T14:30:09.793309"}}
{"event_type": "price_change", "event_ts": "2026-01-16T14:30:09.793437", "ingestion_ts": "2026-01-16T14:30:40.976502", "market_id": "0xe9c127a8c35f045d37b5344b0a36711084fa20c2fc1618bf178a5386f90610be", "raw": {"market": "0xe9c127a8c35f045d37b5344b0a36711084fa20c2fc1618bf178a5386f90610be", "asset_id": "107000426448217931795450451304515386602910396776318075817601265223856116134349", "price": "0.996", "size": "113.08", "side": "SELL", "timestamp": "1768573807302", "received_at": "2026-01-16T14:30:09.793437"}}
{"event_type": "price_change", "event_ts": "2026-01-16T14:30:09.793437", "ingestion_ts": "2026-01-16T14:30:40.976502", "market_id": "0xe9c127a8c35f045d37b5344b0a36711084fa20c2fc1618bf178a5386f90610be", "raw": {"market": "0xe9c127a8c35f045d37b5344b0a36711084fa20c2fc1618bf178a5386f90610be", "asset_id": "80230236018433940569996058935444651347308266584430516013229815570706872276819", "price": "0.004", "size": "113.08", "side": "BUY", "timestamp": "1768573807302", "received_at": "2026-01-16T14:30:09.793437"}}
{"event_type": "price_change", "event_ts": "2026-01-16T14:30:09.795788", "ingestion_ts": "2026-01-16T14:30:40.976502", "market_id": "0xe9c127a8c35f045d37b5344b0a36711084fa20c2fc1618bf178a5386f90610be", "raw": {"market": "0xe9c127a8c35f045d37b5344b0a36711084fa20c2fc1618bf178a5386f90610be", "asset_id": "107000426448217931795450451304515386602910396776318075817601265223856116134349", "price": "0.995", "size": "123.94", "side": "SELL", "timestamp": "1768573807303", "received_at": "2026-01-16T14:30:09.795788"}}
{"event_type": "price_change", "event_ts": "2026-01-16T14:30:09.795788", "ingestion_ts": "2026-01-16T14:30:40.976502", "market_id": "0xe9c127a8c35f045d37b5344b0a36711084fa20c2fc1618bf178a5386f90610be", "raw": {"market": "0xe9c127a8c35f045d37b5344b0a36711084fa20c2fc1618bf178a5386f90610be", "asset_id": "80230236018433940569996058935444651347308266584430516013229815570706872276819", "price": "0.005", "size": "123.94", "side": "BUY", "timestamp": "1768573807303", "received_at": "2026-01-16T14:30:09.795788"}}
{"event_type": "price_change", "event_ts": "2026-01-16T14:30:10.651811", "ingestion_ts": "2026-01-16T14:30:40.976502", "market_id": "0x49686d26fb712515cd5e12c23f0a1c7e10214c7faa3cb0a730aabe0c33694082", "raw": {"market": "0x49686d26fb712515cd5e12c23f0a1c7e10214c7faa3cb0a730aabe0c33694082", "asset_id": "13244681086321087932946246027856416106585284024824496763706748621681543444582", "price": "0.911", "size": "14.98", "side": "SELL", "timestamp": "1768573808357", "received_at": "2026-01-16T14:30:10.651811"}}
{"event_type": "price_change", "event_ts": "2026-01-16T14:30:10.651811", "ingestion_ts": "2026-01-16T14:30:40.976502", "market_id": "0x49686d26fb712515cd5e12c23f0a1c7e10214c7faa3cb0a730aabe0c33694082", "raw": {"market": "0x49686d26fb712515cd5e12c23f0a1c7e10214c7faa3cb0a730aabe0c33694082", "asset_id": "30442780799048074404860985387051749017905070253466005720364298335239299761065", "price": "0.089", "size": "14.98", "side": "BUY", "timestamp": "1768573808357", "received_at": "2026-01-16T14:30:10.651811"}}
{"event_type": "price_change", "event_ts": "2026-01-16T14:30:13.480418", "ingestion_ts": "2026-01-16T14:30:40.976502", "market_id": "0xc0e6b917320a47228fb96e3b5ae0e5c93773a5ae2662ae4e1f37807cfe47ce98", "raw": {"market": "0xc0e6b917320a47228fb96e3b5ae0e5c93773a5ae2662ae4e1f37807cfe47ce98", "asset_id": "58656358377246279051017109359677190749228949103591068167284263961542487110215", "price": "0.072", "size": "0", "side": "SELL", "timestamp": "1768573811279", "received_at": "2026-01-16T14:30:13.480418"}}
{"event_type": "price_change", "event_ts": "2026-01-16T14:30:13.480418", "ingestion_ts": "2026-01-16T14:30:40.976502", "market_id": "0xc0e6b917320a47228fb96e3b5ae0e5c93773a5ae2662ae4e1f37807cfe47ce98", "raw": {"market": "0xc0e6b917320a47228fb96e3b5ae0e5c93773a5ae2662ae4e1f37807cfe47ce98", "asset_id": "81647294538046680798858716589766492074338758116170717123345952330712416337530", "price": "0.928", "size": "0", "side": "BUY", "timestamp": "1768573811279", "received_at": "2026-01-16T14:30:13.480418"}}
{"event_type": "price_change", "event_ts": "2026-01-16T14:30:14.125603", "ingestion_ts": "2026-01-16T14:30:40.976502", "market_id": "0xe68594f1350f5535532b24979b5b5c1948432cbfc0c363802c32a8f9ab4e6509", "raw": {"market": "0xe68594f1350f5535532b24979b5b5c1948432cbfc0c363802c32a8f9ab4e6509", "asset_id": "3074032031589250926591186368301243337494992039402397918135503567058257050088", "price": "0.304", "size": "0", "side": "BUY", "timestamp": "1768573811991", "received_at": "2026-01-16T14:30:14.125603"}}
{"event_type": "price_change", "event_ts": "2026-01-16T14:30:14.125603", "ingestion_ts": "2026-01-16T14:30:40.976502", "market_id": "0xe68594f1350f5535532b24979b5b5c1948432cbfc0c363802c32a8f9ab4e6509", "raw": {"market": "0xe68594f1350f5535532b24979b5b5c1948432cbfc0c363802c32a8f9ab4e6509", "asset_id": "47459180813047899567328389455747872955901265556145057896316155826890276004242", "price": "0.696", "size": "0", "side": "SELL", "timestamp": "1768573811991", "received_at": "2026-01-16T14:30:14.125603"}}
{"event_type": "price_change", "event_ts": "2026-01-16T14:30:14.204038", "ingestion_ts": "2026-01-16T14:30:40.976502", "market_id": "0xe68594f1350f5535532b24979b5b5c1948432cbfc0c363802c32a8f9ab4e6509", "raw": {"market": "0xe68594f1350f5535532b24979b5b5c1948432cbfc0c363802c32a8f9ab4e6509", "asset_id": "3074032031589250926591186368301243337494992039402397918135503567058257050088", "price": "0.304", "size": "6", "side": "BUY", "timestamp": "1768573812065", "received_at": "2026-01-16T14:30:14.204038"}}
{"event_type": "price_change", "event_ts": "2026-01-16T14:30:14.204038", "ingestion_ts": "2026-01-16T14:30:40.976502", "market_id": "0xe68594f1350f5535532b24979b5b5c1948432cbfc0c363802c32a8f9ab4e6509", "raw": {"market": "0xe68594f1350f5535532b24979b5b5c1948432cbfc0c363802c32a8f9ab4e6509", "asset_id": "47459180813047899567328389455747872955901265556145057896316155826890276004242", "price": "0.696", "size": "6", "side": "SELL", "timestamp": "1768573812065", "received_at": "2026-01-16T14:30:14.204038"}}
{"event_type": "price_change", "event_ts": "2026-01-16T14:30:14.286012", "ingestion_ts": "2026-01-16T14:30:40.976502", "market_id": "0xaf9d0e448129a9f657f851d49495ba4742055d80e0ef1166ba0ee81d4d594214", "raw": {"market": "0xaf9d0e448129a9f657f851d49495ba4742055d80e0ef1166ba0ee81d4d594214", "asset_id": "4153292802911610701832309484716814274802943278345248636922528170020319407796", "price": "0.985", "size": "0", "side": "SELL", "timestamp": "1768573812163", "received_at": "2026-01-16T14:30:14.286012"}}
{"event_type": "price_change", "event_ts": "2026-01-16T14:30:14.286012", "ingestion_ts": "2026-01-16T14:30:40.976502", "market_id": "0xaf9d0e448129a9f657f851d49495ba4742055d80e0ef1166ba0ee81d4d594214", "raw": {"market": "0xaf9d0e448129a9f657f851d49495ba4742055d80e0ef1166ba0ee81d4d594214", "asset_id": "101676997363687199724245607342877036148401850938023978421879460310389391082353", "price": "0.015", "size": "0", "side": "BUY", "timestamp": "1768573812163", "received_at": "2026-01-16T14:30:14.286012"}}
{"event_type": "price_change", "event_ts": "2026-01-16T14:30:14.379507", "ingestion_ts": "2026-01-16T14:30:40.976502", "market_id": "0xc0e6b917320a47228fb96e3b5ae0e5c93773a5ae2662ae4e1f37807cfe47ce98", "raw": {"market": "0xc0e6b917320a47228fb96e3b5ae0e5c93773a5ae2662ae4e1f37807cfe47ce98", "asset_id": "58656358377246279051017109359677190749228949103591068167284263961542487110215", "price": "0.071", "size": "7.5", "side": "SELL", "timestamp": "1768573812305", "received_at": "2026-01-16T14:30:14.379507"}}
{"event_type": "price_change", "event_ts": "2026-01-16T14:30:14.379507", "ingestion_ts": "2026-01-16T14:30:40.976502", "market_id": "0xc0e6b917320a47228fb96e3b5ae0e5c93773a5ae2662ae4e1f37807cfe47ce98", "raw": {"market": "0xc0e6b917320a47228fb96e3b5ae0e5c93773a5ae2662ae4e1f37807cfe47ce98", "asset_id": "81647294538046680798858716589766492074338758116170717123345952330712416337530", "price": "0.929", "size": "7.5", "side": "BUY", "timestamp": "1768573812305", "received_at": "2026-01-16T14:30:14.379507"}}
{"event_type": "price_change", "event_ts": "2026-01-16T14:30:14.580442", "ingestion_ts": "2026-01-16T14:30:40.976502", "market_id": "0xaf9d0e448129a9f657f851d49495ba4742055d80e0ef1166ba0ee81d4d594214", "raw": {"market": "0xaf9d0e448129a9f657f851d49495ba4742055d80e0ef1166ba0ee81d4d594214", "asset_id": "4153292802911610701832309484716814274802943278345248636922528170020319407796", "price": "0.983", "size": "140.01", "side": "SELL", "timestamp": "1768573812568", "received_at": "2026-01-16T14:30:14.580442"}}
{"event_type": "price_change", "event_ts": "2026-01-16T14:30:14.580442", "ingestion_ts": "2026-01-16T14:30:40.976502", "market_id": "0xaf9d0e448129a9f657f851d49495ba4742055d80e0ef1166ba0ee81d4d594214", "raw": {"market": "0xaf9d0e448129a9f657f851d49495ba4742055d80e0ef1166ba0ee81d4d594214", "asset_id": "101676997363687199724245607342877036148401850938023978421879460310389391082353", "price": "0.017", "size": "140.01", "side": "BUY", "timestamp": "1768573812568", "received_at": "2026-01-16T14:30:14.580442"}}
{"event_type": "price_change", "event_ts": "2026-01-16T14:30:15.157228", "ingestion_ts": "2026-01-16T14:30:40.976502", "market_id": "0xaf9d0e448129a9f657f851d49495ba4742055d80e0ef1166ba0ee81d4d594214", "raw": {"market": "0xaf9d0e448129a9f657f851d49495ba4742055d80e0ef1166ba0ee81d4d594214", "asset_id": "4153292802911610701832309484716814274802943278345248636922528170020319407796", "price": "0.984", "size": "0", "side": "SELL", "timestamp": "1768573813281", "received_at": "2026-01-16T14:30:15.157228"}}
{"event_type": "price_change", "event_ts": "2026-01-16T14:30:15.157228", "ingestion_ts": "2026-01-16T14:30:40.976502", "market_id": "0xaf9d0e448129a9f657f851d49495ba4742055d80e0ef1166ba0ee81d4d594214", "raw": {"market": "0xaf9d0e448129a9f657f851d49495ba4742055d80e0ef1166ba0ee81d4d594214", "asset_id": "101676997363687199724245607342877036148401850938023978421879460310389391082353", "price": "0.016", "size": "0", "side": "BUY", "timestamp": "1768573813281", "received_at": "2026-01-16T14:30:15.157228"}}
{"event_type": "price_change", "event_ts": "2026-01-16T14:30:15.191900", "ingestion_ts": "2026-01-16T14:30:40.976502", "market_id": "0xaf9d0e448129a9f657f851d49495ba4742055d80e0ef1166ba0ee81d4d594214", "raw": {"market": "0xaf9d0e448129a9f657f851d49495ba4742055d80e0ef1166ba0ee81d4d594214", "asset_id": "4153292802911610701832309484716814274802943278345248636922528170020319407796", "price": "0.982", "size": "20.5", "side": "SELL", "timestamp": "1768573813341", "received_at": "2026-01-16T14:30:15.191900"}}
{"event_type": "price_change", "event_ts": "2026-01-16T14:30:15.191900", "ingestion_ts": "2026-01-16T14:30:40.976502", "market_id": "0xaf9d0e448129a9f657f851d49495ba4742055d80e0ef1166ba0ee81d4d594214", "raw": {"market": "0xaf9d0e448129a9f657f851d49495ba4742055d80e0ef1166ba0ee81d4d594214", "asset_id": "101676997363687199724245607342877036148401850938023978421879460310389391082353", "price": "0.018", "size": "20.5", "side": "BUY", "timestamp": "1768573813341", "received_at": "2026-01-16T14:30:15.191900"}}
{"event_type": "price_change", "event_ts": "2026-01-16T14:30:17.293097", "ingestion_ts": "2026-01-16T14:30:40.976502", "market_id": "0x49686d26fb712515cd5e12c23f0a1c7e10214c7faa3cb0a730aabe0c33694082", "raw": {"market": "0x49686d26fb712515cd5e12c23f0a1c7e10214c7faa3cb0a730aabe0c33694082", "asset_id": "13244681086321087932946246027856416106585284024824496763706748621681543444582", "price": "0.853", "size": "45", "side": "BUY", "timestamp": "1768573815792", "received_at": "2026-01-16T14:30:17.293097"}}
{"event_type": "price_change", "event_ts": "2026-01-16T14:30:17.293097", "ingestion_ts": "2026-01-16T14:30:40.976502", "market_id": "0x49686d26fb712515cd5e12c23f0a1c7e10214c7faa3cb0a730aabe0c33694082", "raw": {"market": "0x49686d26fb712515cd5e12c23f0a1c7e10214c7faa3cb0a730aabe0c33694082", "asset_id": "30442780799048074404860985387051749017905070253466005720364298335239299761065", "price": "0.147", "size": "45", "side": "SELL", "timestamp": "1768573815792", "received_at": "2026-01-16T14:30:17.293097"}}
{"event_type": "price_change", "event_ts": "2026-01-16T14:30:18.702259", "ingestion_ts": "2026-01-16T14:30:40.976502", "market_id": "0xc55db914f0fd1fee18997706712c0dfd8d0369cdbef93a9fef12bd001914ca77", "raw": {"market": "0xc55db914f0fd1fee18997706712c0dfd8d0369cdbef93a9fef12bd001914ca77", "asset_id": "114600293444080540179603459515770723592661967180480327891296353898330242622833", "price": "0.837", "size": "0", "side": "BUY", "timestamp": "1768573817309", "received_at": "2026-01-16T14:30:18.702259"}}
{"event_type": "price_change", "event_ts": "2026-01-16T14:30:18.702259", "ingestion_ts": "2026-01-16T14:30:40.976502", "market_id": "0xc55db914f0fd1fee18997706712c0dfd8d0369cdbef93a9fef12bd001914ca77", "raw": {"market": "0xc55db914f0fd1fee18997706712c0dfd8d0369cdbef93a9fef12bd001914ca77", "asset_id": "72354723612769247426741660426331235762851940382312402276325808095604519806766", "price": "0.163", "size": "0", "side": "SELL", "timestamp": "1768573817309", "received_at": "2026-01-16T14:30:18.702259"}}
{"event_type": "price_change", "event_ts": "2026-01-16T14:30:18.702295", "ingestion_ts": "2026-01-16T14:30:40.976502", "market_id": "0x44f08744458b8896620cd3330bc5e1ea69df4199b02d4fc583b3fc96e5d314ce", "raw": {"market": "0x44f08744458b8896620cd3330bc5e1ea69df4199b02d4fc583b3fc96e5d314ce", "asset_id": "72327831507226612545928776794104143393438710920370371172884559893525100761096", "price": "0.831", "size": "0", "side": "BUY", "timestamp": "1768573817309", "received_at": "2026-01-16T14:30:18.702295"}}
{"event_type": "price_change", "event_ts": "2026-01-16T14:30:18.702295", "ingestion_ts": "2026-01-16T14:30:40.976502", "market_id": "0x44f08744458b8896620cd3330bc5e1ea69df4199b02d4fc583b3fc96e5d314ce", "raw": {"market": "0x44f08744458b8896620cd3330bc5e1ea69df4199b02d4fc583b3fc96e5d314ce", "asset_id": "49194009556504828848509244326501559253829462790583873936160989575507522044057", "price": "0.169", "size": "0", "side": "SELL", "timestamp": "1768573817309", "received_at": "2026-01-16T14:30:18.702295"}}
{"event_type": "price_change", "event_ts": "2026-01-16T14:30:18.717073", "ingestion_ts": "2026-01-16T14:30:40.976502", "market_id": "0x49686d26fb712515cd5e12c23f0a1c7e10214c7faa3cb0a730aabe0c33694082", "raw": {"market": "0x49686d26fb712515cd5e12c23f0a1c7e10214c7faa3cb0a730aabe0c33694082", "asset_id": "30442780799048074404860985387051749017905070253466005720364298335239299761065", "price": "0.002", "size": "672.74", "side": "BUY", "timestamp": "1768573817344", "received_at": "2026-01-16T14:30:18.717073"}}
{"event_type": "price_change", "event_ts": "2026-01-16T14:30:18.717073", "ingestion_ts": "2026-01-16T14:30:40.976502", "market_id": "0x49686d26fb712515cd5e12c23f0a1c7e10214c7faa3cb0a730aabe0c33694082", "raw": {"market": "0x49686d26fb712515cd5e12c23f0a1c7e10214c7faa3cb0a730aabe0c33694082", "asset_id": "13244681086321087932946246027856416106585284024824496763706748621681543444582", "price": "0.998", "size": "672.74", "side": "SELL", "timestamp": "1768573817344", "received_at": "2026-01-16T14:30:18.717073"}}
{"event_type": "price_change", "event_ts": "2026-01-16T14:30:18.717133", "ingestion_ts": "2026-01-16T14:30:40.976502", "market_id": "0xc55db914f0fd1fee18997706712c0dfd8d0369cdbef93a9fef12bd001914ca77", "raw": {"market": "0xc55db914f0fd1fee18997706712c0dfd8d0369cdbef93a9fef12bd001914ca77", "asset_id": "114600293444080540179603459515770723592661967180480327891296353898330242622833", "price": "0.855", "size": "302", "side": "BUY", "timestamp": "1768573817345", "received_at": "2026-01-16T14:30:18.717133"}}
{"event_type": "price_change", "event_ts": "2026-01-16T14:30:18.717133", "ingestion_ts": "2026-01-16T14:30:40.976502", "market_id": "0xc55db914f0fd1fee18997706712c0dfd8d0369cdbef93a9fef12bd001914ca77", "raw": {"market": "0xc55db914f0fd1fee18997706712c0dfd8d0369cdbef93a9fef12bd001914ca77", "asset_id": "72354723612769247426741660426331235762851940382312402276325808095604519806766", "price": "0.145", "size": "302", "side": "SELL", "timestamp": "1768573817345", "received_at": "2026-01-16T14:30:18.717133"}}
{"event_type": "price_change", "event_ts": "2026-01-16T14:30:18.717533", "ingestion_ts": "2026-01-16T14:30:40.976502", "market_id": "0x44f08744458b8896620cd3330bc5e1ea69df4199b02d4fc583b3fc96e5d314ce", "raw": {"market": "0x44f08744458b8896620cd3330bc5e1ea69df4199b02d4fc583b3fc96e5d314ce", "asset_id": "72327831507226612545928776794104143393438710920370371172884559893525100761096", "price": "0.851", "size": "303", "side": "BUY", "timestamp": "1768573817345", "received_at": "2026-01-16T14:30:18.717533"}}
{"event_type": "price_change", "event_ts": "2026-01-16T14:30:18.717533", "ingestion_ts": "2026-01-16T14:30:40.976502", "market_id": "0x44f08744458b8896620cd3330bc5e1ea69df4199b02d4fc583b3fc96e5d314ce", "raw": {"market": "0x44f08744458b8896620cd3330bc5e1ea69df4199b02d4fc583b3fc96e5d314ce", "asset_id": "49194009556504828848509244326501559253829462790583873936160989575507522044057", "price": "0.149", "size": "303", "side": "SELL", "timestamp": "1768573817345", "received_at": "2026-01-16T14:30:18.717533"}}
{"event_type": "price_change", "event_ts": "2026-01-16T14:30:19.495418", "ingestion_ts": "2026-01-16T14:30:40.976502", "market_id": "0x49686d26fb712515cd5e12c23f0a1c7e10214c7faa3cb0a730aabe0c33694082", "raw": {"market": "0x49686d26fb712515cd5e12c23f0a1c7e10214c7faa3cb0a730aabe0c33694082", "asset_id": "30442780799048074404860985387051749017905070253466005720364298335239299761065", "price": "0.146", "size": "0", "side": "SELL", "timestamp": "1768573818143", "received_at": "2026-01-16T14:30:19.495418"}}
{"event_type": "price_change", "event_ts": "2026-01-16T14:30:19.495418", "ingestion_ts": "2026-01-16T14:30:40.976502", "market_id": "0x49686d26fb712515cd5e12c23f0a1c7e10214c7faa3cb0a730aabe0c33694082", "raw": {"market": "0x49686d26fb712515cd5e12c23f0a1c7e10214c7faa3cb0a730aabe0c33694082", "asset_id": "13244681086321087932946246027856416106585284024824496763706748621681543444582", "price": "0.854", "size": "0", "side": "BUY", "timestamp": "1768573818143", "received_at": "2026-01-16T14:30:19.495418"}}
{"event_type": "price_change", "event_ts": "2026-01-16T14:30:19.532160", "ingestion_ts": "2026-01-16T14:30:40.976502", "market_id": "0x49686d26fb712515cd5e12c23f0a1c7e10214c7faa3cb0a730aabe0c33694082", "raw": {"market": "0x49686d26fb712515cd5e12c23f0a1c7e10214c7faa3cb0a730aabe0c33694082", "asset_id": "30442780799048074404860985387051749017905070253466005720364298335239299761065", "price": "0.148", "size": "17.5", "side": "SELL", "timestamp": "1768573818196", "received_at": "2026-01-16T14:30:19.532160"}}
{"event_type": "price_change", "event_ts": "2026-01-16T14:30:19.532160", "ingestion_ts": "2026-01-16T14:30:40.976502", "market_id": "0x49686d26fb712515cd5e12c23f0a1c7e10214c7faa3cb0a730aabe0c33694082", "raw": {"market": "0x49686d26fb712515cd5e12c23f0a1c7e10214c7faa3cb0a730aabe0c33694082", "asset_id": "13244681086321087932946246027856416106585284024824496763706748621681543444582", "price": "0.852", "size": "17.5", "side": "BUY", "timestamp": "1768573818196", "received_at": "2026-01-16T14:30:19.532160"}}
{"event_type": "price_change", "event_ts": "2026-01-16T14:30:19.552416", "ingestion_ts": "2026-01-16T14:30:40.976502", "market_id": "0xaf9d0e448129a9f657f851d49495ba4742055d80e0ef1166ba0ee81d4d594214", "raw": {"market": "0xaf9d0e448129a9f657f851d49495ba4742055d80e0ef1166ba0ee81d4d594214", "asset_id": "4153292802911610701832309484716814274802943278345248636922528170020319407796", "price": "0.983", "size": "0", "side": "SELL", "timestamp": "1768573818216", "received_at": "2026-01-16T14:30:19.552416"}}
{"event_type": "price_change", "event_ts": "2026-01-16T14:30:19.552416", "ingestion_ts": "2026-01-16T14:30:40.976502", "market_id": "0xaf9d0e448129a9f657f851d49495ba4742055d80e0ef1166ba0ee81d4d594214", "raw": {"market": "0xaf9d0e448129a9f657f851d49495ba4742055d80e0ef1166ba0ee81d4d594214", "asset_id": "101676997363687199724245607342877036148401850938023978421879460310389391082353", "price": "0.017", "size": "0", "side": "BUY", "timestamp": "1768573818216", "received_at": "2026-01-16T14:30:19.552416"}}
{"event_type": "price_change", "event_ts": "2026-01-16T14:30:19.740048", "ingestion_ts": "2026-01-16T14:30:40.976502", "market_id": "0xaf9d0e448129a9f657f851d49495ba4742055d80e0ef1166ba0ee81d4d594214", "raw": {"market": "0xaf9d0e448129a9f657f851d49495ba4742055d80e0ef1166ba0ee81d4d594214", "asset_id": "4153292802911610701832309484716814274802943278345248636922528170020319407796", "price": "0.981", "size": "140.01", "side": "SELL", "timestamp": "1768573818386", "received_at": "2026-01-16T14:30:19.740048"}}
{"event_type": "price_change", "event_ts": "2026-01-16T14:30:19.740048", "ingestion_ts": "2026-01-16T14:30:40.976502", "market_id": "0xaf9d0e448129a9f657f851d49495ba4742055d80e0ef1166ba0ee81d4d594214", "raw": {"market": "0xaf9d0e448129a9f657f851d49495ba4742055d80e0ef1166ba0ee81d4d594214", "asset_id": "101676997363687199724245607342877036148401850938023978421879460310389391082353", "price": "0.019", "size": "140.01", "side": "BUY", "timestamp": "1768573818386", "received_at": "2026-01-16T14:30:19.740048"}}
{"event_type": "price_change", "event_ts": "2026-01-16T14:30:20.673893", "ingestion_ts": "2026-01-16T14:30:40.976502", "market_id": "0xaf9d0e448129a9f657f851d49495ba4742055d80e0ef1166ba0ee81d4d594214", "raw": {"market": "0xaf9d0e448129a9f657f851d49495ba4742055d80e0ef1166ba0ee81d4d594214", "asset_id": "4153292802911610701832309484716814274802943278345248636922528170020319407796", "price": "0.982", "size": "0", "side": "SELL", "timestamp": "1768573819323", "received_at": "2026-01-16T14:30:20.673893"}}
{"event_type": "price_change", "event_ts": "2026-01-16T14:30:20.673893", "ingestion_ts": "2026-01-16T14:30:40.976502", "market_id": "0xaf9d0e448129a9f657f851d49495ba4742055d80e0ef1166ba0ee81d4d594214", "raw": {"market": "0xaf9d0e448129a9f657f851d49495ba4742055d80e0ef1166ba0ee81d4d594214", "asset_id": "101676997363687199724245607342877036148401850938023978421879460310389391082353", "price": "0.018", "size": "0", "side": "BUY", "timestamp": "1768573819323", "received_at": "2026-01-16T14:30:20.673893"}}
{"event_type": "price_change", "event_ts": "2026-01-16T14:30:20.691680", "ingestion_ts": "2026-01-16T14:30:40.976502", "market_id": "0x49686d26fb712515cd5e12c23f0a1c7e10214c7faa3cb0a730aabe0c33694082", "raw": {"market": "0x49686d26fb712515cd5e12c23f0a1c7e10214c7faa3cb0a730aabe0c33694082", "asset_id": "13244681086321087932946246027856416106585284024824496763706748621681543444582", "price": "0.911", "size": "145.98", "side": "SELL", "timestamp": "1768573819348", "received_at": "2026-01-16T14:30:20.691680"}}
{"event_type": "price_change", "event_ts": "2026-01-16T14:30:20.691680", "ingestion_ts": "2026-01-16T14:30:40.976502", "market_id": "0x49686d26fb712515cd5e12c23f0a1c7e10214c7faa3cb0a730aabe0c33694082", "raw": {"market": "0x49686d26fb712515cd5e12c23f0a1c7e10214c7faa3cb0a730aabe0c33694082", "asset_id": "30442780799048074404860985387051749017905070253466005720364298335239299761065", "price": "0.089", "size": "145.98", "side": "BUY", "timestamp": "1768573819348", "received_at": "2026-01-16T14:30:20.691680"}}
{"event_type": "price_change", "event_ts": "2026-01-16T14:30:20.714331", "ingestion_ts": "2026-01-16T14:30:40.976502", "market_id": "0xaf9d0e448129a9f657f851d49495ba4742055d80e0ef1166ba0ee81d4d594214", "raw": {"market": "0xaf9d0e448129a9f657f851d49495ba4742055d80e0ef1166ba0ee81d4d594214", "asset_id": "4153292802911610701832309484716814274802943278345248636922528170020319407796", "price": "0.98", "size": "20.5", "side": "SELL", "timestamp": "1768573819368", "received_at": "2026-01-16T14:30:20.714331"}}
{"event_type": "price_change", "event_ts": "2026-01-16T14:30:20.714331", "ingestion_ts": "2026-01-16T14:30:40.976502", "market_id": "0xaf9d0e448129a9f657f851d49495ba4742055d80e0ef1166ba0ee81d4d594214", "raw": {"market": "0xaf9d0e448129a9f657f851d49495ba4742055d80e0ef1166ba0ee81d4d594214", "asset_id": "101676997363687199724245607342877036148401850938023978421879460310389391082353", "price": "0.02", "size": "20.5", "side": "BUY", "timestamp": "1768573819368", "received_at": "2026-01-16T14:30:20.714331"}}
{"event_type": "price_change", "event_ts": "2026-01-16T14:30:21.539443", "ingestion_ts": "2026-01-16T14:30:40.976502", "market_id": "0x49686d26fb712515cd5e12c23f0a1c7e10214c7faa3cb0a730aabe0c33694082", "raw": {"market": "0x49686d26fb712515cd5e12c23f0a1c7e10214c7faa3cb0a730aabe0c33694082", "asset_id": "30442780799048074404860985387051749017905070253466005720364298335239299761065", "price": "0.002", "size": "662.74", "side": "BUY", "timestamp": "1768573820489", "received_at": "2026-01-16T14:30:21.539443"}}
{"event_type": "price_change", "event_ts": "2026-01-16T14:30:21.539443", "ingestion_ts": "2026-01-16T14:30:40.976502", "market_id": "0x49686d26fb712515cd5e12c23f0a1c7e10214c7faa3cb0a730aabe0c33694082", "raw": {"market": "0x49686d26fb712515cd5e12c23f0a1c7e10214c7faa3cb0a730aabe0c33694082", "asset_id": "13244681086321087932946246027856416106585284024824496763706748621681543444582", "price": "0.998", "size": "662.74", "side": "SELL", "timestamp": "1768573820489", "received_at": "2026-01-16T14:30:21.539443"}}
{"event_type": "price_change", "event_ts": "2026-01-16T14:30:21.556216", "ingestion_ts": "2026-01-16T14:30:40.976502", "market_id": "0x49686d26fb712515cd5e12c23f0a1c7e10214c7faa3cb0a730aabe0c33694082", "raw": {"market": "0x49686d26fb712515cd5e12c23f0a1c7e10214c7faa3cb0a730aabe0c33694082", "asset_id": "30442780799048074404860985387051749017905070253466005720364298335239299761065", "price": "0.003", "size": "36.81", "side": "BUY", "timestamp": "1768573820519", "received_at": "2026-01-16T14:30:21.556216"}}
{"event_type": "price_change", "event_ts": "2026-01-16T14:30:21.556216", "ingestion_ts": "2026-01-16T14:30:40.976502", "market_id": "0x49686d26fb712515cd5e12c23f0a1c7e10214c7faa3cb0a730aabe0c33694082", "raw": {"market": "0x49686d26fb712515cd5e12c23f0a1c7e10214c7faa3cb0a730aabe0c33694082", "asset_id": "13244681086321087932946246027856416106585284024824496763706748621681543444582", "price": "0.997", "size": "36.81", "side": "SELL", "timestamp": "1768573820519", "received_at": "2026-01-16T14:30:21.556216"}}
{"event_type": "price_change", "event_ts": "2026-01-16T14:30:21.561940", "ingestion_ts": "2026-01-16T14:30:40.976502", "market_id": "0xaf9d0e448129a9f657f851d49495ba4742055d80e0ef1166ba0ee81d4d594214", "raw": {"market": "0xaf9d0e448129a9f657f851d49495ba4742055d80e0ef1166ba0ee81d4d594214", "asset_id": "4153292802911610701832309484716814274802943278345248636922528170020319407796", "price": "0.884", "size": "7.37", "side": "BUY", "timestamp": "1768573820522", "received_at": "2026-01-16T14:30:21.561940"}}
{"event_type": "price_change", "event_ts": "2026-01-16T14:30:21.561940", "ingestion_ts": "2026-01-16T14:30:40.976502", "market_id": "0xaf9d0e448129a9f657f851d49495ba4742055d80e0ef1166ba0ee81d4d594214", "raw": {"market": "0xaf9d0e448129a9f657f851d49495ba4742055d80e0ef1166ba0ee81d4d594214", "asset_id": "101676997363687199724245607342877036148401850938023978421879460310389391082353", "price": "0.116", "size": "7.37", "side": "SELL", "timestamp": "1768573820522", "received_at": "2026-01-16T14:30:21.561940"}}
{"event_type": "price_change", "event_ts": "2026-01-16T14:30:21.563378", "ingestion_ts": "2026-01-16T14:30:40.976502", "market_id": "0x49686d26fb712515cd5e12c23f0a1c7e10214c7faa3cb0a730aabe0c33694082", "raw": {"market": "0x49686d26fb712515cd5e12c23f0a1c7e10214c7faa3cb0a730aabe0c33694082", "asset_id": "30442780799048074404860985387051749017905070253466005720364298335239299761065", "price": "0.052", "size": "7.37", "side": "BUY", "timestamp": "1768573820522", "received_at": "2026-01-16T14:30:21.563378"}}
{"event_type": "price_change", "event_ts": "2026-01-16T14:30:21.563378", "ingestion_ts": "2026-01-16T14:30:40.976502", "market_id": "0x49686d26fb712515cd5e12c23f0a1c7e10214c7faa3cb0a730aabe0c33694082", "raw": {"market": "0x49686d26fb712515cd5e12c23f0a1c7e10214c7faa3cb0a730aabe0c33694082", "asset_id": "13244681086321087932946246027856416106585284024824496763706748621681543444582", "price": "0.948", "size": "7.37", "side": "SELL", "timestamp": "1768573820522", "received_at": "2026-01-16T14:30:21.563378"}}
{"event_type": "price_change", "event_ts": "2026-01-16T14:30:21.563410", "ingestion_ts": "2026-01-16T14:30:40.976502", "market_id": "0x2393ed0b0fdc450054c7b9071907eca75cf4fc36e385adf4a0a5f99ee62243e8", "raw": {"market": "0x2393ed0b0fdc450054c7b9071907eca75cf4fc36e385adf4a0a5f99ee62243e8", "asset_id": "32769749367306925959219403371425714180265458150646381231272229429098460625924", "price": "0.894", "size": "7.37", "side": "BUY", "timestamp": "1768573820522", "received_at": "2026-01-16T14:30:21.563410"}}
{"event_type": "price_change", "event_ts": "2026-01-16T14:30:21.563410", "ingestion_ts": "2026-01-16T14:30:40.976502", "market_id": "0x2393ed0b0fdc450054c7b9071907eca75cf4fc36e385adf4a0a5f99ee62243e8", "raw": {"market": "0x2393ed0b0fdc450054c7b9071907eca75cf4fc36e385adf4a0a5f99ee62243e8", "asset_id": "100074770378634056601572485653252702850363676459996771990439989989293515601975", "price": "0.106", "size": "7.37", "side": "SELL", "timestamp": "1768573820522", "received_at": "2026-01-16T14:30:21.563410"}}
{"event_type": "price_change", "event_ts": "2026-01-16T14:30:21.563468", "ingestion_ts": "2026-01-16T14:30:40.976502", "market_id": "0xc55db914f0fd1fee18997706712c0dfd8d0369cdbef93a9fef12bd001914ca77", "raw": {"market": "0xc55db914f0fd1fee18997706712c0dfd8d0369cdbef93a9fef12bd001914ca77", "asset_id": "114600293444080540179603459515770723592661967180480327891296353898330242622833", "price": "0.904", "size": "7.37", "side": "BUY", "timestamp": "1768573820522", "received_at": "2026-01-16T14:30:21.563468"}}
{"event_type": "price_change", "event_ts": "2026-01-16T14:30:21.563468", "ingestion_ts": "2026-01-16T14:30:40.976502", "market_id": "0xc55db914f0fd1fee18997706712c0dfd8d0369cdbef93a9fef12bd001914ca77", "raw": {"market": "0xc55db914f0fd1fee18997706712c0dfd8d0369cdbef93a9fef12bd001914ca77", "asset_id": "72354723612769247426741660426331235762851940382312402276325808095604519806766", "price": "0.096", "size": "7.37", "side": "SELL", "timestamp": "1768573820522", "received_at": "2026-01-16T14:30:21.563468"}}
{"event_type": "price_change", "event_ts": "2026-01-16T14:30:21.564831", "ingestion_ts": "2026-01-16T14:30:40.976502", "market_id": "0x44f08744458b8896620cd3330bc5e1ea69df4199b02d4fc583b3fc96e5d314ce", "raw": {"market": "0x44f08744458b8896620cd3330bc5e1ea69df4199b02d4fc583b3fc96e5d314ce", "asset_id": "72327831507226612545928776794104143393438710920370371172884559893525100761096", "price": "0.9", "size": "7.37", "side": "BUY", "timestamp": "1768573820522", "received_at": "2026-01-16T14:30:21.564831"}}
{"event_type": "price_change", "event_ts": "2026-01-16T14:30:21.564831", "ingestion_ts": "2026-01-16T14:30:40.976502", "market_id": "0x44f08744458b8896620cd3330bc5e1ea69df4199b02d4fc583b3fc96e5d314ce", "raw": {"market": "0x44f08744458b8896620cd3330bc5e1ea69df4199b02d4fc583b3fc96e5d314ce", "asset_id": "49194009556504828848509244326501559253829462790583873936160989575507522044057", "price": "0.1", "size": "7.37", "side": "SELL", "timestamp": "1768573820522", "received_at": "2026-01-16T14:30:21.564831"}}
{"event_type": "price_change", "event_ts": "2026-01-16T14:30:22.262840", "ingestion_ts": "2026-01-16T14:30:40.976502", "market_id": "0x2393ed0b0fdc450054c7b9071907eca75cf4fc36e385adf4a0a5f99ee62243e8", "raw": {"market": "0x2393ed0b0fdc450054c7b9071907eca75cf4fc36e385adf4a0a5f99ee62243e8", "asset_id": "100074770378634056601572485653252702850363676459996771990439989989293515601975", "price": "0.047", "size": "0", "side": "SELL", "timestamp": "1768573821411", "received_at": "2026-01-16T14:30:22.262840"}}
{"event_type": "price_change", "event_ts": "2026-01-16T14:30:22.262840", "ingestion_ts": "2026-01-16T14:30:40.976502", "market_id": "0x2393ed0b0fdc450054c7b9071907eca75cf4fc36e385adf4a0a5f99ee62243e8", "raw": {"market": "0x2393ed0b0fdc450054c7b9071907eca75cf4fc36e385adf4a0a5f99ee62243e8", "asset_id": "32769749367306925959219403371425714180265458150646381231272229429098460625924", "price": "0.953", "size": "0", "side": "BUY", "timestamp": "1768573821411", "received_at": "2026-01-16T14:30:22.262840"}}
{"event_type": "price_change", "event_ts": "2026-01-16T14:30:22.282287", "ingestion_ts": "2026-01-16T14:30:40.976502", "market_id": "0x2393ed0b0fdc450054c7b9071907eca75cf4fc36e385adf4a0a5f99ee62243e8", "raw": {"market": "0x2393ed0b0fdc450054c7b9071907eca75cf4fc36e385adf4a0a5f99ee62243e8", "asset_id": "100074770378634056601572485653252702850363676459996771990439989989293515601975", "price": "0.061", "size": "204", "side": "SELL", "timestamp": "1768573821440", "received_at": "2026-01-16T14:30:22.282287"}}
{"event_type": "price_change", "event_ts": "2026-01-16T14:30:22.282287", "ingestion_ts": "2026-01-16T14:30:40.976502", "market_id": "0x2393ed0b0fdc450054c7b9071907eca75cf4fc36e385adf4a0a5f99ee62243e8", "raw": {"market": "0x2393ed0b0fdc450054c7b9071907eca75cf4fc36e385adf4a0a5f99ee62243e8", "asset_id": "32769749367306925959219403371425714180265458150646381231272229429098460625924", "price": "0.939", "size": "204", "side": "BUY", "timestamp": "1768573821440", "received_at": "2026-01-16T14:30:22.282287"}}
{"event_type": "price_change", "event_ts": "2026-01-16T14:30:22.616112", "ingestion_ts": "2026-01-16T14:30:40.976502", "market_id": "0x49686d26fb712515cd5e12c23f0a1c7e10214c7faa3cb0a730aabe0c33694082", "raw": {"market": "0x49686d26fb712515cd5e12c23f0a1c7e10214c7faa3cb0a730aabe0c33694082", "asset_id": "30442780799048074404860985387051749017905070253466005720364298335239299761065", "price": "0.003", "size": "26.81", "side": "BUY", "timestamp": "1768573822017", "received_at": "2026-01-16T14:30:22.616112"}}
{"event_type": "price_change", "event_ts": "2026-01-16T14:30:22.616112", "ingestion_ts": "2026-01-16T14:30:40.976502", "market_id": "0x49686d26fb712515cd5e12c23f0a1c7e10214c7faa3cb0a730aabe0c33694082", "raw": {"market": "0x49686d26fb712515cd5e12c23f0a1c7e10214c7faa3cb0a730aabe0c33694082", "asset_id": "13244681086321087932946246027856416106585284024824496763706748621681543444582", "price": "0.997", "size": "26.81", "side": "SELL", "timestamp": "1768573822017", "received_at": "2026-01-16T14:30:22.616112"}}
{"event_type": "price_change", "event_ts": "2026-01-16T14:30:22.616150", "ingestion_ts": "2026-01-16T14:30:40.976502", "market_id": "0x49a20c7523c271099008f3ef9a31521263b24d637959852a391e6b4697b1a437", "raw": {"market": "0x49a20c7523c271099008f3ef9a31521263b24d637959852a391e6b4697b1a437", "asset_id": "55881023621710858558280545117465775643848233756850602339827152783696837905531", "price": "0.847", "size": "0", "side": "BUY", "timestamp": "1768573822017", "received_at": "2026-01-16T14:30:22.616150"}}
{"event_type": "price_change", "event_ts": "2026-01-16T14:30:22.616150", "ingestion_ts": "2026-01-16T14:30:40.976502", "market_id": "0x49a20c7523c271099008f3ef9a31521263b24d637959852a391e6b4697b1a437", "raw": {"market": "0x49a20c7523c271099008f3ef9a31521263b24d637959852a391e6b4697b1a437", "asset_id": "13018971792603393862521629014128024641178044618205296260525674415067194037856", "price": "0.153", "size": "0", "side": "SELL", "timestamp": "1768573822017", "received_at": "2026-01-16T14:30:22.616150"}}
{"event_type": "price_change", "event_ts": "2026-01-16T14:30:22.616164", "ingestion_ts": "2026-01-16T14:30:40.976502", "market_id": "0xc55db914f0fd1fee18997706712c0dfd8d0369cdbef93a9fef12bd001914ca77", "raw": {"market": "0xc55db914f0fd1fee18997706712c0dfd8d0369cdbef93a9fef12bd001914ca77", "asset_id": "114600293444080540179603459515770723592661967180480327891296353898330242622833", "price": "0.855", "size": "292", "side": "BUY", "timestamp": "1768573822017", "received_at": "2026-01-16T14:30:22.616164"}}
{"event_type": "price_change", "event_ts": "2026-01-16T14:30:22.616164", "ingestion_ts": "2026-01-16T14:30:40.976502", "market_id": "0xc55db914f0fd1fee18997706712c0dfd8d0369cdbef93a9fef12bd001914ca77", "raw": {"market": "0xc55db914f0fd1fee18997706712c0dfd8d0369cdbef93a9fef12bd001914ca77", "asset_id": "72354723612769247426741660426331235762851940382312402276325808095604519806766", "price": "0.145", "size": "292", "side": "SELL", "timestamp": "1768573822017", "received_at": "2026-01-16T14:30:22.616164"}}
{"event_type": "price_change", "event_ts": "2026-01-16T14:30:22.616176", "ingestion_ts": "2026-01-16T14:30:40.976502", "market_id": "0x50c669f178da4e5bbea7f1be25041fd278914712fa87a6a6f8e57d5923d88dee", "raw": {"market": "0x50c669f178da4e5bbea7f1be25041fd278914712fa87a6a6f8e57d5923d88dee", "asset_id": "74040420326294854165772767082819937451857852955603897473157746262672057685461", "price": "0.824", "size": "0", "side": "BUY", "timestamp": "1768573822017", "received_at": "2026-01-16T14:30:22.616176"}}
{"event_type": "price_change", "event_ts": "2026-01-16T14:30:22.616176", "ingestion_ts": "2026-01-16T14:30:40.976502", "market_id": "0x50c669f178da4e5bbea7f1be25041fd278914712fa87a6a6f8e57d5923d88dee", "raw": {"market": "0x50c669f178da4e5bbea7f1be25041fd278914712fa87a6a6f8e57d5923d88dee", "asset_id": "24682525479474221428144937281315825971983904267399062415430320764754931667953", "price": "0.176", "size": "0", "side": "SELL", "timestamp": "1768573822017", "received_at": "2026-01-16T14:30:22.616176"}}
{"event_type": "price_change", "event_ts": "2026-01-16T14:30:22.616188", "ingestion_ts": "2026-01-16T14:30:40.976502", "market_id": "0x9472be65457510b7fc3477b20ba90910e99d92eac8421a14bf4b7b7a08ef31dc", "raw": {"market": "0x9472be65457510b7fc3477b20ba90910e99d92eac8421a14bf4b7b7a08ef31dc", "asset_id": "43311793366960417907757893276427136943959788721376762326430771171648759300146", "price": "0.824", "size": "0", "side": "BUY", "timestamp": "1768573822017", "received_at": "2026-01-16T14:30:22.616188"}}
{"event_type": "price_change", "event_ts": "2026-01-16T14:30:22.616188", "ingestion_ts": "2026-01-16T14:30:40.976502", "market_id": "0x9472be65457510b7fc3477b20ba90910e99d92eac8421a14bf4b7b7a08ef31dc", "raw": {"market": "0x9472be65457510b7fc3477b20ba90910e99d92eac8421a14bf4b7b7a08ef31dc", "asset_id": "73414222381656326204771753454630063673548497164758947581648273905027617570612", "price": "0.176", "size": "0", "side": "SELL", "timestamp": "1768573822017", "received_at": "2026-01-16T14:30:22.616188"}}
{"event_type": "price_change", "event_ts": "2026-01-16T14:30:22.616198", "ingestion_ts": "2026-01-16T14:30:40.976502", "market_id": "0x44f08744458b8896620cd3330bc5e1ea69df4199b02d4fc583b3fc96e5d314ce", "raw": {"market": "0x44f08744458b8896620cd3330bc5e1ea69df4199b02d4fc583b3fc96e5d314ce", "asset_id": "72327831507226612545928776794104143393438710920370371172884559893525100761096", "price": "0.851", "size": "293", "side": "BUY", "timestamp": "1768573822017", "received_at": "2026-01-16T14:30:22.616198"}}
{"event_type": "price_change", "event_ts": "2026-01-16T14:30:22.616198", "ingestion_ts": "2026-01-16T14:30:40.976502", "market_id": "0x44f08744458b8896620cd3330bc5e1ea69df4199b02d4fc583b3fc96e5d314ce", "raw": {"market": "0x44f08744458b8896620cd3330bc5e1ea69df4199b02d4fc583b3fc96e5d314ce", "asset_id": "49194009556504828848509244326501559253829462790583873936160989575507522044057", "price": "0.149", "size": "293", "side": "SELL", "timestamp": "1768573822017", "received_at": "2026-01-16T14:30:22.616198"}}
{"event_type": "price_change", "event_ts": "2026-01-16T14:30:22.651306", "ingestion_ts": "2026-01-16T14:30:40.976502", "market_id": "0x49a20c7523c271099008f3ef9a31521263b24d637959852a391e6b4697b1a437", "raw": {"market": "0x49a20c7523c271099008f3ef9a31521263b24d637959852a391e6b4697b1a437", "asset_id": "55881023621710858558280545117465775643848233756850602339827152783696837905531", "price": "0.854", "size": "2068.31", "side": "BUY", "timestamp": "1768573822053", "received_at": "2026-01-16T14:30:22.651306"}}
{"event_type": "price_change", "event_ts": "2026-01-16T14:30:22.651306", "ingestion_ts": "2026-01-16T14:30:40.976502", "market_id": "0x49a20c7523c271099008f3ef9a31521263b24d637959852a391e6b4697b1a437", "raw": {"market": "0x49a20c7523c271099008f3ef9a31521263b24d637959852a391e6b4697b1a437", "asset_id": "13018971792603393862521629014128024641178044618205296260525674415067194037856", "price": "0.146", "size": "2068.31", "side": "SELL", "timestamp": "1768573822053", "received_at": "2026-01-16T14:30:22.651306"}}
{"event_type": "price_change", "event_ts": "2026-01-16T14:30:22.651354", "ingestion_ts": "2026-01-16T14:30:40.976502", "market_id": "0x44f08744458b8896620cd3330bc5e1ea69df4199b02d4fc583b3fc96e5d314ce", "raw": {"market": "0x44f08744458b8896620cd3330bc5e1ea69df4199b02d4fc583b3fc96e5d314ce", "asset_id": "72327831507226612545928776794104143393438710920370371172884559893525100761096", "price": "0.852", "size": "10", "side": "BUY", "timestamp": "1768573822053", "received_at": "2026-01-16T14:30:22.651354"}}
{"event_type": "price_change", "event_ts": "2026-01-16T14:30:22.651354", "ingestion_ts": "2026-01-16T14:30:40.976502", "market_id": "0x44f08744458b8896620cd3330bc5e1ea69df4199b02d4fc583b3fc96e5d314ce", "raw": {"market": "0x44f08744458b8896620cd3330bc5e1ea69df4199b02d4fc583b3fc96e5d314ce", "asset_id": "49194009556504828848509244326501559253829462790583873936160989575507522044057", "price": "0.148", "size": "10", "side": "SELL", "timestamp": "1768573822053", "received_at": "2026-01-16T14:30:22.651354"}}
{"event_type": "price_change", "event_ts": "2026-01-16T14:30:22.653731", "ingestion_ts": "2026-01-16T14:30:40.976502", "market_id": "0x9472be65457510b7fc3477b20ba90910e99d92eac8421a14bf4b7b7a08ef31dc", "raw": {"market": "0x9472be65457510b7fc3477b20ba90910e99d92eac8421a14bf4b7b7a08ef31dc", "asset_id": "43311793366960417907757893276427136943959788721376762326430771171648759300146", "price": "0.855", "size": "302", "side": "BUY", "timestamp": "1768573822054", "received_at": "2026-01-16T14:30:22.653731"}}
{"event_type": "price_change", "event_ts": "2026-01-16T14:30:22.653731", "ingestion_ts": "2026-01-16T14:30:40.976502", "market_id": "0x9472be65457510b7fc3477b20ba90910e99d92eac8421a14bf4b7b7a08ef31dc", "raw": {"market": "0x9472be65457510b7fc3477b20ba90910e99d92eac8421a14bf4b7b7a08ef31dc", "asset_id": "73414222381656326204771753454630063673548497164758947581648273905027617570612", "price": "0.145", "size": "302", "side": "SELL", "timestamp": "1768573822054", "received_at": "2026-01-16T14:30:22.653731"}}
{"event_type": "price_change", "event_ts": "2026-01-16T14:30:22.653766", "ingestion_ts": "2026-01-16T14:30:40.976502", "market_id": "0x49686d26fb712515cd5e12c23f0a1c7e10214c7faa3cb0a730aabe0c33694082", "raw": {"market": "0x49686d26fb712515cd5e12c23f0a1c7e10214c7faa3cb0a730aabe0c33694082", "asset_id": "30442780799048074404860985387051749017905070253466005720364298335239299761065", "price": "0.004", "size": "10", "side": "BUY", "timestamp": "1768573822054", "received_at": "2026-01-16T14:30:22.653766"}}
{"event_type": "price_change", "event_ts": "2026-01-16T14:30:22.653766", "ingestion_ts": "2026-01-16T14:30:40.976502", "market_id": "0x49686d26fb712515cd5e12c23f0a1c7e10214c7faa3cb0a730aabe0c33694082", "raw": {"market": "0x49686d26fb712515cd5e12c23f0a1c7e10214c7faa3cb0a730aabe0c33694082", "asset_id": "13244681086321087932946246027856416106585284024824496763706748621681543444582", "price": "0.996", "size": "10", "side": "SELL", "timestamp": "1768573822054", "received_at": "2026-01-16T14:30:22.653766"}}
{"event_type": "price_change", "event_ts": "2026-01-16T14:30:22.653780", "ingestion_ts": "2026-01-16T14:30:40.976502", "market_id": "0x50c669f178da4e5bbea7f1be25041fd278914712fa87a6a6f8e57d5923d88dee", "raw": {"market": "0x50c669f178da4e5bbea7f1be25041fd278914712fa87a6a6f8e57d5923d88dee", "asset_id": "74040420326294854165772767082819937451857852955603897473157746262672057685461", "price": "0.855", "size": "594", "side": "BUY", "timestamp": "1768573822054", "received_at": "2026-01-16T14:30:22.653780"}}
{"event_type": "price_change", "event_ts": "2026-01-16T14:30:22.653780", "ingestion_ts": "2026-01-16T14:30:40.976502", "market_id": "0x50c669f178da4e5bbea7f1be25041fd278914712fa87a6a6f8e57d5923d88dee", "raw": {"market": "0x50c669f178da4e5bbea7f1be25041fd278914712fa87a6a6f8e57d5923d88dee", "asset_id": "24682525479474221428144937281315825971983904267399062415430320764754931667953", "price": "0.145", "size": "594", "side": "SELL", "timestamp": "1768573822054", "received_at": "2026-01-16T14:30:22.653780"}}
{"event_type": "price_change", "event_ts": "2026-01-16T14:30:22.653792", "ingestion_ts": "2026-01-16T14:30:40.976502", "market_id": "0xc55db914f0fd1fee18997706712c0dfd8d0369cdbef93a9fef12bd001914ca77", "raw": {"market": "0xc55db914f0fd1fee18997706712c0dfd8d0369cdbef93a9fef12bd001914ca77", "asset_id": "114600293444080540179603459515770723592661967180480327891296353898330242622833", "price": "0.856", "size": "10", "side": "BUY", "timestamp": "1768573822054", "received_at": "2026-01-16T14:30:22.653792"}}
{"event_type": "price_change", "event_ts": "2026-01-16T14:30:22.653792", "ingestion_ts": "2026-01-16T14:30:40.976502", "market_id": "0xc55db914f0fd1fee18997706712c0dfd8d0369cdbef93a9fef12bd001914ca77", "raw": {"market": "0xc55db914f0fd1fee18997706712c0dfd8d0369cdbef93a9fef12bd001914ca77", "asset_id": "72354723612769247426741660426331235762851940382312402276325808095604519806766", "price": "0.144", "size": "10", "side": "SELL", "timestamp": "1768573822054", "received_at": "2026-01-16T14:30:22.653792"}}
{"event_type": "price_change", "event_ts": "2026-01-16T14:30:22.903674", "ingestion_ts": "2026-01-16T14:30:40.976502", "market_id": "0x49686d26fb712515cd5e12c23f0a1c7e10214c7faa3cb0a730aabe0c33694082", "raw": {"market": "0x49686d26fb712515cd5e12c23f0a1c7e10214c7faa3cb0a730aabe0c33694082", "asset_id": "13244681086321087932946246027856416106585284024824496763706748621681543444582", "price": "0.853", "size": "50.86", "side": "BUY", "timestamp": "1768573822290", "received_at": "2026-01-16T14:30:22.903674"}}
{"event_type": "price_change", "event_ts": "2026-01-16T14:30:22.903674", "ingestion_ts": "2026-01-16T14:30:40.976502", "market_id": "0x49686d26fb712515cd5e12c23f0a1c7e10214c7faa3cb0a730aabe0c33694082", "raw": {"market": "0x49686d26fb712515cd5e12c23f0a1c7e10214c7faa3cb0a730aabe0c33694082", "asset_id": "30442780799048074404860985387051749017905070253466005720364298335239299761065", "price": "0.147", "size": "50.86", "side": "SELL", "timestamp": "1768573822290", "received_at": "2026-01-16T14:30:22.903674"}}
{"event_type": "price_change", "event_ts": "2026-01-16T14:30:23.734098", "ingestion_ts": "2026-01-16T14:30:40.976502", "market_id": "0xc0e6b917320a47228fb96e3b5ae0e5c93773a5ae2662ae4e1f37807cfe47ce98", "raw": {"market": "0xc0e6b917320a47228fb96e3b5ae0e5c93773a5ae2662ae4e1f37807cfe47ce98", "asset_id": "58656358377246279051017109359677190749228949103591068167284263961542487110215", "price": "0.071", "size": "0", "side": "SELL", "timestamp": "1768573823210", "received_at": "2026-01-16T14:30:23.734098"}}
{"event_type": "price_change", "event_ts": "2026-01-16T14:30:23.734098", "ingestion_ts": "2026-01-16T14:30:40.976502", "market_id": "0xc0e6b917320a47228fb96e3b5ae0e5c93773a5ae2662ae4e1f37807cfe47ce98", "raw": {"market": "0xc0e6b917320a47228fb96e3b5ae0e5c93773a5ae2662ae4e1f37807cfe47ce98", "asset_id": "81647294538046680798858716589766492074338758116170717123345952330712416337530", "price": "0.929", "size": "0", "side": "BUY", "timestamp": "1768573823210", "received_at": "2026-01-16T14:30:23.734098"}}
{"event_type": "price_change", "event_ts": "2026-01-16T14:30:24.071853", "ingestion_ts": "2026-01-16T14:30:40.976502", "market_id": "0xae5584fbb57f23c1c608d544b656f23d8bf12340cef70811cf31bb0cb4fc2115", "raw": {"market": "0xae5584fbb57f23c1c608d544b656f23d8bf12340cef70811cf31bb0cb4fc2115", "asset_id": "42278252558046940014991595990628759801692726198478046188873057685686228021663", "price": "0.99", "size": "8138.8", "side": "SELL", "timestamp": "1768573823536", "received_at": "2026-01-16T14:30:24.071853"}}
{"event_type": "price_change", "event_ts": "2026-01-16T14:30:24.071853", "ingestion_ts": "2026-01-16T14:30:40.976502", "market_id": "0xae5584fbb57f23c1c608d544b656f23d8bf12340cef70811cf31bb0cb4fc2115", "raw": {"market": "0xae5584fbb57f23c1c608d544b656f23d8bf12340cef70811cf31bb0cb4fc2115", "asset_id": "28946595841244317705636126646676849578876740730186646421280828201004700559420", "price": "0.01", "size": "8138.8", "side": "BUY", "timestamp": "1768573823536", "received_at": "2026-01-16T14:30:24.071853"}}
{"event_type": "price_change", "event_ts": "2026-01-16T14:30:24.158522", "ingestion_ts": "2026-01-16T14:30:40.976502", "market_id": "0xae5584fbb57f23c1c608d544b656f23d8bf12340cef70811cf31bb0cb4fc2115", "raw": {"market": "0xae5584fbb57f23c1c608d544b656f23d8bf12340cef70811cf31bb0cb4fc2115", "asset_id": "28946595841244317705636126646676849578876740730186646421280828201004700559420", "price": "0.01", "size": "8091", "side": "BUY", "timestamp": "1768573823634", "received_at": "2026-01-16T14:30:24.158522"}}
{"event_type": "price_change", "event_ts": "2026-01-16T14:30:24.158522", "ingestion_ts": "2026-01-16T14:30:40.976502", "market_id": "0xae5584fbb57f23c1c608d544b656f23d8bf12340cef70811cf31bb0cb4fc2115", "raw": {"market": "0xae5584fbb57f23c1c608d544b656f23d8bf12340cef70811cf31bb0cb4fc2115", "asset_id": "42278252558046940014991595990628759801692726198478046188873057685686228021663", "price": "0.99", "size": "8091", "side": "SELL", "timestamp": "1768573823634", "received_at": "2026-01-16T14:30:24.158522"}}
{"event_type": "price_change", "event_ts": "2026-01-16T14:30:24.288889", "ingestion_ts": "2026-01-16T14:30:40.976502", "market_id": "0xc0e6b917320a47228fb96e3b5ae0e5c93773a5ae2662ae4e1f37807cfe47ce98", "raw": {"market": "0xc0e6b917320a47228fb96e3b5ae0e5c93773a5ae2662ae4e1f37807cfe47ce98", "asset_id": "58656358377246279051017109359677190749228949103591068167284263961542487110215", "price": "0.07", "size": "7.5", "side": "SELL", "timestamp": "1768573823841", "received_at": "2026-01-16T14:30:24.288889"}}
{"event_type": "price_change", "event_ts": "2026-01-16T14:30:24.288889", "ingestion_ts": "2026-01-16T14:30:40.976502", "market_id": "0xc0e6b917320a47228fb96e3b5ae0e5c93773a5ae2662ae4e1f37807cfe47ce98", "raw": {"market": "0xc0e6b917320a47228fb96e3b5ae0e5c93773a5ae2662ae4e1f37807cfe47ce98", "asset_id": "81647294538046680798858716589766492074338758116170717123345952330712416337530", "price": "0.93", "size": "7.5", "side": "BUY", "timestamp": "1768573823841", "received_at": "2026-01-16T14:30:24.288889"}}
{"event_type": "price_change", "event_ts": "2026-01-16T14:30:24.607235", "ingestion_ts": "2026-01-16T14:30:40.976502", "market_id": "0xaf9d0e448129a9f657f851d49495ba4742055d80e0ef1166ba0ee81d4d594214", "raw": {"market": "0xaf9d0e448129a9f657f851d49495ba4742055d80e0ef1166ba0ee81d4d594214", "asset_id": "4153292802911610701832309484716814274802943278345248636922528170020319407796", "price": "0.981", "size": "0", "side": "SELL", "timestamp": "1768573824185", "received_at": "2026-01-16T14:30:24.607235"}}
{"event_type": "price_change", "event_ts": "2026-01-16T14:30:24.607235", "ingestion_ts": "2026-01-16T14:30:40.976502", "market_id": "0xaf9d0e448129a9f657f851d49495ba4742055d80e0ef1166ba0ee81d4d594214", "raw": {"market": "0xaf9d0e448129a9f657f851d49495ba4742055d80e0ef1166ba0ee81d4d594214", "asset_id": "101676997363687199724245607342877036148401850938023978421879460310389391082353", "price": "0.019", "size": "0", "side": "BUY", "timestamp": "1768573824185", "received_at": "2026-01-16T14:30:24.607235"}}
{"event_type": "price_change", "event_ts": "2026-01-16T14:30:24.678683", "ingestion_ts": "2026-01-16T14:30:40.976502", "market_id": "0x49686d26fb712515cd5e12c23f0a1c7e10214c7faa3cb0a730aabe0c33694082", "raw": {"market": "0x49686d26fb712515cd5e12c23f0a1c7e10214c7faa3cb0a730aabe0c33694082", "asset_id": "30442780799048074404860985387051749017905070253466005720364298335239299761065", "price": "0.148", "size": "0", "side": "SELL", "timestamp": "1768573824260", "received_at": "2026-01-16T14:30:24.678683"}}
{"event_type": "price_change", "event_ts": "2026-01-16T14:30:24.678683", "ingestion_ts": "2026-01-16T14:30:40.976502", "market_id": "0x49686d26fb712515cd5e12c23f0a1c7e10214c7faa3cb0a730aabe0c33694082", "raw": {"market": "0x49686d26fb712515cd5e12c23f0a1c7e10214c7faa3cb0a730aabe0c33694082", "asset_id": "13244681086321087932946246027856416106585284024824496763706748621681543444582", "price": "0.852", "size": "0", "side": "BUY", "timestamp": "1768573824260", "received_at": "2026-01-16T14:30:24.678683"}}
{"event_type": "price_change", "event_ts": "2026-01-16T14:30:24.796785", "ingestion_ts": "2026-01-16T14:30:40.976502", "market_id": "0x49686d26fb712515cd5e12c23f0a1c7e10214c7faa3cb0a730aabe0c33694082", "raw": {"market": "0x49686d26fb712515cd5e12c23f0a1c7e10214c7faa3cb0a730aabe0c33694082", "asset_id": "30442780799048074404860985387051749017905070253466005720364298335239299761065", "price": "0.146", "size": "17.5", "side": "SELL", "timestamp": "1768573824425", "received_at": "2026-01-16T14:30:24.796785"}}
{"event_type": "price_change", "event_ts": "2026-01-16T14:30:24.796785", "ingestion_ts": "2026-01-16T14:30:40.976502", "market_id": "0x49686d26fb712515cd5e12c23f0a1c7e10214c7faa3cb0a730aabe0c33694082", "raw": {"market": "0x49686d26fb712515cd5e12c23f0a1c7e10214c7faa3cb0a730aabe0c33694082", "asset_id": "13244681086321087932946246027856416106585284024824496763706748621681543444582", "price": "0.854", "size": "17.5", "side": "BUY", "timestamp": "1768573824425", "received_at": "2026-01-16T14:30:24.796785"}}
{"event_type": "price_change", "event_ts": "2026-01-16T14:30:24.890687", "ingestion_ts": "2026-01-16T14:30:40.976502", "market_id": "0x2393ed0b0fdc450054c7b9071907eca75cf4fc36e385adf4a0a5f99ee62243e8", "raw": {"market": "0x2393ed0b0fdc450054c7b9071907eca75cf4fc36e385adf4a0a5f99ee62243e8", "asset_id": "32769749367306925959219403371425714180265458150646381231272229429098460625924", "price": "0.94", "size": "50", "side": "BUY", "timestamp": "1768573824575", "received_at": "2026-01-16T14:30:24.890687"}}
{"event_type": "price_change", "event_ts": "2026-01-16T14:30:24.890687", "ingestion_ts": "2026-01-16T14:30:40.976502", "market_id": "0x2393ed0b0fdc450054c7b9071907eca75cf4fc36e385adf4a0a5f99ee62243e8", "raw": {"market": "0x2393ed0b0fdc450054c7b9071907eca75cf4fc36e385adf4a0a5f99ee62243e8", "asset_id": "100074770378634056601572485653252702850363676459996771990439989989293515601975", "price": "0.06", "size": "50", "side": "SELL", "timestamp": "1768573824575", "received_at": "2026-01-16T14:30:24.890687"}}
{"event_type": "price_change", "event_ts": "2026-01-16T14:30:24.902317", "ingestion_ts": "2026-01-16T14:30:40.976502", "market_id": "0x49686d26fb712515cd5e12c23f0a1c7e10214c7faa3cb0a730aabe0c33694082", "raw": {"market": "0x49686d26fb712515cd5e12c23f0a1c7e10214c7faa3cb0a730aabe0c33694082", "asset_id": "13244681086321087932946246027856416106585284024824496763706748621681543444582", "price": "0.911", "size": "14.98", "side": "SELL", "timestamp": "1768573824600", "received_at": "2026-01-16T14:30:24.902317"}}
{"event_type": "price_change", "event_ts": "2026-01-16T14:30:24.902317", "ingestion_ts": "2026-01-16T14:30:40.976502", "market_id": "0x49686d26fb712515cd5e12c23f0a1c7e10214c7faa3cb0a730aabe0c33694082", "raw": {"market": "0x49686d26fb712515cd5e12c23f0a1c7e10214c7faa3cb0a730aabe0c33694082", "asset_id": "30442780799048074404860985387051749017905070253466005720364298335239299761065", "price": "0.089", "size": "14.98", "side": "BUY", "timestamp": "1768573824600", "received_at": "2026-01-16T14:30:24.902317"}}
{"event_type": "price_change", "event_ts": "2026-01-16T14:30:24.911642", "ingestion_ts": "2026-01-16T14:30:40.976502", "market_id": "0x2393ed0b0fdc450054c7b9071907eca75cf4fc36e385adf4a0a5f99ee62243e8", "raw": {"market": "0x2393ed0b0fdc450054c7b9071907eca75cf4fc36e385adf4a0a5f99ee62243e8", "asset_id": "100074770378634056601572485653252702850363676459996771990439989989293515601975", "price": "0.061", "size": "0", "side": "SELL", "timestamp": "1768573824627", "received_at": "2026-01-16T14:30:24.911642"}}
{"event_type": "price_change", "event_ts": "2026-01-16T14:30:24.911642", "ingestion_ts": "2026-01-16T14:30:40.976502", "market_id": "0x2393ed0b0fdc450054c7b9071907eca75cf4fc36e385adf4a0a5f99ee62243e8", "raw": {"market": "0x2393ed0b0fdc450054c7b9071907eca75cf4fc36e385adf4a0a5f99ee62243e8", "asset_id": "32769749367306925959219403371425714180265458150646381231272229429098460625924", "price": "0.939", "size": "0", "side": "BUY", "timestamp": "1768573824627", "received_at": "2026-01-16T14:30:24.911642"}}
{"event_type": "price_change", "event_ts": "2026-01-16T14:30:24.913319", "ingestion_ts": "2026-01-16T14:30:40.976502", "market_id": "0xaf9d0e448129a9f657f851d49495ba4742055d80e0ef1166ba0ee81d4d594214", "raw": {"market": "0xaf9d0e448129a9f657f851d49495ba4742055d80e0ef1166ba0ee81d4d594214", "asset_id": "4153292802911610701832309484716814274802943278345248636922528170020319407796", "price": "0.979", "size": "140.01", "side": "SELL", "timestamp": "1768573824637", "received_at": "2026-01-16T14:30:24.913319"}}
{"event_type": "price_change", "event_ts": "2026-01-16T14:30:24.913319", "ingestion_ts": "2026-01-16T14:30:40.976502", "market_id": "0xaf9d0e448129a9f657f851d49495ba4742055d80e0ef1166ba0ee81d4d594214", "raw": {"market": "0xaf9d0e448129a9f657f851d49495ba4742055d80e0ef1166ba0ee81d4d594214", "asset_id": "101676997363687199724245607342877036148401850938023978421879460310389391082353", "price": "0.021", "size": "140.01", "side": "BUY", "timestamp": "1768573824637", "received_at": "2026-01-16T14:30:24.913319"}}
