{"event_type": "price_change", "event_ts": "2026-01-14T16:27:41.606286", "ingestion_ts": "2026-01-14T16:33:58.842229", "market_id": "0xe9c127a8c35f045d37b5344b0a36711084fa20c2fc1618bf178a5386f90610be", "raw": {"market": "0xe9c127a8c35f045d37b5344b0a36711084fa20c2fc1618bf178a5386f90610be", "asset_id": "107000426448217931795450451304515386602910396776318075817601265223856116134349", "price": "0.997", "size": "0", "side": "SELL", "timestamp": "1768404461940", "received_at": "2026-01-14T16:27:41.606286"}}
{"event_type": "price_change", "event_ts": "2026-01-14T16:27:41.606286", "ingestion_ts": "2026-01-14T16:33:58.842229", "market_id": "0xe9c127a8c35f045d37b5344b0a36711084fa20c2fc1618bf178a5386f90610be", "raw": {"market": "0xe9c127a8c35f045d37b5344b0a36711084fa20c2fc1618bf178a5386f90610be", "asset_id": "80230236018433940569996058935444651347308266584430516013229815570706872276819", "price": "0.003", "size": "0", "side": "BUY", "timestamp": "1768404461940", "received_at": "2026-01-14T16:27:41.606286"}}
{"event_type": "price_change", "event_ts": "2026-01-14T16:27:41.630274", "ingestion_ts": "2026-01-14T16:33:58.842229", "market_id": "0xe9c127a8c35f045d37b5344b0a36711084fa20c2fc1618bf178a5386f90610be", "raw": {"market": "0xe9c127a8c35f045d37b5344b0a36711084fa20c2fc1618bf178a5386f90610be", "asset_id": "107000426448217931795450451304515386602910396776318075817601265223856116134349", "price": "0.997", "size": "251", "side": "SELL", "timestamp": "1768404461966", "received_at": "2026-01-14T16:27:41.630274"}}
{"event_type": "price_change", "event_ts": "2026-01-14T16:27:41.630274", "ingestion_ts": "2026-01-14T16:33:58.842229", "market_id": "0xe9c127a8c35f045d37b5344b0a36711084fa20c2fc1618bf178a5386f90610be", "raw": {"market": "0xe9c127a8c35f045d37b5344b0a36711084fa20c2fc1618bf178a5386f90610be", "asset_id": "80230236018433940569996058935444651347308266584430516013229815570706872276819", "price": "0.003", "size": "251", "side": "BUY", "timestamp": "1768404461966", "received_at": "2026-01-14T16:27:41.630274"}}
{"event_type": "price_change", "event_ts": "2026-01-14T16:27:43.179611", "ingestion_ts": "2026-01-14T16:33:58.842229", "market_id": "0xe9c127a8c35f045d37b5344b0a36711084fa20c2fc1618bf178a5386f90610be", "raw": {"market": "0xe9c127a8c35f045d37b5344b0a36711084fa20c2fc1618bf178a5386f90610be", "asset_id": "107000426448217931795450451304515386602910396776318075817601265223856116134349", "price": "0.997", "size": "0", "side": "SELL", "timestamp": "1768404463446", "received_at": "2026-01-14T16:27:43.179611"}}
{"event_type": "price_change", "event_ts": "2026-01-14T16:27:43.179611", "ingestion_ts": "2026-01-14T16:33:58.842229", "market_id": "0xe9c127a8c35f045d37b5344b0a36711084fa20c2fc1618bf178a5386f90610be", "raw": {"market": "0xe9c127a8c35f045d37b5344b0a36711084fa20c2fc1618bf178a5386f90610be", "asset_id": "80230236018433940569996058935444651347308266584430516013229815570706872276819", "price": "0.003", "size": "0", "side": "BUY", "timestamp": "1768404463446", "received_at": "2026-01-14T16:27:43.179611"}}
{"event_type": "price_change", "event_ts": "2026-01-14T16:27:43.243657", "ingestion_ts": "2026-01-14T16:33:58.842229", "market_id": "0xe9c127a8c35f045d37b5344b0a36711084fa20c2fc1618bf178a5386f90610be", "raw": {"market": "0xe9c127a8c35f045d37b5344b0a36711084fa20c2fc1618bf178a5386f90610be", "asset_id": "107000426448217931795450451304515386602910396776318075817601265223856116134349", "price": "0.997", "size": "251", "side": "SELL", "timestamp": "1768404463516", "received_at": "2026-01-14T16:27:43.243657"}}
{"event_type": "price_change", "event_ts": "2026-01-14T16:27:43.243657", "ingestion_ts": "2026-01-14T16:33:58.842229", "market_id": "0xe9c127a8c35f045d37b5344b0a36711084fa20c2fc1618bf178a5386f90610be", "raw": {"market": "0xe9c127a8c35f045d37b5344b0a36711084fa20c2fc1618bf178a5386f90610be", "asset_id": "80230236018433940569996058935444651347308266584430516013229815570706872276819", "price": "0.003", "size": "251", "side": "BUY", "timestamp": "1768404463516", "received_at": "2026-01-14T16:27:43.243657"}}
{"event_type": "price_change", "event_ts": "2026-01-14T16:27:44.604297", "ingestion_ts": "2026-01-14T16:33:58.842229", "market_id": "0xe9c127a8c35f045d37b5344b0a36711084fa20c2fc1618bf178a5386f90610be", "raw": {"market": "0xe9c127a8c35f045d37b5344b0a36711084fa20c2fc1618bf178a5386f90610be", "asset_id": "107000426448217931795450451304515386602910396776318075817601265223856116134349", "price": "0.997", "size": "0", "side": "SELL", "timestamp": "1768404464939", "received_at": "2026-01-14T16:27:44.604297"}}
{"event_type": "price_change", "event_ts": "2026-01-14T16:27:44.604297", "ingestion_ts": "2026-01-14T16:33:58.842229", "market_id": "0xe9c127a8c35f045d37b5344b0a36711084fa20c2fc1618bf178a5386f90610be", "raw": {"market": "0xe9c127a8c35f045d37b5344b0a36711084fa20c2fc1618bf178a5386f90610be", "asset_id": "80230236018433940569996058935444651347308266584430516013229815570706872276819", "price": "0.003", "size": "0", "side": "BUY", "timestamp": "1768404464939", "received_at": "2026-01-14T16:27:44.604297"}}
{"event_type": "price_change", "event_ts": "2026-01-14T16:27:44.631801", "ingestion_ts": "2026-01-14T16:33:58.842229", "market_id": "0xe9c127a8c35f045d37b5344b0a36711084fa20c2fc1618bf178a5386f90610be", "raw": {"market": "0xe9c127a8c35f045d37b5344b0a36711084fa20c2fc1618bf178a5386f90610be", "asset_id": "107000426448217931795450451304515386602910396776318075817601265223856116134349", "price": "0.997", "size": "251", "side": "SELL", "timestamp": "1768404464966", "received_at": "2026-01-14T16:27:44.631801"}}
{"event_type": "price_change", "event_ts": "2026-01-14T16:27:44.631801", "ingestion_ts": "2026-01-14T16:33:58.842229", "market_id": "0xe9c127a8c35f045d37b5344b0a36711084fa20c2fc1618bf178a5386f90610be", "raw": {"market": "0xe9c127a8c35f045d37b5344b0a36711084fa20c2fc1618bf178a5386f90610be", "asset_id": "80230236018433940569996058935444651347308266584430516013229815570706872276819", "price": "0.003", "size": "251", "side": "BUY", "timestamp": "1768404464966", "received_at": "2026-01-14T16:27:44.631801"}}
{"event_type": "price_change", "event_ts": "2026-01-14T16:27:46.109219", "ingestion_ts": "2026-01-14T16:33:58.842229", "market_id": "0xe9c127a8c35f045d37b5344b0a36711084fa20c2fc1618bf178a5386f90610be", "raw": {"market": "0xe9c127a8c35f045d37b5344b0a36711084fa20c2fc1618bf178a5386f90610be", "asset_id": "107000426448217931795450451304515386602910396776318075817601265223856116134349", "price": "0.997", "size": "0", "side": "SELL", "timestamp": "1768404466437", "received_at": "2026-01-14T16:27:46.109219"}}
{"event_type": "price_change", "event_ts": "2026-01-14T16:27:46.109219", "ingestion_ts": "2026-01-14T16:33:58.842229", "market_id": "0xe9c127a8c35f045d37b5344b0a36711084fa20c2fc1618bf178a5386f90610be", "raw": {"market": "0xe9c127a8c35f045d37b5344b0a36711084fa20c2fc1618bf178a5386f90610be", "asset_id": "80230236018433940569996058935444651347308266584430516013229815570706872276819", "price": "0.003", "size": "0", "side": "BUY", "timestamp": "1768404466437", "received_at": "2026-01-14T16:27:46.109219"}}
{"event_type": "price_change", "event_ts": "2026-01-14T16:27:46.131349", "ingestion_ts": "2026-01-14T16:33:58.842229", "market_id": "0xe9c127a8c35f045d37b5344b0a36711084fa20c2fc1618bf178a5386f90610be", "raw": {"market": "0xe9c127a8c35f045d37b5344b0a36711084fa20c2fc1618bf178a5386f90610be", "asset_id": "107000426448217931795450451304515386602910396776318075817601265223856116134349", "price": "0.997", "size": "251", "side": "SELL", "timestamp": "1768404466466", "received_at": "2026-01-14T16:27:46.131349"}}
{"event_type": "price_change", "event_ts": "2026-01-14T16:27:46.131349", "ingestion_ts": "2026-01-14T16:33:58.842229", "market_id": "0xe9c127a8c35f045d37b5344b0a36711084fa20c2fc1618bf178a5386f90610be", "raw": {"market": "0xe9c127a8c35f045d37b5344b0a36711084fa20c2fc1618bf178a5386f90610be", "asset_id": "80230236018433940569996058935444651347308266584430516013229815570706872276819", "price": "0.003", "size": "251", "side": "BUY", "timestamp": "1768404466466", "received_at": "2026-01-14T16:27:46.131349"}}
{"event_type": "price_change", "event_ts": "2026-01-14T16:27:47.606640", "ingestion_ts": "2026-01-14T16:33:58.842229", "market_id": "0xe9c127a8c35f045d37b5344b0a36711084fa20c2fc1618bf178a5386f90610be", "raw": {"market": "0xe9c127a8c35f045d37b5344b0a36711084fa20c2fc1618bf178a5386f90610be", "asset_id": "107000426448217931795450451304515386602910396776318075817601265223856116134349", "price": "0.997", "size": "0", "side": "SELL", "timestamp": "1768404467939", "received_at": "2026-01-14T16:27:47.606640"}}
{"event_type": "price_change", "event_ts": "2026-01-14T16:27:47.606640", "ingestion_ts": "2026-01-14T16:33:58.842229", "market_id": "0xe9c127a8c35f045d37b5344b0a36711084fa20c2fc1618bf178a5386f90610be", "raw": {"market": "0xe9c127a8c35f045d37b5344b0a36711084fa20c2fc1618bf178a5386f90610be", "asset_id": "80230236018433940569996058935444651347308266584430516013229815570706872276819", "price": "0.003", "size": "0", "side": "BUY", "timestamp": "1768404467939", "received_at": "2026-01-14T16:27:47.606640"}}
{"event_type": "price_change", "event_ts": "2026-01-14T16:27:47.631490", "ingestion_ts": "2026-01-14T16:33:58.842229", "market_id": "0xe9c127a8c35f045d37b5344b0a36711084fa20c2fc1618bf178a5386f90610be", "raw": {"market": "0xe9c127a8c35f045d37b5344b0a36711084fa20c2fc1618bf178a5386f90610be", "asset_id": "107000426448217931795450451304515386602910396776318075817601265223856116134349", "price": "0.997", "size": "251", "side": "SELL", "timestamp": "1768404467967", "received_at": "2026-01-14T16:27:47.631490"}}
{"event_type": "price_change", "event_ts": "2026-01-14T16:27:47.631490", "ingestion_ts": "2026-01-14T16:33:58.842229", "market_id": "0xe9c127a8c35f045d37b5344b0a36711084fa20c2fc1618bf178a5386f90610be", "raw": {"market": "0xe9c127a8c35f045d37b5344b0a36711084fa20c2fc1618bf178a5386f90610be", "asset_id": "80230236018433940569996058935444651347308266584430516013229815570706872276819", "price": "0.003", "size": "251", "side": "BUY", "timestamp": "1768404467967", "received_at": "2026-01-14T16:27:47.631490"}}
{"event_type": "price_change", "event_ts": "2026-01-14T16:27:49.113456", "ingestion_ts": "2026-01-14T16:33:58.842229", "market_id": "0xe9c127a8c35f045d37b5344b0a36711084fa20c2fc1618bf178a5386f90610be", "raw": {"market": "0xe9c127a8c35f045d37b5344b0a36711084fa20c2fc1618bf178a5386f90610be", "asset_id": "107000426448217931795450451304515386602910396776318075817601265223856116134349", "price": "0.997", "size": "0", "side": "SELL", "timestamp": "1768404469441", "received_at": "2026-01-14T16:27:49.113456"}}
{"event_type": "price_change", "event_ts": "2026-01-14T16:27:49.113456", "ingestion_ts": "2026-01-14T16:33:58.842229", "market_id": "0xe9c127a8c35f045d37b5344b0a36711084fa20c2fc1618bf178a5386f90610be", "raw": {"market": "0xe9c127a8c35f045d37b5344b0a36711084fa20c2fc1618bf178a5386f90610be", "asset_id": "80230236018433940569996058935444651347308266584430516013229815570706872276819", "price": "0.003", "size": "0", "side": "BUY", "timestamp": "1768404469441", "received_at": "2026-01-14T16:27:49.113456"}}
{"event_type": "price_change", "event_ts": "2026-01-14T16:27:49.153169", "ingestion_ts": "2026-01-14T16:33:58.842229", "market_id": "0xe9c127a8c35f045d37b5344b0a36711084fa20c2fc1618bf178a5386f90610be", "raw": {"market": "0xe9c127a8c35f045d37b5344b0a36711084fa20c2fc1618bf178a5386f90610be", "asset_id": "107000426448217931795450451304515386602910396776318075817601265223856116134349", "price": "0.997", "size": "251", "side": "SELL", "timestamp": "1768404469486", "received_at": "2026-01-14T16:27:49.153169"}}
{"event_type": "price_change", "event_ts": "2026-01-14T16:27:49.153169", "ingestion_ts": "2026-01-14T16:33:58.842229", "market_id": "0xe9c127a8c35f045d37b5344b0a36711084fa20c2fc1618bf178a5386f90610be", "raw": {"market": "0xe9c127a8c35f045d37b5344b0a36711084fa20c2fc1618bf178a5386f90610be", "asset_id": "80230236018433940569996058935444651347308266584430516013229815570706872276819", "price": "0.003", "size": "251", "side": "BUY", "timestamp": "1768404469486", "received_at": "2026-01-14T16:27:49.153169"}}
{"event_type": "price_change", "event_ts": "2026-01-14T16:27:50.624426", "ingestion_ts": "2026-01-14T16:33:58.842229", "market_id": "0xe9c127a8c35f045d37b5344b0a36711084fa20c2fc1618bf178a5386f90610be", "raw": {"market": "0xe9c127a8c35f045d37b5344b0a36711084fa20c2fc1618bf178a5386f90610be", "asset_id": "107000426448217931795450451304515386602910396776318075817601265223856116134349", "price": "0.997", "size": "0", "side": "SELL", "timestamp": "1768404470939", "received_at": "2026-01-14T16:27:50.624426"}}
{"event_type": "price_change", "event_ts": "2026-01-14T16:27:50.624426", "ingestion_ts": "2026-01-14T16:33:58.842229", "market_id": "0xe9c127a8c35f045d37b5344b0a36711084fa20c2fc1618bf178a5386f90610be", "raw": {"market": "0xe9c127a8c35f045d37b5344b0a36711084fa20c2fc1618bf178a5386f90610be", "asset_id": "80230236018433940569996058935444651347308266584430516013229815570706872276819", "price": "0.003", "size": "0", "side": "BUY", "timestamp": "1768404470939", "received_at": "2026-01-14T16:27:50.624426"}}
{"event_type": "price_change", "event_ts": "2026-01-14T16:27:50.669583", "ingestion_ts": "2026-01-14T16:33:58.842229", "market_id": "0xe9c127a8c35f045d37b5344b0a36711084fa20c2fc1618bf178a5386f90610be", "raw": {"market": "0xe9c127a8c35f045d37b5344b0a36711084fa20c2fc1618bf178a5386f90610be", "asset_id": "107000426448217931795450451304515386602910396776318075817601265223856116134349", "price": "0.997", "size": "251", "side": "SELL", "timestamp": "1768404470986", "received_at": "2026-01-14T16:27:50.669583"}}
{"event_type": "price_change", "event_ts": "2026-01-14T16:27:50.669583", "ingestion_ts": "2026-01-14T16:33:58.842229", "market_id": "0xe9c127a8c35f045d37b5344b0a36711084fa20c2fc1618bf178a5386f90610be", "raw": {"market": "0xe9c127a8c35f045d37b5344b0a36711084fa20c2fc1618bf178a5386f90610be", "asset_id": "80230236018433940569996058935444651347308266584430516013229815570706872276819", "price": "0.003", "size": "251", "side": "BUY", "timestamp": "1768404470986", "received_at": "2026-01-14T16:27:50.669583"}}
{"event_type": "price_change", "event_ts": "2026-01-14T16:27:52.107739", "ingestion_ts": "2026-01-14T16:33:58.842229", "market_id": "0xe9c127a8c35f045d37b5344b0a36711084fa20c2fc1618bf178a5386f90610be", "raw": {"market": "0xe9c127a8c35f045d37b5344b0a36711084fa20c2fc1618bf178a5386f90610be", "asset_id": "107000426448217931795450451304515386602910396776318075817601265223856116134349", "price": "0.997", "size": "0", "side": "SELL", "timestamp": "1768404472443", "received_at": "2026-01-14T16:27:52.107739"}}
{"event_type": "price_change", "event_ts": "2026-01-14T16:27:52.107739", "ingestion_ts": "2026-01-14T16:33:58.842229", "market_id": "0xe9c127a8c35f045d37b5344b0a36711084fa20c2fc1618bf178a5386f90610be", "raw": {"market": "0xe9c127a8c35f045d37b5344b0a36711084fa20c2fc1618bf178a5386f90610be", "asset_id": "80230236018433940569996058935444651347308266584430516013229815570706872276819", "price": "0.003", "size": "0", "side": "BUY", "timestamp": "1768404472443", "received_at": "2026-01-14T16:27:52.107739"}}
{"event_type": "price_change", "event_ts": "2026-01-14T16:27:52.141053", "ingestion_ts": "2026-01-14T16:33:58.842229", "market_id": "0xe9c127a8c35f045d37b5344b0a36711084fa20c2fc1618bf178a5386f90610be", "raw": {"market": "0xe9c127a8c35f045d37b5344b0a36711084fa20c2fc1618bf178a5386f90610be", "asset_id": "107000426448217931795450451304515386602910396776318075817601265223856116134349", "price": "0.997", "size": "251", "side": "SELL", "timestamp": "1768404472474", "received_at": "2026-01-14T16:27:52.141053"}}
{"event_type": "price_change", "event_ts": "2026-01-14T16:27:52.141053", "ingestion_ts": "2026-01-14T16:33:58.842229", "market_id": "0xe9c127a8c35f045d37b5344b0a36711084fa20c2fc1618bf178a5386f90610be", "raw": {"market": "0xe9c127a8c35f045d37b5344b0a36711084fa20c2fc1618bf178a5386f90610be", "asset_id": "80230236018433940569996058935444651347308266584430516013229815570706872276819", "price": "0.003", "size": "251", "side": "BUY", "timestamp": "1768404472474", "received_at": "2026-01-14T16:27:52.141053"}}
{"event_type": "price_change", "event_ts": "2026-01-14T16:27:53.645687", "ingestion_ts": "2026-01-14T16:33:58.842229", "market_id": "0xe9c127a8c35f045d37b5344b0a36711084fa20c2fc1618bf178a5386f90610be", "raw": {"market": "0xe9c127a8c35f045d37b5344b0a36711084fa20c2fc1618bf178a5386f90610be", "asset_id": "107000426448217931795450451304515386602910396776318075817601265223856116134349", "price": "0.997", "size": "0", "side": "SELL", "timestamp": "1768404473939", "received_at": "2026-01-14T16:27:53.645687"}}
{"event_type": "price_change", "event_ts": "2026-01-14T16:27:53.645687", "ingestion_ts": "2026-01-14T16:33:58.842229", "market_id": "0xe9c127a8c35f045d37b5344b0a36711084fa20c2fc1618bf178a5386f90610be", "raw": {"market": "0xe9c127a8c35f045d37b5344b0a36711084fa20c2fc1618bf178a5386f90610be", "asset_id": "80230236018433940569996058935444651347308266584430516013229815570706872276819", "price": "0.003", "size": "0", "side": "BUY", "timestamp": "1768404473939", "received_at": "2026-01-14T16:27:53.645687"}}
{"event_type": "price_change", "event_ts": "2026-01-14T16:27:53.704577", "ingestion_ts": "2026-01-14T16:33:58.842229", "market_id": "0xe9c127a8c35f045d37b5344b0a36711084fa20c2fc1618bf178a5386f90610be", "raw": {"market": "0xe9c127a8c35f045d37b5344b0a36711084fa20c2fc1618bf178a5386f90610be", "asset_id": "107000426448217931795450451304515386602910396776318075817601265223856116134349", "price": "0.997", "size": "251", "side": "SELL", "timestamp": "1768404474007", "received_at": "2026-01-14T16:27:53.704577"}}
{"event_type": "price_change", "event_ts": "2026-01-14T16:27:53.704577", "ingestion_ts": "2026-01-14T16:33:58.842229", "market_id": "0xe9c127a8c35f045d37b5344b0a36711084fa20c2fc1618bf178a5386f90610be", "raw": {"market": "0xe9c127a8c35f045d37b5344b0a36711084fa20c2fc1618bf178a5386f90610be", "asset_id": "80230236018433940569996058935444651347308266584430516013229815570706872276819", "price": "0.003", "size": "251", "side": "BUY", "timestamp": "1768404474007", "received_at": "2026-01-14T16:27:53.704577"}}
{"event_type": "price_change", "event_ts": "2026-01-14T16:27:54.166135", "ingestion_ts": "2026-01-14T16:33:58.842229", "market_id": "0xe9c127a8c35f045d37b5344b0a36711084fa20c2fc1618bf178a5386f90610be", "raw": {"market": "0xe9c127a8c35f045d37b5344b0a36711084fa20c2fc1618bf178a5386f90610be", "asset_id": "80230236018433940569996058935444651347308266584430516013229815570706872276819", "price": "0.006", "size": "0", "side": "SELL", "timestamp": "1768404474461", "received_at": "2026-01-14T16:27:54.166135"}}
{"event_type": "price_change", "event_ts": "2026-01-14T16:27:54.166135", "ingestion_ts": "2026-01-14T16:33:58.842229", "market_id": "0xe9c127a8c35f045d37b5344b0a36711084fa20c2fc1618bf178a5386f90610be", "raw": {"market": "0xe9c127a8c35f045d37b5344b0a36711084fa20c2fc1618bf178a5386f90610be", "asset_id": "107000426448217931795450451304515386602910396776318075817601265223856116134349", "price": "0.994", "size": "0", "side": "BUY", "timestamp": "1768404474461", "received_at": "2026-01-14T16:27:54.166135"}}
{"event_type": "price_change", "event_ts": "2026-01-14T16:27:55.111875", "ingestion_ts": "2026-01-14T16:33:58.842229", "market_id": "0xe9c127a8c35f045d37b5344b0a36711084fa20c2fc1618bf178a5386f90610be", "raw": {"market": "0xe9c127a8c35f045d37b5344b0a36711084fa20c2fc1618bf178a5386f90610be", "asset_id": "107000426448217931795450451304515386602910396776318075817601265223856116134349", "price": "0.997", "size": "0", "side": "SELL", "timestamp": "1768404475447", "received_at": "2026-01-14T16:27:55.111875"}}
{"event_type": "price_change", "event_ts": "2026-01-14T16:27:55.111875", "ingestion_ts": "2026-01-14T16:33:58.842229", "market_id": "0xe9c127a8c35f045d37b5344b0a36711084fa20c2fc1618bf178a5386f90610be", "raw": {"market": "0xe9c127a8c35f045d37b5344b0a36711084fa20c2fc1618bf178a5386f90610be", "asset_id": "80230236018433940569996058935444651347308266584430516013229815570706872276819", "price": "0.003", "size": "0", "side": "BUY", "timestamp": "1768404475447", "received_at": "2026-01-14T16:27:55.111875"}}
{"event_type": "price_change", "event_ts": "2026-01-14T16:27:55.137386", "ingestion_ts": "2026-01-14T16:33:58.842229", "market_id": "0xe9c127a8c35f045d37b5344b0a36711084fa20c2fc1618bf178a5386f90610be", "raw": {"market": "0xe9c127a8c35f045d37b5344b0a36711084fa20c2fc1618bf178a5386f90610be", "asset_id": "80230236018433940569996058935444651347308266584430516013229815570706872276819", "price": "0.003", "size": "612", "side": "BUY", "timestamp": "1768404475474", "received_at": "2026-01-14T16:27:55.137386"}}
{"event_type": "price_change", "event_ts": "2026-01-14T16:27:55.137386", "ingestion_ts": "2026-01-14T16:33:58.842229", "market_id": "0xe9c127a8c35f045d37b5344b0a36711084fa20c2fc1618bf178a5386f90610be", "raw": {"market": "0xe9c127a8c35f045d37b5344b0a36711084fa20c2fc1618bf178a5386f90610be", "asset_id": "107000426448217931795450451304515386602910396776318075817601265223856116134349", "price": "0.997", "size": "612", "side": "SELL", "timestamp": "1768404475474", "received_at": "2026-01-14T16:27:55.137386"}}
{"event_type": "price_change", "event_ts": "2026-01-14T16:27:56.608714", "ingestion_ts": "2026-01-14T16:33:58.842229", "market_id": "0xe9c127a8c35f045d37b5344b0a36711084fa20c2fc1618bf178a5386f90610be", "raw": {"market": "0xe9c127a8c35f045d37b5344b0a36711084fa20c2fc1618bf178a5386f90610be", "asset_id": "80230236018433940569996058935444651347308266584430516013229815570706872276819", "price": "0.003", "size": "0", "side": "BUY", "timestamp": "1768404476943", "received_at": "2026-01-14T16:27:56.608714"}}
{"event_type": "price_change", "event_ts": "2026-01-14T16:27:56.608714", "ingestion_ts": "2026-01-14T16:33:58.842229", "market_id": "0xe9c127a8c35f045d37b5344b0a36711084fa20c2fc1618bf178a5386f90610be", "raw": {"market": "0xe9c127a8c35f045d37b5344b0a36711084fa20c2fc1618bf178a5386f90610be", "asset_id": "107000426448217931795450451304515386602910396776318075817601265223856116134349", "price": "0.997", "size": "0", "side": "SELL", "timestamp": "1768404476943", "received_at": "2026-01-14T16:27:56.608714"}}
{"event_type": "price_change", "event_ts": "2026-01-14T16:27:56.644938", "ingestion_ts": "2026-01-14T16:33:58.842229", "market_id": "0xe9c127a8c35f045d37b5344b0a36711084fa20c2fc1618bf178a5386f90610be", "raw": {"market": "0xe9c127a8c35f045d37b5344b0a36711084fa20c2fc1618bf178a5386f90610be", "asset_id": "80230236018433940569996058935444651347308266584430516013229815570706872276819", "price": "0.003", "size": "612", "side": "BUY", "timestamp": "1768404476978", "received_at": "2026-01-14T16:27:56.644938"}}
{"event_type": "price_change", "event_ts": "2026-01-14T16:27:56.644938", "ingestion_ts": "2026-01-14T16:33:58.842229", "market_id": "0xe9c127a8c35f045d37b5344b0a36711084fa20c2fc1618bf178a5386f90610be", "raw": {"market": "0xe9c127a8c35f045d37b5344b0a36711084fa20c2fc1618bf178a5386f90610be", "asset_id": "107000426448217931795450451304515386602910396776318075817601265223856116134349", "price": "0.997", "size": "612", "side": "SELL", "timestamp": "1768404476978", "received_at": "2026-01-14T16:27:56.644938"}}
{"event_type": "price_change", "event_ts": "2026-01-14T16:27:58.104924", "ingestion_ts": "2026-01-14T16:33:58.842229", "market_id": "0xe9c127a8c35f045d37b5344b0a36711084fa20c2fc1618bf178a5386f90610be", "raw": {"market": "0xe9c127a8c35f045d37b5344b0a36711084fa20c2fc1618bf178a5386f90610be", "asset_id": "80230236018433940569996058935444651347308266584430516013229815570706872276819", "price": "0.003", "size": "0", "side": "BUY", "timestamp": "1768404478441", "received_at": "2026-01-14T16:27:58.104924"}}
{"event_type": "price_change", "event_ts": "2026-01-14T16:27:58.104924", "ingestion_ts": "2026-01-14T16:33:58.842229", "market_id": "0xe9c127a8c35f045d37b5344b0a36711084fa20c2fc1618bf178a5386f90610be", "raw": {"market": "0xe9c127a8c35f045d37b5344b0a36711084fa20c2fc1618bf178a5386f90610be", "asset_id": "107000426448217931795450451304515386602910396776318075817601265223856116134349", "price": "0.997", "size": "0", "side": "SELL", "timestamp": "1768404478441", "received_at": "2026-01-14T16:27:58.104924"}}
{"event_type": "price_change", "event_ts": "2026-01-14T16:27:58.130520", "ingestion_ts": "2026-01-14T16:33:58.842229", "market_id": "0xe9c127a8c35f045d37b5344b0a36711084fa20c2fc1618bf178a5386f90610be", "raw": {"market": "0xe9c127a8c35f045d37b5344b0a36711084fa20c2fc1618bf178a5386f90610be", "asset_id": "80230236018433940569996058935444651347308266584430516013229815570706872276819", "price": "0.003", "size": "612", "side": "BUY", "timestamp": "1768404478467", "received_at": "2026-01-14T16:27:58.130520"}}
{"event_type": "price_change", "event_ts": "2026-01-14T16:27:58.130520", "ingestion_ts": "2026-01-14T16:33:58.842229", "market_id": "0xe9c127a8c35f045d37b5344b0a36711084fa20c2fc1618bf178a5386f90610be", "raw": {"market": "0xe9c127a8c35f045d37b5344b0a36711084fa20c2fc1618bf178a5386f90610be", "asset_id": "107000426448217931795450451304515386602910396776318075817601265223856116134349", "price": "0.997", "size": "612", "side": "SELL", "timestamp": "1768404478467", "received_at": "2026-01-14T16:27:58.130520"}}
{"event_type": "price_change", "event_ts": "2026-01-14T16:27:59.613233", "ingestion_ts": "2026-01-14T16:33:58.842229", "market_id": "0xe9c127a8c35f045d37b5344b0a36711084fa20c2fc1618bf178a5386f90610be", "raw": {"market": "0xe9c127a8c35f045d37b5344b0a36711084fa20c2fc1618bf178a5386f90610be", "asset_id": "80230236018433940569996058935444651347308266584430516013229815570706872276819", "price": "0.003", "size": "0", "side": "BUY", "timestamp": "1768404479943", "received_at": "2026-01-14T16:27:59.613233"}}
{"event_type": "price_change", "event_ts": "2026-01-14T16:27:59.613233", "ingestion_ts": "2026-01-14T16:33:58.842229", "market_id": "0xe9c127a8c35f045d37b5344b0a36711084fa20c2fc1618bf178a5386f90610be", "raw": {"market": "0xe9c127a8c35f045d37b5344b0a36711084fa20c2fc1618bf178a5386f90610be", "asset_id": "107000426448217931795450451304515386602910396776318075817601265223856116134349", "price": "0.997", "size": "0", "side": "SELL", "timestamp": "1768404479943", "received_at": "2026-01-14T16:27:59.613233"}}
{"event_type": "price_change", "event_ts": "2026-01-14T16:27:59.649522", "ingestion_ts": "2026-01-14T16:33:58.842229", "market_id": "0xe9c127a8c35f045d37b5344b0a36711084fa20c2fc1618bf178a5386f90610be", "raw": {"market": "0xe9c127a8c35f045d37b5344b0a36711084fa20c2fc1618bf178a5386f90610be", "asset_id": "80230236018433940569996058935444651347308266584430516013229815570706872276819", "price": "0.003", "size": "612", "side": "BUY", "timestamp": "1768404479981", "received_at": "2026-01-14T16:27:59.649522"}}
{"event_type": "price_change", "event_ts": "2026-01-14T16:27:59.649522", "ingestion_ts": "2026-01-14T16:33:58.842229", "market_id": "0xe9c127a8c35f045d37b5344b0a36711084fa20c2fc1618bf178a5386f90610be", "raw": {"market": "0xe9c127a8c35f045d37b5344b0a36711084fa20c2fc1618bf178a5386f90610be", "asset_id": "107000426448217931795450451304515386602910396776318075817601265223856116134349", "price": "0.997", "size": "612", "side": "SELL", "timestamp": "1768404479981", "received_at": "2026-01-14T16:27:59.649522"}}
{"event_type": "price_change", "event_ts": "2026-01-14T16:28:01.104435", "ingestion_ts": "2026-01-14T16:33:58.842229", "market_id": "0xe9c127a8c35f045d37b5344b0a36711084fa20c2fc1618bf178a5386f90610be", "raw": {"market": "0xe9c127a8c35f045d37b5344b0a36711084fa20c2fc1618bf178a5386f90610be", "asset_id": "80230236018433940569996058935444651347308266584430516013229815570706872276819", "price": "0.003", "size": "0", "side": "BUY", "timestamp": "1768404481438", "received_at": "2026-01-14T16:28:01.104435"}}
{"event_type": "price_change", "event_ts": "2026-01-14T16:28:01.104435", "ingestion_ts": "2026-01-14T16:33:58.842229", "market_id": "0xe9c127a8c35f045d37b5344b0a36711084fa20c2fc1618bf178a5386f90610be", "raw": {"market": "0xe9c127a8c35f045d37b5344b0a36711084fa20c2fc1618bf178a5386f90610be", "asset_id": "107000426448217931795450451304515386602910396776318075817601265223856116134349", "price": "0.997", "size": "0", "side": "SELL", "timestamp": "1768404481438", "received_at": "2026-01-14T16:28:01.104435"}}
{"event_type": "price_change", "event_ts": "2026-01-14T16:28:01.139531", "ingestion_ts": "2026-01-14T16:33:58.842229", "market_id": "0xe9c127a8c35f045d37b5344b0a36711084fa20c2fc1618bf178a5386f90610be", "raw": {"market": "0xe9c127a8c35f045d37b5344b0a36711084fa20c2fc1618bf178a5386f90610be", "asset_id": "80230236018433940569996058935444651347308266584430516013229815570706872276819", "price": "0.003", "size": "612", "side": "BUY", "timestamp": "1768404481473", "received_at": "2026-01-14T16:28:01.139531"}}
{"event_type": "price_change", "event_ts": "2026-01-14T16:28:01.139531", "ingestion_ts": "2026-01-14T16:33:58.842229", "market_id": "0xe9c127a8c35f045d37b5344b0a36711084fa20c2fc1618bf178a5386f90610be", "raw": {"market": "0xe9c127a8c35f045d37b5344b0a36711084fa20c2fc1618bf178a5386f90610be", "asset_id": "107000426448217931795450451304515386602910396776318075817601265223856116134349", "price": "0.997", "size": "612", "side": "SELL", "timestamp": "1768404481473", "received_at": "2026-01-14T16:28:01.139531"}}
{"event_type": "price_change", "event_ts": "2026-01-14T16:28:02.429341", "ingestion_ts": "2026-01-14T16:33:58.842229", "market_id": "0xe9c127a8c35f045d37b5344b0a36711084fa20c2fc1618bf178a5386f90610be", "raw": {"market": "0xe9c127a8c35f045d37b5344b0a36711084fa20c2fc1618bf178a5386f90610be", "asset_id": "80230236018433940569996058935444651347308266584430516013229815570706872276819", "price": "0.008", "size": "113", "side": "SELL", "timestamp": "1768404482758", "received_at": "2026-01-14T16:28:02.429341"}}
{"event_type": "price_change", "event_ts": "2026-01-14T16:28:02.429341", "ingestion_ts": "2026-01-14T16:33:58.842229", "market_id": "0xe9c127a8c35f045d37b5344b0a36711084fa20c2fc1618bf178a5386f90610be", "raw": {"market": "0xe9c127a8c35f045d37b5344b0a36711084fa20c2fc1618bf178a5386f90610be", "asset_id": "107000426448217931795450451304515386602910396776318075817601265223856116134349", "price": "0.992", "size": "113", "side": "BUY", "timestamp": "1768404482758", "received_at": "2026-01-14T16:28:02.429341"}}
{"event_type": "price_change", "event_ts": "2026-01-14T16:28:02.469615", "ingestion_ts": "2026-01-14T16:33:58.842229", "market_id": "0xe9c127a8c35f045d37b5344b0a36711084fa20c2fc1618bf178a5386f90610be", "raw": {"market": "0xe9c127a8c35f045d37b5344b0a36711084fa20c2fc1618bf178a5386f90610be", "asset_id": "80230236018433940569996058935444651347308266584430516013229815570706872276819", "price": "0.003", "size": "0", "side": "BUY", "timestamp": "1768404482803", "received_at": "2026-01-14T16:28:02.469615"}}
{"event_type": "price_change", "event_ts": "2026-01-14T16:28:02.469615", "ingestion_ts": "2026-01-14T16:33:58.842229", "market_id": "0xe9c127a8c35f045d37b5344b0a36711084fa20c2fc1618bf178a5386f90610be", "raw": {"market": "0xe9c127a8c35f045d37b5344b0a36711084fa20c2fc1618bf178a5386f90610be", "asset_id": "107000426448217931795450451304515386602910396776318075817601265223856116134349", "price": "0.997", "size": "0", "side": "SELL", "timestamp": "1768404482803", "received_at": "2026-01-14T16:28:02.469615"}}
{"event_type": "price_change", "event_ts": "2026-01-14T16:28:02.500086", "ingestion_ts": "2026-01-14T16:33:58.842229", "market_id": "0xe9c127a8c35f045d37b5344b0a36711084fa20c2fc1618bf178a5386f90610be", "raw": {"market": "0xe9c127a8c35f045d37b5344b0a36711084fa20c2fc1618bf178a5386f90610be", "asset_id": "107000426448217931795450451304515386602910396776318075817601265223856116134349", "price": "0.997", "size": "251", "side": "SELL", "timestamp": "1768404482836", "received_at": "2026-01-14T16:28:02.500086"}}
{"event_type": "price_change", "event_ts": "2026-01-14T16:28:02.500086", "ingestion_ts": "2026-01-14T16:33:58.842229", "market_id": "0xe9c127a8c35f045d37b5344b0a36711084fa20c2fc1618bf178a5386f90610be", "raw": {"market": "0xe9c127a8c35f045d37b5344b0a36711084fa20c2fc1618bf178a5386f90610be", "asset_id": "80230236018433940569996058935444651347308266584430516013229815570706872276819", "price": "0.003", "size": "251", "side": "BUY", "timestamp": "1768404482836", "received_at": "2026-01-14T16:28:02.500086"}}
{"event_type": "price_change", "event_ts": "2026-01-14T16:28:02.664827", "ingestion_ts": "2026-01-14T16:33:58.842229", "market_id": "0x9d24d9f9b5995949cb158d943793dea20bd448e1b3971cb6f7418bb15e719661", "raw": {"market": "0x9d24d9f9b5995949cb158d943793dea20bd448e1b3971cb6f7418bb15e719661", "asset_id": "79516121807256184736227920754945730465880754940725759201193439378549308939672", "price": "0.001", "size": "303576.42", "side": "BUY", "timestamp": "1768404483000", "received_at": "2026-01-14T16:28:02.664827"}}
{"event_type": "price_change", "event_ts": "2026-01-14T16:28:02.664827", "ingestion_ts": "2026-01-14T16:33:58.842229", "market_id": "0x9d24d9f9b5995949cb158d943793dea20bd448e1b3971cb6f7418bb15e719661", "raw": {"market": "0x9d24d9f9b5995949cb158d943793dea20bd448e1b3971cb6f7418bb15e719661", "asset_id": "70512916946285526357165287373537570327431985324385225788636160168740471920430", "price": "0.999", "size": "303576.42", "side": "SELL", "timestamp": "1768404483000", "received_at": "2026-01-14T16:28:02.664827"}}
{"event_type": "price_change", "event_ts": "2026-01-14T16:28:02.664882", "ingestion_ts": "2026-01-14T16:33:58.842229", "market_id": "0x2393ed0b0fdc450054c7b9071907eca75cf4fc36e385adf4a0a5f99ee62243e8", "raw": {"market": "0x2393ed0b0fdc450054c7b9071907eca75cf4fc36e385adf4a0a5f99ee62243e8", "asset_id": "32769749367306925959219403371425714180265458150646381231272229429098460625924", "price": "0.011", "size": "0", "side": "BUY", "timestamp": "1768404483000", "received_at": "2026-01-14T16:28:02.664882"}}
{"event_type": "price_change", "event_ts": "2026-01-14T16:28:02.664882", "ingestion_ts": "2026-01-14T16:33:58.842229", "market_id": "0x2393ed0b0fdc450054c7b9071907eca75cf4fc36e385adf4a0a5f99ee62243e8", "raw": {"market": "0x2393ed0b0fdc450054c7b9071907eca75cf4fc36e385adf4a0a5f99ee62243e8", "asset_id": "100074770378634056601572485653252702850363676459996771990439989989293515601975", "price": "0.989", "size": "0", "side": "SELL", "timestamp": "1768404483000", "received_at": "2026-01-14T16:28:02.664882"}}
{"event_type": "price_change", "event_ts": "2026-01-14T16:28:02.664901", "ingestion_ts": "2026-01-14T16:33:58.842229", "market_id": "0xaf9d0e448129a9f657f851d49495ba4742055d80e0ef1166ba0ee81d4d594214", "raw": {"market": "0xaf9d0e448129a9f657f851d49495ba4742055d80e0ef1166ba0ee81d4d594214", "asset_id": "4153292802911610701832309484716814274802943278345248636922528170020319407796", "price": "0.052", "size": "0", "side": "BUY", "timestamp": "1768404483000", "received_at": "2026-01-14T16:28:02.664901"}}
{"event_type": "price_change", "event_ts": "2026-01-14T16:28:02.664901", "ingestion_ts": "2026-01-14T16:33:58.842229", "market_id": "0xaf9d0e448129a9f657f851d49495ba4742055d80e0ef1166ba0ee81d4d594214", "raw": {"market": "0xaf9d0e448129a9f657f851d49495ba4742055d80e0ef1166ba0ee81d4d594214", "asset_id": "101676997363687199724245607342877036148401850938023978421879460310389391082353", "price": "0.948", "size": "0", "side": "SELL", "timestamp": "1768404483000", "received_at": "2026-01-14T16:28:02.664901"}}
{"event_type": "price_change", "event_ts": "2026-01-14T16:28:02.666496", "ingestion_ts": "2026-01-14T16:33:58.842229", "market_id": "0x9d24d9f9b5995949cb158d943793dea20bd448e1b3971cb6f7418bb15e719661", "raw": {"market": "0x9d24d9f9b5995949cb158d943793dea20bd448e1b3971cb6f7418bb15e719661", "asset_id": "79516121807256184736227920754945730465880754940725759201193439378549308939672", "price": "0.201", "size": "0", "side": "BUY", "timestamp": "1768404483000", "received_at": "2026-01-14T16:28:02.666496"}}
{"event_type": "price_change", "event_ts": "2026-01-14T16:28:02.666496", "ingestion_ts": "2026-01-14T16:33:58.842229", "market_id": "0x9d24d9f9b5995949cb158d943793dea20bd448e1b3971cb6f7418bb15e719661", "raw": {"market": "0x9d24d9f9b5995949cb158d943793dea20bd448e1b3971cb6f7418bb15e719661", "asset_id": "70512916946285526357165287373537570327431985324385225788636160168740471920430", "price": "0.799", "size": "0", "side": "SELL", "timestamp": "1768404483000", "received_at": "2026-01-14T16:28:02.666496"}}
{"event_type": "price_change", "event_ts": "2026-01-14T16:28:02.666515", "ingestion_ts": "2026-01-14T16:33:58.842229", "market_id": "0x9d24d9f9b5995949cb158d943793dea20bd448e1b3971cb6f7418bb15e719661", "raw": {"market": "0x9d24d9f9b5995949cb158d943793dea20bd448e1b3971cb6f7418bb15e719661", "asset_id": "79516121807256184736227920754945730465880754940725759201193439378549308939672", "price": "0.005", "size": "0", "side": "BUY", "timestamp": "1768404483000", "received_at": "2026-01-14T16:28:02.666515"}}
{"event_type": "price_change", "event_ts": "2026-01-14T16:28:02.666515", "ingestion_ts": "2026-01-14T16:33:58.842229", "market_id": "0x9d24d9f9b5995949cb158d943793dea20bd448e1b3971cb6f7418bb15e719661", "raw": {"market": "0x9d24d9f9b5995949cb158d943793dea20bd448e1b3971cb6f7418bb15e719661", "asset_id": "70512916946285526357165287373537570327431985324385225788636160168740471920430", "price": "0.995", "size": "0", "side": "SELL", "timestamp": "1768404483000", "received_at": "2026-01-14T16:28:02.666515"}}
{"event_type": "price_change", "event_ts": "2026-01-14T16:28:02.668765", "ingestion_ts": "2026-01-14T16:33:58.842229", "market_id": "0xaf9d0e448129a9f657f851d49495ba4742055d80e0ef1166ba0ee81d4d594214", "raw": {"market": "0xaf9d0e448129a9f657f851d49495ba4742055d80e0ef1166ba0ee81d4d594214", "asset_id": "4153292802911610701832309484716814274802943278345248636922528170020319407796", "price": "0.002", "size": "250", "side": "BUY", "timestamp": "1768404483000", "received_at": "2026-01-14T16:28:02.668765"}}
{"event_type": "price_change", "event_ts": "2026-01-14T16:28:02.668765", "ingestion_ts": "2026-01-14T16:33:58.842229", "market_id": "0xaf9d0e448129a9f657f851d49495ba4742055d80e0ef1166ba0ee81d4d594214", "raw": {"market": "0xaf9d0e448129a9f657f851d49495ba4742055d80e0ef1166ba0ee81d4d594214", "asset_id": "101676997363687199724245607342877036148401850938023978421879460310389391082353", "price": "0.998", "size": "250", "side": "SELL", "timestamp": "1768404483000", "received_at": "2026-01-14T16:28:02.668765"}}
{"event_type": "price_change", "event_ts": "2026-01-14T16:28:02.668792", "ingestion_ts": "2026-01-14T16:33:58.842229", "market_id": "0x2393ed0b0fdc450054c7b9071907eca75cf4fc36e385adf4a0a5f99ee62243e8", "raw": {"market": "0x2393ed0b0fdc450054c7b9071907eca75cf4fc36e385adf4a0a5f99ee62243e8", "asset_id": "32769749367306925959219403371425714180265458150646381231272229429098460625924", "price": "0.004", "size": "0", "side": "BUY", "timestamp": "1768404483000", "received_at": "2026-01-14T16:28:02.668792"}}
{"event_type": "price_change", "event_ts": "2026-01-14T16:28:02.668792", "ingestion_ts": "2026-01-14T16:33:58.842229", "market_id": "0x2393ed0b0fdc450054c7b9071907eca75cf4fc36e385adf4a0a5f99ee62243e8", "raw": {"market": "0x2393ed0b0fdc450054c7b9071907eca75cf4fc36e385adf4a0a5f99ee62243e8", "asset_id": "100074770378634056601572485653252702850363676459996771990439989989293515601975", "price": "0.996", "size": "0", "side": "SELL", "timestamp": "1768404483000", "received_at": "2026-01-14T16:28:02.668792"}}
{"event_type": "price_change", "event_ts": "2026-01-14T16:28:02.668809", "ingestion_ts": "2026-01-14T16:33:58.842229", "market_id": "0x9d24d9f9b5995949cb158d943793dea20bd448e1b3971cb6f7418bb15e719661", "raw": {"market": "0x9d24d9f9b5995949cb158d943793dea20bd448e1b3971cb6f7418bb15e719661", "asset_id": "79516121807256184736227920754945730465880754940725759201193439378549308939672", "price": "0.002", "size": "250", "side": "BUY", "timestamp": "1768404483001", "received_at": "2026-01-14T16:28:02.668809"}}
{"event_type": "price_change", "event_ts": "2026-01-14T16:28:02.668809", "ingestion_ts": "2026-01-14T16:33:58.842229", "market_id": "0x9d24d9f9b5995949cb158d943793dea20bd448e1b3971cb6f7418bb15e719661", "raw": {"market": "0x9d24d9f9b5995949cb158d943793dea20bd448e1b3971cb6f7418bb15e719661", "asset_id": "70512916946285526357165287373537570327431985324385225788636160168740471920430", "price": "0.998", "size": "250", "side": "SELL", "timestamp": "1768404483001", "received_at": "2026-01-14T16:28:02.668809"}}
{"event_type": "price_change", "event_ts": "2026-01-14T16:28:02.670504", "ingestion_ts": "2026-01-14T16:33:58.842229", "market_id": "0xaf9d0e448129a9f657f851d49495ba4742055d80e0ef1166ba0ee81d4d594214", "raw": {"market": "0xaf9d0e448129a9f657f851d49495ba4742055d80e0ef1166ba0ee81d4d594214", "asset_id": "4153292802911610701832309484716814274802943278345248636922528170020319407796", "price": "0.001", "size": "2715.72", "side": "BUY", "timestamp": "1768404483001", "received_at": "2026-01-14T16:28:02.670504"}}
{"event_type": "price_change", "event_ts": "2026-01-14T16:28:02.670504", "ingestion_ts": "2026-01-14T16:33:58.842229", "market_id": "0xaf9d0e448129a9f657f851d49495ba4742055d80e0ef1166ba0ee81d4d594214", "raw": {"market": "0xaf9d0e448129a9f657f851d49495ba4742055d80e0ef1166ba0ee81d4d594214", "asset_id": "101676997363687199724245607342877036148401850938023978421879460310389391082353", "price": "0.999", "size": "2715.72", "side": "SELL", "timestamp": "1768404483001", "received_at": "2026-01-14T16:28:02.670504"}}
{"event_type": "price_change", "event_ts": "2026-01-14T16:28:02.672439", "ingestion_ts": "2026-01-14T16:33:58.842229", "market_id": "0x2393ed0b0fdc450054c7b9071907eca75cf4fc36e385adf4a0a5f99ee62243e8", "raw": {"market": "0x2393ed0b0fdc450054c7b9071907eca75cf4fc36e385adf4a0a5f99ee62243e8", "asset_id": "32769749367306925959219403371425714180265458150646381231272229429098460625924", "price": "0.057", "size": "0", "side": "BUY", "timestamp": "1768404483001", "received_at": "2026-01-14T16:28:02.672439"}}
{"event_type": "price_change", "event_ts": "2026-01-14T16:28:02.672439", "ingestion_ts": "2026-01-14T16:33:58.842229", "market_id": "0x2393ed0b0fdc450054c7b9071907eca75cf4fc36e385adf4a0a5f99ee62243e8", "raw": {"market": "0x2393ed0b0fdc450054c7b9071907eca75cf4fc36e385adf4a0a5f99ee62243e8", "asset_id": "100074770378634056601572485653252702850363676459996771990439989989293515601975", "price": "0.943", "size": "0", "side": "SELL", "timestamp": "1768404483001", "received_at": "2026-01-14T16:28:02.672439"}}
{"event_type": "price_change", "event_ts": "2026-01-14T16:28:02.686305", "ingestion_ts": "2026-01-14T16:33:58.842229", "market_id": "0x9d24d9f9b5995949cb158d943793dea20bd448e1b3971cb6f7418bb15e719661", "raw": {"market": "0x9d24d9f9b5995949cb158d943793dea20bd448e1b3971cb6f7418bb15e719661", "asset_id": "79516121807256184736227920754945730465880754940725759201193439378549308939672", "price": "0.011", "size": "0", "side": "BUY", "timestamp": "1768404483001", "received_at": "2026-01-14T16:28:02.686305"}}
{"event_type": "price_change", "event_ts": "2026-01-14T16:28:02.686305", "ingestion_ts": "2026-01-14T16:33:58.842229", "market_id": "0x9d24d9f9b5995949cb158d943793dea20bd448e1b3971cb6f7418bb15e719661", "raw": {"market": "0x9d24d9f9b5995949cb158d943793dea20bd448e1b3971cb6f7418bb15e719661", "asset_id": "70512916946285526357165287373537570327431985324385225788636160168740471920430", "price": "0.989", "size": "0", "side": "SELL", "timestamp": "1768404483001", "received_at": "2026-01-14T16:28:02.686305"}}
{"event_type": "price_change", "event_ts": "2026-01-14T16:28:02.686350", "ingestion_ts": "2026-01-14T16:33:58.842229", "market_id": "0xaf9d0e448129a9f657f851d49495ba4742055d80e0ef1166ba0ee81d4d594214", "raw": {"market": "0xaf9d0e448129a9f657f851d49495ba4742055d80e0ef1166ba0ee81d4d594214", "asset_id": "4153292802911610701832309484716814274802943278345248636922528170020319407796", "price": "0.004", "size": "0", "side": "BUY", "timestamp": "1768404483001", "received_at": "2026-01-14T16:28:02.686350"}}
{"event_type": "price_change", "event_ts": "2026-01-14T16:28:02.686350", "ingestion_ts": "2026-01-14T16:33:58.842229", "market_id": "0xaf9d0e448129a9f657f851d49495ba4742055d80e0ef1166ba0ee81d4d594214", "raw": {"market": "0xaf9d0e448129a9f657f851d49495ba4742055d80e0ef1166ba0ee81d4d594214", "asset_id": "101676997363687199724245607342877036148401850938023978421879460310389391082353", "price": "0.996", "size": "0", "side": "SELL", "timestamp": "1768404483001", "received_at": "2026-01-14T16:28:02.686350"}}
{"event_type": "price_change", "event_ts": "2026-01-14T16:28:02.686368", "ingestion_ts": "2026-01-14T16:33:58.842229", "market_id": "0x2393ed0b0fdc450054c7b9071907eca75cf4fc36e385adf4a0a5f99ee62243e8", "raw": {"market": "0x2393ed0b0fdc450054c7b9071907eca75cf4fc36e385adf4a0a5f99ee62243e8", "asset_id": "32769749367306925959219403371425714180265458150646381231272229429098460625924", "price": "0.002", "size": "250", "side": "BUY", "timestamp": "1768404483001", "received_at": "2026-01-14T16:28:02.686368"}}
{"event_type": "price_change", "event_ts": "2026-01-14T16:28:02.686368", "ingestion_ts": "2026-01-14T16:33:58.842229", "market_id": "0x2393ed0b0fdc450054c7b9071907eca75cf4fc36e385adf4a0a5f99ee62243e8", "raw": {"market": "0x2393ed0b0fdc450054c7b9071907eca75cf4fc36e385adf4a0a5f99ee62243e8", "asset_id": "100074770378634056601572485653252702850363676459996771990439989989293515601975", "price": "0.998", "size": "250", "side": "SELL", "timestamp": "1768404483001", "received_at": "2026-01-14T16:28:02.686368"}}
{"event_type": "price_change", "event_ts": "2026-01-14T16:28:02.686382", "ingestion_ts": "2026-01-14T16:33:58.842229", "market_id": "0x9d24d9f9b5995949cb158d943793dea20bd448e1b3971cb6f7418bb15e719661", "raw": {"market": "0x9d24d9f9b5995949cb158d943793dea20bd448e1b3971cb6f7418bb15e719661", "asset_id": "79516121807256184736227920754945730465880754940725759201193439378549308939672", "price": "0.021", "size": "0", "side": "BUY", "timestamp": "1768404483001", "received_at": "2026-01-14T16:28:02.686382"}}
{"event_type": "price_change", "event_ts": "2026-01-14T16:28:02.686382", "ingestion_ts": "2026-01-14T16:33:58.842229", "market_id": "0x9d24d9f9b5995949cb158d943793dea20bd448e1b3971cb6f7418bb15e719661", "raw": {"market": "0x9d24d9f9b5995949cb158d943793dea20bd448e1b3971cb6f7418bb15e719661", "asset_id": "70512916946285526357165287373537570327431985324385225788636160168740471920430", "price": "0.979", "size": "0", "side": "SELL", "timestamp": "1768404483001", "received_at": "2026-01-14T16:28:02.686382"}}
{"event_type": "price_change", "event_ts": "2026-01-14T16:28:02.686394", "ingestion_ts": "2026-01-14T16:33:58.842229", "market_id": "0xaf9d0e448129a9f657f851d49495ba4742055d80e0ef1166ba0ee81d4d594214", "raw": {"market": "0xaf9d0e448129a9f657f851d49495ba4742055d80e0ef1166ba0ee81d4d594214", "asset_id": "4153292802911610701832309484716814274802943278345248636922528170020319407796", "price": "0.201", "size": "0", "side": "BUY", "timestamp": "1768404483002", "received_at": "2026-01-14T16:28:02.686394"}}
{"event_type": "price_change", "event_ts": "2026-01-14T16:28:02.686394", "ingestion_ts": "2026-01-14T16:33:58.842229", "market_id": "0xaf9d0e448129a9f657f851d49495ba4742055d80e0ef1166ba0ee81d4d594214", "raw": {"market": "0xaf9d0e448129a9f657f851d49495ba4742055d80e0ef1166ba0ee81d4d594214", "asset_id": "101676997363687199724245607342877036148401850938023978421879460310389391082353", "price": "0.799", "size": "0", "side": "SELL", "timestamp": "1768404483002", "received_at": "2026-01-14T16:28:02.686394"}}
{"event_type": "price_change", "event_ts": "2026-01-14T16:28:02.686405", "ingestion_ts": "2026-01-14T16:33:58.842229", "market_id": "0x9d24d9f9b5995949cb158d943793dea20bd448e1b3971cb6f7418bb15e719661", "raw": {"market": "0x9d24d9f9b5995949cb158d943793dea20bd448e1b3971cb6f7418bb15e719661", "asset_id": "79516121807256184736227920754945730465880754940725759201193439378549308939672", "price": "0.051", "size": "0", "side": "BUY", "timestamp": "1768404483002", "received_at": "2026-01-14T16:28:02.686405"}}
{"event_type": "price_change", "event_ts": "2026-01-14T16:28:02.686405", "ingestion_ts": "2026-01-14T16:33:58.842229", "market_id": "0x9d24d9f9b5995949cb158d943793dea20bd448e1b3971cb6f7418bb15e719661", "raw": {"market": "0x9d24d9f9b5995949cb158d943793dea20bd448e1b3971cb6f7418bb15e719661", "asset_id": "70512916946285526357165287373537570327431985324385225788636160168740471920430", "price": "0.949", "size": "0", "side": "SELL", "timestamp": "1768404483002", "received_at": "2026-01-14T16:28:02.686405"}}
{"event_type": "price_change", "event_ts": "2026-01-14T16:28:02.686416", "ingestion_ts": "2026-01-14T16:33:58.842229", "market_id": "0x2393ed0b0fdc450054c7b9071907eca75cf4fc36e385adf4a0a5f99ee62243e8", "raw": {"market": "0x2393ed0b0fdc450054c7b9071907eca75cf4fc36e385adf4a0a5f99ee62243e8", "asset_id": "32769749367306925959219403371425714180265458150646381231272229429098460625924", "price": "0.022", "size": "0", "side": "BUY", "timestamp": "1768404483002", "received_at": "2026-01-14T16:28:02.686416"}}
{"event_type": "price_change", "event_ts": "2026-01-14T16:28:02.686416", "ingestion_ts": "2026-01-14T16:33:58.842229", "market_id": "0x2393ed0b0fdc450054c7b9071907eca75cf4fc36e385adf4a0a5f99ee62243e8", "raw": {"market": "0x2393ed0b0fdc450054c7b9071907eca75cf4fc36e385adf4a0a5f99ee62243e8", "asset_id": "100074770378634056601572485653252702850363676459996771990439989989293515601975", "price": "0.978", "size": "0", "side": "SELL", "timestamp": "1768404483002", "received_at": "2026-01-14T16:28:02.686416"}}
{"event_type": "price_change", "event_ts": "2026-01-14T16:28:02.686427", "ingestion_ts": "2026-01-14T16:33:58.842229", "market_id": "0xaf9d0e448129a9f657f851d49495ba4742055d80e0ef1166ba0ee81d4d594214", "raw": {"market": "0xaf9d0e448129a9f657f851d49495ba4742055d80e0ef1166ba0ee81d4d594214", "asset_id": "4153292802911610701832309484716814274802943278345248636922528170020319407796", "price": "0.011", "size": "0", "side": "BUY", "timestamp": "1768404483002", "received_at": "2026-01-14T16:28:02.686427"}}
{"event_type": "price_change", "event_ts": "2026-01-14T16:28:02.686427", "ingestion_ts": "2026-01-14T16:33:58.842229", "market_id": "0xaf9d0e448129a9f657f851d49495ba4742055d80e0ef1166ba0ee81d4d594214", "raw": {"market": "0xaf9d0e448129a9f657f851d49495ba4742055d80e0ef1166ba0ee81d4d594214", "asset_id": "101676997363687199724245607342877036148401850938023978421879460310389391082353", "price": "0.989", "size": "0", "side": "SELL", "timestamp": "1768404483002", "received_at": "2026-01-14T16:28:02.686427"}}
{"event_type": "price_change", "event_ts": "2026-01-14T16:28:02.686441", "ingestion_ts": "2026-01-14T16:33:58.842229", "market_id": "0x2393ed0b0fdc450054c7b9071907eca75cf4fc36e385adf4a0a5f99ee62243e8", "raw": {"market": "0x2393ed0b0fdc450054c7b9071907eca75cf4fc36e385adf4a0a5f99ee62243e8", "asset_id": "32769749367306925959219403371425714180265458150646381231272229429098460625924", "price": "0.001", "size": "3364.32", "side": "BUY", "timestamp": "1768404483002", "received_at": "2026-01-14T16:28:02.686441"}}
{"event_type": "price_change", "event_ts": "2026-01-14T16:28:02.686441", "ingestion_ts": "2026-01-14T16:33:58.842229", "market_id": "0x2393ed0b0fdc450054c7b9071907eca75cf4fc36e385adf4a0a5f99ee62243e8", "raw": {"market": "0x2393ed0b0fdc450054c7b9071907eca75cf4fc36e385adf4a0a5f99ee62243e8", "asset_id": "100074770378634056601572485653252702850363676459996771990439989989293515601975", "price": "0.999", "size": "3364.32", "side": "SELL", "timestamp": "1768404483002", "received_at": "2026-01-14T16:28:02.686441"}}
{"event_type": "price_change", "event_ts": "2026-01-14T16:28:02.686454", "ingestion_ts": "2026-01-14T16:33:58.842229", "market_id": "0xaf9d0e448129a9f657f851d49495ba4742055d80e0ef1166ba0ee81d4d594214", "raw": {"market": "0xaf9d0e448129a9f657f851d49495ba4742055d80e0ef1166ba0ee81d4d594214", "asset_id": "4153292802911610701832309484716814274802943278345248636922528170020319407796", "price": "0.022", "size": "0", "side": "BUY", "timestamp": "1768404483002", "received_at": "2026-01-14T16:28:02.686454"}}
{"event_type": "price_change", "event_ts": "2026-01-14T16:28:02.686454", "ingestion_ts": "2026-01-14T16:33:58.842229", "market_id": "0xaf9d0e448129a9f657f851d49495ba4742055d80e0ef1166ba0ee81d4d594214", "raw": {"market": "0xaf9d0e448129a9f657f851d49495ba4742055d80e0ef1166ba0ee81d4d594214", "asset_id": "101676997363687199724245607342877036148401850938023978421879460310389391082353", "price": "0.978", "size": "0", "side": "SELL", "timestamp": "1768404483002", "received_at": "2026-01-14T16:28:02.686454"}}
{"event_type": "price_change", "event_ts": "2026-01-14T16:28:02.759460", "ingestion_ts": "2026-01-14T16:33:58.842229", "market_id": "0xaf9d0e448129a9f657f851d49495ba4742055d80e0ef1166ba0ee81d4d594214", "raw": {"market": "0xaf9d0e448129a9f657f851d49495ba4742055d80e0ef1166ba0ee81d4d594214", "asset_id": "4153292802911610701832309484716814274802943278345248636922528170020319407796", "price": "0.942", "size": "99.99", "side": "BUY", "timestamp": "1768404483095", "received_at": "2026-01-14T16:28:02.759460"}}
{"event_type": "price_change", "event_ts": "2026-01-14T16:28:02.759460", "ingestion_ts": "2026-01-14T16:33:58.842229", "market_id": "0xaf9d0e448129a9f657f851d49495ba4742055d80e0ef1166ba0ee81d4d594214", "raw": {"market": "0xaf9d0e448129a9f657f851d49495ba4742055d80e0ef1166ba0ee81d4d594214", "asset_id": "101676997363687199724245607342877036148401850938023978421879460310389391082353", "price": "0.058", "size": "99.99", "side": "SELL", "timestamp": "1768404483095", "received_at": "2026-01-14T16:28:02.759460"}}
{"event_type": "price_change", "event_ts": "2026-01-14T16:28:02.789569", "ingestion_ts": "2026-01-14T16:33:58.842229", "market_id": "0xaf9d0e448129a9f657f851d49495ba4742055d80e0ef1166ba0ee81d4d594214", "raw": {"market": "0xaf9d0e448129a9f657f851d49495ba4742055d80e0ef1166ba0ee81d4d594214", "asset_id": "101676997363687199724245607342877036148401850938023978421879460310389391082353", "price": "0.018", "size": "0", "side": "BUY", "timestamp": "1768404483125", "received_at": "2026-01-14T16:28:02.789569"}}
{"event_type": "price_change", "event_ts": "2026-01-14T16:28:02.789569", "ingestion_ts": "2026-01-14T16:33:58.842229", "market_id": "0xaf9d0e448129a9f657f851d49495ba4742055d80e0ef1166ba0ee81d4d594214", "raw": {"market": "0xaf9d0e448129a9f657f851d49495ba4742055d80e0ef1166ba0ee81d4d594214", "asset_id": "4153292802911610701832309484716814274802943278345248636922528170020319407796", "price": "0.982", "size": "0", "side": "SELL", "timestamp": "1768404483125", "received_at": "2026-01-14T16:28:02.789569"}}
{"event_type": "price_change", "event_ts": "2026-01-14T16:28:02.820370", "ingestion_ts": "2026-01-14T16:33:58.842229", "market_id": "0xaf9d0e448129a9f657f851d49495ba4742055d80e0ef1166ba0ee81d4d594214", "raw": {"market": "0xaf9d0e448129a9f657f851d49495ba4742055d80e0ef1166ba0ee81d4d594214", "asset_id": "101676997363687199724245607342877036148401850938023978421879460310389391082353", "price": "0.016", "size": "128.13", "side": "BUY", "timestamp": "1768404483157", "received_at": "2026-01-14T16:28:02.820370"}}
{"event_type": "price_change", "event_ts": "2026-01-14T16:28:02.820370", "ingestion_ts": "2026-01-14T16:33:58.842229", "market_id": "0xaf9d0e448129a9f657f851d49495ba4742055d80e0ef1166ba0ee81d4d594214", "raw": {"market": "0xaf9d0e448129a9f657f851d49495ba4742055d80e0ef1166ba0ee81d4d594214", "asset_id": "4153292802911610701832309484716814274802943278345248636922528170020319407796", "price": "0.984", "size": "128.13", "side": "SELL", "timestamp": "1768404483157", "received_at": "2026-01-14T16:28:02.820370"}}
{"event_type": "price_change", "event_ts": "2026-01-14T16:28:03.605479", "ingestion_ts": "2026-01-14T16:33:58.842229", "market_id": "0xe9c127a8c35f045d37b5344b0a36711084fa20c2fc1618bf178a5386f90610be", "raw": {"market": "0xe9c127a8c35f045d37b5344b0a36711084fa20c2fc1618bf178a5386f90610be", "asset_id": "107000426448217931795450451304515386602910396776318075817601265223856116134349", "price": "0.997", "size": "0", "side": "SELL", "timestamp": "1768404483941", "received_at": "2026-01-14T16:28:03.605479"}}
{"event_type": "price_change", "event_ts": "2026-01-14T16:28:03.605479", "ingestion_ts": "2026-01-14T16:33:58.842229", "market_id": "0xe9c127a8c35f045d37b5344b0a36711084fa20c2fc1618bf178a5386f90610be", "raw": {"market": "0xe9c127a8c35f045d37b5344b0a36711084fa20c2fc1618bf178a5386f90610be", "asset_id": "80230236018433940569996058935444651347308266584430516013229815570706872276819", "price": "0.003", "size": "0", "side": "BUY", "timestamp": "1768404483941", "received_at": "2026-01-14T16:28:03.605479"}}
{"event_type": "price_change", "event_ts": "2026-01-14T16:28:03.632305", "ingestion_ts": "2026-01-14T16:33:58.842229", "market_id": "0xe9c127a8c35f045d37b5344b0a36711084fa20c2fc1618bf178a5386f90610be", "raw": {"market": "0xe9c127a8c35f045d37b5344b0a36711084fa20c2fc1618bf178a5386f90610be", "asset_id": "107000426448217931795450451304515386602910396776318075817601265223856116134349", "price": "0.997", "size": "251", "side": "SELL", "timestamp": "1768404483968", "received_at": "2026-01-14T16:28:03.632305"}}
{"event_type": "price_change", "event_ts": "2026-01-14T16:28:03.632305", "ingestion_ts": "2026-01-14T16:33:58.842229", "market_id": "0xe9c127a8c35f045d37b5344b0a36711084fa20c2fc1618bf178a5386f90610be", "raw": {"market": "0xe9c127a8c35f045d37b5344b0a36711084fa20c2fc1618bf178a5386f90610be", "asset_id": "80230236018433940569996058935444651347308266584430516013229815570706872276819", "price": "0.003", "size": "251", "side": "BUY", "timestamp": "1768404483968", "received_at": "2026-01-14T16:28:03.632305"}}
{"event_type": "price_change", "event_ts": "2026-01-14T16:28:03.873222", "ingestion_ts": "2026-01-14T16:33:58.842229", "market_id": "0xaf9d0e448129a9f657f851d49495ba4742055d80e0ef1166ba0ee81d4d594214", "raw": {"market": "0xaf9d0e448129a9f657f851d49495ba4742055d80e0ef1166ba0ee81d4d594214", "asset_id": "4153292802911610701832309484716814274802943278345248636922528170020319407796", "price": "0.984", "size": "121", "side": "SELL", "timestamp": "1768404484204", "received_at": "2026-01-14T16:28:03.873222"}}
{"event_type": "price_change", "event_ts": "2026-01-14T16:28:03.873222", "ingestion_ts": "2026-01-14T16:33:58.842229", "market_id": "0xaf9d0e448129a9f657f851d49495ba4742055d80e0ef1166ba0ee81d4d594214", "raw": {"market": "0xaf9d0e448129a9f657f851d49495ba4742055d80e0ef1166ba0ee81d4d594214", "asset_id": "101676997363687199724245607342877036148401850938023978421879460310389391082353", "price": "0.016", "size": "121", "side": "BUY", "timestamp": "1768404484204", "received_at": "2026-01-14T16:28:03.873222"}}
{"event_type": "price_change", "event_ts": "2026-01-14T16:28:04.008027", "ingestion_ts": "2026-01-14T16:33:58.842229", "market_id": "0xaf9d0e448129a9f657f851d49495ba4742055d80e0ef1166ba0ee81d4d594214", "raw": {"market": "0xaf9d0e448129a9f657f851d49495ba4742055d80e0ef1166ba0ee81d4d594214", "asset_id": "4153292802911610701832309484716814274802943278345248636922528170020319407796", "price": "0.983", "size": "7.13", "side": "SELL", "timestamp": "1768404484345", "received_at": "2026-01-14T16:28:04.008027"}}
{"event_type": "price_change", "event_ts": "2026-01-14T16:28:04.008027", "ingestion_ts": "2026-01-14T16:33:58.842229", "market_id": "0xaf9d0e448129a9f657f851d49495ba4742055d80e0ef1166ba0ee81d4d594214", "raw": {"market": "0xaf9d0e448129a9f657f851d49495ba4742055d80e0ef1166ba0ee81d4d594214", "asset_id": "101676997363687199724245607342877036148401850938023978421879460310389391082353", "price": "0.017", "size": "7.13", "side": "BUY", "timestamp": "1768404484345", "received_at": "2026-01-14T16:28:04.008027"}}
{"event_type": "price_change", "event_ts": "2026-01-14T16:28:04.038669", "ingestion_ts": "2026-01-14T16:33:58.842229", "market_id": "0xaf9d0e448129a9f657f851d49495ba4742055d80e0ef1166ba0ee81d4d594214", "raw": {"market": "0xaf9d0e448129a9f657f851d49495ba4742055d80e0ef1166ba0ee81d4d594214", "asset_id": "101676997363687199724245607342877036148401850938023978421879460310389391082353", "price": "0.016", "size": "0", "side": "BUY", "timestamp": "1768404484376", "received_at": "2026-01-14T16:28:04.038669"}}
{"event_type": "price_change", "event_ts": "2026-01-14T16:28:04.038669", "ingestion_ts": "2026-01-14T16:33:58.842229", "market_id": "0xaf9d0e448129a9f657f851d49495ba4742055d80e0ef1166ba0ee81d4d594214", "raw": {"market": "0xaf9d0e448129a9f657f851d49495ba4742055d80e0ef1166ba0ee81d4d594214", "asset_id": "4153292802911610701832309484716814274802943278345248636922528170020319407796", "price": "0.984", "size": "0", "side": "SELL", "timestamp": "1768404484376", "received_at": "2026-01-14T16:28:04.038669"}}
{"event_type": "price_change", "event_ts": "2026-01-14T16:28:04.072334", "ingestion_ts": "2026-01-14T16:33:58.842229", "market_id": "0xaf9d0e448129a9f657f851d49495ba4742055d80e0ef1166ba0ee81d4d594214", "raw": {"market": "0xaf9d0e448129a9f657f851d49495ba4742055d80e0ef1166ba0ee81d4d594214", "asset_id": "101676997363687199724245607342877036148401850938023978421879460310389391082353", "price": "0.018", "size": "121", "side": "BUY", "timestamp": "1768404484403", "received_at": "2026-01-14T16:28:04.072334"}}
{"event_type": "price_change", "event_ts": "2026-01-14T16:28:04.072334", "ingestion_ts": "2026-01-14T16:33:58.842229", "market_id": "0xaf9d0e448129a9f657f851d49495ba4742055d80e0ef1166ba0ee81d4d594214", "raw": {"market": "0xaf9d0e448129a9f657f851d49495ba4742055d80e0ef1166ba0ee81d4d594214", "asset_id": "4153292802911610701832309484716814274802943278345248636922528170020319407796", "price": "0.982", "size": "121", "side": "SELL", "timestamp": "1768404484403", "received_at": "2026-01-14T16:28:04.072334"}}
{"event_type": "price_change", "event_ts": "2026-01-14T16:28:05.198006", "ingestion_ts": "2026-01-14T16:33:58.842229", "market_id": "0xe9c127a8c35f045d37b5344b0a36711084fa20c2fc1618bf178a5386f90610be", "raw": {"market": "0xe9c127a8c35f045d37b5344b0a36711084fa20c2fc1618bf178a5386f90610be", "asset_id": "107000426448217931795450451304515386602910396776318075817601265223856116134349", "price": "0.997", "size": "0", "side": "SELL", "timestamp": "1768404485440", "received_at": "2026-01-14T16:28:05.198006"}}
{"event_type": "price_change", "event_ts": "2026-01-14T16:28:05.198006", "ingestion_ts": "2026-01-14T16:33:58.842229", "market_id": "0xe9c127a8c35f045d37b5344b0a36711084fa20c2fc1618bf178a5386f90610be", "raw": {"market": "0xe9c127a8c35f045d37b5344b0a36711084fa20c2fc1618bf178a5386f90610be", "asset_id": "80230236018433940569996058935444651347308266584430516013229815570706872276819", "price": "0.003", "size": "0", "side": "BUY", "timestamp": "1768404485440", "received_at": "2026-01-14T16:28:05.198006"}}
{"event_type": "price_change", "event_ts": "2026-01-14T16:28:05.325416", "ingestion_ts": "2026-01-14T16:33:58.842229", "market_id": "0xe9c127a8c35f045d37b5344b0a36711084fa20c2fc1618bf178a5386f90610be", "raw": {"market": "0xe9c127a8c35f045d37b5344b0a36711084fa20c2fc1618bf178a5386f90610be", "asset_id": "107000426448217931795450451304515386602910396776318075817601265223856116134349", "price": "0.997", "size": "251", "side": "SELL", "timestamp": "1768404485529", "received_at": "2026-01-14T16:28:05.325416"}}
{"event_type": "price_change", "event_ts": "2026-01-14T16:28:05.325416", "ingestion_ts": "2026-01-14T16:33:58.842229", "market_id": "0xe9c127a8c35f045d37b5344b0a36711084fa20c2fc1618bf178a5386f90610be", "raw": {"market": "0xe9c127a8c35f045d37b5344b0a36711084fa20c2fc1618bf178a5386f90610be", "asset_id": "80230236018433940569996058935444651347308266584430516013229815570706872276819", "price": "0.003", "size": "251", "side": "BUY", "timestamp": "1768404485529", "received_at": "2026-01-14T16:28:05.325416"}}
{"event_type": "price_change", "event_ts": "2026-01-14T16:28:05.931419", "ingestion_ts": "2026-01-14T16:33:58.842229", "market_id": "0xe9c127a8c35f045d37b5344b0a36711084fa20c2fc1618bf178a5386f90610be", "raw": {"market": "0xe9c127a8c35f045d37b5344b0a36711084fa20c2fc1618bf178a5386f90610be", "asset_id": "80230236018433940569996058935444651347308266584430516013229815570706872276819", "price": "0.003", "size": "301.2", "side": "BUY", "timestamp": "1768404486259", "received_at": "2026-01-14T16:28:05.931419"}}
{"event_type": "price_change", "event_ts": "2026-01-14T16:28:05.931419", "ingestion_ts": "2026-01-14T16:33:58.842229", "market_id": "0xe9c127a8c35f045d37b5344b0a36711084fa20c2fc1618bf178a5386f90610be", "raw": {"market": "0xe9c127a8c35f045d37b5344b0a36711084fa20c2fc1618bf178a5386f90610be", "asset_id": "107000426448217931795450451304515386602910396776318075817601265223856116134349", "price": "0.997", "size": "301.2", "side": "SELL", "timestamp": "1768404486259", "received_at": "2026-01-14T16:28:05.931419"}}
{"event_type": "price_change", "event_ts": "2026-01-14T16:28:06.181937", "ingestion_ts": "2026-01-14T16:33:58.842229", "market_id": "0xaf9d0e448129a9f657f851d49495ba4742055d80e0ef1166ba0ee81d4d594214", "raw": {"market": "0xaf9d0e448129a9f657f851d49495ba4742055d80e0ef1166ba0ee81d4d594214", "asset_id": "4153292802911610701832309484716814274802943278345248636922528170020319407796", "price": "0.983", "size": "0", "side": "SELL", "timestamp": "1768404486501", "received_at": "2026-01-14T16:28:06.181937"}}
{"event_type": "price_change", "event_ts": "2026-01-14T16:28:06.181937", "ingestion_ts": "2026-01-14T16:33:58.842229", "market_id": "0xaf9d0e448129a9f657f851d49495ba4742055d80e0ef1166ba0ee81d4d594214", "raw": {"market": "0xaf9d0e448129a9f657f851d49495ba4742055d80e0ef1166ba0ee81d4d594214", "asset_id": "101676997363687199724245607342877036148401850938023978421879460310389391082353", "price": "0.017", "size": "0", "side": "BUY", "timestamp": "1768404486501", "received_at": "2026-01-14T16:28:06.181937"}}
{"event_type": "price_change", "event_ts": "2026-01-14T16:28:06.318528", "ingestion_ts": "2026-01-14T16:33:58.842229", "market_id": "0xaf9d0e448129a9f657f851d49495ba4742055d80e0ef1166ba0ee81d4d594214", "raw": {"market": "0xaf9d0e448129a9f657f851d49495ba4742055d80e0ef1166ba0ee81d4d594214", "asset_id": "4153292802911610701832309484716814274802943278345248636922528170020319407796", "price": "0.984", "size": "7.13", "side": "SELL", "timestamp": "1768404486655", "received_at": "2026-01-14T16:28:06.318528"}}
{"event_type": "price_change", "event_ts": "2026-01-14T16:28:06.318528", "ingestion_ts": "2026-01-14T16:33:58.842229", "market_id": "0xaf9d0e448129a9f657f851d49495ba4742055d80e0ef1166ba0ee81d4d594214", "raw": {"market": "0xaf9d0e448129a9f657f851d49495ba4742055d80e0ef1166ba0ee81d4d594214", "asset_id": "101676997363687199724245607342877036148401850938023978421879460310389391082353", "price": "0.016", "size": "7.13", "side": "BUY", "timestamp": "1768404486655", "received_at": "2026-01-14T16:28:06.318528"}}
{"event_type": "price_change", "event_ts": "2026-01-14T16:28:06.606069", "ingestion_ts": "2026-01-14T16:33:58.842229", "market_id": "0xe9c127a8c35f045d37b5344b0a36711084fa20c2fc1618bf178a5386f90610be", "raw": {"market": "0xe9c127a8c35f045d37b5344b0a36711084fa20c2fc1618bf178a5386f90610be", "asset_id": "107000426448217931795450451304515386602910396776318075817601265223856116134349", "price": "0.997", "size": "50.2", "side": "SELL", "timestamp": "1768404486941", "received_at": "2026-01-14T16:28:06.606069"}}
{"event_type": "price_change", "event_ts": "2026-01-14T16:28:06.606069", "ingestion_ts": "2026-01-14T16:33:58.842229", "market_id": "0xe9c127a8c35f045d37b5344b0a36711084fa20c2fc1618bf178a5386f90610be", "raw": {"market": "0xe9c127a8c35f045d37b5344b0a36711084fa20c2fc1618bf178a5386f90610be", "asset_id": "80230236018433940569996058935444651347308266584430516013229815570706872276819", "price": "0.003", "size": "50.2", "side": "BUY", "timestamp": "1768404486941", "received_at": "2026-01-14T16:28:06.606069"}}
{"event_type": "price_change", "event_ts": "2026-01-14T16:28:08.502476", "ingestion_ts": "2026-01-14T16:33:58.842229", "market_id": "0xe6508d867d153a268bdab732aa8abc8cc57e652d28a23aa042da40895bf031b2", "raw": {"market": "0xe6508d867d153a268bdab732aa8abc8cc57e652d28a23aa042da40895bf031b2", "asset_id": "57878493050148425637822780001963685814731344602319345842647239312888833935027", "price": "0.999", "size": "32270.05", "side": "SELL", "timestamp": "1768404488835", "received_at": "2026-01-14T16:28:08.502476"}}
{"event_type": "price_change", "event_ts": "2026-01-14T16:28:08.502476", "ingestion_ts": "2026-01-14T16:33:58.842229", "market_id": "0xe6508d867d153a268bdab732aa8abc8cc57e652d28a23aa042da40895bf031b2", "raw": {"market": "0xe6508d867d153a268bdab732aa8abc8cc57e652d28a23aa042da40895bf031b2", "asset_id": "2853768819561879023657600399360829876689515906714535926781067187993853038980", "price": "0.001", "size": "32270.05", "side": "BUY", "timestamp": "1768404488835", "received_at": "2026-01-14T16:28:08.502476"}}
{"event_type": "price_change", "event_ts": "2026-01-14T16:28:09.535310", "ingestion_ts": "2026-01-14T16:33:58.842229", "market_id": "0x49686d26fb712515cd5e12c23f0a1c7e10214c7faa3cb0a730aabe0c33694082", "raw": {"market": "0x49686d26fb712515cd5e12c23f0a1c7e10214c7faa3cb0a730aabe0c33694082", "asset_id": "13244681086321087932946246027856416106585284024824496763706748621681543444582", "price": "0.851", "size": "500", "side": "BUY", "timestamp": "1768404489748", "received_at": "2026-01-14T16:28:09.535310"}}
{"event_type": "price_change", "event_ts": "2026-01-14T16:28:09.535310", "ingestion_ts": "2026-01-14T16:33:58.842229", "market_id": "0x49686d26fb712515cd5e12c23f0a1c7e10214c7faa3cb0a730aabe0c33694082", "raw": {"market": "0x49686d26fb712515cd5e12c23f0a1c7e10214c7faa3cb0a730aabe0c33694082", "asset_id": "30442780799048074404860985387051749017905070253466005720364298335239299761065", "price": "0.149", "size": "500", "side": "SELL", "timestamp": "1768404489748", "received_at": "2026-01-14T16:28:09.535310"}}
{"event_type": "price_change", "event_ts": "2026-01-14T16:28:09.767279", "ingestion_ts": "2026-01-14T16:33:58.842229", "market_id": "0x49686d26fb712515cd5e12c23f0a1c7e10214c7faa3cb0a730aabe0c33694082", "raw": {"market": "0x49686d26fb712515cd5e12c23f0a1c7e10214c7faa3cb0a730aabe0c33694082", "asset_id": "13244681086321087932946246027856416106585284024824496763706748621681543444582", "price": "0.899", "size": "16", "side": "SELL", "timestamp": "1768404489893", "received_at": "2026-01-14T16:28:09.767279"}}
{"event_type": "price_change", "event_ts": "2026-01-14T16:28:09.767279", "ingestion_ts": "2026-01-14T16:33:58.842229", "market_id": "0x49686d26fb712515cd5e12c23f0a1c7e10214c7faa3cb0a730aabe0c33694082", "raw": {"market": "0x49686d26fb712515cd5e12c23f0a1c7e10214c7faa3cb0a730aabe0c33694082", "asset_id": "30442780799048074404860985387051749017905070253466005720364298335239299761065", "price": "0.101", "size": "16", "side": "BUY", "timestamp": "1768404489893", "received_at": "2026-01-14T16:28:09.767279"}}
{"event_type": "price_change", "event_ts": "2026-01-14T16:28:09.780722", "ingestion_ts": "2026-01-14T16:33:58.842229", "market_id": "0x49686d26fb712515cd5e12c23f0a1c7e10214c7faa3cb0a730aabe0c33694082", "raw": {"market": "0x49686d26fb712515cd5e12c23f0a1c7e10214c7faa3cb0a730aabe0c33694082", "asset_id": "13244681086321087932946246027856416106585284024824496763706748621681543444582", "price": "0.907", "size": "133", "side": "SELL", "timestamp": "1768404489921", "received_at": "2026-01-14T16:28:09.780722"}}
{"event_type": "price_change", "event_ts": "2026-01-14T16:28:09.780722", "ingestion_ts": "2026-01-14T16:33:58.842229", "market_id": "0x49686d26fb712515cd5e12c23f0a1c7e10214c7faa3cb0a730aabe0c33694082", "raw": {"market": "0x49686d26fb712515cd5e12c23f0a1c7e10214c7faa3cb0a730aabe0c33694082", "asset_id": "30442780799048074404860985387051749017905070253466005720364298335239299761065", "price": "0.093", "size": "133", "side": "BUY", "timestamp": "1768404489921", "received_at": "2026-01-14T16:28:09.780722"}}
{"event_type": "price_change", "event_ts": "2026-01-14T16:28:13.791599", "ingestion_ts": "2026-01-14T16:33:58.842229", "market_id": "0x49686d26fb712515cd5e12c23f0a1c7e10214c7faa3cb0a730aabe0c33694082", "raw": {"market": "0x49686d26fb712515cd5e12c23f0a1c7e10214c7faa3cb0a730aabe0c33694082", "asset_id": "13244681086321087932946246027856416106585284024824496763706748621681543444582", "price": "0.851", "size": "550", "side": "BUY", "timestamp": "1768404493951", "received_at": "2026-01-14T16:28:13.791599"}}
{"event_type": "price_change", "event_ts": "2026-01-14T16:28:13.791599", "ingestion_ts": "2026-01-14T16:33:58.842229", "market_id": "0x49686d26fb712515cd5e12c23f0a1c7e10214c7faa3cb0a730aabe0c33694082", "raw": {"market": "0x49686d26fb712515cd5e12c23f0a1c7e10214c7faa3cb0a730aabe0c33694082", "asset_id": "30442780799048074404860985387051749017905070253466005720364298335239299761065", "price": "0.149", "size": "550", "side": "SELL", "timestamp": "1768404493951", "received_at": "2026-01-14T16:28:13.791599"}}
{"event_type": "price_change", "event_ts": "2026-01-14T16:28:13.846257", "ingestion_ts": "2026-01-14T16:33:58.842229", "market_id": "0x49686d26fb712515cd5e12c23f0a1c7e10214c7faa3cb0a730aabe0c33694082", "raw": {"market": "0x49686d26fb712515cd5e12c23f0a1c7e10214c7faa3cb0a730aabe0c33694082", "asset_id": "30442780799048074404860985387051749017905070253466005720364298335239299761065", "price": "0.094", "size": "50", "side": "BUY", "timestamp": "1768404494005", "received_at": "2026-01-14T16:28:13.846257"}}
{"event_type": "price_change", "event_ts": "2026-01-14T16:28:13.846257", "ingestion_ts": "2026-01-14T16:33:58.842229", "market_id": "0x49686d26fb712515cd5e12c23f0a1c7e10214c7faa3cb0a730aabe0c33694082", "raw": {"market": "0x49686d26fb712515cd5e12c23f0a1c7e10214c7faa3cb0a730aabe0c33694082", "asset_id": "13244681086321087932946246027856416106585284024824496763706748621681543444582", "price": "0.906", "size": "50", "side": "SELL", "timestamp": "1768404494005", "received_at": "2026-01-14T16:28:13.846257"}}
{"event_type": "price_change", "event_ts": "2026-01-14T16:28:13.872039", "ingestion_ts": "2026-01-14T16:33:58.842229", "market_id": "0x49686d26fb712515cd5e12c23f0a1c7e10214c7faa3cb0a730aabe0c33694082", "raw": {"market": "0x49686d26fb712515cd5e12c23f0a1c7e10214c7faa3cb0a730aabe0c33694082", "asset_id": "13244681086321087932946246027856416106585284024824496763706748621681543444582", "price": "0.907", "size": "0", "side": "SELL", "timestamp": "1768404494041", "received_at": "2026-01-14T16:28:13.872039"}}
{"event_type": "price_change", "event_ts": "2026-01-14T16:28:13.872039", "ingestion_ts": "2026-01-14T16:33:58.842229", "market_id": "0x49686d26fb712515cd5e12c23f0a1c7e10214c7faa3cb0a730aabe0c33694082", "raw": {"market": "0x49686d26fb712515cd5e12c23f0a1c7e10214c7faa3cb0a730aabe0c33694082", "asset_id": "30442780799048074404860985387051749017905070253466005720364298335239299761065", "price": "0.093", "size": "0", "side": "BUY", "timestamp": "1768404494041", "received_at": "2026-01-14T16:28:13.872039"}}
{"event_type": "price_change", "event_ts": "2026-01-14T16:28:13.895371", "ingestion_ts": "2026-01-14T16:33:58.842229", "market_id": "0x49686d26fb712515cd5e12c23f0a1c7e10214c7faa3cb0a730aabe0c33694082", "raw": {"market": "0x49686d26fb712515cd5e12c23f0a1c7e10214c7faa3cb0a730aabe0c33694082", "asset_id": "13244681086321087932946246027856416106585284024824496763706748621681543444582", "price": "0.899", "size": "134", "side": "SELL", "timestamp": "1768404494071", "received_at": "2026-01-14T16:28:13.895371"}}
{"event_type": "price_change", "event_ts": "2026-01-14T16:28:13.895371", "ingestion_ts": "2026-01-14T16:33:58.842229", "market_id": "0x49686d26fb712515cd5e12c23f0a1c7e10214c7faa3cb0a730aabe0c33694082", "raw": {"market": "0x49686d26fb712515cd5e12c23f0a1c7e10214c7faa3cb0a730aabe0c33694082", "asset_id": "30442780799048074404860985387051749017905070253466005720364298335239299761065", "price": "0.101", "size": "134", "side": "BUY", "timestamp": "1768404494071", "received_at": "2026-01-14T16:28:13.895371"}}
{"event_type": "price_change", "event_ts": "2026-01-14T16:28:13.915361", "ingestion_ts": "2026-01-14T16:33:58.842229", "market_id": "0x9472be65457510b7fc3477b20ba90910e99d92eac8421a14bf4b7b7a08ef31dc", "raw": {"market": "0x9472be65457510b7fc3477b20ba90910e99d92eac8421a14bf4b7b7a08ef31dc", "asset_id": "43311793366960417907757893276427136943959788721376762326430771171648759300146", "price": "0.825", "size": "0", "side": "BUY", "timestamp": "1768404494098", "received_at": "2026-01-14T16:28:13.915361"}}
{"event_type": "price_change", "event_ts": "2026-01-14T16:28:13.915361", "ingestion_ts": "2026-01-14T16:33:58.842229", "market_id": "0x9472be65457510b7fc3477b20ba90910e99d92eac8421a14bf4b7b7a08ef31dc", "raw": {"market": "0x9472be65457510b7fc3477b20ba90910e99d92eac8421a14bf4b7b7a08ef31dc", "asset_id": "73414222381656326204771753454630063673548497164758947581648273905027617570612", "price": "0.175", "size": "0", "side": "SELL", "timestamp": "1768404494098", "received_at": "2026-01-14T16:28:13.915361"}}
{"event_type": "price_change", "event_ts": "2026-01-14T16:28:13.915403", "ingestion_ts": "2026-01-14T16:33:58.842229", "market_id": "0x50c669f178da4e5bbea7f1be25041fd278914712fa87a6a6f8e57d5923d88dee", "raw": {"market": "0x50c669f178da4e5bbea7f1be25041fd278914712fa87a6a6f8e57d5923d88dee", "asset_id": "74040420326294854165772767082819937451857852955603897473157746262672057685461", "price": "0.824", "size": "0", "side": "BUY", "timestamp": "1768404494098", "received_at": "2026-01-14T16:28:13.915403"}}
{"event_type": "price_change", "event_ts": "2026-01-14T16:28:13.915403", "ingestion_ts": "2026-01-14T16:33:58.842229", "market_id": "0x50c669f178da4e5bbea7f1be25041fd278914712fa87a6a6f8e57d5923d88dee", "raw": {"market": "0x50c669f178da4e5bbea7f1be25041fd278914712fa87a6a6f8e57d5923d88dee", "asset_id": "24682525479474221428144937281315825971983904267399062415430320764754931667953", "price": "0.176", "size": "0", "side": "SELL", "timestamp": "1768404494098", "received_at": "2026-01-14T16:28:13.915403"}}
{"event_type": "price_change", "event_ts": "2026-01-14T16:28:13.915427", "ingestion_ts": "2026-01-14T16:33:58.842229", "market_id": "0x49a20c7523c271099008f3ef9a31521263b24d637959852a391e6b4697b1a437", "raw": {"market": "0x49a20c7523c271099008f3ef9a31521263b24d637959852a391e6b4697b1a437", "asset_id": "55881023621710858558280545117465775643848233756850602339827152783696837905531", "price": "0.825", "size": "0", "side": "BUY", "timestamp": "1768404494098", "received_at": "2026-01-14T16:28:13.915427"}}
{"event_type": "price_change", "event_ts": "2026-01-14T16:28:13.915427", "ingestion_ts": "2026-01-14T16:33:58.842229", "market_id": "0x49a20c7523c271099008f3ef9a31521263b24d637959852a391e6b4697b1a437", "raw": {"market": "0x49a20c7523c271099008f3ef9a31521263b24d637959852a391e6b4697b1a437", "asset_id": "13018971792603393862521629014128024641178044618205296260525674415067194037856", "price": "0.175", "size": "0", "side": "SELL", "timestamp": "1768404494098", "received_at": "2026-01-14T16:28:13.915427"}}
{"event_type": "price_change", "event_ts": "2026-01-14T16:28:13.915446", "ingestion_ts": "2026-01-14T16:33:58.842229", "market_id": "0x44f08744458b8896620cd3330bc5e1ea69df4199b02d4fc583b3fc96e5d314ce", "raw": {"market": "0x44f08744458b8896620cd3330bc5e1ea69df4199b02d4fc583b3fc96e5d314ce", "asset_id": "72327831507226612545928776794104143393438710920370371172884559893525100761096", "price": "0.881", "size": "0", "side": "BUY", "timestamp": "1768404494098", "received_at": "2026-01-14T16:28:13.915446"}}
{"event_type": "price_change", "event_ts": "2026-01-14T16:28:13.915446", "ingestion_ts": "2026-01-14T16:33:58.842229", "market_id": "0x44f08744458b8896620cd3330bc5e1ea69df4199b02d4fc583b3fc96e5d314ce", "raw": {"market": "0x44f08744458b8896620cd3330bc5e1ea69df4199b02d4fc583b3fc96e5d314ce", "asset_id": "49194009556504828848509244326501559253829462790583873936160989575507522044057", "price": "0.119", "size": "0", "side": "SELL", "timestamp": "1768404494098", "received_at": "2026-01-14T16:28:13.915446"}}
{"event_type": "price_change", "event_ts": "2026-01-14T16:28:13.915463", "ingestion_ts": "2026-01-14T16:33:58.842229", "market_id": "0x2393ed0b0fdc450054c7b9071907eca75cf4fc36e385adf4a0a5f99ee62243e8", "raw": {"market": "0x2393ed0b0fdc450054c7b9071907eca75cf4fc36e385adf4a0a5f99ee62243e8", "asset_id": "32769749367306925959219403371425714180265458150646381231272229429098460625924", "price": "0.813", "size": "0", "side": "BUY", "timestamp": "1768404494098", "received_at": "2026-01-14T16:28:13.915463"}}
{"event_type": "price_change", "event_ts": "2026-01-14T16:28:13.915463", "ingestion_ts": "2026-01-14T16:33:58.842229", "market_id": "0x2393ed0b0fdc450054c7b9071907eca75cf4fc36e385adf4a0a5f99ee62243e8", "raw": {"market": "0x2393ed0b0fdc450054c7b9071907eca75cf4fc36e385adf4a0a5f99ee62243e8", "asset_id": "100074770378634056601572485653252702850363676459996771990439989989293515601975", "price": "0.187", "size": "0", "side": "SELL", "timestamp": "1768404494098", "received_at": "2026-01-14T16:28:13.915463"}}
{"event_type": "price_change", "event_ts": "2026-01-14T16:28:13.915482", "ingestion_ts": "2026-01-14T16:33:58.842229", "market_id": "0xaf9d0e448129a9f657f851d49495ba4742055d80e0ef1166ba0ee81d4d594214", "raw": {"market": "0xaf9d0e448129a9f657f851d49495ba4742055d80e0ef1166ba0ee81d4d594214", "asset_id": "4153292802911610701832309484716814274802943278345248636922528170020319407796", "price": "0.728", "size": "274", "side": "BUY", "timestamp": "1768404494098", "received_at": "2026-01-14T16:28:13.915482"}}
{"event_type": "price_change", "event_ts": "2026-01-14T16:28:13.915482", "ingestion_ts": "2026-01-14T16:33:58.842229", "market_id": "0xaf9d0e448129a9f657f851d49495ba4742055d80e0ef1166ba0ee81d4d594214", "raw": {"market": "0xaf9d0e448129a9f657f851d49495ba4742055d80e0ef1166ba0ee81d4d594214", "asset_id": "101676997363687199724245607342877036148401850938023978421879460310389391082353", "price": "0.272", "size": "274", "side": "SELL", "timestamp": "1768404494098", "received_at": "2026-01-14T16:28:13.915482"}}
{"event_type": "price_change", "event_ts": "2026-01-14T16:28:13.916694", "ingestion_ts": "2026-01-14T16:33:58.842229", "market_id": "0xc55db914f0fd1fee18997706712c0dfd8d0369cdbef93a9fef12bd001914ca77", "raw": {"market": "0xc55db914f0fd1fee18997706712c0dfd8d0369cdbef93a9fef12bd001914ca77", "asset_id": "114600293444080540179603459515770723592661967180480327891296353898330242622833", "price": "0.837", "size": "0", "side": "BUY", "timestamp": "1768404494098", "received_at": "2026-01-14T16:28:13.916694"}}
{"event_type": "price_change", "event_ts": "2026-01-14T16:28:13.916694", "ingestion_ts": "2026-01-14T16:33:58.842229", "market_id": "0xc55db914f0fd1fee18997706712c0dfd8d0369cdbef93a9fef12bd001914ca77", "raw": {"market": "0xc55db914f0fd1fee18997706712c0dfd8d0369cdbef93a9fef12bd001914ca77", "asset_id": "72354723612769247426741660426331235762851940382312402276325808095604519806766", "price": "0.163", "size": "0", "side": "SELL", "timestamp": "1768404494098", "received_at": "2026-01-14T16:28:13.916694"}}
{"event_type": "price_change", "event_ts": "2026-01-14T16:28:13.916731", "ingestion_ts": "2026-01-14T16:33:58.842229", "market_id": "0xb9bbdd34304344dcc45803780a34c97d73a00133a5ecf70f63e1008b8abb2fca", "raw": {"market": "0xb9bbdd34304344dcc45803780a34c97d73a00133a5ecf70f63e1008b8abb2fca", "asset_id": "8682484153073832526711485265636767086525069344085206423986003504588877767339", "price": "0.839", "size": "0", "side": "BUY", "timestamp": "1768404494098", "received_at": "2026-01-14T16:28:13.916731"}}
{"event_type": "price_change", "event_ts": "2026-01-14T16:28:13.916731", "ingestion_ts": "2026-01-14T16:33:58.842229", "market_id": "0xb9bbdd34304344dcc45803780a34c97d73a00133a5ecf70f63e1008b8abb2fca", "raw": {"market": "0xb9bbdd34304344dcc45803780a34c97d73a00133a5ecf70f63e1008b8abb2fca", "asset_id": "72012724360700510767037780555710363830014634797787940282136454146828040926557", "price": "0.161", "size": "0", "side": "SELL", "timestamp": "1768404494098", "received_at": "2026-01-14T16:28:13.916731"}}
{"event_type": "price_change", "event_ts": "2026-01-14T16:28:13.966496", "ingestion_ts": "2026-01-14T16:33:58.842229", "market_id": "0xaf9d0e448129a9f657f851d49495ba4742055d80e0ef1166ba0ee81d4d594214", "raw": {"market": "0xaf9d0e448129a9f657f851d49495ba4742055d80e0ef1166ba0ee81d4d594214", "asset_id": "4153292802911610701832309484716814274802943278345248636922528170020319407796", "price": "0.731", "size": "20", "side": "BUY", "timestamp": "1768404494215", "received_at": "2026-01-14T16:28:13.966496"}}
{"event_type": "price_change", "event_ts": "2026-01-14T16:28:13.966496", "ingestion_ts": "2026-01-14T16:33:58.842229", "market_id": "0xaf9d0e448129a9f657f851d49495ba4742055d80e0ef1166ba0ee81d4d594214", "raw": {"market": "0xaf9d0e448129a9f657f851d49495ba4742055d80e0ef1166ba0ee81d4d594214", "asset_id": "101676997363687199724245607342877036148401850938023978421879460310389391082353", "price": "0.269", "size": "20", "side": "SELL", "timestamp": "1768404494215", "received_at": "2026-01-14T16:28:13.966496"}}
{"event_type": "price_change", "event_ts": "2026-01-14T16:28:13.966533", "ingestion_ts": "2026-01-14T16:33:58.842229", "market_id": "0x2393ed0b0fdc450054c7b9071907eca75cf4fc36e385adf4a0a5f99ee62243e8", "raw": {"market": "0x2393ed0b0fdc450054c7b9071907eca75cf4fc36e385adf4a0a5f99ee62243e8", "asset_id": "32769749367306925959219403371425714180265458150646381231272229429098460625924", "price": "0.815", "size": "20", "side": "BUY", "timestamp": "1768404494215", "received_at": "2026-01-14T16:28:13.966533"}}
{"event_type": "price_change", "event_ts": "2026-01-14T16:28:13.966533", "ingestion_ts": "2026-01-14T16:33:58.842229", "market_id": "0x2393ed0b0fdc450054c7b9071907eca75cf4fc36e385adf4a0a5f99ee62243e8", "raw": {"market": "0x2393ed0b0fdc450054c7b9071907eca75cf4fc36e385adf4a0a5f99ee62243e8", "asset_id": "100074770378634056601572485653252702850363676459996771990439989989293515601975", "price": "0.185", "size": "20", "side": "SELL", "timestamp": "1768404494215", "received_at": "2026-01-14T16:28:13.966533"}}
{"event_type": "price_change", "event_ts": "2026-01-14T16:28:13.966548", "ingestion_ts": "2026-01-14T16:33:58.842229", "market_id": "0x9472be65457510b7fc3477b20ba90910e99d92eac8421a14bf4b7b7a08ef31dc", "raw": {"market": "0x9472be65457510b7fc3477b20ba90910e99d92eac8421a14bf4b7b7a08ef31dc", "asset_id": "43311793366960417907757893276427136943959788721376762326430771171648759300146", "price": "0.829", "size": "20", "side": "BUY", "timestamp": "1768404494216", "received_at": "2026-01-14T16:28:13.966548"}}
{"event_type": "price_change", "event_ts": "2026-01-14T16:28:13.966548", "ingestion_ts": "2026-01-14T16:33:58.842229", "market_id": "0x9472be65457510b7fc3477b20ba90910e99d92eac8421a14bf4b7b7a08ef31dc", "raw": {"market": "0x9472be65457510b7fc3477b20ba90910e99d92eac8421a14bf4b7b7a08ef31dc", "asset_id": "73414222381656326204771753454630063673548497164758947581648273905027617570612", "price": "0.171", "size": "20", "side": "SELL", "timestamp": "1768404494216", "received_at": "2026-01-14T16:28:13.966548"}}
{"event_type": "price_change", "event_ts": "2026-01-14T16:28:13.966559", "ingestion_ts": "2026-01-14T16:33:58.842229", "market_id": "0x50c669f178da4e5bbea7f1be25041fd278914712fa87a6a6f8e57d5923d88dee", "raw": {"market": "0x50c669f178da4e5bbea7f1be25041fd278914712fa87a6a6f8e57d5923d88dee", "asset_id": "74040420326294854165772767082819937451857852955603897473157746262672057685461", "price": "0.824", "size": "20", "side": "BUY", "timestamp": "1768404494216", "received_at": "2026-01-14T16:28:13.966559"}}
{"event_type": "price_change", "event_ts": "2026-01-14T16:28:13.966559", "ingestion_ts": "2026-01-14T16:33:58.842229", "market_id": "0x50c669f178da4e5bbea7f1be25041fd278914712fa87a6a6f8e57d5923d88dee", "raw": {"market": "0x50c669f178da4e5bbea7f1be25041fd278914712fa87a6a6f8e57d5923d88dee", "asset_id": "24682525479474221428144937281315825971983904267399062415430320764754931667953", "price": "0.176", "size": "20", "side": "SELL", "timestamp": "1768404494216", "received_at": "2026-01-14T16:28:13.966559"}}
{"event_type": "price_change", "event_ts": "2026-01-14T16:28:13.966569", "ingestion_ts": "2026-01-14T16:33:58.842229", "market_id": "0xc55db914f0fd1fee18997706712c0dfd8d0369cdbef93a9fef12bd001914ca77", "raw": {"market": "0xc55db914f0fd1fee18997706712c0dfd8d0369cdbef93a9fef12bd001914ca77", "asset_id": "114600293444080540179603459515770723592661967180480327891296353898330242622833", "price": "0.841", "size": "20", "side": "BUY", "timestamp": "1768404494216", "received_at": "2026-01-14T16:28:13.966569"}}
{"event_type": "price_change", "event_ts": "2026-01-14T16:28:13.966569", "ingestion_ts": "2026-01-14T16:33:58.842229", "market_id": "0xc55db914f0fd1fee18997706712c0dfd8d0369cdbef93a9fef12bd001914ca77", "raw": {"market": "0xc55db914f0fd1fee18997706712c0dfd8d0369cdbef93a9fef12bd001914ca77", "asset_id": "72354723612769247426741660426331235762851940382312402276325808095604519806766", "price": "0.159", "size": "20", "side": "SELL", "timestamp": "1768404494216", "received_at": "2026-01-14T16:28:13.966569"}}
{"event_type": "price_change", "event_ts": "2026-01-14T16:28:13.966579", "ingestion_ts": "2026-01-14T16:33:58.842229", "market_id": "0x49a20c7523c271099008f3ef9a31521263b24d637959852a391e6b4697b1a437", "raw": {"market": "0x49a20c7523c271099008f3ef9a31521263b24d637959852a391e6b4697b1a437", "asset_id": "55881023621710858558280545117465775643848233756850602339827152783696837905531", "price": "0.825", "size": "20", "side": "BUY", "timestamp": "1768404494216", "received_at": "2026-01-14T16:28:13.966579"}}
{"event_type": "price_change", "event_ts": "2026-01-14T16:28:13.966579", "ingestion_ts": "2026-01-14T16:33:58.842229", "market_id": "0x49a20c7523c271099008f3ef9a31521263b24d637959852a391e6b4697b1a437", "raw": {"market": "0x49a20c7523c271099008f3ef9a31521263b24d637959852a391e6b4697b1a437", "asset_id": "13018971792603393862521629014128024641178044618205296260525674415067194037856", "price": "0.175", "size": "20", "side": "SELL", "timestamp": "1768404494216", "received_at": "2026-01-14T16:28:13.966579"}}
{"event_type": "price_change", "event_ts": "2026-01-14T16:28:13.969027", "ingestion_ts": "2026-01-14T16:33:58.842229", "market_id": "0x44f08744458b8896620cd3330bc5e1ea69df4199b02d4fc583b3fc96e5d314ce", "raw": {"market": "0x44f08744458b8896620cd3330bc5e1ea69df4199b02d4fc583b3fc96e5d314ce", "asset_id": "72327831507226612545928776794104143393438710920370371172884559893525100761096", "price": "0.891", "size": "20", "side": "BUY", "timestamp": "1768404494216", "received_at": "2026-01-14T16:28:13.969027"}}
{"event_type": "price_change", "event_ts": "2026-01-14T16:28:13.969027", "ingestion_ts": "2026-01-14T16:33:58.842229", "market_id": "0x44f08744458b8896620cd3330bc5e1ea69df4199b02d4fc583b3fc96e5d314ce", "raw": {"market": "0x44f08744458b8896620cd3330bc5e1ea69df4199b02d4fc583b3fc96e5d314ce", "asset_id": "49194009556504828848509244326501559253829462790583873936160989575507522044057", "price": "0.109", "size": "20", "side": "SELL", "timestamp": "1768404494216", "received_at": "2026-01-14T16:28:13.969027"}}
{"event_type": "price_change", "event_ts": "2026-01-14T16:28:13.969057", "ingestion_ts": "2026-01-14T16:33:58.842229", "market_id": "0xb9bbdd34304344dcc45803780a34c97d73a00133a5ecf70f63e1008b8abb2fca", "raw": {"market": "0xb9bbdd34304344dcc45803780a34c97d73a00133a5ecf70f63e1008b8abb2fca", "asset_id": "8682484153073832526711485265636767086525069344085206423986003504588877767339", "price": "0.839", "size": "20", "side": "BUY", "timestamp": "1768404494216", "received_at": "2026-01-14T16:28:13.969057"}}
{"event_type": "price_change", "event_ts": "2026-01-14T16:28:13.969057", "ingestion_ts": "2026-01-14T16:33:58.842229", "market_id": "0xb9bbdd34304344dcc45803780a34c97d73a00133a5ecf70f63e1008b8abb2fca", "raw": {"market": "0xb9bbdd34304344dcc45803780a34c97d73a00133a5ecf70f63e1008b8abb2fca", "asset_id": "72012724360700510767037780555710363830014634797787940282136454146828040926557", "price": "0.161", "size": "20", "side": "SELL", "timestamp": "1768404494216", "received_at": "2026-01-14T16:28:13.969057"}}
{"event_type": "price_change", "event_ts": "2026-01-14T16:28:19.854079", "ingestion_ts": "2026-01-14T16:33:58.842229", "market_id": "0x49686d26fb712515cd5e12c23f0a1c7e10214c7faa3cb0a730aabe0c33694082", "raw": {"market": "0x49686d26fb712515cd5e12c23f0a1c7e10214c7faa3cb0a730aabe0c33694082", "asset_id": "30442780799048074404860985387051749017905070253466005720364298335239299761065", "price": "0.094", "size": "0", "side": "BUY", "timestamp": "1768404500189", "received_at": "2026-01-14T16:28:19.854079"}}
{"event_type": "price_change", "event_ts": "2026-01-14T16:28:19.854079", "ingestion_ts": "2026-01-14T16:33:58.842229", "market_id": "0x49686d26fb712515cd5e12c23f0a1c7e10214c7faa3cb0a730aabe0c33694082", "raw": {"market": "0x49686d26fb712515cd5e12c23f0a1c7e10214c7faa3cb0a730aabe0c33694082", "asset_id": "13244681086321087932946246027856416106585284024824496763706748621681543444582", "price": "0.906", "size": "0", "side": "SELL", "timestamp": "1768404500189", "received_at": "2026-01-14T16:28:19.854079"}}
{"event_type": "price_change", "event_ts": "2026-01-14T16:28:20.137781", "ingestion_ts": "2026-01-14T16:33:58.842229", "market_id": "0xaf9d0e448129a9f657f851d49495ba4742055d80e0ef1166ba0ee81d4d594214", "raw": {"market": "0xaf9d0e448129a9f657f851d49495ba4742055d80e0ef1166ba0ee81d4d594214", "asset_id": "4153292802911610701832309484716814274802943278345248636922528170020319407796", "price": "0.941", "size": "0", "side": "BUY", "timestamp": "1768404500437", "received_at": "2026-01-14T16:28:20.137781"}}
{"event_type": "price_change", "event_ts": "2026-01-14T16:28:20.137781", "ingestion_ts": "2026-01-14T16:33:58.842229", "market_id": "0xaf9d0e448129a9f657f851d49495ba4742055d80e0ef1166ba0ee81d4d594214", "raw": {"market": "0xaf9d0e448129a9f657f851d49495ba4742055d80e0ef1166ba0ee81d4d594214", "asset_id": "101676997363687199724245607342877036148401850938023978421879460310389391082353", "price": "0.059", "size": "0", "side": "SELL", "timestamp": "1768404500437", "received_at": "2026-01-14T16:28:20.137781"}}
{"event_type": "price_change", "event_ts": "2026-01-14T16:28:20.137851", "ingestion_ts": "2026-01-14T16:33:58.842229", "market_id": "0xaf9d0e448129a9f657f851d49495ba4742055d80e0ef1166ba0ee81d4d594214", "raw": {"market": "0xaf9d0e448129a9f657f851d49495ba4742055d80e0ef1166ba0ee81d4d594214", "asset_id": "4153292802911610701832309484716814274802943278345248636922528170020319407796", "price": "0.932", "size": "0", "side": "BUY", "timestamp": "1768404500437", "received_at": "2026-01-14T16:28:20.137851"}}
{"event_type": "price_change", "event_ts": "2026-01-14T16:28:20.137851", "ingestion_ts": "2026-01-14T16:33:58.842229", "market_id": "0xaf9d0e448129a9f657f851d49495ba4742055d80e0ef1166ba0ee81d4d594214", "raw": {"market": "0xaf9d0e448129a9f657f851d49495ba4742055d80e0ef1166ba0ee81d4d594214", "asset_id": "101676997363687199724245607342877036148401850938023978421879460310389391082353", "price": "0.068", "size": "0", "side": "SELL", "timestamp": "1768404500437", "received_at": "2026-01-14T16:28:20.137851"}}
{"event_type": "price_change", "event_ts": "2026-01-14T16:28:20.137868", "ingestion_ts": "2026-01-14T16:33:58.842229", "market_id": "0xaf9d0e448129a9f657f851d49495ba4742055d80e0ef1166ba0ee81d4d594214", "raw": {"market": "0xaf9d0e448129a9f657f851d49495ba4742055d80e0ef1166ba0ee81d4d594214", "asset_id": "4153292802911610701832309484716814274802943278345248636922528170020319407796", "price": "0.935", "size": "55.06", "side": "BUY", "timestamp": "1768404500437", "received_at": "2026-01-14T16:28:20.137868"}}
{"event_type": "price_change", "event_ts": "2026-01-14T16:28:20.137868", "ingestion_ts": "2026-01-14T16:33:58.842229", "market_id": "0xaf9d0e448129a9f657f851d49495ba4742055d80e0ef1166ba0ee81d4d594214", "raw": {"market": "0xaf9d0e448129a9f657f851d49495ba4742055d80e0ef1166ba0ee81d4d594214", "asset_id": "101676997363687199724245607342877036148401850938023978421879460310389391082353", "price": "0.065", "size": "55.06", "side": "SELL", "timestamp": "1768404500437", "received_at": "2026-01-14T16:28:20.137868"}}
{"event_type": "price_change", "event_ts": "2026-01-14T16:28:20.137882", "ingestion_ts": "2026-01-14T16:33:58.842229", "market_id": "0xaf9d0e448129a9f657f851d49495ba4742055d80e0ef1166ba0ee81d4d594214", "raw": {"market": "0xaf9d0e448129a9f657f851d49495ba4742055d80e0ef1166ba0ee81d4d594214", "asset_id": "4153292802911610701832309484716814274802943278345248636922528170020319407796", "price": "0.943", "size": "0", "side": "BUY", "timestamp": "1768404500437", "received_at": "2026-01-14T16:28:20.137882"}}
{"event_type": "price_change", "event_ts": "2026-01-14T16:28:20.137882", "ingestion_ts": "2026-01-14T16:33:58.842229", "market_id": "0xaf9d0e448129a9f657f851d49495ba4742055d80e0ef1166ba0ee81d4d594214", "raw": {"market": "0xaf9d0e448129a9f657f851d49495ba4742055d80e0ef1166ba0ee81d4d594214", "asset_id": "101676997363687199724245607342877036148401850938023978421879460310389391082353", "price": "0.057", "size": "0", "side": "SELL", "timestamp": "1768404500437", "received_at": "2026-01-14T16:28:20.137882"}}
{"event_type": "price_change", "event_ts": "2026-01-14T16:28:20.137894", "ingestion_ts": "2026-01-14T16:33:58.842229", "market_id": "0xaf9d0e448129a9f657f851d49495ba4742055d80e0ef1166ba0ee81d4d594214", "raw": {"market": "0xaf9d0e448129a9f657f851d49495ba4742055d80e0ef1166ba0ee81d4d594214", "asset_id": "4153292802911610701832309484716814274802943278345248636922528170020319407796", "price": "0.942", "size": "0", "side": "BUY", "timestamp": "1768404500437", "received_at": "2026-01-14T16:28:20.137894"}}
{"event_type": "price_change", "event_ts": "2026-01-14T16:28:20.137894", "ingestion_ts": "2026-01-14T16:33:58.842229", "market_id": "0xaf9d0e448129a9f657f851d49495ba4742055d80e0ef1166ba0ee81d4d594214", "raw": {"market": "0xaf9d0e448129a9f657f851d49495ba4742055d80e0ef1166ba0ee81d4d594214", "asset_id": "101676997363687199724245607342877036148401850938023978421879460310389391082353", "price": "0.058", "size": "0", "side": "SELL", "timestamp": "1768404500437", "received_at": "2026-01-14T16:28:20.137894"}}
{"event_type": "price_change", "event_ts": "2026-01-14T16:28:20.137914", "ingestion_ts": "2026-01-14T16:33:58.842229", "market_id": "0xaf9d0e448129a9f657f851d49495ba4742055d80e0ef1166ba0ee81d4d594214", "raw": {"market": "0xaf9d0e448129a9f657f851d49495ba4742055d80e0ef1166ba0ee81d4d594214", "asset_id": "4153292802911610701832309484716814274802943278345248636922528170020319407796", "price": "0.931", "size": "0", "side": "BUY", "timestamp": "1768404500437", "received_at": "2026-01-14T16:28:20.137914"}}
{"event_type": "price_change", "event_ts": "2026-01-14T16:28:20.137914", "ingestion_ts": "2026-01-14T16:33:58.842229", "market_id": "0xaf9d0e448129a9f657f851d49495ba4742055d80e0ef1166ba0ee81d4d594214", "raw": {"market": "0xaf9d0e448129a9f657f851d49495ba4742055d80e0ef1166ba0ee81d4d594214", "asset_id": "101676997363687199724245607342877036148401850938023978421879460310389391082353", "price": "0.069", "size": "0", "side": "SELL", "timestamp": "1768404500437", "received_at": "2026-01-14T16:28:20.137914"}}
{"event_type": "price_change", "event_ts": "2026-01-14T16:28:20.137928", "ingestion_ts": "2026-01-14T16:33:58.842229", "market_id": "0xaf9d0e448129a9f657f851d49495ba4742055d80e0ef1166ba0ee81d4d594214", "raw": {"market": "0xaf9d0e448129a9f657f851d49495ba4742055d80e0ef1166ba0ee81d4d594214", "asset_id": "4153292802911610701832309484716814274802943278345248636922528170020319407796", "price": "0.925", "size": "0", "side": "BUY", "timestamp": "1768404500437", "received_at": "2026-01-14T16:28:20.137928"}}
{"event_type": "price_change", "event_ts": "2026-01-14T16:28:20.137928", "ingestion_ts": "2026-01-14T16:33:58.842229", "market_id": "0xaf9d0e448129a9f657f851d49495ba4742055d80e0ef1166ba0ee81d4d594214", "raw": {"market": "0xaf9d0e448129a9f657f851d49495ba4742055d80e0ef1166ba0ee81d4d594214", "asset_id": "101676997363687199724245607342877036148401850938023978421879460310389391082353", "price": "0.075", "size": "0", "side": "SELL", "timestamp": "1768404500437", "received_at": "2026-01-14T16:28:20.137928"}}
{"event_type": "price_change", "event_ts": "2026-01-14T16:28:20.137941", "ingestion_ts": "2026-01-14T16:33:58.842229", "market_id": "0xaf9d0e448129a9f657f851d49495ba4742055d80e0ef1166ba0ee81d4d594214", "raw": {"market": "0xaf9d0e448129a9f657f851d49495ba4742055d80e0ef1166ba0ee81d4d594214", "asset_id": "4153292802911610701832309484716814274802943278345248636922528170020319407796", "price": "0.933", "size": "0", "side": "BUY", "timestamp": "1768404500437", "received_at": "2026-01-14T16:28:20.137941"}}
{"event_type": "price_change", "event_ts": "2026-01-14T16:28:20.137941", "ingestion_ts": "2026-01-14T16:33:58.842229", "market_id": "0xaf9d0e448129a9f657f851d49495ba4742055d80e0ef1166ba0ee81d4d594214", "raw": {"market": "0xaf9d0e448129a9f657f851d49495ba4742055d80e0ef1166ba0ee81d4d594214", "asset_id": "101676997363687199724245607342877036148401850938023978421879460310389391082353", "price": "0.067", "size": "0", "side": "SELL", "timestamp": "1768404500437", "received_at": "2026-01-14T16:28:20.137941"}}
{"event_type": "price_change", "event_ts": "2026-01-14T16:28:20.144261", "ingestion_ts": "2026-01-14T16:33:58.842229", "market_id": "0x9472be65457510b7fc3477b20ba90910e99d92eac8421a14bf4b7b7a08ef31dc", "raw": {"market": "0x9472be65457510b7fc3477b20ba90910e99d92eac8421a14bf4b7b7a08ef31dc", "asset_id": "43311793366960417907757893276427136943959788721376762326430771171648759300146", "price": "0.969", "size": "0", "side": "BUY", "timestamp": "1768404500442", "received_at": "2026-01-14T16:28:20.144261"}}
{"event_type": "price_change", "event_ts": "2026-01-14T16:28:20.144261", "ingestion_ts": "2026-01-14T16:33:58.842229", "market_id": "0x9472be65457510b7fc3477b20ba90910e99d92eac8421a14bf4b7b7a08ef31dc", "raw": {"market": "0x9472be65457510b7fc3477b20ba90910e99d92eac8421a14bf4b7b7a08ef31dc", "asset_id": "73414222381656326204771753454630063673548497164758947581648273905027617570612", "price": "0.031", "size": "0", "side": "SELL", "timestamp": "1768404500442", "received_at": "2026-01-14T16:28:20.144261"}}
{"event_type": "price_change", "event_ts": "2026-01-14T16:28:20.214602", "ingestion_ts": "2026-01-14T16:33:58.842229", "market_id": "0x44f08744458b8896620cd3330bc5e1ea69df4199b02d4fc583b3fc96e5d314ce", "raw": {"market": "0x44f08744458b8896620cd3330bc5e1ea69df4199b02d4fc583b3fc96e5d314ce", "asset_id": "72327831507226612545928776794104143393438710920370371172884559893525100761096", "price": "0.956", "size": "0", "side": "BUY", "timestamp": "1768404500436", "received_at": "2026-01-14T16:28:20.214602"}}
{"event_type": "price_change", "event_ts": "2026-01-14T16:28:20.214602", "ingestion_ts": "2026-01-14T16:33:58.842229", "market_id": "0x44f08744458b8896620cd3330bc5e1ea69df4199b02d4fc583b3fc96e5d314ce", "raw": {"market": "0x44f08744458b8896620cd3330bc5e1ea69df4199b02d4fc583b3fc96e5d314ce", "asset_id": "49194009556504828848509244326501559253829462790583873936160989575507522044057", "price": "0.044", "size": "0", "side": "SELL", "timestamp": "1768404500436", "received_at": "2026-01-14T16:28:20.214602"}}
{"event_type": "price_change", "event_ts": "2026-01-14T16:28:20.235315", "ingestion_ts": "2026-01-14T16:33:58.842229", "market_id": "0x50c669f178da4e5bbea7f1be25041fd278914712fa87a6a6f8e57d5923d88dee", "raw": {"market": "0x50c669f178da4e5bbea7f1be25041fd278914712fa87a6a6f8e57d5923d88dee", "asset_id": "74040420326294854165772767082819937451857852955603897473157746262672057685461", "price": "0.968", "size": "0", "side": "BUY", "timestamp": "1768404500439", "received_at": "2026-01-14T16:28:20.235315"}}
{"event_type": "price_change", "event_ts": "2026-01-14T16:28:20.235315", "ingestion_ts": "2026-01-14T16:33:58.842229", "market_id": "0x50c669f178da4e5bbea7f1be25041fd278914712fa87a6a6f8e57d5923d88dee", "raw": {"market": "0x50c669f178da4e5bbea7f1be25041fd278914712fa87a6a6f8e57d5923d88dee", "asset_id": "24682525479474221428144937281315825971983904267399062415430320764754931667953", "price": "0.032", "size": "0", "side": "SELL", "timestamp": "1768404500439", "received_at": "2026-01-14T16:28:20.235315"}}
{"event_type": "price_change", "event_ts": "2026-01-14T16:28:20.497090", "ingestion_ts": "2026-01-14T16:33:58.842229", "market_id": "0xaf9d0e448129a9f657f851d49495ba4742055d80e0ef1166ba0ee81d4d594214", "raw": {"market": "0xaf9d0e448129a9f657f851d49495ba4742055d80e0ef1166ba0ee81d4d594214", "asset_id": "101676997363687199724245607342877036148401850938023978421879460310389391082353", "price": "0.018", "size": "0", "side": "BUY", "timestamp": "1768404500491", "received_at": "2026-01-14T16:28:20.497090"}}
{"event_type": "price_change", "event_ts": "2026-01-14T16:28:20.497090", "ingestion_ts": "2026-01-14T16:33:58.842229", "market_id": "0xaf9d0e448129a9f657f851d49495ba4742055d80e0ef1166ba0ee81d4d594214", "raw": {"market": "0xaf9d0e448129a9f657f851d49495ba4742055d80e0ef1166ba0ee81d4d594214", "asset_id": "4153292802911610701832309484716814274802943278345248636922528170020319407796", "price": "0.982", "size": "0", "side": "SELL", "timestamp": "1768404500491", "received_at": "2026-01-14T16:28:20.497090"}}
{"event_type": "price_change", "event_ts": "2026-01-14T16:28:20.514943", "ingestion_ts": "2026-01-14T16:33:58.842229", "market_id": "0x9472be65457510b7fc3477b20ba90910e99d92eac8421a14bf4b7b7a08ef31dc", "raw": {"market": "0x9472be65457510b7fc3477b20ba90910e99d92eac8421a14bf4b7b7a08ef31dc", "asset_id": "43311793366960417907757893276427136943959788721376762326430771171648759300146", "price": "0.828", "size": "0", "side": "BUY", "timestamp": "1768404500514", "received_at": "2026-01-14T16:28:20.514943"}}
{"event_type": "price_change", "event_ts": "2026-01-14T16:28:20.514943", "ingestion_ts": "2026-01-14T16:33:58.842229", "market_id": "0x9472be65457510b7fc3477b20ba90910e99d92eac8421a14bf4b7b7a08ef31dc", "raw": {"market": "0x9472be65457510b7fc3477b20ba90910e99d92eac8421a14bf4b7b7a08ef31dc", "asset_id": "73414222381656326204771753454630063673548497164758947581648273905027617570612", "price": "0.172", "size": "0", "side": "SELL", "timestamp": "1768404500514", "received_at": "2026-01-14T16:28:20.514943"}}
{"event_type": "price_change", "event_ts": "2026-01-14T16:28:20.515023", "ingestion_ts": "2026-01-14T16:33:58.842229", "market_id": "0xaf9d0e448129a9f657f851d49495ba4742055d80e0ef1166ba0ee81d4d594214", "raw": {"market": "0xaf9d0e448129a9f657f851d49495ba4742055d80e0ef1166ba0ee81d4d594214", "asset_id": "101676997363687199724245607342877036148401850938023978421879460310389391082353", "price": "0.016", "size": "127.13", "side": "BUY", "timestamp": "1768404500518", "received_at": "2026-01-14T16:28:20.515023"}}
{"event_type": "price_change", "event_ts": "2026-01-14T16:28:20.515023", "ingestion_ts": "2026-01-14T16:33:58.842229", "market_id": "0xaf9d0e448129a9f657f851d49495ba4742055d80e0ef1166ba0ee81d4d594214", "raw": {"market": "0xaf9d0e448129a9f657f851d49495ba4742055d80e0ef1166ba0ee81d4d594214", "asset_id": "4153292802911610701832309484716814274802943278345248636922528170020319407796", "price": "0.984", "size": "127.13", "side": "SELL", "timestamp": "1768404500518", "received_at": "2026-01-14T16:28:20.515023"}}
{"event_type": "price_change", "event_ts": "2026-01-14T16:28:22.496643", "ingestion_ts": "2026-01-14T16:33:58.842229", "market_id": "0xaf9d0e448129a9f657f851d49495ba4742055d80e0ef1166ba0ee81d4d594214", "raw": {"market": "0xaf9d0e448129a9f657f851d49495ba4742055d80e0ef1166ba0ee81d4d594214", "asset_id": "4153292802911610701832309484716814274802943278345248636922528170020319407796", "price": "0.984", "size": "120", "side": "SELL", "timestamp": "1768404502805", "received_at": "2026-01-14T16:28:22.496643"}}
{"event_type": "price_change", "event_ts": "2026-01-14T16:28:22.496643", "ingestion_ts": "2026-01-14T16:33:58.842229", "market_id": "0xaf9d0e448129a9f657f851d49495ba4742055d80e0ef1166ba0ee81d4d594214", "raw": {"market": "0xaf9d0e448129a9f657f851d49495ba4742055d80e0ef1166ba0ee81d4d594214", "asset_id": "101676997363687199724245607342877036148401850938023978421879460310389391082353", "price": "0.016", "size": "120", "side": "BUY", "timestamp": "1768404502805", "received_at": "2026-01-14T16:28:22.496643"}}
{"event_type": "price_change", "event_ts": "2026-01-14T16:28:22.610711", "ingestion_ts": "2026-01-14T16:33:58.842229", "market_id": "0xaf9d0e448129a9f657f851d49495ba4742055d80e0ef1166ba0ee81d4d594214", "raw": {"market": "0xaf9d0e448129a9f657f851d49495ba4742055d80e0ef1166ba0ee81d4d594214", "asset_id": "4153292802911610701832309484716814274802943278345248636922528170020319407796", "price": "0.983", "size": "7.13", "side": "SELL", "timestamp": "1768404502946", "received_at": "2026-01-14T16:28:22.610711"}}
{"event_type": "price_change", "event_ts": "2026-01-14T16:28:22.610711", "ingestion_ts": "2026-01-14T16:33:58.842229", "market_id": "0xaf9d0e448129a9f657f851d49495ba4742055d80e0ef1166ba0ee81d4d594214", "raw": {"market": "0xaf9d0e448129a9f657f851d49495ba4742055d80e0ef1166ba0ee81d4d594214", "asset_id": "101676997363687199724245607342877036148401850938023978421879460310389391082353", "price": "0.017", "size": "7.13", "side": "BUY", "timestamp": "1768404502946", "received_at": "2026-01-14T16:28:22.610711"}}
{"event_type": "price_change", "event_ts": "2026-01-14T16:28:22.633196", "ingestion_ts": "2026-01-14T16:33:58.842229", "market_id": "0xaf9d0e448129a9f657f851d49495ba4742055d80e0ef1166ba0ee81d4d594214", "raw": {"market": "0xaf9d0e448129a9f657f851d49495ba4742055d80e0ef1166ba0ee81d4d594214", "asset_id": "101676997363687199724245607342877036148401850938023978421879460310389391082353", "price": "0.016", "size": "0", "side": "BUY", "timestamp": "1768404502970", "received_at": "2026-01-14T16:28:22.633196"}}
{"event_type": "price_change", "event_ts": "2026-01-14T16:28:22.633196", "ingestion_ts": "2026-01-14T16:33:58.842229", "market_id": "0xaf9d0e448129a9f657f851d49495ba4742055d80e0ef1166ba0ee81d4d594214", "raw": {"market": "0xaf9d0e448129a9f657f851d49495ba4742055d80e0ef1166ba0ee81d4d594214", "asset_id": "4153292802911610701832309484716814274802943278345248636922528170020319407796", "price": "0.984", "size": "0", "side": "SELL", "timestamp": "1768404502970", "received_at": "2026-01-14T16:28:22.633196"}}
{"event_type": "price_change", "event_ts": "2026-01-14T16:28:22.672229", "ingestion_ts": "2026-01-14T16:33:58.842229", "market_id": "0xaf9d0e448129a9f657f851d49495ba4742055d80e0ef1166ba0ee81d4d594214", "raw": {"market": "0xaf9d0e448129a9f657f851d49495ba4742055d80e0ef1166ba0ee81d4d594214", "asset_id": "101676997363687199724245607342877036148401850938023978421879460310389391082353", "price": "0.017", "size": "127.13", "side": "BUY", "timestamp": "1768404503002", "received_at": "2026-01-14T16:28:22.672229"}}
{"event_type": "price_change", "event_ts": "2026-01-14T16:28:22.672229", "ingestion_ts": "2026-01-14T16:33:58.842229", "market_id": "0xaf9d0e448129a9f657f851d49495ba4742055d80e0ef1166ba0ee81d4d594214", "raw": {"market": "0xaf9d0e448129a9f657f851d49495ba4742055d80e0ef1166ba0ee81d4d594214", "asset_id": "4153292802911610701832309484716814274802943278345248636922528170020319407796", "price": "0.983", "size": "127.13", "side": "SELL", "timestamp": "1768404503002", "received_at": "2026-01-14T16:28:22.672229"}}
{"event_type": "price_change", "event_ts": "2026-01-14T16:28:24.788557", "ingestion_ts": "2026-01-14T16:33:58.842229", "market_id": "0xaf9d0e448129a9f657f851d49495ba4742055d80e0ef1166ba0ee81d4d594214", "raw": {"market": "0xaf9d0e448129a9f657f851d49495ba4742055d80e0ef1166ba0ee81d4d594214", "asset_id": "4153292802911610701832309484716814274802943278345248636922528170020319407796", "price": "0.983", "size": "120", "side": "SELL", "timestamp": "1768404505113", "received_at": "2026-01-14T16:28:24.788557"}}
{"event_type": "price_change", "event_ts": "2026-01-14T16:28:24.788557", "ingestion_ts": "2026-01-14T16:33:58.842229", "market_id": "0xaf9d0e448129a9f657f851d49495ba4742055d80e0ef1166ba0ee81d4d594214", "raw": {"market": "0xaf9d0e448129a9f657f851d49495ba4742055d80e0ef1166ba0ee81d4d594214", "asset_id": "101676997363687199724245607342877036148401850938023978421879460310389391082353", "price": "0.017", "size": "120", "side": "BUY", "timestamp": "1768404505113", "received_at": "2026-01-14T16:28:24.788557"}}
{"event_type": "price_change", "event_ts": "2026-01-14T16:28:24.958278", "ingestion_ts": "2026-01-14T16:33:58.842229", "market_id": "0xaf9d0e448129a9f657f851d49495ba4742055d80e0ef1166ba0ee81d4d594214", "raw": {"market": "0xaf9d0e448129a9f657f851d49495ba4742055d80e0ef1166ba0ee81d4d594214", "asset_id": "4153292802911610701832309484716814274802943278345248636922528170020319407796", "price": "0.982", "size": "7.13", "side": "SELL", "timestamp": "1768404505289", "received_at": "2026-01-14T16:28:24.958278"}}
{"event_type": "price_change", "event_ts": "2026-01-14T16:28:24.958278", "ingestion_ts": "2026-01-14T16:33:58.842229", "market_id": "0xaf9d0e448129a9f657f851d49495ba4742055d80e0ef1166ba0ee81d4d594214", "raw": {"market": "0xaf9d0e448129a9f657f851d49495ba4742055d80e0ef1166ba0ee81d4d594214", "asset_id": "101676997363687199724245607342877036148401850938023978421879460310389391082353", "price": "0.018", "size": "7.13", "side": "BUY", "timestamp": "1768404505289", "received_at": "2026-01-14T16:28:24.958278"}}
{"event_type": "price_change", "event_ts": "2026-01-14T16:28:24.986488", "ingestion_ts": "2026-01-14T16:33:58.842229", "market_id": "0xaf9d0e448129a9f657f851d49495ba4742055d80e0ef1166ba0ee81d4d594214", "raw": {"market": "0xaf9d0e448129a9f657f851d49495ba4742055d80e0ef1166ba0ee81d4d594214", "asset_id": "101676997363687199724245607342877036148401850938023978421879460310389391082353", "price": "0.017", "size": "0", "side": "BUY", "timestamp": "1768404505323", "received_at": "2026-01-14T16:28:24.986488"}}
{"event_type": "price_change", "event_ts": "2026-01-14T16:28:24.986488", "ingestion_ts": "2026-01-14T16:33:58.842229", "market_id": "0xaf9d0e448129a9f657f851d49495ba4742055d80e0ef1166ba0ee81d4d594214", "raw": {"market": "0xaf9d0e448129a9f657f851d49495ba4742055d80e0ef1166ba0ee81d4d594214", "asset_id": "4153292802911610701832309484716814274802943278345248636922528170020319407796", "price": "0.983", "size": "0", "side": "SELL", "timestamp": "1768404505323", "received_at": "2026-01-14T16:28:24.986488"}}
{"event_type": "price_change", "event_ts": "2026-01-14T16:28:25.049901", "ingestion_ts": "2026-01-14T16:33:58.842229", "market_id": "0xaf9d0e448129a9f657f851d49495ba4742055d80e0ef1166ba0ee81d4d594214", "raw": {"market": "0xaf9d0e448129a9f657f851d49495ba4742055d80e0ef1166ba0ee81d4d594214", "asset_id": "101676997363687199724245607342877036148401850938023978421879460310389391082353", "price": "0.018", "size": "127.13", "side": "BUY", "timestamp": "1768404505368", "received_at": "2026-01-14T16:28:25.049901"}}
{"event_type": "price_change", "event_ts": "2026-01-14T16:28:25.049901", "ingestion_ts": "2026-01-14T16:33:58.842229", "market_id": "0xaf9d0e448129a9f657f851d49495ba4742055d80e0ef1166ba0ee81d4d594214", "raw": {"market": "0xaf9d0e448129a9f657f851d49495ba4742055d80e0ef1166ba0ee81d4d594214", "asset_id": "4153292802911610701832309484716814274802943278345248636922528170020319407796", "price": "0.982", "size": "127.13", "side": "SELL", "timestamp": "1768404505368", "received_at": "2026-01-14T16:28:25.049901"}}
{"event_type": "price_change", "event_ts": "2026-01-14T16:28:25.974054", "ingestion_ts": "2026-01-14T16:33:58.842229", "market_id": "0xcab7ba4a9133cfd407d7e73e5757e5abbace413b59421527a31113406c97815c", "raw": {"market": "0xcab7ba4a9133cfd407d7e73e5757e5abbace413b59421527a31113406c97815c", "asset_id": "20002636398944597965698652220992177552927816915094913583821579024925426590022", "price": "0.476", "size": "0", "side": "BUY", "timestamp": "1768404506279", "received_at": "2026-01-14T16:28:25.974054"}}
{"event_type": "price_change", "event_ts": "2026-01-14T16:28:25.974054", "ingestion_ts": "2026-01-14T16:33:58.842229", "market_id": "0xcab7ba4a9133cfd407d7e73e5757e5abbace413b59421527a31113406c97815c", "raw": {"market": "0xcab7ba4a9133cfd407d7e73e5757e5abbace413b59421527a31113406c97815c", "asset_id": "96361925776989336186111887920533578209326565663637092688733016597062311745569", "price": "0.524", "size": "0", "side": "SELL", "timestamp": "1768404506279", "received_at": "2026-01-14T16:28:25.974054"}}
{"event_type": "price_change", "event_ts": "2026-01-14T16:28:26.143703", "ingestion_ts": "2026-01-14T16:33:58.842229", "market_id": "0xcab7ba4a9133cfd407d7e73e5757e5abbace413b59421527a31113406c97815c", "raw": {"market": "0xcab7ba4a9133cfd407d7e73e5757e5abbace413b59421527a31113406c97815c", "asset_id": "20002636398944597965698652220992177552927816915094913583821579024925426590022", "price": "0.383", "size": "0", "side": "BUY", "timestamp": "1768404506480", "received_at": "2026-01-14T16:28:26.143703"}}
{"event_type": "price_change", "event_ts": "2026-01-14T16:28:26.143703", "ingestion_ts": "2026-01-14T16:33:58.842229", "market_id": "0xcab7ba4a9133cfd407d7e73e5757e5abbace413b59421527a31113406c97815c", "raw": {"market": "0xcab7ba4a9133cfd407d7e73e5757e5abbace413b59421527a31113406c97815c", "asset_id": "96361925776989336186111887920533578209326565663637092688733016597062311745569", "price": "0.617", "size": "0", "side": "SELL", "timestamp": "1768404506480", "received_at": "2026-01-14T16:28:26.143703"}}
{"event_type": "price_change", "event_ts": "2026-01-14T16:28:26.385140", "ingestion_ts": "2026-01-14T16:33:58.842229", "market_id": "0xcab7ba4a9133cfd407d7e73e5757e5abbace413b59421527a31113406c97815c", "raw": {"market": "0xcab7ba4a9133cfd407d7e73e5757e5abbace413b59421527a31113406c97815c", "asset_id": "20002636398944597965698652220992177552927816915094913583821579024925426590022", "price": "0.253", "size": "0", "side": "BUY", "timestamp": "1768404506716", "received_at": "2026-01-14T16:28:26.385140"}}
{"event_type": "price_change", "event_ts": "2026-01-14T16:28:26.385140", "ingestion_ts": "2026-01-14T16:33:58.842229", "market_id": "0xcab7ba4a9133cfd407d7e73e5757e5abbace413b59421527a31113406c97815c", "raw": {"market": "0xcab7ba4a9133cfd407d7e73e5757e5abbace413b59421527a31113406c97815c", "asset_id": "96361925776989336186111887920533578209326565663637092688733016597062311745569", "price": "0.747", "size": "0", "side": "SELL", "timestamp": "1768404506716", "received_at": "2026-01-14T16:28:26.385140"}}
{"event_type": "price_change", "event_ts": "2026-01-14T16:28:26.563646", "ingestion_ts": "2026-01-14T16:33:58.842229", "market_id": "0xcab7ba4a9133cfd407d7e73e5757e5abbace413b59421527a31113406c97815c", "raw": {"market": "0xcab7ba4a9133cfd407d7e73e5757e5abbace413b59421527a31113406c97815c", "asset_id": "20002636398944597965698652220992177552927816915094913583821579024925426590022", "price": "0.168", "size": "0", "side": "BUY", "timestamp": "1768404506900", "received_at": "2026-01-14T16:28:26.563646"}}
{"event_type": "price_change", "event_ts": "2026-01-14T16:28:26.563646", "ingestion_ts": "2026-01-14T16:33:58.842229", "market_id": "0xcab7ba4a9133cfd407d7e73e5757e5abbace413b59421527a31113406c97815c", "raw": {"market": "0xcab7ba4a9133cfd407d7e73e5757e5abbace413b59421527a31113406c97815c", "asset_id": "96361925776989336186111887920533578209326565663637092688733016597062311745569", "price": "0.832", "size": "0", "side": "SELL", "timestamp": "1768404506900", "received_at": "2026-01-14T16:28:26.563646"}}
{"event_type": "price_change", "event_ts": "2026-01-14T16:28:26.765871", "ingestion_ts": "2026-01-14T16:33:58.842229", "market_id": "0xcab7ba4a9133cfd407d7e73e5757e5abbace413b59421527a31113406c97815c", "raw": {"market": "0xcab7ba4a9133cfd407d7e73e5757e5abbace413b59421527a31113406c97815c", "asset_id": "20002636398944597965698652220992177552927816915094913583821579024925426590022", "price": "0.122", "size": "0", "side": "BUY", "timestamp": "1768404507101", "received_at": "2026-01-14T16:28:26.765871"}}
{"event_type": "price_change", "event_ts": "2026-01-14T16:28:26.765871", "ingestion_ts": "2026-01-14T16:33:58.842229", "market_id": "0xcab7ba4a9133cfd407d7e73e5757e5abbace413b59421527a31113406c97815c", "raw": {"market": "0xcab7ba4a9133cfd407d7e73e5757e5abbace413b59421527a31113406c97815c", "asset_id": "96361925776989336186111887920533578209326565663637092688733016597062311745569", "price": "0.878", "size": "0", "side": "SELL", "timestamp": "1768404507101", "received_at": "2026-01-14T16:28:26.765871"}}
{"event_type": "price_change", "event_ts": "2026-01-14T16:28:26.973299", "ingestion_ts": "2026-01-14T16:33:58.842229", "market_id": "0xcab7ba4a9133cfd407d7e73e5757e5abbace413b59421527a31113406c97815c", "raw": {"market": "0xcab7ba4a9133cfd407d7e73e5757e5abbace413b59421527a31113406c97815c", "asset_id": "20002636398944597965698652220992177552927816915094913583821579024925426590022", "price": "0.108", "size": "0", "side": "BUY", "timestamp": "1768404507302", "received_at": "2026-01-14T16:28:26.973299"}}
{"event_type": "price_change", "event_ts": "2026-01-14T16:28:26.973299", "ingestion_ts": "2026-01-14T16:33:58.842229", "market_id": "0xcab7ba4a9133cfd407d7e73e5757e5abbace413b59421527a31113406c97815c", "raw": {"market": "0xcab7ba4a9133cfd407d7e73e5757e5abbace413b59421527a31113406c97815c", "asset_id": "96361925776989336186111887920533578209326565663637092688733016597062311745569", "price": "0.892", "size": "0", "side": "SELL", "timestamp": "1768404507302", "received_at": "2026-01-14T16:28:26.973299"}}
{"event_type": "price_change", "event_ts": "2026-01-14T16:28:27.113462", "ingestion_ts": "2026-01-14T16:33:58.842229", "market_id": "0xaf9d0e448129a9f657f851d49495ba4742055d80e0ef1166ba0ee81d4d594214", "raw": {"market": "0xaf9d0e448129a9f657f851d49495ba4742055d80e0ef1166ba0ee81d4d594214", "asset_id": "4153292802911610701832309484716814274802943278345248636922528170020319407796", "price": "0.982", "size": "120", "side": "SELL", "timestamp": "1768404507449", "received_at": "2026-01-14T16:28:27.113462"}}
{"event_type": "price_change", "event_ts": "2026-01-14T16:28:27.113462", "ingestion_ts": "2026-01-14T16:33:58.842229", "market_id": "0xaf9d0e448129a9f657f851d49495ba4742055d80e0ef1166ba0ee81d4d594214", "raw": {"market": "0xaf9d0e448129a9f657f851d49495ba4742055d80e0ef1166ba0ee81d4d594214", "asset_id": "101676997363687199724245607342877036148401850938023978421879460310389391082353", "price": "0.018", "size": "120", "side": "BUY", "timestamp": "1768404507449", "received_at": "2026-01-14T16:28:27.113462"}}
{"event_type": "price_change", "event_ts": "2026-01-14T16:28:27.189156", "ingestion_ts": "2026-01-14T16:33:58.842229", "market_id": "0xcab7ba4a9133cfd407d7e73e5757e5abbace413b59421527a31113406c97815c", "raw": {"market": "0xcab7ba4a9133cfd407d7e73e5757e5abbace413b59421527a31113406c97815c", "asset_id": "20002636398944597965698652220992177552927816915094913583821579024925426590022", "price": "0.052", "size": "0", "side": "BUY", "timestamp": "1768404507519", "received_at": "2026-01-14T16:28:27.189156"}}
{"event_type": "price_change", "event_ts": "2026-01-14T16:28:27.189156", "ingestion_ts": "2026-01-14T16:33:58.842229", "market_id": "0xcab7ba4a9133cfd407d7e73e5757e5abbace413b59421527a31113406c97815c", "raw": {"market": "0xcab7ba4a9133cfd407d7e73e5757e5abbace413b59421527a31113406c97815c", "asset_id": "96361925776989336186111887920533578209326565663637092688733016597062311745569", "price": "0.948", "size": "0", "side": "SELL", "timestamp": "1768404507519", "received_at": "2026-01-14T16:28:27.189156"}}
{"event_type": "price_change", "event_ts": "2026-01-14T16:28:27.244907", "ingestion_ts": "2026-01-14T16:33:58.842229", "market_id": "0xaf9d0e448129a9f657f851d49495ba4742055d80e0ef1166ba0ee81d4d594214", "raw": {"market": "0xaf9d0e448129a9f657f851d49495ba4742055d80e0ef1166ba0ee81d4d594214", "asset_id": "4153292802911610701832309484716814274802943278345248636922528170020319407796", "price": "0.984", "size": "7.13", "side": "SELL", "timestamp": "1768404507581", "received_at": "2026-01-14T16:28:27.244907"}}
{"event_type": "price_change", "event_ts": "2026-01-14T16:28:27.244907", "ingestion_ts": "2026-01-14T16:33:58.842229", "market_id": "0xaf9d0e448129a9f657f851d49495ba4742055d80e0ef1166ba0ee81d4d594214", "raw": {"market": "0xaf9d0e448129a9f657f851d49495ba4742055d80e0ef1166ba0ee81d4d594214", "asset_id": "101676997363687199724245607342877036148401850938023978421879460310389391082353", "price": "0.016", "size": "7.13", "side": "BUY", "timestamp": "1768404507581", "received_at": "2026-01-14T16:28:27.244907"}}
{"event_type": "price_change", "event_ts": "2026-01-14T16:28:27.416586", "ingestion_ts": "2026-01-14T16:33:58.842229", "market_id": "0xcab7ba4a9133cfd407d7e73e5757e5abbace413b59421527a31113406c97815c", "raw": {"market": "0xcab7ba4a9133cfd407d7e73e5757e5abbace413b59421527a31113406c97815c", "asset_id": "20002636398944597965698652220992177552927816915094913583821579024925426590022", "price": "0.054", "size": "63.49", "side": "BUY", "timestamp": "1768404507753", "received_at": "2026-01-14T16:28:27.416586"}}
{"event_type": "price_change", "event_ts": "2026-01-14T16:28:27.416586", "ingestion_ts": "2026-01-14T16:33:58.842229", "market_id": "0xcab7ba4a9133cfd407d7e73e5757e5abbace413b59421527a31113406c97815c", "raw": {"market": "0xcab7ba4a9133cfd407d7e73e5757e5abbace413b59421527a31113406c97815c", "asset_id": "96361925776989336186111887920533578209326565663637092688733016597062311745569", "price": "0.946", "size": "63.49", "side": "SELL", "timestamp": "1768404507753", "received_at": "2026-01-14T16:28:27.416586"}}
{"event_type": "price_change", "event_ts": "2026-01-14T16:28:27.500037", "ingestion_ts": "2026-01-14T16:33:58.842229", "market_id": "0xc55db914f0fd1fee18997706712c0dfd8d0369cdbef93a9fef12bd001914ca77", "raw": {"market": "0xc55db914f0fd1fee18997706712c0dfd8d0369cdbef93a9fef12bd001914ca77", "asset_id": "114600293444080540179603459515770723592661967180480327891296353898330242622833", "price": "0.84", "size": "0", "side": "BUY", "timestamp": "1768404507836", "received_at": "2026-01-14T16:28:27.500037"}}
{"event_type": "price_change", "event_ts": "2026-01-14T16:28:27.500037", "ingestion_ts": "2026-01-14T16:33:58.842229", "market_id": "0xc55db914f0fd1fee18997706712c0dfd8d0369cdbef93a9fef12bd001914ca77", "raw": {"market": "0xc55db914f0fd1fee18997706712c0dfd8d0369cdbef93a9fef12bd001914ca77", "asset_id": "72354723612769247426741660426331235762851940382312402276325808095604519806766", "price": "0.16", "size": "0", "side": "SELL", "timestamp": "1768404507836", "received_at": "2026-01-14T16:28:27.500037"}}
{"event_type": "price_change", "event_ts": "2026-01-14T16:28:27.657171", "ingestion_ts": "2026-01-14T16:33:58.842229", "market_id": "0xcab7ba4a9133cfd407d7e73e5757e5abbace413b59421527a31113406c97815c", "raw": {"market": "0xcab7ba4a9133cfd407d7e73e5757e5abbace413b59421527a31113406c97815c", "asset_id": "20002636398944597965698652220992177552927816915094913583821579024925426590022", "price": "0.105", "size": "32.65", "side": "BUY", "timestamp": "1768404507992", "received_at": "2026-01-14T16:28:27.657171"}}
{"event_type": "price_change", "event_ts": "2026-01-14T16:28:27.657171", "ingestion_ts": "2026-01-14T16:33:58.842229", "market_id": "0xcab7ba4a9133cfd407d7e73e5757e5abbace413b59421527a31113406c97815c", "raw": {"market": "0xcab7ba4a9133cfd407d7e73e5757e5abbace413b59421527a31113406c97815c", "asset_id": "96361925776989336186111887920533578209326565663637092688733016597062311745569", "price": "0.895", "size": "32.65", "side": "SELL", "timestamp": "1768404507992", "received_at": "2026-01-14T16:28:27.657171"}}
{"event_type": "price_change", "event_ts": "2026-01-14T16:28:27.897772", "ingestion_ts": "2026-01-14T16:33:58.842229", "market_id": "0xcab7ba4a9133cfd407d7e73e5757e5abbace413b59421527a31113406c97815c", "raw": {"market": "0xcab7ba4a9133cfd407d7e73e5757e5abbace413b59421527a31113406c97815c", "asset_id": "20002636398944597965698652220992177552927816915094913583821579024925426590022", "price": "0.124", "size": "27.64", "side": "BUY", "timestamp": "1768404508224", "received_at": "2026-01-14T16:28:27.897772"}}
{"event_type": "price_change", "event_ts": "2026-01-14T16:28:27.897772", "ingestion_ts": "2026-01-14T16:33:58.842229", "market_id": "0xcab7ba4a9133cfd407d7e73e5757e5abbace413b59421527a31113406c97815c", "raw": {"market": "0xcab7ba4a9133cfd407d7e73e5757e5abbace413b59421527a31113406c97815c", "asset_id": "96361925776989336186111887920533578209326565663637092688733016597062311745569", "price": "0.876", "size": "27.64", "side": "SELL", "timestamp": "1768404508224", "received_at": "2026-01-14T16:28:27.897772"}}
{"event_type": "price_change", "event_ts": "2026-01-14T16:28:28.133041", "ingestion_ts": "2026-01-14T16:33:58.842229", "market_id": "0xcab7ba4a9133cfd407d7e73e5757e5abbace413b59421527a31113406c97815c", "raw": {"market": "0xcab7ba4a9133cfd407d7e73e5757e5abbace413b59421527a31113406c97815c", "asset_id": "20002636398944597965698652220992177552927816915094913583821579024925426590022", "price": "0.17", "size": "20.16", "side": "BUY", "timestamp": "1768404508467", "received_at": "2026-01-14T16:28:28.133041"}}
{"event_type": "price_change", "event_ts": "2026-01-14T16:28:28.133041", "ingestion_ts": "2026-01-14T16:33:58.842229", "market_id": "0xcab7ba4a9133cfd407d7e73e5757e5abbace413b59421527a31113406c97815c", "raw": {"market": "0xcab7ba4a9133cfd407d7e73e5757e5abbace413b59421527a31113406c97815c", "asset_id": "96361925776989336186111887920533578209326565663637092688733016597062311745569", "price": "0.83", "size": "20.16", "side": "SELL", "timestamp": "1768404508467", "received_at": "2026-01-14T16:28:28.133041"}}
{"event_type": "price_change", "event_ts": "2026-01-14T16:28:28.382972", "ingestion_ts": "2026-01-14T16:33:58.842229", "market_id": "0xcab7ba4a9133cfd407d7e73e5757e5abbace413b59421527a31113406c97815c", "raw": {"market": "0xcab7ba4a9133cfd407d7e73e5757e5abbace413b59421527a31113406c97815c", "asset_id": "20002636398944597965698652220992177552927816915094913583821579024925426590022", "price": "0.255", "size": "13.44", "side": "BUY", "timestamp": "1768404508720", "received_at": "2026-01-14T16:28:28.382972"}}
{"event_type": "price_change", "event_ts": "2026-01-14T16:28:28.382972", "ingestion_ts": "2026-01-14T16:33:58.842229", "market_id": "0xcab7ba4a9133cfd407d7e73e5757e5abbace413b59421527a31113406c97815c", "raw": {"market": "0xcab7ba4a9133cfd407d7e73e5757e5abbace413b59421527a31113406c97815c", "asset_id": "96361925776989336186111887920533578209326565663637092688733016597062311745569", "price": "0.745", "size": "13.44", "side": "SELL", "timestamp": "1768404508720", "received_at": "2026-01-14T16:28:28.382972"}}
{"event_type": "price_change", "event_ts": "2026-01-14T16:28:28.637172", "ingestion_ts": "2026-01-14T16:33:58.842229", "market_id": "0xcab7ba4a9133cfd407d7e73e5757e5abbace413b59421527a31113406c97815c", "raw": {"market": "0xcab7ba4a9133cfd407d7e73e5757e5abbace413b59421527a31113406c97815c", "asset_id": "20002636398944597965698652220992177552927816915094913583821579024925426590022", "price": "0.385", "size": "8.9", "side": "BUY", "timestamp": "1768404508961", "received_at": "2026-01-14T16:28:28.637172"}}
{"event_type": "price_change", "event_ts": "2026-01-14T16:28:28.637172", "ingestion_ts": "2026-01-14T16:33:58.842229", "market_id": "0xcab7ba4a9133cfd407d7e73e5757e5abbace413b59421527a31113406c97815c", "raw": {"market": "0xcab7ba4a9133cfd407d7e73e5757e5abbace413b59421527a31113406c97815c", "asset_id": "96361925776989336186111887920533578209326565663637092688733016597062311745569", "price": "0.615", "size": "8.9", "side": "SELL", "timestamp": "1768404508961", "received_at": "2026-01-14T16:28:28.637172"}}
{"event_type": "price_change", "event_ts": "2026-01-14T16:28:28.834417", "ingestion_ts": "2026-01-14T16:33:58.842229", "market_id": "0xcab7ba4a9133cfd407d7e73e5757e5abbace413b59421527a31113406c97815c", "raw": {"market": "0xcab7ba4a9133cfd407d7e73e5757e5abbace413b59421527a31113406c97815c", "asset_id": "20002636398944597965698652220992177552927816915094913583821579024925426590022", "price": "0.478", "size": "7.17", "side": "BUY", "timestamp": "1768404509172", "received_at": "2026-01-14T16:28:28.834417"}}
{"event_type": "price_change", "event_ts": "2026-01-14T16:28:28.834417", "ingestion_ts": "2026-01-14T16:33:58.842229", "market_id": "0xcab7ba4a9133cfd407d7e73e5757e5abbace413b59421527a31113406c97815c", "raw": {"market": "0xcab7ba4a9133cfd407d7e73e5757e5abbace413b59421527a31113406c97815c", "asset_id": "96361925776989336186111887920533578209326565663637092688733016597062311745569", "price": "0.522", "size": "7.17", "side": "SELL", "timestamp": "1768404509172", "received_at": "2026-01-14T16:28:28.834417"}}
{"event_type": "price_change", "event_ts": "2026-01-14T16:28:29.035421", "ingestion_ts": "2026-01-14T16:33:58.842229", "market_id": "0xe9c127a8c35f045d37b5344b0a36711084fa20c2fc1618bf178a5386f90610be", "raw": {"market": "0xe9c127a8c35f045d37b5344b0a36711084fa20c2fc1618bf178a5386f90610be", "asset_id": "107000426448217931795450451304515386602910396776318075817601265223856116134349", "price": "0.255", "size": "0", "side": "BUY", "timestamp": "1768404509369", "received_at": "2026-01-14T16:28:29.035421"}}
{"event_type": "price_change", "event_ts": "2026-01-14T16:28:29.035421", "ingestion_ts": "2026-01-14T16:33:58.842229", "market_id": "0xe9c127a8c35f045d37b5344b0a36711084fa20c2fc1618bf178a5386f90610be", "raw": {"market": "0xe9c127a8c35f045d37b5344b0a36711084fa20c2fc1618bf178a5386f90610be", "asset_id": "80230236018433940569996058935444651347308266584430516013229815570706872276819", "price": "0.745", "size": "0", "side": "SELL", "timestamp": "1768404509369", "received_at": "2026-01-14T16:28:29.035421"}}
{"event_type": "price_change", "event_ts": "2026-01-14T16:28:29.256388", "ingestion_ts": "2026-01-14T16:33:58.842229", "market_id": "0xe9c127a8c35f045d37b5344b0a36711084fa20c2fc1618bf178a5386f90610be", "raw": {"market": "0xe9c127a8c35f045d37b5344b0a36711084fa20c2fc1618bf178a5386f90610be", "asset_id": "107000426448217931795450451304515386602910396776318075817601265223856116134349", "price": "0.213", "size": "0", "side": "BUY", "timestamp": "1768404509553", "received_at": "2026-01-14T16:28:29.256388"}}
{"event_type": "price_change", "event_ts": "2026-01-14T16:28:29.256388", "ingestion_ts": "2026-01-14T16:33:58.842229", "market_id": "0xe9c127a8c35f045d37b5344b0a36711084fa20c2fc1618bf178a5386f90610be", "raw": {"market": "0xe9c127a8c35f045d37b5344b0a36711084fa20c2fc1618bf178a5386f90610be", "asset_id": "80230236018433940569996058935444651347308266584430516013229815570706872276819", "price": "0.787", "size": "0", "side": "SELL", "timestamp": "1768404509553", "received_at": "2026-01-14T16:28:29.256388"}}
{"event_type": "price_change", "event_ts": "2026-01-14T16:28:29.426360", "ingestion_ts": "2026-01-14T16:33:58.842229", "market_id": "0xe9c127a8c35f045d37b5344b0a36711084fa20c2fc1618bf178a5386f90610be", "raw": {"market": "0xe9c127a8c35f045d37b5344b0a36711084fa20c2fc1618bf178a5386f90610be", "asset_id": "107000426448217931795450451304515386602910396776318075817601265223856116134349", "price": "0.176", "size": "0", "side": "BUY", "timestamp": "1768404509762", "received_at": "2026-01-14T16:28:29.426360"}}
{"event_type": "price_change", "event_ts": "2026-01-14T16:28:29.426360", "ingestion_ts": "2026-01-14T16:33:58.842229", "market_id": "0xe9c127a8c35f045d37b5344b0a36711084fa20c2fc1618bf178a5386f90610be", "raw": {"market": "0xe9c127a8c35f045d37b5344b0a36711084fa20c2fc1618bf178a5386f90610be", "asset_id": "80230236018433940569996058935444651347308266584430516013229815570706872276819", "price": "0.824", "size": "0", "side": "SELL", "timestamp": "1768404509762", "received_at": "2026-01-14T16:28:29.426360"}}
{"event_type": "price_change", "event_ts": "2026-01-14T16:28:29.614880", "ingestion_ts": "2026-01-14T16:33:58.842229", "market_id": "0xe9c127a8c35f045d37b5344b0a36711084fa20c2fc1618bf178a5386f90610be", "raw": {"market": "0xe9c127a8c35f045d37b5344b0a36711084fa20c2fc1618bf178a5386f90610be", "asset_id": "107000426448217931795450451304515386602910396776318075817601265223856116134349", "price": "0.114", "size": "0", "side": "BUY", "timestamp": "1768404509944", "received_at": "2026-01-14T16:28:29.614880"}}
{"event_type": "price_change", "event_ts": "2026-01-14T16:28:29.614880", "ingestion_ts": "2026-01-14T16:33:58.842229", "market_id": "0xe9c127a8c35f045d37b5344b0a36711084fa20c2fc1618bf178a5386f90610be", "raw": {"market": "0xe9c127a8c35f045d37b5344b0a36711084fa20c2fc1618bf178a5386f90610be", "asset_id": "80230236018433940569996058935444651347308266584430516013229815570706872276819", "price": "0.886", "size": "0", "side": "SELL", "timestamp": "1768404509944", "received_at": "2026-01-14T16:28:29.614880"}}
{"event_type": "price_change", "event_ts": "2026-01-14T16:28:29.821410", "ingestion_ts": "2026-01-14T16:33:58.842229", "market_id": "0xe9c127a8c35f045d37b5344b0a36711084fa20c2fc1618bf178a5386f90610be", "raw": {"market": "0xe9c127a8c35f045d37b5344b0a36711084fa20c2fc1618bf178a5386f90610be", "asset_id": "107000426448217931795450451304515386602910396776318075817601265223856116134349", "price": "0.106", "size": "0", "side": "BUY", "timestamp": "1768404510158", "received_at": "2026-01-14T16:28:29.821410"}}
{"event_type": "price_change", "event_ts": "2026-01-14T16:28:29.821410", "ingestion_ts": "2026-01-14T16:33:58.842229", "market_id": "0xe9c127a8c35f045d37b5344b0a36711084fa20c2fc1618bf178a5386f90610be", "raw": {"market": "0xe9c127a8c35f045d37b5344b0a36711084fa20c2fc1618bf178a5386f90610be", "asset_id": "80230236018433940569996058935444651347308266584430516013229815570706872276819", "price": "0.894", "size": "0", "side": "SELL", "timestamp": "1768404510158", "received_at": "2026-01-14T16:28:29.821410"}}
{"event_type": "price_change", "event_ts": "2026-01-14T16:28:30.027060", "ingestion_ts": "2026-01-14T16:33:58.842229", "market_id": "0xe9c127a8c35f045d37b5344b0a36711084fa20c2fc1618bf178a5386f90610be", "raw": {"market": "0xe9c127a8c35f045d37b5344b0a36711084fa20c2fc1618bf178a5386f90610be", "asset_id": "107000426448217931795450451304515386602910396776318075817601265223856116134349", "price": "0.056", "size": "0", "side": "BUY", "timestamp": "1768404510364", "received_at": "2026-01-14T16:28:30.027060"}}
{"event_type": "price_change", "event_ts": "2026-01-14T16:28:30.027060", "ingestion_ts": "2026-01-14T16:33:58.842229", "market_id": "0xe9c127a8c35f045d37b5344b0a36711084fa20c2fc1618bf178a5386f90610be", "raw": {"market": "0xe9c127a8c35f045d37b5344b0a36711084fa20c2fc1618bf178a5386f90610be", "asset_id": "80230236018433940569996058935444651347308266584430516013229815570706872276819", "price": "0.944", "size": "0", "side": "SELL", "timestamp": "1768404510364", "received_at": "2026-01-14T16:28:30.027060"}}
{"event_type": "price_change", "event_ts": "2026-01-14T16:28:30.243624", "ingestion_ts": "2026-01-14T16:33:58.842229", "market_id": "0xe9c127a8c35f045d37b5344b0a36711084fa20c2fc1618bf178a5386f90610be", "raw": {"market": "0xe9c127a8c35f045d37b5344b0a36711084fa20c2fc1618bf178a5386f90610be", "asset_id": "107000426448217931795450451304515386602910396776318075817601265223856116134349", "price": "0.033", "size": "0", "side": "BUY", "timestamp": "1768404510574", "received_at": "2026-01-14T16:28:30.243624"}}
{"event_type": "price_change", "event_ts": "2026-01-14T16:28:30.243624", "ingestion_ts": "2026-01-14T16:33:58.842229", "market_id": "0xe9c127a8c35f045d37b5344b0a36711084fa20c2fc1618bf178a5386f90610be", "raw": {"market": "0xe9c127a8c35f045d37b5344b0a36711084fa20c2fc1618bf178a5386f90610be", "asset_id": "80230236018433940569996058935444651347308266584430516013229815570706872276819", "price": "0.967", "size": "0", "side": "SELL", "timestamp": "1768404510574", "received_at": "2026-01-14T16:28:30.243624"}}
{"event_type": "price_change", "event_ts": "2026-01-14T16:28:30.465485", "ingestion_ts": "2026-01-14T16:33:58.842229", "market_id": "0xe9c127a8c35f045d37b5344b0a36711084fa20c2fc1618bf178a5386f90610be", "raw": {"market": "0xe9c127a8c35f045d37b5344b0a36711084fa20c2fc1618bf178a5386f90610be", "asset_id": "107000426448217931795450451304515386602910396776318075817601265223856116134349", "price": "0.035", "size": "97.95", "side": "BUY", "timestamp": "1768404510802", "received_at": "2026-01-14T16:28:30.465485"}}
{"event_type": "price_change", "event_ts": "2026-01-14T16:28:30.465485", "ingestion_ts": "2026-01-14T16:33:58.842229", "market_id": "0xe9c127a8c35f045d37b5344b0a36711084fa20c2fc1618bf178a5386f90610be", "raw": {"market": "0xe9c127a8c35f045d37b5344b0a36711084fa20c2fc1618bf178a5386f90610be", "asset_id": "80230236018433940569996058935444651347308266584430516013229815570706872276819", "price": "0.965", "size": "97.95", "side": "SELL", "timestamp": "1768404510802", "received_at": "2026-01-14T16:28:30.465485"}}
{"event_type": "price_change", "event_ts": "2026-01-14T16:28:30.693959", "ingestion_ts": "2026-01-14T16:33:58.842229", "market_id": "0xe9c127a8c35f045d37b5344b0a36711084fa20c2fc1618bf178a5386f90610be", "raw": {"market": "0xe9c127a8c35f045d37b5344b0a36711084fa20c2fc1618bf178a5386f90610be", "asset_id": "107000426448217931795450451304515386602910396776318075817601265223856116134349", "price": "0.058", "size": "59.11", "side": "BUY", "timestamp": "1768404511028", "received_at": "2026-01-14T16:28:30.693959"}}
{"event_type": "price_change", "event_ts": "2026-01-14T16:28:30.693959", "ingestion_ts": "2026-01-14T16:33:58.842229", "market_id": "0xe9c127a8c35f045d37b5344b0a36711084fa20c2fc1618bf178a5386f90610be", "raw": {"market": "0xe9c127a8c35f045d37b5344b0a36711084fa20c2fc1618bf178a5386f90610be", "asset_id": "80230236018433940569996058935444651347308266584430516013229815570706872276819", "price": "0.942", "size": "59.11", "side": "SELL", "timestamp": "1768404511028", "received_at": "2026-01-14T16:28:30.693959"}}
{"event_type": "price_change", "event_ts": "2026-01-14T16:28:30.917363", "ingestion_ts": "2026-01-14T16:33:58.842229", "market_id": "0xe9c127a8c35f045d37b5344b0a36711084fa20c2fc1618bf178a5386f90610be", "raw": {"market": "0xe9c127a8c35f045d37b5344b0a36711084fa20c2fc1618bf178a5386f90610be", "asset_id": "107000426448217931795450451304515386602910396776318075817601265223856116134349", "price": "0.108", "size": "31.74", "side": "BUY", "timestamp": "1768404511252", "received_at": "2026-01-14T16:28:30.917363"}}
{"event_type": "price_change", "event_ts": "2026-01-14T16:28:30.917363", "ingestion_ts": "2026-01-14T16:33:58.842229", "market_id": "0xe9c127a8c35f045d37b5344b0a36711084fa20c2fc1618bf178a5386f90610be", "raw": {"market": "0xe9c127a8c35f045d37b5344b0a36711084fa20c2fc1618bf178a5386f90610be", "asset_id": "80230236018433940569996058935444651347308266584430516013229815570706872276819", "price": "0.892", "size": "31.74", "side": "SELL", "timestamp": "1768404511252", "received_at": "2026-01-14T16:28:30.917363"}}
{"event_type": "price_change", "event_ts": "2026-01-14T16:28:31.136835", "ingestion_ts": "2026-01-14T16:33:58.842229", "market_id": "0xe9c127a8c35f045d37b5344b0a36711084fa20c2fc1618bf178a5386f90610be", "raw": {"market": "0xe9c127a8c35f045d37b5344b0a36711084fa20c2fc1618bf178a5386f90610be", "asset_id": "107000426448217931795450451304515386602910396776318075817601265223856116134349", "price": "0.116", "size": "29.55", "side": "BUY", "timestamp": "1768404511468", "received_at": "2026-01-14T16:28:31.136835"}}
{"event_type": "price_change", "event_ts": "2026-01-14T16:28:31.136835", "ingestion_ts": "2026-01-14T16:33:58.842229", "market_id": "0xe9c127a8c35f045d37b5344b0a36711084fa20c2fc1618bf178a5386f90610be", "raw": {"market": "0xe9c127a8c35f045d37b5344b0a36711084fa20c2fc1618bf178a5386f90610be", "asset_id": "80230236018433940569996058935444651347308266584430516013229815570706872276819", "price": "0.884", "size": "29.55", "side": "SELL", "timestamp": "1768404511468", "received_at": "2026-01-14T16:28:31.136835"}}
{"event_type": "price_change", "event_ts": "2026-01-14T16:28:31.345245", "ingestion_ts": "2026-01-14T16:33:58.842229", "market_id": "0xe9c127a8c35f045d37b5344b0a36711084fa20c2fc1618bf178a5386f90610be", "raw": {"market": "0xe9c127a8c35f045d37b5344b0a36711084fa20c2fc1618bf178a5386f90610be", "asset_id": "107000426448217931795450451304515386602910396776318075817601265223856116134349", "price": "0.178", "size": "19.26", "side": "BUY", "timestamp": "1768404511680", "received_at": "2026-01-14T16:28:31.345245"}}
{"event_type": "price_change", "event_ts": "2026-01-14T16:28:31.345245", "ingestion_ts": "2026-01-14T16:33:58.842229", "market_id": "0xe9c127a8c35f045d37b5344b0a36711084fa20c2fc1618bf178a5386f90610be", "raw": {"market": "0xe9c127a8c35f045d37b5344b0a36711084fa20c2fc1618bf178a5386f90610be", "asset_id": "80230236018433940569996058935444651347308266584430516013229815570706872276819", "price": "0.822", "size": "19.26", "side": "SELL", "timestamp": "1768404511680", "received_at": "2026-01-14T16:28:31.345245"}}
{"event_type": "price_change", "event_ts": "2026-01-14T16:28:31.587876", "ingestion_ts": "2026-01-14T16:33:58.842229", "market_id": "0xe9c127a8c35f045d37b5344b0a36711084fa20c2fc1618bf178a5386f90610be", "raw": {"market": "0xe9c127a8c35f045d37b5344b0a36711084fa20c2fc1618bf178a5386f90610be", "asset_id": "107000426448217931795450451304515386602910396776318075817601265223856116134349", "price": "0.215", "size": "15.94", "side": "BUY", "timestamp": "1768404511913", "received_at": "2026-01-14T16:28:31.587876"}}
{"event_type": "price_change", "event_ts": "2026-01-14T16:28:31.587876", "ingestion_ts": "2026-01-14T16:33:58.842229", "market_id": "0xe9c127a8c35f045d37b5344b0a36711084fa20c2fc1618bf178a5386f90610be", "raw": {"market": "0xe9c127a8c35f045d37b5344b0a36711084fa20c2fc1618bf178a5386f90610be", "asset_id": "80230236018433940569996058935444651347308266584430516013229815570706872276819", "price": "0.785", "size": "15.94", "side": "SELL", "timestamp": "1768404511913", "received_at": "2026-01-14T16:28:31.587876"}}
{"event_type": "price_change", "event_ts": "2026-01-14T16:28:31.799670", "ingestion_ts": "2026-01-14T16:33:58.842229", "market_id": "0xe9c127a8c35f045d37b5344b0a36711084fa20c2fc1618bf178a5386f90610be", "raw": {"market": "0xe9c127a8c35f045d37b5344b0a36711084fa20c2fc1618bf178a5386f90610be", "asset_id": "107000426448217931795450451304515386602910396776318075817601265223856116134349", "price": "0.251", "size": "0", "side": "BUY", "timestamp": "1768404512135", "received_at": "2026-01-14T16:28:31.799670"}}
{"event_type": "price_change", "event_ts": "2026-01-14T16:28:31.799670", "ingestion_ts": "2026-01-14T16:33:58.842229", "market_id": "0xe9c127a8c35f045d37b5344b0a36711084fa20c2fc1618bf178a5386f90610be", "raw": {"market": "0xe9c127a8c35f045d37b5344b0a36711084fa20c2fc1618bf178a5386f90610be", "asset_id": "80230236018433940569996058935444651347308266584430516013229815570706872276819", "price": "0.749", "size": "0", "side": "SELL", "timestamp": "1768404512135", "received_at": "2026-01-14T16:28:31.799670"}}
{"event_type": "price_change", "event_ts": "2026-01-14T16:28:32.023544", "ingestion_ts": "2026-01-14T16:33:58.842229", "market_id": "0xe9c127a8c35f045d37b5344b0a36711084fa20c2fc1618bf178a5386f90610be", "raw": {"market": "0xe9c127a8c35f045d37b5344b0a36711084fa20c2fc1618bf178a5386f90610be", "asset_id": "107000426448217931795450451304515386602910396776318075817601265223856116134349", "price": "0.251", "size": "13.65", "side": "BUY", "timestamp": "1768404512360", "received_at": "2026-01-14T16:28:32.023544"}}
{"event_type": "price_change", "event_ts": "2026-01-14T16:28:32.023544", "ingestion_ts": "2026-01-14T16:33:58.842229", "market_id": "0xe9c127a8c35f045d37b5344b0a36711084fa20c2fc1618bf178a5386f90610be", "raw": {"market": "0xe9c127a8c35f045d37b5344b0a36711084fa20c2fc1618bf178a5386f90610be", "asset_id": "80230236018433940569996058935444651347308266584430516013229815570706872276819", "price": "0.749", "size": "13.65", "side": "SELL", "timestamp": "1768404512360", "received_at": "2026-01-14T16:28:32.023544"}}
{"event_type": "price_change", "event_ts": "2026-01-14T16:28:32.241326", "ingestion_ts": "2026-01-14T16:33:58.842229", "market_id": "0xe9c127a8c35f045d37b5344b0a36711084fa20c2fc1618bf178a5386f90610be", "raw": {"market": "0xe9c127a8c35f045d37b5344b0a36711084fa20c2fc1618bf178a5386f90610be", "asset_id": "107000426448217931795450451304515386602910396776318075817601265223856116134349", "price": "0.257", "size": "13.34", "side": "BUY", "timestamp": "1768404512578", "received_at": "2026-01-14T16:28:32.241326"}}
{"event_type": "price_change", "event_ts": "2026-01-14T16:28:32.241326", "ingestion_ts": "2026-01-14T16:33:58.842229", "market_id": "0xe9c127a8c35f045d37b5344b0a36711084fa20c2fc1618bf178a5386f90610be", "raw": {"market": "0xe9c127a8c35f045d37b5344b0a36711084fa20c2fc1618bf178a5386f90610be", "asset_id": "80230236018433940569996058935444651347308266584430516013229815570706872276819", "price": "0.743", "size": "13.34", "side": "SELL", "timestamp": "1768404512578", "received_at": "2026-01-14T16:28:32.241326"}}
{"event_type": "price_change", "event_ts": "2026-01-14T16:28:32.459929", "ingestion_ts": "2026-01-14T16:33:58.842229", "market_id": "0xe9c127a8c35f045d37b5344b0a36711084fa20c2fc1618bf178a5386f90610be", "raw": {"market": "0xe9c127a8c35f045d37b5344b0a36711084fa20c2fc1618bf178a5386f90610be", "asset_id": "107000426448217931795450451304515386602910396776318075817601265223856116134349", "price": "0.305", "size": "0", "side": "BUY", "timestamp": "1768404512793", "received_at": "2026-01-14T16:28:32.459929"}}
{"event_type": "price_change", "event_ts": "2026-01-14T16:28:32.459929", "ingestion_ts": "2026-01-14T16:33:58.842229", "market_id": "0xe9c127a8c35f045d37b5344b0a36711084fa20c2fc1618bf178a5386f90610be", "raw": {"market": "0xe9c127a8c35f045d37b5344b0a36711084fa20c2fc1618bf178a5386f90610be", "asset_id": "80230236018433940569996058935444651347308266584430516013229815570706872276819", "price": "0.695", "size": "0", "side": "SELL", "timestamp": "1768404512793", "received_at": "2026-01-14T16:28:32.459929"}}
{"event_type": "price_change", "event_ts": "2026-01-14T16:28:32.750940", "ingestion_ts": "2026-01-14T16:33:58.842229", "market_id": "0xe9c127a8c35f045d37b5344b0a36711084fa20c2fc1618bf178a5386f90610be", "raw": {"market": "0xe9c127a8c35f045d37b5344b0a36711084fa20c2fc1618bf178a5386f90610be", "asset_id": "107000426448217931795450451304515386602910396776318075817601265223856116134349", "price": "0.305", "size": "11.24", "side": "BUY", "timestamp": "1768404513029", "received_at": "2026-01-14T16:28:32.750940"}}
{"event_type": "price_change", "event_ts": "2026-01-14T16:28:32.750940", "ingestion_ts": "2026-01-14T16:33:58.842229", "market_id": "0xe9c127a8c35f045d37b5344b0a36711084fa20c2fc1618bf178a5386f90610be", "raw": {"market": "0xe9c127a8c35f045d37b5344b0a36711084fa20c2fc1618bf178a5386f90610be", "asset_id": "80230236018433940569996058935444651347308266584430516013229815570706872276819", "price": "0.695", "size": "11.24", "side": "SELL", "timestamp": "1768404513029", "received_at": "2026-01-14T16:28:32.750940"}}
{"event_type": "price_change", "event_ts": "2026-01-14T16:28:33.009351", "ingestion_ts": "2026-01-14T16:33:58.842229", "market_id": "0xe9c127a8c35f045d37b5344b0a36711084fa20c2fc1618bf178a5386f90610be", "raw": {"market": "0xe9c127a8c35f045d37b5344b0a36711084fa20c2fc1618bf178a5386f90610be", "asset_id": "107000426448217931795450451304515386602910396776318075817601265223856116134349", "price": "0.351", "size": "0", "side": "BUY", "timestamp": "1768404513222", "received_at": "2026-01-14T16:28:33.009351"}}
{"event_type": "price_change", "event_ts": "2026-01-14T16:28:33.009351", "ingestion_ts": "2026-01-14T16:33:58.842229", "market_id": "0xe9c127a8c35f045d37b5344b0a36711084fa20c2fc1618bf178a5386f90610be", "raw": {"market": "0xe9c127a8c35f045d37b5344b0a36711084fa20c2fc1618bf178a5386f90610be", "asset_id": "80230236018433940569996058935444651347308266584430516013229815570706872276819", "price": "0.649", "size": "0", "side": "SELL", "timestamp": "1768404513222", "received_at": "2026-01-14T16:28:33.009351"}}
{"event_type": "price_change", "event_ts": "2026-01-14T16:28:33.263011", "ingestion_ts": "2026-01-14T16:33:58.842229", "market_id": "0xe9c127a8c35f045d37b5344b0a36711084fa20c2fc1618bf178a5386f90610be", "raw": {"market": "0xe9c127a8c35f045d37b5344b0a36711084fa20c2fc1618bf178a5386f90610be", "asset_id": "107000426448217931795450451304515386602910396776318075817601265223856116134349", "price": "0.351", "size": "9.76", "side": "BUY", "timestamp": "1768404513443", "received_at": "2026-01-14T16:28:33.263011"}}
{"event_type": "price_change", "event_ts": "2026-01-14T16:28:33.263011", "ingestion_ts": "2026-01-14T16:33:58.842229", "market_id": "0xe9c127a8c35f045d37b5344b0a36711084fa20c2fc1618bf178a5386f90610be", "raw": {"market": "0xe9c127a8c35f045d37b5344b0a36711084fa20c2fc1618bf178a5386f90610be", "asset_id": "80230236018433940569996058935444651347308266584430516013229815570706872276819", "price": "0.649", "size": "9.76", "side": "SELL", "timestamp": "1768404513443", "received_at": "2026-01-14T16:28:33.263011"}}
{"event_type": "price_change", "event_ts": "2026-01-14T16:28:33.430726", "ingestion_ts": "2026-01-14T16:33:58.842229", "market_id": "0xe9c127a8c35f045d37b5344b0a36711084fa20c2fc1618bf178a5386f90610be", "raw": {"market": "0xe9c127a8c35f045d37b5344b0a36711084fa20c2fc1618bf178a5386f90610be", "asset_id": "107000426448217931795450451304515386602910396776318075817601265223856116134349", "price": "0.371", "size": "0", "side": "BUY", "timestamp": "1768404513651", "received_at": "2026-01-14T16:28:33.430726"}}
{"event_type": "price_change", "event_ts": "2026-01-14T16:28:33.430726", "ingestion_ts": "2026-01-14T16:33:58.842229", "market_id": "0xe9c127a8c35f045d37b5344b0a36711084fa20c2fc1618bf178a5386f90610be", "raw": {"market": "0xe9c127a8c35f045d37b5344b0a36711084fa20c2fc1618bf178a5386f90610be", "asset_id": "80230236018433940569996058935444651347308266584430516013229815570706872276819", "price": "0.629", "size": "0", "side": "SELL", "timestamp": "1768404513651", "received_at": "2026-01-14T16:28:33.430726"}}
{"event_type": "price_change", "event_ts": "2026-01-14T16:28:33.554923", "ingestion_ts": "2026-01-14T16:33:58.842229", "market_id": "0xe9c127a8c35f045d37b5344b0a36711084fa20c2fc1618bf178a5386f90610be", "raw": {"market": "0xe9c127a8c35f045d37b5344b0a36711084fa20c2fc1618bf178a5386f90610be", "asset_id": "107000426448217931795450451304515386602910396776318075817601265223856116134349", "price": "0.371", "size": "9.24", "side": "BUY", "timestamp": "1768404513891", "received_at": "2026-01-14T16:28:33.554923"}}
{"event_type": "price_change", "event_ts": "2026-01-14T16:28:33.554923", "ingestion_ts": "2026-01-14T16:33:58.842229", "market_id": "0xe9c127a8c35f045d37b5344b0a36711084fa20c2fc1618bf178a5386f90610be", "raw": {"market": "0xe9c127a8c35f045d37b5344b0a36711084fa20c2fc1618bf178a5386f90610be", "asset_id": "80230236018433940569996058935444651347308266584430516013229815570706872276819", "price": "0.629", "size": "9.24", "side": "SELL", "timestamp": "1768404513891", "received_at": "2026-01-14T16:28:33.554923"}}
{"event_type": "price_change", "event_ts": "2026-01-14T16:28:33.765726", "ingestion_ts": "2026-01-14T16:33:58.842229", "market_id": "0xe9c127a8c35f045d37b5344b0a36711084fa20c2fc1618bf178a5386f90610be", "raw": {"market": "0xe9c127a8c35f045d37b5344b0a36711084fa20c2fc1618bf178a5386f90610be", "asset_id": "107000426448217931795450451304515386602910396776318075817601265223856116134349", "price": "0.413", "size": "0", "side": "BUY", "timestamp": "1768404514100", "received_at": "2026-01-14T16:28:33.765726"}}
{"event_type": "price_change", "event_ts": "2026-01-14T16:28:33.765726", "ingestion_ts": "2026-01-14T16:33:58.842229", "market_id": "0xe9c127a8c35f045d37b5344b0a36711084fa20c2fc1618bf178a5386f90610be", "raw": {"market": "0xe9c127a8c35f045d37b5344b0a36711084fa20c2fc1618bf178a5386f90610be", "asset_id": "80230236018433940569996058935444651347308266584430516013229815570706872276819", "price": "0.587", "size": "0", "side": "SELL", "timestamp": "1768404514100", "received_at": "2026-01-14T16:28:33.765726"}}
{"event_type": "price_change", "event_ts": "2026-01-14T16:28:33.970151", "ingestion_ts": "2026-01-14T16:33:58.842229", "market_id": "0xe9c127a8c35f045d37b5344b0a36711084fa20c2fc1618bf178a5386f90610be", "raw": {"market": "0xe9c127a8c35f045d37b5344b0a36711084fa20c2fc1618bf178a5386f90610be", "asset_id": "107000426448217931795450451304515386602910396776318075817601265223856116134349", "price": "0.413", "size": "8.3", "side": "BUY", "timestamp": "1768404514307", "received_at": "2026-01-14T16:28:33.970151"}}
{"event_type": "price_change", "event_ts": "2026-01-14T16:28:33.970151", "ingestion_ts": "2026-01-14T16:33:58.842229", "market_id": "0xe9c127a8c35f045d37b5344b0a36711084fa20c2fc1618bf178a5386f90610be", "raw": {"market": "0xe9c127a8c35f045d37b5344b0a36711084fa20c2fc1618bf178a5386f90610be", "asset_id": "80230236018433940569996058935444651347308266584430516013229815570706872276819", "price": "0.587", "size": "8.3", "side": "SELL", "timestamp": "1768404514307", "received_at": "2026-01-14T16:28:33.970151"}}
{"event_type": "price_change", "event_ts": "2026-01-14T16:28:34.188811", "ingestion_ts": "2026-01-14T16:33:58.842229", "market_id": "0xe9c127a8c35f045d37b5344b0a36711084fa20c2fc1618bf178a5386f90610be", "raw": {"market": "0xe9c127a8c35f045d37b5344b0a36711084fa20c2fc1618bf178a5386f90610be", "asset_id": "107000426448217931795450451304515386602910396776318075817601265223856116134349", "price": "0.5", "size": "19.85", "side": "BUY", "timestamp": "1768404514522", "received_at": "2026-01-14T16:28:34.188811"}}
{"event_type": "price_change", "event_ts": "2026-01-14T16:28:34.188811", "ingestion_ts": "2026-01-14T16:33:58.842229", "market_id": "0xe9c127a8c35f045d37b5344b0a36711084fa20c2fc1618bf178a5386f90610be", "raw": {"market": "0xe9c127a8c35f045d37b5344b0a36711084fa20c2fc1618bf178a5386f90610be", "asset_id": "80230236018433940569996058935444651347308266584430516013229815570706872276819", "price": "0.5", "size": "19.85", "side": "SELL", "timestamp": "1768404514522", "received_at": "2026-01-14T16:28:34.188811"}}
{"event_type": "price_change", "event_ts": "2026-01-14T16:28:34.422302", "ingestion_ts": "2026-01-14T16:33:58.842229", "market_id": "0xe9c127a8c35f045d37b5344b0a36711084fa20c2fc1618bf178a5386f90610be", "raw": {"market": "0xe9c127a8c35f045d37b5344b0a36711084fa20c2fc1618bf178a5386f90610be", "asset_id": "107000426448217931795450451304515386602910396776318075817601265223856116134349", "price": "0.501", "size": "6.84", "side": "BUY", "timestamp": "1768404514747", "received_at": "2026-01-14T16:28:34.422302"}}
{"event_type": "price_change", "event_ts": "2026-01-14T16:28:34.422302", "ingestion_ts": "2026-01-14T16:33:58.842229", "market_id": "0xe9c127a8c35f045d37b5344b0a36711084fa20c2fc1618bf178a5386f90610be", "raw": {"market": "0xe9c127a8c35f045d37b5344b0a36711084fa20c2fc1618bf178a5386f90610be", "asset_id": "80230236018433940569996058935444651347308266584430516013229815570706872276819", "price": "0.499", "size": "6.84", "side": "SELL", "timestamp": "1768404514747", "received_at": "2026-01-14T16:28:34.422302"}}
{"event_type": "price_change", "event_ts": "2026-01-14T16:28:46.665584", "ingestion_ts": "2026-01-14T16:33:58.842229", "market_id": "0xea644975be7b2ad32b536a94ae21b707ecb2f84290225b24e60ca46dd77903dd", "raw": {"market": "0xea644975be7b2ad32b536a94ae21b707ecb2f84290225b24e60ca46dd77903dd", "asset_id": "19255594762111702415265750364124818677094538461124581923455280001407159960455", "price": "0.001", "size": "203518.5", "side": "BUY", "timestamp": "1768404527000", "received_at": "2026-01-14T16:28:46.665584"}}
{"event_type": "price_change", "event_ts": "2026-01-14T16:28:46.665584", "ingestion_ts": "2026-01-14T16:33:58.842229", "market_id": "0xea644975be7b2ad32b536a94ae21b707ecb2f84290225b24e60ca46dd77903dd", "raw": {"market": "0xea644975be7b2ad32b536a94ae21b707ecb2f84290225b24e60ca46dd77903dd", "asset_id": "110044455628775971785618539427229099821815416148768008176051068105157446559241", "price": "0.999", "size": "203518.5", "side": "SELL", "timestamp": "1768404527000", "received_at": "2026-01-14T16:28:46.665584"}}
{"event_type": "price_change", "event_ts": "2026-01-14T16:28:46.665636", "ingestion_ts": "2026-01-14T16:33:58.842229", "market_id": "0x44f08744458b8896620cd3330bc5e1ea69df4199b02d4fc583b3fc96e5d314ce", "raw": {"market": "0x44f08744458b8896620cd3330bc5e1ea69df4199b02d4fc583b3fc96e5d314ce", "asset_id": "72327831507226612545928776794104143393438710920370371172884559893525100761096", "price": "0.002", "size": "250", "side": "BUY", "timestamp": "1768404527000", "received_at": "2026-01-14T16:28:46.665636"}}
{"event_type": "price_change", "event_ts": "2026-01-14T16:28:46.665636", "ingestion_ts": "2026-01-14T16:33:58.842229", "market_id": "0x44f08744458b8896620cd3330bc5e1ea69df4199b02d4fc583b3fc96e5d314ce", "raw": {"market": "0x44f08744458b8896620cd3330bc5e1ea69df4199b02d4fc583b3fc96e5d314ce", "asset_id": "49194009556504828848509244326501559253829462790583873936160989575507522044057", "price": "0.998", "size": "250", "side": "SELL", "timestamp": "1768404527000", "received_at": "2026-01-14T16:28:46.665636"}}
{"event_type": "price_change", "event_ts": "2026-01-14T16:28:46.665655", "ingestion_ts": "2026-01-14T16:33:58.842229", "market_id": "0xe68594f1350f5535532b24979b5b5c1948432cbfc0c363802c32a8f9ab4e6509", "raw": {"market": "0xe68594f1350f5535532b24979b5b5c1948432cbfc0c363802c32a8f9ab4e6509", "asset_id": "3074032031589250926591186368301243337494992039402397918135503567058257050088", "price": "0.004", "size": "0", "side": "BUY", "timestamp": "1768404527000", "received_at": "2026-01-14T16:28:46.665655"}}
{"event_type": "price_change", "event_ts": "2026-01-14T16:28:46.665655", "ingestion_ts": "2026-01-14T16:33:58.842229", "market_id": "0xe68594f1350f5535532b24979b5b5c1948432cbfc0c363802c32a8f9ab4e6509", "raw": {"market": "0xe68594f1350f5535532b24979b5b5c1948432cbfc0c363802c32a8f9ab4e6509", "asset_id": "47459180813047899567328389455747872955901265556145057896316155826890276004242", "price": "0.996", "size": "0", "side": "SELL", "timestamp": "1768404527000", "received_at": "2026-01-14T16:28:46.665655"}}
{"event_type": "price_change", "event_ts": "2026-01-14T16:28:46.667139", "ingestion_ts": "2026-01-14T16:33:58.842229", "market_id": "0xea644975be7b2ad32b536a94ae21b707ecb2f84290225b24e60ca46dd77903dd", "raw": {"market": "0xea644975be7b2ad32b536a94ae21b707ecb2f84290225b24e60ca46dd77903dd", "asset_id": "19255594762111702415265750364124818677094538461124581923455280001407159960455", "price": "0.011", "size": "0", "side": "BUY", "timestamp": "1768404527000", "received_at": "2026-01-14T16:28:46.667139"}}
{"event_type": "price_change", "event_ts": "2026-01-14T16:28:46.667139", "ingestion_ts": "2026-01-14T16:33:58.842229", "market_id": "0xea644975be7b2ad32b536a94ae21b707ecb2f84290225b24e60ca46dd77903dd", "raw": {"market": "0xea644975be7b2ad32b536a94ae21b707ecb2f84290225b24e60ca46dd77903dd", "asset_id": "110044455628775971785618539427229099821815416148768008176051068105157446559241", "price": "0.989", "size": "0", "side": "SELL", "timestamp": "1768404527000", "received_at": "2026-01-14T16:28:46.667139"}}
{"event_type": "price_change", "event_ts": "2026-01-14T16:28:46.667169", "ingestion_ts": "2026-01-14T16:33:58.842229", "market_id": "0xe68594f1350f5535532b24979b5b5c1948432cbfc0c363802c32a8f9ab4e6509", "raw": {"market": "0xe68594f1350f5535532b24979b5b5c1948432cbfc0c363802c32a8f9ab4e6509", "asset_id": "3074032031589250926591186368301243337494992039402397918135503567058257050088", "price": "0.002", "size": "250", "side": "BUY", "timestamp": "1768404527000", "received_at": "2026-01-14T16:28:46.667169"}}
{"event_type": "price_change", "event_ts": "2026-01-14T16:28:46.667169", "ingestion_ts": "2026-01-14T16:33:58.842229", "market_id": "0xe68594f1350f5535532b24979b5b5c1948432cbfc0c363802c32a8f9ab4e6509", "raw": {"market": "0xe68594f1350f5535532b24979b5b5c1948432cbfc0c363802c32a8f9ab4e6509", "asset_id": "47459180813047899567328389455747872955901265556145057896316155826890276004242", "price": "0.998", "size": "250", "side": "SELL", "timestamp": "1768404527000", "received_at": "2026-01-14T16:28:46.667169"}}
{"event_type": "price_change", "event_ts": "2026-01-14T16:28:46.669056", "ingestion_ts": "2026-01-14T16:33:58.842229", "market_id": "0xea644975be7b2ad32b536a94ae21b707ecb2f84290225b24e60ca46dd77903dd", "raw": {"market": "0xea644975be7b2ad32b536a94ae21b707ecb2f84290225b24e60ca46dd77903dd", "asset_id": "19255594762111702415265750364124818677094538461124581923455280001407159960455", "price": "0.201", "size": "0", "side": "BUY", "timestamp": "1768404527001", "received_at": "2026-01-14T16:28:46.669056"}}
{"event_type": "price_change", "event_ts": "2026-01-14T16:28:46.669056", "ingestion_ts": "2026-01-14T16:33:58.842229", "market_id": "0xea644975be7b2ad32b536a94ae21b707ecb2f84290225b24e60ca46dd77903dd", "raw": {"market": "0xea644975be7b2ad32b536a94ae21b707ecb2f84290225b24e60ca46dd77903dd", "asset_id": "110044455628775971785618539427229099821815416148768008176051068105157446559241", "price": "0.799", "size": "0", "side": "SELL", "timestamp": "1768404527001", "received_at": "2026-01-14T16:28:46.669056"}}
{"event_type": "price_change", "event_ts": "2026-01-14T16:28:46.669105", "ingestion_ts": "2026-01-14T16:33:58.842229", "market_id": "0xe68594f1350f5535532b24979b5b5c1948432cbfc0c363802c32a8f9ab4e6509", "raw": {"market": "0xe68594f1350f5535532b24979b5b5c1948432cbfc0c363802c32a8f9ab4e6509", "asset_id": "3074032031589250926591186368301243337494992039402397918135503567058257050088", "price": "0.201", "size": "0", "side": "BUY", "timestamp": "1768404527001", "received_at": "2026-01-14T16:28:46.669105"}}
{"event_type": "price_change", "event_ts": "2026-01-14T16:28:46.669105", "ingestion_ts": "2026-01-14T16:33:58.842229", "market_id": "0xe68594f1350f5535532b24979b5b5c1948432cbfc0c363802c32a8f9ab4e6509", "raw": {"market": "0xe68594f1350f5535532b24979b5b5c1948432cbfc0c363802c32a8f9ab4e6509", "asset_id": "47459180813047899567328389455747872955901265556145057896316155826890276004242", "price": "0.799", "size": "0", "side": "SELL", "timestamp": "1768404527001", "received_at": "2026-01-14T16:28:46.669105"}}
{"event_type": "price_change", "event_ts": "2026-01-14T16:28:46.669131", "ingestion_ts": "2026-01-14T16:33:58.842229", "market_id": "0x44f08744458b8896620cd3330bc5e1ea69df4199b02d4fc583b3fc96e5d314ce", "raw": {"market": "0x44f08744458b8896620cd3330bc5e1ea69df4199b02d4fc583b3fc96e5d314ce", "asset_id": "72327831507226612545928776794104143393438710920370371172884559893525100761096", "price": "0.001", "size": "2625.71", "side": "BUY", "timestamp": "1768404527001", "received_at": "2026-01-14T16:28:46.669131"}}
{"event_type": "price_change", "event_ts": "2026-01-14T16:28:46.669131", "ingestion_ts": "2026-01-14T16:33:58.842229", "market_id": "0x44f08744458b8896620cd3330bc5e1ea69df4199b02d4fc583b3fc96e5d314ce", "raw": {"market": "0x44f08744458b8896620cd3330bc5e1ea69df4199b02d4fc583b3fc96e5d314ce", "asset_id": "49194009556504828848509244326501559253829462790583873936160989575507522044057", "price": "0.999", "size": "2625.71", "side": "SELL", "timestamp": "1768404527001", "received_at": "2026-01-14T16:28:46.669131"}}
{"event_type": "price_change", "event_ts": "2026-01-14T16:28:46.670489", "ingestion_ts": "2026-01-14T16:33:58.842229", "market_id": "0xea644975be7b2ad32b536a94ae21b707ecb2f84290225b24e60ca46dd77903dd", "raw": {"market": "0xea644975be7b2ad32b536a94ae21b707ecb2f84290225b24e60ca46dd77903dd", "asset_id": "19255594762111702415265750364124818677094538461124581923455280001407159960455", "price": "0.004", "size": "0", "side": "BUY", "timestamp": "1768404527001", "received_at": "2026-01-14T16:28:46.670489"}}
{"event_type": "price_change", "event_ts": "2026-01-14T16:28:46.670489", "ingestion_ts": "2026-01-14T16:33:58.842229", "market_id": "0xea644975be7b2ad32b536a94ae21b707ecb2f84290225b24e60ca46dd77903dd", "raw": {"market": "0xea644975be7b2ad32b536a94ae21b707ecb2f84290225b24e60ca46dd77903dd", "asset_id": "110044455628775971785618539427229099821815416148768008176051068105157446559241", "price": "0.996", "size": "0", "side": "SELL", "timestamp": "1768404527001", "received_at": "2026-01-14T16:28:46.670489"}}
{"event_type": "price_change", "event_ts": "2026-01-14T16:28:46.670516", "ingestion_ts": "2026-01-14T16:33:58.842229", "market_id": "0xe68594f1350f5535532b24979b5b5c1948432cbfc0c363802c32a8f9ab4e6509", "raw": {"market": "0xe68594f1350f5535532b24979b5b5c1948432cbfc0c363802c32a8f9ab4e6509", "asset_id": "3074032031589250926591186368301243337494992039402397918135503567058257050088", "price": "0.011", "size": "0", "side": "BUY", "timestamp": "1768404527001", "received_at": "2026-01-14T16:28:46.670516"}}
{"event_type": "price_change", "event_ts": "2026-01-14T16:28:46.670516", "ingestion_ts": "2026-01-14T16:33:58.842229", "market_id": "0xe68594f1350f5535532b24979b5b5c1948432cbfc0c363802c32a8f9ab4e6509", "raw": {"market": "0xe68594f1350f5535532b24979b5b5c1948432cbfc0c363802c32a8f9ab4e6509", "asset_id": "47459180813047899567328389455747872955901265556145057896316155826890276004242", "price": "0.989", "size": "0", "side": "SELL", "timestamp": "1768404527001", "received_at": "2026-01-14T16:28:46.670516"}}
{"event_type": "price_change", "event_ts": "2026-01-14T16:28:46.683516", "ingestion_ts": "2026-01-14T16:33:58.842229", "market_id": "0x44f08744458b8896620cd3330bc5e1ea69df4199b02d4fc583b3fc96e5d314ce", "raw": {"market": "0x44f08744458b8896620cd3330bc5e1ea69df4199b02d4fc583b3fc96e5d314ce", "asset_id": "72327831507226612545928776794104143393438710920370371172884559893525100761096", "price": "0.201", "size": "0", "side": "BUY", "timestamp": "1768404527001", "received_at": "2026-01-14T16:28:46.683516"}}
{"event_type": "price_change", "event_ts": "2026-01-14T16:28:46.683516", "ingestion_ts": "2026-01-14T16:33:58.842229", "market_id": "0x44f08744458b8896620cd3330bc5e1ea69df4199b02d4fc583b3fc96e5d314ce", "raw": {"market": "0x44f08744458b8896620cd3330bc5e1ea69df4199b02d4fc583b3fc96e5d314ce", "asset_id": "49194009556504828848509244326501559253829462790583873936160989575507522044057", "price": "0.799", "size": "0", "side": "SELL", "timestamp": "1768404527001", "received_at": "2026-01-14T16:28:46.683516"}}
{"event_type": "price_change", "event_ts": "2026-01-14T16:28:46.683558", "ingestion_ts": "2026-01-14T16:33:58.842229", "market_id": "0xe68594f1350f5535532b24979b5b5c1948432cbfc0c363802c32a8f9ab4e6509", "raw": {"market": "0xe68594f1350f5535532b24979b5b5c1948432cbfc0c363802c32a8f9ab4e6509", "asset_id": "3074032031589250926591186368301243337494992039402397918135503567058257050088", "price": "0.001", "size": "203628.37", "side": "BUY", "timestamp": "1768404527002", "received_at": "2026-01-14T16:28:46.683558"}}
{"event_type": "price_change", "event_ts": "2026-01-14T16:28:46.683558", "ingestion_ts": "2026-01-14T16:33:58.842229", "market_id": "0xe68594f1350f5535532b24979b5b5c1948432cbfc0c363802c32a8f9ab4e6509", "raw": {"market": "0xe68594f1350f5535532b24979b5b5c1948432cbfc0c363802c32a8f9ab4e6509", "asset_id": "47459180813047899567328389455747872955901265556145057896316155826890276004242", "price": "0.999", "size": "203628.37", "side": "SELL", "timestamp": "1768404527002", "received_at": "2026-01-14T16:28:46.683558"}}
{"event_type": "price_change", "event_ts": "2026-01-14T16:28:46.683583", "ingestion_ts": "2026-01-14T16:33:58.842229", "market_id": "0xe68594f1350f5535532b24979b5b5c1948432cbfc0c363802c32a8f9ab4e6509", "raw": {"market": "0xe68594f1350f5535532b24979b5b5c1948432cbfc0c363802c32a8f9ab4e6509", "asset_id": "3074032031589250926591186368301243337494992039402397918135503567058257050088", "price": "0.051", "size": "0", "side": "BUY", "timestamp": "1768404527003", "received_at": "2026-01-14T16:28:46.683583"}}
{"event_type": "price_change", "event_ts": "2026-01-14T16:28:46.683583", "ingestion_ts": "2026-01-14T16:33:58.842229", "market_id": "0xe68594f1350f5535532b24979b5b5c1948432cbfc0c363802c32a8f9ab4e6509", "raw": {"market": "0xe68594f1350f5535532b24979b5b5c1948432cbfc0c363802c32a8f9ab4e6509", "asset_id": "47459180813047899567328389455747872955901265556145057896316155826890276004242", "price": "0.949", "size": "0", "side": "SELL", "timestamp": "1768404527003", "received_at": "2026-01-14T16:28:46.683583"}}
{"event_type": "price_change", "event_ts": "2026-01-14T16:28:46.683601", "ingestion_ts": "2026-01-14T16:33:58.842229", "market_id": "0xea644975be7b2ad32b536a94ae21b707ecb2f84290225b24e60ca46dd77903dd", "raw": {"market": "0xea644975be7b2ad32b536a94ae21b707ecb2f84290225b24e60ca46dd77903dd", "asset_id": "19255594762111702415265750364124818677094538461124581923455280001407159960455", "price": "0.021", "size": "0", "side": "BUY", "timestamp": "1768404527003", "received_at": "2026-01-14T16:28:46.683601"}}
{"event_type": "price_change", "event_ts": "2026-01-14T16:28:46.683601", "ingestion_ts": "2026-01-14T16:33:58.842229", "market_id": "0xea644975be7b2ad32b536a94ae21b707ecb2f84290225b24e60ca46dd77903dd", "raw": {"market": "0xea644975be7b2ad32b536a94ae21b707ecb2f84290225b24e60ca46dd77903dd", "asset_id": "110044455628775971785618539427229099821815416148768008176051068105157446559241", "price": "0.979", "size": "0", "side": "SELL", "timestamp": "1768404527003", "received_at": "2026-01-14T16:28:46.683601"}}
{"event_type": "price_change", "event_ts": "2026-01-14T16:28:46.683620", "ingestion_ts": "2026-01-14T16:33:58.842229", "market_id": "0x44f08744458b8896620cd3330bc5e1ea69df4199b02d4fc583b3fc96e5d314ce", "raw": {"market": "0x44f08744458b8896620cd3330bc5e1ea69df4199b02d4fc583b3fc96e5d314ce", "asset_id": "72327831507226612545928776794104143393438710920370371172884559893525100761096", "price": "0.024", "size": "0", "side": "BUY", "timestamp": "1768404527003", "received_at": "2026-01-14T16:28:46.683620"}}
{"event_type": "price_change", "event_ts": "2026-01-14T16:28:46.683620", "ingestion_ts": "2026-01-14T16:33:58.842229", "market_id": "0x44f08744458b8896620cd3330bc5e1ea69df4199b02d4fc583b3fc96e5d314ce", "raw": {"market": "0x44f08744458b8896620cd3330bc5e1ea69df4199b02d4fc583b3fc96e5d314ce", "asset_id": "49194009556504828848509244326501559253829462790583873936160989575507522044057", "price": "0.976", "size": "0", "side": "SELL", "timestamp": "1768404527003", "received_at": "2026-01-14T16:28:46.683620"}}
{"event_type": "price_change", "event_ts": "2026-01-14T16:28:46.683636", "ingestion_ts": "2026-01-14T16:33:58.842229", "market_id": "0xea644975be7b2ad32b536a94ae21b707ecb2f84290225b24e60ca46dd77903dd", "raw": {"market": "0xea644975be7b2ad32b536a94ae21b707ecb2f84290225b24e60ca46dd77903dd", "asset_id": "19255594762111702415265750364124818677094538461124581923455280001407159960455", "price": "0.002", "size": "250", "side": "BUY", "timestamp": "1768404527004", "received_at": "2026-01-14T16:28:46.683636"}}
{"event_type": "price_change", "event_ts": "2026-01-14T16:28:46.683636", "ingestion_ts": "2026-01-14T16:33:58.842229", "market_id": "0xea644975be7b2ad32b536a94ae21b707ecb2f84290225b24e60ca46dd77903dd", "raw": {"market": "0xea644975be7b2ad32b536a94ae21b707ecb2f84290225b24e60ca46dd77903dd", "asset_id": "110044455628775971785618539427229099821815416148768008176051068105157446559241", "price": "0.998", "size": "250", "side": "SELL", "timestamp": "1768404527004", "received_at": "2026-01-14T16:28:46.683636"}}
{"event_type": "price_change", "event_ts": "2026-01-14T16:28:46.683652", "ingestion_ts": "2026-01-14T16:33:58.842229", "market_id": "0x44f08744458b8896620cd3330bc5e1ea69df4199b02d4fc583b3fc96e5d314ce", "raw": {"market": "0x44f08744458b8896620cd3330bc5e1ea69df4199b02d4fc583b3fc96e5d314ce", "asset_id": "72327831507226612545928776794104143393438710920370371172884559893525100761096", "price": "0.011", "size": "0", "side": "BUY", "timestamp": "1768404527004", "received_at": "2026-01-14T16:28:46.683652"}}
{"event_type": "price_change", "event_ts": "2026-01-14T16:28:46.683652", "ingestion_ts": "2026-01-14T16:33:58.842229", "market_id": "0x44f08744458b8896620cd3330bc5e1ea69df4199b02d4fc583b3fc96e5d314ce", "raw": {"market": "0x44f08744458b8896620cd3330bc5e1ea69df4199b02d4fc583b3fc96e5d314ce", "asset_id": "49194009556504828848509244326501559253829462790583873936160989575507522044057", "price": "0.989", "size": "0", "side": "SELL", "timestamp": "1768404527004", "received_at": "2026-01-14T16:28:46.683652"}}
{"event_type": "price_change", "event_ts": "2026-01-14T16:28:46.683670", "ingestion_ts": "2026-01-14T16:33:58.842229", "market_id": "0xea644975be7b2ad32b536a94ae21b707ecb2f84290225b24e60ca46dd77903dd", "raw": {"market": "0xea644975be7b2ad32b536a94ae21b707ecb2f84290225b24e60ca46dd77903dd", "asset_id": "19255594762111702415265750364124818677094538461124581923455280001407159960455", "price": "0.051", "size": "0", "side": "BUY", "timestamp": "1768404527004", "received_at": "2026-01-14T16:28:46.683670"}}
{"event_type": "price_change", "event_ts": "2026-01-14T16:28:46.683670", "ingestion_ts": "2026-01-14T16:33:58.842229", "market_id": "0xea644975be7b2ad32b536a94ae21b707ecb2f84290225b24e60ca46dd77903dd", "raw": {"market": "0xea644975be7b2ad32b536a94ae21b707ecb2f84290225b24e60ca46dd77903dd", "asset_id": "110044455628775971785618539427229099821815416148768008176051068105157446559241", "price": "0.949", "size": "0", "side": "SELL", "timestamp": "1768404527004", "received_at": "2026-01-14T16:28:46.683670"}}
{"event_type": "price_change", "event_ts": "2026-01-14T16:28:46.683688", "ingestion_ts": "2026-01-14T16:33:58.842229", "market_id": "0xe68594f1350f5535532b24979b5b5c1948432cbfc0c363802c32a8f9ab4e6509", "raw": {"market": "0xe68594f1350f5535532b24979b5b5c1948432cbfc0c363802c32a8f9ab4e6509", "asset_id": "3074032031589250926591186368301243337494992039402397918135503567058257050088", "price": "0.021", "size": "0", "side": "BUY", "timestamp": "1768404527004", "received_at": "2026-01-14T16:28:46.683688"}}
{"event_type": "price_change", "event_ts": "2026-01-14T16:28:46.683688", "ingestion_ts": "2026-01-14T16:33:58.842229", "market_id": "0xe68594f1350f5535532b24979b5b5c1948432cbfc0c363802c32a8f9ab4e6509", "raw": {"market": "0xe68594f1350f5535532b24979b5b5c1948432cbfc0c363802c32a8f9ab4e6509", "asset_id": "47459180813047899567328389455747872955901265556145057896316155826890276004242", "price": "0.979", "size": "0", "side": "SELL", "timestamp": "1768404527004", "received_at": "2026-01-14T16:28:46.683688"}}
{"event_type": "price_change", "event_ts": "2026-01-14T16:28:46.685065", "ingestion_ts": "2026-01-14T16:33:58.842229", "market_id": "0x44f08744458b8896620cd3330bc5e1ea69df4199b02d4fc583b3fc96e5d314ce", "raw": {"market": "0x44f08744458b8896620cd3330bc5e1ea69df4199b02d4fc583b3fc96e5d314ce", "asset_id": "72327831507226612545928776794104143393438710920370371172884559893525100761096", "price": "0.057", "size": "0", "side": "BUY", "timestamp": "1768404527004", "received_at": "2026-01-14T16:28:46.685065"}}
{"event_type": "price_change", "event_ts": "2026-01-14T16:28:46.685065", "ingestion_ts": "2026-01-14T16:33:58.842229", "market_id": "0x44f08744458b8896620cd3330bc5e1ea69df4199b02d4fc583b3fc96e5d314ce", "raw": {"market": "0x44f08744458b8896620cd3330bc5e1ea69df4199b02d4fc583b3fc96e5d314ce", "asset_id": "49194009556504828848509244326501559253829462790583873936160989575507522044057", "price": "0.943", "size": "0", "side": "SELL", "timestamp": "1768404527004", "received_at": "2026-01-14T16:28:46.685065"}}
{"event_type": "price_change", "event_ts": "2026-01-14T16:28:46.685081", "ingestion_ts": "2026-01-14T16:33:58.842229", "market_id": "0x44f08744458b8896620cd3330bc5e1ea69df4199b02d4fc583b3fc96e5d314ce", "raw": {"market": "0x44f08744458b8896620cd3330bc5e1ea69df4199b02d4fc583b3fc96e5d314ce", "asset_id": "72327831507226612545928776794104143393438710920370371172884559893525100761096", "price": "0.005", "size": "0", "side": "BUY", "timestamp": "1768404527005", "received_at": "2026-01-14T16:28:46.685081"}}
{"event_type": "price_change", "event_ts": "2026-01-14T16:28:46.685081", "ingestion_ts": "2026-01-14T16:33:58.842229", "market_id": "0x44f08744458b8896620cd3330bc5e1ea69df4199b02d4fc583b3fc96e5d314ce", "raw": {"market": "0x44f08744458b8896620cd3330bc5e1ea69df4199b02d4fc583b3fc96e5d314ce", "asset_id": "49194009556504828848509244326501559253829462790583873936160989575507522044057", "price": "0.995", "size": "0", "side": "SELL", "timestamp": "1768404527005", "received_at": "2026-01-14T16:28:46.685081"}}
{"event_type": "price_change", "event_ts": "2026-01-14T16:28:46.736907", "ingestion_ts": "2026-01-14T16:33:58.842229", "market_id": "0x50c669f178da4e5bbea7f1be25041fd278914712fa87a6a6f8e57d5923d88dee", "raw": {"market": "0x50c669f178da4e5bbea7f1be25041fd278914712fa87a6a6f8e57d5923d88dee", "asset_id": "74040420326294854165772767082819937451857852955603897473157746262672057685461", "price": "0.925", "size": "0", "side": "BUY", "timestamp": "1768404527073", "received_at": "2026-01-14T16:28:46.736907"}}
{"event_type": "price_change", "event_ts": "2026-01-14T16:28:46.736907", "ingestion_ts": "2026-01-14T16:33:58.842229", "market_id": "0x50c669f178da4e5bbea7f1be25041fd278914712fa87a6a6f8e57d5923d88dee", "raw": {"market": "0x50c669f178da4e5bbea7f1be25041fd278914712fa87a6a6f8e57d5923d88dee", "asset_id": "24682525479474221428144937281315825971983904267399062415430320764754931667953", "price": "0.075", "size": "0", "side": "SELL", "timestamp": "1768404527073", "received_at": "2026-01-14T16:28:46.736907"}}
{"event_type": "price_change", "event_ts": "2026-01-14T16:28:46.915915", "ingestion_ts": "2026-01-14T16:33:58.842229", "market_id": "0xc55db914f0fd1fee18997706712c0dfd8d0369cdbef93a9fef12bd001914ca77", "raw": {"market": "0xc55db914f0fd1fee18997706712c0dfd8d0369cdbef93a9fef12bd001914ca77", "asset_id": "114600293444080540179603459515770723592661967180480327891296353898330242622833", "price": "0.925", "size": "0", "side": "BUY", "timestamp": "1768404527231", "received_at": "2026-01-14T16:28:46.915915"}}
{"event_type": "price_change", "event_ts": "2026-01-14T16:28:46.915915", "ingestion_ts": "2026-01-14T16:33:58.842229", "market_id": "0xc55db914f0fd1fee18997706712c0dfd8d0369cdbef93a9fef12bd001914ca77", "raw": {"market": "0xc55db914f0fd1fee18997706712c0dfd8d0369cdbef93a9fef12bd001914ca77", "asset_id": "72354723612769247426741660426331235762851940382312402276325808095604519806766", "price": "0.075", "size": "0", "side": "SELL", "timestamp": "1768404527231", "received_at": "2026-01-14T16:28:46.915915"}}
{"event_type": "price_change", "event_ts": "2026-01-14T16:28:47.010895", "ingestion_ts": "2026-01-14T16:33:58.842229", "market_id": "0xc55db914f0fd1fee18997706712c0dfd8d0369cdbef93a9fef12bd001914ca77", "raw": {"market": "0xc55db914f0fd1fee18997706712c0dfd8d0369cdbef93a9fef12bd001914ca77", "asset_id": "114600293444080540179603459515770723592661967180480327891296353898330242622833", "price": "0.842", "size": "10", "side": "BUY", "timestamp": "1768404527347", "received_at": "2026-01-14T16:28:47.010895"}}
{"event_type": "price_change", "event_ts": "2026-01-14T16:28:47.010895", "ingestion_ts": "2026-01-14T16:33:58.842229", "market_id": "0xc55db914f0fd1fee18997706712c0dfd8d0369cdbef93a9fef12bd001914ca77", "raw": {"market": "0xc55db914f0fd1fee18997706712c0dfd8d0369cdbef93a9fef12bd001914ca77", "asset_id": "72354723612769247426741660426331235762851940382312402276325808095604519806766", "price": "0.158", "size": "10", "side": "SELL", "timestamp": "1768404527347", "received_at": "2026-01-14T16:28:47.010895"}}
{"event_type": "price_change", "event_ts": "2026-01-14T16:28:47.010947", "ingestion_ts": "2026-01-14T16:33:58.842229", "market_id": "0xc55db914f0fd1fee18997706712c0dfd8d0369cdbef93a9fef12bd001914ca77", "raw": {"market": "0xc55db914f0fd1fee18997706712c0dfd8d0369cdbef93a9fef12bd001914ca77", "asset_id": "114600293444080540179603459515770723592661967180480327891296353898330242622833", "price": "0.925", "size": "20", "side": "BUY", "timestamp": "1768404527348", "received_at": "2026-01-14T16:28:47.010947"}}
{"event_type": "price_change", "event_ts": "2026-01-14T16:28:47.010947", "ingestion_ts": "2026-01-14T16:33:58.842229", "market_id": "0xc55db914f0fd1fee18997706712c0dfd8d0369cdbef93a9fef12bd001914ca77", "raw": {"market": "0xc55db914f0fd1fee18997706712c0dfd8d0369cdbef93a9fef12bd001914ca77", "asset_id": "72354723612769247426741660426331235762851940382312402276325808095604519806766", "price": "0.075", "size": "20", "side": "SELL", "timestamp": "1768404527348", "received_at": "2026-01-14T16:28:47.010947"}}
{"event_type": "price_change", "event_ts": "2026-01-14T16:28:49.666758", "ingestion_ts": "2026-01-14T16:33:58.842229", "market_id": "0x50c669f178da4e5bbea7f1be25041fd278914712fa87a6a6f8e57d5923d88dee", "raw": {"market": "0x50c669f178da4e5bbea7f1be25041fd278914712fa87a6a6f8e57d5923d88dee", "asset_id": "74040420326294854165772767082819937451857852955603897473157746262672057685461", "price": "0.005", "size": "0", "side": "BUY", "timestamp": "1768404530000", "received_at": "2026-01-14T16:28:49.666758"}}
{"event_type": "price_change", "event_ts": "2026-01-14T16:28:49.666758", "ingestion_ts": "2026-01-14T16:33:58.842229", "market_id": "0x50c669f178da4e5bbea7f1be25041fd278914712fa87a6a6f8e57d5923d88dee", "raw": {"market": "0x50c669f178da4e5bbea7f1be25041fd278914712fa87a6a6f8e57d5923d88dee", "asset_id": "24682525479474221428144937281315825971983904267399062415430320764754931667953", "price": "0.995", "size": "0", "side": "SELL", "timestamp": "1768404530000", "received_at": "2026-01-14T16:28:49.666758"}}
{"event_type": "price_change", "event_ts": "2026-01-14T16:28:49.671532", "ingestion_ts": "2026-01-14T16:33:58.842229", "market_id": "0xc55db914f0fd1fee18997706712c0dfd8d0369cdbef93a9fef12bd001914ca77", "raw": {"market": "0xc55db914f0fd1fee18997706712c0dfd8d0369cdbef93a9fef12bd001914ca77", "asset_id": "114600293444080540179603459515770723592661967180480327891296353898330242622833", "price": "0.201", "size": "0", "side": "BUY", "timestamp": "1768404530000", "received_at": "2026-01-14T16:28:49.671532"}}
{"event_type": "price_change", "event_ts": "2026-01-14T16:28:49.671532", "ingestion_ts": "2026-01-14T16:33:58.842229", "market_id": "0xc55db914f0fd1fee18997706712c0dfd8d0369cdbef93a9fef12bd001914ca77", "raw": {"market": "0xc55db914f0fd1fee18997706712c0dfd8d0369cdbef93a9fef12bd001914ca77", "asset_id": "72354723612769247426741660426331235762851940382312402276325808095604519806766", "price": "0.799", "size": "0", "side": "SELL", "timestamp": "1768404530000", "received_at": "2026-01-14T16:28:49.671532"}}
{"event_type": "price_change", "event_ts": "2026-01-14T16:28:49.671565", "ingestion_ts": "2026-01-14T16:33:58.842229", "market_id": "0xb9bbdd34304344dcc45803780a34c97d73a00133a5ecf70f63e1008b8abb2fca", "raw": {"market": "0xb9bbdd34304344dcc45803780a34c97d73a00133a5ecf70f63e1008b8abb2fca", "asset_id": "8682484153073832526711485265636767086525069344085206423986003504588877767339", "price": "0.001", "size": "5098.33", "side": "BUY", "timestamp": "1768404530000", "received_at": "2026-01-14T16:28:49.671565"}}
{"event_type": "price_change", "event_ts": "2026-01-14T16:28:49.671565", "ingestion_ts": "2026-01-14T16:33:58.842229", "market_id": "0xb9bbdd34304344dcc45803780a34c97d73a00133a5ecf70f63e1008b8abb2fca", "raw": {"market": "0xb9bbdd34304344dcc45803780a34c97d73a00133a5ecf70f63e1008b8abb2fca", "asset_id": "72012724360700510767037780555710363830014634797787940282136454146828040926557", "price": "0.999", "size": "5098.33", "side": "SELL", "timestamp": "1768404530000", "received_at": "2026-01-14T16:28:49.671565"}}
{"event_type": "price_change", "event_ts": "2026-01-14T16:28:49.675575", "ingestion_ts": "2026-01-14T16:33:58.842229", "market_id": "0x50c669f178da4e5bbea7f1be25041fd278914712fa87a6a6f8e57d5923d88dee", "raw": {"market": "0x50c669f178da4e5bbea7f1be25041fd278914712fa87a6a6f8e57d5923d88dee", "asset_id": "74040420326294854165772767082819937451857852955603897473157746262672057685461", "price": "0.001", "size": "6161.89", "side": "BUY", "timestamp": "1768404530000", "received_at": "2026-01-14T16:28:49.675575"}}
{"event_type": "price_change", "event_ts": "2026-01-14T16:28:49.675575", "ingestion_ts": "2026-01-14T16:33:58.842229", "market_id": "0x50c669f178da4e5bbea7f1be25041fd278914712fa87a6a6f8e57d5923d88dee", "raw": {"market": "0x50c669f178da4e5bbea7f1be25041fd278914712fa87a6a6f8e57d5923d88dee", "asset_id": "24682525479474221428144937281315825971983904267399062415430320764754931667953", "price": "0.999", "size": "6161.89", "side": "SELL", "timestamp": "1768404530000", "received_at": "2026-01-14T16:28:49.675575"}}
{"event_type": "price_change", "event_ts": "2026-01-14T16:28:49.677166", "ingestion_ts": "2026-01-14T16:33:58.842229", "market_id": "0x49a20c7523c271099008f3ef9a31521263b24d637959852a391e6b4697b1a437", "raw": {"market": "0x49a20c7523c271099008f3ef9a31521263b24d637959852a391e6b4697b1a437", "asset_id": "55881023621710858558280545117465775643848233756850602339827152783696837905531", "price": "0.025", "size": "0", "side": "BUY", "timestamp": "1768404530000", "received_at": "2026-01-14T16:28:49.677166"}}
{"event_type": "price_change", "event_ts": "2026-01-14T16:28:49.677166", "ingestion_ts": "2026-01-14T16:33:58.842229", "market_id": "0x49a20c7523c271099008f3ef9a31521263b24d637959852a391e6b4697b1a437", "raw": {"market": "0x49a20c7523c271099008f3ef9a31521263b24d637959852a391e6b4697b1a437", "asset_id": "13018971792603393862521629014128024641178044618205296260525674415067194037856", "price": "0.975", "size": "0", "side": "SELL", "timestamp": "1768404530000", "received_at": "2026-01-14T16:28:49.677166"}}
{"event_type": "price_change", "event_ts": "2026-01-14T16:28:49.677207", "ingestion_ts": "2026-01-14T16:33:58.842229", "market_id": "0xc55db914f0fd1fee18997706712c0dfd8d0369cdbef93a9fef12bd001914ca77", "raw": {"market": "0xc55db914f0fd1fee18997706712c0dfd8d0369cdbef93a9fef12bd001914ca77", "asset_id": "114600293444080540179603459515770723592661967180480327891296353898330242622833", "price": "0.007", "size": "0", "side": "BUY", "timestamp": "1768404530001", "received_at": "2026-01-14T16:28:49.677207"}}
{"event_type": "price_change", "event_ts": "2026-01-14T16:28:49.677207", "ingestion_ts": "2026-01-14T16:33:58.842229", "market_id": "0xc55db914f0fd1fee18997706712c0dfd8d0369cdbef93a9fef12bd001914ca77", "raw": {"market": "0xc55db914f0fd1fee18997706712c0dfd8d0369cdbef93a9fef12bd001914ca77", "asset_id": "72354723612769247426741660426331235762851940382312402276325808095604519806766", "price": "0.993", "size": "0", "side": "SELL", "timestamp": "1768404530001", "received_at": "2026-01-14T16:28:49.677207"}}
{"event_type": "price_change", "event_ts": "2026-01-14T16:28:49.677229", "ingestion_ts": "2026-01-14T16:33:58.842229", "market_id": "0xb9bbdd34304344dcc45803780a34c97d73a00133a5ecf70f63e1008b8abb2fca", "raw": {"market": "0xb9bbdd34304344dcc45803780a34c97d73a00133a5ecf70f63e1008b8abb2fca", "asset_id": "8682484153073832526711485265636767086525069344085206423986003504588877767339", "price": "0.201", "size": "0", "side": "BUY", "timestamp": "1768404530001", "received_at": "2026-01-14T16:28:49.677229"}}
{"event_type": "price_change", "event_ts": "2026-01-14T16:28:49.677229", "ingestion_ts": "2026-01-14T16:33:58.842229", "market_id": "0xb9bbdd34304344dcc45803780a34c97d73a00133a5ecf70f63e1008b8abb2fca", "raw": {"market": "0xb9bbdd34304344dcc45803780a34c97d73a00133a5ecf70f63e1008b8abb2fca", "asset_id": "72012724360700510767037780555710363830014634797787940282136454146828040926557", "price": "0.799", "size": "0", "side": "SELL", "timestamp": "1768404530001", "received_at": "2026-01-14T16:28:49.677229"}}
{"event_type": "price_change", "event_ts": "2026-01-14T16:28:49.686929", "ingestion_ts": "2026-01-14T16:33:58.842229", "market_id": "0x50c669f178da4e5bbea7f1be25041fd278914712fa87a6a6f8e57d5923d88dee", "raw": {"market": "0x50c669f178da4e5bbea7f1be25041fd278914712fa87a6a6f8e57d5923d88dee", "asset_id": "74040420326294854165772767082819937451857852955603897473157746262672057685461", "price": "0.081", "size": "0", "side": "BUY", "timestamp": "1768404530001", "received_at": "2026-01-14T16:28:49.686929"}}
{"event_type": "price_change", "event_ts": "2026-01-14T16:28:49.686929", "ingestion_ts": "2026-01-14T16:33:58.842229", "market_id": "0x50c669f178da4e5bbea7f1be25041fd278914712fa87a6a6f8e57d5923d88dee", "raw": {"market": "0x50c669f178da4e5bbea7f1be25041fd278914712fa87a6a6f8e57d5923d88dee", "asset_id": "24682525479474221428144937281315825971983904267399062415430320764754931667953", "price": "0.919", "size": "0", "side": "SELL", "timestamp": "1768404530001", "received_at": "2026-01-14T16:28:49.686929"}}
{"event_type": "price_change", "event_ts": "2026-01-14T16:28:49.686978", "ingestion_ts": "2026-01-14T16:33:58.842229", "market_id": "0xc55db914f0fd1fee18997706712c0dfd8d0369cdbef93a9fef12bd001914ca77", "raw": {"market": "0xc55db914f0fd1fee18997706712c0dfd8d0369cdbef93a9fef12bd001914ca77", "asset_id": "114600293444080540179603459515770723592661967180480327891296353898330242622833", "price": "0.001", "size": "8569.51", "side": "BUY", "timestamp": "1768404530001", "received_at": "2026-01-14T16:28:49.686978"}}
{"event_type": "price_change", "event_ts": "2026-01-14T16:28:49.686978", "ingestion_ts": "2026-01-14T16:33:58.842229", "market_id": "0xc55db914f0fd1fee18997706712c0dfd8d0369cdbef93a9fef12bd001914ca77", "raw": {"market": "0xc55db914f0fd1fee18997706712c0dfd8d0369cdbef93a9fef12bd001914ca77", "asset_id": "72354723612769247426741660426331235762851940382312402276325808095604519806766", "price": "0.999", "size": "8569.51", "side": "SELL", "timestamp": "1768404530001", "received_at": "2026-01-14T16:28:49.686978"}}
{"event_type": "price_change", "event_ts": "2026-01-14T16:28:49.686997", "ingestion_ts": "2026-01-14T16:33:58.842229", "market_id": "0x49a20c7523c271099008f3ef9a31521263b24d637959852a391e6b4697b1a437", "raw": {"market": "0x49a20c7523c271099008f3ef9a31521263b24d637959852a391e6b4697b1a437", "asset_id": "55881023621710858558280545117465775643848233756850602339827152783696837905531", "price": "0.001", "size": "5664.41", "side": "BUY", "timestamp": "1768404530001", "received_at": "2026-01-14T16:28:49.686997"}}
{"event_type": "price_change", "event_ts": "2026-01-14T16:28:49.686997", "ingestion_ts": "2026-01-14T16:33:58.842229", "market_id": "0x49a20c7523c271099008f3ef9a31521263b24d637959852a391e6b4697b1a437", "raw": {"market": "0x49a20c7523c271099008f3ef9a31521263b24d637959852a391e6b4697b1a437", "asset_id": "13018971792603393862521629014128024641178044618205296260525674415067194037856", "price": "0.999", "size": "5664.41", "side": "SELL", "timestamp": "1768404530001", "received_at": "2026-01-14T16:28:49.686997"}}
{"event_type": "price_change", "event_ts": "2026-01-14T16:28:49.687011", "ingestion_ts": "2026-01-14T16:33:58.842229", "market_id": "0xb9bbdd34304344dcc45803780a34c97d73a00133a5ecf70f63e1008b8abb2fca", "raw": {"market": "0xb9bbdd34304344dcc45803780a34c97d73a00133a5ecf70f63e1008b8abb2fca", "asset_id": "8682484153073832526711485265636767086525069344085206423986003504588877767339", "price": "0.004", "size": "0", "side": "BUY", "timestamp": "1768404530001", "received_at": "2026-01-14T16:28:49.687011"}}
{"event_type": "price_change", "event_ts": "2026-01-14T16:28:49.687011", "ingestion_ts": "2026-01-14T16:33:58.842229", "market_id": "0xb9bbdd34304344dcc45803780a34c97d73a00133a5ecf70f63e1008b8abb2fca", "raw": {"market": "0xb9bbdd34304344dcc45803780a34c97d73a00133a5ecf70f63e1008b8abb2fca", "asset_id": "72012724360700510767037780555710363830014634797787940282136454146828040926557", "price": "0.996", "size": "0", "side": "SELL", "timestamp": "1768404530001", "received_at": "2026-01-14T16:28:49.687011"}}
{"event_type": "price_change", "event_ts": "2026-01-14T16:28:49.687023", "ingestion_ts": "2026-01-14T16:33:58.842229", "market_id": "0x49a20c7523c271099008f3ef9a31521263b24d637959852a391e6b4697b1a437", "raw": {"market": "0x49a20c7523c271099008f3ef9a31521263b24d637959852a391e6b4697b1a437", "asset_id": "55881023621710858558280545117465775643848233756850602339827152783696837905531", "price": "0.201", "size": "0", "side": "BUY", "timestamp": "1768404530002", "received_at": "2026-01-14T16:28:49.687023"}}
{"event_type": "price_change", "event_ts": "2026-01-14T16:28:49.687023", "ingestion_ts": "2026-01-14T16:33:58.842229", "market_id": "0x49a20c7523c271099008f3ef9a31521263b24d637959852a391e6b4697b1a437", "raw": {"market": "0x49a20c7523c271099008f3ef9a31521263b24d637959852a391e6b4697b1a437", "asset_id": "13018971792603393862521629014128024641178044618205296260525674415067194037856", "price": "0.799", "size": "0", "side": "SELL", "timestamp": "1768404530002", "received_at": "2026-01-14T16:28:49.687023"}}
{"event_type": "price_change", "event_ts": "2026-01-14T16:28:49.688441", "ingestion_ts": "2026-01-14T16:33:58.842229", "market_id": "0xb9bbdd34304344dcc45803780a34c97d73a00133a5ecf70f63e1008b8abb2fca", "raw": {"market": "0xb9bbdd34304344dcc45803780a34c97d73a00133a5ecf70f63e1008b8abb2fca", "asset_id": "8682484153073832526711485265636767086525069344085206423986003504588877767339", "price": "0.021", "size": "0", "side": "BUY", "timestamp": "1768404530002", "received_at": "2026-01-14T16:28:49.688441"}}
{"event_type": "price_change", "event_ts": "2026-01-14T16:28:49.688441", "ingestion_ts": "2026-01-14T16:33:58.842229", "market_id": "0xb9bbdd34304344dcc45803780a34c97d73a00133a5ecf70f63e1008b8abb2fca", "raw": {"market": "0xb9bbdd34304344dcc45803780a34c97d73a00133a5ecf70f63e1008b8abb2fca", "asset_id": "72012724360700510767037780555710363830014634797787940282136454146828040926557", "price": "0.979", "size": "0", "side": "SELL", "timestamp": "1768404530002", "received_at": "2026-01-14T16:28:49.688441"}}
{"event_type": "price_change", "event_ts": "2026-01-14T16:28:49.688461", "ingestion_ts": "2026-01-14T16:33:58.842229", "market_id": "0x50c669f178da4e5bbea7f1be25041fd278914712fa87a6a6f8e57d5923d88dee", "raw": {"market": "0x50c669f178da4e5bbea7f1be25041fd278914712fa87a6a6f8e57d5923d88dee", "asset_id": "74040420326294854165772767082819937451857852955603897473157746262672057685461", "price": "0.002", "size": "0", "side": "BUY", "timestamp": "1768404530002", "received_at": "2026-01-14T16:28:49.688461"}}
{"event_type": "price_change", "event_ts": "2026-01-14T16:28:49.688461", "ingestion_ts": "2026-01-14T16:33:58.842229", "market_id": "0x50c669f178da4e5bbea7f1be25041fd278914712fa87a6a6f8e57d5923d88dee", "raw": {"market": "0x50c669f178da4e5bbea7f1be25041fd278914712fa87a6a6f8e57d5923d88dee", "asset_id": "24682525479474221428144937281315825971983904267399062415430320764754931667953", "price": "0.998", "size": "0", "side": "SELL", "timestamp": "1768404530002", "received_at": "2026-01-14T16:28:49.688461"}}
{"event_type": "price_change", "event_ts": "2026-01-14T16:28:49.688471", "ingestion_ts": "2026-01-14T16:33:58.842229", "market_id": "0xc55db914f0fd1fee18997706712c0dfd8d0369cdbef93a9fef12bd001914ca77", "raw": {"market": "0xc55db914f0fd1fee18997706712c0dfd8d0369cdbef93a9fef12bd001914ca77", "asset_id": "114600293444080540179603459515770723592661967180480327891296353898330242622833", "price": "0.021", "size": "0", "side": "BUY", "timestamp": "1768404530002", "received_at": "2026-01-14T16:28:49.688471"}}
{"event_type": "price_change", "event_ts": "2026-01-14T16:28:49.688471", "ingestion_ts": "2026-01-14T16:33:58.842229", "market_id": "0xc55db914f0fd1fee18997706712c0dfd8d0369cdbef93a9fef12bd001914ca77", "raw": {"market": "0xc55db914f0fd1fee18997706712c0dfd8d0369cdbef93a9fef12bd001914ca77", "asset_id": "72354723612769247426741660426331235762851940382312402276325808095604519806766", "price": "0.979", "size": "0", "side": "SELL", "timestamp": "1768404530002", "received_at": "2026-01-14T16:28:49.688471"}}
