{"event_type": "price_change", "event_ts": "2026-01-14T16:30:24.405765", "ingestion_ts": "2026-01-14T16:33:58.842229", "market_id": "0x9472be65457510b7fc3477b20ba90910e99d92eac8421a14bf4b7b7a08ef31dc", "raw": {"market": "0x9472be65457510b7fc3477b20ba90910e99d92eac8421a14bf4b7b7a08ef31dc", "asset_id": "73414222381656326204771753454630063673548497164758947581648273905027617570612", "price": "0.999", "size": "7293.15", "side": "SELL", "timestamp": "1768404624646", "received_at": "2026-01-14T16:30:24.405765"}}
{"event_type": "price_change", "event_ts": "2026-01-14T16:30:24.405796", "ingestion_ts": "2026-01-14T16:33:58.842229", "market_id": "0x9472be65457510b7fc3477b20ba90910e99d92eac8421a14bf4b7b7a08ef31dc", "raw": {"market": "0x9472be65457510b7fc3477b20ba90910e99d92eac8421a14bf4b7b7a08ef31dc", "asset_id": "43311793366960417907757893276427136943959788721376762326430771171648759300146", "price": "0.011", "size": "12.31", "side": "BUY", "timestamp": "1768404624647", "received_at": "2026-01-14T16:30:24.405796"}}
{"event_type": "price_change", "event_ts": "2026-01-14T16:30:24.405796", "ingestion_ts": "2026-01-14T16:33:58.842229", "market_id": "0x9472be65457510b7fc3477b20ba90910e99d92eac8421a14bf4b7b7a08ef31dc", "raw": {"market": "0x9472be65457510b7fc3477b20ba90910e99d92eac8421a14bf4b7b7a08ef31dc", "asset_id": "73414222381656326204771753454630063673548497164758947581648273905027617570612", "price": "0.989", "size": "12.31", "side": "SELL", "timestamp": "1768404624647", "received_at": "2026-01-14T16:30:24.405796"}}
{"event_type": "price_change", "event_ts": "2026-01-14T16:30:24.405813", "ingestion_ts": "2026-01-14T16:33:58.842229", "market_id": "0x9472be65457510b7fc3477b20ba90910e99d92eac8421a14bf4b7b7a08ef31dc", "raw": {"market": "0x9472be65457510b7fc3477b20ba90910e99d92eac8421a14bf4b7b7a08ef31dc", "asset_id": "43311793366960417907757893276427136943959788721376762326430771171648759300146", "price": "0.005", "size": "6.23", "side": "BUY", "timestamp": "1768404624648", "received_at": "2026-01-14T16:30:24.405813"}}
{"event_type": "price_change", "event_ts": "2026-01-14T16:30:24.405813", "ingestion_ts": "2026-01-14T16:33:58.842229", "market_id": "0x9472be65457510b7fc3477b20ba90910e99d92eac8421a14bf4b7b7a08ef31dc", "raw": {"market": "0x9472be65457510b7fc3477b20ba90910e99d92eac8421a14bf4b7b7a08ef31dc", "asset_id": "73414222381656326204771753454630063673548497164758947581648273905027617570612", "price": "0.995", "size": "6.23", "side": "SELL", "timestamp": "1768404624648", "received_at": "2026-01-14T16:30:24.405813"}}
{"event_type": "price_change", "event_ts": "2026-01-14T16:30:24.408042", "ingestion_ts": "2026-01-14T16:33:58.842229", "market_id": "0x9472be65457510b7fc3477b20ba90910e99d92eac8421a14bf4b7b7a08ef31dc", "raw": {"market": "0x9472be65457510b7fc3477b20ba90910e99d92eac8421a14bf4b7b7a08ef31dc", "asset_id": "43311793366960417907757893276427136943959788721376762326430771171648759300146", "price": "0.002", "size": "80.29", "side": "BUY", "timestamp": "1768404624649", "received_at": "2026-01-14T16:30:24.408042"}}
{"event_type": "price_change", "event_ts": "2026-01-14T16:30:24.408042", "ingestion_ts": "2026-01-14T16:33:58.842229", "market_id": "0x9472be65457510b7fc3477b20ba90910e99d92eac8421a14bf4b7b7a08ef31dc", "raw": {"market": "0x9472be65457510b7fc3477b20ba90910e99d92eac8421a14bf4b7b7a08ef31dc", "asset_id": "73414222381656326204771753454630063673548497164758947581648273905027617570612", "price": "0.998", "size": "80.29", "side": "SELL", "timestamp": "1768404624649", "received_at": "2026-01-14T16:30:24.408042"}}
{"event_type": "price_change", "event_ts": "2026-01-14T16:30:24.409627", "ingestion_ts": "2026-01-14T16:33:58.842229", "market_id": "0x9472be65457510b7fc3477b20ba90910e99d92eac8421a14bf4b7b7a08ef31dc", "raw": {"market": "0x9472be65457510b7fc3477b20ba90910e99d92eac8421a14bf4b7b7a08ef31dc", "asset_id": "43311793366960417907757893276427136943959788721376762326430771171648759300146", "price": "0.038", "size": "5.72", "side": "BUY", "timestamp": "1768404624650", "received_at": "2026-01-14T16:30:24.409627"}}
{"event_type": "price_change", "event_ts": "2026-01-14T16:30:24.409627", "ingestion_ts": "2026-01-14T16:33:58.842229", "market_id": "0x9472be65457510b7fc3477b20ba90910e99d92eac8421a14bf4b7b7a08ef31dc", "raw": {"market": "0x9472be65457510b7fc3477b20ba90910e99d92eac8421a14bf4b7b7a08ef31dc", "asset_id": "73414222381656326204771753454630063673548497164758947581648273905027617570612", "price": "0.962", "size": "5.72", "side": "SELL", "timestamp": "1768404624650", "received_at": "2026-01-14T16:30:24.409627"}}
{"event_type": "price_change", "event_ts": "2026-01-14T16:30:24.671448", "ingestion_ts": "2026-01-14T16:33:58.842229", "market_id": "0x49686d26fb712515cd5e12c23f0a1c7e10214c7faa3cb0a730aabe0c33694082", "raw": {"market": "0x49686d26fb712515cd5e12c23f0a1c7e10214c7faa3cb0a730aabe0c33694082", "asset_id": "30442780799048074404860985387051749017905070253466005720364298335239299761065", "price": "0.017", "size": "0", "side": "BUY", "timestamp": "1768404625001", "received_at": "2026-01-14T16:30:24.671448"}}
{"event_type": "price_change", "event_ts": "2026-01-14T16:30:24.671448", "ingestion_ts": "2026-01-14T16:33:58.842229", "market_id": "0x49686d26fb712515cd5e12c23f0a1c7e10214c7faa3cb0a730aabe0c33694082", "raw": {"market": "0x49686d26fb712515cd5e12c23f0a1c7e10214c7faa3cb0a730aabe0c33694082", "asset_id": "13244681086321087932946246027856416106585284024824496763706748621681543444582", "price": "0.983", "size": "0", "side": "SELL", "timestamp": "1768404625001", "received_at": "2026-01-14T16:30:24.671448"}}
{"event_type": "price_change", "event_ts": "2026-01-14T16:30:24.671507", "ingestion_ts": "2026-01-14T16:33:58.842229", "market_id": "0x49686d26fb712515cd5e12c23f0a1c7e10214c7faa3cb0a730aabe0c33694082", "raw": {"market": "0x49686d26fb712515cd5e12c23f0a1c7e10214c7faa3cb0a730aabe0c33694082", "asset_id": "30442780799048074404860985387051749017905070253466005720364298335239299761065", "price": "0.022", "size": "0", "side": "BUY", "timestamp": "1768404625001", "received_at": "2026-01-14T16:30:24.671507"}}
{"event_type": "price_change", "event_ts": "2026-01-14T16:30:24.671507", "ingestion_ts": "2026-01-14T16:33:58.842229", "market_id": "0x49686d26fb712515cd5e12c23f0a1c7e10214c7faa3cb0a730aabe0c33694082", "raw": {"market": "0x49686d26fb712515cd5e12c23f0a1c7e10214c7faa3cb0a730aabe0c33694082", "asset_id": "13244681086321087932946246027856416106585284024824496763706748621681543444582", "price": "0.978", "size": "0", "side": "SELL", "timestamp": "1768404625001", "received_at": "2026-01-14T16:30:24.671507"}}
{"event_type": "price_change", "event_ts": "2026-01-14T16:30:24.671525", "ingestion_ts": "2026-01-14T16:33:58.842229", "market_id": "0x49686d26fb712515cd5e12c23f0a1c7e10214c7faa3cb0a730aabe0c33694082", "raw": {"market": "0x49686d26fb712515cd5e12c23f0a1c7e10214c7faa3cb0a730aabe0c33694082", "asset_id": "30442780799048074404860985387051749017905070253466005720364298335239299761065", "price": "0.041", "size": "0", "side": "BUY", "timestamp": "1768404625001", "received_at": "2026-01-14T16:30:24.671525"}}
{"event_type": "price_change", "event_ts": "2026-01-14T16:30:24.671525", "ingestion_ts": "2026-01-14T16:33:58.842229", "market_id": "0x49686d26fb712515cd5e12c23f0a1c7e10214c7faa3cb0a730aabe0c33694082", "raw": {"market": "0x49686d26fb712515cd5e12c23f0a1c7e10214c7faa3cb0a730aabe0c33694082", "asset_id": "13244681086321087932946246027856416106585284024824496763706748621681543444582", "price": "0.959", "size": "0", "side": "SELL", "timestamp": "1768404625001", "received_at": "2026-01-14T16:30:24.671525"}}
{"event_type": "price_change", "event_ts": "2026-01-14T16:30:24.671541", "ingestion_ts": "2026-01-14T16:33:58.842229", "market_id": "0x49686d26fb712515cd5e12c23f0a1c7e10214c7faa3cb0a730aabe0c33694082", "raw": {"market": "0x49686d26fb712515cd5e12c23f0a1c7e10214c7faa3cb0a730aabe0c33694082", "asset_id": "30442780799048074404860985387051749017905070253466005720364298335239299761065", "price": "0.061", "size": "0", "side": "BUY", "timestamp": "1768404625001", "received_at": "2026-01-14T16:30:24.671541"}}
{"event_type": "price_change", "event_ts": "2026-01-14T16:30:24.671541", "ingestion_ts": "2026-01-14T16:33:58.842229", "market_id": "0x49686d26fb712515cd5e12c23f0a1c7e10214c7faa3cb0a730aabe0c33694082", "raw": {"market": "0x49686d26fb712515cd5e12c23f0a1c7e10214c7faa3cb0a730aabe0c33694082", "asset_id": "13244681086321087932946246027856416106585284024824496763706748621681543444582", "price": "0.939", "size": "0", "side": "SELL", "timestamp": "1768404625001", "received_at": "2026-01-14T16:30:24.671541"}}
{"event_type": "price_change", "event_ts": "2026-01-14T16:30:24.671555", "ingestion_ts": "2026-01-14T16:33:58.842229", "market_id": "0x49686d26fb712515cd5e12c23f0a1c7e10214c7faa3cb0a730aabe0c33694082", "raw": {"market": "0x49686d26fb712515cd5e12c23f0a1c7e10214c7faa3cb0a730aabe0c33694082", "asset_id": "30442780799048074404860985387051749017905070253466005720364298335239299761065", "price": "0.084", "size": "0", "side": "BUY", "timestamp": "1768404625001", "received_at": "2026-01-14T16:30:24.671555"}}
{"event_type": "price_change", "event_ts": "2026-01-14T16:30:24.671555", "ingestion_ts": "2026-01-14T16:33:58.842229", "market_id": "0x49686d26fb712515cd5e12c23f0a1c7e10214c7faa3cb0a730aabe0c33694082", "raw": {"market": "0x49686d26fb712515cd5e12c23f0a1c7e10214c7faa3cb0a730aabe0c33694082", "asset_id": "13244681086321087932946246027856416106585284024824496763706748621681543444582", "price": "0.916", "size": "0", "side": "SELL", "timestamp": "1768404625001", "received_at": "2026-01-14T16:30:24.671555"}}
{"event_type": "price_change", "event_ts": "2026-01-14T16:30:24.671582", "ingestion_ts": "2026-01-14T16:33:58.842229", "market_id": "0x44f08744458b8896620cd3330bc5e1ea69df4199b02d4fc583b3fc96e5d314ce", "raw": {"market": "0x44f08744458b8896620cd3330bc5e1ea69df4199b02d4fc583b3fc96e5d314ce", "asset_id": "49194009556504828848509244326501559253829462790583873936160989575507522044057", "price": "0.002", "size": "3364.8", "side": "BUY", "timestamp": "1768404625001", "received_at": "2026-01-14T16:30:24.671582"}}
{"event_type": "price_change", "event_ts": "2026-01-14T16:30:24.671582", "ingestion_ts": "2026-01-14T16:33:58.842229", "market_id": "0x44f08744458b8896620cd3330bc5e1ea69df4199b02d4fc583b3fc96e5d314ce", "raw": {"market": "0x44f08744458b8896620cd3330bc5e1ea69df4199b02d4fc583b3fc96e5d314ce", "asset_id": "72327831507226612545928776794104143393438710920370371172884559893525100761096", "price": "0.998", "size": "3364.8", "side": "SELL", "timestamp": "1768404625001", "received_at": "2026-01-14T16:30:24.671582"}}
{"event_type": "price_change", "event_ts": "2026-01-14T16:30:24.672971", "ingestion_ts": "2026-01-14T16:33:58.842229", "market_id": "0x44f08744458b8896620cd3330bc5e1ea69df4199b02d4fc583b3fc96e5d314ce", "raw": {"market": "0x44f08744458b8896620cd3330bc5e1ea69df4199b02d4fc583b3fc96e5d314ce", "asset_id": "49194009556504828848509244326501559253829462790583873936160989575507522044057", "price": "0.006", "size": "0", "side": "BUY", "timestamp": "1768404625002", "received_at": "2026-01-14T16:30:24.672971"}}
{"event_type": "price_change", "event_ts": "2026-01-14T16:30:24.672971", "ingestion_ts": "2026-01-14T16:33:58.842229", "market_id": "0x44f08744458b8896620cd3330bc5e1ea69df4199b02d4fc583b3fc96e5d314ce", "raw": {"market": "0x44f08744458b8896620cd3330bc5e1ea69df4199b02d4fc583b3fc96e5d314ce", "asset_id": "72327831507226612545928776794104143393438710920370371172884559893525100761096", "price": "0.994", "size": "0", "side": "SELL", "timestamp": "1768404625002", "received_at": "2026-01-14T16:30:24.672971"}}
{"event_type": "price_change", "event_ts": "2026-01-14T16:30:24.673002", "ingestion_ts": "2026-01-14T16:33:58.842229", "market_id": "0x44f08744458b8896620cd3330bc5e1ea69df4199b02d4fc583b3fc96e5d314ce", "raw": {"market": "0x44f08744458b8896620cd3330bc5e1ea69df4199b02d4fc583b3fc96e5d314ce", "asset_id": "49194009556504828848509244326501559253829462790583873936160989575507522044057", "price": "0.005", "size": "1462.79", "side": "BUY", "timestamp": "1768404625002", "received_at": "2026-01-14T16:30:24.673002"}}
{"event_type": "price_change", "event_ts": "2026-01-14T16:30:24.673002", "ingestion_ts": "2026-01-14T16:33:58.842229", "market_id": "0x44f08744458b8896620cd3330bc5e1ea69df4199b02d4fc583b3fc96e5d314ce", "raw": {"market": "0x44f08744458b8896620cd3330bc5e1ea69df4199b02d4fc583b3fc96e5d314ce", "asset_id": "72327831507226612545928776794104143393438710920370371172884559893525100761096", "price": "0.995", "size": "1462.79", "side": "SELL", "timestamp": "1768404625002", "received_at": "2026-01-14T16:30:24.673002"}}
{"event_type": "price_change", "event_ts": "2026-01-14T16:30:24.677128", "ingestion_ts": "2026-01-14T16:33:58.842229", "market_id": "0x44f08744458b8896620cd3330bc5e1ea69df4199b02d4fc583b3fc96e5d314ce", "raw": {"market": "0x44f08744458b8896620cd3330bc5e1ea69df4199b02d4fc583b3fc96e5d314ce", "asset_id": "49194009556504828848509244326501559253829462790583873936160989575507522044057", "price": "0.004", "size": "219.79", "side": "BUY", "timestamp": "1768404625002", "received_at": "2026-01-14T16:30:24.677128"}}
{"event_type": "price_change", "event_ts": "2026-01-14T16:30:24.677128", "ingestion_ts": "2026-01-14T16:33:58.842229", "market_id": "0x44f08744458b8896620cd3330bc5e1ea69df4199b02d4fc583b3fc96e5d314ce", "raw": {"market": "0x44f08744458b8896620cd3330bc5e1ea69df4199b02d4fc583b3fc96e5d314ce", "asset_id": "72327831507226612545928776794104143393438710920370371172884559893525100761096", "price": "0.996", "size": "219.79", "side": "SELL", "timestamp": "1768404625002", "received_at": "2026-01-14T16:30:24.677128"}}
{"event_type": "price_change", "event_ts": "2026-01-14T16:30:24.677154", "ingestion_ts": "2026-01-14T16:33:58.842229", "market_id": "0x44f08744458b8896620cd3330bc5e1ea69df4199b02d4fc583b3fc96e5d314ce", "raw": {"market": "0x44f08744458b8896620cd3330bc5e1ea69df4199b02d4fc583b3fc96e5d314ce", "asset_id": "49194009556504828848509244326501559253829462790583873936160989575507522044057", "price": "0.003", "size": "1111.17", "side": "BUY", "timestamp": "1768404625003", "received_at": "2026-01-14T16:30:24.677154"}}
{"event_type": "price_change", "event_ts": "2026-01-14T16:30:24.677154", "ingestion_ts": "2026-01-14T16:33:58.842229", "market_id": "0x44f08744458b8896620cd3330bc5e1ea69df4199b02d4fc583b3fc96e5d314ce", "raw": {"market": "0x44f08744458b8896620cd3330bc5e1ea69df4199b02d4fc583b3fc96e5d314ce", "asset_id": "72327831507226612545928776794104143393438710920370371172884559893525100761096", "price": "0.997", "size": "1111.17", "side": "SELL", "timestamp": "1768404625003", "received_at": "2026-01-14T16:30:24.677154"}}
{"event_type": "price_change", "event_ts": "2026-01-14T16:30:24.725131", "ingestion_ts": "2026-01-14T16:33:58.842229", "market_id": "0x49686d26fb712515cd5e12c23f0a1c7e10214c7faa3cb0a730aabe0c33694082", "raw": {"market": "0x49686d26fb712515cd5e12c23f0a1c7e10214c7faa3cb0a730aabe0c33694082", "asset_id": "13244681086321087932946246027856416106585284024824496763706748621681543444582", "price": "0.899", "size": "16", "side": "SELL", "timestamp": "1768404625050", "received_at": "2026-01-14T16:30:24.725131"}}
{"event_type": "price_change", "event_ts": "2026-01-14T16:30:24.725131", "ingestion_ts": "2026-01-14T16:33:58.842229", "market_id": "0x49686d26fb712515cd5e12c23f0a1c7e10214c7faa3cb0a730aabe0c33694082", "raw": {"market": "0x49686d26fb712515cd5e12c23f0a1c7e10214c7faa3cb0a730aabe0c33694082", "asset_id": "30442780799048074404860985387051749017905070253466005720364298335239299761065", "price": "0.101", "size": "16", "side": "BUY", "timestamp": "1768404625050", "received_at": "2026-01-14T16:30:24.725131"}}
{"event_type": "price_change", "event_ts": "2026-01-14T16:30:24.739278", "ingestion_ts": "2026-01-14T16:33:58.842229", "market_id": "0x49686d26fb712515cd5e12c23f0a1c7e10214c7faa3cb0a730aabe0c33694082", "raw": {"market": "0x49686d26fb712515cd5e12c23f0a1c7e10214c7faa3cb0a730aabe0c33694082", "asset_id": "13244681086321087932946246027856416106585284024824496763706748621681543444582", "price": "0.907", "size": "131", "side": "SELL", "timestamp": "1768404625078", "received_at": "2026-01-14T16:30:24.739278"}}
{"event_type": "price_change", "event_ts": "2026-01-14T16:30:24.739278", "ingestion_ts": "2026-01-14T16:33:58.842229", "market_id": "0x49686d26fb712515cd5e12c23f0a1c7e10214c7faa3cb0a730aabe0c33694082", "raw": {"market": "0x49686d26fb712515cd5e12c23f0a1c7e10214c7faa3cb0a730aabe0c33694082", "asset_id": "30442780799048074404860985387051749017905070253466005720364298335239299761065", "price": "0.093", "size": "131", "side": "BUY", "timestamp": "1768404625078", "received_at": "2026-01-14T16:30:24.739278"}}
{"event_type": "price_change", "event_ts": "2026-01-14T16:30:24.807985", "ingestion_ts": "2026-01-14T16:33:58.842229", "market_id": "0xc55db914f0fd1fee18997706712c0dfd8d0369cdbef93a9fef12bd001914ca77", "raw": {"market": "0xc55db914f0fd1fee18997706712c0dfd8d0369cdbef93a9fef12bd001914ca77", "asset_id": "114600293444080540179603459515770723592661967180480327891296353898330242622833", "price": "0.925", "size": "0", "side": "BUY", "timestamp": "1768404625144", "received_at": "2026-01-14T16:30:24.807985"}}
{"event_type": "price_change", "event_ts": "2026-01-14T16:30:24.807985", "ingestion_ts": "2026-01-14T16:33:58.842229", "market_id": "0xc55db914f0fd1fee18997706712c0dfd8d0369cdbef93a9fef12bd001914ca77", "raw": {"market": "0xc55db914f0fd1fee18997706712c0dfd8d0369cdbef93a9fef12bd001914ca77", "asset_id": "72354723612769247426741660426331235762851940382312402276325808095604519806766", "price": "0.075", "size": "0", "side": "SELL", "timestamp": "1768404625144", "received_at": "2026-01-14T16:30:24.807985"}}
{"event_type": "price_change", "event_ts": "2026-01-14T16:30:24.809618", "ingestion_ts": "2026-01-14T16:33:58.842229", "market_id": "0x50c669f178da4e5bbea7f1be25041fd278914712fa87a6a6f8e57d5923d88dee", "raw": {"market": "0x50c669f178da4e5bbea7f1be25041fd278914712fa87a6a6f8e57d5923d88dee", "asset_id": "74040420326294854165772767082819937451857852955603897473157746262672057685461", "price": "0.925", "size": "0", "side": "BUY", "timestamp": "1768404625144", "received_at": "2026-01-14T16:30:24.809618"}}
{"event_type": "price_change", "event_ts": "2026-01-14T16:30:24.809618", "ingestion_ts": "2026-01-14T16:33:58.842229", "market_id": "0x50c669f178da4e5bbea7f1be25041fd278914712fa87a6a6f8e57d5923d88dee", "raw": {"market": "0x50c669f178da4e5bbea7f1be25041fd278914712fa87a6a6f8e57d5923d88dee", "asset_id": "24682525479474221428144937281315825971983904267399062415430320764754931667953", "price": "0.075", "size": "0", "side": "SELL", "timestamp": "1768404625144", "received_at": "2026-01-14T16:30:24.809618"}}
{"event_type": "price_change", "event_ts": "2026-01-14T16:30:24.809642", "ingestion_ts": "2026-01-14T16:33:58.842229", "market_id": "0x9472be65457510b7fc3477b20ba90910e99d92eac8421a14bf4b7b7a08ef31dc", "raw": {"market": "0x9472be65457510b7fc3477b20ba90910e99d92eac8421a14bf4b7b7a08ef31dc", "asset_id": "43311793366960417907757893276427136943959788721376762326430771171648759300146", "price": "0.926", "size": "0", "side": "BUY", "timestamp": "1768404625144", "received_at": "2026-01-14T16:30:24.809642"}}
{"event_type": "price_change", "event_ts": "2026-01-14T16:30:24.809642", "ingestion_ts": "2026-01-14T16:33:58.842229", "market_id": "0x9472be65457510b7fc3477b20ba90910e99d92eac8421a14bf4b7b7a08ef31dc", "raw": {"market": "0x9472be65457510b7fc3477b20ba90910e99d92eac8421a14bf4b7b7a08ef31dc", "asset_id": "73414222381656326204771753454630063673548497164758947581648273905027617570612", "price": "0.074", "size": "0", "side": "SELL", "timestamp": "1768404625144", "received_at": "2026-01-14T16:30:24.809642"}}
{"event_type": "price_change", "event_ts": "2026-01-14T16:30:25.515444", "ingestion_ts": "2026-01-14T16:33:58.842229", "market_id": "0x22ac5f75af18fdb453497fbf7ac0606a09a6fd55b78b2d08aace6b946ad62038", "raw": {"market": "0x22ac5f75af18fdb453497fbf7ac0606a09a6fd55b78b2d08aace6b946ad62038", "asset_id": "59259495934562596318644973716893809974860301509869285036503555129962149752635", "price": "0.224", "size": "0", "side": "BUY", "timestamp": "1768404625850", "received_at": "2026-01-14T16:30:25.515444"}}
{"event_type": "price_change", "event_ts": "2026-01-14T16:30:25.515444", "ingestion_ts": "2026-01-14T16:33:58.842229", "market_id": "0x22ac5f75af18fdb453497fbf7ac0606a09a6fd55b78b2d08aace6b946ad62038", "raw": {"market": "0x22ac5f75af18fdb453497fbf7ac0606a09a6fd55b78b2d08aace6b946ad62038", "asset_id": "97449340182256366014320155718265676486703217567849039806162053075113517266910", "price": "0.776", "size": "0", "side": "SELL", "timestamp": "1768404625850", "received_at": "2026-01-14T16:30:25.515444"}}
{"event_type": "price_change", "event_ts": "2026-01-14T16:30:25.694874", "ingestion_ts": "2026-01-14T16:33:58.842229", "market_id": "0x22ac5f75af18fdb453497fbf7ac0606a09a6fd55b78b2d08aace6b946ad62038", "raw": {"market": "0x22ac5f75af18fdb453497fbf7ac0606a09a6fd55b78b2d08aace6b946ad62038", "asset_id": "59259495934562596318644973716893809974860301509869285036503555129962149752635", "price": "0.224", "size": "6208", "side": "BUY", "timestamp": "1768404626031", "received_at": "2026-01-14T16:30:25.694874"}}
{"event_type": "price_change", "event_ts": "2026-01-14T16:30:25.694874", "ingestion_ts": "2026-01-14T16:33:58.842229", "market_id": "0x22ac5f75af18fdb453497fbf7ac0606a09a6fd55b78b2d08aace6b946ad62038", "raw": {"market": "0x22ac5f75af18fdb453497fbf7ac0606a09a6fd55b78b2d08aace6b946ad62038", "asset_id": "97449340182256366014320155718265676486703217567849039806162053075113517266910", "price": "0.776", "size": "6208", "side": "SELL", "timestamp": "1768404626031", "received_at": "2026-01-14T16:30:25.694874"}}
{"event_type": "price_change", "event_ts": "2026-01-14T16:30:26.203879", "ingestion_ts": "2026-01-14T16:33:58.842229", "market_id": "0x49686d26fb712515cd5e12c23f0a1c7e10214c7faa3cb0a730aabe0c33694082", "raw": {"market": "0x49686d26fb712515cd5e12c23f0a1c7e10214c7faa3cb0a730aabe0c33694082", "asset_id": "30442780799048074404860985387051749017905070253466005720364298335239299761065", "price": "0.016", "size": "5.83", "side": "BUY", "timestamp": "1768404626482", "received_at": "2026-01-14T16:30:26.203879"}}
{"event_type": "price_change", "event_ts": "2026-01-14T16:30:26.203879", "ingestion_ts": "2026-01-14T16:33:58.842229", "market_id": "0x49686d26fb712515cd5e12c23f0a1c7e10214c7faa3cb0a730aabe0c33694082", "raw": {"market": "0x49686d26fb712515cd5e12c23f0a1c7e10214c7faa3cb0a730aabe0c33694082", "asset_id": "13244681086321087932946246027856416106585284024824496763706748621681543444582", "price": "0.984", "size": "5.83", "side": "SELL", "timestamp": "1768404626482", "received_at": "2026-01-14T16:30:26.203879"}}
{"event_type": "price_change", "event_ts": "2026-01-14T16:30:26.203939", "ingestion_ts": "2026-01-14T16:33:58.842229", "market_id": "0x49686d26fb712515cd5e12c23f0a1c7e10214c7faa3cb0a730aabe0c33694082", "raw": {"market": "0x49686d26fb712515cd5e12c23f0a1c7e10214c7faa3cb0a730aabe0c33694082", "asset_id": "30442780799048074404860985387051749017905070253466005720364298335239299761065", "price": "0.008", "size": "7.14", "side": "BUY", "timestamp": "1768404626483", "received_at": "2026-01-14T16:30:26.203939"}}
{"event_type": "price_change", "event_ts": "2026-01-14T16:30:26.203939", "ingestion_ts": "2026-01-14T16:33:58.842229", "market_id": "0x49686d26fb712515cd5e12c23f0a1c7e10214c7faa3cb0a730aabe0c33694082", "raw": {"market": "0x49686d26fb712515cd5e12c23f0a1c7e10214c7faa3cb0a730aabe0c33694082", "asset_id": "13244681086321087932946246027856416106585284024824496763706748621681543444582", "price": "0.992", "size": "7.14", "side": "SELL", "timestamp": "1768404626483", "received_at": "2026-01-14T16:30:26.203939"}}
{"event_type": "price_change", "event_ts": "2026-01-14T16:30:26.203954", "ingestion_ts": "2026-01-14T16:33:58.842229", "market_id": "0x49686d26fb712515cd5e12c23f0a1c7e10214c7faa3cb0a730aabe0c33694082", "raw": {"market": "0x49686d26fb712515cd5e12c23f0a1c7e10214c7faa3cb0a730aabe0c33694082", "asset_id": "30442780799048074404860985387051749017905070253466005720364298335239299761065", "price": "0.002", "size": "1359.67", "side": "BUY", "timestamp": "1768404626484", "received_at": "2026-01-14T16:30:26.203954"}}
{"event_type": "price_change", "event_ts": "2026-01-14T16:30:26.203954", "ingestion_ts": "2026-01-14T16:33:58.842229", "market_id": "0x49686d26fb712515cd5e12c23f0a1c7e10214c7faa3cb0a730aabe0c33694082", "raw": {"market": "0x49686d26fb712515cd5e12c23f0a1c7e10214c7faa3cb0a730aabe0c33694082", "asset_id": "13244681086321087932946246027856416106585284024824496763706748621681543444582", "price": "0.998", "size": "1359.67", "side": "SELL", "timestamp": "1768404626484", "received_at": "2026-01-14T16:30:26.203954"}}
{"event_type": "price_change", "event_ts": "2026-01-14T16:30:26.203973", "ingestion_ts": "2026-01-14T16:33:58.842229", "market_id": "0x49686d26fb712515cd5e12c23f0a1c7e10214c7faa3cb0a730aabe0c33694082", "raw": {"market": "0x49686d26fb712515cd5e12c23f0a1c7e10214c7faa3cb0a730aabe0c33694082", "asset_id": "30442780799048074404860985387051749017905070253466005720364298335239299761065", "price": "0.09", "size": "5.14", "side": "BUY", "timestamp": "1768404626485", "received_at": "2026-01-14T16:30:26.203973"}}
{"event_type": "price_change", "event_ts": "2026-01-14T16:30:26.203973", "ingestion_ts": "2026-01-14T16:33:58.842229", "market_id": "0x49686d26fb712515cd5e12c23f0a1c7e10214c7faa3cb0a730aabe0c33694082", "raw": {"market": "0x49686d26fb712515cd5e12c23f0a1c7e10214c7faa3cb0a730aabe0c33694082", "asset_id": "13244681086321087932946246027856416106585284024824496763706748621681543444582", "price": "0.91", "size": "5.14", "side": "SELL", "timestamp": "1768404626485", "received_at": "2026-01-14T16:30:26.203973"}}
{"event_type": "price_change", "event_ts": "2026-01-14T16:30:26.214348", "ingestion_ts": "2026-01-14T16:33:58.842229", "market_id": "0x49686d26fb712515cd5e12c23f0a1c7e10214c7faa3cb0a730aabe0c33694082", "raw": {"market": "0x49686d26fb712515cd5e12c23f0a1c7e10214c7faa3cb0a730aabe0c33694082", "asset_id": "30442780799048074404860985387051749017905070253466005720364298335239299761065", "price": "0.039", "size": "9.39", "side": "BUY", "timestamp": "1768404626486", "received_at": "2026-01-14T16:30:26.214348"}}
{"event_type": "price_change", "event_ts": "2026-01-14T16:30:26.214348", "ingestion_ts": "2026-01-14T16:33:58.842229", "market_id": "0x49686d26fb712515cd5e12c23f0a1c7e10214c7faa3cb0a730aabe0c33694082", "raw": {"market": "0x49686d26fb712515cd5e12c23f0a1c7e10214c7faa3cb0a730aabe0c33694082", "asset_id": "13244681086321087932946246027856416106585284024824496763706748621681543444582", "price": "0.961", "size": "9.39", "side": "SELL", "timestamp": "1768404626486", "received_at": "2026-01-14T16:30:26.214348"}}
{"event_type": "price_change", "event_ts": "2026-01-14T16:30:26.214379", "ingestion_ts": "2026-01-14T16:33:58.842229", "market_id": "0x49686d26fb712515cd5e12c23f0a1c7e10214c7faa3cb0a730aabe0c33694082", "raw": {"market": "0x49686d26fb712515cd5e12c23f0a1c7e10214c7faa3cb0a730aabe0c33694082", "asset_id": "30442780799048074404860985387051749017905070253466005720364298335239299761065", "price": "0.021", "size": "15.6", "side": "BUY", "timestamp": "1768404626487", "received_at": "2026-01-14T16:30:26.214379"}}
{"event_type": "price_change", "event_ts": "2026-01-14T16:30:26.214379", "ingestion_ts": "2026-01-14T16:33:58.842229", "market_id": "0x49686d26fb712515cd5e12c23f0a1c7e10214c7faa3cb0a730aabe0c33694082", "raw": {"market": "0x49686d26fb712515cd5e12c23f0a1c7e10214c7faa3cb0a730aabe0c33694082", "asset_id": "13244681086321087932946246027856416106585284024824496763706748621681543444582", "price": "0.979", "size": "15.6", "side": "SELL", "timestamp": "1768404626487", "received_at": "2026-01-14T16:30:26.214379"}}
{"event_type": "price_change", "event_ts": "2026-01-14T16:30:26.214399", "ingestion_ts": "2026-01-14T16:33:58.842229", "market_id": "0x49686d26fb712515cd5e12c23f0a1c7e10214c7faa3cb0a730aabe0c33694082", "raw": {"market": "0x49686d26fb712515cd5e12c23f0a1c7e10214c7faa3cb0a730aabe0c33694082", "asset_id": "30442780799048074404860985387051749017905070253466005720364298335239299761065", "price": "0.003", "size": "19.26", "side": "BUY", "timestamp": "1768404626488", "received_at": "2026-01-14T16:30:26.214399"}}
{"event_type": "price_change", "event_ts": "2026-01-14T16:30:26.214399", "ingestion_ts": "2026-01-14T16:33:58.842229", "market_id": "0x49686d26fb712515cd5e12c23f0a1c7e10214c7faa3cb0a730aabe0c33694082", "raw": {"market": "0x49686d26fb712515cd5e12c23f0a1c7e10214c7faa3cb0a730aabe0c33694082", "asset_id": "13244681086321087932946246027856416106585284024824496763706748621681543444582", "price": "0.997", "size": "19.26", "side": "SELL", "timestamp": "1768404626488", "received_at": "2026-01-14T16:30:26.214399"}}
{"event_type": "price_change", "event_ts": "2026-01-14T16:30:26.216437", "ingestion_ts": "2026-01-14T16:33:58.842229", "market_id": "0x49686d26fb712515cd5e12c23f0a1c7e10214c7faa3cb0a730aabe0c33694082", "raw": {"market": "0x49686d26fb712515cd5e12c23f0a1c7e10214c7faa3cb0a730aabe0c33694082", "asset_id": "30442780799048074404860985387051749017905070253466005720364298335239299761065", "price": "0.06", "size": "8.24", "side": "BUY", "timestamp": "1768404626489", "received_at": "2026-01-14T16:30:26.216437"}}
{"event_type": "price_change", "event_ts": "2026-01-14T16:30:26.216437", "ingestion_ts": "2026-01-14T16:33:58.842229", "market_id": "0x49686d26fb712515cd5e12c23f0a1c7e10214c7faa3cb0a730aabe0c33694082", "raw": {"market": "0x49686d26fb712515cd5e12c23f0a1c7e10214c7faa3cb0a730aabe0c33694082", "asset_id": "13244681086321087932946246027856416106585284024824496763706748621681543444582", "price": "0.94", "size": "8.24", "side": "SELL", "timestamp": "1768404626489", "received_at": "2026-01-14T16:30:26.216437"}}
{"event_type": "price_change", "event_ts": "2026-01-14T16:30:26.216463", "ingestion_ts": "2026-01-14T16:33:58.842229", "market_id": "0x49686d26fb712515cd5e12c23f0a1c7e10214c7faa3cb0a730aabe0c33694082", "raw": {"market": "0x49686d26fb712515cd5e12c23f0a1c7e10214c7faa3cb0a730aabe0c33694082", "asset_id": "30442780799048074404860985387051749017905070253466005720364298335239299761065", "price": "0.006", "size": "6.38", "side": "BUY", "timestamp": "1768404626490", "received_at": "2026-01-14T16:30:26.216463"}}
{"event_type": "price_change", "event_ts": "2026-01-14T16:30:26.216463", "ingestion_ts": "2026-01-14T16:33:58.842229", "market_id": "0x49686d26fb712515cd5e12c23f0a1c7e10214c7faa3cb0a730aabe0c33694082", "raw": {"market": "0x49686d26fb712515cd5e12c23f0a1c7e10214c7faa3cb0a730aabe0c33694082", "asset_id": "13244681086321087932946246027856416106585284024824496763706748621681543444582", "price": "0.994", "size": "6.38", "side": "SELL", "timestamp": "1768404626490", "received_at": "2026-01-14T16:30:26.216463"}}
{"event_type": "price_change", "event_ts": "2026-01-14T16:30:26.346934", "ingestion_ts": "2026-01-14T16:33:58.842229", "market_id": "0xaf9d0e448129a9f657f851d49495ba4742055d80e0ef1166ba0ee81d4d594214", "raw": {"market": "0xaf9d0e448129a9f657f851d49495ba4742055d80e0ef1166ba0ee81d4d594214", "asset_id": "4153292802911610701832309484716814274802943278345248636922528170020319407796", "price": "0.101", "size": "100", "side": "BUY", "timestamp": "1768404626635", "received_at": "2026-01-14T16:30:26.346934"}}
{"event_type": "price_change", "event_ts": "2026-01-14T16:30:26.346934", "ingestion_ts": "2026-01-14T16:33:58.842229", "market_id": "0xaf9d0e448129a9f657f851d49495ba4742055d80e0ef1166ba0ee81d4d594214", "raw": {"market": "0xaf9d0e448129a9f657f851d49495ba4742055d80e0ef1166ba0ee81d4d594214", "asset_id": "101676997363687199724245607342877036148401850938023978421879460310389391082353", "price": "0.899", "size": "100", "side": "SELL", "timestamp": "1768404626635", "received_at": "2026-01-14T16:30:26.346934"}}
{"event_type": "price_change", "event_ts": "2026-01-14T16:30:26.467894", "ingestion_ts": "2026-01-14T16:33:58.842229", "market_id": "0xaf9d0e448129a9f657f851d49495ba4742055d80e0ef1166ba0ee81d4d594214", "raw": {"market": "0xaf9d0e448129a9f657f851d49495ba4742055d80e0ef1166ba0ee81d4d594214", "asset_id": "4153292802911610701832309484716814274802943278345248636922528170020319407796", "price": "0.201", "size": "8074.66", "side": "BUY", "timestamp": "1768404626797", "received_at": "2026-01-14T16:30:26.467894"}}
{"event_type": "price_change", "event_ts": "2026-01-14T16:30:26.467894", "ingestion_ts": "2026-01-14T16:33:58.842229", "market_id": "0xaf9d0e448129a9f657f851d49495ba4742055d80e0ef1166ba0ee81d4d594214", "raw": {"market": "0xaf9d0e448129a9f657f851d49495ba4742055d80e0ef1166ba0ee81d4d594214", "asset_id": "101676997363687199724245607342877036148401850938023978421879460310389391082353", "price": "0.799", "size": "8074.66", "side": "SELL", "timestamp": "1768404626797", "received_at": "2026-01-14T16:30:26.467894"}}
{"event_type": "price_change", "event_ts": "2026-01-14T16:30:26.523312", "ingestion_ts": "2026-01-14T16:33:58.842229", "market_id": "0xaf9d0e448129a9f657f851d49495ba4742055d80e0ef1166ba0ee81d4d594214", "raw": {"market": "0xaf9d0e448129a9f657f851d49495ba4742055d80e0ef1166ba0ee81d4d594214", "asset_id": "4153292802911610701832309484716814274802943278345248636922528170020319407796", "price": "0.2", "size": "171.42", "side": "BUY", "timestamp": "1768404626846", "received_at": "2026-01-14T16:30:26.523312"}}
{"event_type": "price_change", "event_ts": "2026-01-14T16:30:26.523312", "ingestion_ts": "2026-01-14T16:33:58.842229", "market_id": "0xaf9d0e448129a9f657f851d49495ba4742055d80e0ef1166ba0ee81d4d594214", "raw": {"market": "0xaf9d0e448129a9f657f851d49495ba4742055d80e0ef1166ba0ee81d4d594214", "asset_id": "101676997363687199724245607342877036148401850938023978421879460310389391082353", "price": "0.8", "size": "171.42", "side": "SELL", "timestamp": "1768404626846", "received_at": "2026-01-14T16:30:26.523312"}}
{"event_type": "price_change", "event_ts": "2026-01-14T16:30:26.733890", "ingestion_ts": "2026-01-14T16:33:58.842229", "market_id": "0xaf9d0e448129a9f657f851d49495ba4742055d80e0ef1166ba0ee81d4d594214", "raw": {"market": "0xaf9d0e448129a9f657f851d49495ba4742055d80e0ef1166ba0ee81d4d594214", "asset_id": "4153292802911610701832309484716814274802943278345248636922528170020319407796", "price": "0.733", "size": "20", "side": "BUY", "timestamp": "1768404627057", "received_at": "2026-01-14T16:30:26.733890"}}
{"event_type": "price_change", "event_ts": "2026-01-14T16:30:26.733890", "ingestion_ts": "2026-01-14T16:33:58.842229", "market_id": "0xaf9d0e448129a9f657f851d49495ba4742055d80e0ef1166ba0ee81d4d594214", "raw": {"market": "0xaf9d0e448129a9f657f851d49495ba4742055d80e0ef1166ba0ee81d4d594214", "asset_id": "101676997363687199724245607342877036148401850938023978421879460310389391082353", "price": "0.267", "size": "20", "side": "SELL", "timestamp": "1768404627057", "received_at": "2026-01-14T16:30:26.733890"}}
{"event_type": "price_change", "event_ts": "2026-01-14T16:30:26.733925", "ingestion_ts": "2026-01-14T16:33:58.842229", "market_id": "0xaf9d0e448129a9f657f851d49495ba4742055d80e0ef1166ba0ee81d4d594214", "raw": {"market": "0xaf9d0e448129a9f657f851d49495ba4742055d80e0ef1166ba0ee81d4d594214", "asset_id": "4153292802911610701832309484716814274802943278345248636922528170020319407796", "price": "0.733", "size": "30", "side": "BUY", "timestamp": "1768404627058", "received_at": "2026-01-14T16:30:26.733925"}}
{"event_type": "price_change", "event_ts": "2026-01-14T16:30:26.733925", "ingestion_ts": "2026-01-14T16:33:58.842229", "market_id": "0xaf9d0e448129a9f657f851d49495ba4742055d80e0ef1166ba0ee81d4d594214", "raw": {"market": "0xaf9d0e448129a9f657f851d49495ba4742055d80e0ef1166ba0ee81d4d594214", "asset_id": "101676997363687199724245607342877036148401850938023978421879460310389391082353", "price": "0.267", "size": "30", "side": "SELL", "timestamp": "1768404627058", "received_at": "2026-01-14T16:30:26.733925"}}
{"event_type": "price_change", "event_ts": "2026-01-14T16:30:26.733942", "ingestion_ts": "2026-01-14T16:33:58.842229", "market_id": "0xaf9d0e448129a9f657f851d49495ba4742055d80e0ef1166ba0ee81d4d594214", "raw": {"market": "0xaf9d0e448129a9f657f851d49495ba4742055d80e0ef1166ba0ee81d4d594214", "asset_id": "4153292802911610701832309484716814274802943278345248636922528170020319407796", "price": "0.24", "size": "759.52", "side": "BUY", "timestamp": "1768404627059", "received_at": "2026-01-14T16:30:26.733942"}}
{"event_type": "price_change", "event_ts": "2026-01-14T16:30:26.733942", "ingestion_ts": "2026-01-14T16:33:58.842229", "market_id": "0xaf9d0e448129a9f657f851d49495ba4742055d80e0ef1166ba0ee81d4d594214", "raw": {"market": "0xaf9d0e448129a9f657f851d49495ba4742055d80e0ef1166ba0ee81d4d594214", "asset_id": "101676997363687199724245607342877036148401850938023978421879460310389391082353", "price": "0.76", "size": "759.52", "side": "SELL", "timestamp": "1768404627059", "received_at": "2026-01-14T16:30:26.733942"}}
{"event_type": "price_change", "event_ts": "2026-01-14T16:30:26.745570", "ingestion_ts": "2026-01-14T16:33:58.842229", "market_id": "0x49686d26fb712515cd5e12c23f0a1c7e10214c7faa3cb0a730aabe0c33694082", "raw": {"market": "0x49686d26fb712515cd5e12c23f0a1c7e10214c7faa3cb0a730aabe0c33694082", "asset_id": "13244681086321087932946246027856416106585284024824496763706748621681543444582", "price": "0.292", "size": "0", "side": "BUY", "timestamp": "1768404627082", "received_at": "2026-01-14T16:30:26.745570"}}
{"event_type": "price_change", "event_ts": "2026-01-14T16:30:26.745570", "ingestion_ts": "2026-01-14T16:33:58.842229", "market_id": "0x49686d26fb712515cd5e12c23f0a1c7e10214c7faa3cb0a730aabe0c33694082", "raw": {"market": "0x49686d26fb712515cd5e12c23f0a1c7e10214c7faa3cb0a730aabe0c33694082", "asset_id": "30442780799048074404860985387051749017905070253466005720364298335239299761065", "price": "0.708", "size": "0", "side": "SELL", "timestamp": "1768404627082", "received_at": "2026-01-14T16:30:26.745570"}}
{"event_type": "price_change", "event_ts": "2026-01-14T16:30:26.949238", "ingestion_ts": "2026-01-14T16:33:58.842229", "market_id": "0x49686d26fb712515cd5e12c23f0a1c7e10214c7faa3cb0a730aabe0c33694082", "raw": {"market": "0x49686d26fb712515cd5e12c23f0a1c7e10214c7faa3cb0a730aabe0c33694082", "asset_id": "13244681086321087932946246027856416106585284024824496763706748621681543444582", "price": "0.294", "size": "4724", "side": "BUY", "timestamp": "1768404627286", "received_at": "2026-01-14T16:30:26.949238"}}
{"event_type": "price_change", "event_ts": "2026-01-14T16:30:26.949238", "ingestion_ts": "2026-01-14T16:33:58.842229", "market_id": "0x49686d26fb712515cd5e12c23f0a1c7e10214c7faa3cb0a730aabe0c33694082", "raw": {"market": "0x49686d26fb712515cd5e12c23f0a1c7e10214c7faa3cb0a730aabe0c33694082", "asset_id": "30442780799048074404860985387051749017905070253466005720364298335239299761065", "price": "0.706", "size": "4724", "side": "SELL", "timestamp": "1768404627286", "received_at": "2026-01-14T16:30:26.949238"}}
{"event_type": "price_change", "event_ts": "2026-01-14T16:30:27.635448", "ingestion_ts": "2026-01-14T16:33:58.842229", "market_id": "0x2393ed0b0fdc450054c7b9071907eca75cf4fc36e385adf4a0a5f99ee62243e8", "raw": {"market": "0x2393ed0b0fdc450054c7b9071907eca75cf4fc36e385adf4a0a5f99ee62243e8", "asset_id": "32769749367306925959219403371425714180265458150646381231272229429098460625924", "price": "0.449", "size": "0", "side": "BUY", "timestamp": "1768404627963", "received_at": "2026-01-14T16:30:27.635448"}}
{"event_type": "price_change", "event_ts": "2026-01-14T16:30:27.635448", "ingestion_ts": "2026-01-14T16:33:58.842229", "market_id": "0x2393ed0b0fdc450054c7b9071907eca75cf4fc36e385adf4a0a5f99ee62243e8", "raw": {"market": "0x2393ed0b0fdc450054c7b9071907eca75cf4fc36e385adf4a0a5f99ee62243e8", "asset_id": "100074770378634056601572485653252702850363676459996771990439989989293515601975", "price": "0.551", "size": "0", "side": "SELL", "timestamp": "1768404627963", "received_at": "2026-01-14T16:30:27.635448"}}
{"event_type": "price_change", "event_ts": "2026-01-14T16:30:27.813590", "ingestion_ts": "2026-01-14T16:33:58.842229", "market_id": "0x2393ed0b0fdc450054c7b9071907eca75cf4fc36e385adf4a0a5f99ee62243e8", "raw": {"market": "0x2393ed0b0fdc450054c7b9071907eca75cf4fc36e385adf4a0a5f99ee62243e8", "asset_id": "32769749367306925959219403371425714180265458150646381231272229429098460625924", "price": "0.452", "size": "3611", "side": "BUY", "timestamp": "1768404628145", "received_at": "2026-01-14T16:30:27.813590"}}
{"event_type": "price_change", "event_ts": "2026-01-14T16:30:27.813590", "ingestion_ts": "2026-01-14T16:33:58.842229", "market_id": "0x2393ed0b0fdc450054c7b9071907eca75cf4fc36e385adf4a0a5f99ee62243e8", "raw": {"market": "0x2393ed0b0fdc450054c7b9071907eca75cf4fc36e385adf4a0a5f99ee62243e8", "asset_id": "100074770378634056601572485653252702850363676459996771990439989989293515601975", "price": "0.548", "size": "3611", "side": "SELL", "timestamp": "1768404628145", "received_at": "2026-01-14T16:30:27.813590"}}
{"event_type": "price_change", "event_ts": "2026-01-14T16:30:27.861165", "ingestion_ts": "2026-01-14T16:33:58.842229", "market_id": "0x2393ed0b0fdc450054c7b9071907eca75cf4fc36e385adf4a0a5f99ee62243e8", "raw": {"market": "0x2393ed0b0fdc450054c7b9071907eca75cf4fc36e385adf4a0a5f99ee62243e8", "asset_id": "32769749367306925959219403371425714180265458150646381231272229429098460625924", "price": "0.451", "size": "5", "side": "BUY", "timestamp": "1768404628199", "received_at": "2026-01-14T16:30:27.861165"}}
{"event_type": "price_change", "event_ts": "2026-01-14T16:30:27.861165", "ingestion_ts": "2026-01-14T16:33:58.842229", "market_id": "0x2393ed0b0fdc450054c7b9071907eca75cf4fc36e385adf4a0a5f99ee62243e8", "raw": {"market": "0x2393ed0b0fdc450054c7b9071907eca75cf4fc36e385adf4a0a5f99ee62243e8", "asset_id": "100074770378634056601572485653252702850363676459996771990439989989293515601975", "price": "0.549", "size": "5", "side": "SELL", "timestamp": "1768404628199", "received_at": "2026-01-14T16:30:27.861165"}}
{"event_type": "price_change", "event_ts": "2026-01-14T16:30:28.493003", "ingestion_ts": "2026-01-14T16:33:58.842229", "market_id": "0x44f08744458b8896620cd3330bc5e1ea69df4199b02d4fc583b3fc96e5d314ce", "raw": {"market": "0x44f08744458b8896620cd3330bc5e1ea69df4199b02d4fc583b3fc96e5d314ce", "asset_id": "72327831507226612545928776794104143393438710920370371172884559893525100761096", "price": "0.401", "size": "0", "side": "BUY", "timestamp": "1768404628831", "received_at": "2026-01-14T16:30:28.493003"}}
{"event_type": "price_change", "event_ts": "2026-01-14T16:30:28.493003", "ingestion_ts": "2026-01-14T16:33:58.842229", "market_id": "0x44f08744458b8896620cd3330bc5e1ea69df4199b02d4fc583b3fc96e5d314ce", "raw": {"market": "0x44f08744458b8896620cd3330bc5e1ea69df4199b02d4fc583b3fc96e5d314ce", "asset_id": "49194009556504828848509244326501559253829462790583873936160989575507522044057", "price": "0.599", "size": "0", "side": "SELL", "timestamp": "1768404628831", "received_at": "2026-01-14T16:30:28.493003"}}
{"event_type": "price_change", "event_ts": "2026-01-14T16:30:28.676831", "ingestion_ts": "2026-01-14T16:33:58.842229", "market_id": "0x44f08744458b8896620cd3330bc5e1ea69df4199b02d4fc583b3fc96e5d314ce", "raw": {"market": "0x44f08744458b8896620cd3330bc5e1ea69df4199b02d4fc583b3fc96e5d314ce", "asset_id": "72327831507226612545928776794104143393438710920370371172884559893525100761096", "price": "0.401", "size": "4714", "side": "BUY", "timestamp": "1768404629012", "received_at": "2026-01-14T16:30:28.676831"}}
{"event_type": "price_change", "event_ts": "2026-01-14T16:30:28.676831", "ingestion_ts": "2026-01-14T16:33:58.842229", "market_id": "0x44f08744458b8896620cd3330bc5e1ea69df4199b02d4fc583b3fc96e5d314ce", "raw": {"market": "0x44f08744458b8896620cd3330bc5e1ea69df4199b02d4fc583b3fc96e5d314ce", "asset_id": "49194009556504828848509244326501559253829462790583873936160989575507522044057", "price": "0.599", "size": "4714", "side": "SELL", "timestamp": "1768404629012", "received_at": "2026-01-14T16:30:28.676831"}}
{"event_type": "price_change", "event_ts": "2026-01-14T16:30:29.204801", "ingestion_ts": "2026-01-14T16:33:58.842229", "market_id": "0x49a20c7523c271099008f3ef9a31521263b24d637959852a391e6b4697b1a437", "raw": {"market": "0x49a20c7523c271099008f3ef9a31521263b24d637959852a391e6b4697b1a437", "asset_id": "55881023621710858558280545117465775643848233756850602339827152783696837905531", "price": "0.533", "size": "0", "side": "BUY", "timestamp": "1768404629543", "received_at": "2026-01-14T16:30:29.204801"}}
{"event_type": "price_change", "event_ts": "2026-01-14T16:30:29.204801", "ingestion_ts": "2026-01-14T16:33:58.842229", "market_id": "0x49a20c7523c271099008f3ef9a31521263b24d637959852a391e6b4697b1a437", "raw": {"market": "0x49a20c7523c271099008f3ef9a31521263b24d637959852a391e6b4697b1a437", "asset_id": "13018971792603393862521629014128024641178044618205296260525674415067194037856", "price": "0.467", "size": "0", "side": "SELL", "timestamp": "1768404629543", "received_at": "2026-01-14T16:30:29.204801"}}
{"event_type": "price_change", "event_ts": "2026-01-14T16:30:29.385248", "ingestion_ts": "2026-01-14T16:33:58.842229", "market_id": "0x49a20c7523c271099008f3ef9a31521263b24d637959852a391e6b4697b1a437", "raw": {"market": "0x49a20c7523c271099008f3ef9a31521263b24d637959852a391e6b4697b1a437", "asset_id": "55881023621710858558280545117465775643848233756850602339827152783696837905531", "price": "0.533", "size": "4477", "side": "BUY", "timestamp": "1768404629710", "received_at": "2026-01-14T16:30:29.385248"}}
{"event_type": "price_change", "event_ts": "2026-01-14T16:30:29.385248", "ingestion_ts": "2026-01-14T16:33:58.842229", "market_id": "0x49a20c7523c271099008f3ef9a31521263b24d637959852a391e6b4697b1a437", "raw": {"market": "0x49a20c7523c271099008f3ef9a31521263b24d637959852a391e6b4697b1a437", "asset_id": "13018971792603393862521629014128024641178044618205296260525674415067194037856", "price": "0.467", "size": "4477", "side": "SELL", "timestamp": "1768404629710", "received_at": "2026-01-14T16:30:29.385248"}}
{"event_type": "price_change", "event_ts": "2026-01-14T16:30:29.397534", "ingestion_ts": "2026-01-14T16:33:58.842229", "market_id": "0xcab7ba4a9133cfd407d7e73e5757e5abbace413b59421527a31113406c97815c", "raw": {"market": "0xcab7ba4a9133cfd407d7e73e5757e5abbace413b59421527a31113406c97815c", "asset_id": "20002636398944597965698652220992177552927816915094913583821579024925426590022", "price": "0.477", "size": "0", "side": "BUY", "timestamp": "1768404629736", "received_at": "2026-01-14T16:30:29.397534"}}
{"event_type": "price_change", "event_ts": "2026-01-14T16:30:29.397534", "ingestion_ts": "2026-01-14T16:33:58.842229", "market_id": "0xcab7ba4a9133cfd407d7e73e5757e5abbace413b59421527a31113406c97815c", "raw": {"market": "0xcab7ba4a9133cfd407d7e73e5757e5abbace413b59421527a31113406c97815c", "asset_id": "96361925776989336186111887920533578209326565663637092688733016597062311745569", "price": "0.523", "size": "0", "side": "SELL", "timestamp": "1768404629736", "received_at": "2026-01-14T16:30:29.397534"}}
{"event_type": "price_change", "event_ts": "2026-01-14T16:30:29.611968", "ingestion_ts": "2026-01-14T16:33:58.842229", "market_id": "0xcab7ba4a9133cfd407d7e73e5757e5abbace413b59421527a31113406c97815c", "raw": {"market": "0xcab7ba4a9133cfd407d7e73e5757e5abbace413b59421527a31113406c97815c", "asset_id": "20002636398944597965698652220992177552927816915094913583821579024925426590022", "price": "0.384", "size": "0", "side": "BUY", "timestamp": "1768404629933", "received_at": "2026-01-14T16:30:29.611968"}}
{"event_type": "price_change", "event_ts": "2026-01-14T16:30:29.611968", "ingestion_ts": "2026-01-14T16:33:58.842229", "market_id": "0xcab7ba4a9133cfd407d7e73e5757e5abbace413b59421527a31113406c97815c", "raw": {"market": "0xcab7ba4a9133cfd407d7e73e5757e5abbace413b59421527a31113406c97815c", "asset_id": "96361925776989336186111887920533578209326565663637092688733016597062311745569", "price": "0.616", "size": "0", "side": "SELL", "timestamp": "1768404629933", "received_at": "2026-01-14T16:30:29.611968"}}
{"event_type": "price_change", "event_ts": "2026-01-14T16:30:29.682290", "ingestion_ts": "2026-01-14T16:33:58.842229", "market_id": "0xe6508d867d153a268bdab732aa8abc8cc57e652d28a23aa042da40895bf031b2", "raw": {"market": "0xe6508d867d153a268bdab732aa8abc8cc57e652d28a23aa042da40895bf031b2", "asset_id": "57878493050148425637822780001963685814731344602319345842647239312888833935027", "price": "0.001", "size": "3102375.42", "side": "BUY", "timestamp": "1768404630000", "received_at": "2026-01-14T16:30:29.682290"}}
{"event_type": "price_change", "event_ts": "2026-01-14T16:30:29.682290", "ingestion_ts": "2026-01-14T16:33:58.842229", "market_id": "0xe6508d867d153a268bdab732aa8abc8cc57e652d28a23aa042da40895bf031b2", "raw": {"market": "0xe6508d867d153a268bdab732aa8abc8cc57e652d28a23aa042da40895bf031b2", "asset_id": "2853768819561879023657600399360829876689515906714535926781067187993853038980", "price": "0.999", "size": "3102375.42", "side": "SELL", "timestamp": "1768404630000", "received_at": "2026-01-14T16:30:29.682290"}}
{"event_type": "price_change", "event_ts": "2026-01-14T16:30:29.682338", "ingestion_ts": "2026-01-14T16:33:58.842229", "market_id": "0xe6508d867d153a268bdab732aa8abc8cc57e652d28a23aa042da40895bf031b2", "raw": {"market": "0xe6508d867d153a268bdab732aa8abc8cc57e652d28a23aa042da40895bf031b2", "asset_id": "57878493050148425637822780001963685814731344602319345842647239312888833935027", "price": "0.005", "size": "0", "side": "BUY", "timestamp": "1768404630001", "received_at": "2026-01-14T16:30:29.682338"}}
{"event_type": "price_change", "event_ts": "2026-01-14T16:30:29.682338", "ingestion_ts": "2026-01-14T16:33:58.842229", "market_id": "0xe6508d867d153a268bdab732aa8abc8cc57e652d28a23aa042da40895bf031b2", "raw": {"market": "0xe6508d867d153a268bdab732aa8abc8cc57e652d28a23aa042da40895bf031b2", "asset_id": "2853768819561879023657600399360829876689515906714535926781067187993853038980", "price": "0.995", "size": "0", "side": "SELL", "timestamp": "1768404630001", "received_at": "2026-01-14T16:30:29.682338"}}
{"event_type": "price_change", "event_ts": "2026-01-14T16:30:29.682359", "ingestion_ts": "2026-01-14T16:33:58.842229", "market_id": "0xe6508d867d153a268bdab732aa8abc8cc57e652d28a23aa042da40895bf031b2", "raw": {"market": "0xe6508d867d153a268bdab732aa8abc8cc57e652d28a23aa042da40895bf031b2", "asset_id": "57878493050148425637822780001963685814731344602319345842647239312888833935027", "price": "0.002", "size": "30250", "side": "BUY", "timestamp": "1768404630001", "received_at": "2026-01-14T16:30:29.682359"}}
{"event_type": "price_change", "event_ts": "2026-01-14T16:30:29.682359", "ingestion_ts": "2026-01-14T16:33:58.842229", "market_id": "0xe6508d867d153a268bdab732aa8abc8cc57e652d28a23aa042da40895bf031b2", "raw": {"market": "0xe6508d867d153a268bdab732aa8abc8cc57e652d28a23aa042da40895bf031b2", "asset_id": "2853768819561879023657600399360829876689515906714535926781067187993853038980", "price": "0.998", "size": "30250", "side": "SELL", "timestamp": "1768404630001", "received_at": "2026-01-14T16:30:29.682359"}}
{"event_type": "price_change", "event_ts": "2026-01-14T16:30:29.682379", "ingestion_ts": "2026-01-14T16:33:58.842229", "market_id": "0xe6508d867d153a268bdab732aa8abc8cc57e652d28a23aa042da40895bf031b2", "raw": {"market": "0xe6508d867d153a268bdab732aa8abc8cc57e652d28a23aa042da40895bf031b2", "asset_id": "57878493050148425637822780001963685814731344602319345842647239312888833935027", "price": "0.101", "size": "0", "side": "BUY", "timestamp": "1768404630002", "received_at": "2026-01-14T16:30:29.682379"}}
{"event_type": "price_change", "event_ts": "2026-01-14T16:30:29.682379", "ingestion_ts": "2026-01-14T16:33:58.842229", "market_id": "0xe6508d867d153a268bdab732aa8abc8cc57e652d28a23aa042da40895bf031b2", "raw": {"market": "0xe6508d867d153a268bdab732aa8abc8cc57e652d28a23aa042da40895bf031b2", "asset_id": "2853768819561879023657600399360829876689515906714535926781067187993853038980", "price": "0.899", "size": "0", "side": "SELL", "timestamp": "1768404630002", "received_at": "2026-01-14T16:30:29.682379"}}
{"event_type": "price_change", "event_ts": "2026-01-14T16:30:29.682398", "ingestion_ts": "2026-01-14T16:33:58.842229", "market_id": "0xe6508d867d153a268bdab732aa8abc8cc57e652d28a23aa042da40895bf031b2", "raw": {"market": "0xe6508d867d153a268bdab732aa8abc8cc57e652d28a23aa042da40895bf031b2", "asset_id": "57878493050148425637822780001963685814731344602319345842647239312888833935027", "price": "0.023", "size": "0", "side": "BUY", "timestamp": "1768404630002", "received_at": "2026-01-14T16:30:29.682398"}}
{"event_type": "price_change", "event_ts": "2026-01-14T16:30:29.682398", "ingestion_ts": "2026-01-14T16:33:58.842229", "market_id": "0xe6508d867d153a268bdab732aa8abc8cc57e652d28a23aa042da40895bf031b2", "raw": {"market": "0xe6508d867d153a268bdab732aa8abc8cc57e652d28a23aa042da40895bf031b2", "asset_id": "2853768819561879023657600399360829876689515906714535926781067187993853038980", "price": "0.977", "size": "0", "side": "SELL", "timestamp": "1768404630002", "received_at": "2026-01-14T16:30:29.682398"}}
{"event_type": "price_change", "event_ts": "2026-01-14T16:30:29.682413", "ingestion_ts": "2026-01-14T16:33:58.842229", "market_id": "0xe6508d867d153a268bdab732aa8abc8cc57e652d28a23aa042da40895bf031b2", "raw": {"market": "0xe6508d867d153a268bdab732aa8abc8cc57e652d28a23aa042da40895bf031b2", "asset_id": "57878493050148425637822780001963685814731344602319345842647239312888833935027", "price": "0.011", "size": "0", "side": "BUY", "timestamp": "1768404630003", "received_at": "2026-01-14T16:30:29.682413"}}
{"event_type": "price_change", "event_ts": "2026-01-14T16:30:29.682413", "ingestion_ts": "2026-01-14T16:33:58.842229", "market_id": "0xe6508d867d153a268bdab732aa8abc8cc57e652d28a23aa042da40895bf031b2", "raw": {"market": "0xe6508d867d153a268bdab732aa8abc8cc57e652d28a23aa042da40895bf031b2", "asset_id": "2853768819561879023657600399360829876689515906714535926781067187993853038980", "price": "0.989", "size": "0", "side": "SELL", "timestamp": "1768404630003", "received_at": "2026-01-14T16:30:29.682413"}}
{"event_type": "price_change", "event_ts": "2026-01-14T16:30:29.723638", "ingestion_ts": "2026-01-14T16:33:58.842229", "market_id": "0xaf9d0e448129a9f657f851d49495ba4742055d80e0ef1166ba0ee81d4d594214", "raw": {"market": "0xaf9d0e448129a9f657f851d49495ba4742055d80e0ef1166ba0ee81d4d594214", "asset_id": "4153292802911610701832309484716814274802943278345248636922528170020319407796", "price": "0.732", "size": "0", "side": "BUY", "timestamp": "1768404630062", "received_at": "2026-01-14T16:30:29.723638"}}
{"event_type": "price_change", "event_ts": "2026-01-14T16:30:29.723638", "ingestion_ts": "2026-01-14T16:33:58.842229", "market_id": "0xaf9d0e448129a9f657f851d49495ba4742055d80e0ef1166ba0ee81d4d594214", "raw": {"market": "0xaf9d0e448129a9f657f851d49495ba4742055d80e0ef1166ba0ee81d4d594214", "asset_id": "101676997363687199724245607342877036148401850938023978421879460310389391082353", "price": "0.268", "size": "0", "side": "SELL", "timestamp": "1768404630062", "received_at": "2026-01-14T16:30:29.723638"}}
{"event_type": "price_change", "event_ts": "2026-01-14T16:30:29.757309", "ingestion_ts": "2026-01-14T16:33:58.842229", "market_id": "0xaf9d0e448129a9f657f851d49495ba4742055d80e0ef1166ba0ee81d4d594214", "raw": {"market": "0xaf9d0e448129a9f657f851d49495ba4742055d80e0ef1166ba0ee81d4d594214", "asset_id": "4153292802911610701832309484716814274802943278345248636922528170020319407796", "price": "0.734", "size": "5", "side": "BUY", "timestamp": "1768404630096", "received_at": "2026-01-14T16:30:29.757309"}}
{"event_type": "price_change", "event_ts": "2026-01-14T16:30:29.757309", "ingestion_ts": "2026-01-14T16:33:58.842229", "market_id": "0xaf9d0e448129a9f657f851d49495ba4742055d80e0ef1166ba0ee81d4d594214", "raw": {"market": "0xaf9d0e448129a9f657f851d49495ba4742055d80e0ef1166ba0ee81d4d594214", "asset_id": "101676997363687199724245607342877036148401850938023978421879460310389391082353", "price": "0.266", "size": "5", "side": "SELL", "timestamp": "1768404630096", "received_at": "2026-01-14T16:30:29.757309"}}
{"event_type": "price_change", "event_ts": "2026-01-14T16:30:29.807199", "ingestion_ts": "2026-01-14T16:33:58.842229", "market_id": "0xcab7ba4a9133cfd407d7e73e5757e5abbace413b59421527a31113406c97815c", "raw": {"market": "0xcab7ba4a9133cfd407d7e73e5757e5abbace413b59421527a31113406c97815c", "asset_id": "20002636398944597965698652220992177552927816915094913583821579024925426590022", "price": "0.254", "size": "0", "side": "BUY", "timestamp": "1768404630146", "received_at": "2026-01-14T16:30:29.807199"}}
{"event_type": "price_change", "event_ts": "2026-01-14T16:30:29.807199", "ingestion_ts": "2026-01-14T16:33:58.842229", "market_id": "0xcab7ba4a9133cfd407d7e73e5757e5abbace413b59421527a31113406c97815c", "raw": {"market": "0xcab7ba4a9133cfd407d7e73e5757e5abbace413b59421527a31113406c97815c", "asset_id": "96361925776989336186111887920533578209326565663637092688733016597062311745569", "price": "0.746", "size": "0", "side": "SELL", "timestamp": "1768404630146", "received_at": "2026-01-14T16:30:29.807199"}}
{"event_type": "price_change", "event_ts": "2026-01-14T16:30:30.002664", "ingestion_ts": "2026-01-14T16:33:58.842229", "market_id": "0xcab7ba4a9133cfd407d7e73e5757e5abbace413b59421527a31113406c97815c", "raw": {"market": "0xcab7ba4a9133cfd407d7e73e5757e5abbace413b59421527a31113406c97815c", "asset_id": "20002636398944597965698652220992177552927816915094913583821579024925426590022", "price": "0.169", "size": "0", "side": "BUY", "timestamp": "1768404630341", "received_at": "2026-01-14T16:30:30.002664"}}
{"event_type": "price_change", "event_ts": "2026-01-14T16:30:30.002664", "ingestion_ts": "2026-01-14T16:33:58.842229", "market_id": "0xcab7ba4a9133cfd407d7e73e5757e5abbace413b59421527a31113406c97815c", "raw": {"market": "0xcab7ba4a9133cfd407d7e73e5757e5abbace413b59421527a31113406c97815c", "asset_id": "96361925776989336186111887920533578209326565663637092688733016597062311745569", "price": "0.831", "size": "0", "side": "SELL", "timestamp": "1768404630341", "received_at": "2026-01-14T16:30:30.002664"}}
{"event_type": "price_change", "event_ts": "2026-01-14T16:30:30.023319", "ingestion_ts": "2026-01-14T16:33:58.842229", "market_id": "0x50c669f178da4e5bbea7f1be25041fd278914712fa87a6a6f8e57d5923d88dee", "raw": {"market": "0x50c669f178da4e5bbea7f1be25041fd278914712fa87a6a6f8e57d5923d88dee", "asset_id": "74040420326294854165772767082819937451857852955603897473157746262672057685461", "price": "0.468", "size": "0", "side": "BUY", "timestamp": "1768404630361", "received_at": "2026-01-14T16:30:30.023319"}}
{"event_type": "price_change", "event_ts": "2026-01-14T16:30:30.023319", "ingestion_ts": "2026-01-14T16:33:58.842229", "market_id": "0x50c669f178da4e5bbea7f1be25041fd278914712fa87a6a6f8e57d5923d88dee", "raw": {"market": "0x50c669f178da4e5bbea7f1be25041fd278914712fa87a6a6f8e57d5923d88dee", "asset_id": "24682525479474221428144937281315825971983904267399062415430320764754931667953", "price": "0.532", "size": "0", "side": "SELL", "timestamp": "1768404630361", "received_at": "2026-01-14T16:30:30.023319"}}
{"event_type": "price_change", "event_ts": "2026-01-14T16:30:30.190404", "ingestion_ts": "2026-01-14T16:33:58.842229", "market_id": "0x50c669f178da4e5bbea7f1be25041fd278914712fa87a6a6f8e57d5923d88dee", "raw": {"market": "0x50c669f178da4e5bbea7f1be25041fd278914712fa87a6a6f8e57d5923d88dee", "asset_id": "74040420326294854165772767082819937451857852955603897473157746262672057685461", "price": "0.468", "size": "4083", "side": "BUY", "timestamp": "1768404630527", "received_at": "2026-01-14T16:30:30.190404"}}
{"event_type": "price_change", "event_ts": "2026-01-14T16:30:30.190404", "ingestion_ts": "2026-01-14T16:33:58.842229", "market_id": "0x50c669f178da4e5bbea7f1be25041fd278914712fa87a6a6f8e57d5923d88dee", "raw": {"market": "0x50c669f178da4e5bbea7f1be25041fd278914712fa87a6a6f8e57d5923d88dee", "asset_id": "24682525479474221428144937281315825971983904267399062415430320764754931667953", "price": "0.532", "size": "4083", "side": "SELL", "timestamp": "1768404630527", "received_at": "2026-01-14T16:30:30.190404"}}
{"event_type": "price_change", "event_ts": "2026-01-14T16:30:30.196649", "ingestion_ts": "2026-01-14T16:33:58.842229", "market_id": "0xcab7ba4a9133cfd407d7e73e5757e5abbace413b59421527a31113406c97815c", "raw": {"market": "0xcab7ba4a9133cfd407d7e73e5757e5abbace413b59421527a31113406c97815c", "asset_id": "20002636398944597965698652220992177552927816915094913583821579024925426590022", "price": "0.123", "size": "0", "side": "BUY", "timestamp": "1768404630535", "received_at": "2026-01-14T16:30:30.196649"}}
{"event_type": "price_change", "event_ts": "2026-01-14T16:30:30.196649", "ingestion_ts": "2026-01-14T16:33:58.842229", "market_id": "0xcab7ba4a9133cfd407d7e73e5757e5abbace413b59421527a31113406c97815c", "raw": {"market": "0xcab7ba4a9133cfd407d7e73e5757e5abbace413b59421527a31113406c97815c", "asset_id": "96361925776989336186111887920533578209326565663637092688733016597062311745569", "price": "0.877", "size": "0", "side": "SELL", "timestamp": "1768404630535", "received_at": "2026-01-14T16:30:30.196649"}}
{"event_type": "price_change", "event_ts": "2026-01-14T16:30:30.394643", "ingestion_ts": "2026-01-14T16:33:58.842229", "market_id": "0xcab7ba4a9133cfd407d7e73e5757e5abbace413b59421527a31113406c97815c", "raw": {"market": "0xcab7ba4a9133cfd407d7e73e5757e5abbace413b59421527a31113406c97815c", "asset_id": "20002636398944597965698652220992177552927816915094913583821579024925426590022", "price": "0.104", "size": "0", "side": "BUY", "timestamp": "1768404630733", "received_at": "2026-01-14T16:30:30.394643"}}
{"event_type": "price_change", "event_ts": "2026-01-14T16:30:30.394643", "ingestion_ts": "2026-01-14T16:33:58.842229", "market_id": "0xcab7ba4a9133cfd407d7e73e5757e5abbace413b59421527a31113406c97815c", "raw": {"market": "0xcab7ba4a9133cfd407d7e73e5757e5abbace413b59421527a31113406c97815c", "asset_id": "96361925776989336186111887920533578209326565663637092688733016597062311745569", "price": "0.896", "size": "0", "side": "SELL", "timestamp": "1768404630733", "received_at": "2026-01-14T16:30:30.394643"}}
{"event_type": "price_change", "event_ts": "2026-01-14T16:30:30.406070", "ingestion_ts": "2026-01-14T16:33:58.842229", "market_id": "0x49686d26fb712515cd5e12c23f0a1c7e10214c7faa3cb0a730aabe0c33694082", "raw": {"market": "0x49686d26fb712515cd5e12c23f0a1c7e10214c7faa3cb0a730aabe0c33694082", "asset_id": "30442780799048074404860985387051749017905070253466005720364298335239299761065", "price": "0.094", "size": "50", "side": "BUY", "timestamp": "1768404630745", "received_at": "2026-01-14T16:30:30.406070"}}
{"event_type": "price_change", "event_ts": "2026-01-14T16:30:30.406070", "ingestion_ts": "2026-01-14T16:33:58.842229", "market_id": "0x49686d26fb712515cd5e12c23f0a1c7e10214c7faa3cb0a730aabe0c33694082", "raw": {"market": "0x49686d26fb712515cd5e12c23f0a1c7e10214c7faa3cb0a730aabe0c33694082", "asset_id": "13244681086321087932946246027856416106585284024824496763706748621681543444582", "price": "0.906", "size": "50", "side": "SELL", "timestamp": "1768404630745", "received_at": "2026-01-14T16:30:30.406070"}}
{"event_type": "price_change", "event_ts": "2026-01-14T16:30:30.435794", "ingestion_ts": "2026-01-14T16:33:58.842229", "market_id": "0x49686d26fb712515cd5e12c23f0a1c7e10214c7faa3cb0a730aabe0c33694082", "raw": {"market": "0x49686d26fb712515cd5e12c23f0a1c7e10214c7faa3cb0a730aabe0c33694082", "asset_id": "13244681086321087932946246027856416106585284024824496763706748621681543444582", "price": "0.907", "size": "0", "side": "SELL", "timestamp": "1768404630771", "received_at": "2026-01-14T16:30:30.435794"}}
{"event_type": "price_change", "event_ts": "2026-01-14T16:30:30.435794", "ingestion_ts": "2026-01-14T16:33:58.842229", "market_id": "0x49686d26fb712515cd5e12c23f0a1c7e10214c7faa3cb0a730aabe0c33694082", "raw": {"market": "0x49686d26fb712515cd5e12c23f0a1c7e10214c7faa3cb0a730aabe0c33694082", "asset_id": "30442780799048074404860985387051749017905070253466005720364298335239299761065", "price": "0.093", "size": "0", "side": "BUY", "timestamp": "1768404630771", "received_at": "2026-01-14T16:30:30.435794"}}
{"event_type": "price_change", "event_ts": "2026-01-14T16:30:30.456291", "ingestion_ts": "2026-01-14T16:33:58.842229", "market_id": "0x49686d26fb712515cd5e12c23f0a1c7e10214c7faa3cb0a730aabe0c33694082", "raw": {"market": "0x49686d26fb712515cd5e12c23f0a1c7e10214c7faa3cb0a730aabe0c33694082", "asset_id": "13244681086321087932946246027856416106585284024824496763706748621681543444582", "price": "0.851", "size": "550", "side": "BUY", "timestamp": "1768404630795", "received_at": "2026-01-14T16:30:30.456291"}}
{"event_type": "price_change", "event_ts": "2026-01-14T16:30:30.456291", "ingestion_ts": "2026-01-14T16:33:58.842229", "market_id": "0x49686d26fb712515cd5e12c23f0a1c7e10214c7faa3cb0a730aabe0c33694082", "raw": {"market": "0x49686d26fb712515cd5e12c23f0a1c7e10214c7faa3cb0a730aabe0c33694082", "asset_id": "30442780799048074404860985387051749017905070253466005720364298335239299761065", "price": "0.149", "size": "550", "side": "SELL", "timestamp": "1768404630795", "received_at": "2026-01-14T16:30:30.456291"}}
{"event_type": "price_change", "event_ts": "2026-01-14T16:30:30.463405", "ingestion_ts": "2026-01-14T16:33:58.842229", "market_id": "0x49686d26fb712515cd5e12c23f0a1c7e10214c7faa3cb0a730aabe0c33694082", "raw": {"market": "0x49686d26fb712515cd5e12c23f0a1c7e10214c7faa3cb0a730aabe0c33694082", "asset_id": "13244681086321087932946246027856416106585284024824496763706748621681543444582", "price": "0.905", "size": "105", "side": "SELL", "timestamp": "1768404630798", "received_at": "2026-01-14T16:30:30.463405"}}
{"event_type": "price_change", "event_ts": "2026-01-14T16:30:30.463405", "ingestion_ts": "2026-01-14T16:33:58.842229", "market_id": "0x49686d26fb712515cd5e12c23f0a1c7e10214c7faa3cb0a730aabe0c33694082", "raw": {"market": "0x49686d26fb712515cd5e12c23f0a1c7e10214c7faa3cb0a730aabe0c33694082", "asset_id": "30442780799048074404860985387051749017905070253466005720364298335239299761065", "price": "0.095", "size": "105", "side": "BUY", "timestamp": "1768404630798", "received_at": "2026-01-14T16:30:30.463405"}}
{"event_type": "price_change", "event_ts": "2026-01-14T16:30:30.606284", "ingestion_ts": "2026-01-14T16:33:58.842229", "market_id": "0xcab7ba4a9133cfd407d7e73e5757e5abbace413b59421527a31113406c97815c", "raw": {"market": "0xcab7ba4a9133cfd407d7e73e5757e5abbace413b59421527a31113406c97815c", "asset_id": "20002636398944597965698652220992177552927816915094913583821579024925426590022", "price": "0.053", "size": "0", "side": "BUY", "timestamp": "1768404630945", "received_at": "2026-01-14T16:30:30.606284"}}
{"event_type": "price_change", "event_ts": "2026-01-14T16:30:30.606284", "ingestion_ts": "2026-01-14T16:33:58.842229", "market_id": "0xcab7ba4a9133cfd407d7e73e5757e5abbace413b59421527a31113406c97815c", "raw": {"market": "0xcab7ba4a9133cfd407d7e73e5757e5abbace413b59421527a31113406c97815c", "asset_id": "96361925776989336186111887920533578209326565663637092688733016597062311745569", "price": "0.947", "size": "0", "side": "SELL", "timestamp": "1768404630945", "received_at": "2026-01-14T16:30:30.606284"}}
{"event_type": "price_change", "event_ts": "2026-01-14T16:30:30.806881", "ingestion_ts": "2026-01-14T16:33:58.842229", "market_id": "0x9472be65457510b7fc3477b20ba90910e99d92eac8421a14bf4b7b7a08ef31dc", "raw": {"market": "0x9472be65457510b7fc3477b20ba90910e99d92eac8421a14bf4b7b7a08ef31dc", "asset_id": "43311793366960417907757893276427136943959788721376762326430771171648759300146", "price": "0.571", "size": "0", "side": "BUY", "timestamp": "1768404631136", "received_at": "2026-01-14T16:30:30.806881"}}
{"event_type": "price_change", "event_ts": "2026-01-14T16:30:30.806881", "ingestion_ts": "2026-01-14T16:33:58.842229", "market_id": "0x9472be65457510b7fc3477b20ba90910e99d92eac8421a14bf4b7b7a08ef31dc", "raw": {"market": "0x9472be65457510b7fc3477b20ba90910e99d92eac8421a14bf4b7b7a08ef31dc", "asset_id": "73414222381656326204771753454630063673548497164758947581648273905027617570612", "price": "0.429", "size": "0", "side": "SELL", "timestamp": "1768404631136", "received_at": "2026-01-14T16:30:30.806881"}}
{"event_type": "price_change", "event_ts": "2026-01-14T16:30:30.834128", "ingestion_ts": "2026-01-14T16:33:58.842229", "market_id": "0xcab7ba4a9133cfd407d7e73e5757e5abbace413b59421527a31113406c97815c", "raw": {"market": "0xcab7ba4a9133cfd407d7e73e5757e5abbace413b59421527a31113406c97815c", "asset_id": "20002636398944597965698652220992177552927816915094913583821579024925426590022", "price": "0.043", "size": "0", "side": "BUY", "timestamp": "1768404631172", "received_at": "2026-01-14T16:30:30.834128"}}
{"event_type": "price_change", "event_ts": "2026-01-14T16:30:30.834128", "ingestion_ts": "2026-01-14T16:33:58.842229", "market_id": "0xcab7ba4a9133cfd407d7e73e5757e5abbace413b59421527a31113406c97815c", "raw": {"market": "0xcab7ba4a9133cfd407d7e73e5757e5abbace413b59421527a31113406c97815c", "asset_id": "96361925776989336186111887920533578209326565663637092688733016597062311745569", "price": "0.957", "size": "0", "side": "SELL", "timestamp": "1768404631172", "received_at": "2026-01-14T16:30:30.834128"}}
{"event_type": "price_change", "event_ts": "2026-01-14T16:30:30.957084", "ingestion_ts": "2026-01-14T16:33:58.842229", "market_id": "0x9472be65457510b7fc3477b20ba90910e99d92eac8421a14bf4b7b7a08ef31dc", "raw": {"market": "0x9472be65457510b7fc3477b20ba90910e99d92eac8421a14bf4b7b7a08ef31dc", "asset_id": "43311793366960417907757893276427136943959788721376762326430771171648759300146", "price": "0.571", "size": "3352", "side": "BUY", "timestamp": "1768404631292", "received_at": "2026-01-14T16:30:30.957084"}}
{"event_type": "price_change", "event_ts": "2026-01-14T16:30:30.957084", "ingestion_ts": "2026-01-14T16:33:58.842229", "market_id": "0x9472be65457510b7fc3477b20ba90910e99d92eac8421a14bf4b7b7a08ef31dc", "raw": {"market": "0x9472be65457510b7fc3477b20ba90910e99d92eac8421a14bf4b7b7a08ef31dc", "asset_id": "73414222381656326204771753454630063673548497164758947581648273905027617570612", "price": "0.429", "size": "3352", "side": "SELL", "timestamp": "1768404631292", "received_at": "2026-01-14T16:30:30.957084"}}
{"event_type": "price_change", "event_ts": "2026-01-14T16:30:31.033716", "ingestion_ts": "2026-01-14T16:33:58.842229", "market_id": "0xcab7ba4a9133cfd407d7e73e5757e5abbace413b59421527a31113406c97815c", "raw": {"market": "0xcab7ba4a9133cfd407d7e73e5757e5abbace413b59421527a31113406c97815c", "asset_id": "20002636398944597965698652220992177552927816915094913583821579024925426590022", "price": "0.022", "size": "0", "side": "BUY", "timestamp": "1768404631373", "received_at": "2026-01-14T16:30:31.033716"}}
{"event_type": "price_change", "event_ts": "2026-01-14T16:30:31.033716", "ingestion_ts": "2026-01-14T16:33:58.842229", "market_id": "0xcab7ba4a9133cfd407d7e73e5757e5abbace413b59421527a31113406c97815c", "raw": {"market": "0xcab7ba4a9133cfd407d7e73e5757e5abbace413b59421527a31113406c97815c", "asset_id": "96361925776989336186111887920533578209326565663637092688733016597062311745569", "price": "0.978", "size": "0", "side": "SELL", "timestamp": "1768404631373", "received_at": "2026-01-14T16:30:31.033716"}}
{"event_type": "price_change", "event_ts": "2026-01-14T16:30:31.247400", "ingestion_ts": "2026-01-14T16:33:58.842229", "market_id": "0xcab7ba4a9133cfd407d7e73e5757e5abbace413b59421527a31113406c97815c", "raw": {"market": "0xcab7ba4a9133cfd407d7e73e5757e5abbace413b59421527a31113406c97815c", "asset_id": "20002636398944597965698652220992177552927816915094913583821579024925426590022", "price": "0.022", "size": "167.83", "side": "BUY", "timestamp": "1768404631586", "received_at": "2026-01-14T16:30:31.247400"}}
{"event_type": "price_change", "event_ts": "2026-01-14T16:30:31.247400", "ingestion_ts": "2026-01-14T16:33:58.842229", "market_id": "0xcab7ba4a9133cfd407d7e73e5757e5abbace413b59421527a31113406c97815c", "raw": {"market": "0xcab7ba4a9133cfd407d7e73e5757e5abbace413b59421527a31113406c97815c", "asset_id": "96361925776989336186111887920533578209326565663637092688733016597062311745569", "price": "0.978", "size": "167.83", "side": "SELL", "timestamp": "1768404631586", "received_at": "2026-01-14T16:30:31.247400"}}
{"event_type": "price_change", "event_ts": "2026-01-14T16:30:31.487916", "ingestion_ts": "2026-01-14T16:33:58.842229", "market_id": "0xcab7ba4a9133cfd407d7e73e5757e5abbace413b59421527a31113406c97815c", "raw": {"market": "0xcab7ba4a9133cfd407d7e73e5757e5abbace413b59421527a31113406c97815c", "asset_id": "20002636398944597965698652220992177552927816915094913583821579024925426590022", "price": "0.044", "size": "90.27", "side": "BUY", "timestamp": "1768404631819", "received_at": "2026-01-14T16:30:31.487916"}}
{"event_type": "price_change", "event_ts": "2026-01-14T16:30:31.487916", "ingestion_ts": "2026-01-14T16:33:58.842229", "market_id": "0xcab7ba4a9133cfd407d7e73e5757e5abbace413b59421527a31113406c97815c", "raw": {"market": "0xcab7ba4a9133cfd407d7e73e5757e5abbace413b59421527a31113406c97815c", "asset_id": "96361925776989336186111887920533578209326565663637092688733016597062311745569", "price": "0.956", "size": "90.27", "side": "SELL", "timestamp": "1768404631819", "received_at": "2026-01-14T16:30:31.487916"}}
{"event_type": "price_change", "event_ts": "2026-01-14T16:30:31.508789", "ingestion_ts": "2026-01-14T16:33:58.842229", "market_id": "0xc55db914f0fd1fee18997706712c0dfd8d0369cdbef93a9fef12bd001914ca77", "raw": {"market": "0xc55db914f0fd1fee18997706712c0dfd8d0369cdbef93a9fef12bd001914ca77", "asset_id": "114600293444080540179603459515770723592661967180480327891296353898330242622833", "price": "0.436", "size": "0", "side": "BUY", "timestamp": "1768404631847", "received_at": "2026-01-14T16:30:31.508789"}}
{"event_type": "price_change", "event_ts": "2026-01-14T16:30:31.508789", "ingestion_ts": "2026-01-14T16:33:58.842229", "market_id": "0xc55db914f0fd1fee18997706712c0dfd8d0369cdbef93a9fef12bd001914ca77", "raw": {"market": "0xc55db914f0fd1fee18997706712c0dfd8d0369cdbef93a9fef12bd001914ca77", "asset_id": "72354723612769247426741660426331235762851940382312402276325808095604519806766", "price": "0.564", "size": "0", "side": "SELL", "timestamp": "1768404631847", "received_at": "2026-01-14T16:30:31.508789"}}
{"event_type": "price_change", "event_ts": "2026-01-14T16:30:31.690493", "ingestion_ts": "2026-01-14T16:33:58.842229", "market_id": "0xc55db914f0fd1fee18997706712c0dfd8d0369cdbef93a9fef12bd001914ca77", "raw": {"market": "0xc55db914f0fd1fee18997706712c0dfd8d0369cdbef93a9fef12bd001914ca77", "asset_id": "114600293444080540179603459515770723592661967180480327891296353898330242622833", "price": "0.436", "size": "4380", "side": "BUY", "timestamp": "1768404632006", "received_at": "2026-01-14T16:30:31.690493"}}
{"event_type": "price_change", "event_ts": "2026-01-14T16:30:31.690493", "ingestion_ts": "2026-01-14T16:33:58.842229", "market_id": "0xc55db914f0fd1fee18997706712c0dfd8d0369cdbef93a9fef12bd001914ca77", "raw": {"market": "0xc55db914f0fd1fee18997706712c0dfd8d0369cdbef93a9fef12bd001914ca77", "asset_id": "72354723612769247426741660426331235762851940382312402276325808095604519806766", "price": "0.564", "size": "4380", "side": "SELL", "timestamp": "1768404632006", "received_at": "2026-01-14T16:30:31.690493"}}
{"event_type": "price_change", "event_ts": "2026-01-14T16:30:31.714536", "ingestion_ts": "2026-01-14T16:33:58.842229", "market_id": "0xcab7ba4a9133cfd407d7e73e5757e5abbace413b59421527a31113406c97815c", "raw": {"market": "0xcab7ba4a9133cfd407d7e73e5757e5abbace413b59421527a31113406c97815c", "asset_id": "20002636398944597965698652220992177552927816915094913583821579024925426590022", "price": "0.055", "size": "67.13", "side": "BUY", "timestamp": "1768404632041", "received_at": "2026-01-14T16:30:31.714536"}}
{"event_type": "price_change", "event_ts": "2026-01-14T16:30:31.714536", "ingestion_ts": "2026-01-14T16:33:58.842229", "market_id": "0xcab7ba4a9133cfd407d7e73e5757e5abbace413b59421527a31113406c97815c", "raw": {"market": "0xcab7ba4a9133cfd407d7e73e5757e5abbace413b59421527a31113406c97815c", "asset_id": "96361925776989336186111887920533578209326565663637092688733016597062311745569", "price": "0.945", "size": "67.13", "side": "SELL", "timestamp": "1768404632041", "received_at": "2026-01-14T16:30:31.714536"}}
{"event_type": "price_change", "event_ts": "2026-01-14T16:30:31.925102", "ingestion_ts": "2026-01-14T16:33:58.842229", "market_id": "0xcab7ba4a9133cfd407d7e73e5757e5abbace413b59421527a31113406c97815c", "raw": {"market": "0xcab7ba4a9133cfd407d7e73e5757e5abbace413b59421527a31113406c97815c", "asset_id": "20002636398944597965698652220992177552927816915094913583821579024925426590022", "price": "0.106", "size": "34.83", "side": "BUY", "timestamp": "1768404632258", "received_at": "2026-01-14T16:30:31.925102"}}
{"event_type": "price_change", "event_ts": "2026-01-14T16:30:31.925102", "ingestion_ts": "2026-01-14T16:33:58.842229", "market_id": "0xcab7ba4a9133cfd407d7e73e5757e5abbace413b59421527a31113406c97815c", "raw": {"market": "0xcab7ba4a9133cfd407d7e73e5757e5abbace413b59421527a31113406c97815c", "asset_id": "96361925776989336186111887920533578209326565663637092688733016597062311745569", "price": "0.894", "size": "34.83", "side": "SELL", "timestamp": "1768404632258", "received_at": "2026-01-14T16:30:31.925102"}}
{"event_type": "price_change", "event_ts": "2026-01-14T16:30:32.184005", "ingestion_ts": "2026-01-14T16:33:58.842229", "market_id": "0xcab7ba4a9133cfd407d7e73e5757e5abbace413b59421527a31113406c97815c", "raw": {"market": "0xcab7ba4a9133cfd407d7e73e5757e5abbace413b59421527a31113406c97815c", "asset_id": "20002636398944597965698652220992177552927816915094913583821579024925426590022", "price": "0.125", "size": "29.53", "side": "BUY", "timestamp": "1768404632507", "received_at": "2026-01-14T16:30:32.184005"}}
{"event_type": "price_change", "event_ts": "2026-01-14T16:30:32.184005", "ingestion_ts": "2026-01-14T16:33:58.842229", "market_id": "0xcab7ba4a9133cfd407d7e73e5757e5abbace413b59421527a31113406c97815c", "raw": {"market": "0xcab7ba4a9133cfd407d7e73e5757e5abbace413b59421527a31113406c97815c", "asset_id": "96361925776989336186111887920533578209326565663637092688733016597062311745569", "price": "0.875", "size": "29.53", "side": "SELL", "timestamp": "1768404632507", "received_at": "2026-01-14T16:30:32.184005"}}
{"event_type": "price_change", "event_ts": "2026-01-14T16:30:32.292191", "ingestion_ts": "2026-01-14T16:33:58.842229", "market_id": "0xb9bbdd34304344dcc45803780a34c97d73a00133a5ecf70f63e1008b8abb2fca", "raw": {"market": "0xb9bbdd34304344dcc45803780a34c97d73a00133a5ecf70f63e1008b8abb2fca", "asset_id": "8682484153073832526711485265636767086525069344085206423986003504588877767339", "price": "0.576", "size": "0", "side": "BUY", "timestamp": "1768404632604", "received_at": "2026-01-14T16:30:32.292191"}}
{"event_type": "price_change", "event_ts": "2026-01-14T16:30:32.292191", "ingestion_ts": "2026-01-14T16:33:58.842229", "market_id": "0xb9bbdd34304344dcc45803780a34c97d73a00133a5ecf70f63e1008b8abb2fca", "raw": {"market": "0xb9bbdd34304344dcc45803780a34c97d73a00133a5ecf70f63e1008b8abb2fca", "asset_id": "72012724360700510767037780555710363830014634797787940282136454146828040926557", "price": "0.424", "size": "0", "side": "SELL", "timestamp": "1768404632604", "received_at": "2026-01-14T16:30:32.292191"}}
{"event_type": "price_change", "event_ts": "2026-01-14T16:30:32.384671", "ingestion_ts": "2026-01-14T16:33:58.842229", "market_id": "0xcab7ba4a9133cfd407d7e73e5757e5abbace413b59421527a31113406c97815c", "raw": {"market": "0xcab7ba4a9133cfd407d7e73e5757e5abbace413b59421527a31113406c97815c", "asset_id": "20002636398944597965698652220992177552927816915094913583821579024925426590022", "price": "0.151", "size": "0", "side": "BUY", "timestamp": "1768404632713", "received_at": "2026-01-14T16:30:32.384671"}}
{"event_type": "price_change", "event_ts": "2026-01-14T16:30:32.384671", "ingestion_ts": "2026-01-14T16:33:58.842229", "market_id": "0xcab7ba4a9133cfd407d7e73e5757e5abbace413b59421527a31113406c97815c", "raw": {"market": "0xcab7ba4a9133cfd407d7e73e5757e5abbace413b59421527a31113406c97815c", "asset_id": "96361925776989336186111887920533578209326565663637092688733016597062311745569", "price": "0.849", "size": "0", "side": "SELL", "timestamp": "1768404632713", "received_at": "2026-01-14T16:30:32.384671"}}
{"event_type": "price_change", "event_ts": "2026-01-14T16:30:32.416823", "ingestion_ts": "2026-01-14T16:33:58.842229", "market_id": "0xb9bbdd34304344dcc45803780a34c97d73a00133a5ecf70f63e1008b8abb2fca", "raw": {"market": "0xb9bbdd34304344dcc45803780a34c97d73a00133a5ecf70f63e1008b8abb2fca", "asset_id": "8682484153073832526711485265636767086525069344085206423986003504588877767339", "price": "0.576", "size": "3324", "side": "BUY", "timestamp": "1768404632755", "received_at": "2026-01-14T16:30:32.416823"}}
{"event_type": "price_change", "event_ts": "2026-01-14T16:30:32.416823", "ingestion_ts": "2026-01-14T16:33:58.842229", "market_id": "0xb9bbdd34304344dcc45803780a34c97d73a00133a5ecf70f63e1008b8abb2fca", "raw": {"market": "0xb9bbdd34304344dcc45803780a34c97d73a00133a5ecf70f63e1008b8abb2fca", "asset_id": "72012724360700510767037780555710363830014634797787940282136454146828040926557", "price": "0.424", "size": "3324", "side": "SELL", "timestamp": "1768404632755", "received_at": "2026-01-14T16:30:32.416823"}}
{"event_type": "price_change", "event_ts": "2026-01-14T16:30:32.578250", "ingestion_ts": "2026-01-14T16:33:58.842229", "market_id": "0xe6508d867d153a268bdab732aa8abc8cc57e652d28a23aa042da40895bf031b2", "raw": {"market": "0xe6508d867d153a268bdab732aa8abc8cc57e652d28a23aa042da40895bf031b2", "asset_id": "57878493050148425637822780001963685814731344602319345842647239312888833935027", "price": "0.005", "size": "5.9", "side": "BUY", "timestamp": "1768404632911", "received_at": "2026-01-14T16:30:32.578250"}}
{"event_type": "price_change", "event_ts": "2026-01-14T16:30:32.578250", "ingestion_ts": "2026-01-14T16:33:58.842229", "market_id": "0xe6508d867d153a268bdab732aa8abc8cc57e652d28a23aa042da40895bf031b2", "raw": {"market": "0xe6508d867d153a268bdab732aa8abc8cc57e652d28a23aa042da40895bf031b2", "asset_id": "2853768819561879023657600399360829876689515906714535926781067187993853038980", "price": "0.995", "size": "5.9", "side": "SELL", "timestamp": "1768404632911", "received_at": "2026-01-14T16:30:32.578250"}}
{"event_type": "price_change", "event_ts": "2026-01-14T16:30:32.578307", "ingestion_ts": "2026-01-14T16:33:58.842229", "market_id": "0xe6508d867d153a268bdab732aa8abc8cc57e652d28a23aa042da40895bf031b2", "raw": {"market": "0xe6508d867d153a268bdab732aa8abc8cc57e652d28a23aa042da40895bf031b2", "asset_id": "57878493050148425637822780001963685814731344602319345842647239312888833935027", "price": "0.001", "size": "3102380.5", "side": "BUY", "timestamp": "1768404632912", "received_at": "2026-01-14T16:30:32.578307"}}
{"event_type": "price_change", "event_ts": "2026-01-14T16:30:32.578307", "ingestion_ts": "2026-01-14T16:33:58.842229", "market_id": "0xe6508d867d153a268bdab732aa8abc8cc57e652d28a23aa042da40895bf031b2", "raw": {"market": "0xe6508d867d153a268bdab732aa8abc8cc57e652d28a23aa042da40895bf031b2", "asset_id": "2853768819561879023657600399360829876689515906714535926781067187993853038980", "price": "0.999", "size": "3102380.5", "side": "SELL", "timestamp": "1768404632912", "received_at": "2026-01-14T16:30:32.578307"}}
{"event_type": "price_change", "event_ts": "2026-01-14T16:30:32.578323", "ingestion_ts": "2026-01-14T16:33:58.842229", "market_id": "0xe6508d867d153a268bdab732aa8abc8cc57e652d28a23aa042da40895bf031b2", "raw": {"market": "0xe6508d867d153a268bdab732aa8abc8cc57e652d28a23aa042da40895bf031b2", "asset_id": "57878493050148425637822780001963685814731344602319345842647239312888833935027", "price": "0.023", "size": "12.81", "side": "BUY", "timestamp": "1768404632912", "received_at": "2026-01-14T16:30:32.578323"}}
{"event_type": "price_change", "event_ts": "2026-01-14T16:30:32.578323", "ingestion_ts": "2026-01-14T16:33:58.842229", "market_id": "0xe6508d867d153a268bdab732aa8abc8cc57e652d28a23aa042da40895bf031b2", "raw": {"market": "0xe6508d867d153a268bdab732aa8abc8cc57e652d28a23aa042da40895bf031b2", "asset_id": "2853768819561879023657600399360829876689515906714535926781067187993853038980", "price": "0.977", "size": "12.81", "side": "SELL", "timestamp": "1768404632912", "received_at": "2026-01-14T16:30:32.578323"}}
{"event_type": "price_change", "event_ts": "2026-01-14T16:30:32.579920", "ingestion_ts": "2026-01-14T16:33:58.842229", "market_id": "0xe6508d867d153a268bdab732aa8abc8cc57e652d28a23aa042da40895bf031b2", "raw": {"market": "0xe6508d867d153a268bdab732aa8abc8cc57e652d28a23aa042da40895bf031b2", "asset_id": "57878493050148425637822780001963685814731344602319345842647239312888833935027", "price": "0.002", "size": "30257.54", "side": "BUY", "timestamp": "1768404632913", "received_at": "2026-01-14T16:30:32.579920"}}
{"event_type": "price_change", "event_ts": "2026-01-14T16:30:32.579920", "ingestion_ts": "2026-01-14T16:33:58.842229", "market_id": "0xe6508d867d153a268bdab732aa8abc8cc57e652d28a23aa042da40895bf031b2", "raw": {"market": "0xe6508d867d153a268bdab732aa8abc8cc57e652d28a23aa042da40895bf031b2", "asset_id": "2853768819561879023657600399360829876689515906714535926781067187993853038980", "price": "0.998", "size": "30257.54", "side": "SELL", "timestamp": "1768404632913", "received_at": "2026-01-14T16:30:32.579920"}}
{"event_type": "price_change", "event_ts": "2026-01-14T16:30:32.579945", "ingestion_ts": "2026-01-14T16:33:58.842229", "market_id": "0xe6508d867d153a268bdab732aa8abc8cc57e652d28a23aa042da40895bf031b2", "raw": {"market": "0xe6508d867d153a268bdab732aa8abc8cc57e652d28a23aa042da40895bf031b2", "asset_id": "57878493050148425637822780001963685814731344602319345842647239312888833935027", "price": "0.011", "size": "5.13", "side": "BUY", "timestamp": "1768404632914", "received_at": "2026-01-14T16:30:32.579945"}}
{"event_type": "price_change", "event_ts": "2026-01-14T16:30:32.579945", "ingestion_ts": "2026-01-14T16:33:58.842229", "market_id": "0xe6508d867d153a268bdab732aa8abc8cc57e652d28a23aa042da40895bf031b2", "raw": {"market": "0xe6508d867d153a268bdab732aa8abc8cc57e652d28a23aa042da40895bf031b2", "asset_id": "2853768819561879023657600399360829876689515906714535926781067187993853038980", "price": "0.989", "size": "5.13", "side": "SELL", "timestamp": "1768404632914", "received_at": "2026-01-14T16:30:32.579945"}}
{"event_type": "price_change", "event_ts": "2026-01-14T16:30:32.585082", "ingestion_ts": "2026-01-14T16:33:58.842229", "market_id": "0xcab7ba4a9133cfd407d7e73e5757e5abbace413b59421527a31113406c97815c", "raw": {"market": "0xcab7ba4a9133cfd407d7e73e5757e5abbace413b59421527a31113406c97815c", "asset_id": "20002636398944597965698652220992177552927816915094913583821579024925426590022", "price": "0.151", "size": "24.45", "side": "BUY", "timestamp": "1768404632919", "received_at": "2026-01-14T16:30:32.585082"}}
{"event_type": "price_change", "event_ts": "2026-01-14T16:30:32.585082", "ingestion_ts": "2026-01-14T16:33:58.842229", "market_id": "0xcab7ba4a9133cfd407d7e73e5757e5abbace413b59421527a31113406c97815c", "raw": {"market": "0xcab7ba4a9133cfd407d7e73e5757e5abbace413b59421527a31113406c97815c", "asset_id": "96361925776989336186111887920533578209326565663637092688733016597062311745569", "price": "0.849", "size": "24.45", "side": "SELL", "timestamp": "1768404632919", "received_at": "2026-01-14T16:30:32.585082"}}
{"event_type": "price_change", "event_ts": "2026-01-14T16:30:32.667559", "ingestion_ts": "2026-01-14T16:33:58.842229", "market_id": "0xe6508d867d153a268bdab732aa8abc8cc57e652d28a23aa042da40895bf031b2", "raw": {"market": "0xe6508d867d153a268bdab732aa8abc8cc57e652d28a23aa042da40895bf031b2", "asset_id": "57878493050148425637822780001963685814731344602319345842647239312888833935027", "price": "0.231", "size": "0", "side": "BUY", "timestamp": "1768404633001", "received_at": "2026-01-14T16:30:32.667559"}}
{"event_type": "price_change", "event_ts": "2026-01-14T16:30:32.667559", "ingestion_ts": "2026-01-14T16:33:58.842229", "market_id": "0xe6508d867d153a268bdab732aa8abc8cc57e652d28a23aa042da40895bf031b2", "raw": {"market": "0xe6508d867d153a268bdab732aa8abc8cc57e652d28a23aa042da40895bf031b2", "asset_id": "2853768819561879023657600399360829876689515906714535926781067187993853038980", "price": "0.769", "size": "0", "side": "SELL", "timestamp": "1768404633001", "received_at": "2026-01-14T16:30:32.667559"}}
{"event_type": "price_change", "event_ts": "2026-01-14T16:30:32.829762", "ingestion_ts": "2026-01-14T16:33:58.842229", "market_id": "0xcab7ba4a9133cfd407d7e73e5757e5abbace413b59421527a31113406c97815c", "raw": {"market": "0xcab7ba4a9133cfd407d7e73e5757e5abbace413b59421527a31113406c97815c", "asset_id": "20002636398944597965698652220992177552927816915094913583821579024925426590022", "price": "0.171", "size": "21.59", "side": "BUY", "timestamp": "1768404633150", "received_at": "2026-01-14T16:30:32.829762"}}
{"event_type": "price_change", "event_ts": "2026-01-14T16:30:32.829762", "ingestion_ts": "2026-01-14T16:33:58.842229", "market_id": "0xcab7ba4a9133cfd407d7e73e5757e5abbace413b59421527a31113406c97815c", "raw": {"market": "0xcab7ba4a9133cfd407d7e73e5757e5abbace413b59421527a31113406c97815c", "asset_id": "96361925776989336186111887920533578209326565663637092688733016597062311745569", "price": "0.829", "size": "21.59", "side": "SELL", "timestamp": "1768404633150", "received_at": "2026-01-14T16:30:32.829762"}}
{"event_type": "price_change", "event_ts": "2026-01-14T16:30:32.894657", "ingestion_ts": "2026-01-14T16:33:58.842229", "market_id": "0xe6508d867d153a268bdab732aa8abc8cc57e652d28a23aa042da40895bf031b2", "raw": {"market": "0xe6508d867d153a268bdab732aa8abc8cc57e652d28a23aa042da40895bf031b2", "asset_id": "57878493050148425637822780001963685814731344602319345842647239312888833935027", "price": "0.231", "size": "3896.1", "side": "BUY", "timestamp": "1768404633206", "received_at": "2026-01-14T16:30:32.894657"}}
{"event_type": "price_change", "event_ts": "2026-01-14T16:30:32.894657", "ingestion_ts": "2026-01-14T16:33:58.842229", "market_id": "0xe6508d867d153a268bdab732aa8abc8cc57e652d28a23aa042da40895bf031b2", "raw": {"market": "0xe6508d867d153a268bdab732aa8abc8cc57e652d28a23aa042da40895bf031b2", "asset_id": "2853768819561879023657600399360829876689515906714535926781067187993853038980", "price": "0.769", "size": "3896.1", "side": "SELL", "timestamp": "1768404633206", "received_at": "2026-01-14T16:30:32.894657"}}
{"event_type": "price_change", "event_ts": "2026-01-14T16:30:32.991554", "ingestion_ts": "2026-01-14T16:33:58.842229", "market_id": "0xe6508d867d153a268bdab732aa8abc8cc57e652d28a23aa042da40895bf031b2", "raw": {"market": "0xe6508d867d153a268bdab732aa8abc8cc57e652d28a23aa042da40895bf031b2", "asset_id": "57878493050148425637822780001963685814731344602319345842647239312888833935027", "price": "0.101", "size": "5.93", "side": "BUY", "timestamp": "1768404633320", "received_at": "2026-01-14T16:30:32.991554"}}
{"event_type": "price_change", "event_ts": "2026-01-14T16:30:32.991554", "ingestion_ts": "2026-01-14T16:33:58.842229", "market_id": "0xe6508d867d153a268bdab732aa8abc8cc57e652d28a23aa042da40895bf031b2", "raw": {"market": "0xe6508d867d153a268bdab732aa8abc8cc57e652d28a23aa042da40895bf031b2", "asset_id": "2853768819561879023657600399360829876689515906714535926781067187993853038980", "price": "0.899", "size": "5.93", "side": "SELL", "timestamp": "1768404633320", "received_at": "2026-01-14T16:30:32.991554"}}
{"event_type": "price_change", "event_ts": "2026-01-14T16:30:33.066111", "ingestion_ts": "2026-01-14T16:33:58.842229", "market_id": "0xcab7ba4a9133cfd407d7e73e5757e5abbace413b59421527a31113406c97815c", "raw": {"market": "0xcab7ba4a9133cfd407d7e73e5757e5abbace413b59421527a31113406c97815c", "asset_id": "20002636398944597965698652220992177552927816915094913583821579024925426590022", "price": "0.201", "size": "17.05", "side": "BUY", "timestamp": "1768404633405", "received_at": "2026-01-14T16:30:33.066111"}}
{"event_type": "price_change", "event_ts": "2026-01-14T16:30:33.066111", "ingestion_ts": "2026-01-14T16:33:58.842229", "market_id": "0xcab7ba4a9133cfd407d7e73e5757e5abbace413b59421527a31113406c97815c", "raw": {"market": "0xcab7ba4a9133cfd407d7e73e5757e5abbace413b59421527a31113406c97815c", "asset_id": "96361925776989336186111887920533578209326565663637092688733016597062311745569", "price": "0.799", "size": "17.05", "side": "SELL", "timestamp": "1768404633405", "received_at": "2026-01-14T16:30:33.066111"}}
{"event_type": "price_change", "event_ts": "2026-01-14T16:30:33.109063", "ingestion_ts": "2026-01-14T16:33:58.842229", "market_id": "0xcab7ba4a9133cfd407d7e73e5757e5abbace413b59421527a31113406c97815c", "raw": {"market": "0xcab7ba4a9133cfd407d7e73e5757e5abbace413b59421527a31113406c97815c", "asset_id": "20002636398944597965698652220992177552927816915094913583821579024925426590022", "price": "0.103", "size": "100", "side": "BUY", "timestamp": "1768404633447", "received_at": "2026-01-14T16:30:33.109063"}}
{"event_type": "price_change", "event_ts": "2026-01-14T16:30:33.109063", "ingestion_ts": "2026-01-14T16:33:58.842229", "market_id": "0xcab7ba4a9133cfd407d7e73e5757e5abbace413b59421527a31113406c97815c", "raw": {"market": "0xcab7ba4a9133cfd407d7e73e5757e5abbace413b59421527a31113406c97815c", "asset_id": "96361925776989336186111887920533578209326565663637092688733016597062311745569", "price": "0.897", "size": "100", "side": "SELL", "timestamp": "1768404633447", "received_at": "2026-01-14T16:30:33.109063"}}
{"event_type": "price_change", "event_ts": "2026-01-14T16:30:33.270500", "ingestion_ts": "2026-01-14T16:33:58.842229", "market_id": "0xcab7ba4a9133cfd407d7e73e5757e5abbace413b59421527a31113406c97815c", "raw": {"market": "0xcab7ba4a9133cfd407d7e73e5757e5abbace413b59421527a31113406c97815c", "asset_id": "20002636398944597965698652220992177552927816915094913583821579024925426590022", "price": "0.103", "size": "7866.99", "side": "BUY", "timestamp": "1768404633604", "received_at": "2026-01-14T16:30:33.270500"}}
{"event_type": "price_change", "event_ts": "2026-01-14T16:30:33.270500", "ingestion_ts": "2026-01-14T16:33:58.842229", "market_id": "0xcab7ba4a9133cfd407d7e73e5757e5abbace413b59421527a31113406c97815c", "raw": {"market": "0xcab7ba4a9133cfd407d7e73e5757e5abbace413b59421527a31113406c97815c", "asset_id": "96361925776989336186111887920533578209326565663637092688733016597062311745569", "price": "0.897", "size": "7866.99", "side": "SELL", "timestamp": "1768404633604", "received_at": "2026-01-14T16:30:33.270500"}}
{"event_type": "price_change", "event_ts": "2026-01-14T16:30:33.312101", "ingestion_ts": "2026-01-14T16:33:58.842229", "market_id": "0xcab7ba4a9133cfd407d7e73e5757e5abbace413b59421527a31113406c97815c", "raw": {"market": "0xcab7ba4a9133cfd407d7e73e5757e5abbace413b59421527a31113406c97815c", "asset_id": "20002636398944597965698652220992177552927816915094913583821579024925426590022", "price": "0.201", "size": "35.41", "side": "BUY", "timestamp": "1768404633651", "received_at": "2026-01-14T16:30:33.312101"}}
{"event_type": "price_change", "event_ts": "2026-01-14T16:30:33.312101", "ingestion_ts": "2026-01-14T16:33:58.842229", "market_id": "0xcab7ba4a9133cfd407d7e73e5757e5abbace413b59421527a31113406c97815c", "raw": {"market": "0xcab7ba4a9133cfd407d7e73e5757e5abbace413b59421527a31113406c97815c", "asset_id": "96361925776989336186111887920533578209326565663637092688733016597062311745569", "price": "0.799", "size": "35.41", "side": "SELL", "timestamp": "1768404633651", "received_at": "2026-01-14T16:30:33.312101"}}
{"event_type": "price_change", "event_ts": "2026-01-14T16:30:34.335413", "ingestion_ts": "2026-01-14T16:33:58.842229", "market_id": "0xcab7ba4a9133cfd407d7e73e5757e5abbace413b59421527a31113406c97815c", "raw": {"market": "0xcab7ba4a9133cfd407d7e73e5757e5abbace413b59421527a31113406c97815c", "asset_id": "20002636398944597965698652220992177552927816915094913583821579024925426590022", "price": "0.224", "size": "0", "side": "BUY", "timestamp": "1768404633889", "received_at": "2026-01-14T16:30:34.335413"}}
{"event_type": "price_change", "event_ts": "2026-01-14T16:30:34.335413", "ingestion_ts": "2026-01-14T16:33:58.842229", "market_id": "0xcab7ba4a9133cfd407d7e73e5757e5abbace413b59421527a31113406c97815c", "raw": {"market": "0xcab7ba4a9133cfd407d7e73e5757e5abbace413b59421527a31113406c97815c", "asset_id": "96361925776989336186111887920533578209326565663637092688733016597062311745569", "price": "0.776", "size": "0", "side": "SELL", "timestamp": "1768404633889", "received_at": "2026-01-14T16:30:34.335413"}}
{"event_type": "price_change", "event_ts": "2026-01-14T16:30:34.413176", "ingestion_ts": "2026-01-14T16:33:58.842229", "market_id": "0xe9c127a8c35f045d37b5344b0a36711084fa20c2fc1618bf178a5386f90610be", "raw": {"market": "0xe9c127a8c35f045d37b5344b0a36711084fa20c2fc1618bf178a5386f90610be", "asset_id": "107000426448217931795450451304515386602910396776318075817601265223856116134349", "price": "0.362", "size": "0", "side": "BUY", "timestamp": "1768404634016", "received_at": "2026-01-14T16:30:34.413176"}}
{"event_type": "price_change", "event_ts": "2026-01-14T16:30:34.413176", "ingestion_ts": "2026-01-14T16:33:58.842229", "market_id": "0xe9c127a8c35f045d37b5344b0a36711084fa20c2fc1618bf178a5386f90610be", "raw": {"market": "0xe9c127a8c35f045d37b5344b0a36711084fa20c2fc1618bf178a5386f90610be", "asset_id": "80230236018433940569996058935444651347308266584430516013229815570706872276819", "price": "0.638", "size": "0", "side": "SELL", "timestamp": "1768404634016", "received_at": "2026-01-14T16:30:34.413176"}}
{"event_type": "price_change", "event_ts": "2026-01-14T16:30:34.476328", "ingestion_ts": "2026-01-14T16:33:58.842229", "market_id": "0xcab7ba4a9133cfd407d7e73e5757e5abbace413b59421527a31113406c97815c", "raw": {"market": "0xcab7ba4a9133cfd407d7e73e5757e5abbace413b59421527a31113406c97815c", "asset_id": "20002636398944597965698652220992177552927816915094913583821579024925426590022", "price": "0.224", "size": "16.48", "side": "BUY", "timestamp": "1768404634102", "received_at": "2026-01-14T16:30:34.476328"}}
{"event_type": "price_change", "event_ts": "2026-01-14T16:30:34.476328", "ingestion_ts": "2026-01-14T16:33:58.842229", "market_id": "0xcab7ba4a9133cfd407d7e73e5757e5abbace413b59421527a31113406c97815c", "raw": {"market": "0xcab7ba4a9133cfd407d7e73e5757e5abbace413b59421527a31113406c97815c", "asset_id": "96361925776989336186111887920533578209326565663637092688733016597062311745569", "price": "0.776", "size": "16.48", "side": "SELL", "timestamp": "1768404634102", "received_at": "2026-01-14T16:30:34.476328"}}
{"event_type": "price_change", "event_ts": "2026-01-14T16:30:34.522026", "ingestion_ts": "2026-01-14T16:33:58.842229", "market_id": "0xe9c127a8c35f045d37b5344b0a36711084fa20c2fc1618bf178a5386f90610be", "raw": {"market": "0xe9c127a8c35f045d37b5344b0a36711084fa20c2fc1618bf178a5386f90610be", "asset_id": "107000426448217931795450451304515386602910396776318075817601265223856116134349", "price": "0.362", "size": "4972.37", "side": "BUY", "timestamp": "1768404634203", "received_at": "2026-01-14T16:30:34.522026"}}
{"event_type": "price_change", "event_ts": "2026-01-14T16:30:34.522026", "ingestion_ts": "2026-01-14T16:33:58.842229", "market_id": "0xe9c127a8c35f045d37b5344b0a36711084fa20c2fc1618bf178a5386f90610be", "raw": {"market": "0xe9c127a8c35f045d37b5344b0a36711084fa20c2fc1618bf178a5386f90610be", "asset_id": "80230236018433940569996058935444651347308266584430516013229815570706872276819", "price": "0.638", "size": "4972.37", "side": "SELL", "timestamp": "1768404634203", "received_at": "2026-01-14T16:30:34.522026"}}
{"event_type": "price_change", "event_ts": "2026-01-14T16:30:34.734495", "ingestion_ts": "2026-01-14T16:33:58.842229", "market_id": "0xcab7ba4a9133cfd407d7e73e5757e5abbace413b59421527a31113406c97815c", "raw": {"market": "0xcab7ba4a9133cfd407d7e73e5757e5abbace413b59421527a31113406c97815c", "asset_id": "20002636398944597965698652220992177552927816915094913583821579024925426590022", "price": "0.256", "size": "14.42", "side": "BUY", "timestamp": "1768404634328", "received_at": "2026-01-14T16:30:34.734495"}}
{"event_type": "price_change", "event_ts": "2026-01-14T16:30:34.734495", "ingestion_ts": "2026-01-14T16:33:58.842229", "market_id": "0xcab7ba4a9133cfd407d7e73e5757e5abbace413b59421527a31113406c97815c", "raw": {"market": "0xcab7ba4a9133cfd407d7e73e5757e5abbace413b59421527a31113406c97815c", "asset_id": "96361925776989336186111887920533578209326565663637092688733016597062311745569", "price": "0.744", "size": "14.42", "side": "SELL", "timestamp": "1768404634328", "received_at": "2026-01-14T16:30:34.734495"}}
{"event_type": "price_change", "event_ts": "2026-01-14T16:30:34.823067", "ingestion_ts": "2026-01-14T16:33:58.842229", "market_id": "0xcab7ba4a9133cfd407d7e73e5757e5abbace413b59421527a31113406c97815c", "raw": {"market": "0xcab7ba4a9133cfd407d7e73e5757e5abbace413b59421527a31113406c97815c", "asset_id": "20002636398944597965698652220992177552927816915094913583821579024925426590022", "price": "0.3", "size": "59.91", "side": "BUY", "timestamp": "1768404634541", "received_at": "2026-01-14T16:30:34.823067"}}
{"event_type": "price_change", "event_ts": "2026-01-14T16:30:34.823067", "ingestion_ts": "2026-01-14T16:33:58.842229", "market_id": "0xcab7ba4a9133cfd407d7e73e5757e5abbace413b59421527a31113406c97815c", "raw": {"market": "0xcab7ba4a9133cfd407d7e73e5757e5abbace413b59421527a31113406c97815c", "asset_id": "96361925776989336186111887920533578209326565663637092688733016597062311745569", "price": "0.7", "size": "59.91", "side": "SELL", "timestamp": "1768404634541", "received_at": "2026-01-14T16:30:34.823067"}}
{"event_type": "price_change", "event_ts": "2026-01-14T16:30:34.960770", "ingestion_ts": "2026-01-14T16:33:58.842229", "market_id": "0xcab7ba4a9133cfd407d7e73e5757e5abbace413b59421527a31113406c97815c", "raw": {"market": "0xcab7ba4a9133cfd407d7e73e5757e5abbace413b59421527a31113406c97815c", "asset_id": "20002636398944597965698652220992177552927816915094913583821579024925426590022", "price": "0.4", "size": "44.94", "side": "BUY", "timestamp": "1768404634800", "received_at": "2026-01-14T16:30:34.960770"}}
{"event_type": "price_change", "event_ts": "2026-01-14T16:30:34.960770", "ingestion_ts": "2026-01-14T16:33:58.842229", "market_id": "0xcab7ba4a9133cfd407d7e73e5757e5abbace413b59421527a31113406c97815c", "raw": {"market": "0xcab7ba4a9133cfd407d7e73e5757e5abbace413b59421527a31113406c97815c", "asset_id": "96361925776989336186111887920533578209326565663637092688733016597062311745569", "price": "0.6", "size": "44.94", "side": "SELL", "timestamp": "1768404634800", "received_at": "2026-01-14T16:30:34.960770"}}
{"event_type": "price_change", "event_ts": "2026-01-14T16:30:35.082084", "ingestion_ts": "2026-01-14T16:33:58.842229", "market_id": "0xcab7ba4a9133cfd407d7e73e5757e5abbace413b59421527a31113406c97815c", "raw": {"market": "0xcab7ba4a9133cfd407d7e73e5757e5abbace413b59421527a31113406c97815c", "asset_id": "20002636398944597965698652220992177552927816915094913583821579024925426590022", "price": "0.479", "size": "7.7", "side": "BUY", "timestamp": "1768404635002", "received_at": "2026-01-14T16:30:35.082084"}}
{"event_type": "price_change", "event_ts": "2026-01-14T16:30:35.082084", "ingestion_ts": "2026-01-14T16:33:58.842229", "market_id": "0xcab7ba4a9133cfd407d7e73e5757e5abbace413b59421527a31113406c97815c", "raw": {"market": "0xcab7ba4a9133cfd407d7e73e5757e5abbace413b59421527a31113406c97815c", "asset_id": "96361925776989336186111887920533578209326565663637092688733016597062311745569", "price": "0.521", "size": "7.7", "side": "SELL", "timestamp": "1768404635002", "received_at": "2026-01-14T16:30:35.082084"}}
{"event_type": "price_change", "event_ts": "2026-01-14T16:30:35.208890", "ingestion_ts": "2026-01-14T16:33:58.842229", "market_id": "0xe9c127a8c35f045d37b5344b0a36711084fa20c2fc1618bf178a5386f90610be", "raw": {"market": "0xe9c127a8c35f045d37b5344b0a36711084fa20c2fc1618bf178a5386f90610be", "asset_id": "107000426448217931795450451304515386602910396776318075817601265223856116134349", "price": "0.5", "size": "11.85", "side": "BUY", "timestamp": "1768404635222", "received_at": "2026-01-14T16:30:35.208890"}}
{"event_type": "price_change", "event_ts": "2026-01-14T16:30:35.208890", "ingestion_ts": "2026-01-14T16:33:58.842229", "market_id": "0xe9c127a8c35f045d37b5344b0a36711084fa20c2fc1618bf178a5386f90610be", "raw": {"market": "0xe9c127a8c35f045d37b5344b0a36711084fa20c2fc1618bf178a5386f90610be", "asset_id": "80230236018433940569996058935444651347308266584430516013229815570706872276819", "price": "0.5", "size": "11.85", "side": "SELL", "timestamp": "1768404635222", "received_at": "2026-01-14T16:30:35.208890"}}
{"event_type": "price_change", "event_ts": "2026-01-14T16:30:35.420844", "ingestion_ts": "2026-01-14T16:33:58.842229", "market_id": "0xe9c127a8c35f045d37b5344b0a36711084fa20c2fc1618bf178a5386f90610be", "raw": {"market": "0xe9c127a8c35f045d37b5344b0a36711084fa20c2fc1618bf178a5386f90610be", "asset_id": "107000426448217931795450451304515386602910396776318075817601265223856116134349", "price": "0.4", "size": "35.71", "side": "BUY", "timestamp": "1768404635432", "received_at": "2026-01-14T16:30:35.420844"}}
{"event_type": "price_change", "event_ts": "2026-01-14T16:30:35.420844", "ingestion_ts": "2026-01-14T16:33:58.842229", "market_id": "0xe9c127a8c35f045d37b5344b0a36711084fa20c2fc1618bf178a5386f90610be", "raw": {"market": "0xe9c127a8c35f045d37b5344b0a36711084fa20c2fc1618bf178a5386f90610be", "asset_id": "80230236018433940569996058935444651347308266584430516013229815570706872276819", "price": "0.6", "size": "35.71", "side": "SELL", "timestamp": "1768404635432", "received_at": "2026-01-14T16:30:35.420844"}}
{"event_type": "price_change", "event_ts": "2026-01-14T16:30:35.607216", "ingestion_ts": "2026-01-14T16:33:58.842229", "market_id": "0xe9c127a8c35f045d37b5344b0a36711084fa20c2fc1618bf178a5386f90610be", "raw": {"market": "0xe9c127a8c35f045d37b5344b0a36711084fa20c2fc1618bf178a5386f90610be", "asset_id": "107000426448217931795450451304515386602910396776318075817601265223856116134349", "price": "0.3", "size": "47.61", "side": "BUY", "timestamp": "1768404635628", "received_at": "2026-01-14T16:30:35.607216"}}
{"event_type": "price_change", "event_ts": "2026-01-14T16:30:35.607216", "ingestion_ts": "2026-01-14T16:33:58.842229", "market_id": "0xe9c127a8c35f045d37b5344b0a36711084fa20c2fc1618bf178a5386f90610be", "raw": {"market": "0xe9c127a8c35f045d37b5344b0a36711084fa20c2fc1618bf178a5386f90610be", "asset_id": "80230236018433940569996058935444651347308266584430516013229815570706872276819", "price": "0.7", "size": "47.61", "side": "SELL", "timestamp": "1768404635628", "received_at": "2026-01-14T16:30:35.607216"}}
{"event_type": "price_change", "event_ts": "2026-01-14T16:30:35.734131", "ingestion_ts": "2026-01-14T16:33:58.842229", "market_id": "0xe9c127a8c35f045d37b5344b0a36711084fa20c2fc1618bf178a5386f90610be", "raw": {"market": "0xe9c127a8c35f045d37b5344b0a36711084fa20c2fc1618bf178a5386f90610be", "asset_id": "107000426448217931795450451304515386602910396776318075817601265223856116134349", "price": "0.256", "size": "0", "side": "BUY", "timestamp": "1768404635854", "received_at": "2026-01-14T16:30:35.734131"}}
{"event_type": "price_change", "event_ts": "2026-01-14T16:30:35.734131", "ingestion_ts": "2026-01-14T16:33:58.842229", "market_id": "0xe9c127a8c35f045d37b5344b0a36711084fa20c2fc1618bf178a5386f90610be", "raw": {"market": "0xe9c127a8c35f045d37b5344b0a36711084fa20c2fc1618bf178a5386f90610be", "asset_id": "80230236018433940569996058935444651347308266584430516013229815570706872276819", "price": "0.744", "size": "0", "side": "SELL", "timestamp": "1768404635854", "received_at": "2026-01-14T16:30:35.734131"}}
{"event_type": "price_change", "event_ts": "2026-01-14T16:30:35.836583", "ingestion_ts": "2026-01-14T16:33:58.842229", "market_id": "0xc0e6b917320a47228fb96e3b5ae0e5c93773a5ae2662ae4e1f37807cfe47ce98", "raw": {"market": "0xc0e6b917320a47228fb96e3b5ae0e5c93773a5ae2662ae4e1f37807cfe47ce98", "asset_id": "58656358377246279051017109359677190749228949103591068167284263961542487110215", "price": "0.002", "size": "3305.07", "side": "BUY", "timestamp": "1768404636002", "received_at": "2026-01-14T16:30:35.836583"}}
{"event_type": "price_change", "event_ts": "2026-01-14T16:30:35.836583", "ingestion_ts": "2026-01-14T16:33:58.842229", "market_id": "0xc0e6b917320a47228fb96e3b5ae0e5c93773a5ae2662ae4e1f37807cfe47ce98", "raw": {"market": "0xc0e6b917320a47228fb96e3b5ae0e5c93773a5ae2662ae4e1f37807cfe47ce98", "asset_id": "81647294538046680798858716589766492074338758116170717123345952330712416337530", "price": "0.998", "size": "3305.07", "side": "SELL", "timestamp": "1768404636002", "received_at": "2026-01-14T16:30:35.836583"}}
{"event_type": "price_change", "event_ts": "2026-01-14T16:30:35.877029", "ingestion_ts": "2026-01-14T16:33:58.842229", "market_id": "0xe9c127a8c35f045d37b5344b0a36711084fa20c2fc1618bf178a5386f90610be", "raw": {"market": "0xe9c127a8c35f045d37b5344b0a36711084fa20c2fc1618bf178a5386f90610be", "asset_id": "107000426448217931795450451304515386602910396776318075817601265223856116134349", "price": "0.214", "size": "0", "side": "BUY", "timestamp": "1768404636058", "received_at": "2026-01-14T16:30:35.877029"}}
{"event_type": "price_change", "event_ts": "2026-01-14T16:30:35.877029", "ingestion_ts": "2026-01-14T16:33:58.842229", "market_id": "0xe9c127a8c35f045d37b5344b0a36711084fa20c2fc1618bf178a5386f90610be", "raw": {"market": "0xe9c127a8c35f045d37b5344b0a36711084fa20c2fc1618bf178a5386f90610be", "asset_id": "80230236018433940569996058935444651347308266584430516013229815570706872276819", "price": "0.786", "size": "0", "side": "SELL", "timestamp": "1768404636058", "received_at": "2026-01-14T16:30:35.877029"}}
{"event_type": "price_change", "event_ts": "2026-01-14T16:30:35.997490", "ingestion_ts": "2026-01-14T16:33:58.842229", "market_id": "0xe9c127a8c35f045d37b5344b0a36711084fa20c2fc1618bf178a5386f90610be", "raw": {"market": "0xe9c127a8c35f045d37b5344b0a36711084fa20c2fc1618bf178a5386f90610be", "asset_id": "107000426448217931795450451304515386602910396776318075817601265223856116134349", "price": "0.177", "size": "0", "side": "BUY", "timestamp": "1768404636265", "received_at": "2026-01-14T16:30:35.997490"}}
{"event_type": "price_change", "event_ts": "2026-01-14T16:30:35.997490", "ingestion_ts": "2026-01-14T16:33:58.842229", "market_id": "0xe9c127a8c35f045d37b5344b0a36711084fa20c2fc1618bf178a5386f90610be", "raw": {"market": "0xe9c127a8c35f045d37b5344b0a36711084fa20c2fc1618bf178a5386f90610be", "asset_id": "80230236018433940569996058935444651347308266584430516013229815570706872276819", "price": "0.823", "size": "0", "side": "SELL", "timestamp": "1768404636265", "received_at": "2026-01-14T16:30:35.997490"}}
{"event_type": "price_change", "event_ts": "2026-01-14T16:30:36.225669", "ingestion_ts": "2026-01-14T16:33:58.842229", "market_id": "0xe9c127a8c35f045d37b5344b0a36711084fa20c2fc1618bf178a5386f90610be", "raw": {"market": "0xe9c127a8c35f045d37b5344b0a36711084fa20c2fc1618bf178a5386f90610be", "asset_id": "107000426448217931795450451304515386602910396776318075817601265223856116134349", "price": "0.115", "size": "0", "side": "BUY", "timestamp": "1768404636513", "received_at": "2026-01-14T16:30:36.225669"}}
{"event_type": "price_change", "event_ts": "2026-01-14T16:30:36.225669", "ingestion_ts": "2026-01-14T16:33:58.842229", "market_id": "0xe9c127a8c35f045d37b5344b0a36711084fa20c2fc1618bf178a5386f90610be", "raw": {"market": "0xe9c127a8c35f045d37b5344b0a36711084fa20c2fc1618bf178a5386f90610be", "asset_id": "80230236018433940569996058935444651347308266584430516013229815570706872276819", "price": "0.885", "size": "0", "side": "SELL", "timestamp": "1768404636513", "received_at": "2026-01-14T16:30:36.225669"}}
{"event_type": "price_change", "event_ts": "2026-01-14T16:30:36.402492", "ingestion_ts": "2026-01-14T16:33:58.842229", "market_id": "0x49686d26fb712515cd5e12c23f0a1c7e10214c7faa3cb0a730aabe0c33694082", "raw": {"market": "0x49686d26fb712515cd5e12c23f0a1c7e10214c7faa3cb0a730aabe0c33694082", "asset_id": "30442780799048074404860985387051749017905070253466005720364298335239299761065", "price": "0.096", "size": "50", "side": "BUY", "timestamp": "1768404636679", "received_at": "2026-01-14T16:30:36.402492"}}
{"event_type": "price_change", "event_ts": "2026-01-14T16:30:36.402492", "ingestion_ts": "2026-01-14T16:33:58.842229", "market_id": "0x49686d26fb712515cd5e12c23f0a1c7e10214c7faa3cb0a730aabe0c33694082", "raw": {"market": "0x49686d26fb712515cd5e12c23f0a1c7e10214c7faa3cb0a730aabe0c33694082", "asset_id": "13244681086321087932946246027856416106585284024824496763706748621681543444582", "price": "0.904", "size": "50", "side": "SELL", "timestamp": "1768404636679", "received_at": "2026-01-14T16:30:36.402492"}}
{"event_type": "price_change", "event_ts": "2026-01-14T16:30:36.439606", "ingestion_ts": "2026-01-14T16:33:58.842229", "market_id": "0x49686d26fb712515cd5e12c23f0a1c7e10214c7faa3cb0a730aabe0c33694082", "raw": {"market": "0x49686d26fb712515cd5e12c23f0a1c7e10214c7faa3cb0a730aabe0c33694082", "asset_id": "13244681086321087932946246027856416106585284024824496763706748621681543444582", "price": "0.905", "size": "0", "side": "SELL", "timestamp": "1768404636740", "received_at": "2026-01-14T16:30:36.439606"}}
{"event_type": "price_change", "event_ts": "2026-01-14T16:30:36.439606", "ingestion_ts": "2026-01-14T16:33:58.842229", "market_id": "0x49686d26fb712515cd5e12c23f0a1c7e10214c7faa3cb0a730aabe0c33694082", "raw": {"market": "0x49686d26fb712515cd5e12c23f0a1c7e10214c7faa3cb0a730aabe0c33694082", "asset_id": "30442780799048074404860985387051749017905070253466005720364298335239299761065", "price": "0.095", "size": "0", "side": "BUY", "timestamp": "1768404636740", "received_at": "2026-01-14T16:30:36.439606"}}
{"event_type": "price_change", "event_ts": "2026-01-14T16:30:36.460984", "ingestion_ts": "2026-01-14T16:33:58.842229", "market_id": "0xe9c127a8c35f045d37b5344b0a36711084fa20c2fc1618bf178a5386f90610be", "raw": {"market": "0xe9c127a8c35f045d37b5344b0a36711084fa20c2fc1618bf178a5386f90610be", "asset_id": "107000426448217931795450451304515386602910396776318075817601265223856116134349", "price": "0.107", "size": "0", "side": "BUY", "timestamp": "1768404636758", "received_at": "2026-01-14T16:30:36.460984"}}
{"event_type": "price_change", "event_ts": "2026-01-14T16:30:36.460984", "ingestion_ts": "2026-01-14T16:33:58.842229", "market_id": "0xe9c127a8c35f045d37b5344b0a36711084fa20c2fc1618bf178a5386f90610be", "raw": {"market": "0xe9c127a8c35f045d37b5344b0a36711084fa20c2fc1618bf178a5386f90610be", "asset_id": "80230236018433940569996058935444651347308266584430516013229815570706872276819", "price": "0.893", "size": "0", "side": "SELL", "timestamp": "1768404636758", "received_at": "2026-01-14T16:30:36.460984"}}
{"event_type": "price_change", "event_ts": "2026-01-14T16:30:36.475507", "ingestion_ts": "2026-01-14T16:33:58.842229", "market_id": "0x49686d26fb712515cd5e12c23f0a1c7e10214c7faa3cb0a730aabe0c33694082", "raw": {"market": "0x49686d26fb712515cd5e12c23f0a1c7e10214c7faa3cb0a730aabe0c33694082", "asset_id": "13244681086321087932946246027856416106585284024824496763706748621681543444582", "price": "0.899", "size": "123", "side": "SELL", "timestamp": "1768404636769", "received_at": "2026-01-14T16:30:36.475507"}}
{"event_type": "price_change", "event_ts": "2026-01-14T16:30:36.475507", "ingestion_ts": "2026-01-14T16:33:58.842229", "market_id": "0x49686d26fb712515cd5e12c23f0a1c7e10214c7faa3cb0a730aabe0c33694082", "raw": {"market": "0x49686d26fb712515cd5e12c23f0a1c7e10214c7faa3cb0a730aabe0c33694082", "asset_id": "30442780799048074404860985387051749017905070253466005720364298335239299761065", "price": "0.101", "size": "123", "side": "BUY", "timestamp": "1768404636769", "received_at": "2026-01-14T16:30:36.475507"}}
{"event_type": "price_change", "event_ts": "2026-01-14T16:30:36.658294", "ingestion_ts": "2026-01-14T16:33:58.842229", "market_id": "0xe9c127a8c35f045d37b5344b0a36711084fa20c2fc1618bf178a5386f90610be", "raw": {"market": "0xe9c127a8c35f045d37b5344b0a36711084fa20c2fc1618bf178a5386f90610be", "asset_id": "107000426448217931795450451304515386602910396776318075817601265223856116134349", "price": "0.057", "size": "0", "side": "BUY", "timestamp": "1768404636992", "received_at": "2026-01-14T16:30:36.658294"}}
{"event_type": "price_change", "event_ts": "2026-01-14T16:30:36.658294", "ingestion_ts": "2026-01-14T16:33:58.842229", "market_id": "0xe9c127a8c35f045d37b5344b0a36711084fa20c2fc1618bf178a5386f90610be", "raw": {"market": "0xe9c127a8c35f045d37b5344b0a36711084fa20c2fc1618bf178a5386f90610be", "asset_id": "80230236018433940569996058935444651347308266584430516013229815570706872276819", "price": "0.943", "size": "0", "side": "SELL", "timestamp": "1768404636992", "received_at": "2026-01-14T16:30:36.658294"}}
{"event_type": "price_change", "event_ts": "2026-01-14T16:30:36.679712", "ingestion_ts": "2026-01-14T16:33:58.842229", "market_id": "0x49686d26fb712515cd5e12c23f0a1c7e10214c7faa3cb0a730aabe0c33694082", "raw": {"market": "0x49686d26fb712515cd5e12c23f0a1c7e10214c7faa3cb0a730aabe0c33694082", "asset_id": "30442780799048074404860985387051749017905070253466005720364298335239299761065", "price": "0.094", "size": "0", "side": "BUY", "timestamp": "1768404637009", "received_at": "2026-01-14T16:30:36.679712"}}
{"event_type": "price_change", "event_ts": "2026-01-14T16:30:36.679712", "ingestion_ts": "2026-01-14T16:33:58.842229", "market_id": "0x49686d26fb712515cd5e12c23f0a1c7e10214c7faa3cb0a730aabe0c33694082", "raw": {"market": "0x49686d26fb712515cd5e12c23f0a1c7e10214c7faa3cb0a730aabe0c33694082", "asset_id": "13244681086321087932946246027856416106585284024824496763706748621681543444582", "price": "0.906", "size": "0", "side": "SELL", "timestamp": "1768404637009", "received_at": "2026-01-14T16:30:36.679712"}}
{"event_type": "price_change", "event_ts": "2026-01-14T16:30:36.843080", "ingestion_ts": "2026-01-14T16:33:58.842229", "market_id": "0xe9c127a8c35f045d37b5344b0a36711084fa20c2fc1618bf178a5386f90610be", "raw": {"market": "0xe9c127a8c35f045d37b5344b0a36711084fa20c2fc1618bf178a5386f90610be", "asset_id": "107000426448217931795450451304515386602910396776318075817601265223856116134349", "price": "0.034", "size": "0", "side": "BUY", "timestamp": "1768404637181", "received_at": "2026-01-14T16:30:36.843080"}}
{"event_type": "price_change", "event_ts": "2026-01-14T16:30:36.843080", "ingestion_ts": "2026-01-14T16:33:58.842229", "market_id": "0xe9c127a8c35f045d37b5344b0a36711084fa20c2fc1618bf178a5386f90610be", "raw": {"market": "0xe9c127a8c35f045d37b5344b0a36711084fa20c2fc1618bf178a5386f90610be", "asset_id": "80230236018433940569996058935444651347308266584430516013229815570706872276819", "price": "0.966", "size": "0", "side": "SELL", "timestamp": "1768404637181", "received_at": "2026-01-14T16:30:36.843080"}}
{"event_type": "price_change", "event_ts": "2026-01-14T16:30:37.069938", "ingestion_ts": "2026-01-14T16:33:58.842229", "market_id": "0xe9c127a8c35f045d37b5344b0a36711084fa20c2fc1618bf178a5386f90610be", "raw": {"market": "0xe9c127a8c35f045d37b5344b0a36711084fa20c2fc1618bf178a5386f90610be", "asset_id": "107000426448217931795450451304515386602910396776318075817601265223856116134349", "price": "0.022", "size": "0", "side": "BUY", "timestamp": "1768404637380", "received_at": "2026-01-14T16:30:37.069938"}}
{"event_type": "price_change", "event_ts": "2026-01-14T16:30:37.069938", "ingestion_ts": "2026-01-14T16:33:58.842229", "market_id": "0xe9c127a8c35f045d37b5344b0a36711084fa20c2fc1618bf178a5386f90610be", "raw": {"market": "0xe9c127a8c35f045d37b5344b0a36711084fa20c2fc1618bf178a5386f90610be", "asset_id": "80230236018433940569996058935444651347308266584430516013229815570706872276819", "price": "0.978", "size": "0", "side": "SELL", "timestamp": "1768404637380", "received_at": "2026-01-14T16:30:37.069938"}}
{"event_type": "price_change", "event_ts": "2026-01-14T16:30:37.355778", "ingestion_ts": "2026-01-14T16:33:58.842229", "market_id": "0xe9c127a8c35f045d37b5344b0a36711084fa20c2fc1618bf178a5386f90610be", "raw": {"market": "0xe9c127a8c35f045d37b5344b0a36711084fa20c2fc1618bf178a5386f90610be", "asset_id": "107000426448217931795450451304515386602910396776318075817601265223856116134349", "price": "0.022", "size": "167.83", "side": "BUY", "timestamp": "1768404637656", "received_at": "2026-01-14T16:30:37.355778"}}
{"event_type": "price_change", "event_ts": "2026-01-14T16:30:37.355778", "ingestion_ts": "2026-01-14T16:33:58.842229", "market_id": "0xe9c127a8c35f045d37b5344b0a36711084fa20c2fc1618bf178a5386f90610be", "raw": {"market": "0xe9c127a8c35f045d37b5344b0a36711084fa20c2fc1618bf178a5386f90610be", "asset_id": "80230236018433940569996058935444651347308266584430516013229815570706872276819", "price": "0.978", "size": "167.83", "side": "SELL", "timestamp": "1768404637656", "received_at": "2026-01-14T16:30:37.355778"}}
{"event_type": "price_change", "event_ts": "2026-01-14T16:30:37.560924", "ingestion_ts": "2026-01-14T16:33:58.842229", "market_id": "0xe9c127a8c35f045d37b5344b0a36711084fa20c2fc1618bf178a5386f90610be", "raw": {"market": "0xe9c127a8c35f045d37b5344b0a36711084fa20c2fc1618bf178a5386f90610be", "asset_id": "107000426448217931795450451304515386602910396776318075817601265223856116134349", "price": "0.036", "size": "102.56", "side": "BUY", "timestamp": "1768404637899", "received_at": "2026-01-14T16:30:37.560924"}}
{"event_type": "price_change", "event_ts": "2026-01-14T16:30:37.560924", "ingestion_ts": "2026-01-14T16:33:58.842229", "market_id": "0xe9c127a8c35f045d37b5344b0a36711084fa20c2fc1618bf178a5386f90610be", "raw": {"market": "0xe9c127a8c35f045d37b5344b0a36711084fa20c2fc1618bf178a5386f90610be", "asset_id": "80230236018433940569996058935444651347308266584430516013229815570706872276819", "price": "0.964", "size": "102.56", "side": "SELL", "timestamp": "1768404637899", "received_at": "2026-01-14T16:30:37.560924"}}
{"event_type": "price_change", "event_ts": "2026-01-14T16:30:37.804204", "ingestion_ts": "2026-01-14T16:33:58.842229", "market_id": "0xe9c127a8c35f045d37b5344b0a36711084fa20c2fc1618bf178a5386f90610be", "raw": {"market": "0xe9c127a8c35f045d37b5344b0a36711084fa20c2fc1618bf178a5386f90610be", "asset_id": "107000426448217931795450451304515386602910396776318075817601265223856116134349", "price": "0.059", "size": "62.58", "side": "BUY", "timestamp": "1768404638132", "received_at": "2026-01-14T16:30:37.804204"}}
{"event_type": "price_change", "event_ts": "2026-01-14T16:30:37.804204", "ingestion_ts": "2026-01-14T16:33:58.842229", "market_id": "0xe9c127a8c35f045d37b5344b0a36711084fa20c2fc1618bf178a5386f90610be", "raw": {"market": "0xe9c127a8c35f045d37b5344b0a36711084fa20c2fc1618bf178a5386f90610be", "asset_id": "80230236018433940569996058935444651347308266584430516013229815570706872276819", "price": "0.941", "size": "62.58", "side": "SELL", "timestamp": "1768404638132", "received_at": "2026-01-14T16:30:37.804204"}}
{"event_type": "price_change", "event_ts": "2026-01-14T16:30:38.020742", "ingestion_ts": "2026-01-14T16:33:58.842229", "market_id": "0xe9c127a8c35f045d37b5344b0a36711084fa20c2fc1618bf178a5386f90610be", "raw": {"market": "0xe9c127a8c35f045d37b5344b0a36711084fa20c2fc1618bf178a5386f90610be", "asset_id": "107000426448217931795450451304515386602910396776318075817601265223856116134349", "price": "0.108", "size": "65.92", "side": "BUY", "timestamp": "1768404638350", "received_at": "2026-01-14T16:30:38.020742"}}
{"event_type": "price_change", "event_ts": "2026-01-14T16:30:38.020742", "ingestion_ts": "2026-01-14T16:33:58.842229", "market_id": "0xe9c127a8c35f045d37b5344b0a36711084fa20c2fc1618bf178a5386f90610be", "raw": {"market": "0xe9c127a8c35f045d37b5344b0a36711084fa20c2fc1618bf178a5386f90610be", "asset_id": "80230236018433940569996058935444651347308266584430516013229815570706872276819", "price": "0.892", "size": "65.92", "side": "SELL", "timestamp": "1768404638350", "received_at": "2026-01-14T16:30:38.020742"}}
{"event_type": "price_change", "event_ts": "2026-01-14T16:30:38.222573", "ingestion_ts": "2026-01-14T16:33:58.842229", "market_id": "0xe9c127a8c35f045d37b5344b0a36711084fa20c2fc1618bf178a5386f90610be", "raw": {"market": "0xe9c127a8c35f045d37b5344b0a36711084fa20c2fc1618bf178a5386f90610be", "asset_id": "107000426448217931795450451304515386602910396776318075817601265223856116134349", "price": "0.117", "size": "31.55", "side": "BUY", "timestamp": "1768404638561", "received_at": "2026-01-14T16:30:38.222573"}}
{"event_type": "price_change", "event_ts": "2026-01-14T16:30:38.222573", "ingestion_ts": "2026-01-14T16:33:58.842229", "market_id": "0xe9c127a8c35f045d37b5344b0a36711084fa20c2fc1618bf178a5386f90610be", "raw": {"market": "0xe9c127a8c35f045d37b5344b0a36711084fa20c2fc1618bf178a5386f90610be", "asset_id": "80230236018433940569996058935444651347308266584430516013229815570706872276819", "price": "0.883", "size": "31.55", "side": "SELL", "timestamp": "1768404638561", "received_at": "2026-01-14T16:30:38.222573"}}
{"event_type": "price_change", "event_ts": "2026-01-14T16:30:38.425156", "ingestion_ts": "2026-01-14T16:33:58.842229", "market_id": "0xe9c127a8c35f045d37b5344b0a36711084fa20c2fc1618bf178a5386f90610be", "raw": {"market": "0xe9c127a8c35f045d37b5344b0a36711084fa20c2fc1618bf178a5386f90610be", "asset_id": "107000426448217931795450451304515386602910396776318075817601265223856116134349", "price": "0.151", "size": "0", "side": "BUY", "timestamp": "1768404638761", "received_at": "2026-01-14T16:30:38.425156"}}
{"event_type": "price_change", "event_ts": "2026-01-14T16:30:38.425156", "ingestion_ts": "2026-01-14T16:33:58.842229", "market_id": "0xe9c127a8c35f045d37b5344b0a36711084fa20c2fc1618bf178a5386f90610be", "raw": {"market": "0xe9c127a8c35f045d37b5344b0a36711084fa20c2fc1618bf178a5386f90610be", "asset_id": "80230236018433940569996058935444651347308266584430516013229815570706872276819", "price": "0.849", "size": "0", "side": "SELL", "timestamp": "1768404638761", "received_at": "2026-01-14T16:30:38.425156"}}
{"event_type": "price_change", "event_ts": "2026-01-14T16:30:38.660088", "ingestion_ts": "2026-01-14T16:33:58.842229", "market_id": "0xe9c127a8c35f045d37b5344b0a36711084fa20c2fc1618bf178a5386f90610be", "raw": {"market": "0xe9c127a8c35f045d37b5344b0a36711084fa20c2fc1618bf178a5386f90610be", "asset_id": "107000426448217931795450451304515386602910396776318075817601265223856116134349", "price": "0.151", "size": "24.45", "side": "BUY", "timestamp": "1768404638996", "received_at": "2026-01-14T16:30:38.660088"}}
{"event_type": "price_change", "event_ts": "2026-01-14T16:30:38.660088", "ingestion_ts": "2026-01-14T16:33:58.842229", "market_id": "0xe9c127a8c35f045d37b5344b0a36711084fa20c2fc1618bf178a5386f90610be", "raw": {"market": "0xe9c127a8c35f045d37b5344b0a36711084fa20c2fc1618bf178a5386f90610be", "asset_id": "80230236018433940569996058935444651347308266584430516013229815570706872276819", "price": "0.849", "size": "24.45", "side": "SELL", "timestamp": "1768404638996", "received_at": "2026-01-14T16:30:38.660088"}}
{"event_type": "price_change", "event_ts": "2026-01-14T16:30:38.879979", "ingestion_ts": "2026-01-14T16:33:58.842229", "market_id": "0xe9c127a8c35f045d37b5344b0a36711084fa20c2fc1618bf178a5386f90610be", "raw": {"market": "0xe9c127a8c35f045d37b5344b0a36711084fa20c2fc1618bf178a5386f90610be", "asset_id": "107000426448217931795450451304515386602910396776318075817601265223856116134349", "price": "0.179", "size": "20.62", "side": "BUY", "timestamp": "1768404639216", "received_at": "2026-01-14T16:30:38.879979"}}
{"event_type": "price_change", "event_ts": "2026-01-14T16:30:38.879979", "ingestion_ts": "2026-01-14T16:33:58.842229", "market_id": "0xe9c127a8c35f045d37b5344b0a36711084fa20c2fc1618bf178a5386f90610be", "raw": {"market": "0xe9c127a8c35f045d37b5344b0a36711084fa20c2fc1618bf178a5386f90610be", "asset_id": "80230236018433940569996058935444651347308266584430516013229815570706872276819", "price": "0.821", "size": "20.62", "side": "SELL", "timestamp": "1768404639216", "received_at": "2026-01-14T16:30:38.879979"}}
{"event_type": "price_change", "event_ts": "2026-01-14T16:30:39.106615", "ingestion_ts": "2026-01-14T16:33:58.842229", "market_id": "0xe9c127a8c35f045d37b5344b0a36711084fa20c2fc1618bf178a5386f90610be", "raw": {"market": "0xe9c127a8c35f045d37b5344b0a36711084fa20c2fc1618bf178a5386f90610be", "asset_id": "107000426448217931795450451304515386602910396776318075817601265223856116134349", "price": "0.215", "size": "33.11", "side": "BUY", "timestamp": "1768404639444", "received_at": "2026-01-14T16:30:39.106615"}}
{"event_type": "price_change", "event_ts": "2026-01-14T16:30:39.106615", "ingestion_ts": "2026-01-14T16:33:58.842229", "market_id": "0xe9c127a8c35f045d37b5344b0a36711084fa20c2fc1618bf178a5386f90610be", "raw": {"market": "0xe9c127a8c35f045d37b5344b0a36711084fa20c2fc1618bf178a5386f90610be", "asset_id": "80230236018433940569996058935444651347308266584430516013229815570706872276819", "price": "0.785", "size": "33.11", "side": "SELL", "timestamp": "1768404639444", "received_at": "2026-01-14T16:30:39.106615"}}
{"event_type": "price_change", "event_ts": "2026-01-14T16:30:39.338989", "ingestion_ts": "2026-01-14T16:33:58.842229", "market_id": "0xe9c127a8c35f045d37b5344b0a36711084fa20c2fc1618bf178a5386f90610be", "raw": {"market": "0xe9c127a8c35f045d37b5344b0a36711084fa20c2fc1618bf178a5386f90610be", "asset_id": "107000426448217931795450451304515386602910396776318075817601265223856116134349", "price": "0.216", "size": "17.09", "side": "BUY", "timestamp": "1768404639678", "received_at": "2026-01-14T16:30:39.338989"}}
{"event_type": "price_change", "event_ts": "2026-01-14T16:30:39.338989", "ingestion_ts": "2026-01-14T16:33:58.842229", "market_id": "0xe9c127a8c35f045d37b5344b0a36711084fa20c2fc1618bf178a5386f90610be", "raw": {"market": "0xe9c127a8c35f045d37b5344b0a36711084fa20c2fc1618bf178a5386f90610be", "asset_id": "80230236018433940569996058935444651347308266584430516013229815570706872276819", "price": "0.784", "size": "17.09", "side": "SELL", "timestamp": "1768404639678", "received_at": "2026-01-14T16:30:39.338989"}}
{"event_type": "price_change", "event_ts": "2026-01-14T16:30:39.570517", "ingestion_ts": "2026-01-14T16:33:58.842229", "market_id": "0xe9c127a8c35f045d37b5344b0a36711084fa20c2fc1618bf178a5386f90610be", "raw": {"market": "0xe9c127a8c35f045d37b5344b0a36711084fa20c2fc1618bf178a5386f90610be", "asset_id": "107000426448217931795450451304515386602910396776318075817601265223856116134349", "price": "0.257", "size": "27.7", "side": "BUY", "timestamp": "1768404639908", "received_at": "2026-01-14T16:30:39.570517"}}
{"event_type": "price_change", "event_ts": "2026-01-14T16:30:39.570517", "ingestion_ts": "2026-01-14T16:33:58.842229", "market_id": "0xe9c127a8c35f045d37b5344b0a36711084fa20c2fc1618bf178a5386f90610be", "raw": {"market": "0xe9c127a8c35f045d37b5344b0a36711084fa20c2fc1618bf178a5386f90610be", "asset_id": "80230236018433940569996058935444651347308266584430516013229815570706872276819", "price": "0.743", "size": "27.7", "side": "SELL", "timestamp": "1768404639908", "received_at": "2026-01-14T16:30:39.570517"}}
{"event_type": "price_change", "event_ts": "2026-01-14T16:30:39.786842", "ingestion_ts": "2026-01-14T16:33:58.842229", "market_id": "0xe9c127a8c35f045d37b5344b0a36711084fa20c2fc1618bf178a5386f90610be", "raw": {"market": "0xe9c127a8c35f045d37b5344b0a36711084fa20c2fc1618bf178a5386f90610be", "asset_id": "107000426448217931795450451304515386602910396776318075817601265223856116134349", "price": "0.258", "size": "14.31", "side": "BUY", "timestamp": "1768404640125", "received_at": "2026-01-14T16:30:39.786842"}}
{"event_type": "price_change", "event_ts": "2026-01-14T16:30:39.786842", "ingestion_ts": "2026-01-14T16:33:58.842229", "market_id": "0xe9c127a8c35f045d37b5344b0a36711084fa20c2fc1618bf178a5386f90610be", "raw": {"market": "0xe9c127a8c35f045d37b5344b0a36711084fa20c2fc1618bf178a5386f90610be", "asset_id": "80230236018433940569996058935444651347308266584430516013229815570706872276819", "price": "0.742", "size": "14.31", "side": "SELL", "timestamp": "1768404640125", "received_at": "2026-01-14T16:30:39.786842"}}
{"event_type": "price_change", "event_ts": "2026-01-14T16:30:40.037010", "ingestion_ts": "2026-01-14T16:33:58.842229", "market_id": "0xe9c127a8c35f045d37b5344b0a36711084fa20c2fc1618bf178a5386f90610be", "raw": {"market": "0xe9c127a8c35f045d37b5344b0a36711084fa20c2fc1618bf178a5386f90610be", "asset_id": "107000426448217931795450451304515386602910396776318075817601265223856116134349", "price": "0.372", "size": "9.92", "side": "BUY", "timestamp": "1768404640363", "received_at": "2026-01-14T16:30:40.037010"}}
{"event_type": "price_change", "event_ts": "2026-01-14T16:30:40.037010", "ingestion_ts": "2026-01-14T16:33:58.842229", "market_id": "0xe9c127a8c35f045d37b5344b0a36711084fa20c2fc1618bf178a5386f90610be", "raw": {"market": "0xe9c127a8c35f045d37b5344b0a36711084fa20c2fc1618bf178a5386f90610be", "asset_id": "80230236018433940569996058935444651347308266584430516013229815570706872276819", "price": "0.628", "size": "9.92", "side": "SELL", "timestamp": "1768404640363", "received_at": "2026-01-14T16:30:40.037010"}}
{"event_type": "price_change", "event_ts": "2026-01-14T16:30:40.253677", "ingestion_ts": "2026-01-14T16:33:58.842229", "market_id": "0xe9c127a8c35f045d37b5344b0a36711084fa20c2fc1618bf178a5386f90610be", "raw": {"market": "0xe9c127a8c35f045d37b5344b0a36711084fa20c2fc1618bf178a5386f90610be", "asset_id": "107000426448217931795450451304515386602910396776318075817601265223856116134349", "price": "0.414", "size": "8.91", "side": "BUY", "timestamp": "1768404640580", "received_at": "2026-01-14T16:30:40.253677"}}
{"event_type": "price_change", "event_ts": "2026-01-14T16:30:40.253677", "ingestion_ts": "2026-01-14T16:33:58.842229", "market_id": "0xe9c127a8c35f045d37b5344b0a36711084fa20c2fc1618bf178a5386f90610be", "raw": {"market": "0xe9c127a8c35f045d37b5344b0a36711084fa20c2fc1618bf178a5386f90610be", "asset_id": "80230236018433940569996058935444651347308266584430516013229815570706872276819", "price": "0.586", "size": "8.91", "side": "SELL", "timestamp": "1768404640580", "received_at": "2026-01-14T16:30:40.253677"}}
{"event_type": "price_change", "event_ts": "2026-01-14T16:30:42.578231", "ingestion_ts": "2026-01-14T16:33:58.842229", "market_id": "0x49686d26fb712515cd5e12c23f0a1c7e10214c7faa3cb0a730aabe0c33694082", "raw": {"market": "0x49686d26fb712515cd5e12c23f0a1c7e10214c7faa3cb0a730aabe0c33694082", "asset_id": "30442780799048074404860985387051749017905070253466005720364298335239299761065", "price": "0.096", "size": "0", "side": "BUY", "timestamp": "1768404642913", "received_at": "2026-01-14T16:30:42.578231"}}
{"event_type": "price_change", "event_ts": "2026-01-14T16:30:42.578231", "ingestion_ts": "2026-01-14T16:33:58.842229", "market_id": "0x49686d26fb712515cd5e12c23f0a1c7e10214c7faa3cb0a730aabe0c33694082", "raw": {"market": "0x49686d26fb712515cd5e12c23f0a1c7e10214c7faa3cb0a730aabe0c33694082", "asset_id": "13244681086321087932946246027856416106585284024824496763706748621681543444582", "price": "0.904", "size": "0", "side": "SELL", "timestamp": "1768404642913", "received_at": "2026-01-14T16:30:42.578231"}}
{"event_type": "price_change", "event_ts": "2026-01-14T16:30:54.550372", "ingestion_ts": "2026-01-14T16:33:58.842229", "market_id": "0xe9c127a8c35f045d37b5344b0a36711084fa20c2fc1618bf178a5386f90610be", "raw": {"market": "0xe9c127a8c35f045d37b5344b0a36711084fa20c2fc1618bf178a5386f90610be", "asset_id": "107000426448217931795450451304515386602910396776318075817601265223856116134349", "price": "0.045", "size": "0", "side": "BUY", "timestamp": "1768404654887", "received_at": "2026-01-14T16:30:54.550372"}}
{"event_type": "price_change", "event_ts": "2026-01-14T16:30:54.550372", "ingestion_ts": "2026-01-14T16:33:58.842229", "market_id": "0xe9c127a8c35f045d37b5344b0a36711084fa20c2fc1618bf178a5386f90610be", "raw": {"market": "0xe9c127a8c35f045d37b5344b0a36711084fa20c2fc1618bf178a5386f90610be", "asset_id": "80230236018433940569996058935444651347308266584430516013229815570706872276819", "price": "0.955", "size": "0", "side": "SELL", "timestamp": "1768404654887", "received_at": "2026-01-14T16:30:54.550372"}}
{"event_type": "price_change", "event_ts": "2026-01-14T16:30:54.550406", "ingestion_ts": "2026-01-14T16:33:58.842229", "market_id": "0xe9c127a8c35f045d37b5344b0a36711084fa20c2fc1618bf178a5386f90610be", "raw": {"market": "0xe9c127a8c35f045d37b5344b0a36711084fa20c2fc1618bf178a5386f90610be", "asset_id": "107000426448217931795450451304515386602910396776318075817601265223856116134349", "price": "0.111", "size": "0", "side": "BUY", "timestamp": "1768404654887", "received_at": "2026-01-14T16:30:54.550406"}}
{"event_type": "price_change", "event_ts": "2026-01-14T16:30:54.550406", "ingestion_ts": "2026-01-14T16:33:58.842229", "market_id": "0xe9c127a8c35f045d37b5344b0a36711084fa20c2fc1618bf178a5386f90610be", "raw": {"market": "0xe9c127a8c35f045d37b5344b0a36711084fa20c2fc1618bf178a5386f90610be", "asset_id": "80230236018433940569996058935444651347308266584430516013229815570706872276819", "price": "0.889", "size": "0", "side": "SELL", "timestamp": "1768404654887", "received_at": "2026-01-14T16:30:54.550406"}}
{"event_type": "price_change", "event_ts": "2026-01-14T16:30:54.550420", "ingestion_ts": "2026-01-14T16:33:58.842229", "market_id": "0xcab7ba4a9133cfd407d7e73e5757e5abbace413b59421527a31113406c97815c", "raw": {"market": "0xcab7ba4a9133cfd407d7e73e5757e5abbace413b59421527a31113406c97815c", "asset_id": "20002636398944597965698652220992177552927816915094913583821579024925426590022", "price": "0.001", "size": "503797.9", "side": "BUY", "timestamp": "1768404654887", "received_at": "2026-01-14T16:30:54.550420"}}
{"event_type": "price_change", "event_ts": "2026-01-14T16:30:54.550420", "ingestion_ts": "2026-01-14T16:33:58.842229", "market_id": "0xcab7ba4a9133cfd407d7e73e5757e5abbace413b59421527a31113406c97815c", "raw": {"market": "0xcab7ba4a9133cfd407d7e73e5757e5abbace413b59421527a31113406c97815c", "asset_id": "96361925776989336186111887920533578209326565663637092688733016597062311745569", "price": "0.999", "size": "503797.9", "side": "SELL", "timestamp": "1768404654887", "received_at": "2026-01-14T16:30:54.550420"}}
{"event_type": "price_change", "event_ts": "2026-01-14T16:30:54.550441", "ingestion_ts": "2026-01-14T16:33:58.842229", "market_id": "0xcab7ba4a9133cfd407d7e73e5757e5abbace413b59421527a31113406c97815c", "raw": {"market": "0xcab7ba4a9133cfd407d7e73e5757e5abbace413b59421527a31113406c97815c", "asset_id": "20002636398944597965698652220992177552927816915094913583821579024925426590022", "price": "0.044", "size": "83.91", "side": "BUY", "timestamp": "1768404654887", "received_at": "2026-01-14T16:30:54.550441"}}
{"event_type": "price_change", "event_ts": "2026-01-14T16:30:54.550441", "ingestion_ts": "2026-01-14T16:33:58.842229", "market_id": "0xcab7ba4a9133cfd407d7e73e5757e5abbace413b59421527a31113406c97815c", "raw": {"market": "0xcab7ba4a9133cfd407d7e73e5757e5abbace413b59421527a31113406c97815c", "asset_id": "96361925776989336186111887920533578209326565663637092688733016597062311745569", "price": "0.956", "size": "83.91", "side": "SELL", "timestamp": "1768404654887", "received_at": "2026-01-14T16:30:54.550441"}}
{"event_type": "price_change", "event_ts": "2026-01-14T16:30:55.431132", "ingestion_ts": "2026-01-14T16:33:58.842229", "market_id": "0x318b222c1435b47c338e66ca6001f782711186a488ae7b7248f7edc6ff076a83", "raw": {"market": "0x318b222c1435b47c338e66ca6001f782711186a488ae7b7248f7edc6ff076a83", "asset_id": "63773739594775606083258239254748928077067768053882704658119720069071630213026", "price": "0.101", "size": "5.82", "side": "BUY", "timestamp": "1768404655667", "received_at": "2026-01-14T16:30:55.431132"}}
{"event_type": "price_change", "event_ts": "2026-01-14T16:30:55.431132", "ingestion_ts": "2026-01-14T16:33:58.842229", "market_id": "0x318b222c1435b47c338e66ca6001f782711186a488ae7b7248f7edc6ff076a83", "raw": {"market": "0x318b222c1435b47c338e66ca6001f782711186a488ae7b7248f7edc6ff076a83", "asset_id": "56738600572035832904895845056468792275697823297413384908752239327866518310010", "price": "0.899", "size": "5.82", "side": "SELL", "timestamp": "1768404655667", "received_at": "2026-01-14T16:30:55.431132"}}
{"event_type": "price_change", "event_ts": "2026-01-14T16:30:55.433676", "ingestion_ts": "2026-01-14T16:33:58.842229", "market_id": "0x318b222c1435b47c338e66ca6001f782711186a488ae7b7248f7edc6ff076a83", "raw": {"market": "0x318b222c1435b47c338e66ca6001f782711186a488ae7b7248f7edc6ff076a83", "asset_id": "63773739594775606083258239254748928077067768053882704658119720069071630213026", "price": "0.021", "size": "14.82", "side": "BUY", "timestamp": "1768404655668", "received_at": "2026-01-14T16:30:55.433676"}}
{"event_type": "price_change", "event_ts": "2026-01-14T16:30:55.433676", "ingestion_ts": "2026-01-14T16:33:58.842229", "market_id": "0x318b222c1435b47c338e66ca6001f782711186a488ae7b7248f7edc6ff076a83", "raw": {"market": "0x318b222c1435b47c338e66ca6001f782711186a488ae7b7248f7edc6ff076a83", "asset_id": "56738600572035832904895845056468792275697823297413384908752239327866518310010", "price": "0.979", "size": "14.82", "side": "SELL", "timestamp": "1768404655668", "received_at": "2026-01-14T16:30:55.433676"}}
{"event_type": "price_change", "event_ts": "2026-01-14T16:30:55.435936", "ingestion_ts": "2026-01-14T16:33:58.842229", "market_id": "0x318b222c1435b47c338e66ca6001f782711186a488ae7b7248f7edc6ff076a83", "raw": {"market": "0x318b222c1435b47c338e66ca6001f782711186a488ae7b7248f7edc6ff076a83", "asset_id": "63773739594775606083258239254748928077067768053882704658119720069071630213026", "price": "0.007", "size": "9.86", "side": "BUY", "timestamp": "1768404655670", "received_at": "2026-01-14T16:30:55.435936"}}
{"event_type": "price_change", "event_ts": "2026-01-14T16:30:55.435936", "ingestion_ts": "2026-01-14T16:33:58.842229", "market_id": "0x318b222c1435b47c338e66ca6001f782711186a488ae7b7248f7edc6ff076a83", "raw": {"market": "0x318b222c1435b47c338e66ca6001f782711186a488ae7b7248f7edc6ff076a83", "asset_id": "56738600572035832904895845056468792275697823297413384908752239327866518310010", "price": "0.993", "size": "9.86", "side": "SELL", "timestamp": "1768404655670", "received_at": "2026-01-14T16:30:55.435936"}}
{"event_type": "price_change", "event_ts": "2026-01-14T16:30:55.435962", "ingestion_ts": "2026-01-14T16:33:58.842229", "market_id": "0x318b222c1435b47c338e66ca6001f782711186a488ae7b7248f7edc6ff076a83", "raw": {"market": "0x318b222c1435b47c338e66ca6001f782711186a488ae7b7248f7edc6ff076a83", "asset_id": "63773739594775606083258239254748928077067768053882704658119720069071630213026", "price": "0.001", "size": "3130.47", "side": "BUY", "timestamp": "1768404655671", "received_at": "2026-01-14T16:30:55.435962"}}
{"event_type": "price_change", "event_ts": "2026-01-14T16:30:55.435962", "ingestion_ts": "2026-01-14T16:33:58.842229", "market_id": "0x318b222c1435b47c338e66ca6001f782711186a488ae7b7248f7edc6ff076a83", "raw": {"market": "0x318b222c1435b47c338e66ca6001f782711186a488ae7b7248f7edc6ff076a83", "asset_id": "56738600572035832904895845056468792275697823297413384908752239327866518310010", "price": "0.999", "size": "3130.47", "side": "SELL", "timestamp": "1768404655671", "received_at": "2026-01-14T16:30:55.435962"}}
{"event_type": "price_change", "event_ts": "2026-01-14T16:30:55.435982", "ingestion_ts": "2026-01-14T16:33:58.842229", "market_id": "0x318b222c1435b47c338e66ca6001f782711186a488ae7b7248f7edc6ff076a83", "raw": {"market": "0x318b222c1435b47c338e66ca6001f782711186a488ae7b7248f7edc6ff076a83", "asset_id": "63773739594775606083258239254748928077067768053882704658119720069071630213026", "price": "0.003", "size": "2306.89", "side": "BUY", "timestamp": "1768404655672", "received_at": "2026-01-14T16:30:55.435982"}}
{"event_type": "price_change", "event_ts": "2026-01-14T16:30:55.435982", "ingestion_ts": "2026-01-14T16:33:58.842229", "market_id": "0x318b222c1435b47c338e66ca6001f782711186a488ae7b7248f7edc6ff076a83", "raw": {"market": "0x318b222c1435b47c338e66ca6001f782711186a488ae7b7248f7edc6ff076a83", "asset_id": "56738600572035832904895845056468792275697823297413384908752239327866518310010", "price": "0.997", "size": "2306.89", "side": "SELL", "timestamp": "1768404655672", "received_at": "2026-01-14T16:30:55.435982"}}
{"event_type": "price_change", "event_ts": "2026-01-14T16:30:57.349705", "ingestion_ts": "2026-01-14T16:33:58.842229", "market_id": "0xcab7ba4a9133cfd407d7e73e5757e5abbace413b59421527a31113406c97815c", "raw": {"market": "0xcab7ba4a9133cfd407d7e73e5757e5abbace413b59421527a31113406c97815c", "asset_id": "20002636398944597965698652220992177552927816915094913583821579024925426590022", "price": "0.002", "size": "5256.1", "side": "BUY", "timestamp": "1768404657687", "received_at": "2026-01-14T16:30:57.349705"}}
{"event_type": "price_change", "event_ts": "2026-01-14T16:30:57.349705", "ingestion_ts": "2026-01-14T16:33:58.842229", "market_id": "0xcab7ba4a9133cfd407d7e73e5757e5abbace413b59421527a31113406c97815c", "raw": {"market": "0xcab7ba4a9133cfd407d7e73e5757e5abbace413b59421527a31113406c97815c", "asset_id": "96361925776989336186111887920533578209326565663637092688733016597062311745569", "price": "0.998", "size": "5256.1", "side": "SELL", "timestamp": "1768404657687", "received_at": "2026-01-14T16:30:57.349705"}}
{"event_type": "price_change", "event_ts": "2026-01-14T16:30:57.349754", "ingestion_ts": "2026-01-14T16:33:58.842229", "market_id": "0xe9c127a8c35f045d37b5344b0a36711084fa20c2fc1618bf178a5386f90610be", "raw": {"market": "0xe9c127a8c35f045d37b5344b0a36711084fa20c2fc1618bf178a5386f90610be", "asset_id": "107000426448217931795450451304515386602910396776318075817601265223856116134349", "price": "0.109", "size": "5.27", "side": "BUY", "timestamp": "1768404657687", "received_at": "2026-01-14T16:30:57.349754"}}
{"event_type": "price_change", "event_ts": "2026-01-14T16:30:57.349754", "ingestion_ts": "2026-01-14T16:33:58.842229", "market_id": "0xe9c127a8c35f045d37b5344b0a36711084fa20c2fc1618bf178a5386f90610be", "raw": {"market": "0xe9c127a8c35f045d37b5344b0a36711084fa20c2fc1618bf178a5386f90610be", "asset_id": "80230236018433940569996058935444651347308266584430516013229815570706872276819", "price": "0.891", "size": "5.27", "side": "SELL", "timestamp": "1768404657687", "received_at": "2026-01-14T16:30:57.349754"}}
{"event_type": "price_change", "event_ts": "2026-01-14T16:30:57.351342", "ingestion_ts": "2026-01-14T16:33:58.842229", "market_id": "0xcab7ba4a9133cfd407d7e73e5757e5abbace413b59421527a31113406c97815c", "raw": {"market": "0xcab7ba4a9133cfd407d7e73e5757e5abbace413b59421527a31113406c97815c", "asset_id": "20002636398944597965698652220992177552927816915094913583821579024925426590022", "price": "0.045", "size": "6.17", "side": "BUY", "timestamp": "1768404657689", "received_at": "2026-01-14T16:30:57.351342"}}
{"event_type": "price_change", "event_ts": "2026-01-14T16:30:57.351342", "ingestion_ts": "2026-01-14T16:33:58.842229", "market_id": "0xcab7ba4a9133cfd407d7e73e5757e5abbace413b59421527a31113406c97815c", "raw": {"market": "0xcab7ba4a9133cfd407d7e73e5757e5abbace413b59421527a31113406c97815c", "asset_id": "96361925776989336186111887920533578209326565663637092688733016597062311745569", "price": "0.955", "size": "6.17", "side": "SELL", "timestamp": "1768404657689", "received_at": "2026-01-14T16:30:57.351342"}}
{"event_type": "price_change", "event_ts": "2026-01-14T16:30:57.352930", "ingestion_ts": "2026-01-14T16:33:58.842229", "market_id": "0xe9c127a8c35f045d37b5344b0a36711084fa20c2fc1618bf178a5386f90610be", "raw": {"market": "0xe9c127a8c35f045d37b5344b0a36711084fa20c2fc1618bf178a5386f90610be", "asset_id": "107000426448217931795450451304515386602910396776318075817601265223856116134349", "price": "0.037", "size": "6.95", "side": "BUY", "timestamp": "1768404657691", "received_at": "2026-01-14T16:30:57.352930"}}
{"event_type": "price_change", "event_ts": "2026-01-14T16:30:57.352930", "ingestion_ts": "2026-01-14T16:33:58.842229", "market_id": "0xe9c127a8c35f045d37b5344b0a36711084fa20c2fc1618bf178a5386f90610be", "raw": {"market": "0xe9c127a8c35f045d37b5344b0a36711084fa20c2fc1618bf178a5386f90610be", "asset_id": "80230236018433940569996058935444651347308266584430516013229815570706872276819", "price": "0.963", "size": "6.95", "side": "SELL", "timestamp": "1768404657691", "received_at": "2026-01-14T16:30:57.352930"}}
{"event_type": "price_change", "event_ts": "2026-01-14T16:30:57.976351", "ingestion_ts": "2026-01-14T16:33:58.842229", "market_id": "0xc0e6b917320a47228fb96e3b5ae0e5c93773a5ae2662ae4e1f37807cfe47ce98", "raw": {"market": "0xc0e6b917320a47228fb96e3b5ae0e5c93773a5ae2662ae4e1f37807cfe47ce98", "asset_id": "81647294538046680798858716589766492074338758116170717123345952330712416337530", "price": "0.002", "size": "257.51", "side": "BUY", "timestamp": "1768404658312", "received_at": "2026-01-14T16:30:57.976351"}}
{"event_type": "price_change", "event_ts": "2026-01-14T16:30:57.976351", "ingestion_ts": "2026-01-14T16:33:58.842229", "market_id": "0xc0e6b917320a47228fb96e3b5ae0e5c93773a5ae2662ae4e1f37807cfe47ce98", "raw": {"market": "0xc0e6b917320a47228fb96e3b5ae0e5c93773a5ae2662ae4e1f37807cfe47ce98", "asset_id": "58656358377246279051017109359677190749228949103591068167284263961542487110215", "price": "0.998", "size": "257.51", "side": "SELL", "timestamp": "1768404658312", "received_at": "2026-01-14T16:30:57.976351"}}
{"event_type": "price_change", "event_ts": "2026-01-14T16:30:57.976387", "ingestion_ts": "2026-01-14T16:33:58.842229", "market_id": "0xc0e6b917320a47228fb96e3b5ae0e5c93773a5ae2662ae4e1f37807cfe47ce98", "raw": {"market": "0xc0e6b917320a47228fb96e3b5ae0e5c93773a5ae2662ae4e1f37807cfe47ce98", "asset_id": "81647294538046680798858716589766492074338758116170717123345952330712416337530", "price": "0.051", "size": "5.09", "side": "BUY", "timestamp": "1768404658313", "received_at": "2026-01-14T16:30:57.976387"}}
{"event_type": "price_change", "event_ts": "2026-01-14T16:30:57.976387", "ingestion_ts": "2026-01-14T16:33:58.842229", "market_id": "0xc0e6b917320a47228fb96e3b5ae0e5c93773a5ae2662ae4e1f37807cfe47ce98", "raw": {"market": "0xc0e6b917320a47228fb96e3b5ae0e5c93773a5ae2662ae4e1f37807cfe47ce98", "asset_id": "58656358377246279051017109359677190749228949103591068167284263961542487110215", "price": "0.949", "size": "5.09", "side": "SELL", "timestamp": "1768404658313", "received_at": "2026-01-14T16:30:57.976387"}}
{"event_type": "price_change", "event_ts": "2026-01-14T16:31:03.188497", "ingestion_ts": "2026-01-14T16:33:58.842229", "market_id": "0xea644975be7b2ad32b536a94ae21b707ecb2f84290225b24e60ca46dd77903dd", "raw": {"market": "0xea644975be7b2ad32b536a94ae21b707ecb2f84290225b24e60ca46dd77903dd", "asset_id": "19255594762111702415265750364124818677094538461124581923455280001407159960455", "price": "0.052", "size": "0", "side": "BUY", "timestamp": "1768404663527", "received_at": "2026-01-14T16:31:03.188497"}}
{"event_type": "price_change", "event_ts": "2026-01-14T16:31:03.188497", "ingestion_ts": "2026-01-14T16:33:58.842229", "market_id": "0xea644975be7b2ad32b536a94ae21b707ecb2f84290225b24e60ca46dd77903dd", "raw": {"market": "0xea644975be7b2ad32b536a94ae21b707ecb2f84290225b24e60ca46dd77903dd", "asset_id": "110044455628775971785618539427229099821815416148768008176051068105157446559241", "price": "0.948", "size": "0", "side": "SELL", "timestamp": "1768404663527", "received_at": "2026-01-14T16:31:03.188497"}}
{"event_type": "price_change", "event_ts": "2026-01-14T16:31:04.386678", "ingestion_ts": "2026-01-14T16:33:58.842229", "market_id": "0xea644975be7b2ad32b536a94ae21b707ecb2f84290225b24e60ca46dd77903dd", "raw": {"market": "0xea644975be7b2ad32b536a94ae21b707ecb2f84290225b24e60ca46dd77903dd", "asset_id": "19255594762111702415265750364124818677094538461124581923455280001407159960455", "price": "0.051", "size": "12.93", "side": "BUY", "timestamp": "1768404664721", "received_at": "2026-01-14T16:31:04.386678"}}
{"event_type": "price_change", "event_ts": "2026-01-14T16:31:04.386678", "ingestion_ts": "2026-01-14T16:33:58.842229", "market_id": "0xea644975be7b2ad32b536a94ae21b707ecb2f84290225b24e60ca46dd77903dd", "raw": {"market": "0xea644975be7b2ad32b536a94ae21b707ecb2f84290225b24e60ca46dd77903dd", "asset_id": "110044455628775971785618539427229099821815416148768008176051068105157446559241", "price": "0.949", "size": "12.93", "side": "SELL", "timestamp": "1768404664721", "received_at": "2026-01-14T16:31:04.386678"}}
{"event_type": "price_change", "event_ts": "2026-01-14T16:31:07.610349", "ingestion_ts": "2026-01-14T16:33:58.842229", "market_id": "0x44f08744458b8896620cd3330bc5e1ea69df4199b02d4fc583b3fc96e5d314ce", "raw": {"market": "0x44f08744458b8896620cd3330bc5e1ea69df4199b02d4fc583b3fc96e5d314ce", "asset_id": "72327831507226612545928776794104143393438710920370371172884559893525100761096", "price": "0.402", "size": "0", "side": "BUY", "timestamp": "1768404667674", "received_at": "2026-01-14T16:31:07.610349"}}
{"event_type": "price_change", "event_ts": "2026-01-14T16:31:07.610349", "ingestion_ts": "2026-01-14T16:33:58.842229", "market_id": "0x44f08744458b8896620cd3330bc5e1ea69df4199b02d4fc583b3fc96e5d314ce", "raw": {"market": "0x44f08744458b8896620cd3330bc5e1ea69df4199b02d4fc583b3fc96e5d314ce", "asset_id": "49194009556504828848509244326501559253829462790583873936160989575507522044057", "price": "0.598", "size": "0", "side": "SELL", "timestamp": "1768404667674", "received_at": "2026-01-14T16:31:07.610349"}}
{"event_type": "price_change", "event_ts": "2026-01-14T16:31:07.670406", "ingestion_ts": "2026-01-14T16:33:58.842229", "market_id": "0x44f08744458b8896620cd3330bc5e1ea69df4199b02d4fc583b3fc96e5d314ce", "raw": {"market": "0x44f08744458b8896620cd3330bc5e1ea69df4199b02d4fc583b3fc96e5d314ce", "asset_id": "72327831507226612545928776794104143393438710920370371172884559893525100761096", "price": "0.402", "size": "5", "side": "BUY", "timestamp": "1768404667720", "received_at": "2026-01-14T16:31:07.670406"}}
{"event_type": "price_change", "event_ts": "2026-01-14T16:31:07.670406", "ingestion_ts": "2026-01-14T16:33:58.842229", "market_id": "0x44f08744458b8896620cd3330bc5e1ea69df4199b02d4fc583b3fc96e5d314ce", "raw": {"market": "0x44f08744458b8896620cd3330bc5e1ea69df4199b02d4fc583b3fc96e5d314ce", "asset_id": "49194009556504828848509244326501559253829462790583873936160989575507522044057", "price": "0.598", "size": "5", "side": "SELL", "timestamp": "1768404667720", "received_at": "2026-01-14T16:31:07.670406"}}
{"event_type": "price_change", "event_ts": "2026-01-14T16:31:13.464840", "ingestion_ts": "2026-01-14T16:33:58.842229", "market_id": "0xcab7ba4a9133cfd407d7e73e5757e5abbace413b59421527a31113406c97815c", "raw": {"market": "0xcab7ba4a9133cfd407d7e73e5757e5abbace413b59421527a31113406c97815c", "asset_id": "20002636398944597965698652220992177552927816915094913583821579024925426590022", "price": "0.971", "size": "0", "side": "BUY", "timestamp": "1768404673711", "received_at": "2026-01-14T16:31:13.464840"}}
{"event_type": "price_change", "event_ts": "2026-01-14T16:31:13.464840", "ingestion_ts": "2026-01-14T16:33:58.842229", "market_id": "0xcab7ba4a9133cfd407d7e73e5757e5abbace413b59421527a31113406c97815c", "raw": {"market": "0xcab7ba4a9133cfd407d7e73e5757e5abbace413b59421527a31113406c97815c", "asset_id": "96361925776989336186111887920533578209326565663637092688733016597062311745569", "price": "0.029", "size": "0", "side": "SELL", "timestamp": "1768404673711", "received_at": "2026-01-14T16:31:13.464840"}}
{"event_type": "price_change", "event_ts": "2026-01-14T16:31:13.464914", "ingestion_ts": "2026-01-14T16:33:58.842229", "market_id": "0xcab7ba4a9133cfd407d7e73e5757e5abbace413b59421527a31113406c97815c", "raw": {"market": "0xcab7ba4a9133cfd407d7e73e5757e5abbace413b59421527a31113406c97815c", "asset_id": "96361925776989336186111887920533578209326565663637092688733016597062311745569", "price": "0.009", "size": "0", "side": "BUY", "timestamp": "1768404673711", "received_at": "2026-01-14T16:31:13.464914"}}
{"event_type": "price_change", "event_ts": "2026-01-14T16:31:13.464914", "ingestion_ts": "2026-01-14T16:33:58.842229", "market_id": "0xcab7ba4a9133cfd407d7e73e5757e5abbace413b59421527a31113406c97815c", "raw": {"market": "0xcab7ba4a9133cfd407d7e73e5757e5abbace413b59421527a31113406c97815c", "asset_id": "20002636398944597965698652220992177552927816915094913583821579024925426590022", "price": "0.991", "size": "0", "side": "SELL", "timestamp": "1768404673711", "received_at": "2026-01-14T16:31:13.464914"}}
{"event_type": "price_change", "event_ts": "2026-01-14T16:31:14.512972", "ingestion_ts": "2026-01-14T16:33:58.842229", "market_id": "0x9d24d9f9b5995949cb158d943793dea20bd448e1b3971cb6f7418bb15e719661", "raw": {"market": "0x9d24d9f9b5995949cb158d943793dea20bd448e1b3971cb6f7418bb15e719661", "asset_id": "79516121807256184736227920754945730465880754940725759201193439378549308939672", "price": "0.938", "size": "54.66", "side": "BUY", "timestamp": "1768404674771", "received_at": "2026-01-14T16:31:14.512972"}}
{"event_type": "price_change", "event_ts": "2026-01-14T16:31:14.512972", "ingestion_ts": "2026-01-14T16:33:58.842229", "market_id": "0x9d24d9f9b5995949cb158d943793dea20bd448e1b3971cb6f7418bb15e719661", "raw": {"market": "0x9d24d9f9b5995949cb158d943793dea20bd448e1b3971cb6f7418bb15e719661", "asset_id": "70512916946285526357165287373537570327431985324385225788636160168740471920430", "price": "0.062", "size": "54.66", "side": "SELL", "timestamp": "1768404674771", "received_at": "2026-01-14T16:31:14.512972"}}
{"event_type": "price_change", "event_ts": "2026-01-14T16:31:16.102779", "ingestion_ts": "2026-01-14T16:33:58.842229", "market_id": "0x49686d26fb712515cd5e12c23f0a1c7e10214c7faa3cb0a730aabe0c33694082", "raw": {"market": "0x49686d26fb712515cd5e12c23f0a1c7e10214c7faa3cb0a730aabe0c33694082", "asset_id": "13244681086321087932946246027856416106585284024824496763706748621681543444582", "price": "0.851", "size": "500", "side": "BUY", "timestamp": "1768404676250", "received_at": "2026-01-14T16:31:16.102779"}}
{"event_type": "price_change", "event_ts": "2026-01-14T16:31:16.102779", "ingestion_ts": "2026-01-14T16:33:58.842229", "market_id": "0x49686d26fb712515cd5e12c23f0a1c7e10214c7faa3cb0a730aabe0c33694082", "raw": {"market": "0x49686d26fb712515cd5e12c23f0a1c7e10214c7faa3cb0a730aabe0c33694082", "asset_id": "30442780799048074404860985387051749017905070253466005720364298335239299761065", "price": "0.149", "size": "500", "side": "SELL", "timestamp": "1768404676250", "received_at": "2026-01-14T16:31:16.102779"}}
{"event_type": "price_change", "event_ts": "2026-01-14T16:31:16.255611", "ingestion_ts": "2026-01-14T16:33:58.842229", "market_id": "0x49686d26fb712515cd5e12c23f0a1c7e10214c7faa3cb0a730aabe0c33694082", "raw": {"market": "0x49686d26fb712515cd5e12c23f0a1c7e10214c7faa3cb0a730aabe0c33694082", "asset_id": "13244681086321087932946246027856416106585284024824496763706748621681543444582", "price": "0.899", "size": "16", "side": "SELL", "timestamp": "1768404676469", "received_at": "2026-01-14T16:31:16.255611"}}
{"event_type": "price_change", "event_ts": "2026-01-14T16:31:16.255611", "ingestion_ts": "2026-01-14T16:33:58.842229", "market_id": "0x49686d26fb712515cd5e12c23f0a1c7e10214c7faa3cb0a730aabe0c33694082", "raw": {"market": "0x49686d26fb712515cd5e12c23f0a1c7e10214c7faa3cb0a730aabe0c33694082", "asset_id": "30442780799048074404860985387051749017905070253466005720364298335239299761065", "price": "0.101", "size": "16", "side": "BUY", "timestamp": "1768404676469", "received_at": "2026-01-14T16:31:16.255611"}}
{"event_type": "price_change", "event_ts": "2026-01-14T16:31:16.305169", "ingestion_ts": "2026-01-14T16:33:58.842229", "market_id": "0x49686d26fb712515cd5e12c23f0a1c7e10214c7faa3cb0a730aabe0c33694082", "raw": {"market": "0x49686d26fb712515cd5e12c23f0a1c7e10214c7faa3cb0a730aabe0c33694082", "asset_id": "13244681086321087932946246027856416106585284024824496763706748621681543444582", "price": "0.907", "size": "122", "side": "SELL", "timestamp": "1768404676499", "received_at": "2026-01-14T16:31:16.305169"}}
{"event_type": "price_change", "event_ts": "2026-01-14T16:31:16.305169", "ingestion_ts": "2026-01-14T16:33:58.842229", "market_id": "0x49686d26fb712515cd5e12c23f0a1c7e10214c7faa3cb0a730aabe0c33694082", "raw": {"market": "0x49686d26fb712515cd5e12c23f0a1c7e10214c7faa3cb0a730aabe0c33694082", "asset_id": "30442780799048074404860985387051749017905070253466005720364298335239299761065", "price": "0.093", "size": "122", "side": "BUY", "timestamp": "1768404676499", "received_at": "2026-01-14T16:31:16.305169"}}
{"event_type": "price_change", "event_ts": "2026-01-14T16:31:18.514328", "ingestion_ts": "2026-01-14T16:33:58.842229", "market_id": "0x49686d26fb712515cd5e12c23f0a1c7e10214c7faa3cb0a730aabe0c33694082", "raw": {"market": "0x49686d26fb712515cd5e12c23f0a1c7e10214c7faa3cb0a730aabe0c33694082", "asset_id": "30442780799048074404860985387051749017905070253466005720364298335239299761065", "price": "0.094", "size": "50", "side": "BUY", "timestamp": "1768404678780", "received_at": "2026-01-14T16:31:18.514328"}}
{"event_type": "price_change", "event_ts": "2026-01-14T16:31:18.514328", "ingestion_ts": "2026-01-14T16:33:58.842229", "market_id": "0x49686d26fb712515cd5e12c23f0a1c7e10214c7faa3cb0a730aabe0c33694082", "raw": {"market": "0x49686d26fb712515cd5e12c23f0a1c7e10214c7faa3cb0a730aabe0c33694082", "asset_id": "13244681086321087932946246027856416106585284024824496763706748621681543444582", "price": "0.906", "size": "50", "side": "SELL", "timestamp": "1768404678780", "received_at": "2026-01-14T16:31:18.514328"}}
{"event_type": "price_change", "event_ts": "2026-01-14T16:31:18.555813", "ingestion_ts": "2026-01-14T16:33:58.842229", "market_id": "0x49686d26fb712515cd5e12c23f0a1c7e10214c7faa3cb0a730aabe0c33694082", "raw": {"market": "0x49686d26fb712515cd5e12c23f0a1c7e10214c7faa3cb0a730aabe0c33694082", "asset_id": "13244681086321087932946246027856416106585284024824496763706748621681543444582", "price": "0.907", "size": "0", "side": "SELL", "timestamp": "1768404678837", "received_at": "2026-01-14T16:31:18.555813"}}
{"event_type": "price_change", "event_ts": "2026-01-14T16:31:18.555813", "ingestion_ts": "2026-01-14T16:33:58.842229", "market_id": "0x49686d26fb712515cd5e12c23f0a1c7e10214c7faa3cb0a730aabe0c33694082", "raw": {"market": "0x49686d26fb712515cd5e12c23f0a1c7e10214c7faa3cb0a730aabe0c33694082", "asset_id": "30442780799048074404860985387051749017905070253466005720364298335239299761065", "price": "0.093", "size": "0", "side": "BUY", "timestamp": "1768404678837", "received_at": "2026-01-14T16:31:18.555813"}}
{"event_type": "price_change", "event_ts": "2026-01-14T16:31:18.568436", "ingestion_ts": "2026-01-14T16:33:58.842229", "market_id": "0x9d24d9f9b5995949cb158d943793dea20bd448e1b3971cb6f7418bb15e719661", "raw": {"market": "0x9d24d9f9b5995949cb158d943793dea20bd448e1b3971cb6f7418bb15e719661", "asset_id": "79516121807256184736227920754945730465880754940725759201193439378549308939672", "price": "0.524", "size": "0", "side": "BUY", "timestamp": "1768404678864", "received_at": "2026-01-14T16:31:18.568436"}}
{"event_type": "price_change", "event_ts": "2026-01-14T16:31:18.568436", "ingestion_ts": "2026-01-14T16:33:58.842229", "market_id": "0x9d24d9f9b5995949cb158d943793dea20bd448e1b3971cb6f7418bb15e719661", "raw": {"market": "0x9d24d9f9b5995949cb158d943793dea20bd448e1b3971cb6f7418bb15e719661", "asset_id": "70512916946285526357165287373537570327431985324385225788636160168740471920430", "price": "0.476", "size": "0", "side": "SELL", "timestamp": "1768404678864", "received_at": "2026-01-14T16:31:18.568436"}}
{"event_type": "price_change", "event_ts": "2026-01-14T16:31:18.570930", "ingestion_ts": "2026-01-14T16:33:58.842229", "market_id": "0x49686d26fb712515cd5e12c23f0a1c7e10214c7faa3cb0a730aabe0c33694082", "raw": {"market": "0x49686d26fb712515cd5e12c23f0a1c7e10214c7faa3cb0a730aabe0c33694082", "asset_id": "13244681086321087932946246027856416106585284024824496763706748621681543444582", "price": "0.905", "size": "105", "side": "SELL", "timestamp": "1768404678869", "received_at": "2026-01-14T16:31:18.570930"}}
{"event_type": "price_change", "event_ts": "2026-01-14T16:31:18.570930", "ingestion_ts": "2026-01-14T16:33:58.842229", "market_id": "0x49686d26fb712515cd5e12c23f0a1c7e10214c7faa3cb0a730aabe0c33694082", "raw": {"market": "0x49686d26fb712515cd5e12c23f0a1c7e10214c7faa3cb0a730aabe0c33694082", "asset_id": "30442780799048074404860985387051749017905070253466005720364298335239299761065", "price": "0.095", "size": "105", "side": "BUY", "timestamp": "1768404678869", "received_at": "2026-01-14T16:31:18.570930"}}
{"event_type": "price_change", "event_ts": "2026-01-14T16:31:18.591577", "ingestion_ts": "2026-01-14T16:33:58.842229", "market_id": "0x9d24d9f9b5995949cb158d943793dea20bd448e1b3971cb6f7418bb15e719661", "raw": {"market": "0x9d24d9f9b5995949cb158d943793dea20bd448e1b3971cb6f7418bb15e719661", "asset_id": "79516121807256184736227920754945730465880754940725759201193439378549308939672", "price": "0.524", "size": "5", "side": "BUY", "timestamp": "1768404678913", "received_at": "2026-01-14T16:31:18.591577"}}
{"event_type": "price_change", "event_ts": "2026-01-14T16:31:18.591577", "ingestion_ts": "2026-01-14T16:33:58.842229", "market_id": "0x9d24d9f9b5995949cb158d943793dea20bd448e1b3971cb6f7418bb15e719661", "raw": {"market": "0x9d24d9f9b5995949cb158d943793dea20bd448e1b3971cb6f7418bb15e719661", "asset_id": "70512916946285526357165287373537570327431985324385225788636160168740471920430", "price": "0.476", "size": "5", "side": "SELL", "timestamp": "1768404678913", "received_at": "2026-01-14T16:31:18.591577"}}
{"event_type": "price_change", "event_ts": "2026-01-14T16:31:19.045808", "ingestion_ts": "2026-01-14T16:33:58.842229", "market_id": "0x49686d26fb712515cd5e12c23f0a1c7e10214c7faa3cb0a730aabe0c33694082", "raw": {"market": "0x49686d26fb712515cd5e12c23f0a1c7e10214c7faa3cb0a730aabe0c33694082", "asset_id": "13244681086321087932946246027856416106585284024824496763706748621681543444582", "price": "0.851", "size": "550", "side": "BUY", "timestamp": "1768404679357", "received_at": "2026-01-14T16:31:19.045808"}}
{"event_type": "price_change", "event_ts": "2026-01-14T16:31:19.045808", "ingestion_ts": "2026-01-14T16:33:58.842229", "market_id": "0x49686d26fb712515cd5e12c23f0a1c7e10214c7faa3cb0a730aabe0c33694082", "raw": {"market": "0x49686d26fb712515cd5e12c23f0a1c7e10214c7faa3cb0a730aabe0c33694082", "asset_id": "30442780799048074404860985387051749017905070253466005720364298335239299761065", "price": "0.149", "size": "550", "side": "SELL", "timestamp": "1768404679357", "received_at": "2026-01-14T16:31:19.045808"}}
{"event_type": "price_change", "event_ts": "2026-01-14T16:31:19.391750", "ingestion_ts": "2026-01-14T16:33:58.842229", "market_id": "0xaf9d0e448129a9f657f851d49495ba4742055d80e0ef1166ba0ee81d4d594214", "raw": {"market": "0xaf9d0e448129a9f657f851d49495ba4742055d80e0ef1166ba0ee81d4d594214", "asset_id": "4153292802911610701832309484716814274802943278345248636922528170020319407796", "price": "0.488", "size": "0", "side": "BUY", "timestamp": "1768404679583", "received_at": "2026-01-14T16:31:19.391750"}}
{"event_type": "price_change", "event_ts": "2026-01-14T16:31:19.391750", "ingestion_ts": "2026-01-14T16:33:58.842229", "market_id": "0xaf9d0e448129a9f657f851d49495ba4742055d80e0ef1166ba0ee81d4d594214", "raw": {"market": "0xaf9d0e448129a9f657f851d49495ba4742055d80e0ef1166ba0ee81d4d594214", "asset_id": "101676997363687199724245607342877036148401850938023978421879460310389391082353", "price": "0.512", "size": "0", "side": "SELL", "timestamp": "1768404679583", "received_at": "2026-01-14T16:31:19.391750"}}
{"event_type": "price_change", "event_ts": "2026-01-14T16:31:19.435682", "ingestion_ts": "2026-01-14T16:33:58.842229", "market_id": "0xaf9d0e448129a9f657f851d49495ba4742055d80e0ef1166ba0ee81d4d594214", "raw": {"market": "0xaf9d0e448129a9f657f851d49495ba4742055d80e0ef1166ba0ee81d4d594214", "asset_id": "4153292802911610701832309484716814274802943278345248636922528170020319407796", "price": "0.241", "size": "8", "side": "BUY", "timestamp": "1768404679631", "received_at": "2026-01-14T16:31:19.435682"}}
{"event_type": "price_change", "event_ts": "2026-01-14T16:31:19.435682", "ingestion_ts": "2026-01-14T16:33:58.842229", "market_id": "0xaf9d0e448129a9f657f851d49495ba4742055d80e0ef1166ba0ee81d4d594214", "raw": {"market": "0xaf9d0e448129a9f657f851d49495ba4742055d80e0ef1166ba0ee81d4d594214", "asset_id": "101676997363687199724245607342877036148401850938023978421879460310389391082353", "price": "0.759", "size": "8", "side": "SELL", "timestamp": "1768404679631", "received_at": "2026-01-14T16:31:19.435682"}}
{"event_type": "price_change", "event_ts": "2026-01-14T16:31:23.581743", "ingestion_ts": "2026-01-14T16:33:58.842229", "market_id": "0xcab7ba4a9133cfd407d7e73e5757e5abbace413b59421527a31113406c97815c", "raw": {"market": "0xcab7ba4a9133cfd407d7e73e5757e5abbace413b59421527a31113406c97815c", "asset_id": "20002636398944597965698652220992177552927816915094913583821579024925426590022", "price": "0.971", "size": "188", "side": "BUY", "timestamp": "1768404683884", "received_at": "2026-01-14T16:31:23.581743"}}
{"event_type": "price_change", "event_ts": "2026-01-14T16:31:23.581743", "ingestion_ts": "2026-01-14T16:33:58.842229", "market_id": "0xcab7ba4a9133cfd407d7e73e5757e5abbace413b59421527a31113406c97815c", "raw": {"market": "0xcab7ba4a9133cfd407d7e73e5757e5abbace413b59421527a31113406c97815c", "asset_id": "96361925776989336186111887920533578209326565663637092688733016597062311745569", "price": "0.029", "size": "188", "side": "SELL", "timestamp": "1768404683884", "received_at": "2026-01-14T16:31:23.581743"}}
{"event_type": "price_change", "event_ts": "2026-01-14T16:31:23.581801", "ingestion_ts": "2026-01-14T16:33:58.842229", "market_id": "0xcab7ba4a9133cfd407d7e73e5757e5abbace413b59421527a31113406c97815c", "raw": {"market": "0xcab7ba4a9133cfd407d7e73e5757e5abbace413b59421527a31113406c97815c", "asset_id": "96361925776989336186111887920533578209326565663637092688733016597062311745569", "price": "0.009", "size": "188", "side": "BUY", "timestamp": "1768404683885", "received_at": "2026-01-14T16:31:23.581801"}}
{"event_type": "price_change", "event_ts": "2026-01-14T16:31:23.581801", "ingestion_ts": "2026-01-14T16:33:58.842229", "market_id": "0xcab7ba4a9133cfd407d7e73e5757e5abbace413b59421527a31113406c97815c", "raw": {"market": "0xcab7ba4a9133cfd407d7e73e5757e5abbace413b59421527a31113406c97815c", "asset_id": "20002636398944597965698652220992177552927816915094913583821579024925426590022", "price": "0.991", "size": "188", "side": "SELL", "timestamp": "1768404683885", "received_at": "2026-01-14T16:31:23.581801"}}
{"event_type": "price_change", "event_ts": "2026-01-14T16:31:24.402995", "ingestion_ts": "2026-01-14T16:33:58.842229", "market_id": "0x49686d26fb712515cd5e12c23f0a1c7e10214c7faa3cb0a730aabe0c33694082", "raw": {"market": "0x49686d26fb712515cd5e12c23f0a1c7e10214c7faa3cb0a730aabe0c33694082", "asset_id": "30442780799048074404860985387051749017905070253466005720364298335239299761065", "price": "0.096", "size": "50", "side": "BUY", "timestamp": "1768404684743", "received_at": "2026-01-14T16:31:24.402995"}}
{"event_type": "price_change", "event_ts": "2026-01-14T16:31:24.402995", "ingestion_ts": "2026-01-14T16:33:58.842229", "market_id": "0x49686d26fb712515cd5e12c23f0a1c7e10214c7faa3cb0a730aabe0c33694082", "raw": {"market": "0x49686d26fb712515cd5e12c23f0a1c7e10214c7faa3cb0a730aabe0c33694082", "asset_id": "13244681086321087932946246027856416106585284024824496763706748621681543444582", "price": "0.904", "size": "50", "side": "SELL", "timestamp": "1768404684743", "received_at": "2026-01-14T16:31:24.402995"}}
{"event_type": "price_change", "event_ts": "2026-01-14T16:31:24.429426", "ingestion_ts": "2026-01-14T16:33:58.842229", "market_id": "0x49686d26fb712515cd5e12c23f0a1c7e10214c7faa3cb0a730aabe0c33694082", "raw": {"market": "0x49686d26fb712515cd5e12c23f0a1c7e10214c7faa3cb0a730aabe0c33694082", "asset_id": "13244681086321087932946246027856416106585284024824496763706748621681543444582", "price": "0.905", "size": "0", "side": "SELL", "timestamp": "1768404684770", "received_at": "2026-01-14T16:31:24.429426"}}
{"event_type": "price_change", "event_ts": "2026-01-14T16:31:24.429426", "ingestion_ts": "2026-01-14T16:33:58.842229", "market_id": "0x49686d26fb712515cd5e12c23f0a1c7e10214c7faa3cb0a730aabe0c33694082", "raw": {"market": "0x49686d26fb712515cd5e12c23f0a1c7e10214c7faa3cb0a730aabe0c33694082", "asset_id": "30442780799048074404860985387051749017905070253466005720364298335239299761065", "price": "0.095", "size": "0", "side": "BUY", "timestamp": "1768404684770", "received_at": "2026-01-14T16:31:24.429426"}}
{"event_type": "price_change", "event_ts": "2026-01-14T16:31:24.460034", "ingestion_ts": "2026-01-14T16:33:58.842229", "market_id": "0x49686d26fb712515cd5e12c23f0a1c7e10214c7faa3cb0a730aabe0c33694082", "raw": {"market": "0x49686d26fb712515cd5e12c23f0a1c7e10214c7faa3cb0a730aabe0c33694082", "asset_id": "13244681086321087932946246027856416106585284024824496763706748621681543444582", "price": "0.899", "size": "123", "side": "SELL", "timestamp": "1768404684798", "received_at": "2026-01-14T16:31:24.460034"}}
{"event_type": "price_change", "event_ts": "2026-01-14T16:31:24.460034", "ingestion_ts": "2026-01-14T16:33:58.842229", "market_id": "0x49686d26fb712515cd5e12c23f0a1c7e10214c7faa3cb0a730aabe0c33694082", "raw": {"market": "0x49686d26fb712515cd5e12c23f0a1c7e10214c7faa3cb0a730aabe0c33694082", "asset_id": "30442780799048074404860985387051749017905070253466005720364298335239299761065", "price": "0.101", "size": "123", "side": "BUY", "timestamp": "1768404684798", "received_at": "2026-01-14T16:31:24.460034"}}
{"event_type": "price_change", "event_ts": "2026-01-14T16:31:24.750537", "ingestion_ts": "2026-01-14T16:33:58.842229", "market_id": "0x49686d26fb712515cd5e12c23f0a1c7e10214c7faa3cb0a730aabe0c33694082", "raw": {"market": "0x49686d26fb712515cd5e12c23f0a1c7e10214c7faa3cb0a730aabe0c33694082", "asset_id": "30442780799048074404860985387051749017905070253466005720364298335239299761065", "price": "0.094", "size": "0", "side": "BUY", "timestamp": "1768404685089", "received_at": "2026-01-14T16:31:24.750537"}}
{"event_type": "price_change", "event_ts": "2026-01-14T16:31:24.750537", "ingestion_ts": "2026-01-14T16:33:58.842229", "market_id": "0x49686d26fb712515cd5e12c23f0a1c7e10214c7faa3cb0a730aabe0c33694082", "raw": {"market": "0x49686d26fb712515cd5e12c23f0a1c7e10214c7faa3cb0a730aabe0c33694082", "asset_id": "13244681086321087932946246027856416106585284024824496763706748621681543444582", "price": "0.906", "size": "0", "side": "SELL", "timestamp": "1768404685089", "received_at": "2026-01-14T16:31:24.750537"}}
{"event_type": "price_change", "event_ts": "2026-01-14T16:31:27.026025", "ingestion_ts": "2026-01-14T16:33:58.842229", "market_id": "0xc0e6b917320a47228fb96e3b5ae0e5c93773a5ae2662ae4e1f37807cfe47ce98", "raw": {"market": "0xc0e6b917320a47228fb96e3b5ae0e5c93773a5ae2662ae4e1f37807cfe47ce98", "asset_id": "58656358377246279051017109359677190749228949103591068167284263961542487110215", "price": "0.001", "size": "466.66", "side": "BUY", "timestamp": "1768404687365", "received_at": "2026-01-14T16:31:27.026025"}}
{"event_type": "price_change", "event_ts": "2026-01-14T16:31:27.026025", "ingestion_ts": "2026-01-14T16:33:58.842229", "market_id": "0xc0e6b917320a47228fb96e3b5ae0e5c93773a5ae2662ae4e1f37807cfe47ce98", "raw": {"market": "0xc0e6b917320a47228fb96e3b5ae0e5c93773a5ae2662ae4e1f37807cfe47ce98", "asset_id": "81647294538046680798858716589766492074338758116170717123345952330712416337530", "price": "0.999", "size": "466.66", "side": "SELL", "timestamp": "1768404687365", "received_at": "2026-01-14T16:31:27.026025"}}
{"event_type": "price_change", "event_ts": "2026-01-14T16:31:30.708163", "ingestion_ts": "2026-01-14T16:33:58.842229", "market_id": "0x49686d26fb712515cd5e12c23f0a1c7e10214c7faa3cb0a730aabe0c33694082", "raw": {"market": "0x49686d26fb712515cd5e12c23f0a1c7e10214c7faa3cb0a730aabe0c33694082", "asset_id": "30442780799048074404860985387051749017905070253466005720364298335239299761065", "price": "0.096", "size": "0", "side": "BUY", "timestamp": "1768404691031", "received_at": "2026-01-14T16:31:30.708163"}}
{"event_type": "price_change", "event_ts": "2026-01-14T16:31:30.708163", "ingestion_ts": "2026-01-14T16:33:58.842229", "market_id": "0x49686d26fb712515cd5e12c23f0a1c7e10214c7faa3cb0a730aabe0c33694082", "raw": {"market": "0x49686d26fb712515cd5e12c23f0a1c7e10214c7faa3cb0a730aabe0c33694082", "asset_id": "13244681086321087932946246027856416106585284024824496763706748621681543444582", "price": "0.904", "size": "0", "side": "SELL", "timestamp": "1768404691031", "received_at": "2026-01-14T16:31:30.708163"}}
{"event_type": "price_change", "event_ts": "2026-01-14T16:31:51.025935", "ingestion_ts": "2026-01-14T16:33:58.842229", "market_id": "0xaf9d0e448129a9f657f851d49495ba4742055d80e0ef1166ba0ee81d4d594214", "raw": {"market": "0xaf9d0e448129a9f657f851d49495ba4742055d80e0ef1166ba0ee81d4d594214", "asset_id": "4153292802911610701832309484716814274802943278345248636922528170020319407796", "price": "0.101", "size": "0", "side": "BUY", "timestamp": "1768404711233", "received_at": "2026-01-14T16:31:51.025935"}}
{"event_type": "price_change", "event_ts": "2026-01-14T16:31:51.025935", "ingestion_ts": "2026-01-14T16:33:58.842229", "market_id": "0xaf9d0e448129a9f657f851d49495ba4742055d80e0ef1166ba0ee81d4d594214", "raw": {"market": "0xaf9d0e448129a9f657f851d49495ba4742055d80e0ef1166ba0ee81d4d594214", "asset_id": "101676997363687199724245607342877036148401850938023978421879460310389391082353", "price": "0.899", "size": "0", "side": "SELL", "timestamp": "1768404711233", "received_at": "2026-01-14T16:31:51.025935"}}
{"event_type": "price_change", "event_ts": "2026-01-14T16:31:51.025977", "ingestion_ts": "2026-01-14T16:33:58.842229", "market_id": "0xaf9d0e448129a9f657f851d49495ba4742055d80e0ef1166ba0ee81d4d594214", "raw": {"market": "0xaf9d0e448129a9f657f851d49495ba4742055d80e0ef1166ba0ee81d4d594214", "asset_id": "4153292802911610701832309484716814274802943278345248636922528170020319407796", "price": "0.2", "size": "71.42", "side": "BUY", "timestamp": "1768404711233", "received_at": "2026-01-14T16:31:51.025977"}}
{"event_type": "price_change", "event_ts": "2026-01-14T16:31:51.025977", "ingestion_ts": "2026-01-14T16:33:58.842229", "market_id": "0xaf9d0e448129a9f657f851d49495ba4742055d80e0ef1166ba0ee81d4d594214", "raw": {"market": "0xaf9d0e448129a9f657f851d49495ba4742055d80e0ef1166ba0ee81d4d594214", "asset_id": "101676997363687199724245607342877036148401850938023978421879460310389391082353", "price": "0.8", "size": "71.42", "side": "SELL", "timestamp": "1768404711233", "received_at": "2026-01-14T16:31:51.025977"}}
{"event_type": "price_change", "event_ts": "2026-01-14T16:31:51.424402", "ingestion_ts": "2026-01-14T16:33:58.842229", "market_id": "0xaf9d0e448129a9f657f851d49495ba4742055d80e0ef1166ba0ee81d4d594214", "raw": {"market": "0xaf9d0e448129a9f657f851d49495ba4742055d80e0ef1166ba0ee81d4d594214", "asset_id": "4153292802911610701832309484716814274802943278345248636922528170020319407796", "price": "0.1", "size": "442.85", "side": "BUY", "timestamp": "1768404711548", "received_at": "2026-01-14T16:31:51.424402"}}
{"event_type": "price_change", "event_ts": "2026-01-14T16:31:51.424402", "ingestion_ts": "2026-01-14T16:33:58.842229", "market_id": "0xaf9d0e448129a9f657f851d49495ba4742055d80e0ef1166ba0ee81d4d594214", "raw": {"market": "0xaf9d0e448129a9f657f851d49495ba4742055d80e0ef1166ba0ee81d4d594214", "asset_id": "101676997363687199724245607342877036148401850938023978421879460310389391082353", "price": "0.9", "size": "442.85", "side": "SELL", "timestamp": "1768404711548", "received_at": "2026-01-14T16:31:51.424402"}}
{"event_type": "price_change", "event_ts": "2026-01-14T16:31:52.237867", "ingestion_ts": "2026-01-14T16:33:58.842229", "market_id": "0x318b222c1435b47c338e66ca6001f782711186a488ae7b7248f7edc6ff076a83", "raw": {"market": "0x318b222c1435b47c338e66ca6001f782711186a488ae7b7248f7edc6ff076a83", "asset_id": "63773739594775606083258239254748928077067768053882704658119720069071630213026", "price": "0.151", "size": "1058", "side": "BUY", "timestamp": "1768404712542", "received_at": "2026-01-14T16:31:52.237867"}}
{"event_type": "price_change", "event_ts": "2026-01-14T16:31:52.237867", "ingestion_ts": "2026-01-14T16:33:58.842229", "market_id": "0x318b222c1435b47c338e66ca6001f782711186a488ae7b7248f7edc6ff076a83", "raw": {"market": "0x318b222c1435b47c338e66ca6001f782711186a488ae7b7248f7edc6ff076a83", "asset_id": "56738600572035832904895845056468792275697823297413384908752239327866518310010", "price": "0.849", "size": "1058", "side": "SELL", "timestamp": "1768404712542", "received_at": "2026-01-14T16:31:52.237867"}}
{"event_type": "price_change", "event_ts": "2026-01-14T16:32:41.582127", "ingestion_ts": "2026-01-14T16:33:58.842229", "market_id": "0x50c669f178da4e5bbea7f1be25041fd278914712fa87a6a6f8e57d5923d88dee", "raw": {"market": "0x50c669f178da4e5bbea7f1be25041fd278914712fa87a6a6f8e57d5923d88dee", "asset_id": "74040420326294854165772767082819937451857852955603897473157746262672057685461", "price": "0.881", "size": "923.47", "side": "BUY", "timestamp": "1768404761916", "received_at": "2026-01-14T16:32:41.582127"}}
{"event_type": "price_change", "event_ts": "2026-01-14T16:32:41.582127", "ingestion_ts": "2026-01-14T16:33:58.842229", "market_id": "0x50c669f178da4e5bbea7f1be25041fd278914712fa87a6a6f8e57d5923d88dee", "raw": {"market": "0x50c669f178da4e5bbea7f1be25041fd278914712fa87a6a6f8e57d5923d88dee", "asset_id": "24682525479474221428144937281315825971983904267399062415430320764754931667953", "price": "0.119", "size": "923.47", "side": "SELL", "timestamp": "1768404761916", "received_at": "2026-01-14T16:32:41.582127"}}
{"event_type": "price_change", "event_ts": "2026-01-14T16:32:42.799559", "ingestion_ts": "2026-01-14T16:33:58.842229", "market_id": "0x50e477f0b316a3d97d60486479657c63be0763834d0e2e8a30b1b86dc3c1c001", "raw": {"market": "0x50e477f0b316a3d97d60486479657c63be0763834d0e2e8a30b1b86dc3c1c001", "asset_id": "39981134260608444876865205057565852475343967395624370698967311821208058420507", "price": "0.937", "size": "54.66", "side": "BUY", "timestamp": "1768404763075", "received_at": "2026-01-14T16:32:42.799559"}}
{"event_type": "price_change", "event_ts": "2026-01-14T16:32:42.799559", "ingestion_ts": "2026-01-14T16:33:58.842229", "market_id": "0x50e477f0b316a3d97d60486479657c63be0763834d0e2e8a30b1b86dc3c1c001", "raw": {"market": "0x50e477f0b316a3d97d60486479657c63be0763834d0e2e8a30b1b86dc3c1c001", "asset_id": "60573178197991590327120832143415406583517170365625050489007297367895074266641", "price": "0.063", "size": "54.66", "side": "SELL", "timestamp": "1768404763075", "received_at": "2026-01-14T16:32:42.799559"}}
{"event_type": "price_change", "event_ts": "2026-01-14T16:33:03.035755", "ingestion_ts": "2026-01-14T16:33:58.842229", "market_id": "0xea644975be7b2ad32b536a94ae21b707ecb2f84290225b24e60ca46dd77903dd", "raw": {"market": "0xea644975be7b2ad32b536a94ae21b707ecb2f84290225b24e60ca46dd77903dd", "asset_id": "19255594762111702415265750364124818677094538461124581923455280001407159960455", "price": "0.938", "size": "54.66", "side": "BUY", "timestamp": "1768404783367", "received_at": "2026-01-14T16:33:03.035755"}}
{"event_type": "price_change", "event_ts": "2026-01-14T16:33:03.035755", "ingestion_ts": "2026-01-14T16:33:58.842229", "market_id": "0xea644975be7b2ad32b536a94ae21b707ecb2f84290225b24e60ca46dd77903dd", "raw": {"market": "0xea644975be7b2ad32b536a94ae21b707ecb2f84290225b24e60ca46dd77903dd", "asset_id": "110044455628775971785618539427229099821815416148768008176051068105157446559241", "price": "0.062", "size": "54.66", "side": "SELL", "timestamp": "1768404783367", "received_at": "2026-01-14T16:33:03.035755"}}
{"event_type": "price_change", "event_ts": "2026-01-14T16:33:03.586191", "ingestion_ts": "2026-01-14T16:33:58.842229", "market_id": "0x2393ed0b0fdc450054c7b9071907eca75cf4fc36e385adf4a0a5f99ee62243e8", "raw": {"market": "0x2393ed0b0fdc450054c7b9071907eca75cf4fc36e385adf4a0a5f99ee62243e8", "asset_id": "32769749367306925959219403371425714180265458150646381231272229429098460625924", "price": "0.946", "size": "255.69", "side": "BUY", "timestamp": "1768404783917", "received_at": "2026-01-14T16:33:03.586191"}}
{"event_type": "price_change", "event_ts": "2026-01-14T16:33:03.586191", "ingestion_ts": "2026-01-14T16:33:58.842229", "market_id": "0x2393ed0b0fdc450054c7b9071907eca75cf4fc36e385adf4a0a5f99ee62243e8", "raw": {"market": "0x2393ed0b0fdc450054c7b9071907eca75cf4fc36e385adf4a0a5f99ee62243e8", "asset_id": "100074770378634056601572485653252702850363676459996771990439989989293515601975", "price": "0.054", "size": "255.69", "side": "SELL", "timestamp": "1768404783917", "received_at": "2026-01-14T16:33:03.586191"}}
{"event_type": "price_change", "event_ts": "2026-01-14T16:33:03.586224", "ingestion_ts": "2026-01-14T16:33:58.842229", "market_id": "0x2393ed0b0fdc450054c7b9071907eca75cf4fc36e385adf4a0a5f99ee62243e8", "raw": {"market": "0x2393ed0b0fdc450054c7b9071907eca75cf4fc36e385adf4a0a5f99ee62243e8", "asset_id": "100074770378634056601572485653252702850363676459996771990439989989293515601975", "price": "0.047", "size": "153", "side": "BUY", "timestamp": "1768404783918", "received_at": "2026-01-14T16:33:03.586224"}}
{"event_type": "price_change", "event_ts": "2026-01-14T16:33:03.586224", "ingestion_ts": "2026-01-14T16:33:58.842229", "market_id": "0x2393ed0b0fdc450054c7b9071907eca75cf4fc36e385adf4a0a5f99ee62243e8", "raw": {"market": "0x2393ed0b0fdc450054c7b9071907eca75cf4fc36e385adf4a0a5f99ee62243e8", "asset_id": "32769749367306925959219403371425714180265458150646381231272229429098460625924", "price": "0.953", "size": "153", "side": "SELL", "timestamp": "1768404783918", "received_at": "2026-01-14T16:33:03.586224"}}
{"event_type": "price_change", "event_ts": "2026-01-14T16:33:03.782378", "ingestion_ts": "2026-01-14T16:33:58.842229", "market_id": "0x9472be65457510b7fc3477b20ba90910e99d92eac8421a14bf4b7b7a08ef31dc", "raw": {"market": "0x9472be65457510b7fc3477b20ba90910e99d92eac8421a14bf4b7b7a08ef31dc", "asset_id": "43311793366960417907757893276427136943959788721376762326430771171648759300146", "price": "0.83", "size": "0", "side": "BUY", "timestamp": "1768404784123", "received_at": "2026-01-14T16:33:03.782378"}}
{"event_type": "price_change", "event_ts": "2026-01-14T16:33:03.782378", "ingestion_ts": "2026-01-14T16:33:58.842229", "market_id": "0x9472be65457510b7fc3477b20ba90910e99d92eac8421a14bf4b7b7a08ef31dc", "raw": {"market": "0x9472be65457510b7fc3477b20ba90910e99d92eac8421a14bf4b7b7a08ef31dc", "asset_id": "73414222381656326204771753454630063673548497164758947581648273905027617570612", "price": "0.17", "size": "0", "side": "SELL", "timestamp": "1768404784123", "received_at": "2026-01-14T16:33:03.782378"}}
{"event_type": "price_change", "event_ts": "2026-01-14T16:33:03.937178", "ingestion_ts": "2026-01-14T16:33:58.842229", "market_id": "0x9472be65457510b7fc3477b20ba90910e99d92eac8421a14bf4b7b7a08ef31dc", "raw": {"market": "0x9472be65457510b7fc3477b20ba90910e99d92eac8421a14bf4b7b7a08ef31dc", "asset_id": "43311793366960417907757893276427136943959788721376762326430771171648759300146", "price": "0.923", "size": "419", "side": "BUY", "timestamp": "1768404784278", "received_at": "2026-01-14T16:33:03.937178"}}
{"event_type": "price_change", "event_ts": "2026-01-14T16:33:03.937178", "ingestion_ts": "2026-01-14T16:33:58.842229", "market_id": "0x9472be65457510b7fc3477b20ba90910e99d92eac8421a14bf4b7b7a08ef31dc", "raw": {"market": "0x9472be65457510b7fc3477b20ba90910e99d92eac8421a14bf4b7b7a08ef31dc", "asset_id": "73414222381656326204771753454630063673548497164758947581648273905027617570612", "price": "0.077", "size": "419", "side": "SELL", "timestamp": "1768404784278", "received_at": "2026-01-14T16:33:03.937178"}}
{"event_type": "price_change", "event_ts": "2026-01-14T16:33:03.937215", "ingestion_ts": "2026-01-14T16:33:58.842229", "market_id": "0x9472be65457510b7fc3477b20ba90910e99d92eac8421a14bf4b7b7a08ef31dc", "raw": {"market": "0x9472be65457510b7fc3477b20ba90910e99d92eac8421a14bf4b7b7a08ef31dc", "asset_id": "43311793366960417907757893276427136943959788721376762326430771171648759300146", "price": "0.83", "size": "10", "side": "BUY", "timestamp": "1768404784279", "received_at": "2026-01-14T16:33:03.937215"}}
{"event_type": "price_change", "event_ts": "2026-01-14T16:33:03.937215", "ingestion_ts": "2026-01-14T16:33:58.842229", "market_id": "0x9472be65457510b7fc3477b20ba90910e99d92eac8421a14bf4b7b7a08ef31dc", "raw": {"market": "0x9472be65457510b7fc3477b20ba90910e99d92eac8421a14bf4b7b7a08ef31dc", "asset_id": "73414222381656326204771753454630063673548497164758947581648273905027617570612", "price": "0.17", "size": "10", "side": "SELL", "timestamp": "1768404784279", "received_at": "2026-01-14T16:33:03.937215"}}
{"event_type": "price_change", "event_ts": "2026-01-14T16:33:29.346997", "ingestion_ts": "2026-01-14T16:33:58.842229", "market_id": "0x9472be65457510b7fc3477b20ba90910e99d92eac8421a14bf4b7b7a08ef31dc", "raw": {"market": "0x9472be65457510b7fc3477b20ba90910e99d92eac8421a14bf4b7b7a08ef31dc", "asset_id": "43311793366960417907757893276427136943959788721376762326430771171648759300146", "price": "0.574", "size": "0", "side": "BUY", "timestamp": "1768404809689", "received_at": "2026-01-14T16:33:29.346997"}}
{"event_type": "price_change", "event_ts": "2026-01-14T16:33:29.346997", "ingestion_ts": "2026-01-14T16:33:58.842229", "market_id": "0x9472be65457510b7fc3477b20ba90910e99d92eac8421a14bf4b7b7a08ef31dc", "raw": {"market": "0x9472be65457510b7fc3477b20ba90910e99d92eac8421a14bf4b7b7a08ef31dc", "asset_id": "73414222381656326204771753454630063673548497164758947581648273905027617570612", "price": "0.426", "size": "0", "side": "SELL", "timestamp": "1768404809689", "received_at": "2026-01-14T16:33:29.346997"}}
{"event_type": "price_change", "event_ts": "2026-01-14T16:33:29.394422", "ingestion_ts": "2026-01-14T16:33:58.842229", "market_id": "0x9472be65457510b7fc3477b20ba90910e99d92eac8421a14bf4b7b7a08ef31dc", "raw": {"market": "0x9472be65457510b7fc3477b20ba90910e99d92eac8421a14bf4b7b7a08ef31dc", "asset_id": "43311793366960417907757893276427136943959788721376762326430771171648759300146", "price": "0.572", "size": "5", "side": "BUY", "timestamp": "1768404809735", "received_at": "2026-01-14T16:33:29.394422"}}
{"event_type": "price_change", "event_ts": "2026-01-14T16:33:29.394422", "ingestion_ts": "2026-01-14T16:33:58.842229", "market_id": "0x9472be65457510b7fc3477b20ba90910e99d92eac8421a14bf4b7b7a08ef31dc", "raw": {"market": "0x9472be65457510b7fc3477b20ba90910e99d92eac8421a14bf4b7b7a08ef31dc", "asset_id": "73414222381656326204771753454630063673548497164758947581648273905027617570612", "price": "0.428", "size": "5", "side": "SELL", "timestamp": "1768404809735", "received_at": "2026-01-14T16:33:29.394422"}}
{"event_type": "price_change", "event_ts": "2026-01-14T16:33:29.468190", "ingestion_ts": "2026-01-14T16:33:58.842229", "market_id": "0x50c669f178da4e5bbea7f1be25041fd278914712fa87a6a6f8e57d5923d88dee", "raw": {"market": "0x50c669f178da4e5bbea7f1be25041fd278914712fa87a6a6f8e57d5923d88dee", "asset_id": "74040420326294854165772767082819937451857852955603897473157746262672057685461", "price": "0.882", "size": "0", "side": "BUY", "timestamp": "1768404809808", "received_at": "2026-01-14T16:33:29.468190"}}
{"event_type": "price_change", "event_ts": "2026-01-14T16:33:29.468190", "ingestion_ts": "2026-01-14T16:33:58.842229", "market_id": "0x50c669f178da4e5bbea7f1be25041fd278914712fa87a6a6f8e57d5923d88dee", "raw": {"market": "0x50c669f178da4e5bbea7f1be25041fd278914712fa87a6a6f8e57d5923d88dee", "asset_id": "24682525479474221428144937281315825971983904267399062415430320764754931667953", "price": "0.118", "size": "0", "side": "SELL", "timestamp": "1768404809808", "received_at": "2026-01-14T16:33:29.468190"}}
{"event_type": "price_change", "event_ts": "2026-01-14T16:33:29.614321", "ingestion_ts": "2026-01-14T16:33:58.842229", "market_id": "0x50c669f178da4e5bbea7f1be25041fd278914712fa87a6a6f8e57d5923d88dee", "raw": {"market": "0x50c669f178da4e5bbea7f1be25041fd278914712fa87a6a6f8e57d5923d88dee", "asset_id": "74040420326294854165772767082819937451857852955603897473157746262672057685461", "price": "0.882", "size": "10", "side": "BUY", "timestamp": "1768404809954", "received_at": "2026-01-14T16:33:29.614321"}}
{"event_type": "price_change", "event_ts": "2026-01-14T16:33:29.614321", "ingestion_ts": "2026-01-14T16:33:58.842229", "market_id": "0x50c669f178da4e5bbea7f1be25041fd278914712fa87a6a6f8e57d5923d88dee", "raw": {"market": "0x50c669f178da4e5bbea7f1be25041fd278914712fa87a6a6f8e57d5923d88dee", "asset_id": "24682525479474221428144937281315825971983904267399062415430320764754931667953", "price": "0.118", "size": "10", "side": "SELL", "timestamp": "1768404809954", "received_at": "2026-01-14T16:33:29.614321"}}
{"event_type": "price_change", "event_ts": "2026-01-14T16:33:29.614372", "ingestion_ts": "2026-01-14T16:33:58.842229", "market_id": "0x50c669f178da4e5bbea7f1be25041fd278914712fa87a6a6f8e57d5923d88dee", "raw": {"market": "0x50c669f178da4e5bbea7f1be25041fd278914712fa87a6a6f8e57d5923d88dee", "asset_id": "74040420326294854165772767082819937451857852955603897473157746262672057685461", "price": "0.923", "size": "1805", "side": "BUY", "timestamp": "1768404809955", "received_at": "2026-01-14T16:33:29.614372"}}
{"event_type": "price_change", "event_ts": "2026-01-14T16:33:29.614372", "ingestion_ts": "2026-01-14T16:33:58.842229", "market_id": "0x50c669f178da4e5bbea7f1be25041fd278914712fa87a6a6f8e57d5923d88dee", "raw": {"market": "0x50c669f178da4e5bbea7f1be25041fd278914712fa87a6a6f8e57d5923d88dee", "asset_id": "24682525479474221428144937281315825971983904267399062415430320764754931667953", "price": "0.077", "size": "1805", "side": "SELL", "timestamp": "1768404809955", "received_at": "2026-01-14T16:33:29.614372"}}
{"event_type": "price_change", "event_ts": "2026-01-14T16:33:37.542460", "ingestion_ts": "2026-01-14T16:33:58.842229", "market_id": "0x49686d26fb712515cd5e12c23f0a1c7e10214c7faa3cb0a730aabe0c33694082", "raw": {"market": "0x49686d26fb712515cd5e12c23f0a1c7e10214c7faa3cb0a730aabe0c33694082", "asset_id": "13244681086321087932946246027856416106585284024824496763706748621681543444582", "price": "0.293", "size": "0", "side": "BUY", "timestamp": "1768404817763", "received_at": "2026-01-14T16:33:37.542460"}}
{"event_type": "price_change", "event_ts": "2026-01-14T16:33:37.542460", "ingestion_ts": "2026-01-14T16:33:58.842229", "market_id": "0x49686d26fb712515cd5e12c23f0a1c7e10214c7faa3cb0a730aabe0c33694082", "raw": {"market": "0x49686d26fb712515cd5e12c23f0a1c7e10214c7faa3cb0a730aabe0c33694082", "asset_id": "30442780799048074404860985387051749017905070253466005720364298335239299761065", "price": "0.707", "size": "0", "side": "SELL", "timestamp": "1768404817763", "received_at": "2026-01-14T16:33:37.542460"}}
{"event_type": "price_change", "event_ts": "2026-01-14T16:33:37.782874", "ingestion_ts": "2026-01-14T16:33:58.842229", "market_id": "0xc55db914f0fd1fee18997706712c0dfd8d0369cdbef93a9fef12bd001914ca77", "raw": {"market": "0xc55db914f0fd1fee18997706712c0dfd8d0369cdbef93a9fef12bd001914ca77", "asset_id": "114600293444080540179603459515770723592661967180480327891296353898330242622833", "price": "0.842", "size": "0", "side": "BUY", "timestamp": "1768404817987", "received_at": "2026-01-14T16:33:37.782874"}}
{"event_type": "price_change", "event_ts": "2026-01-14T16:33:37.782874", "ingestion_ts": "2026-01-14T16:33:58.842229", "market_id": "0xc55db914f0fd1fee18997706712c0dfd8d0369cdbef93a9fef12bd001914ca77", "raw": {"market": "0xc55db914f0fd1fee18997706712c0dfd8d0369cdbef93a9fef12bd001914ca77", "asset_id": "72354723612769247426741660426331235762851940382312402276325808095604519806766", "price": "0.158", "size": "0", "side": "SELL", "timestamp": "1768404817987", "received_at": "2026-01-14T16:33:37.782874"}}
{"event_type": "price_change", "event_ts": "2026-01-14T16:33:37.935866", "ingestion_ts": "2026-01-14T16:33:58.842229", "market_id": "0xc55db914f0fd1fee18997706712c0dfd8d0369cdbef93a9fef12bd001914ca77", "raw": {"market": "0xc55db914f0fd1fee18997706712c0dfd8d0369cdbef93a9fef12bd001914ca77", "asset_id": "114600293444080540179603459515770723592661967180480327891296353898330242622833", "price": "0.842", "size": "10", "side": "BUY", "timestamp": "1768404818216", "received_at": "2026-01-14T16:33:37.935866"}}
{"event_type": "price_change", "event_ts": "2026-01-14T16:33:37.935866", "ingestion_ts": "2026-01-14T16:33:58.842229", "market_id": "0xc55db914f0fd1fee18997706712c0dfd8d0369cdbef93a9fef12bd001914ca77", "raw": {"market": "0xc55db914f0fd1fee18997706712c0dfd8d0369cdbef93a9fef12bd001914ca77", "asset_id": "72354723612769247426741660426331235762851940382312402276325808095604519806766", "price": "0.158", "size": "10", "side": "SELL", "timestamp": "1768404818216", "received_at": "2026-01-14T16:33:37.935866"}}
{"event_type": "price_change", "event_ts": "2026-01-14T16:33:37.935899", "ingestion_ts": "2026-01-14T16:33:58.842229", "market_id": "0xc55db914f0fd1fee18997706712c0dfd8d0369cdbef93a9fef12bd001914ca77", "raw": {"market": "0xc55db914f0fd1fee18997706712c0dfd8d0369cdbef93a9fef12bd001914ca77", "asset_id": "114600293444080540179603459515770723592661967180480327891296353898330242622833", "price": "0.923", "size": "782", "side": "BUY", "timestamp": "1768404818217", "received_at": "2026-01-14T16:33:37.935899"}}
{"event_type": "price_change", "event_ts": "2026-01-14T16:33:37.935899", "ingestion_ts": "2026-01-14T16:33:58.842229", "market_id": "0xc55db914f0fd1fee18997706712c0dfd8d0369cdbef93a9fef12bd001914ca77", "raw": {"market": "0xc55db914f0fd1fee18997706712c0dfd8d0369cdbef93a9fef12bd001914ca77", "asset_id": "72354723612769247426741660426331235762851940382312402276325808095604519806766", "price": "0.077", "size": "782", "side": "SELL", "timestamp": "1768404818217", "received_at": "2026-01-14T16:33:37.935899"}}
{"event_type": "price_change", "event_ts": "2026-01-14T16:33:39.887683", "ingestion_ts": "2026-01-14T16:33:58.842229", "market_id": "0x2393ed0b0fdc450054c7b9071907eca75cf4fc36e385adf4a0a5f99ee62243e8", "raw": {"market": "0x2393ed0b0fdc450054c7b9071907eca75cf4fc36e385adf4a0a5f99ee62243e8", "asset_id": "32769749367306925959219403371425714180265458150646381231272229429098460625924", "price": "0.946", "size": "149.99", "side": "BUY", "timestamp": "1768404820221", "received_at": "2026-01-14T16:33:39.887683"}}
{"event_type": "price_change", "event_ts": "2026-01-14T16:33:39.887683", "ingestion_ts": "2026-01-14T16:33:58.842229", "market_id": "0x2393ed0b0fdc450054c7b9071907eca75cf4fc36e385adf4a0a5f99ee62243e8", "raw": {"market": "0x2393ed0b0fdc450054c7b9071907eca75cf4fc36e385adf4a0a5f99ee62243e8", "asset_id": "100074770378634056601572485653252702850363676459996771990439989989293515601975", "price": "0.054", "size": "149.99", "side": "SELL", "timestamp": "1768404820221", "received_at": "2026-01-14T16:33:39.887683"}}
