{"event_type": "price_change", "event_ts": "2026-01-14T16:23:19.735753", "ingestion_ts": "2026-01-14T16:33:58.842229", "market_id": "0xc0e6b917320a47228fb96e3b5ae0e5c93773a5ae2662ae4e1f37807cfe47ce98", "raw": {"market": "0xc0e6b917320a47228fb96e3b5ae0e5c93773a5ae2662ae4e1f37807cfe47ce98", "asset_id": "58656358377246279051017109359677190749228949103591068167284263961542487110215", "price": "0.002", "size": "3304.31", "side": "BUY", "timestamp": "1768404200021", "received_at": "2026-01-14T16:23:19.735753"}}
{"event_type": "price_change", "event_ts": "2026-01-14T16:23:19.735753", "ingestion_ts": "2026-01-14T16:33:58.842229", "market_id": "0xc0e6b917320a47228fb96e3b5ae0e5c93773a5ae2662ae4e1f37807cfe47ce98", "raw": {"market": "0xc0e6b917320a47228fb96e3b5ae0e5c93773a5ae2662ae4e1f37807cfe47ce98", "asset_id": "81647294538046680798858716589766492074338758116170717123345952330712416337530", "price": "0.998", "size": "3304.31", "side": "SELL", "timestamp": "1768404200021", "received_at": "2026-01-14T16:23:19.735753"}}
{"event_type": "price_change", "event_ts": "2026-01-14T16:23:21.642218", "ingestion_ts": "2026-01-14T16:33:58.842229", "market_id": "0xe9c127a8c35f045d37b5344b0a36711084fa20c2fc1618bf178a5386f90610be", "raw": {"market": "0xe9c127a8c35f045d37b5344b0a36711084fa20c2fc1618bf178a5386f90610be", "asset_id": "80230236018433940569996058935444651347308266584430516013229815570706872276819", "price": "0.004", "size": "115.74", "side": "SELL", "timestamp": "1768404201971", "received_at": "2026-01-14T16:23:21.642218"}}
{"event_type": "price_change", "event_ts": "2026-01-14T16:23:21.642218", "ingestion_ts": "2026-01-14T16:33:58.842229", "market_id": "0xe9c127a8c35f045d37b5344b0a36711084fa20c2fc1618bf178a5386f90610be", "raw": {"market": "0xe9c127a8c35f045d37b5344b0a36711084fa20c2fc1618bf178a5386f90610be", "asset_id": "107000426448217931795450451304515386602910396776318075817601265223856116134349", "price": "0.996", "size": "115.74", "side": "BUY", "timestamp": "1768404201971", "received_at": "2026-01-14T16:23:21.642218"}}
{"event_type": "price_change", "event_ts": "2026-01-14T16:23:21.642242", "ingestion_ts": "2026-01-14T16:33:58.842229", "market_id": "0xe9c127a8c35f045d37b5344b0a36711084fa20c2fc1618bf178a5386f90610be", "raw": {"market": "0xe9c127a8c35f045d37b5344b0a36711084fa20c2fc1618bf178a5386f90610be", "asset_id": "80230236018433940569996058935444651347308266584430516013229815570706872276819", "price": "0.003", "size": "0", "side": "SELL", "timestamp": "1768404201971", "received_at": "2026-01-14T16:23:21.642242"}}
{"event_type": "price_change", "event_ts": "2026-01-14T16:23:21.642242", "ingestion_ts": "2026-01-14T16:33:58.842229", "market_id": "0xe9c127a8c35f045d37b5344b0a36711084fa20c2fc1618bf178a5386f90610be", "raw": {"market": "0xe9c127a8c35f045d37b5344b0a36711084fa20c2fc1618bf178a5386f90610be", "asset_id": "107000426448217931795450451304515386602910396776318075817601265223856116134349", "price": "0.997", "size": "0", "side": "BUY", "timestamp": "1768404201971", "received_at": "2026-01-14T16:23:21.642242"}}
{"event_type": "price_change", "event_ts": "2026-01-14T16:23:21.700301", "ingestion_ts": "2026-01-14T16:33:58.842229", "market_id": "0xe9c127a8c35f045d37b5344b0a36711084fa20c2fc1618bf178a5386f90610be", "raw": {"market": "0xe9c127a8c35f045d37b5344b0a36711084fa20c2fc1618bf178a5386f90610be", "asset_id": "80230236018433940569996058935444651347308266584430516013229815570706872276819", "price": "0.022", "size": "0", "side": "SELL", "timestamp": "1768404202002", "received_at": "2026-01-14T16:23:21.700301"}}
{"event_type": "price_change", "event_ts": "2026-01-14T16:23:21.700301", "ingestion_ts": "2026-01-14T16:33:58.842229", "market_id": "0xe9c127a8c35f045d37b5344b0a36711084fa20c2fc1618bf178a5386f90610be", "raw": {"market": "0xe9c127a8c35f045d37b5344b0a36711084fa20c2fc1618bf178a5386f90610be", "asset_id": "107000426448217931795450451304515386602910396776318075817601265223856116134349", "price": "0.978", "size": "0", "side": "BUY", "timestamp": "1768404202002", "received_at": "2026-01-14T16:23:21.700301"}}
{"event_type": "price_change", "event_ts": "2026-01-14T16:23:31.315311", "ingestion_ts": "2026-01-14T16:33:58.842229", "market_id": "0xcab7ba4a9133cfd407d7e73e5757e5abbace413b59421527a31113406c97815c", "raw": {"market": "0xcab7ba4a9133cfd407d7e73e5757e5abbace413b59421527a31113406c97815c", "asset_id": "96361925776989336186111887920533578209326565663637092688733016597062311745569", "price": "0.011", "size": "12", "side": "SELL", "timestamp": "1768404211644", "received_at": "2026-01-14T16:23:31.315311"}}
{"event_type": "price_change", "event_ts": "2026-01-14T16:23:31.315311", "ingestion_ts": "2026-01-14T16:33:58.842229", "market_id": "0xcab7ba4a9133cfd407d7e73e5757e5abbace413b59421527a31113406c97815c", "raw": {"market": "0xcab7ba4a9133cfd407d7e73e5757e5abbace413b59421527a31113406c97815c", "asset_id": "20002636398944597965698652220992177552927816915094913583821579024925426590022", "price": "0.989", "size": "12", "side": "BUY", "timestamp": "1768404211644", "received_at": "2026-01-14T16:23:31.315311"}}
{"event_type": "price_change", "event_ts": "2026-01-14T16:23:31.315332", "ingestion_ts": "2026-01-14T16:33:58.842229", "market_id": "0xcab7ba4a9133cfd407d7e73e5757e5abbace413b59421527a31113406c97815c", "raw": {"market": "0xcab7ba4a9133cfd407d7e73e5757e5abbace413b59421527a31113406c97815c", "asset_id": "96361925776989336186111887920533578209326565663637092688733016597062311745569", "price": "0.01", "size": "0", "side": "SELL", "timestamp": "1768404211644", "received_at": "2026-01-14T16:23:31.315332"}}
{"event_type": "price_change", "event_ts": "2026-01-14T16:23:31.315332", "ingestion_ts": "2026-01-14T16:33:58.842229", "market_id": "0xcab7ba4a9133cfd407d7e73e5757e5abbace413b59421527a31113406c97815c", "raw": {"market": "0xcab7ba4a9133cfd407d7e73e5757e5abbace413b59421527a31113406c97815c", "asset_id": "20002636398944597965698652220992177552927816915094913583821579024925426590022", "price": "0.99", "size": "0", "side": "BUY", "timestamp": "1768404211644", "received_at": "2026-01-14T16:23:31.315332"}}
{"event_type": "price_change", "event_ts": "2026-01-14T16:23:31.343288", "ingestion_ts": "2026-01-14T16:33:58.842229", "market_id": "0xcab7ba4a9133cfd407d7e73e5757e5abbace413b59421527a31113406c97815c", "raw": {"market": "0xcab7ba4a9133cfd407d7e73e5757e5abbace413b59421527a31113406c97815c", "asset_id": "96361925776989336186111887920533578209326565663637092688733016597062311745569", "price": "0.007", "size": "31.38", "side": "BUY", "timestamp": "1768404211674", "received_at": "2026-01-14T16:23:31.343288"}}
{"event_type": "price_change", "event_ts": "2026-01-14T16:23:31.343288", "ingestion_ts": "2026-01-14T16:33:58.842229", "market_id": "0xcab7ba4a9133cfd407d7e73e5757e5abbace413b59421527a31113406c97815c", "raw": {"market": "0xcab7ba4a9133cfd407d7e73e5757e5abbace413b59421527a31113406c97815c", "asset_id": "20002636398944597965698652220992177552927816915094913583821579024925426590022", "price": "0.993", "size": "31.38", "side": "SELL", "timestamp": "1768404211674", "received_at": "2026-01-14T16:23:31.343288"}}
{"event_type": "price_change", "event_ts": "2026-01-14T16:23:31.344920", "ingestion_ts": "2026-01-14T16:33:58.842229", "market_id": "0xcab7ba4a9133cfd407d7e73e5757e5abbace413b59421527a31113406c97815c", "raw": {"market": "0xcab7ba4a9133cfd407d7e73e5757e5abbace413b59421527a31113406c97815c", "asset_id": "20002636398944597965698652220992177552927816915094913583821579024925426590022", "price": "0.971", "size": "188", "side": "BUY", "timestamp": "1768404211676", "received_at": "2026-01-14T16:23:31.344920"}}
{"event_type": "price_change", "event_ts": "2026-01-14T16:23:31.344920", "ingestion_ts": "2026-01-14T16:33:58.842229", "market_id": "0xcab7ba4a9133cfd407d7e73e5757e5abbace413b59421527a31113406c97815c", "raw": {"market": "0xcab7ba4a9133cfd407d7e73e5757e5abbace413b59421527a31113406c97815c", "asset_id": "96361925776989336186111887920533578209326565663637092688733016597062311745569", "price": "0.029", "size": "188", "side": "SELL", "timestamp": "1768404211676", "received_at": "2026-01-14T16:23:31.344920"}}
{"event_type": "price_change", "event_ts": "2026-01-14T16:23:31.368696", "ingestion_ts": "2026-01-14T16:33:58.842229", "market_id": "0xcab7ba4a9133cfd407d7e73e5757e5abbace413b59421527a31113406c97815c", "raw": {"market": "0xcab7ba4a9133cfd407d7e73e5757e5abbace413b59421527a31113406c97815c", "asset_id": "96361925776989336186111887920533578209326565663637092688733016597062311745569", "price": "0.009", "size": "188", "side": "BUY", "timestamp": "1768404211700", "received_at": "2026-01-14T16:23:31.368696"}}
{"event_type": "price_change", "event_ts": "2026-01-14T16:23:31.368696", "ingestion_ts": "2026-01-14T16:33:58.842229", "market_id": "0xcab7ba4a9133cfd407d7e73e5757e5abbace413b59421527a31113406c97815c", "raw": {"market": "0xcab7ba4a9133cfd407d7e73e5757e5abbace413b59421527a31113406c97815c", "asset_id": "20002636398944597965698652220992177552927816915094913583821579024925426590022", "price": "0.991", "size": "188", "side": "SELL", "timestamp": "1768404211700", "received_at": "2026-01-14T16:23:31.368696"}}
{"event_type": "price_change", "event_ts": "2026-01-14T16:23:54.894501", "ingestion_ts": "2026-01-14T16:33:58.842229", "market_id": "0x318b222c1435b47c338e66ca6001f782711186a488ae7b7248f7edc6ff076a83", "raw": {"market": "0x318b222c1435b47c338e66ca6001f782711186a488ae7b7248f7edc6ff076a83", "asset_id": "63773739594775606083258239254748928077067768053882704658119720069071630213026", "price": "0.205", "size": "1462", "side": "BUY", "timestamp": "1768404235227", "received_at": "2026-01-14T16:23:54.894501"}}
{"event_type": "price_change", "event_ts": "2026-01-14T16:23:54.894501", "ingestion_ts": "2026-01-14T16:33:58.842229", "market_id": "0x318b222c1435b47c338e66ca6001f782711186a488ae7b7248f7edc6ff076a83", "raw": {"market": "0x318b222c1435b47c338e66ca6001f782711186a488ae7b7248f7edc6ff076a83", "asset_id": "56738600572035832904895845056468792275697823297413384908752239327866518310010", "price": "0.795", "size": "1462", "side": "SELL", "timestamp": "1768404235227", "received_at": "2026-01-14T16:23:54.894501"}}
{"event_type": "price_change", "event_ts": "2026-01-14T16:24:22.171289", "ingestion_ts": "2026-01-14T16:33:58.842229", "market_id": "0x44f08744458b8896620cd3330bc5e1ea69df4199b02d4fc583b3fc96e5d314ce", "raw": {"market": "0x44f08744458b8896620cd3330bc5e1ea69df4199b02d4fc583b3fc96e5d314ce", "asset_id": "72327831507226612545928776794104143393438710920370371172884559893525100761096", "price": "0.88", "size": "870.47", "side": "BUY", "timestamp": "1768404262457", "received_at": "2026-01-14T16:24:22.171289"}}
{"event_type": "price_change", "event_ts": "2026-01-14T16:24:22.171289", "ingestion_ts": "2026-01-14T16:33:58.842229", "market_id": "0x44f08744458b8896620cd3330bc5e1ea69df4199b02d4fc583b3fc96e5d314ce", "raw": {"market": "0x44f08744458b8896620cd3330bc5e1ea69df4199b02d4fc583b3fc96e5d314ce", "asset_id": "49194009556504828848509244326501559253829462790583873936160989575507522044057", "price": "0.12", "size": "870.47", "side": "SELL", "timestamp": "1768404262457", "received_at": "2026-01-14T16:24:22.171289"}}
{"event_type": "price_change", "event_ts": "2026-01-14T16:24:22.408169", "ingestion_ts": "2026-01-14T16:33:58.842229", "market_id": "0x2393ed0b0fdc450054c7b9071907eca75cf4fc36e385adf4a0a5f99ee62243e8", "raw": {"market": "0x2393ed0b0fdc450054c7b9071907eca75cf4fc36e385adf4a0a5f99ee62243e8", "asset_id": "32769749367306925959219403371425714180265458150646381231272229429098460625924", "price": "0.814", "size": "0", "side": "BUY", "timestamp": "1768404262622", "received_at": "2026-01-14T16:24:22.408169"}}
{"event_type": "price_change", "event_ts": "2026-01-14T16:24:22.408169", "ingestion_ts": "2026-01-14T16:33:58.842229", "market_id": "0x2393ed0b0fdc450054c7b9071907eca75cf4fc36e385adf4a0a5f99ee62243e8", "raw": {"market": "0x2393ed0b0fdc450054c7b9071907eca75cf4fc36e385adf4a0a5f99ee62243e8", "asset_id": "100074770378634056601572485653252702850363676459996771990439989989293515601975", "price": "0.186", "size": "0", "side": "SELL", "timestamp": "1768404262622", "received_at": "2026-01-14T16:24:22.408169"}}
{"event_type": "price_change", "event_ts": "2026-01-14T16:24:30.969314", "ingestion_ts": "2026-01-14T16:33:58.842229", "market_id": "0x2393ed0b0fdc450054c7b9071907eca75cf4fc36e385adf4a0a5f99ee62243e8", "raw": {"market": "0x2393ed0b0fdc450054c7b9071907eca75cf4fc36e385adf4a0a5f99ee62243e8", "asset_id": "32769749367306925959219403371425714180265458150646381231272229429098460625924", "price": "0.191", "size": "836", "side": "BUY", "timestamp": "1768404271292", "received_at": "2026-01-14T16:24:30.969314"}}
{"event_type": "price_change", "event_ts": "2026-01-14T16:24:30.969314", "ingestion_ts": "2026-01-14T16:33:58.842229", "market_id": "0x2393ed0b0fdc450054c7b9071907eca75cf4fc36e385adf4a0a5f99ee62243e8", "raw": {"market": "0x2393ed0b0fdc450054c7b9071907eca75cf4fc36e385adf4a0a5f99ee62243e8", "asset_id": "100074770378634056601572485653252702850363676459996771990439989989293515601975", "price": "0.809", "size": "836", "side": "SELL", "timestamp": "1768404271292", "received_at": "2026-01-14T16:24:30.969314"}}
{"event_type": "price_change", "event_ts": "2026-01-14T16:24:31.153159", "ingestion_ts": "2026-01-14T16:33:58.842229", "market_id": "0x49686d26fb712515cd5e12c23f0a1c7e10214c7faa3cb0a730aabe0c33694082", "raw": {"market": "0x49686d26fb712515cd5e12c23f0a1c7e10214c7faa3cb0a730aabe0c33694082", "asset_id": "13244681086321087932946246027856416106585284024824496763706748621681543444582", "price": "0.191", "size": "836", "side": "BUY", "timestamp": "1768404271461", "received_at": "2026-01-14T16:24:31.153159"}}
{"event_type": "price_change", "event_ts": "2026-01-14T16:24:31.153159", "ingestion_ts": "2026-01-14T16:33:58.842229", "market_id": "0x49686d26fb712515cd5e12c23f0a1c7e10214c7faa3cb0a730aabe0c33694082", "raw": {"market": "0x49686d26fb712515cd5e12c23f0a1c7e10214c7faa3cb0a730aabe0c33694082", "asset_id": "30442780799048074404860985387051749017905070253466005720364298335239299761065", "price": "0.809", "size": "836", "side": "SELL", "timestamp": "1768404271461", "received_at": "2026-01-14T16:24:31.153159"}}
{"event_type": "price_change", "event_ts": "2026-01-14T16:24:31.164358", "ingestion_ts": "2026-01-14T16:33:58.842229", "market_id": "0x50c669f178da4e5bbea7f1be25041fd278914712fa87a6a6f8e57d5923d88dee", "raw": {"market": "0x50c669f178da4e5bbea7f1be25041fd278914712fa87a6a6f8e57d5923d88dee", "asset_id": "74040420326294854165772767082819937451857852955603897473157746262672057685461", "price": "0.925", "size": "0", "side": "BUY", "timestamp": "1768404271477", "received_at": "2026-01-14T16:24:31.164358"}}
{"event_type": "price_change", "event_ts": "2026-01-14T16:24:31.164358", "ingestion_ts": "2026-01-14T16:33:58.842229", "market_id": "0x50c669f178da4e5bbea7f1be25041fd278914712fa87a6a6f8e57d5923d88dee", "raw": {"market": "0x50c669f178da4e5bbea7f1be25041fd278914712fa87a6a6f8e57d5923d88dee", "asset_id": "24682525479474221428144937281315825971983904267399062415430320764754931667953", "price": "0.075", "size": "0", "side": "SELL", "timestamp": "1768404271477", "received_at": "2026-01-14T16:24:31.164358"}}
{"event_type": "price_change", "event_ts": "2026-01-14T16:24:31.164397", "ingestion_ts": "2026-01-14T16:33:58.842229", "market_id": "0x9472be65457510b7fc3477b20ba90910e99d92eac8421a14bf4b7b7a08ef31dc", "raw": {"market": "0x9472be65457510b7fc3477b20ba90910e99d92eac8421a14bf4b7b7a08ef31dc", "asset_id": "43311793366960417907757893276427136943959788721376762326430771171648759300146", "price": "0.926", "size": "0", "side": "BUY", "timestamp": "1768404271477", "received_at": "2026-01-14T16:24:31.164397"}}
{"event_type": "price_change", "event_ts": "2026-01-14T16:24:31.164397", "ingestion_ts": "2026-01-14T16:33:58.842229", "market_id": "0x9472be65457510b7fc3477b20ba90910e99d92eac8421a14bf4b7b7a08ef31dc", "raw": {"market": "0x9472be65457510b7fc3477b20ba90910e99d92eac8421a14bf4b7b7a08ef31dc", "asset_id": "73414222381656326204771753454630063673548497164758947581648273905027617570612", "price": "0.074", "size": "0", "side": "SELL", "timestamp": "1768404271477", "received_at": "2026-01-14T16:24:31.164397"}}
{"event_type": "price_change", "event_ts": "2026-01-14T16:24:31.315901", "ingestion_ts": "2026-01-14T16:33:58.842229", "market_id": "0x9472be65457510b7fc3477b20ba90910e99d92eac8421a14bf4b7b7a08ef31dc", "raw": {"market": "0x9472be65457510b7fc3477b20ba90910e99d92eac8421a14bf4b7b7a08ef31dc", "asset_id": "43311793366960417907757893276427136943959788721376762326430771171648759300146", "price": "0.826", "size": "0", "side": "BUY", "timestamp": "1768404271636", "received_at": "2026-01-14T16:24:31.315901"}}
{"event_type": "price_change", "event_ts": "2026-01-14T16:24:31.315901", "ingestion_ts": "2026-01-14T16:33:58.842229", "market_id": "0x9472be65457510b7fc3477b20ba90910e99d92eac8421a14bf4b7b7a08ef31dc", "raw": {"market": "0x9472be65457510b7fc3477b20ba90910e99d92eac8421a14bf4b7b7a08ef31dc", "asset_id": "73414222381656326204771753454630063673548497164758947581648273905027617570612", "price": "0.174", "size": "0", "side": "SELL", "timestamp": "1768404271636", "received_at": "2026-01-14T16:24:31.315901"}}
{"event_type": "price_change", "event_ts": "2026-01-14T16:24:31.316056", "ingestion_ts": "2026-01-14T16:33:58.842229", "market_id": "0xc55db914f0fd1fee18997706712c0dfd8d0369cdbef93a9fef12bd001914ca77", "raw": {"market": "0xc55db914f0fd1fee18997706712c0dfd8d0369cdbef93a9fef12bd001914ca77", "asset_id": "114600293444080540179603459515770723592661967180480327891296353898330242622833", "price": "0.925", "size": "0", "side": "BUY", "timestamp": "1768404271636", "received_at": "2026-01-14T16:24:31.316056"}}
{"event_type": "price_change", "event_ts": "2026-01-14T16:24:31.316056", "ingestion_ts": "2026-01-14T16:33:58.842229", "market_id": "0xc55db914f0fd1fee18997706712c0dfd8d0369cdbef93a9fef12bd001914ca77", "raw": {"market": "0xc55db914f0fd1fee18997706712c0dfd8d0369cdbef93a9fef12bd001914ca77", "asset_id": "72354723612769247426741660426331235762851940382312402276325808095604519806766", "price": "0.075", "size": "0", "side": "SELL", "timestamp": "1768404271636", "received_at": "2026-01-14T16:24:31.316056"}}
{"event_type": "price_change", "event_ts": "2026-01-14T16:24:31.316083", "ingestion_ts": "2026-01-14T16:33:58.842229", "market_id": "0xc55db914f0fd1fee18997706712c0dfd8d0369cdbef93a9fef12bd001914ca77", "raw": {"market": "0xc55db914f0fd1fee18997706712c0dfd8d0369cdbef93a9fef12bd001914ca77", "asset_id": "114600293444080540179603459515770723592661967180480327891296353898330242622833", "price": "0.838", "size": "0", "side": "BUY", "timestamp": "1768404271636", "received_at": "2026-01-14T16:24:31.316083"}}
{"event_type": "price_change", "event_ts": "2026-01-14T16:24:31.316083", "ingestion_ts": "2026-01-14T16:33:58.842229", "market_id": "0xc55db914f0fd1fee18997706712c0dfd8d0369cdbef93a9fef12bd001914ca77", "raw": {"market": "0xc55db914f0fd1fee18997706712c0dfd8d0369cdbef93a9fef12bd001914ca77", "asset_id": "72354723612769247426741660426331235762851940382312402276325808095604519806766", "price": "0.162", "size": "0", "side": "SELL", "timestamp": "1768404271636", "received_at": "2026-01-14T16:24:31.316083"}}
{"event_type": "price_change", "event_ts": "2026-01-14T16:24:31.382177", "ingestion_ts": "2026-01-14T16:33:58.842229", "market_id": "0xb9bbdd34304344dcc45803780a34c97d73a00133a5ecf70f63e1008b8abb2fca", "raw": {"market": "0xb9bbdd34304344dcc45803780a34c97d73a00133a5ecf70f63e1008b8abb2fca", "asset_id": "8682484153073832526711485265636767086525069344085206423986003504588877767339", "price": "0.946", "size": "0", "side": "BUY", "timestamp": "1768404271711", "received_at": "2026-01-14T16:24:31.382177"}}
{"event_type": "price_change", "event_ts": "2026-01-14T16:24:31.382177", "ingestion_ts": "2026-01-14T16:33:58.842229", "market_id": "0xb9bbdd34304344dcc45803780a34c97d73a00133a5ecf70f63e1008b8abb2fca", "raw": {"market": "0xb9bbdd34304344dcc45803780a34c97d73a00133a5ecf70f63e1008b8abb2fca", "asset_id": "72012724360700510767037780555710363830014634797787940282136454146828040926557", "price": "0.054", "size": "0", "side": "SELL", "timestamp": "1768404271711", "received_at": "2026-01-14T16:24:31.382177"}}
{"event_type": "price_change", "event_ts": "2026-01-14T16:24:31.424093", "ingestion_ts": "2026-01-14T16:33:58.842229", "market_id": "0x9472be65457510b7fc3477b20ba90910e99d92eac8421a14bf4b7b7a08ef31dc", "raw": {"market": "0x9472be65457510b7fc3477b20ba90910e99d92eac8421a14bf4b7b7a08ef31dc", "asset_id": "43311793366960417907757893276427136943959788721376762326430771171648759300146", "price": "0.926", "size": "20", "side": "BUY", "timestamp": "1768404271751", "received_at": "2026-01-14T16:24:31.424093"}}
{"event_type": "price_change", "event_ts": "2026-01-14T16:24:31.424093", "ingestion_ts": "2026-01-14T16:33:58.842229", "market_id": "0x9472be65457510b7fc3477b20ba90910e99d92eac8421a14bf4b7b7a08ef31dc", "raw": {"market": "0x9472be65457510b7fc3477b20ba90910e99d92eac8421a14bf4b7b7a08ef31dc", "asset_id": "73414222381656326204771753454630063673548497164758947581648273905027617570612", "price": "0.074", "size": "20", "side": "SELL", "timestamp": "1768404271751", "received_at": "2026-01-14T16:24:31.424093"}}
{"event_type": "price_change", "event_ts": "2026-01-14T16:24:31.424130", "ingestion_ts": "2026-01-14T16:33:58.842229", "market_id": "0xc55db914f0fd1fee18997706712c0dfd8d0369cdbef93a9fef12bd001914ca77", "raw": {"market": "0xc55db914f0fd1fee18997706712c0dfd8d0369cdbef93a9fef12bd001914ca77", "asset_id": "114600293444080540179603459515770723592661967180480327891296353898330242622833", "price": "0.925", "size": "20", "side": "BUY", "timestamp": "1768404271751", "received_at": "2026-01-14T16:24:31.424130"}}
{"event_type": "price_change", "event_ts": "2026-01-14T16:24:31.424130", "ingestion_ts": "2026-01-14T16:33:58.842229", "market_id": "0xc55db914f0fd1fee18997706712c0dfd8d0369cdbef93a9fef12bd001914ca77", "raw": {"market": "0xc55db914f0fd1fee18997706712c0dfd8d0369cdbef93a9fef12bd001914ca77", "asset_id": "72354723612769247426741660426331235762851940382312402276325808095604519806766", "price": "0.075", "size": "20", "side": "SELL", "timestamp": "1768404271751", "received_at": "2026-01-14T16:24:31.424130"}}
{"event_type": "price_change", "event_ts": "2026-01-14T16:24:31.424147", "ingestion_ts": "2026-01-14T16:33:58.842229", "market_id": "0x9472be65457510b7fc3477b20ba90910e99d92eac8421a14bf4b7b7a08ef31dc", "raw": {"market": "0x9472be65457510b7fc3477b20ba90910e99d92eac8421a14bf4b7b7a08ef31dc", "asset_id": "43311793366960417907757893276427136943959788721376762326430771171648759300146", "price": "0.828", "size": "10", "side": "BUY", "timestamp": "1768404271752", "received_at": "2026-01-14T16:24:31.424147"}}
{"event_type": "price_change", "event_ts": "2026-01-14T16:24:31.424147", "ingestion_ts": "2026-01-14T16:33:58.842229", "market_id": "0x9472be65457510b7fc3477b20ba90910e99d92eac8421a14bf4b7b7a08ef31dc", "raw": {"market": "0x9472be65457510b7fc3477b20ba90910e99d92eac8421a14bf4b7b7a08ef31dc", "asset_id": "73414222381656326204771753454630063673548497164758947581648273905027617570612", "price": "0.172", "size": "10", "side": "SELL", "timestamp": "1768404271752", "received_at": "2026-01-14T16:24:31.424147"}}
{"event_type": "price_change", "event_ts": "2026-01-14T16:24:31.424160", "ingestion_ts": "2026-01-14T16:33:58.842229", "market_id": "0xc55db914f0fd1fee18997706712c0dfd8d0369cdbef93a9fef12bd001914ca77", "raw": {"market": "0xc55db914f0fd1fee18997706712c0dfd8d0369cdbef93a9fef12bd001914ca77", "asset_id": "114600293444080540179603459515770723592661967180480327891296353898330242622833", "price": "0.84", "size": "10", "side": "BUY", "timestamp": "1768404271752", "received_at": "2026-01-14T16:24:31.424160"}}
{"event_type": "price_change", "event_ts": "2026-01-14T16:24:31.424160", "ingestion_ts": "2026-01-14T16:33:58.842229", "market_id": "0xc55db914f0fd1fee18997706712c0dfd8d0369cdbef93a9fef12bd001914ca77", "raw": {"market": "0xc55db914f0fd1fee18997706712c0dfd8d0369cdbef93a9fef12bd001914ca77", "asset_id": "72354723612769247426741660426331235762851940382312402276325808095604519806766", "price": "0.16", "size": "10", "side": "SELL", "timestamp": "1768404271752", "received_at": "2026-01-14T16:24:31.424160"}}
{"event_type": "price_change", "event_ts": "2026-01-14T16:24:31.487578", "ingestion_ts": "2026-01-14T16:33:58.842229", "market_id": "0xb9bbdd34304344dcc45803780a34c97d73a00133a5ecf70f63e1008b8abb2fca", "raw": {"market": "0xb9bbdd34304344dcc45803780a34c97d73a00133a5ecf70f63e1008b8abb2fca", "asset_id": "8682484153073832526711485265636767086525069344085206423986003504588877767339", "price": "0.952", "size": "325.29", "side": "BUY", "timestamp": "1768404271787", "received_at": "2026-01-14T16:24:31.487578"}}
{"event_type": "price_change", "event_ts": "2026-01-14T16:24:31.487578", "ingestion_ts": "2026-01-14T16:33:58.842229", "market_id": "0xb9bbdd34304344dcc45803780a34c97d73a00133a5ecf70f63e1008b8abb2fca", "raw": {"market": "0xb9bbdd34304344dcc45803780a34c97d73a00133a5ecf70f63e1008b8abb2fca", "asset_id": "72012724360700510767037780555710363830014634797787940282136454146828040926557", "price": "0.048", "size": "325.29", "side": "SELL", "timestamp": "1768404271787", "received_at": "2026-01-14T16:24:31.487578"}}
{"event_type": "price_change", "event_ts": "2026-01-14T16:24:37.682323", "ingestion_ts": "2026-01-14T16:33:58.842229", "market_id": "0x318b222c1435b47c338e66ca6001f782711186a488ae7b7248f7edc6ff076a83", "raw": {"market": "0x318b222c1435b47c338e66ca6001f782711186a488ae7b7248f7edc6ff076a83", "asset_id": "63773739594775606083258239254748928077067768053882704658119720069071630213026", "price": "0.206", "size": "776", "side": "BUY", "timestamp": "1768404278014", "received_at": "2026-01-14T16:24:37.682323"}}
{"event_type": "price_change", "event_ts": "2026-01-14T16:24:37.682323", "ingestion_ts": "2026-01-14T16:33:58.842229", "market_id": "0x318b222c1435b47c338e66ca6001f782711186a488ae7b7248f7edc6ff076a83", "raw": {"market": "0x318b222c1435b47c338e66ca6001f782711186a488ae7b7248f7edc6ff076a83", "asset_id": "56738600572035832904895845056468792275697823297413384908752239327866518310010", "price": "0.794", "size": "776", "side": "SELL", "timestamp": "1768404278014", "received_at": "2026-01-14T16:24:37.682323"}}
{"event_type": "price_change", "event_ts": "2026-01-14T16:24:54.665981", "ingestion_ts": "2026-01-14T16:33:58.842229", "market_id": "0x49686d26fb712515cd5e12c23f0a1c7e10214c7faa3cb0a730aabe0c33694082", "raw": {"market": "0x49686d26fb712515cd5e12c23f0a1c7e10214c7faa3cb0a730aabe0c33694082", "asset_id": "13244681086321087932946246027856416106585284024824496763706748621681543444582", "price": "0.851", "size": "500", "side": "BUY", "timestamp": "1768404295000", "received_at": "2026-01-14T16:24:54.665981"}}
{"event_type": "price_change", "event_ts": "2026-01-14T16:24:54.665981", "ingestion_ts": "2026-01-14T16:33:58.842229", "market_id": "0x49686d26fb712515cd5e12c23f0a1c7e10214c7faa3cb0a730aabe0c33694082", "raw": {"market": "0x49686d26fb712515cd5e12c23f0a1c7e10214c7faa3cb0a730aabe0c33694082", "asset_id": "30442780799048074404860985387051749017905070253466005720364298335239299761065", "price": "0.149", "size": "500", "side": "SELL", "timestamp": "1768404295000", "received_at": "2026-01-14T16:24:54.665981"}}
{"event_type": "price_change", "event_ts": "2026-01-14T16:24:54.701208", "ingestion_ts": "2026-01-14T16:33:58.842229", "market_id": "0x49686d26fb712515cd5e12c23f0a1c7e10214c7faa3cb0a730aabe0c33694082", "raw": {"market": "0x49686d26fb712515cd5e12c23f0a1c7e10214c7faa3cb0a730aabe0c33694082", "asset_id": "13244681086321087932946246027856416106585284024824496763706748621681543444582", "price": "0.899", "size": "16", "side": "SELL", "timestamp": "1768404295028", "received_at": "2026-01-14T16:24:54.701208"}}
{"event_type": "price_change", "event_ts": "2026-01-14T16:24:54.701208", "ingestion_ts": "2026-01-14T16:33:58.842229", "market_id": "0x49686d26fb712515cd5e12c23f0a1c7e10214c7faa3cb0a730aabe0c33694082", "raw": {"market": "0x49686d26fb712515cd5e12c23f0a1c7e10214c7faa3cb0a730aabe0c33694082", "asset_id": "30442780799048074404860985387051749017905070253466005720364298335239299761065", "price": "0.101", "size": "16", "side": "BUY", "timestamp": "1768404295028", "received_at": "2026-01-14T16:24:54.701208"}}
{"event_type": "price_change", "event_ts": "2026-01-14T16:24:54.701237", "ingestion_ts": "2026-01-14T16:33:58.842229", "market_id": "0x49686d26fb712515cd5e12c23f0a1c7e10214c7faa3cb0a730aabe0c33694082", "raw": {"market": "0x49686d26fb712515cd5e12c23f0a1c7e10214c7faa3cb0a730aabe0c33694082", "asset_id": "13244681086321087932946246027856416106585284024824496763706748621681543444582", "price": "0.851", "size": "550", "side": "BUY", "timestamp": "1768404295034", "received_at": "2026-01-14T16:24:54.701237"}}
{"event_type": "price_change", "event_ts": "2026-01-14T16:24:54.701237", "ingestion_ts": "2026-01-14T16:33:58.842229", "market_id": "0x49686d26fb712515cd5e12c23f0a1c7e10214c7faa3cb0a730aabe0c33694082", "raw": {"market": "0x49686d26fb712515cd5e12c23f0a1c7e10214c7faa3cb0a730aabe0c33694082", "asset_id": "30442780799048074404860985387051749017905070253466005720364298335239299761065", "price": "0.149", "size": "550", "side": "SELL", "timestamp": "1768404295034", "received_at": "2026-01-14T16:24:54.701237"}}
{"event_type": "price_change", "event_ts": "2026-01-14T16:24:54.727677", "ingestion_ts": "2026-01-14T16:33:58.842229", "market_id": "0x49686d26fb712515cd5e12c23f0a1c7e10214c7faa3cb0a730aabe0c33694082", "raw": {"market": "0x49686d26fb712515cd5e12c23f0a1c7e10214c7faa3cb0a730aabe0c33694082", "asset_id": "13244681086321087932946246027856416106585284024824496763706748621681543444582", "price": "0.907", "size": "133", "side": "SELL", "timestamp": "1768404295059", "received_at": "2026-01-14T16:24:54.727677"}}
{"event_type": "price_change", "event_ts": "2026-01-14T16:24:54.727677", "ingestion_ts": "2026-01-14T16:33:58.842229", "market_id": "0x49686d26fb712515cd5e12c23f0a1c7e10214c7faa3cb0a730aabe0c33694082", "raw": {"market": "0x49686d26fb712515cd5e12c23f0a1c7e10214c7faa3cb0a730aabe0c33694082", "asset_id": "30442780799048074404860985387051749017905070253466005720364298335239299761065", "price": "0.093", "size": "133", "side": "BUY", "timestamp": "1768404295059", "received_at": "2026-01-14T16:24:54.727677"}}
{"event_type": "price_change", "event_ts": "2026-01-14T16:24:54.815476", "ingestion_ts": "2026-01-14T16:33:58.842229", "market_id": "0x50c669f178da4e5bbea7f1be25041fd278914712fa87a6a6f8e57d5923d88dee", "raw": {"market": "0x50c669f178da4e5bbea7f1be25041fd278914712fa87a6a6f8e57d5923d88dee", "asset_id": "74040420326294854165772767082819937451857852955603897473157746262672057685461", "price": "0.882", "size": "0", "side": "BUY", "timestamp": "1768404295148", "received_at": "2026-01-14T16:24:54.815476"}}
{"event_type": "price_change", "event_ts": "2026-01-14T16:24:54.815476", "ingestion_ts": "2026-01-14T16:33:58.842229", "market_id": "0x50c669f178da4e5bbea7f1be25041fd278914712fa87a6a6f8e57d5923d88dee", "raw": {"market": "0x50c669f178da4e5bbea7f1be25041fd278914712fa87a6a6f8e57d5923d88dee", "asset_id": "24682525479474221428144937281315825971983904267399062415430320764754931667953", "price": "0.118", "size": "0", "side": "SELL", "timestamp": "1768404295148", "received_at": "2026-01-14T16:24:54.815476"}}
{"event_type": "price_change", "event_ts": "2026-01-14T16:24:55.004704", "ingestion_ts": "2026-01-14T16:33:58.842229", "market_id": "0x50c669f178da4e5bbea7f1be25041fd278914712fa87a6a6f8e57d5923d88dee", "raw": {"market": "0x50c669f178da4e5bbea7f1be25041fd278914712fa87a6a6f8e57d5923d88dee", "asset_id": "74040420326294854165772767082819937451857852955603897473157746262672057685461", "price": "0.925", "size": "20", "side": "BUY", "timestamp": "1768404295339", "received_at": "2026-01-14T16:24:55.004704"}}
{"event_type": "price_change", "event_ts": "2026-01-14T16:24:55.004704", "ingestion_ts": "2026-01-14T16:33:58.842229", "market_id": "0x50c669f178da4e5bbea7f1be25041fd278914712fa87a6a6f8e57d5923d88dee", "raw": {"market": "0x50c669f178da4e5bbea7f1be25041fd278914712fa87a6a6f8e57d5923d88dee", "asset_id": "24682525479474221428144937281315825971983904267399062415430320764754931667953", "price": "0.075", "size": "20", "side": "SELL", "timestamp": "1768404295339", "received_at": "2026-01-14T16:24:55.004704"}}
{"event_type": "price_change", "event_ts": "2026-01-14T16:24:55.004772", "ingestion_ts": "2026-01-14T16:33:58.842229", "market_id": "0x50c669f178da4e5bbea7f1be25041fd278914712fa87a6a6f8e57d5923d88dee", "raw": {"market": "0x50c669f178da4e5bbea7f1be25041fd278914712fa87a6a6f8e57d5923d88dee", "asset_id": "74040420326294854165772767082819937451857852955603897473157746262672057685461", "price": "0.882", "size": "10", "side": "BUY", "timestamp": "1768404295340", "received_at": "2026-01-14T16:24:55.004772"}}
{"event_type": "price_change", "event_ts": "2026-01-14T16:24:55.004772", "ingestion_ts": "2026-01-14T16:33:58.842229", "market_id": "0x50c669f178da4e5bbea7f1be25041fd278914712fa87a6a6f8e57d5923d88dee", "raw": {"market": "0x50c669f178da4e5bbea7f1be25041fd278914712fa87a6a6f8e57d5923d88dee", "asset_id": "24682525479474221428144937281315825971983904267399062415430320764754931667953", "price": "0.118", "size": "10", "side": "SELL", "timestamp": "1768404295340", "received_at": "2026-01-14T16:24:55.004772"}}
{"event_type": "price_change", "event_ts": "2026-01-14T16:24:55.874678", "ingestion_ts": "2026-01-14T16:33:58.842229", "market_id": "0x49686d26fb712515cd5e12c23f0a1c7e10214c7faa3cb0a730aabe0c33694082", "raw": {"market": "0x49686d26fb712515cd5e12c23f0a1c7e10214c7faa3cb0a730aabe0c33694082", "asset_id": "30442780799048074404860985387051749017905070253466005720364298335239299761065", "price": "0.094", "size": "50", "side": "BUY", "timestamp": "1768404296184", "received_at": "2026-01-14T16:24:55.874678"}}
{"event_type": "price_change", "event_ts": "2026-01-14T16:24:55.874678", "ingestion_ts": "2026-01-14T16:33:58.842229", "market_id": "0x49686d26fb712515cd5e12c23f0a1c7e10214c7faa3cb0a730aabe0c33694082", "raw": {"market": "0x49686d26fb712515cd5e12c23f0a1c7e10214c7faa3cb0a730aabe0c33694082", "asset_id": "13244681086321087932946246027856416106585284024824496763706748621681543444582", "price": "0.906", "size": "50", "side": "SELL", "timestamp": "1768404296184", "received_at": "2026-01-14T16:24:55.874678"}}
{"event_type": "price_change", "event_ts": "2026-01-14T16:24:55.888182", "ingestion_ts": "2026-01-14T16:33:58.842229", "market_id": "0x49686d26fb712515cd5e12c23f0a1c7e10214c7faa3cb0a730aabe0c33694082", "raw": {"market": "0x49686d26fb712515cd5e12c23f0a1c7e10214c7faa3cb0a730aabe0c33694082", "asset_id": "13244681086321087932946246027856416106585284024824496763706748621681543444582", "price": "0.907", "size": "0", "side": "SELL", "timestamp": "1768404296213", "received_at": "2026-01-14T16:24:55.888182"}}
{"event_type": "price_change", "event_ts": "2026-01-14T16:24:55.888182", "ingestion_ts": "2026-01-14T16:33:58.842229", "market_id": "0x49686d26fb712515cd5e12c23f0a1c7e10214c7faa3cb0a730aabe0c33694082", "raw": {"market": "0x49686d26fb712515cd5e12c23f0a1c7e10214c7faa3cb0a730aabe0c33694082", "asset_id": "30442780799048074404860985387051749017905070253466005720364298335239299761065", "price": "0.093", "size": "0", "side": "BUY", "timestamp": "1768404296213", "received_at": "2026-01-14T16:24:55.888182"}}
{"event_type": "price_change", "event_ts": "2026-01-14T16:24:55.918504", "ingestion_ts": "2026-01-14T16:33:58.842229", "market_id": "0x49686d26fb712515cd5e12c23f0a1c7e10214c7faa3cb0a730aabe0c33694082", "raw": {"market": "0x49686d26fb712515cd5e12c23f0a1c7e10214c7faa3cb0a730aabe0c33694082", "asset_id": "13244681086321087932946246027856416106585284024824496763706748621681543444582", "price": "0.899", "size": "134", "side": "SELL", "timestamp": "1768404296239", "received_at": "2026-01-14T16:24:55.918504"}}
{"event_type": "price_change", "event_ts": "2026-01-14T16:24:55.918504", "ingestion_ts": "2026-01-14T16:33:58.842229", "market_id": "0x49686d26fb712515cd5e12c23f0a1c7e10214c7faa3cb0a730aabe0c33694082", "raw": {"market": "0x49686d26fb712515cd5e12c23f0a1c7e10214c7faa3cb0a730aabe0c33694082", "asset_id": "30442780799048074404860985387051749017905070253466005720364298335239299761065", "price": "0.101", "size": "134", "side": "BUY", "timestamp": "1768404296239", "received_at": "2026-01-14T16:24:55.918504"}}
{"event_type": "price_change", "event_ts": "2026-01-14T16:24:56.010801", "ingestion_ts": "2026-01-14T16:33:58.842229", "market_id": "0x2393ed0b0fdc450054c7b9071907eca75cf4fc36e385adf4a0a5f99ee62243e8", "raw": {"market": "0x2393ed0b0fdc450054c7b9071907eca75cf4fc36e385adf4a0a5f99ee62243e8", "asset_id": "32769749367306925959219403371425714180265458150646381231272229429098460625924", "price": "0.877", "size": "0", "side": "BUY", "timestamp": "1768404296335", "received_at": "2026-01-14T16:24:56.010801"}}
{"event_type": "price_change", "event_ts": "2026-01-14T16:24:56.010801", "ingestion_ts": "2026-01-14T16:33:58.842229", "market_id": "0x2393ed0b0fdc450054c7b9071907eca75cf4fc36e385adf4a0a5f99ee62243e8", "raw": {"market": "0x2393ed0b0fdc450054c7b9071907eca75cf4fc36e385adf4a0a5f99ee62243e8", "asset_id": "100074770378634056601572485653252702850363676459996771990439989989293515601975", "price": "0.123", "size": "0", "side": "SELL", "timestamp": "1768404296335", "received_at": "2026-01-14T16:24:56.010801"}}
{"event_type": "price_change", "event_ts": "2026-01-14T16:24:56.215334", "ingestion_ts": "2026-01-14T16:33:58.842229", "market_id": "0x2393ed0b0fdc450054c7b9071907eca75cf4fc36e385adf4a0a5f99ee62243e8", "raw": {"market": "0x2393ed0b0fdc450054c7b9071907eca75cf4fc36e385adf4a0a5f99ee62243e8", "asset_id": "32769749367306925959219403371425714180265458150646381231272229429098460625924", "price": "0.879", "size": "20", "side": "BUY", "timestamp": "1768404296537", "received_at": "2026-01-14T16:24:56.215334"}}
{"event_type": "price_change", "event_ts": "2026-01-14T16:24:56.215334", "ingestion_ts": "2026-01-14T16:33:58.842229", "market_id": "0x2393ed0b0fdc450054c7b9071907eca75cf4fc36e385adf4a0a5f99ee62243e8", "raw": {"market": "0x2393ed0b0fdc450054c7b9071907eca75cf4fc36e385adf4a0a5f99ee62243e8", "asset_id": "100074770378634056601572485653252702850363676459996771990439989989293515601975", "price": "0.121", "size": "20", "side": "SELL", "timestamp": "1768404296537", "received_at": "2026-01-14T16:24:56.215334"}}
{"event_type": "price_change", "event_ts": "2026-01-14T16:24:56.215383", "ingestion_ts": "2026-01-14T16:33:58.842229", "market_id": "0x2393ed0b0fdc450054c7b9071907eca75cf4fc36e385adf4a0a5f99ee62243e8", "raw": {"market": "0x2393ed0b0fdc450054c7b9071907eca75cf4fc36e385adf4a0a5f99ee62243e8", "asset_id": "32769749367306925959219403371425714180265458150646381231272229429098460625924", "price": "0.814", "size": "10", "side": "BUY", "timestamp": "1768404296538", "received_at": "2026-01-14T16:24:56.215383"}}
{"event_type": "price_change", "event_ts": "2026-01-14T16:24:56.215383", "ingestion_ts": "2026-01-14T16:33:58.842229", "market_id": "0x2393ed0b0fdc450054c7b9071907eca75cf4fc36e385adf4a0a5f99ee62243e8", "raw": {"market": "0x2393ed0b0fdc450054c7b9071907eca75cf4fc36e385adf4a0a5f99ee62243e8", "asset_id": "100074770378634056601572485653252702850363676459996771990439989989293515601975", "price": "0.186", "size": "10", "side": "SELL", "timestamp": "1768404296538", "received_at": "2026-01-14T16:24:56.215383"}}
{"event_type": "price_change", "event_ts": "2026-01-14T16:25:02.103887", "ingestion_ts": "2026-01-14T16:33:58.842229", "market_id": "0x318b222c1435b47c338e66ca6001f782711186a488ae7b7248f7edc6ff076a83", "raw": {"market": "0x318b222c1435b47c338e66ca6001f782711186a488ae7b7248f7edc6ff076a83", "asset_id": "63773739594775606083258239254748928077067768053882704658119720069071630213026", "price": "0.129", "size": "1860", "side": "BUY", "timestamp": "1768404302434", "received_at": "2026-01-14T16:25:02.103887"}}
{"event_type": "price_change", "event_ts": "2026-01-14T16:25:02.103887", "ingestion_ts": "2026-01-14T16:33:58.842229", "market_id": "0x318b222c1435b47c338e66ca6001f782711186a488ae7b7248f7edc6ff076a83", "raw": {"market": "0x318b222c1435b47c338e66ca6001f782711186a488ae7b7248f7edc6ff076a83", "asset_id": "56738600572035832904895845056468792275697823297413384908752239327866518310010", "price": "0.871", "size": "1860", "side": "SELL", "timestamp": "1768404302434", "received_at": "2026-01-14T16:25:02.103887"}}
{"event_type": "price_change", "event_ts": "2026-01-14T16:25:02.262373", "ingestion_ts": "2026-01-14T16:33:58.842229", "market_id": "0x49686d26fb712515cd5e12c23f0a1c7e10214c7faa3cb0a730aabe0c33694082", "raw": {"market": "0x49686d26fb712515cd5e12c23f0a1c7e10214c7faa3cb0a730aabe0c33694082", "asset_id": "30442780799048074404860985387051749017905070253466005720364298335239299761065", "price": "0.094", "size": "0", "side": "BUY", "timestamp": "1768404302592", "received_at": "2026-01-14T16:25:02.262373"}}
{"event_type": "price_change", "event_ts": "2026-01-14T16:25:02.262373", "ingestion_ts": "2026-01-14T16:33:58.842229", "market_id": "0x49686d26fb712515cd5e12c23f0a1c7e10214c7faa3cb0a730aabe0c33694082", "raw": {"market": "0x49686d26fb712515cd5e12c23f0a1c7e10214c7faa3cb0a730aabe0c33694082", "asset_id": "13244681086321087932946246027856416106585284024824496763706748621681543444582", "price": "0.906", "size": "0", "side": "SELL", "timestamp": "1768404302592", "received_at": "2026-01-14T16:25:02.262373"}}
{"event_type": "price_change", "event_ts": "2026-01-14T16:25:15.550022", "ingestion_ts": "2026-01-14T16:33:58.842229", "market_id": "0x49686d26fb712515cd5e12c23f0a1c7e10214c7faa3cb0a730aabe0c33694082", "raw": {"market": "0x49686d26fb712515cd5e12c23f0a1c7e10214c7faa3cb0a730aabe0c33694082", "asset_id": "13244681086321087932946246027856416106585284024824496763706748621681543444582", "price": "0.14", "size": "102.04", "side": "BUY", "timestamp": "1768404315836", "received_at": "2026-01-14T16:25:15.550022"}}
{"event_type": "price_change", "event_ts": "2026-01-14T16:25:15.550022", "ingestion_ts": "2026-01-14T16:33:58.842229", "market_id": "0x49686d26fb712515cd5e12c23f0a1c7e10214c7faa3cb0a730aabe0c33694082", "raw": {"market": "0x49686d26fb712515cd5e12c23f0a1c7e10214c7faa3cb0a730aabe0c33694082", "asset_id": "30442780799048074404860985387051749017905070253466005720364298335239299761065", "price": "0.86", "size": "102.04", "side": "SELL", "timestamp": "1768404315836", "received_at": "2026-01-14T16:25:15.550022"}}
{"event_type": "price_change", "event_ts": "2026-01-14T16:25:15.934160", "ingestion_ts": "2026-01-14T16:33:58.842229", "market_id": "0x49686d26fb712515cd5e12c23f0a1c7e10214c7faa3cb0a730aabe0c33694082", "raw": {"market": "0x49686d26fb712515cd5e12c23f0a1c7e10214c7faa3cb0a730aabe0c33694082", "asset_id": "13244681086321087932946246027856416106585284024824496763706748621681543444582", "price": "0.116", "size": "2168", "side": "BUY", "timestamp": "1768404316125", "received_at": "2026-01-14T16:25:15.934160"}}
{"event_type": "price_change", "event_ts": "2026-01-14T16:25:15.934160", "ingestion_ts": "2026-01-14T16:33:58.842229", "market_id": "0x49686d26fb712515cd5e12c23f0a1c7e10214c7faa3cb0a730aabe0c33694082", "raw": {"market": "0x49686d26fb712515cd5e12c23f0a1c7e10214c7faa3cb0a730aabe0c33694082", "asset_id": "30442780799048074404860985387051749017905070253466005720364298335239299761065", "price": "0.884", "size": "2168", "side": "SELL", "timestamp": "1768404316125", "received_at": "2026-01-14T16:25:15.934160"}}
{"event_type": "price_change", "event_ts": "2026-01-14T16:25:42.912098", "ingestion_ts": "2026-01-14T16:33:58.842229", "market_id": "0x9d24d9f9b5995949cb158d943793dea20bd448e1b3971cb6f7418bb15e719661", "raw": {"market": "0x9d24d9f9b5995949cb158d943793dea20bd448e1b3971cb6f7418bb15e719661", "asset_id": "79516121807256184736227920754945730465880754940725759201193439378549308939672", "price": "0.938", "size": "54.66", "side": "BUY", "timestamp": "1768404343245", "received_at": "2026-01-14T16:25:42.912098"}}
{"event_type": "price_change", "event_ts": "2026-01-14T16:25:42.912098", "ingestion_ts": "2026-01-14T16:33:58.842229", "market_id": "0x9d24d9f9b5995949cb158d943793dea20bd448e1b3971cb6f7418bb15e719661", "raw": {"market": "0x9d24d9f9b5995949cb158d943793dea20bd448e1b3971cb6f7418bb15e719661", "asset_id": "70512916946285526357165287373537570327431985324385225788636160168740471920430", "price": "0.062", "size": "54.66", "side": "SELL", "timestamp": "1768404343245", "received_at": "2026-01-14T16:25:42.912098"}}
{"event_type": "price_change", "event_ts": "2026-01-14T16:25:53.273881", "ingestion_ts": "2026-01-14T16:33:58.842229", "market_id": "0xc55db914f0fd1fee18997706712c0dfd8d0369cdbef93a9fef12bd001914ca77", "raw": {"market": "0xc55db914f0fd1fee18997706712c0dfd8d0369cdbef93a9fef12bd001914ca77", "asset_id": "114600293444080540179603459515770723592661967180480327891296353898330242622833", "price": "0.437", "size": "0", "side": "BUY", "timestamp": "1768404353536", "received_at": "2026-01-14T16:25:53.273881"}}
{"event_type": "price_change", "event_ts": "2026-01-14T16:25:53.273881", "ingestion_ts": "2026-01-14T16:33:58.842229", "market_id": "0xc55db914f0fd1fee18997706712c0dfd8d0369cdbef93a9fef12bd001914ca77", "raw": {"market": "0xc55db914f0fd1fee18997706712c0dfd8d0369cdbef93a9fef12bd001914ca77", "asset_id": "72354723612769247426741660426331235762851940382312402276325808095604519806766", "price": "0.563", "size": "0", "side": "SELL", "timestamp": "1768404353536", "received_at": "2026-01-14T16:25:53.273881"}}
{"event_type": "price_change", "event_ts": "2026-01-14T16:25:53.317066", "ingestion_ts": "2026-01-14T16:33:58.842229", "market_id": "0xc55db914f0fd1fee18997706712c0dfd8d0369cdbef93a9fef12bd001914ca77", "raw": {"market": "0xc55db914f0fd1fee18997706712c0dfd8d0369cdbef93a9fef12bd001914ca77", "asset_id": "114600293444080540179603459515770723592661967180480327891296353898330242622833", "price": "0.437", "size": "5", "side": "BUY", "timestamp": "1768404353595", "received_at": "2026-01-14T16:25:53.317066"}}
{"event_type": "price_change", "event_ts": "2026-01-14T16:25:53.317066", "ingestion_ts": "2026-01-14T16:33:58.842229", "market_id": "0xc55db914f0fd1fee18997706712c0dfd8d0369cdbef93a9fef12bd001914ca77", "raw": {"market": "0xc55db914f0fd1fee18997706712c0dfd8d0369cdbef93a9fef12bd001914ca77", "asset_id": "72354723612769247426741660426331235762851940382312402276325808095604519806766", "price": "0.563", "size": "5", "side": "SELL", "timestamp": "1768404353595", "received_at": "2026-01-14T16:25:53.317066"}}
{"event_type": "price_change", "event_ts": "2026-01-14T16:25:54.438539", "ingestion_ts": "2026-01-14T16:33:58.842229", "market_id": "0x318b222c1435b47c338e66ca6001f782711186a488ae7b7248f7edc6ff076a83", "raw": {"market": "0x318b222c1435b47c338e66ca6001f782711186a488ae7b7248f7edc6ff076a83", "asset_id": "63773739594775606083258239254748928077067768053882704658119720069071630213026", "price": "0.1", "size": "142.85", "side": "BUY", "timestamp": "1768404354663", "received_at": "2026-01-14T16:25:54.438539"}}
{"event_type": "price_change", "event_ts": "2026-01-14T16:25:54.438539", "ingestion_ts": "2026-01-14T16:33:58.842229", "market_id": "0x318b222c1435b47c338e66ca6001f782711186a488ae7b7248f7edc6ff076a83", "raw": {"market": "0x318b222c1435b47c338e66ca6001f782711186a488ae7b7248f7edc6ff076a83", "asset_id": "56738600572035832904895845056468792275697823297413384908752239327866518310010", "price": "0.9", "size": "142.85", "side": "SELL", "timestamp": "1768404354663", "received_at": "2026-01-14T16:25:54.438539"}}
{"event_type": "price_change", "event_ts": "2026-01-14T16:25:54.946628", "ingestion_ts": "2026-01-14T16:33:58.842229", "market_id": "0x318b222c1435b47c338e66ca6001f782711186a488ae7b7248f7edc6ff076a83", "raw": {"market": "0x318b222c1435b47c338e66ca6001f782711186a488ae7b7248f7edc6ff076a83", "asset_id": "63773739594775606083258239254748928077067768053882704658119720069071630213026", "price": "0.129", "size": "1960", "side": "BUY", "timestamp": "1768404355189", "received_at": "2026-01-14T16:25:54.946628"}}
{"event_type": "price_change", "event_ts": "2026-01-14T16:25:54.946628", "ingestion_ts": "2026-01-14T16:33:58.842229", "market_id": "0x318b222c1435b47c338e66ca6001f782711186a488ae7b7248f7edc6ff076a83", "raw": {"market": "0x318b222c1435b47c338e66ca6001f782711186a488ae7b7248f7edc6ff076a83", "asset_id": "56738600572035832904895845056468792275697823297413384908752239327866518310010", "price": "0.871", "size": "1960", "side": "SELL", "timestamp": "1768404355189", "received_at": "2026-01-14T16:25:54.946628"}}
{"event_type": "price_change", "event_ts": "2026-01-14T16:26:00.668847", "ingestion_ts": "2026-01-14T16:33:58.842229", "market_id": "0xe9c127a8c35f045d37b5344b0a36711084fa20c2fc1618bf178a5386f90610be", "raw": {"market": "0xe9c127a8c35f045d37b5344b0a36711084fa20c2fc1618bf178a5386f90610be", "asset_id": "107000426448217931795450451304515386602910396776318075817601265223856116134349", "price": "0.997", "size": "251", "side": "SELL", "timestamp": "1768404360972", "received_at": "2026-01-14T16:26:00.668847"}}
{"event_type": "price_change", "event_ts": "2026-01-14T16:26:00.668847", "ingestion_ts": "2026-01-14T16:33:58.842229", "market_id": "0xe9c127a8c35f045d37b5344b0a36711084fa20c2fc1618bf178a5386f90610be", "raw": {"market": "0xe9c127a8c35f045d37b5344b0a36711084fa20c2fc1618bf178a5386f90610be", "asset_id": "80230236018433940569996058935444651347308266584430516013229815570706872276819", "price": "0.003", "size": "251", "side": "BUY", "timestamp": "1768404360972", "received_at": "2026-01-14T16:26:00.668847"}}
{"event_type": "price_change", "event_ts": "2026-01-14T16:26:02.126222", "ingestion_ts": "2026-01-14T16:33:58.842229", "market_id": "0xe9c127a8c35f045d37b5344b0a36711084fa20c2fc1618bf178a5386f90610be", "raw": {"market": "0xe9c127a8c35f045d37b5344b0a36711084fa20c2fc1618bf178a5386f90610be", "asset_id": "107000426448217931795450451304515386602910396776318075817601265223856116134349", "price": "0.997", "size": "0", "side": "SELL", "timestamp": "1768404362441", "received_at": "2026-01-14T16:26:02.126222"}}
{"event_type": "price_change", "event_ts": "2026-01-14T16:26:02.126222", "ingestion_ts": "2026-01-14T16:33:58.842229", "market_id": "0xe9c127a8c35f045d37b5344b0a36711084fa20c2fc1618bf178a5386f90610be", "raw": {"market": "0xe9c127a8c35f045d37b5344b0a36711084fa20c2fc1618bf178a5386f90610be", "asset_id": "80230236018433940569996058935444651347308266584430516013229815570706872276819", "price": "0.003", "size": "0", "side": "BUY", "timestamp": "1768404362441", "received_at": "2026-01-14T16:26:02.126222"}}
{"event_type": "price_change", "event_ts": "2026-01-14T16:26:02.176084", "ingestion_ts": "2026-01-14T16:33:58.842229", "market_id": "0xe9c127a8c35f045d37b5344b0a36711084fa20c2fc1618bf178a5386f90610be", "raw": {"market": "0xe9c127a8c35f045d37b5344b0a36711084fa20c2fc1618bf178a5386f90610be", "asset_id": "107000426448217931795450451304515386602910396776318075817601265223856116134349", "price": "0.997", "size": "251", "side": "SELL", "timestamp": "1768404362499", "received_at": "2026-01-14T16:26:02.176084"}}
{"event_type": "price_change", "event_ts": "2026-01-14T16:26:02.176084", "ingestion_ts": "2026-01-14T16:33:58.842229", "market_id": "0xe9c127a8c35f045d37b5344b0a36711084fa20c2fc1618bf178a5386f90610be", "raw": {"market": "0xe9c127a8c35f045d37b5344b0a36711084fa20c2fc1618bf178a5386f90610be", "asset_id": "80230236018433940569996058935444651347308266584430516013229815570706872276819", "price": "0.003", "size": "251", "side": "BUY", "timestamp": "1768404362499", "received_at": "2026-01-14T16:26:02.176084"}}
{"event_type": "price_change", "event_ts": "2026-01-14T16:26:03.659978", "ingestion_ts": "2026-01-14T16:33:58.842229", "market_id": "0xe9c127a8c35f045d37b5344b0a36711084fa20c2fc1618bf178a5386f90610be", "raw": {"market": "0xe9c127a8c35f045d37b5344b0a36711084fa20c2fc1618bf178a5386f90610be", "asset_id": "107000426448217931795450451304515386602910396776318075817601265223856116134349", "price": "0.997", "size": "0", "side": "SELL", "timestamp": "1768404363939", "received_at": "2026-01-14T16:26:03.659978"}}
{"event_type": "price_change", "event_ts": "2026-01-14T16:26:03.659978", "ingestion_ts": "2026-01-14T16:33:58.842229", "market_id": "0xe9c127a8c35f045d37b5344b0a36711084fa20c2fc1618bf178a5386f90610be", "raw": {"market": "0xe9c127a8c35f045d37b5344b0a36711084fa20c2fc1618bf178a5386f90610be", "asset_id": "80230236018433940569996058935444651347308266584430516013229815570706872276819", "price": "0.003", "size": "0", "side": "BUY", "timestamp": "1768404363939", "received_at": "2026-01-14T16:26:03.659978"}}
{"event_type": "price_change", "event_ts": "2026-01-14T16:26:03.728117", "ingestion_ts": "2026-01-14T16:33:58.842229", "market_id": "0xe9c127a8c35f045d37b5344b0a36711084fa20c2fc1618bf178a5386f90610be", "raw": {"market": "0xe9c127a8c35f045d37b5344b0a36711084fa20c2fc1618bf178a5386f90610be", "asset_id": "107000426448217931795450451304515386602910396776318075817601265223856116134349", "price": "0.997", "size": "251", "side": "SELL", "timestamp": "1768404363994", "received_at": "2026-01-14T16:26:03.728117"}}
{"event_type": "price_change", "event_ts": "2026-01-14T16:26:03.728117", "ingestion_ts": "2026-01-14T16:33:58.842229", "market_id": "0xe9c127a8c35f045d37b5344b0a36711084fa20c2fc1618bf178a5386f90610be", "raw": {"market": "0xe9c127a8c35f045d37b5344b0a36711084fa20c2fc1618bf178a5386f90610be", "asset_id": "80230236018433940569996058935444651347308266584430516013229815570706872276819", "price": "0.003", "size": "251", "side": "BUY", "timestamp": "1768404363994", "received_at": "2026-01-14T16:26:03.728117"}}
{"event_type": "price_change", "event_ts": "2026-01-14T16:26:05.118523", "ingestion_ts": "2026-01-14T16:33:58.842229", "market_id": "0xe9c127a8c35f045d37b5344b0a36711084fa20c2fc1618bf178a5386f90610be", "raw": {"market": "0xe9c127a8c35f045d37b5344b0a36711084fa20c2fc1618bf178a5386f90610be", "asset_id": "107000426448217931795450451304515386602910396776318075817601265223856116134349", "price": "0.997", "size": "0", "side": "SELL", "timestamp": "1768404365439", "received_at": "2026-01-14T16:26:05.118523"}}
{"event_type": "price_change", "event_ts": "2026-01-14T16:26:05.118523", "ingestion_ts": "2026-01-14T16:33:58.842229", "market_id": "0xe9c127a8c35f045d37b5344b0a36711084fa20c2fc1618bf178a5386f90610be", "raw": {"market": "0xe9c127a8c35f045d37b5344b0a36711084fa20c2fc1618bf178a5386f90610be", "asset_id": "80230236018433940569996058935444651347308266584430516013229815570706872276819", "price": "0.003", "size": "0", "side": "BUY", "timestamp": "1768404365439", "received_at": "2026-01-14T16:26:05.118523"}}
{"event_type": "price_change", "event_ts": "2026-01-14T16:26:05.167796", "ingestion_ts": "2026-01-14T16:33:58.842229", "market_id": "0xe9c127a8c35f045d37b5344b0a36711084fa20c2fc1618bf178a5386f90610be", "raw": {"market": "0xe9c127a8c35f045d37b5344b0a36711084fa20c2fc1618bf178a5386f90610be", "asset_id": "107000426448217931795450451304515386602910396776318075817601265223856116134349", "price": "0.997", "size": "251", "side": "SELL", "timestamp": "1768404365487", "received_at": "2026-01-14T16:26:05.167796"}}
{"event_type": "price_change", "event_ts": "2026-01-14T16:26:05.167796", "ingestion_ts": "2026-01-14T16:33:58.842229", "market_id": "0xe9c127a8c35f045d37b5344b0a36711084fa20c2fc1618bf178a5386f90610be", "raw": {"market": "0xe9c127a8c35f045d37b5344b0a36711084fa20c2fc1618bf178a5386f90610be", "asset_id": "80230236018433940569996058935444651347308266584430516013229815570706872276819", "price": "0.003", "size": "251", "side": "BUY", "timestamp": "1768404365487", "received_at": "2026-01-14T16:26:05.167796"}}
{"event_type": "price_change", "event_ts": "2026-01-14T16:26:06.609640", "ingestion_ts": "2026-01-14T16:33:58.842229", "market_id": "0xe9c127a8c35f045d37b5344b0a36711084fa20c2fc1618bf178a5386f90610be", "raw": {"market": "0xe9c127a8c35f045d37b5344b0a36711084fa20c2fc1618bf178a5386f90610be", "asset_id": "107000426448217931795450451304515386602910396776318075817601265223856116134349", "price": "0.997", "size": "0", "side": "SELL", "timestamp": "1768404366938", "received_at": "2026-01-14T16:26:06.609640"}}
{"event_type": "price_change", "event_ts": "2026-01-14T16:26:06.609640", "ingestion_ts": "2026-01-14T16:33:58.842229", "market_id": "0xe9c127a8c35f045d37b5344b0a36711084fa20c2fc1618bf178a5386f90610be", "raw": {"market": "0xe9c127a8c35f045d37b5344b0a36711084fa20c2fc1618bf178a5386f90610be", "asset_id": "80230236018433940569996058935444651347308266584430516013229815570706872276819", "price": "0.003", "size": "0", "side": "BUY", "timestamp": "1768404366938", "received_at": "2026-01-14T16:26:06.609640"}}
{"event_type": "price_change", "event_ts": "2026-01-14T16:26:06.635698", "ingestion_ts": "2026-01-14T16:33:58.842229", "market_id": "0xe9c127a8c35f045d37b5344b0a36711084fa20c2fc1618bf178a5386f90610be", "raw": {"market": "0xe9c127a8c35f045d37b5344b0a36711084fa20c2fc1618bf178a5386f90610be", "asset_id": "107000426448217931795450451304515386602910396776318075817601265223856116134349", "price": "0.997", "size": "251", "side": "SELL", "timestamp": "1768404366969", "received_at": "2026-01-14T16:26:06.635698"}}
{"event_type": "price_change", "event_ts": "2026-01-14T16:26:06.635698", "ingestion_ts": "2026-01-14T16:33:58.842229", "market_id": "0xe9c127a8c35f045d37b5344b0a36711084fa20c2fc1618bf178a5386f90610be", "raw": {"market": "0xe9c127a8c35f045d37b5344b0a36711084fa20c2fc1618bf178a5386f90610be", "asset_id": "80230236018433940569996058935444651347308266584430516013229815570706872276819", "price": "0.003", "size": "251", "side": "BUY", "timestamp": "1768404366969", "received_at": "2026-01-14T16:26:06.635698"}}
{"event_type": "price_change", "event_ts": "2026-01-14T16:26:08.117749", "ingestion_ts": "2026-01-14T16:33:58.842229", "market_id": "0xe9c127a8c35f045d37b5344b0a36711084fa20c2fc1618bf178a5386f90610be", "raw": {"market": "0xe9c127a8c35f045d37b5344b0a36711084fa20c2fc1618bf178a5386f90610be", "asset_id": "107000426448217931795450451304515386602910396776318075817601265223856116134349", "price": "0.997", "size": "0", "side": "SELL", "timestamp": "1768404368451", "received_at": "2026-01-14T16:26:08.117749"}}
{"event_type": "price_change", "event_ts": "2026-01-14T16:26:08.117749", "ingestion_ts": "2026-01-14T16:33:58.842229", "market_id": "0xe9c127a8c35f045d37b5344b0a36711084fa20c2fc1618bf178a5386f90610be", "raw": {"market": "0xe9c127a8c35f045d37b5344b0a36711084fa20c2fc1618bf178a5386f90610be", "asset_id": "80230236018433940569996058935444651347308266584430516013229815570706872276819", "price": "0.003", "size": "0", "side": "BUY", "timestamp": "1768404368451", "received_at": "2026-01-14T16:26:08.117749"}}
{"event_type": "price_change", "event_ts": "2026-01-14T16:26:08.150457", "ingestion_ts": "2026-01-14T16:33:58.842229", "market_id": "0xe9c127a8c35f045d37b5344b0a36711084fa20c2fc1618bf178a5386f90610be", "raw": {"market": "0xe9c127a8c35f045d37b5344b0a36711084fa20c2fc1618bf178a5386f90610be", "asset_id": "107000426448217931795450451304515386602910396776318075817601265223856116134349", "price": "0.997", "size": "251", "side": "SELL", "timestamp": "1768404368482", "received_at": "2026-01-14T16:26:08.150457"}}
{"event_type": "price_change", "event_ts": "2026-01-14T16:26:08.150457", "ingestion_ts": "2026-01-14T16:33:58.842229", "market_id": "0xe9c127a8c35f045d37b5344b0a36711084fa20c2fc1618bf178a5386f90610be", "raw": {"market": "0xe9c127a8c35f045d37b5344b0a36711084fa20c2fc1618bf178a5386f90610be", "asset_id": "80230236018433940569996058935444651347308266584430516013229815570706872276819", "price": "0.003", "size": "251", "side": "BUY", "timestamp": "1768404368482", "received_at": "2026-01-14T16:26:08.150457"}}
{"event_type": "price_change", "event_ts": "2026-01-14T16:26:09.623592", "ingestion_ts": "2026-01-14T16:33:58.842229", "market_id": "0xe9c127a8c35f045d37b5344b0a36711084fa20c2fc1618bf178a5386f90610be", "raw": {"market": "0xe9c127a8c35f045d37b5344b0a36711084fa20c2fc1618bf178a5386f90610be", "asset_id": "107000426448217931795450451304515386602910396776318075817601265223856116134349", "price": "0.997", "size": "0", "side": "SELL", "timestamp": "1768404369939", "received_at": "2026-01-14T16:26:09.623592"}}
{"event_type": "price_change", "event_ts": "2026-01-14T16:26:09.623592", "ingestion_ts": "2026-01-14T16:33:58.842229", "market_id": "0xe9c127a8c35f045d37b5344b0a36711084fa20c2fc1618bf178a5386f90610be", "raw": {"market": "0xe9c127a8c35f045d37b5344b0a36711084fa20c2fc1618bf178a5386f90610be", "asset_id": "80230236018433940569996058935444651347308266584430516013229815570706872276819", "price": "0.003", "size": "0", "side": "BUY", "timestamp": "1768404369939", "received_at": "2026-01-14T16:26:09.623592"}}
{"event_type": "price_change", "event_ts": "2026-01-14T16:26:09.659480", "ingestion_ts": "2026-01-14T16:33:58.842229", "market_id": "0xe9c127a8c35f045d37b5344b0a36711084fa20c2fc1618bf178a5386f90610be", "raw": {"market": "0xe9c127a8c35f045d37b5344b0a36711084fa20c2fc1618bf178a5386f90610be", "asset_id": "107000426448217931795450451304515386602910396776318075817601265223856116134349", "price": "0.997", "size": "251", "side": "SELL", "timestamp": "1768404369993", "received_at": "2026-01-14T16:26:09.659480"}}
{"event_type": "price_change", "event_ts": "2026-01-14T16:26:09.659480", "ingestion_ts": "2026-01-14T16:33:58.842229", "market_id": "0xe9c127a8c35f045d37b5344b0a36711084fa20c2fc1618bf178a5386f90610be", "raw": {"market": "0xe9c127a8c35f045d37b5344b0a36711084fa20c2fc1618bf178a5386f90610be", "asset_id": "80230236018433940569996058935444651347308266584430516013229815570706872276819", "price": "0.003", "size": "251", "side": "BUY", "timestamp": "1768404369993", "received_at": "2026-01-14T16:26:09.659480"}}
{"event_type": "price_change", "event_ts": "2026-01-14T16:26:11.185613", "ingestion_ts": "2026-01-14T16:33:58.842229", "market_id": "0xe9c127a8c35f045d37b5344b0a36711084fa20c2fc1618bf178a5386f90610be", "raw": {"market": "0xe9c127a8c35f045d37b5344b0a36711084fa20c2fc1618bf178a5386f90610be", "asset_id": "107000426448217931795450451304515386602910396776318075817601265223856116134349", "price": "0.997", "size": "0", "side": "SELL", "timestamp": "1768404371451", "received_at": "2026-01-14T16:26:11.185613"}}
{"event_type": "price_change", "event_ts": "2026-01-14T16:26:11.185613", "ingestion_ts": "2026-01-14T16:33:58.842229", "market_id": "0xe9c127a8c35f045d37b5344b0a36711084fa20c2fc1618bf178a5386f90610be", "raw": {"market": "0xe9c127a8c35f045d37b5344b0a36711084fa20c2fc1618bf178a5386f90610be", "asset_id": "80230236018433940569996058935444651347308266584430516013229815570706872276819", "price": "0.003", "size": "0", "side": "BUY", "timestamp": "1768404371451", "received_at": "2026-01-14T16:26:11.185613"}}
{"event_type": "price_change", "event_ts": "2026-01-14T16:26:11.251791", "ingestion_ts": "2026-01-14T16:33:58.842229", "market_id": "0xe9c127a8c35f045d37b5344b0a36711084fa20c2fc1618bf178a5386f90610be", "raw": {"market": "0xe9c127a8c35f045d37b5344b0a36711084fa20c2fc1618bf178a5386f90610be", "asset_id": "107000426448217931795450451304515386602910396776318075817601265223856116134349", "price": "0.997", "size": "251", "side": "SELL", "timestamp": "1768404371532", "received_at": "2026-01-14T16:26:11.251791"}}
{"event_type": "price_change", "event_ts": "2026-01-14T16:26:11.251791", "ingestion_ts": "2026-01-14T16:33:58.842229", "market_id": "0xe9c127a8c35f045d37b5344b0a36711084fa20c2fc1618bf178a5386f90610be", "raw": {"market": "0xe9c127a8c35f045d37b5344b0a36711084fa20c2fc1618bf178a5386f90610be", "asset_id": "80230236018433940569996058935444651347308266584430516013229815570706872276819", "price": "0.003", "size": "251", "side": "BUY", "timestamp": "1768404371532", "received_at": "2026-01-14T16:26:11.251791"}}
{"event_type": "price_change", "event_ts": "2026-01-14T16:26:12.608296", "ingestion_ts": "2026-01-14T16:33:58.842229", "market_id": "0xe9c127a8c35f045d37b5344b0a36711084fa20c2fc1618bf178a5386f90610be", "raw": {"market": "0xe9c127a8c35f045d37b5344b0a36711084fa20c2fc1618bf178a5386f90610be", "asset_id": "107000426448217931795450451304515386602910396776318075817601265223856116134349", "price": "0.997", "size": "0", "side": "SELL", "timestamp": "1768404372938", "received_at": "2026-01-14T16:26:12.608296"}}
{"event_type": "price_change", "event_ts": "2026-01-14T16:26:12.608296", "ingestion_ts": "2026-01-14T16:33:58.842229", "market_id": "0xe9c127a8c35f045d37b5344b0a36711084fa20c2fc1618bf178a5386f90610be", "raw": {"market": "0xe9c127a8c35f045d37b5344b0a36711084fa20c2fc1618bf178a5386f90610be", "asset_id": "80230236018433940569996058935444651347308266584430516013229815570706872276819", "price": "0.003", "size": "0", "side": "BUY", "timestamp": "1768404372938", "received_at": "2026-01-14T16:26:12.608296"}}
{"event_type": "price_change", "event_ts": "2026-01-14T16:26:12.637793", "ingestion_ts": "2026-01-14T16:33:58.842229", "market_id": "0xe9c127a8c35f045d37b5344b0a36711084fa20c2fc1618bf178a5386f90610be", "raw": {"market": "0xe9c127a8c35f045d37b5344b0a36711084fa20c2fc1618bf178a5386f90610be", "asset_id": "107000426448217931795450451304515386602910396776318075817601265223856116134349", "price": "0.997", "size": "251", "side": "SELL", "timestamp": "1768404372967", "received_at": "2026-01-14T16:26:12.637793"}}
{"event_type": "price_change", "event_ts": "2026-01-14T16:26:12.637793", "ingestion_ts": "2026-01-14T16:33:58.842229", "market_id": "0xe9c127a8c35f045d37b5344b0a36711084fa20c2fc1618bf178a5386f90610be", "raw": {"market": "0xe9c127a8c35f045d37b5344b0a36711084fa20c2fc1618bf178a5386f90610be", "asset_id": "80230236018433940569996058935444651347308266584430516013229815570706872276819", "price": "0.003", "size": "251", "side": "BUY", "timestamp": "1768404372967", "received_at": "2026-01-14T16:26:12.637793"}}
{"event_type": "price_change", "event_ts": "2026-01-14T16:26:14.115294", "ingestion_ts": "2026-01-14T16:33:58.842229", "market_id": "0xe9c127a8c35f045d37b5344b0a36711084fa20c2fc1618bf178a5386f90610be", "raw": {"market": "0xe9c127a8c35f045d37b5344b0a36711084fa20c2fc1618bf178a5386f90610be", "asset_id": "107000426448217931795450451304515386602910396776318075817601265223856116134349", "price": "0.997", "size": "0", "side": "SELL", "timestamp": "1768404374442", "received_at": "2026-01-14T16:26:14.115294"}}
{"event_type": "price_change", "event_ts": "2026-01-14T16:26:14.115294", "ingestion_ts": "2026-01-14T16:33:58.842229", "market_id": "0xe9c127a8c35f045d37b5344b0a36711084fa20c2fc1618bf178a5386f90610be", "raw": {"market": "0xe9c127a8c35f045d37b5344b0a36711084fa20c2fc1618bf178a5386f90610be", "asset_id": "80230236018433940569996058935444651347308266584430516013229815570706872276819", "price": "0.003", "size": "0", "side": "BUY", "timestamp": "1768404374442", "received_at": "2026-01-14T16:26:14.115294"}}
{"event_type": "price_change", "event_ts": "2026-01-14T16:26:14.153912", "ingestion_ts": "2026-01-14T16:33:58.842229", "market_id": "0xe9c127a8c35f045d37b5344b0a36711084fa20c2fc1618bf178a5386f90610be", "raw": {"market": "0xe9c127a8c35f045d37b5344b0a36711084fa20c2fc1618bf178a5386f90610be", "asset_id": "107000426448217931795450451304515386602910396776318075817601265223856116134349", "price": "0.997", "size": "251", "side": "SELL", "timestamp": "1768404374487", "received_at": "2026-01-14T16:26:14.153912"}}
{"event_type": "price_change", "event_ts": "2026-01-14T16:26:14.153912", "ingestion_ts": "2026-01-14T16:33:58.842229", "market_id": "0xe9c127a8c35f045d37b5344b0a36711084fa20c2fc1618bf178a5386f90610be", "raw": {"market": "0xe9c127a8c35f045d37b5344b0a36711084fa20c2fc1618bf178a5386f90610be", "asset_id": "80230236018433940569996058935444651347308266584430516013229815570706872276819", "price": "0.003", "size": "251", "side": "BUY", "timestamp": "1768404374487", "received_at": "2026-01-14T16:26:14.153912"}}
{"event_type": "price_change", "event_ts": "2026-01-14T16:26:15.603699", "ingestion_ts": "2026-01-14T16:33:58.842229", "market_id": "0xe9c127a8c35f045d37b5344b0a36711084fa20c2fc1618bf178a5386f90610be", "raw": {"market": "0xe9c127a8c35f045d37b5344b0a36711084fa20c2fc1618bf178a5386f90610be", "asset_id": "107000426448217931795450451304515386602910396776318075817601265223856116134349", "price": "0.997", "size": "0", "side": "SELL", "timestamp": "1768404375938", "received_at": "2026-01-14T16:26:15.603699"}}
{"event_type": "price_change", "event_ts": "2026-01-14T16:26:15.603699", "ingestion_ts": "2026-01-14T16:33:58.842229", "market_id": "0xe9c127a8c35f045d37b5344b0a36711084fa20c2fc1618bf178a5386f90610be", "raw": {"market": "0xe9c127a8c35f045d37b5344b0a36711084fa20c2fc1618bf178a5386f90610be", "asset_id": "80230236018433940569996058935444651347308266584430516013229815570706872276819", "price": "0.003", "size": "0", "side": "BUY", "timestamp": "1768404375938", "received_at": "2026-01-14T16:26:15.603699"}}
{"event_type": "price_change", "event_ts": "2026-01-14T16:26:15.634717", "ingestion_ts": "2026-01-14T16:33:58.842229", "market_id": "0xe9c127a8c35f045d37b5344b0a36711084fa20c2fc1618bf178a5386f90610be", "raw": {"market": "0xe9c127a8c35f045d37b5344b0a36711084fa20c2fc1618bf178a5386f90610be", "asset_id": "107000426448217931795450451304515386602910396776318075817601265223856116134349", "price": "0.997", "size": "251", "side": "SELL", "timestamp": "1768404375970", "received_at": "2026-01-14T16:26:15.634717"}}
{"event_type": "price_change", "event_ts": "2026-01-14T16:26:15.634717", "ingestion_ts": "2026-01-14T16:33:58.842229", "market_id": "0xe9c127a8c35f045d37b5344b0a36711084fa20c2fc1618bf178a5386f90610be", "raw": {"market": "0xe9c127a8c35f045d37b5344b0a36711084fa20c2fc1618bf178a5386f90610be", "asset_id": "80230236018433940569996058935444651347308266584430516013229815570706872276819", "price": "0.003", "size": "251", "side": "BUY", "timestamp": "1768404375970", "received_at": "2026-01-14T16:26:15.634717"}}
{"event_type": "price_change", "event_ts": "2026-01-14T16:26:17.165656", "ingestion_ts": "2026-01-14T16:33:58.842229", "market_id": "0xe9c127a8c35f045d37b5344b0a36711084fa20c2fc1618bf178a5386f90610be", "raw": {"market": "0xe9c127a8c35f045d37b5344b0a36711084fa20c2fc1618bf178a5386f90610be", "asset_id": "107000426448217931795450451304515386602910396776318075817601265223856116134349", "price": "0.997", "size": "0", "side": "SELL", "timestamp": "1768404377495", "received_at": "2026-01-14T16:26:17.165656"}}
{"event_type": "price_change", "event_ts": "2026-01-14T16:26:17.165656", "ingestion_ts": "2026-01-14T16:33:58.842229", "market_id": "0xe9c127a8c35f045d37b5344b0a36711084fa20c2fc1618bf178a5386f90610be", "raw": {"market": "0xe9c127a8c35f045d37b5344b0a36711084fa20c2fc1618bf178a5386f90610be", "asset_id": "80230236018433940569996058935444651347308266584430516013229815570706872276819", "price": "0.003", "size": "0", "side": "BUY", "timestamp": "1768404377495", "received_at": "2026-01-14T16:26:17.165656"}}
{"event_type": "price_change", "event_ts": "2026-01-14T16:26:17.212799", "ingestion_ts": "2026-01-14T16:33:58.842229", "market_id": "0xe9c127a8c35f045d37b5344b0a36711084fa20c2fc1618bf178a5386f90610be", "raw": {"market": "0xe9c127a8c35f045d37b5344b0a36711084fa20c2fc1618bf178a5386f90610be", "asset_id": "107000426448217931795450451304515386602910396776318075817601265223856116134349", "price": "0.997", "size": "251", "side": "SELL", "timestamp": "1768404377542", "received_at": "2026-01-14T16:26:17.212799"}}
{"event_type": "price_change", "event_ts": "2026-01-14T16:26:17.212799", "ingestion_ts": "2026-01-14T16:33:58.842229", "market_id": "0xe9c127a8c35f045d37b5344b0a36711084fa20c2fc1618bf178a5386f90610be", "raw": {"market": "0xe9c127a8c35f045d37b5344b0a36711084fa20c2fc1618bf178a5386f90610be", "asset_id": "80230236018433940569996058935444651347308266584430516013229815570706872276819", "price": "0.003", "size": "251", "side": "BUY", "timestamp": "1768404377542", "received_at": "2026-01-14T16:26:17.212799"}}
{"event_type": "price_change", "event_ts": "2026-01-14T16:26:18.621505", "ingestion_ts": "2026-01-14T16:33:58.842229", "market_id": "0xe9c127a8c35f045d37b5344b0a36711084fa20c2fc1618bf178a5386f90610be", "raw": {"market": "0xe9c127a8c35f045d37b5344b0a36711084fa20c2fc1618bf178a5386f90610be", "asset_id": "107000426448217931795450451304515386602910396776318075817601265223856116134349", "price": "0.997", "size": "0", "side": "SELL", "timestamp": "1768404378941", "received_at": "2026-01-14T16:26:18.621505"}}
{"event_type": "price_change", "event_ts": "2026-01-14T16:26:18.621505", "ingestion_ts": "2026-01-14T16:33:58.842229", "market_id": "0xe9c127a8c35f045d37b5344b0a36711084fa20c2fc1618bf178a5386f90610be", "raw": {"market": "0xe9c127a8c35f045d37b5344b0a36711084fa20c2fc1618bf178a5386f90610be", "asset_id": "80230236018433940569996058935444651347308266584430516013229815570706872276819", "price": "0.003", "size": "0", "side": "BUY", "timestamp": "1768404378941", "received_at": "2026-01-14T16:26:18.621505"}}
{"event_type": "price_change", "event_ts": "2026-01-14T16:26:18.665681", "ingestion_ts": "2026-01-14T16:33:58.842229", "market_id": "0xe9c127a8c35f045d37b5344b0a36711084fa20c2fc1618bf178a5386f90610be", "raw": {"market": "0xe9c127a8c35f045d37b5344b0a36711084fa20c2fc1618bf178a5386f90610be", "asset_id": "107000426448217931795450451304515386602910396776318075817601265223856116134349", "price": "0.997", "size": "251", "side": "SELL", "timestamp": "1768404378969", "received_at": "2026-01-14T16:26:18.665681"}}
{"event_type": "price_change", "event_ts": "2026-01-14T16:26:18.665681", "ingestion_ts": "2026-01-14T16:33:58.842229", "market_id": "0xe9c127a8c35f045d37b5344b0a36711084fa20c2fc1618bf178a5386f90610be", "raw": {"market": "0xe9c127a8c35f045d37b5344b0a36711084fa20c2fc1618bf178a5386f90610be", "asset_id": "80230236018433940569996058935444651347308266584430516013229815570706872276819", "price": "0.003", "size": "251", "side": "BUY", "timestamp": "1768404378969", "received_at": "2026-01-14T16:26:18.665681"}}
{"event_type": "price_change", "event_ts": "2026-01-14T16:26:20.104736", "ingestion_ts": "2026-01-14T16:33:58.842229", "market_id": "0xe9c127a8c35f045d37b5344b0a36711084fa20c2fc1618bf178a5386f90610be", "raw": {"market": "0xe9c127a8c35f045d37b5344b0a36711084fa20c2fc1618bf178a5386f90610be", "asset_id": "107000426448217931795450451304515386602910396776318075817601265223856116134349", "price": "0.997", "size": "0", "side": "SELL", "timestamp": "1768404380439", "received_at": "2026-01-14T16:26:20.104736"}}
{"event_type": "price_change", "event_ts": "2026-01-14T16:26:20.104736", "ingestion_ts": "2026-01-14T16:33:58.842229", "market_id": "0xe9c127a8c35f045d37b5344b0a36711084fa20c2fc1618bf178a5386f90610be", "raw": {"market": "0xe9c127a8c35f045d37b5344b0a36711084fa20c2fc1618bf178a5386f90610be", "asset_id": "80230236018433940569996058935444651347308266584430516013229815570706872276819", "price": "0.003", "size": "0", "side": "BUY", "timestamp": "1768404380439", "received_at": "2026-01-14T16:26:20.104736"}}
{"event_type": "price_change", "event_ts": "2026-01-14T16:26:20.134644", "ingestion_ts": "2026-01-14T16:33:58.842229", "market_id": "0xe9c127a8c35f045d37b5344b0a36711084fa20c2fc1618bf178a5386f90610be", "raw": {"market": "0xe9c127a8c35f045d37b5344b0a36711084fa20c2fc1618bf178a5386f90610be", "asset_id": "107000426448217931795450451304515386602910396776318075817601265223856116134349", "price": "0.997", "size": "251", "side": "SELL", "timestamp": "1768404380469", "received_at": "2026-01-14T16:26:20.134644"}}
{"event_type": "price_change", "event_ts": "2026-01-14T16:26:20.134644", "ingestion_ts": "2026-01-14T16:33:58.842229", "market_id": "0xe9c127a8c35f045d37b5344b0a36711084fa20c2fc1618bf178a5386f90610be", "raw": {"market": "0xe9c127a8c35f045d37b5344b0a36711084fa20c2fc1618bf178a5386f90610be", "asset_id": "80230236018433940569996058935444651347308266584430516013229815570706872276819", "price": "0.003", "size": "251", "side": "BUY", "timestamp": "1768404380469", "received_at": "2026-01-14T16:26:20.134644"}}
{"event_type": "price_change", "event_ts": "2026-01-14T16:26:21.619630", "ingestion_ts": "2026-01-14T16:33:58.842229", "market_id": "0xe9c127a8c35f045d37b5344b0a36711084fa20c2fc1618bf178a5386f90610be", "raw": {"market": "0xe9c127a8c35f045d37b5344b0a36711084fa20c2fc1618bf178a5386f90610be", "asset_id": "107000426448217931795450451304515386602910396776318075817601265223856116134349", "price": "0.997", "size": "0", "side": "SELL", "timestamp": "1768404381955", "received_at": "2026-01-14T16:26:21.619630"}}
{"event_type": "price_change", "event_ts": "2026-01-14T16:26:21.619630", "ingestion_ts": "2026-01-14T16:33:58.842229", "market_id": "0xe9c127a8c35f045d37b5344b0a36711084fa20c2fc1618bf178a5386f90610be", "raw": {"market": "0xe9c127a8c35f045d37b5344b0a36711084fa20c2fc1618bf178a5386f90610be", "asset_id": "80230236018433940569996058935444651347308266584430516013229815570706872276819", "price": "0.003", "size": "0", "side": "BUY", "timestamp": "1768404381955", "received_at": "2026-01-14T16:26:21.619630"}}
{"event_type": "price_change", "event_ts": "2026-01-14T16:26:21.654214", "ingestion_ts": "2026-01-14T16:33:58.842229", "market_id": "0xe9c127a8c35f045d37b5344b0a36711084fa20c2fc1618bf178a5386f90610be", "raw": {"market": "0xe9c127a8c35f045d37b5344b0a36711084fa20c2fc1618bf178a5386f90610be", "asset_id": "107000426448217931795450451304515386602910396776318075817601265223856116134349", "price": "0.997", "size": "251", "side": "SELL", "timestamp": "1768404381988", "received_at": "2026-01-14T16:26:21.654214"}}
{"event_type": "price_change", "event_ts": "2026-01-14T16:26:21.654214", "ingestion_ts": "2026-01-14T16:33:58.842229", "market_id": "0xe9c127a8c35f045d37b5344b0a36711084fa20c2fc1618bf178a5386f90610be", "raw": {"market": "0xe9c127a8c35f045d37b5344b0a36711084fa20c2fc1618bf178a5386f90610be", "asset_id": "80230236018433940569996058935444651347308266584430516013229815570706872276819", "price": "0.003", "size": "251", "side": "BUY", "timestamp": "1768404381988", "received_at": "2026-01-14T16:26:21.654214"}}
{"event_type": "price_change", "event_ts": "2026-01-14T16:26:21.666737", "ingestion_ts": "2026-01-14T16:33:58.842229", "market_id": "0xc0e6b917320a47228fb96e3b5ae0e5c93773a5ae2662ae4e1f37807cfe47ce98", "raw": {"market": "0xc0e6b917320a47228fb96e3b5ae0e5c93773a5ae2662ae4e1f37807cfe47ce98", "asset_id": "58656358377246279051017109359677190749228949103591068167284263961542487110215", "price": "0.003", "size": "134", "side": "BUY", "timestamp": "1768404382000", "received_at": "2026-01-14T16:26:21.666737"}}
{"event_type": "price_change", "event_ts": "2026-01-14T16:26:21.666737", "ingestion_ts": "2026-01-14T16:33:58.842229", "market_id": "0xc0e6b917320a47228fb96e3b5ae0e5c93773a5ae2662ae4e1f37807cfe47ce98", "raw": {"market": "0xc0e6b917320a47228fb96e3b5ae0e5c93773a5ae2662ae4e1f37807cfe47ce98", "asset_id": "81647294538046680798858716589766492074338758116170717123345952330712416337530", "price": "0.997", "size": "134", "side": "SELL", "timestamp": "1768404382000", "received_at": "2026-01-14T16:26:21.666737"}}
{"event_type": "price_change", "event_ts": "2026-01-14T16:26:23.392047", "ingestion_ts": "2026-01-14T16:33:58.842229", "market_id": "0xe9c127a8c35f045d37b5344b0a36711084fa20c2fc1618bf178a5386f90610be", "raw": {"market": "0xe9c127a8c35f045d37b5344b0a36711084fa20c2fc1618bf178a5386f90610be", "asset_id": "107000426448217931795450451304515386602910396776318075817601265223856116134349", "price": "0.997", "size": "0", "side": "SELL", "timestamp": "1768404383441", "received_at": "2026-01-14T16:26:23.392047"}}
{"event_type": "price_change", "event_ts": "2026-01-14T16:26:23.392047", "ingestion_ts": "2026-01-14T16:33:58.842229", "market_id": "0xe9c127a8c35f045d37b5344b0a36711084fa20c2fc1618bf178a5386f90610be", "raw": {"market": "0xe9c127a8c35f045d37b5344b0a36711084fa20c2fc1618bf178a5386f90610be", "asset_id": "80230236018433940569996058935444651347308266584430516013229815570706872276819", "price": "0.003", "size": "0", "side": "BUY", "timestamp": "1768404383441", "received_at": "2026-01-14T16:26:23.392047"}}
{"event_type": "price_change", "event_ts": "2026-01-14T16:26:23.553049", "ingestion_ts": "2026-01-14T16:33:58.842229", "market_id": "0xe9c127a8c35f045d37b5344b0a36711084fa20c2fc1618bf178a5386f90610be", "raw": {"market": "0xe9c127a8c35f045d37b5344b0a36711084fa20c2fc1618bf178a5386f90610be", "asset_id": "107000426448217931795450451304515386602910396776318075817601265223856116134349", "price": "0.997", "size": "251", "side": "SELL", "timestamp": "1768404383649", "received_at": "2026-01-14T16:26:23.553049"}}
{"event_type": "price_change", "event_ts": "2026-01-14T16:26:23.553049", "ingestion_ts": "2026-01-14T16:33:58.842229", "market_id": "0xe9c127a8c35f045d37b5344b0a36711084fa20c2fc1618bf178a5386f90610be", "raw": {"market": "0xe9c127a8c35f045d37b5344b0a36711084fa20c2fc1618bf178a5386f90610be", "asset_id": "80230236018433940569996058935444651347308266584430516013229815570706872276819", "price": "0.003", "size": "251", "side": "BUY", "timestamp": "1768404383649", "received_at": "2026-01-14T16:26:23.553049"}}
{"event_type": "price_change", "event_ts": "2026-01-14T16:26:24.708857", "ingestion_ts": "2026-01-14T16:33:58.842229", "market_id": "0xe9c127a8c35f045d37b5344b0a36711084fa20c2fc1618bf178a5386f90610be", "raw": {"market": "0xe9c127a8c35f045d37b5344b0a36711084fa20c2fc1618bf178a5386f90610be", "asset_id": "107000426448217931795450451304515386602910396776318075817601265223856116134349", "price": "0.997", "size": "0", "side": "SELL", "timestamp": "1768404384942", "received_at": "2026-01-14T16:26:24.708857"}}
{"event_type": "price_change", "event_ts": "2026-01-14T16:26:24.708857", "ingestion_ts": "2026-01-14T16:33:58.842229", "market_id": "0xe9c127a8c35f045d37b5344b0a36711084fa20c2fc1618bf178a5386f90610be", "raw": {"market": "0xe9c127a8c35f045d37b5344b0a36711084fa20c2fc1618bf178a5386f90610be", "asset_id": "80230236018433940569996058935444651347308266584430516013229815570706872276819", "price": "0.003", "size": "0", "side": "BUY", "timestamp": "1768404384942", "received_at": "2026-01-14T16:26:24.708857"}}
{"event_type": "price_change", "event_ts": "2026-01-14T16:26:24.775207", "ingestion_ts": "2026-01-14T16:33:58.842229", "market_id": "0xe9c127a8c35f045d37b5344b0a36711084fa20c2fc1618bf178a5386f90610be", "raw": {"market": "0xe9c127a8c35f045d37b5344b0a36711084fa20c2fc1618bf178a5386f90610be", "asset_id": "107000426448217931795450451304515386602910396776318075817601265223856116134349", "price": "0.997", "size": "251", "side": "SELL", "timestamp": "1768404385006", "received_at": "2026-01-14T16:26:24.775207"}}
{"event_type": "price_change", "event_ts": "2026-01-14T16:26:24.775207", "ingestion_ts": "2026-01-14T16:33:58.842229", "market_id": "0xe9c127a8c35f045d37b5344b0a36711084fa20c2fc1618bf178a5386f90610be", "raw": {"market": "0xe9c127a8c35f045d37b5344b0a36711084fa20c2fc1618bf178a5386f90610be", "asset_id": "80230236018433940569996058935444651347308266584430516013229815570706872276819", "price": "0.003", "size": "251", "side": "BUY", "timestamp": "1768404385006", "received_at": "2026-01-14T16:26:24.775207"}}
{"event_type": "price_change", "event_ts": "2026-01-14T16:26:26.423099", "ingestion_ts": "2026-01-14T16:33:58.842229", "market_id": "0xe9c127a8c35f045d37b5344b0a36711084fa20c2fc1618bf178a5386f90610be", "raw": {"market": "0xe9c127a8c35f045d37b5344b0a36711084fa20c2fc1618bf178a5386f90610be", "asset_id": "107000426448217931795450451304515386602910396776318075817601265223856116134349", "price": "0.997", "size": "0", "side": "SELL", "timestamp": "1768404386440", "received_at": "2026-01-14T16:26:26.423099"}}
{"event_type": "price_change", "event_ts": "2026-01-14T16:26:26.423099", "ingestion_ts": "2026-01-14T16:33:58.842229", "market_id": "0xe9c127a8c35f045d37b5344b0a36711084fa20c2fc1618bf178a5386f90610be", "raw": {"market": "0xe9c127a8c35f045d37b5344b0a36711084fa20c2fc1618bf178a5386f90610be", "asset_id": "80230236018433940569996058935444651347308266584430516013229815570706872276819", "price": "0.003", "size": "0", "side": "BUY", "timestamp": "1768404386440", "received_at": "2026-01-14T16:26:26.423099"}}
{"event_type": "price_change", "event_ts": "2026-01-14T16:26:26.468153", "ingestion_ts": "2026-01-14T16:33:58.842229", "market_id": "0xe9c127a8c35f045d37b5344b0a36711084fa20c2fc1618bf178a5386f90610be", "raw": {"market": "0xe9c127a8c35f045d37b5344b0a36711084fa20c2fc1618bf178a5386f90610be", "asset_id": "107000426448217931795450451304515386602910396776318075817601265223856116134349", "price": "0.997", "size": "251", "side": "SELL", "timestamp": "1768404386489", "received_at": "2026-01-14T16:26:26.468153"}}
{"event_type": "price_change", "event_ts": "2026-01-14T16:26:26.468153", "ingestion_ts": "2026-01-14T16:33:58.842229", "market_id": "0xe9c127a8c35f045d37b5344b0a36711084fa20c2fc1618bf178a5386f90610be", "raw": {"market": "0xe9c127a8c35f045d37b5344b0a36711084fa20c2fc1618bf178a5386f90610be", "asset_id": "80230236018433940569996058935444651347308266584430516013229815570706872276819", "price": "0.003", "size": "251", "side": "BUY", "timestamp": "1768404386489", "received_at": "2026-01-14T16:26:26.468153"}}
{"event_type": "price_change", "event_ts": "2026-01-14T16:26:27.621657", "ingestion_ts": "2026-01-14T16:33:58.842229", "market_id": "0xe9c127a8c35f045d37b5344b0a36711084fa20c2fc1618bf178a5386f90610be", "raw": {"market": "0xe9c127a8c35f045d37b5344b0a36711084fa20c2fc1618bf178a5386f90610be", "asset_id": "107000426448217931795450451304515386602910396776318075817601265223856116134349", "price": "0.997", "size": "0", "side": "SELL", "timestamp": "1768404387954", "received_at": "2026-01-14T16:26:27.621657"}}
{"event_type": "price_change", "event_ts": "2026-01-14T16:26:27.621657", "ingestion_ts": "2026-01-14T16:33:58.842229", "market_id": "0xe9c127a8c35f045d37b5344b0a36711084fa20c2fc1618bf178a5386f90610be", "raw": {"market": "0xe9c127a8c35f045d37b5344b0a36711084fa20c2fc1618bf178a5386f90610be", "asset_id": "80230236018433940569996058935444651347308266584430516013229815570706872276819", "price": "0.003", "size": "0", "side": "BUY", "timestamp": "1768404387954", "received_at": "2026-01-14T16:26:27.621657"}}
{"event_type": "price_change", "event_ts": "2026-01-14T16:26:27.706261", "ingestion_ts": "2026-01-14T16:33:58.842229", "market_id": "0xe9c127a8c35f045d37b5344b0a36711084fa20c2fc1618bf178a5386f90610be", "raw": {"market": "0xe9c127a8c35f045d37b5344b0a36711084fa20c2fc1618bf178a5386f90610be", "asset_id": "107000426448217931795450451304515386602910396776318075817601265223856116134349", "price": "0.997", "size": "251", "side": "SELL", "timestamp": "1768404387995", "received_at": "2026-01-14T16:26:27.706261"}}
{"event_type": "price_change", "event_ts": "2026-01-14T16:26:27.706261", "ingestion_ts": "2026-01-14T16:33:58.842229", "market_id": "0xe9c127a8c35f045d37b5344b0a36711084fa20c2fc1618bf178a5386f90610be", "raw": {"market": "0xe9c127a8c35f045d37b5344b0a36711084fa20c2fc1618bf178a5386f90610be", "asset_id": "80230236018433940569996058935444651347308266584430516013229815570706872276819", "price": "0.003", "size": "251", "side": "BUY", "timestamp": "1768404387995", "received_at": "2026-01-14T16:26:27.706261"}}
{"event_type": "price_change", "event_ts": "2026-01-14T16:26:29.365280", "ingestion_ts": "2026-01-14T16:33:58.842229", "market_id": "0xe9c127a8c35f045d37b5344b0a36711084fa20c2fc1618bf178a5386f90610be", "raw": {"market": "0xe9c127a8c35f045d37b5344b0a36711084fa20c2fc1618bf178a5386f90610be", "asset_id": "107000426448217931795450451304515386602910396776318075817601265223856116134349", "price": "0.997", "size": "0", "side": "SELL", "timestamp": "1768404389450", "received_at": "2026-01-14T16:26:29.365280"}}
{"event_type": "price_change", "event_ts": "2026-01-14T16:26:29.365280", "ingestion_ts": "2026-01-14T16:33:58.842229", "market_id": "0xe9c127a8c35f045d37b5344b0a36711084fa20c2fc1618bf178a5386f90610be", "raw": {"market": "0xe9c127a8c35f045d37b5344b0a36711084fa20c2fc1618bf178a5386f90610be", "asset_id": "80230236018433940569996058935444651347308266584430516013229815570706872276819", "price": "0.003", "size": "0", "side": "BUY", "timestamp": "1768404389450", "received_at": "2026-01-14T16:26:29.365280"}}
{"event_type": "price_change", "event_ts": "2026-01-14T16:26:29.403841", "ingestion_ts": "2026-01-14T16:33:58.842229", "market_id": "0xe9c127a8c35f045d37b5344b0a36711084fa20c2fc1618bf178a5386f90610be", "raw": {"market": "0xe9c127a8c35f045d37b5344b0a36711084fa20c2fc1618bf178a5386f90610be", "asset_id": "107000426448217931795450451304515386602910396776318075817601265223856116134349", "price": "0.997", "size": "251", "side": "SELL", "timestamp": "1768404389497", "received_at": "2026-01-14T16:26:29.403841"}}
{"event_type": "price_change", "event_ts": "2026-01-14T16:26:29.403841", "ingestion_ts": "2026-01-14T16:33:58.842229", "market_id": "0xe9c127a8c35f045d37b5344b0a36711084fa20c2fc1618bf178a5386f90610be", "raw": {"market": "0xe9c127a8c35f045d37b5344b0a36711084fa20c2fc1618bf178a5386f90610be", "asset_id": "80230236018433940569996058935444651347308266584430516013229815570706872276819", "price": "0.003", "size": "251", "side": "BUY", "timestamp": "1768404389497", "received_at": "2026-01-14T16:26:29.403841"}}
{"event_type": "price_change", "event_ts": "2026-01-14T16:26:30.780966", "ingestion_ts": "2026-01-14T16:33:58.842229", "market_id": "0xe9c127a8c35f045d37b5344b0a36711084fa20c2fc1618bf178a5386f90610be", "raw": {"market": "0xe9c127a8c35f045d37b5344b0a36711084fa20c2fc1618bf178a5386f90610be", "asset_id": "107000426448217931795450451304515386602910396776318075817601265223856116134349", "price": "0.997", "size": "0", "side": "SELL", "timestamp": "1768404390980", "received_at": "2026-01-14T16:26:30.780966"}}
{"event_type": "price_change", "event_ts": "2026-01-14T16:26:30.780966", "ingestion_ts": "2026-01-14T16:33:58.842229", "market_id": "0xe9c127a8c35f045d37b5344b0a36711084fa20c2fc1618bf178a5386f90610be", "raw": {"market": "0xe9c127a8c35f045d37b5344b0a36711084fa20c2fc1618bf178a5386f90610be", "asset_id": "80230236018433940569996058935444651347308266584430516013229815570706872276819", "price": "0.003", "size": "0", "side": "BUY", "timestamp": "1768404390980", "received_at": "2026-01-14T16:26:30.780966"}}
{"event_type": "price_change", "event_ts": "2026-01-14T16:26:30.804674", "ingestion_ts": "2026-01-14T16:33:58.842229", "market_id": "0xe9c127a8c35f045d37b5344b0a36711084fa20c2fc1618bf178a5386f90610be", "raw": {"market": "0xe9c127a8c35f045d37b5344b0a36711084fa20c2fc1618bf178a5386f90610be", "asset_id": "107000426448217931795450451304515386602910396776318075817601265223856116134349", "price": "0.997", "size": "251", "side": "SELL", "timestamp": "1768404391012", "received_at": "2026-01-14T16:26:30.804674"}}
{"event_type": "price_change", "event_ts": "2026-01-14T16:26:30.804674", "ingestion_ts": "2026-01-14T16:33:58.842229", "market_id": "0xe9c127a8c35f045d37b5344b0a36711084fa20c2fc1618bf178a5386f90610be", "raw": {"market": "0xe9c127a8c35f045d37b5344b0a36711084fa20c2fc1618bf178a5386f90610be", "asset_id": "80230236018433940569996058935444651347308266584430516013229815570706872276819", "price": "0.003", "size": "251", "side": "BUY", "timestamp": "1768404391012", "received_at": "2026-01-14T16:26:30.804674"}}
{"event_type": "price_change", "event_ts": "2026-01-14T16:26:32.113157", "ingestion_ts": "2026-01-14T16:33:58.842229", "market_id": "0xe9c127a8c35f045d37b5344b0a36711084fa20c2fc1618bf178a5386f90610be", "raw": {"market": "0xe9c127a8c35f045d37b5344b0a36711084fa20c2fc1618bf178a5386f90610be", "asset_id": "107000426448217931795450451304515386602910396776318075817601265223856116134349", "price": "0.997", "size": "0", "side": "SELL", "timestamp": "1768404392442", "received_at": "2026-01-14T16:26:32.113157"}}
{"event_type": "price_change", "event_ts": "2026-01-14T16:26:32.113157", "ingestion_ts": "2026-01-14T16:33:58.842229", "market_id": "0xe9c127a8c35f045d37b5344b0a36711084fa20c2fc1618bf178a5386f90610be", "raw": {"market": "0xe9c127a8c35f045d37b5344b0a36711084fa20c2fc1618bf178a5386f90610be", "asset_id": "80230236018433940569996058935444651347308266584430516013229815570706872276819", "price": "0.003", "size": "0", "side": "BUY", "timestamp": "1768404392442", "received_at": "2026-01-14T16:26:32.113157"}}
{"event_type": "price_change", "event_ts": "2026-01-14T16:26:32.133382", "ingestion_ts": "2026-01-14T16:33:58.842229", "market_id": "0xe9c127a8c35f045d37b5344b0a36711084fa20c2fc1618bf178a5386f90610be", "raw": {"market": "0xe9c127a8c35f045d37b5344b0a36711084fa20c2fc1618bf178a5386f90610be", "asset_id": "107000426448217931795450451304515386602910396776318075817601265223856116134349", "price": "0.997", "size": "251", "side": "SELL", "timestamp": "1768404392468", "received_at": "2026-01-14T16:26:32.133382"}}
{"event_type": "price_change", "event_ts": "2026-01-14T16:26:32.133382", "ingestion_ts": "2026-01-14T16:33:58.842229", "market_id": "0xe9c127a8c35f045d37b5344b0a36711084fa20c2fc1618bf178a5386f90610be", "raw": {"market": "0xe9c127a8c35f045d37b5344b0a36711084fa20c2fc1618bf178a5386f90610be", "asset_id": "80230236018433940569996058935444651347308266584430516013229815570706872276819", "price": "0.003", "size": "251", "side": "BUY", "timestamp": "1768404392468", "received_at": "2026-01-14T16:26:32.133382"}}
{"event_type": "price_change", "event_ts": "2026-01-14T16:26:33.610910", "ingestion_ts": "2026-01-14T16:33:58.842229", "market_id": "0xe9c127a8c35f045d37b5344b0a36711084fa20c2fc1618bf178a5386f90610be", "raw": {"market": "0xe9c127a8c35f045d37b5344b0a36711084fa20c2fc1618bf178a5386f90610be", "asset_id": "107000426448217931795450451304515386602910396776318075817601265223856116134349", "price": "0.997", "size": "0", "side": "SELL", "timestamp": "1768404393942", "received_at": "2026-01-14T16:26:33.610910"}}
{"event_type": "price_change", "event_ts": "2026-01-14T16:26:33.610910", "ingestion_ts": "2026-01-14T16:33:58.842229", "market_id": "0xe9c127a8c35f045d37b5344b0a36711084fa20c2fc1618bf178a5386f90610be", "raw": {"market": "0xe9c127a8c35f045d37b5344b0a36711084fa20c2fc1618bf178a5386f90610be", "asset_id": "80230236018433940569996058935444651347308266584430516013229815570706872276819", "price": "0.003", "size": "0", "side": "BUY", "timestamp": "1768404393942", "received_at": "2026-01-14T16:26:33.610910"}}
{"event_type": "price_change", "event_ts": "2026-01-14T16:26:33.647022", "ingestion_ts": "2026-01-14T16:33:58.842229", "market_id": "0xe9c127a8c35f045d37b5344b0a36711084fa20c2fc1618bf178a5386f90610be", "raw": {"market": "0xe9c127a8c35f045d37b5344b0a36711084fa20c2fc1618bf178a5386f90610be", "asset_id": "107000426448217931795450451304515386602910396776318075817601265223856116134349", "price": "0.997", "size": "251", "side": "SELL", "timestamp": "1768404393969", "received_at": "2026-01-14T16:26:33.647022"}}
{"event_type": "price_change", "event_ts": "2026-01-14T16:26:33.647022", "ingestion_ts": "2026-01-14T16:33:58.842229", "market_id": "0xe9c127a8c35f045d37b5344b0a36711084fa20c2fc1618bf178a5386f90610be", "raw": {"market": "0xe9c127a8c35f045d37b5344b0a36711084fa20c2fc1618bf178a5386f90610be", "asset_id": "80230236018433940569996058935444651347308266584430516013229815570706872276819", "price": "0.003", "size": "251", "side": "BUY", "timestamp": "1768404393969", "received_at": "2026-01-14T16:26:33.647022"}}
{"event_type": "price_change", "event_ts": "2026-01-14T16:26:35.105888", "ingestion_ts": "2026-01-14T16:33:58.842229", "market_id": "0xe9c127a8c35f045d37b5344b0a36711084fa20c2fc1618bf178a5386f90610be", "raw": {"market": "0xe9c127a8c35f045d37b5344b0a36711084fa20c2fc1618bf178a5386f90610be", "asset_id": "107000426448217931795450451304515386602910396776318075817601265223856116134349", "price": "0.997", "size": "0", "side": "SELL", "timestamp": "1768404395439", "received_at": "2026-01-14T16:26:35.105888"}}
{"event_type": "price_change", "event_ts": "2026-01-14T16:26:35.105888", "ingestion_ts": "2026-01-14T16:33:58.842229", "market_id": "0xe9c127a8c35f045d37b5344b0a36711084fa20c2fc1618bf178a5386f90610be", "raw": {"market": "0xe9c127a8c35f045d37b5344b0a36711084fa20c2fc1618bf178a5386f90610be", "asset_id": "80230236018433940569996058935444651347308266584430516013229815570706872276819", "price": "0.003", "size": "0", "side": "BUY", "timestamp": "1768404395439", "received_at": "2026-01-14T16:26:35.105888"}}
{"event_type": "price_change", "event_ts": "2026-01-14T16:26:35.135385", "ingestion_ts": "2026-01-14T16:33:58.842229", "market_id": "0xe9c127a8c35f045d37b5344b0a36711084fa20c2fc1618bf178a5386f90610be", "raw": {"market": "0xe9c127a8c35f045d37b5344b0a36711084fa20c2fc1618bf178a5386f90610be", "asset_id": "107000426448217931795450451304515386602910396776318075817601265223856116134349", "price": "0.997", "size": "251", "side": "SELL", "timestamp": "1768404395470", "received_at": "2026-01-14T16:26:35.135385"}}
{"event_type": "price_change", "event_ts": "2026-01-14T16:26:35.135385", "ingestion_ts": "2026-01-14T16:33:58.842229", "market_id": "0xe9c127a8c35f045d37b5344b0a36711084fa20c2fc1618bf178a5386f90610be", "raw": {"market": "0xe9c127a8c35f045d37b5344b0a36711084fa20c2fc1618bf178a5386f90610be", "asset_id": "80230236018433940569996058935444651347308266584430516013229815570706872276819", "price": "0.003", "size": "251", "side": "BUY", "timestamp": "1768404395470", "received_at": "2026-01-14T16:26:35.135385"}}
{"event_type": "price_change", "event_ts": "2026-01-14T16:26:36.617764", "ingestion_ts": "2026-01-14T16:33:58.842229", "market_id": "0xe9c127a8c35f045d37b5344b0a36711084fa20c2fc1618bf178a5386f90610be", "raw": {"market": "0xe9c127a8c35f045d37b5344b0a36711084fa20c2fc1618bf178a5386f90610be", "asset_id": "107000426448217931795450451304515386602910396776318075817601265223856116134349", "price": "0.997", "size": "0", "side": "SELL", "timestamp": "1768404396941", "received_at": "2026-01-14T16:26:36.617764"}}
{"event_type": "price_change", "event_ts": "2026-01-14T16:26:36.617764", "ingestion_ts": "2026-01-14T16:33:58.842229", "market_id": "0xe9c127a8c35f045d37b5344b0a36711084fa20c2fc1618bf178a5386f90610be", "raw": {"market": "0xe9c127a8c35f045d37b5344b0a36711084fa20c2fc1618bf178a5386f90610be", "asset_id": "80230236018433940569996058935444651347308266584430516013229815570706872276819", "price": "0.003", "size": "0", "side": "BUY", "timestamp": "1768404396941", "received_at": "2026-01-14T16:26:36.617764"}}
{"event_type": "price_change", "event_ts": "2026-01-14T16:26:36.666777", "ingestion_ts": "2026-01-14T16:33:58.842229", "market_id": "0xe9c127a8c35f045d37b5344b0a36711084fa20c2fc1618bf178a5386f90610be", "raw": {"market": "0xe9c127a8c35f045d37b5344b0a36711084fa20c2fc1618bf178a5386f90610be", "asset_id": "107000426448217931795450451304515386602910396776318075817601265223856116134349", "price": "0.997", "size": "251", "side": "SELL", "timestamp": "1768404396969", "received_at": "2026-01-14T16:26:36.666777"}}
{"event_type": "price_change", "event_ts": "2026-01-14T16:26:36.666777", "ingestion_ts": "2026-01-14T16:33:58.842229", "market_id": "0xe9c127a8c35f045d37b5344b0a36711084fa20c2fc1618bf178a5386f90610be", "raw": {"market": "0xe9c127a8c35f045d37b5344b0a36711084fa20c2fc1618bf178a5386f90610be", "asset_id": "80230236018433940569996058935444651347308266584430516013229815570706872276819", "price": "0.003", "size": "251", "side": "BUY", "timestamp": "1768404396969", "received_at": "2026-01-14T16:26:36.666777"}}
{"event_type": "price_change", "event_ts": "2026-01-14T16:26:37.498294", "ingestion_ts": "2026-01-14T16:33:58.842229", "market_id": "0xe6508d867d153a268bdab732aa8abc8cc57e652d28a23aa042da40895bf031b2", "raw": {"market": "0xe6508d867d153a268bdab732aa8abc8cc57e652d28a23aa042da40895bf031b2", "asset_id": "57878493050148425637822780001963685814731344602319345842647239312888833935027", "price": "0.999", "size": "32307.09", "side": "SELL", "timestamp": "1768404397794", "received_at": "2026-01-14T16:26:37.498294"}}
{"event_type": "price_change", "event_ts": "2026-01-14T16:26:37.498294", "ingestion_ts": "2026-01-14T16:33:58.842229", "market_id": "0xe6508d867d153a268bdab732aa8abc8cc57e652d28a23aa042da40895bf031b2", "raw": {"market": "0xe6508d867d153a268bdab732aa8abc8cc57e652d28a23aa042da40895bf031b2", "asset_id": "2853768819561879023657600399360829876689515906714535926781067187993853038980", "price": "0.001", "size": "32307.09", "side": "BUY", "timestamp": "1768404397794", "received_at": "2026-01-14T16:26:37.498294"}}
{"event_type": "price_change", "event_ts": "2026-01-14T16:26:38.139718", "ingestion_ts": "2026-01-14T16:33:58.842229", "market_id": "0xe9c127a8c35f045d37b5344b0a36711084fa20c2fc1618bf178a5386f90610be", "raw": {"market": "0xe9c127a8c35f045d37b5344b0a36711084fa20c2fc1618bf178a5386f90610be", "asset_id": "107000426448217931795450451304515386602910396776318075817601265223856116134349", "price": "0.997", "size": "0", "side": "SELL", "timestamp": "1768404398475", "received_at": "2026-01-14T16:26:38.139718"}}
{"event_type": "price_change", "event_ts": "2026-01-14T16:26:38.139718", "ingestion_ts": "2026-01-14T16:33:58.842229", "market_id": "0xe9c127a8c35f045d37b5344b0a36711084fa20c2fc1618bf178a5386f90610be", "raw": {"market": "0xe9c127a8c35f045d37b5344b0a36711084fa20c2fc1618bf178a5386f90610be", "asset_id": "80230236018433940569996058935444651347308266584430516013229815570706872276819", "price": "0.003", "size": "0", "side": "BUY", "timestamp": "1768404398475", "received_at": "2026-01-14T16:26:38.139718"}}
{"event_type": "price_change", "event_ts": "2026-01-14T16:26:38.176417", "ingestion_ts": "2026-01-14T16:33:58.842229", "market_id": "0xe9c127a8c35f045d37b5344b0a36711084fa20c2fc1618bf178a5386f90610be", "raw": {"market": "0xe9c127a8c35f045d37b5344b0a36711084fa20c2fc1618bf178a5386f90610be", "asset_id": "107000426448217931795450451304515386602910396776318075817601265223856116134349", "price": "0.997", "size": "251", "side": "SELL", "timestamp": "1768404398510", "received_at": "2026-01-14T16:26:38.176417"}}
{"event_type": "price_change", "event_ts": "2026-01-14T16:26:38.176417", "ingestion_ts": "2026-01-14T16:33:58.842229", "market_id": "0xe9c127a8c35f045d37b5344b0a36711084fa20c2fc1618bf178a5386f90610be", "raw": {"market": "0xe9c127a8c35f045d37b5344b0a36711084fa20c2fc1618bf178a5386f90610be", "asset_id": "80230236018433940569996058935444651347308266584430516013229815570706872276819", "price": "0.003", "size": "251", "side": "BUY", "timestamp": "1768404398510", "received_at": "2026-01-14T16:26:38.176417"}}
{"event_type": "price_change", "event_ts": "2026-01-14T16:26:39.604431", "ingestion_ts": "2026-01-14T16:33:58.842229", "market_id": "0xe9c127a8c35f045d37b5344b0a36711084fa20c2fc1618bf178a5386f90610be", "raw": {"market": "0xe9c127a8c35f045d37b5344b0a36711084fa20c2fc1618bf178a5386f90610be", "asset_id": "107000426448217931795450451304515386602910396776318075817601265223856116134349", "price": "0.997", "size": "0", "side": "SELL", "timestamp": "1768404399939", "received_at": "2026-01-14T16:26:39.604431"}}
{"event_type": "price_change", "event_ts": "2026-01-14T16:26:39.604431", "ingestion_ts": "2026-01-14T16:33:58.842229", "market_id": "0xe9c127a8c35f045d37b5344b0a36711084fa20c2fc1618bf178a5386f90610be", "raw": {"market": "0xe9c127a8c35f045d37b5344b0a36711084fa20c2fc1618bf178a5386f90610be", "asset_id": "80230236018433940569996058935444651347308266584430516013229815570706872276819", "price": "0.003", "size": "0", "side": "BUY", "timestamp": "1768404399939", "received_at": "2026-01-14T16:26:39.604431"}}
{"event_type": "price_change", "event_ts": "2026-01-14T16:26:39.634082", "ingestion_ts": "2026-01-14T16:33:58.842229", "market_id": "0xe9c127a8c35f045d37b5344b0a36711084fa20c2fc1618bf178a5386f90610be", "raw": {"market": "0xe9c127a8c35f045d37b5344b0a36711084fa20c2fc1618bf178a5386f90610be", "asset_id": "107000426448217931795450451304515386602910396776318075817601265223856116134349", "price": "0.997", "size": "251", "side": "SELL", "timestamp": "1768404399969", "received_at": "2026-01-14T16:26:39.634082"}}
{"event_type": "price_change", "event_ts": "2026-01-14T16:26:39.634082", "ingestion_ts": "2026-01-14T16:33:58.842229", "market_id": "0xe9c127a8c35f045d37b5344b0a36711084fa20c2fc1618bf178a5386f90610be", "raw": {"market": "0xe9c127a8c35f045d37b5344b0a36711084fa20c2fc1618bf178a5386f90610be", "asset_id": "80230236018433940569996058935444651347308266584430516013229815570706872276819", "price": "0.003", "size": "251", "side": "BUY", "timestamp": "1768404399969", "received_at": "2026-01-14T16:26:39.634082"}}
{"event_type": "price_change", "event_ts": "2026-01-14T16:26:41.143667", "ingestion_ts": "2026-01-14T16:33:58.842229", "market_id": "0xe9c127a8c35f045d37b5344b0a36711084fa20c2fc1618bf178a5386f90610be", "raw": {"market": "0xe9c127a8c35f045d37b5344b0a36711084fa20c2fc1618bf178a5386f90610be", "asset_id": "107000426448217931795450451304515386602910396776318075817601265223856116134349", "price": "0.997", "size": "0", "side": "SELL", "timestamp": "1768404401440", "received_at": "2026-01-14T16:26:41.143667"}}
{"event_type": "price_change", "event_ts": "2026-01-14T16:26:41.143667", "ingestion_ts": "2026-01-14T16:33:58.842229", "market_id": "0xe9c127a8c35f045d37b5344b0a36711084fa20c2fc1618bf178a5386f90610be", "raw": {"market": "0xe9c127a8c35f045d37b5344b0a36711084fa20c2fc1618bf178a5386f90610be", "asset_id": "80230236018433940569996058935444651347308266584430516013229815570706872276819", "price": "0.003", "size": "0", "side": "BUY", "timestamp": "1768404401440", "received_at": "2026-01-14T16:26:41.143667"}}
{"event_type": "price_change", "event_ts": "2026-01-14T16:26:41.182712", "ingestion_ts": "2026-01-14T16:33:58.842229", "market_id": "0xe9c127a8c35f045d37b5344b0a36711084fa20c2fc1618bf178a5386f90610be", "raw": {"market": "0xe9c127a8c35f045d37b5344b0a36711084fa20c2fc1618bf178a5386f90610be", "asset_id": "107000426448217931795450451304515386602910396776318075817601265223856116134349", "price": "0.997", "size": "251", "side": "SELL", "timestamp": "1768404401476", "received_at": "2026-01-14T16:26:41.182712"}}
{"event_type": "price_change", "event_ts": "2026-01-14T16:26:41.182712", "ingestion_ts": "2026-01-14T16:33:58.842229", "market_id": "0xe9c127a8c35f045d37b5344b0a36711084fa20c2fc1618bf178a5386f90610be", "raw": {"market": "0xe9c127a8c35f045d37b5344b0a36711084fa20c2fc1618bf178a5386f90610be", "asset_id": "80230236018433940569996058935444651347308266584430516013229815570706872276819", "price": "0.003", "size": "251", "side": "BUY", "timestamp": "1768404401476", "received_at": "2026-01-14T16:26:41.182712"}}
{"event_type": "price_change", "event_ts": "2026-01-14T16:26:42.704229", "ingestion_ts": "2026-01-14T16:33:58.842229", "market_id": "0xe9c127a8c35f045d37b5344b0a36711084fa20c2fc1618bf178a5386f90610be", "raw": {"market": "0xe9c127a8c35f045d37b5344b0a36711084fa20c2fc1618bf178a5386f90610be", "asset_id": "107000426448217931795450451304515386602910396776318075817601265223856116134349", "price": "0.997", "size": "0", "side": "SELL", "timestamp": "1768404402948", "received_at": "2026-01-14T16:26:42.704229"}}
{"event_type": "price_change", "event_ts": "2026-01-14T16:26:42.704229", "ingestion_ts": "2026-01-14T16:33:58.842229", "market_id": "0xe9c127a8c35f045d37b5344b0a36711084fa20c2fc1618bf178a5386f90610be", "raw": {"market": "0xe9c127a8c35f045d37b5344b0a36711084fa20c2fc1618bf178a5386f90610be", "asset_id": "80230236018433940569996058935444651347308266584430516013229815570706872276819", "price": "0.003", "size": "0", "side": "BUY", "timestamp": "1768404402948", "received_at": "2026-01-14T16:26:42.704229"}}
{"event_type": "price_change", "event_ts": "2026-01-14T16:26:42.761576", "ingestion_ts": "2026-01-14T16:33:58.842229", "market_id": "0xe9c127a8c35f045d37b5344b0a36711084fa20c2fc1618bf178a5386f90610be", "raw": {"market": "0xe9c127a8c35f045d37b5344b0a36711084fa20c2fc1618bf178a5386f90610be", "asset_id": "107000426448217931795450451304515386602910396776318075817601265223856116134349", "price": "0.997", "size": "251", "side": "SELL", "timestamp": "1768404403002", "received_at": "2026-01-14T16:26:42.761576"}}
{"event_type": "price_change", "event_ts": "2026-01-14T16:26:42.761576", "ingestion_ts": "2026-01-14T16:33:58.842229", "market_id": "0xe9c127a8c35f045d37b5344b0a36711084fa20c2fc1618bf178a5386f90610be", "raw": {"market": "0xe9c127a8c35f045d37b5344b0a36711084fa20c2fc1618bf178a5386f90610be", "asset_id": "80230236018433940569996058935444651347308266584430516013229815570706872276819", "price": "0.003", "size": "251", "side": "BUY", "timestamp": "1768404403002", "received_at": "2026-01-14T16:26:42.761576"}}
{"event_type": "price_change", "event_ts": "2026-01-14T16:26:44.153188", "ingestion_ts": "2026-01-14T16:33:58.842229", "market_id": "0xe9c127a8c35f045d37b5344b0a36711084fa20c2fc1618bf178a5386f90610be", "raw": {"market": "0xe9c127a8c35f045d37b5344b0a36711084fa20c2fc1618bf178a5386f90610be", "asset_id": "107000426448217931795450451304515386602910396776318075817601265223856116134349", "price": "0.997", "size": "0", "side": "SELL", "timestamp": "1768404404486", "received_at": "2026-01-14T16:26:44.153188"}}
{"event_type": "price_change", "event_ts": "2026-01-14T16:26:44.153188", "ingestion_ts": "2026-01-14T16:33:58.842229", "market_id": "0xe9c127a8c35f045d37b5344b0a36711084fa20c2fc1618bf178a5386f90610be", "raw": {"market": "0xe9c127a8c35f045d37b5344b0a36711084fa20c2fc1618bf178a5386f90610be", "asset_id": "80230236018433940569996058935444651347308266584430516013229815570706872276819", "price": "0.003", "size": "0", "side": "BUY", "timestamp": "1768404404486", "received_at": "2026-01-14T16:26:44.153188"}}
{"event_type": "price_change", "event_ts": "2026-01-14T16:26:44.193515", "ingestion_ts": "2026-01-14T16:33:58.842229", "market_id": "0xe9c127a8c35f045d37b5344b0a36711084fa20c2fc1618bf178a5386f90610be", "raw": {"market": "0xe9c127a8c35f045d37b5344b0a36711084fa20c2fc1618bf178a5386f90610be", "asset_id": "107000426448217931795450451304515386602910396776318075817601265223856116134349", "price": "0.997", "size": "251", "side": "SELL", "timestamp": "1768404404528", "received_at": "2026-01-14T16:26:44.193515"}}
{"event_type": "price_change", "event_ts": "2026-01-14T16:26:44.193515", "ingestion_ts": "2026-01-14T16:33:58.842229", "market_id": "0xe9c127a8c35f045d37b5344b0a36711084fa20c2fc1618bf178a5386f90610be", "raw": {"market": "0xe9c127a8c35f045d37b5344b0a36711084fa20c2fc1618bf178a5386f90610be", "asset_id": "80230236018433940569996058935444651347308266584430516013229815570706872276819", "price": "0.003", "size": "251", "side": "BUY", "timestamp": "1768404404528", "received_at": "2026-01-14T16:26:44.193515"}}
{"event_type": "price_change", "event_ts": "2026-01-14T16:26:45.689952", "ingestion_ts": "2026-01-14T16:33:58.842229", "market_id": "0xe9c127a8c35f045d37b5344b0a36711084fa20c2fc1618bf178a5386f90610be", "raw": {"market": "0xe9c127a8c35f045d37b5344b0a36711084fa20c2fc1618bf178a5386f90610be", "asset_id": "107000426448217931795450451304515386602910396776318075817601265223856116134349", "price": "0.997", "size": "0", "side": "SELL", "timestamp": "1768404405939", "received_at": "2026-01-14T16:26:45.689952"}}
{"event_type": "price_change", "event_ts": "2026-01-14T16:26:45.689952", "ingestion_ts": "2026-01-14T16:33:58.842229", "market_id": "0xe9c127a8c35f045d37b5344b0a36711084fa20c2fc1618bf178a5386f90610be", "raw": {"market": "0xe9c127a8c35f045d37b5344b0a36711084fa20c2fc1618bf178a5386f90610be", "asset_id": "80230236018433940569996058935444651347308266584430516013229815570706872276819", "price": "0.003", "size": "0", "side": "BUY", "timestamp": "1768404405939", "received_at": "2026-01-14T16:26:45.689952"}}
{"event_type": "price_change", "event_ts": "2026-01-14T16:26:45.816680", "ingestion_ts": "2026-01-14T16:33:58.842229", "market_id": "0xe9c127a8c35f045d37b5344b0a36711084fa20c2fc1618bf178a5386f90610be", "raw": {"market": "0xe9c127a8c35f045d37b5344b0a36711084fa20c2fc1618bf178a5386f90610be", "asset_id": "107000426448217931795450451304515386602910396776318075817601265223856116134349", "price": "0.997", "size": "251", "side": "SELL", "timestamp": "1768404406039", "received_at": "2026-01-14T16:26:45.816680"}}
{"event_type": "price_change", "event_ts": "2026-01-14T16:26:45.816680", "ingestion_ts": "2026-01-14T16:33:58.842229", "market_id": "0xe9c127a8c35f045d37b5344b0a36711084fa20c2fc1618bf178a5386f90610be", "raw": {"market": "0xe9c127a8c35f045d37b5344b0a36711084fa20c2fc1618bf178a5386f90610be", "asset_id": "80230236018433940569996058935444651347308266584430516013229815570706872276819", "price": "0.003", "size": "251", "side": "BUY", "timestamp": "1768404406039", "received_at": "2026-01-14T16:26:45.816680"}}
{"event_type": "price_change", "event_ts": "2026-01-14T16:26:46.917450", "ingestion_ts": "2026-01-14T16:33:58.842229", "market_id": "0x318b222c1435b47c338e66ca6001f782711186a488ae7b7248f7edc6ff076a83", "raw": {"market": "0x318b222c1435b47c338e66ca6001f782711186a488ae7b7248f7edc6ff076a83", "asset_id": "63773739594775606083258239254748928077067768053882704658119720069071630213026", "price": "0.205", "size": "0", "side": "BUY", "timestamp": "1768404407057", "received_at": "2026-01-14T16:26:46.917450"}}
{"event_type": "price_change", "event_ts": "2026-01-14T16:26:46.917450", "ingestion_ts": "2026-01-14T16:33:58.842229", "market_id": "0x318b222c1435b47c338e66ca6001f782711186a488ae7b7248f7edc6ff076a83", "raw": {"market": "0x318b222c1435b47c338e66ca6001f782711186a488ae7b7248f7edc6ff076a83", "asset_id": "56738600572035832904895845056468792275697823297413384908752239327866518310010", "price": "0.795", "size": "0", "side": "SELL", "timestamp": "1768404407057", "received_at": "2026-01-14T16:26:46.917450"}}
{"event_type": "price_change", "event_ts": "2026-01-14T16:26:47.657776", "ingestion_ts": "2026-01-14T16:33:58.842229", "market_id": "0xe9c127a8c35f045d37b5344b0a36711084fa20c2fc1618bf178a5386f90610be", "raw": {"market": "0xe9c127a8c35f045d37b5344b0a36711084fa20c2fc1618bf178a5386f90610be", "asset_id": "107000426448217931795450451304515386602910396776318075817601265223856116134349", "price": "0.997", "size": "0", "side": "SELL", "timestamp": "1768404407440", "received_at": "2026-01-14T16:26:47.657776"}}
{"event_type": "price_change", "event_ts": "2026-01-14T16:26:47.657776", "ingestion_ts": "2026-01-14T16:33:58.842229", "market_id": "0xe9c127a8c35f045d37b5344b0a36711084fa20c2fc1618bf178a5386f90610be", "raw": {"market": "0xe9c127a8c35f045d37b5344b0a36711084fa20c2fc1618bf178a5386f90610be", "asset_id": "80230236018433940569996058935444651347308266584430516013229815570706872276819", "price": "0.003", "size": "0", "side": "BUY", "timestamp": "1768404407440", "received_at": "2026-01-14T16:26:47.657776"}}
{"event_type": "price_change", "event_ts": "2026-01-14T16:26:48.008171", "ingestion_ts": "2026-01-14T16:33:58.842229", "market_id": "0xe9c127a8c35f045d37b5344b0a36711084fa20c2fc1618bf178a5386f90610be", "raw": {"market": "0xe9c127a8c35f045d37b5344b0a36711084fa20c2fc1618bf178a5386f90610be", "asset_id": "107000426448217931795450451304515386602910396776318075817601265223856116134349", "price": "0.997", "size": "251", "side": "SELL", "timestamp": "1768404407982", "received_at": "2026-01-14T16:26:48.008171"}}
{"event_type": "price_change", "event_ts": "2026-01-14T16:26:48.008171", "ingestion_ts": "2026-01-14T16:33:58.842229", "market_id": "0xe9c127a8c35f045d37b5344b0a36711084fa20c2fc1618bf178a5386f90610be", "raw": {"market": "0xe9c127a8c35f045d37b5344b0a36711084fa20c2fc1618bf178a5386f90610be", "asset_id": "80230236018433940569996058935444651347308266584430516013229815570706872276819", "price": "0.003", "size": "251", "side": "BUY", "timestamp": "1768404407982", "received_at": "2026-01-14T16:26:48.008171"}}
{"event_type": "price_change", "event_ts": "2026-01-14T16:26:49.108966", "ingestion_ts": "2026-01-14T16:33:58.842229", "market_id": "0xe9c127a8c35f045d37b5344b0a36711084fa20c2fc1618bf178a5386f90610be", "raw": {"market": "0xe9c127a8c35f045d37b5344b0a36711084fa20c2fc1618bf178a5386f90610be", "asset_id": "107000426448217931795450451304515386602910396776318075817601265223856116134349", "price": "0.997", "size": "0", "side": "SELL", "timestamp": "1768404409444", "received_at": "2026-01-14T16:26:49.108966"}}
{"event_type": "price_change", "event_ts": "2026-01-14T16:26:49.108966", "ingestion_ts": "2026-01-14T16:33:58.842229", "market_id": "0xe9c127a8c35f045d37b5344b0a36711084fa20c2fc1618bf178a5386f90610be", "raw": {"market": "0xe9c127a8c35f045d37b5344b0a36711084fa20c2fc1618bf178a5386f90610be", "asset_id": "80230236018433940569996058935444651347308266584430516013229815570706872276819", "price": "0.003", "size": "0", "side": "BUY", "timestamp": "1768404409444", "received_at": "2026-01-14T16:26:49.108966"}}
{"event_type": "price_change", "event_ts": "2026-01-14T16:26:49.143258", "ingestion_ts": "2026-01-14T16:33:58.842229", "market_id": "0xe9c127a8c35f045d37b5344b0a36711084fa20c2fc1618bf178a5386f90610be", "raw": {"market": "0xe9c127a8c35f045d37b5344b0a36711084fa20c2fc1618bf178a5386f90610be", "asset_id": "107000426448217931795450451304515386602910396776318075817601265223856116134349", "price": "0.997", "size": "251", "side": "SELL", "timestamp": "1768404409478", "received_at": "2026-01-14T16:26:49.143258"}}
{"event_type": "price_change", "event_ts": "2026-01-14T16:26:49.143258", "ingestion_ts": "2026-01-14T16:33:58.842229", "market_id": "0xe9c127a8c35f045d37b5344b0a36711084fa20c2fc1618bf178a5386f90610be", "raw": {"market": "0xe9c127a8c35f045d37b5344b0a36711084fa20c2fc1618bf178a5386f90610be", "asset_id": "80230236018433940569996058935444651347308266584430516013229815570706872276819", "price": "0.003", "size": "251", "side": "BUY", "timestamp": "1768404409478", "received_at": "2026-01-14T16:26:49.143258"}}
{"event_type": "price_change", "event_ts": "2026-01-14T16:26:50.607361", "ingestion_ts": "2026-01-14T16:33:58.842229", "market_id": "0xe9c127a8c35f045d37b5344b0a36711084fa20c2fc1618bf178a5386f90610be", "raw": {"market": "0xe9c127a8c35f045d37b5344b0a36711084fa20c2fc1618bf178a5386f90610be", "asset_id": "107000426448217931795450451304515386602910396776318075817601265223856116134349", "price": "0.997", "size": "0", "side": "SELL", "timestamp": "1768404410941", "received_at": "2026-01-14T16:26:50.607361"}}
{"event_type": "price_change", "event_ts": "2026-01-14T16:26:50.607361", "ingestion_ts": "2026-01-14T16:33:58.842229", "market_id": "0xe9c127a8c35f045d37b5344b0a36711084fa20c2fc1618bf178a5386f90610be", "raw": {"market": "0xe9c127a8c35f045d37b5344b0a36711084fa20c2fc1618bf178a5386f90610be", "asset_id": "80230236018433940569996058935444651347308266584430516013229815570706872276819", "price": "0.003", "size": "0", "side": "BUY", "timestamp": "1768404410941", "received_at": "2026-01-14T16:26:50.607361"}}
{"event_type": "price_change", "event_ts": "2026-01-14T16:26:50.640604", "ingestion_ts": "2026-01-14T16:33:58.842229", "market_id": "0xe9c127a8c35f045d37b5344b0a36711084fa20c2fc1618bf178a5386f90610be", "raw": {"market": "0xe9c127a8c35f045d37b5344b0a36711084fa20c2fc1618bf178a5386f90610be", "asset_id": "107000426448217931795450451304515386602910396776318075817601265223856116134349", "price": "0.997", "size": "251", "side": "SELL", "timestamp": "1768404410976", "received_at": "2026-01-14T16:26:50.640604"}}
{"event_type": "price_change", "event_ts": "2026-01-14T16:26:50.640604", "ingestion_ts": "2026-01-14T16:33:58.842229", "market_id": "0xe9c127a8c35f045d37b5344b0a36711084fa20c2fc1618bf178a5386f90610be", "raw": {"market": "0xe9c127a8c35f045d37b5344b0a36711084fa20c2fc1618bf178a5386f90610be", "asset_id": "80230236018433940569996058935444651347308266584430516013229815570706872276819", "price": "0.003", "size": "251", "side": "BUY", "timestamp": "1768404410976", "received_at": "2026-01-14T16:26:50.640604"}}
{"event_type": "price_change", "event_ts": "2026-01-14T16:26:52.118755", "ingestion_ts": "2026-01-14T16:33:58.842229", "market_id": "0xe9c127a8c35f045d37b5344b0a36711084fa20c2fc1618bf178a5386f90610be", "raw": {"market": "0xe9c127a8c35f045d37b5344b0a36711084fa20c2fc1618bf178a5386f90610be", "asset_id": "107000426448217931795450451304515386602910396776318075817601265223856116134349", "price": "0.997", "size": "0", "side": "SELL", "timestamp": "1768404412441", "received_at": "2026-01-14T16:26:52.118755"}}
{"event_type": "price_change", "event_ts": "2026-01-14T16:26:52.118755", "ingestion_ts": "2026-01-14T16:33:58.842229", "market_id": "0xe9c127a8c35f045d37b5344b0a36711084fa20c2fc1618bf178a5386f90610be", "raw": {"market": "0xe9c127a8c35f045d37b5344b0a36711084fa20c2fc1618bf178a5386f90610be", "asset_id": "80230236018433940569996058935444651347308266584430516013229815570706872276819", "price": "0.003", "size": "0", "side": "BUY", "timestamp": "1768404412441", "received_at": "2026-01-14T16:26:52.118755"}}
{"event_type": "price_change", "event_ts": "2026-01-14T16:26:52.143669", "ingestion_ts": "2026-01-14T16:33:58.842229", "market_id": "0xe9c127a8c35f045d37b5344b0a36711084fa20c2fc1618bf178a5386f90610be", "raw": {"market": "0xe9c127a8c35f045d37b5344b0a36711084fa20c2fc1618bf178a5386f90610be", "asset_id": "107000426448217931795450451304515386602910396776318075817601265223856116134349", "price": "0.997", "size": "251", "side": "SELL", "timestamp": "1768404412479", "received_at": "2026-01-14T16:26:52.143669"}}
{"event_type": "price_change", "event_ts": "2026-01-14T16:26:52.143669", "ingestion_ts": "2026-01-14T16:33:58.842229", "market_id": "0xe9c127a8c35f045d37b5344b0a36711084fa20c2fc1618bf178a5386f90610be", "raw": {"market": "0xe9c127a8c35f045d37b5344b0a36711084fa20c2fc1618bf178a5386f90610be", "asset_id": "80230236018433940569996058935444651347308266584430516013229815570706872276819", "price": "0.003", "size": "251", "side": "BUY", "timestamp": "1768404412479", "received_at": "2026-01-14T16:26:52.143669"}}
{"event_type": "price_change", "event_ts": "2026-01-14T16:26:53.611087", "ingestion_ts": "2026-01-14T16:33:58.842229", "market_id": "0xe9c127a8c35f045d37b5344b0a36711084fa20c2fc1618bf178a5386f90610be", "raw": {"market": "0xe9c127a8c35f045d37b5344b0a36711084fa20c2fc1618bf178a5386f90610be", "asset_id": "107000426448217931795450451304515386602910396776318075817601265223856116134349", "price": "0.997", "size": "0", "side": "SELL", "timestamp": "1768404413940", "received_at": "2026-01-14T16:26:53.611087"}}
{"event_type": "price_change", "event_ts": "2026-01-14T16:26:53.611087", "ingestion_ts": "2026-01-14T16:33:58.842229", "market_id": "0xe9c127a8c35f045d37b5344b0a36711084fa20c2fc1618bf178a5386f90610be", "raw": {"market": "0xe9c127a8c35f045d37b5344b0a36711084fa20c2fc1618bf178a5386f90610be", "asset_id": "80230236018433940569996058935444651347308266584430516013229815570706872276819", "price": "0.003", "size": "0", "side": "BUY", "timestamp": "1768404413940", "received_at": "2026-01-14T16:26:53.611087"}}
{"event_type": "price_change", "event_ts": "2026-01-14T16:26:53.649685", "ingestion_ts": "2026-01-14T16:33:58.842229", "market_id": "0xe9c127a8c35f045d37b5344b0a36711084fa20c2fc1618bf178a5386f90610be", "raw": {"market": "0xe9c127a8c35f045d37b5344b0a36711084fa20c2fc1618bf178a5386f90610be", "asset_id": "107000426448217931795450451304515386602910396776318075817601265223856116134349", "price": "0.997", "size": "251", "side": "SELL", "timestamp": "1768404413969", "received_at": "2026-01-14T16:26:53.649685"}}
{"event_type": "price_change", "event_ts": "2026-01-14T16:26:53.649685", "ingestion_ts": "2026-01-14T16:33:58.842229", "market_id": "0xe9c127a8c35f045d37b5344b0a36711084fa20c2fc1618bf178a5386f90610be", "raw": {"market": "0xe9c127a8c35f045d37b5344b0a36711084fa20c2fc1618bf178a5386f90610be", "asset_id": "80230236018433940569996058935444651347308266584430516013229815570706872276819", "price": "0.003", "size": "251", "side": "BUY", "timestamp": "1768404413969", "received_at": "2026-01-14T16:26:53.649685"}}
{"event_type": "price_change", "event_ts": "2026-01-14T16:26:53.826158", "ingestion_ts": "2026-01-14T16:33:58.842229", "market_id": "0x2393ed0b0fdc450054c7b9071907eca75cf4fc36e385adf4a0a5f99ee62243e8", "raw": {"market": "0x2393ed0b0fdc450054c7b9071907eca75cf4fc36e385adf4a0a5f99ee62243e8", "asset_id": "32769749367306925959219403371425714180265458150646381231272229429098460625924", "price": "0.946", "size": "99.99", "side": "BUY", "timestamp": "1768404414161", "received_at": "2026-01-14T16:26:53.826158"}}
{"event_type": "price_change", "event_ts": "2026-01-14T16:26:53.826158", "ingestion_ts": "2026-01-14T16:33:58.842229", "market_id": "0x2393ed0b0fdc450054c7b9071907eca75cf4fc36e385adf4a0a5f99ee62243e8", "raw": {"market": "0x2393ed0b0fdc450054c7b9071907eca75cf4fc36e385adf4a0a5f99ee62243e8", "asset_id": "100074770378634056601572485653252702850363676459996771990439989989293515601975", "price": "0.054", "size": "99.99", "side": "SELL", "timestamp": "1768404414161", "received_at": "2026-01-14T16:26:53.826158"}}
{"event_type": "price_change", "event_ts": "2026-01-14T16:26:53.826218", "ingestion_ts": "2026-01-14T16:33:58.842229", "market_id": "0x2393ed0b0fdc450054c7b9071907eca75cf4fc36e385adf4a0a5f99ee62243e8", "raw": {"market": "0x2393ed0b0fdc450054c7b9071907eca75cf4fc36e385adf4a0a5f99ee62243e8", "asset_id": "100074770378634056601572485653252702850363676459996771990439989989293515601975", "price": "0.047", "size": "0", "side": "BUY", "timestamp": "1768404414162", "received_at": "2026-01-14T16:26:53.826218"}}
{"event_type": "price_change", "event_ts": "2026-01-14T16:26:53.826218", "ingestion_ts": "2026-01-14T16:33:58.842229", "market_id": "0x2393ed0b0fdc450054c7b9071907eca75cf4fc36e385adf4a0a5f99ee62243e8", "raw": {"market": "0x2393ed0b0fdc450054c7b9071907eca75cf4fc36e385adf4a0a5f99ee62243e8", "asset_id": "32769749367306925959219403371425714180265458150646381231272229429098460625924", "price": "0.953", "size": "0", "side": "SELL", "timestamp": "1768404414162", "received_at": "2026-01-14T16:26:53.826218"}}
{"event_type": "price_change", "event_ts": "2026-01-14T16:26:55.104766", "ingestion_ts": "2026-01-14T16:33:58.842229", "market_id": "0xe9c127a8c35f045d37b5344b0a36711084fa20c2fc1618bf178a5386f90610be", "raw": {"market": "0xe9c127a8c35f045d37b5344b0a36711084fa20c2fc1618bf178a5386f90610be", "asset_id": "107000426448217931795450451304515386602910396776318075817601265223856116134349", "price": "0.997", "size": "0", "side": "SELL", "timestamp": "1768404415439", "received_at": "2026-01-14T16:26:55.104766"}}
{"event_type": "price_change", "event_ts": "2026-01-14T16:26:55.104766", "ingestion_ts": "2026-01-14T16:33:58.842229", "market_id": "0xe9c127a8c35f045d37b5344b0a36711084fa20c2fc1618bf178a5386f90610be", "raw": {"market": "0xe9c127a8c35f045d37b5344b0a36711084fa20c2fc1618bf178a5386f90610be", "asset_id": "80230236018433940569996058935444651347308266584430516013229815570706872276819", "price": "0.003", "size": "0", "side": "BUY", "timestamp": "1768404415439", "received_at": "2026-01-14T16:26:55.104766"}}
{"event_type": "price_change", "event_ts": "2026-01-14T16:26:55.131417", "ingestion_ts": "2026-01-14T16:33:58.842229", "market_id": "0xe9c127a8c35f045d37b5344b0a36711084fa20c2fc1618bf178a5386f90610be", "raw": {"market": "0xe9c127a8c35f045d37b5344b0a36711084fa20c2fc1618bf178a5386f90610be", "asset_id": "107000426448217931795450451304515386602910396776318075817601265223856116134349", "price": "0.997", "size": "251", "side": "SELL", "timestamp": "1768404415467", "received_at": "2026-01-14T16:26:55.131417"}}
{"event_type": "price_change", "event_ts": "2026-01-14T16:26:55.131417", "ingestion_ts": "2026-01-14T16:33:58.842229", "market_id": "0xe9c127a8c35f045d37b5344b0a36711084fa20c2fc1618bf178a5386f90610be", "raw": {"market": "0xe9c127a8c35f045d37b5344b0a36711084fa20c2fc1618bf178a5386f90610be", "asset_id": "80230236018433940569996058935444651347308266584430516013229815570706872276819", "price": "0.003", "size": "251", "side": "BUY", "timestamp": "1768404415467", "received_at": "2026-01-14T16:26:55.131417"}}
{"event_type": "price_change", "event_ts": "2026-01-14T16:26:56.611352", "ingestion_ts": "2026-01-14T16:33:58.842229", "market_id": "0xe9c127a8c35f045d37b5344b0a36711084fa20c2fc1618bf178a5386f90610be", "raw": {"market": "0xe9c127a8c35f045d37b5344b0a36711084fa20c2fc1618bf178a5386f90610be", "asset_id": "107000426448217931795450451304515386602910396776318075817601265223856116134349", "price": "0.997", "size": "0", "side": "SELL", "timestamp": "1768404416943", "received_at": "2026-01-14T16:26:56.611352"}}
{"event_type": "price_change", "event_ts": "2026-01-14T16:26:56.611352", "ingestion_ts": "2026-01-14T16:33:58.842229", "market_id": "0xe9c127a8c35f045d37b5344b0a36711084fa20c2fc1618bf178a5386f90610be", "raw": {"market": "0xe9c127a8c35f045d37b5344b0a36711084fa20c2fc1618bf178a5386f90610be", "asset_id": "80230236018433940569996058935444651347308266584430516013229815570706872276819", "price": "0.003", "size": "0", "side": "BUY", "timestamp": "1768404416943", "received_at": "2026-01-14T16:26:56.611352"}}
{"event_type": "price_change", "event_ts": "2026-01-14T16:26:56.642772", "ingestion_ts": "2026-01-14T16:33:58.842229", "market_id": "0xe9c127a8c35f045d37b5344b0a36711084fa20c2fc1618bf178a5386f90610be", "raw": {"market": "0xe9c127a8c35f045d37b5344b0a36711084fa20c2fc1618bf178a5386f90610be", "asset_id": "107000426448217931795450451304515386602910396776318075817601265223856116134349", "price": "0.997", "size": "251", "side": "SELL", "timestamp": "1768404416973", "received_at": "2026-01-14T16:26:56.642772"}}
{"event_type": "price_change", "event_ts": "2026-01-14T16:26:56.642772", "ingestion_ts": "2026-01-14T16:33:58.842229", "market_id": "0xe9c127a8c35f045d37b5344b0a36711084fa20c2fc1618bf178a5386f90610be", "raw": {"market": "0xe9c127a8c35f045d37b5344b0a36711084fa20c2fc1618bf178a5386f90610be", "asset_id": "80230236018433940569996058935444651347308266584430516013229815570706872276819", "price": "0.003", "size": "251", "side": "BUY", "timestamp": "1768404416973", "received_at": "2026-01-14T16:26:56.642772"}}
{"event_type": "price_change", "event_ts": "2026-01-14T16:26:58.189249", "ingestion_ts": "2026-01-14T16:33:58.842229", "market_id": "0xe9c127a8c35f045d37b5344b0a36711084fa20c2fc1618bf178a5386f90610be", "raw": {"market": "0xe9c127a8c35f045d37b5344b0a36711084fa20c2fc1618bf178a5386f90610be", "asset_id": "107000426448217931795450451304515386602910396776318075817601265223856116134349", "price": "0.997", "size": "0", "side": "SELL", "timestamp": "1768404418445", "received_at": "2026-01-14T16:26:58.189249"}}
{"event_type": "price_change", "event_ts": "2026-01-14T16:26:58.189249", "ingestion_ts": "2026-01-14T16:33:58.842229", "market_id": "0xe9c127a8c35f045d37b5344b0a36711084fa20c2fc1618bf178a5386f90610be", "raw": {"market": "0xe9c127a8c35f045d37b5344b0a36711084fa20c2fc1618bf178a5386f90610be", "asset_id": "80230236018433940569996058935444651347308266584430516013229815570706872276819", "price": "0.003", "size": "0", "side": "BUY", "timestamp": "1768404418445", "received_at": "2026-01-14T16:26:58.189249"}}
{"event_type": "price_change", "event_ts": "2026-01-14T16:26:58.318385", "ingestion_ts": "2026-01-14T16:33:58.842229", "market_id": "0xe9c127a8c35f045d37b5344b0a36711084fa20c2fc1618bf178a5386f90610be", "raw": {"market": "0xe9c127a8c35f045d37b5344b0a36711084fa20c2fc1618bf178a5386f90610be", "asset_id": "107000426448217931795450451304515386602910396776318075817601265223856116134349", "price": "0.997", "size": "251", "side": "SELL", "timestamp": "1768404418508", "received_at": "2026-01-14T16:26:58.318385"}}
{"event_type": "price_change", "event_ts": "2026-01-14T16:26:58.318385", "ingestion_ts": "2026-01-14T16:33:58.842229", "market_id": "0xe9c127a8c35f045d37b5344b0a36711084fa20c2fc1618bf178a5386f90610be", "raw": {"market": "0xe9c127a8c35f045d37b5344b0a36711084fa20c2fc1618bf178a5386f90610be", "asset_id": "80230236018433940569996058935444651347308266584430516013229815570706872276819", "price": "0.003", "size": "251", "side": "BUY", "timestamp": "1768404418508", "received_at": "2026-01-14T16:26:58.318385"}}
{"event_type": "price_change", "event_ts": "2026-01-14T16:26:59.617349", "ingestion_ts": "2026-01-14T16:33:58.842229", "market_id": "0xe9c127a8c35f045d37b5344b0a36711084fa20c2fc1618bf178a5386f90610be", "raw": {"market": "0xe9c127a8c35f045d37b5344b0a36711084fa20c2fc1618bf178a5386f90610be", "asset_id": "107000426448217931795450451304515386602910396776318075817601265223856116134349", "price": "0.997", "size": "0", "side": "SELL", "timestamp": "1768404419940", "received_at": "2026-01-14T16:26:59.617349"}}
{"event_type": "price_change", "event_ts": "2026-01-14T16:26:59.617349", "ingestion_ts": "2026-01-14T16:33:58.842229", "market_id": "0xe9c127a8c35f045d37b5344b0a36711084fa20c2fc1618bf178a5386f90610be", "raw": {"market": "0xe9c127a8c35f045d37b5344b0a36711084fa20c2fc1618bf178a5386f90610be", "asset_id": "80230236018433940569996058935444651347308266584430516013229815570706872276819", "price": "0.003", "size": "0", "side": "BUY", "timestamp": "1768404419940", "received_at": "2026-01-14T16:26:59.617349"}}
{"event_type": "price_change", "event_ts": "2026-01-14T16:26:59.645617", "ingestion_ts": "2026-01-14T16:33:58.842229", "market_id": "0xe9c127a8c35f045d37b5344b0a36711084fa20c2fc1618bf178a5386f90610be", "raw": {"market": "0xe9c127a8c35f045d37b5344b0a36711084fa20c2fc1618bf178a5386f90610be", "asset_id": "107000426448217931795450451304515386602910396776318075817601265223856116134349", "price": "0.997", "size": "251", "side": "SELL", "timestamp": "1768404419967", "received_at": "2026-01-14T16:26:59.645617"}}
{"event_type": "price_change", "event_ts": "2026-01-14T16:26:59.645617", "ingestion_ts": "2026-01-14T16:33:58.842229", "market_id": "0xe9c127a8c35f045d37b5344b0a36711084fa20c2fc1618bf178a5386f90610be", "raw": {"market": "0xe9c127a8c35f045d37b5344b0a36711084fa20c2fc1618bf178a5386f90610be", "asset_id": "80230236018433940569996058935444651347308266584430516013229815570706872276819", "price": "0.003", "size": "251", "side": "BUY", "timestamp": "1768404419967", "received_at": "2026-01-14T16:26:59.645617"}}
{"event_type": "price_change", "event_ts": "2026-01-14T16:27:00.164626", "ingestion_ts": "2026-01-14T16:33:58.842229", "market_id": "0x2393ed0b0fdc450054c7b9071907eca75cf4fc36e385adf4a0a5f99ee62243e8", "raw": {"market": "0x2393ed0b0fdc450054c7b9071907eca75cf4fc36e385adf4a0a5f99ee62243e8", "asset_id": "32769749367306925959219403371425714180265458150646381231272229429098460625924", "price": "0.946", "size": "205.69", "side": "BUY", "timestamp": "1768404420476", "received_at": "2026-01-14T16:27:00.164626"}}
{"event_type": "price_change", "event_ts": "2026-01-14T16:27:00.164626", "ingestion_ts": "2026-01-14T16:33:58.842229", "market_id": "0x2393ed0b0fdc450054c7b9071907eca75cf4fc36e385adf4a0a5f99ee62243e8", "raw": {"market": "0x2393ed0b0fdc450054c7b9071907eca75cf4fc36e385adf4a0a5f99ee62243e8", "asset_id": "100074770378634056601572485653252702850363676459996771990439989989293515601975", "price": "0.054", "size": "205.69", "side": "SELL", "timestamp": "1768404420476", "received_at": "2026-01-14T16:27:00.164626"}}
{"event_type": "price_change", "event_ts": "2026-01-14T16:27:00.164689", "ingestion_ts": "2026-01-14T16:33:58.842229", "market_id": "0x2393ed0b0fdc450054c7b9071907eca75cf4fc36e385adf4a0a5f99ee62243e8", "raw": {"market": "0x2393ed0b0fdc450054c7b9071907eca75cf4fc36e385adf4a0a5f99ee62243e8", "asset_id": "100074770378634056601572485653252702850363676459996771990439989989293515601975", "price": "0.047", "size": "103", "side": "BUY", "timestamp": "1768404420477", "received_at": "2026-01-14T16:27:00.164689"}}
{"event_type": "price_change", "event_ts": "2026-01-14T16:27:00.164689", "ingestion_ts": "2026-01-14T16:33:58.842229", "market_id": "0x2393ed0b0fdc450054c7b9071907eca75cf4fc36e385adf4a0a5f99ee62243e8", "raw": {"market": "0x2393ed0b0fdc450054c7b9071907eca75cf4fc36e385adf4a0a5f99ee62243e8", "asset_id": "32769749367306925959219403371425714180265458150646381231272229429098460625924", "price": "0.953", "size": "103", "side": "SELL", "timestamp": "1768404420477", "received_at": "2026-01-14T16:27:00.164689"}}
{"event_type": "price_change", "event_ts": "2026-01-14T16:27:01.128603", "ingestion_ts": "2026-01-14T16:33:58.842229", "market_id": "0xe9c127a8c35f045d37b5344b0a36711084fa20c2fc1618bf178a5386f90610be", "raw": {"market": "0xe9c127a8c35f045d37b5344b0a36711084fa20c2fc1618bf178a5386f90610be", "asset_id": "107000426448217931795450451304515386602910396776318075817601265223856116134349", "price": "0.997", "size": "0", "side": "SELL", "timestamp": "1768404421441", "received_at": "2026-01-14T16:27:01.128603"}}
{"event_type": "price_change", "event_ts": "2026-01-14T16:27:01.128603", "ingestion_ts": "2026-01-14T16:33:58.842229", "market_id": "0xe9c127a8c35f045d37b5344b0a36711084fa20c2fc1618bf178a5386f90610be", "raw": {"market": "0xe9c127a8c35f045d37b5344b0a36711084fa20c2fc1618bf178a5386f90610be", "asset_id": "80230236018433940569996058935444651347308266584430516013229815570706872276819", "price": "0.003", "size": "0", "side": "BUY", "timestamp": "1768404421441", "received_at": "2026-01-14T16:27:01.128603"}}
{"event_type": "price_change", "event_ts": "2026-01-14T16:27:01.148229", "ingestion_ts": "2026-01-14T16:33:58.842229", "market_id": "0xe9c127a8c35f045d37b5344b0a36711084fa20c2fc1618bf178a5386f90610be", "raw": {"market": "0xe9c127a8c35f045d37b5344b0a36711084fa20c2fc1618bf178a5386f90610be", "asset_id": "107000426448217931795450451304515386602910396776318075817601265223856116134349", "price": "0.997", "size": "251", "side": "SELL", "timestamp": "1768404421467", "received_at": "2026-01-14T16:27:01.148229"}}
{"event_type": "price_change", "event_ts": "2026-01-14T16:27:01.148229", "ingestion_ts": "2026-01-14T16:33:58.842229", "market_id": "0xe9c127a8c35f045d37b5344b0a36711084fa20c2fc1618bf178a5386f90610be", "raw": {"market": "0xe9c127a8c35f045d37b5344b0a36711084fa20c2fc1618bf178a5386f90610be", "asset_id": "80230236018433940569996058935444651347308266584430516013229815570706872276819", "price": "0.003", "size": "251", "side": "BUY", "timestamp": "1768404421467", "received_at": "2026-01-14T16:27:01.148229"}}
{"event_type": "price_change", "event_ts": "2026-01-14T16:27:02.609131", "ingestion_ts": "2026-01-14T16:33:58.842229", "market_id": "0xe9c127a8c35f045d37b5344b0a36711084fa20c2fc1618bf178a5386f90610be", "raw": {"market": "0xe9c127a8c35f045d37b5344b0a36711084fa20c2fc1618bf178a5386f90610be", "asset_id": "107000426448217931795450451304515386602910396776318075817601265223856116134349", "price": "0.997", "size": "0", "side": "SELL", "timestamp": "1768404422945", "received_at": "2026-01-14T16:27:02.609131"}}
{"event_type": "price_change", "event_ts": "2026-01-14T16:27:02.609131", "ingestion_ts": "2026-01-14T16:33:58.842229", "market_id": "0xe9c127a8c35f045d37b5344b0a36711084fa20c2fc1618bf178a5386f90610be", "raw": {"market": "0xe9c127a8c35f045d37b5344b0a36711084fa20c2fc1618bf178a5386f90610be", "asset_id": "80230236018433940569996058935444651347308266584430516013229815570706872276819", "price": "0.003", "size": "0", "side": "BUY", "timestamp": "1768404422945", "received_at": "2026-01-14T16:27:02.609131"}}
{"event_type": "price_change", "event_ts": "2026-01-14T16:27:02.651568", "ingestion_ts": "2026-01-14T16:33:58.842229", "market_id": "0xe9c127a8c35f045d37b5344b0a36711084fa20c2fc1618bf178a5386f90610be", "raw": {"market": "0xe9c127a8c35f045d37b5344b0a36711084fa20c2fc1618bf178a5386f90610be", "asset_id": "107000426448217931795450451304515386602910396776318075817601265223856116134349", "price": "0.997", "size": "251", "side": "SELL", "timestamp": "1768404422974", "received_at": "2026-01-14T16:27:02.651568"}}
{"event_type": "price_change", "event_ts": "2026-01-14T16:27:02.651568", "ingestion_ts": "2026-01-14T16:33:58.842229", "market_id": "0xe9c127a8c35f045d37b5344b0a36711084fa20c2fc1618bf178a5386f90610be", "raw": {"market": "0xe9c127a8c35f045d37b5344b0a36711084fa20c2fc1618bf178a5386f90610be", "asset_id": "80230236018433940569996058935444651347308266584430516013229815570706872276819", "price": "0.003", "size": "251", "side": "BUY", "timestamp": "1768404422974", "received_at": "2026-01-14T16:27:02.651568"}}
{"event_type": "price_change", "event_ts": "2026-01-14T16:27:04.123228", "ingestion_ts": "2026-01-14T16:33:58.842229", "market_id": "0xe9c127a8c35f045d37b5344b0a36711084fa20c2fc1618bf178a5386f90610be", "raw": {"market": "0xe9c127a8c35f045d37b5344b0a36711084fa20c2fc1618bf178a5386f90610be", "asset_id": "107000426448217931795450451304515386602910396776318075817601265223856116134349", "price": "0.997", "size": "0", "side": "SELL", "timestamp": "1768404424439", "received_at": "2026-01-14T16:27:04.123228"}}
{"event_type": "price_change", "event_ts": "2026-01-14T16:27:04.123228", "ingestion_ts": "2026-01-14T16:33:58.842229", "market_id": "0xe9c127a8c35f045d37b5344b0a36711084fa20c2fc1618bf178a5386f90610be", "raw": {"market": "0xe9c127a8c35f045d37b5344b0a36711084fa20c2fc1618bf178a5386f90610be", "asset_id": "80230236018433940569996058935444651347308266584430516013229815570706872276819", "price": "0.003", "size": "0", "side": "BUY", "timestamp": "1768404424439", "received_at": "2026-01-14T16:27:04.123228"}}
{"event_type": "price_change", "event_ts": "2026-01-14T16:27:04.136938", "ingestion_ts": "2026-01-14T16:33:58.842229", "market_id": "0xe9c127a8c35f045d37b5344b0a36711084fa20c2fc1618bf178a5386f90610be", "raw": {"market": "0xe9c127a8c35f045d37b5344b0a36711084fa20c2fc1618bf178a5386f90610be", "asset_id": "107000426448217931795450451304515386602910396776318075817601265223856116134349", "price": "0.997", "size": "251", "side": "SELL", "timestamp": "1768404424469", "received_at": "2026-01-14T16:27:04.136938"}}
{"event_type": "price_change", "event_ts": "2026-01-14T16:27:04.136938", "ingestion_ts": "2026-01-14T16:33:58.842229", "market_id": "0xe9c127a8c35f045d37b5344b0a36711084fa20c2fc1618bf178a5386f90610be", "raw": {"market": "0xe9c127a8c35f045d37b5344b0a36711084fa20c2fc1618bf178a5386f90610be", "asset_id": "80230236018433940569996058935444651347308266584430516013229815570706872276819", "price": "0.003", "size": "251", "side": "BUY", "timestamp": "1768404424469", "received_at": "2026-01-14T16:27:04.136938"}}
{"event_type": "price_change", "event_ts": "2026-01-14T16:27:05.621517", "ingestion_ts": "2026-01-14T16:33:58.842229", "market_id": "0xe9c127a8c35f045d37b5344b0a36711084fa20c2fc1618bf178a5386f90610be", "raw": {"market": "0xe9c127a8c35f045d37b5344b0a36711084fa20c2fc1618bf178a5386f90610be", "asset_id": "107000426448217931795450451304515386602910396776318075817601265223856116134349", "price": "0.997", "size": "0", "side": "SELL", "timestamp": "1768404425941", "received_at": "2026-01-14T16:27:05.621517"}}
{"event_type": "price_change", "event_ts": "2026-01-14T16:27:05.621517", "ingestion_ts": "2026-01-14T16:33:58.842229", "market_id": "0xe9c127a8c35f045d37b5344b0a36711084fa20c2fc1618bf178a5386f90610be", "raw": {"market": "0xe9c127a8c35f045d37b5344b0a36711084fa20c2fc1618bf178a5386f90610be", "asset_id": "80230236018433940569996058935444651347308266584430516013229815570706872276819", "price": "0.003", "size": "0", "side": "BUY", "timestamp": "1768404425941", "received_at": "2026-01-14T16:27:05.621517"}}
{"event_type": "price_change", "event_ts": "2026-01-14T16:27:05.638638", "ingestion_ts": "2026-01-14T16:33:58.842229", "market_id": "0xe9c127a8c35f045d37b5344b0a36711084fa20c2fc1618bf178a5386f90610be", "raw": {"market": "0xe9c127a8c35f045d37b5344b0a36711084fa20c2fc1618bf178a5386f90610be", "asset_id": "107000426448217931795450451304515386602910396776318075817601265223856116134349", "price": "0.997", "size": "251", "side": "SELL", "timestamp": "1768404425972", "received_at": "2026-01-14T16:27:05.638638"}}
{"event_type": "price_change", "event_ts": "2026-01-14T16:27:05.638638", "ingestion_ts": "2026-01-14T16:33:58.842229", "market_id": "0xe9c127a8c35f045d37b5344b0a36711084fa20c2fc1618bf178a5386f90610be", "raw": {"market": "0xe9c127a8c35f045d37b5344b0a36711084fa20c2fc1618bf178a5386f90610be", "asset_id": "80230236018433940569996058935444651347308266584430516013229815570706872276819", "price": "0.003", "size": "251", "side": "BUY", "timestamp": "1768404425972", "received_at": "2026-01-14T16:27:05.638638"}}
{"event_type": "price_change", "event_ts": "2026-01-14T16:27:07.103820", "ingestion_ts": "2026-01-14T16:33:58.842229", "market_id": "0xe9c127a8c35f045d37b5344b0a36711084fa20c2fc1618bf178a5386f90610be", "raw": {"market": "0xe9c127a8c35f045d37b5344b0a36711084fa20c2fc1618bf178a5386f90610be", "asset_id": "107000426448217931795450451304515386602910396776318075817601265223856116134349", "price": "0.997", "size": "0", "side": "SELL", "timestamp": "1768404427438", "received_at": "2026-01-14T16:27:07.103820"}}
{"event_type": "price_change", "event_ts": "2026-01-14T16:27:07.103820", "ingestion_ts": "2026-01-14T16:33:58.842229", "market_id": "0xe9c127a8c35f045d37b5344b0a36711084fa20c2fc1618bf178a5386f90610be", "raw": {"market": "0xe9c127a8c35f045d37b5344b0a36711084fa20c2fc1618bf178a5386f90610be", "asset_id": "80230236018433940569996058935444651347308266584430516013229815570706872276819", "price": "0.003", "size": "0", "side": "BUY", "timestamp": "1768404427438", "received_at": "2026-01-14T16:27:07.103820"}}
{"event_type": "price_change", "event_ts": "2026-01-14T16:27:07.143220", "ingestion_ts": "2026-01-14T16:33:58.842229", "market_id": "0xe9c127a8c35f045d37b5344b0a36711084fa20c2fc1618bf178a5386f90610be", "raw": {"market": "0xe9c127a8c35f045d37b5344b0a36711084fa20c2fc1618bf178a5386f90610be", "asset_id": "107000426448217931795450451304515386602910396776318075817601265223856116134349", "price": "0.997", "size": "251", "side": "SELL", "timestamp": "1768404427469", "received_at": "2026-01-14T16:27:07.143220"}}
{"event_type": "price_change", "event_ts": "2026-01-14T16:27:07.143220", "ingestion_ts": "2026-01-14T16:33:58.842229", "market_id": "0xe9c127a8c35f045d37b5344b0a36711084fa20c2fc1618bf178a5386f90610be", "raw": {"market": "0xe9c127a8c35f045d37b5344b0a36711084fa20c2fc1618bf178a5386f90610be", "asset_id": "80230236018433940569996058935444651347308266584430516013229815570706872276819", "price": "0.003", "size": "251", "side": "BUY", "timestamp": "1768404427469", "received_at": "2026-01-14T16:27:07.143220"}}
{"event_type": "price_change", "event_ts": "2026-01-14T16:27:08.602100", "ingestion_ts": "2026-01-14T16:33:58.842229", "market_id": "0xe9c127a8c35f045d37b5344b0a36711084fa20c2fc1618bf178a5386f90610be", "raw": {"market": "0xe9c127a8c35f045d37b5344b0a36711084fa20c2fc1618bf178a5386f90610be", "asset_id": "107000426448217931795450451304515386602910396776318075817601265223856116134349", "price": "0.997", "size": "0", "side": "SELL", "timestamp": "1768404428938", "received_at": "2026-01-14T16:27:08.602100"}}
{"event_type": "price_change", "event_ts": "2026-01-14T16:27:08.602100", "ingestion_ts": "2026-01-14T16:33:58.842229", "market_id": "0xe9c127a8c35f045d37b5344b0a36711084fa20c2fc1618bf178a5386f90610be", "raw": {"market": "0xe9c127a8c35f045d37b5344b0a36711084fa20c2fc1618bf178a5386f90610be", "asset_id": "80230236018433940569996058935444651347308266584430516013229815570706872276819", "price": "0.003", "size": "0", "side": "BUY", "timestamp": "1768404428938", "received_at": "2026-01-14T16:27:08.602100"}}
{"event_type": "price_change", "event_ts": "2026-01-14T16:27:08.650266", "ingestion_ts": "2026-01-14T16:33:58.842229", "market_id": "0xe9c127a8c35f045d37b5344b0a36711084fa20c2fc1618bf178a5386f90610be", "raw": {"market": "0xe9c127a8c35f045d37b5344b0a36711084fa20c2fc1618bf178a5386f90610be", "asset_id": "107000426448217931795450451304515386602910396776318075817601265223856116134349", "price": "0.997", "size": "251", "side": "SELL", "timestamp": "1768404428964", "received_at": "2026-01-14T16:27:08.650266"}}
{"event_type": "price_change", "event_ts": "2026-01-14T16:27:08.650266", "ingestion_ts": "2026-01-14T16:33:58.842229", "market_id": "0xe9c127a8c35f045d37b5344b0a36711084fa20c2fc1618bf178a5386f90610be", "raw": {"market": "0xe9c127a8c35f045d37b5344b0a36711084fa20c2fc1618bf178a5386f90610be", "asset_id": "80230236018433940569996058935444651347308266584430516013229815570706872276819", "price": "0.003", "size": "251", "side": "BUY", "timestamp": "1768404428964", "received_at": "2026-01-14T16:27:08.650266"}}
{"event_type": "price_change", "event_ts": "2026-01-14T16:27:09.727338", "ingestion_ts": "2026-01-14T16:33:58.842229", "market_id": "0xe68594f1350f5535532b24979b5b5c1948432cbfc0c363802c32a8f9ab4e6509", "raw": {"market": "0xe68594f1350f5535532b24979b5b5c1948432cbfc0c363802c32a8f9ab4e6509", "asset_id": "3074032031589250926591186368301243337494992039402397918135503567058257050088", "price": "0.937", "size": "54.66", "side": "BUY", "timestamp": "1768404429826", "received_at": "2026-01-14T16:27:09.727338"}}
{"event_type": "price_change", "event_ts": "2026-01-14T16:27:09.727338", "ingestion_ts": "2026-01-14T16:33:58.842229", "market_id": "0xe68594f1350f5535532b24979b5b5c1948432cbfc0c363802c32a8f9ab4e6509", "raw": {"market": "0xe68594f1350f5535532b24979b5b5c1948432cbfc0c363802c32a8f9ab4e6509", "asset_id": "47459180813047899567328389455747872955901265556145057896316155826890276004242", "price": "0.063", "size": "54.66", "side": "SELL", "timestamp": "1768404429826", "received_at": "2026-01-14T16:27:09.727338"}}
{"event_type": "price_change", "event_ts": "2026-01-14T16:27:10.362869", "ingestion_ts": "2026-01-14T16:33:58.842229", "market_id": "0xe9c127a8c35f045d37b5344b0a36711084fa20c2fc1618bf178a5386f90610be", "raw": {"market": "0xe9c127a8c35f045d37b5344b0a36711084fa20c2fc1618bf178a5386f90610be", "asset_id": "107000426448217931795450451304515386602910396776318075817601265223856116134349", "price": "0.997", "size": "0", "side": "SELL", "timestamp": "1768404430439", "received_at": "2026-01-14T16:27:10.362869"}}
{"event_type": "price_change", "event_ts": "2026-01-14T16:27:10.362869", "ingestion_ts": "2026-01-14T16:33:58.842229", "market_id": "0xe9c127a8c35f045d37b5344b0a36711084fa20c2fc1618bf178a5386f90610be", "raw": {"market": "0xe9c127a8c35f045d37b5344b0a36711084fa20c2fc1618bf178a5386f90610be", "asset_id": "80230236018433940569996058935444651347308266584430516013229815570706872276819", "price": "0.003", "size": "0", "side": "BUY", "timestamp": "1768404430439", "received_at": "2026-01-14T16:27:10.362869"}}
{"event_type": "price_change", "event_ts": "2026-01-14T16:27:10.399364", "ingestion_ts": "2026-01-14T16:33:58.842229", "market_id": "0xe9c127a8c35f045d37b5344b0a36711084fa20c2fc1618bf178a5386f90610be", "raw": {"market": "0xe9c127a8c35f045d37b5344b0a36711084fa20c2fc1618bf178a5386f90610be", "asset_id": "107000426448217931795450451304515386602910396776318075817601265223856116134349", "price": "0.997", "size": "251", "side": "SELL", "timestamp": "1768404430481", "received_at": "2026-01-14T16:27:10.399364"}}
{"event_type": "price_change", "event_ts": "2026-01-14T16:27:10.399364", "ingestion_ts": "2026-01-14T16:33:58.842229", "market_id": "0xe9c127a8c35f045d37b5344b0a36711084fa20c2fc1618bf178a5386f90610be", "raw": {"market": "0xe9c127a8c35f045d37b5344b0a36711084fa20c2fc1618bf178a5386f90610be", "asset_id": "80230236018433940569996058935444651347308266584430516013229815570706872276819", "price": "0.003", "size": "251", "side": "BUY", "timestamp": "1768404430481", "received_at": "2026-01-14T16:27:10.399364"}}
{"event_type": "price_change", "event_ts": "2026-01-14T16:27:11.631997", "ingestion_ts": "2026-01-14T16:33:58.842229", "market_id": "0xe9c127a8c35f045d37b5344b0a36711084fa20c2fc1618bf178a5386f90610be", "raw": {"market": "0xe9c127a8c35f045d37b5344b0a36711084fa20c2fc1618bf178a5386f90610be", "asset_id": "107000426448217931795450451304515386602910396776318075817601265223856116134349", "price": "0.997", "size": "0", "side": "SELL", "timestamp": "1768404431938", "received_at": "2026-01-14T16:27:11.631997"}}
{"event_type": "price_change", "event_ts": "2026-01-14T16:27:11.631997", "ingestion_ts": "2026-01-14T16:33:58.842229", "market_id": "0xe9c127a8c35f045d37b5344b0a36711084fa20c2fc1618bf178a5386f90610be", "raw": {"market": "0xe9c127a8c35f045d37b5344b0a36711084fa20c2fc1618bf178a5386f90610be", "asset_id": "80230236018433940569996058935444651347308266584430516013229815570706872276819", "price": "0.003", "size": "0", "side": "BUY", "timestamp": "1768404431938", "received_at": "2026-01-14T16:27:11.631997"}}
{"event_type": "price_change", "event_ts": "2026-01-14T16:27:11.658495", "ingestion_ts": "2026-01-14T16:33:58.842229", "market_id": "0xe9c127a8c35f045d37b5344b0a36711084fa20c2fc1618bf178a5386f90610be", "raw": {"market": "0xe9c127a8c35f045d37b5344b0a36711084fa20c2fc1618bf178a5386f90610be", "asset_id": "107000426448217931795450451304515386602910396776318075817601265223856116134349", "price": "0.997", "size": "251", "side": "SELL", "timestamp": "1768404431982", "received_at": "2026-01-14T16:27:11.658495"}}
{"event_type": "price_change", "event_ts": "2026-01-14T16:27:11.658495", "ingestion_ts": "2026-01-14T16:33:58.842229", "market_id": "0xe9c127a8c35f045d37b5344b0a36711084fa20c2fc1618bf178a5386f90610be", "raw": {"market": "0xe9c127a8c35f045d37b5344b0a36711084fa20c2fc1618bf178a5386f90610be", "asset_id": "80230236018433940569996058935444651347308266584430516013229815570706872276819", "price": "0.003", "size": "251", "side": "BUY", "timestamp": "1768404431982", "received_at": "2026-01-14T16:27:11.658495"}}
{"event_type": "price_change", "event_ts": "2026-01-14T16:27:11.714238", "ingestion_ts": "2026-01-14T16:33:58.842229", "market_id": "0x50e477f0b316a3d97d60486479657c63be0763834d0e2e8a30b1b86dc3c1c001", "raw": {"market": "0x50e477f0b316a3d97d60486479657c63be0763834d0e2e8a30b1b86dc3c1c001", "asset_id": "39981134260608444876865205057565852475343967395624370698967311821208058420507", "price": "0.353", "size": "0", "side": "BUY", "timestamp": "1768404432048", "received_at": "2026-01-14T16:27:11.714238"}}
{"event_type": "price_change", "event_ts": "2026-01-14T16:27:11.714238", "ingestion_ts": "2026-01-14T16:33:58.842229", "market_id": "0x50e477f0b316a3d97d60486479657c63be0763834d0e2e8a30b1b86dc3c1c001", "raw": {"market": "0x50e477f0b316a3d97d60486479657c63be0763834d0e2e8a30b1b86dc3c1c001", "asset_id": "60573178197991590327120832143415406583517170365625050489007297367895074266641", "price": "0.647", "size": "0", "side": "SELL", "timestamp": "1768404432048", "received_at": "2026-01-14T16:27:11.714238"}}
{"event_type": "price_change", "event_ts": "2026-01-14T16:27:11.760188", "ingestion_ts": "2026-01-14T16:33:58.842229", "market_id": "0x50e477f0b316a3d97d60486479657c63be0763834d0e2e8a30b1b86dc3c1c001", "raw": {"market": "0x50e477f0b316a3d97d60486479657c63be0763834d0e2e8a30b1b86dc3c1c001", "asset_id": "39981134260608444876865205057565852475343967395624370698967311821208058420507", "price": "0.353", "size": "5", "side": "BUY", "timestamp": "1768404432096", "received_at": "2026-01-14T16:27:11.760188"}}
{"event_type": "price_change", "event_ts": "2026-01-14T16:27:11.760188", "ingestion_ts": "2026-01-14T16:33:58.842229", "market_id": "0x50e477f0b316a3d97d60486479657c63be0763834d0e2e8a30b1b86dc3c1c001", "raw": {"market": "0x50e477f0b316a3d97d60486479657c63be0763834d0e2e8a30b1b86dc3c1c001", "asset_id": "60573178197991590327120832143415406583517170365625050489007297367895074266641", "price": "0.647", "size": "5", "side": "SELL", "timestamp": "1768404432096", "received_at": "2026-01-14T16:27:11.760188"}}
{"event_type": "price_change", "event_ts": "2026-01-14T16:27:11.821810", "ingestion_ts": "2026-01-14T16:33:58.842229", "market_id": "0x50e477f0b316a3d97d60486479657c63be0763834d0e2e8a30b1b86dc3c1c001", "raw": {"market": "0x50e477f0b316a3d97d60486479657c63be0763834d0e2e8a30b1b86dc3c1c001", "asset_id": "39981134260608444876865205057565852475343967395624370698967311821208058420507", "price": "0.986", "size": "911.92", "side": "BUY", "timestamp": "1768404432156", "received_at": "2026-01-14T16:27:11.821810"}}
{"event_type": "price_change", "event_ts": "2026-01-14T16:27:11.821810", "ingestion_ts": "2026-01-14T16:33:58.842229", "market_id": "0x50e477f0b316a3d97d60486479657c63be0763834d0e2e8a30b1b86dc3c1c001", "raw": {"market": "0x50e477f0b316a3d97d60486479657c63be0763834d0e2e8a30b1b86dc3c1c001", "asset_id": "60573178197991590327120832143415406583517170365625050489007297367895074266641", "price": "0.014", "size": "911.92", "side": "SELL", "timestamp": "1768404432156", "received_at": "2026-01-14T16:27:11.821810"}}
{"event_type": "price_change", "event_ts": "2026-01-14T16:27:13.049636", "ingestion_ts": "2026-01-14T16:33:58.842229", "market_id": "0x50e477f0b316a3d97d60486479657c63be0763834d0e2e8a30b1b86dc3c1c001", "raw": {"market": "0x50e477f0b316a3d97d60486479657c63be0763834d0e2e8a30b1b86dc3c1c001", "asset_id": "39981134260608444876865205057565852475343967395624370698967311821208058420507", "price": "0.986", "size": "830.92", "side": "BUY", "timestamp": "1768404433383", "received_at": "2026-01-14T16:27:13.049636"}}
{"event_type": "price_change", "event_ts": "2026-01-14T16:27:13.049636", "ingestion_ts": "2026-01-14T16:33:58.842229", "market_id": "0x50e477f0b316a3d97d60486479657c63be0763834d0e2e8a30b1b86dc3c1c001", "raw": {"market": "0x50e477f0b316a3d97d60486479657c63be0763834d0e2e8a30b1b86dc3c1c001", "asset_id": "60573178197991590327120832143415406583517170365625050489007297367895074266641", "price": "0.014", "size": "830.92", "side": "SELL", "timestamp": "1768404433383", "received_at": "2026-01-14T16:27:13.049636"}}
{"event_type": "price_change", "event_ts": "2026-01-14T16:27:13.081683", "ingestion_ts": "2026-01-14T16:33:58.842229", "market_id": "0x50e477f0b316a3d97d60486479657c63be0763834d0e2e8a30b1b86dc3c1c001", "raw": {"market": "0x50e477f0b316a3d97d60486479657c63be0763834d0e2e8a30b1b86dc3c1c001", "asset_id": "39981134260608444876865205057565852475343967395624370698967311821208058420507", "price": "0.989", "size": "126", "side": "BUY", "timestamp": "1768404433414", "received_at": "2026-01-14T16:27:13.081683"}}
{"event_type": "price_change", "event_ts": "2026-01-14T16:27:13.081683", "ingestion_ts": "2026-01-14T16:33:58.842229", "market_id": "0x50e477f0b316a3d97d60486479657c63be0763834d0e2e8a30b1b86dc3c1c001", "raw": {"market": "0x50e477f0b316a3d97d60486479657c63be0763834d0e2e8a30b1b86dc3c1c001", "asset_id": "60573178197991590327120832143415406583517170365625050489007297367895074266641", "price": "0.011", "size": "126", "side": "SELL", "timestamp": "1768404433414", "received_at": "2026-01-14T16:27:13.081683"}}
{"event_type": "price_change", "event_ts": "2026-01-14T16:27:13.102437", "ingestion_ts": "2026-01-14T16:33:58.842229", "market_id": "0xe9c127a8c35f045d37b5344b0a36711084fa20c2fc1618bf178a5386f90610be", "raw": {"market": "0xe9c127a8c35f045d37b5344b0a36711084fa20c2fc1618bf178a5386f90610be", "asset_id": "107000426448217931795450451304515386602910396776318075817601265223856116134349", "price": "0.997", "size": "0", "side": "SELL", "timestamp": "1768404433438", "received_at": "2026-01-14T16:27:13.102437"}}
{"event_type": "price_change", "event_ts": "2026-01-14T16:27:13.102437", "ingestion_ts": "2026-01-14T16:33:58.842229", "market_id": "0xe9c127a8c35f045d37b5344b0a36711084fa20c2fc1618bf178a5386f90610be", "raw": {"market": "0xe9c127a8c35f045d37b5344b0a36711084fa20c2fc1618bf178a5386f90610be", "asset_id": "80230236018433940569996058935444651347308266584430516013229815570706872276819", "price": "0.003", "size": "0", "side": "BUY", "timestamp": "1768404433438", "received_at": "2026-01-14T16:27:13.102437"}}
{"event_type": "price_change", "event_ts": "2026-01-14T16:27:13.135797", "ingestion_ts": "2026-01-14T16:33:58.842229", "market_id": "0xe9c127a8c35f045d37b5344b0a36711084fa20c2fc1618bf178a5386f90610be", "raw": {"market": "0xe9c127a8c35f045d37b5344b0a36711084fa20c2fc1618bf178a5386f90610be", "asset_id": "107000426448217931795450451304515386602910396776318075817601265223856116134349", "price": "0.997", "size": "251", "side": "SELL", "timestamp": "1768404433471", "received_at": "2026-01-14T16:27:13.135797"}}
{"event_type": "price_change", "event_ts": "2026-01-14T16:27:13.135797", "ingestion_ts": "2026-01-14T16:33:58.842229", "market_id": "0xe9c127a8c35f045d37b5344b0a36711084fa20c2fc1618bf178a5386f90610be", "raw": {"market": "0xe9c127a8c35f045d37b5344b0a36711084fa20c2fc1618bf178a5386f90610be", "asset_id": "80230236018433940569996058935444651347308266584430516013229815570706872276819", "price": "0.003", "size": "251", "side": "BUY", "timestamp": "1768404433471", "received_at": "2026-01-14T16:27:13.135797"}}
{"event_type": "price_change", "event_ts": "2026-01-14T16:27:14.204884", "ingestion_ts": "2026-01-14T16:33:58.842229", "market_id": "0x50e477f0b316a3d97d60486479657c63be0763834d0e2e8a30b1b86dc3c1c001", "raw": {"market": "0x50e477f0b316a3d97d60486479657c63be0763834d0e2e8a30b1b86dc3c1c001", "asset_id": "39981134260608444876865205057565852475343967395624370698967311821208058420507", "price": "0.988", "size": "0", "side": "BUY", "timestamp": "1768404434538", "received_at": "2026-01-14T16:27:14.204884"}}
{"event_type": "price_change", "event_ts": "2026-01-14T16:27:14.204884", "ingestion_ts": "2026-01-14T16:33:58.842229", "market_id": "0x50e477f0b316a3d97d60486479657c63be0763834d0e2e8a30b1b86dc3c1c001", "raw": {"market": "0x50e477f0b316a3d97d60486479657c63be0763834d0e2e8a30b1b86dc3c1c001", "asset_id": "60573178197991590327120832143415406583517170365625050489007297367895074266641", "price": "0.012", "size": "0", "side": "SELL", "timestamp": "1768404434538", "received_at": "2026-01-14T16:27:14.204884"}}
{"event_type": "price_change", "event_ts": "2026-01-14T16:27:14.257781", "ingestion_ts": "2026-01-14T16:33:58.842229", "market_id": "0x50e477f0b316a3d97d60486479657c63be0763834d0e2e8a30b1b86dc3c1c001", "raw": {"market": "0x50e477f0b316a3d97d60486479657c63be0763834d0e2e8a30b1b86dc3c1c001", "asset_id": "39981134260608444876865205057565852475343967395624370698967311821208058420507", "price": "0.989", "size": "156", "side": "BUY", "timestamp": "1768404434593", "received_at": "2026-01-14T16:27:14.257781"}}
{"event_type": "price_change", "event_ts": "2026-01-14T16:27:14.257781", "ingestion_ts": "2026-01-14T16:33:58.842229", "market_id": "0x50e477f0b316a3d97d60486479657c63be0763834d0e2e8a30b1b86dc3c1c001", "raw": {"market": "0x50e477f0b316a3d97d60486479657c63be0763834d0e2e8a30b1b86dc3c1c001", "asset_id": "60573178197991590327120832143415406583517170365625050489007297367895074266641", "price": "0.011", "size": "156", "side": "SELL", "timestamp": "1768404434593", "received_at": "2026-01-14T16:27:14.257781"}}
{"event_type": "price_change", "event_ts": "2026-01-14T16:27:14.624323", "ingestion_ts": "2026-01-14T16:33:58.842229", "market_id": "0xe9c127a8c35f045d37b5344b0a36711084fa20c2fc1618bf178a5386f90610be", "raw": {"market": "0xe9c127a8c35f045d37b5344b0a36711084fa20c2fc1618bf178a5386f90610be", "asset_id": "107000426448217931795450451304515386602910396776318075817601265223856116134349", "price": "0.997", "size": "0", "side": "SELL", "timestamp": "1768404434940", "received_at": "2026-01-14T16:27:14.624323"}}
{"event_type": "price_change", "event_ts": "2026-01-14T16:27:14.624323", "ingestion_ts": "2026-01-14T16:33:58.842229", "market_id": "0xe9c127a8c35f045d37b5344b0a36711084fa20c2fc1618bf178a5386f90610be", "raw": {"market": "0xe9c127a8c35f045d37b5344b0a36711084fa20c2fc1618bf178a5386f90610be", "asset_id": "80230236018433940569996058935444651347308266584430516013229815570706872276819", "price": "0.003", "size": "0", "side": "BUY", "timestamp": "1768404434940", "received_at": "2026-01-14T16:27:14.624323"}}
{"event_type": "price_change", "event_ts": "2026-01-14T16:27:14.661664", "ingestion_ts": "2026-01-14T16:33:58.842229", "market_id": "0xe9c127a8c35f045d37b5344b0a36711084fa20c2fc1618bf178a5386f90610be", "raw": {"market": "0xe9c127a8c35f045d37b5344b0a36711084fa20c2fc1618bf178a5386f90610be", "asset_id": "107000426448217931795450451304515386602910396776318075817601265223856116134349", "price": "0.997", "size": "251", "side": "SELL", "timestamp": "1768404434986", "received_at": "2026-01-14T16:27:14.661664"}}
{"event_type": "price_change", "event_ts": "2026-01-14T16:27:14.661664", "ingestion_ts": "2026-01-14T16:33:58.842229", "market_id": "0xe9c127a8c35f045d37b5344b0a36711084fa20c2fc1618bf178a5386f90610be", "raw": {"market": "0xe9c127a8c35f045d37b5344b0a36711084fa20c2fc1618bf178a5386f90610be", "asset_id": "80230236018433940569996058935444651347308266584430516013229815570706872276819", "price": "0.003", "size": "251", "side": "BUY", "timestamp": "1768404434986", "received_at": "2026-01-14T16:27:14.661664"}}
{"event_type": "price_change", "event_ts": "2026-01-14T16:27:16.115365", "ingestion_ts": "2026-01-14T16:33:58.842229", "market_id": "0xe9c127a8c35f045d37b5344b0a36711084fa20c2fc1618bf178a5386f90610be", "raw": {"market": "0xe9c127a8c35f045d37b5344b0a36711084fa20c2fc1618bf178a5386f90610be", "asset_id": "107000426448217931795450451304515386602910396776318075817601265223856116134349", "price": "0.997", "size": "0", "side": "SELL", "timestamp": "1768404436450", "received_at": "2026-01-14T16:27:16.115365"}}
{"event_type": "price_change", "event_ts": "2026-01-14T16:27:16.115365", "ingestion_ts": "2026-01-14T16:33:58.842229", "market_id": "0xe9c127a8c35f045d37b5344b0a36711084fa20c2fc1618bf178a5386f90610be", "raw": {"market": "0xe9c127a8c35f045d37b5344b0a36711084fa20c2fc1618bf178a5386f90610be", "asset_id": "80230236018433940569996058935444651347308266584430516013229815570706872276819", "price": "0.003", "size": "0", "side": "BUY", "timestamp": "1768404436450", "received_at": "2026-01-14T16:27:16.115365"}}
{"event_type": "price_change", "event_ts": "2026-01-14T16:27:16.146231", "ingestion_ts": "2026-01-14T16:33:58.842229", "market_id": "0xe9c127a8c35f045d37b5344b0a36711084fa20c2fc1618bf178a5386f90610be", "raw": {"market": "0xe9c127a8c35f045d37b5344b0a36711084fa20c2fc1618bf178a5386f90610be", "asset_id": "107000426448217931795450451304515386602910396776318075817601265223856116134349", "price": "0.997", "size": "251", "side": "SELL", "timestamp": "1768404436477", "received_at": "2026-01-14T16:27:16.146231"}}
{"event_type": "price_change", "event_ts": "2026-01-14T16:27:16.146231", "ingestion_ts": "2026-01-14T16:33:58.842229", "market_id": "0xe9c127a8c35f045d37b5344b0a36711084fa20c2fc1618bf178a5386f90610be", "raw": {"market": "0xe9c127a8c35f045d37b5344b0a36711084fa20c2fc1618bf178a5386f90610be", "asset_id": "80230236018433940569996058935444651347308266584430516013229815570706872276819", "price": "0.003", "size": "251", "side": "BUY", "timestamp": "1768404436477", "received_at": "2026-01-14T16:27:16.146231"}}
{"event_type": "price_change", "event_ts": "2026-01-14T16:27:17.601999", "ingestion_ts": "2026-01-14T16:33:58.842229", "market_id": "0xe9c127a8c35f045d37b5344b0a36711084fa20c2fc1618bf178a5386f90610be", "raw": {"market": "0xe9c127a8c35f045d37b5344b0a36711084fa20c2fc1618bf178a5386f90610be", "asset_id": "107000426448217931795450451304515386602910396776318075817601265223856116134349", "price": "0.997", "size": "0", "side": "SELL", "timestamp": "1768404437938", "received_at": "2026-01-14T16:27:17.601999"}}
{"event_type": "price_change", "event_ts": "2026-01-14T16:27:17.601999", "ingestion_ts": "2026-01-14T16:33:58.842229", "market_id": "0xe9c127a8c35f045d37b5344b0a36711084fa20c2fc1618bf178a5386f90610be", "raw": {"market": "0xe9c127a8c35f045d37b5344b0a36711084fa20c2fc1618bf178a5386f90610be", "asset_id": "80230236018433940569996058935444651347308266584430516013229815570706872276819", "price": "0.003", "size": "0", "side": "BUY", "timestamp": "1768404437938", "received_at": "2026-01-14T16:27:17.601999"}}
{"event_type": "price_change", "event_ts": "2026-01-14T16:27:17.633471", "ingestion_ts": "2026-01-14T16:33:58.842229", "market_id": "0xe9c127a8c35f045d37b5344b0a36711084fa20c2fc1618bf178a5386f90610be", "raw": {"market": "0xe9c127a8c35f045d37b5344b0a36711084fa20c2fc1618bf178a5386f90610be", "asset_id": "107000426448217931795450451304515386602910396776318075817601265223856116134349", "price": "0.997", "size": "251", "side": "SELL", "timestamp": "1768404437967", "received_at": "2026-01-14T16:27:17.633471"}}
{"event_type": "price_change", "event_ts": "2026-01-14T16:27:17.633471", "ingestion_ts": "2026-01-14T16:33:58.842229", "market_id": "0xe9c127a8c35f045d37b5344b0a36711084fa20c2fc1618bf178a5386f90610be", "raw": {"market": "0xe9c127a8c35f045d37b5344b0a36711084fa20c2fc1618bf178a5386f90610be", "asset_id": "80230236018433940569996058935444651347308266584430516013229815570706872276819", "price": "0.003", "size": "251", "side": "BUY", "timestamp": "1768404437967", "received_at": "2026-01-14T16:27:17.633471"}}
{"event_type": "price_change", "event_ts": "2026-01-14T16:27:19.105671", "ingestion_ts": "2026-01-14T16:33:58.842229", "market_id": "0xe9c127a8c35f045d37b5344b0a36711084fa20c2fc1618bf178a5386f90610be", "raw": {"market": "0xe9c127a8c35f045d37b5344b0a36711084fa20c2fc1618bf178a5386f90610be", "asset_id": "107000426448217931795450451304515386602910396776318075817601265223856116134349", "price": "0.997", "size": "0", "side": "SELL", "timestamp": "1768404439440", "received_at": "2026-01-14T16:27:19.105671"}}
{"event_type": "price_change", "event_ts": "2026-01-14T16:27:19.105671", "ingestion_ts": "2026-01-14T16:33:58.842229", "market_id": "0xe9c127a8c35f045d37b5344b0a36711084fa20c2fc1618bf178a5386f90610be", "raw": {"market": "0xe9c127a8c35f045d37b5344b0a36711084fa20c2fc1618bf178a5386f90610be", "asset_id": "80230236018433940569996058935444651347308266584430516013229815570706872276819", "price": "0.003", "size": "0", "side": "BUY", "timestamp": "1768404439440", "received_at": "2026-01-14T16:27:19.105671"}}
{"event_type": "price_change", "event_ts": "2026-01-14T16:27:19.133864", "ingestion_ts": "2026-01-14T16:33:58.842229", "market_id": "0xe9c127a8c35f045d37b5344b0a36711084fa20c2fc1618bf178a5386f90610be", "raw": {"market": "0xe9c127a8c35f045d37b5344b0a36711084fa20c2fc1618bf178a5386f90610be", "asset_id": "107000426448217931795450451304515386602910396776318075817601265223856116134349", "price": "0.997", "size": "251", "side": "SELL", "timestamp": "1768404439468", "received_at": "2026-01-14T16:27:19.133864"}}
{"event_type": "price_change", "event_ts": "2026-01-14T16:27:19.133864", "ingestion_ts": "2026-01-14T16:33:58.842229", "market_id": "0xe9c127a8c35f045d37b5344b0a36711084fa20c2fc1618bf178a5386f90610be", "raw": {"market": "0xe9c127a8c35f045d37b5344b0a36711084fa20c2fc1618bf178a5386f90610be", "asset_id": "80230236018433940569996058935444651347308266584430516013229815570706872276819", "price": "0.003", "size": "251", "side": "BUY", "timestamp": "1768404439468", "received_at": "2026-01-14T16:27:19.133864"}}
{"event_type": "price_change", "event_ts": "2026-01-14T16:27:20.605467", "ingestion_ts": "2026-01-14T16:33:58.842229", "market_id": "0xe9c127a8c35f045d37b5344b0a36711084fa20c2fc1618bf178a5386f90610be", "raw": {"market": "0xe9c127a8c35f045d37b5344b0a36711084fa20c2fc1618bf178a5386f90610be", "asset_id": "107000426448217931795450451304515386602910396776318075817601265223856116134349", "price": "0.997", "size": "0", "side": "SELL", "timestamp": "1768404440941", "received_at": "2026-01-14T16:27:20.605467"}}
{"event_type": "price_change", "event_ts": "2026-01-14T16:27:20.605467", "ingestion_ts": "2026-01-14T16:33:58.842229", "market_id": "0xe9c127a8c35f045d37b5344b0a36711084fa20c2fc1618bf178a5386f90610be", "raw": {"market": "0xe9c127a8c35f045d37b5344b0a36711084fa20c2fc1618bf178a5386f90610be", "asset_id": "80230236018433940569996058935444651347308266584430516013229815570706872276819", "price": "0.003", "size": "0", "side": "BUY", "timestamp": "1768404440941", "received_at": "2026-01-14T16:27:20.605467"}}
{"event_type": "price_change", "event_ts": "2026-01-14T16:27:20.639535", "ingestion_ts": "2026-01-14T16:33:58.842229", "market_id": "0xe9c127a8c35f045d37b5344b0a36711084fa20c2fc1618bf178a5386f90610be", "raw": {"market": "0xe9c127a8c35f045d37b5344b0a36711084fa20c2fc1618bf178a5386f90610be", "asset_id": "107000426448217931795450451304515386602910396776318075817601265223856116134349", "price": "0.997", "size": "251", "side": "SELL", "timestamp": "1768404440971", "received_at": "2026-01-14T16:27:20.639535"}}
{"event_type": "price_change", "event_ts": "2026-01-14T16:27:20.639535", "ingestion_ts": "2026-01-14T16:33:58.842229", "market_id": "0xe9c127a8c35f045d37b5344b0a36711084fa20c2fc1618bf178a5386f90610be", "raw": {"market": "0xe9c127a8c35f045d37b5344b0a36711084fa20c2fc1618bf178a5386f90610be", "asset_id": "80230236018433940569996058935444651347308266584430516013229815570706872276819", "price": "0.003", "size": "251", "side": "BUY", "timestamp": "1768404440971", "received_at": "2026-01-14T16:27:20.639535"}}
{"event_type": "price_change", "event_ts": "2026-01-14T16:27:22.248759", "ingestion_ts": "2026-01-14T16:33:58.842229", "market_id": "0xe9c127a8c35f045d37b5344b0a36711084fa20c2fc1618bf178a5386f90610be", "raw": {"market": "0xe9c127a8c35f045d37b5344b0a36711084fa20c2fc1618bf178a5386f90610be", "asset_id": "107000426448217931795450451304515386602910396776318075817601265223856116134349", "price": "0.997", "size": "0", "side": "SELL", "timestamp": "1768404442442", "received_at": "2026-01-14T16:27:22.248759"}}
{"event_type": "price_change", "event_ts": "2026-01-14T16:27:22.248759", "ingestion_ts": "2026-01-14T16:33:58.842229", "market_id": "0xe9c127a8c35f045d37b5344b0a36711084fa20c2fc1618bf178a5386f90610be", "raw": {"market": "0xe9c127a8c35f045d37b5344b0a36711084fa20c2fc1618bf178a5386f90610be", "asset_id": "80230236018433940569996058935444651347308266584430516013229815570706872276819", "price": "0.003", "size": "0", "side": "BUY", "timestamp": "1768404442442", "received_at": "2026-01-14T16:27:22.248759"}}
{"event_type": "price_change", "event_ts": "2026-01-14T16:27:22.407013", "ingestion_ts": "2026-01-14T16:33:58.842229", "market_id": "0xe9c127a8c35f045d37b5344b0a36711084fa20c2fc1618bf178a5386f90610be", "raw": {"market": "0xe9c127a8c35f045d37b5344b0a36711084fa20c2fc1618bf178a5386f90610be", "asset_id": "107000426448217931795450451304515386602910396776318075817601265223856116134349", "price": "0.997", "size": "251", "side": "SELL", "timestamp": "1768404442602", "received_at": "2026-01-14T16:27:22.407013"}}
{"event_type": "price_change", "event_ts": "2026-01-14T16:27:22.407013", "ingestion_ts": "2026-01-14T16:33:58.842229", "market_id": "0xe9c127a8c35f045d37b5344b0a36711084fa20c2fc1618bf178a5386f90610be", "raw": {"market": "0xe9c127a8c35f045d37b5344b0a36711084fa20c2fc1618bf178a5386f90610be", "asset_id": "80230236018433940569996058935444651347308266584430516013229815570706872276819", "price": "0.003", "size": "251", "side": "BUY", "timestamp": "1768404442602", "received_at": "2026-01-14T16:27:22.407013"}}
{"event_type": "price_change", "event_ts": "2026-01-14T16:27:23.637340", "ingestion_ts": "2026-01-14T16:33:58.842229", "market_id": "0xe9c127a8c35f045d37b5344b0a36711084fa20c2fc1618bf178a5386f90610be", "raw": {"market": "0xe9c127a8c35f045d37b5344b0a36711084fa20c2fc1618bf178a5386f90610be", "asset_id": "107000426448217931795450451304515386602910396776318075817601265223856116134349", "price": "0.997", "size": "0", "side": "SELL", "timestamp": "1768404443968", "received_at": "2026-01-14T16:27:23.637340"}}
{"event_type": "price_change", "event_ts": "2026-01-14T16:27:23.637340", "ingestion_ts": "2026-01-14T16:33:58.842229", "market_id": "0xe9c127a8c35f045d37b5344b0a36711084fa20c2fc1618bf178a5386f90610be", "raw": {"market": "0xe9c127a8c35f045d37b5344b0a36711084fa20c2fc1618bf178a5386f90610be", "asset_id": "80230236018433940569996058935444651347308266584430516013229815570706872276819", "price": "0.003", "size": "0", "side": "BUY", "timestamp": "1768404443968", "received_at": "2026-01-14T16:27:23.637340"}}
{"event_type": "price_change", "event_ts": "2026-01-14T16:27:23.670891", "ingestion_ts": "2026-01-14T16:33:58.842229", "market_id": "0xe9c127a8c35f045d37b5344b0a36711084fa20c2fc1618bf178a5386f90610be", "raw": {"market": "0xe9c127a8c35f045d37b5344b0a36711084fa20c2fc1618bf178a5386f90610be", "asset_id": "107000426448217931795450451304515386602910396776318075817601265223856116134349", "price": "0.997", "size": "251", "side": "SELL", "timestamp": "1768404444002", "received_at": "2026-01-14T16:27:23.670891"}}
{"event_type": "price_change", "event_ts": "2026-01-14T16:27:23.670891", "ingestion_ts": "2026-01-14T16:33:58.842229", "market_id": "0xe9c127a8c35f045d37b5344b0a36711084fa20c2fc1618bf178a5386f90610be", "raw": {"market": "0xe9c127a8c35f045d37b5344b0a36711084fa20c2fc1618bf178a5386f90610be", "asset_id": "80230236018433940569996058935444651347308266584430516013229815570706872276819", "price": "0.003", "size": "251", "side": "BUY", "timestamp": "1768404444002", "received_at": "2026-01-14T16:27:23.670891"}}
{"event_type": "price_change", "event_ts": "2026-01-14T16:27:25.102940", "ingestion_ts": "2026-01-14T16:33:58.842229", "market_id": "0xe9c127a8c35f045d37b5344b0a36711084fa20c2fc1618bf178a5386f90610be", "raw": {"market": "0xe9c127a8c35f045d37b5344b0a36711084fa20c2fc1618bf178a5386f90610be", "asset_id": "107000426448217931795450451304515386602910396776318075817601265223856116134349", "price": "0.997", "size": "0", "side": "SELL", "timestamp": "1768404445438", "received_at": "2026-01-14T16:27:25.102940"}}
{"event_type": "price_change", "event_ts": "2026-01-14T16:27:25.102940", "ingestion_ts": "2026-01-14T16:33:58.842229", "market_id": "0xe9c127a8c35f045d37b5344b0a36711084fa20c2fc1618bf178a5386f90610be", "raw": {"market": "0xe9c127a8c35f045d37b5344b0a36711084fa20c2fc1618bf178a5386f90610be", "asset_id": "80230236018433940569996058935444651347308266584430516013229815570706872276819", "price": "0.003", "size": "0", "side": "BUY", "timestamp": "1768404445438", "received_at": "2026-01-14T16:27:25.102940"}}
{"event_type": "price_change", "event_ts": "2026-01-14T16:27:25.134272", "ingestion_ts": "2026-01-14T16:33:58.842229", "market_id": "0xe9c127a8c35f045d37b5344b0a36711084fa20c2fc1618bf178a5386f90610be", "raw": {"market": "0xe9c127a8c35f045d37b5344b0a36711084fa20c2fc1618bf178a5386f90610be", "asset_id": "107000426448217931795450451304515386602910396776318075817601265223856116134349", "price": "0.997", "size": "251", "side": "SELL", "timestamp": "1768404445468", "received_at": "2026-01-14T16:27:25.134272"}}
{"event_type": "price_change", "event_ts": "2026-01-14T16:27:25.134272", "ingestion_ts": "2026-01-14T16:33:58.842229", "market_id": "0xe9c127a8c35f045d37b5344b0a36711084fa20c2fc1618bf178a5386f90610be", "raw": {"market": "0xe9c127a8c35f045d37b5344b0a36711084fa20c2fc1618bf178a5386f90610be", "asset_id": "80230236018433940569996058935444651347308266584430516013229815570706872276819", "price": "0.003", "size": "251", "side": "BUY", "timestamp": "1768404445468", "received_at": "2026-01-14T16:27:25.134272"}}
{"event_type": "price_change", "event_ts": "2026-01-14T16:27:26.611765", "ingestion_ts": "2026-01-14T16:33:58.842229", "market_id": "0xe9c127a8c35f045d37b5344b0a36711084fa20c2fc1618bf178a5386f90610be", "raw": {"market": "0xe9c127a8c35f045d37b5344b0a36711084fa20c2fc1618bf178a5386f90610be", "asset_id": "107000426448217931795450451304515386602910396776318075817601265223856116134349", "price": "0.997", "size": "0", "side": "SELL", "timestamp": "1768404446938", "received_at": "2026-01-14T16:27:26.611765"}}
{"event_type": "price_change", "event_ts": "2026-01-14T16:27:26.611765", "ingestion_ts": "2026-01-14T16:33:58.842229", "market_id": "0xe9c127a8c35f045d37b5344b0a36711084fa20c2fc1618bf178a5386f90610be", "raw": {"market": "0xe9c127a8c35f045d37b5344b0a36711084fa20c2fc1618bf178a5386f90610be", "asset_id": "80230236018433940569996058935444651347308266584430516013229815570706872276819", "price": "0.003", "size": "0", "side": "BUY", "timestamp": "1768404446938", "received_at": "2026-01-14T16:27:26.611765"}}
{"event_type": "price_change", "event_ts": "2026-01-14T16:27:26.637798", "ingestion_ts": "2026-01-14T16:33:58.842229", "market_id": "0xe9c127a8c35f045d37b5344b0a36711084fa20c2fc1618bf178a5386f90610be", "raw": {"market": "0xe9c127a8c35f045d37b5344b0a36711084fa20c2fc1618bf178a5386f90610be", "asset_id": "107000426448217931795450451304515386602910396776318075817601265223856116134349", "price": "0.997", "size": "251", "side": "SELL", "timestamp": "1768404446971", "received_at": "2026-01-14T16:27:26.637798"}}
{"event_type": "price_change", "event_ts": "2026-01-14T16:27:26.637798", "ingestion_ts": "2026-01-14T16:33:58.842229", "market_id": "0xe9c127a8c35f045d37b5344b0a36711084fa20c2fc1618bf178a5386f90610be", "raw": {"market": "0xe9c127a8c35f045d37b5344b0a36711084fa20c2fc1618bf178a5386f90610be", "asset_id": "80230236018433940569996058935444651347308266584430516013229815570706872276819", "price": "0.003", "size": "251", "side": "BUY", "timestamp": "1768404446971", "received_at": "2026-01-14T16:27:26.637798"}}
{"event_type": "price_change", "event_ts": "2026-01-14T16:27:28.102078", "ingestion_ts": "2026-01-14T16:33:58.842229", "market_id": "0xe9c127a8c35f045d37b5344b0a36711084fa20c2fc1618bf178a5386f90610be", "raw": {"market": "0xe9c127a8c35f045d37b5344b0a36711084fa20c2fc1618bf178a5386f90610be", "asset_id": "107000426448217931795450451304515386602910396776318075817601265223856116134349", "price": "0.997", "size": "0", "side": "SELL", "timestamp": "1768404448438", "received_at": "2026-01-14T16:27:28.102078"}}
{"event_type": "price_change", "event_ts": "2026-01-14T16:27:28.102078", "ingestion_ts": "2026-01-14T16:33:58.842229", "market_id": "0xe9c127a8c35f045d37b5344b0a36711084fa20c2fc1618bf178a5386f90610be", "raw": {"market": "0xe9c127a8c35f045d37b5344b0a36711084fa20c2fc1618bf178a5386f90610be", "asset_id": "80230236018433940569996058935444651347308266584430516013229815570706872276819", "price": "0.003", "size": "0", "side": "BUY", "timestamp": "1768404448438", "received_at": "2026-01-14T16:27:28.102078"}}
{"event_type": "price_change", "event_ts": "2026-01-14T16:27:28.131899", "ingestion_ts": "2026-01-14T16:33:58.842229", "market_id": "0xe9c127a8c35f045d37b5344b0a36711084fa20c2fc1618bf178a5386f90610be", "raw": {"market": "0xe9c127a8c35f045d37b5344b0a36711084fa20c2fc1618bf178a5386f90610be", "asset_id": "107000426448217931795450451304515386602910396776318075817601265223856116134349", "price": "0.997", "size": "251", "side": "SELL", "timestamp": "1768404448463", "received_at": "2026-01-14T16:27:28.131899"}}
{"event_type": "price_change", "event_ts": "2026-01-14T16:27:28.131899", "ingestion_ts": "2026-01-14T16:33:58.842229", "market_id": "0xe9c127a8c35f045d37b5344b0a36711084fa20c2fc1618bf178a5386f90610be", "raw": {"market": "0xe9c127a8c35f045d37b5344b0a36711084fa20c2fc1618bf178a5386f90610be", "asset_id": "80230236018433940569996058935444651347308266584430516013229815570706872276819", "price": "0.003", "size": "251", "side": "BUY", "timestamp": "1768404448463", "received_at": "2026-01-14T16:27:28.131899"}}
{"event_type": "price_change", "event_ts": "2026-01-14T16:27:29.606082", "ingestion_ts": "2026-01-14T16:33:58.842229", "market_id": "0xe9c127a8c35f045d37b5344b0a36711084fa20c2fc1618bf178a5386f90610be", "raw": {"market": "0xe9c127a8c35f045d37b5344b0a36711084fa20c2fc1618bf178a5386f90610be", "asset_id": "107000426448217931795450451304515386602910396776318075817601265223856116134349", "price": "0.997", "size": "0", "side": "SELL", "timestamp": "1768404449940", "received_at": "2026-01-14T16:27:29.606082"}}
{"event_type": "price_change", "event_ts": "2026-01-14T16:27:29.606082", "ingestion_ts": "2026-01-14T16:33:58.842229", "market_id": "0xe9c127a8c35f045d37b5344b0a36711084fa20c2fc1618bf178a5386f90610be", "raw": {"market": "0xe9c127a8c35f045d37b5344b0a36711084fa20c2fc1618bf178a5386f90610be", "asset_id": "80230236018433940569996058935444651347308266584430516013229815570706872276819", "price": "0.003", "size": "0", "side": "BUY", "timestamp": "1768404449940", "received_at": "2026-01-14T16:27:29.606082"}}
{"event_type": "price_change", "event_ts": "2026-01-14T16:27:29.641784", "ingestion_ts": "2026-01-14T16:33:58.842229", "market_id": "0xe9c127a8c35f045d37b5344b0a36711084fa20c2fc1618bf178a5386f90610be", "raw": {"market": "0xe9c127a8c35f045d37b5344b0a36711084fa20c2fc1618bf178a5386f90610be", "asset_id": "107000426448217931795450451304515386602910396776318075817601265223856116134349", "price": "0.997", "size": "251", "side": "SELL", "timestamp": "1768404449968", "received_at": "2026-01-14T16:27:29.641784"}}
{"event_type": "price_change", "event_ts": "2026-01-14T16:27:29.641784", "ingestion_ts": "2026-01-14T16:33:58.842229", "market_id": "0xe9c127a8c35f045d37b5344b0a36711084fa20c2fc1618bf178a5386f90610be", "raw": {"market": "0xe9c127a8c35f045d37b5344b0a36711084fa20c2fc1618bf178a5386f90610be", "asset_id": "80230236018433940569996058935444651347308266584430516013229815570706872276819", "price": "0.003", "size": "251", "side": "BUY", "timestamp": "1768404449968", "received_at": "2026-01-14T16:27:29.641784"}}
{"event_type": "price_change", "event_ts": "2026-01-14T16:27:31.160598", "ingestion_ts": "2026-01-14T16:33:58.842229", "market_id": "0xe9c127a8c35f045d37b5344b0a36711084fa20c2fc1618bf178a5386f90610be", "raw": {"market": "0xe9c127a8c35f045d37b5344b0a36711084fa20c2fc1618bf178a5386f90610be", "asset_id": "107000426448217931795450451304515386602910396776318075817601265223856116134349", "price": "0.997", "size": "0", "side": "SELL", "timestamp": "1768404451438", "received_at": "2026-01-14T16:27:31.160598"}}
{"event_type": "price_change", "event_ts": "2026-01-14T16:27:31.160598", "ingestion_ts": "2026-01-14T16:33:58.842229", "market_id": "0xe9c127a8c35f045d37b5344b0a36711084fa20c2fc1618bf178a5386f90610be", "raw": {"market": "0xe9c127a8c35f045d37b5344b0a36711084fa20c2fc1618bf178a5386f90610be", "asset_id": "80230236018433940569996058935444651347308266584430516013229815570706872276819", "price": "0.003", "size": "0", "side": "BUY", "timestamp": "1768404451438", "received_at": "2026-01-14T16:27:31.160598"}}
{"event_type": "price_change", "event_ts": "2026-01-14T16:27:31.218739", "ingestion_ts": "2026-01-14T16:33:58.842229", "market_id": "0xe9c127a8c35f045d37b5344b0a36711084fa20c2fc1618bf178a5386f90610be", "raw": {"market": "0xe9c127a8c35f045d37b5344b0a36711084fa20c2fc1618bf178a5386f90610be", "asset_id": "107000426448217931795450451304515386602910396776318075817601265223856116134349", "price": "0.997", "size": "251", "side": "SELL", "timestamp": "1768404451520", "received_at": "2026-01-14T16:27:31.218739"}}
{"event_type": "price_change", "event_ts": "2026-01-14T16:27:31.218739", "ingestion_ts": "2026-01-14T16:33:58.842229", "market_id": "0xe9c127a8c35f045d37b5344b0a36711084fa20c2fc1618bf178a5386f90610be", "raw": {"market": "0xe9c127a8c35f045d37b5344b0a36711084fa20c2fc1618bf178a5386f90610be", "asset_id": "80230236018433940569996058935444651347308266584430516013229815570706872276819", "price": "0.003", "size": "251", "side": "BUY", "timestamp": "1768404451520", "received_at": "2026-01-14T16:27:31.218739"}}
{"event_type": "price_change", "event_ts": "2026-01-14T16:27:32.603577", "ingestion_ts": "2026-01-14T16:33:58.842229", "market_id": "0xe9c127a8c35f045d37b5344b0a36711084fa20c2fc1618bf178a5386f90610be", "raw": {"market": "0xe9c127a8c35f045d37b5344b0a36711084fa20c2fc1618bf178a5386f90610be", "asset_id": "107000426448217931795450451304515386602910396776318075817601265223856116134349", "price": "0.997", "size": "0", "side": "SELL", "timestamp": "1768404452938", "received_at": "2026-01-14T16:27:32.603577"}}
{"event_type": "price_change", "event_ts": "2026-01-14T16:27:32.603577", "ingestion_ts": "2026-01-14T16:33:58.842229", "market_id": "0xe9c127a8c35f045d37b5344b0a36711084fa20c2fc1618bf178a5386f90610be", "raw": {"market": "0xe9c127a8c35f045d37b5344b0a36711084fa20c2fc1618bf178a5386f90610be", "asset_id": "80230236018433940569996058935444651347308266584430516013229815570706872276819", "price": "0.003", "size": "0", "side": "BUY", "timestamp": "1768404452938", "received_at": "2026-01-14T16:27:32.603577"}}
{"event_type": "price_change", "event_ts": "2026-01-14T16:27:32.636674", "ingestion_ts": "2026-01-14T16:33:58.842229", "market_id": "0xe9c127a8c35f045d37b5344b0a36711084fa20c2fc1618bf178a5386f90610be", "raw": {"market": "0xe9c127a8c35f045d37b5344b0a36711084fa20c2fc1618bf178a5386f90610be", "asset_id": "107000426448217931795450451304515386602910396776318075817601265223856116134349", "price": "0.997", "size": "251", "side": "SELL", "timestamp": "1768404452970", "received_at": "2026-01-14T16:27:32.636674"}}
{"event_type": "price_change", "event_ts": "2026-01-14T16:27:32.636674", "ingestion_ts": "2026-01-14T16:33:58.842229", "market_id": "0xe9c127a8c35f045d37b5344b0a36711084fa20c2fc1618bf178a5386f90610be", "raw": {"market": "0xe9c127a8c35f045d37b5344b0a36711084fa20c2fc1618bf178a5386f90610be", "asset_id": "80230236018433940569996058935444651347308266584430516013229815570706872276819", "price": "0.003", "size": "251", "side": "BUY", "timestamp": "1768404452970", "received_at": "2026-01-14T16:27:32.636674"}}
{"event_type": "price_change", "event_ts": "2026-01-14T16:27:32.674367", "ingestion_ts": "2026-01-14T16:33:58.842229", "market_id": "0xc0e6b917320a47228fb96e3b5ae0e5c93773a5ae2662ae4e1f37807cfe47ce98", "raw": {"market": "0xc0e6b917320a47228fb96e3b5ae0e5c93773a5ae2662ae4e1f37807cfe47ce98", "asset_id": "58656358377246279051017109359677190749228949103591068167284263961542487110215", "price": "0.002", "size": "3299.26", "side": "BUY", "timestamp": "1768404453003", "received_at": "2026-01-14T16:27:32.674367"}}
{"event_type": "price_change", "event_ts": "2026-01-14T16:27:32.674367", "ingestion_ts": "2026-01-14T16:33:58.842229", "market_id": "0xc0e6b917320a47228fb96e3b5ae0e5c93773a5ae2662ae4e1f37807cfe47ce98", "raw": {"market": "0xc0e6b917320a47228fb96e3b5ae0e5c93773a5ae2662ae4e1f37807cfe47ce98", "asset_id": "81647294538046680798858716589766492074338758116170717123345952330712416337530", "price": "0.998", "size": "3299.26", "side": "SELL", "timestamp": "1768404453003", "received_at": "2026-01-14T16:27:32.674367"}}
{"event_type": "price_change", "event_ts": "2026-01-14T16:27:34.154071", "ingestion_ts": "2026-01-14T16:33:58.842229", "market_id": "0xe9c127a8c35f045d37b5344b0a36711084fa20c2fc1618bf178a5386f90610be", "raw": {"market": "0xe9c127a8c35f045d37b5344b0a36711084fa20c2fc1618bf178a5386f90610be", "asset_id": "107000426448217931795450451304515386602910396776318075817601265223856116134349", "price": "0.997", "size": "0", "side": "SELL", "timestamp": "1768404454440", "received_at": "2026-01-14T16:27:34.154071"}}
{"event_type": "price_change", "event_ts": "2026-01-14T16:27:34.154071", "ingestion_ts": "2026-01-14T16:33:58.842229", "market_id": "0xe9c127a8c35f045d37b5344b0a36711084fa20c2fc1618bf178a5386f90610be", "raw": {"market": "0xe9c127a8c35f045d37b5344b0a36711084fa20c2fc1618bf178a5386f90610be", "asset_id": "80230236018433940569996058935444651347308266584430516013229815570706872276819", "price": "0.003", "size": "0", "side": "BUY", "timestamp": "1768404454440", "received_at": "2026-01-14T16:27:34.154071"}}
{"event_type": "price_change", "event_ts": "2026-01-14T16:27:34.221999", "ingestion_ts": "2026-01-14T16:33:58.842229", "market_id": "0xe9c127a8c35f045d37b5344b0a36711084fa20c2fc1618bf178a5386f90610be", "raw": {"market": "0xe9c127a8c35f045d37b5344b0a36711084fa20c2fc1618bf178a5386f90610be", "asset_id": "107000426448217931795450451304515386602910396776318075817601265223856116134349", "price": "0.997", "size": "251", "side": "SELL", "timestamp": "1768404454497", "received_at": "2026-01-14T16:27:34.221999"}}
{"event_type": "price_change", "event_ts": "2026-01-14T16:27:34.221999", "ingestion_ts": "2026-01-14T16:33:58.842229", "market_id": "0xe9c127a8c35f045d37b5344b0a36711084fa20c2fc1618bf178a5386f90610be", "raw": {"market": "0xe9c127a8c35f045d37b5344b0a36711084fa20c2fc1618bf178a5386f90610be", "asset_id": "80230236018433940569996058935444651347308266584430516013229815570706872276819", "price": "0.003", "size": "251", "side": "BUY", "timestamp": "1768404454497", "received_at": "2026-01-14T16:27:34.221999"}}
{"event_type": "price_change", "event_ts": "2026-01-14T16:27:35.613776", "ingestion_ts": "2026-01-14T16:33:58.842229", "market_id": "0xe9c127a8c35f045d37b5344b0a36711084fa20c2fc1618bf178a5386f90610be", "raw": {"market": "0xe9c127a8c35f045d37b5344b0a36711084fa20c2fc1618bf178a5386f90610be", "asset_id": "107000426448217931795450451304515386602910396776318075817601265223856116134349", "price": "0.997", "size": "0", "side": "SELL", "timestamp": "1768404455941", "received_at": "2026-01-14T16:27:35.613776"}}
{"event_type": "price_change", "event_ts": "2026-01-14T16:27:35.613776", "ingestion_ts": "2026-01-14T16:33:58.842229", "market_id": "0xe9c127a8c35f045d37b5344b0a36711084fa20c2fc1618bf178a5386f90610be", "raw": {"market": "0xe9c127a8c35f045d37b5344b0a36711084fa20c2fc1618bf178a5386f90610be", "asset_id": "80230236018433940569996058935444651347308266584430516013229815570706872276819", "price": "0.003", "size": "0", "side": "BUY", "timestamp": "1768404455941", "received_at": "2026-01-14T16:27:35.613776"}}
{"event_type": "price_change", "event_ts": "2026-01-14T16:27:35.636970", "ingestion_ts": "2026-01-14T16:33:58.842229", "market_id": "0xe9c127a8c35f045d37b5344b0a36711084fa20c2fc1618bf178a5386f90610be", "raw": {"market": "0xe9c127a8c35f045d37b5344b0a36711084fa20c2fc1618bf178a5386f90610be", "asset_id": "107000426448217931795450451304515386602910396776318075817601265223856116134349", "price": "0.997", "size": "251", "side": "SELL", "timestamp": "1768404455970", "received_at": "2026-01-14T16:27:35.636970"}}
{"event_type": "price_change", "event_ts": "2026-01-14T16:27:35.636970", "ingestion_ts": "2026-01-14T16:33:58.842229", "market_id": "0xe9c127a8c35f045d37b5344b0a36711084fa20c2fc1618bf178a5386f90610be", "raw": {"market": "0xe9c127a8c35f045d37b5344b0a36711084fa20c2fc1618bf178a5386f90610be", "asset_id": "80230236018433940569996058935444651347308266584430516013229815570706872276819", "price": "0.003", "size": "251", "side": "BUY", "timestamp": "1768404455970", "received_at": "2026-01-14T16:27:35.636970"}}
{"event_type": "price_change", "event_ts": "2026-01-14T16:27:37.106722", "ingestion_ts": "2026-01-14T16:33:58.842229", "market_id": "0xe9c127a8c35f045d37b5344b0a36711084fa20c2fc1618bf178a5386f90610be", "raw": {"market": "0xe9c127a8c35f045d37b5344b0a36711084fa20c2fc1618bf178a5386f90610be", "asset_id": "107000426448217931795450451304515386602910396776318075817601265223856116134349", "price": "0.997", "size": "0", "side": "SELL", "timestamp": "1768404457440", "received_at": "2026-01-14T16:27:37.106722"}}
{"event_type": "price_change", "event_ts": "2026-01-14T16:27:37.106722", "ingestion_ts": "2026-01-14T16:33:58.842229", "market_id": "0xe9c127a8c35f045d37b5344b0a36711084fa20c2fc1618bf178a5386f90610be", "raw": {"market": "0xe9c127a8c35f045d37b5344b0a36711084fa20c2fc1618bf178a5386f90610be", "asset_id": "80230236018433940569996058935444651347308266584430516013229815570706872276819", "price": "0.003", "size": "0", "side": "BUY", "timestamp": "1768404457440", "received_at": "2026-01-14T16:27:37.106722"}}
{"event_type": "price_change", "event_ts": "2026-01-14T16:27:37.131937", "ingestion_ts": "2026-01-14T16:33:58.842229", "market_id": "0xe9c127a8c35f045d37b5344b0a36711084fa20c2fc1618bf178a5386f90610be", "raw": {"market": "0xe9c127a8c35f045d37b5344b0a36711084fa20c2fc1618bf178a5386f90610be", "asset_id": "107000426448217931795450451304515386602910396776318075817601265223856116134349", "price": "0.997", "size": "251", "side": "SELL", "timestamp": "1768404457466", "received_at": "2026-01-14T16:27:37.131937"}}
{"event_type": "price_change", "event_ts": "2026-01-14T16:27:37.131937", "ingestion_ts": "2026-01-14T16:33:58.842229", "market_id": "0xe9c127a8c35f045d37b5344b0a36711084fa20c2fc1618bf178a5386f90610be", "raw": {"market": "0xe9c127a8c35f045d37b5344b0a36711084fa20c2fc1618bf178a5386f90610be", "asset_id": "80230236018433940569996058935444651347308266584430516013229815570706872276819", "price": "0.003", "size": "251", "side": "BUY", "timestamp": "1768404457466", "received_at": "2026-01-14T16:27:37.131937"}}
{"event_type": "price_change", "event_ts": "2026-01-14T16:27:38.608693", "ingestion_ts": "2026-01-14T16:33:58.842229", "market_id": "0xe9c127a8c35f045d37b5344b0a36711084fa20c2fc1618bf178a5386f90610be", "raw": {"market": "0xe9c127a8c35f045d37b5344b0a36711084fa20c2fc1618bf178a5386f90610be", "asset_id": "107000426448217931795450451304515386602910396776318075817601265223856116134349", "price": "0.997", "size": "0", "side": "SELL", "timestamp": "1768404458942", "received_at": "2026-01-14T16:27:38.608693"}}
{"event_type": "price_change", "event_ts": "2026-01-14T16:27:38.608693", "ingestion_ts": "2026-01-14T16:33:58.842229", "market_id": "0xe9c127a8c35f045d37b5344b0a36711084fa20c2fc1618bf178a5386f90610be", "raw": {"market": "0xe9c127a8c35f045d37b5344b0a36711084fa20c2fc1618bf178a5386f90610be", "asset_id": "80230236018433940569996058935444651347308266584430516013229815570706872276819", "price": "0.003", "size": "0", "side": "BUY", "timestamp": "1768404458942", "received_at": "2026-01-14T16:27:38.608693"}}
{"event_type": "price_change", "event_ts": "2026-01-14T16:27:38.641724", "ingestion_ts": "2026-01-14T16:33:58.842229", "market_id": "0xe9c127a8c35f045d37b5344b0a36711084fa20c2fc1618bf178a5386f90610be", "raw": {"market": "0xe9c127a8c35f045d37b5344b0a36711084fa20c2fc1618bf178a5386f90610be", "asset_id": "107000426448217931795450451304515386602910396776318075817601265223856116134349", "price": "0.997", "size": "251", "side": "SELL", "timestamp": "1768404458978", "received_at": "2026-01-14T16:27:38.641724"}}
{"event_type": "price_change", "event_ts": "2026-01-14T16:27:38.641724", "ingestion_ts": "2026-01-14T16:33:58.842229", "market_id": "0xe9c127a8c35f045d37b5344b0a36711084fa20c2fc1618bf178a5386f90610be", "raw": {"market": "0xe9c127a8c35f045d37b5344b0a36711084fa20c2fc1618bf178a5386f90610be", "asset_id": "80230236018433940569996058935444651347308266584430516013229815570706872276819", "price": "0.003", "size": "251", "side": "BUY", "timestamp": "1768404458978", "received_at": "2026-01-14T16:27:38.641724"}}
{"event_type": "price_change", "event_ts": "2026-01-14T16:27:40.105650", "ingestion_ts": "2026-01-14T16:33:58.842229", "market_id": "0xe9c127a8c35f045d37b5344b0a36711084fa20c2fc1618bf178a5386f90610be", "raw": {"market": "0xe9c127a8c35f045d37b5344b0a36711084fa20c2fc1618bf178a5386f90610be", "asset_id": "107000426448217931795450451304515386602910396776318075817601265223856116134349", "price": "0.997", "size": "0", "side": "SELL", "timestamp": "1768404460439", "received_at": "2026-01-14T16:27:40.105650"}}
{"event_type": "price_change", "event_ts": "2026-01-14T16:27:40.105650", "ingestion_ts": "2026-01-14T16:33:58.842229", "market_id": "0xe9c127a8c35f045d37b5344b0a36711084fa20c2fc1618bf178a5386f90610be", "raw": {"market": "0xe9c127a8c35f045d37b5344b0a36711084fa20c2fc1618bf178a5386f90610be", "asset_id": "80230236018433940569996058935444651347308266584430516013229815570706872276819", "price": "0.003", "size": "0", "side": "BUY", "timestamp": "1768404460439", "received_at": "2026-01-14T16:27:40.105650"}}
{"event_type": "price_change", "event_ts": "2026-01-14T16:27:40.132491", "ingestion_ts": "2026-01-14T16:33:58.842229", "market_id": "0xe9c127a8c35f045d37b5344b0a36711084fa20c2fc1618bf178a5386f90610be", "raw": {"market": "0xe9c127a8c35f045d37b5344b0a36711084fa20c2fc1618bf178a5386f90610be", "asset_id": "107000426448217931795450451304515386602910396776318075817601265223856116134349", "price": "0.997", "size": "251", "side": "SELL", "timestamp": "1768404460469", "received_at": "2026-01-14T16:27:40.132491"}}
{"event_type": "price_change", "event_ts": "2026-01-14T16:27:40.132491", "ingestion_ts": "2026-01-14T16:33:58.842229", "market_id": "0xe9c127a8c35f045d37b5344b0a36711084fa20c2fc1618bf178a5386f90610be", "raw": {"market": "0xe9c127a8c35f045d37b5344b0a36711084fa20c2fc1618bf178a5386f90610be", "asset_id": "80230236018433940569996058935444651347308266584430516013229815570706872276819", "price": "0.003", "size": "251", "side": "BUY", "timestamp": "1768404460469", "received_at": "2026-01-14T16:27:40.132491"}}
