{"event_type": "price_change", "event_ts": "2026-01-14T16:17:48.718391", "ingestion_ts": "2026-01-14T16:33:58.842229", "market_id": "0x2393ed0b0fdc450054c7b9071907eca75cf4fc36e385adf4a0a5f99ee62243e8", "raw": {"market": "0x2393ed0b0fdc450054c7b9071907eca75cf4fc36e385adf4a0a5f99ee62243e8", "asset_id": "32769749367306925959219403371425714180265458150646381231272229429098460625924", "price": "0.865", "size": "1999.66", "side": "BUY", "timestamp": "1768403869015", "received_at": "2026-01-14T16:17:48.718391"}}
{"event_type": "price_change", "event_ts": "2026-01-14T16:17:48.718391", "ingestion_ts": "2026-01-14T16:33:58.842229", "market_id": "0x2393ed0b0fdc450054c7b9071907eca75cf4fc36e385adf4a0a5f99ee62243e8", "raw": {"market": "0x2393ed0b0fdc450054c7b9071907eca75cf4fc36e385adf4a0a5f99ee62243e8", "asset_id": "100074770378634056601572485653252702850363676459996771990439989989293515601975", "price": "0.135", "size": "1999.66", "side": "SELL", "timestamp": "1768403869015", "received_at": "2026-01-14T16:17:48.718391"}}
{"event_type": "price_change", "event_ts": "2026-01-14T16:17:48.718433", "ingestion_ts": "2026-01-14T16:33:58.842229", "market_id": "0x49686d26fb712515cd5e12c23f0a1c7e10214c7faa3cb0a730aabe0c33694082", "raw": {"market": "0x49686d26fb712515cd5e12c23f0a1c7e10214c7faa3cb0a730aabe0c33694082", "asset_id": "13244681086321087932946246027856416106585284024824496763706748621681543444582", "price": "0.907", "size": "114", "side": "SELL", "timestamp": "1768403869018", "received_at": "2026-01-14T16:17:48.718433"}}
{"event_type": "price_change", "event_ts": "2026-01-14T16:17:48.718433", "ingestion_ts": "2026-01-14T16:33:58.842229", "market_id": "0x49686d26fb712515cd5e12c23f0a1c7e10214c7faa3cb0a730aabe0c33694082", "raw": {"market": "0x49686d26fb712515cd5e12c23f0a1c7e10214c7faa3cb0a730aabe0c33694082", "asset_id": "30442780799048074404860985387051749017905070253466005720364298335239299761065", "price": "0.093", "size": "114", "side": "BUY", "timestamp": "1768403869018", "received_at": "2026-01-14T16:17:48.718433"}}
{"event_type": "price_change", "event_ts": "2026-01-14T16:17:48.881068", "ingestion_ts": "2026-01-14T16:33:58.842229", "market_id": "0x2393ed0b0fdc450054c7b9071907eca75cf4fc36e385adf4a0a5f99ee62243e8", "raw": {"market": "0x2393ed0b0fdc450054c7b9071907eca75cf4fc36e385adf4a0a5f99ee62243e8", "asset_id": "32769749367306925959219403371425714180265458150646381231272229429098460625924", "price": "0.45", "size": "0", "side": "BUY", "timestamp": "1768403869171", "received_at": "2026-01-14T16:17:48.881068"}}
{"event_type": "price_change", "event_ts": "2026-01-14T16:17:48.881068", "ingestion_ts": "2026-01-14T16:33:58.842229", "market_id": "0x2393ed0b0fdc450054c7b9071907eca75cf4fc36e385adf4a0a5f99ee62243e8", "raw": {"market": "0x2393ed0b0fdc450054c7b9071907eca75cf4fc36e385adf4a0a5f99ee62243e8", "asset_id": "100074770378634056601572485653252702850363676459996771990439989989293515601975", "price": "0.55", "size": "0", "side": "SELL", "timestamp": "1768403869171", "received_at": "2026-01-14T16:17:48.881068"}}
{"event_type": "price_change", "event_ts": "2026-01-14T16:17:50.882147", "ingestion_ts": "2026-01-14T16:33:58.842229", "market_id": "0x49686d26fb712515cd5e12c23f0a1c7e10214c7faa3cb0a730aabe0c33694082", "raw": {"market": "0x49686d26fb712515cd5e12c23f0a1c7e10214c7faa3cb0a730aabe0c33694082", "asset_id": "30442780799048074404860985387051749017905070253466005720364298335239299761065", "price": "0.094", "size": "50", "side": "BUY", "timestamp": "1768403871180", "received_at": "2026-01-14T16:17:50.882147"}}
{"event_type": "price_change", "event_ts": "2026-01-14T16:17:50.882147", "ingestion_ts": "2026-01-14T16:33:58.842229", "market_id": "0x49686d26fb712515cd5e12c23f0a1c7e10214c7faa3cb0a730aabe0c33694082", "raw": {"market": "0x49686d26fb712515cd5e12c23f0a1c7e10214c7faa3cb0a730aabe0c33694082", "asset_id": "13244681086321087932946246027856416106585284024824496763706748621681543444582", "price": "0.906", "size": "50", "side": "SELL", "timestamp": "1768403871180", "received_at": "2026-01-14T16:17:50.882147"}}
{"event_type": "price_change", "event_ts": "2026-01-14T16:17:50.929499", "ingestion_ts": "2026-01-14T16:33:58.842229", "market_id": "0x49686d26fb712515cd5e12c23f0a1c7e10214c7faa3cb0a730aabe0c33694082", "raw": {"market": "0x49686d26fb712515cd5e12c23f0a1c7e10214c7faa3cb0a730aabe0c33694082", "asset_id": "13244681086321087932946246027856416106585284024824496763706748621681543444582", "price": "0.907", "size": "0", "side": "SELL", "timestamp": "1768403871257", "received_at": "2026-01-14T16:17:50.929499"}}
{"event_type": "price_change", "event_ts": "2026-01-14T16:17:50.929499", "ingestion_ts": "2026-01-14T16:33:58.842229", "market_id": "0x49686d26fb712515cd5e12c23f0a1c7e10214c7faa3cb0a730aabe0c33694082", "raw": {"market": "0x49686d26fb712515cd5e12c23f0a1c7e10214c7faa3cb0a730aabe0c33694082", "asset_id": "30442780799048074404860985387051749017905070253466005720364298335239299761065", "price": "0.093", "size": "0", "side": "BUY", "timestamp": "1768403871257", "received_at": "2026-01-14T16:17:50.929499"}}
{"event_type": "price_change", "event_ts": "2026-01-14T16:17:50.942948", "ingestion_ts": "2026-01-14T16:33:58.842229", "market_id": "0x49686d26fb712515cd5e12c23f0a1c7e10214c7faa3cb0a730aabe0c33694082", "raw": {"market": "0x49686d26fb712515cd5e12c23f0a1c7e10214c7faa3cb0a730aabe0c33694082", "asset_id": "30442780799048074404860985387051749017905070253466005720364298335239299761065", "price": "0.033", "size": "0", "side": "BUY", "timestamp": "1768403871270", "received_at": "2026-01-14T16:17:50.942948"}}
{"event_type": "price_change", "event_ts": "2026-01-14T16:17:50.942948", "ingestion_ts": "2026-01-14T16:33:58.842229", "market_id": "0x49686d26fb712515cd5e12c23f0a1c7e10214c7faa3cb0a730aabe0c33694082", "raw": {"market": "0x49686d26fb712515cd5e12c23f0a1c7e10214c7faa3cb0a730aabe0c33694082", "asset_id": "13244681086321087932946246027856416106585284024824496763706748621681543444582", "price": "0.967", "size": "0", "side": "SELL", "timestamp": "1768403871270", "received_at": "2026-01-14T16:17:50.942948"}}
{"event_type": "price_change", "event_ts": "2026-01-14T16:17:50.960303", "ingestion_ts": "2026-01-14T16:33:58.842229", "market_id": "0x49686d26fb712515cd5e12c23f0a1c7e10214c7faa3cb0a730aabe0c33694082", "raw": {"market": "0x49686d26fb712515cd5e12c23f0a1c7e10214c7faa3cb0a730aabe0c33694082", "asset_id": "13244681086321087932946246027856416106585284024824496763706748621681543444582", "price": "0.898", "size": "107", "side": "SELL", "timestamp": "1768403871287", "received_at": "2026-01-14T16:17:50.960303"}}
{"event_type": "price_change", "event_ts": "2026-01-14T16:17:50.960303", "ingestion_ts": "2026-01-14T16:33:58.842229", "market_id": "0x49686d26fb712515cd5e12c23f0a1c7e10214c7faa3cb0a730aabe0c33694082", "raw": {"market": "0x49686d26fb712515cd5e12c23f0a1c7e10214c7faa3cb0a730aabe0c33694082", "asset_id": "30442780799048074404860985387051749017905070253466005720364298335239299761065", "price": "0.102", "size": "107", "side": "BUY", "timestamp": "1768403871287", "received_at": "2026-01-14T16:17:50.960303"}}
{"event_type": "price_change", "event_ts": "2026-01-14T16:17:51.107335", "ingestion_ts": "2026-01-14T16:33:58.842229", "market_id": "0x49686d26fb712515cd5e12c23f0a1c7e10214c7faa3cb0a730aabe0c33694082", "raw": {"market": "0x49686d26fb712515cd5e12c23f0a1c7e10214c7faa3cb0a730aabe0c33694082", "asset_id": "30442780799048074404860985387051749017905070253466005720364298335239299761065", "price": "0.039", "size": "20", "side": "BUY", "timestamp": "1768403871433", "received_at": "2026-01-14T16:17:51.107335"}}
{"event_type": "price_change", "event_ts": "2026-01-14T16:17:51.107335", "ingestion_ts": "2026-01-14T16:33:58.842229", "market_id": "0x49686d26fb712515cd5e12c23f0a1c7e10214c7faa3cb0a730aabe0c33694082", "raw": {"market": "0x49686d26fb712515cd5e12c23f0a1c7e10214c7faa3cb0a730aabe0c33694082", "asset_id": "13244681086321087932946246027856416106585284024824496763706748621681543444582", "price": "0.961", "size": "20", "side": "SELL", "timestamp": "1768403871433", "received_at": "2026-01-14T16:17:51.107335"}}
{"event_type": "price_change", "event_ts": "2026-01-14T16:17:51.135854", "ingestion_ts": "2026-01-14T16:33:58.842229", "market_id": "0x49686d26fb712515cd5e12c23f0a1c7e10214c7faa3cb0a730aabe0c33694082", "raw": {"market": "0x49686d26fb712515cd5e12c23f0a1c7e10214c7faa3cb0a730aabe0c33694082", "asset_id": "30442780799048074404860985387051749017905070253466005720364298335239299761065", "price": "0.06", "size": "0", "side": "BUY", "timestamp": "1768403871460", "received_at": "2026-01-14T16:17:51.135854"}}
{"event_type": "price_change", "event_ts": "2026-01-14T16:17:51.135854", "ingestion_ts": "2026-01-14T16:33:58.842229", "market_id": "0x49686d26fb712515cd5e12c23f0a1c7e10214c7faa3cb0a730aabe0c33694082", "raw": {"market": "0x49686d26fb712515cd5e12c23f0a1c7e10214c7faa3cb0a730aabe0c33694082", "asset_id": "13244681086321087932946246027856416106585284024824496763706748621681543444582", "price": "0.94", "size": "0", "side": "SELL", "timestamp": "1768403871460", "received_at": "2026-01-14T16:17:51.135854"}}
{"event_type": "price_change", "event_ts": "2026-01-14T16:17:57.193899", "ingestion_ts": "2026-01-14T16:33:58.842229", "market_id": "0x49686d26fb712515cd5e12c23f0a1c7e10214c7faa3cb0a730aabe0c33694082", "raw": {"market": "0x49686d26fb712515cd5e12c23f0a1c7e10214c7faa3cb0a730aabe0c33694082", "asset_id": "30442780799048074404860985387051749017905070253466005720364298335239299761065", "price": "0.094", "size": "0", "side": "BUY", "timestamp": "1768403877516", "received_at": "2026-01-14T16:17:57.193899"}}
{"event_type": "price_change", "event_ts": "2026-01-14T16:17:57.193899", "ingestion_ts": "2026-01-14T16:33:58.842229", "market_id": "0x49686d26fb712515cd5e12c23f0a1c7e10214c7faa3cb0a730aabe0c33694082", "raw": {"market": "0x49686d26fb712515cd5e12c23f0a1c7e10214c7faa3cb0a730aabe0c33694082", "asset_id": "13244681086321087932946246027856416106585284024824496763706748621681543444582", "price": "0.906", "size": "0", "side": "SELL", "timestamp": "1768403877516", "received_at": "2026-01-14T16:17:57.193899"}}
{"event_type": "price_change", "event_ts": "2026-01-14T16:18:10.617818", "ingestion_ts": "2026-01-14T16:33:58.842229", "market_id": "0x318b222c1435b47c338e66ca6001f782711186a488ae7b7248f7edc6ff076a83", "raw": {"market": "0x318b222c1435b47c338e66ca6001f782711186a488ae7b7248f7edc6ff076a83", "asset_id": "63773739594775606083258239254748928077067768053882704658119720069071630213026", "price": "0.204", "size": "0", "side": "BUY", "timestamp": "1768403890814", "received_at": "2026-01-14T16:18:10.617818"}}
{"event_type": "price_change", "event_ts": "2026-01-14T16:18:10.617818", "ingestion_ts": "2026-01-14T16:33:58.842229", "market_id": "0x318b222c1435b47c338e66ca6001f782711186a488ae7b7248f7edc6ff076a83", "raw": {"market": "0x318b222c1435b47c338e66ca6001f782711186a488ae7b7248f7edc6ff076a83", "asset_id": "56738600572035832904895845056468792275697823297413384908752239327866518310010", "price": "0.796", "size": "0", "side": "SELL", "timestamp": "1768403890814", "received_at": "2026-01-14T16:18:10.617818"}}
{"event_type": "price_change", "event_ts": "2026-01-14T16:18:11.234423", "ingestion_ts": "2026-01-14T16:33:58.842229", "market_id": "0xc0e6b917320a47228fb96e3b5ae0e5c93773a5ae2662ae4e1f37807cfe47ce98", "raw": {"market": "0xc0e6b917320a47228fb96e3b5ae0e5c93773a5ae2662ae4e1f37807cfe47ce98", "asset_id": "58656358377246279051017109359677190749228949103591068167284263961542487110215", "price": "0.001", "size": "466.66", "side": "BUY", "timestamp": "1768403891446", "received_at": "2026-01-14T16:18:11.234423"}}
{"event_type": "price_change", "event_ts": "2026-01-14T16:18:11.234423", "ingestion_ts": "2026-01-14T16:33:58.842229", "market_id": "0xc0e6b917320a47228fb96e3b5ae0e5c93773a5ae2662ae4e1f37807cfe47ce98", "raw": {"market": "0xc0e6b917320a47228fb96e3b5ae0e5c93773a5ae2662ae4e1f37807cfe47ce98", "asset_id": "81647294538046680798858716589766492074338758116170717123345952330712416337530", "price": "0.999", "size": "466.66", "side": "SELL", "timestamp": "1768403891446", "received_at": "2026-01-14T16:18:11.234423"}}
{"event_type": "price_change", "event_ts": "2026-01-14T16:18:15.581190", "ingestion_ts": "2026-01-14T16:33:58.842229", "market_id": "0xe6508d867d153a268bdab732aa8abc8cc57e652d28a23aa042da40895bf031b2", "raw": {"market": "0xe6508d867d153a268bdab732aa8abc8cc57e652d28a23aa042da40895bf031b2", "asset_id": "57878493050148425637822780001963685814731344602319345842647239312888833935027", "price": "0.999", "size": "32317.11", "side": "SELL", "timestamp": "1768403895901", "received_at": "2026-01-14T16:18:15.581190"}}
{"event_type": "price_change", "event_ts": "2026-01-14T16:18:15.581190", "ingestion_ts": "2026-01-14T16:33:58.842229", "market_id": "0xe6508d867d153a268bdab732aa8abc8cc57e652d28a23aa042da40895bf031b2", "raw": {"market": "0xe6508d867d153a268bdab732aa8abc8cc57e652d28a23aa042da40895bf031b2", "asset_id": "2853768819561879023657600399360829876689515906714535926781067187993853038980", "price": "0.001", "size": "32317.11", "side": "BUY", "timestamp": "1768403895901", "received_at": "2026-01-14T16:18:15.581190"}}
{"event_type": "price_change", "event_ts": "2026-01-14T16:18:22.408761", "ingestion_ts": "2026-01-14T16:33:58.842229", "market_id": "0x318b222c1435b47c338e66ca6001f782711186a488ae7b7248f7edc6ff076a83", "raw": {"market": "0x318b222c1435b47c338e66ca6001f782711186a488ae7b7248f7edc6ff076a83", "asset_id": "63773739594775606083258239254748928077067768053882704658119720069071630213026", "price": "0.205", "size": "1462", "side": "BUY", "timestamp": "1768403902726", "received_at": "2026-01-14T16:18:22.408761"}}
{"event_type": "price_change", "event_ts": "2026-01-14T16:18:22.408761", "ingestion_ts": "2026-01-14T16:33:58.842229", "market_id": "0x318b222c1435b47c338e66ca6001f782711186a488ae7b7248f7edc6ff076a83", "raw": {"market": "0x318b222c1435b47c338e66ca6001f782711186a488ae7b7248f7edc6ff076a83", "asset_id": "56738600572035832904895845056468792275697823297413384908752239327866518310010", "price": "0.795", "size": "1462", "side": "SELL", "timestamp": "1768403902726", "received_at": "2026-01-14T16:18:22.408761"}}
{"event_type": "price_change", "event_ts": "2026-01-14T16:18:35.702924", "ingestion_ts": "2026-01-14T16:33:58.842229", "market_id": "0x22ac5f75af18fdb453497fbf7ac0606a09a6fd55b78b2d08aace6b946ad62038", "raw": {"market": "0x22ac5f75af18fdb453497fbf7ac0606a09a6fd55b78b2d08aace6b946ad62038", "asset_id": "97449340182256366014320155718265676486703217567849039806162053075113517266910", "price": "0.028", "size": "40.92", "side": "SELL", "timestamp": "1768403916029", "received_at": "2026-01-14T16:18:35.702924"}}
{"event_type": "price_change", "event_ts": "2026-01-14T16:18:35.702924", "ingestion_ts": "2026-01-14T16:33:58.842229", "market_id": "0x22ac5f75af18fdb453497fbf7ac0606a09a6fd55b78b2d08aace6b946ad62038", "raw": {"market": "0x22ac5f75af18fdb453497fbf7ac0606a09a6fd55b78b2d08aace6b946ad62038", "asset_id": "59259495934562596318644973716893809974860301509869285036503555129962149752635", "price": "0.972", "size": "40.92", "side": "BUY", "timestamp": "1768403916029", "received_at": "2026-01-14T16:18:35.702924"}}
{"event_type": "price_change", "event_ts": "2026-01-14T16:19:50.172887", "ingestion_ts": "2026-01-14T16:33:58.842229", "market_id": "0x50c669f178da4e5bbea7f1be25041fd278914712fa87a6a6f8e57d5923d88dee", "raw": {"market": "0x50c669f178da4e5bbea7f1be25041fd278914712fa87a6a6f8e57d5923d88dee", "asset_id": "74040420326294854165772767082819937451857852955603897473157746262672057685461", "price": "0.881", "size": "820.47", "side": "BUY", "timestamp": "1768403990471", "received_at": "2026-01-14T16:19:50.172887"}}
{"event_type": "price_change", "event_ts": "2026-01-14T16:19:50.172887", "ingestion_ts": "2026-01-14T16:33:58.842229", "market_id": "0x50c669f178da4e5bbea7f1be25041fd278914712fa87a6a6f8e57d5923d88dee", "raw": {"market": "0x50c669f178da4e5bbea7f1be25041fd278914712fa87a6a6f8e57d5923d88dee", "asset_id": "24682525479474221428144937281315825971983904267399062415430320764754931667953", "price": "0.119", "size": "820.47", "side": "SELL", "timestamp": "1768403990471", "received_at": "2026-01-14T16:19:50.172887"}}
{"event_type": "price_change", "event_ts": "2026-01-14T16:19:50.447671", "ingestion_ts": "2026-01-14T16:33:58.842229", "market_id": "0x50c669f178da4e5bbea7f1be25041fd278914712fa87a6a6f8e57d5923d88dee", "raw": {"market": "0x50c669f178da4e5bbea7f1be25041fd278914712fa87a6a6f8e57d5923d88dee", "asset_id": "74040420326294854165772767082819937451857852955603897473157746262672057685461", "price": "0.882", "size": "0", "side": "BUY", "timestamp": "1768403990740", "received_at": "2026-01-14T16:19:50.447671"}}
{"event_type": "price_change", "event_ts": "2026-01-14T16:19:50.447671", "ingestion_ts": "2026-01-14T16:33:58.842229", "market_id": "0x50c669f178da4e5bbea7f1be25041fd278914712fa87a6a6f8e57d5923d88dee", "raw": {"market": "0x50c669f178da4e5bbea7f1be25041fd278914712fa87a6a6f8e57d5923d88dee", "asset_id": "24682525479474221428144937281315825971983904267399062415430320764754931667953", "price": "0.118", "size": "0", "side": "SELL", "timestamp": "1768403990740", "received_at": "2026-01-14T16:19:50.447671"}}
{"event_type": "price_change", "event_ts": "2026-01-14T16:19:50.447721", "ingestion_ts": "2026-01-14T16:33:58.842229", "market_id": "0x9472be65457510b7fc3477b20ba90910e99d92eac8421a14bf4b7b7a08ef31dc", "raw": {"market": "0x9472be65457510b7fc3477b20ba90910e99d92eac8421a14bf4b7b7a08ef31dc", "asset_id": "43311793366960417907757893276427136943959788721376762326430771171648759300146", "price": "0.926", "size": "0", "side": "BUY", "timestamp": "1768403990741", "received_at": "2026-01-14T16:19:50.447721"}}
{"event_type": "price_change", "event_ts": "2026-01-14T16:19:50.447721", "ingestion_ts": "2026-01-14T16:33:58.842229", "market_id": "0x9472be65457510b7fc3477b20ba90910e99d92eac8421a14bf4b7b7a08ef31dc", "raw": {"market": "0x9472be65457510b7fc3477b20ba90910e99d92eac8421a14bf4b7b7a08ef31dc", "asset_id": "73414222381656326204771753454630063673548497164758947581648273905027617570612", "price": "0.074", "size": "0", "side": "SELL", "timestamp": "1768403990741", "received_at": "2026-01-14T16:19:50.447721"}}
{"event_type": "price_change", "event_ts": "2026-01-14T16:19:50.447736", "ingestion_ts": "2026-01-14T16:33:58.842229", "market_id": "0x9472be65457510b7fc3477b20ba90910e99d92eac8421a14bf4b7b7a08ef31dc", "raw": {"market": "0x9472be65457510b7fc3477b20ba90910e99d92eac8421a14bf4b7b7a08ef31dc", "asset_id": "43311793366960417907757893276427136943959788721376762326430771171648759300146", "price": "0.882", "size": "0", "side": "BUY", "timestamp": "1768403990741", "received_at": "2026-01-14T16:19:50.447736"}}
{"event_type": "price_change", "event_ts": "2026-01-14T16:19:50.447736", "ingestion_ts": "2026-01-14T16:33:58.842229", "market_id": "0x9472be65457510b7fc3477b20ba90910e99d92eac8421a14bf4b7b7a08ef31dc", "raw": {"market": "0x9472be65457510b7fc3477b20ba90910e99d92eac8421a14bf4b7b7a08ef31dc", "asset_id": "73414222381656326204771753454630063673548497164758947581648273905027617570612", "price": "0.118", "size": "0", "side": "SELL", "timestamp": "1768403990741", "received_at": "2026-01-14T16:19:50.447736"}}
{"event_type": "price_change", "event_ts": "2026-01-14T16:19:50.498672", "ingestion_ts": "2026-01-14T16:33:58.842229", "market_id": "0x9472be65457510b7fc3477b20ba90910e99d92eac8421a14bf4b7b7a08ef31dc", "raw": {"market": "0x9472be65457510b7fc3477b20ba90910e99d92eac8421a14bf4b7b7a08ef31dc", "asset_id": "43311793366960417907757893276427136943959788721376762326430771171648759300146", "price": "0.826", "size": "10", "side": "BUY", "timestamp": "1768403990825", "received_at": "2026-01-14T16:19:50.498672"}}
{"event_type": "price_change", "event_ts": "2026-01-14T16:19:50.498672", "ingestion_ts": "2026-01-14T16:33:58.842229", "market_id": "0x9472be65457510b7fc3477b20ba90910e99d92eac8421a14bf4b7b7a08ef31dc", "raw": {"market": "0x9472be65457510b7fc3477b20ba90910e99d92eac8421a14bf4b7b7a08ef31dc", "asset_id": "73414222381656326204771753454630063673548497164758947581648273905027617570612", "price": "0.174", "size": "10", "side": "SELL", "timestamp": "1768403990825", "received_at": "2026-01-14T16:19:50.498672"}}
{"event_type": "price_change", "event_ts": "2026-01-14T16:19:50.498727", "ingestion_ts": "2026-01-14T16:33:58.842229", "market_id": "0x9472be65457510b7fc3477b20ba90910e99d92eac8421a14bf4b7b7a08ef31dc", "raw": {"market": "0x9472be65457510b7fc3477b20ba90910e99d92eac8421a14bf4b7b7a08ef31dc", "asset_id": "43311793366960417907757893276427136943959788721376762326430771171648759300146", "price": "0.926", "size": "20", "side": "BUY", "timestamp": "1768403990826", "received_at": "2026-01-14T16:19:50.498727"}}
{"event_type": "price_change", "event_ts": "2026-01-14T16:19:50.498727", "ingestion_ts": "2026-01-14T16:33:58.842229", "market_id": "0x9472be65457510b7fc3477b20ba90910e99d92eac8421a14bf4b7b7a08ef31dc", "raw": {"market": "0x9472be65457510b7fc3477b20ba90910e99d92eac8421a14bf4b7b7a08ef31dc", "asset_id": "73414222381656326204771753454630063673548497164758947581648273905027617570612", "price": "0.074", "size": "20", "side": "SELL", "timestamp": "1768403990826", "received_at": "2026-01-14T16:19:50.498727"}}
{"event_type": "price_change", "event_ts": "2026-01-14T16:19:50.586107", "ingestion_ts": "2026-01-14T16:33:58.842229", "market_id": "0x50c669f178da4e5bbea7f1be25041fd278914712fa87a6a6f8e57d5923d88dee", "raw": {"market": "0x50c669f178da4e5bbea7f1be25041fd278914712fa87a6a6f8e57d5923d88dee", "asset_id": "74040420326294854165772767082819937451857852955603897473157746262672057685461", "price": "0.925", "size": "0", "side": "BUY", "timestamp": "1768403990913", "received_at": "2026-01-14T16:19:50.586107"}}
{"event_type": "price_change", "event_ts": "2026-01-14T16:19:50.586107", "ingestion_ts": "2026-01-14T16:33:58.842229", "market_id": "0x50c669f178da4e5bbea7f1be25041fd278914712fa87a6a6f8e57d5923d88dee", "raw": {"market": "0x50c669f178da4e5bbea7f1be25041fd278914712fa87a6a6f8e57d5923d88dee", "asset_id": "24682525479474221428144937281315825971983904267399062415430320764754931667953", "price": "0.075", "size": "0", "side": "SELL", "timestamp": "1768403990913", "received_at": "2026-01-14T16:19:50.586107"}}
{"event_type": "price_change", "event_ts": "2026-01-14T16:19:50.647111", "ingestion_ts": "2026-01-14T16:33:58.842229", "market_id": "0x50c669f178da4e5bbea7f1be25041fd278914712fa87a6a6f8e57d5923d88dee", "raw": {"market": "0x50c669f178da4e5bbea7f1be25041fd278914712fa87a6a6f8e57d5923d88dee", "asset_id": "74040420326294854165772767082819937451857852955603897473157746262672057685461", "price": "0.925", "size": "20", "side": "BUY", "timestamp": "1768403990976", "received_at": "2026-01-14T16:19:50.647111"}}
{"event_type": "price_change", "event_ts": "2026-01-14T16:19:50.647111", "ingestion_ts": "2026-01-14T16:33:58.842229", "market_id": "0x50c669f178da4e5bbea7f1be25041fd278914712fa87a6a6f8e57d5923d88dee", "raw": {"market": "0x50c669f178da4e5bbea7f1be25041fd278914712fa87a6a6f8e57d5923d88dee", "asset_id": "24682525479474221428144937281315825971983904267399062415430320764754931667953", "price": "0.075", "size": "20", "side": "SELL", "timestamp": "1768403990976", "received_at": "2026-01-14T16:19:50.647111"}}
{"event_type": "price_change", "event_ts": "2026-01-14T16:19:50.655900", "ingestion_ts": "2026-01-14T16:33:58.842229", "market_id": "0x50c669f178da4e5bbea7f1be25041fd278914712fa87a6a6f8e57d5923d88dee", "raw": {"market": "0x50c669f178da4e5bbea7f1be25041fd278914712fa87a6a6f8e57d5923d88dee", "asset_id": "74040420326294854165772767082819937451857852955603897473157746262672057685461", "price": "0.882", "size": "10", "side": "BUY", "timestamp": "1768403990977", "received_at": "2026-01-14T16:19:50.655900"}}
{"event_type": "price_change", "event_ts": "2026-01-14T16:19:50.655900", "ingestion_ts": "2026-01-14T16:33:58.842229", "market_id": "0x50c669f178da4e5bbea7f1be25041fd278914712fa87a6a6f8e57d5923d88dee", "raw": {"market": "0x50c669f178da4e5bbea7f1be25041fd278914712fa87a6a6f8e57d5923d88dee", "asset_id": "24682525479474221428144937281315825971983904267399062415430320764754931667953", "price": "0.118", "size": "10", "side": "SELL", "timestamp": "1768403990977", "received_at": "2026-01-14T16:19:50.655900"}}
{"event_type": "price_change", "event_ts": "2026-01-14T16:20:02.287074", "ingestion_ts": "2026-01-14T16:33:58.842229", "market_id": "0x2393ed0b0fdc450054c7b9071907eca75cf4fc36e385adf4a0a5f99ee62243e8", "raw": {"market": "0x2393ed0b0fdc450054c7b9071907eca75cf4fc36e385adf4a0a5f99ee62243e8", "asset_id": "32769749367306925959219403371425714180265458150646381231272229429098460625924", "price": "0.448", "size": "0", "side": "BUY", "timestamp": "1768404002375", "received_at": "2026-01-14T16:20:02.287074"}}
{"event_type": "price_change", "event_ts": "2026-01-14T16:20:02.287074", "ingestion_ts": "2026-01-14T16:33:58.842229", "market_id": "0x2393ed0b0fdc450054c7b9071907eca75cf4fc36e385adf4a0a5f99ee62243e8", "raw": {"market": "0x2393ed0b0fdc450054c7b9071907eca75cf4fc36e385adf4a0a5f99ee62243e8", "asset_id": "100074770378634056601572485653252702850363676459996771990439989989293515601975", "price": "0.552", "size": "0", "side": "SELL", "timestamp": "1768404002375", "received_at": "2026-01-14T16:20:02.287074"}}
{"event_type": "price_change", "event_ts": "2026-01-14T16:20:02.481073", "ingestion_ts": "2026-01-14T16:33:58.842229", "market_id": "0x318b222c1435b47c338e66ca6001f782711186a488ae7b7248f7edc6ff076a83", "raw": {"market": "0x318b222c1435b47c338e66ca6001f782711186a488ae7b7248f7edc6ff076a83", "asset_id": "63773739594775606083258239254748928077067768053882704658119720069071630213026", "price": "0.496", "size": "0", "side": "BUY", "timestamp": "1768404002390", "received_at": "2026-01-14T16:20:02.481073"}}
{"event_type": "price_change", "event_ts": "2026-01-14T16:20:02.481073", "ingestion_ts": "2026-01-14T16:33:58.842229", "market_id": "0x318b222c1435b47c338e66ca6001f782711186a488ae7b7248f7edc6ff076a83", "raw": {"market": "0x318b222c1435b47c338e66ca6001f782711186a488ae7b7248f7edc6ff076a83", "asset_id": "56738600572035832904895845056468792275697823297413384908752239327866518310010", "price": "0.504", "size": "0", "side": "SELL", "timestamp": "1768404002390", "received_at": "2026-01-14T16:20:02.481073"}}
{"event_type": "price_change", "event_ts": "2026-01-14T16:20:03.223715", "ingestion_ts": "2026-01-14T16:33:58.842229", "market_id": "0x49686d26fb712515cd5e12c23f0a1c7e10214c7faa3cb0a730aabe0c33694082", "raw": {"market": "0x49686d26fb712515cd5e12c23f0a1c7e10214c7faa3cb0a730aabe0c33694082", "asset_id": "13244681086321087932946246027856416106585284024824496763706748621681543444582", "price": "0.191", "size": "0", "side": "BUY", "timestamp": "1768404002494", "received_at": "2026-01-14T16:20:03.223715"}}
{"event_type": "price_change", "event_ts": "2026-01-14T16:20:03.223715", "ingestion_ts": "2026-01-14T16:33:58.842229", "market_id": "0x49686d26fb712515cd5e12c23f0a1c7e10214c7faa3cb0a730aabe0c33694082", "raw": {"market": "0x49686d26fb712515cd5e12c23f0a1c7e10214c7faa3cb0a730aabe0c33694082", "asset_id": "30442780799048074404860985387051749017905070253466005720364298335239299761065", "price": "0.809", "size": "0", "side": "SELL", "timestamp": "1768404002494", "received_at": "2026-01-14T16:20:03.223715"}}
{"event_type": "price_change", "event_ts": "2026-01-14T16:20:03.264956", "ingestion_ts": "2026-01-14T16:33:58.842229", "market_id": "0x49686d26fb712515cd5e12c23f0a1c7e10214c7faa3cb0a730aabe0c33694082", "raw": {"market": "0x49686d26fb712515cd5e12c23f0a1c7e10214c7faa3cb0a730aabe0c33694082", "asset_id": "13244681086321087932946246027856416106585284024824496763706748621681543444582", "price": "0.115", "size": "100", "side": "BUY", "timestamp": "1768404002547", "received_at": "2026-01-14T16:20:03.264956"}}
{"event_type": "price_change", "event_ts": "2026-01-14T16:20:03.264956", "ingestion_ts": "2026-01-14T16:33:58.842229", "market_id": "0x49686d26fb712515cd5e12c23f0a1c7e10214c7faa3cb0a730aabe0c33694082", "raw": {"market": "0x49686d26fb712515cd5e12c23f0a1c7e10214c7faa3cb0a730aabe0c33694082", "asset_id": "30442780799048074404860985387051749017905070253466005720364298335239299761065", "price": "0.885", "size": "100", "side": "SELL", "timestamp": "1768404002547", "received_at": "2026-01-14T16:20:03.264956"}}
{"event_type": "price_change", "event_ts": "2026-01-14T16:20:03.770016", "ingestion_ts": "2026-01-14T16:33:58.842229", "market_id": "0x2393ed0b0fdc450054c7b9071907eca75cf4fc36e385adf4a0a5f99ee62243e8", "raw": {"market": "0x2393ed0b0fdc450054c7b9071907eca75cf4fc36e385adf4a0a5f99ee62243e8", "asset_id": "32769749367306925959219403371425714180265458150646381231272229429098460625924", "price": "0.151", "size": "0", "side": "BUY", "timestamp": "1768404002465", "received_at": "2026-01-14T16:20:03.770016"}}
{"event_type": "price_change", "event_ts": "2026-01-14T16:20:03.770016", "ingestion_ts": "2026-01-14T16:33:58.842229", "market_id": "0x2393ed0b0fdc450054c7b9071907eca75cf4fc36e385adf4a0a5f99ee62243e8", "raw": {"market": "0x2393ed0b0fdc450054c7b9071907eca75cf4fc36e385adf4a0a5f99ee62243e8", "asset_id": "100074770378634056601572485653252702850363676459996771990439989989293515601975", "price": "0.849", "size": "0", "side": "SELL", "timestamp": "1768404002465", "received_at": "2026-01-14T16:20:03.770016"}}
{"event_type": "price_change", "event_ts": "2026-01-14T16:20:03.796415", "ingestion_ts": "2026-01-14T16:33:58.842229", "market_id": "0x2393ed0b0fdc450054c7b9071907eca75cf4fc36e385adf4a0a5f99ee62243e8", "raw": {"market": "0x2393ed0b0fdc450054c7b9071907eca75cf4fc36e385adf4a0a5f99ee62243e8", "asset_id": "32769749367306925959219403371425714180265458150646381231272229429098460625924", "price": "0.191", "size": "0", "side": "BUY", "timestamp": "1768404002600", "received_at": "2026-01-14T16:20:03.796415"}}
{"event_type": "price_change", "event_ts": "2026-01-14T16:20:03.796415", "ingestion_ts": "2026-01-14T16:33:58.842229", "market_id": "0x2393ed0b0fdc450054c7b9071907eca75cf4fc36e385adf4a0a5f99ee62243e8", "raw": {"market": "0x2393ed0b0fdc450054c7b9071907eca75cf4fc36e385adf4a0a5f99ee62243e8", "asset_id": "100074770378634056601572485653252702850363676459996771990439989989293515601975", "price": "0.809", "size": "0", "side": "SELL", "timestamp": "1768404002600", "received_at": "2026-01-14T16:20:03.796415"}}
{"event_type": "price_change", "event_ts": "2026-01-14T16:20:03.800739", "ingestion_ts": "2026-01-14T16:33:58.842229", "market_id": "0x2393ed0b0fdc450054c7b9071907eca75cf4fc36e385adf4a0a5f99ee62243e8", "raw": {"market": "0x2393ed0b0fdc450054c7b9071907eca75cf4fc36e385adf4a0a5f99ee62243e8", "asset_id": "32769749367306925959219403371425714180265458150646381231272229429098460625924", "price": "0.113", "size": "100", "side": "BUY", "timestamp": "1768404002604", "received_at": "2026-01-14T16:20:03.800739"}}
{"event_type": "price_change", "event_ts": "2026-01-14T16:20:03.800739", "ingestion_ts": "2026-01-14T16:33:58.842229", "market_id": "0x2393ed0b0fdc450054c7b9071907eca75cf4fc36e385adf4a0a5f99ee62243e8", "raw": {"market": "0x2393ed0b0fdc450054c7b9071907eca75cf4fc36e385adf4a0a5f99ee62243e8", "asset_id": "100074770378634056601572485653252702850363676459996771990439989989293515601975", "price": "0.887", "size": "100", "side": "SELL", "timestamp": "1768404002604", "received_at": "2026-01-14T16:20:03.800739"}}
{"event_type": "price_change", "event_ts": "2026-01-14T16:20:03.895338", "ingestion_ts": "2026-01-14T16:33:58.842229", "market_id": "0x318b222c1435b47c338e66ca6001f782711186a488ae7b7248f7edc6ff076a83", "raw": {"market": "0x318b222c1435b47c338e66ca6001f782711186a488ae7b7248f7edc6ff076a83", "asset_id": "63773739594775606083258239254748928077067768053882704658119720069071630213026", "price": "0.151", "size": "0", "side": "BUY", "timestamp": "1768404002467", "received_at": "2026-01-14T16:20:03.895338"}}
{"event_type": "price_change", "event_ts": "2026-01-14T16:20:03.895338", "ingestion_ts": "2026-01-14T16:33:58.842229", "market_id": "0x318b222c1435b47c338e66ca6001f782711186a488ae7b7248f7edc6ff076a83", "raw": {"market": "0x318b222c1435b47c338e66ca6001f782711186a488ae7b7248f7edc6ff076a83", "asset_id": "56738600572035832904895845056468792275697823297413384908752239327866518310010", "price": "0.849", "size": "0", "side": "SELL", "timestamp": "1768404002467", "received_at": "2026-01-14T16:20:03.895338"}}
{"event_type": "price_change", "event_ts": "2026-01-14T16:20:03.904007", "ingestion_ts": "2026-01-14T16:33:58.842229", "market_id": "0x318b222c1435b47c338e66ca6001f782711186a488ae7b7248f7edc6ff076a83", "raw": {"market": "0x318b222c1435b47c338e66ca6001f782711186a488ae7b7248f7edc6ff076a83", "asset_id": "63773739594775606083258239254748928077067768053882704658119720069071630213026", "price": "0.203", "size": "0", "side": "BUY", "timestamp": "1768404002613", "received_at": "2026-01-14T16:20:03.904007"}}
{"event_type": "price_change", "event_ts": "2026-01-14T16:20:03.904007", "ingestion_ts": "2026-01-14T16:33:58.842229", "market_id": "0x318b222c1435b47c338e66ca6001f782711186a488ae7b7248f7edc6ff076a83", "raw": {"market": "0x318b222c1435b47c338e66ca6001f782711186a488ae7b7248f7edc6ff076a83", "asset_id": "56738600572035832904895845056468792275697823297413384908752239327866518310010", "price": "0.797", "size": "0", "side": "SELL", "timestamp": "1768404002613", "received_at": "2026-01-14T16:20:03.904007"}}
{"event_type": "price_change", "event_ts": "2026-01-14T16:20:03.927363", "ingestion_ts": "2026-01-14T16:33:58.842229", "market_id": "0x318b222c1435b47c338e66ca6001f782711186a488ae7b7248f7edc6ff076a83", "raw": {"market": "0x318b222c1435b47c338e66ca6001f782711186a488ae7b7248f7edc6ff076a83", "asset_id": "63773739594775606083258239254748928077067768053882704658119720069071630213026", "price": "0.128", "size": "100", "side": "BUY", "timestamp": "1768404002614", "received_at": "2026-01-14T16:20:03.927363"}}
{"event_type": "price_change", "event_ts": "2026-01-14T16:20:03.927363", "ingestion_ts": "2026-01-14T16:33:58.842229", "market_id": "0x318b222c1435b47c338e66ca6001f782711186a488ae7b7248f7edc6ff076a83", "raw": {"market": "0x318b222c1435b47c338e66ca6001f782711186a488ae7b7248f7edc6ff076a83", "asset_id": "56738600572035832904895845056468792275697823297413384908752239327866518310010", "price": "0.872", "size": "100", "side": "SELL", "timestamp": "1768404002614", "received_at": "2026-01-14T16:20:03.927363"}}
{"event_type": "price_change", "event_ts": "2026-01-14T16:20:05.087420", "ingestion_ts": "2026-01-14T16:33:58.842229", "market_id": "0xc55db914f0fd1fee18997706712c0dfd8d0369cdbef93a9fef12bd001914ca77", "raw": {"market": "0xc55db914f0fd1fee18997706712c0dfd8d0369cdbef93a9fef12bd001914ca77", "asset_id": "114600293444080540179603459515770723592661967180480327891296353898330242622833", "price": "0.925", "size": "0", "side": "BUY", "timestamp": "1768404003699", "received_at": "2026-01-14T16:20:05.087420"}}
{"event_type": "price_change", "event_ts": "2026-01-14T16:20:05.087420", "ingestion_ts": "2026-01-14T16:33:58.842229", "market_id": "0xc55db914f0fd1fee18997706712c0dfd8d0369cdbef93a9fef12bd001914ca77", "raw": {"market": "0xc55db914f0fd1fee18997706712c0dfd8d0369cdbef93a9fef12bd001914ca77", "asset_id": "72354723612769247426741660426331235762851940382312402276325808095604519806766", "price": "0.075", "size": "0", "side": "SELL", "timestamp": "1768404003699", "received_at": "2026-01-14T16:20:05.087420"}}
{"event_type": "price_change", "event_ts": "2026-01-14T16:20:05.939561", "ingestion_ts": "2026-01-14T16:33:58.842229", "market_id": "0x49686d26fb712515cd5e12c23f0a1c7e10214c7faa3cb0a730aabe0c33694082", "raw": {"market": "0x49686d26fb712515cd5e12c23f0a1c7e10214c7faa3cb0a730aabe0c33694082", "asset_id": "13244681086321087932946246027856416106585284024824496763706748621681543444582", "price": "0.851", "size": "500", "side": "BUY", "timestamp": "1768404004805", "received_at": "2026-01-14T16:20:05.939561"}}
{"event_type": "price_change", "event_ts": "2026-01-14T16:20:05.939561", "ingestion_ts": "2026-01-14T16:33:58.842229", "market_id": "0x49686d26fb712515cd5e12c23f0a1c7e10214c7faa3cb0a730aabe0c33694082", "raw": {"market": "0x49686d26fb712515cd5e12c23f0a1c7e10214c7faa3cb0a730aabe0c33694082", "asset_id": "30442780799048074404860985387051749017905070253466005720364298335239299761065", "price": "0.149", "size": "500", "side": "SELL", "timestamp": "1768404004805", "received_at": "2026-01-14T16:20:05.939561"}}
{"event_type": "price_change", "event_ts": "2026-01-14T16:20:06.835605", "ingestion_ts": "2026-01-14T16:33:58.842229", "market_id": "0x49686d26fb712515cd5e12c23f0a1c7e10214c7faa3cb0a730aabe0c33694082", "raw": {"market": "0x49686d26fb712515cd5e12c23f0a1c7e10214c7faa3cb0a730aabe0c33694082", "asset_id": "13244681086321087932946246027856416106585284024824496763706748621681543444582", "price": "0.898", "size": "0", "side": "SELL", "timestamp": "1768404005902", "received_at": "2026-01-14T16:20:06.835605"}}
{"event_type": "price_change", "event_ts": "2026-01-14T16:20:06.835605", "ingestion_ts": "2026-01-14T16:33:58.842229", "market_id": "0x49686d26fb712515cd5e12c23f0a1c7e10214c7faa3cb0a730aabe0c33694082", "raw": {"market": "0x49686d26fb712515cd5e12c23f0a1c7e10214c7faa3cb0a730aabe0c33694082", "asset_id": "30442780799048074404860985387051749017905070253466005720364298335239299761065", "price": "0.102", "size": "0", "side": "BUY", "timestamp": "1768404005902", "received_at": "2026-01-14T16:20:06.835605"}}
{"event_type": "price_change", "event_ts": "2026-01-14T16:20:06.849671", "ingestion_ts": "2026-01-14T16:33:58.842229", "market_id": "0x49686d26fb712515cd5e12c23f0a1c7e10214c7faa3cb0a730aabe0c33694082", "raw": {"market": "0x49686d26fb712515cd5e12c23f0a1c7e10214c7faa3cb0a730aabe0c33694082", "asset_id": "13244681086321087932946246027856416106585284024824496763706748621681543444582", "price": "0.907", "size": "116", "side": "SELL", "timestamp": "1768404005960", "received_at": "2026-01-14T16:20:06.849671"}}
{"event_type": "price_change", "event_ts": "2026-01-14T16:20:06.849671", "ingestion_ts": "2026-01-14T16:33:58.842229", "market_id": "0x49686d26fb712515cd5e12c23f0a1c7e10214c7faa3cb0a730aabe0c33694082", "raw": {"market": "0x49686d26fb712515cd5e12c23f0a1c7e10214c7faa3cb0a730aabe0c33694082", "asset_id": "30442780799048074404860985387051749017905070253466005720364298335239299761065", "price": "0.093", "size": "116", "side": "BUY", "timestamp": "1768404005960", "received_at": "2026-01-14T16:20:06.849671"}}
{"event_type": "price_change", "event_ts": "2026-01-14T16:20:07.951078", "ingestion_ts": "2026-01-14T16:33:58.842229", "market_id": "0xb9bbdd34304344dcc45803780a34c97d73a00133a5ecf70f63e1008b8abb2fca", "raw": {"market": "0xb9bbdd34304344dcc45803780a34c97d73a00133a5ecf70f63e1008b8abb2fca", "asset_id": "8682484153073832526711485265636767086525069344085206423986003504588877767339", "price": "0.924", "size": "0", "side": "BUY", "timestamp": "1768404007092", "received_at": "2026-01-14T16:20:07.951078"}}
{"event_type": "price_change", "event_ts": "2026-01-14T16:20:07.951078", "ingestion_ts": "2026-01-14T16:33:58.842229", "market_id": "0xb9bbdd34304344dcc45803780a34c97d73a00133a5ecf70f63e1008b8abb2fca", "raw": {"market": "0xb9bbdd34304344dcc45803780a34c97d73a00133a5ecf70f63e1008b8abb2fca", "asset_id": "72012724360700510767037780555710363830014634797787940282136454146828040926557", "price": "0.076", "size": "0", "side": "SELL", "timestamp": "1768404007092", "received_at": "2026-01-14T16:20:07.951078"}}
{"event_type": "price_change", "event_ts": "2026-01-14T16:20:07.951114", "ingestion_ts": "2026-01-14T16:33:58.842229", "market_id": "0xc55db914f0fd1fee18997706712c0dfd8d0369cdbef93a9fef12bd001914ca77", "raw": {"market": "0xc55db914f0fd1fee18997706712c0dfd8d0369cdbef93a9fef12bd001914ca77", "asset_id": "114600293444080540179603459515770723592661967180480327891296353898330242622833", "price": "0.838", "size": "0", "side": "BUY", "timestamp": "1768404007092", "received_at": "2026-01-14T16:20:07.951114"}}
{"event_type": "price_change", "event_ts": "2026-01-14T16:20:07.951114", "ingestion_ts": "2026-01-14T16:33:58.842229", "market_id": "0xc55db914f0fd1fee18997706712c0dfd8d0369cdbef93a9fef12bd001914ca77", "raw": {"market": "0xc55db914f0fd1fee18997706712c0dfd8d0369cdbef93a9fef12bd001914ca77", "asset_id": "72354723612769247426741660426331235762851940382312402276325808095604519806766", "price": "0.162", "size": "0", "side": "SELL", "timestamp": "1768404007092", "received_at": "2026-01-14T16:20:07.951114"}}
{"event_type": "price_change", "event_ts": "2026-01-14T16:20:08.746055", "ingestion_ts": "2026-01-14T16:33:58.842229", "market_id": "0xc55db914f0fd1fee18997706712c0dfd8d0369cdbef93a9fef12bd001914ca77", "raw": {"market": "0xc55db914f0fd1fee18997706712c0dfd8d0369cdbef93a9fef12bd001914ca77", "asset_id": "114600293444080540179603459515770723592661967180480327891296353898330242622833", "price": "0.925", "size": "20", "side": "BUY", "timestamp": "1768404007946", "received_at": "2026-01-14T16:20:08.746055"}}
{"event_type": "price_change", "event_ts": "2026-01-14T16:20:08.746055", "ingestion_ts": "2026-01-14T16:33:58.842229", "market_id": "0xc55db914f0fd1fee18997706712c0dfd8d0369cdbef93a9fef12bd001914ca77", "raw": {"market": "0xc55db914f0fd1fee18997706712c0dfd8d0369cdbef93a9fef12bd001914ca77", "asset_id": "72354723612769247426741660426331235762851940382312402276325808095604519806766", "price": "0.075", "size": "20", "side": "SELL", "timestamp": "1768404007946", "received_at": "2026-01-14T16:20:08.746055"}}
{"event_type": "price_change", "event_ts": "2026-01-14T16:20:08.762239", "ingestion_ts": "2026-01-14T16:33:58.842229", "market_id": "0xc55db914f0fd1fee18997706712c0dfd8d0369cdbef93a9fef12bd001914ca77", "raw": {"market": "0xc55db914f0fd1fee18997706712c0dfd8d0369cdbef93a9fef12bd001914ca77", "asset_id": "114600293444080540179603459515770723592661967180480327891296353898330242622833", "price": "0.838", "size": "10", "side": "BUY", "timestamp": "1768404007947", "received_at": "2026-01-14T16:20:08.762239"}}
{"event_type": "price_change", "event_ts": "2026-01-14T16:20:08.762239", "ingestion_ts": "2026-01-14T16:33:58.842229", "market_id": "0xc55db914f0fd1fee18997706712c0dfd8d0369cdbef93a9fef12bd001914ca77", "raw": {"market": "0xc55db914f0fd1fee18997706712c0dfd8d0369cdbef93a9fef12bd001914ca77", "asset_id": "72354723612769247426741660426331235762851940382312402276325808095604519806766", "price": "0.162", "size": "10", "side": "SELL", "timestamp": "1768404007947", "received_at": "2026-01-14T16:20:08.762239"}}
{"event_type": "price_change", "event_ts": "2026-01-14T16:20:10.337455", "ingestion_ts": "2026-01-14T16:33:58.842229", "market_id": "0xe9c127a8c35f045d37b5344b0a36711084fa20c2fc1618bf178a5386f90610be", "raw": {"market": "0xe9c127a8c35f045d37b5344b0a36711084fa20c2fc1618bf178a5386f90610be", "asset_id": "107000426448217931795450451304515386602910396776318075817601265223856116134349", "price": "0.414", "size": "0", "side": "BUY", "timestamp": "1768404009869", "received_at": "2026-01-14T16:20:10.337455"}}
{"event_type": "price_change", "event_ts": "2026-01-14T16:20:10.337455", "ingestion_ts": "2026-01-14T16:33:58.842229", "market_id": "0xe9c127a8c35f045d37b5344b0a36711084fa20c2fc1618bf178a5386f90610be", "raw": {"market": "0xe9c127a8c35f045d37b5344b0a36711084fa20c2fc1618bf178a5386f90610be", "asset_id": "80230236018433940569996058935444651347308266584430516013229815570706872276819", "price": "0.586", "size": "0", "side": "SELL", "timestamp": "1768404009869", "received_at": "2026-01-14T16:20:10.337455"}}
{"event_type": "price_change", "event_ts": "2026-01-14T16:20:10.547205", "ingestion_ts": "2026-01-14T16:33:58.842229", "market_id": "0xe9c127a8c35f045d37b5344b0a36711084fa20c2fc1618bf178a5386f90610be", "raw": {"market": "0xe9c127a8c35f045d37b5344b0a36711084fa20c2fc1618bf178a5386f90610be", "asset_id": "107000426448217931795450451304515386602910396776318075817601265223856116134349", "price": "0.372", "size": "0", "side": "BUY", "timestamp": "1768404010096", "received_at": "2026-01-14T16:20:10.547205"}}
{"event_type": "price_change", "event_ts": "2026-01-14T16:20:10.547205", "ingestion_ts": "2026-01-14T16:33:58.842229", "market_id": "0xe9c127a8c35f045d37b5344b0a36711084fa20c2fc1618bf178a5386f90610be", "raw": {"market": "0xe9c127a8c35f045d37b5344b0a36711084fa20c2fc1618bf178a5386f90610be", "asset_id": "80230236018433940569996058935444651347308266584430516013229815570706872276819", "price": "0.628", "size": "0", "side": "SELL", "timestamp": "1768404010096", "received_at": "2026-01-14T16:20:10.547205"}}
{"event_type": "price_change", "event_ts": "2026-01-14T16:20:10.577670", "ingestion_ts": "2026-01-14T16:33:58.842229", "market_id": "0x49686d26fb712515cd5e12c23f0a1c7e10214c7faa3cb0a730aabe0c33694082", "raw": {"market": "0x49686d26fb712515cd5e12c23f0a1c7e10214c7faa3cb0a730aabe0c33694082", "asset_id": "30442780799048074404860985387051749017905070253466005720364298335239299761065", "price": "0.094", "size": "50", "side": "BUY", "timestamp": "1768404010155", "received_at": "2026-01-14T16:20:10.577670"}}
{"event_type": "price_change", "event_ts": "2026-01-14T16:20:10.577670", "ingestion_ts": "2026-01-14T16:33:58.842229", "market_id": "0x49686d26fb712515cd5e12c23f0a1c7e10214c7faa3cb0a730aabe0c33694082", "raw": {"market": "0x49686d26fb712515cd5e12c23f0a1c7e10214c7faa3cb0a730aabe0c33694082", "asset_id": "13244681086321087932946246027856416106585284024824496763706748621681543444582", "price": "0.906", "size": "50", "side": "SELL", "timestamp": "1768404010155", "received_at": "2026-01-14T16:20:10.577670"}}
{"event_type": "price_change", "event_ts": "2026-01-14T16:20:10.612291", "ingestion_ts": "2026-01-14T16:33:58.842229", "market_id": "0x49686d26fb712515cd5e12c23f0a1c7e10214c7faa3cb0a730aabe0c33694082", "raw": {"market": "0x49686d26fb712515cd5e12c23f0a1c7e10214c7faa3cb0a730aabe0c33694082", "asset_id": "13244681086321087932946246027856416106585284024824496763706748621681543444582", "price": "0.907", "size": "0", "side": "SELL", "timestamp": "1768404010197", "received_at": "2026-01-14T16:20:10.612291"}}
{"event_type": "price_change", "event_ts": "2026-01-14T16:20:10.612291", "ingestion_ts": "2026-01-14T16:33:58.842229", "market_id": "0x49686d26fb712515cd5e12c23f0a1c7e10214c7faa3cb0a730aabe0c33694082", "raw": {"market": "0x49686d26fb712515cd5e12c23f0a1c7e10214c7faa3cb0a730aabe0c33694082", "asset_id": "30442780799048074404860985387051749017905070253466005720364298335239299761065", "price": "0.093", "size": "0", "side": "BUY", "timestamp": "1768404010197", "received_at": "2026-01-14T16:20:10.612291"}}
{"event_type": "price_change", "event_ts": "2026-01-14T16:20:10.639157", "ingestion_ts": "2026-01-14T16:33:58.842229", "market_id": "0x49686d26fb712515cd5e12c23f0a1c7e10214c7faa3cb0a730aabe0c33694082", "raw": {"market": "0x49686d26fb712515cd5e12c23f0a1c7e10214c7faa3cb0a730aabe0c33694082", "asset_id": "13244681086321087932946246027856416106585284024824496763706748621681543444582", "price": "0.898", "size": "117", "side": "SELL", "timestamp": "1768404010236", "received_at": "2026-01-14T16:20:10.639157"}}
{"event_type": "price_change", "event_ts": "2026-01-14T16:20:10.639157", "ingestion_ts": "2026-01-14T16:33:58.842229", "market_id": "0x49686d26fb712515cd5e12c23f0a1c7e10214c7faa3cb0a730aabe0c33694082", "raw": {"market": "0x49686d26fb712515cd5e12c23f0a1c7e10214c7faa3cb0a730aabe0c33694082", "asset_id": "30442780799048074404860985387051749017905070253466005720364298335239299761065", "price": "0.102", "size": "117", "side": "BUY", "timestamp": "1768404010236", "received_at": "2026-01-14T16:20:10.639157"}}
{"event_type": "price_change", "event_ts": "2026-01-14T16:20:10.699608", "ingestion_ts": "2026-01-14T16:33:58.842229", "market_id": "0xe9c127a8c35f045d37b5344b0a36711084fa20c2fc1618bf178a5386f90610be", "raw": {"market": "0xe9c127a8c35f045d37b5344b0a36711084fa20c2fc1618bf178a5386f90610be", "asset_id": "107000426448217931795450451304515386602910396776318075817601265223856116134349", "price": "0.022", "size": "0", "side": "BUY", "timestamp": "1768404010331", "received_at": "2026-01-14T16:20:10.699608"}}
{"event_type": "price_change", "event_ts": "2026-01-14T16:20:10.699608", "ingestion_ts": "2026-01-14T16:33:58.842229", "market_id": "0xe9c127a8c35f045d37b5344b0a36711084fa20c2fc1618bf178a5386f90610be", "raw": {"market": "0xe9c127a8c35f045d37b5344b0a36711084fa20c2fc1618bf178a5386f90610be", "asset_id": "80230236018433940569996058935444651347308266584430516013229815570706872276819", "price": "0.978", "size": "0", "side": "SELL", "timestamp": "1768404010331", "received_at": "2026-01-14T16:20:10.699608"}}
{"event_type": "price_change", "event_ts": "2026-01-14T16:20:10.725956", "ingestion_ts": "2026-01-14T16:33:58.842229", "market_id": "0x49686d26fb712515cd5e12c23f0a1c7e10214c7faa3cb0a730aabe0c33694082", "raw": {"market": "0x49686d26fb712515cd5e12c23f0a1c7e10214c7faa3cb0a730aabe0c33694082", "asset_id": "30442780799048074404860985387051749017905070253466005720364298335239299761065", "price": "0.039", "size": "0", "side": "BUY", "timestamp": "1768404010394", "received_at": "2026-01-14T16:20:10.725956"}}
{"event_type": "price_change", "event_ts": "2026-01-14T16:20:10.725956", "ingestion_ts": "2026-01-14T16:33:58.842229", "market_id": "0x49686d26fb712515cd5e12c23f0a1c7e10214c7faa3cb0a730aabe0c33694082", "raw": {"market": "0x49686d26fb712515cd5e12c23f0a1c7e10214c7faa3cb0a730aabe0c33694082", "asset_id": "13244681086321087932946246027856416106585284024824496763706748621681543444582", "price": "0.961", "size": "0", "side": "SELL", "timestamp": "1768404010394", "received_at": "2026-01-14T16:20:10.725956"}}
{"event_type": "price_change", "event_ts": "2026-01-14T16:20:10.815014", "ingestion_ts": "2026-01-14T16:33:58.842229", "market_id": "0x2393ed0b0fdc450054c7b9071907eca75cf4fc36e385adf4a0a5f99ee62243e8", "raw": {"market": "0x2393ed0b0fdc450054c7b9071907eca75cf4fc36e385adf4a0a5f99ee62243e8", "asset_id": "32769749367306925959219403371425714180265458150646381231272229429098460625924", "price": "0.875", "size": "0", "side": "BUY", "timestamp": "1768404010521", "received_at": "2026-01-14T16:20:10.815014"}}
{"event_type": "price_change", "event_ts": "2026-01-14T16:20:10.815014", "ingestion_ts": "2026-01-14T16:33:58.842229", "market_id": "0x2393ed0b0fdc450054c7b9071907eca75cf4fc36e385adf4a0a5f99ee62243e8", "raw": {"market": "0x2393ed0b0fdc450054c7b9071907eca75cf4fc36e385adf4a0a5f99ee62243e8", "asset_id": "100074770378634056601572485653252702850363676459996771990439989989293515601975", "price": "0.125", "size": "0", "side": "SELL", "timestamp": "1768404010521", "received_at": "2026-01-14T16:20:10.815014"}}
{"event_type": "price_change", "event_ts": "2026-01-14T16:20:10.815062", "ingestion_ts": "2026-01-14T16:33:58.842229", "market_id": "0x2393ed0b0fdc450054c7b9071907eca75cf4fc36e385adf4a0a5f99ee62243e8", "raw": {"market": "0x2393ed0b0fdc450054c7b9071907eca75cf4fc36e385adf4a0a5f99ee62243e8", "asset_id": "32769749367306925959219403371425714180265458150646381231272229429098460625924", "price": "0.814", "size": "0", "side": "BUY", "timestamp": "1768404010521", "received_at": "2026-01-14T16:20:10.815062"}}
{"event_type": "price_change", "event_ts": "2026-01-14T16:20:10.815062", "ingestion_ts": "2026-01-14T16:33:58.842229", "market_id": "0x2393ed0b0fdc450054c7b9071907eca75cf4fc36e385adf4a0a5f99ee62243e8", "raw": {"market": "0x2393ed0b0fdc450054c7b9071907eca75cf4fc36e385adf4a0a5f99ee62243e8", "asset_id": "100074770378634056601572485653252702850363676459996771990439989989293515601975", "price": "0.186", "size": "0", "side": "SELL", "timestamp": "1768404010521", "received_at": "2026-01-14T16:20:10.815062"}}
{"event_type": "price_change", "event_ts": "2026-01-14T16:20:10.827587", "ingestion_ts": "2026-01-14T16:33:58.842229", "market_id": "0x49686d26fb712515cd5e12c23f0a1c7e10214c7faa3cb0a730aabe0c33694082", "raw": {"market": "0x49686d26fb712515cd5e12c23f0a1c7e10214c7faa3cb0a730aabe0c33694082", "asset_id": "30442780799048074404860985387051749017905070253466005720364298335239299761065", "price": "0.042", "size": "20", "side": "BUY", "timestamp": "1768404010553", "received_at": "2026-01-14T16:20:10.827587"}}
{"event_type": "price_change", "event_ts": "2026-01-14T16:20:10.827587", "ingestion_ts": "2026-01-14T16:33:58.842229", "market_id": "0x49686d26fb712515cd5e12c23f0a1c7e10214c7faa3cb0a730aabe0c33694082", "raw": {"market": "0x49686d26fb712515cd5e12c23f0a1c7e10214c7faa3cb0a730aabe0c33694082", "asset_id": "13244681086321087932946246027856416106585284024824496763706748621681543444582", "price": "0.958", "size": "20", "side": "SELL", "timestamp": "1768404010553", "received_at": "2026-01-14T16:20:10.827587"}}
{"event_type": "price_change", "event_ts": "2026-01-14T16:20:10.842156", "ingestion_ts": "2026-01-14T16:33:58.842229", "market_id": "0xe9c127a8c35f045d37b5344b0a36711084fa20c2fc1618bf178a5386f90610be", "raw": {"market": "0xe9c127a8c35f045d37b5344b0a36711084fa20c2fc1618bf178a5386f90610be", "asset_id": "107000426448217931795450451304515386602910396776318075817601265223856116134349", "price": "0.022", "size": "181.81", "side": "BUY", "timestamp": "1768404010565", "received_at": "2026-01-14T16:20:10.842156"}}
{"event_type": "price_change", "event_ts": "2026-01-14T16:20:10.842156", "ingestion_ts": "2026-01-14T16:33:58.842229", "market_id": "0xe9c127a8c35f045d37b5344b0a36711084fa20c2fc1618bf178a5386f90610be", "raw": {"market": "0xe9c127a8c35f045d37b5344b0a36711084fa20c2fc1618bf178a5386f90610be", "asset_id": "80230236018433940569996058935444651347308266584430516013229815570706872276819", "price": "0.978", "size": "181.81", "side": "SELL", "timestamp": "1768404010565", "received_at": "2026-01-14T16:20:10.842156"}}
{"event_type": "price_change", "event_ts": "2026-01-14T16:20:10.903326", "ingestion_ts": "2026-01-14T16:33:58.842229", "market_id": "0x2393ed0b0fdc450054c7b9071907eca75cf4fc36e385adf4a0a5f99ee62243e8", "raw": {"market": "0x2393ed0b0fdc450054c7b9071907eca75cf4fc36e385adf4a0a5f99ee62243e8", "asset_id": "32769749367306925959219403371425714180265458150646381231272229429098460625924", "price": "0.877", "size": "20", "side": "BUY", "timestamp": "1768404010649", "received_at": "2026-01-14T16:20:10.903326"}}
{"event_type": "price_change", "event_ts": "2026-01-14T16:20:10.903326", "ingestion_ts": "2026-01-14T16:33:58.842229", "market_id": "0x2393ed0b0fdc450054c7b9071907eca75cf4fc36e385adf4a0a5f99ee62243e8", "raw": {"market": "0x2393ed0b0fdc450054c7b9071907eca75cf4fc36e385adf4a0a5f99ee62243e8", "asset_id": "100074770378634056601572485653252702850363676459996771990439989989293515601975", "price": "0.123", "size": "20", "side": "SELL", "timestamp": "1768404010649", "received_at": "2026-01-14T16:20:10.903326"}}
{"event_type": "price_change", "event_ts": "2026-01-14T16:20:10.903380", "ingestion_ts": "2026-01-14T16:33:58.842229", "market_id": "0x2393ed0b0fdc450054c7b9071907eca75cf4fc36e385adf4a0a5f99ee62243e8", "raw": {"market": "0x2393ed0b0fdc450054c7b9071907eca75cf4fc36e385adf4a0a5f99ee62243e8", "asset_id": "32769749367306925959219403371425714180265458150646381231272229429098460625924", "price": "0.814", "size": "10", "side": "BUY", "timestamp": "1768404010650", "received_at": "2026-01-14T16:20:10.903380"}}
{"event_type": "price_change", "event_ts": "2026-01-14T16:20:10.903380", "ingestion_ts": "2026-01-14T16:33:58.842229", "market_id": "0x2393ed0b0fdc450054c7b9071907eca75cf4fc36e385adf4a0a5f99ee62243e8", "raw": {"market": "0x2393ed0b0fdc450054c7b9071907eca75cf4fc36e385adf4a0a5f99ee62243e8", "asset_id": "100074770378634056601572485653252702850363676459996771990439989989293515601975", "price": "0.186", "size": "10", "side": "SELL", "timestamp": "1768404010650", "received_at": "2026-01-14T16:20:10.903380"}}
{"event_type": "price_change", "event_ts": "2026-01-14T16:20:10.987942", "ingestion_ts": "2026-01-14T16:33:58.842229", "market_id": "0xe9c127a8c35f045d37b5344b0a36711084fa20c2fc1618bf178a5386f90610be", "raw": {"market": "0xe9c127a8c35f045d37b5344b0a36711084fa20c2fc1618bf178a5386f90610be", "asset_id": "107000426448217931795450451304515386602910396776318075817601265223856116134349", "price": "0.034", "size": "0", "side": "BUY", "timestamp": "1768404010779", "received_at": "2026-01-14T16:20:10.987942"}}
{"event_type": "price_change", "event_ts": "2026-01-14T16:20:10.987942", "ingestion_ts": "2026-01-14T16:33:58.842229", "market_id": "0xe9c127a8c35f045d37b5344b0a36711084fa20c2fc1618bf178a5386f90610be", "raw": {"market": "0xe9c127a8c35f045d37b5344b0a36711084fa20c2fc1618bf178a5386f90610be", "asset_id": "80230236018433940569996058935444651347308266584430516013229815570706872276819", "price": "0.966", "size": "0", "side": "SELL", "timestamp": "1768404010779", "received_at": "2026-01-14T16:20:10.987942"}}
{"event_type": "price_change", "event_ts": "2026-01-14T16:20:11.110752", "ingestion_ts": "2026-01-14T16:33:58.842229", "market_id": "0xe9c127a8c35f045d37b5344b0a36711084fa20c2fc1618bf178a5386f90610be", "raw": {"market": "0xe9c127a8c35f045d37b5344b0a36711084fa20c2fc1618bf178a5386f90610be", "asset_id": "107000426448217931795450451304515386602910396776318075817601265223856116134349", "price": "0.034", "size": "117.64", "side": "BUY", "timestamp": "1768404010991", "received_at": "2026-01-14T16:20:11.110752"}}
{"event_type": "price_change", "event_ts": "2026-01-14T16:20:11.110752", "ingestion_ts": "2026-01-14T16:33:58.842229", "market_id": "0xe9c127a8c35f045d37b5344b0a36711084fa20c2fc1618bf178a5386f90610be", "raw": {"market": "0xe9c127a8c35f045d37b5344b0a36711084fa20c2fc1618bf178a5386f90610be", "asset_id": "80230236018433940569996058935444651347308266584430516013229815570706872276819", "price": "0.966", "size": "117.64", "side": "SELL", "timestamp": "1768404010991", "received_at": "2026-01-14T16:20:11.110752"}}
{"event_type": "price_change", "event_ts": "2026-01-14T16:20:11.167317", "ingestion_ts": "2026-01-14T16:33:58.842229", "market_id": "0x49a20c7523c271099008f3ef9a31521263b24d637959852a391e6b4697b1a437", "raw": {"market": "0x49a20c7523c271099008f3ef9a31521263b24d637959852a391e6b4697b1a437", "asset_id": "55881023621710858558280545117465775643848233756850602339827152783696837905531", "price": "0.927", "size": "0", "side": "BUY", "timestamp": "1768404011072", "received_at": "2026-01-14T16:20:11.167317"}}
{"event_type": "price_change", "event_ts": "2026-01-14T16:20:11.167317", "ingestion_ts": "2026-01-14T16:33:58.842229", "market_id": "0x49a20c7523c271099008f3ef9a31521263b24d637959852a391e6b4697b1a437", "raw": {"market": "0x49a20c7523c271099008f3ef9a31521263b24d637959852a391e6b4697b1a437", "asset_id": "13018971792603393862521629014128024641178044618205296260525674415067194037856", "price": "0.073", "size": "0", "side": "SELL", "timestamp": "1768404011072", "received_at": "2026-01-14T16:20:11.167317"}}
{"event_type": "price_change", "event_ts": "2026-01-14T16:20:11.167387", "ingestion_ts": "2026-01-14T16:33:58.842229", "market_id": "0x2393ed0b0fdc450054c7b9071907eca75cf4fc36e385adf4a0a5f99ee62243e8", "raw": {"market": "0x2393ed0b0fdc450054c7b9071907eca75cf4fc36e385adf4a0a5f99ee62243e8", "asset_id": "32769749367306925959219403371425714180265458150646381231272229429098460625924", "price": "0.867", "size": "0", "side": "BUY", "timestamp": "1768404011072", "received_at": "2026-01-14T16:20:11.167387"}}
{"event_type": "price_change", "event_ts": "2026-01-14T16:20:11.167387", "ingestion_ts": "2026-01-14T16:33:58.842229", "market_id": "0x2393ed0b0fdc450054c7b9071907eca75cf4fc36e385adf4a0a5f99ee62243e8", "raw": {"market": "0x2393ed0b0fdc450054c7b9071907eca75cf4fc36e385adf4a0a5f99ee62243e8", "asset_id": "100074770378634056601572485653252702850363676459996771990439989989293515601975", "price": "0.133", "size": "0", "side": "SELL", "timestamp": "1768404011072", "received_at": "2026-01-14T16:20:11.167387"}}
{"event_type": "price_change", "event_ts": "2026-01-14T16:20:11.167411", "ingestion_ts": "2026-01-14T16:33:58.842229", "market_id": "0x49686d26fb712515cd5e12c23f0a1c7e10214c7faa3cb0a730aabe0c33694082", "raw": {"market": "0x49686d26fb712515cd5e12c23f0a1c7e10214c7faa3cb0a730aabe0c33694082", "asset_id": "30442780799048074404860985387051749017905070253466005720364298335239299761065", "price": "0.074", "size": "0", "side": "BUY", "timestamp": "1768404011072", "received_at": "2026-01-14T16:20:11.167411"}}
{"event_type": "price_change", "event_ts": "2026-01-14T16:20:11.167411", "ingestion_ts": "2026-01-14T16:33:58.842229", "market_id": "0x49686d26fb712515cd5e12c23f0a1c7e10214c7faa3cb0a730aabe0c33694082", "raw": {"market": "0x49686d26fb712515cd5e12c23f0a1c7e10214c7faa3cb0a730aabe0c33694082", "asset_id": "13244681086321087932946246027856416106585284024824496763706748621681543444582", "price": "0.926", "size": "0", "side": "SELL", "timestamp": "1768404011072", "received_at": "2026-01-14T16:20:11.167411"}}
{"event_type": "price_change", "event_ts": "2026-01-14T16:20:11.167434", "ingestion_ts": "2026-01-14T16:33:58.842229", "market_id": "0x9472be65457510b7fc3477b20ba90910e99d92eac8421a14bf4b7b7a08ef31dc", "raw": {"market": "0x9472be65457510b7fc3477b20ba90910e99d92eac8421a14bf4b7b7a08ef31dc", "asset_id": "43311793366960417907757893276427136943959788721376762326430771171648759300146", "price": "0.824", "size": "0", "side": "BUY", "timestamp": "1768404011072", "received_at": "2026-01-14T16:20:11.167434"}}
{"event_type": "price_change", "event_ts": "2026-01-14T16:20:11.167434", "ingestion_ts": "2026-01-14T16:33:58.842229", "market_id": "0x9472be65457510b7fc3477b20ba90910e99d92eac8421a14bf4b7b7a08ef31dc", "raw": {"market": "0x9472be65457510b7fc3477b20ba90910e99d92eac8421a14bf4b7b7a08ef31dc", "asset_id": "73414222381656326204771753454630063673548497164758947581648273905027617570612", "price": "0.176", "size": "0", "side": "SELL", "timestamp": "1768404011072", "received_at": "2026-01-14T16:20:11.167434"}}
{"event_type": "price_change", "event_ts": "2026-01-14T16:20:11.167455", "ingestion_ts": "2026-01-14T16:33:58.842229", "market_id": "0xaf9d0e448129a9f657f851d49495ba4742055d80e0ef1166ba0ee81d4d594214", "raw": {"market": "0xaf9d0e448129a9f657f851d49495ba4742055d80e0ef1166ba0ee81d4d594214", "asset_id": "4153292802911610701832309484716814274802943278345248636922528170020319407796", "price": "0.727", "size": "0", "side": "BUY", "timestamp": "1768404011072", "received_at": "2026-01-14T16:20:11.167455"}}
{"event_type": "price_change", "event_ts": "2026-01-14T16:20:11.167455", "ingestion_ts": "2026-01-14T16:33:58.842229", "market_id": "0xaf9d0e448129a9f657f851d49495ba4742055d80e0ef1166ba0ee81d4d594214", "raw": {"market": "0xaf9d0e448129a9f657f851d49495ba4742055d80e0ef1166ba0ee81d4d594214", "asset_id": "101676997363687199724245607342877036148401850938023978421879460310389391082353", "price": "0.273", "size": "0", "side": "SELL", "timestamp": "1768404011072", "received_at": "2026-01-14T16:20:11.167455"}}
{"event_type": "price_change", "event_ts": "2026-01-14T16:20:11.296267", "ingestion_ts": "2026-01-14T16:33:58.842229", "market_id": "0xe9c127a8c35f045d37b5344b0a36711084fa20c2fc1618bf178a5386f90610be", "raw": {"market": "0xe9c127a8c35f045d37b5344b0a36711084fa20c2fc1618bf178a5386f90610be", "asset_id": "107000426448217931795450451304515386602910396776318075817601265223856116134349", "price": "0.057", "size": "0", "side": "BUY", "timestamp": "1768404011187", "received_at": "2026-01-14T16:20:11.296267"}}
{"event_type": "price_change", "event_ts": "2026-01-14T16:20:11.296267", "ingestion_ts": "2026-01-14T16:33:58.842229", "market_id": "0xe9c127a8c35f045d37b5344b0a36711084fa20c2fc1618bf178a5386f90610be", "raw": {"market": "0xe9c127a8c35f045d37b5344b0a36711084fa20c2fc1618bf178a5386f90610be", "asset_id": "80230236018433940569996058935444651347308266584430516013229815570706872276819", "price": "0.943", "size": "0", "side": "SELL", "timestamp": "1768404011187", "received_at": "2026-01-14T16:20:11.296267"}}
{"event_type": "price_change", "event_ts": "2026-01-14T16:20:11.343771", "ingestion_ts": "2026-01-14T16:33:58.842229", "market_id": "0x9472be65457510b7fc3477b20ba90910e99d92eac8421a14bf4b7b7a08ef31dc", "raw": {"market": "0x9472be65457510b7fc3477b20ba90910e99d92eac8421a14bf4b7b7a08ef31dc", "asset_id": "43311793366960417907757893276427136943959788721376762326430771171648759300146", "price": "0.827", "size": "25", "side": "BUY", "timestamp": "1768404011247", "received_at": "2026-01-14T16:20:11.343771"}}
{"event_type": "price_change", "event_ts": "2026-01-14T16:20:11.343771", "ingestion_ts": "2026-01-14T16:33:58.842229", "market_id": "0x9472be65457510b7fc3477b20ba90910e99d92eac8421a14bf4b7b7a08ef31dc", "raw": {"market": "0x9472be65457510b7fc3477b20ba90910e99d92eac8421a14bf4b7b7a08ef31dc", "asset_id": "73414222381656326204771753454630063673548497164758947581648273905027617570612", "price": "0.173", "size": "25", "side": "SELL", "timestamp": "1768404011247", "received_at": "2026-01-14T16:20:11.343771"}}
{"event_type": "price_change", "event_ts": "2026-01-14T16:20:11.343826", "ingestion_ts": "2026-01-14T16:33:58.842229", "market_id": "0x2393ed0b0fdc450054c7b9071907eca75cf4fc36e385adf4a0a5f99ee62243e8", "raw": {"market": "0x2393ed0b0fdc450054c7b9071907eca75cf4fc36e385adf4a0a5f99ee62243e8", "asset_id": "32769749367306925959219403371425714180265458150646381231272229429098460625924", "price": "0.878", "size": "25", "side": "BUY", "timestamp": "1768404011247", "received_at": "2026-01-14T16:20:11.343826"}}
{"event_type": "price_change", "event_ts": "2026-01-14T16:20:11.343826", "ingestion_ts": "2026-01-14T16:33:58.842229", "market_id": "0x2393ed0b0fdc450054c7b9071907eca75cf4fc36e385adf4a0a5f99ee62243e8", "raw": {"market": "0x2393ed0b0fdc450054c7b9071907eca75cf4fc36e385adf4a0a5f99ee62243e8", "asset_id": "100074770378634056601572485653252702850363676459996771990439989989293515601975", "price": "0.122", "size": "25", "side": "SELL", "timestamp": "1768404011247", "received_at": "2026-01-14T16:20:11.343826"}}
{"event_type": "price_change", "event_ts": "2026-01-14T16:20:11.343845", "ingestion_ts": "2026-01-14T16:33:58.842229", "market_id": "0x49686d26fb712515cd5e12c23f0a1c7e10214c7faa3cb0a730aabe0c33694082", "raw": {"market": "0x49686d26fb712515cd5e12c23f0a1c7e10214c7faa3cb0a730aabe0c33694082", "asset_id": "30442780799048074404860985387051749017905070253466005720364298335239299761065", "price": "0.075", "size": "25", "side": "BUY", "timestamp": "1768404011247", "received_at": "2026-01-14T16:20:11.343845"}}
{"event_type": "price_change", "event_ts": "2026-01-14T16:20:11.343845", "ingestion_ts": "2026-01-14T16:33:58.842229", "market_id": "0x49686d26fb712515cd5e12c23f0a1c7e10214c7faa3cb0a730aabe0c33694082", "raw": {"market": "0x49686d26fb712515cd5e12c23f0a1c7e10214c7faa3cb0a730aabe0c33694082", "asset_id": "13244681086321087932946246027856416106585284024824496763706748621681543444582", "price": "0.925", "size": "25", "side": "SELL", "timestamp": "1768404011247", "received_at": "2026-01-14T16:20:11.343845"}}
{"event_type": "price_change", "event_ts": "2026-01-14T16:20:11.343860", "ingestion_ts": "2026-01-14T16:33:58.842229", "market_id": "0xaf9d0e448129a9f657f851d49495ba4742055d80e0ef1166ba0ee81d4d594214", "raw": {"market": "0xaf9d0e448129a9f657f851d49495ba4742055d80e0ef1166ba0ee81d4d594214", "asset_id": "4153292802911610701832309484716814274802943278345248636922528170020319407796", "price": "0.73", "size": "25", "side": "BUY", "timestamp": "1768404011247", "received_at": "2026-01-14T16:20:11.343860"}}
{"event_type": "price_change", "event_ts": "2026-01-14T16:20:11.343860", "ingestion_ts": "2026-01-14T16:33:58.842229", "market_id": "0xaf9d0e448129a9f657f851d49495ba4742055d80e0ef1166ba0ee81d4d594214", "raw": {"market": "0xaf9d0e448129a9f657f851d49495ba4742055d80e0ef1166ba0ee81d4d594214", "asset_id": "101676997363687199724245607342877036148401850938023978421879460310389391082353", "price": "0.27", "size": "25", "side": "SELL", "timestamp": "1768404011247", "received_at": "2026-01-14T16:20:11.343860"}}
{"event_type": "price_change", "event_ts": "2026-01-14T16:20:11.343873", "ingestion_ts": "2026-01-14T16:33:58.842229", "market_id": "0x49a20c7523c271099008f3ef9a31521263b24d637959852a391e6b4697b1a437", "raw": {"market": "0x49a20c7523c271099008f3ef9a31521263b24d637959852a391e6b4697b1a437", "asset_id": "55881023621710858558280545117465775643848233756850602339827152783696837905531", "price": "0.928", "size": "25", "side": "BUY", "timestamp": "1768404011247", "received_at": "2026-01-14T16:20:11.343873"}}
{"event_type": "price_change", "event_ts": "2026-01-14T16:20:11.343873", "ingestion_ts": "2026-01-14T16:33:58.842229", "market_id": "0x49a20c7523c271099008f3ef9a31521263b24d637959852a391e6b4697b1a437", "raw": {"market": "0x49a20c7523c271099008f3ef9a31521263b24d637959852a391e6b4697b1a437", "asset_id": "13018971792603393862521629014128024641178044618205296260525674415067194037856", "price": "0.072", "size": "25", "side": "SELL", "timestamp": "1768404011247", "received_at": "2026-01-14T16:20:11.343873"}}
{"event_type": "price_change", "event_ts": "2026-01-14T16:20:11.389996", "ingestion_ts": "2026-01-14T16:33:58.842229", "market_id": "0x50c669f178da4e5bbea7f1be25041fd278914712fa87a6a6f8e57d5923d88dee", "raw": {"market": "0x50c669f178da4e5bbea7f1be25041fd278914712fa87a6a6f8e57d5923d88dee", "asset_id": "74040420326294854165772767082819937451857852955603897473157746262672057685461", "price": "0.951", "size": "0", "side": "BUY", "timestamp": "1768404011299", "received_at": "2026-01-14T16:20:11.389996"}}
{"event_type": "price_change", "event_ts": "2026-01-14T16:20:11.389996", "ingestion_ts": "2026-01-14T16:33:58.842229", "market_id": "0x50c669f178da4e5bbea7f1be25041fd278914712fa87a6a6f8e57d5923d88dee", "raw": {"market": "0x50c669f178da4e5bbea7f1be25041fd278914712fa87a6a6f8e57d5923d88dee", "asset_id": "24682525479474221428144937281315825971983904267399062415430320764754931667953", "price": "0.049", "size": "0", "side": "SELL", "timestamp": "1768404011299", "received_at": "2026-01-14T16:20:11.389996"}}
{"event_type": "price_change", "event_ts": "2026-01-14T16:20:11.390054", "ingestion_ts": "2026-01-14T16:33:58.842229", "market_id": "0x44f08744458b8896620cd3330bc5e1ea69df4199b02d4fc583b3fc96e5d314ce", "raw": {"market": "0x44f08744458b8896620cd3330bc5e1ea69df4199b02d4fc583b3fc96e5d314ce", "asset_id": "72327831507226612545928776794104143393438710920370371172884559893525100761096", "price": "0.906", "size": "0", "side": "BUY", "timestamp": "1768404011299", "received_at": "2026-01-14T16:20:11.390054"}}
{"event_type": "price_change", "event_ts": "2026-01-14T16:20:11.390054", "ingestion_ts": "2026-01-14T16:33:58.842229", "market_id": "0x44f08744458b8896620cd3330bc5e1ea69df4199b02d4fc583b3fc96e5d314ce", "raw": {"market": "0x44f08744458b8896620cd3330bc5e1ea69df4199b02d4fc583b3fc96e5d314ce", "asset_id": "49194009556504828848509244326501559253829462790583873936160989575507522044057", "price": "0.094", "size": "0", "side": "SELL", "timestamp": "1768404011299", "received_at": "2026-01-14T16:20:11.390054"}}
{"event_type": "price_change", "event_ts": "2026-01-14T16:20:11.500194", "ingestion_ts": "2026-01-14T16:33:58.842229", "market_id": "0xe9c127a8c35f045d37b5344b0a36711084fa20c2fc1618bf178a5386f90610be", "raw": {"market": "0xe9c127a8c35f045d37b5344b0a36711084fa20c2fc1618bf178a5386f90610be", "asset_id": "107000426448217931795450451304515386602910396776318075817601265223856116134349", "price": "0.057", "size": "70.17", "side": "BUY", "timestamp": "1768404011416", "received_at": "2026-01-14T16:20:11.500194"}}
{"event_type": "price_change", "event_ts": "2026-01-14T16:20:11.500194", "ingestion_ts": "2026-01-14T16:33:58.842229", "market_id": "0xe9c127a8c35f045d37b5344b0a36711084fa20c2fc1618bf178a5386f90610be", "raw": {"market": "0xe9c127a8c35f045d37b5344b0a36711084fa20c2fc1618bf178a5386f90610be", "asset_id": "80230236018433940569996058935444651347308266584430516013229815570706872276819", "price": "0.943", "size": "70.17", "side": "SELL", "timestamp": "1768404011416", "received_at": "2026-01-14T16:20:11.500194"}}
{"event_type": "price_change", "event_ts": "2026-01-14T16:20:11.608627", "ingestion_ts": "2026-01-14T16:33:58.842229", "market_id": "0x50c669f178da4e5bbea7f1be25041fd278914712fa87a6a6f8e57d5923d88dee", "raw": {"market": "0x50c669f178da4e5bbea7f1be25041fd278914712fa87a6a6f8e57d5923d88dee", "asset_id": "74040420326294854165772767082819937451857852955603897473157746262672057685461", "price": "0.952", "size": "25", "side": "BUY", "timestamp": "1768404011538", "received_at": "2026-01-14T16:20:11.608627"}}
{"event_type": "price_change", "event_ts": "2026-01-14T16:20:11.608627", "ingestion_ts": "2026-01-14T16:33:58.842229", "market_id": "0x50c669f178da4e5bbea7f1be25041fd278914712fa87a6a6f8e57d5923d88dee", "raw": {"market": "0x50c669f178da4e5bbea7f1be25041fd278914712fa87a6a6f8e57d5923d88dee", "asset_id": "24682525479474221428144937281315825971983904267399062415430320764754931667953", "price": "0.048", "size": "25", "side": "SELL", "timestamp": "1768404011538", "received_at": "2026-01-14T16:20:11.608627"}}
{"event_type": "price_change", "event_ts": "2026-01-14T16:20:11.608667", "ingestion_ts": "2026-01-14T16:33:58.842229", "market_id": "0x44f08744458b8896620cd3330bc5e1ea69df4199b02d4fc583b3fc96e5d314ce", "raw": {"market": "0x44f08744458b8896620cd3330bc5e1ea69df4199b02d4fc583b3fc96e5d314ce", "asset_id": "72327831507226612545928776794104143393438710920370371172884559893525100761096", "price": "0.908", "size": "25", "side": "BUY", "timestamp": "1768404011538", "received_at": "2026-01-14T16:20:11.608667"}}
{"event_type": "price_change", "event_ts": "2026-01-14T16:20:11.608667", "ingestion_ts": "2026-01-14T16:33:58.842229", "market_id": "0x44f08744458b8896620cd3330bc5e1ea69df4199b02d4fc583b3fc96e5d314ce", "raw": {"market": "0x44f08744458b8896620cd3330bc5e1ea69df4199b02d4fc583b3fc96e5d314ce", "asset_id": "49194009556504828848509244326501559253829462790583873936160989575507522044057", "price": "0.092", "size": "25", "side": "SELL", "timestamp": "1768404011538", "received_at": "2026-01-14T16:20:11.608667"}}
{"event_type": "price_change", "event_ts": "2026-01-14T16:20:11.706810", "ingestion_ts": "2026-01-14T16:33:58.842229", "market_id": "0xe9c127a8c35f045d37b5344b0a36711084fa20c2fc1618bf178a5386f90610be", "raw": {"market": "0xe9c127a8c35f045d37b5344b0a36711084fa20c2fc1618bf178a5386f90610be", "asset_id": "107000426448217931795450451304515386602910396776318075817601265223856116134349", "price": "0.107", "size": "0", "side": "BUY", "timestamp": "1768404011629", "received_at": "2026-01-14T16:20:11.706810"}}
{"event_type": "price_change", "event_ts": "2026-01-14T16:20:11.706810", "ingestion_ts": "2026-01-14T16:33:58.842229", "market_id": "0xe9c127a8c35f045d37b5344b0a36711084fa20c2fc1618bf178a5386f90610be", "raw": {"market": "0xe9c127a8c35f045d37b5344b0a36711084fa20c2fc1618bf178a5386f90610be", "asset_id": "80230236018433940569996058935444651347308266584430516013229815570706872276819", "price": "0.893", "size": "0", "side": "SELL", "timestamp": "1768404011629", "received_at": "2026-01-14T16:20:11.706810"}}
{"event_type": "price_change", "event_ts": "2026-01-14T16:20:11.792104", "ingestion_ts": "2026-01-14T16:33:58.842229", "market_id": "0x2393ed0b0fdc450054c7b9071907eca75cf4fc36e385adf4a0a5f99ee62243e8", "raw": {"market": "0x2393ed0b0fdc450054c7b9071907eca75cf4fc36e385adf4a0a5f99ee62243e8", "asset_id": "32769749367306925959219403371425714180265458150646381231272229429098460625924", "price": "0.876", "size": "0", "side": "BUY", "timestamp": "1768404011673", "received_at": "2026-01-14T16:20:11.792104"}}
{"event_type": "price_change", "event_ts": "2026-01-14T16:20:11.792104", "ingestion_ts": "2026-01-14T16:33:58.842229", "market_id": "0x2393ed0b0fdc450054c7b9071907eca75cf4fc36e385adf4a0a5f99ee62243e8", "raw": {"market": "0x2393ed0b0fdc450054c7b9071907eca75cf4fc36e385adf4a0a5f99ee62243e8", "asset_id": "100074770378634056601572485653252702850363676459996771990439989989293515601975", "price": "0.124", "size": "0", "side": "SELL", "timestamp": "1768404011673", "received_at": "2026-01-14T16:20:11.792104"}}
{"event_type": "price_change", "event_ts": "2026-01-14T16:20:11.792189", "ingestion_ts": "2026-01-14T16:33:58.842229", "market_id": "0xaf9d0e448129a9f657f851d49495ba4742055d80e0ef1166ba0ee81d4d594214", "raw": {"market": "0xaf9d0e448129a9f657f851d49495ba4742055d80e0ef1166ba0ee81d4d594214", "asset_id": "4153292802911610701832309484716814274802943278345248636922528170020319407796", "price": "0.729", "size": "0", "side": "BUY", "timestamp": "1768404011673", "received_at": "2026-01-14T16:20:11.792189"}}
{"event_type": "price_change", "event_ts": "2026-01-14T16:20:11.792189", "ingestion_ts": "2026-01-14T16:33:58.842229", "market_id": "0xaf9d0e448129a9f657f851d49495ba4742055d80e0ef1166ba0ee81d4d594214", "raw": {"market": "0xaf9d0e448129a9f657f851d49495ba4742055d80e0ef1166ba0ee81d4d594214", "asset_id": "101676997363687199724245607342877036148401850938023978421879460310389391082353", "price": "0.271", "size": "0", "side": "SELL", "timestamp": "1768404011673", "received_at": "2026-01-14T16:20:11.792189"}}
{"event_type": "price_change", "event_ts": "2026-01-14T16:20:11.835939", "ingestion_ts": "2026-01-14T16:33:58.842229", "market_id": "0xaf9d0e448129a9f657f851d49495ba4742055d80e0ef1166ba0ee81d4d594214", "raw": {"market": "0xaf9d0e448129a9f657f851d49495ba4742055d80e0ef1166ba0ee81d4d594214", "asset_id": "4153292802911610701832309484716814274802943278345248636922528170020319407796", "price": "0.731", "size": "5", "side": "BUY", "timestamp": "1768404011704", "received_at": "2026-01-14T16:20:11.835939"}}
{"event_type": "price_change", "event_ts": "2026-01-14T16:20:11.835939", "ingestion_ts": "2026-01-14T16:33:58.842229", "market_id": "0xaf9d0e448129a9f657f851d49495ba4742055d80e0ef1166ba0ee81d4d594214", "raw": {"market": "0xaf9d0e448129a9f657f851d49495ba4742055d80e0ef1166ba0ee81d4d594214", "asset_id": "101676997363687199724245607342877036148401850938023978421879460310389391082353", "price": "0.269", "size": "5", "side": "SELL", "timestamp": "1768404011704", "received_at": "2026-01-14T16:20:11.835939"}}
{"event_type": "price_change", "event_ts": "2026-01-14T16:20:11.835976", "ingestion_ts": "2026-01-14T16:33:58.842229", "market_id": "0x2393ed0b0fdc450054c7b9071907eca75cf4fc36e385adf4a0a5f99ee62243e8", "raw": {"market": "0x2393ed0b0fdc450054c7b9071907eca75cf4fc36e385adf4a0a5f99ee62243e8", "asset_id": "32769749367306925959219403371425714180265458150646381231272229429098460625924", "price": "0.878", "size": "30", "side": "BUY", "timestamp": "1768404011704", "received_at": "2026-01-14T16:20:11.835976"}}
{"event_type": "price_change", "event_ts": "2026-01-14T16:20:11.835976", "ingestion_ts": "2026-01-14T16:33:58.842229", "market_id": "0x2393ed0b0fdc450054c7b9071907eca75cf4fc36e385adf4a0a5f99ee62243e8", "raw": {"market": "0x2393ed0b0fdc450054c7b9071907eca75cf4fc36e385adf4a0a5f99ee62243e8", "asset_id": "100074770378634056601572485653252702850363676459996771990439989989293515601975", "price": "0.122", "size": "30", "side": "SELL", "timestamp": "1768404011704", "received_at": "2026-01-14T16:20:11.835976"}}
{"event_type": "price_change", "event_ts": "2026-01-14T16:20:11.890969", "ingestion_ts": "2026-01-14T16:33:58.842229", "market_id": "0x49686d26fb712515cd5e12c23f0a1c7e10214c7faa3cb0a730aabe0c33694082", "raw": {"market": "0x49686d26fb712515cd5e12c23f0a1c7e10214c7faa3cb0a730aabe0c33694082", "asset_id": "30442780799048074404860985387051749017905070253466005720364298335239299761065", "price": "0.075", "size": "0", "side": "BUY", "timestamp": "1768404011760", "received_at": "2026-01-14T16:20:11.890969"}}
{"event_type": "price_change", "event_ts": "2026-01-14T16:20:11.890969", "ingestion_ts": "2026-01-14T16:33:58.842229", "market_id": "0x49686d26fb712515cd5e12c23f0a1c7e10214c7faa3cb0a730aabe0c33694082", "raw": {"market": "0x49686d26fb712515cd5e12c23f0a1c7e10214c7faa3cb0a730aabe0c33694082", "asset_id": "13244681086321087932946246027856416106585284024824496763706748621681543444582", "price": "0.925", "size": "0", "side": "SELL", "timestamp": "1768404011760", "received_at": "2026-01-14T16:20:11.890969"}}
{"event_type": "price_change", "event_ts": "2026-01-14T16:20:11.962149", "ingestion_ts": "2026-01-14T16:33:58.842229", "market_id": "0xe9c127a8c35f045d37b5344b0a36711084fa20c2fc1618bf178a5386f90610be", "raw": {"market": "0xe9c127a8c35f045d37b5344b0a36711084fa20c2fc1618bf178a5386f90610be", "asset_id": "107000426448217931795450451304515386602910396776318075817601265223856116134349", "price": "0.107", "size": "37.38", "side": "BUY", "timestamp": "1768404011867", "received_at": "2026-01-14T16:20:11.962149"}}
{"event_type": "price_change", "event_ts": "2026-01-14T16:20:11.962149", "ingestion_ts": "2026-01-14T16:33:58.842229", "market_id": "0xe9c127a8c35f045d37b5344b0a36711084fa20c2fc1618bf178a5386f90610be", "raw": {"market": "0xe9c127a8c35f045d37b5344b0a36711084fa20c2fc1618bf178a5386f90610be", "asset_id": "80230236018433940569996058935444651347308266584430516013229815570706872276819", "price": "0.893", "size": "37.38", "side": "SELL", "timestamp": "1768404011867", "received_at": "2026-01-14T16:20:11.962149"}}
{"event_type": "price_change", "event_ts": "2026-01-14T16:20:12.097286", "ingestion_ts": "2026-01-14T16:33:58.842229", "market_id": "0x49686d26fb712515cd5e12c23f0a1c7e10214c7faa3cb0a730aabe0c33694082", "raw": {"market": "0x49686d26fb712515cd5e12c23f0a1c7e10214c7faa3cb0a730aabe0c33694082", "asset_id": "30442780799048074404860985387051749017905070253466005720364298335239299761065", "price": "0.076", "size": "25", "side": "BUY", "timestamp": "1768404012005", "received_at": "2026-01-14T16:20:12.097286"}}
{"event_type": "price_change", "event_ts": "2026-01-14T16:20:12.097286", "ingestion_ts": "2026-01-14T16:33:58.842229", "market_id": "0x49686d26fb712515cd5e12c23f0a1c7e10214c7faa3cb0a730aabe0c33694082", "raw": {"market": "0x49686d26fb712515cd5e12c23f0a1c7e10214c7faa3cb0a730aabe0c33694082", "asset_id": "13244681086321087932946246027856416106585284024824496763706748621681543444582", "price": "0.924", "size": "25", "side": "SELL", "timestamp": "1768404012005", "received_at": "2026-01-14T16:20:12.097286"}}
{"event_type": "price_change", "event_ts": "2026-01-14T16:20:12.139986", "ingestion_ts": "2026-01-14T16:33:58.842229", "market_id": "0xe9c127a8c35f045d37b5344b0a36711084fa20c2fc1618bf178a5386f90610be", "raw": {"market": "0xe9c127a8c35f045d37b5344b0a36711084fa20c2fc1618bf178a5386f90610be", "asset_id": "107000426448217931795450451304515386602910396776318075817601265223856116134349", "price": "0.115", "size": "0", "side": "BUY", "timestamp": "1768404012079", "received_at": "2026-01-14T16:20:12.139986"}}
{"event_type": "price_change", "event_ts": "2026-01-14T16:20:12.139986", "ingestion_ts": "2026-01-14T16:33:58.842229", "market_id": "0xe9c127a8c35f045d37b5344b0a36711084fa20c2fc1618bf178a5386f90610be", "raw": {"market": "0xe9c127a8c35f045d37b5344b0a36711084fa20c2fc1618bf178a5386f90610be", "asset_id": "80230236018433940569996058935444651347308266584430516013229815570706872276819", "price": "0.885", "size": "0", "side": "SELL", "timestamp": "1768404012079", "received_at": "2026-01-14T16:20:12.139986"}}
{"event_type": "price_change", "event_ts": "2026-01-14T16:20:12.344231", "ingestion_ts": "2026-01-14T16:33:58.842229", "market_id": "0xe9c127a8c35f045d37b5344b0a36711084fa20c2fc1618bf178a5386f90610be", "raw": {"market": "0xe9c127a8c35f045d37b5344b0a36711084fa20c2fc1618bf178a5386f90610be", "asset_id": "107000426448217931795450451304515386602910396776318075817601265223856116134349", "price": "0.115", "size": "34.78", "side": "BUY", "timestamp": "1768404012283", "received_at": "2026-01-14T16:20:12.344231"}}
{"event_type": "price_change", "event_ts": "2026-01-14T16:20:12.344231", "ingestion_ts": "2026-01-14T16:33:58.842229", "market_id": "0xe9c127a8c35f045d37b5344b0a36711084fa20c2fc1618bf178a5386f90610be", "raw": {"market": "0xe9c127a8c35f045d37b5344b0a36711084fa20c2fc1618bf178a5386f90610be", "asset_id": "80230236018433940569996058935444651347308266584430516013229815570706872276819", "price": "0.885", "size": "34.78", "side": "SELL", "timestamp": "1768404012283", "received_at": "2026-01-14T16:20:12.344231"}}
{"event_type": "price_change", "event_ts": "2026-01-14T16:20:12.595639", "ingestion_ts": "2026-01-14T16:33:58.842229", "market_id": "0xe9c127a8c35f045d37b5344b0a36711084fa20c2fc1618bf178a5386f90610be", "raw": {"market": "0xe9c127a8c35f045d37b5344b0a36711084fa20c2fc1618bf178a5386f90610be", "asset_id": "107000426448217931795450451304515386602910396776318075817601265223856116134349", "price": "0.151", "size": "0", "side": "BUY", "timestamp": "1768404012515", "received_at": "2026-01-14T16:20:12.595639"}}
{"event_type": "price_change", "event_ts": "2026-01-14T16:20:12.595639", "ingestion_ts": "2026-01-14T16:33:58.842229", "market_id": "0xe9c127a8c35f045d37b5344b0a36711084fa20c2fc1618bf178a5386f90610be", "raw": {"market": "0xe9c127a8c35f045d37b5344b0a36711084fa20c2fc1618bf178a5386f90610be", "asset_id": "80230236018433940569996058935444651347308266584430516013229815570706872276819", "price": "0.849", "size": "0", "side": "SELL", "timestamp": "1768404012515", "received_at": "2026-01-14T16:20:12.595639"}}
{"event_type": "price_change", "event_ts": "2026-01-14T16:20:12.763063", "ingestion_ts": "2026-01-14T16:33:58.842229", "market_id": "0xe9c127a8c35f045d37b5344b0a36711084fa20c2fc1618bf178a5386f90610be", "raw": {"market": "0xe9c127a8c35f045d37b5344b0a36711084fa20c2fc1618bf178a5386f90610be", "asset_id": "107000426448217931795450451304515386602910396776318075817601265223856116134349", "price": "0.151", "size": "26.49", "side": "BUY", "timestamp": "1768404012742", "received_at": "2026-01-14T16:20:12.763063"}}
{"event_type": "price_change", "event_ts": "2026-01-14T16:20:12.763063", "ingestion_ts": "2026-01-14T16:33:58.842229", "market_id": "0xe9c127a8c35f045d37b5344b0a36711084fa20c2fc1618bf178a5386f90610be", "raw": {"market": "0xe9c127a8c35f045d37b5344b0a36711084fa20c2fc1618bf178a5386f90610be", "asset_id": "80230236018433940569996058935444651347308266584430516013229815570706872276819", "price": "0.849", "size": "26.49", "side": "SELL", "timestamp": "1768404012742", "received_at": "2026-01-14T16:20:12.763063"}}
{"event_type": "price_change", "event_ts": "2026-01-14T16:20:12.921765", "ingestion_ts": "2026-01-14T16:33:58.842229", "market_id": "0xe9c127a8c35f045d37b5344b0a36711084fa20c2fc1618bf178a5386f90610be", "raw": {"market": "0xe9c127a8c35f045d37b5344b0a36711084fa20c2fc1618bf178a5386f90610be", "asset_id": "107000426448217931795450451304515386602910396776318075817601265223856116134349", "price": "0.177", "size": "0", "side": "BUY", "timestamp": "1768404012963", "received_at": "2026-01-14T16:20:12.921765"}}
{"event_type": "price_change", "event_ts": "2026-01-14T16:20:12.921765", "ingestion_ts": "2026-01-14T16:33:58.842229", "market_id": "0xe9c127a8c35f045d37b5344b0a36711084fa20c2fc1618bf178a5386f90610be", "raw": {"market": "0xe9c127a8c35f045d37b5344b0a36711084fa20c2fc1618bf178a5386f90610be", "asset_id": "80230236018433940569996058935444651347308266584430516013229815570706872276819", "price": "0.823", "size": "0", "side": "SELL", "timestamp": "1768404012963", "received_at": "2026-01-14T16:20:12.921765"}}
{"event_type": "price_change", "event_ts": "2026-01-14T16:20:13.140431", "ingestion_ts": "2026-01-14T16:33:58.842229", "market_id": "0xe9c127a8c35f045d37b5344b0a36711084fa20c2fc1618bf178a5386f90610be", "raw": {"market": "0xe9c127a8c35f045d37b5344b0a36711084fa20c2fc1618bf178a5386f90610be", "asset_id": "107000426448217931795450451304515386602910396776318075817601265223856116134349", "price": "0.177", "size": "22.59", "side": "BUY", "timestamp": "1768404013196", "received_at": "2026-01-14T16:20:13.140431"}}
{"event_type": "price_change", "event_ts": "2026-01-14T16:20:13.140431", "ingestion_ts": "2026-01-14T16:33:58.842229", "market_id": "0xe9c127a8c35f045d37b5344b0a36711084fa20c2fc1618bf178a5386f90610be", "raw": {"market": "0xe9c127a8c35f045d37b5344b0a36711084fa20c2fc1618bf178a5386f90610be", "asset_id": "80230236018433940569996058935444651347308266584430516013229815570706872276819", "price": "0.823", "size": "22.59", "side": "SELL", "timestamp": "1768404013196", "received_at": "2026-01-14T16:20:13.140431"}}
{"event_type": "price_change", "event_ts": "2026-01-14T16:20:13.324916", "ingestion_ts": "2026-01-14T16:33:58.842229", "market_id": "0xe9c127a8c35f045d37b5344b0a36711084fa20c2fc1618bf178a5386f90610be", "raw": {"market": "0xe9c127a8c35f045d37b5344b0a36711084fa20c2fc1618bf178a5386f90610be", "asset_id": "107000426448217931795450451304515386602910396776318075817601265223856116134349", "price": "0.214", "size": "0", "side": "BUY", "timestamp": "1768404013409", "received_at": "2026-01-14T16:20:13.324916"}}
{"event_type": "price_change", "event_ts": "2026-01-14T16:20:13.324916", "ingestion_ts": "2026-01-14T16:33:58.842229", "market_id": "0xe9c127a8c35f045d37b5344b0a36711084fa20c2fc1618bf178a5386f90610be", "raw": {"market": "0xe9c127a8c35f045d37b5344b0a36711084fa20c2fc1618bf178a5386f90610be", "asset_id": "80230236018433940569996058935444651347308266584430516013229815570706872276819", "price": "0.786", "size": "0", "side": "SELL", "timestamp": "1768404013409", "received_at": "2026-01-14T16:20:13.324916"}}
{"event_type": "price_change", "event_ts": "2026-01-14T16:20:13.471308", "ingestion_ts": "2026-01-14T16:33:58.842229", "market_id": "0xe9c127a8c35f045d37b5344b0a36711084fa20c2fc1618bf178a5386f90610be", "raw": {"market": "0xe9c127a8c35f045d37b5344b0a36711084fa20c2fc1618bf178a5386f90610be", "asset_id": "107000426448217931795450451304515386602910396776318075817601265223856116134349", "price": "0.214", "size": "18.69", "side": "BUY", "timestamp": "1768404013615", "received_at": "2026-01-14T16:20:13.471308"}}
{"event_type": "price_change", "event_ts": "2026-01-14T16:20:13.471308", "ingestion_ts": "2026-01-14T16:33:58.842229", "market_id": "0xe9c127a8c35f045d37b5344b0a36711084fa20c2fc1618bf178a5386f90610be", "raw": {"market": "0xe9c127a8c35f045d37b5344b0a36711084fa20c2fc1618bf178a5386f90610be", "asset_id": "80230236018433940569996058935444651347308266584430516013229815570706872276819", "price": "0.786", "size": "18.69", "side": "SELL", "timestamp": "1768404013615", "received_at": "2026-01-14T16:20:13.471308"}}
{"event_type": "price_change", "event_ts": "2026-01-14T16:20:13.654767", "ingestion_ts": "2026-01-14T16:33:58.842229", "market_id": "0xe9c127a8c35f045d37b5344b0a36711084fa20c2fc1618bf178a5386f90610be", "raw": {"market": "0xe9c127a8c35f045d37b5344b0a36711084fa20c2fc1618bf178a5386f90610be", "asset_id": "107000426448217931795450451304515386602910396776318075817601265223856116134349", "price": "0.256", "size": "0", "side": "BUY", "timestamp": "1768404013840", "received_at": "2026-01-14T16:20:13.654767"}}
{"event_type": "price_change", "event_ts": "2026-01-14T16:20:13.654767", "ingestion_ts": "2026-01-14T16:33:58.842229", "market_id": "0xe9c127a8c35f045d37b5344b0a36711084fa20c2fc1618bf178a5386f90610be", "raw": {"market": "0xe9c127a8c35f045d37b5344b0a36711084fa20c2fc1618bf178a5386f90610be", "asset_id": "80230236018433940569996058935444651347308266584430516013229815570706872276819", "price": "0.744", "size": "0", "side": "SELL", "timestamp": "1768404013840", "received_at": "2026-01-14T16:20:13.654767"}}
{"event_type": "price_change", "event_ts": "2026-01-14T16:20:13.818476", "ingestion_ts": "2026-01-14T16:33:58.842229", "market_id": "0xe9c127a8c35f045d37b5344b0a36711084fa20c2fc1618bf178a5386f90610be", "raw": {"market": "0xe9c127a8c35f045d37b5344b0a36711084fa20c2fc1618bf178a5386f90610be", "asset_id": "107000426448217931795450451304515386602910396776318075817601265223856116134349", "price": "0.256", "size": "15.62", "side": "BUY", "timestamp": "1768404014068", "received_at": "2026-01-14T16:20:13.818476"}}
{"event_type": "price_change", "event_ts": "2026-01-14T16:20:13.818476", "ingestion_ts": "2026-01-14T16:33:58.842229", "market_id": "0xe9c127a8c35f045d37b5344b0a36711084fa20c2fc1618bf178a5386f90610be", "raw": {"market": "0xe9c127a8c35f045d37b5344b0a36711084fa20c2fc1618bf178a5386f90610be", "asset_id": "80230236018433940569996058935444651347308266584430516013229815570706872276819", "price": "0.744", "size": "15.62", "side": "SELL", "timestamp": "1768404014068", "received_at": "2026-01-14T16:20:13.818476"}}
{"event_type": "price_change", "event_ts": "2026-01-14T16:20:13.970379", "ingestion_ts": "2026-01-14T16:33:58.842229", "market_id": "0xe9c127a8c35f045d37b5344b0a36711084fa20c2fc1618bf178a5386f90610be", "raw": {"market": "0xe9c127a8c35f045d37b5344b0a36711084fa20c2fc1618bf178a5386f90610be", "asset_id": "107000426448217931795450451304515386602910396776318075817601265223856116134349", "price": "0.3", "size": "60.94", "side": "BUY", "timestamp": "1768404014293", "received_at": "2026-01-14T16:20:13.970379"}}
{"event_type": "price_change", "event_ts": "2026-01-14T16:20:13.970379", "ingestion_ts": "2026-01-14T16:33:58.842229", "market_id": "0xe9c127a8c35f045d37b5344b0a36711084fa20c2fc1618bf178a5386f90610be", "raw": {"market": "0xe9c127a8c35f045d37b5344b0a36711084fa20c2fc1618bf178a5386f90610be", "asset_id": "80230236018433940569996058935444651347308266584430516013229815570706872276819", "price": "0.7", "size": "60.94", "side": "SELL", "timestamp": "1768404014293", "received_at": "2026-01-14T16:20:13.970379"}}
{"event_type": "price_change", "event_ts": "2026-01-14T16:20:14.210295", "ingestion_ts": "2026-01-14T16:33:58.842229", "market_id": "0xe9c127a8c35f045d37b5344b0a36711084fa20c2fc1618bf178a5386f90610be", "raw": {"market": "0xe9c127a8c35f045d37b5344b0a36711084fa20c2fc1618bf178a5386f90610be", "asset_id": "107000426448217931795450451304515386602910396776318075817601265223856116134349", "price": "0.4", "size": "45.71", "side": "BUY", "timestamp": "1768404014534", "received_at": "2026-01-14T16:20:14.210295"}}
{"event_type": "price_change", "event_ts": "2026-01-14T16:20:14.210295", "ingestion_ts": "2026-01-14T16:33:58.842229", "market_id": "0xe9c127a8c35f045d37b5344b0a36711084fa20c2fc1618bf178a5386f90610be", "raw": {"market": "0xe9c127a8c35f045d37b5344b0a36711084fa20c2fc1618bf178a5386f90610be", "asset_id": "80230236018433940569996058935444651347308266584430516013229815570706872276819", "price": "0.6", "size": "45.71", "side": "SELL", "timestamp": "1768404014534", "received_at": "2026-01-14T16:20:14.210295"}}
{"event_type": "price_change", "event_ts": "2026-01-14T16:20:14.416290", "ingestion_ts": "2026-01-14T16:33:58.842229", "market_id": "0xe9c127a8c35f045d37b5344b0a36711084fa20c2fc1618bf178a5386f90610be", "raw": {"market": "0xe9c127a8c35f045d37b5344b0a36711084fa20c2fc1618bf178a5386f90610be", "asset_id": "107000426448217931795450451304515386602910396776318075817601265223856116134349", "price": "0.5", "size": "13", "side": "BUY", "timestamp": "1768404014746", "received_at": "2026-01-14T16:20:14.416290"}}
{"event_type": "price_change", "event_ts": "2026-01-14T16:20:14.416290", "ingestion_ts": "2026-01-14T16:33:58.842229", "market_id": "0xe9c127a8c35f045d37b5344b0a36711084fa20c2fc1618bf178a5386f90610be", "raw": {"market": "0xe9c127a8c35f045d37b5344b0a36711084fa20c2fc1618bf178a5386f90610be", "asset_id": "80230236018433940569996058935444651347308266584430516013229815570706872276819", "price": "0.5", "size": "13", "side": "SELL", "timestamp": "1768404014746", "received_at": "2026-01-14T16:20:14.416290"}}
{"event_type": "price_change", "event_ts": "2026-01-14T16:20:14.635912", "ingestion_ts": "2026-01-14T16:33:58.842229", "market_id": "0xcab7ba4a9133cfd407d7e73e5757e5abbace413b59421527a31113406c97815c", "raw": {"market": "0xcab7ba4a9133cfd407d7e73e5757e5abbace413b59421527a31113406c97815c", "asset_id": "20002636398944597965698652220992177552927816915094913583821579024925426590022", "price": "0.4", "size": "35.71", "side": "BUY", "timestamp": "1768404014964", "received_at": "2026-01-14T16:20:14.635912"}}
{"event_type": "price_change", "event_ts": "2026-01-14T16:20:14.635912", "ingestion_ts": "2026-01-14T16:33:58.842229", "market_id": "0xcab7ba4a9133cfd407d7e73e5757e5abbace413b59421527a31113406c97815c", "raw": {"market": "0xcab7ba4a9133cfd407d7e73e5757e5abbace413b59421527a31113406c97815c", "asset_id": "96361925776989336186111887920533578209326565663637092688733016597062311745569", "price": "0.6", "size": "35.71", "side": "SELL", "timestamp": "1768404014964", "received_at": "2026-01-14T16:20:14.635912"}}
{"event_type": "price_change", "event_ts": "2026-01-14T16:20:14.823333", "ingestion_ts": "2026-01-14T16:33:58.842229", "market_id": "0xcab7ba4a9133cfd407d7e73e5757e5abbace413b59421527a31113406c97815c", "raw": {"market": "0xcab7ba4a9133cfd407d7e73e5757e5abbace413b59421527a31113406c97815c", "asset_id": "20002636398944597965698652220992177552927816915094913583821579024925426590022", "price": "0.3", "size": "47.61", "side": "BUY", "timestamp": "1768404015152", "received_at": "2026-01-14T16:20:14.823333"}}
{"event_type": "price_change", "event_ts": "2026-01-14T16:20:14.823333", "ingestion_ts": "2026-01-14T16:33:58.842229", "market_id": "0xcab7ba4a9133cfd407d7e73e5757e5abbace413b59421527a31113406c97815c", "raw": {"market": "0xcab7ba4a9133cfd407d7e73e5757e5abbace413b59421527a31113406c97815c", "asset_id": "96361925776989336186111887920533578209326565663637092688733016597062311745569", "price": "0.7", "size": "47.61", "side": "SELL", "timestamp": "1768404015152", "received_at": "2026-01-14T16:20:14.823333"}}
{"event_type": "price_change", "event_ts": "2026-01-14T16:20:15.106651", "ingestion_ts": "2026-01-14T16:33:58.842229", "market_id": "0xcab7ba4a9133cfd407d7e73e5757e5abbace413b59421527a31113406c97815c", "raw": {"market": "0xcab7ba4a9133cfd407d7e73e5757e5abbace413b59421527a31113406c97815c", "asset_id": "20002636398944597965698652220992177552927816915094913583821579024925426590022", "price": "0.108", "size": "31.74", "side": "BUY", "timestamp": "1768404015400", "received_at": "2026-01-14T16:20:15.106651"}}
{"event_type": "price_change", "event_ts": "2026-01-14T16:20:15.106651", "ingestion_ts": "2026-01-14T16:33:58.842229", "market_id": "0xcab7ba4a9133cfd407d7e73e5757e5abbace413b59421527a31113406c97815c", "raw": {"market": "0xcab7ba4a9133cfd407d7e73e5757e5abbace413b59421527a31113406c97815c", "asset_id": "96361925776989336186111887920533578209326565663637092688733016597062311745569", "price": "0.892", "size": "31.74", "side": "SELL", "timestamp": "1768404015400", "received_at": "2026-01-14T16:20:15.106651"}}
{"event_type": "price_change", "event_ts": "2026-01-14T16:20:15.309013", "ingestion_ts": "2026-01-14T16:33:58.842229", "market_id": "0xcab7ba4a9133cfd407d7e73e5757e5abbace413b59421527a31113406c97815c", "raw": {"market": "0xcab7ba4a9133cfd407d7e73e5757e5abbace413b59421527a31113406c97815c", "asset_id": "20002636398944597965698652220992177552927816915094913583821579024925426590022", "price": "0.022", "size": "0", "side": "BUY", "timestamp": "1768404015638", "received_at": "2026-01-14T16:20:15.309013"}}
{"event_type": "price_change", "event_ts": "2026-01-14T16:20:15.309013", "ingestion_ts": "2026-01-14T16:33:58.842229", "market_id": "0xcab7ba4a9133cfd407d7e73e5757e5abbace413b59421527a31113406c97815c", "raw": {"market": "0xcab7ba4a9133cfd407d7e73e5757e5abbace413b59421527a31113406c97815c", "asset_id": "96361925776989336186111887920533578209326565663637092688733016597062311745569", "price": "0.978", "size": "0", "side": "SELL", "timestamp": "1768404015638", "received_at": "2026-01-14T16:20:15.309013"}}
{"event_type": "price_change", "event_ts": "2026-01-14T16:20:15.476598", "ingestion_ts": "2026-01-14T16:33:58.842229", "market_id": "0x44f08744458b8896620cd3330bc5e1ea69df4199b02d4fc583b3fc96e5d314ce", "raw": {"market": "0x44f08744458b8896620cd3330bc5e1ea69df4199b02d4fc583b3fc96e5d314ce", "asset_id": "72327831507226612545928776794104143393438710920370371172884559893525100761096", "price": "0.907", "size": "0", "side": "BUY", "timestamp": "1768404015798", "received_at": "2026-01-14T16:20:15.476598"}}
{"event_type": "price_change", "event_ts": "2026-01-14T16:20:15.476598", "ingestion_ts": "2026-01-14T16:33:58.842229", "market_id": "0x44f08744458b8896620cd3330bc5e1ea69df4199b02d4fc583b3fc96e5d314ce", "raw": {"market": "0x44f08744458b8896620cd3330bc5e1ea69df4199b02d4fc583b3fc96e5d314ce", "asset_id": "49194009556504828848509244326501559253829462790583873936160989575507522044057", "price": "0.093", "size": "0", "side": "SELL", "timestamp": "1768404015798", "received_at": "2026-01-14T16:20:15.476598"}}
{"event_type": "price_change", "event_ts": "2026-01-14T16:20:15.498160", "ingestion_ts": "2026-01-14T16:33:58.842229", "market_id": "0x44f08744458b8896620cd3330bc5e1ea69df4199b02d4fc583b3fc96e5d314ce", "raw": {"market": "0x44f08744458b8896620cd3330bc5e1ea69df4199b02d4fc583b3fc96e5d314ce", "asset_id": "72327831507226612545928776794104143393438710920370371172884559893525100761096", "price": "0.909", "size": "5", "side": "BUY", "timestamp": "1768404015826", "received_at": "2026-01-14T16:20:15.498160"}}
{"event_type": "price_change", "event_ts": "2026-01-14T16:20:15.498160", "ingestion_ts": "2026-01-14T16:33:58.842229", "market_id": "0x44f08744458b8896620cd3330bc5e1ea69df4199b02d4fc583b3fc96e5d314ce", "raw": {"market": "0x44f08744458b8896620cd3330bc5e1ea69df4199b02d4fc583b3fc96e5d314ce", "asset_id": "49194009556504828848509244326501559253829462790583873936160989575507522044057", "price": "0.091", "size": "5", "side": "SELL", "timestamp": "1768404015826", "received_at": "2026-01-14T16:20:15.498160"}}
{"event_type": "price_change", "event_ts": "2026-01-14T16:20:15.569940", "ingestion_ts": "2026-01-14T16:33:58.842229", "market_id": "0xcab7ba4a9133cfd407d7e73e5757e5abbace413b59421527a31113406c97815c", "raw": {"market": "0xcab7ba4a9133cfd407d7e73e5757e5abbace413b59421527a31113406c97815c", "asset_id": "20002636398944597965698652220992177552927816915094913583821579024925426590022", "price": "0.022", "size": "181.81", "side": "BUY", "timestamp": "1768404015899", "received_at": "2026-01-14T16:20:15.569940"}}
{"event_type": "price_change", "event_ts": "2026-01-14T16:20:15.569940", "ingestion_ts": "2026-01-14T16:33:58.842229", "market_id": "0xcab7ba4a9133cfd407d7e73e5757e5abbace413b59421527a31113406c97815c", "raw": {"market": "0xcab7ba4a9133cfd407d7e73e5757e5abbace413b59421527a31113406c97815c", "asset_id": "96361925776989336186111887920533578209326565663637092688733016597062311745569", "price": "0.978", "size": "181.81", "side": "SELL", "timestamp": "1768404015899", "received_at": "2026-01-14T16:20:15.569940"}}
{"event_type": "price_change", "event_ts": "2026-01-14T16:20:15.793121", "ingestion_ts": "2026-01-14T16:33:58.842229", "market_id": "0xcab7ba4a9133cfd407d7e73e5757e5abbace413b59421527a31113406c97815c", "raw": {"market": "0xcab7ba4a9133cfd407d7e73e5757e5abbace413b59421527a31113406c97815c", "asset_id": "20002636398944597965698652220992177552927816915094913583821579024925426590022", "price": "0.043", "size": "0", "side": "BUY", "timestamp": "1768404016122", "received_at": "2026-01-14T16:20:15.793121"}}
{"event_type": "price_change", "event_ts": "2026-01-14T16:20:15.793121", "ingestion_ts": "2026-01-14T16:33:58.842229", "market_id": "0xcab7ba4a9133cfd407d7e73e5757e5abbace413b59421527a31113406c97815c", "raw": {"market": "0xcab7ba4a9133cfd407d7e73e5757e5abbace413b59421527a31113406c97815c", "asset_id": "96361925776989336186111887920533578209326565663637092688733016597062311745569", "price": "0.957", "size": "0", "side": "SELL", "timestamp": "1768404016122", "received_at": "2026-01-14T16:20:15.793121"}}
{"event_type": "price_change", "event_ts": "2026-01-14T16:20:16.019837", "ingestion_ts": "2026-01-14T16:33:58.842229", "market_id": "0xcab7ba4a9133cfd407d7e73e5757e5abbace413b59421527a31113406c97815c", "raw": {"market": "0xcab7ba4a9133cfd407d7e73e5757e5abbace413b59421527a31113406c97815c", "asset_id": "20002636398944597965698652220992177552927816915094913583821579024925426590022", "price": "0.043", "size": "93.02", "side": "BUY", "timestamp": "1768404016336", "received_at": "2026-01-14T16:20:16.019837"}}
{"event_type": "price_change", "event_ts": "2026-01-14T16:20:16.019837", "ingestion_ts": "2026-01-14T16:33:58.842229", "market_id": "0xcab7ba4a9133cfd407d7e73e5757e5abbace413b59421527a31113406c97815c", "raw": {"market": "0xcab7ba4a9133cfd407d7e73e5757e5abbace413b59421527a31113406c97815c", "asset_id": "96361925776989336186111887920533578209326565663637092688733016597062311745569", "price": "0.957", "size": "93.02", "side": "SELL", "timestamp": "1768404016336", "received_at": "2026-01-14T16:20:16.019837"}}
{"event_type": "price_change", "event_ts": "2026-01-14T16:20:16.215803", "ingestion_ts": "2026-01-14T16:33:58.842229", "market_id": "0x49686d26fb712515cd5e12c23f0a1c7e10214c7faa3cb0a730aabe0c33694082", "raw": {"market": "0x49686d26fb712515cd5e12c23f0a1c7e10214c7faa3cb0a730aabe0c33694082", "asset_id": "30442780799048074404860985387051749017905070253466005720364298335239299761065", "price": "0.094", "size": "0", "side": "BUY", "timestamp": "1768404016524", "received_at": "2026-01-14T16:20:16.215803"}}
{"event_type": "price_change", "event_ts": "2026-01-14T16:20:16.215803", "ingestion_ts": "2026-01-14T16:33:58.842229", "market_id": "0x49686d26fb712515cd5e12c23f0a1c7e10214c7faa3cb0a730aabe0c33694082", "raw": {"market": "0x49686d26fb712515cd5e12c23f0a1c7e10214c7faa3cb0a730aabe0c33694082", "asset_id": "13244681086321087932946246027856416106585284024824496763706748621681543444582", "price": "0.906", "size": "0", "side": "SELL", "timestamp": "1768404016524", "received_at": "2026-01-14T16:20:16.215803"}}
{"event_type": "price_change", "event_ts": "2026-01-14T16:20:16.270113", "ingestion_ts": "2026-01-14T16:33:58.842229", "market_id": "0xcab7ba4a9133cfd407d7e73e5757e5abbace413b59421527a31113406c97815c", "raw": {"market": "0xcab7ba4a9133cfd407d7e73e5757e5abbace413b59421527a31113406c97815c", "asset_id": "20002636398944597965698652220992177552927816915094913583821579024925426590022", "price": "0.053", "size": "0", "side": "BUY", "timestamp": "1768404016559", "received_at": "2026-01-14T16:20:16.270113"}}
{"event_type": "price_change", "event_ts": "2026-01-14T16:20:16.270113", "ingestion_ts": "2026-01-14T16:33:58.842229", "market_id": "0xcab7ba4a9133cfd407d7e73e5757e5abbace413b59421527a31113406c97815c", "raw": {"market": "0xcab7ba4a9133cfd407d7e73e5757e5abbace413b59421527a31113406c97815c", "asset_id": "96361925776989336186111887920533578209326565663637092688733016597062311745569", "price": "0.947", "size": "0", "side": "SELL", "timestamp": "1768404016559", "received_at": "2026-01-14T16:20:16.270113"}}
{"event_type": "price_change", "event_ts": "2026-01-14T16:20:16.603590", "ingestion_ts": "2026-01-14T16:33:58.842229", "market_id": "0xcab7ba4a9133cfd407d7e73e5757e5abbace413b59421527a31113406c97815c", "raw": {"market": "0xcab7ba4a9133cfd407d7e73e5757e5abbace413b59421527a31113406c97815c", "asset_id": "20002636398944597965698652220992177552927816915094913583821579024925426590022", "price": "0.053", "size": "75.47", "side": "BUY", "timestamp": "1768404016808", "received_at": "2026-01-14T16:20:16.603590"}}
{"event_type": "price_change", "event_ts": "2026-01-14T16:20:16.603590", "ingestion_ts": "2026-01-14T16:33:58.842229", "market_id": "0xcab7ba4a9133cfd407d7e73e5757e5abbace413b59421527a31113406c97815c", "raw": {"market": "0xcab7ba4a9133cfd407d7e73e5757e5abbace413b59421527a31113406c97815c", "asset_id": "96361925776989336186111887920533578209326565663637092688733016597062311745569", "price": "0.947", "size": "75.47", "side": "SELL", "timestamp": "1768404016808", "received_at": "2026-01-14T16:20:16.603590"}}
{"event_type": "price_change", "event_ts": "2026-01-14T16:20:16.785172", "ingestion_ts": "2026-01-14T16:33:58.842229", "market_id": "0xcab7ba4a9133cfd407d7e73e5757e5abbace413b59421527a31113406c97815c", "raw": {"market": "0xcab7ba4a9133cfd407d7e73e5757e5abbace413b59421527a31113406c97815c", "asset_id": "20002636398944597965698652220992177552927816915094913583821579024925426590022", "price": "0.104", "size": "38.46", "side": "BUY", "timestamp": "1768404017025", "received_at": "2026-01-14T16:20:16.785172"}}
{"event_type": "price_change", "event_ts": "2026-01-14T16:20:16.785172", "ingestion_ts": "2026-01-14T16:33:58.842229", "market_id": "0xcab7ba4a9133cfd407d7e73e5757e5abbace413b59421527a31113406c97815c", "raw": {"market": "0xcab7ba4a9133cfd407d7e73e5757e5abbace413b59421527a31113406c97815c", "asset_id": "96361925776989336186111887920533578209326565663637092688733016597062311745569", "price": "0.896", "size": "38.46", "side": "SELL", "timestamp": "1768404017025", "received_at": "2026-01-14T16:20:16.785172"}}
{"event_type": "price_change", "event_ts": "2026-01-14T16:20:17.063039", "ingestion_ts": "2026-01-14T16:33:58.842229", "market_id": "0xcab7ba4a9133cfd407d7e73e5757e5abbace413b59421527a31113406c97815c", "raw": {"market": "0xcab7ba4a9133cfd407d7e73e5757e5abbace413b59421527a31113406c97815c", "asset_id": "20002636398944597965698652220992177552927816915094913583821579024925426590022", "price": "0.123", "size": "0", "side": "BUY", "timestamp": "1768404017277", "received_at": "2026-01-14T16:20:17.063039"}}
{"event_type": "price_change", "event_ts": "2026-01-14T16:20:17.063039", "ingestion_ts": "2026-01-14T16:33:58.842229", "market_id": "0xcab7ba4a9133cfd407d7e73e5757e5abbace413b59421527a31113406c97815c", "raw": {"market": "0xcab7ba4a9133cfd407d7e73e5757e5abbace413b59421527a31113406c97815c", "asset_id": "96361925776989336186111887920533578209326565663637092688733016597062311745569", "price": "0.877", "size": "0", "side": "SELL", "timestamp": "1768404017277", "received_at": "2026-01-14T16:20:17.063039"}}
{"event_type": "price_change", "event_ts": "2026-01-14T16:20:17.202323", "ingestion_ts": "2026-01-14T16:33:58.842229", "market_id": "0xcab7ba4a9133cfd407d7e73e5757e5abbace413b59421527a31113406c97815c", "raw": {"market": "0xcab7ba4a9133cfd407d7e73e5757e5abbace413b59421527a31113406c97815c", "asset_id": "20002636398944597965698652220992177552927816915094913583821579024925426590022", "price": "0.123", "size": "32.52", "side": "BUY", "timestamp": "1768404017506", "received_at": "2026-01-14T16:20:17.202323"}}
{"event_type": "price_change", "event_ts": "2026-01-14T16:20:17.202323", "ingestion_ts": "2026-01-14T16:33:58.842229", "market_id": "0xcab7ba4a9133cfd407d7e73e5757e5abbace413b59421527a31113406c97815c", "raw": {"market": "0xcab7ba4a9133cfd407d7e73e5757e5abbace413b59421527a31113406c97815c", "asset_id": "96361925776989336186111887920533578209326565663637092688733016597062311745569", "price": "0.877", "size": "32.52", "side": "SELL", "timestamp": "1768404017506", "received_at": "2026-01-14T16:20:17.202323"}}
{"event_type": "price_change", "event_ts": "2026-01-14T16:20:17.422197", "ingestion_ts": "2026-01-14T16:33:58.842229", "market_id": "0xcab7ba4a9133cfd407d7e73e5757e5abbace413b59421527a31113406c97815c", "raw": {"market": "0xcab7ba4a9133cfd407d7e73e5757e5abbace413b59421527a31113406c97815c", "asset_id": "20002636398944597965698652220992177552927816915094913583821579024925426590022", "price": "0.151", "size": "0", "side": "BUY", "timestamp": "1768404017751", "received_at": "2026-01-14T16:20:17.422197"}}
{"event_type": "price_change", "event_ts": "2026-01-14T16:20:17.422197", "ingestion_ts": "2026-01-14T16:33:58.842229", "market_id": "0xcab7ba4a9133cfd407d7e73e5757e5abbace413b59421527a31113406c97815c", "raw": {"market": "0xcab7ba4a9133cfd407d7e73e5757e5abbace413b59421527a31113406c97815c", "asset_id": "96361925776989336186111887920533578209326565663637092688733016597062311745569", "price": "0.849", "size": "0", "side": "SELL", "timestamp": "1768404017751", "received_at": "2026-01-14T16:20:17.422197"}}
{"event_type": "price_change", "event_ts": "2026-01-14T16:20:17.691071", "ingestion_ts": "2026-01-14T16:33:58.842229", "market_id": "0xcab7ba4a9133cfd407d7e73e5757e5abbace413b59421527a31113406c97815c", "raw": {"market": "0xcab7ba4a9133cfd407d7e73e5757e5abbace413b59421527a31113406c97815c", "asset_id": "20002636398944597965698652220992177552927816915094913583821579024925426590022", "price": "0.151", "size": "26.49", "side": "BUY", "timestamp": "1768404018017", "received_at": "2026-01-14T16:20:17.691071"}}
{"event_type": "price_change", "event_ts": "2026-01-14T16:20:17.691071", "ingestion_ts": "2026-01-14T16:33:58.842229", "market_id": "0xcab7ba4a9133cfd407d7e73e5757e5abbace413b59421527a31113406c97815c", "raw": {"market": "0xcab7ba4a9133cfd407d7e73e5757e5abbace413b59421527a31113406c97815c", "asset_id": "96361925776989336186111887920533578209326565663637092688733016597062311745569", "price": "0.849", "size": "26.49", "side": "SELL", "timestamp": "1768404018017", "received_at": "2026-01-14T16:20:17.691071"}}
{"event_type": "price_change", "event_ts": "2026-01-14T16:20:17.939124", "ingestion_ts": "2026-01-14T16:33:58.842229", "market_id": "0xcab7ba4a9133cfd407d7e73e5757e5abbace413b59421527a31113406c97815c", "raw": {"market": "0xcab7ba4a9133cfd407d7e73e5757e5abbace413b59421527a31113406c97815c", "asset_id": "20002636398944597965698652220992177552927816915094913583821579024925426590022", "price": "0.169", "size": "0", "side": "BUY", "timestamp": "1768404018269", "received_at": "2026-01-14T16:20:17.939124"}}
{"event_type": "price_change", "event_ts": "2026-01-14T16:20:17.939124", "ingestion_ts": "2026-01-14T16:33:58.842229", "market_id": "0xcab7ba4a9133cfd407d7e73e5757e5abbace413b59421527a31113406c97815c", "raw": {"market": "0xcab7ba4a9133cfd407d7e73e5757e5abbace413b59421527a31113406c97815c", "asset_id": "96361925776989336186111887920533578209326565663637092688733016597062311745569", "price": "0.831", "size": "0", "side": "SELL", "timestamp": "1768404018269", "received_at": "2026-01-14T16:20:17.939124"}}
{"event_type": "price_change", "event_ts": "2026-01-14T16:20:18.171560", "ingestion_ts": "2026-01-14T16:33:58.842229", "market_id": "0xcab7ba4a9133cfd407d7e73e5757e5abbace413b59421527a31113406c97815c", "raw": {"market": "0xcab7ba4a9133cfd407d7e73e5757e5abbace413b59421527a31113406c97815c", "asset_id": "20002636398944597965698652220992177552927816915094913583821579024925426590022", "price": "0.169", "size": "23.66", "side": "BUY", "timestamp": "1768404018499", "received_at": "2026-01-14T16:20:18.171560"}}
{"event_type": "price_change", "event_ts": "2026-01-14T16:20:18.171560", "ingestion_ts": "2026-01-14T16:33:58.842229", "market_id": "0xcab7ba4a9133cfd407d7e73e5757e5abbace413b59421527a31113406c97815c", "raw": {"market": "0xcab7ba4a9133cfd407d7e73e5757e5abbace413b59421527a31113406c97815c", "asset_id": "96361925776989336186111887920533578209326565663637092688733016597062311745569", "price": "0.831", "size": "23.66", "side": "SELL", "timestamp": "1768404018499", "received_at": "2026-01-14T16:20:18.171560"}}
{"event_type": "price_change", "event_ts": "2026-01-14T16:20:18.439148", "ingestion_ts": "2026-01-14T16:33:58.842229", "market_id": "0xcab7ba4a9133cfd407d7e73e5757e5abbace413b59421527a31113406c97815c", "raw": {"market": "0xcab7ba4a9133cfd407d7e73e5757e5abbace413b59421527a31113406c97815c", "asset_id": "20002636398944597965698652220992177552927816915094913583821579024925426590022", "price": "0.201", "size": "17.05", "side": "BUY", "timestamp": "1768404018720", "received_at": "2026-01-14T16:20:18.439148"}}
{"event_type": "price_change", "event_ts": "2026-01-14T16:20:18.439148", "ingestion_ts": "2026-01-14T16:33:58.842229", "market_id": "0xcab7ba4a9133cfd407d7e73e5757e5abbace413b59421527a31113406c97815c", "raw": {"market": "0xcab7ba4a9133cfd407d7e73e5757e5abbace413b59421527a31113406c97815c", "asset_id": "96361925776989336186111887920533578209326565663637092688733016597062311745569", "price": "0.799", "size": "17.05", "side": "SELL", "timestamp": "1768404018720", "received_at": "2026-01-14T16:20:18.439148"}}
{"event_type": "price_change", "event_ts": "2026-01-14T16:20:18.649335", "ingestion_ts": "2026-01-14T16:33:58.842229", "market_id": "0xcab7ba4a9133cfd407d7e73e5757e5abbace413b59421527a31113406c97815c", "raw": {"market": "0xcab7ba4a9133cfd407d7e73e5757e5abbace413b59421527a31113406c97815c", "asset_id": "20002636398944597965698652220992177552927816915094913583821579024925426590022", "price": "0.201", "size": "36.95", "side": "BUY", "timestamp": "1768404018955", "received_at": "2026-01-14T16:20:18.649335"}}
{"event_type": "price_change", "event_ts": "2026-01-14T16:20:18.649335", "ingestion_ts": "2026-01-14T16:33:58.842229", "market_id": "0xcab7ba4a9133cfd407d7e73e5757e5abbace413b59421527a31113406c97815c", "raw": {"market": "0xcab7ba4a9133cfd407d7e73e5757e5abbace413b59421527a31113406c97815c", "asset_id": "96361925776989336186111887920533578209326565663637092688733016597062311745569", "price": "0.799", "size": "36.95", "side": "SELL", "timestamp": "1768404018955", "received_at": "2026-01-14T16:20:18.649335"}}
{"event_type": "price_change", "event_ts": "2026-01-14T16:20:18.800915", "ingestion_ts": "2026-01-14T16:33:58.842229", "market_id": "0x2393ed0b0fdc450054c7b9071907eca75cf4fc36e385adf4a0a5f99ee62243e8", "raw": {"market": "0x2393ed0b0fdc450054c7b9071907eca75cf4fc36e385adf4a0a5f99ee62243e8", "asset_id": "32769749367306925959219403371425714180265458150646381231272229429098460625924", "price": "0.114", "size": "2104", "side": "BUY", "timestamp": "1768404019058", "received_at": "2026-01-14T16:20:18.800915"}}
{"event_type": "price_change", "event_ts": "2026-01-14T16:20:18.800915", "ingestion_ts": "2026-01-14T16:33:58.842229", "market_id": "0x2393ed0b0fdc450054c7b9071907eca75cf4fc36e385adf4a0a5f99ee62243e8", "raw": {"market": "0x2393ed0b0fdc450054c7b9071907eca75cf4fc36e385adf4a0a5f99ee62243e8", "asset_id": "100074770378634056601572485653252702850363676459996771990439989989293515601975", "price": "0.886", "size": "2104", "side": "SELL", "timestamp": "1768404019058", "received_at": "2026-01-14T16:20:18.800915"}}
{"event_type": "price_change", "event_ts": "2026-01-14T16:20:18.845369", "ingestion_ts": "2026-01-14T16:33:58.842229", "market_id": "0x49686d26fb712515cd5e12c23f0a1c7e10214c7faa3cb0a730aabe0c33694082", "raw": {"market": "0x49686d26fb712515cd5e12c23f0a1c7e10214c7faa3cb0a730aabe0c33694082", "asset_id": "13244681086321087932946246027856416106585284024824496763706748621681543444582", "price": "0.116", "size": "2068", "side": "BUY", "timestamp": "1768404019140", "received_at": "2026-01-14T16:20:18.845369"}}
{"event_type": "price_change", "event_ts": "2026-01-14T16:20:18.845369", "ingestion_ts": "2026-01-14T16:33:58.842229", "market_id": "0x49686d26fb712515cd5e12c23f0a1c7e10214c7faa3cb0a730aabe0c33694082", "raw": {"market": "0x49686d26fb712515cd5e12c23f0a1c7e10214c7faa3cb0a730aabe0c33694082", "asset_id": "30442780799048074404860985387051749017905070253466005720364298335239299761065", "price": "0.884", "size": "2068", "side": "SELL", "timestamp": "1768404019140", "received_at": "2026-01-14T16:20:18.845369"}}
{"event_type": "price_change", "event_ts": "2026-01-14T16:20:18.866274", "ingestion_ts": "2026-01-14T16:33:58.842229", "market_id": "0xcab7ba4a9133cfd407d7e73e5757e5abbace413b59421527a31113406c97815c", "raw": {"market": "0xcab7ba4a9133cfd407d7e73e5757e5abbace413b59421527a31113406c97815c", "asset_id": "20002636398944597965698652220992177552927816915094913583821579024925426590022", "price": "0.224", "size": "0", "side": "BUY", "timestamp": "1768404019173", "received_at": "2026-01-14T16:20:18.866274"}}
{"event_type": "price_change", "event_ts": "2026-01-14T16:20:18.866274", "ingestion_ts": "2026-01-14T16:33:58.842229", "market_id": "0xcab7ba4a9133cfd407d7e73e5757e5abbace413b59421527a31113406c97815c", "raw": {"market": "0xcab7ba4a9133cfd407d7e73e5757e5abbace413b59421527a31113406c97815c", "asset_id": "96361925776989336186111887920533578209326565663637092688733016597062311745569", "price": "0.776", "size": "0", "side": "SELL", "timestamp": "1768404019173", "received_at": "2026-01-14T16:20:18.866274"}}
{"event_type": "price_change", "event_ts": "2026-01-14T16:20:19.072533", "ingestion_ts": "2026-01-14T16:33:58.842229", "market_id": "0xcab7ba4a9133cfd407d7e73e5757e5abbace413b59421527a31113406c97815c", "raw": {"market": "0xcab7ba4a9133cfd407d7e73e5757e5abbace413b59421527a31113406c97815c", "asset_id": "20002636398944597965698652220992177552927816915094913583821579024925426590022", "price": "0.224", "size": "17.85", "side": "BUY", "timestamp": "1768404019392", "received_at": "2026-01-14T16:20:19.072533"}}
{"event_type": "price_change", "event_ts": "2026-01-14T16:20:19.072533", "ingestion_ts": "2026-01-14T16:33:58.842229", "market_id": "0xcab7ba4a9133cfd407d7e73e5757e5abbace413b59421527a31113406c97815c", "raw": {"market": "0xcab7ba4a9133cfd407d7e73e5757e5abbace413b59421527a31113406c97815c", "asset_id": "96361925776989336186111887920533578209326565663637092688733016597062311745569", "price": "0.776", "size": "17.85", "side": "SELL", "timestamp": "1768404019392", "received_at": "2026-01-14T16:20:19.072533"}}
{"event_type": "price_change", "event_ts": "2026-01-14T16:20:19.289920", "ingestion_ts": "2026-01-14T16:33:58.842229", "market_id": "0xcab7ba4a9133cfd407d7e73e5757e5abbace413b59421527a31113406c97815c", "raw": {"market": "0xcab7ba4a9133cfd407d7e73e5757e5abbace413b59421527a31113406c97815c", "asset_id": "20002636398944597965698652220992177552927816915094913583821579024925426590022", "price": "0.254", "size": "0", "side": "BUY", "timestamp": "1768404019619", "received_at": "2026-01-14T16:20:19.289920"}}
{"event_type": "price_change", "event_ts": "2026-01-14T16:20:19.289920", "ingestion_ts": "2026-01-14T16:33:58.842229", "market_id": "0xcab7ba4a9133cfd407d7e73e5757e5abbace413b59421527a31113406c97815c", "raw": {"market": "0xcab7ba4a9133cfd407d7e73e5757e5abbace413b59421527a31113406c97815c", "asset_id": "96361925776989336186111887920533578209326565663637092688733016597062311745569", "price": "0.746", "size": "0", "side": "SELL", "timestamp": "1768404019619", "received_at": "2026-01-14T16:20:19.289920"}}
{"event_type": "price_change", "event_ts": "2026-01-14T16:20:19.541798", "ingestion_ts": "2026-01-14T16:33:58.842229", "market_id": "0xcab7ba4a9133cfd407d7e73e5757e5abbace413b59421527a31113406c97815c", "raw": {"market": "0xcab7ba4a9133cfd407d7e73e5757e5abbace413b59421527a31113406c97815c", "asset_id": "20002636398944597965698652220992177552927816915094913583821579024925426590022", "price": "0.254", "size": "15.74", "side": "BUY", "timestamp": "1768404019868", "received_at": "2026-01-14T16:20:19.541798"}}
{"event_type": "price_change", "event_ts": "2026-01-14T16:20:19.541798", "ingestion_ts": "2026-01-14T16:33:58.842229", "market_id": "0xcab7ba4a9133cfd407d7e73e5757e5abbace413b59421527a31113406c97815c", "raw": {"market": "0xcab7ba4a9133cfd407d7e73e5757e5abbace413b59421527a31113406c97815c", "asset_id": "96361925776989336186111887920533578209326565663637092688733016597062311745569", "price": "0.746", "size": "15.74", "side": "SELL", "timestamp": "1768404019868", "received_at": "2026-01-14T16:20:19.541798"}}
{"event_type": "price_change", "event_ts": "2026-01-14T16:20:19.783040", "ingestion_ts": "2026-01-14T16:33:58.842229", "market_id": "0xcab7ba4a9133cfd407d7e73e5757e5abbace413b59421527a31113406c97815c", "raw": {"market": "0xcab7ba4a9133cfd407d7e73e5757e5abbace413b59421527a31113406c97815c", "asset_id": "20002636398944597965698652220992177552927816915094913583821579024925426590022", "price": "0.384", "size": "10.41", "side": "BUY", "timestamp": "1768404020108", "received_at": "2026-01-14T16:20:19.783040"}}
{"event_type": "price_change", "event_ts": "2026-01-14T16:20:19.783040", "ingestion_ts": "2026-01-14T16:33:58.842229", "market_id": "0xcab7ba4a9133cfd407d7e73e5757e5abbace413b59421527a31113406c97815c", "raw": {"market": "0xcab7ba4a9133cfd407d7e73e5757e5abbace413b59421527a31113406c97815c", "asset_id": "96361925776989336186111887920533578209326565663637092688733016597062311745569", "price": "0.616", "size": "10.41", "side": "SELL", "timestamp": "1768404020108", "received_at": "2026-01-14T16:20:19.783040"}}
{"event_type": "price_change", "event_ts": "2026-01-14T16:20:19.988456", "ingestion_ts": "2026-01-14T16:33:58.842229", "market_id": "0xcab7ba4a9133cfd407d7e73e5757e5abbace413b59421527a31113406c97815c", "raw": {"market": "0xcab7ba4a9133cfd407d7e73e5757e5abbace413b59421527a31113406c97815c", "asset_id": "20002636398944597965698652220992177552927816915094913583821579024925426590022", "price": "0.477", "size": "0", "side": "BUY", "timestamp": "1768404020309", "received_at": "2026-01-14T16:20:19.988456"}}
{"event_type": "price_change", "event_ts": "2026-01-14T16:20:19.988456", "ingestion_ts": "2026-01-14T16:33:58.842229", "market_id": "0xcab7ba4a9133cfd407d7e73e5757e5abbace413b59421527a31113406c97815c", "raw": {"market": "0xcab7ba4a9133cfd407d7e73e5757e5abbace413b59421527a31113406c97815c", "asset_id": "96361925776989336186111887920533578209326565663637092688733016597062311745569", "price": "0.523", "size": "0", "side": "SELL", "timestamp": "1768404020309", "received_at": "2026-01-14T16:20:19.988456"}}
{"event_type": "price_change", "event_ts": "2026-01-14T16:20:20.184673", "ingestion_ts": "2026-01-14T16:33:58.842229", "market_id": "0xcab7ba4a9133cfd407d7e73e5757e5abbace413b59421527a31113406c97815c", "raw": {"market": "0xcab7ba4a9133cfd407d7e73e5757e5abbace413b59421527a31113406c97815c", "asset_id": "20002636398944597965698652220992177552927816915094913583821579024925426590022", "price": "0.477", "size": "8.38", "side": "BUY", "timestamp": "1768404020514", "received_at": "2026-01-14T16:20:20.184673"}}
{"event_type": "price_change", "event_ts": "2026-01-14T16:20:20.184673", "ingestion_ts": "2026-01-14T16:33:58.842229", "market_id": "0xcab7ba4a9133cfd407d7e73e5757e5abbace413b59421527a31113406c97815c", "raw": {"market": "0xcab7ba4a9133cfd407d7e73e5757e5abbace413b59421527a31113406c97815c", "asset_id": "96361925776989336186111887920533578209326565663637092688733016597062311745569", "price": "0.523", "size": "8.38", "side": "SELL", "timestamp": "1768404020514", "received_at": "2026-01-14T16:20:20.184673"}}
{"event_type": "price_change", "event_ts": "2026-01-14T16:20:23.386868", "ingestion_ts": "2026-01-14T16:33:58.842229", "market_id": "0xe68594f1350f5535532b24979b5b5c1948432cbfc0c363802c32a8f9ab4e6509", "raw": {"market": "0xe68594f1350f5535532b24979b5b5c1948432cbfc0c363802c32a8f9ab4e6509", "asset_id": "3074032031589250926591186368301243337494992039402397918135503567058257050088", "price": "0.304", "size": "0", "side": "BUY", "timestamp": "1768404023705", "received_at": "2026-01-14T16:20:23.386868"}}
{"event_type": "price_change", "event_ts": "2026-01-14T16:20:23.386868", "ingestion_ts": "2026-01-14T16:33:58.842229", "market_id": "0xe68594f1350f5535532b24979b5b5c1948432cbfc0c363802c32a8f9ab4e6509", "raw": {"market": "0xe68594f1350f5535532b24979b5b5c1948432cbfc0c363802c32a8f9ab4e6509", "asset_id": "47459180813047899567328389455747872955901265556145057896316155826890276004242", "price": "0.696", "size": "0", "side": "SELL", "timestamp": "1768404023705", "received_at": "2026-01-14T16:20:23.386868"}}
{"event_type": "price_change", "event_ts": "2026-01-14T16:20:23.438674", "ingestion_ts": "2026-01-14T16:33:58.842229", "market_id": "0xe68594f1350f5535532b24979b5b5c1948432cbfc0c363802c32a8f9ab4e6509", "raw": {"market": "0xe68594f1350f5535532b24979b5b5c1948432cbfc0c363802c32a8f9ab4e6509", "asset_id": "3074032031589250926591186368301243337494992039402397918135503567058257050088", "price": "0.304", "size": "6", "side": "BUY", "timestamp": "1768404023767", "received_at": "2026-01-14T16:20:23.438674"}}
{"event_type": "price_change", "event_ts": "2026-01-14T16:20:23.438674", "ingestion_ts": "2026-01-14T16:33:58.842229", "market_id": "0xe68594f1350f5535532b24979b5b5c1948432cbfc0c363802c32a8f9ab4e6509", "raw": {"market": "0xe68594f1350f5535532b24979b5b5c1948432cbfc0c363802c32a8f9ab4e6509", "asset_id": "47459180813047899567328389455747872955901265556145057896316155826890276004242", "price": "0.696", "size": "6", "side": "SELL", "timestamp": "1768404023767", "received_at": "2026-01-14T16:20:23.438674"}}
{"event_type": "price_change", "event_ts": "2026-01-14T16:20:25.851037", "ingestion_ts": "2026-01-14T16:33:58.842229", "market_id": "0xb9bbdd34304344dcc45803780a34c97d73a00133a5ecf70f63e1008b8abb2fca", "raw": {"market": "0xb9bbdd34304344dcc45803780a34c97d73a00133a5ecf70f63e1008b8abb2fca", "asset_id": "8682484153073832526711485265636767086525069344085206423986003504588877767339", "price": "0.88", "size": "820.47", "side": "BUY", "timestamp": "1768404026172", "received_at": "2026-01-14T16:20:25.851037"}}
{"event_type": "price_change", "event_ts": "2026-01-14T16:20:25.851037", "ingestion_ts": "2026-01-14T16:33:58.842229", "market_id": "0xb9bbdd34304344dcc45803780a34c97d73a00133a5ecf70f63e1008b8abb2fca", "raw": {"market": "0xb9bbdd34304344dcc45803780a34c97d73a00133a5ecf70f63e1008b8abb2fca", "asset_id": "72012724360700510767037780555710363830014634797787940282136454146828040926557", "price": "0.12", "size": "820.47", "side": "SELL", "timestamp": "1768404026172", "received_at": "2026-01-14T16:20:25.851037"}}
{"event_type": "price_change", "event_ts": "2026-01-14T16:20:27.955391", "ingestion_ts": "2026-01-14T16:33:58.842229", "market_id": "0x318b222c1435b47c338e66ca6001f782711186a488ae7b7248f7edc6ff076a83", "raw": {"market": "0x318b222c1435b47c338e66ca6001f782711186a488ae7b7248f7edc6ff076a83", "asset_id": "63773739594775606083258239254748928077067768053882704658119720069071630213026", "price": "0.205", "size": "0", "side": "BUY", "timestamp": "1768404028114", "received_at": "2026-01-14T16:20:27.955391"}}
{"event_type": "price_change", "event_ts": "2026-01-14T16:20:27.955391", "ingestion_ts": "2026-01-14T16:33:58.842229", "market_id": "0x318b222c1435b47c338e66ca6001f782711186a488ae7b7248f7edc6ff076a83", "raw": {"market": "0x318b222c1435b47c338e66ca6001f782711186a488ae7b7248f7edc6ff076a83", "asset_id": "56738600572035832904895845056468792275697823297413384908752239327866518310010", "price": "0.795", "size": "0", "side": "SELL", "timestamp": "1768404028114", "received_at": "2026-01-14T16:20:27.955391"}}
{"event_type": "price_change", "event_ts": "2026-01-14T16:20:51.442094", "ingestion_ts": "2026-01-14T16:33:58.842229", "market_id": "0xaf9d0e448129a9f657f851d49495ba4742055d80e0ef1166ba0ee81d4d594214", "raw": {"market": "0xaf9d0e448129a9f657f851d49495ba4742055d80e0ef1166ba0ee81d4d594214", "asset_id": "4153292802911610701832309484716814274802943278345248636922528170020319407796", "price": "0.879", "size": "820.47", "side": "BUY", "timestamp": "1768404051752", "received_at": "2026-01-14T16:20:51.442094"}}
{"event_type": "price_change", "event_ts": "2026-01-14T16:20:51.442094", "ingestion_ts": "2026-01-14T16:33:58.842229", "market_id": "0xaf9d0e448129a9f657f851d49495ba4742055d80e0ef1166ba0ee81d4d594214", "raw": {"market": "0xaf9d0e448129a9f657f851d49495ba4742055d80e0ef1166ba0ee81d4d594214", "asset_id": "101676997363687199724245607342877036148401850938023978421879460310389391082353", "price": "0.121", "size": "820.47", "side": "SELL", "timestamp": "1768404051752", "received_at": "2026-01-14T16:20:51.442094"}}
{"event_type": "price_change", "event_ts": "2026-01-14T16:20:51.465188", "ingestion_ts": "2026-01-14T16:33:58.842229", "market_id": "0xaf9d0e448129a9f657f851d49495ba4742055d80e0ef1166ba0ee81d4d594214", "raw": {"market": "0xaf9d0e448129a9f657f851d49495ba4742055d80e0ef1166ba0ee81d4d594214", "asset_id": "101676997363687199724245607342877036148401850938023978421879460310389391082353", "price": "0.018", "size": "0", "side": "BUY", "timestamp": "1768404051786", "received_at": "2026-01-14T16:20:51.465188"}}
{"event_type": "price_change", "event_ts": "2026-01-14T16:20:51.465188", "ingestion_ts": "2026-01-14T16:33:58.842229", "market_id": "0xaf9d0e448129a9f657f851d49495ba4742055d80e0ef1166ba0ee81d4d594214", "raw": {"market": "0xaf9d0e448129a9f657f851d49495ba4742055d80e0ef1166ba0ee81d4d594214", "asset_id": "4153292802911610701832309484716814274802943278345248636922528170020319407796", "price": "0.982", "size": "0", "side": "SELL", "timestamp": "1768404051786", "received_at": "2026-01-14T16:20:51.465188"}}
{"event_type": "price_change", "event_ts": "2026-01-14T16:20:51.489304", "ingestion_ts": "2026-01-14T16:33:58.842229", "market_id": "0xaf9d0e448129a9f657f851d49495ba4742055d80e0ef1166ba0ee81d4d594214", "raw": {"market": "0xaf9d0e448129a9f657f851d49495ba4742055d80e0ef1166ba0ee81d4d594214", "asset_id": "101676997363687199724245607342877036148401850938023978421879460310389391082353", "price": "0.016", "size": "128.13", "side": "BUY", "timestamp": "1768404051818", "received_at": "2026-01-14T16:20:51.489304"}}
{"event_type": "price_change", "event_ts": "2026-01-14T16:20:51.489304", "ingestion_ts": "2026-01-14T16:33:58.842229", "market_id": "0xaf9d0e448129a9f657f851d49495ba4742055d80e0ef1166ba0ee81d4d594214", "raw": {"market": "0xaf9d0e448129a9f657f851d49495ba4742055d80e0ef1166ba0ee81d4d594214", "asset_id": "4153292802911610701832309484716814274802943278345248636922528170020319407796", "price": "0.984", "size": "128.13", "side": "SELL", "timestamp": "1768404051818", "received_at": "2026-01-14T16:20:51.489304"}}
{"event_type": "price_change", "event_ts": "2026-01-14T16:20:52.286900", "ingestion_ts": "2026-01-14T16:33:58.842229", "market_id": "0xaf9d0e448129a9f657f851d49495ba4742055d80e0ef1166ba0ee81d4d594214", "raw": {"market": "0xaf9d0e448129a9f657f851d49495ba4742055d80e0ef1166ba0ee81d4d594214", "asset_id": "4153292802911610701832309484716814274802943278345248636922528170020319407796", "price": "0.731", "size": "0", "side": "BUY", "timestamp": "1768404052616", "received_at": "2026-01-14T16:20:52.286900"}}
{"event_type": "price_change", "event_ts": "2026-01-14T16:20:52.286900", "ingestion_ts": "2026-01-14T16:33:58.842229", "market_id": "0xaf9d0e448129a9f657f851d49495ba4742055d80e0ef1166ba0ee81d4d594214", "raw": {"market": "0xaf9d0e448129a9f657f851d49495ba4742055d80e0ef1166ba0ee81d4d594214", "asset_id": "101676997363687199724245607342877036148401850938023978421879460310389391082353", "price": "0.269", "size": "0", "side": "SELL", "timestamp": "1768404052616", "received_at": "2026-01-14T16:20:52.286900"}}
{"event_type": "price_change", "event_ts": "2026-01-14T16:20:52.317879", "ingestion_ts": "2026-01-14T16:33:58.842229", "market_id": "0xaf9d0e448129a9f657f851d49495ba4742055d80e0ef1166ba0ee81d4d594214", "raw": {"market": "0xaf9d0e448129a9f657f851d49495ba4742055d80e0ef1166ba0ee81d4d594214", "asset_id": "4153292802911610701832309484716814274802943278345248636922528170020319407796", "price": "0.88", "size": "5", "side": "BUY", "timestamp": "1768404052648", "received_at": "2026-01-14T16:20:52.317879"}}
{"event_type": "price_change", "event_ts": "2026-01-14T16:20:52.317879", "ingestion_ts": "2026-01-14T16:33:58.842229", "market_id": "0xaf9d0e448129a9f657f851d49495ba4742055d80e0ef1166ba0ee81d4d594214", "raw": {"market": "0xaf9d0e448129a9f657f851d49495ba4742055d80e0ef1166ba0ee81d4d594214", "asset_id": "101676997363687199724245607342877036148401850938023978421879460310389391082353", "price": "0.12", "size": "5", "side": "SELL", "timestamp": "1768404052648", "received_at": "2026-01-14T16:20:52.317879"}}
{"event_type": "price_change", "event_ts": "2026-01-14T16:20:52.376389", "ingestion_ts": "2026-01-14T16:33:58.842229", "market_id": "0xb9bbdd34304344dcc45803780a34c97d73a00133a5ecf70f63e1008b8abb2fca", "raw": {"market": "0xb9bbdd34304344dcc45803780a34c97d73a00133a5ecf70f63e1008b8abb2fca", "asset_id": "8682484153073832526711485265636767086525069344085206423986003504588877767339", "price": "0.883", "size": "0", "side": "BUY", "timestamp": "1768404052705", "received_at": "2026-01-14T16:20:52.376389"}}
{"event_type": "price_change", "event_ts": "2026-01-14T16:20:52.376389", "ingestion_ts": "2026-01-14T16:33:58.842229", "market_id": "0xb9bbdd34304344dcc45803780a34c97d73a00133a5ecf70f63e1008b8abb2fca", "raw": {"market": "0xb9bbdd34304344dcc45803780a34c97d73a00133a5ecf70f63e1008b8abb2fca", "asset_id": "72012724360700510767037780555710363830014634797787940282136454146828040926557", "price": "0.117", "size": "0", "side": "SELL", "timestamp": "1768404052705", "received_at": "2026-01-14T16:20:52.376389"}}
{"event_type": "price_change", "event_ts": "2026-01-14T16:20:53.359504", "ingestion_ts": "2026-01-14T16:33:58.842229", "market_id": "0xb9bbdd34304344dcc45803780a34c97d73a00133a5ecf70f63e1008b8abb2fca", "raw": {"market": "0xb9bbdd34304344dcc45803780a34c97d73a00133a5ecf70f63e1008b8abb2fca", "asset_id": "8682484153073832526711485265636767086525069344085206423986003504588877767339", "price": "0.884", "size": "0", "side": "BUY", "timestamp": "1768404053673", "received_at": "2026-01-14T16:20:53.359504"}}
{"event_type": "price_change", "event_ts": "2026-01-14T16:20:53.359504", "ingestion_ts": "2026-01-14T16:33:58.842229", "market_id": "0xb9bbdd34304344dcc45803780a34c97d73a00133a5ecf70f63e1008b8abb2fca", "raw": {"market": "0xb9bbdd34304344dcc45803780a34c97d73a00133a5ecf70f63e1008b8abb2fca", "asset_id": "72012724360700510767037780555710363830014634797787940282136454146828040926557", "price": "0.116", "size": "0", "side": "SELL", "timestamp": "1768404053673", "received_at": "2026-01-14T16:20:53.359504"}}
{"event_type": "price_change", "event_ts": "2026-01-14T16:20:53.378132", "ingestion_ts": "2026-01-14T16:33:58.842229", "market_id": "0xb9bbdd34304344dcc45803780a34c97d73a00133a5ecf70f63e1008b8abb2fca", "raw": {"market": "0xb9bbdd34304344dcc45803780a34c97d73a00133a5ecf70f63e1008b8abb2fca", "asset_id": "8682484153073832526711485265636767086525069344085206423986003504588877767339", "price": "0.882", "size": "5", "side": "BUY", "timestamp": "1768404053706", "received_at": "2026-01-14T16:20:53.378132"}}
{"event_type": "price_change", "event_ts": "2026-01-14T16:20:53.378132", "ingestion_ts": "2026-01-14T16:33:58.842229", "market_id": "0xb9bbdd34304344dcc45803780a34c97d73a00133a5ecf70f63e1008b8abb2fca", "raw": {"market": "0xb9bbdd34304344dcc45803780a34c97d73a00133a5ecf70f63e1008b8abb2fca", "asset_id": "72012724360700510767037780555710363830014634797787940282136454146828040926557", "price": "0.118", "size": "5", "side": "SELL", "timestamp": "1768404053706", "received_at": "2026-01-14T16:20:53.378132"}}
{"event_type": "price_change", "event_ts": "2026-01-14T16:20:53.506018", "ingestion_ts": "2026-01-14T16:33:58.842229", "market_id": "0xaf9d0e448129a9f657f851d49495ba4742055d80e0ef1166ba0ee81d4d594214", "raw": {"market": "0xaf9d0e448129a9f657f851d49495ba4742055d80e0ef1166ba0ee81d4d594214", "asset_id": "4153292802911610701832309484716814274802943278345248636922528170020319407796", "price": "0.984", "size": "121", "side": "SELL", "timestamp": "1768404053836", "received_at": "2026-01-14T16:20:53.506018"}}
{"event_type": "price_change", "event_ts": "2026-01-14T16:20:53.506018", "ingestion_ts": "2026-01-14T16:33:58.842229", "market_id": "0xaf9d0e448129a9f657f851d49495ba4742055d80e0ef1166ba0ee81d4d594214", "raw": {"market": "0xaf9d0e448129a9f657f851d49495ba4742055d80e0ef1166ba0ee81d4d594214", "asset_id": "101676997363687199724245607342877036148401850938023978421879460310389391082353", "price": "0.016", "size": "121", "side": "BUY", "timestamp": "1768404053836", "received_at": "2026-01-14T16:20:53.506018"}}
{"event_type": "price_change", "event_ts": "2026-01-14T16:20:53.708188", "ingestion_ts": "2026-01-14T16:33:58.842229", "market_id": "0xaf9d0e448129a9f657f851d49495ba4742055d80e0ef1166ba0ee81d4d594214", "raw": {"market": "0xaf9d0e448129a9f657f851d49495ba4742055d80e0ef1166ba0ee81d4d594214", "asset_id": "4153292802911610701832309484716814274802943278345248636922528170020319407796", "price": "0.983", "size": "7.13", "side": "SELL", "timestamp": "1768404054009", "received_at": "2026-01-14T16:20:53.708188"}}
{"event_type": "price_change", "event_ts": "2026-01-14T16:20:53.708188", "ingestion_ts": "2026-01-14T16:33:58.842229", "market_id": "0xaf9d0e448129a9f657f851d49495ba4742055d80e0ef1166ba0ee81d4d594214", "raw": {"market": "0xaf9d0e448129a9f657f851d49495ba4742055d80e0ef1166ba0ee81d4d594214", "asset_id": "101676997363687199724245607342877036148401850938023978421879460310389391082353", "price": "0.017", "size": "7.13", "side": "BUY", "timestamp": "1768404054009", "received_at": "2026-01-14T16:20:53.708188"}}
{"event_type": "price_change", "event_ts": "2026-01-14T16:20:53.713471", "ingestion_ts": "2026-01-14T16:33:58.842229", "market_id": "0xaf9d0e448129a9f657f851d49495ba4742055d80e0ef1166ba0ee81d4d594214", "raw": {"market": "0xaf9d0e448129a9f657f851d49495ba4742055d80e0ef1166ba0ee81d4d594214", "asset_id": "101676997363687199724245607342877036148401850938023978421879460310389391082353", "price": "0.016", "size": "0", "side": "BUY", "timestamp": "1768404054035", "received_at": "2026-01-14T16:20:53.713471"}}
{"event_type": "price_change", "event_ts": "2026-01-14T16:20:53.713471", "ingestion_ts": "2026-01-14T16:33:58.842229", "market_id": "0xaf9d0e448129a9f657f851d49495ba4742055d80e0ef1166ba0ee81d4d594214", "raw": {"market": "0xaf9d0e448129a9f657f851d49495ba4742055d80e0ef1166ba0ee81d4d594214", "asset_id": "4153292802911610701832309484716814274802943278345248636922528170020319407796", "price": "0.984", "size": "0", "side": "SELL", "timestamp": "1768404054035", "received_at": "2026-01-14T16:20:53.713471"}}
{"event_type": "price_change", "event_ts": "2026-01-14T16:20:53.735354", "ingestion_ts": "2026-01-14T16:33:58.842229", "market_id": "0xaf9d0e448129a9f657f851d49495ba4742055d80e0ef1166ba0ee81d4d594214", "raw": {"market": "0xaf9d0e448129a9f657f851d49495ba4742055d80e0ef1166ba0ee81d4d594214", "asset_id": "101676997363687199724245607342877036148401850938023978421879460310389391082353", "price": "0.017", "size": "128.13", "side": "BUY", "timestamp": "1768404054065", "received_at": "2026-01-14T16:20:53.735354"}}
{"event_type": "price_change", "event_ts": "2026-01-14T16:20:53.735354", "ingestion_ts": "2026-01-14T16:33:58.842229", "market_id": "0xaf9d0e448129a9f657f851d49495ba4742055d80e0ef1166ba0ee81d4d594214", "raw": {"market": "0xaf9d0e448129a9f657f851d49495ba4742055d80e0ef1166ba0ee81d4d594214", "asset_id": "4153292802911610701832309484716814274802943278345248636922528170020319407796", "price": "0.983", "size": "128.13", "side": "SELL", "timestamp": "1768404054065", "received_at": "2026-01-14T16:20:53.735354"}}
{"event_type": "price_change", "event_ts": "2026-01-14T16:20:53.809123", "ingestion_ts": "2026-01-14T16:33:58.842229", "market_id": "0x49686d26fb712515cd5e12c23f0a1c7e10214c7faa3cb0a730aabe0c33694082", "raw": {"market": "0x49686d26fb712515cd5e12c23f0a1c7e10214c7faa3cb0a730aabe0c33694082", "asset_id": "30442780799048074404860985387051749017905070253466005720364298335239299761065", "price": "0.042", "size": "0", "side": "BUY", "timestamp": "1768404054137", "received_at": "2026-01-14T16:20:53.809123"}}
{"event_type": "price_change", "event_ts": "2026-01-14T16:20:53.809123", "ingestion_ts": "2026-01-14T16:33:58.842229", "market_id": "0x49686d26fb712515cd5e12c23f0a1c7e10214c7faa3cb0a730aabe0c33694082", "raw": {"market": "0x49686d26fb712515cd5e12c23f0a1c7e10214c7faa3cb0a730aabe0c33694082", "asset_id": "13244681086321087932946246027856416106585284024824496763706748621681543444582", "price": "0.958", "size": "0", "side": "SELL", "timestamp": "1768404054137", "received_at": "2026-01-14T16:20:53.809123"}}
{"event_type": "price_change", "event_ts": "2026-01-14T16:20:53.833266", "ingestion_ts": "2026-01-14T16:33:58.842229", "market_id": "0x49686d26fb712515cd5e12c23f0a1c7e10214c7faa3cb0a730aabe0c33694082", "raw": {"market": "0x49686d26fb712515cd5e12c23f0a1c7e10214c7faa3cb0a730aabe0c33694082", "asset_id": "13244681086321087932946246027856416106585284024824496763706748621681543444582", "price": "0.898", "size": "0", "side": "SELL", "timestamp": "1768404054163", "received_at": "2026-01-14T16:20:53.833266"}}
{"event_type": "price_change", "event_ts": "2026-01-14T16:20:53.833266", "ingestion_ts": "2026-01-14T16:33:58.842229", "market_id": "0x49686d26fb712515cd5e12c23f0a1c7e10214c7faa3cb0a730aabe0c33694082", "raw": {"market": "0x49686d26fb712515cd5e12c23f0a1c7e10214c7faa3cb0a730aabe0c33694082", "asset_id": "30442780799048074404860985387051749017905070253466005720364298335239299761065", "price": "0.102", "size": "0", "side": "BUY", "timestamp": "1768404054163", "received_at": "2026-01-14T16:20:53.833266"}}
{"event_type": "price_change", "event_ts": "2026-01-14T16:20:53.858410", "ingestion_ts": "2026-01-14T16:33:58.842229", "market_id": "0x49686d26fb712515cd5e12c23f0a1c7e10214c7faa3cb0a730aabe0c33694082", "raw": {"market": "0x49686d26fb712515cd5e12c23f0a1c7e10214c7faa3cb0a730aabe0c33694082", "asset_id": "13244681086321087932946246027856416106585284024824496763706748621681543444582", "price": "0.851", "size": "550", "side": "BUY", "timestamp": "1768404054177", "received_at": "2026-01-14T16:20:53.858410"}}
{"event_type": "price_change", "event_ts": "2026-01-14T16:20:53.858410", "ingestion_ts": "2026-01-14T16:33:58.842229", "market_id": "0x49686d26fb712515cd5e12c23f0a1c7e10214c7faa3cb0a730aabe0c33694082", "raw": {"market": "0x49686d26fb712515cd5e12c23f0a1c7e10214c7faa3cb0a730aabe0c33694082", "asset_id": "30442780799048074404860985387051749017905070253466005720364298335239299761065", "price": "0.149", "size": "550", "side": "SELL", "timestamp": "1768404054177", "received_at": "2026-01-14T16:20:53.858410"}}
{"event_type": "price_change", "event_ts": "2026-01-14T16:20:53.866401", "ingestion_ts": "2026-01-14T16:33:58.842229", "market_id": "0x49686d26fb712515cd5e12c23f0a1c7e10214c7faa3cb0a730aabe0c33694082", "raw": {"market": "0x49686d26fb712515cd5e12c23f0a1c7e10214c7faa3cb0a730aabe0c33694082", "asset_id": "13244681086321087932946246027856416106585284024824496763706748621681543444582", "price": "0.907", "size": "133", "side": "SELL", "timestamp": "1768404054196", "received_at": "2026-01-14T16:20:53.866401"}}
{"event_type": "price_change", "event_ts": "2026-01-14T16:20:53.866401", "ingestion_ts": "2026-01-14T16:33:58.842229", "market_id": "0x49686d26fb712515cd5e12c23f0a1c7e10214c7faa3cb0a730aabe0c33694082", "raw": {"market": "0x49686d26fb712515cd5e12c23f0a1c7e10214c7faa3cb0a730aabe0c33694082", "asset_id": "30442780799048074404860985387051749017905070253466005720364298335239299761065", "price": "0.093", "size": "133", "side": "BUY", "timestamp": "1768404054196", "received_at": "2026-01-14T16:20:53.866401"}}
{"event_type": "price_change", "event_ts": "2026-01-14T16:20:53.966243", "ingestion_ts": "2026-01-14T16:33:58.842229", "market_id": "0x49686d26fb712515cd5e12c23f0a1c7e10214c7faa3cb0a730aabe0c33694082", "raw": {"market": "0x49686d26fb712515cd5e12c23f0a1c7e10214c7faa3cb0a730aabe0c33694082", "asset_id": "30442780799048074404860985387051749017905070253466005720364298335239299761065", "price": "0.051", "size": "25", "side": "BUY", "timestamp": "1768404054296", "received_at": "2026-01-14T16:20:53.966243"}}
{"event_type": "price_change", "event_ts": "2026-01-14T16:20:53.966243", "ingestion_ts": "2026-01-14T16:33:58.842229", "market_id": "0x49686d26fb712515cd5e12c23f0a1c7e10214c7faa3cb0a730aabe0c33694082", "raw": {"market": "0x49686d26fb712515cd5e12c23f0a1c7e10214c7faa3cb0a730aabe0c33694082", "asset_id": "13244681086321087932946246027856416106585284024824496763706748621681543444582", "price": "0.949", "size": "25", "side": "SELL", "timestamp": "1768404054296", "received_at": "2026-01-14T16:20:53.966243"}}
{"event_type": "price_change", "event_ts": "2026-01-14T16:20:54.375283", "ingestion_ts": "2026-01-14T16:33:58.842229", "market_id": "0x49686d26fb712515cd5e12c23f0a1c7e10214c7faa3cb0a730aabe0c33694082", "raw": {"market": "0x49686d26fb712515cd5e12c23f0a1c7e10214c7faa3cb0a730aabe0c33694082", "asset_id": "30442780799048074404860985387051749017905070253466005720364298335239299761065", "price": "0.051", "size": "20", "side": "BUY", "timestamp": "1768404054700", "received_at": "2026-01-14T16:20:54.375283"}}
{"event_type": "price_change", "event_ts": "2026-01-14T16:20:54.375283", "ingestion_ts": "2026-01-14T16:33:58.842229", "market_id": "0x49686d26fb712515cd5e12c23f0a1c7e10214c7faa3cb0a730aabe0c33694082", "raw": {"market": "0x49686d26fb712515cd5e12c23f0a1c7e10214c7faa3cb0a730aabe0c33694082", "asset_id": "13244681086321087932946246027856416106585284024824496763706748621681543444582", "price": "0.949", "size": "20", "side": "SELL", "timestamp": "1768404054700", "received_at": "2026-01-14T16:20:54.375283"}}
{"event_type": "price_change", "event_ts": "2026-01-14T16:20:54.402530", "ingestion_ts": "2026-01-14T16:33:58.842229", "market_id": "0x49686d26fb712515cd5e12c23f0a1c7e10214c7faa3cb0a730aabe0c33694082", "raw": {"market": "0x49686d26fb712515cd5e12c23f0a1c7e10214c7faa3cb0a730aabe0c33694082", "asset_id": "30442780799048074404860985387051749017905070253466005720364298335239299761065", "price": "0.052", "size": "5", "side": "BUY", "timestamp": "1768404054730", "received_at": "2026-01-14T16:20:54.402530"}}
{"event_type": "price_change", "event_ts": "2026-01-14T16:20:54.402530", "ingestion_ts": "2026-01-14T16:33:58.842229", "market_id": "0x49686d26fb712515cd5e12c23f0a1c7e10214c7faa3cb0a730aabe0c33694082", "raw": {"market": "0x49686d26fb712515cd5e12c23f0a1c7e10214c7faa3cb0a730aabe0c33694082", "asset_id": "13244681086321087932946246027856416106585284024824496763706748621681543444582", "price": "0.948", "size": "5", "side": "SELL", "timestamp": "1768404054730", "received_at": "2026-01-14T16:20:54.402530"}}
{"event_type": "price_change", "event_ts": "2026-01-14T16:20:54.492056", "ingestion_ts": "2026-01-14T16:33:58.842229", "market_id": "0x49686d26fb712515cd5e12c23f0a1c7e10214c7faa3cb0a730aabe0c33694082", "raw": {"market": "0x49686d26fb712515cd5e12c23f0a1c7e10214c7faa3cb0a730aabe0c33694082", "asset_id": "30442780799048074404860985387051749017905070253466005720364298335239299761065", "price": "0.051", "size": "0", "side": "BUY", "timestamp": "1768404054817", "received_at": "2026-01-14T16:20:54.492056"}}
{"event_type": "price_change", "event_ts": "2026-01-14T16:20:54.492056", "ingestion_ts": "2026-01-14T16:33:58.842229", "market_id": "0x49686d26fb712515cd5e12c23f0a1c7e10214c7faa3cb0a730aabe0c33694082", "raw": {"market": "0x49686d26fb712515cd5e12c23f0a1c7e10214c7faa3cb0a730aabe0c33694082", "asset_id": "13244681086321087932946246027856416106585284024824496763706748621681543444582", "price": "0.949", "size": "0", "side": "SELL", "timestamp": "1768404054817", "received_at": "2026-01-14T16:20:54.492056"}}
{"event_type": "price_change", "event_ts": "2026-01-14T16:20:55.509841", "ingestion_ts": "2026-01-14T16:33:58.842229", "market_id": "0x49686d26fb712515cd5e12c23f0a1c7e10214c7faa3cb0a730aabe0c33694082", "raw": {"market": "0x49686d26fb712515cd5e12c23f0a1c7e10214c7faa3cb0a730aabe0c33694082", "asset_id": "30442780799048074404860985387051749017905070253466005720364298335239299761065", "price": "0.052", "size": "0", "side": "BUY", "timestamp": "1768404055816", "received_at": "2026-01-14T16:20:55.509841"}}
{"event_type": "price_change", "event_ts": "2026-01-14T16:20:55.509841", "ingestion_ts": "2026-01-14T16:33:58.842229", "market_id": "0x49686d26fb712515cd5e12c23f0a1c7e10214c7faa3cb0a730aabe0c33694082", "raw": {"market": "0x49686d26fb712515cd5e12c23f0a1c7e10214c7faa3cb0a730aabe0c33694082", "asset_id": "13244681086321087932946246027856416106585284024824496763706748621681543444582", "price": "0.948", "size": "0", "side": "SELL", "timestamp": "1768404055816", "received_at": "2026-01-14T16:20:55.509841"}}
{"event_type": "price_change", "event_ts": "2026-01-14T16:20:55.522170", "ingestion_ts": "2026-01-14T16:33:58.842229", "market_id": "0x49686d26fb712515cd5e12c23f0a1c7e10214c7faa3cb0a730aabe0c33694082", "raw": {"market": "0x49686d26fb712515cd5e12c23f0a1c7e10214c7faa3cb0a730aabe0c33694082", "asset_id": "30442780799048074404860985387051749017905070253466005720364298335239299761065", "price": "0.051", "size": "5", "side": "BUY", "timestamp": "1768404055849", "received_at": "2026-01-14T16:20:55.522170"}}
{"event_type": "price_change", "event_ts": "2026-01-14T16:20:55.522170", "ingestion_ts": "2026-01-14T16:33:58.842229", "market_id": "0x49686d26fb712515cd5e12c23f0a1c7e10214c7faa3cb0a730aabe0c33694082", "raw": {"market": "0x49686d26fb712515cd5e12c23f0a1c7e10214c7faa3cb0a730aabe0c33694082", "asset_id": "13244681086321087932946246027856416106585284024824496763706748621681543444582", "price": "0.949", "size": "5", "side": "SELL", "timestamp": "1768404055849", "received_at": "2026-01-14T16:20:55.522170"}}
{"event_type": "price_change", "event_ts": "2026-01-14T16:20:55.619405", "ingestion_ts": "2026-01-14T16:33:58.842229", "market_id": "0x49686d26fb712515cd5e12c23f0a1c7e10214c7faa3cb0a730aabe0c33694082", "raw": {"market": "0x49686d26fb712515cd5e12c23f0a1c7e10214c7faa3cb0a730aabe0c33694082", "asset_id": "30442780799048074404860985387051749017905070253466005720364298335239299761065", "price": "0.039", "size": "20", "side": "BUY", "timestamp": "1768404055949", "received_at": "2026-01-14T16:20:55.619405"}}
{"event_type": "price_change", "event_ts": "2026-01-14T16:20:55.619405", "ingestion_ts": "2026-01-14T16:33:58.842229", "market_id": "0x49686d26fb712515cd5e12c23f0a1c7e10214c7faa3cb0a730aabe0c33694082", "raw": {"market": "0x49686d26fb712515cd5e12c23f0a1c7e10214c7faa3cb0a730aabe0c33694082", "asset_id": "13244681086321087932946246027856416106585284024824496763706748621681543444582", "price": "0.961", "size": "20", "side": "SELL", "timestamp": "1768404055949", "received_at": "2026-01-14T16:20:55.619405"}}
{"event_type": "price_change", "event_ts": "2026-01-14T16:20:55.844577", "ingestion_ts": "2026-01-14T16:33:58.842229", "market_id": "0xaf9d0e448129a9f657f851d49495ba4742055d80e0ef1166ba0ee81d4d594214", "raw": {"market": "0xaf9d0e448129a9f657f851d49495ba4742055d80e0ef1166ba0ee81d4d594214", "asset_id": "4153292802911610701832309484716814274802943278345248636922528170020319407796", "price": "0.983", "size": "121", "side": "SELL", "timestamp": "1768404056173", "received_at": "2026-01-14T16:20:55.844577"}}
{"event_type": "price_change", "event_ts": "2026-01-14T16:20:55.844577", "ingestion_ts": "2026-01-14T16:33:58.842229", "market_id": "0xaf9d0e448129a9f657f851d49495ba4742055d80e0ef1166ba0ee81d4d594214", "raw": {"market": "0xaf9d0e448129a9f657f851d49495ba4742055d80e0ef1166ba0ee81d4d594214", "asset_id": "101676997363687199724245607342877036148401850938023978421879460310389391082353", "price": "0.017", "size": "121", "side": "BUY", "timestamp": "1768404056173", "received_at": "2026-01-14T16:20:55.844577"}}
{"event_type": "price_change", "event_ts": "2026-01-14T16:20:56.029301", "ingestion_ts": "2026-01-14T16:33:58.842229", "market_id": "0xaf9d0e448129a9f657f851d49495ba4742055d80e0ef1166ba0ee81d4d594214", "raw": {"market": "0xaf9d0e448129a9f657f851d49495ba4742055d80e0ef1166ba0ee81d4d594214", "asset_id": "4153292802911610701832309484716814274802943278345248636922528170020319407796", "price": "0.982", "size": "7.13", "side": "SELL", "timestamp": "1768404056350", "received_at": "2026-01-14T16:20:56.029301"}}
{"event_type": "price_change", "event_ts": "2026-01-14T16:20:56.029301", "ingestion_ts": "2026-01-14T16:33:58.842229", "market_id": "0xaf9d0e448129a9f657f851d49495ba4742055d80e0ef1166ba0ee81d4d594214", "raw": {"market": "0xaf9d0e448129a9f657f851d49495ba4742055d80e0ef1166ba0ee81d4d594214", "asset_id": "101676997363687199724245607342877036148401850938023978421879460310389391082353", "price": "0.018", "size": "7.13", "side": "BUY", "timestamp": "1768404056350", "received_at": "2026-01-14T16:20:56.029301"}}
{"event_type": "price_change", "event_ts": "2026-01-14T16:20:56.059897", "ingestion_ts": "2026-01-14T16:33:58.842229", "market_id": "0xaf9d0e448129a9f657f851d49495ba4742055d80e0ef1166ba0ee81d4d594214", "raw": {"market": "0xaf9d0e448129a9f657f851d49495ba4742055d80e0ef1166ba0ee81d4d594214", "asset_id": "101676997363687199724245607342877036148401850938023978421879460310389391082353", "price": "0.017", "size": "0", "side": "BUY", "timestamp": "1768404056382", "received_at": "2026-01-14T16:20:56.059897"}}
{"event_type": "price_change", "event_ts": "2026-01-14T16:20:56.059897", "ingestion_ts": "2026-01-14T16:33:58.842229", "market_id": "0xaf9d0e448129a9f657f851d49495ba4742055d80e0ef1166ba0ee81d4d594214", "raw": {"market": "0xaf9d0e448129a9f657f851d49495ba4742055d80e0ef1166ba0ee81d4d594214", "asset_id": "4153292802911610701832309484716814274802943278345248636922528170020319407796", "price": "0.983", "size": "0", "side": "SELL", "timestamp": "1768404056382", "received_at": "2026-01-14T16:20:56.059897"}}
{"event_type": "price_change", "event_ts": "2026-01-14T16:20:56.092073", "ingestion_ts": "2026-01-14T16:33:58.842229", "market_id": "0xaf9d0e448129a9f657f851d49495ba4742055d80e0ef1166ba0ee81d4d594214", "raw": {"market": "0xaf9d0e448129a9f657f851d49495ba4742055d80e0ef1166ba0ee81d4d594214", "asset_id": "101676997363687199724245607342877036148401850938023978421879460310389391082353", "price": "0.019", "size": "121", "side": "BUY", "timestamp": "1768404056415", "received_at": "2026-01-14T16:20:56.092073"}}
{"event_type": "price_change", "event_ts": "2026-01-14T16:20:56.092073", "ingestion_ts": "2026-01-14T16:33:58.842229", "market_id": "0xaf9d0e448129a9f657f851d49495ba4742055d80e0ef1166ba0ee81d4d594214", "raw": {"market": "0xaf9d0e448129a9f657f851d49495ba4742055d80e0ef1166ba0ee81d4d594214", "asset_id": "4153292802911610701832309484716814274802943278345248636922528170020319407796", "price": "0.981", "size": "121", "side": "SELL", "timestamp": "1768404056415", "received_at": "2026-01-14T16:20:56.092073"}}
{"event_type": "price_change", "event_ts": "2026-01-14T16:20:56.190501", "ingestion_ts": "2026-01-14T16:33:58.842229", "market_id": "0x49686d26fb712515cd5e12c23f0a1c7e10214c7faa3cb0a730aabe0c33694082", "raw": {"market": "0x49686d26fb712515cd5e12c23f0a1c7e10214c7faa3cb0a730aabe0c33694082", "asset_id": "30442780799048074404860985387051749017905070253466005720364298335239299761065", "price": "0.039", "size": "0", "side": "BUY", "timestamp": "1768404056521", "received_at": "2026-01-14T16:20:56.190501"}}
{"event_type": "price_change", "event_ts": "2026-01-14T16:20:56.190501", "ingestion_ts": "2026-01-14T16:33:58.842229", "market_id": "0x49686d26fb712515cd5e12c23f0a1c7e10214c7faa3cb0a730aabe0c33694082", "raw": {"market": "0x49686d26fb712515cd5e12c23f0a1c7e10214c7faa3cb0a730aabe0c33694082", "asset_id": "13244681086321087932946246027856416106585284024824496763706748621681543444582", "price": "0.961", "size": "0", "side": "SELL", "timestamp": "1768404056521", "received_at": "2026-01-14T16:20:56.190501"}}
{"event_type": "price_change", "event_ts": "2026-01-14T16:20:56.370640", "ingestion_ts": "2026-01-14T16:33:58.842229", "market_id": "0x49686d26fb712515cd5e12c23f0a1c7e10214c7faa3cb0a730aabe0c33694082", "raw": {"market": "0x49686d26fb712515cd5e12c23f0a1c7e10214c7faa3cb0a730aabe0c33694082", "asset_id": "30442780799048074404860985387051749017905070253466005720364298335239299761065", "price": "0.033", "size": "20", "side": "BUY", "timestamp": "1768404056698", "received_at": "2026-01-14T16:20:56.370640"}}
{"event_type": "price_change", "event_ts": "2026-01-14T16:20:56.370640", "ingestion_ts": "2026-01-14T16:33:58.842229", "market_id": "0x49686d26fb712515cd5e12c23f0a1c7e10214c7faa3cb0a730aabe0c33694082", "raw": {"market": "0x49686d26fb712515cd5e12c23f0a1c7e10214c7faa3cb0a730aabe0c33694082", "asset_id": "13244681086321087932946246027856416106585284024824496763706748621681543444582", "price": "0.967", "size": "20", "side": "SELL", "timestamp": "1768404056698", "received_at": "2026-01-14T16:20:56.370640"}}
{"event_type": "price_change", "event_ts": "2026-01-14T16:20:58.184411", "ingestion_ts": "2026-01-14T16:33:58.842229", "market_id": "0xaf9d0e448129a9f657f851d49495ba4742055d80e0ef1166ba0ee81d4d594214", "raw": {"market": "0xaf9d0e448129a9f657f851d49495ba4742055d80e0ef1166ba0ee81d4d594214", "asset_id": "4153292802911610701832309484716814274802943278345248636922528170020319407796", "price": "0.982", "size": "0", "side": "SELL", "timestamp": "1768404058505", "received_at": "2026-01-14T16:20:58.184411"}}
{"event_type": "price_change", "event_ts": "2026-01-14T16:20:58.184411", "ingestion_ts": "2026-01-14T16:33:58.842229", "market_id": "0xaf9d0e448129a9f657f851d49495ba4742055d80e0ef1166ba0ee81d4d594214", "raw": {"market": "0xaf9d0e448129a9f657f851d49495ba4742055d80e0ef1166ba0ee81d4d594214", "asset_id": "101676997363687199724245607342877036148401850938023978421879460310389391082353", "price": "0.018", "size": "0", "side": "BUY", "timestamp": "1768404058505", "received_at": "2026-01-14T16:20:58.184411"}}
{"event_type": "price_change", "event_ts": "2026-01-14T16:20:58.313711", "ingestion_ts": "2026-01-14T16:33:58.842229", "market_id": "0x49686d26fb712515cd5e12c23f0a1c7e10214c7faa3cb0a730aabe0c33694082", "raw": {"market": "0x49686d26fb712515cd5e12c23f0a1c7e10214c7faa3cb0a730aabe0c33694082", "asset_id": "30442780799048074404860985387051749017905070253466005720364298335239299761065", "price": "0.094", "size": "50", "side": "BUY", "timestamp": "1768404058639", "received_at": "2026-01-14T16:20:58.313711"}}
{"event_type": "price_change", "event_ts": "2026-01-14T16:20:58.313711", "ingestion_ts": "2026-01-14T16:33:58.842229", "market_id": "0x49686d26fb712515cd5e12c23f0a1c7e10214c7faa3cb0a730aabe0c33694082", "raw": {"market": "0x49686d26fb712515cd5e12c23f0a1c7e10214c7faa3cb0a730aabe0c33694082", "asset_id": "13244681086321087932946246027856416106585284024824496763706748621681543444582", "price": "0.906", "size": "50", "side": "SELL", "timestamp": "1768404058639", "received_at": "2026-01-14T16:20:58.313711"}}
{"event_type": "price_change", "event_ts": "2026-01-14T16:20:58.345451", "ingestion_ts": "2026-01-14T16:33:58.842229", "market_id": "0x49686d26fb712515cd5e12c23f0a1c7e10214c7faa3cb0a730aabe0c33694082", "raw": {"market": "0x49686d26fb712515cd5e12c23f0a1c7e10214c7faa3cb0a730aabe0c33694082", "asset_id": "13244681086321087932946246027856416106585284024824496763706748621681543444582", "price": "0.907", "size": "0", "side": "SELL", "timestamp": "1768404058670", "received_at": "2026-01-14T16:20:58.345451"}}
{"event_type": "price_change", "event_ts": "2026-01-14T16:20:58.345451", "ingestion_ts": "2026-01-14T16:33:58.842229", "market_id": "0x49686d26fb712515cd5e12c23f0a1c7e10214c7faa3cb0a730aabe0c33694082", "raw": {"market": "0x49686d26fb712515cd5e12c23f0a1c7e10214c7faa3cb0a730aabe0c33694082", "asset_id": "30442780799048074404860985387051749017905070253466005720364298335239299761065", "price": "0.093", "size": "0", "side": "BUY", "timestamp": "1768404058670", "received_at": "2026-01-14T16:20:58.345451"}}
{"event_type": "price_change", "event_ts": "2026-01-14T16:20:58.350457", "ingestion_ts": "2026-01-14T16:33:58.842229", "market_id": "0xaf9d0e448129a9f657f851d49495ba4742055d80e0ef1166ba0ee81d4d594214", "raw": {"market": "0xaf9d0e448129a9f657f851d49495ba4742055d80e0ef1166ba0ee81d4d594214", "asset_id": "4153292802911610701832309484716814274802943278345248636922528170020319407796", "price": "0.984", "size": "7.13", "side": "SELL", "timestamp": "1768404058674", "received_at": "2026-01-14T16:20:58.350457"}}
{"event_type": "price_change", "event_ts": "2026-01-14T16:20:58.350457", "ingestion_ts": "2026-01-14T16:33:58.842229", "market_id": "0xaf9d0e448129a9f657f851d49495ba4742055d80e0ef1166ba0ee81d4d594214", "raw": {"market": "0xaf9d0e448129a9f657f851d49495ba4742055d80e0ef1166ba0ee81d4d594214", "asset_id": "101676997363687199724245607342877036148401850938023978421879460310389391082353", "price": "0.016", "size": "7.13", "side": "BUY", "timestamp": "1768404058674", "received_at": "2026-01-14T16:20:58.350457"}}
{"event_type": "price_change", "event_ts": "2026-01-14T16:20:58.369148", "ingestion_ts": "2026-01-14T16:33:58.842229", "market_id": "0x49686d26fb712515cd5e12c23f0a1c7e10214c7faa3cb0a730aabe0c33694082", "raw": {"market": "0x49686d26fb712515cd5e12c23f0a1c7e10214c7faa3cb0a730aabe0c33694082", "asset_id": "13244681086321087932946246027856416106585284024824496763706748621681543444582", "price": "0.899", "size": "134", "side": "SELL", "timestamp": "1768404058699", "received_at": "2026-01-14T16:20:58.369148"}}
{"event_type": "price_change", "event_ts": "2026-01-14T16:20:58.369148", "ingestion_ts": "2026-01-14T16:33:58.842229", "market_id": "0x49686d26fb712515cd5e12c23f0a1c7e10214c7faa3cb0a730aabe0c33694082", "raw": {"market": "0x49686d26fb712515cd5e12c23f0a1c7e10214c7faa3cb0a730aabe0c33694082", "asset_id": "30442780799048074404860985387051749017905070253466005720364298335239299761065", "price": "0.101", "size": "134", "side": "BUY", "timestamp": "1768404058699", "received_at": "2026-01-14T16:20:58.369148"}}
{"event_type": "price_change", "event_ts": "2026-01-14T16:20:59.870435", "ingestion_ts": "2026-01-14T16:33:58.842229", "market_id": "0x2393ed0b0fdc450054c7b9071907eca75cf4fc36e385adf4a0a5f99ee62243e8", "raw": {"market": "0x2393ed0b0fdc450054c7b9071907eca75cf4fc36e385adf4a0a5f99ee62243e8", "asset_id": "32769749367306925959219403371425714180265458150646381231272229429098460625924", "price": "0.946", "size": "149.99", "side": "BUY", "timestamp": "1768404060182", "received_at": "2026-01-14T16:20:59.870435"}}
{"event_type": "price_change", "event_ts": "2026-01-14T16:20:59.870435", "ingestion_ts": "2026-01-14T16:33:58.842229", "market_id": "0x2393ed0b0fdc450054c7b9071907eca75cf4fc36e385adf4a0a5f99ee62243e8", "raw": {"market": "0x2393ed0b0fdc450054c7b9071907eca75cf4fc36e385adf4a0a5f99ee62243e8", "asset_id": "100074770378634056601572485653252702850363676459996771990439989989293515601975", "price": "0.054", "size": "149.99", "side": "SELL", "timestamp": "1768404060182", "received_at": "2026-01-14T16:20:59.870435"}}
{"event_type": "price_change", "event_ts": "2026-01-14T16:20:59.870470", "ingestion_ts": "2026-01-14T16:33:58.842229", "market_id": "0x2393ed0b0fdc450054c7b9071907eca75cf4fc36e385adf4a0a5f99ee62243e8", "raw": {"market": "0x2393ed0b0fdc450054c7b9071907eca75cf4fc36e385adf4a0a5f99ee62243e8", "asset_id": "100074770378634056601572485653252702850363676459996771990439989989293515601975", "price": "0.047", "size": "50", "side": "BUY", "timestamp": "1768404060183", "received_at": "2026-01-14T16:20:59.870470"}}
{"event_type": "price_change", "event_ts": "2026-01-14T16:20:59.870470", "ingestion_ts": "2026-01-14T16:33:58.842229", "market_id": "0x2393ed0b0fdc450054c7b9071907eca75cf4fc36e385adf4a0a5f99ee62243e8", "raw": {"market": "0x2393ed0b0fdc450054c7b9071907eca75cf4fc36e385adf4a0a5f99ee62243e8", "asset_id": "32769749367306925959219403371425714180265458150646381231272229429098460625924", "price": "0.953", "size": "50", "side": "SELL", "timestamp": "1768404060183", "received_at": "2026-01-14T16:20:59.870470"}}
{"event_type": "price_change", "event_ts": "2026-01-14T16:20:59.974569", "ingestion_ts": "2026-01-14T16:33:58.842229", "market_id": "0xc55db914f0fd1fee18997706712c0dfd8d0369cdbef93a9fef12bd001914ca77", "raw": {"market": "0xc55db914f0fd1fee18997706712c0dfd8d0369cdbef93a9fef12bd001914ca77", "asset_id": "114600293444080540179603459515770723592661967180480327891296353898330242622833", "price": "0.951", "size": "0", "side": "BUY", "timestamp": "1768404060277", "received_at": "2026-01-14T16:20:59.974569"}}
{"event_type": "price_change", "event_ts": "2026-01-14T16:20:59.974569", "ingestion_ts": "2026-01-14T16:33:58.842229", "market_id": "0xc55db914f0fd1fee18997706712c0dfd8d0369cdbef93a9fef12bd001914ca77", "raw": {"market": "0xc55db914f0fd1fee18997706712c0dfd8d0369cdbef93a9fef12bd001914ca77", "asset_id": "72354723612769247426741660426331235762851940382312402276325808095604519806766", "price": "0.049", "size": "0", "side": "SELL", "timestamp": "1768404060277", "received_at": "2026-01-14T16:20:59.974569"}}
{"event_type": "price_change", "event_ts": "2026-01-14T16:21:00.058503", "ingestion_ts": "2026-01-14T16:33:58.842229", "market_id": "0xc55db914f0fd1fee18997706712c0dfd8d0369cdbef93a9fef12bd001914ca77", "raw": {"market": "0xc55db914f0fd1fee18997706712c0dfd8d0369cdbef93a9fef12bd001914ca77", "asset_id": "114600293444080540179603459515770723592661967180480327891296353898330242622833", "price": "0.839", "size": "25", "side": "BUY", "timestamp": "1768404060367", "received_at": "2026-01-14T16:21:00.058503"}}
{"event_type": "price_change", "event_ts": "2026-01-14T16:21:00.058503", "ingestion_ts": "2026-01-14T16:33:58.842229", "market_id": "0xc55db914f0fd1fee18997706712c0dfd8d0369cdbef93a9fef12bd001914ca77", "raw": {"market": "0xc55db914f0fd1fee18997706712c0dfd8d0369cdbef93a9fef12bd001914ca77", "asset_id": "72354723612769247426741660426331235762851940382312402276325808095604519806766", "price": "0.161", "size": "25", "side": "SELL", "timestamp": "1768404060367", "received_at": "2026-01-14T16:21:00.058503"}}
{"event_type": "price_change", "event_ts": "2026-01-14T16:21:04.426770", "ingestion_ts": "2026-01-14T16:33:58.842229", "market_id": "0x49686d26fb712515cd5e12c23f0a1c7e10214c7faa3cb0a730aabe0c33694082", "raw": {"market": "0x49686d26fb712515cd5e12c23f0a1c7e10214c7faa3cb0a730aabe0c33694082", "asset_id": "13244681086321087932946246027856416106585284024824496763706748621681543444582", "price": "0.115", "size": "0", "side": "BUY", "timestamp": "1768404064668", "received_at": "2026-01-14T16:21:04.426770"}}
{"event_type": "price_change", "event_ts": "2026-01-14T16:21:04.426770", "ingestion_ts": "2026-01-14T16:33:58.842229", "market_id": "0x49686d26fb712515cd5e12c23f0a1c7e10214c7faa3cb0a730aabe0c33694082", "raw": {"market": "0x49686d26fb712515cd5e12c23f0a1c7e10214c7faa3cb0a730aabe0c33694082", "asset_id": "30442780799048074404860985387051749017905070253466005720364298335239299761065", "price": "0.885", "size": "0", "side": "SELL", "timestamp": "1768404064668", "received_at": "2026-01-14T16:21:04.426770"}}
{"event_type": "price_change", "event_ts": "2026-01-14T16:21:04.429311", "ingestion_ts": "2026-01-14T16:33:58.842229", "market_id": "0x318b222c1435b47c338e66ca6001f782711186a488ae7b7248f7edc6ff076a83", "raw": {"market": "0x318b222c1435b47c338e66ca6001f782711186a488ae7b7248f7edc6ff076a83", "asset_id": "63773739594775606083258239254748928077067768053882704658119720069071630213026", "price": "0.128", "size": "0", "side": "BUY", "timestamp": "1768404064668", "received_at": "2026-01-14T16:21:04.429311"}}
{"event_type": "price_change", "event_ts": "2026-01-14T16:21:04.429311", "ingestion_ts": "2026-01-14T16:33:58.842229", "market_id": "0x318b222c1435b47c338e66ca6001f782711186a488ae7b7248f7edc6ff076a83", "raw": {"market": "0x318b222c1435b47c338e66ca6001f782711186a488ae7b7248f7edc6ff076a83", "asset_id": "56738600572035832904895845056468792275697823297413384908752239327866518310010", "price": "0.872", "size": "0", "side": "SELL", "timestamp": "1768404064668", "received_at": "2026-01-14T16:21:04.429311"}}
{"event_type": "price_change", "event_ts": "2026-01-14T16:21:04.432231", "ingestion_ts": "2026-01-14T16:33:58.842229", "market_id": "0x2393ed0b0fdc450054c7b9071907eca75cf4fc36e385adf4a0a5f99ee62243e8", "raw": {"market": "0x2393ed0b0fdc450054c7b9071907eca75cf4fc36e385adf4a0a5f99ee62243e8", "asset_id": "32769749367306925959219403371425714180265458150646381231272229429098460625924", "price": "0.113", "size": "0", "side": "BUY", "timestamp": "1768404064668", "received_at": "2026-01-14T16:21:04.432231"}}
{"event_type": "price_change", "event_ts": "2026-01-14T16:21:04.432231", "ingestion_ts": "2026-01-14T16:33:58.842229", "market_id": "0x2393ed0b0fdc450054c7b9071907eca75cf4fc36e385adf4a0a5f99ee62243e8", "raw": {"market": "0x2393ed0b0fdc450054c7b9071907eca75cf4fc36e385adf4a0a5f99ee62243e8", "asset_id": "100074770378634056601572485653252702850363676459996771990439989989293515601975", "price": "0.887", "size": "0", "side": "SELL", "timestamp": "1768404064668", "received_at": "2026-01-14T16:21:04.432231"}}
{"event_type": "price_change", "event_ts": "2026-01-14T16:21:04.740870", "ingestion_ts": "2026-01-14T16:33:58.842229", "market_id": "0x49686d26fb712515cd5e12c23f0a1c7e10214c7faa3cb0a730aabe0c33694082", "raw": {"market": "0x49686d26fb712515cd5e12c23f0a1c7e10214c7faa3cb0a730aabe0c33694082", "asset_id": "30442780799048074404860985387051749017905070253466005720364298335239299761065", "price": "0.094", "size": "0", "side": "BUY", "timestamp": "1768404065014", "received_at": "2026-01-14T16:21:04.740870"}}
{"event_type": "price_change", "event_ts": "2026-01-14T16:21:04.740870", "ingestion_ts": "2026-01-14T16:33:58.842229", "market_id": "0x49686d26fb712515cd5e12c23f0a1c7e10214c7faa3cb0a730aabe0c33694082", "raw": {"market": "0x49686d26fb712515cd5e12c23f0a1c7e10214c7faa3cb0a730aabe0c33694082", "asset_id": "13244681086321087932946246027856416106585284024824496763706748621681543444582", "price": "0.906", "size": "0", "side": "SELL", "timestamp": "1768404065014", "received_at": "2026-01-14T16:21:04.740870"}}
{"event_type": "price_change", "event_ts": "2026-01-14T16:21:04.862840", "ingestion_ts": "2026-01-14T16:33:58.842229", "market_id": "0x2393ed0b0fdc450054c7b9071907eca75cf4fc36e385adf4a0a5f99ee62243e8", "raw": {"market": "0x2393ed0b0fdc450054c7b9071907eca75cf4fc36e385adf4a0a5f99ee62243e8", "asset_id": "32769749367306925959219403371425714180265458150646381231272229429098460625924", "price": "0.1", "size": "447.97", "side": "BUY", "timestamp": "1768404065084", "received_at": "2026-01-14T16:21:04.862840"}}
{"event_type": "price_change", "event_ts": "2026-01-14T16:21:04.862840", "ingestion_ts": "2026-01-14T16:33:58.842229", "market_id": "0x2393ed0b0fdc450054c7b9071907eca75cf4fc36e385adf4a0a5f99ee62243e8", "raw": {"market": "0x2393ed0b0fdc450054c7b9071907eca75cf4fc36e385adf4a0a5f99ee62243e8", "asset_id": "100074770378634056601572485653252702850363676459996771990439989989293515601975", "price": "0.9", "size": "447.97", "side": "SELL", "timestamp": "1768404065084", "received_at": "2026-01-14T16:21:04.862840"}}
{"event_type": "price_change", "event_ts": "2026-01-14T16:21:04.862899", "ingestion_ts": "2026-01-14T16:33:58.842229", "market_id": "0x318b222c1435b47c338e66ca6001f782711186a488ae7b7248f7edc6ff076a83", "raw": {"market": "0x318b222c1435b47c338e66ca6001f782711186a488ae7b7248f7edc6ff076a83", "asset_id": "63773739594775606083258239254748928077067768053882704658119720069071630213026", "price": "0.1", "size": "442.85", "side": "BUY", "timestamp": "1768404065079", "received_at": "2026-01-14T16:21:04.862899"}}
{"event_type": "price_change", "event_ts": "2026-01-14T16:21:04.862899", "ingestion_ts": "2026-01-14T16:33:58.842229", "market_id": "0x318b222c1435b47c338e66ca6001f782711186a488ae7b7248f7edc6ff076a83", "raw": {"market": "0x318b222c1435b47c338e66ca6001f782711186a488ae7b7248f7edc6ff076a83", "asset_id": "56738600572035832904895845056468792275697823297413384908752239327866518310010", "price": "0.9", "size": "442.85", "side": "SELL", "timestamp": "1768404065079", "received_at": "2026-01-14T16:21:04.862899"}}
{"event_type": "price_change", "event_ts": "2026-01-14T16:21:04.867272", "ingestion_ts": "2026-01-14T16:33:58.842229", "market_id": "0x49686d26fb712515cd5e12c23f0a1c7e10214c7faa3cb0a730aabe0c33694082", "raw": {"market": "0x49686d26fb712515cd5e12c23f0a1c7e10214c7faa3cb0a730aabe0c33694082", "asset_id": "13244681086321087932946246027856416106585284024824496763706748621681543444582", "price": "0.14", "size": "202.04", "side": "BUY", "timestamp": "1768404065081", "received_at": "2026-01-14T16:21:04.867272"}}
{"event_type": "price_change", "event_ts": "2026-01-14T16:21:04.867272", "ingestion_ts": "2026-01-14T16:33:58.842229", "market_id": "0x49686d26fb712515cd5e12c23f0a1c7e10214c7faa3cb0a730aabe0c33694082", "raw": {"market": "0x49686d26fb712515cd5e12c23f0a1c7e10214c7faa3cb0a730aabe0c33694082", "asset_id": "30442780799048074404860985387051749017905070253466005720364298335239299761065", "price": "0.86", "size": "202.04", "side": "SELL", "timestamp": "1768404065081", "received_at": "2026-01-14T16:21:04.867272"}}
{"event_type": "price_change", "event_ts": "2026-01-14T16:21:05.045139", "ingestion_ts": "2026-01-14T16:33:58.842229", "market_id": "0xaf9d0e448129a9f657f851d49495ba4742055d80e0ef1166ba0ee81d4d594214", "raw": {"market": "0xaf9d0e448129a9f657f851d49495ba4742055d80e0ef1166ba0ee81d4d594214", "asset_id": "4153292802911610701832309484716814274802943278345248636922528170020319407796", "price": "0.942", "size": "99.99", "side": "BUY", "timestamp": "1768404065315", "received_at": "2026-01-14T16:21:05.045139"}}
{"event_type": "price_change", "event_ts": "2026-01-14T16:21:05.045139", "ingestion_ts": "2026-01-14T16:33:58.842229", "market_id": "0xaf9d0e448129a9f657f851d49495ba4742055d80e0ef1166ba0ee81d4d594214", "raw": {"market": "0xaf9d0e448129a9f657f851d49495ba4742055d80e0ef1166ba0ee81d4d594214", "asset_id": "101676997363687199724245607342877036148401850938023978421879460310389391082353", "price": "0.058", "size": "99.99", "side": "SELL", "timestamp": "1768404065315", "received_at": "2026-01-14T16:21:05.045139"}}
{"event_type": "price_change", "event_ts": "2026-01-14T16:21:35.387409", "ingestion_ts": "2026-01-14T16:33:58.842229", "market_id": "0x2393ed0b0fdc450054c7b9071907eca75cf4fc36e385adf4a0a5f99ee62243e8", "raw": {"market": "0x2393ed0b0fdc450054c7b9071907eca75cf4fc36e385adf4a0a5f99ee62243e8", "asset_id": "32769749367306925959219403371425714180265458150646381231272229429098460625924", "price": "0.151", "size": "1058", "side": "BUY", "timestamp": "1768404095716", "received_at": "2026-01-14T16:21:35.387409"}}
{"event_type": "price_change", "event_ts": "2026-01-14T16:21:35.387409", "ingestion_ts": "2026-01-14T16:33:58.842229", "market_id": "0x2393ed0b0fdc450054c7b9071907eca75cf4fc36e385adf4a0a5f99ee62243e8", "raw": {"market": "0x2393ed0b0fdc450054c7b9071907eca75cf4fc36e385adf4a0a5f99ee62243e8", "asset_id": "100074770378634056601572485653252702850363676459996771990439989989293515601975", "price": "0.849", "size": "1058", "side": "SELL", "timestamp": "1768404095716", "received_at": "2026-01-14T16:21:35.387409"}}
{"event_type": "price_change", "event_ts": "2026-01-14T16:21:44.493821", "ingestion_ts": "2026-01-14T16:33:58.842229", "market_id": "0x318b222c1435b47c338e66ca6001f782711186a488ae7b7248f7edc6ff076a83", "raw": {"market": "0x318b222c1435b47c338e66ca6001f782711186a488ae7b7248f7edc6ff076a83", "asset_id": "63773739594775606083258239254748928077067768053882704658119720069071630213026", "price": "0.204", "size": "1470", "side": "BUY", "timestamp": "1768404104766", "received_at": "2026-01-14T16:21:44.493821"}}
{"event_type": "price_change", "event_ts": "2026-01-14T16:21:44.493821", "ingestion_ts": "2026-01-14T16:33:58.842229", "market_id": "0x318b222c1435b47c338e66ca6001f782711186a488ae7b7248f7edc6ff076a83", "raw": {"market": "0x318b222c1435b47c338e66ca6001f782711186a488ae7b7248f7edc6ff076a83", "asset_id": "56738600572035832904895845056468792275697823297413384908752239327866518310010", "price": "0.796", "size": "1470", "side": "SELL", "timestamp": "1768404104766", "received_at": "2026-01-14T16:21:44.493821"}}
{"event_type": "price_change", "event_ts": "2026-01-14T16:21:49.673608", "ingestion_ts": "2026-01-14T16:33:58.842229", "market_id": "0x22ac5f75af18fdb453497fbf7ac0606a09a6fd55b78b2d08aace6b946ad62038", "raw": {"market": "0x22ac5f75af18fdb453497fbf7ac0606a09a6fd55b78b2d08aace6b946ad62038", "asset_id": "97449340182256366014320155718265676486703217567849039806162053075113517266910", "price": "0.003", "size": "17.22", "side": "BUY", "timestamp": "1768404110003", "received_at": "2026-01-14T16:21:49.673608"}}
{"event_type": "price_change", "event_ts": "2026-01-14T16:21:49.673608", "ingestion_ts": "2026-01-14T16:33:58.842229", "market_id": "0x22ac5f75af18fdb453497fbf7ac0606a09a6fd55b78b2d08aace6b946ad62038", "raw": {"market": "0x22ac5f75af18fdb453497fbf7ac0606a09a6fd55b78b2d08aace6b946ad62038", "asset_id": "59259495934562596318644973716893809974860301509869285036503555129962149752635", "price": "0.997", "size": "17.22", "side": "SELL", "timestamp": "1768404110003", "received_at": "2026-01-14T16:21:49.673608"}}
{"event_type": "price_change", "event_ts": "2026-01-14T16:21:59.638825", "ingestion_ts": "2026-01-14T16:33:58.842229", "market_id": "0x2393ed0b0fdc450054c7b9071907eca75cf4fc36e385adf4a0a5f99ee62243e8", "raw": {"market": "0x2393ed0b0fdc450054c7b9071907eca75cf4fc36e385adf4a0a5f99ee62243e8", "asset_id": "32769749367306925959219403371425714180265458150646381231272229429098460625924", "price": "0.1", "size": "147.97", "side": "BUY", "timestamp": "1768404119935", "received_at": "2026-01-14T16:21:59.638825"}}
{"event_type": "price_change", "event_ts": "2026-01-14T16:21:59.638825", "ingestion_ts": "2026-01-14T16:33:58.842229", "market_id": "0x2393ed0b0fdc450054c7b9071907eca75cf4fc36e385adf4a0a5f99ee62243e8", "raw": {"market": "0x2393ed0b0fdc450054c7b9071907eca75cf4fc36e385adf4a0a5f99ee62243e8", "asset_id": "100074770378634056601572485653252702850363676459996771990439989989293515601975", "price": "0.9", "size": "147.97", "side": "SELL", "timestamp": "1768404119935", "received_at": "2026-01-14T16:21:59.638825"}}
{"event_type": "price_change", "event_ts": "2026-01-14T16:21:59.790943", "ingestion_ts": "2026-01-14T16:33:58.842229", "market_id": "0xaf9d0e448129a9f657f851d49495ba4742055d80e0ef1166ba0ee81d4d594214", "raw": {"market": "0xaf9d0e448129a9f657f851d49495ba4742055d80e0ef1166ba0ee81d4d594214", "asset_id": "4153292802911610701832309484716814274802943278345248636922528170020319407796", "price": "0.942", "size": "88.78", "side": "BUY", "timestamp": "1768404120051", "received_at": "2026-01-14T16:21:59.790943"}}
{"event_type": "price_change", "event_ts": "2026-01-14T16:21:59.790943", "ingestion_ts": "2026-01-14T16:33:58.842229", "market_id": "0xaf9d0e448129a9f657f851d49495ba4742055d80e0ef1166ba0ee81d4d594214", "raw": {"market": "0xaf9d0e448129a9f657f851d49495ba4742055d80e0ef1166ba0ee81d4d594214", "asset_id": "101676997363687199724245607342877036148401850938023978421879460310389391082353", "price": "0.058", "size": "88.78", "side": "SELL", "timestamp": "1768404120051", "received_at": "2026-01-14T16:21:59.790943"}}
{"event_type": "price_change", "event_ts": "2026-01-14T16:21:59.878164", "ingestion_ts": "2026-01-14T16:33:58.842229", "market_id": "0xaf9d0e448129a9f657f851d49495ba4742055d80e0ef1166ba0ee81d4d594214", "raw": {"market": "0xaf9d0e448129a9f657f851d49495ba4742055d80e0ef1166ba0ee81d4d594214", "asset_id": "101676997363687199724245607342877036148401850938023978421879460310389391082353", "price": "0.019", "size": "0", "side": "BUY", "timestamp": "1768404120124", "received_at": "2026-01-14T16:21:59.878164"}}
{"event_type": "price_change", "event_ts": "2026-01-14T16:21:59.878164", "ingestion_ts": "2026-01-14T16:33:58.842229", "market_id": "0xaf9d0e448129a9f657f851d49495ba4742055d80e0ef1166ba0ee81d4d594214", "raw": {"market": "0xaf9d0e448129a9f657f851d49495ba4742055d80e0ef1166ba0ee81d4d594214", "asset_id": "4153292802911610701832309484716814274802943278345248636922528170020319407796", "price": "0.981", "size": "0", "side": "SELL", "timestamp": "1768404120124", "received_at": "2026-01-14T16:21:59.878164"}}
{"event_type": "price_change", "event_ts": "2026-01-14T16:21:59.900589", "ingestion_ts": "2026-01-14T16:33:58.842229", "market_id": "0xaf9d0e448129a9f657f851d49495ba4742055d80e0ef1166ba0ee81d4d594214", "raw": {"market": "0xaf9d0e448129a9f657f851d49495ba4742055d80e0ef1166ba0ee81d4d594214", "asset_id": "101676997363687199724245607342877036148401850938023978421879460310389391082353", "price": "0.016", "size": "128.13", "side": "BUY", "timestamp": "1768404120157", "received_at": "2026-01-14T16:21:59.900589"}}
{"event_type": "price_change", "event_ts": "2026-01-14T16:21:59.900589", "ingestion_ts": "2026-01-14T16:33:58.842229", "market_id": "0xaf9d0e448129a9f657f851d49495ba4742055d80e0ef1166ba0ee81d4d594214", "raw": {"market": "0xaf9d0e448129a9f657f851d49495ba4742055d80e0ef1166ba0ee81d4d594214", "asset_id": "4153292802911610701832309484716814274802943278345248636922528170020319407796", "price": "0.984", "size": "128.13", "side": "SELL", "timestamp": "1768404120157", "received_at": "2026-01-14T16:21:59.900589"}}
{"event_type": "price_change", "event_ts": "2026-01-14T16:22:00.019166", "ingestion_ts": "2026-01-14T16:33:58.842229", "market_id": "0x2393ed0b0fdc450054c7b9071907eca75cf4fc36e385adf4a0a5f99ee62243e8", "raw": {"market": "0x2393ed0b0fdc450054c7b9071907eca75cf4fc36e385adf4a0a5f99ee62243e8", "asset_id": "32769749367306925959219403371425714180265458150646381231272229429098460625924", "price": "0.114", "size": "2204", "side": "BUY", "timestamp": "1768404120236", "received_at": "2026-01-14T16:22:00.019166"}}
{"event_type": "price_change", "event_ts": "2026-01-14T16:22:00.019166", "ingestion_ts": "2026-01-14T16:33:58.842229", "market_id": "0x2393ed0b0fdc450054c7b9071907eca75cf4fc36e385adf4a0a5f99ee62243e8", "raw": {"market": "0x2393ed0b0fdc450054c7b9071907eca75cf4fc36e385adf4a0a5f99ee62243e8", "asset_id": "100074770378634056601572485653252702850363676459996771990439989989293515601975", "price": "0.886", "size": "2204", "side": "SELL", "timestamp": "1768404120236", "received_at": "2026-01-14T16:22:00.019166"}}
{"event_type": "price_change", "event_ts": "2026-01-14T16:22:00.533764", "ingestion_ts": "2026-01-14T16:33:58.842229", "market_id": "0xaf9d0e448129a9f657f851d49495ba4742055d80e0ef1166ba0ee81d4d594214", "raw": {"market": "0xaf9d0e448129a9f657f851d49495ba4742055d80e0ef1166ba0ee81d4d594214", "asset_id": "4153292802911610701832309484716814274802943278345248636922528170020319407796", "price": "0.984", "size": "121", "side": "SELL", "timestamp": "1768404120860", "received_at": "2026-01-14T16:22:00.533764"}}
{"event_type": "price_change", "event_ts": "2026-01-14T16:22:00.533764", "ingestion_ts": "2026-01-14T16:33:58.842229", "market_id": "0xaf9d0e448129a9f657f851d49495ba4742055d80e0ef1166ba0ee81d4d594214", "raw": {"market": "0xaf9d0e448129a9f657f851d49495ba4742055d80e0ef1166ba0ee81d4d594214", "asset_id": "101676997363687199724245607342877036148401850938023978421879460310389391082353", "price": "0.016", "size": "121", "side": "BUY", "timestamp": "1768404120860", "received_at": "2026-01-14T16:22:00.533764"}}
{"event_type": "price_change", "event_ts": "2026-01-14T16:22:00.716182", "ingestion_ts": "2026-01-14T16:33:58.842229", "market_id": "0xaf9d0e448129a9f657f851d49495ba4742055d80e0ef1166ba0ee81d4d594214", "raw": {"market": "0xaf9d0e448129a9f657f851d49495ba4742055d80e0ef1166ba0ee81d4d594214", "asset_id": "4153292802911610701832309484716814274802943278345248636922528170020319407796", "price": "0.983", "size": "7.13", "side": "SELL", "timestamp": "1768404121042", "received_at": "2026-01-14T16:22:00.716182"}}
{"event_type": "price_change", "event_ts": "2026-01-14T16:22:00.716182", "ingestion_ts": "2026-01-14T16:33:58.842229", "market_id": "0xaf9d0e448129a9f657f851d49495ba4742055d80e0ef1166ba0ee81d4d594214", "raw": {"market": "0xaf9d0e448129a9f657f851d49495ba4742055d80e0ef1166ba0ee81d4d594214", "asset_id": "101676997363687199724245607342877036148401850938023978421879460310389391082353", "price": "0.017", "size": "7.13", "side": "BUY", "timestamp": "1768404121042", "received_at": "2026-01-14T16:22:00.716182"}}
{"event_type": "price_change", "event_ts": "2026-01-14T16:22:01.328432", "ingestion_ts": "2026-01-14T16:33:58.842229", "market_id": "0xaf9d0e448129a9f657f851d49495ba4742055d80e0ef1166ba0ee81d4d594214", "raw": {"market": "0xaf9d0e448129a9f657f851d49495ba4742055d80e0ef1166ba0ee81d4d594214", "asset_id": "101676997363687199724245607342877036148401850938023978421879460310389391082353", "price": "0.016", "size": "0", "side": "BUY", "timestamp": "1768404121657", "received_at": "2026-01-14T16:22:01.328432"}}
{"event_type": "price_change", "event_ts": "2026-01-14T16:22:01.328432", "ingestion_ts": "2026-01-14T16:33:58.842229", "market_id": "0xaf9d0e448129a9f657f851d49495ba4742055d80e0ef1166ba0ee81d4d594214", "raw": {"market": "0xaf9d0e448129a9f657f851d49495ba4742055d80e0ef1166ba0ee81d4d594214", "asset_id": "4153292802911610701832309484716814274802943278345248636922528170020319407796", "price": "0.984", "size": "0", "side": "SELL", "timestamp": "1768404121657", "received_at": "2026-01-14T16:22:01.328432"}}
{"event_type": "price_change", "event_ts": "2026-01-14T16:22:01.361821", "ingestion_ts": "2026-01-14T16:33:58.842229", "market_id": "0xaf9d0e448129a9f657f851d49495ba4742055d80e0ef1166ba0ee81d4d594214", "raw": {"market": "0xaf9d0e448129a9f657f851d49495ba4742055d80e0ef1166ba0ee81d4d594214", "asset_id": "101676997363687199724245607342877036148401850938023978421879460310389391082353", "price": "0.018", "size": "121", "side": "BUY", "timestamp": "1768404121692", "received_at": "2026-01-14T16:22:01.361821"}}
{"event_type": "price_change", "event_ts": "2026-01-14T16:22:01.361821", "ingestion_ts": "2026-01-14T16:33:58.842229", "market_id": "0xaf9d0e448129a9f657f851d49495ba4742055d80e0ef1166ba0ee81d4d594214", "raw": {"market": "0xaf9d0e448129a9f657f851d49495ba4742055d80e0ef1166ba0ee81d4d594214", "asset_id": "4153292802911610701832309484716814274802943278345248636922528170020319407796", "price": "0.982", "size": "121", "side": "SELL", "timestamp": "1768404121692", "received_at": "2026-01-14T16:22:01.361821"}}
{"event_type": "price_change", "event_ts": "2026-01-14T16:22:02.946831", "ingestion_ts": "2026-01-14T16:33:58.842229", "market_id": "0xaf9d0e448129a9f657f851d49495ba4742055d80e0ef1166ba0ee81d4d594214", "raw": {"market": "0xaf9d0e448129a9f657f851d49495ba4742055d80e0ef1166ba0ee81d4d594214", "asset_id": "4153292802911610701832309484716814274802943278345248636922528170020319407796", "price": "0.983", "size": "0", "side": "SELL", "timestamp": "1768404123251", "received_at": "2026-01-14T16:22:02.946831"}}
{"event_type": "price_change", "event_ts": "2026-01-14T16:22:02.946831", "ingestion_ts": "2026-01-14T16:33:58.842229", "market_id": "0xaf9d0e448129a9f657f851d49495ba4742055d80e0ef1166ba0ee81d4d594214", "raw": {"market": "0xaf9d0e448129a9f657f851d49495ba4742055d80e0ef1166ba0ee81d4d594214", "asset_id": "101676997363687199724245607342877036148401850938023978421879460310389391082353", "price": "0.017", "size": "0", "side": "BUY", "timestamp": "1768404123251", "received_at": "2026-01-14T16:22:02.946831"}}
{"event_type": "price_change", "event_ts": "2026-01-14T16:22:03.177043", "ingestion_ts": "2026-01-14T16:33:58.842229", "market_id": "0xaf9d0e448129a9f657f851d49495ba4742055d80e0ef1166ba0ee81d4d594214", "raw": {"market": "0xaf9d0e448129a9f657f851d49495ba4742055d80e0ef1166ba0ee81d4d594214", "asset_id": "4153292802911610701832309484716814274802943278345248636922528170020319407796", "price": "0.984", "size": "7.13", "side": "SELL", "timestamp": "1768404123425", "received_at": "2026-01-14T16:22:03.177043"}}
{"event_type": "price_change", "event_ts": "2026-01-14T16:22:03.177043", "ingestion_ts": "2026-01-14T16:33:58.842229", "market_id": "0xaf9d0e448129a9f657f851d49495ba4742055d80e0ef1166ba0ee81d4d594214", "raw": {"market": "0xaf9d0e448129a9f657f851d49495ba4742055d80e0ef1166ba0ee81d4d594214", "asset_id": "101676997363687199724245607342877036148401850938023978421879460310389391082353", "price": "0.016", "size": "7.13", "side": "BUY", "timestamp": "1768404123425", "received_at": "2026-01-14T16:22:03.177043"}}
{"event_type": "price_change", "event_ts": "2026-01-14T16:22:23.492540", "ingestion_ts": "2026-01-14T16:33:58.842229", "market_id": "0x5533fb9ab797777a243c75b1bf3882c54b1ee91f794730c090bf701598993529", "raw": {"market": "0x5533fb9ab797777a243c75b1bf3882c54b1ee91f794730c090bf701598993529", "asset_id": "99478074208094578615268494931219682040135218828258512927013036335093067688695", "price": "0.937", "size": "75.36", "side": "BUY", "timestamp": "1768404143681", "received_at": "2026-01-14T16:22:23.492540"}}
{"event_type": "price_change", "event_ts": "2026-01-14T16:22:23.492540", "ingestion_ts": "2026-01-14T16:33:58.842229", "market_id": "0x5533fb9ab797777a243c75b1bf3882c54b1ee91f794730c090bf701598993529", "raw": {"market": "0x5533fb9ab797777a243c75b1bf3882c54b1ee91f794730c090bf701598993529", "asset_id": "22532055631814907447535815649879981046415248231878961745474659705989546420934", "price": "0.063", "size": "75.36", "side": "SELL", "timestamp": "1768404143681", "received_at": "2026-01-14T16:22:23.492540"}}
{"event_type": "price_change", "event_ts": "2026-01-14T16:22:24.913427", "ingestion_ts": "2026-01-14T16:33:58.842229", "market_id": "0x2393ed0b0fdc450054c7b9071907eca75cf4fc36e385adf4a0a5f99ee62243e8", "raw": {"market": "0x2393ed0b0fdc450054c7b9071907eca75cf4fc36e385adf4a0a5f99ee62243e8", "asset_id": "32769749367306925959219403371425714180265458150646381231272229429098460625924", "price": "0.45", "size": "1332", "side": "BUY", "timestamp": "1768404145218", "received_at": "2026-01-14T16:22:24.913427"}}
{"event_type": "price_change", "event_ts": "2026-01-14T16:22:24.913427", "ingestion_ts": "2026-01-14T16:33:58.842229", "market_id": "0x2393ed0b0fdc450054c7b9071907eca75cf4fc36e385adf4a0a5f99ee62243e8", "raw": {"market": "0x2393ed0b0fdc450054c7b9071907eca75cf4fc36e385adf4a0a5f99ee62243e8", "asset_id": "100074770378634056601572485653252702850363676459996771990439989989293515601975", "price": "0.55", "size": "1332", "side": "SELL", "timestamp": "1768404145218", "received_at": "2026-01-14T16:22:24.913427"}}
{"event_type": "price_change", "event_ts": "2026-01-14T16:22:28.474616", "ingestion_ts": "2026-01-14T16:33:58.842229", "market_id": "0x318b222c1435b47c338e66ca6001f782711186a488ae7b7248f7edc6ff076a83", "raw": {"market": "0x318b222c1435b47c338e66ca6001f782711186a488ae7b7248f7edc6ff076a83", "asset_id": "63773739594775606083258239254748928077067768053882704658119720069071630213026", "price": "0.496", "size": "1208", "side": "BUY", "timestamp": "1768404148752", "received_at": "2026-01-14T16:22:28.474616"}}
{"event_type": "price_change", "event_ts": "2026-01-14T16:22:28.474616", "ingestion_ts": "2026-01-14T16:33:58.842229", "market_id": "0x318b222c1435b47c338e66ca6001f782711186a488ae7b7248f7edc6ff076a83", "raw": {"market": "0x318b222c1435b47c338e66ca6001f782711186a488ae7b7248f7edc6ff076a83", "asset_id": "56738600572035832904895845056468792275697823297413384908752239327866518310010", "price": "0.504", "size": "1208", "side": "SELL", "timestamp": "1768404148752", "received_at": "2026-01-14T16:22:28.474616"}}
{"event_type": "price_change", "event_ts": "2026-01-14T16:22:40.936069", "ingestion_ts": "2026-01-14T16:33:58.842229", "market_id": "0x2393ed0b0fdc450054c7b9071907eca75cf4fc36e385adf4a0a5f99ee62243e8", "raw": {"market": "0x2393ed0b0fdc450054c7b9071907eca75cf4fc36e385adf4a0a5f99ee62243e8", "asset_id": "32769749367306925959219403371425714180265458150646381231272229429098460625924", "price": "0.473", "size": "0", "side": "BUY", "timestamp": "1768404161245", "received_at": "2026-01-14T16:22:40.936069"}}
{"event_type": "price_change", "event_ts": "2026-01-14T16:22:40.936069", "ingestion_ts": "2026-01-14T16:33:58.842229", "market_id": "0x2393ed0b0fdc450054c7b9071907eca75cf4fc36e385adf4a0a5f99ee62243e8", "raw": {"market": "0x2393ed0b0fdc450054c7b9071907eca75cf4fc36e385adf4a0a5f99ee62243e8", "asset_id": "100074770378634056601572485653252702850363676459996771990439989989293515601975", "price": "0.527", "size": "0", "side": "SELL", "timestamp": "1768404161245", "received_at": "2026-01-14T16:22:40.936069"}}
{"event_type": "price_change", "event_ts": "2026-01-14T16:22:40.988148", "ingestion_ts": "2026-01-14T16:33:58.842229", "market_id": "0x2393ed0b0fdc450054c7b9071907eca75cf4fc36e385adf4a0a5f99ee62243e8", "raw": {"market": "0x2393ed0b0fdc450054c7b9071907eca75cf4fc36e385adf4a0a5f99ee62243e8", "asset_id": "32769749367306925959219403371425714180265458150646381231272229429098460625924", "price": "0.451", "size": "5", "side": "BUY", "timestamp": "1768404161291", "received_at": "2026-01-14T16:22:40.988148"}}
{"event_type": "price_change", "event_ts": "2026-01-14T16:22:40.988148", "ingestion_ts": "2026-01-14T16:33:58.842229", "market_id": "0x2393ed0b0fdc450054c7b9071907eca75cf4fc36e385adf4a0a5f99ee62243e8", "raw": {"market": "0x2393ed0b0fdc450054c7b9071907eca75cf4fc36e385adf4a0a5f99ee62243e8", "asset_id": "100074770378634056601572485653252702850363676459996771990439989989293515601975", "price": "0.549", "size": "5", "side": "SELL", "timestamp": "1768404161291", "received_at": "2026-01-14T16:22:40.988148"}}
{"event_type": "price_change", "event_ts": "2026-01-14T16:22:43.663923", "ingestion_ts": "2026-01-14T16:33:58.842229", "market_id": "0x318b222c1435b47c338e66ca6001f782711186a488ae7b7248f7edc6ff076a83", "raw": {"market": "0x318b222c1435b47c338e66ca6001f782711186a488ae7b7248f7edc6ff076a83", "asset_id": "63773739594775606083258239254748928077067768053882704658119720069071630213026", "price": "0.204", "size": "0", "side": "BUY", "timestamp": "1768404163962", "received_at": "2026-01-14T16:22:43.663923"}}
{"event_type": "price_change", "event_ts": "2026-01-14T16:22:43.663923", "ingestion_ts": "2026-01-14T16:33:58.842229", "market_id": "0x318b222c1435b47c338e66ca6001f782711186a488ae7b7248f7edc6ff076a83", "raw": {"market": "0x318b222c1435b47c338e66ca6001f782711186a488ae7b7248f7edc6ff076a83", "asset_id": "56738600572035832904895845056468792275697823297413384908752239327866518310010", "price": "0.796", "size": "0", "side": "SELL", "timestamp": "1768404163962", "received_at": "2026-01-14T16:22:43.663923"}}
{"event_type": "price_change", "event_ts": "2026-01-14T16:22:53.004452", "ingestion_ts": "2026-01-14T16:33:58.842229", "market_id": "0x318b222c1435b47c338e66ca6001f782711186a488ae7b7248f7edc6ff076a83", "raw": {"market": "0x318b222c1435b47c338e66ca6001f782711186a488ae7b7248f7edc6ff076a83", "asset_id": "63773739594775606083258239254748928077067768053882704658119720069071630213026", "price": "0.689", "size": "0", "side": "BUY", "timestamp": "1768404173334", "received_at": "2026-01-14T16:22:53.004452"}}
{"event_type": "price_change", "event_ts": "2026-01-14T16:22:53.004452", "ingestion_ts": "2026-01-14T16:33:58.842229", "market_id": "0x318b222c1435b47c338e66ca6001f782711186a488ae7b7248f7edc6ff076a83", "raw": {"market": "0x318b222c1435b47c338e66ca6001f782711186a488ae7b7248f7edc6ff076a83", "asset_id": "56738600572035832904895845056468792275697823297413384908752239327866518310010", "price": "0.311", "size": "0", "side": "SELL", "timestamp": "1768404173334", "received_at": "2026-01-14T16:22:53.004452"}}
{"event_type": "price_change", "event_ts": "2026-01-14T16:22:53.071647", "ingestion_ts": "2026-01-14T16:33:58.842229", "market_id": "0x318b222c1435b47c338e66ca6001f782711186a488ae7b7248f7edc6ff076a83", "raw": {"market": "0x318b222c1435b47c338e66ca6001f782711186a488ae7b7248f7edc6ff076a83", "asset_id": "63773739594775606083258239254748928077067768053882704658119720069071630213026", "price": "0.689", "size": "5", "side": "BUY", "timestamp": "1768404173394", "received_at": "2026-01-14T16:22:53.071647"}}
{"event_type": "price_change", "event_ts": "2026-01-14T16:22:53.071647", "ingestion_ts": "2026-01-14T16:33:58.842229", "market_id": "0x318b222c1435b47c338e66ca6001f782711186a488ae7b7248f7edc6ff076a83", "raw": {"market": "0x318b222c1435b47c338e66ca6001f782711186a488ae7b7248f7edc6ff076a83", "asset_id": "56738600572035832904895845056468792275697823297413384908752239327866518310010", "price": "0.311", "size": "5", "side": "SELL", "timestamp": "1768404173394", "received_at": "2026-01-14T16:22:53.071647"}}
{"event_type": "price_change", "event_ts": "2026-01-14T16:23:11.472467", "ingestion_ts": "2026-01-14T16:33:58.842229", "market_id": "0xe6508d867d153a268bdab732aa8abc8cc57e652d28a23aa042da40895bf031b2", "raw": {"market": "0xe6508d867d153a268bdab732aa8abc8cc57e652d28a23aa042da40895bf031b2", "asset_id": "57878493050148425637822780001963685814731344602319345842647239312888833935027", "price": "0.998", "size": "2469.8", "side": "BUY", "timestamp": "1768404191714", "received_at": "2026-01-14T16:23:11.472467"}}
{"event_type": "price_change", "event_ts": "2026-01-14T16:23:11.472467", "ingestion_ts": "2026-01-14T16:33:58.842229", "market_id": "0xe6508d867d153a268bdab732aa8abc8cc57e652d28a23aa042da40895bf031b2", "raw": {"market": "0xe6508d867d153a268bdab732aa8abc8cc57e652d28a23aa042da40895bf031b2", "asset_id": "2853768819561879023657600399360829876689515906714535926781067187993853038980", "price": "0.002", "size": "2469.8", "side": "SELL", "timestamp": "1768404191714", "received_at": "2026-01-14T16:23:11.472467"}}
