{"event_type": "price_change", "event_ts": "2026-01-14T16:28:49.688480", "ingestion_ts": "2026-01-14T16:33:58.842229", "market_id": "0xb9bbdd34304344dcc45803780a34c97d73a00133a5ecf70f63e1008b8abb2fca", "raw": {"market": "0xb9bbdd34304344dcc45803780a34c97d73a00133a5ecf70f63e1008b8abb2fca", "asset_id": "8682484153073832526711485265636767086525069344085206423986003504588877767339", "price": "0.053", "size": "0", "side": "BUY", "timestamp": "1768404530002", "received_at": "2026-01-14T16:28:49.688480"}}
{"event_type": "price_change", "event_ts": "2026-01-14T16:28:49.688480", "ingestion_ts": "2026-01-14T16:33:58.842229", "market_id": "0xb9bbdd34304344dcc45803780a34c97d73a00133a5ecf70f63e1008b8abb2fca", "raw": {"market": "0xb9bbdd34304344dcc45803780a34c97d73a00133a5ecf70f63e1008b8abb2fca", "asset_id": "72012724360700510767037780555710363830014634797787940282136454146828040926557", "price": "0.947", "size": "0", "side": "SELL", "timestamp": "1768404530002", "received_at": "2026-01-14T16:28:49.688480"}}
{"event_type": "price_change", "event_ts": "2026-01-14T16:28:49.688490", "ingestion_ts": "2026-01-14T16:33:58.842229", "market_id": "0x49a20c7523c271099008f3ef9a31521263b24d637959852a391e6b4697b1a437", "raw": {"market": "0x49a20c7523c271099008f3ef9a31521263b24d637959852a391e6b4697b1a437", "asset_id": "55881023621710858558280545117465775643848233756850602339827152783696837905531", "price": "0.011", "size": "0", "side": "BUY", "timestamp": "1768404530002", "received_at": "2026-01-14T16:28:49.688490"}}
{"event_type": "price_change", "event_ts": "2026-01-14T16:28:49.688490", "ingestion_ts": "2026-01-14T16:33:58.842229", "market_id": "0x49a20c7523c271099008f3ef9a31521263b24d637959852a391e6b4697b1a437", "raw": {"market": "0x49a20c7523c271099008f3ef9a31521263b24d637959852a391e6b4697b1a437", "asset_id": "13018971792603393862521629014128024641178044618205296260525674415067194037856", "price": "0.989", "size": "0", "side": "SELL", "timestamp": "1768404530002", "received_at": "2026-01-14T16:28:49.688490"}}
{"event_type": "price_change", "event_ts": "2026-01-14T16:28:49.688501", "ingestion_ts": "2026-01-14T16:33:58.842229", "market_id": "0x50c669f178da4e5bbea7f1be25041fd278914712fa87a6a6f8e57d5923d88dee", "raw": {"market": "0x50c669f178da4e5bbea7f1be25041fd278914712fa87a6a6f8e57d5923d88dee", "asset_id": "74040420326294854165772767082819937451857852955603897473157746262672057685461", "price": "0.03", "size": "0", "side": "BUY", "timestamp": "1768404530002", "received_at": "2026-01-14T16:28:49.688501"}}
{"event_type": "price_change", "event_ts": "2026-01-14T16:28:49.688501", "ingestion_ts": "2026-01-14T16:33:58.842229", "market_id": "0x50c669f178da4e5bbea7f1be25041fd278914712fa87a6a6f8e57d5923d88dee", "raw": {"market": "0x50c669f178da4e5bbea7f1be25041fd278914712fa87a6a6f8e57d5923d88dee", "asset_id": "24682525479474221428144937281315825971983904267399062415430320764754931667953", "price": "0.97", "size": "0", "side": "SELL", "timestamp": "1768404530002", "received_at": "2026-01-14T16:28:49.688501"}}
{"event_type": "price_change", "event_ts": "2026-01-14T16:28:49.688510", "ingestion_ts": "2026-01-14T16:33:58.842229", "market_id": "0xb9bbdd34304344dcc45803780a34c97d73a00133a5ecf70f63e1008b8abb2fca", "raw": {"market": "0xb9bbdd34304344dcc45803780a34c97d73a00133a5ecf70f63e1008b8abb2fca", "asset_id": "8682484153073832526711485265636767086525069344085206423986003504588877767339", "price": "0.008", "size": "0", "side": "BUY", "timestamp": "1768404530003", "received_at": "2026-01-14T16:28:49.688510"}}
{"event_type": "price_change", "event_ts": "2026-01-14T16:28:49.688510", "ingestion_ts": "2026-01-14T16:33:58.842229", "market_id": "0xb9bbdd34304344dcc45803780a34c97d73a00133a5ecf70f63e1008b8abb2fca", "raw": {"market": "0xb9bbdd34304344dcc45803780a34c97d73a00133a5ecf70f63e1008b8abb2fca", "asset_id": "72012724360700510767037780555710363830014634797787940282136454146828040926557", "price": "0.992", "size": "0", "side": "SELL", "timestamp": "1768404530003", "received_at": "2026-01-14T16:28:49.688510"}}
{"event_type": "price_change", "event_ts": "2026-01-14T16:28:49.688518", "ingestion_ts": "2026-01-14T16:33:58.842229", "market_id": "0xc55db914f0fd1fee18997706712c0dfd8d0369cdbef93a9fef12bd001914ca77", "raw": {"market": "0xc55db914f0fd1fee18997706712c0dfd8d0369cdbef93a9fef12bd001914ca77", "asset_id": "114600293444080540179603459515770723592661967180480327891296353898330242622833", "price": "0.002", "size": "0", "side": "BUY", "timestamp": "1768404530002", "received_at": "2026-01-14T16:28:49.688518"}}
{"event_type": "price_change", "event_ts": "2026-01-14T16:28:49.688518", "ingestion_ts": "2026-01-14T16:33:58.842229", "market_id": "0xc55db914f0fd1fee18997706712c0dfd8d0369cdbef93a9fef12bd001914ca77", "raw": {"market": "0xc55db914f0fd1fee18997706712c0dfd8d0369cdbef93a9fef12bd001914ca77", "asset_id": "72354723612769247426741660426331235762851940382312402276325808095604519806766", "price": "0.998", "size": "0", "side": "SELL", "timestamp": "1768404530002", "received_at": "2026-01-14T16:28:49.688518"}}
{"event_type": "price_change", "event_ts": "2026-01-14T16:28:49.688526", "ingestion_ts": "2026-01-14T16:33:58.842229", "market_id": "0x49a20c7523c271099008f3ef9a31521263b24d637959852a391e6b4697b1a437", "raw": {"market": "0x49a20c7523c271099008f3ef9a31521263b24d637959852a391e6b4697b1a437", "asset_id": "55881023621710858558280545117465775643848233756850602339827152783696837905531", "price": "0.004", "size": "0", "side": "BUY", "timestamp": "1768404530003", "received_at": "2026-01-14T16:28:49.688526"}}
{"event_type": "price_change", "event_ts": "2026-01-14T16:28:49.688526", "ingestion_ts": "2026-01-14T16:33:58.842229", "market_id": "0x49a20c7523c271099008f3ef9a31521263b24d637959852a391e6b4697b1a437", "raw": {"market": "0x49a20c7523c271099008f3ef9a31521263b24d637959852a391e6b4697b1a437", "asset_id": "13018971792603393862521629014128024641178044618205296260525674415067194037856", "price": "0.996", "size": "0", "side": "SELL", "timestamp": "1768404530003", "received_at": "2026-01-14T16:28:49.688526"}}
{"event_type": "price_change", "event_ts": "2026-01-14T16:28:49.695591", "ingestion_ts": "2026-01-14T16:33:58.842229", "market_id": "0x50c669f178da4e5bbea7f1be25041fd278914712fa87a6a6f8e57d5923d88dee", "raw": {"market": "0x50c669f178da4e5bbea7f1be25041fd278914712fa87a6a6f8e57d5923d88dee", "asset_id": "74040420326294854165772767082819937451857852955603897473157746262672057685461", "price": "0.011", "size": "0", "side": "BUY", "timestamp": "1768404530003", "received_at": "2026-01-14T16:28:49.695591"}}
{"event_type": "price_change", "event_ts": "2026-01-14T16:28:49.695591", "ingestion_ts": "2026-01-14T16:33:58.842229", "market_id": "0x50c669f178da4e5bbea7f1be25041fd278914712fa87a6a6f8e57d5923d88dee", "raw": {"market": "0x50c669f178da4e5bbea7f1be25041fd278914712fa87a6a6f8e57d5923d88dee", "asset_id": "24682525479474221428144937281315825971983904267399062415430320764754931667953", "price": "0.989", "size": "0", "side": "SELL", "timestamp": "1768404530003", "received_at": "2026-01-14T16:28:49.695591"}}
{"event_type": "price_change", "event_ts": "2026-01-14T16:28:49.695624", "ingestion_ts": "2026-01-14T16:33:58.842229", "market_id": "0xb9bbdd34304344dcc45803780a34c97d73a00133a5ecf70f63e1008b8abb2fca", "raw": {"market": "0xb9bbdd34304344dcc45803780a34c97d73a00133a5ecf70f63e1008b8abb2fca", "asset_id": "8682484153073832526711485265636767086525069344085206423986003504588877767339", "price": "0.002", "size": "0", "side": "BUY", "timestamp": "1768404530003", "received_at": "2026-01-14T16:28:49.695624"}}
{"event_type": "price_change", "event_ts": "2026-01-14T16:28:49.695624", "ingestion_ts": "2026-01-14T16:33:58.842229", "market_id": "0xb9bbdd34304344dcc45803780a34c97d73a00133a5ecf70f63e1008b8abb2fca", "raw": {"market": "0xb9bbdd34304344dcc45803780a34c97d73a00133a5ecf70f63e1008b8abb2fca", "asset_id": "72012724360700510767037780555710363830014634797787940282136454146828040926557", "price": "0.998", "size": "0", "side": "SELL", "timestamp": "1768404530003", "received_at": "2026-01-14T16:28:49.695624"}}
{"event_type": "price_change", "event_ts": "2026-01-14T16:28:49.695645", "ingestion_ts": "2026-01-14T16:33:58.842229", "market_id": "0xc55db914f0fd1fee18997706712c0dfd8d0369cdbef93a9fef12bd001914ca77", "raw": {"market": "0xc55db914f0fd1fee18997706712c0dfd8d0369cdbef93a9fef12bd001914ca77", "asset_id": "114600293444080540179603459515770723592661967180480327891296353898330242622833", "price": "0.052", "size": "0", "side": "BUY", "timestamp": "1768404530003", "received_at": "2026-01-14T16:28:49.695645"}}
{"event_type": "price_change", "event_ts": "2026-01-14T16:28:49.695645", "ingestion_ts": "2026-01-14T16:33:58.842229", "market_id": "0xc55db914f0fd1fee18997706712c0dfd8d0369cdbef93a9fef12bd001914ca77", "raw": {"market": "0xc55db914f0fd1fee18997706712c0dfd8d0369cdbef93a9fef12bd001914ca77", "asset_id": "72354723612769247426741660426331235762851940382312402276325808095604519806766", "price": "0.948", "size": "0", "side": "SELL", "timestamp": "1768404530003", "received_at": "2026-01-14T16:28:49.695645"}}
{"event_type": "price_change", "event_ts": "2026-01-14T16:28:49.695659", "ingestion_ts": "2026-01-14T16:33:58.842229", "market_id": "0x49a20c7523c271099008f3ef9a31521263b24d637959852a391e6b4697b1a437", "raw": {"market": "0x49a20c7523c271099008f3ef9a31521263b24d637959852a391e6b4697b1a437", "asset_id": "55881023621710858558280545117465775643848233756850602339827152783696837905531", "price": "0.002", "size": "0", "side": "BUY", "timestamp": "1768404530003", "received_at": "2026-01-14T16:28:49.695659"}}
{"event_type": "price_change", "event_ts": "2026-01-14T16:28:49.695659", "ingestion_ts": "2026-01-14T16:33:58.842229", "market_id": "0x49a20c7523c271099008f3ef9a31521263b24d637959852a391e6b4697b1a437", "raw": {"market": "0x49a20c7523c271099008f3ef9a31521263b24d637959852a391e6b4697b1a437", "asset_id": "13018971792603393862521629014128024641178044618205296260525674415067194037856", "price": "0.998", "size": "0", "side": "SELL", "timestamp": "1768404530003", "received_at": "2026-01-14T16:28:49.695659"}}
{"event_type": "price_change", "event_ts": "2026-01-14T16:28:49.695671", "ingestion_ts": "2026-01-14T16:33:58.842229", "market_id": "0x50c669f178da4e5bbea7f1be25041fd278914712fa87a6a6f8e57d5923d88dee", "raw": {"market": "0x50c669f178da4e5bbea7f1be25041fd278914712fa87a6a6f8e57d5923d88dee", "asset_id": "74040420326294854165772767082819937451857852955603897473157746262672057685461", "price": "0.201", "size": "0", "side": "BUY", "timestamp": "1768404530003", "received_at": "2026-01-14T16:28:49.695671"}}
{"event_type": "price_change", "event_ts": "2026-01-14T16:28:49.695671", "ingestion_ts": "2026-01-14T16:33:58.842229", "market_id": "0x50c669f178da4e5bbea7f1be25041fd278914712fa87a6a6f8e57d5923d88dee", "raw": {"market": "0x50c669f178da4e5bbea7f1be25041fd278914712fa87a6a6f8e57d5923d88dee", "asset_id": "24682525479474221428144937281315825971983904267399062415430320764754931667953", "price": "0.799", "size": "0", "side": "SELL", "timestamp": "1768404530003", "received_at": "2026-01-14T16:28:49.695671"}}
{"event_type": "price_change", "event_ts": "2026-01-14T16:28:49.695688", "ingestion_ts": "2026-01-14T16:33:58.842229", "market_id": "0x49a20c7523c271099008f3ef9a31521263b24d637959852a391e6b4697b1a437", "raw": {"market": "0x49a20c7523c271099008f3ef9a31521263b24d637959852a391e6b4697b1a437", "asset_id": "55881023621710858558280545117465775643848233756850602339827152783696837905531", "price": "0.051", "size": "0", "side": "BUY", "timestamp": "1768404530003", "received_at": "2026-01-14T16:28:49.695688"}}
{"event_type": "price_change", "event_ts": "2026-01-14T16:28:49.695688", "ingestion_ts": "2026-01-14T16:33:58.842229", "market_id": "0x49a20c7523c271099008f3ef9a31521263b24d637959852a391e6b4697b1a437", "raw": {"market": "0x49a20c7523c271099008f3ef9a31521263b24d637959852a391e6b4697b1a437", "asset_id": "13018971792603393862521629014128024641178044618205296260525674415067194037856", "price": "0.949", "size": "0", "side": "SELL", "timestamp": "1768404530003", "received_at": "2026-01-14T16:28:49.695688"}}
{"event_type": "price_change", "event_ts": "2026-01-14T16:28:49.838462", "ingestion_ts": "2026-01-14T16:33:58.842229", "market_id": "0x9472be65457510b7fc3477b20ba90910e99d92eac8421a14bf4b7b7a08ef31dc", "raw": {"market": "0x9472be65457510b7fc3477b20ba90910e99d92eac8421a14bf4b7b7a08ef31dc", "asset_id": "43311793366960417907757893276427136943959788721376762326430771171648759300146", "price": "0.926", "size": "0", "side": "BUY", "timestamp": "1768404530135", "received_at": "2026-01-14T16:28:49.838462"}}
{"event_type": "price_change", "event_ts": "2026-01-14T16:28:49.838462", "ingestion_ts": "2026-01-14T16:33:58.842229", "market_id": "0x9472be65457510b7fc3477b20ba90910e99d92eac8421a14bf4b7b7a08ef31dc", "raw": {"market": "0x9472be65457510b7fc3477b20ba90910e99d92eac8421a14bf4b7b7a08ef31dc", "asset_id": "73414222381656326204771753454630063673548497164758947581648273905027617570612", "price": "0.074", "size": "0", "side": "SELL", "timestamp": "1768404530135", "received_at": "2026-01-14T16:28:49.838462"}}
{"event_type": "price_change", "event_ts": "2026-01-14T16:28:49.838499", "ingestion_ts": "2026-01-14T16:33:58.842229", "market_id": "0x2393ed0b0fdc450054c7b9071907eca75cf4fc36e385adf4a0a5f99ee62243e8", "raw": {"market": "0x2393ed0b0fdc450054c7b9071907eca75cf4fc36e385adf4a0a5f99ee62243e8", "asset_id": "32769749367306925959219403371425714180265458150646381231272229429098460625924", "price": "0.814", "size": "0", "side": "BUY", "timestamp": "1768404530135", "received_at": "2026-01-14T16:28:49.838499"}}
{"event_type": "price_change", "event_ts": "2026-01-14T16:28:49.838499", "ingestion_ts": "2026-01-14T16:33:58.842229", "market_id": "0x2393ed0b0fdc450054c7b9071907eca75cf4fc36e385adf4a0a5f99ee62243e8", "raw": {"market": "0x2393ed0b0fdc450054c7b9071907eca75cf4fc36e385adf4a0a5f99ee62243e8", "asset_id": "100074770378634056601572485653252702850363676459996771990439989989293515601975", "price": "0.186", "size": "0", "side": "SELL", "timestamp": "1768404530135", "received_at": "2026-01-14T16:28:49.838499"}}
{"event_type": "price_change", "event_ts": "2026-01-14T16:28:50.015304", "ingestion_ts": "2026-01-14T16:33:58.842229", "market_id": "0x9472be65457510b7fc3477b20ba90910e99d92eac8421a14bf4b7b7a08ef31dc", "raw": {"market": "0x9472be65457510b7fc3477b20ba90910e99d92eac8421a14bf4b7b7a08ef31dc", "asset_id": "43311793366960417907757893276427136943959788721376762326430771171648759300146", "price": "0.83", "size": "10", "side": "BUY", "timestamp": "1768404530352", "received_at": "2026-01-14T16:28:50.015304"}}
{"event_type": "price_change", "event_ts": "2026-01-14T16:28:50.015304", "ingestion_ts": "2026-01-14T16:33:58.842229", "market_id": "0x9472be65457510b7fc3477b20ba90910e99d92eac8421a14bf4b7b7a08ef31dc", "raw": {"market": "0x9472be65457510b7fc3477b20ba90910e99d92eac8421a14bf4b7b7a08ef31dc", "asset_id": "73414222381656326204771753454630063673548497164758947581648273905027617570612", "price": "0.17", "size": "10", "side": "SELL", "timestamp": "1768404530352", "received_at": "2026-01-14T16:28:50.015304"}}
{"event_type": "price_change", "event_ts": "2026-01-14T16:28:50.019458", "ingestion_ts": "2026-01-14T16:33:58.842229", "market_id": "0x9472be65457510b7fc3477b20ba90910e99d92eac8421a14bf4b7b7a08ef31dc", "raw": {"market": "0x9472be65457510b7fc3477b20ba90910e99d92eac8421a14bf4b7b7a08ef31dc", "asset_id": "43311793366960417907757893276427136943959788721376762326430771171648759300146", "price": "0.926", "size": "20", "side": "BUY", "timestamp": "1768404530353", "received_at": "2026-01-14T16:28:50.019458"}}
{"event_type": "price_change", "event_ts": "2026-01-14T16:28:50.019458", "ingestion_ts": "2026-01-14T16:33:58.842229", "market_id": "0x9472be65457510b7fc3477b20ba90910e99d92eac8421a14bf4b7b7a08ef31dc", "raw": {"market": "0x9472be65457510b7fc3477b20ba90910e99d92eac8421a14bf4b7b7a08ef31dc", "asset_id": "73414222381656326204771753454630063673548497164758947581648273905027617570612", "price": "0.074", "size": "20", "side": "SELL", "timestamp": "1768404530353", "received_at": "2026-01-14T16:28:50.019458"}}
{"event_type": "price_change", "event_ts": "2026-01-14T16:29:01.708666", "ingestion_ts": "2026-01-14T16:33:58.842229", "market_id": "0x49a20c7523c271099008f3ef9a31521263b24d637959852a391e6b4697b1a437", "raw": {"market": "0x49a20c7523c271099008f3ef9a31521263b24d637959852a391e6b4697b1a437", "asset_id": "55881023621710858558280545117465775643848233756850602339827152783696837905531", "price": "0.534", "size": "0", "side": "BUY", "timestamp": "1768404542040", "received_at": "2026-01-14T16:29:01.708666"}}
{"event_type": "price_change", "event_ts": "2026-01-14T16:29:01.708666", "ingestion_ts": "2026-01-14T16:33:58.842229", "market_id": "0x49a20c7523c271099008f3ef9a31521263b24d637959852a391e6b4697b1a437", "raw": {"market": "0x49a20c7523c271099008f3ef9a31521263b24d637959852a391e6b4697b1a437", "asset_id": "13018971792603393862521629014128024641178044618205296260525674415067194037856", "price": "0.466", "size": "0", "side": "SELL", "timestamp": "1768404542040", "received_at": "2026-01-14T16:29:01.708666"}}
{"event_type": "price_change", "event_ts": "2026-01-14T16:29:01.765459", "ingestion_ts": "2026-01-14T16:33:58.842229", "market_id": "0x49a20c7523c271099008f3ef9a31521263b24d637959852a391e6b4697b1a437", "raw": {"market": "0x49a20c7523c271099008f3ef9a31521263b24d637959852a391e6b4697b1a437", "asset_id": "55881023621710858558280545117465775643848233756850602339827152783696837905531", "price": "0.534", "size": "5", "side": "BUY", "timestamp": "1768404542103", "received_at": "2026-01-14T16:29:01.765459"}}
{"event_type": "price_change", "event_ts": "2026-01-14T16:29:01.765459", "ingestion_ts": "2026-01-14T16:33:58.842229", "market_id": "0x49a20c7523c271099008f3ef9a31521263b24d637959852a391e6b4697b1a437", "raw": {"market": "0x49a20c7523c271099008f3ef9a31521263b24d637959852a391e6b4697b1a437", "asset_id": "13018971792603393862521629014128024641178044618205296260525674415067194037856", "price": "0.466", "size": "5", "side": "SELL", "timestamp": "1768404542103", "received_at": "2026-01-14T16:29:01.765459"}}
{"event_type": "price_change", "event_ts": "2026-01-14T16:29:01.928284", "ingestion_ts": "2026-01-14T16:33:58.842229", "market_id": "0x50c669f178da4e5bbea7f1be25041fd278914712fa87a6a6f8e57d5923d88dee", "raw": {"market": "0x50c669f178da4e5bbea7f1be25041fd278914712fa87a6a6f8e57d5923d88dee", "asset_id": "74040420326294854165772767082819937451857852955603897473157746262672057685461", "price": "0.882", "size": "0", "side": "BUY", "timestamp": "1768404542265", "received_at": "2026-01-14T16:29:01.928284"}}
{"event_type": "price_change", "event_ts": "2026-01-14T16:29:01.928284", "ingestion_ts": "2026-01-14T16:33:58.842229", "market_id": "0x50c669f178da4e5bbea7f1be25041fd278914712fa87a6a6f8e57d5923d88dee", "raw": {"market": "0x50c669f178da4e5bbea7f1be25041fd278914712fa87a6a6f8e57d5923d88dee", "asset_id": "24682525479474221428144937281315825971983904267399062415430320764754931667953", "price": "0.118", "size": "0", "side": "SELL", "timestamp": "1768404542265", "received_at": "2026-01-14T16:29:01.928284"}}
{"event_type": "price_change", "event_ts": "2026-01-14T16:29:02.055749", "ingestion_ts": "2026-01-14T16:33:58.842229", "market_id": "0x50c669f178da4e5bbea7f1be25041fd278914712fa87a6a6f8e57d5923d88dee", "raw": {"market": "0x50c669f178da4e5bbea7f1be25041fd278914712fa87a6a6f8e57d5923d88dee", "asset_id": "74040420326294854165772767082819937451857852955603897473157746262672057685461", "price": "0.925", "size": "20", "side": "BUY", "timestamp": "1768404542391", "received_at": "2026-01-14T16:29:02.055749"}}
{"event_type": "price_change", "event_ts": "2026-01-14T16:29:02.055749", "ingestion_ts": "2026-01-14T16:33:58.842229", "market_id": "0x50c669f178da4e5bbea7f1be25041fd278914712fa87a6a6f8e57d5923d88dee", "raw": {"market": "0x50c669f178da4e5bbea7f1be25041fd278914712fa87a6a6f8e57d5923d88dee", "asset_id": "24682525479474221428144937281315825971983904267399062415430320764754931667953", "price": "0.075", "size": "20", "side": "SELL", "timestamp": "1768404542391", "received_at": "2026-01-14T16:29:02.055749"}}
{"event_type": "price_change", "event_ts": "2026-01-14T16:29:02.055791", "ingestion_ts": "2026-01-14T16:33:58.842229", "market_id": "0x50c669f178da4e5bbea7f1be25041fd278914712fa87a6a6f8e57d5923d88dee", "raw": {"market": "0x50c669f178da4e5bbea7f1be25041fd278914712fa87a6a6f8e57d5923d88dee", "asset_id": "74040420326294854165772767082819937451857852955603897473157746262672057685461", "price": "0.882", "size": "10", "side": "BUY", "timestamp": "1768404542392", "received_at": "2026-01-14T16:29:02.055791"}}
{"event_type": "price_change", "event_ts": "2026-01-14T16:29:02.055791", "ingestion_ts": "2026-01-14T16:33:58.842229", "market_id": "0x50c669f178da4e5bbea7f1be25041fd278914712fa87a6a6f8e57d5923d88dee", "raw": {"market": "0x50c669f178da4e5bbea7f1be25041fd278914712fa87a6a6f8e57d5923d88dee", "asset_id": "24682525479474221428144937281315825971983904267399062415430320764754931667953", "price": "0.118", "size": "10", "side": "SELL", "timestamp": "1768404542392", "received_at": "2026-01-14T16:29:02.055791"}}
{"event_type": "price_change", "event_ts": "2026-01-14T16:29:15.405079", "ingestion_ts": "2026-01-14T16:33:58.842229", "market_id": "0x2393ed0b0fdc450054c7b9071907eca75cf4fc36e385adf4a0a5f99ee62243e8", "raw": {"market": "0x2393ed0b0fdc450054c7b9071907eca75cf4fc36e385adf4a0a5f99ee62243e8", "asset_id": "32769749367306925959219403371425714180265458150646381231272229429098460625924", "price": "0.865", "size": "0", "side": "BUY", "timestamp": "1768404555438", "received_at": "2026-01-14T16:29:15.405079"}}
{"event_type": "price_change", "event_ts": "2026-01-14T16:29:15.405079", "ingestion_ts": "2026-01-14T16:33:58.842229", "market_id": "0x2393ed0b0fdc450054c7b9071907eca75cf4fc36e385adf4a0a5f99ee62243e8", "raw": {"market": "0x2393ed0b0fdc450054c7b9071907eca75cf4fc36e385adf4a0a5f99ee62243e8", "asset_id": "100074770378634056601572485653252702850363676459996771990439989989293515601975", "price": "0.135", "size": "0", "side": "SELL", "timestamp": "1768404555438", "received_at": "2026-01-14T16:29:15.405079"}}
{"event_type": "price_change", "event_ts": "2026-01-14T16:29:15.408396", "ingestion_ts": "2026-01-14T16:33:58.842229", "market_id": "0xaf9d0e448129a9f657f851d49495ba4742055d80e0ef1166ba0ee81d4d594214", "raw": {"market": "0xaf9d0e448129a9f657f851d49495ba4742055d80e0ef1166ba0ee81d4d594214", "asset_id": "4153292802911610701832309484716814274802943278345248636922528170020319407796", "price": "0.879", "size": "0", "side": "BUY", "timestamp": "1768404555439", "received_at": "2026-01-14T16:29:15.408396"}}
{"event_type": "price_change", "event_ts": "2026-01-14T16:29:15.408396", "ingestion_ts": "2026-01-14T16:33:58.842229", "market_id": "0xaf9d0e448129a9f657f851d49495ba4742055d80e0ef1166ba0ee81d4d594214", "raw": {"market": "0xaf9d0e448129a9f657f851d49495ba4742055d80e0ef1166ba0ee81d4d594214", "asset_id": "101676997363687199724245607342877036148401850938023978421879460310389391082353", "price": "0.121", "size": "0", "side": "SELL", "timestamp": "1768404555439", "received_at": "2026-01-14T16:29:15.408396"}}
{"event_type": "price_change", "event_ts": "2026-01-14T16:29:15.435745", "ingestion_ts": "2026-01-14T16:33:58.842229", "market_id": "0x49686d26fb712515cd5e12c23f0a1c7e10214c7faa3cb0a730aabe0c33694082", "raw": {"market": "0x49686d26fb712515cd5e12c23f0a1c7e10214c7faa3cb0a730aabe0c33694082", "asset_id": "30442780799048074404860985387051749017905070253466005720364298335239299761065", "price": "0.032", "size": "0", "side": "BUY", "timestamp": "1768404555438", "received_at": "2026-01-14T16:29:15.435745"}}
{"event_type": "price_change", "event_ts": "2026-01-14T16:29:15.435745", "ingestion_ts": "2026-01-14T16:33:58.842229", "market_id": "0x49686d26fb712515cd5e12c23f0a1c7e10214c7faa3cb0a730aabe0c33694082", "raw": {"market": "0x49686d26fb712515cd5e12c23f0a1c7e10214c7faa3cb0a730aabe0c33694082", "asset_id": "13244681086321087932946246027856416106585284024824496763706748621681543444582", "price": "0.968", "size": "0", "side": "SELL", "timestamp": "1768404555438", "received_at": "2026-01-14T16:29:15.435745"}}
{"event_type": "price_change", "event_ts": "2026-01-14T16:29:15.508077", "ingestion_ts": "2026-01-14T16:33:58.842229", "market_id": "0xb9bbdd34304344dcc45803780a34c97d73a00133a5ecf70f63e1008b8abb2fca", "raw": {"market": "0xb9bbdd34304344dcc45803780a34c97d73a00133a5ecf70f63e1008b8abb2fca", "asset_id": "8682484153073832526711485265636767086525069344085206423986003504588877767339", "price": "0.88", "size": "0", "side": "BUY", "timestamp": "1768404555436", "received_at": "2026-01-14T16:29:15.508077"}}
{"event_type": "price_change", "event_ts": "2026-01-14T16:29:15.508077", "ingestion_ts": "2026-01-14T16:33:58.842229", "market_id": "0xb9bbdd34304344dcc45803780a34c97d73a00133a5ecf70f63e1008b8abb2fca", "raw": {"market": "0xb9bbdd34304344dcc45803780a34c97d73a00133a5ecf70f63e1008b8abb2fca", "asset_id": "72012724360700510767037780555710363830014634797787940282136454146828040926557", "price": "0.12", "size": "0", "side": "SELL", "timestamp": "1768404555436", "received_at": "2026-01-14T16:29:15.508077"}}
{"event_type": "price_change", "event_ts": "2026-01-14T16:29:15.520098", "ingestion_ts": "2026-01-14T16:33:58.842229", "market_id": "0xe68594f1350f5535532b24979b5b5c1948432cbfc0c363802c32a8f9ab4e6509", "raw": {"market": "0xe68594f1350f5535532b24979b5b5c1948432cbfc0c363802c32a8f9ab4e6509", "asset_id": "3074032031589250926591186368301243337494992039402397918135503567058257050088", "price": "0.937", "size": "0", "side": "BUY", "timestamp": "1768404555453", "received_at": "2026-01-14T16:29:15.520098"}}
{"event_type": "price_change", "event_ts": "2026-01-14T16:29:15.520098", "ingestion_ts": "2026-01-14T16:33:58.842229", "market_id": "0xe68594f1350f5535532b24979b5b5c1948432cbfc0c363802c32a8f9ab4e6509", "raw": {"market": "0xe68594f1350f5535532b24979b5b5c1948432cbfc0c363802c32a8f9ab4e6509", "asset_id": "47459180813047899567328389455747872955901265556145057896316155826890276004242", "price": "0.063", "size": "0", "side": "SELL", "timestamp": "1768404555453", "received_at": "2026-01-14T16:29:15.520098"}}
{"event_type": "price_change", "event_ts": "2026-01-14T16:29:15.725409", "ingestion_ts": "2026-01-14T16:33:58.842229", "market_id": "0x44f08744458b8896620cd3330bc5e1ea69df4199b02d4fc583b3fc96e5d314ce", "raw": {"market": "0x44f08744458b8896620cd3330bc5e1ea69df4199b02d4fc583b3fc96e5d314ce", "asset_id": "72327831507226612545928776794104143393438710920370371172884559893525100761096", "price": "0.88", "size": "0", "side": "BUY", "timestamp": "1768404555444", "received_at": "2026-01-14T16:29:15.725409"}}
{"event_type": "price_change", "event_ts": "2026-01-14T16:29:15.725409", "ingestion_ts": "2026-01-14T16:33:58.842229", "market_id": "0x44f08744458b8896620cd3330bc5e1ea69df4199b02d4fc583b3fc96e5d314ce", "raw": {"market": "0x44f08744458b8896620cd3330bc5e1ea69df4199b02d4fc583b3fc96e5d314ce", "asset_id": "49194009556504828848509244326501559253829462790583873936160989575507522044057", "price": "0.12", "size": "0", "side": "SELL", "timestamp": "1768404555444", "received_at": "2026-01-14T16:29:15.725409"}}
{"event_type": "price_change", "event_ts": "2026-01-14T16:29:15.834080", "ingestion_ts": "2026-01-14T16:33:58.842229", "market_id": "0x5533fb9ab797777a243c75b1bf3882c54b1ee91f794730c090bf701598993529", "raw": {"market": "0x5533fb9ab797777a243c75b1bf3882c54b1ee91f794730c090bf701598993529", "asset_id": "99478074208094578615268494931219682040135218828258512927013036335093067688695", "price": "0.937", "size": "0", "side": "BUY", "timestamp": "1768404555456", "received_at": "2026-01-14T16:29:15.834080"}}
{"event_type": "price_change", "event_ts": "2026-01-14T16:29:15.834080", "ingestion_ts": "2026-01-14T16:33:58.842229", "market_id": "0x5533fb9ab797777a243c75b1bf3882c54b1ee91f794730c090bf701598993529", "raw": {"market": "0x5533fb9ab797777a243c75b1bf3882c54b1ee91f794730c090bf701598993529", "asset_id": "22532055631814907447535815649879981046415248231878961745474659705989546420934", "price": "0.063", "size": "0", "side": "SELL", "timestamp": "1768404555456", "received_at": "2026-01-14T16:29:15.834080"}}
{"event_type": "price_change", "event_ts": "2026-01-14T16:29:15.842173", "ingestion_ts": "2026-01-14T16:33:58.842229", "market_id": "0xc0e6b917320a47228fb96e3b5ae0e5c93773a5ae2662ae4e1f37807cfe47ce98", "raw": {"market": "0xc0e6b917320a47228fb96e3b5ae0e5c93773a5ae2662ae4e1f37807cfe47ce98", "asset_id": "58656358377246279051017109359677190749228949103591068167284263961542487110215", "price": "0.001", "size": "412", "side": "BUY", "timestamp": "1768404555464", "received_at": "2026-01-14T16:29:15.842173"}}
{"event_type": "price_change", "event_ts": "2026-01-14T16:29:15.842173", "ingestion_ts": "2026-01-14T16:33:58.842229", "market_id": "0xc0e6b917320a47228fb96e3b5ae0e5c93773a5ae2662ae4e1f37807cfe47ce98", "raw": {"market": "0xc0e6b917320a47228fb96e3b5ae0e5c93773a5ae2662ae4e1f37807cfe47ce98", "asset_id": "81647294538046680798858716589766492074338758116170717123345952330712416337530", "price": "0.999", "size": "412", "side": "SELL", "timestamp": "1768404555464", "received_at": "2026-01-14T16:29:15.842173"}}
{"event_type": "price_change", "event_ts": "2026-01-14T16:29:15.911361", "ingestion_ts": "2026-01-14T16:33:58.842229", "market_id": "0x9d24d9f9b5995949cb158d943793dea20bd448e1b3971cb6f7418bb15e719661", "raw": {"market": "0x9d24d9f9b5995949cb158d943793dea20bd448e1b3971cb6f7418bb15e719661", "asset_id": "79516121807256184736227920754945730465880754940725759201193439378549308939672", "price": "0.938", "size": "0", "side": "BUY", "timestamp": "1768404555464", "received_at": "2026-01-14T16:29:15.911361"}}
{"event_type": "price_change", "event_ts": "2026-01-14T16:29:15.911361", "ingestion_ts": "2026-01-14T16:33:58.842229", "market_id": "0x9d24d9f9b5995949cb158d943793dea20bd448e1b3971cb6f7418bb15e719661", "raw": {"market": "0x9d24d9f9b5995949cb158d943793dea20bd448e1b3971cb6f7418bb15e719661", "asset_id": "70512916946285526357165287373537570327431985324385225788636160168740471920430", "price": "0.062", "size": "0", "side": "SELL", "timestamp": "1768404555464", "received_at": "2026-01-14T16:29:15.911361"}}
{"event_type": "price_change", "event_ts": "2026-01-14T16:29:15.920761", "ingestion_ts": "2026-01-14T16:33:58.842229", "market_id": "0x50c669f178da4e5bbea7f1be25041fd278914712fa87a6a6f8e57d5923d88dee", "raw": {"market": "0x50c669f178da4e5bbea7f1be25041fd278914712fa87a6a6f8e57d5923d88dee", "asset_id": "74040420326294854165772767082819937451857852955603897473157746262672057685461", "price": "0.881", "size": "0", "side": "BUY", "timestamp": "1768404555460", "received_at": "2026-01-14T16:29:15.920761"}}
{"event_type": "price_change", "event_ts": "2026-01-14T16:29:15.920761", "ingestion_ts": "2026-01-14T16:33:58.842229", "market_id": "0x50c669f178da4e5bbea7f1be25041fd278914712fa87a6a6f8e57d5923d88dee", "raw": {"market": "0x50c669f178da4e5bbea7f1be25041fd278914712fa87a6a6f8e57d5923d88dee", "asset_id": "24682525479474221428144937281315825971983904267399062415430320764754931667953", "price": "0.119", "size": "0", "side": "SELL", "timestamp": "1768404555460", "received_at": "2026-01-14T16:29:15.920761"}}
{"event_type": "price_change", "event_ts": "2026-01-14T16:29:15.973566", "ingestion_ts": "2026-01-14T16:33:58.842229", "market_id": "0x50e477f0b316a3d97d60486479657c63be0763834d0e2e8a30b1b86dc3c1c001", "raw": {"market": "0x50e477f0b316a3d97d60486479657c63be0763834d0e2e8a30b1b86dc3c1c001", "asset_id": "39981134260608444876865205057565852475343967395624370698967311821208058420507", "price": "0.937", "size": "0", "side": "BUY", "timestamp": "1768404555464", "received_at": "2026-01-14T16:29:15.973566"}}
{"event_type": "price_change", "event_ts": "2026-01-14T16:29:15.973566", "ingestion_ts": "2026-01-14T16:33:58.842229", "market_id": "0x50e477f0b316a3d97d60486479657c63be0763834d0e2e8a30b1b86dc3c1c001", "raw": {"market": "0x50e477f0b316a3d97d60486479657c63be0763834d0e2e8a30b1b86dc3c1c001", "asset_id": "60573178197991590327120832143415406583517170365625050489007297367895074266641", "price": "0.063", "size": "0", "side": "SELL", "timestamp": "1768404555464", "received_at": "2026-01-14T16:29:15.973566"}}
{"event_type": "price_change", "event_ts": "2026-01-14T16:29:16.619440", "ingestion_ts": "2026-01-14T16:33:58.842229", "market_id": "0xaf9d0e448129a9f657f851d49495ba4742055d80e0ef1166ba0ee81d4d594214", "raw": {"market": "0xaf9d0e448129a9f657f851d49495ba4742055d80e0ef1166ba0ee81d4d594214", "asset_id": "4153292802911610701832309484716814274802943278345248636922528170020319407796", "price": "0.88", "size": "0", "side": "BUY", "timestamp": "1768404556710", "received_at": "2026-01-14T16:29:16.619440"}}
{"event_type": "price_change", "event_ts": "2026-01-14T16:29:16.619440", "ingestion_ts": "2026-01-14T16:33:58.842229", "market_id": "0xaf9d0e448129a9f657f851d49495ba4742055d80e0ef1166ba0ee81d4d594214", "raw": {"market": "0xaf9d0e448129a9f657f851d49495ba4742055d80e0ef1166ba0ee81d4d594214", "asset_id": "101676997363687199724245607342877036148401850938023978421879460310389391082353", "price": "0.12", "size": "0", "side": "SELL", "timestamp": "1768404556710", "received_at": "2026-01-14T16:29:16.619440"}}
{"event_type": "price_change", "event_ts": "2026-01-14T16:29:16.632655", "ingestion_ts": "2026-01-14T16:33:58.842229", "market_id": "0xaf9d0e448129a9f657f851d49495ba4742055d80e0ef1166ba0ee81d4d594214", "raw": {"market": "0xaf9d0e448129a9f657f851d49495ba4742055d80e0ef1166ba0ee81d4d594214", "asset_id": "4153292802911610701832309484716814274802943278345248636922528170020319407796", "price": "0.732", "size": "5", "side": "BUY", "timestamp": "1768404556747", "received_at": "2026-01-14T16:29:16.632655"}}
{"event_type": "price_change", "event_ts": "2026-01-14T16:29:16.632655", "ingestion_ts": "2026-01-14T16:33:58.842229", "market_id": "0xaf9d0e448129a9f657f851d49495ba4742055d80e0ef1166ba0ee81d4d594214", "raw": {"market": "0xaf9d0e448129a9f657f851d49495ba4742055d80e0ef1166ba0ee81d4d594214", "asset_id": "101676997363687199724245607342877036148401850938023978421879460310389391082353", "price": "0.268", "size": "5", "side": "SELL", "timestamp": "1768404556747", "received_at": "2026-01-14T16:29:16.632655"}}
{"event_type": "price_change", "event_ts": "2026-01-14T16:29:31.478554", "ingestion_ts": "2026-01-14T16:33:58.842229", "market_id": "0x318b222c1435b47c338e66ca6001f782711186a488ae7b7248f7edc6ff076a83", "raw": {"market": "0x318b222c1435b47c338e66ca6001f782711186a488ae7b7248f7edc6ff076a83", "asset_id": "63773739594775606083258239254748928077067768053882704658119720069071630213026", "price": "0.207", "size": "1448", "side": "BUY", "timestamp": "1768404571814", "received_at": "2026-01-14T16:29:31.478554"}}
{"event_type": "price_change", "event_ts": "2026-01-14T16:29:31.478554", "ingestion_ts": "2026-01-14T16:33:58.842229", "market_id": "0x318b222c1435b47c338e66ca6001f782711186a488ae7b7248f7edc6ff076a83", "raw": {"market": "0x318b222c1435b47c338e66ca6001f782711186a488ae7b7248f7edc6ff076a83", "asset_id": "56738600572035832904895845056468792275697823297413384908752239327866518310010", "price": "0.793", "size": "1448", "side": "SELL", "timestamp": "1768404571814", "received_at": "2026-01-14T16:29:31.478554"}}
{"event_type": "price_change", "event_ts": "2026-01-14T16:29:38.208850", "ingestion_ts": "2026-01-14T16:33:58.842229", "market_id": "0xcab7ba4a9133cfd407d7e73e5757e5abbace413b59421527a31113406c97815c", "raw": {"market": "0xcab7ba4a9133cfd407d7e73e5757e5abbace413b59421527a31113406c97815c", "asset_id": "20002636398944597965698652220992177552927816915094913583821579024925426590022", "price": "0.002", "size": "5250", "side": "BUY", "timestamp": "1768404578544", "received_at": "2026-01-14T16:29:38.208850"}}
{"event_type": "price_change", "event_ts": "2026-01-14T16:29:38.208850", "ingestion_ts": "2026-01-14T16:33:58.842229", "market_id": "0xcab7ba4a9133cfd407d7e73e5757e5abbace413b59421527a31113406c97815c", "raw": {"market": "0xcab7ba4a9133cfd407d7e73e5757e5abbace413b59421527a31113406c97815c", "asset_id": "96361925776989336186111887920533578209326565663637092688733016597062311745569", "price": "0.998", "size": "5250", "side": "SELL", "timestamp": "1768404578544", "received_at": "2026-01-14T16:29:38.208850"}}
{"event_type": "price_change", "event_ts": "2026-01-14T16:29:38.208887", "ingestion_ts": "2026-01-14T16:33:58.842229", "market_id": "0xcab7ba4a9133cfd407d7e73e5757e5abbace413b59421527a31113406c97815c", "raw": {"market": "0xcab7ba4a9133cfd407d7e73e5757e5abbace413b59421527a31113406c97815c", "asset_id": "20002636398944597965698652220992177552927816915094913583821579024925426590022", "price": "0.042", "size": "0", "side": "BUY", "timestamp": "1768404578544", "received_at": "2026-01-14T16:29:38.208887"}}
{"event_type": "price_change", "event_ts": "2026-01-14T16:29:38.208887", "ingestion_ts": "2026-01-14T16:33:58.842229", "market_id": "0xcab7ba4a9133cfd407d7e73e5757e5abbace413b59421527a31113406c97815c", "raw": {"market": "0xcab7ba4a9133cfd407d7e73e5757e5abbace413b59421527a31113406c97815c", "asset_id": "96361925776989336186111887920533578209326565663637092688733016597062311745569", "price": "0.958", "size": "0", "side": "SELL", "timestamp": "1768404578544", "received_at": "2026-01-14T16:29:38.208887"}}
{"event_type": "price_change", "event_ts": "2026-01-14T16:29:38.208906", "ingestion_ts": "2026-01-14T16:33:58.842229", "market_id": "0x22ac5f75af18fdb453497fbf7ac0606a09a6fd55b78b2d08aace6b946ad62038", "raw": {"market": "0x22ac5f75af18fdb453497fbf7ac0606a09a6fd55b78b2d08aace6b946ad62038", "asset_id": "97449340182256366014320155718265676486703217567849039806162053075113517266910", "price": "0.006", "size": "0", "side": "BUY", "timestamp": "1768404578545", "received_at": "2026-01-14T16:29:38.208906"}}
{"event_type": "price_change", "event_ts": "2026-01-14T16:29:38.208906", "ingestion_ts": "2026-01-14T16:33:58.842229", "market_id": "0x22ac5f75af18fdb453497fbf7ac0606a09a6fd55b78b2d08aace6b946ad62038", "raw": {"market": "0x22ac5f75af18fdb453497fbf7ac0606a09a6fd55b78b2d08aace6b946ad62038", "asset_id": "59259495934562596318644973716893809974860301509869285036503555129962149752635", "price": "0.994", "size": "0", "side": "SELL", "timestamp": "1768404578545", "received_at": "2026-01-14T16:29:38.208906"}}
{"event_type": "price_change", "event_ts": "2026-01-14T16:29:38.208919", "ingestion_ts": "2026-01-14T16:33:58.842229", "market_id": "0x22ac5f75af18fdb453497fbf7ac0606a09a6fd55b78b2d08aace6b946ad62038", "raw": {"market": "0x22ac5f75af18fdb453497fbf7ac0606a09a6fd55b78b2d08aace6b946ad62038", "asset_id": "97449340182256366014320155718265676486703217567849039806162053075113517266910", "price": "0.008", "size": "0", "side": "BUY", "timestamp": "1768404578545", "received_at": "2026-01-14T16:29:38.208919"}}
{"event_type": "price_change", "event_ts": "2026-01-14T16:29:38.208919", "ingestion_ts": "2026-01-14T16:33:58.842229", "market_id": "0x22ac5f75af18fdb453497fbf7ac0606a09a6fd55b78b2d08aace6b946ad62038", "raw": {"market": "0x22ac5f75af18fdb453497fbf7ac0606a09a6fd55b78b2d08aace6b946ad62038", "asset_id": "59259495934562596318644973716893809974860301509869285036503555129962149752635", "price": "0.992", "size": "0", "side": "SELL", "timestamp": "1768404578545", "received_at": "2026-01-14T16:29:38.208919"}}
{"event_type": "price_change", "event_ts": "2026-01-14T16:29:38.212750", "ingestion_ts": "2026-01-14T16:33:58.842229", "market_id": "0xcab7ba4a9133cfd407d7e73e5757e5abbace413b59421527a31113406c97815c", "raw": {"market": "0xcab7ba4a9133cfd407d7e73e5757e5abbace413b59421527a31113406c97815c", "asset_id": "96361925776989336186111887920533578209326565663637092688733016597062311745569", "price": "0.002", "size": "142.2", "side": "BUY", "timestamp": "1768404578545", "received_at": "2026-01-14T16:29:38.212750"}}
{"event_type": "price_change", "event_ts": "2026-01-14T16:29:38.212750", "ingestion_ts": "2026-01-14T16:33:58.842229", "market_id": "0xcab7ba4a9133cfd407d7e73e5757e5abbace413b59421527a31113406c97815c", "raw": {"market": "0xcab7ba4a9133cfd407d7e73e5757e5abbace413b59421527a31113406c97815c", "asset_id": "20002636398944597965698652220992177552927816915094913583821579024925426590022", "price": "0.998", "size": "142.2", "side": "SELL", "timestamp": "1768404578545", "received_at": "2026-01-14T16:29:38.212750"}}
{"event_type": "price_change", "event_ts": "2026-01-14T16:29:38.212787", "ingestion_ts": "2026-01-14T16:33:58.842229", "market_id": "0xcab7ba4a9133cfd407d7e73e5757e5abbace413b59421527a31113406c97815c", "raw": {"market": "0xcab7ba4a9133cfd407d7e73e5757e5abbace413b59421527a31113406c97815c", "asset_id": "96361925776989336186111887920533578209326565663637092688733016597062311745569", "price": "0.006", "size": "134.41", "side": "BUY", "timestamp": "1768404578545", "received_at": "2026-01-14T16:29:38.212787"}}
{"event_type": "price_change", "event_ts": "2026-01-14T16:29:38.212787", "ingestion_ts": "2026-01-14T16:33:58.842229", "market_id": "0xcab7ba4a9133cfd407d7e73e5757e5abbace413b59421527a31113406c97815c", "raw": {"market": "0xcab7ba4a9133cfd407d7e73e5757e5abbace413b59421527a31113406c97815c", "asset_id": "20002636398944597965698652220992177552927816915094913583821579024925426590022", "price": "0.994", "size": "134.41", "side": "SELL", "timestamp": "1768404578545", "received_at": "2026-01-14T16:29:38.212787"}}
{"event_type": "price_change", "event_ts": "2026-01-14T16:29:38.699666", "ingestion_ts": "2026-01-14T16:33:58.842229", "market_id": "0xcab7ba4a9133cfd407d7e73e5757e5abbace413b59421527a31113406c97815c", "raw": {"market": "0xcab7ba4a9133cfd407d7e73e5757e5abbace413b59421527a31113406c97815c", "asset_id": "96361925776989336186111887920533578209326565663637092688733016597062311745569", "price": "0.007", "size": "41.8", "side": "BUY", "timestamp": "1768404579037", "received_at": "2026-01-14T16:29:38.699666"}}
{"event_type": "price_change", "event_ts": "2026-01-14T16:29:38.699666", "ingestion_ts": "2026-01-14T16:33:58.842229", "market_id": "0xcab7ba4a9133cfd407d7e73e5757e5abbace413b59421527a31113406c97815c", "raw": {"market": "0xcab7ba4a9133cfd407d7e73e5757e5abbace413b59421527a31113406c97815c", "asset_id": "20002636398944597965698652220992177552927816915094913583821579024925426590022", "price": "0.993", "size": "41.8", "side": "SELL", "timestamp": "1768404579037", "received_at": "2026-01-14T16:29:38.699666"}}
{"event_type": "price_change", "event_ts": "2026-01-14T16:29:38.701174", "ingestion_ts": "2026-01-14T16:33:58.842229", "market_id": "0xcab7ba4a9133cfd407d7e73e5757e5abbace413b59421527a31113406c97815c", "raw": {"market": "0xcab7ba4a9133cfd407d7e73e5757e5abbace413b59421527a31113406c97815c", "asset_id": "20002636398944597965698652220992177552927816915094913583821579024925426590022", "price": "0.044", "size": "6.36", "side": "BUY", "timestamp": "1768404579038", "received_at": "2026-01-14T16:29:38.701174"}}
{"event_type": "price_change", "event_ts": "2026-01-14T16:29:38.701174", "ingestion_ts": "2026-01-14T16:33:58.842229", "market_id": "0xcab7ba4a9133cfd407d7e73e5757e5abbace413b59421527a31113406c97815c", "raw": {"market": "0xcab7ba4a9133cfd407d7e73e5757e5abbace413b59421527a31113406c97815c", "asset_id": "96361925776989336186111887920533578209326565663637092688733016597062311745569", "price": "0.956", "size": "6.36", "side": "SELL", "timestamp": "1768404579038", "received_at": "2026-01-14T16:29:38.701174"}}
{"event_type": "price_change", "event_ts": "2026-01-14T16:29:38.701198", "ingestion_ts": "2026-01-14T16:33:58.842229", "market_id": "0xcab7ba4a9133cfd407d7e73e5757e5abbace413b59421527a31113406c97815c", "raw": {"market": "0xcab7ba4a9133cfd407d7e73e5757e5abbace413b59421527a31113406c97815c", "asset_id": "96361925776989336186111887920533578209326565663637092688733016597062311745569", "price": "0.003", "size": "64.27", "side": "BUY", "timestamp": "1768404579039", "received_at": "2026-01-14T16:29:38.701198"}}
{"event_type": "price_change", "event_ts": "2026-01-14T16:29:38.701198", "ingestion_ts": "2026-01-14T16:33:58.842229", "market_id": "0xcab7ba4a9133cfd407d7e73e5757e5abbace413b59421527a31113406c97815c", "raw": {"market": "0xcab7ba4a9133cfd407d7e73e5757e5abbace413b59421527a31113406c97815c", "asset_id": "20002636398944597965698652220992177552927816915094913583821579024925426590022", "price": "0.997", "size": "64.27", "side": "SELL", "timestamp": "1768404579039", "received_at": "2026-01-14T16:29:38.701198"}}
{"event_type": "price_change", "event_ts": "2026-01-14T16:29:38.702899", "ingestion_ts": "2026-01-14T16:33:58.842229", "market_id": "0xcab7ba4a9133cfd407d7e73e5757e5abbace413b59421527a31113406c97815c", "raw": {"market": "0xcab7ba4a9133cfd407d7e73e5757e5abbace413b59421527a31113406c97815c", "asset_id": "96361925776989336186111887920533578209326565663637092688733016597062311745569", "price": "0.005", "size": "50.2", "side": "BUY", "timestamp": "1768404579040", "received_at": "2026-01-14T16:29:38.702899"}}
{"event_type": "price_change", "event_ts": "2026-01-14T16:29:38.702899", "ingestion_ts": "2026-01-14T16:33:58.842229", "market_id": "0xcab7ba4a9133cfd407d7e73e5757e5abbace413b59421527a31113406c97815c", "raw": {"market": "0xcab7ba4a9133cfd407d7e73e5757e5abbace413b59421527a31113406c97815c", "asset_id": "20002636398944597965698652220992177552927816915094913583821579024925426590022", "price": "0.995", "size": "50.2", "side": "SELL", "timestamp": "1768404579040", "received_at": "2026-01-14T16:29:38.702899"}}
{"event_type": "price_change", "event_ts": "2026-01-14T16:29:38.706091", "ingestion_ts": "2026-01-14T16:33:58.842229", "market_id": "0xcab7ba4a9133cfd407d7e73e5757e5abbace413b59421527a31113406c97815c", "raw": {"market": "0xcab7ba4a9133cfd407d7e73e5757e5abbace413b59421527a31113406c97815c", "asset_id": "20002636398944597965698652220992177552927816915094913583821579024925426590022", "price": "0.001", "size": "503809.38", "side": "BUY", "timestamp": "1768404579041", "received_at": "2026-01-14T16:29:38.706091"}}
{"event_type": "price_change", "event_ts": "2026-01-14T16:29:38.706091", "ingestion_ts": "2026-01-14T16:33:58.842229", "market_id": "0xcab7ba4a9133cfd407d7e73e5757e5abbace413b59421527a31113406c97815c", "raw": {"market": "0xcab7ba4a9133cfd407d7e73e5757e5abbace413b59421527a31113406c97815c", "asset_id": "96361925776989336186111887920533578209326565663637092688733016597062311745569", "price": "0.999", "size": "503809.38", "side": "SELL", "timestamp": "1768404579041", "received_at": "2026-01-14T16:29:38.706091"}}
{"event_type": "price_change", "event_ts": "2026-01-14T16:29:38.928136", "ingestion_ts": "2026-01-14T16:33:58.842229", "market_id": "0x22ac5f75af18fdb453497fbf7ac0606a09a6fd55b78b2d08aace6b946ad62038", "raw": {"market": "0x22ac5f75af18fdb453497fbf7ac0606a09a6fd55b78b2d08aace6b946ad62038", "asset_id": "97449340182256366014320155718265676486703217567849039806162053075113517266910", "price": "0.007", "size": "5.38", "side": "BUY", "timestamp": "1768404579254", "received_at": "2026-01-14T16:29:38.928136"}}
{"event_type": "price_change", "event_ts": "2026-01-14T16:29:38.928136", "ingestion_ts": "2026-01-14T16:33:58.842229", "market_id": "0x22ac5f75af18fdb453497fbf7ac0606a09a6fd55b78b2d08aace6b946ad62038", "raw": {"market": "0x22ac5f75af18fdb453497fbf7ac0606a09a6fd55b78b2d08aace6b946ad62038", "asset_id": "59259495934562596318644973716893809974860301509869285036503555129962149752635", "price": "0.993", "size": "5.38", "side": "SELL", "timestamp": "1768404579254", "received_at": "2026-01-14T16:29:38.928136"}}
{"event_type": "price_change", "event_ts": "2026-01-14T16:29:38.931065", "ingestion_ts": "2026-01-14T16:33:58.842229", "market_id": "0x22ac5f75af18fdb453497fbf7ac0606a09a6fd55b78b2d08aace6b946ad62038", "raw": {"market": "0x22ac5f75af18fdb453497fbf7ac0606a09a6fd55b78b2d08aace6b946ad62038", "asset_id": "97449340182256366014320155718265676486703217567849039806162053075113517266910", "price": "0.012", "size": "20.8", "side": "BUY", "timestamp": "1768404579255", "received_at": "2026-01-14T16:29:38.931065"}}
{"event_type": "price_change", "event_ts": "2026-01-14T16:29:38.931065", "ingestion_ts": "2026-01-14T16:33:58.842229", "market_id": "0x22ac5f75af18fdb453497fbf7ac0606a09a6fd55b78b2d08aace6b946ad62038", "raw": {"market": "0x22ac5f75af18fdb453497fbf7ac0606a09a6fd55b78b2d08aace6b946ad62038", "asset_id": "59259495934562596318644973716893809974860301509869285036503555129962149752635", "price": "0.988", "size": "20.8", "side": "SELL", "timestamp": "1768404579255", "received_at": "2026-01-14T16:29:38.931065"}}
{"event_type": "price_change", "event_ts": "2026-01-14T16:29:38.932501", "ingestion_ts": "2026-01-14T16:33:58.842229", "market_id": "0x22ac5f75af18fdb453497fbf7ac0606a09a6fd55b78b2d08aace6b946ad62038", "raw": {"market": "0x22ac5f75af18fdb453497fbf7ac0606a09a6fd55b78b2d08aace6b946ad62038", "asset_id": "97449340182256366014320155718265676486703217567849039806162053075113517266910", "price": "0.003", "size": "39.17", "side": "BUY", "timestamp": "1768404579256", "received_at": "2026-01-14T16:29:38.932501"}}
{"event_type": "price_change", "event_ts": "2026-01-14T16:29:38.932501", "ingestion_ts": "2026-01-14T16:33:58.842229", "market_id": "0x22ac5f75af18fdb453497fbf7ac0606a09a6fd55b78b2d08aace6b946ad62038", "raw": {"market": "0x22ac5f75af18fdb453497fbf7ac0606a09a6fd55b78b2d08aace6b946ad62038", "asset_id": "59259495934562596318644973716893809974860301509869285036503555129962149752635", "price": "0.997", "size": "39.17", "side": "SELL", "timestamp": "1768404579256", "received_at": "2026-01-14T16:29:38.932501"}}
{"event_type": "price_change", "event_ts": "2026-01-14T16:29:38.934073", "ingestion_ts": "2026-01-14T16:33:58.842229", "market_id": "0x22ac5f75af18fdb453497fbf7ac0606a09a6fd55b78b2d08aace6b946ad62038", "raw": {"market": "0x22ac5f75af18fdb453497fbf7ac0606a09a6fd55b78b2d08aace6b946ad62038", "asset_id": "97449340182256366014320155718265676486703217567849039806162053075113517266910", "price": "0.009", "size": "8.59", "side": "BUY", "timestamp": "1768404579256", "received_at": "2026-01-14T16:29:38.934073"}}
{"event_type": "price_change", "event_ts": "2026-01-14T16:29:38.934073", "ingestion_ts": "2026-01-14T16:33:58.842229", "market_id": "0x22ac5f75af18fdb453497fbf7ac0606a09a6fd55b78b2d08aace6b946ad62038", "raw": {"market": "0x22ac5f75af18fdb453497fbf7ac0606a09a6fd55b78b2d08aace6b946ad62038", "asset_id": "59259495934562596318644973716893809974860301509869285036503555129962149752635", "price": "0.991", "size": "8.59", "side": "SELL", "timestamp": "1768404579256", "received_at": "2026-01-14T16:29:38.934073"}}
{"event_type": "price_change", "event_ts": "2026-01-14T16:29:38.935772", "ingestion_ts": "2026-01-14T16:33:58.842229", "market_id": "0x22ac5f75af18fdb453497fbf7ac0606a09a6fd55b78b2d08aace6b946ad62038", "raw": {"market": "0x22ac5f75af18fdb453497fbf7ac0606a09a6fd55b78b2d08aace6b946ad62038", "asset_id": "97449340182256366014320155718265676486703217567849039806162053075113517266910", "price": "0.002", "size": "77.82", "side": "BUY", "timestamp": "1768404579257", "received_at": "2026-01-14T16:29:38.935772"}}
{"event_type": "price_change", "event_ts": "2026-01-14T16:29:38.935772", "ingestion_ts": "2026-01-14T16:33:58.842229", "market_id": "0x22ac5f75af18fdb453497fbf7ac0606a09a6fd55b78b2d08aace6b946ad62038", "raw": {"market": "0x22ac5f75af18fdb453497fbf7ac0606a09a6fd55b78b2d08aace6b946ad62038", "asset_id": "59259495934562596318644973716893809974860301509869285036503555129962149752635", "price": "0.998", "size": "77.82", "side": "SELL", "timestamp": "1768404579257", "received_at": "2026-01-14T16:29:38.935772"}}
{"event_type": "price_change", "event_ts": "2026-01-14T16:29:39.943181", "ingestion_ts": "2026-01-14T16:33:58.842229", "market_id": "0x5533fb9ab797777a243c75b1bf3882c54b1ee91f794730c090bf701598993529", "raw": {"market": "0x5533fb9ab797777a243c75b1bf3882c54b1ee91f794730c090bf701598993529", "asset_id": "99478074208094578615268494931219682040135218828258512927013036335093067688695", "price": "0.051", "size": "13.02", "side": "BUY", "timestamp": "1768404580277", "received_at": "2026-01-14T16:29:39.943181"}}
{"event_type": "price_change", "event_ts": "2026-01-14T16:29:39.943181", "ingestion_ts": "2026-01-14T16:33:58.842229", "market_id": "0x5533fb9ab797777a243c75b1bf3882c54b1ee91f794730c090bf701598993529", "raw": {"market": "0x5533fb9ab797777a243c75b1bf3882c54b1ee91f794730c090bf701598993529", "asset_id": "22532055631814907447535815649879981046415248231878961745474659705989546420934", "price": "0.949", "size": "13.02", "side": "SELL", "timestamp": "1768404580277", "received_at": "2026-01-14T16:29:39.943181"}}
{"event_type": "price_change", "event_ts": "2026-01-14T16:29:39.943216", "ingestion_ts": "2026-01-14T16:33:58.842229", "market_id": "0x5533fb9ab797777a243c75b1bf3882c54b1ee91f794730c090bf701598993529", "raw": {"market": "0x5533fb9ab797777a243c75b1bf3882c54b1ee91f794730c090bf701598993529", "asset_id": "99478074208094578615268494931219682040135218828258512927013036335093067688695", "price": "0.011", "size": "5.42", "side": "BUY", "timestamp": "1768404580278", "received_at": "2026-01-14T16:29:39.943216"}}
{"event_type": "price_change", "event_ts": "2026-01-14T16:29:39.943216", "ingestion_ts": "2026-01-14T16:33:58.842229", "market_id": "0x5533fb9ab797777a243c75b1bf3882c54b1ee91f794730c090bf701598993529", "raw": {"market": "0x5533fb9ab797777a243c75b1bf3882c54b1ee91f794730c090bf701598993529", "asset_id": "22532055631814907447535815649879981046415248231878961745474659705989546420934", "price": "0.989", "size": "5.42", "side": "SELL", "timestamp": "1768404580278", "received_at": "2026-01-14T16:29:39.943216"}}
{"event_type": "price_change", "event_ts": "2026-01-14T16:29:39.943231", "ingestion_ts": "2026-01-14T16:33:58.842229", "market_id": "0x5533fb9ab797777a243c75b1bf3882c54b1ee91f794730c090bf701598993529", "raw": {"market": "0x5533fb9ab797777a243c75b1bf3882c54b1ee91f794730c090bf701598993529", "asset_id": "99478074208094578615268494931219682040135218828258512927013036335093067688695", "price": "0.001", "size": "453698.37", "side": "BUY", "timestamp": "1768404580278", "received_at": "2026-01-14T16:29:39.943231"}}
{"event_type": "price_change", "event_ts": "2026-01-14T16:29:39.943231", "ingestion_ts": "2026-01-14T16:33:58.842229", "market_id": "0x5533fb9ab797777a243c75b1bf3882c54b1ee91f794730c090bf701598993529", "raw": {"market": "0x5533fb9ab797777a243c75b1bf3882c54b1ee91f794730c090bf701598993529", "asset_id": "22532055631814907447535815649879981046415248231878961745474659705989546420934", "price": "0.999", "size": "453698.37", "side": "SELL", "timestamp": "1768404580278", "received_at": "2026-01-14T16:29:39.943231"}}
{"event_type": "price_change", "event_ts": "2026-01-14T16:29:39.943251", "ingestion_ts": "2026-01-14T16:33:58.842229", "market_id": "0x5533fb9ab797777a243c75b1bf3882c54b1ee91f794730c090bf701598993529", "raw": {"market": "0x5533fb9ab797777a243c75b1bf3882c54b1ee91f794730c090bf701598993529", "asset_id": "99478074208094578615268494931219682040135218828258512927013036335093067688695", "price": "0.004", "size": "10.68", "side": "BUY", "timestamp": "1768404580279", "received_at": "2026-01-14T16:29:39.943251"}}
{"event_type": "price_change", "event_ts": "2026-01-14T16:29:39.943251", "ingestion_ts": "2026-01-14T16:33:58.842229", "market_id": "0x5533fb9ab797777a243c75b1bf3882c54b1ee91f794730c090bf701598993529", "raw": {"market": "0x5533fb9ab797777a243c75b1bf3882c54b1ee91f794730c090bf701598993529", "asset_id": "22532055631814907447535815649879981046415248231878961745474659705989546420934", "price": "0.996", "size": "10.68", "side": "SELL", "timestamp": "1768404580279", "received_at": "2026-01-14T16:29:39.943251"}}
{"event_type": "price_change", "event_ts": "2026-01-14T16:29:39.943261", "ingestion_ts": "2026-01-14T16:33:58.842229", "market_id": "0x5533fb9ab797777a243c75b1bf3882c54b1ee91f794730c090bf701598993529", "raw": {"market": "0x5533fb9ab797777a243c75b1bf3882c54b1ee91f794730c090bf701598993529", "asset_id": "99478074208094578615268494931219682040135218828258512927013036335093067688695", "price": "0.021", "size": "8.06", "side": "BUY", "timestamp": "1768404580280", "received_at": "2026-01-14T16:29:39.943261"}}
{"event_type": "price_change", "event_ts": "2026-01-14T16:29:39.943261", "ingestion_ts": "2026-01-14T16:33:58.842229", "market_id": "0x5533fb9ab797777a243c75b1bf3882c54b1ee91f794730c090bf701598993529", "raw": {"market": "0x5533fb9ab797777a243c75b1bf3882c54b1ee91f794730c090bf701598993529", "asset_id": "22532055631814907447535815649879981046415248231878961745474659705989546420934", "price": "0.979", "size": "8.06", "side": "SELL", "timestamp": "1768404580280", "received_at": "2026-01-14T16:29:39.943261"}}
{"event_type": "price_change", "event_ts": "2026-01-14T16:29:39.943271", "ingestion_ts": "2026-01-14T16:33:58.842229", "market_id": "0x5533fb9ab797777a243c75b1bf3882c54b1ee91f794730c090bf701598993529", "raw": {"market": "0x5533fb9ab797777a243c75b1bf3882c54b1ee91f794730c090bf701598993529", "asset_id": "99478074208094578615268494931219682040135218828258512927013036335093067688695", "price": "0.201", "size": "5.2", "side": "BUY", "timestamp": "1768404580281", "received_at": "2026-01-14T16:29:39.943271"}}
{"event_type": "price_change", "event_ts": "2026-01-14T16:29:39.943271", "ingestion_ts": "2026-01-14T16:33:58.842229", "market_id": "0x5533fb9ab797777a243c75b1bf3882c54b1ee91f794730c090bf701598993529", "raw": {"market": "0x5533fb9ab797777a243c75b1bf3882c54b1ee91f794730c090bf701598993529", "asset_id": "22532055631814907447535815649879981046415248231878961745474659705989546420934", "price": "0.799", "size": "5.2", "side": "SELL", "timestamp": "1768404580281", "received_at": "2026-01-14T16:29:39.943271"}}
{"event_type": "price_change", "event_ts": "2026-01-14T16:29:39.943280", "ingestion_ts": "2026-01-14T16:33:58.842229", "market_id": "0x5533fb9ab797777a243c75b1bf3882c54b1ee91f794730c090bf701598993529", "raw": {"market": "0x5533fb9ab797777a243c75b1bf3882c54b1ee91f794730c090bf701598993529", "asset_id": "99478074208094578615268494931219682040135218828258512927013036335093067688695", "price": "0.002", "size": "256.18", "side": "BUY", "timestamp": "1768404580282", "received_at": "2026-01-14T16:29:39.943280"}}
{"event_type": "price_change", "event_ts": "2026-01-14T16:29:39.943280", "ingestion_ts": "2026-01-14T16:33:58.842229", "market_id": "0x5533fb9ab797777a243c75b1bf3882c54b1ee91f794730c090bf701598993529", "raw": {"market": "0x5533fb9ab797777a243c75b1bf3882c54b1ee91f794730c090bf701598993529", "asset_id": "22532055631814907447535815649879981046415248231878961745474659705989546420934", "price": "0.998", "size": "256.18", "side": "SELL", "timestamp": "1768404580282", "received_at": "2026-01-14T16:29:39.943280"}}
{"event_type": "price_change", "event_ts": "2026-01-14T16:29:40.759026", "ingestion_ts": "2026-01-14T16:33:58.842229", "market_id": "0x50e477f0b316a3d97d60486479657c63be0763834d0e2e8a30b1b86dc3c1c001", "raw": {"market": "0x50e477f0b316a3d97d60486479657c63be0763834d0e2e8a30b1b86dc3c1c001", "asset_id": "60573178197991590327120832143415406583517170365625050489007297367895074266641", "price": "0.011", "size": "111", "side": "SELL", "timestamp": "1768404581091", "received_at": "2026-01-14T16:29:40.759026"}}
{"event_type": "price_change", "event_ts": "2026-01-14T16:29:40.759026", "ingestion_ts": "2026-01-14T16:33:58.842229", "market_id": "0x50e477f0b316a3d97d60486479657c63be0763834d0e2e8a30b1b86dc3c1c001", "raw": {"market": "0x50e477f0b316a3d97d60486479657c63be0763834d0e2e8a30b1b86dc3c1c001", "asset_id": "39981134260608444876865205057565852475343967395624370698967311821208058420507", "price": "0.989", "size": "111", "side": "BUY", "timestamp": "1768404581091", "received_at": "2026-01-14T16:29:40.759026"}}
{"event_type": "price_change", "event_ts": "2026-01-14T16:29:40.759067", "ingestion_ts": "2026-01-14T16:33:58.842229", "market_id": "0x50e477f0b316a3d97d60486479657c63be0763834d0e2e8a30b1b86dc3c1c001", "raw": {"market": "0x50e477f0b316a3d97d60486479657c63be0763834d0e2e8a30b1b86dc3c1c001", "asset_id": "60573178197991590327120832143415406583517170365625050489007297367895074266641", "price": "0.013", "size": "0", "side": "SELL", "timestamp": "1768404581091", "received_at": "2026-01-14T16:29:40.759067"}}
{"event_type": "price_change", "event_ts": "2026-01-14T16:29:40.759067", "ingestion_ts": "2026-01-14T16:33:58.842229", "market_id": "0x50e477f0b316a3d97d60486479657c63be0763834d0e2e8a30b1b86dc3c1c001", "raw": {"market": "0x50e477f0b316a3d97d60486479657c63be0763834d0e2e8a30b1b86dc3c1c001", "asset_id": "39981134260608444876865205057565852475343967395624370698967311821208058420507", "price": "0.987", "size": "0", "side": "BUY", "timestamp": "1768404581091", "received_at": "2026-01-14T16:29:40.759067"}}
{"event_type": "price_change", "event_ts": "2026-01-14T16:29:41.505250", "ingestion_ts": "2026-01-14T16:33:58.842229", "market_id": "0x50e477f0b316a3d97d60486479657c63be0763834d0e2e8a30b1b86dc3c1c001", "raw": {"market": "0x50e477f0b316a3d97d60486479657c63be0763834d0e2e8a30b1b86dc3c1c001", "asset_id": "39981134260608444876865205057565852475343967395624370698967311821208058420507", "price": "0.989", "size": "81", "side": "BUY", "timestamp": "1768404581839", "received_at": "2026-01-14T16:29:41.505250"}}
{"event_type": "price_change", "event_ts": "2026-01-14T16:29:41.505250", "ingestion_ts": "2026-01-14T16:33:58.842229", "market_id": "0x50e477f0b316a3d97d60486479657c63be0763834d0e2e8a30b1b86dc3c1c001", "raw": {"market": "0x50e477f0b316a3d97d60486479657c63be0763834d0e2e8a30b1b86dc3c1c001", "asset_id": "60573178197991590327120832143415406583517170365625050489007297367895074266641", "price": "0.011", "size": "81", "side": "SELL", "timestamp": "1768404581839", "received_at": "2026-01-14T16:29:41.505250"}}
{"event_type": "price_change", "event_ts": "2026-01-14T16:29:41.528620", "ingestion_ts": "2026-01-14T16:33:58.842229", "market_id": "0x50e477f0b316a3d97d60486479657c63be0763834d0e2e8a30b1b86dc3c1c001", "raw": {"market": "0x50e477f0b316a3d97d60486479657c63be0763834d0e2e8a30b1b86dc3c1c001", "asset_id": "39981134260608444876865205057565852475343967395624370698967311821208058420507", "price": "0.989", "size": "0", "side": "BUY", "timestamp": "1768404581866", "received_at": "2026-01-14T16:29:41.528620"}}
{"event_type": "price_change", "event_ts": "2026-01-14T16:29:41.528620", "ingestion_ts": "2026-01-14T16:33:58.842229", "market_id": "0x50e477f0b316a3d97d60486479657c63be0763834d0e2e8a30b1b86dc3c1c001", "raw": {"market": "0x50e477f0b316a3d97d60486479657c63be0763834d0e2e8a30b1b86dc3c1c001", "asset_id": "60573178197991590327120832143415406583517170365625050489007297367895074266641", "price": "0.011", "size": "0", "side": "SELL", "timestamp": "1768404581866", "received_at": "2026-01-14T16:29:41.528620"}}
{"event_type": "price_change", "event_ts": "2026-01-14T16:29:41.556723", "ingestion_ts": "2026-01-14T16:33:58.842229", "market_id": "0x50e477f0b316a3d97d60486479657c63be0763834d0e2e8a30b1b86dc3c1c001", "raw": {"market": "0x50e477f0b316a3d97d60486479657c63be0763834d0e2e8a30b1b86dc3c1c001", "asset_id": "39981134260608444876865205057565852475343967395624370698967311821208058420507", "price": "0.987", "size": "84", "side": "BUY", "timestamp": "1768404581895", "received_at": "2026-01-14T16:29:41.556723"}}
{"event_type": "price_change", "event_ts": "2026-01-14T16:29:41.556723", "ingestion_ts": "2026-01-14T16:33:58.842229", "market_id": "0x50e477f0b316a3d97d60486479657c63be0763834d0e2e8a30b1b86dc3c1c001", "raw": {"market": "0x50e477f0b316a3d97d60486479657c63be0763834d0e2e8a30b1b86dc3c1c001", "asset_id": "60573178197991590327120832143415406583517170365625050489007297367895074266641", "price": "0.013", "size": "84", "side": "SELL", "timestamp": "1768404581895", "received_at": "2026-01-14T16:29:41.556723"}}
{"event_type": "price_change", "event_ts": "2026-01-14T16:29:42.913396", "ingestion_ts": "2026-01-14T16:33:58.842229", "market_id": "0x50e477f0b316a3d97d60486479657c63be0763834d0e2e8a30b1b86dc3c1c001", "raw": {"market": "0x50e477f0b316a3d97d60486479657c63be0763834d0e2e8a30b1b86dc3c1c001", "asset_id": "39981134260608444876865205057565852475343967395624370698967311821208058420507", "price": "0.988", "size": "50", "side": "BUY", "timestamp": "1768404583251", "received_at": "2026-01-14T16:29:42.913396"}}
{"event_type": "price_change", "event_ts": "2026-01-14T16:29:42.913396", "ingestion_ts": "2026-01-14T16:33:58.842229", "market_id": "0x50e477f0b316a3d97d60486479657c63be0763834d0e2e8a30b1b86dc3c1c001", "raw": {"market": "0x50e477f0b316a3d97d60486479657c63be0763834d0e2e8a30b1b86dc3c1c001", "asset_id": "60573178197991590327120832143415406583517170365625050489007297367895074266641", "price": "0.012", "size": "50", "side": "SELL", "timestamp": "1768404583251", "received_at": "2026-01-14T16:29:42.913396"}}
{"event_type": "price_change", "event_ts": "2026-01-14T16:29:42.939558", "ingestion_ts": "2026-01-14T16:33:58.842229", "market_id": "0x50e477f0b316a3d97d60486479657c63be0763834d0e2e8a30b1b86dc3c1c001", "raw": {"market": "0x50e477f0b316a3d97d60486479657c63be0763834d0e2e8a30b1b86dc3c1c001", "asset_id": "39981134260608444876865205057565852475343967395624370698967311821208058420507", "price": "0.987", "size": "0", "side": "BUY", "timestamp": "1768404583278", "received_at": "2026-01-14T16:29:42.939558"}}
{"event_type": "price_change", "event_ts": "2026-01-14T16:29:42.939558", "ingestion_ts": "2026-01-14T16:33:58.842229", "market_id": "0x50e477f0b316a3d97d60486479657c63be0763834d0e2e8a30b1b86dc3c1c001", "raw": {"market": "0x50e477f0b316a3d97d60486479657c63be0763834d0e2e8a30b1b86dc3c1c001", "asset_id": "60573178197991590327120832143415406583517170365625050489007297367895074266641", "price": "0.013", "size": "0", "side": "SELL", "timestamp": "1768404583278", "received_at": "2026-01-14T16:29:42.939558"}}
{"event_type": "price_change", "event_ts": "2026-01-14T16:29:42.969936", "ingestion_ts": "2026-01-14T16:33:58.842229", "market_id": "0x50e477f0b316a3d97d60486479657c63be0763834d0e2e8a30b1b86dc3c1c001", "raw": {"market": "0x50e477f0b316a3d97d60486479657c63be0763834d0e2e8a30b1b86dc3c1c001", "asset_id": "39981134260608444876865205057565852475343967395624370698967311821208058420507", "price": "0.988", "size": "131", "side": "BUY", "timestamp": "1768404583307", "received_at": "2026-01-14T16:29:42.969936"}}
{"event_type": "price_change", "event_ts": "2026-01-14T16:29:42.969936", "ingestion_ts": "2026-01-14T16:33:58.842229", "market_id": "0x50e477f0b316a3d97d60486479657c63be0763834d0e2e8a30b1b86dc3c1c001", "raw": {"market": "0x50e477f0b316a3d97d60486479657c63be0763834d0e2e8a30b1b86dc3c1c001", "asset_id": "60573178197991590327120832143415406583517170365625050489007297367895074266641", "price": "0.012", "size": "131", "side": "SELL", "timestamp": "1768404583307", "received_at": "2026-01-14T16:29:42.969936"}}
{"event_type": "price_change", "event_ts": "2026-01-14T16:29:44.522074", "ingestion_ts": "2026-01-14T16:33:58.842229", "market_id": "0x50e477f0b316a3d97d60486479657c63be0763834d0e2e8a30b1b86dc3c1c001", "raw": {"market": "0x50e477f0b316a3d97d60486479657c63be0763834d0e2e8a30b1b86dc3c1c001", "asset_id": "60573178197991590327120832143415406583517170365625050489007297367895074266641", "price": "0.01", "size": "138.86", "side": "SELL", "timestamp": "1768404584858", "received_at": "2026-01-14T16:29:44.522074"}}
{"event_type": "price_change", "event_ts": "2026-01-14T16:29:44.522074", "ingestion_ts": "2026-01-14T16:33:58.842229", "market_id": "0x50e477f0b316a3d97d60486479657c63be0763834d0e2e8a30b1b86dc3c1c001", "raw": {"market": "0x50e477f0b316a3d97d60486479657c63be0763834d0e2e8a30b1b86dc3c1c001", "asset_id": "39981134260608444876865205057565852475343967395624370698967311821208058420507", "price": "0.99", "size": "138.86", "side": "BUY", "timestamp": "1768404584858", "received_at": "2026-01-14T16:29:44.522074"}}
{"event_type": "price_change", "event_ts": "2026-01-14T16:29:44.559116", "ingestion_ts": "2026-01-14T16:33:58.842229", "market_id": "0x50e477f0b316a3d97d60486479657c63be0763834d0e2e8a30b1b86dc3c1c001", "raw": {"market": "0x50e477f0b316a3d97d60486479657c63be0763834d0e2e8a30b1b86dc3c1c001", "asset_id": "39981134260608444876865205057565852475343967395624370698967311821208058420507", "price": "0.988", "size": "50", "side": "BUY", "timestamp": "1768404584895", "received_at": "2026-01-14T16:29:44.559116"}}
{"event_type": "price_change", "event_ts": "2026-01-14T16:29:44.559116", "ingestion_ts": "2026-01-14T16:33:58.842229", "market_id": "0x50e477f0b316a3d97d60486479657c63be0763834d0e2e8a30b1b86dc3c1c001", "raw": {"market": "0x50e477f0b316a3d97d60486479657c63be0763834d0e2e8a30b1b86dc3c1c001", "asset_id": "60573178197991590327120832143415406583517170365625050489007297367895074266641", "price": "0.012", "size": "50", "side": "SELL", "timestamp": "1768404584895", "received_at": "2026-01-14T16:29:44.559116"}}
{"event_type": "price_change", "event_ts": "2026-01-14T16:29:44.584564", "ingestion_ts": "2026-01-14T16:33:58.842229", "market_id": "0x50e477f0b316a3d97d60486479657c63be0763834d0e2e8a30b1b86dc3c1c001", "raw": {"market": "0x50e477f0b316a3d97d60486479657c63be0763834d0e2e8a30b1b86dc3c1c001", "asset_id": "39981134260608444876865205057565852475343967395624370698967311821208058420507", "price": "0.991", "size": "83", "side": "BUY", "timestamp": "1768404584922", "received_at": "2026-01-14T16:29:44.584564"}}
{"event_type": "price_change", "event_ts": "2026-01-14T16:29:44.584564", "ingestion_ts": "2026-01-14T16:33:58.842229", "market_id": "0x50e477f0b316a3d97d60486479657c63be0763834d0e2e8a30b1b86dc3c1c001", "raw": {"market": "0x50e477f0b316a3d97d60486479657c63be0763834d0e2e8a30b1b86dc3c1c001", "asset_id": "60573178197991590327120832143415406583517170365625050489007297367895074266641", "price": "0.009", "size": "83", "side": "SELL", "timestamp": "1768404584922", "received_at": "2026-01-14T16:29:44.584564"}}
{"event_type": "price_change", "event_ts": "2026-01-14T16:29:44.829410", "ingestion_ts": "2026-01-14T16:33:58.842229", "market_id": "0x50e477f0b316a3d97d60486479657c63be0763834d0e2e8a30b1b86dc3c1c001", "raw": {"market": "0x50e477f0b316a3d97d60486479657c63be0763834d0e2e8a30b1b86dc3c1c001", "asset_id": "39981134260608444876865205057565852475343967395624370698967311821208058420507", "price": "0.991", "size": "113", "side": "BUY", "timestamp": "1768404585157", "received_at": "2026-01-14T16:29:44.829410"}}
{"event_type": "price_change", "event_ts": "2026-01-14T16:29:44.829410", "ingestion_ts": "2026-01-14T16:33:58.842229", "market_id": "0x50e477f0b316a3d97d60486479657c63be0763834d0e2e8a30b1b86dc3c1c001", "raw": {"market": "0x50e477f0b316a3d97d60486479657c63be0763834d0e2e8a30b1b86dc3c1c001", "asset_id": "60573178197991590327120832143415406583517170365625050489007297367895074266641", "price": "0.009", "size": "113", "side": "SELL", "timestamp": "1768404585157", "received_at": "2026-01-14T16:29:44.829410"}}
{"event_type": "price_change", "event_ts": "2026-01-14T16:29:46.042562", "ingestion_ts": "2026-01-14T16:33:58.842229", "market_id": "0x50e477f0b316a3d97d60486479657c63be0763834d0e2e8a30b1b86dc3c1c001", "raw": {"market": "0x50e477f0b316a3d97d60486479657c63be0763834d0e2e8a30b1b86dc3c1c001", "asset_id": "39981134260608444876865205057565852475343967395624370698967311821208058420507", "price": "0.991", "size": "30", "side": "BUY", "timestamp": "1768404586381", "received_at": "2026-01-14T16:29:46.042562"}}
{"event_type": "price_change", "event_ts": "2026-01-14T16:29:46.042562", "ingestion_ts": "2026-01-14T16:33:58.842229", "market_id": "0x50e477f0b316a3d97d60486479657c63be0763834d0e2e8a30b1b86dc3c1c001", "raw": {"market": "0x50e477f0b316a3d97d60486479657c63be0763834d0e2e8a30b1b86dc3c1c001", "asset_id": "60573178197991590327120832143415406583517170365625050489007297367895074266641", "price": "0.009", "size": "30", "side": "SELL", "timestamp": "1768404586381", "received_at": "2026-01-14T16:29:46.042562"}}
{"event_type": "price_change", "event_ts": "2026-01-14T16:29:47.543882", "ingestion_ts": "2026-01-14T16:33:58.842229", "market_id": "0x2393ed0b0fdc450054c7b9071907eca75cf4fc36e385adf4a0a5f99ee62243e8", "raw": {"market": "0x2393ed0b0fdc450054c7b9071907eca75cf4fc36e385adf4a0a5f99ee62243e8", "asset_id": "32769749367306925959219403371425714180265458150646381231272229429098460625924", "price": "0.199", "size": "0", "side": "BUY", "timestamp": "1768404587881", "received_at": "2026-01-14T16:29:47.543882"}}
{"event_type": "price_change", "event_ts": "2026-01-14T16:29:47.543882", "ingestion_ts": "2026-01-14T16:33:58.842229", "market_id": "0x2393ed0b0fdc450054c7b9071907eca75cf4fc36e385adf4a0a5f99ee62243e8", "raw": {"market": "0x2393ed0b0fdc450054c7b9071907eca75cf4fc36e385adf4a0a5f99ee62243e8", "asset_id": "100074770378634056601572485653252702850363676459996771990439989989293515601975", "price": "0.801", "size": "0", "side": "SELL", "timestamp": "1768404587881", "received_at": "2026-01-14T16:29:47.543882"}}
{"event_type": "price_change", "event_ts": "2026-01-14T16:29:48.922593", "ingestion_ts": "2026-01-14T16:33:58.842229", "market_id": "0x2393ed0b0fdc450054c7b9071907eca75cf4fc36e385adf4a0a5f99ee62243e8", "raw": {"market": "0x2393ed0b0fdc450054c7b9071907eca75cf4fc36e385adf4a0a5f99ee62243e8", "asset_id": "32769749367306925959219403371425714180265458150646381231272229429098460625924", "price": "0.001", "size": "3369.58", "side": "BUY", "timestamp": "1768404589258", "received_at": "2026-01-14T16:29:48.922593"}}
{"event_type": "price_change", "event_ts": "2026-01-14T16:29:48.922593", "ingestion_ts": "2026-01-14T16:33:58.842229", "market_id": "0x2393ed0b0fdc450054c7b9071907eca75cf4fc36e385adf4a0a5f99ee62243e8", "raw": {"market": "0x2393ed0b0fdc450054c7b9071907eca75cf4fc36e385adf4a0a5f99ee62243e8", "asset_id": "100074770378634056601572485653252702850363676459996771990439989989293515601975", "price": "0.999", "size": "3369.58", "side": "SELL", "timestamp": "1768404589258", "received_at": "2026-01-14T16:29:48.922593"}}
{"event_type": "price_change", "event_ts": "2026-01-14T16:29:48.922634", "ingestion_ts": "2026-01-14T16:33:58.842229", "market_id": "0x2393ed0b0fdc450054c7b9071907eca75cf4fc36e385adf4a0a5f99ee62243e8", "raw": {"market": "0x2393ed0b0fdc450054c7b9071907eca75cf4fc36e385adf4a0a5f99ee62243e8", "asset_id": "32769749367306925959219403371425714180265458150646381231272229429098460625924", "price": "0.004", "size": "9.09", "side": "BUY", "timestamp": "1768404589259", "received_at": "2026-01-14T16:29:48.922634"}}
{"event_type": "price_change", "event_ts": "2026-01-14T16:29:48.922634", "ingestion_ts": "2026-01-14T16:33:58.842229", "market_id": "0x2393ed0b0fdc450054c7b9071907eca75cf4fc36e385adf4a0a5f99ee62243e8", "raw": {"market": "0x2393ed0b0fdc450054c7b9071907eca75cf4fc36e385adf4a0a5f99ee62243e8", "asset_id": "100074770378634056601572485653252702850363676459996771990439989989293515601975", "price": "0.996", "size": "9.09", "side": "SELL", "timestamp": "1768404589259", "received_at": "2026-01-14T16:29:48.922634"}}
{"event_type": "price_change", "event_ts": "2026-01-14T16:29:48.922652", "ingestion_ts": "2026-01-14T16:33:58.842229", "market_id": "0x2393ed0b0fdc450054c7b9071907eca75cf4fc36e385adf4a0a5f99ee62243e8", "raw": {"market": "0x2393ed0b0fdc450054c7b9071907eca75cf4fc36e385adf4a0a5f99ee62243e8", "asset_id": "32769749367306925959219403371425714180265458150646381231272229429098460625924", "price": "0.192", "size": "6.12", "side": "BUY", "timestamp": "1768404589260", "received_at": "2026-01-14T16:29:48.922652"}}
{"event_type": "price_change", "event_ts": "2026-01-14T16:29:48.922652", "ingestion_ts": "2026-01-14T16:33:58.842229", "market_id": "0x2393ed0b0fdc450054c7b9071907eca75cf4fc36e385adf4a0a5f99ee62243e8", "raw": {"market": "0x2393ed0b0fdc450054c7b9071907eca75cf4fc36e385adf4a0a5f99ee62243e8", "asset_id": "100074770378634056601572485653252702850363676459996771990439989989293515601975", "price": "0.808", "size": "6.12", "side": "SELL", "timestamp": "1768404589260", "received_at": "2026-01-14T16:29:48.922652"}}
{"event_type": "price_change", "event_ts": "2026-01-14T16:29:48.922667", "ingestion_ts": "2026-01-14T16:33:58.842229", "market_id": "0x2393ed0b0fdc450054c7b9071907eca75cf4fc36e385adf4a0a5f99ee62243e8", "raw": {"market": "0x2393ed0b0fdc450054c7b9071907eca75cf4fc36e385adf4a0a5f99ee62243e8", "asset_id": "32769749367306925959219403371425714180265458150646381231272229429098460625924", "price": "0.002", "size": "255.25", "side": "BUY", "timestamp": "1768404589260", "received_at": "2026-01-14T16:29:48.922667"}}
{"event_type": "price_change", "event_ts": "2026-01-14T16:29:48.922667", "ingestion_ts": "2026-01-14T16:33:58.842229", "market_id": "0x2393ed0b0fdc450054c7b9071907eca75cf4fc36e385adf4a0a5f99ee62243e8", "raw": {"market": "0x2393ed0b0fdc450054c7b9071907eca75cf4fc36e385adf4a0a5f99ee62243e8", "asset_id": "100074770378634056601572485653252702850363676459996771990439989989293515601975", "price": "0.998", "size": "255.25", "side": "SELL", "timestamp": "1768404589260", "received_at": "2026-01-14T16:29:48.922667"}}
{"event_type": "price_change", "event_ts": "2026-01-14T16:29:48.925090", "ingestion_ts": "2026-01-14T16:33:58.842229", "market_id": "0x2393ed0b0fdc450054c7b9071907eca75cf4fc36e385adf4a0a5f99ee62243e8", "raw": {"market": "0x2393ed0b0fdc450054c7b9071907eca75cf4fc36e385adf4a0a5f99ee62243e8", "asset_id": "32769749367306925959219403371425714180265458150646381231272229429098460625924", "price": "0.057", "size": "9.58", "side": "BUY", "timestamp": "1768404589261", "received_at": "2026-01-14T16:29:48.925090"}}
{"event_type": "price_change", "event_ts": "2026-01-14T16:29:48.925090", "ingestion_ts": "2026-01-14T16:33:58.842229", "market_id": "0x2393ed0b0fdc450054c7b9071907eca75cf4fc36e385adf4a0a5f99ee62243e8", "raw": {"market": "0x2393ed0b0fdc450054c7b9071907eca75cf4fc36e385adf4a0a5f99ee62243e8", "asset_id": "100074770378634056601572485653252702850363676459996771990439989989293515601975", "price": "0.943", "size": "9.58", "side": "SELL", "timestamp": "1768404589261", "received_at": "2026-01-14T16:29:48.925090"}}
{"event_type": "price_change", "event_ts": "2026-01-14T16:29:48.925123", "ingestion_ts": "2026-01-14T16:33:58.842229", "market_id": "0x2393ed0b0fdc450054c7b9071907eca75cf4fc36e385adf4a0a5f99ee62243e8", "raw": {"market": "0x2393ed0b0fdc450054c7b9071907eca75cf4fc36e385adf4a0a5f99ee62243e8", "asset_id": "32769749367306925959219403371425714180265458150646381231272229429098460625924", "price": "0.011", "size": "5.09", "side": "BUY", "timestamp": "1768404589262", "received_at": "2026-01-14T16:29:48.925123"}}
{"event_type": "price_change", "event_ts": "2026-01-14T16:29:48.925123", "ingestion_ts": "2026-01-14T16:33:58.842229", "market_id": "0x2393ed0b0fdc450054c7b9071907eca75cf4fc36e385adf4a0a5f99ee62243e8", "raw": {"market": "0x2393ed0b0fdc450054c7b9071907eca75cf4fc36e385adf4a0a5f99ee62243e8", "asset_id": "100074770378634056601572485653252702850363676459996771990439989989293515601975", "price": "0.989", "size": "5.09", "side": "SELL", "timestamp": "1768404589262", "received_at": "2026-01-14T16:29:48.925123"}}
{"event_type": "price_change", "event_ts": "2026-01-14T16:29:48.925141", "ingestion_ts": "2026-01-14T16:33:58.842229", "market_id": "0x2393ed0b0fdc450054c7b9071907eca75cf4fc36e385adf4a0a5f99ee62243e8", "raw": {"market": "0x2393ed0b0fdc450054c7b9071907eca75cf4fc36e385adf4a0a5f99ee62243e8", "asset_id": "32769749367306925959219403371425714180265458150646381231272229429098460625924", "price": "0.022", "size": "7.71", "side": "BUY", "timestamp": "1768404589263", "received_at": "2026-01-14T16:29:48.925141"}}
{"event_type": "price_change", "event_ts": "2026-01-14T16:29:48.925141", "ingestion_ts": "2026-01-14T16:33:58.842229", "market_id": "0x2393ed0b0fdc450054c7b9071907eca75cf4fc36e385adf4a0a5f99ee62243e8", "raw": {"market": "0x2393ed0b0fdc450054c7b9071907eca75cf4fc36e385adf4a0a5f99ee62243e8", "asset_id": "100074770378634056601572485653252702850363676459996771990439989989293515601975", "price": "0.978", "size": "7.71", "side": "SELL", "timestamp": "1768404589263", "received_at": "2026-01-14T16:29:48.925141"}}
{"event_type": "price_change", "event_ts": "2026-01-14T16:29:49.205266", "ingestion_ts": "2026-01-14T16:33:58.842229", "market_id": "0x50e477f0b316a3d97d60486479657c63be0763834d0e2e8a30b1b86dc3c1c001", "raw": {"market": "0x50e477f0b316a3d97d60486479657c63be0763834d0e2e8a30b1b86dc3c1c001", "asset_id": "39981134260608444876865205057565852475343967395624370698967311821208058420507", "price": "0.988", "size": "0", "side": "BUY", "timestamp": "1768404589543", "received_at": "2026-01-14T16:29:49.205266"}}
{"event_type": "price_change", "event_ts": "2026-01-14T16:29:49.205266", "ingestion_ts": "2026-01-14T16:33:58.842229", "market_id": "0x50e477f0b316a3d97d60486479657c63be0763834d0e2e8a30b1b86dc3c1c001", "raw": {"market": "0x50e477f0b316a3d97d60486479657c63be0763834d0e2e8a30b1b86dc3c1c001", "asset_id": "60573178197991590327120832143415406583517170365625050489007297367895074266641", "price": "0.012", "size": "0", "side": "SELL", "timestamp": "1768404589543", "received_at": "2026-01-14T16:29:49.205266"}}
{"event_type": "price_change", "event_ts": "2026-01-14T16:29:49.449157", "ingestion_ts": "2026-01-14T16:33:58.842229", "market_id": "0xea644975be7b2ad32b536a94ae21b707ecb2f84290225b24e60ca46dd77903dd", "raw": {"market": "0xea644975be7b2ad32b536a94ae21b707ecb2f84290225b24e60ca46dd77903dd", "asset_id": "19255594762111702415265750364124818677094538461124581923455280001407159960455", "price": "0.021", "size": "8.31", "side": "BUY", "timestamp": "1768404589785", "received_at": "2026-01-14T16:29:49.449157"}}
{"event_type": "price_change", "event_ts": "2026-01-14T16:29:49.449157", "ingestion_ts": "2026-01-14T16:33:58.842229", "market_id": "0xea644975be7b2ad32b536a94ae21b707ecb2f84290225b24e60ca46dd77903dd", "raw": {"market": "0xea644975be7b2ad32b536a94ae21b707ecb2f84290225b24e60ca46dd77903dd", "asset_id": "110044455628775971785618539427229099821815416148768008176051068105157446559241", "price": "0.979", "size": "8.31", "side": "SELL", "timestamp": "1768404589785", "received_at": "2026-01-14T16:29:49.449157"}}
{"event_type": "price_change", "event_ts": "2026-01-14T16:29:49.449192", "ingestion_ts": "2026-01-14T16:33:58.842229", "market_id": "0xea644975be7b2ad32b536a94ae21b707ecb2f84290225b24e60ca46dd77903dd", "raw": {"market": "0xea644975be7b2ad32b536a94ae21b707ecb2f84290225b24e60ca46dd77903dd", "asset_id": "19255594762111702415265750364124818677094538461124581923455280001407159960455", "price": "0.011", "size": "5.41", "side": "BUY", "timestamp": "1768404589786", "received_at": "2026-01-14T16:29:49.449192"}}
{"event_type": "price_change", "event_ts": "2026-01-14T16:29:49.449192", "ingestion_ts": "2026-01-14T16:33:58.842229", "market_id": "0xea644975be7b2ad32b536a94ae21b707ecb2f84290225b24e60ca46dd77903dd", "raw": {"market": "0xea644975be7b2ad32b536a94ae21b707ecb2f84290225b24e60ca46dd77903dd", "asset_id": "110044455628775971785618539427229099821815416148768008176051068105157446559241", "price": "0.989", "size": "5.41", "side": "SELL", "timestamp": "1768404589786", "received_at": "2026-01-14T16:29:49.449192"}}
{"event_type": "price_change", "event_ts": "2026-01-14T16:29:49.450775", "ingestion_ts": "2026-01-14T16:33:58.842229", "market_id": "0xea644975be7b2ad32b536a94ae21b707ecb2f84290225b24e60ca46dd77903dd", "raw": {"market": "0xea644975be7b2ad32b536a94ae21b707ecb2f84290225b24e60ca46dd77903dd", "asset_id": "19255594762111702415265750364124818677094538461124581923455280001407159960455", "price": "0.004", "size": "10.67", "side": "BUY", "timestamp": "1768404589787", "received_at": "2026-01-14T16:29:49.450775"}}
{"event_type": "price_change", "event_ts": "2026-01-14T16:29:49.450775", "ingestion_ts": "2026-01-14T16:33:58.842229", "market_id": "0xea644975be7b2ad32b536a94ae21b707ecb2f84290225b24e60ca46dd77903dd", "raw": {"market": "0xea644975be7b2ad32b536a94ae21b707ecb2f84290225b24e60ca46dd77903dd", "asset_id": "110044455628775971785618539427229099821815416148768008176051068105157446559241", "price": "0.996", "size": "10.67", "side": "SELL", "timestamp": "1768404589787", "received_at": "2026-01-14T16:29:49.450775"}}
{"event_type": "price_change", "event_ts": "2026-01-14T16:29:49.450806", "ingestion_ts": "2026-01-14T16:33:58.842229", "market_id": "0xea644975be7b2ad32b536a94ae21b707ecb2f84290225b24e60ca46dd77903dd", "raw": {"market": "0xea644975be7b2ad32b536a94ae21b707ecb2f84290225b24e60ca46dd77903dd", "asset_id": "19255594762111702415265750364124818677094538461124581923455280001407159960455", "price": "0.052", "size": "12.66", "side": "BUY", "timestamp": "1768404589788", "received_at": "2026-01-14T16:29:49.450806"}}
{"event_type": "price_change", "event_ts": "2026-01-14T16:29:49.450806", "ingestion_ts": "2026-01-14T16:33:58.842229", "market_id": "0xea644975be7b2ad32b536a94ae21b707ecb2f84290225b24e60ca46dd77903dd", "raw": {"market": "0xea644975be7b2ad32b536a94ae21b707ecb2f84290225b24e60ca46dd77903dd", "asset_id": "110044455628775971785618539427229099821815416148768008176051068105157446559241", "price": "0.948", "size": "12.66", "side": "SELL", "timestamp": "1768404589788", "received_at": "2026-01-14T16:29:49.450806"}}
{"event_type": "price_change", "event_ts": "2026-01-14T16:29:49.453092", "ingestion_ts": "2026-01-14T16:33:58.842229", "market_id": "0xea644975be7b2ad32b536a94ae21b707ecb2f84290225b24e60ca46dd77903dd", "raw": {"market": "0xea644975be7b2ad32b536a94ae21b707ecb2f84290225b24e60ca46dd77903dd", "asset_id": "19255594762111702415265750364124818677094538461124581923455280001407159960455", "price": "0.002", "size": "256.17", "side": "BUY", "timestamp": "1768404589789", "received_at": "2026-01-14T16:29:49.453092"}}
{"event_type": "price_change", "event_ts": "2026-01-14T16:29:49.453092", "ingestion_ts": "2026-01-14T16:33:58.842229", "market_id": "0xea644975be7b2ad32b536a94ae21b707ecb2f84290225b24e60ca46dd77903dd", "raw": {"market": "0xea644975be7b2ad32b536a94ae21b707ecb2f84290225b24e60ca46dd77903dd", "asset_id": "110044455628775971785618539427229099821815416148768008176051068105157446559241", "price": "0.998", "size": "256.17", "side": "SELL", "timestamp": "1768404589789", "received_at": "2026-01-14T16:29:49.453092"}}
{"event_type": "price_change", "event_ts": "2026-01-14T16:29:49.453115", "ingestion_ts": "2026-01-14T16:33:58.842229", "market_id": "0xea644975be7b2ad32b536a94ae21b707ecb2f84290225b24e60ca46dd77903dd", "raw": {"market": "0xea644975be7b2ad32b536a94ae21b707ecb2f84290225b24e60ca46dd77903dd", "asset_id": "19255594762111702415265750364124818677094538461124581923455280001407159960455", "price": "0.201", "size": "5.2", "side": "BUY", "timestamp": "1768404589789", "received_at": "2026-01-14T16:29:49.453115"}}
{"event_type": "price_change", "event_ts": "2026-01-14T16:29:49.453115", "ingestion_ts": "2026-01-14T16:33:58.842229", "market_id": "0xea644975be7b2ad32b536a94ae21b707ecb2f84290225b24e60ca46dd77903dd", "raw": {"market": "0xea644975be7b2ad32b536a94ae21b707ecb2f84290225b24e60ca46dd77903dd", "asset_id": "110044455628775971785618539427229099821815416148768008176051068105157446559241", "price": "0.799", "size": "5.2", "side": "SELL", "timestamp": "1768404589789", "received_at": "2026-01-14T16:29:49.453115"}}
{"event_type": "price_change", "event_ts": "2026-01-14T16:29:49.764343", "ingestion_ts": "2026-01-14T16:33:58.842229", "market_id": "0xe68594f1350f5535532b24979b5b5c1948432cbfc0c363802c32a8f9ab4e6509", "raw": {"market": "0xe68594f1350f5535532b24979b5b5c1948432cbfc0c363802c32a8f9ab4e6509", "asset_id": "3074032031589250926591186368301243337494992039402397918135503567058257050088", "price": "0.011", "size": "5.41", "side": "BUY", "timestamp": "1768404590090", "received_at": "2026-01-14T16:29:49.764343"}}
{"event_type": "price_change", "event_ts": "2026-01-14T16:29:49.764343", "ingestion_ts": "2026-01-14T16:33:58.842229", "market_id": "0xe68594f1350f5535532b24979b5b5c1948432cbfc0c363802c32a8f9ab4e6509", "raw": {"market": "0xe68594f1350f5535532b24979b5b5c1948432cbfc0c363802c32a8f9ab4e6509", "asset_id": "47459180813047899567328389455747872955901265556145057896316155826890276004242", "price": "0.989", "size": "5.41", "side": "SELL", "timestamp": "1768404590090", "received_at": "2026-01-14T16:29:49.764343"}}
{"event_type": "price_change", "event_ts": "2026-01-14T16:29:49.764378", "ingestion_ts": "2026-01-14T16:33:58.842229", "market_id": "0x50e477f0b316a3d97d60486479657c63be0763834d0e2e8a30b1b86dc3c1c001", "raw": {"market": "0x50e477f0b316a3d97d60486479657c63be0763834d0e2e8a30b1b86dc3c1c001", "asset_id": "39981134260608444876865205057565852475343967395624370698967311821208058420507", "price": "0.201", "size": "5.2", "side": "BUY", "timestamp": "1768404590090", "received_at": "2026-01-14T16:29:49.764378"}}
{"event_type": "price_change", "event_ts": "2026-01-14T16:29:49.764378", "ingestion_ts": "2026-01-14T16:33:58.842229", "market_id": "0x50e477f0b316a3d97d60486479657c63be0763834d0e2e8a30b1b86dc3c1c001", "raw": {"market": "0x50e477f0b316a3d97d60486479657c63be0763834d0e2e8a30b1b86dc3c1c001", "asset_id": "60573178197991590327120832143415406583517170365625050489007297367895074266641", "price": "0.799", "size": "5.2", "side": "SELL", "timestamp": "1768404590090", "received_at": "2026-01-14T16:29:49.764378"}}
{"event_type": "price_change", "event_ts": "2026-01-14T16:29:49.764395", "ingestion_ts": "2026-01-14T16:33:58.842229", "market_id": "0xea644975be7b2ad32b536a94ae21b707ecb2f84290225b24e60ca46dd77903dd", "raw": {"market": "0xea644975be7b2ad32b536a94ae21b707ecb2f84290225b24e60ca46dd77903dd", "asset_id": "19255594762111702415265750364124818677094538461124581923455280001407159960455", "price": "0.001", "size": "203524.7", "side": "BUY", "timestamp": "1768404590090", "received_at": "2026-01-14T16:29:49.764395"}}
{"event_type": "price_change", "event_ts": "2026-01-14T16:29:49.764395", "ingestion_ts": "2026-01-14T16:33:58.842229", "market_id": "0xea644975be7b2ad32b536a94ae21b707ecb2f84290225b24e60ca46dd77903dd", "raw": {"market": "0xea644975be7b2ad32b536a94ae21b707ecb2f84290225b24e60ca46dd77903dd", "asset_id": "110044455628775971785618539427229099821815416148768008176051068105157446559241", "price": "0.999", "size": "203524.7", "side": "SELL", "timestamp": "1768404590090", "received_at": "2026-01-14T16:29:49.764395"}}
{"event_type": "price_change", "event_ts": "2026-01-14T16:29:49.765833", "ingestion_ts": "2026-01-14T16:33:58.842229", "market_id": "0xe68594f1350f5535532b24979b5b5c1948432cbfc0c363802c32a8f9ab4e6509", "raw": {"market": "0xe68594f1350f5535532b24979b5b5c1948432cbfc0c363802c32a8f9ab4e6509", "asset_id": "3074032031589250926591186368301243337494992039402397918135503567058257050088", "price": "0.051", "size": "13.02", "side": "BUY", "timestamp": "1768404590091", "received_at": "2026-01-14T16:29:49.765833"}}
{"event_type": "price_change", "event_ts": "2026-01-14T16:29:49.765833", "ingestion_ts": "2026-01-14T16:33:58.842229", "market_id": "0xe68594f1350f5535532b24979b5b5c1948432cbfc0c363802c32a8f9ab4e6509", "raw": {"market": "0xe68594f1350f5535532b24979b5b5c1948432cbfc0c363802c32a8f9ab4e6509", "asset_id": "47459180813047899567328389455747872955901265556145057896316155826890276004242", "price": "0.949", "size": "13.02", "side": "SELL", "timestamp": "1768404590091", "received_at": "2026-01-14T16:29:49.765833"}}
{"event_type": "price_change", "event_ts": "2026-01-14T16:29:49.765855", "ingestion_ts": "2026-01-14T16:33:58.842229", "market_id": "0x50e477f0b316a3d97d60486479657c63be0763834d0e2e8a30b1b86dc3c1c001", "raw": {"market": "0x50e477f0b316a3d97d60486479657c63be0763834d0e2e8a30b1b86dc3c1c001", "asset_id": "39981134260608444876865205057565852475343967395624370698967311821208058420507", "price": "0.004", "size": "10.68", "side": "BUY", "timestamp": "1768404590091", "received_at": "2026-01-14T16:29:49.765855"}}
{"event_type": "price_change", "event_ts": "2026-01-14T16:29:49.765855", "ingestion_ts": "2026-01-14T16:33:58.842229", "market_id": "0x50e477f0b316a3d97d60486479657c63be0763834d0e2e8a30b1b86dc3c1c001", "raw": {"market": "0x50e477f0b316a3d97d60486479657c63be0763834d0e2e8a30b1b86dc3c1c001", "asset_id": "60573178197991590327120832143415406583517170365625050489007297367895074266641", "price": "0.996", "size": "10.68", "side": "SELL", "timestamp": "1768404590091", "received_at": "2026-01-14T16:29:49.765855"}}
{"event_type": "price_change", "event_ts": "2026-01-14T16:29:49.767585", "ingestion_ts": "2026-01-14T16:33:58.842229", "market_id": "0xe68594f1350f5535532b24979b5b5c1948432cbfc0c363802c32a8f9ab4e6509", "raw": {"market": "0xe68594f1350f5535532b24979b5b5c1948432cbfc0c363802c32a8f9ab4e6509", "asset_id": "3074032031589250926591186368301243337494992039402397918135503567058257050088", "price": "0.201", "size": "5.2", "side": "BUY", "timestamp": "1768404590091", "received_at": "2026-01-14T16:29:49.767585"}}
{"event_type": "price_change", "event_ts": "2026-01-14T16:29:49.767585", "ingestion_ts": "2026-01-14T16:33:58.842229", "market_id": "0xe68594f1350f5535532b24979b5b5c1948432cbfc0c363802c32a8f9ab4e6509", "raw": {"market": "0xe68594f1350f5535532b24979b5b5c1948432cbfc0c363802c32a8f9ab4e6509", "asset_id": "47459180813047899567328389455747872955901265556145057896316155826890276004242", "price": "0.799", "size": "5.2", "side": "SELL", "timestamp": "1768404590091", "received_at": "2026-01-14T16:29:49.767585"}}
{"event_type": "price_change", "event_ts": "2026-01-14T16:29:49.767609", "ingestion_ts": "2026-01-14T16:33:58.842229", "market_id": "0x50e477f0b316a3d97d60486479657c63be0763834d0e2e8a30b1b86dc3c1c001", "raw": {"market": "0x50e477f0b316a3d97d60486479657c63be0763834d0e2e8a30b1b86dc3c1c001", "asset_id": "39981134260608444876865205057565852475343967395624370698967311821208058420507", "price": "0.001", "size": "203513.45", "side": "BUY", "timestamp": "1768404590092", "received_at": "2026-01-14T16:29:49.767609"}}
{"event_type": "price_change", "event_ts": "2026-01-14T16:29:49.767609", "ingestion_ts": "2026-01-14T16:33:58.842229", "market_id": "0x50e477f0b316a3d97d60486479657c63be0763834d0e2e8a30b1b86dc3c1c001", "raw": {"market": "0x50e477f0b316a3d97d60486479657c63be0763834d0e2e8a30b1b86dc3c1c001", "asset_id": "60573178197991590327120832143415406583517170365625050489007297367895074266641", "price": "0.999", "size": "203513.45", "side": "SELL", "timestamp": "1768404590092", "received_at": "2026-01-14T16:29:49.767609"}}
{"event_type": "price_change", "event_ts": "2026-01-14T16:29:49.767625", "ingestion_ts": "2026-01-14T16:33:58.842229", "market_id": "0xe68594f1350f5535532b24979b5b5c1948432cbfc0c363802c32a8f9ab4e6509", "raw": {"market": "0xe68594f1350f5535532b24979b5b5c1948432cbfc0c363802c32a8f9ab4e6509", "asset_id": "3074032031589250926591186368301243337494992039402397918135503567058257050088", "price": "0.001", "size": "203634.57", "side": "BUY", "timestamp": "1768404590092", "received_at": "2026-01-14T16:29:49.767625"}}
{"event_type": "price_change", "event_ts": "2026-01-14T16:29:49.767625", "ingestion_ts": "2026-01-14T16:33:58.842229", "market_id": "0xe68594f1350f5535532b24979b5b5c1948432cbfc0c363802c32a8f9ab4e6509", "raw": {"market": "0xe68594f1350f5535532b24979b5b5c1948432cbfc0c363802c32a8f9ab4e6509", "asset_id": "47459180813047899567328389455747872955901265556145057896316155826890276004242", "price": "0.999", "size": "203634.57", "side": "SELL", "timestamp": "1768404590092", "received_at": "2026-01-14T16:29:49.767625"}}
{"event_type": "price_change", "event_ts": "2026-01-14T16:29:49.767641", "ingestion_ts": "2026-01-14T16:33:58.842229", "market_id": "0x50e477f0b316a3d97d60486479657c63be0763834d0e2e8a30b1b86dc3c1c001", "raw": {"market": "0x50e477f0b316a3d97d60486479657c63be0763834d0e2e8a30b1b86dc3c1c001", "asset_id": "39981134260608444876865205057565852475343967395624370698967311821208058420507", "price": "0.021", "size": "8.06", "side": "BUY", "timestamp": "1768404590093", "received_at": "2026-01-14T16:29:49.767641"}}
{"event_type": "price_change", "event_ts": "2026-01-14T16:29:49.767641", "ingestion_ts": "2026-01-14T16:33:58.842229", "market_id": "0x50e477f0b316a3d97d60486479657c63be0763834d0e2e8a30b1b86dc3c1c001", "raw": {"market": "0x50e477f0b316a3d97d60486479657c63be0763834d0e2e8a30b1b86dc3c1c001", "asset_id": "60573178197991590327120832143415406583517170365625050489007297367895074266641", "price": "0.979", "size": "8.06", "side": "SELL", "timestamp": "1768404590093", "received_at": "2026-01-14T16:29:49.767641"}}
{"event_type": "price_change", "event_ts": "2026-01-14T16:29:49.767652", "ingestion_ts": "2026-01-14T16:33:58.842229", "market_id": "0xe68594f1350f5535532b24979b5b5c1948432cbfc0c363802c32a8f9ab4e6509", "raw": {"market": "0xe68594f1350f5535532b24979b5b5c1948432cbfc0c363802c32a8f9ab4e6509", "asset_id": "3074032031589250926591186368301243337494992039402397918135503567058257050088", "price": "0.002", "size": "256.17", "side": "BUY", "timestamp": "1768404590093", "received_at": "2026-01-14T16:29:49.767652"}}
{"event_type": "price_change", "event_ts": "2026-01-14T16:29:49.767652", "ingestion_ts": "2026-01-14T16:33:58.842229", "market_id": "0xe68594f1350f5535532b24979b5b5c1948432cbfc0c363802c32a8f9ab4e6509", "raw": {"market": "0xe68594f1350f5535532b24979b5b5c1948432cbfc0c363802c32a8f9ab4e6509", "asset_id": "47459180813047899567328389455747872955901265556145057896316155826890276004242", "price": "0.998", "size": "256.17", "side": "SELL", "timestamp": "1768404590093", "received_at": "2026-01-14T16:29:49.767652"}}
{"event_type": "price_change", "event_ts": "2026-01-14T16:29:49.782102", "ingestion_ts": "2026-01-14T16:33:58.842229", "market_id": "0x50e477f0b316a3d97d60486479657c63be0763834d0e2e8a30b1b86dc3c1c001", "raw": {"market": "0x50e477f0b316a3d97d60486479657c63be0763834d0e2e8a30b1b86dc3c1c001", "asset_id": "39981134260608444876865205057565852475343967395624370698967311821208058420507", "price": "0.002", "size": "256.18", "side": "BUY", "timestamp": "1768404590093", "received_at": "2026-01-14T16:29:49.782102"}}
{"event_type": "price_change", "event_ts": "2026-01-14T16:29:49.782102", "ingestion_ts": "2026-01-14T16:33:58.842229", "market_id": "0x50e477f0b316a3d97d60486479657c63be0763834d0e2e8a30b1b86dc3c1c001", "raw": {"market": "0x50e477f0b316a3d97d60486479657c63be0763834d0e2e8a30b1b86dc3c1c001", "asset_id": "60573178197991590327120832143415406583517170365625050489007297367895074266641", "price": "0.998", "size": "256.18", "side": "SELL", "timestamp": "1768404590093", "received_at": "2026-01-14T16:29:49.782102"}}
{"event_type": "price_change", "event_ts": "2026-01-14T16:29:49.782129", "ingestion_ts": "2026-01-14T16:33:58.842229", "market_id": "0xe68594f1350f5535532b24979b5b5c1948432cbfc0c363802c32a8f9ab4e6509", "raw": {"market": "0xe68594f1350f5535532b24979b5b5c1948432cbfc0c363802c32a8f9ab4e6509", "asset_id": "3074032031589250926591186368301243337494992039402397918135503567058257050088", "price": "0.004", "size": "10.67", "side": "BUY", "timestamp": "1768404590094", "received_at": "2026-01-14T16:29:49.782129"}}
{"event_type": "price_change", "event_ts": "2026-01-14T16:29:49.782129", "ingestion_ts": "2026-01-14T16:33:58.842229", "market_id": "0xe68594f1350f5535532b24979b5b5c1948432cbfc0c363802c32a8f9ab4e6509", "raw": {"market": "0xe68594f1350f5535532b24979b5b5c1948432cbfc0c363802c32a8f9ab4e6509", "asset_id": "47459180813047899567328389455747872955901265556145057896316155826890276004242", "price": "0.996", "size": "10.67", "side": "SELL", "timestamp": "1768404590094", "received_at": "2026-01-14T16:29:49.782129"}}
{"event_type": "price_change", "event_ts": "2026-01-14T16:29:49.782143", "ingestion_ts": "2026-01-14T16:33:58.842229", "market_id": "0x50e477f0b316a3d97d60486479657c63be0763834d0e2e8a30b1b86dc3c1c001", "raw": {"market": "0x50e477f0b316a3d97d60486479657c63be0763834d0e2e8a30b1b86dc3c1c001", "asset_id": "39981134260608444876865205057565852475343967395624370698967311821208058420507", "price": "0.011", "size": "5.42", "side": "BUY", "timestamp": "1768404590094", "received_at": "2026-01-14T16:29:49.782143"}}
{"event_type": "price_change", "event_ts": "2026-01-14T16:29:49.782143", "ingestion_ts": "2026-01-14T16:33:58.842229", "market_id": "0x50e477f0b316a3d97d60486479657c63be0763834d0e2e8a30b1b86dc3c1c001", "raw": {"market": "0x50e477f0b316a3d97d60486479657c63be0763834d0e2e8a30b1b86dc3c1c001", "asset_id": "60573178197991590327120832143415406583517170365625050489007297367895074266641", "price": "0.989", "size": "5.42", "side": "SELL", "timestamp": "1768404590094", "received_at": "2026-01-14T16:29:49.782143"}}
{"event_type": "price_change", "event_ts": "2026-01-14T16:29:49.782159", "ingestion_ts": "2026-01-14T16:33:58.842229", "market_id": "0xe68594f1350f5535532b24979b5b5c1948432cbfc0c363802c32a8f9ab4e6509", "raw": {"market": "0xe68594f1350f5535532b24979b5b5c1948432cbfc0c363802c32a8f9ab4e6509", "asset_id": "3074032031589250926591186368301243337494992039402397918135503567058257050088", "price": "0.021", "size": "8.05", "side": "BUY", "timestamp": "1768404590095", "received_at": "2026-01-14T16:29:49.782159"}}
{"event_type": "price_change", "event_ts": "2026-01-14T16:29:49.782159", "ingestion_ts": "2026-01-14T16:33:58.842229", "market_id": "0xe68594f1350f5535532b24979b5b5c1948432cbfc0c363802c32a8f9ab4e6509", "raw": {"market": "0xe68594f1350f5535532b24979b5b5c1948432cbfc0c363802c32a8f9ab4e6509", "asset_id": "47459180813047899567328389455747872955901265556145057896316155826890276004242", "price": "0.979", "size": "8.05", "side": "SELL", "timestamp": "1768404590095", "received_at": "2026-01-14T16:29:49.782159"}}
{"event_type": "price_change", "event_ts": "2026-01-14T16:29:49.782172", "ingestion_ts": "2026-01-14T16:33:58.842229", "market_id": "0x50e477f0b316a3d97d60486479657c63be0763834d0e2e8a30b1b86dc3c1c001", "raw": {"market": "0x50e477f0b316a3d97d60486479657c63be0763834d0e2e8a30b1b86dc3c1c001", "asset_id": "39981134260608444876865205057565852475343967395624370698967311821208058420507", "price": "0.051", "size": "13.02", "side": "BUY", "timestamp": "1768404590095", "received_at": "2026-01-14T16:29:49.782172"}}
{"event_type": "price_change", "event_ts": "2026-01-14T16:29:49.782172", "ingestion_ts": "2026-01-14T16:33:58.842229", "market_id": "0x50e477f0b316a3d97d60486479657c63be0763834d0e2e8a30b1b86dc3c1c001", "raw": {"market": "0x50e477f0b316a3d97d60486479657c63be0763834d0e2e8a30b1b86dc3c1c001", "asset_id": "60573178197991590327120832143415406583517170365625050489007297367895074266641", "price": "0.949", "size": "13.02", "side": "SELL", "timestamp": "1768404590095", "received_at": "2026-01-14T16:29:49.782172"}}
{"event_type": "price_change", "event_ts": "2026-01-14T16:29:49.945527", "ingestion_ts": "2026-01-14T16:33:58.842229", "market_id": "0xaf9d0e448129a9f657f851d49495ba4742055d80e0ef1166ba0ee81d4d594214", "raw": {"market": "0xaf9d0e448129a9f657f851d49495ba4742055d80e0ef1166ba0ee81d4d594214", "asset_id": "4153292802911610701832309484716814274802943278345248636922528170020319407796", "price": "0.011", "size": "5.14", "side": "BUY", "timestamp": "1768404590275", "received_at": "2026-01-14T16:29:49.945527"}}
{"event_type": "price_change", "event_ts": "2026-01-14T16:29:49.945527", "ingestion_ts": "2026-01-14T16:33:58.842229", "market_id": "0xaf9d0e448129a9f657f851d49495ba4742055d80e0ef1166ba0ee81d4d594214", "raw": {"market": "0xaf9d0e448129a9f657f851d49495ba4742055d80e0ef1166ba0ee81d4d594214", "asset_id": "101676997363687199724245607342877036148401850938023978421879460310389391082353", "price": "0.989", "size": "5.14", "side": "SELL", "timestamp": "1768404590275", "received_at": "2026-01-14T16:29:49.945527"}}
{"event_type": "price_change", "event_ts": "2026-01-14T16:29:49.945560", "ingestion_ts": "2026-01-14T16:33:58.842229", "market_id": "0x9d24d9f9b5995949cb158d943793dea20bd448e1b3971cb6f7418bb15e719661", "raw": {"market": "0x9d24d9f9b5995949cb158d943793dea20bd448e1b3971cb6f7418bb15e719661", "asset_id": "79516121807256184736227920754945730465880754940725759201193439378549308939672", "price": "0.051", "size": "13.01", "side": "BUY", "timestamp": "1768404590275", "received_at": "2026-01-14T16:29:49.945560"}}
{"event_type": "price_change", "event_ts": "2026-01-14T16:29:49.945560", "ingestion_ts": "2026-01-14T16:33:58.842229", "market_id": "0x9d24d9f9b5995949cb158d943793dea20bd448e1b3971cb6f7418bb15e719661", "raw": {"market": "0x9d24d9f9b5995949cb158d943793dea20bd448e1b3971cb6f7418bb15e719661", "asset_id": "70512916946285526357165287373537570327431985324385225788636160168740471920430", "price": "0.949", "size": "13.01", "side": "SELL", "timestamp": "1768404590275", "received_at": "2026-01-14T16:29:49.945560"}}
{"event_type": "price_change", "event_ts": "2026-01-14T16:29:49.945579", "ingestion_ts": "2026-01-14T16:33:58.842229", "market_id": "0x44f08744458b8896620cd3330bc5e1ea69df4199b02d4fc583b3fc96e5d314ce", "raw": {"market": "0x44f08744458b8896620cd3330bc5e1ea69df4199b02d4fc583b3fc96e5d314ce", "asset_id": "72327831507226612545928776794104143393438710920370371172884559893525100761096", "price": "0.002", "size": "257.88", "side": "BUY", "timestamp": "1768404590275", "received_at": "2026-01-14T16:29:49.945579"}}
{"event_type": "price_change", "event_ts": "2026-01-14T16:29:49.945579", "ingestion_ts": "2026-01-14T16:33:58.842229", "market_id": "0x44f08744458b8896620cd3330bc5e1ea69df4199b02d4fc583b3fc96e5d314ce", "raw": {"market": "0x44f08744458b8896620cd3330bc5e1ea69df4199b02d4fc583b3fc96e5d314ce", "asset_id": "49194009556504828848509244326501559253829462790583873936160989575507522044057", "price": "0.998", "size": "257.88", "side": "SELL", "timestamp": "1768404590275", "received_at": "2026-01-14T16:29:49.945579"}}
{"event_type": "price_change", "event_ts": "2026-01-14T16:29:49.953413", "ingestion_ts": "2026-01-14T16:33:58.842229", "market_id": "0x9d24d9f9b5995949cb158d943793dea20bd448e1b3971cb6f7418bb15e719661", "raw": {"market": "0x9d24d9f9b5995949cb158d943793dea20bd448e1b3971cb6f7418bb15e719661", "asset_id": "79516121807256184736227920754945730465880754940725759201193439378549308939672", "price": "0.021", "size": "8.05", "side": "BUY", "timestamp": "1768404590276", "received_at": "2026-01-14T16:29:49.953413"}}
{"event_type": "price_change", "event_ts": "2026-01-14T16:29:49.953413", "ingestion_ts": "2026-01-14T16:33:58.842229", "market_id": "0x9d24d9f9b5995949cb158d943793dea20bd448e1b3971cb6f7418bb15e719661", "raw": {"market": "0x9d24d9f9b5995949cb158d943793dea20bd448e1b3971cb6f7418bb15e719661", "asset_id": "70512916946285526357165287373537570327431985324385225788636160168740471920430", "price": "0.979", "size": "8.05", "side": "SELL", "timestamp": "1768404590276", "received_at": "2026-01-14T16:29:49.953413"}}
{"event_type": "price_change", "event_ts": "2026-01-14T16:29:49.953438", "ingestion_ts": "2026-01-14T16:33:58.842229", "market_id": "0xaf9d0e448129a9f657f851d49495ba4742055d80e0ef1166ba0ee81d4d594214", "raw": {"market": "0xaf9d0e448129a9f657f851d49495ba4742055d80e0ef1166ba0ee81d4d594214", "asset_id": "4153292802911610701832309484716814274802943278345248636922528170020319407796", "price": "0.201", "size": "5.66", "side": "BUY", "timestamp": "1768404590276", "received_at": "2026-01-14T16:29:49.953438"}}
{"event_type": "price_change", "event_ts": "2026-01-14T16:29:49.953438", "ingestion_ts": "2026-01-14T16:33:58.842229", "market_id": "0xaf9d0e448129a9f657f851d49495ba4742055d80e0ef1166ba0ee81d4d594214", "raw": {"market": "0xaf9d0e448129a9f657f851d49495ba4742055d80e0ef1166ba0ee81d4d594214", "asset_id": "101676997363687199724245607342877036148401850938023978421879460310389391082353", "price": "0.799", "size": "5.66", "side": "SELL", "timestamp": "1768404590276", "received_at": "2026-01-14T16:29:49.953438"}}
{"event_type": "price_change", "event_ts": "2026-01-14T16:29:49.953454", "ingestion_ts": "2026-01-14T16:33:58.842229", "market_id": "0x44f08744458b8896620cd3330bc5e1ea69df4199b02d4fc583b3fc96e5d314ce", "raw": {"market": "0x44f08744458b8896620cd3330bc5e1ea69df4199b02d4fc583b3fc96e5d314ce", "asset_id": "72327831507226612545928776794104143393438710920370371172884559893525100761096", "price": "0.024", "size": "6.66", "side": "BUY", "timestamp": "1768404590276", "received_at": "2026-01-14T16:29:49.953454"}}
{"event_type": "price_change", "event_ts": "2026-01-14T16:29:49.953454", "ingestion_ts": "2026-01-14T16:33:58.842229", "market_id": "0x44f08744458b8896620cd3330bc5e1ea69df4199b02d4fc583b3fc96e5d314ce", "raw": {"market": "0x44f08744458b8896620cd3330bc5e1ea69df4199b02d4fc583b3fc96e5d314ce", "asset_id": "49194009556504828848509244326501559253829462790583873936160989575507522044057", "price": "0.976", "size": "6.66", "side": "SELL", "timestamp": "1768404590276", "received_at": "2026-01-14T16:29:49.953454"}}
{"event_type": "price_change", "event_ts": "2026-01-14T16:29:49.953467", "ingestion_ts": "2026-01-14T16:33:58.842229", "market_id": "0x9d24d9f9b5995949cb158d943793dea20bd448e1b3971cb6f7418bb15e719661", "raw": {"market": "0x9d24d9f9b5995949cb158d943793dea20bd448e1b3971cb6f7418bb15e719661", "asset_id": "79516121807256184736227920754945730465880754940725759201193439378549308939672", "price": "0.011", "size": "5.41", "side": "BUY", "timestamp": "1768404590277", "received_at": "2026-01-14T16:29:49.953467"}}
{"event_type": "price_change", "event_ts": "2026-01-14T16:29:49.953467", "ingestion_ts": "2026-01-14T16:33:58.842229", "market_id": "0x9d24d9f9b5995949cb158d943793dea20bd448e1b3971cb6f7418bb15e719661", "raw": {"market": "0x9d24d9f9b5995949cb158d943793dea20bd448e1b3971cb6f7418bb15e719661", "asset_id": "70512916946285526357165287373537570327431985324385225788636160168740471920430", "price": "0.989", "size": "5.41", "side": "SELL", "timestamp": "1768404590277", "received_at": "2026-01-14T16:29:49.953467"}}
{"event_type": "price_change", "event_ts": "2026-01-14T16:29:49.957157", "ingestion_ts": "2026-01-14T16:33:58.842229", "market_id": "0xaf9d0e448129a9f657f851d49495ba4742055d80e0ef1166ba0ee81d4d594214", "raw": {"market": "0xaf9d0e448129a9f657f851d49495ba4742055d80e0ef1166ba0ee81d4d594214", "asset_id": "4153292802911610701832309484716814274802943278345248636922528170020319407796", "price": "0.052", "size": "11.61", "side": "BUY", "timestamp": "1768404590277", "received_at": "2026-01-14T16:29:49.957157"}}
{"event_type": "price_change", "event_ts": "2026-01-14T16:29:49.957157", "ingestion_ts": "2026-01-14T16:33:58.842229", "market_id": "0xaf9d0e448129a9f657f851d49495ba4742055d80e0ef1166ba0ee81d4d594214", "raw": {"market": "0xaf9d0e448129a9f657f851d49495ba4742055d80e0ef1166ba0ee81d4d594214", "asset_id": "101676997363687199724245607342877036148401850938023978421879460310389391082353", "price": "0.948", "size": "11.61", "side": "SELL", "timestamp": "1768404590277", "received_at": "2026-01-14T16:29:49.957157"}}
{"event_type": "price_change", "event_ts": "2026-01-14T16:29:49.957184", "ingestion_ts": "2026-01-14T16:33:58.842229", "market_id": "0x44f08744458b8896620cd3330bc5e1ea69df4199b02d4fc583b3fc96e5d314ce", "raw": {"market": "0x44f08744458b8896620cd3330bc5e1ea69df4199b02d4fc583b3fc96e5d314ce", "asset_id": "72327831507226612545928776794104143393438710920370371172884559893525100761096", "price": "0.005", "size": "6.24", "side": "BUY", "timestamp": "1768404590277", "received_at": "2026-01-14T16:29:49.957184"}}
{"event_type": "price_change", "event_ts": "2026-01-14T16:29:49.957184", "ingestion_ts": "2026-01-14T16:33:58.842229", "market_id": "0x44f08744458b8896620cd3330bc5e1ea69df4199b02d4fc583b3fc96e5d314ce", "raw": {"market": "0x44f08744458b8896620cd3330bc5e1ea69df4199b02d4fc583b3fc96e5d314ce", "asset_id": "49194009556504828848509244326501559253829462790583873936160989575507522044057", "price": "0.995", "size": "6.24", "side": "SELL", "timestamp": "1768404590277", "received_at": "2026-01-14T16:29:49.957184"}}
{"event_type": "price_change", "event_ts": "2026-01-14T16:29:49.957199", "ingestion_ts": "2026-01-14T16:33:58.842229", "market_id": "0x9d24d9f9b5995949cb158d943793dea20bd448e1b3971cb6f7418bb15e719661", "raw": {"market": "0x9d24d9f9b5995949cb158d943793dea20bd448e1b3971cb6f7418bb15e719661", "asset_id": "79516121807256184736227920754945730465880754940725759201193439378549308939672", "price": "0.201", "size": "5.2", "side": "BUY", "timestamp": "1768404590278", "received_at": "2026-01-14T16:29:49.957199"}}
{"event_type": "price_change", "event_ts": "2026-01-14T16:29:49.957199", "ingestion_ts": "2026-01-14T16:33:58.842229", "market_id": "0x9d24d9f9b5995949cb158d943793dea20bd448e1b3971cb6f7418bb15e719661", "raw": {"market": "0x9d24d9f9b5995949cb158d943793dea20bd448e1b3971cb6f7418bb15e719661", "asset_id": "70512916946285526357165287373537570327431985324385225788636160168740471920430", "price": "0.799", "size": "5.2", "side": "SELL", "timestamp": "1768404590278", "received_at": "2026-01-14T16:29:49.957199"}}
{"event_type": "price_change", "event_ts": "2026-01-14T16:29:49.962637", "ingestion_ts": "2026-01-14T16:33:58.842229", "market_id": "0xaf9d0e448129a9f657f851d49495ba4742055d80e0ef1166ba0ee81d4d594214", "raw": {"market": "0xaf9d0e448129a9f657f851d49495ba4742055d80e0ef1166ba0ee81d4d594214", "asset_id": "4153292802911610701832309484716814274802943278345248636922528170020319407796", "price": "0.001", "size": "2721.03", "side": "BUY", "timestamp": "1768404590278", "received_at": "2026-01-14T16:29:49.962637"}}
{"event_type": "price_change", "event_ts": "2026-01-14T16:29:49.962637", "ingestion_ts": "2026-01-14T16:33:58.842229", "market_id": "0xaf9d0e448129a9f657f851d49495ba4742055d80e0ef1166ba0ee81d4d594214", "raw": {"market": "0xaf9d0e448129a9f657f851d49495ba4742055d80e0ef1166ba0ee81d4d594214", "asset_id": "101676997363687199724245607342877036148401850938023978421879460310389391082353", "price": "0.999", "size": "2721.03", "side": "SELL", "timestamp": "1768404590278", "received_at": "2026-01-14T16:29:49.962637"}}
{"event_type": "price_change", "event_ts": "2026-01-14T16:29:49.962662", "ingestion_ts": "2026-01-14T16:33:58.842229", "market_id": "0x9d24d9f9b5995949cb158d943793dea20bd448e1b3971cb6f7418bb15e719661", "raw": {"market": "0x9d24d9f9b5995949cb158d943793dea20bd448e1b3971cb6f7418bb15e719661", "asset_id": "79516121807256184736227920754945730465880754940725759201193439378549308939672", "price": "0.002", "size": "259.24", "side": "BUY", "timestamp": "1768404590278", "received_at": "2026-01-14T16:29:49.962662"}}
{"event_type": "price_change", "event_ts": "2026-01-14T16:29:49.962662", "ingestion_ts": "2026-01-14T16:33:58.842229", "market_id": "0x9d24d9f9b5995949cb158d943793dea20bd448e1b3971cb6f7418bb15e719661", "raw": {"market": "0x9d24d9f9b5995949cb158d943793dea20bd448e1b3971cb6f7418bb15e719661", "asset_id": "70512916946285526357165287373537570327431985324385225788636160168740471920430", "price": "0.998", "size": "259.24", "side": "SELL", "timestamp": "1768404590278", "received_at": "2026-01-14T16:29:49.962662"}}
{"event_type": "price_change", "event_ts": "2026-01-14T16:29:49.962679", "ingestion_ts": "2026-01-14T16:33:58.842229", "market_id": "0x44f08744458b8896620cd3330bc5e1ea69df4199b02d4fc583b3fc96e5d314ce", "raw": {"market": "0x44f08744458b8896620cd3330bc5e1ea69df4199b02d4fc583b3fc96e5d314ce", "asset_id": "72327831507226612545928776794104143393438710920370371172884559893525100761096", "price": "0.057", "size": "10.13", "side": "BUY", "timestamp": "1768404590278", "received_at": "2026-01-14T16:29:49.962679"}}
{"event_type": "price_change", "event_ts": "2026-01-14T16:29:49.962679", "ingestion_ts": "2026-01-14T16:33:58.842229", "market_id": "0x44f08744458b8896620cd3330bc5e1ea69df4199b02d4fc583b3fc96e5d314ce", "raw": {"market": "0x44f08744458b8896620cd3330bc5e1ea69df4199b02d4fc583b3fc96e5d314ce", "asset_id": "49194009556504828848509244326501559253829462790583873936160989575507522044057", "price": "0.943", "size": "10.13", "side": "SELL", "timestamp": "1768404590278", "received_at": "2026-01-14T16:29:49.962679"}}
{"event_type": "price_change", "event_ts": "2026-01-14T16:29:49.962693", "ingestion_ts": "2026-01-14T16:33:58.842229", "market_id": "0xaf9d0e448129a9f657f851d49495ba4742055d80e0ef1166ba0ee81d4d594214", "raw": {"market": "0xaf9d0e448129a9f657f851d49495ba4742055d80e0ef1166ba0ee81d4d594214", "asset_id": "4153292802911610701832309484716814274802943278345248636922528170020319407796", "price": "0.022", "size": "6.7", "side": "BUY", "timestamp": "1768404590279", "received_at": "2026-01-14T16:29:49.962693"}}
{"event_type": "price_change", "event_ts": "2026-01-14T16:29:49.962693", "ingestion_ts": "2026-01-14T16:33:58.842229", "market_id": "0xaf9d0e448129a9f657f851d49495ba4742055d80e0ef1166ba0ee81d4d594214", "raw": {"market": "0xaf9d0e448129a9f657f851d49495ba4742055d80e0ef1166ba0ee81d4d594214", "asset_id": "101676997363687199724245607342877036148401850938023978421879460310389391082353", "price": "0.978", "size": "6.7", "side": "SELL", "timestamp": "1768404590279", "received_at": "2026-01-14T16:29:49.962693"}}
{"event_type": "price_change", "event_ts": "2026-01-14T16:29:49.962704", "ingestion_ts": "2026-01-14T16:33:58.842229", "market_id": "0x9d24d9f9b5995949cb158d943793dea20bd448e1b3971cb6f7418bb15e719661", "raw": {"market": "0x9d24d9f9b5995949cb158d943793dea20bd448e1b3971cb6f7418bb15e719661", "asset_id": "79516121807256184736227920754945730465880754940725759201193439378549308939672", "price": "0.005", "size": "7.3", "side": "BUY", "timestamp": "1768404590279", "received_at": "2026-01-14T16:29:49.962704"}}
{"event_type": "price_change", "event_ts": "2026-01-14T16:29:49.962704", "ingestion_ts": "2026-01-14T16:33:58.842229", "market_id": "0x9d24d9f9b5995949cb158d943793dea20bd448e1b3971cb6f7418bb15e719661", "raw": {"market": "0x9d24d9f9b5995949cb158d943793dea20bd448e1b3971cb6f7418bb15e719661", "asset_id": "70512916946285526357165287373537570327431985324385225788636160168740471920430", "price": "0.995", "size": "7.3", "side": "SELL", "timestamp": "1768404590279", "received_at": "2026-01-14T16:29:49.962704"}}
{"event_type": "price_change", "event_ts": "2026-01-14T16:29:49.962714", "ingestion_ts": "2026-01-14T16:33:58.842229", "market_id": "0xaf9d0e448129a9f657f851d49495ba4742055d80e0ef1166ba0ee81d4d594214", "raw": {"market": "0xaf9d0e448129a9f657f851d49495ba4742055d80e0ef1166ba0ee81d4d594214", "asset_id": "4153292802911610701832309484716814274802943278345248636922528170020319407796", "price": "0.002", "size": "255.3", "side": "BUY", "timestamp": "1768404590280", "received_at": "2026-01-14T16:29:49.962714"}}
{"event_type": "price_change", "event_ts": "2026-01-14T16:29:49.962714", "ingestion_ts": "2026-01-14T16:33:58.842229", "market_id": "0xaf9d0e448129a9f657f851d49495ba4742055d80e0ef1166ba0ee81d4d594214", "raw": {"market": "0xaf9d0e448129a9f657f851d49495ba4742055d80e0ef1166ba0ee81d4d594214", "asset_id": "101676997363687199724245607342877036148401850938023978421879460310389391082353", "price": "0.998", "size": "255.3", "side": "SELL", "timestamp": "1768404590280", "received_at": "2026-01-14T16:29:49.962714"}}
{"event_type": "price_change", "event_ts": "2026-01-14T16:29:49.962725", "ingestion_ts": "2026-01-14T16:33:58.842229", "market_id": "0x44f08744458b8896620cd3330bc5e1ea69df4199b02d4fc583b3fc96e5d314ce", "raw": {"market": "0x44f08744458b8896620cd3330bc5e1ea69df4199b02d4fc583b3fc96e5d314ce", "asset_id": "72327831507226612545928776794104143393438710920370371172884559893525100761096", "price": "0.011", "size": "6.02", "side": "BUY", "timestamp": "1768404590280", "received_at": "2026-01-14T16:29:49.962725"}}
{"event_type": "price_change", "event_ts": "2026-01-14T16:29:49.962725", "ingestion_ts": "2026-01-14T16:33:58.842229", "market_id": "0x44f08744458b8896620cd3330bc5e1ea69df4199b02d4fc583b3fc96e5d314ce", "raw": {"market": "0x44f08744458b8896620cd3330bc5e1ea69df4199b02d4fc583b3fc96e5d314ce", "asset_id": "49194009556504828848509244326501559253829462790583873936160989575507522044057", "price": "0.989", "size": "6.02", "side": "SELL", "timestamp": "1768404590280", "received_at": "2026-01-14T16:29:49.962725"}}
{"event_type": "price_change", "event_ts": "2026-01-14T16:29:49.962735", "ingestion_ts": "2026-01-14T16:33:58.842229", "market_id": "0x9d24d9f9b5995949cb158d943793dea20bd448e1b3971cb6f7418bb15e719661", "raw": {"market": "0x9d24d9f9b5995949cb158d943793dea20bd448e1b3971cb6f7418bb15e719661", "asset_id": "79516121807256184736227920754945730465880754940725759201193439378549308939672", "price": "0.001", "size": "303582.62", "side": "BUY", "timestamp": "1768404590280", "received_at": "2026-01-14T16:29:49.962735"}}
{"event_type": "price_change", "event_ts": "2026-01-14T16:29:49.962735", "ingestion_ts": "2026-01-14T16:33:58.842229", "market_id": "0x9d24d9f9b5995949cb158d943793dea20bd448e1b3971cb6f7418bb15e719661", "raw": {"market": "0x9d24d9f9b5995949cb158d943793dea20bd448e1b3971cb6f7418bb15e719661", "asset_id": "70512916946285526357165287373537570327431985324385225788636160168740471920430", "price": "0.999", "size": "303582.62", "side": "SELL", "timestamp": "1768404590280", "received_at": "2026-01-14T16:29:49.962735"}}
{"event_type": "price_change", "event_ts": "2026-01-14T16:29:49.962748", "ingestion_ts": "2026-01-14T16:33:58.842229", "market_id": "0xaf9d0e448129a9f657f851d49495ba4742055d80e0ef1166ba0ee81d4d594214", "raw": {"market": "0xaf9d0e448129a9f657f851d49495ba4742055d80e0ef1166ba0ee81d4d594214", "asset_id": "4153292802911610701832309484716814274802943278345248636922528170020319407796", "price": "0.004", "size": "9.18", "side": "BUY", "timestamp": "1768404590280", "received_at": "2026-01-14T16:29:49.962748"}}
{"event_type": "price_change", "event_ts": "2026-01-14T16:29:49.962748", "ingestion_ts": "2026-01-14T16:33:58.842229", "market_id": "0xaf9d0e448129a9f657f851d49495ba4742055d80e0ef1166ba0ee81d4d594214", "raw": {"market": "0xaf9d0e448129a9f657f851d49495ba4742055d80e0ef1166ba0ee81d4d594214", "asset_id": "101676997363687199724245607342877036148401850938023978421879460310389391082353", "price": "0.996", "size": "9.18", "side": "SELL", "timestamp": "1768404590280", "received_at": "2026-01-14T16:29:49.962748"}}
{"event_type": "price_change", "event_ts": "2026-01-14T16:29:49.962760", "ingestion_ts": "2026-01-14T16:33:58.842229", "market_id": "0x44f08744458b8896620cd3330bc5e1ea69df4199b02d4fc583b3fc96e5d314ce", "raw": {"market": "0x44f08744458b8896620cd3330bc5e1ea69df4199b02d4fc583b3fc96e5d314ce", "asset_id": "72327831507226612545928776794104143393438710920370371172884559893525100761096", "price": "0.201", "size": "5.68", "side": "BUY", "timestamp": "1768404590281", "received_at": "2026-01-14T16:29:49.962760"}}
{"event_type": "price_change", "event_ts": "2026-01-14T16:29:49.962760", "ingestion_ts": "2026-01-14T16:33:58.842229", "market_id": "0x44f08744458b8896620cd3330bc5e1ea69df4199b02d4fc583b3fc96e5d314ce", "raw": {"market": "0x44f08744458b8896620cd3330bc5e1ea69df4199b02d4fc583b3fc96e5d314ce", "asset_id": "49194009556504828848509244326501559253829462790583873936160989575507522044057", "price": "0.799", "size": "5.68", "side": "SELL", "timestamp": "1768404590281", "received_at": "2026-01-14T16:29:49.962760"}}
{"event_type": "price_change", "event_ts": "2026-01-14T16:29:49.964950", "ingestion_ts": "2026-01-14T16:33:58.842229", "market_id": "0x44f08744458b8896620cd3330bc5e1ea69df4199b02d4fc583b3fc96e5d314ce", "raw": {"market": "0x44f08744458b8896620cd3330bc5e1ea69df4199b02d4fc583b3fc96e5d314ce", "asset_id": "72327831507226612545928776794104143393438710920370371172884559893525100761096", "price": "0.001", "size": "2630.98", "side": "BUY", "timestamp": "1768404590282", "received_at": "2026-01-14T16:29:49.964950"}}
{"event_type": "price_change", "event_ts": "2026-01-14T16:29:49.964950", "ingestion_ts": "2026-01-14T16:33:58.842229", "market_id": "0x44f08744458b8896620cd3330bc5e1ea69df4199b02d4fc583b3fc96e5d314ce", "raw": {"market": "0x44f08744458b8896620cd3330bc5e1ea69df4199b02d4fc583b3fc96e5d314ce", "asset_id": "49194009556504828848509244326501559253829462790583873936160989575507522044057", "price": "0.999", "size": "2630.98", "side": "SELL", "timestamp": "1768404590282", "received_at": "2026-01-14T16:29:49.964950"}}
{"event_type": "price_change", "event_ts": "2026-01-14T16:29:50.100704", "ingestion_ts": "2026-01-14T16:33:58.842229", "market_id": "0x2393ed0b0fdc450054c7b9071907eca75cf4fc36e385adf4a0a5f99ee62243e8", "raw": {"market": "0x2393ed0b0fdc450054c7b9071907eca75cf4fc36e385adf4a0a5f99ee62243e8", "asset_id": "32769749367306925959219403371425714180265458150646381231272229429098460625924", "price": "0.879", "size": "0", "side": "BUY", "timestamp": "1768404590419", "received_at": "2026-01-14T16:29:50.100704"}}
{"event_type": "price_change", "event_ts": "2026-01-14T16:29:50.100704", "ingestion_ts": "2026-01-14T16:33:58.842229", "market_id": "0x2393ed0b0fdc450054c7b9071907eca75cf4fc36e385adf4a0a5f99ee62243e8", "raw": {"market": "0x2393ed0b0fdc450054c7b9071907eca75cf4fc36e385adf4a0a5f99ee62243e8", "asset_id": "100074770378634056601572485653252702850363676459996771990439989989293515601975", "price": "0.121", "size": "0", "side": "SELL", "timestamp": "1768404590419", "received_at": "2026-01-14T16:29:50.100704"}}
{"event_type": "price_change", "event_ts": "2026-01-14T16:29:50.250318", "ingestion_ts": "2026-01-14T16:33:58.842229", "market_id": "0x2393ed0b0fdc450054c7b9071907eca75cf4fc36e385adf4a0a5f99ee62243e8", "raw": {"market": "0x2393ed0b0fdc450054c7b9071907eca75cf4fc36e385adf4a0a5f99ee62243e8", "asset_id": "32769749367306925959219403371425714180265458150646381231272229429098460625924", "price": "0.816", "size": "10", "side": "BUY", "timestamp": "1768404590558", "received_at": "2026-01-14T16:29:50.250318"}}
{"event_type": "price_change", "event_ts": "2026-01-14T16:29:50.250318", "ingestion_ts": "2026-01-14T16:33:58.842229", "market_id": "0x2393ed0b0fdc450054c7b9071907eca75cf4fc36e385adf4a0a5f99ee62243e8", "raw": {"market": "0x2393ed0b0fdc450054c7b9071907eca75cf4fc36e385adf4a0a5f99ee62243e8", "asset_id": "100074770378634056601572485653252702850363676459996771990439989989293515601975", "price": "0.184", "size": "10", "side": "SELL", "timestamp": "1768404590558", "received_at": "2026-01-14T16:29:50.250318"}}
{"event_type": "price_change", "event_ts": "2026-01-14T16:29:50.258588", "ingestion_ts": "2026-01-14T16:33:58.842229", "market_id": "0x2393ed0b0fdc450054c7b9071907eca75cf4fc36e385adf4a0a5f99ee62243e8", "raw": {"market": "0x2393ed0b0fdc450054c7b9071907eca75cf4fc36e385adf4a0a5f99ee62243e8", "asset_id": "32769749367306925959219403371425714180265458150646381231272229429098460625924", "price": "0.879", "size": "20", "side": "BUY", "timestamp": "1768404590560", "received_at": "2026-01-14T16:29:50.258588"}}
{"event_type": "price_change", "event_ts": "2026-01-14T16:29:50.258588", "ingestion_ts": "2026-01-14T16:33:58.842229", "market_id": "0x2393ed0b0fdc450054c7b9071907eca75cf4fc36e385adf4a0a5f99ee62243e8", "raw": {"market": "0x2393ed0b0fdc450054c7b9071907eca75cf4fc36e385adf4a0a5f99ee62243e8", "asset_id": "100074770378634056601572485653252702850363676459996771990439989989293515601975", "price": "0.121", "size": "20", "side": "SELL", "timestamp": "1768404590560", "received_at": "2026-01-14T16:29:50.258588"}}
{"event_type": "price_change", "event_ts": "2026-01-14T16:29:50.258613", "ingestion_ts": "2026-01-14T16:33:58.842229", "market_id": "0x2393ed0b0fdc450054c7b9071907eca75cf4fc36e385adf4a0a5f99ee62243e8", "raw": {"market": "0x2393ed0b0fdc450054c7b9071907eca75cf4fc36e385adf4a0a5f99ee62243e8", "asset_id": "32769749367306925959219403371425714180265458150646381231272229429098460625924", "price": "0.451", "size": "367", "side": "BUY", "timestamp": "1768404590561", "received_at": "2026-01-14T16:29:50.258613"}}
{"event_type": "price_change", "event_ts": "2026-01-14T16:29:50.258613", "ingestion_ts": "2026-01-14T16:33:58.842229", "market_id": "0x2393ed0b0fdc450054c7b9071907eca75cf4fc36e385adf4a0a5f99ee62243e8", "raw": {"market": "0x2393ed0b0fdc450054c7b9071907eca75cf4fc36e385adf4a0a5f99ee62243e8", "asset_id": "100074770378634056601572485653252702850363676459996771990439989989293515601975", "price": "0.549", "size": "367", "side": "SELL", "timestamp": "1768404590561", "received_at": "2026-01-14T16:29:50.258613"}}
{"event_type": "price_change", "event_ts": "2026-01-14T16:29:51.014438", "ingestion_ts": "2026-01-14T16:33:58.842229", "market_id": "0xb9bbdd34304344dcc45803780a34c97d73a00133a5ecf70f63e1008b8abb2fca", "raw": {"market": "0xb9bbdd34304344dcc45803780a34c97d73a00133a5ecf70f63e1008b8abb2fca", "asset_id": "8682484153073832526711485265636767086525069344085206423986003504588877767339", "price": "0.201", "size": "5.69", "side": "BUY", "timestamp": "1768404591323", "received_at": "2026-01-14T16:29:51.014438"}}
{"event_type": "price_change", "event_ts": "2026-01-14T16:29:51.014438", "ingestion_ts": "2026-01-14T16:33:58.842229", "market_id": "0xb9bbdd34304344dcc45803780a34c97d73a00133a5ecf70f63e1008b8abb2fca", "raw": {"market": "0xb9bbdd34304344dcc45803780a34c97d73a00133a5ecf70f63e1008b8abb2fca", "asset_id": "72012724360700510767037780555710363830014634797787940282136454146828040926557", "price": "0.799", "size": "5.69", "side": "SELL", "timestamp": "1768404591323", "received_at": "2026-01-14T16:29:51.014438"}}
{"event_type": "price_change", "event_ts": "2026-01-14T16:29:51.014471", "ingestion_ts": "2026-01-14T16:33:58.842229", "market_id": "0x50c669f178da4e5bbea7f1be25041fd278914712fa87a6a6f8e57d5923d88dee", "raw": {"market": "0x50c669f178da4e5bbea7f1be25041fd278914712fa87a6a6f8e57d5923d88dee", "asset_id": "74040420326294854165772767082819937451857852955603897473157746262672057685461", "price": "0.201", "size": "5.69", "side": "BUY", "timestamp": "1768404591323", "received_at": "2026-01-14T16:29:51.014471"}}
{"event_type": "price_change", "event_ts": "2026-01-14T16:29:51.014471", "ingestion_ts": "2026-01-14T16:33:58.842229", "market_id": "0x50c669f178da4e5bbea7f1be25041fd278914712fa87a6a6f8e57d5923d88dee", "raw": {"market": "0x50c669f178da4e5bbea7f1be25041fd278914712fa87a6a6f8e57d5923d88dee", "asset_id": "24682525479474221428144937281315825971983904267399062415430320764754931667953", "price": "0.799", "size": "5.69", "side": "SELL", "timestamp": "1768404591323", "received_at": "2026-01-14T16:29:51.014471"}}
{"event_type": "price_change", "event_ts": "2026-01-14T16:29:51.014489", "ingestion_ts": "2026-01-14T16:33:58.842229", "market_id": "0xb9bbdd34304344dcc45803780a34c97d73a00133a5ecf70f63e1008b8abb2fca", "raw": {"market": "0xb9bbdd34304344dcc45803780a34c97d73a00133a5ecf70f63e1008b8abb2fca", "asset_id": "8682484153073832526711485265636767086525069344085206423986003504588877767339", "price": "0.004", "size": "5.21", "side": "BUY", "timestamp": "1768404591323", "received_at": "2026-01-14T16:29:51.014489"}}
{"event_type": "price_change", "event_ts": "2026-01-14T16:29:51.014489", "ingestion_ts": "2026-01-14T16:33:58.842229", "market_id": "0xb9bbdd34304344dcc45803780a34c97d73a00133a5ecf70f63e1008b8abb2fca", "raw": {"market": "0xb9bbdd34304344dcc45803780a34c97d73a00133a5ecf70f63e1008b8abb2fca", "asset_id": "72012724360700510767037780555710363830014634797787940282136454146828040926557", "price": "0.996", "size": "5.21", "side": "SELL", "timestamp": "1768404591323", "received_at": "2026-01-14T16:29:51.014489"}}
{"event_type": "price_change", "event_ts": "2026-01-14T16:29:51.014504", "ingestion_ts": "2026-01-14T16:33:58.842229", "market_id": "0x50c669f178da4e5bbea7f1be25041fd278914712fa87a6a6f8e57d5923d88dee", "raw": {"market": "0x50c669f178da4e5bbea7f1be25041fd278914712fa87a6a6f8e57d5923d88dee", "asset_id": "74040420326294854165772767082819937451857852955603897473157746262672057685461", "price": "0.005", "size": "6.23", "side": "BUY", "timestamp": "1768404591324", "received_at": "2026-01-14T16:29:51.014504"}}
{"event_type": "price_change", "event_ts": "2026-01-14T16:29:51.014504", "ingestion_ts": "2026-01-14T16:33:58.842229", "market_id": "0x50c669f178da4e5bbea7f1be25041fd278914712fa87a6a6f8e57d5923d88dee", "raw": {"market": "0x50c669f178da4e5bbea7f1be25041fd278914712fa87a6a6f8e57d5923d88dee", "asset_id": "24682525479474221428144937281315825971983904267399062415430320764754931667953", "price": "0.995", "size": "6.23", "side": "SELL", "timestamp": "1768404591324", "received_at": "2026-01-14T16:29:51.014504"}}
{"event_type": "price_change", "event_ts": "2026-01-14T16:29:51.014517", "ingestion_ts": "2026-01-14T16:33:58.842229", "market_id": "0xb9bbdd34304344dcc45803780a34c97d73a00133a5ecf70f63e1008b8abb2fca", "raw": {"market": "0xb9bbdd34304344dcc45803780a34c97d73a00133a5ecf70f63e1008b8abb2fca", "asset_id": "8682484153073832526711485265636767086525069344085206423986003504588877767339", "price": "0.001", "size": "5103.59", "side": "BUY", "timestamp": "1768404591324", "received_at": "2026-01-14T16:29:51.014517"}}
{"event_type": "price_change", "event_ts": "2026-01-14T16:29:51.014517", "ingestion_ts": "2026-01-14T16:33:58.842229", "market_id": "0xb9bbdd34304344dcc45803780a34c97d73a00133a5ecf70f63e1008b8abb2fca", "raw": {"market": "0xb9bbdd34304344dcc45803780a34c97d73a00133a5ecf70f63e1008b8abb2fca", "asset_id": "72012724360700510767037780555710363830014634797787940282136454146828040926557", "price": "0.999", "size": "5103.59", "side": "SELL", "timestamp": "1768404591324", "received_at": "2026-01-14T16:29:51.014517"}}
{"event_type": "price_change", "event_ts": "2026-01-14T16:29:51.014527", "ingestion_ts": "2026-01-14T16:33:58.842229", "market_id": "0x50c669f178da4e5bbea7f1be25041fd278914712fa87a6a6f8e57d5923d88dee", "raw": {"market": "0x50c669f178da4e5bbea7f1be25041fd278914712fa87a6a6f8e57d5923d88dee", "asset_id": "74040420326294854165772767082819937451857852955603897473157746262672057685461", "price": "0.081", "size": "5.78", "side": "BUY", "timestamp": "1768404591324", "received_at": "2026-01-14T16:29:51.014527"}}
{"event_type": "price_change", "event_ts": "2026-01-14T16:29:51.014527", "ingestion_ts": "2026-01-14T16:33:58.842229", "market_id": "0x50c669f178da4e5bbea7f1be25041fd278914712fa87a6a6f8e57d5923d88dee", "raw": {"market": "0x50c669f178da4e5bbea7f1be25041fd278914712fa87a6a6f8e57d5923d88dee", "asset_id": "24682525479474221428144937281315825971983904267399062415430320764754931667953", "price": "0.919", "size": "5.78", "side": "SELL", "timestamp": "1768404591324", "received_at": "2026-01-14T16:29:51.014527"}}
{"event_type": "price_change", "event_ts": "2026-01-14T16:29:51.014538", "ingestion_ts": "2026-01-14T16:33:58.842229", "market_id": "0x50c669f178da4e5bbea7f1be25041fd278914712fa87a6a6f8e57d5923d88dee", "raw": {"market": "0x50c669f178da4e5bbea7f1be25041fd278914712fa87a6a6f8e57d5923d88dee", "asset_id": "74040420326294854165772767082819937451857852955603897473157746262672057685461", "price": "0.001", "size": "6167.15", "side": "BUY", "timestamp": "1768404591325", "received_at": "2026-01-14T16:29:51.014538"}}
{"event_type": "price_change", "event_ts": "2026-01-14T16:29:51.014538", "ingestion_ts": "2026-01-14T16:33:58.842229", "market_id": "0x50c669f178da4e5bbea7f1be25041fd278914712fa87a6a6f8e57d5923d88dee", "raw": {"market": "0x50c669f178da4e5bbea7f1be25041fd278914712fa87a6a6f8e57d5923d88dee", "asset_id": "24682525479474221428144937281315825971983904267399062415430320764754931667953", "price": "0.999", "size": "6167.15", "side": "SELL", "timestamp": "1768404591325", "received_at": "2026-01-14T16:29:51.014538"}}
{"event_type": "price_change", "event_ts": "2026-01-14T16:29:51.014548", "ingestion_ts": "2026-01-14T16:33:58.842229", "market_id": "0xb9bbdd34304344dcc45803780a34c97d73a00133a5ecf70f63e1008b8abb2fca", "raw": {"market": "0xb9bbdd34304344dcc45803780a34c97d73a00133a5ecf70f63e1008b8abb2fca", "asset_id": "8682484153073832526711485265636767086525069344085206423986003504588877767339", "price": "0.021", "size": "7.43", "side": "BUY", "timestamp": "1768404591325", "received_at": "2026-01-14T16:29:51.014548"}}
{"event_type": "price_change", "event_ts": "2026-01-14T16:29:51.014548", "ingestion_ts": "2026-01-14T16:33:58.842229", "market_id": "0xb9bbdd34304344dcc45803780a34c97d73a00133a5ecf70f63e1008b8abb2fca", "raw": {"market": "0xb9bbdd34304344dcc45803780a34c97d73a00133a5ecf70f63e1008b8abb2fca", "asset_id": "72012724360700510767037780555710363830014634797787940282136454146828040926557", "price": "0.979", "size": "7.43", "side": "SELL", "timestamp": "1768404591325", "received_at": "2026-01-14T16:29:51.014548"}}
{"event_type": "price_change", "event_ts": "2026-01-14T16:29:51.014557", "ingestion_ts": "2026-01-14T16:33:58.842229", "market_id": "0x50c669f178da4e5bbea7f1be25041fd278914712fa87a6a6f8e57d5923d88dee", "raw": {"market": "0x50c669f178da4e5bbea7f1be25041fd278914712fa87a6a6f8e57d5923d88dee", "asset_id": "74040420326294854165772767082819937451857852955603897473157746262672057685461", "price": "0.002", "size": "7.86", "side": "BUY", "timestamp": "1768404591326", "received_at": "2026-01-14T16:29:51.014557"}}
{"event_type": "price_change", "event_ts": "2026-01-14T16:29:51.014557", "ingestion_ts": "2026-01-14T16:33:58.842229", "market_id": "0x50c669f178da4e5bbea7f1be25041fd278914712fa87a6a6f8e57d5923d88dee", "raw": {"market": "0x50c669f178da4e5bbea7f1be25041fd278914712fa87a6a6f8e57d5923d88dee", "asset_id": "24682525479474221428144937281315825971983904267399062415430320764754931667953", "price": "0.998", "size": "7.86", "side": "SELL", "timestamp": "1768404591326", "received_at": "2026-01-14T16:29:51.014557"}}
{"event_type": "price_change", "event_ts": "2026-01-14T16:29:51.014566", "ingestion_ts": "2026-01-14T16:33:58.842229", "market_id": "0xb9bbdd34304344dcc45803780a34c97d73a00133a5ecf70f63e1008b8abb2fca", "raw": {"market": "0xb9bbdd34304344dcc45803780a34c97d73a00133a5ecf70f63e1008b8abb2fca", "asset_id": "8682484153073832526711485265636767086525069344085206423986003504588877767339", "price": "0.002", "size": "5.24", "side": "BUY", "timestamp": "1768404591326", "received_at": "2026-01-14T16:29:51.014566"}}
{"event_type": "price_change", "event_ts": "2026-01-14T16:29:51.014566", "ingestion_ts": "2026-01-14T16:33:58.842229", "market_id": "0xb9bbdd34304344dcc45803780a34c97d73a00133a5ecf70f63e1008b8abb2fca", "raw": {"market": "0xb9bbdd34304344dcc45803780a34c97d73a00133a5ecf70f63e1008b8abb2fca", "asset_id": "72012724360700510767037780555710363830014634797787940282136454146828040926557", "price": "0.998", "size": "5.24", "side": "SELL", "timestamp": "1768404591326", "received_at": "2026-01-14T16:29:51.014566"}}
{"event_type": "price_change", "event_ts": "2026-01-14T16:29:51.014576", "ingestion_ts": "2026-01-14T16:33:58.842229", "market_id": "0x50c669f178da4e5bbea7f1be25041fd278914712fa87a6a6f8e57d5923d88dee", "raw": {"market": "0x50c669f178da4e5bbea7f1be25041fd278914712fa87a6a6f8e57d5923d88dee", "asset_id": "74040420326294854165772767082819937451857852955603897473157746262672057685461", "price": "0.03", "size": "7.96", "side": "BUY", "timestamp": "1768404591327", "received_at": "2026-01-14T16:29:51.014576"}}
{"event_type": "price_change", "event_ts": "2026-01-14T16:29:51.014576", "ingestion_ts": "2026-01-14T16:33:58.842229", "market_id": "0x50c669f178da4e5bbea7f1be25041fd278914712fa87a6a6f8e57d5923d88dee", "raw": {"market": "0x50c669f178da4e5bbea7f1be25041fd278914712fa87a6a6f8e57d5923d88dee", "asset_id": "24682525479474221428144937281315825971983904267399062415430320764754931667953", "price": "0.97", "size": "7.96", "side": "SELL", "timestamp": "1768404591327", "received_at": "2026-01-14T16:29:51.014576"}}
{"event_type": "price_change", "event_ts": "2026-01-14T16:29:51.014585", "ingestion_ts": "2026-01-14T16:33:58.842229", "market_id": "0xb9bbdd34304344dcc45803780a34c97d73a00133a5ecf70f63e1008b8abb2fca", "raw": {"market": "0xb9bbdd34304344dcc45803780a34c97d73a00133a5ecf70f63e1008b8abb2fca", "asset_id": "8682484153073832526711485265636767086525069344085206423986003504588877767339", "price": "0.008", "size": "8.32", "side": "BUY", "timestamp": "1768404591327", "received_at": "2026-01-14T16:29:51.014585"}}
{"event_type": "price_change", "event_ts": "2026-01-14T16:29:51.014585", "ingestion_ts": "2026-01-14T16:33:58.842229", "market_id": "0xb9bbdd34304344dcc45803780a34c97d73a00133a5ecf70f63e1008b8abb2fca", "raw": {"market": "0xb9bbdd34304344dcc45803780a34c97d73a00133a5ecf70f63e1008b8abb2fca", "asset_id": "72012724360700510767037780555710363830014634797787940282136454146828040926557", "price": "0.992", "size": "8.32", "side": "SELL", "timestamp": "1768404591327", "received_at": "2026-01-14T16:29:51.014585"}}
{"event_type": "price_change", "event_ts": "2026-01-14T16:29:51.014595", "ingestion_ts": "2026-01-14T16:33:58.842229", "market_id": "0xb9bbdd34304344dcc45803780a34c97d73a00133a5ecf70f63e1008b8abb2fca", "raw": {"market": "0xb9bbdd34304344dcc45803780a34c97d73a00133a5ecf70f63e1008b8abb2fca", "asset_id": "8682484153073832526711485265636767086525069344085206423986003504588877767339", "price": "0.053", "size": "11.24", "side": "BUY", "timestamp": "1768404591328", "received_at": "2026-01-14T16:29:51.014595"}}
{"event_type": "price_change", "event_ts": "2026-01-14T16:29:51.014595", "ingestion_ts": "2026-01-14T16:33:58.842229", "market_id": "0xb9bbdd34304344dcc45803780a34c97d73a00133a5ecf70f63e1008b8abb2fca", "raw": {"market": "0xb9bbdd34304344dcc45803780a34c97d73a00133a5ecf70f63e1008b8abb2fca", "asset_id": "72012724360700510767037780555710363830014634797787940282136454146828040926557", "price": "0.947", "size": "11.24", "side": "SELL", "timestamp": "1768404591328", "received_at": "2026-01-14T16:29:51.014595"}}
{"event_type": "price_change", "event_ts": "2026-01-14T16:29:51.014604", "ingestion_ts": "2026-01-14T16:33:58.842229", "market_id": "0x50c669f178da4e5bbea7f1be25041fd278914712fa87a6a6f8e57d5923d88dee", "raw": {"market": "0x50c669f178da4e5bbea7f1be25041fd278914712fa87a6a6f8e57d5923d88dee", "asset_id": "74040420326294854165772767082819937451857852955603897473157746262672057685461", "price": "0.011", "size": "8.73", "side": "BUY", "timestamp": "1768404591328", "received_at": "2026-01-14T16:29:51.014604"}}
{"event_type": "price_change", "event_ts": "2026-01-14T16:29:51.014604", "ingestion_ts": "2026-01-14T16:33:58.842229", "market_id": "0x50c669f178da4e5bbea7f1be25041fd278914712fa87a6a6f8e57d5923d88dee", "raw": {"market": "0x50c669f178da4e5bbea7f1be25041fd278914712fa87a6a6f8e57d5923d88dee", "asset_id": "24682525479474221428144937281315825971983904267399062415430320764754931667953", "price": "0.989", "size": "8.73", "side": "SELL", "timestamp": "1768404591328", "received_at": "2026-01-14T16:29:51.014604"}}
{"event_type": "price_change", "event_ts": "2026-01-14T16:29:52.179845", "ingestion_ts": "2026-01-14T16:33:58.842229", "market_id": "0xc55db914f0fd1fee18997706712c0dfd8d0369cdbef93a9fef12bd001914ca77", "raw": {"market": "0xc55db914f0fd1fee18997706712c0dfd8d0369cdbef93a9fef12bd001914ca77", "asset_id": "114600293444080540179603459515770723592661967180480327891296353898330242622833", "price": "0.002", "size": "13.08", "side": "BUY", "timestamp": "1768404592499", "received_at": "2026-01-14T16:29:52.179845"}}
{"event_type": "price_change", "event_ts": "2026-01-14T16:29:52.179845", "ingestion_ts": "2026-01-14T16:33:58.842229", "market_id": "0xc55db914f0fd1fee18997706712c0dfd8d0369cdbef93a9fef12bd001914ca77", "raw": {"market": "0xc55db914f0fd1fee18997706712c0dfd8d0369cdbef93a9fef12bd001914ca77", "asset_id": "72354723612769247426741660426331235762851940382312402276325808095604519806766", "price": "0.998", "size": "13.08", "side": "SELL", "timestamp": "1768404592499", "received_at": "2026-01-14T16:29:52.179845"}}
{"event_type": "price_change", "event_ts": "2026-01-14T16:29:52.179883", "ingestion_ts": "2026-01-14T16:33:58.842229", "market_id": "0x49a20c7523c271099008f3ef9a31521263b24d637959852a391e6b4697b1a437", "raw": {"market": "0x49a20c7523c271099008f3ef9a31521263b24d637959852a391e6b4697b1a437", "asset_id": "55881023621710858558280545117465775643848233756850602339827152783696837905531", "price": "0.051", "size": "11.87", "side": "BUY", "timestamp": "1768404592499", "received_at": "2026-01-14T16:29:52.179883"}}
{"event_type": "price_change", "event_ts": "2026-01-14T16:29:52.179883", "ingestion_ts": "2026-01-14T16:33:58.842229", "market_id": "0x49a20c7523c271099008f3ef9a31521263b24d637959852a391e6b4697b1a437", "raw": {"market": "0x49a20c7523c271099008f3ef9a31521263b24d637959852a391e6b4697b1a437", "asset_id": "13018971792603393862521629014128024641178044618205296260525674415067194037856", "price": "0.949", "size": "11.87", "side": "SELL", "timestamp": "1768404592499", "received_at": "2026-01-14T16:29:52.179883"}}
{"event_type": "price_change", "event_ts": "2026-01-14T16:29:52.179899", "ingestion_ts": "2026-01-14T16:33:58.842229", "market_id": "0x49a20c7523c271099008f3ef9a31521263b24d637959852a391e6b4697b1a437", "raw": {"market": "0x49a20c7523c271099008f3ef9a31521263b24d637959852a391e6b4697b1a437", "asset_id": "55881023621710858558280545117465775643848233756850602339827152783696837905531", "price": "0.201", "size": "5.69", "side": "BUY", "timestamp": "1768404592500", "received_at": "2026-01-14T16:29:52.179899"}}
{"event_type": "price_change", "event_ts": "2026-01-14T16:29:52.179899", "ingestion_ts": "2026-01-14T16:33:58.842229", "market_id": "0x49a20c7523c271099008f3ef9a31521263b24d637959852a391e6b4697b1a437", "raw": {"market": "0x49a20c7523c271099008f3ef9a31521263b24d637959852a391e6b4697b1a437", "asset_id": "13018971792603393862521629014128024641178044618205296260525674415067194037856", "price": "0.799", "size": "5.69", "side": "SELL", "timestamp": "1768404592500", "received_at": "2026-01-14T16:29:52.179899"}}
{"event_type": "price_change", "event_ts": "2026-01-14T16:29:52.179913", "ingestion_ts": "2026-01-14T16:33:58.842229", "market_id": "0xc55db914f0fd1fee18997706712c0dfd8d0369cdbef93a9fef12bd001914ca77", "raw": {"market": "0xc55db914f0fd1fee18997706712c0dfd8d0369cdbef93a9fef12bd001914ca77", "asset_id": "114600293444080540179603459515770723592661967180480327891296353898330242622833", "price": "0.007", "size": "10.25", "side": "BUY", "timestamp": "1768404592500", "received_at": "2026-01-14T16:29:52.179913"}}
{"event_type": "price_change", "event_ts": "2026-01-14T16:29:52.179913", "ingestion_ts": "2026-01-14T16:33:58.842229", "market_id": "0xc55db914f0fd1fee18997706712c0dfd8d0369cdbef93a9fef12bd001914ca77", "raw": {"market": "0xc55db914f0fd1fee18997706712c0dfd8d0369cdbef93a9fef12bd001914ca77", "asset_id": "72354723612769247426741660426331235762851940382312402276325808095604519806766", "price": "0.993", "size": "10.25", "side": "SELL", "timestamp": "1768404592500", "received_at": "2026-01-14T16:29:52.179913"}}
{"event_type": "price_change", "event_ts": "2026-01-14T16:29:52.179924", "ingestion_ts": "2026-01-14T16:33:58.842229", "market_id": "0x49a20c7523c271099008f3ef9a31521263b24d637959852a391e6b4697b1a437", "raw": {"market": "0x49a20c7523c271099008f3ef9a31521263b24d637959852a391e6b4697b1a437", "asset_id": "55881023621710858558280545117465775643848233756850602339827152783696837905531", "price": "0.011", "size": "6.46", "side": "BUY", "timestamp": "1768404592500", "received_at": "2026-01-14T16:29:52.179924"}}
{"event_type": "price_change", "event_ts": "2026-01-14T16:29:52.179924", "ingestion_ts": "2026-01-14T16:33:58.842229", "market_id": "0x49a20c7523c271099008f3ef9a31521263b24d637959852a391e6b4697b1a437", "raw": {"market": "0x49a20c7523c271099008f3ef9a31521263b24d637959852a391e6b4697b1a437", "asset_id": "13018971792603393862521629014128024641178044618205296260525674415067194037856", "price": "0.989", "size": "6.46", "side": "SELL", "timestamp": "1768404592500", "received_at": "2026-01-14T16:29:52.179924"}}
{"event_type": "price_change", "event_ts": "2026-01-14T16:29:52.179935", "ingestion_ts": "2026-01-14T16:33:58.842229", "market_id": "0xc55db914f0fd1fee18997706712c0dfd8d0369cdbef93a9fef12bd001914ca77", "raw": {"market": "0xc55db914f0fd1fee18997706712c0dfd8d0369cdbef93a9fef12bd001914ca77", "asset_id": "114600293444080540179603459515770723592661967180480327891296353898330242622833", "price": "0.001", "size": "8574.77", "side": "BUY", "timestamp": "1768404592501", "received_at": "2026-01-14T16:29:52.179935"}}
{"event_type": "price_change", "event_ts": "2026-01-14T16:29:52.179935", "ingestion_ts": "2026-01-14T16:33:58.842229", "market_id": "0xc55db914f0fd1fee18997706712c0dfd8d0369cdbef93a9fef12bd001914ca77", "raw": {"market": "0xc55db914f0fd1fee18997706712c0dfd8d0369cdbef93a9fef12bd001914ca77", "asset_id": "72354723612769247426741660426331235762851940382312402276325808095604519806766", "price": "0.999", "size": "8574.77", "side": "SELL", "timestamp": "1768404592501", "received_at": "2026-01-14T16:29:52.179935"}}
{"event_type": "price_change", "event_ts": "2026-01-14T16:29:52.179946", "ingestion_ts": "2026-01-14T16:33:58.842229", "market_id": "0x49a20c7523c271099008f3ef9a31521263b24d637959852a391e6b4697b1a437", "raw": {"market": "0x49a20c7523c271099008f3ef9a31521263b24d637959852a391e6b4697b1a437", "asset_id": "55881023621710858558280545117465775643848233756850602339827152783696837905531", "price": "0.004", "size": "9.09", "side": "BUY", "timestamp": "1768404592501", "received_at": "2026-01-14T16:29:52.179946"}}
{"event_type": "price_change", "event_ts": "2026-01-14T16:29:52.179946", "ingestion_ts": "2026-01-14T16:33:58.842229", "market_id": "0x49a20c7523c271099008f3ef9a31521263b24d637959852a391e6b4697b1a437", "raw": {"market": "0x49a20c7523c271099008f3ef9a31521263b24d637959852a391e6b4697b1a437", "asset_id": "13018971792603393862521629014128024641178044618205296260525674415067194037856", "price": "0.996", "size": "9.09", "side": "SELL", "timestamp": "1768404592501", "received_at": "2026-01-14T16:29:52.179946"}}
{"event_type": "price_change", "event_ts": "2026-01-14T16:29:52.179956", "ingestion_ts": "2026-01-14T16:33:58.842229", "market_id": "0xc55db914f0fd1fee18997706712c0dfd8d0369cdbef93a9fef12bd001914ca77", "raw": {"market": "0xc55db914f0fd1fee18997706712c0dfd8d0369cdbef93a9fef12bd001914ca77", "asset_id": "114600293444080540179603459515770723592661967180480327891296353898330242622833", "price": "0.021", "size": "7.2", "side": "BUY", "timestamp": "1768404592502", "received_at": "2026-01-14T16:29:52.179956"}}
{"event_type": "price_change", "event_ts": "2026-01-14T16:29:52.179956", "ingestion_ts": "2026-01-14T16:33:58.842229", "market_id": "0xc55db914f0fd1fee18997706712c0dfd8d0369cdbef93a9fef12bd001914ca77", "raw": {"market": "0xc55db914f0fd1fee18997706712c0dfd8d0369cdbef93a9fef12bd001914ca77", "asset_id": "72354723612769247426741660426331235762851940382312402276325808095604519806766", "price": "0.979", "size": "7.2", "side": "SELL", "timestamp": "1768404592502", "received_at": "2026-01-14T16:29:52.179956"}}
{"event_type": "price_change", "event_ts": "2026-01-14T16:29:52.179971", "ingestion_ts": "2026-01-14T16:33:58.842229", "market_id": "0x49a20c7523c271099008f3ef9a31521263b24d637959852a391e6b4697b1a437", "raw": {"market": "0x49a20c7523c271099008f3ef9a31521263b24d637959852a391e6b4697b1a437", "asset_id": "55881023621710858558280545117465775643848233756850602339827152783696837905531", "price": "0.002", "size": "5.25", "side": "BUY", "timestamp": "1768404592502", "received_at": "2026-01-14T16:29:52.179971"}}
{"event_type": "price_change", "event_ts": "2026-01-14T16:29:52.179971", "ingestion_ts": "2026-01-14T16:33:58.842229", "market_id": "0x49a20c7523c271099008f3ef9a31521263b24d637959852a391e6b4697b1a437", "raw": {"market": "0x49a20c7523c271099008f3ef9a31521263b24d637959852a391e6b4697b1a437", "asset_id": "13018971792603393862521629014128024641178044618205296260525674415067194037856", "price": "0.998", "size": "5.25", "side": "SELL", "timestamp": "1768404592502", "received_at": "2026-01-14T16:29:52.179971"}}
{"event_type": "price_change", "event_ts": "2026-01-14T16:29:52.179982", "ingestion_ts": "2026-01-14T16:33:58.842229", "market_id": "0xc55db914f0fd1fee18997706712c0dfd8d0369cdbef93a9fef12bd001914ca77", "raw": {"market": "0xc55db914f0fd1fee18997706712c0dfd8d0369cdbef93a9fef12bd001914ca77", "asset_id": "114600293444080540179603459515770723592661967180480327891296353898330242622833", "price": "0.201", "size": "5.69", "side": "BUY", "timestamp": "1768404592502", "received_at": "2026-01-14T16:29:52.179982"}}
{"event_type": "price_change", "event_ts": "2026-01-14T16:29:52.179982", "ingestion_ts": "2026-01-14T16:33:58.842229", "market_id": "0xc55db914f0fd1fee18997706712c0dfd8d0369cdbef93a9fef12bd001914ca77", "raw": {"market": "0xc55db914f0fd1fee18997706712c0dfd8d0369cdbef93a9fef12bd001914ca77", "asset_id": "72354723612769247426741660426331235762851940382312402276325808095604519806766", "price": "0.799", "size": "5.69", "side": "SELL", "timestamp": "1768404592502", "received_at": "2026-01-14T16:29:52.179982"}}
{"event_type": "price_change", "event_ts": "2026-01-14T16:29:52.179993", "ingestion_ts": "2026-01-14T16:33:58.842229", "market_id": "0x49a20c7523c271099008f3ef9a31521263b24d637959852a391e6b4697b1a437", "raw": {"market": "0x49a20c7523c271099008f3ef9a31521263b24d637959852a391e6b4697b1a437", "asset_id": "55881023621710858558280545117465775643848233756850602339827152783696837905531", "price": "0.001", "size": "5669.67", "side": "BUY", "timestamp": "1768404592503", "received_at": "2026-01-14T16:29:52.179993"}}
{"event_type": "price_change", "event_ts": "2026-01-14T16:29:52.179993", "ingestion_ts": "2026-01-14T16:33:58.842229", "market_id": "0x49a20c7523c271099008f3ef9a31521263b24d637959852a391e6b4697b1a437", "raw": {"market": "0x49a20c7523c271099008f3ef9a31521263b24d637959852a391e6b4697b1a437", "asset_id": "13018971792603393862521629014128024641178044618205296260525674415067194037856", "price": "0.999", "size": "5669.67", "side": "SELL", "timestamp": "1768404592503", "received_at": "2026-01-14T16:29:52.179993"}}
{"event_type": "price_change", "event_ts": "2026-01-14T16:29:52.180004", "ingestion_ts": "2026-01-14T16:33:58.842229", "market_id": "0xc55db914f0fd1fee18997706712c0dfd8d0369cdbef93a9fef12bd001914ca77", "raw": {"market": "0xc55db914f0fd1fee18997706712c0dfd8d0369cdbef93a9fef12bd001914ca77", "asset_id": "114600293444080540179603459515770723592661967180480327891296353898330242622833", "price": "0.052", "size": "11.55", "side": "BUY", "timestamp": "1768404592503", "received_at": "2026-01-14T16:29:52.180004"}}
{"event_type": "price_change", "event_ts": "2026-01-14T16:29:52.180004", "ingestion_ts": "2026-01-14T16:33:58.842229", "market_id": "0xc55db914f0fd1fee18997706712c0dfd8d0369cdbef93a9fef12bd001914ca77", "raw": {"market": "0xc55db914f0fd1fee18997706712c0dfd8d0369cdbef93a9fef12bd001914ca77", "asset_id": "72354723612769247426741660426331235762851940382312402276325808095604519806766", "price": "0.948", "size": "11.55", "side": "SELL", "timestamp": "1768404592503", "received_at": "2026-01-14T16:29:52.180004"}}
{"event_type": "price_change", "event_ts": "2026-01-14T16:29:52.180015", "ingestion_ts": "2026-01-14T16:33:58.842229", "market_id": "0x49a20c7523c271099008f3ef9a31521263b24d637959852a391e6b4697b1a437", "raw": {"market": "0x49a20c7523c271099008f3ef9a31521263b24d637959852a391e6b4697b1a437", "asset_id": "55881023621710858558280545117465775643848233756850602339827152783696837905531", "price": "0.025", "size": "5.06", "side": "BUY", "timestamp": "1768404592504", "received_at": "2026-01-14T16:29:52.180015"}}
{"event_type": "price_change", "event_ts": "2026-01-14T16:29:52.180015", "ingestion_ts": "2026-01-14T16:33:58.842229", "market_id": "0x49a20c7523c271099008f3ef9a31521263b24d637959852a391e6b4697b1a437", "raw": {"market": "0x49a20c7523c271099008f3ef9a31521263b24d637959852a391e6b4697b1a437", "asset_id": "13018971792603393862521629014128024641178044618205296260525674415067194037856", "price": "0.975", "size": "5.06", "side": "SELL", "timestamp": "1768404592504", "received_at": "2026-01-14T16:29:52.180015"}}
{"event_type": "price_change", "event_ts": "2026-01-14T16:30:14.293760", "ingestion_ts": "2026-01-14T16:33:58.842229", "market_id": "0x318b222c1435b47c338e66ca6001f782711186a488ae7b7248f7edc6ff076a83", "raw": {"market": "0x318b222c1435b47c338e66ca6001f782711186a488ae7b7248f7edc6ff076a83", "asset_id": "63773739594775606083258239254748928077067768053882704658119720069071630213026", "price": "0.021", "size": "0", "side": "BUY", "timestamp": "1768404614590", "received_at": "2026-01-14T16:30:14.293760"}}
{"event_type": "price_change", "event_ts": "2026-01-14T16:30:14.293760", "ingestion_ts": "2026-01-14T16:33:58.842229", "market_id": "0x318b222c1435b47c338e66ca6001f782711186a488ae7b7248f7edc6ff076a83", "raw": {"market": "0x318b222c1435b47c338e66ca6001f782711186a488ae7b7248f7edc6ff076a83", "asset_id": "56738600572035832904895845056468792275697823297413384908752239327866518310010", "price": "0.979", "size": "0", "side": "SELL", "timestamp": "1768404614590", "received_at": "2026-01-14T16:30:14.293760"}}
{"event_type": "price_change", "event_ts": "2026-01-14T16:30:14.293795", "ingestion_ts": "2026-01-14T16:33:58.842229", "market_id": "0x318b222c1435b47c338e66ca6001f782711186a488ae7b7248f7edc6ff076a83", "raw": {"market": "0x318b222c1435b47c338e66ca6001f782711186a488ae7b7248f7edc6ff076a83", "asset_id": "63773739594775606083258239254748928077067768053882704658119720069071630213026", "price": "0.003", "size": "2300", "side": "BUY", "timestamp": "1768404614590", "received_at": "2026-01-14T16:30:14.293795"}}
{"event_type": "price_change", "event_ts": "2026-01-14T16:30:14.293795", "ingestion_ts": "2026-01-14T16:33:58.842229", "market_id": "0x318b222c1435b47c338e66ca6001f782711186a488ae7b7248f7edc6ff076a83", "raw": {"market": "0x318b222c1435b47c338e66ca6001f782711186a488ae7b7248f7edc6ff076a83", "asset_id": "56738600572035832904895845056468792275697823297413384908752239327866518310010", "price": "0.997", "size": "2300", "side": "SELL", "timestamp": "1768404614590", "received_at": "2026-01-14T16:30:14.293795"}}
{"event_type": "price_change", "event_ts": "2026-01-14T16:30:14.293810", "ingestion_ts": "2026-01-14T16:33:58.842229", "market_id": "0x318b222c1435b47c338e66ca6001f782711186a488ae7b7248f7edc6ff076a83", "raw": {"market": "0x318b222c1435b47c338e66ca6001f782711186a488ae7b7248f7edc6ff076a83", "asset_id": "63773739594775606083258239254748928077067768053882704658119720069071630213026", "price": "0.101", "size": "0", "side": "BUY", "timestamp": "1768404614590", "received_at": "2026-01-14T16:30:14.293810"}}
{"event_type": "price_change", "event_ts": "2026-01-14T16:30:14.293810", "ingestion_ts": "2026-01-14T16:33:58.842229", "market_id": "0x318b222c1435b47c338e66ca6001f782711186a488ae7b7248f7edc6ff076a83", "raw": {"market": "0x318b222c1435b47c338e66ca6001f782711186a488ae7b7248f7edc6ff076a83", "asset_id": "56738600572035832904895845056468792275697823297413384908752239327866518310010", "price": "0.899", "size": "0", "side": "SELL", "timestamp": "1768404614590", "received_at": "2026-01-14T16:30:14.293810"}}
{"event_type": "price_change", "event_ts": "2026-01-14T16:30:14.293823", "ingestion_ts": "2026-01-14T16:33:58.842229", "market_id": "0x318b222c1435b47c338e66ca6001f782711186a488ae7b7248f7edc6ff076a83", "raw": {"market": "0x318b222c1435b47c338e66ca6001f782711186a488ae7b7248f7edc6ff076a83", "asset_id": "63773739594775606083258239254748928077067768053882704658119720069071630213026", "price": "0.007", "size": "0", "side": "BUY", "timestamp": "1768404614590", "received_at": "2026-01-14T16:30:14.293823"}}
{"event_type": "price_change", "event_ts": "2026-01-14T16:30:14.293823", "ingestion_ts": "2026-01-14T16:33:58.842229", "market_id": "0x318b222c1435b47c338e66ca6001f782711186a488ae7b7248f7edc6ff076a83", "raw": {"market": "0x318b222c1435b47c338e66ca6001f782711186a488ae7b7248f7edc6ff076a83", "asset_id": "56738600572035832904895845056468792275697823297413384908752239327866518310010", "price": "0.993", "size": "0", "side": "SELL", "timestamp": "1768404614590", "received_at": "2026-01-14T16:30:14.293823"}}
{"event_type": "price_change", "event_ts": "2026-01-14T16:30:14.293835", "ingestion_ts": "2026-01-14T16:33:58.842229", "market_id": "0x318b222c1435b47c338e66ca6001f782711186a488ae7b7248f7edc6ff076a83", "raw": {"market": "0x318b222c1435b47c338e66ca6001f782711186a488ae7b7248f7edc6ff076a83", "asset_id": "63773739594775606083258239254748928077067768053882704658119720069071630213026", "price": "0.001", "size": "3119.98", "side": "BUY", "timestamp": "1768404614590", "received_at": "2026-01-14T16:30:14.293835"}}
{"event_type": "price_change", "event_ts": "2026-01-14T16:30:14.293835", "ingestion_ts": "2026-01-14T16:33:58.842229", "market_id": "0x318b222c1435b47c338e66ca6001f782711186a488ae7b7248f7edc6ff076a83", "raw": {"market": "0x318b222c1435b47c338e66ca6001f782711186a488ae7b7248f7edc6ff076a83", "asset_id": "56738600572035832904895845056468792275697823297413384908752239327866518310010", "price": "0.999", "size": "3119.98", "side": "SELL", "timestamp": "1768404614590", "received_at": "2026-01-14T16:30:14.293835"}}
{"event_type": "price_change", "event_ts": "2026-01-14T16:30:14.293874", "ingestion_ts": "2026-01-14T16:33:58.842229", "market_id": "0xc0e6b917320a47228fb96e3b5ae0e5c93773a5ae2662ae4e1f37807cfe47ce98", "raw": {"market": "0xc0e6b917320a47228fb96e3b5ae0e5c93773a5ae2662ae4e1f37807cfe47ce98", "asset_id": "58656358377246279051017109359677190749228949103591068167284263961542487110215", "price": "0.004", "size": "0", "side": "BUY", "timestamp": "1768404614589", "received_at": "2026-01-14T16:30:14.293874"}}
{"event_type": "price_change", "event_ts": "2026-01-14T16:30:14.293874", "ingestion_ts": "2026-01-14T16:33:58.842229", "market_id": "0xc0e6b917320a47228fb96e3b5ae0e5c93773a5ae2662ae4e1f37807cfe47ce98", "raw": {"market": "0xc0e6b917320a47228fb96e3b5ae0e5c93773a5ae2662ae4e1f37807cfe47ce98", "asset_id": "81647294538046680798858716589766492074338758116170717123345952330712416337530", "price": "0.996", "size": "0", "side": "SELL", "timestamp": "1768404614589", "received_at": "2026-01-14T16:30:14.293874"}}
{"event_type": "price_change", "event_ts": "2026-01-14T16:30:14.293888", "ingestion_ts": "2026-01-14T16:33:58.842229", "market_id": "0xc0e6b917320a47228fb96e3b5ae0e5c93773a5ae2662ae4e1f37807cfe47ce98", "raw": {"market": "0xc0e6b917320a47228fb96e3b5ae0e5c93773a5ae2662ae4e1f37807cfe47ce98", "asset_id": "58656358377246279051017109359677190749228949103591068167284263961542487110215", "price": "0.006", "size": "8.08", "side": "BUY", "timestamp": "1768404614589", "received_at": "2026-01-14T16:30:14.293888"}}
{"event_type": "price_change", "event_ts": "2026-01-14T16:30:14.293888", "ingestion_ts": "2026-01-14T16:33:58.842229", "market_id": "0xc0e6b917320a47228fb96e3b5ae0e5c93773a5ae2662ae4e1f37807cfe47ce98", "raw": {"market": "0xc0e6b917320a47228fb96e3b5ae0e5c93773a5ae2662ae4e1f37807cfe47ce98", "asset_id": "81647294538046680798858716589766492074338758116170717123345952330712416337530", "price": "0.994", "size": "8.08", "side": "SELL", "timestamp": "1768404614589", "received_at": "2026-01-14T16:30:14.293888"}}
{"event_type": "price_change", "event_ts": "2026-01-14T16:30:14.293900", "ingestion_ts": "2026-01-14T16:33:58.842229", "market_id": "0xc0e6b917320a47228fb96e3b5ae0e5c93773a5ae2662ae4e1f37807cfe47ce98", "raw": {"market": "0xc0e6b917320a47228fb96e3b5ae0e5c93773a5ae2662ae4e1f37807cfe47ce98", "asset_id": "58656358377246279051017109359677190749228949103591068167284263961542487110215", "price": "0.008", "size": "0", "side": "BUY", "timestamp": "1768404614589", "received_at": "2026-01-14T16:30:14.293900"}}
{"event_type": "price_change", "event_ts": "2026-01-14T16:30:14.293900", "ingestion_ts": "2026-01-14T16:33:58.842229", "market_id": "0xc0e6b917320a47228fb96e3b5ae0e5c93773a5ae2662ae4e1f37807cfe47ce98", "raw": {"market": "0xc0e6b917320a47228fb96e3b5ae0e5c93773a5ae2662ae4e1f37807cfe47ce98", "asset_id": "81647294538046680798858716589766492074338758116170717123345952330712416337530", "price": "0.992", "size": "0", "side": "SELL", "timestamp": "1768404614589", "received_at": "2026-01-14T16:30:14.293900"}}
{"event_type": "price_change", "event_ts": "2026-01-14T16:30:14.305001", "ingestion_ts": "2026-01-14T16:33:58.842229", "market_id": "0xc0e6b917320a47228fb96e3b5ae0e5c93773a5ae2662ae4e1f37807cfe47ce98", "raw": {"market": "0xc0e6b917320a47228fb96e3b5ae0e5c93773a5ae2662ae4e1f37807cfe47ce98", "asset_id": "58656358377246279051017109359677190749228949103591068167284263961542487110215", "price": "0.009", "size": "0", "side": "BUY", "timestamp": "1768404614589", "received_at": "2026-01-14T16:30:14.305001"}}
{"event_type": "price_change", "event_ts": "2026-01-14T16:30:14.305001", "ingestion_ts": "2026-01-14T16:33:58.842229", "market_id": "0xc0e6b917320a47228fb96e3b5ae0e5c93773a5ae2662ae4e1f37807cfe47ce98", "raw": {"market": "0xc0e6b917320a47228fb96e3b5ae0e5c93773a5ae2662ae4e1f37807cfe47ce98", "asset_id": "81647294538046680798858716589766492074338758116170717123345952330712416337530", "price": "0.991", "size": "0", "side": "SELL", "timestamp": "1768404614589", "received_at": "2026-01-14T16:30:14.305001"}}
{"event_type": "price_change", "event_ts": "2026-01-14T16:30:14.305035", "ingestion_ts": "2026-01-14T16:33:58.842229", "market_id": "0xc0e6b917320a47228fb96e3b5ae0e5c93773a5ae2662ae4e1f37807cfe47ce98", "raw": {"market": "0xc0e6b917320a47228fb96e3b5ae0e5c93773a5ae2662ae4e1f37807cfe47ce98", "asset_id": "58656358377246279051017109359677190749228949103591068167284263961542487110215", "price": "0.011", "size": "0", "side": "BUY", "timestamp": "1768404614589", "received_at": "2026-01-14T16:30:14.305035"}}
{"event_type": "price_change", "event_ts": "2026-01-14T16:30:14.305035", "ingestion_ts": "2026-01-14T16:33:58.842229", "market_id": "0xc0e6b917320a47228fb96e3b5ae0e5c93773a5ae2662ae4e1f37807cfe47ce98", "raw": {"market": "0xc0e6b917320a47228fb96e3b5ae0e5c93773a5ae2662ae4e1f37807cfe47ce98", "asset_id": "81647294538046680798858716589766492074338758116170717123345952330712416337530", "price": "0.989", "size": "0", "side": "SELL", "timestamp": "1768404614589", "received_at": "2026-01-14T16:30:14.305035"}}
{"event_type": "price_change", "event_ts": "2026-01-14T16:30:14.305050", "ingestion_ts": "2026-01-14T16:33:58.842229", "market_id": "0xc0e6b917320a47228fb96e3b5ae0e5c93773a5ae2662ae4e1f37807cfe47ce98", "raw": {"market": "0xc0e6b917320a47228fb96e3b5ae0e5c93773a5ae2662ae4e1f37807cfe47ce98", "asset_id": "58656358377246279051017109359677190749228949103591068167284263961542487110215", "price": "0.012", "size": "0", "side": "BUY", "timestamp": "1768404614589", "received_at": "2026-01-14T16:30:14.305050"}}
{"event_type": "price_change", "event_ts": "2026-01-14T16:30:14.305050", "ingestion_ts": "2026-01-14T16:33:58.842229", "market_id": "0xc0e6b917320a47228fb96e3b5ae0e5c93773a5ae2662ae4e1f37807cfe47ce98", "raw": {"market": "0xc0e6b917320a47228fb96e3b5ae0e5c93773a5ae2662ae4e1f37807cfe47ce98", "asset_id": "81647294538046680798858716589766492074338758116170717123345952330712416337530", "price": "0.988", "size": "0", "side": "SELL", "timestamp": "1768404614589", "received_at": "2026-01-14T16:30:14.305050"}}
{"event_type": "price_change", "event_ts": "2026-01-14T16:30:14.305061", "ingestion_ts": "2026-01-14T16:33:58.842229", "market_id": "0xc0e6b917320a47228fb96e3b5ae0e5c93773a5ae2662ae4e1f37807cfe47ce98", "raw": {"market": "0xc0e6b917320a47228fb96e3b5ae0e5c93773a5ae2662ae4e1f37807cfe47ce98", "asset_id": "58656358377246279051017109359677190749228949103591068167284263961542487110215", "price": "0.015", "size": "0", "side": "BUY", "timestamp": "1768404614589", "received_at": "2026-01-14T16:30:14.305061"}}
{"event_type": "price_change", "event_ts": "2026-01-14T16:30:14.305061", "ingestion_ts": "2026-01-14T16:33:58.842229", "market_id": "0xc0e6b917320a47228fb96e3b5ae0e5c93773a5ae2662ae4e1f37807cfe47ce98", "raw": {"market": "0xc0e6b917320a47228fb96e3b5ae0e5c93773a5ae2662ae4e1f37807cfe47ce98", "asset_id": "81647294538046680798858716589766492074338758116170717123345952330712416337530", "price": "0.985", "size": "0", "side": "SELL", "timestamp": "1768404614589", "received_at": "2026-01-14T16:30:14.305061"}}
{"event_type": "price_change", "event_ts": "2026-01-14T16:30:14.305072", "ingestion_ts": "2026-01-14T16:33:58.842229", "market_id": "0xc0e6b917320a47228fb96e3b5ae0e5c93773a5ae2662ae4e1f37807cfe47ce98", "raw": {"market": "0xc0e6b917320a47228fb96e3b5ae0e5c93773a5ae2662ae4e1f37807cfe47ce98", "asset_id": "58656358377246279051017109359677190749228949103591068167284263961542487110215", "price": "0.017", "size": "0", "side": "BUY", "timestamp": "1768404614589", "received_at": "2026-01-14T16:30:14.305072"}}
{"event_type": "price_change", "event_ts": "2026-01-14T16:30:14.305072", "ingestion_ts": "2026-01-14T16:33:58.842229", "market_id": "0xc0e6b917320a47228fb96e3b5ae0e5c93773a5ae2662ae4e1f37807cfe47ce98", "raw": {"market": "0xc0e6b917320a47228fb96e3b5ae0e5c93773a5ae2662ae4e1f37807cfe47ce98", "asset_id": "81647294538046680798858716589766492074338758116170717123345952330712416337530", "price": "0.983", "size": "0", "side": "SELL", "timestamp": "1768404614589", "received_at": "2026-01-14T16:30:14.305072"}}
{"event_type": "price_change", "event_ts": "2026-01-14T16:30:15.829578", "ingestion_ts": "2026-01-14T16:33:58.842229", "market_id": "0xc0e6b917320a47228fb96e3b5ae0e5c93773a5ae2662ae4e1f37807cfe47ce98", "raw": {"market": "0xc0e6b917320a47228fb96e3b5ae0e5c93773a5ae2662ae4e1f37807cfe47ce98", "asset_id": "58656358377246279051017109359677190749228949103591068167284263961542487110215", "price": "0.002", "size": "3310.15", "side": "BUY", "timestamp": "1768404616155", "received_at": "2026-01-14T16:30:15.829578"}}
{"event_type": "price_change", "event_ts": "2026-01-14T16:30:15.829578", "ingestion_ts": "2026-01-14T16:33:58.842229", "market_id": "0xc0e6b917320a47228fb96e3b5ae0e5c93773a5ae2662ae4e1f37807cfe47ce98", "raw": {"market": "0xc0e6b917320a47228fb96e3b5ae0e5c93773a5ae2662ae4e1f37807cfe47ce98", "asset_id": "81647294538046680798858716589766492074338758116170717123345952330712416337530", "price": "0.998", "size": "3310.15", "side": "SELL", "timestamp": "1768404616155", "received_at": "2026-01-14T16:30:15.829578"}}
{"event_type": "price_change", "event_ts": "2026-01-14T16:30:15.831203", "ingestion_ts": "2026-01-14T16:33:58.842229", "market_id": "0xc0e6b917320a47228fb96e3b5ae0e5c93773a5ae2662ae4e1f37807cfe47ce98", "raw": {"market": "0xc0e6b917320a47228fb96e3b5ae0e5c93773a5ae2662ae4e1f37807cfe47ce98", "asset_id": "58656358377246279051017109359677190749228949103591068167284263961542487110215", "price": "0.01", "size": "21.84", "side": "BUY", "timestamp": "1768404616155", "received_at": "2026-01-14T16:30:15.831203"}}
{"event_type": "price_change", "event_ts": "2026-01-14T16:30:15.831203", "ingestion_ts": "2026-01-14T16:33:58.842229", "market_id": "0xc0e6b917320a47228fb96e3b5ae0e5c93773a5ae2662ae4e1f37807cfe47ce98", "raw": {"market": "0xc0e6b917320a47228fb96e3b5ae0e5c93773a5ae2662ae4e1f37807cfe47ce98", "asset_id": "81647294538046680798858716589766492074338758116170717123345952330712416337530", "price": "0.99", "size": "21.84", "side": "SELL", "timestamp": "1768404616155", "received_at": "2026-01-14T16:30:15.831203"}}
{"event_type": "price_change", "event_ts": "2026-01-14T16:30:15.832967", "ingestion_ts": "2026-01-14T16:33:58.842229", "market_id": "0xc0e6b917320a47228fb96e3b5ae0e5c93773a5ae2662ae4e1f37807cfe47ce98", "raw": {"market": "0xc0e6b917320a47228fb96e3b5ae0e5c93773a5ae2662ae4e1f37807cfe47ce98", "asset_id": "58656358377246279051017109359677190749228949103591068167284263961542487110215", "price": "0.006", "size": "13.41", "side": "BUY", "timestamp": "1768404616156", "received_at": "2026-01-14T16:30:15.832967"}}
{"event_type": "price_change", "event_ts": "2026-01-14T16:30:15.832967", "ingestion_ts": "2026-01-14T16:33:58.842229", "market_id": "0xc0e6b917320a47228fb96e3b5ae0e5c93773a5ae2662ae4e1f37807cfe47ce98", "raw": {"market": "0xc0e6b917320a47228fb96e3b5ae0e5c93773a5ae2662ae4e1f37807cfe47ce98", "asset_id": "81647294538046680798858716589766492074338758116170717123345952330712416337530", "price": "0.994", "size": "13.41", "side": "SELL", "timestamp": "1768404616156", "received_at": "2026-01-14T16:30:15.832967"}}
{"event_type": "price_change", "event_ts": "2026-01-14T16:30:15.837040", "ingestion_ts": "2026-01-14T16:33:58.842229", "market_id": "0xc0e6b917320a47228fb96e3b5ae0e5c93773a5ae2662ae4e1f37807cfe47ce98", "raw": {"market": "0xc0e6b917320a47228fb96e3b5ae0e5c93773a5ae2662ae4e1f37807cfe47ce98", "asset_id": "58656358377246279051017109359677190749228949103591068167284263961542487110215", "price": "0.005", "size": "31.72", "side": "BUY", "timestamp": "1768404616157", "received_at": "2026-01-14T16:30:15.837040"}}
{"event_type": "price_change", "event_ts": "2026-01-14T16:30:15.837040", "ingestion_ts": "2026-01-14T16:33:58.842229", "market_id": "0xc0e6b917320a47228fb96e3b5ae0e5c93773a5ae2662ae4e1f37807cfe47ce98", "raw": {"market": "0xc0e6b917320a47228fb96e3b5ae0e5c93773a5ae2662ae4e1f37807cfe47ce98", "asset_id": "81647294538046680798858716589766492074338758116170717123345952330712416337530", "price": "0.995", "size": "31.72", "side": "SELL", "timestamp": "1768404616157", "received_at": "2026-01-14T16:30:15.837040"}}
{"event_type": "price_change", "event_ts": "2026-01-14T16:30:15.837063", "ingestion_ts": "2026-01-14T16:33:58.842229", "market_id": "0xc0e6b917320a47228fb96e3b5ae0e5c93773a5ae2662ae4e1f37807cfe47ce98", "raw": {"market": "0xc0e6b917320a47228fb96e3b5ae0e5c93773a5ae2662ae4e1f37807cfe47ce98", "asset_id": "58656358377246279051017109359677190749228949103591068167284263961542487110215", "price": "0.007", "size": "30.65", "side": "BUY", "timestamp": "1768404616158", "received_at": "2026-01-14T16:30:15.837063"}}
{"event_type": "price_change", "event_ts": "2026-01-14T16:30:15.837063", "ingestion_ts": "2026-01-14T16:33:58.842229", "market_id": "0xc0e6b917320a47228fb96e3b5ae0e5c93773a5ae2662ae4e1f37807cfe47ce98", "raw": {"market": "0xc0e6b917320a47228fb96e3b5ae0e5c93773a5ae2662ae4e1f37807cfe47ce98", "asset_id": "81647294538046680798858716589766492074338758116170717123345952330712416337530", "price": "0.993", "size": "30.65", "side": "SELL", "timestamp": "1768404616158", "received_at": "2026-01-14T16:30:15.837063"}}
{"event_type": "price_change", "event_ts": "2026-01-14T16:30:15.837078", "ingestion_ts": "2026-01-14T16:33:58.842229", "market_id": "0xc0e6b917320a47228fb96e3b5ae0e5c93773a5ae2662ae4e1f37807cfe47ce98", "raw": {"market": "0xc0e6b917320a47228fb96e3b5ae0e5c93773a5ae2662ae4e1f37807cfe47ce98", "asset_id": "58656358377246279051017109359677190749228949103591068167284263961542487110215", "price": "0.012", "size": "9.31", "side": "BUY", "timestamp": "1768404616159", "received_at": "2026-01-14T16:30:15.837078"}}
{"event_type": "price_change", "event_ts": "2026-01-14T16:30:15.837078", "ingestion_ts": "2026-01-14T16:33:58.842229", "market_id": "0xc0e6b917320a47228fb96e3b5ae0e5c93773a5ae2662ae4e1f37807cfe47ce98", "raw": {"market": "0xc0e6b917320a47228fb96e3b5ae0e5c93773a5ae2662ae4e1f37807cfe47ce98", "asset_id": "81647294538046680798858716589766492074338758116170717123345952330712416337530", "price": "0.988", "size": "9.31", "side": "SELL", "timestamp": "1768404616159", "received_at": "2026-01-14T16:30:15.837078"}}
{"event_type": "price_change", "event_ts": "2026-01-14T16:30:15.839703", "ingestion_ts": "2026-01-14T16:33:58.842229", "market_id": "0xc0e6b917320a47228fb96e3b5ae0e5c93773a5ae2662ae4e1f37807cfe47ce98", "raw": {"market": "0xc0e6b917320a47228fb96e3b5ae0e5c93773a5ae2662ae4e1f37807cfe47ce98", "asset_id": "58656358377246279051017109359677190749228949103591068167284263961542487110215", "price": "0.009", "size": "11.79", "side": "BUY", "timestamp": "1768404616160", "received_at": "2026-01-14T16:30:15.839703"}}
{"event_type": "price_change", "event_ts": "2026-01-14T16:30:15.839703", "ingestion_ts": "2026-01-14T16:33:58.842229", "market_id": "0xc0e6b917320a47228fb96e3b5ae0e5c93773a5ae2662ae4e1f37807cfe47ce98", "raw": {"market": "0xc0e6b917320a47228fb96e3b5ae0e5c93773a5ae2662ae4e1f37807cfe47ce98", "asset_id": "81647294538046680798858716589766492074338758116170717123345952330712416337530", "price": "0.991", "size": "11.79", "side": "SELL", "timestamp": "1768404616160", "received_at": "2026-01-14T16:30:15.839703"}}
{"event_type": "price_change", "event_ts": "2026-01-14T16:30:17.175699", "ingestion_ts": "2026-01-14T16:33:58.842229", "market_id": "0xc0e6b917320a47228fb96e3b5ae0e5c93773a5ae2662ae4e1f37807cfe47ce98", "raw": {"market": "0xc0e6b917320a47228fb96e3b5ae0e5c93773a5ae2662ae4e1f37807cfe47ce98", "asset_id": "58656358377246279051017109359677190749228949103591068167284263961542487110215", "price": "0.016", "size": "7.33", "side": "BUY", "timestamp": "1768404617470", "received_at": "2026-01-14T16:30:17.175699"}}
{"event_type": "price_change", "event_ts": "2026-01-14T16:30:17.175699", "ingestion_ts": "2026-01-14T16:33:58.842229", "market_id": "0xc0e6b917320a47228fb96e3b5ae0e5c93773a5ae2662ae4e1f37807cfe47ce98", "raw": {"market": "0xc0e6b917320a47228fb96e3b5ae0e5c93773a5ae2662ae4e1f37807cfe47ce98", "asset_id": "81647294538046680798858716589766492074338758116170717123345952330712416337530", "price": "0.984", "size": "7.33", "side": "SELL", "timestamp": "1768404617470", "received_at": "2026-01-14T16:30:17.175699"}}
{"event_type": "price_change", "event_ts": "2026-01-14T16:30:17.175723", "ingestion_ts": "2026-01-14T16:33:58.842229", "market_id": "0xc0e6b917320a47228fb96e3b5ae0e5c93773a5ae2662ae4e1f37807cfe47ce98", "raw": {"market": "0xc0e6b917320a47228fb96e3b5ae0e5c93773a5ae2662ae4e1f37807cfe47ce98", "asset_id": "58656358377246279051017109359677190749228949103591068167284263961542487110215", "price": "0.014", "size": "23.24", "side": "BUY", "timestamp": "1768404617471", "received_at": "2026-01-14T16:30:17.175723"}}
{"event_type": "price_change", "event_ts": "2026-01-14T16:30:17.175723", "ingestion_ts": "2026-01-14T16:33:58.842229", "market_id": "0xc0e6b917320a47228fb96e3b5ae0e5c93773a5ae2662ae4e1f37807cfe47ce98", "raw": {"market": "0xc0e6b917320a47228fb96e3b5ae0e5c93773a5ae2662ae4e1f37807cfe47ce98", "asset_id": "81647294538046680798858716589766492074338758116170717123345952330712416337530", "price": "0.986", "size": "23.24", "side": "SELL", "timestamp": "1768404617471", "received_at": "2026-01-14T16:30:17.175723"}}
{"event_type": "price_change", "event_ts": "2026-01-14T16:30:17.175754", "ingestion_ts": "2026-01-14T16:33:58.842229", "market_id": "0xc0e6b917320a47228fb96e3b5ae0e5c93773a5ae2662ae4e1f37807cfe47ce98", "raw": {"market": "0xc0e6b917320a47228fb96e3b5ae0e5c93773a5ae2662ae4e1f37807cfe47ce98", "asset_id": "58656358377246279051017109359677190749228949103591068167284263961542487110215", "price": "0.018", "size": "6.1", "side": "BUY", "timestamp": "1768404617472", "received_at": "2026-01-14T16:30:17.175754"}}
{"event_type": "price_change", "event_ts": "2026-01-14T16:30:17.175754", "ingestion_ts": "2026-01-14T16:33:58.842229", "market_id": "0xc0e6b917320a47228fb96e3b5ae0e5c93773a5ae2662ae4e1f37807cfe47ce98", "raw": {"market": "0xc0e6b917320a47228fb96e3b5ae0e5c93773a5ae2662ae4e1f37807cfe47ce98", "asset_id": "81647294538046680798858716589766492074338758116170717123345952330712416337530", "price": "0.982", "size": "6.1", "side": "SELL", "timestamp": "1768404617472", "received_at": "2026-01-14T16:30:17.175754"}}
{"event_type": "price_change", "event_ts": "2026-01-14T16:30:17.175766", "ingestion_ts": "2026-01-14T16:33:58.842229", "market_id": "0xc0e6b917320a47228fb96e3b5ae0e5c93773a5ae2662ae4e1f37807cfe47ce98", "raw": {"market": "0xc0e6b917320a47228fb96e3b5ae0e5c93773a5ae2662ae4e1f37807cfe47ce98", "asset_id": "58656358377246279051017109359677190749228949103591068167284263961542487110215", "price": "0.013", "size": "58.57", "side": "BUY", "timestamp": "1768404617473", "received_at": "2026-01-14T16:30:17.175766"}}
{"event_type": "price_change", "event_ts": "2026-01-14T16:30:17.175766", "ingestion_ts": "2026-01-14T16:33:58.842229", "market_id": "0xc0e6b917320a47228fb96e3b5ae0e5c93773a5ae2662ae4e1f37807cfe47ce98", "raw": {"market": "0xc0e6b917320a47228fb96e3b5ae0e5c93773a5ae2662ae4e1f37807cfe47ce98", "asset_id": "81647294538046680798858716589766492074338758116170717123345952330712416337530", "price": "0.987", "size": "58.57", "side": "SELL", "timestamp": "1768404617473", "received_at": "2026-01-14T16:30:17.175766"}}
{"event_type": "price_change", "event_ts": "2026-01-14T16:30:17.266133", "ingestion_ts": "2026-01-14T16:33:58.842229", "market_id": "0x50e477f0b316a3d97d60486479657c63be0763834d0e2e8a30b1b86dc3c1c001", "raw": {"market": "0x50e477f0b316a3d97d60486479657c63be0763834d0e2e8a30b1b86dc3c1c001", "asset_id": "60573178197991590327120832143415406583517170365625050489007297367895074266641", "price": "0.01", "size": "0", "side": "SELL", "timestamp": "1768404617603", "received_at": "2026-01-14T16:30:17.266133"}}
{"event_type": "price_change", "event_ts": "2026-01-14T16:30:17.266133", "ingestion_ts": "2026-01-14T16:33:58.842229", "market_id": "0x50e477f0b316a3d97d60486479657c63be0763834d0e2e8a30b1b86dc3c1c001", "raw": {"market": "0x50e477f0b316a3d97d60486479657c63be0763834d0e2e8a30b1b86dc3c1c001", "asset_id": "39981134260608444876865205057565852475343967395624370698967311821208058420507", "price": "0.99", "size": "0", "side": "BUY", "timestamp": "1768404617603", "received_at": "2026-01-14T16:30:17.266133"}}
{"event_type": "price_change", "event_ts": "2026-01-14T16:30:17.691993", "ingestion_ts": "2026-01-14T16:33:58.842229", "market_id": "0xe9c127a8c35f045d37b5344b0a36711084fa20c2fc1618bf178a5386f90610be", "raw": {"market": "0xe9c127a8c35f045d37b5344b0a36711084fa20c2fc1618bf178a5386f90610be", "asset_id": "80230236018433940569996058935444651347308266584430516013229815570706872276819", "price": "0.009", "size": "0", "side": "SELL", "timestamp": "1768404618028", "received_at": "2026-01-14T16:30:17.691993"}}
{"event_type": "price_change", "event_ts": "2026-01-14T16:30:17.691993", "ingestion_ts": "2026-01-14T16:33:58.842229", "market_id": "0xe9c127a8c35f045d37b5344b0a36711084fa20c2fc1618bf178a5386f90610be", "raw": {"market": "0xe9c127a8c35f045d37b5344b0a36711084fa20c2fc1618bf178a5386f90610be", "asset_id": "107000426448217931795450451304515386602910396776318075817601265223856116134349", "price": "0.991", "size": "0", "side": "BUY", "timestamp": "1768404618028", "received_at": "2026-01-14T16:30:17.691993"}}
{"event_type": "price_change", "event_ts": "2026-01-14T16:30:17.726524", "ingestion_ts": "2026-01-14T16:33:58.842229", "market_id": "0x49686d26fb712515cd5e12c23f0a1c7e10214c7faa3cb0a730aabe0c33694082", "raw": {"market": "0x49686d26fb712515cd5e12c23f0a1c7e10214c7faa3cb0a730aabe0c33694082", "asset_id": "13244681086321087932946246027856416106585284024824496763706748621681543444582", "price": "0.851", "size": "500", "side": "BUY", "timestamp": "1768404618030", "received_at": "2026-01-14T16:30:17.726524"}}
{"event_type": "price_change", "event_ts": "2026-01-14T16:30:17.726524", "ingestion_ts": "2026-01-14T16:33:58.842229", "market_id": "0x49686d26fb712515cd5e12c23f0a1c7e10214c7faa3cb0a730aabe0c33694082", "raw": {"market": "0x49686d26fb712515cd5e12c23f0a1c7e10214c7faa3cb0a730aabe0c33694082", "asset_id": "30442780799048074404860985387051749017905070253466005720364298335239299761065", "price": "0.149", "size": "500", "side": "SELL", "timestamp": "1768404618030", "received_at": "2026-01-14T16:30:17.726524"}}
{"event_type": "price_change", "event_ts": "2026-01-14T16:30:18.170794", "ingestion_ts": "2026-01-14T16:33:58.842229", "market_id": "0x50e477f0b316a3d97d60486479657c63be0763834d0e2e8a30b1b86dc3c1c001", "raw": {"market": "0x50e477f0b316a3d97d60486479657c63be0763834d0e2e8a30b1b86dc3c1c001", "asset_id": "39981134260608444876865205057565852475343967395624370698967311821208058420507", "price": "0.991", "size": "0", "side": "BUY", "timestamp": "1768404618472", "received_at": "2026-01-14T16:30:18.170794"}}
{"event_type": "price_change", "event_ts": "2026-01-14T16:30:18.170794", "ingestion_ts": "2026-01-14T16:33:58.842229", "market_id": "0x50e477f0b316a3d97d60486479657c63be0763834d0e2e8a30b1b86dc3c1c001", "raw": {"market": "0x50e477f0b316a3d97d60486479657c63be0763834d0e2e8a30b1b86dc3c1c001", "asset_id": "60573178197991590327120832143415406583517170365625050489007297367895074266641", "price": "0.009", "size": "0", "side": "SELL", "timestamp": "1768404618472", "received_at": "2026-01-14T16:30:18.170794"}}
{"event_type": "price_change", "event_ts": "2026-01-14T16:30:18.194563", "ingestion_ts": "2026-01-14T16:33:58.842229", "market_id": "0x50e477f0b316a3d97d60486479657c63be0763834d0e2e8a30b1b86dc3c1c001", "raw": {"market": "0x50e477f0b316a3d97d60486479657c63be0763834d0e2e8a30b1b86dc3c1c001", "asset_id": "39981134260608444876865205057565852475343967395624370698967311821208058420507", "price": "0.987", "size": "81", "side": "BUY", "timestamp": "1768404618503", "received_at": "2026-01-14T16:30:18.194563"}}
{"event_type": "price_change", "event_ts": "2026-01-14T16:30:18.194563", "ingestion_ts": "2026-01-14T16:33:58.842229", "market_id": "0x50e477f0b316a3d97d60486479657c63be0763834d0e2e8a30b1b86dc3c1c001", "raw": {"market": "0x50e477f0b316a3d97d60486479657c63be0763834d0e2e8a30b1b86dc3c1c001", "asset_id": "60573178197991590327120832143415406583517170365625050489007297367895074266641", "price": "0.013", "size": "81", "side": "SELL", "timestamp": "1768404618503", "received_at": "2026-01-14T16:30:18.194563"}}
{"event_type": "price_change", "event_ts": "2026-01-14T16:30:18.446401", "ingestion_ts": "2026-01-14T16:33:58.842229", "market_id": "0xc0e6b917320a47228fb96e3b5ae0e5c93773a5ae2662ae4e1f37807cfe47ce98", "raw": {"market": "0xc0e6b917320a47228fb96e3b5ae0e5c93773a5ae2662ae4e1f37807cfe47ce98", "asset_id": "58656358377246279051017109359677190749228949103591068167284263961542487110215", "price": "0.008", "size": "50", "side": "BUY", "timestamp": "1768404618774", "received_at": "2026-01-14T16:30:18.446401"}}
{"event_type": "price_change", "event_ts": "2026-01-14T16:30:18.446401", "ingestion_ts": "2026-01-14T16:33:58.842229", "market_id": "0xc0e6b917320a47228fb96e3b5ae0e5c93773a5ae2662ae4e1f37807cfe47ce98", "raw": {"market": "0xc0e6b917320a47228fb96e3b5ae0e5c93773a5ae2662ae4e1f37807cfe47ce98", "asset_id": "81647294538046680798858716589766492074338758116170717123345952330712416337530", "price": "0.992", "size": "50", "side": "SELL", "timestamp": "1768404618774", "received_at": "2026-01-14T16:30:18.446401"}}
{"event_type": "price_change", "event_ts": "2026-01-14T16:30:18.767370", "ingestion_ts": "2026-01-14T16:33:58.842229", "market_id": "0xc0e6b917320a47228fb96e3b5ae0e5c93773a5ae2662ae4e1f37807cfe47ce98", "raw": {"market": "0xc0e6b917320a47228fb96e3b5ae0e5c93773a5ae2662ae4e1f37807cfe47ce98", "asset_id": "58656358377246279051017109359677190749228949103591068167284263961542487110215", "price": "0.013", "size": "8.57", "side": "BUY", "timestamp": "1768404619103", "received_at": "2026-01-14T16:30:18.767370"}}
{"event_type": "price_change", "event_ts": "2026-01-14T16:30:18.767370", "ingestion_ts": "2026-01-14T16:33:58.842229", "market_id": "0xc0e6b917320a47228fb96e3b5ae0e5c93773a5ae2662ae4e1f37807cfe47ce98", "raw": {"market": "0xc0e6b917320a47228fb96e3b5ae0e5c93773a5ae2662ae4e1f37807cfe47ce98", "asset_id": "81647294538046680798858716589766492074338758116170717123345952330712416337530", "price": "0.987", "size": "8.57", "side": "SELL", "timestamp": "1768404619103", "received_at": "2026-01-14T16:30:18.767370"}}
{"event_type": "price_change", "event_ts": "2026-01-14T16:30:20.048062", "ingestion_ts": "2026-01-14T16:33:58.842229", "market_id": "0xe9c127a8c35f045d37b5344b0a36711084fa20c2fc1618bf178a5386f90610be", "raw": {"market": "0xe9c127a8c35f045d37b5344b0a36711084fa20c2fc1618bf178a5386f90610be", "asset_id": "80230236018433940569996058935444651347308266584430516013229815570706872276819", "price": "0.007", "size": "61.87", "side": "SELL", "timestamp": "1768404620295", "received_at": "2026-01-14T16:30:20.048062"}}
{"event_type": "price_change", "event_ts": "2026-01-14T16:30:20.048062", "ingestion_ts": "2026-01-14T16:33:58.842229", "market_id": "0xe9c127a8c35f045d37b5344b0a36711084fa20c2fc1618bf178a5386f90610be", "raw": {"market": "0xe9c127a8c35f045d37b5344b0a36711084fa20c2fc1618bf178a5386f90610be", "asset_id": "107000426448217931795450451304515386602910396776318075817601265223856116134349", "price": "0.993", "size": "61.87", "side": "BUY", "timestamp": "1768404620295", "received_at": "2026-01-14T16:30:20.048062"}}
{"event_type": "price_change", "event_ts": "2026-01-14T16:30:20.650348", "ingestion_ts": "2026-01-14T16:33:58.842229", "market_id": "0xcab7ba4a9133cfd407d7e73e5757e5abbace413b59421527a31113406c97815c", "raw": {"market": "0xcab7ba4a9133cfd407d7e73e5757e5abbace413b59421527a31113406c97815c", "asset_id": "96361925776989336186111887920533578209326565663637092688733016597062311745569", "price": "0.003", "size": "0", "side": "BUY", "timestamp": "1768404620988", "received_at": "2026-01-14T16:30:20.650348"}}
{"event_type": "price_change", "event_ts": "2026-01-14T16:30:20.650348", "ingestion_ts": "2026-01-14T16:33:58.842229", "market_id": "0xcab7ba4a9133cfd407d7e73e5757e5abbace413b59421527a31113406c97815c", "raw": {"market": "0xcab7ba4a9133cfd407d7e73e5757e5abbace413b59421527a31113406c97815c", "asset_id": "20002636398944597965698652220992177552927816915094913583821579024925426590022", "price": "0.997", "size": "0", "side": "SELL", "timestamp": "1768404620988", "received_at": "2026-01-14T16:30:20.650348"}}
{"event_type": "price_change", "event_ts": "2026-01-14T16:30:21.640177", "ingestion_ts": "2026-01-14T16:33:58.842229", "market_id": "0x50e477f0b316a3d97d60486479657c63be0763834d0e2e8a30b1b86dc3c1c001", "raw": {"market": "0x50e477f0b316a3d97d60486479657c63be0763834d0e2e8a30b1b86dc3c1c001", "asset_id": "60573178197991590327120832143415406583517170365625050489007297367895074266641", "price": "0.008", "size": "45", "side": "SELL", "timestamp": "1768404621969", "received_at": "2026-01-14T16:30:21.640177"}}
{"event_type": "price_change", "event_ts": "2026-01-14T16:30:21.640177", "ingestion_ts": "2026-01-14T16:33:58.842229", "market_id": "0x50e477f0b316a3d97d60486479657c63be0763834d0e2e8a30b1b86dc3c1c001", "raw": {"market": "0x50e477f0b316a3d97d60486479657c63be0763834d0e2e8a30b1b86dc3c1c001", "asset_id": "39981134260608444876865205057565852475343967395624370698967311821208058420507", "price": "0.992", "size": "45", "side": "BUY", "timestamp": "1768404621969", "received_at": "2026-01-14T16:30:21.640177"}}
{"event_type": "price_change", "event_ts": "2026-01-14T16:30:21.640206", "ingestion_ts": "2026-01-14T16:33:58.842229", "market_id": "0x50e477f0b316a3d97d60486479657c63be0763834d0e2e8a30b1b86dc3c1c001", "raw": {"market": "0x50e477f0b316a3d97d60486479657c63be0763834d0e2e8a30b1b86dc3c1c001", "asset_id": "60573178197991590327120832143415406583517170365625050489007297367895074266641", "price": "0.013", "size": "174.86", "side": "SELL", "timestamp": "1768404621970", "received_at": "2026-01-14T16:30:21.640206"}}
{"event_type": "price_change", "event_ts": "2026-01-14T16:30:21.640206", "ingestion_ts": "2026-01-14T16:33:58.842229", "market_id": "0x50e477f0b316a3d97d60486479657c63be0763834d0e2e8a30b1b86dc3c1c001", "raw": {"market": "0x50e477f0b316a3d97d60486479657c63be0763834d0e2e8a30b1b86dc3c1c001", "asset_id": "39981134260608444876865205057565852475343967395624370698967311821208058420507", "price": "0.987", "size": "174.86", "side": "BUY", "timestamp": "1768404621970", "received_at": "2026-01-14T16:30:21.640206"}}
{"event_type": "price_change", "event_ts": "2026-01-14T16:30:21.704360", "ingestion_ts": "2026-01-14T16:33:58.842229", "market_id": "0x50e477f0b316a3d97d60486479657c63be0763834d0e2e8a30b1b86dc3c1c001", "raw": {"market": "0x50e477f0b316a3d97d60486479657c63be0763834d0e2e8a30b1b86dc3c1c001", "asset_id": "39981134260608444876865205057565852475343967395624370698967311821208058420507", "price": "0.987", "size": "93.86", "side": "BUY", "timestamp": "1768404622009", "received_at": "2026-01-14T16:30:21.704360"}}
{"event_type": "price_change", "event_ts": "2026-01-14T16:30:21.704360", "ingestion_ts": "2026-01-14T16:33:58.842229", "market_id": "0x50e477f0b316a3d97d60486479657c63be0763834d0e2e8a30b1b86dc3c1c001", "raw": {"market": "0x50e477f0b316a3d97d60486479657c63be0763834d0e2e8a30b1b86dc3c1c001", "asset_id": "60573178197991590327120832143415406583517170365625050489007297367895074266641", "price": "0.013", "size": "93.86", "side": "SELL", "timestamp": "1768404622009", "received_at": "2026-01-14T16:30:21.704360"}}
{"event_type": "price_change", "event_ts": "2026-01-14T16:30:22.131167", "ingestion_ts": "2026-01-14T16:33:58.842229", "market_id": "0x50e477f0b316a3d97d60486479657c63be0763834d0e2e8a30b1b86dc3c1c001", "raw": {"market": "0x50e477f0b316a3d97d60486479657c63be0763834d0e2e8a30b1b86dc3c1c001", "asset_id": "39981134260608444876865205057565852475343967395624370698967311821208058420507", "price": "0.987", "size": "123.86", "side": "BUY", "timestamp": "1768404622469", "received_at": "2026-01-14T16:30:22.131167"}}
{"event_type": "price_change", "event_ts": "2026-01-14T16:30:22.131167", "ingestion_ts": "2026-01-14T16:33:58.842229", "market_id": "0x50e477f0b316a3d97d60486479657c63be0763834d0e2e8a30b1b86dc3c1c001", "raw": {"market": "0x50e477f0b316a3d97d60486479657c63be0763834d0e2e8a30b1b86dc3c1c001", "asset_id": "60573178197991590327120832143415406583517170365625050489007297367895074266641", "price": "0.013", "size": "123.86", "side": "SELL", "timestamp": "1768404622469", "received_at": "2026-01-14T16:30:22.131167"}}
{"event_type": "price_change", "event_ts": "2026-01-14T16:30:22.685597", "ingestion_ts": "2026-01-14T16:33:58.842229", "market_id": "0x22ac5f75af18fdb453497fbf7ac0606a09a6fd55b78b2d08aace6b946ad62038", "raw": {"market": "0x22ac5f75af18fdb453497fbf7ac0606a09a6fd55b78b2d08aace6b946ad62038", "asset_id": "97449340182256366014320155718265676486703217567849039806162053075113517266910", "price": "0.007", "size": "0", "side": "BUY", "timestamp": "1768404622948", "received_at": "2026-01-14T16:30:22.685597"}}
{"event_type": "price_change", "event_ts": "2026-01-14T16:30:22.685597", "ingestion_ts": "2026-01-14T16:33:58.842229", "market_id": "0x22ac5f75af18fdb453497fbf7ac0606a09a6fd55b78b2d08aace6b946ad62038", "raw": {"market": "0x22ac5f75af18fdb453497fbf7ac0606a09a6fd55b78b2d08aace6b946ad62038", "asset_id": "59259495934562596318644973716893809974860301509869285036503555129962149752635", "price": "0.993", "size": "0", "side": "SELL", "timestamp": "1768404622948", "received_at": "2026-01-14T16:30:22.685597"}}
{"event_type": "price_change", "event_ts": "2026-01-14T16:30:22.685633", "ingestion_ts": "2026-01-14T16:33:58.842229", "market_id": "0x22ac5f75af18fdb453497fbf7ac0606a09a6fd55b78b2d08aace6b946ad62038", "raw": {"market": "0x22ac5f75af18fdb453497fbf7ac0606a09a6fd55b78b2d08aace6b946ad62038", "asset_id": "97449340182256366014320155718265676486703217567849039806162053075113517266910", "price": "0.009", "size": "0", "side": "BUY", "timestamp": "1768404622948", "received_at": "2026-01-14T16:30:22.685633"}}
{"event_type": "price_change", "event_ts": "2026-01-14T16:30:22.685633", "ingestion_ts": "2026-01-14T16:33:58.842229", "market_id": "0x22ac5f75af18fdb453497fbf7ac0606a09a6fd55b78b2d08aace6b946ad62038", "raw": {"market": "0x22ac5f75af18fdb453497fbf7ac0606a09a6fd55b78b2d08aace6b946ad62038", "asset_id": "59259495934562596318644973716893809974860301509869285036503555129962149752635", "price": "0.991", "size": "0", "side": "SELL", "timestamp": "1768404622948", "received_at": "2026-01-14T16:30:22.685633"}}
{"event_type": "price_change", "event_ts": "2026-01-14T16:30:22.869033", "ingestion_ts": "2026-01-14T16:33:58.842229", "market_id": "0xcab7ba4a9133cfd407d7e73e5757e5abbace413b59421527a31113406c97815c", "raw": {"market": "0xcab7ba4a9133cfd407d7e73e5757e5abbace413b59421527a31113406c97815c", "asset_id": "96361925776989336186111887920533578209326565663637092688733016597062311745569", "price": "0.002", "size": "238.62", "side": "BUY", "timestamp": "1768404623129", "received_at": "2026-01-14T16:30:22.869033"}}
{"event_type": "price_change", "event_ts": "2026-01-14T16:30:22.869033", "ingestion_ts": "2026-01-14T16:33:58.842229", "market_id": "0xcab7ba4a9133cfd407d7e73e5757e5abbace413b59421527a31113406c97815c", "raw": {"market": "0xcab7ba4a9133cfd407d7e73e5757e5abbace413b59421527a31113406c97815c", "asset_id": "20002636398944597965698652220992177552927816915094913583821579024925426590022", "price": "0.998", "size": "238.62", "side": "SELL", "timestamp": "1768404623129", "received_at": "2026-01-14T16:30:22.869033"}}
{"event_type": "price_change", "event_ts": "2026-01-14T16:30:23.576775", "ingestion_ts": "2026-01-14T16:33:58.842229", "market_id": "0x22ac5f75af18fdb453497fbf7ac0606a09a6fd55b78b2d08aace6b946ad62038", "raw": {"market": "0x22ac5f75af18fdb453497fbf7ac0606a09a6fd55b78b2d08aace6b946ad62038", "asset_id": "97449340182256366014320155718265676486703217567849039806162053075113517266910", "price": "0.002", "size": "135.35", "side": "BUY", "timestamp": "1768404623746", "received_at": "2026-01-14T16:30:23.576775"}}
{"event_type": "price_change", "event_ts": "2026-01-14T16:30:23.576775", "ingestion_ts": "2026-01-14T16:33:58.842229", "market_id": "0x22ac5f75af18fdb453497fbf7ac0606a09a6fd55b78b2d08aace6b946ad62038", "raw": {"market": "0x22ac5f75af18fdb453497fbf7ac0606a09a6fd55b78b2d08aace6b946ad62038", "asset_id": "59259495934562596318644973716893809974860301509869285036503555129962149752635", "price": "0.998", "size": "135.35", "side": "SELL", "timestamp": "1768404623746", "received_at": "2026-01-14T16:30:23.576775"}}
{"event_type": "price_change", "event_ts": "2026-01-14T16:30:24.400670", "ingestion_ts": "2026-01-14T16:33:58.842229", "market_id": "0x9472be65457510b7fc3477b20ba90910e99d92eac8421a14bf4b7b7a08ef31dc", "raw": {"market": "0x9472be65457510b7fc3477b20ba90910e99d92eac8421a14bf4b7b7a08ef31dc", "asset_id": "43311793366960417907757893276427136943959788721376762326430771171648759300146", "price": "0.201", "size": "5.69", "side": "BUY", "timestamp": "1768404624644", "received_at": "2026-01-14T16:30:24.400670"}}
{"event_type": "price_change", "event_ts": "2026-01-14T16:30:24.400670", "ingestion_ts": "2026-01-14T16:33:58.842229", "market_id": "0x9472be65457510b7fc3477b20ba90910e99d92eac8421a14bf4b7b7a08ef31dc", "raw": {"market": "0x9472be65457510b7fc3477b20ba90910e99d92eac8421a14bf4b7b7a08ef31dc", "asset_id": "73414222381656326204771753454630063673548497164758947581648273905027617570612", "price": "0.799", "size": "5.69", "side": "SELL", "timestamp": "1768404624644", "received_at": "2026-01-14T16:30:24.400670"}}
{"event_type": "price_change", "event_ts": "2026-01-14T16:30:24.402919", "ingestion_ts": "2026-01-14T16:33:58.842229", "market_id": "0x9472be65457510b7fc3477b20ba90910e99d92eac8421a14bf4b7b7a08ef31dc", "raw": {"market": "0x9472be65457510b7fc3477b20ba90910e99d92eac8421a14bf4b7b7a08ef31dc", "asset_id": "43311793366960417907757893276427136943959788721376762326430771171648759300146", "price": "0.085", "size": "5.3", "side": "BUY", "timestamp": "1768404624645", "received_at": "2026-01-14T16:30:24.402919"}}
{"event_type": "price_change", "event_ts": "2026-01-14T16:30:24.402919", "ingestion_ts": "2026-01-14T16:33:58.842229", "market_id": "0x9472be65457510b7fc3477b20ba90910e99d92eac8421a14bf4b7b7a08ef31dc", "raw": {"market": "0x9472be65457510b7fc3477b20ba90910e99d92eac8421a14bf4b7b7a08ef31dc", "asset_id": "73414222381656326204771753454630063673548497164758947581648273905027617570612", "price": "0.915", "size": "5.3", "side": "SELL", "timestamp": "1768404624645", "received_at": "2026-01-14T16:30:24.402919"}}
{"event_type": "price_change", "event_ts": "2026-01-14T16:30:24.405765", "ingestion_ts": "2026-01-14T16:33:58.842229", "market_id": "0x9472be65457510b7fc3477b20ba90910e99d92eac8421a14bf4b7b7a08ef31dc", "raw": {"market": "0x9472be65457510b7fc3477b20ba90910e99d92eac8421a14bf4b7b7a08ef31dc", "asset_id": "43311793366960417907757893276427136943959788721376762326430771171648759300146", "price": "0.001", "size": "7293.15", "side": "BUY", "timestamp": "1768404624646", "received_at": "2026-01-14T16:30:24.405765"}}
