{"event_type": "price_change", "event_ts": "2026-01-15T12:10:43.368536", "ingestion_ts": "2026-01-15T12:11:41.230171", "market_id": "0x427bc4b40c09b3dcbc973747f0e4b079bed91b3e5a0aed5c36edd0f7591485f4", "raw": {"market": "0x427bc4b40c09b3dcbc973747f0e4b079bed91b3e5a0aed5c36edd0f7591485f4", "asset_id": "115669573443672055876643967408433138119481486650803218131873713375232186497057", "price": "0.002", "size": "63.15", "side": "BUY", "timestamp": "1768475443251", "received_at": "2026-01-15T12:10:43.368536"}}
{"event_type": "price_change", "event_ts": "2026-01-15T12:10:43.368536", "ingestion_ts": "2026-01-15T12:11:41.230171", "market_id": "0x427bc4b40c09b3dcbc973747f0e4b079bed91b3e5a0aed5c36edd0f7591485f4", "raw": {"market": "0x427bc4b40c09b3dcbc973747f0e4b079bed91b3e5a0aed5c36edd0f7591485f4", "asset_id": "86130975769502911188457673769190265049139877688522439001984850068234616395137", "price": "0.998", "size": "63.15", "side": "SELL", "timestamp": "1768475443251", "received_at": "2026-01-15T12:10:43.368536"}}
{"event_type": "price_change", "event_ts": "2026-01-15T12:10:43.556812", "ingestion_ts": "2026-01-15T12:11:41.230171", "market_id": "0xc0e6b917320a47228fb96e3b5ae0e5c93773a5ae2662ae4e1f37807cfe47ce98", "raw": {"market": "0xc0e6b917320a47228fb96e3b5ae0e5c93773a5ae2662ae4e1f37807cfe47ce98", "asset_id": "81647294538046680798858716589766492074338758116170717123345952330712416337530", "price": "0.984", "size": "54.32", "side": "SELL", "timestamp": "1768475443437", "received_at": "2026-01-15T12:10:43.556812"}}
{"event_type": "price_change", "event_ts": "2026-01-15T12:10:43.556812", "ingestion_ts": "2026-01-15T12:11:41.230171", "market_id": "0xc0e6b917320a47228fb96e3b5ae0e5c93773a5ae2662ae4e1f37807cfe47ce98", "raw": {"market": "0xc0e6b917320a47228fb96e3b5ae0e5c93773a5ae2662ae4e1f37807cfe47ce98", "asset_id": "58656358377246279051017109359677190749228949103591068167284263961542487110215", "price": "0.016", "size": "54.32", "side": "BUY", "timestamp": "1768475443437", "received_at": "2026-01-15T12:10:43.556812"}}
{"event_type": "price_change", "event_ts": "2026-01-15T12:10:43.722282", "ingestion_ts": "2026-01-15T12:11:41.230171", "market_id": "0x427bc4b40c09b3dcbc973747f0e4b079bed91b3e5a0aed5c36edd0f7591485f4", "raw": {"market": "0x427bc4b40c09b3dcbc973747f0e4b079bed91b3e5a0aed5c36edd0f7591485f4", "asset_id": "115669573443672055876643967408433138119481486650803218131873713375232186497057", "price": "0.002", "size": "72.33", "side": "BUY", "timestamp": "1768475443599", "received_at": "2026-01-15T12:10:43.722282"}}
{"event_type": "price_change", "event_ts": "2026-01-15T12:10:43.722282", "ingestion_ts": "2026-01-15T12:11:41.230171", "market_id": "0x427bc4b40c09b3dcbc973747f0e4b079bed91b3e5a0aed5c36edd0f7591485f4", "raw": {"market": "0x427bc4b40c09b3dcbc973747f0e4b079bed91b3e5a0aed5c36edd0f7591485f4", "asset_id": "86130975769502911188457673769190265049139877688522439001984850068234616395137", "price": "0.998", "size": "72.33", "side": "SELL", "timestamp": "1768475443599", "received_at": "2026-01-15T12:10:43.722282"}}
{"event_type": "price_change", "event_ts": "2026-01-15T12:10:43.867337", "ingestion_ts": "2026-01-15T12:11:41.230171", "market_id": "0xcab7ba4a9133cfd407d7e73e5757e5abbace413b59421527a31113406c97815c", "raw": {"market": "0xcab7ba4a9133cfd407d7e73e5757e5abbace413b59421527a31113406c97815c", "asset_id": "96361925776989336186111887920533578209326565663637092688733016597062311745569", "price": "0.006", "size": "127.41", "side": "BUY", "timestamp": "1768475443748", "received_at": "2026-01-15T12:10:43.867337"}}
{"event_type": "price_change", "event_ts": "2026-01-15T12:10:43.867337", "ingestion_ts": "2026-01-15T12:11:41.230171", "market_id": "0xcab7ba4a9133cfd407d7e73e5757e5abbace413b59421527a31113406c97815c", "raw": {"market": "0xcab7ba4a9133cfd407d7e73e5757e5abbace413b59421527a31113406c97815c", "asset_id": "20002636398944597965698652220992177552927816915094913583821579024925426590022", "price": "0.994", "size": "127.41", "side": "SELL", "timestamp": "1768475443748", "received_at": "2026-01-15T12:10:43.867337"}}
{"event_type": "price_change", "event_ts": "2026-01-15T12:10:43.867429", "ingestion_ts": "2026-01-15T12:11:41.230171", "market_id": "0xcab7ba4a9133cfd407d7e73e5757e5abbace413b59421527a31113406c97815c", "raw": {"market": "0xcab7ba4a9133cfd407d7e73e5757e5abbace413b59421527a31113406c97815c", "asset_id": "96361925776989336186111887920533578209326565663637092688733016597062311745569", "price": "0.009", "size": "812.25", "side": "BUY", "timestamp": "1768475443748", "received_at": "2026-01-15T12:10:43.867429"}}
{"event_type": "price_change", "event_ts": "2026-01-15T12:10:43.867429", "ingestion_ts": "2026-01-15T12:11:41.230171", "market_id": "0xcab7ba4a9133cfd407d7e73e5757e5abbace413b59421527a31113406c97815c", "raw": {"market": "0xcab7ba4a9133cfd407d7e73e5757e5abbace413b59421527a31113406c97815c", "asset_id": "20002636398944597965698652220992177552927816915094913583821579024925426590022", "price": "0.991", "size": "812.25", "side": "SELL", "timestamp": "1768475443748", "received_at": "2026-01-15T12:10:43.867429"}}
{"event_type": "price_change", "event_ts": "2026-01-15T12:10:44.259125", "ingestion_ts": "2026-01-15T12:11:41.230171", "market_id": "0x427bc4b40c09b3dcbc973747f0e4b079bed91b3e5a0aed5c36edd0f7591485f4", "raw": {"market": "0x427bc4b40c09b3dcbc973747f0e4b079bed91b3e5a0aed5c36edd0f7591485f4", "asset_id": "115669573443672055876643967408433138119481486650803218131873713375232186497057", "price": "0.163", "size": "0", "side": "SELL", "timestamp": "1768475444140", "received_at": "2026-01-15T12:10:44.259125"}}
{"event_type": "price_change", "event_ts": "2026-01-15T12:10:44.259125", "ingestion_ts": "2026-01-15T12:11:41.230171", "market_id": "0x427bc4b40c09b3dcbc973747f0e4b079bed91b3e5a0aed5c36edd0f7591485f4", "raw": {"market": "0x427bc4b40c09b3dcbc973747f0e4b079bed91b3e5a0aed5c36edd0f7591485f4", "asset_id": "86130975769502911188457673769190265049139877688522439001984850068234616395137", "price": "0.837", "size": "0", "side": "BUY", "timestamp": "1768475444140", "received_at": "2026-01-15T12:10:44.259125"}}
{"event_type": "price_change", "event_ts": "2026-01-15T12:10:44.293001", "ingestion_ts": "2026-01-15T12:11:41.230171", "market_id": "0xcab7ba4a9133cfd407d7e73e5757e5abbace413b59421527a31113406c97815c", "raw": {"market": "0xcab7ba4a9133cfd407d7e73e5757e5abbace413b59421527a31113406c97815c", "asset_id": "96361925776989336186111887920533578209326565663637092688733016597062311745569", "price": "0.009", "size": "818.33", "side": "BUY", "timestamp": "1768475444175", "received_at": "2026-01-15T12:10:44.293001"}}
{"event_type": "price_change", "event_ts": "2026-01-15T12:10:44.293001", "ingestion_ts": "2026-01-15T12:11:41.230171", "market_id": "0xcab7ba4a9133cfd407d7e73e5757e5abbace413b59421527a31113406c97815c", "raw": {"market": "0xcab7ba4a9133cfd407d7e73e5757e5abbace413b59421527a31113406c97815c", "asset_id": "20002636398944597965698652220992177552927816915094913583821579024925426590022", "price": "0.991", "size": "818.33", "side": "SELL", "timestamp": "1768475444175", "received_at": "2026-01-15T12:10:44.293001"}}
{"event_type": "price_change", "event_ts": "2026-01-15T12:10:44.296338", "ingestion_ts": "2026-01-15T12:11:41.230171", "market_id": "0xcab7ba4a9133cfd407d7e73e5757e5abbace413b59421527a31113406c97815c", "raw": {"market": "0xcab7ba4a9133cfd407d7e73e5757e5abbace413b59421527a31113406c97815c", "asset_id": "96361925776989336186111887920533578209326565663637092688733016597062311745569", "price": "0.006", "size": "136.51", "side": "BUY", "timestamp": "1768475444176", "received_at": "2026-01-15T12:10:44.296338"}}
{"event_type": "price_change", "event_ts": "2026-01-15T12:10:44.296338", "ingestion_ts": "2026-01-15T12:11:41.230171", "market_id": "0xcab7ba4a9133cfd407d7e73e5757e5abbace413b59421527a31113406c97815c", "raw": {"market": "0xcab7ba4a9133cfd407d7e73e5757e5abbace413b59421527a31113406c97815c", "asset_id": "20002636398944597965698652220992177552927816915094913583821579024925426590022", "price": "0.994", "size": "136.51", "side": "SELL", "timestamp": "1768475444176", "received_at": "2026-01-15T12:10:44.296338"}}
{"event_type": "price_change", "event_ts": "2026-01-15T12:10:44.466430", "ingestion_ts": "2026-01-15T12:11:41.230171", "market_id": "0x427bc4b40c09b3dcbc973747f0e4b079bed91b3e5a0aed5c36edd0f7591485f4", "raw": {"market": "0x427bc4b40c09b3dcbc973747f0e4b079bed91b3e5a0aed5c36edd0f7591485f4", "asset_id": "115669573443672055876643967408433138119481486650803218131873713375232186497057", "price": "0.162", "size": "7.96", "side": "SELL", "timestamp": "1768475444347", "received_at": "2026-01-15T12:10:44.466430"}}
{"event_type": "price_change", "event_ts": "2026-01-15T12:10:44.466430", "ingestion_ts": "2026-01-15T12:11:41.230171", "market_id": "0x427bc4b40c09b3dcbc973747f0e4b079bed91b3e5a0aed5c36edd0f7591485f4", "raw": {"market": "0x427bc4b40c09b3dcbc973747f0e4b079bed91b3e5a0aed5c36edd0f7591485f4", "asset_id": "86130975769502911188457673769190265049139877688522439001984850068234616395137", "price": "0.838", "size": "7.96", "side": "BUY", "timestamp": "1768475444347", "received_at": "2026-01-15T12:10:44.466430"}}
{"event_type": "price_change", "event_ts": "2026-01-15T12:10:46.937511", "ingestion_ts": "2026-01-15T12:11:41.230171", "market_id": "0xc0e6b917320a47228fb96e3b5ae0e5c93773a5ae2662ae4e1f37807cfe47ce98", "raw": {"market": "0xc0e6b917320a47228fb96e3b5ae0e5c93773a5ae2662ae4e1f37807cfe47ce98", "asset_id": "58656358377246279051017109359677190749228949103591068167284263961542487110215", "price": "0.016", "size": "46.63", "side": "BUY", "timestamp": "1768475446811", "received_at": "2026-01-15T12:10:46.937511"}}
{"event_type": "price_change", "event_ts": "2026-01-15T12:10:46.937511", "ingestion_ts": "2026-01-15T12:11:41.230171", "market_id": "0xc0e6b917320a47228fb96e3b5ae0e5c93773a5ae2662ae4e1f37807cfe47ce98", "raw": {"market": "0xc0e6b917320a47228fb96e3b5ae0e5c93773a5ae2662ae4e1f37807cfe47ce98", "asset_id": "81647294538046680798858716589766492074338758116170717123345952330712416337530", "price": "0.984", "size": "46.63", "side": "SELL", "timestamp": "1768475446811", "received_at": "2026-01-15T12:10:46.937511"}}
{"event_type": "price_change", "event_ts": "2026-01-15T12:10:47.261144", "ingestion_ts": "2026-01-15T12:11:41.230171", "market_id": "0xc0e6b917320a47228fb96e3b5ae0e5c93773a5ae2662ae4e1f37807cfe47ce98", "raw": {"market": "0xc0e6b917320a47228fb96e3b5ae0e5c93773a5ae2662ae4e1f37807cfe47ce98", "asset_id": "58656358377246279051017109359677190749228949103591068167284263961542487110215", "price": "0.017", "size": "9.5", "side": "BUY", "timestamp": "1768475447139", "received_at": "2026-01-15T12:10:47.261144"}}
{"event_type": "price_change", "event_ts": "2026-01-15T12:10:47.261144", "ingestion_ts": "2026-01-15T12:11:41.230171", "market_id": "0xc0e6b917320a47228fb96e3b5ae0e5c93773a5ae2662ae4e1f37807cfe47ce98", "raw": {"market": "0xc0e6b917320a47228fb96e3b5ae0e5c93773a5ae2662ae4e1f37807cfe47ce98", "asset_id": "81647294538046680798858716589766492074338758116170717123345952330712416337530", "price": "0.983", "size": "9.5", "side": "SELL", "timestamp": "1768475447139", "received_at": "2026-01-15T12:10:47.261144"}}
{"event_type": "price_change", "event_ts": "2026-01-15T12:10:48.832256", "ingestion_ts": "2026-01-15T12:11:41.230171", "market_id": "0xcab7ba4a9133cfd407d7e73e5757e5abbace413b59421527a31113406c97815c", "raw": {"market": "0xcab7ba4a9133cfd407d7e73e5757e5abbace413b59421527a31113406c97815c", "asset_id": "96361925776989336186111887920533578209326565663637092688733016597062311745569", "price": "0.006", "size": "127.41", "side": "BUY", "timestamp": "1768475448714", "received_at": "2026-01-15T12:10:48.832256"}}
{"event_type": "price_change", "event_ts": "2026-01-15T12:10:48.832256", "ingestion_ts": "2026-01-15T12:11:41.230171", "market_id": "0xcab7ba4a9133cfd407d7e73e5757e5abbace413b59421527a31113406c97815c", "raw": {"market": "0xcab7ba4a9133cfd407d7e73e5757e5abbace413b59421527a31113406c97815c", "asset_id": "20002636398944597965698652220992177552927816915094913583821579024925426590022", "price": "0.994", "size": "127.41", "side": "SELL", "timestamp": "1768475448714", "received_at": "2026-01-15T12:10:48.832256"}}
{"event_type": "price_change", "event_ts": "2026-01-15T12:10:48.833409", "ingestion_ts": "2026-01-15T12:11:41.230171", "market_id": "0xcab7ba4a9133cfd407d7e73e5757e5abbace413b59421527a31113406c97815c", "raw": {"market": "0xcab7ba4a9133cfd407d7e73e5757e5abbace413b59421527a31113406c97815c", "asset_id": "96361925776989336186111887920533578209326565663637092688733016597062311745569", "price": "0.009", "size": "812.25", "side": "BUY", "timestamp": "1768475448714", "received_at": "2026-01-15T12:10:48.833409"}}
{"event_type": "price_change", "event_ts": "2026-01-15T12:10:48.833409", "ingestion_ts": "2026-01-15T12:11:41.230171", "market_id": "0xcab7ba4a9133cfd407d7e73e5757e5abbace413b59421527a31113406c97815c", "raw": {"market": "0xcab7ba4a9133cfd407d7e73e5757e5abbace413b59421527a31113406c97815c", "asset_id": "20002636398944597965698652220992177552927816915094913583821579024925426590022", "price": "0.991", "size": "812.25", "side": "SELL", "timestamp": "1768475448714", "received_at": "2026-01-15T12:10:48.833409"}}
{"event_type": "price_change", "event_ts": "2026-01-15T12:10:49.544238", "ingestion_ts": "2026-01-15T12:11:41.230171", "market_id": "0xcab7ba4a9133cfd407d7e73e5757e5abbace413b59421527a31113406c97815c", "raw": {"market": "0xcab7ba4a9133cfd407d7e73e5757e5abbace413b59421527a31113406c97815c", "asset_id": "96361925776989336186111887920533578209326565663637092688733016597062311745569", "price": "0.009", "size": "818.33", "side": "BUY", "timestamp": "1768475449420", "received_at": "2026-01-15T12:10:49.544238"}}
{"event_type": "price_change", "event_ts": "2026-01-15T12:10:49.544238", "ingestion_ts": "2026-01-15T12:11:41.230171", "market_id": "0xcab7ba4a9133cfd407d7e73e5757e5abbace413b59421527a31113406c97815c", "raw": {"market": "0xcab7ba4a9133cfd407d7e73e5757e5abbace413b59421527a31113406c97815c", "asset_id": "20002636398944597965698652220992177552927816915094913583821579024925426590022", "price": "0.991", "size": "818.33", "side": "SELL", "timestamp": "1768475449420", "received_at": "2026-01-15T12:10:49.544238"}}
{"event_type": "price_change", "event_ts": "2026-01-15T12:10:49.544308", "ingestion_ts": "2026-01-15T12:11:41.230171", "market_id": "0xcab7ba4a9133cfd407d7e73e5757e5abbace413b59421527a31113406c97815c", "raw": {"market": "0xcab7ba4a9133cfd407d7e73e5757e5abbace413b59421527a31113406c97815c", "asset_id": "96361925776989336186111887920533578209326565663637092688733016597062311745569", "price": "0.006", "size": "136.51", "side": "BUY", "timestamp": "1768475449424", "received_at": "2026-01-15T12:10:49.544308"}}
{"event_type": "price_change", "event_ts": "2026-01-15T12:10:49.544308", "ingestion_ts": "2026-01-15T12:11:41.230171", "market_id": "0xcab7ba4a9133cfd407d7e73e5757e5abbace413b59421527a31113406c97815c", "raw": {"market": "0xcab7ba4a9133cfd407d7e73e5757e5abbace413b59421527a31113406c97815c", "asset_id": "20002636398944597965698652220992177552927816915094913583821579024925426590022", "price": "0.994", "size": "136.51", "side": "SELL", "timestamp": "1768475449424", "received_at": "2026-01-15T12:10:49.544308"}}
{"event_type": "price_change", "event_ts": "2026-01-15T12:10:49.803442", "ingestion_ts": "2026-01-15T12:11:41.230171", "market_id": "0xc0e6b917320a47228fb96e3b5ae0e5c93773a5ae2662ae4e1f37807cfe47ce98", "raw": {"market": "0xc0e6b917320a47228fb96e3b5ae0e5c93773a5ae2662ae4e1f37807cfe47ce98", "asset_id": "58656358377246279051017109359677190749228949103591068167284263961542487110215", "price": "0.001", "size": "437", "side": "BUY", "timestamp": "1768475449682", "received_at": "2026-01-15T12:10:49.803442"}}
{"event_type": "price_change", "event_ts": "2026-01-15T12:10:49.803442", "ingestion_ts": "2026-01-15T12:11:41.230171", "market_id": "0xc0e6b917320a47228fb96e3b5ae0e5c93773a5ae2662ae4e1f37807cfe47ce98", "raw": {"market": "0xc0e6b917320a47228fb96e3b5ae0e5c93773a5ae2662ae4e1f37807cfe47ce98", "asset_id": "81647294538046680798858716589766492074338758116170717123345952330712416337530", "price": "0.999", "size": "437", "side": "SELL", "timestamp": "1768475449682", "received_at": "2026-01-15T12:10:49.803442"}}
{"event_type": "price_change", "event_ts": "2026-01-15T12:10:49.803548", "ingestion_ts": "2026-01-15T12:11:41.230171", "market_id": "0xc0e6b917320a47228fb96e3b5ae0e5c93773a5ae2662ae4e1f37807cfe47ce98", "raw": {"market": "0xc0e6b917320a47228fb96e3b5ae0e5c93773a5ae2662ae4e1f37807cfe47ce98", "asset_id": "58656358377246279051017109359677190749228949103591068167284263961542487110215", "price": "0.002", "size": "3304.3", "side": "BUY", "timestamp": "1768475449682", "received_at": "2026-01-15T12:10:49.803548"}}
{"event_type": "price_change", "event_ts": "2026-01-15T12:10:49.803548", "ingestion_ts": "2026-01-15T12:11:41.230171", "market_id": "0xc0e6b917320a47228fb96e3b5ae0e5c93773a5ae2662ae4e1f37807cfe47ce98", "raw": {"market": "0xc0e6b917320a47228fb96e3b5ae0e5c93773a5ae2662ae4e1f37807cfe47ce98", "asset_id": "81647294538046680798858716589766492074338758116170717123345952330712416337530", "price": "0.998", "size": "3304.3", "side": "SELL", "timestamp": "1768475449682", "received_at": "2026-01-15T12:10:49.803548"}}
{"event_type": "price_change", "event_ts": "2026-01-15T12:10:49.803589", "ingestion_ts": "2026-01-15T12:11:41.230171", "market_id": "0xc0e6b917320a47228fb96e3b5ae0e5c93773a5ae2662ae4e1f37807cfe47ce98", "raw": {"market": "0xc0e6b917320a47228fb96e3b5ae0e5c93773a5ae2662ae4e1f37807cfe47ce98", "asset_id": "58656358377246279051017109359677190749228949103591068167284263961542487110215", "price": "0.003", "size": "433", "side": "BUY", "timestamp": "1768475449682", "received_at": "2026-01-15T12:10:49.803589"}}
{"event_type": "price_change", "event_ts": "2026-01-15T12:10:49.803589", "ingestion_ts": "2026-01-15T12:11:41.230171", "market_id": "0xc0e6b917320a47228fb96e3b5ae0e5c93773a5ae2662ae4e1f37807cfe47ce98", "raw": {"market": "0xc0e6b917320a47228fb96e3b5ae0e5c93773a5ae2662ae4e1f37807cfe47ce98", "asset_id": "81647294538046680798858716589766492074338758116170717123345952330712416337530", "price": "0.997", "size": "433", "side": "SELL", "timestamp": "1768475449682", "received_at": "2026-01-15T12:10:49.803589"}}
{"event_type": "price_change", "event_ts": "2026-01-15T12:10:50.170270", "ingestion_ts": "2026-01-15T12:11:41.230171", "market_id": "0xc0e6b917320a47228fb96e3b5ae0e5c93773a5ae2662ae4e1f37807cfe47ce98", "raw": {"market": "0xc0e6b917320a47228fb96e3b5ae0e5c93773a5ae2662ae4e1f37807cfe47ce98", "asset_id": "58656358377246279051017109359677190749228949103591068167284263961542487110215", "price": "0.004", "size": "7.37", "side": "BUY", "timestamp": "1768475450036", "received_at": "2026-01-15T12:10:50.170270"}}
{"event_type": "price_change", "event_ts": "2026-01-15T12:10:50.170270", "ingestion_ts": "2026-01-15T12:11:41.230171", "market_id": "0xc0e6b917320a47228fb96e3b5ae0e5c93773a5ae2662ae4e1f37807cfe47ce98", "raw": {"market": "0xc0e6b917320a47228fb96e3b5ae0e5c93773a5ae2662ae4e1f37807cfe47ce98", "asset_id": "81647294538046680798858716589766492074338758116170717123345952330712416337530", "price": "0.996", "size": "7.37", "side": "SELL", "timestamp": "1768475450036", "received_at": "2026-01-15T12:10:50.170270"}}
{"event_type": "price_change", "event_ts": "2026-01-15T12:10:50.170910", "ingestion_ts": "2026-01-15T12:11:41.230171", "market_id": "0xc0e6b917320a47228fb96e3b5ae0e5c93773a5ae2662ae4e1f37807cfe47ce98", "raw": {"market": "0xc0e6b917320a47228fb96e3b5ae0e5c93773a5ae2662ae4e1f37807cfe47ce98", "asset_id": "58656358377246279051017109359677190749228949103591068167284263961542487110215", "price": "0.001", "size": "442.78", "side": "BUY", "timestamp": "1768475450039", "received_at": "2026-01-15T12:10:50.170910"}}
{"event_type": "price_change", "event_ts": "2026-01-15T12:10:50.170910", "ingestion_ts": "2026-01-15T12:11:41.230171", "market_id": "0xc0e6b917320a47228fb96e3b5ae0e5c93773a5ae2662ae4e1f37807cfe47ce98", "raw": {"market": "0xc0e6b917320a47228fb96e3b5ae0e5c93773a5ae2662ae4e1f37807cfe47ce98", "asset_id": "81647294538046680798858716589766492074338758116170717123345952330712416337530", "price": "0.999", "size": "442.78", "side": "SELL", "timestamp": "1768475450039", "received_at": "2026-01-15T12:10:50.170910"}}
{"event_type": "price_change", "event_ts": "2026-01-15T12:10:50.172818", "ingestion_ts": "2026-01-15T12:11:41.230171", "market_id": "0xc0e6b917320a47228fb96e3b5ae0e5c93773a5ae2662ae4e1f37807cfe47ce98", "raw": {"market": "0xc0e6b917320a47228fb96e3b5ae0e5c93773a5ae2662ae4e1f37807cfe47ce98", "asset_id": "58656358377246279051017109359677190749228949103591068167284263961542487110215", "price": "0.004", "size": "14.74", "side": "BUY", "timestamp": "1768475450043", "received_at": "2026-01-15T12:10:50.172818"}}
{"event_type": "price_change", "event_ts": "2026-01-15T12:10:50.172818", "ingestion_ts": "2026-01-15T12:11:41.230171", "market_id": "0xc0e6b917320a47228fb96e3b5ae0e5c93773a5ae2662ae4e1f37807cfe47ce98", "raw": {"market": "0xc0e6b917320a47228fb96e3b5ae0e5c93773a5ae2662ae4e1f37807cfe47ce98", "asset_id": "81647294538046680798858716589766492074338758116170717123345952330712416337530", "price": "0.996", "size": "14.74", "side": "SELL", "timestamp": "1768475450043", "received_at": "2026-01-15T12:10:50.172818"}}
{"event_type": "price_change", "event_ts": "2026-01-15T12:10:51.328434", "ingestion_ts": "2026-01-15T12:11:41.230171", "market_id": "0xcab7ba4a9133cfd407d7e73e5757e5abbace413b59421527a31113406c97815c", "raw": {"market": "0xcab7ba4a9133cfd407d7e73e5757e5abbace413b59421527a31113406c97815c", "asset_id": "96361925776989336186111887920533578209326565663637092688733016597062311745569", "price": "0.006", "size": "127.41", "side": "BUY", "timestamp": "1768475451194", "received_at": "2026-01-15T12:10:51.328434"}}
{"event_type": "price_change", "event_ts": "2026-01-15T12:10:51.328434", "ingestion_ts": "2026-01-15T12:11:41.230171", "market_id": "0xcab7ba4a9133cfd407d7e73e5757e5abbace413b59421527a31113406c97815c", "raw": {"market": "0xcab7ba4a9133cfd407d7e73e5757e5abbace413b59421527a31113406c97815c", "asset_id": "20002636398944597965698652220992177552927816915094913583821579024925426590022", "price": "0.994", "size": "127.41", "side": "SELL", "timestamp": "1768475451194", "received_at": "2026-01-15T12:10:51.328434"}}
{"event_type": "price_change", "event_ts": "2026-01-15T12:10:51.328536", "ingestion_ts": "2026-01-15T12:11:41.230171", "market_id": "0xcab7ba4a9133cfd407d7e73e5757e5abbace413b59421527a31113406c97815c", "raw": {"market": "0xcab7ba4a9133cfd407d7e73e5757e5abbace413b59421527a31113406c97815c", "asset_id": "96361925776989336186111887920533578209326565663637092688733016597062311745569", "price": "0.009", "size": "812.25", "side": "BUY", "timestamp": "1768475451194", "received_at": "2026-01-15T12:10:51.328536"}}
{"event_type": "price_change", "event_ts": "2026-01-15T12:10:51.328536", "ingestion_ts": "2026-01-15T12:11:41.230171", "market_id": "0xcab7ba4a9133cfd407d7e73e5757e5abbace413b59421527a31113406c97815c", "raw": {"market": "0xcab7ba4a9133cfd407d7e73e5757e5abbace413b59421527a31113406c97815c", "asset_id": "20002636398944597965698652220992177552927816915094913583821579024925426590022", "price": "0.991", "size": "812.25", "side": "SELL", "timestamp": "1768475451194", "received_at": "2026-01-15T12:10:51.328536"}}
{"event_type": "price_change", "event_ts": "2026-01-15T12:10:51.833168", "ingestion_ts": "2026-01-15T12:11:41.230171", "market_id": "0xcab7ba4a9133cfd407d7e73e5757e5abbace413b59421527a31113406c97815c", "raw": {"market": "0xcab7ba4a9133cfd407d7e73e5757e5abbace413b59421527a31113406c97815c", "asset_id": "96361925776989336186111887920533578209326565663637092688733016597062311745569", "price": "0.009", "size": "818.33", "side": "BUY", "timestamp": "1768475451706", "received_at": "2026-01-15T12:10:51.833168"}}
{"event_type": "price_change", "event_ts": "2026-01-15T12:10:51.833168", "ingestion_ts": "2026-01-15T12:11:41.230171", "market_id": "0xcab7ba4a9133cfd407d7e73e5757e5abbace413b59421527a31113406c97815c", "raw": {"market": "0xcab7ba4a9133cfd407d7e73e5757e5abbace413b59421527a31113406c97815c", "asset_id": "20002636398944597965698652220992177552927816915094913583821579024925426590022", "price": "0.991", "size": "818.33", "side": "SELL", "timestamp": "1768475451706", "received_at": "2026-01-15T12:10:51.833168"}}
{"event_type": "price_change", "event_ts": "2026-01-15T12:10:51.835557", "ingestion_ts": "2026-01-15T12:11:41.230171", "market_id": "0xcab7ba4a9133cfd407d7e73e5757e5abbace413b59421527a31113406c97815c", "raw": {"market": "0xcab7ba4a9133cfd407d7e73e5757e5abbace413b59421527a31113406c97815c", "asset_id": "96361925776989336186111887920533578209326565663637092688733016597062311745569", "price": "0.006", "size": "136.51", "side": "BUY", "timestamp": "1768475451708", "received_at": "2026-01-15T12:10:51.835557"}}
{"event_type": "price_change", "event_ts": "2026-01-15T12:10:51.835557", "ingestion_ts": "2026-01-15T12:11:41.230171", "market_id": "0xcab7ba4a9133cfd407d7e73e5757e5abbace413b59421527a31113406c97815c", "raw": {"market": "0xcab7ba4a9133cfd407d7e73e5757e5abbace413b59421527a31113406c97815c", "asset_id": "20002636398944597965698652220992177552927816915094913583821579024925426590022", "price": "0.994", "size": "136.51", "side": "SELL", "timestamp": "1768475451708", "received_at": "2026-01-15T12:10:51.835557"}}
{"event_type": "price_change", "event_ts": "2026-01-15T12:10:52.406887", "ingestion_ts": "2026-01-15T12:11:41.230171", "market_id": "0x427bc4b40c09b3dcbc973747f0e4b079bed91b3e5a0aed5c36edd0f7591485f4", "raw": {"market": "0x427bc4b40c09b3dcbc973747f0e4b079bed91b3e5a0aed5c36edd0f7591485f4", "asset_id": "115669573443672055876643967408433138119481486650803218131873713375232186497057", "price": "0.002", "size": "63.15", "side": "BUY", "timestamp": "1768475452288", "received_at": "2026-01-15T12:10:52.406887"}}
{"event_type": "price_change", "event_ts": "2026-01-15T12:10:52.406887", "ingestion_ts": "2026-01-15T12:11:41.230171", "market_id": "0x427bc4b40c09b3dcbc973747f0e4b079bed91b3e5a0aed5c36edd0f7591485f4", "raw": {"market": "0x427bc4b40c09b3dcbc973747f0e4b079bed91b3e5a0aed5c36edd0f7591485f4", "asset_id": "86130975769502911188457673769190265049139877688522439001984850068234616395137", "price": "0.998", "size": "63.15", "side": "SELL", "timestamp": "1768475452288", "received_at": "2026-01-15T12:10:52.406887"}}
{"event_type": "price_change", "event_ts": "2026-01-15T12:10:52.775008", "ingestion_ts": "2026-01-15T12:11:41.230171", "market_id": "0x427bc4b40c09b3dcbc973747f0e4b079bed91b3e5a0aed5c36edd0f7591485f4", "raw": {"market": "0x427bc4b40c09b3dcbc973747f0e4b079bed91b3e5a0aed5c36edd0f7591485f4", "asset_id": "115669573443672055876643967408433138119481486650803218131873713375232186497057", "price": "0.002", "size": "72.33", "side": "BUY", "timestamp": "1768475452643", "received_at": "2026-01-15T12:10:52.775008"}}
{"event_type": "price_change", "event_ts": "2026-01-15T12:10:52.775008", "ingestion_ts": "2026-01-15T12:11:41.230171", "market_id": "0x427bc4b40c09b3dcbc973747f0e4b079bed91b3e5a0aed5c36edd0f7591485f4", "raw": {"market": "0x427bc4b40c09b3dcbc973747f0e4b079bed91b3e5a0aed5c36edd0f7591485f4", "asset_id": "86130975769502911188457673769190265049139877688522439001984850068234616395137", "price": "0.998", "size": "72.33", "side": "SELL", "timestamp": "1768475452643", "received_at": "2026-01-15T12:10:52.775008"}}
{"event_type": "price_change", "event_ts": "2026-01-15T12:10:52.960460", "ingestion_ts": "2026-01-15T12:11:41.230171", "market_id": "0xae5584fbb57f23c1c608d544b656f23d8bf12340cef70811cf31bb0cb4fc2115", "raw": {"market": "0xae5584fbb57f23c1c608d544b656f23d8bf12340cef70811cf31bb0cb4fc2115", "asset_id": "28946595841244317705636126646676849578876740730186646421280828201004700559420", "price": "0.004", "size": "1018.66", "side": "BUY", "timestamp": "1768475452833", "received_at": "2026-01-15T12:10:52.960460"}}
{"event_type": "price_change", "event_ts": "2026-01-15T12:10:52.960460", "ingestion_ts": "2026-01-15T12:11:41.230171", "market_id": "0xae5584fbb57f23c1c608d544b656f23d8bf12340cef70811cf31bb0cb4fc2115", "raw": {"market": "0xae5584fbb57f23c1c608d544b656f23d8bf12340cef70811cf31bb0cb4fc2115", "asset_id": "42278252558046940014991595990628759801692726198478046188873057685686228021663", "price": "0.996", "size": "1018.66", "side": "SELL", "timestamp": "1768475452833", "received_at": "2026-01-15T12:10:52.960460"}}
{"event_type": "price_change", "event_ts": "2026-01-15T12:10:52.960556", "ingestion_ts": "2026-01-15T12:11:41.230171", "market_id": "0xae5584fbb57f23c1c608d544b656f23d8bf12340cef70811cf31bb0cb4fc2115", "raw": {"market": "0xae5584fbb57f23c1c608d544b656f23d8bf12340cef70811cf31bb0cb4fc2115", "asset_id": "28946595841244317705636126646676849578876740730186646421280828201004700559420", "price": "0.008", "size": "10770.93", "side": "BUY", "timestamp": "1768475452833", "received_at": "2026-01-15T12:10:52.960556"}}
{"event_type": "price_change", "event_ts": "2026-01-15T12:10:52.960556", "ingestion_ts": "2026-01-15T12:11:41.230171", "market_id": "0xae5584fbb57f23c1c608d544b656f23d8bf12340cef70811cf31bb0cb4fc2115", "raw": {"market": "0xae5584fbb57f23c1c608d544b656f23d8bf12340cef70811cf31bb0cb4fc2115", "asset_id": "42278252558046940014991595990628759801692726198478046188873057685686228021663", "price": "0.992", "size": "10770.93", "side": "SELL", "timestamp": "1768475452833", "received_at": "2026-01-15T12:10:52.960556"}}
{"event_type": "price_change", "event_ts": "2026-01-15T12:10:53.080868", "ingestion_ts": "2026-01-15T12:11:41.230171", "market_id": "0xc0e6b917320a47228fb96e3b5ae0e5c93773a5ae2662ae4e1f37807cfe47ce98", "raw": {"market": "0xc0e6b917320a47228fb96e3b5ae0e5c93773a5ae2662ae4e1f37807cfe47ce98", "asset_id": "58656358377246279051017109359677190749228949103591068167284263961542487110215", "price": "0.003", "size": "418.98", "side": "BUY", "timestamp": "1768475452962", "received_at": "2026-01-15T12:10:53.080868"}}
{"event_type": "price_change", "event_ts": "2026-01-15T12:10:53.080868", "ingestion_ts": "2026-01-15T12:11:41.230171", "market_id": "0xc0e6b917320a47228fb96e3b5ae0e5c93773a5ae2662ae4e1f37807cfe47ce98", "raw": {"market": "0xc0e6b917320a47228fb96e3b5ae0e5c93773a5ae2662ae4e1f37807cfe47ce98", "asset_id": "81647294538046680798858716589766492074338758116170717123345952330712416337530", "price": "0.997", "size": "418.98", "side": "SELL", "timestamp": "1768475452962", "received_at": "2026-01-15T12:10:53.080868"}}
{"event_type": "price_change", "event_ts": "2026-01-15T12:10:53.080905", "ingestion_ts": "2026-01-15T12:11:41.230171", "market_id": "0xc0e6b917320a47228fb96e3b5ae0e5c93773a5ae2662ae4e1f37807cfe47ce98", "raw": {"market": "0xc0e6b917320a47228fb96e3b5ae0e5c93773a5ae2662ae4e1f37807cfe47ce98", "asset_id": "58656358377246279051017109359677190749228949103591068167284263961542487110215", "price": "0.004", "size": "7.37", "side": "BUY", "timestamp": "1768475452962", "received_at": "2026-01-15T12:10:53.080905"}}
{"event_type": "price_change", "event_ts": "2026-01-15T12:10:53.080905", "ingestion_ts": "2026-01-15T12:11:41.230171", "market_id": "0xc0e6b917320a47228fb96e3b5ae0e5c93773a5ae2662ae4e1f37807cfe47ce98", "raw": {"market": "0xc0e6b917320a47228fb96e3b5ae0e5c93773a5ae2662ae4e1f37807cfe47ce98", "asset_id": "81647294538046680798858716589766492074338758116170717123345952330712416337530", "price": "0.996", "size": "7.37", "side": "SELL", "timestamp": "1768475452962", "received_at": "2026-01-15T12:10:53.080905"}}
{"event_type": "price_change", "event_ts": "2026-01-15T12:10:53.164369", "ingestion_ts": "2026-01-15T12:11:41.230171", "market_id": "0x427bc4b40c09b3dcbc973747f0e4b079bed91b3e5a0aed5c36edd0f7591485f4", "raw": {"market": "0x427bc4b40c09b3dcbc973747f0e4b079bed91b3e5a0aed5c36edd0f7591485f4", "asset_id": "115669573443672055876643967408433138119481486650803218131873713375232186497057", "price": "0.162", "size": "0", "side": "SELL", "timestamp": "1768475453034", "received_at": "2026-01-15T12:10:53.164369"}}
{"event_type": "price_change", "event_ts": "2026-01-15T12:10:53.164369", "ingestion_ts": "2026-01-15T12:11:41.230171", "market_id": "0x427bc4b40c09b3dcbc973747f0e4b079bed91b3e5a0aed5c36edd0f7591485f4", "raw": {"market": "0x427bc4b40c09b3dcbc973747f0e4b079bed91b3e5a0aed5c36edd0f7591485f4", "asset_id": "86130975769502911188457673769190265049139877688522439001984850068234616395137", "price": "0.838", "size": "0", "side": "BUY", "timestamp": "1768475453034", "received_at": "2026-01-15T12:10:53.164369"}}
{"event_type": "price_change", "event_ts": "2026-01-15T12:10:53.544261", "ingestion_ts": "2026-01-15T12:11:41.230171", "market_id": "0x427bc4b40c09b3dcbc973747f0e4b079bed91b3e5a0aed5c36edd0f7591485f4", "raw": {"market": "0x427bc4b40c09b3dcbc973747f0e4b079bed91b3e5a0aed5c36edd0f7591485f4", "asset_id": "115669573443672055876643967408433138119481486650803218131873713375232186497057", "price": "0.161", "size": "7.96", "side": "SELL", "timestamp": "1768475453406", "received_at": "2026-01-15T12:10:53.544261"}}
{"event_type": "price_change", "event_ts": "2026-01-15T12:10:53.544261", "ingestion_ts": "2026-01-15T12:11:41.230171", "market_id": "0x427bc4b40c09b3dcbc973747f0e4b079bed91b3e5a0aed5c36edd0f7591485f4", "raw": {"market": "0x427bc4b40c09b3dcbc973747f0e4b079bed91b3e5a0aed5c36edd0f7591485f4", "asset_id": "86130975769502911188457673769190265049139877688522439001984850068234616395137", "price": "0.839", "size": "7.96", "side": "BUY", "timestamp": "1768475453406", "received_at": "2026-01-15T12:10:53.544261"}}
{"event_type": "price_change", "event_ts": "2026-01-15T12:10:53.895918", "ingestion_ts": "2026-01-15T12:11:41.230171", "market_id": "0xc0e6b917320a47228fb96e3b5ae0e5c93773a5ae2662ae4e1f37807cfe47ce98", "raw": {"market": "0xc0e6b917320a47228fb96e3b5ae0e5c93773a5ae2662ae4e1f37807cfe47ce98", "asset_id": "58656358377246279051017109359677190749228949103591068167284263961542487110215", "price": "0.002", "size": "3322.18", "side": "BUY", "timestamp": "1768475453773", "received_at": "2026-01-15T12:10:53.895918"}}
{"event_type": "price_change", "event_ts": "2026-01-15T12:10:53.895918", "ingestion_ts": "2026-01-15T12:11:41.230171", "market_id": "0xc0e6b917320a47228fb96e3b5ae0e5c93773a5ae2662ae4e1f37807cfe47ce98", "raw": {"market": "0xc0e6b917320a47228fb96e3b5ae0e5c93773a5ae2662ae4e1f37807cfe47ce98", "asset_id": "81647294538046680798858716589766492074338758116170717123345952330712416337530", "price": "0.998", "size": "3322.18", "side": "SELL", "timestamp": "1768475453773", "received_at": "2026-01-15T12:10:53.895918"}}
{"event_type": "price_change", "event_ts": "2026-01-15T12:10:53.896007", "ingestion_ts": "2026-01-15T12:11:41.230171", "market_id": "0xc0e6b917320a47228fb96e3b5ae0e5c93773a5ae2662ae4e1f37807cfe47ce98", "raw": {"market": "0xc0e6b917320a47228fb96e3b5ae0e5c93773a5ae2662ae4e1f37807cfe47ce98", "asset_id": "58656358377246279051017109359677190749228949103591068167284263961542487110215", "price": "0.002", "size": "3340.06", "side": "BUY", "timestamp": "1768475453774", "received_at": "2026-01-15T12:10:53.896007"}}
{"event_type": "price_change", "event_ts": "2026-01-15T12:10:53.896007", "ingestion_ts": "2026-01-15T12:11:41.230171", "market_id": "0xc0e6b917320a47228fb96e3b5ae0e5c93773a5ae2662ae4e1f37807cfe47ce98", "raw": {"market": "0xc0e6b917320a47228fb96e3b5ae0e5c93773a5ae2662ae4e1f37807cfe47ce98", "asset_id": "81647294538046680798858716589766492074338758116170717123345952330712416337530", "price": "0.998", "size": "3340.06", "side": "SELL", "timestamp": "1768475453774", "received_at": "2026-01-15T12:10:53.896007"}}
{"event_type": "price_change", "event_ts": "2026-01-15T12:10:54.025076", "ingestion_ts": "2026-01-15T12:11:41.230171", "market_id": "0xcab7ba4a9133cfd407d7e73e5757e5abbace413b59421527a31113406c97815c", "raw": {"market": "0xcab7ba4a9133cfd407d7e73e5757e5abbace413b59421527a31113406c97815c", "asset_id": "96361925776989336186111887920533578209326565663637092688733016597062311745569", "price": "0.006", "size": "127.41", "side": "BUY", "timestamp": "1768475453907", "received_at": "2026-01-15T12:10:54.025076"}}
{"event_type": "price_change", "event_ts": "2026-01-15T12:10:54.025076", "ingestion_ts": "2026-01-15T12:11:41.230171", "market_id": "0xcab7ba4a9133cfd407d7e73e5757e5abbace413b59421527a31113406c97815c", "raw": {"market": "0xcab7ba4a9133cfd407d7e73e5757e5abbace413b59421527a31113406c97815c", "asset_id": "20002636398944597965698652220992177552927816915094913583821579024925426590022", "price": "0.994", "size": "127.41", "side": "SELL", "timestamp": "1768475453907", "received_at": "2026-01-15T12:10:54.025076"}}
{"event_type": "price_change", "event_ts": "2026-01-15T12:10:54.025178", "ingestion_ts": "2026-01-15T12:11:41.230171", "market_id": "0xcab7ba4a9133cfd407d7e73e5757e5abbace413b59421527a31113406c97815c", "raw": {"market": "0xcab7ba4a9133cfd407d7e73e5757e5abbace413b59421527a31113406c97815c", "asset_id": "96361925776989336186111887920533578209326565663637092688733016597062311745569", "price": "0.009", "size": "812.25", "side": "BUY", "timestamp": "1768475453907", "received_at": "2026-01-15T12:10:54.025178"}}
{"event_type": "price_change", "event_ts": "2026-01-15T12:10:54.025178", "ingestion_ts": "2026-01-15T12:11:41.230171", "market_id": "0xcab7ba4a9133cfd407d7e73e5757e5abbace413b59421527a31113406c97815c", "raw": {"market": "0xcab7ba4a9133cfd407d7e73e5757e5abbace413b59421527a31113406c97815c", "asset_id": "20002636398944597965698652220992177552927816915094913583821579024925426590022", "price": "0.991", "size": "812.25", "side": "SELL", "timestamp": "1768475453907", "received_at": "2026-01-15T12:10:54.025178"}}
{"event_type": "price_change", "event_ts": "2026-01-15T12:10:54.390057", "ingestion_ts": "2026-01-15T12:11:41.230171", "market_id": "0xcab7ba4a9133cfd407d7e73e5757e5abbace413b59421527a31113406c97815c", "raw": {"market": "0xcab7ba4a9133cfd407d7e73e5757e5abbace413b59421527a31113406c97815c", "asset_id": "96361925776989336186111887920533578209326565663637092688733016597062311745569", "price": "0.009", "size": "818.33", "side": "BUY", "timestamp": "1768475454267", "received_at": "2026-01-15T12:10:54.390057"}}
{"event_type": "price_change", "event_ts": "2026-01-15T12:10:54.390057", "ingestion_ts": "2026-01-15T12:11:41.230171", "market_id": "0xcab7ba4a9133cfd407d7e73e5757e5abbace413b59421527a31113406c97815c", "raw": {"market": "0xcab7ba4a9133cfd407d7e73e5757e5abbace413b59421527a31113406c97815c", "asset_id": "20002636398944597965698652220992177552927816915094913583821579024925426590022", "price": "0.991", "size": "818.33", "side": "SELL", "timestamp": "1768475454267", "received_at": "2026-01-15T12:10:54.390057"}}
{"event_type": "price_change", "event_ts": "2026-01-15T12:10:54.390094", "ingestion_ts": "2026-01-15T12:11:41.230171", "market_id": "0xcab7ba4a9133cfd407d7e73e5757e5abbace413b59421527a31113406c97815c", "raw": {"market": "0xcab7ba4a9133cfd407d7e73e5757e5abbace413b59421527a31113406c97815c", "asset_id": "96361925776989336186111887920533578209326565663637092688733016597062311745569", "price": "0.006", "size": "136.51", "side": "BUY", "timestamp": "1768475454268", "received_at": "2026-01-15T12:10:54.390094"}}
{"event_type": "price_change", "event_ts": "2026-01-15T12:10:54.390094", "ingestion_ts": "2026-01-15T12:11:41.230171", "market_id": "0xcab7ba4a9133cfd407d7e73e5757e5abbace413b59421527a31113406c97815c", "raw": {"market": "0xcab7ba4a9133cfd407d7e73e5757e5abbace413b59421527a31113406c97815c", "asset_id": "20002636398944597965698652220992177552927816915094913583821579024925426590022", "price": "0.994", "size": "136.51", "side": "SELL", "timestamp": "1768475454268", "received_at": "2026-01-15T12:10:54.390094"}}
{"event_type": "price_change", "event_ts": "2026-01-15T12:10:54.935624", "ingestion_ts": "2026-01-15T12:11:41.230171", "market_id": "0xc0e6b917320a47228fb96e3b5ae0e5c93773a5ae2662ae4e1f37807cfe47ce98", "raw": {"market": "0xc0e6b917320a47228fb96e3b5ae0e5c93773a5ae2662ae4e1f37807cfe47ce98", "asset_id": "58656358377246279051017109359677190749228949103591068167284263961542487110215", "price": "0.002", "size": "3322.18", "side": "BUY", "timestamp": "1768475454817", "received_at": "2026-01-15T12:10:54.935624"}}
{"event_type": "price_change", "event_ts": "2026-01-15T12:10:54.935624", "ingestion_ts": "2026-01-15T12:11:41.230171", "market_id": "0xc0e6b917320a47228fb96e3b5ae0e5c93773a5ae2662ae4e1f37807cfe47ce98", "raw": {"market": "0xc0e6b917320a47228fb96e3b5ae0e5c93773a5ae2662ae4e1f37807cfe47ce98", "asset_id": "81647294538046680798858716589766492074338758116170717123345952330712416337530", "price": "0.998", "size": "3322.18", "side": "SELL", "timestamp": "1768475454817", "received_at": "2026-01-15T12:10:54.935624"}}
{"event_type": "price_change", "event_ts": "2026-01-15T12:10:54.935692", "ingestion_ts": "2026-01-15T12:11:41.230171", "market_id": "0xc0e6b917320a47228fb96e3b5ae0e5c93773a5ae2662ae4e1f37807cfe47ce98", "raw": {"market": "0xc0e6b917320a47228fb96e3b5ae0e5c93773a5ae2662ae4e1f37807cfe47ce98", "asset_id": "58656358377246279051017109359677190749228949103591068167284263961542487110215", "price": "0.004", "size": "0", "side": "BUY", "timestamp": "1768475454817", "received_at": "2026-01-15T12:10:54.935692"}}
{"event_type": "price_change", "event_ts": "2026-01-15T12:10:54.935692", "ingestion_ts": "2026-01-15T12:11:41.230171", "market_id": "0xc0e6b917320a47228fb96e3b5ae0e5c93773a5ae2662ae4e1f37807cfe47ce98", "raw": {"market": "0xc0e6b917320a47228fb96e3b5ae0e5c93773a5ae2662ae4e1f37807cfe47ce98", "asset_id": "81647294538046680798858716589766492074338758116170717123345952330712416337530", "price": "0.996", "size": "0", "side": "SELL", "timestamp": "1768475454817", "received_at": "2026-01-15T12:10:54.935692"}}
{"event_type": "price_change", "event_ts": "2026-01-15T12:10:56.045418", "ingestion_ts": "2026-01-15T12:11:41.230171", "market_id": "0xc0e6b917320a47228fb96e3b5ae0e5c93773a5ae2662ae4e1f37807cfe47ce98", "raw": {"market": "0xc0e6b917320a47228fb96e3b5ae0e5c93773a5ae2662ae4e1f37807cfe47ce98", "asset_id": "58656358377246279051017109359677190749228949103591068167284263961542487110215", "price": "0.005", "size": "9.5", "side": "BUY", "timestamp": "1768475455921", "received_at": "2026-01-15T12:10:56.045418"}}
{"event_type": "price_change", "event_ts": "2026-01-15T12:10:56.045418", "ingestion_ts": "2026-01-15T12:11:41.230171", "market_id": "0xc0e6b917320a47228fb96e3b5ae0e5c93773a5ae2662ae4e1f37807cfe47ce98", "raw": {"market": "0xc0e6b917320a47228fb96e3b5ae0e5c93773a5ae2662ae4e1f37807cfe47ce98", "asset_id": "81647294538046680798858716589766492074338758116170717123345952330712416337530", "price": "0.995", "size": "9.5", "side": "SELL", "timestamp": "1768475455921", "received_at": "2026-01-15T12:10:56.045418"}}
{"event_type": "price_change", "event_ts": "2026-01-15T12:10:56.047254", "ingestion_ts": "2026-01-15T12:11:41.230171", "market_id": "0xc0e6b917320a47228fb96e3b5ae0e5c93773a5ae2662ae4e1f37807cfe47ce98", "raw": {"market": "0xc0e6b917320a47228fb96e3b5ae0e5c93773a5ae2662ae4e1f37807cfe47ce98", "asset_id": "58656358377246279051017109359677190749228949103591068167284263961542487110215", "price": "0.005", "size": "16.02", "side": "BUY", "timestamp": "1768475455922", "received_at": "2026-01-15T12:10:56.047254"}}
{"event_type": "price_change", "event_ts": "2026-01-15T12:10:56.047254", "ingestion_ts": "2026-01-15T12:11:41.230171", "market_id": "0xc0e6b917320a47228fb96e3b5ae0e5c93773a5ae2662ae4e1f37807cfe47ce98", "raw": {"market": "0xc0e6b917320a47228fb96e3b5ae0e5c93773a5ae2662ae4e1f37807cfe47ce98", "asset_id": "81647294538046680798858716589766492074338758116170717123345952330712416337530", "price": "0.995", "size": "16.02", "side": "SELL", "timestamp": "1768475455922", "received_at": "2026-01-15T12:10:56.047254"}}
{"event_type": "price_change", "event_ts": "2026-01-15T12:10:56.211621", "ingestion_ts": "2026-01-15T12:11:41.230171", "market_id": "0x427bc4b40c09b3dcbc973747f0e4b079bed91b3e5a0aed5c36edd0f7591485f4", "raw": {"market": "0x427bc4b40c09b3dcbc973747f0e4b079bed91b3e5a0aed5c36edd0f7591485f4", "asset_id": "115669573443672055876643967408433138119481486650803218131873713375232186497057", "price": "0.002", "size": "63.15", "side": "BUY", "timestamp": "1768475456087", "received_at": "2026-01-15T12:10:56.211621"}}
{"event_type": "price_change", "event_ts": "2026-01-15T12:10:56.211621", "ingestion_ts": "2026-01-15T12:11:41.230171", "market_id": "0x427bc4b40c09b3dcbc973747f0e4b079bed91b3e5a0aed5c36edd0f7591485f4", "raw": {"market": "0x427bc4b40c09b3dcbc973747f0e4b079bed91b3e5a0aed5c36edd0f7591485f4", "asset_id": "86130975769502911188457673769190265049139877688522439001984850068234616395137", "price": "0.998", "size": "63.15", "side": "SELL", "timestamp": "1768475456087", "received_at": "2026-01-15T12:10:56.211621"}}
{"event_type": "price_change", "event_ts": "2026-01-15T12:10:56.521695", "ingestion_ts": "2026-01-15T12:11:41.230171", "market_id": "0x427bc4b40c09b3dcbc973747f0e4b079bed91b3e5a0aed5c36edd0f7591485f4", "raw": {"market": "0x427bc4b40c09b3dcbc973747f0e4b079bed91b3e5a0aed5c36edd0f7591485f4", "asset_id": "115669573443672055876643967408433138119481486650803218131873713375232186497057", "price": "0.002", "size": "72.33", "side": "BUY", "timestamp": "1768475456405", "received_at": "2026-01-15T12:10:56.521695"}}
{"event_type": "price_change", "event_ts": "2026-01-15T12:10:56.521695", "ingestion_ts": "2026-01-15T12:11:41.230171", "market_id": "0x427bc4b40c09b3dcbc973747f0e4b079bed91b3e5a0aed5c36edd0f7591485f4", "raw": {"market": "0x427bc4b40c09b3dcbc973747f0e4b079bed91b3e5a0aed5c36edd0f7591485f4", "asset_id": "86130975769502911188457673769190265049139877688522439001984850068234616395137", "price": "0.998", "size": "72.33", "side": "SELL", "timestamp": "1768475456405", "received_at": "2026-01-15T12:10:56.521695"}}
{"event_type": "price_change", "event_ts": "2026-01-15T12:10:57.270933", "ingestion_ts": "2026-01-15T12:11:41.230171", "market_id": "0x427bc4b40c09b3dcbc973747f0e4b079bed91b3e5a0aed5c36edd0f7591485f4", "raw": {"market": "0x427bc4b40c09b3dcbc973747f0e4b079bed91b3e5a0aed5c36edd0f7591485f4", "asset_id": "115669573443672055876643967408433138119481486650803218131873713375232186497057", "price": "0.161", "size": "0", "side": "SELL", "timestamp": "1768475456980", "received_at": "2026-01-15T12:10:57.270933"}}
{"event_type": "price_change", "event_ts": "2026-01-15T12:10:57.270933", "ingestion_ts": "2026-01-15T12:11:41.230171", "market_id": "0x427bc4b40c09b3dcbc973747f0e4b079bed91b3e5a0aed5c36edd0f7591485f4", "raw": {"market": "0x427bc4b40c09b3dcbc973747f0e4b079bed91b3e5a0aed5c36edd0f7591485f4", "asset_id": "86130975769502911188457673769190265049139877688522439001984850068234616395137", "price": "0.839", "size": "0", "side": "BUY", "timestamp": "1768475456980", "received_at": "2026-01-15T12:10:57.270933"}}
{"event_type": "price_change", "event_ts": "2026-01-15T12:10:57.387141", "ingestion_ts": "2026-01-15T12:11:41.230171", "market_id": "0x427bc4b40c09b3dcbc973747f0e4b079bed91b3e5a0aed5c36edd0f7591485f4", "raw": {"market": "0x427bc4b40c09b3dcbc973747f0e4b079bed91b3e5a0aed5c36edd0f7591485f4", "asset_id": "115669573443672055876643967408433138119481486650803218131873713375232186497057", "price": "0.16", "size": "7.96", "side": "SELL", "timestamp": "1768475457143", "received_at": "2026-01-15T12:10:57.387141"}}
{"event_type": "price_change", "event_ts": "2026-01-15T12:10:57.387141", "ingestion_ts": "2026-01-15T12:11:41.230171", "market_id": "0x427bc4b40c09b3dcbc973747f0e4b079bed91b3e5a0aed5c36edd0f7591485f4", "raw": {"market": "0x427bc4b40c09b3dcbc973747f0e4b079bed91b3e5a0aed5c36edd0f7591485f4", "asset_id": "86130975769502911188457673769190265049139877688522439001984850068234616395137", "price": "0.84", "size": "7.96", "side": "BUY", "timestamp": "1768475457143", "received_at": "2026-01-15T12:10:57.387141"}}
{"event_type": "price_change", "event_ts": "2026-01-15T12:10:57.815312", "ingestion_ts": "2026-01-15T12:11:41.230171", "market_id": "0xc0e6b917320a47228fb96e3b5ae0e5c93773a5ae2662ae4e1f37807cfe47ce98", "raw": {"market": "0xc0e6b917320a47228fb96e3b5ae0e5c93773a5ae2662ae4e1f37807cfe47ce98", "asset_id": "58656358377246279051017109359677190749228949103591068167284263961542487110215", "price": "0.002", "size": "3304.3", "side": "BUY", "timestamp": "1768475457696", "received_at": "2026-01-15T12:10:57.815312"}}
{"event_type": "price_change", "event_ts": "2026-01-15T12:10:57.815312", "ingestion_ts": "2026-01-15T12:11:41.230171", "market_id": "0xc0e6b917320a47228fb96e3b5ae0e5c93773a5ae2662ae4e1f37807cfe47ce98", "raw": {"market": "0xc0e6b917320a47228fb96e3b5ae0e5c93773a5ae2662ae4e1f37807cfe47ce98", "asset_id": "81647294538046680798858716589766492074338758116170717123345952330712416337530", "price": "0.998", "size": "3304.3", "side": "SELL", "timestamp": "1768475457696", "received_at": "2026-01-15T12:10:57.815312"}}
{"event_type": "price_change", "event_ts": "2026-01-15T12:10:57.816545", "ingestion_ts": "2026-01-15T12:11:41.230171", "market_id": "0xc0e6b917320a47228fb96e3b5ae0e5c93773a5ae2662ae4e1f37807cfe47ce98", "raw": {"market": "0xc0e6b917320a47228fb96e3b5ae0e5c93773a5ae2662ae4e1f37807cfe47ce98", "asset_id": "58656358377246279051017109359677190749228949103591068167284263961542487110215", "price": "0.005", "size": "9.5", "side": "BUY", "timestamp": "1768475457696", "received_at": "2026-01-15T12:10:57.816545"}}
{"event_type": "price_change", "event_ts": "2026-01-15T12:10:57.816545", "ingestion_ts": "2026-01-15T12:11:41.230171", "market_id": "0xc0e6b917320a47228fb96e3b5ae0e5c93773a5ae2662ae4e1f37807cfe47ce98", "raw": {"market": "0xc0e6b917320a47228fb96e3b5ae0e5c93773a5ae2662ae4e1f37807cfe47ce98", "asset_id": "81647294538046680798858716589766492074338758116170717123345952330712416337530", "price": "0.995", "size": "9.5", "side": "SELL", "timestamp": "1768475457696", "received_at": "2026-01-15T12:10:57.816545"}}
{"event_type": "price_change", "event_ts": "2026-01-15T12:10:58.298528", "ingestion_ts": "2026-01-15T12:11:41.230171", "market_id": "0xcab7ba4a9133cfd407d7e73e5757e5abbace413b59421527a31113406c97815c", "raw": {"market": "0xcab7ba4a9133cfd407d7e73e5757e5abbace413b59421527a31113406c97815c", "asset_id": "96361925776989336186111887920533578209326565663637092688733016597062311745569", "price": "0.006", "size": "127.41", "side": "BUY", "timestamp": "1768475458179", "received_at": "2026-01-15T12:10:58.298528"}}
{"event_type": "price_change", "event_ts": "2026-01-15T12:10:58.298528", "ingestion_ts": "2026-01-15T12:11:41.230171", "market_id": "0xcab7ba4a9133cfd407d7e73e5757e5abbace413b59421527a31113406c97815c", "raw": {"market": "0xcab7ba4a9133cfd407d7e73e5757e5abbace413b59421527a31113406c97815c", "asset_id": "20002636398944597965698652220992177552927816915094913583821579024925426590022", "price": "0.994", "size": "127.41", "side": "SELL", "timestamp": "1768475458179", "received_at": "2026-01-15T12:10:58.298528"}}
{"event_type": "price_change", "event_ts": "2026-01-15T12:10:58.298566", "ingestion_ts": "2026-01-15T12:11:41.230171", "market_id": "0xcab7ba4a9133cfd407d7e73e5757e5abbace413b59421527a31113406c97815c", "raw": {"market": "0xcab7ba4a9133cfd407d7e73e5757e5abbace413b59421527a31113406c97815c", "asset_id": "96361925776989336186111887920533578209326565663637092688733016597062311745569", "price": "0.009", "size": "812.25", "side": "BUY", "timestamp": "1768475458179", "received_at": "2026-01-15T12:10:58.298566"}}
{"event_type": "price_change", "event_ts": "2026-01-15T12:10:58.298566", "ingestion_ts": "2026-01-15T12:11:41.230171", "market_id": "0xcab7ba4a9133cfd407d7e73e5757e5abbace413b59421527a31113406c97815c", "raw": {"market": "0xcab7ba4a9133cfd407d7e73e5757e5abbace413b59421527a31113406c97815c", "asset_id": "20002636398944597965698652220992177552927816915094913583821579024925426590022", "price": "0.991", "size": "812.25", "side": "SELL", "timestamp": "1768475458179", "received_at": "2026-01-15T12:10:58.298566"}}
{"event_type": "price_change", "event_ts": "2026-01-15T12:10:58.521074", "ingestion_ts": "2026-01-15T12:11:41.230171", "market_id": "0xc0e6b917320a47228fb96e3b5ae0e5c93773a5ae2662ae4e1f37807cfe47ce98", "raw": {"market": "0xc0e6b917320a47228fb96e3b5ae0e5c93773a5ae2662ae4e1f37807cfe47ce98", "asset_id": "58656358377246279051017109359677190749228949103591068167284263961542487110215", "price": "0.006", "size": "5.7", "side": "BUY", "timestamp": "1768475458391", "received_at": "2026-01-15T12:10:58.521074"}}
{"event_type": "price_change", "event_ts": "2026-01-15T12:10:58.521074", "ingestion_ts": "2026-01-15T12:11:41.230171", "market_id": "0xc0e6b917320a47228fb96e3b5ae0e5c93773a5ae2662ae4e1f37807cfe47ce98", "raw": {"market": "0xc0e6b917320a47228fb96e3b5ae0e5c93773a5ae2662ae4e1f37807cfe47ce98", "asset_id": "81647294538046680798858716589766492074338758116170717123345952330712416337530", "price": "0.994", "size": "5.7", "side": "SELL", "timestamp": "1768475458391", "received_at": "2026-01-15T12:10:58.521074"}}
{"event_type": "price_change", "event_ts": "2026-01-15T12:10:58.521200", "ingestion_ts": "2026-01-15T12:11:41.230171", "market_id": "0xc0e6b917320a47228fb96e3b5ae0e5c93773a5ae2662ae4e1f37807cfe47ce98", "raw": {"market": "0xc0e6b917320a47228fb96e3b5ae0e5c93773a5ae2662ae4e1f37807cfe47ce98", "asset_id": "58656358377246279051017109359677190749228949103591068167284263961542487110215", "price": "0.006", "size": "11.4", "side": "BUY", "timestamp": "1768475458393", "received_at": "2026-01-15T12:10:58.521200"}}
{"event_type": "price_change", "event_ts": "2026-01-15T12:10:58.521200", "ingestion_ts": "2026-01-15T12:11:41.230171", "market_id": "0xc0e6b917320a47228fb96e3b5ae0e5c93773a5ae2662ae4e1f37807cfe47ce98", "raw": {"market": "0xc0e6b917320a47228fb96e3b5ae0e5c93773a5ae2662ae4e1f37807cfe47ce98", "asset_id": "81647294538046680798858716589766492074338758116170717123345952330712416337530", "price": "0.994", "size": "11.4", "side": "SELL", "timestamp": "1768475458393", "received_at": "2026-01-15T12:10:58.521200"}}
{"event_type": "price_change", "event_ts": "2026-01-15T12:10:58.736235", "ingestion_ts": "2026-01-15T12:11:41.230171", "market_id": "0xcab7ba4a9133cfd407d7e73e5757e5abbace413b59421527a31113406c97815c", "raw": {"market": "0xcab7ba4a9133cfd407d7e73e5757e5abbace413b59421527a31113406c97815c", "asset_id": "96361925776989336186111887920533578209326565663637092688733016597062311745569", "price": "0.006", "size": "136.51", "side": "BUY", "timestamp": "1768475458619", "received_at": "2026-01-15T12:10:58.736235"}}
{"event_type": "price_change", "event_ts": "2026-01-15T12:10:58.736235", "ingestion_ts": "2026-01-15T12:11:41.230171", "market_id": "0xcab7ba4a9133cfd407d7e73e5757e5abbace413b59421527a31113406c97815c", "raw": {"market": "0xcab7ba4a9133cfd407d7e73e5757e5abbace413b59421527a31113406c97815c", "asset_id": "20002636398944597965698652220992177552927816915094913583821579024925426590022", "price": "0.994", "size": "136.51", "side": "SELL", "timestamp": "1768475458619", "received_at": "2026-01-15T12:10:58.736235"}}
{"event_type": "price_change", "event_ts": "2026-01-15T12:10:58.737239", "ingestion_ts": "2026-01-15T12:11:41.230171", "market_id": "0xcab7ba4a9133cfd407d7e73e5757e5abbace413b59421527a31113406c97815c", "raw": {"market": "0xcab7ba4a9133cfd407d7e73e5757e5abbace413b59421527a31113406c97815c", "asset_id": "96361925776989336186111887920533578209326565663637092688733016597062311745569", "price": "0.009", "size": "818.33", "side": "BUY", "timestamp": "1768475458620", "received_at": "2026-01-15T12:10:58.737239"}}
{"event_type": "price_change", "event_ts": "2026-01-15T12:10:58.737239", "ingestion_ts": "2026-01-15T12:11:41.230171", "market_id": "0xcab7ba4a9133cfd407d7e73e5757e5abbace413b59421527a31113406c97815c", "raw": {"market": "0xcab7ba4a9133cfd407d7e73e5757e5abbace413b59421527a31113406c97815c", "asset_id": "20002636398944597965698652220992177552927816915094913583821579024925426590022", "price": "0.991", "size": "818.33", "side": "SELL", "timestamp": "1768475458620", "received_at": "2026-01-15T12:10:58.737239"}}
{"event_type": "price_change", "event_ts": "2026-01-15T12:10:59.223716", "ingestion_ts": "2026-01-15T12:11:41.230171", "market_id": "0xc0e6b917320a47228fb96e3b5ae0e5c93773a5ae2662ae4e1f37807cfe47ce98", "raw": {"market": "0xc0e6b917320a47228fb96e3b5ae0e5c93773a5ae2662ae4e1f37807cfe47ce98", "asset_id": "58656358377246279051017109359677190749228949103591068167284263961542487110215", "price": "0.005", "size": "2.98", "side": "BUY", "timestamp": "1768475459100", "received_at": "2026-01-15T12:10:59.223716"}}
{"event_type": "price_change", "event_ts": "2026-01-15T12:10:59.223716", "ingestion_ts": "2026-01-15T12:11:41.230171", "market_id": "0xc0e6b917320a47228fb96e3b5ae0e5c93773a5ae2662ae4e1f37807cfe47ce98", "raw": {"market": "0xc0e6b917320a47228fb96e3b5ae0e5c93773a5ae2662ae4e1f37807cfe47ce98", "asset_id": "81647294538046680798858716589766492074338758116170717123345952330712416337530", "price": "0.995", "size": "2.98", "side": "SELL", "timestamp": "1768475459100", "received_at": "2026-01-15T12:10:59.223716"}}
{"event_type": "price_change", "event_ts": "2026-01-15T12:10:59.223755", "ingestion_ts": "2026-01-15T12:11:41.230171", "market_id": "0xc0e6b917320a47228fb96e3b5ae0e5c93773a5ae2662ae4e1f37807cfe47ce98", "raw": {"market": "0xc0e6b917320a47228fb96e3b5ae0e5c93773a5ae2662ae4e1f37807cfe47ce98", "asset_id": "58656358377246279051017109359677190749228949103591068167284263961542487110215", "price": "0.006", "size": "5.7", "side": "BUY", "timestamp": "1768475459100", "received_at": "2026-01-15T12:10:59.223755"}}
{"event_type": "price_change", "event_ts": "2026-01-15T12:10:59.223755", "ingestion_ts": "2026-01-15T12:11:41.230171", "market_id": "0xc0e6b917320a47228fb96e3b5ae0e5c93773a5ae2662ae4e1f37807cfe47ce98", "raw": {"market": "0xc0e6b917320a47228fb96e3b5ae0e5c93773a5ae2662ae4e1f37807cfe47ce98", "asset_id": "81647294538046680798858716589766492074338758116170717123345952330712416337530", "price": "0.994", "size": "5.7", "side": "SELL", "timestamp": "1768475459100", "received_at": "2026-01-15T12:10:59.223755"}}
{"event_type": "price_change", "event_ts": "2026-01-15T12:10:59.730496", "ingestion_ts": "2026-01-15T12:11:41.230171", "market_id": "0xc0e6b917320a47228fb96e3b5ae0e5c93773a5ae2662ae4e1f37807cfe47ce98", "raw": {"market": "0xc0e6b917320a47228fb96e3b5ae0e5c93773a5ae2662ae4e1f37807cfe47ce98", "asset_id": "58656358377246279051017109359677190749228949103591068167284263961542487110215", "price": "0.002", "size": "3310.15", "side": "BUY", "timestamp": "1768475459594", "received_at": "2026-01-15T12:10:59.730496"}}
{"event_type": "price_change", "event_ts": "2026-01-15T12:10:59.730496", "ingestion_ts": "2026-01-15T12:11:41.230171", "market_id": "0xc0e6b917320a47228fb96e3b5ae0e5c93773a5ae2662ae4e1f37807cfe47ce98", "raw": {"market": "0xc0e6b917320a47228fb96e3b5ae0e5c93773a5ae2662ae4e1f37807cfe47ce98", "asset_id": "81647294538046680798858716589766492074338758116170717123345952330712416337530", "price": "0.998", "size": "3310.15", "side": "SELL", "timestamp": "1768475459594", "received_at": "2026-01-15T12:10:59.730496"}}
{"event_type": "price_change", "event_ts": "2026-01-15T12:10:59.735076", "ingestion_ts": "2026-01-15T12:11:41.230171", "market_id": "0xc0e6b917320a47228fb96e3b5ae0e5c93773a5ae2662ae4e1f37807cfe47ce98", "raw": {"market": "0xc0e6b917320a47228fb96e3b5ae0e5c93773a5ae2662ae4e1f37807cfe47ce98", "asset_id": "58656358377246279051017109359677190749228949103591068167284263961542487110215", "price": "0.006", "size": "12.93", "side": "BUY", "timestamp": "1768475459595", "received_at": "2026-01-15T12:10:59.735076"}}
{"event_type": "price_change", "event_ts": "2026-01-15T12:10:59.735076", "ingestion_ts": "2026-01-15T12:11:41.230171", "market_id": "0xc0e6b917320a47228fb96e3b5ae0e5c93773a5ae2662ae4e1f37807cfe47ce98", "raw": {"market": "0xc0e6b917320a47228fb96e3b5ae0e5c93773a5ae2662ae4e1f37807cfe47ce98", "asset_id": "81647294538046680798858716589766492074338758116170717123345952330712416337530", "price": "0.994", "size": "12.93", "side": "SELL", "timestamp": "1768475459595", "received_at": "2026-01-15T12:10:59.735076"}}
{"event_type": "price_change", "event_ts": "2026-01-15T12:10:59.735444", "ingestion_ts": "2026-01-15T12:11:41.230171", "market_id": "0xc0e6b917320a47228fb96e3b5ae0e5c93773a5ae2662ae4e1f37807cfe47ce98", "raw": {"market": "0xc0e6b917320a47228fb96e3b5ae0e5c93773a5ae2662ae4e1f37807cfe47ce98", "asset_id": "58656358377246279051017109359677190749228949103591068167284263961542487110215", "price": "0.002", "size": "3316", "side": "BUY", "timestamp": "1768475459596", "received_at": "2026-01-15T12:10:59.735444"}}
{"event_type": "price_change", "event_ts": "2026-01-15T12:10:59.735444", "ingestion_ts": "2026-01-15T12:11:41.230171", "market_id": "0xc0e6b917320a47228fb96e3b5ae0e5c93773a5ae2662ae4e1f37807cfe47ce98", "raw": {"market": "0xc0e6b917320a47228fb96e3b5ae0e5c93773a5ae2662ae4e1f37807cfe47ce98", "asset_id": "81647294538046680798858716589766492074338758116170717123345952330712416337530", "price": "0.998", "size": "3316", "side": "SELL", "timestamp": "1768475459596", "received_at": "2026-01-15T12:10:59.735444"}}
{"event_type": "price_change", "event_ts": "2026-01-15T12:11:00.535034", "ingestion_ts": "2026-01-15T12:11:41.230171", "market_id": "0x427bc4b40c09b3dcbc973747f0e4b079bed91b3e5a0aed5c36edd0f7591485f4", "raw": {"market": "0x427bc4b40c09b3dcbc973747f0e4b079bed91b3e5a0aed5c36edd0f7591485f4", "asset_id": "115669573443672055876643967408433138119481486650803218131873713375232186497057", "price": "0.002", "size": "63.15", "side": "BUY", "timestamp": "1768475460389", "received_at": "2026-01-15T12:11:00.535034"}}
{"event_type": "price_change", "event_ts": "2026-01-15T12:11:00.535034", "ingestion_ts": "2026-01-15T12:11:41.230171", "market_id": "0x427bc4b40c09b3dcbc973747f0e4b079bed91b3e5a0aed5c36edd0f7591485f4", "raw": {"market": "0x427bc4b40c09b3dcbc973747f0e4b079bed91b3e5a0aed5c36edd0f7591485f4", "asset_id": "86130975769502911188457673769190265049139877688522439001984850068234616395137", "price": "0.998", "size": "63.15", "side": "SELL", "timestamp": "1768475460389", "received_at": "2026-01-15T12:11:00.535034"}}
{"event_type": "price_change", "event_ts": "2026-01-15T12:11:00.779548", "ingestion_ts": "2026-01-15T12:11:41.230171", "market_id": "0x427bc4b40c09b3dcbc973747f0e4b079bed91b3e5a0aed5c36edd0f7591485f4", "raw": {"market": "0x427bc4b40c09b3dcbc973747f0e4b079bed91b3e5a0aed5c36edd0f7591485f4", "asset_id": "115669573443672055876643967408433138119481486650803218131873713375232186497057", "price": "0.003", "size": "10.15", "side": "BUY", "timestamp": "1768475460653", "received_at": "2026-01-15T12:11:00.779548"}}
{"event_type": "price_change", "event_ts": "2026-01-15T12:11:00.779548", "ingestion_ts": "2026-01-15T12:11:41.230171", "market_id": "0x427bc4b40c09b3dcbc973747f0e4b079bed91b3e5a0aed5c36edd0f7591485f4", "raw": {"market": "0x427bc4b40c09b3dcbc973747f0e4b079bed91b3e5a0aed5c36edd0f7591485f4", "asset_id": "86130975769502911188457673769190265049139877688522439001984850068234616395137", "price": "0.997", "size": "10.15", "side": "SELL", "timestamp": "1768475460653", "received_at": "2026-01-15T12:11:00.779548"}}
{"event_type": "price_change", "event_ts": "2026-01-15T12:11:01.366377", "ingestion_ts": "2026-01-15T12:11:41.230171", "market_id": "0x427bc4b40c09b3dcbc973747f0e4b079bed91b3e5a0aed5c36edd0f7591485f4", "raw": {"market": "0x427bc4b40c09b3dcbc973747f0e4b079bed91b3e5a0aed5c36edd0f7591485f4", "asset_id": "115669573443672055876643967408433138119481486650803218131873713375232186497057", "price": "0.16", "size": "0", "side": "SELL", "timestamp": "1768475461241", "received_at": "2026-01-15T12:11:01.366377"}}
{"event_type": "price_change", "event_ts": "2026-01-15T12:11:01.366377", "ingestion_ts": "2026-01-15T12:11:41.230171", "market_id": "0x427bc4b40c09b3dcbc973747f0e4b079bed91b3e5a0aed5c36edd0f7591485f4", "raw": {"market": "0x427bc4b40c09b3dcbc973747f0e4b079bed91b3e5a0aed5c36edd0f7591485f4", "asset_id": "86130975769502911188457673769190265049139877688522439001984850068234616395137", "price": "0.84", "size": "0", "side": "BUY", "timestamp": "1768475461241", "received_at": "2026-01-15T12:11:01.366377"}}
{"event_type": "price_change", "event_ts": "2026-01-15T12:11:01.559946", "ingestion_ts": "2026-01-15T12:11:41.230171", "market_id": "0x427bc4b40c09b3dcbc973747f0e4b079bed91b3e5a0aed5c36edd0f7591485f4", "raw": {"market": "0x427bc4b40c09b3dcbc973747f0e4b079bed91b3e5a0aed5c36edd0f7591485f4", "asset_id": "115669573443672055876643967408433138119481486650803218131873713375232186497057", "price": "0.159", "size": "7.96", "side": "SELL", "timestamp": "1768475461438", "received_at": "2026-01-15T12:11:01.559946"}}
{"event_type": "price_change", "event_ts": "2026-01-15T12:11:01.559946", "ingestion_ts": "2026-01-15T12:11:41.230171", "market_id": "0x427bc4b40c09b3dcbc973747f0e4b079bed91b3e5a0aed5c36edd0f7591485f4", "raw": {"market": "0x427bc4b40c09b3dcbc973747f0e4b079bed91b3e5a0aed5c36edd0f7591485f4", "asset_id": "86130975769502911188457673769190265049139877688522439001984850068234616395137", "price": "0.841", "size": "7.96", "side": "BUY", "timestamp": "1768475461438", "received_at": "2026-01-15T12:11:01.559946"}}
{"event_type": "price_change", "event_ts": "2026-01-15T12:11:02.302151", "ingestion_ts": "2026-01-15T12:11:41.230171", "market_id": "0xc0e6b917320a47228fb96e3b5ae0e5c93773a5ae2662ae4e1f37807cfe47ce98", "raw": {"market": "0xc0e6b917320a47228fb96e3b5ae0e5c93773a5ae2662ae4e1f37807cfe47ce98", "asset_id": "58656358377246279051017109359677190749228949103591068167284263961542487110215", "price": "0.002", "size": "3308.89", "side": "BUY", "timestamp": "1768475462178", "received_at": "2026-01-15T12:11:02.302151"}}
{"event_type": "price_change", "event_ts": "2026-01-15T12:11:02.302151", "ingestion_ts": "2026-01-15T12:11:41.230171", "market_id": "0xc0e6b917320a47228fb96e3b5ae0e5c93773a5ae2662ae4e1f37807cfe47ce98", "raw": {"market": "0xc0e6b917320a47228fb96e3b5ae0e5c93773a5ae2662ae4e1f37807cfe47ce98", "asset_id": "81647294538046680798858716589766492074338758116170717123345952330712416337530", "price": "0.998", "size": "3308.89", "side": "SELL", "timestamp": "1768475462178", "received_at": "2026-01-15T12:11:02.302151"}}
{"event_type": "price_change", "event_ts": "2026-01-15T12:11:02.302185", "ingestion_ts": "2026-01-15T12:11:41.230171", "market_id": "0xc0e6b917320a47228fb96e3b5ae0e5c93773a5ae2662ae4e1f37807cfe47ce98", "raw": {"market": "0xc0e6b917320a47228fb96e3b5ae0e5c93773a5ae2662ae4e1f37807cfe47ce98", "asset_id": "58656358377246279051017109359677190749228949103591068167284263961542487110215", "price": "0.006", "size": "5.7", "side": "BUY", "timestamp": "1768475462178", "received_at": "2026-01-15T12:11:02.302185"}}
{"event_type": "price_change", "event_ts": "2026-01-15T12:11:02.302185", "ingestion_ts": "2026-01-15T12:11:41.230171", "market_id": "0xc0e6b917320a47228fb96e3b5ae0e5c93773a5ae2662ae4e1f37807cfe47ce98", "raw": {"market": "0xc0e6b917320a47228fb96e3b5ae0e5c93773a5ae2662ae4e1f37807cfe47ce98", "asset_id": "81647294538046680798858716589766492074338758116170717123345952330712416337530", "price": "0.994", "size": "5.7", "side": "SELL", "timestamp": "1768475462178", "received_at": "2026-01-15T12:11:02.302185"}}
{"event_type": "price_change", "event_ts": "2026-01-15T12:11:02.844028", "ingestion_ts": "2026-01-15T12:11:41.230171", "market_id": "0xc0e6b917320a47228fb96e3b5ae0e5c93773a5ae2662ae4e1f37807cfe47ce98", "raw": {"market": "0xc0e6b917320a47228fb96e3b5ae0e5c93773a5ae2662ae4e1f37807cfe47ce98", "asset_id": "58656358377246279051017109359677190749228949103591068167284263961542487110215", "price": "0.007", "size": "8.23", "side": "BUY", "timestamp": "1768475462720", "received_at": "2026-01-15T12:11:02.844028"}}
{"event_type": "price_change", "event_ts": "2026-01-15T12:11:02.844028", "ingestion_ts": "2026-01-15T12:11:41.230171", "market_id": "0xc0e6b917320a47228fb96e3b5ae0e5c93773a5ae2662ae4e1f37807cfe47ce98", "raw": {"market": "0xc0e6b917320a47228fb96e3b5ae0e5c93773a5ae2662ae4e1f37807cfe47ce98", "asset_id": "81647294538046680798858716589766492074338758116170717123345952330712416337530", "price": "0.993", "size": "8.23", "side": "SELL", "timestamp": "1768475462720", "received_at": "2026-01-15T12:11:02.844028"}}
{"event_type": "price_change", "event_ts": "2026-01-15T12:11:02.964286", "ingestion_ts": "2026-01-15T12:11:41.230171", "market_id": "0xcab7ba4a9133cfd407d7e73e5757e5abbace413b59421527a31113406c97815c", "raw": {"market": "0xcab7ba4a9133cfd407d7e73e5757e5abbace413b59421527a31113406c97815c", "asset_id": "96361925776989336186111887920533578209326565663637092688733016597062311745569", "price": "0.006", "size": "127.41", "side": "BUY", "timestamp": "1768475462839", "received_at": "2026-01-15T12:11:02.964286"}}
{"event_type": "price_change", "event_ts": "2026-01-15T12:11:02.964286", "ingestion_ts": "2026-01-15T12:11:41.230171", "market_id": "0xcab7ba4a9133cfd407d7e73e5757e5abbace413b59421527a31113406c97815c", "raw": {"market": "0xcab7ba4a9133cfd407d7e73e5757e5abbace413b59421527a31113406c97815c", "asset_id": "20002636398944597965698652220992177552927816915094913583821579024925426590022", "price": "0.994", "size": "127.41", "side": "SELL", "timestamp": "1768475462839", "received_at": "2026-01-15T12:11:02.964286"}}
{"event_type": "price_change", "event_ts": "2026-01-15T12:11:02.964336", "ingestion_ts": "2026-01-15T12:11:41.230171", "market_id": "0xcab7ba4a9133cfd407d7e73e5757e5abbace413b59421527a31113406c97815c", "raw": {"market": "0xcab7ba4a9133cfd407d7e73e5757e5abbace413b59421527a31113406c97815c", "asset_id": "96361925776989336186111887920533578209326565663637092688733016597062311745569", "price": "0.009", "size": "812.25", "side": "BUY", "timestamp": "1768475462839", "received_at": "2026-01-15T12:11:02.964336"}}
{"event_type": "price_change", "event_ts": "2026-01-15T12:11:02.964336", "ingestion_ts": "2026-01-15T12:11:41.230171", "market_id": "0xcab7ba4a9133cfd407d7e73e5757e5abbace413b59421527a31113406c97815c", "raw": {"market": "0xcab7ba4a9133cfd407d7e73e5757e5abbace413b59421527a31113406c97815c", "asset_id": "20002636398944597965698652220992177552927816915094913583821579024925426590022", "price": "0.991", "size": "812.25", "side": "SELL", "timestamp": "1768475462839", "received_at": "2026-01-15T12:11:02.964336"}}
{"event_type": "price_change", "event_ts": "2026-01-15T12:11:03.281390", "ingestion_ts": "2026-01-15T12:11:41.230171", "market_id": "0xcab7ba4a9133cfd407d7e73e5757e5abbace413b59421527a31113406c97815c", "raw": {"market": "0xcab7ba4a9133cfd407d7e73e5757e5abbace413b59421527a31113406c97815c", "asset_id": "96361925776989336186111887920533578209326565663637092688733016597062311745569", "price": "0.009", "size": "818.33", "side": "BUY", "timestamp": "1768475463161", "received_at": "2026-01-15T12:11:03.281390"}}
{"event_type": "price_change", "event_ts": "2026-01-15T12:11:03.281390", "ingestion_ts": "2026-01-15T12:11:41.230171", "market_id": "0xcab7ba4a9133cfd407d7e73e5757e5abbace413b59421527a31113406c97815c", "raw": {"market": "0xcab7ba4a9133cfd407d7e73e5757e5abbace413b59421527a31113406c97815c", "asset_id": "20002636398944597965698652220992177552927816915094913583821579024925426590022", "price": "0.991", "size": "818.33", "side": "SELL", "timestamp": "1768475463161", "received_at": "2026-01-15T12:11:03.281390"}}
{"event_type": "price_change", "event_ts": "2026-01-15T12:11:03.283216", "ingestion_ts": "2026-01-15T12:11:41.230171", "market_id": "0xcab7ba4a9133cfd407d7e73e5757e5abbace413b59421527a31113406c97815c", "raw": {"market": "0xcab7ba4a9133cfd407d7e73e5757e5abbace413b59421527a31113406c97815c", "asset_id": "96361925776989336186111887920533578209326565663637092688733016597062311745569", "price": "0.006", "size": "136.51", "side": "BUY", "timestamp": "1768475463163", "received_at": "2026-01-15T12:11:03.283216"}}
{"event_type": "price_change", "event_ts": "2026-01-15T12:11:03.283216", "ingestion_ts": "2026-01-15T12:11:41.230171", "market_id": "0xcab7ba4a9133cfd407d7e73e5757e5abbace413b59421527a31113406c97815c", "raw": {"market": "0xcab7ba4a9133cfd407d7e73e5757e5abbace413b59421527a31113406c97815c", "asset_id": "20002636398944597965698652220992177552927816915094913583821579024925426590022", "price": "0.994", "size": "136.51", "side": "SELL", "timestamp": "1768475463163", "received_at": "2026-01-15T12:11:03.283216"}}
{"event_type": "price_change", "event_ts": "2026-01-15T12:11:03.827282", "ingestion_ts": "2026-01-15T12:11:41.230171", "market_id": "0xc0e6b917320a47228fb96e3b5ae0e5c93773a5ae2662ae4e1f37807cfe47ce98", "raw": {"market": "0xc0e6b917320a47228fb96e3b5ae0e5c93773a5ae2662ae4e1f37807cfe47ce98", "asset_id": "58656358377246279051017109359677190749228949103591068167284263961542487110215", "price": "0.006", "size": "0", "side": "BUY", "timestamp": "1768475463703", "received_at": "2026-01-15T12:11:03.827282"}}
{"event_type": "price_change", "event_ts": "2026-01-15T12:11:03.827282", "ingestion_ts": "2026-01-15T12:11:41.230171", "market_id": "0xc0e6b917320a47228fb96e3b5ae0e5c93773a5ae2662ae4e1f37807cfe47ce98", "raw": {"market": "0xc0e6b917320a47228fb96e3b5ae0e5c93773a5ae2662ae4e1f37807cfe47ce98", "asset_id": "81647294538046680798858716589766492074338758116170717123345952330712416337530", "price": "0.994", "size": "0", "side": "SELL", "timestamp": "1768475463703", "received_at": "2026-01-15T12:11:03.827282"}}
{"event_type": "price_change", "event_ts": "2026-01-15T12:11:03.827369", "ingestion_ts": "2026-01-15T12:11:41.230171", "market_id": "0xc0e6b917320a47228fb96e3b5ae0e5c93773a5ae2662ae4e1f37807cfe47ce98", "raw": {"market": "0xc0e6b917320a47228fb96e3b5ae0e5c93773a5ae2662ae4e1f37807cfe47ce98", "asset_id": "58656358377246279051017109359677190749228949103591068167284263961542487110215", "price": "0.007", "size": "0", "side": "BUY", "timestamp": "1768475463703", "received_at": "2026-01-15T12:11:03.827369"}}
{"event_type": "price_change", "event_ts": "2026-01-15T12:11:03.827369", "ingestion_ts": "2026-01-15T12:11:41.230171", "market_id": "0xc0e6b917320a47228fb96e3b5ae0e5c93773a5ae2662ae4e1f37807cfe47ce98", "raw": {"market": "0xc0e6b917320a47228fb96e3b5ae0e5c93773a5ae2662ae4e1f37807cfe47ce98", "asset_id": "81647294538046680798858716589766492074338758116170717123345952330712416337530", "price": "0.993", "size": "0", "side": "SELL", "timestamp": "1768475463703", "received_at": "2026-01-15T12:11:03.827369"}}
{"event_type": "price_change", "event_ts": "2026-01-15T12:11:04.271221", "ingestion_ts": "2026-01-15T12:11:41.230171", "market_id": "0xc0e6b917320a47228fb96e3b5ae0e5c93773a5ae2662ae4e1f37807cfe47ce98", "raw": {"market": "0xc0e6b917320a47228fb96e3b5ae0e5c93773a5ae2662ae4e1f37807cfe47ce98", "asset_id": "58656358377246279051017109359677190749228949103591068167284263961542487110215", "price": "0.017", "size": "14.9", "side": "BUY", "timestamp": "1768475464154", "received_at": "2026-01-15T12:11:04.271221"}}
{"event_type": "price_change", "event_ts": "2026-01-15T12:11:04.271221", "ingestion_ts": "2026-01-15T12:11:41.230171", "market_id": "0xc0e6b917320a47228fb96e3b5ae0e5c93773a5ae2662ae4e1f37807cfe47ce98", "raw": {"market": "0xc0e6b917320a47228fb96e3b5ae0e5c93773a5ae2662ae4e1f37807cfe47ce98", "asset_id": "81647294538046680798858716589766492074338758116170717123345952330712416337530", "price": "0.983", "size": "14.9", "side": "SELL", "timestamp": "1768475464154", "received_at": "2026-01-15T12:11:04.271221"}}
{"event_type": "price_change", "event_ts": "2026-01-15T12:11:04.486439", "ingestion_ts": "2026-01-15T12:11:41.230171", "market_id": "0xcab7ba4a9133cfd407d7e73e5757e5abbace413b59421527a31113406c97815c", "raw": {"market": "0xcab7ba4a9133cfd407d7e73e5757e5abbace413b59421527a31113406c97815c", "asset_id": "96361925776989336186111887920533578209326565663637092688733016597062311745569", "price": "0.006", "size": "127.41", "side": "BUY", "timestamp": "1768475464368", "received_at": "2026-01-15T12:11:04.486439"}}
{"event_type": "price_change", "event_ts": "2026-01-15T12:11:04.486439", "ingestion_ts": "2026-01-15T12:11:41.230171", "market_id": "0xcab7ba4a9133cfd407d7e73e5757e5abbace413b59421527a31113406c97815c", "raw": {"market": "0xcab7ba4a9133cfd407d7e73e5757e5abbace413b59421527a31113406c97815c", "asset_id": "20002636398944597965698652220992177552927816915094913583821579024925426590022", "price": "0.994", "size": "127.41", "side": "SELL", "timestamp": "1768475464368", "received_at": "2026-01-15T12:11:04.486439"}}
{"event_type": "price_change", "event_ts": "2026-01-15T12:11:04.486485", "ingestion_ts": "2026-01-15T12:11:41.230171", "market_id": "0xcab7ba4a9133cfd407d7e73e5757e5abbace413b59421527a31113406c97815c", "raw": {"market": "0xcab7ba4a9133cfd407d7e73e5757e5abbace413b59421527a31113406c97815c", "asset_id": "96361925776989336186111887920533578209326565663637092688733016597062311745569", "price": "0.009", "size": "812.25", "side": "BUY", "timestamp": "1768475464368", "received_at": "2026-01-15T12:11:04.486485"}}
{"event_type": "price_change", "event_ts": "2026-01-15T12:11:04.486485", "ingestion_ts": "2026-01-15T12:11:41.230171", "market_id": "0xcab7ba4a9133cfd407d7e73e5757e5abbace413b59421527a31113406c97815c", "raw": {"market": "0xcab7ba4a9133cfd407d7e73e5757e5abbace413b59421527a31113406c97815c", "asset_id": "20002636398944597965698652220992177552927816915094913583821579024925426590022", "price": "0.991", "size": "812.25", "side": "SELL", "timestamp": "1768475464368", "received_at": "2026-01-15T12:11:04.486485"}}
{"event_type": "price_change", "event_ts": "2026-01-15T12:11:04.832161", "ingestion_ts": "2026-01-15T12:11:41.230171", "market_id": "0xcab7ba4a9133cfd407d7e73e5757e5abbace413b59421527a31113406c97815c", "raw": {"market": "0xcab7ba4a9133cfd407d7e73e5757e5abbace413b59421527a31113406c97815c", "asset_id": "96361925776989336186111887920533578209326565663637092688733016597062311745569", "price": "0.006", "size": "136.51", "side": "BUY", "timestamp": "1768475464712", "received_at": "2026-01-15T12:11:04.832161"}}
{"event_type": "price_change", "event_ts": "2026-01-15T12:11:04.832161", "ingestion_ts": "2026-01-15T12:11:41.230171", "market_id": "0xcab7ba4a9133cfd407d7e73e5757e5abbace413b59421527a31113406c97815c", "raw": {"market": "0xcab7ba4a9133cfd407d7e73e5757e5abbace413b59421527a31113406c97815c", "asset_id": "20002636398944597965698652220992177552927816915094913583821579024925426590022", "price": "0.994", "size": "136.51", "side": "SELL", "timestamp": "1768475464712", "received_at": "2026-01-15T12:11:04.832161"}}
{"event_type": "price_change", "event_ts": "2026-01-15T12:11:04.837699", "ingestion_ts": "2026-01-15T12:11:41.230171", "market_id": "0xcab7ba4a9133cfd407d7e73e5757e5abbace413b59421527a31113406c97815c", "raw": {"market": "0xcab7ba4a9133cfd407d7e73e5757e5abbace413b59421527a31113406c97815c", "asset_id": "96361925776989336186111887920533578209326565663637092688733016597062311745569", "price": "0.009", "size": "818.33", "side": "BUY", "timestamp": "1768475464713", "received_at": "2026-01-15T12:11:04.837699"}}
{"event_type": "price_change", "event_ts": "2026-01-15T12:11:04.837699", "ingestion_ts": "2026-01-15T12:11:41.230171", "market_id": "0xcab7ba4a9133cfd407d7e73e5757e5abbace413b59421527a31113406c97815c", "raw": {"market": "0xcab7ba4a9133cfd407d7e73e5757e5abbace413b59421527a31113406c97815c", "asset_id": "20002636398944597965698652220992177552927816915094913583821579024925426590022", "price": "0.991", "size": "818.33", "side": "SELL", "timestamp": "1768475464713", "received_at": "2026-01-15T12:11:04.837699"}}
{"event_type": "price_change", "event_ts": "2026-01-15T12:11:04.997733", "ingestion_ts": "2026-01-15T12:11:41.230171", "market_id": "0x427bc4b40c09b3dcbc973747f0e4b079bed91b3e5a0aed5c36edd0f7591485f4", "raw": {"market": "0x427bc4b40c09b3dcbc973747f0e4b079bed91b3e5a0aed5c36edd0f7591485f4", "asset_id": "115669573443672055876643967408433138119481486650803218131873713375232186497057", "price": "0.003", "size": "4.03", "side": "BUY", "timestamp": "1768475464875", "received_at": "2026-01-15T12:11:04.997733"}}
{"event_type": "price_change", "event_ts": "2026-01-15T12:11:04.997733", "ingestion_ts": "2026-01-15T12:11:41.230171", "market_id": "0x427bc4b40c09b3dcbc973747f0e4b079bed91b3e5a0aed5c36edd0f7591485f4", "raw": {"market": "0x427bc4b40c09b3dcbc973747f0e4b079bed91b3e5a0aed5c36edd0f7591485f4", "asset_id": "86130975769502911188457673769190265049139877688522439001984850068234616395137", "price": "0.997", "size": "4.03", "side": "SELL", "timestamp": "1768475464875", "received_at": "2026-01-15T12:11:04.997733"}}
{"event_type": "price_change", "event_ts": "2026-01-15T12:11:05.324287", "ingestion_ts": "2026-01-15T12:11:41.230171", "market_id": "0x427bc4b40c09b3dcbc973747f0e4b079bed91b3e5a0aed5c36edd0f7591485f4", "raw": {"market": "0x427bc4b40c09b3dcbc973747f0e4b079bed91b3e5a0aed5c36edd0f7591485f4", "asset_id": "115669573443672055876643967408433138119481486650803218131873713375232186497057", "price": "0.002", "size": "72.33", "side": "BUY", "timestamp": "1768475465204", "received_at": "2026-01-15T12:11:05.324287"}}
{"event_type": "price_change", "event_ts": "2026-01-15T12:11:05.324287", "ingestion_ts": "2026-01-15T12:11:41.230171", "market_id": "0x427bc4b40c09b3dcbc973747f0e4b079bed91b3e5a0aed5c36edd0f7591485f4", "raw": {"market": "0x427bc4b40c09b3dcbc973747f0e4b079bed91b3e5a0aed5c36edd0f7591485f4", "asset_id": "86130975769502911188457673769190265049139877688522439001984850068234616395137", "price": "0.998", "size": "72.33", "side": "SELL", "timestamp": "1768475465204", "received_at": "2026-01-15T12:11:05.324287"}}
{"event_type": "price_change", "event_ts": "2026-01-15T12:11:05.842322", "ingestion_ts": "2026-01-15T12:11:41.230171", "market_id": "0x427bc4b40c09b3dcbc973747f0e4b079bed91b3e5a0aed5c36edd0f7591485f4", "raw": {"market": "0x427bc4b40c09b3dcbc973747f0e4b079bed91b3e5a0aed5c36edd0f7591485f4", "asset_id": "115669573443672055876643967408433138119481486650803218131873713375232186497057", "price": "0.159", "size": "0", "side": "SELL", "timestamp": "1768475465718", "received_at": "2026-01-15T12:11:05.842322"}}
{"event_type": "price_change", "event_ts": "2026-01-15T12:11:05.842322", "ingestion_ts": "2026-01-15T12:11:41.230171", "market_id": "0x427bc4b40c09b3dcbc973747f0e4b079bed91b3e5a0aed5c36edd0f7591485f4", "raw": {"market": "0x427bc4b40c09b3dcbc973747f0e4b079bed91b3e5a0aed5c36edd0f7591485f4", "asset_id": "86130975769502911188457673769190265049139877688522439001984850068234616395137", "price": "0.841", "size": "0", "side": "BUY", "timestamp": "1768475465718", "received_at": "2026-01-15T12:11:05.842322"}}
{"event_type": "price_change", "event_ts": "2026-01-15T12:11:06.262110", "ingestion_ts": "2026-01-15T12:11:41.230171", "market_id": "0x427bc4b40c09b3dcbc973747f0e4b079bed91b3e5a0aed5c36edd0f7591485f4", "raw": {"market": "0x427bc4b40c09b3dcbc973747f0e4b079bed91b3e5a0aed5c36edd0f7591485f4", "asset_id": "115669573443672055876643967408433138119481486650803218131873713375232186497057", "price": "0.164", "size": "15.92", "side": "SELL", "timestamp": "1768475466110", "received_at": "2026-01-15T12:11:06.262110"}}
{"event_type": "price_change", "event_ts": "2026-01-15T12:11:06.262110", "ingestion_ts": "2026-01-15T12:11:41.230171", "market_id": "0x427bc4b40c09b3dcbc973747f0e4b079bed91b3e5a0aed5c36edd0f7591485f4", "raw": {"market": "0x427bc4b40c09b3dcbc973747f0e4b079bed91b3e5a0aed5c36edd0f7591485f4", "asset_id": "86130975769502911188457673769190265049139877688522439001984850068234616395137", "price": "0.836", "size": "15.92", "side": "BUY", "timestamp": "1768475466110", "received_at": "2026-01-15T12:11:06.262110"}}
{"event_type": "price_change", "event_ts": "2026-01-15T12:11:06.335314", "ingestion_ts": "2026-01-15T12:11:41.230171", "market_id": "0xcab7ba4a9133cfd407d7e73e5757e5abbace413b59421527a31113406c97815c", "raw": {"market": "0xcab7ba4a9133cfd407d7e73e5757e5abbace413b59421527a31113406c97815c", "asset_id": "96361925776989336186111887920533578209326565663637092688733016597062311745569", "price": "0.006", "size": "127.41", "side": "BUY", "timestamp": "1768475466183", "received_at": "2026-01-15T12:11:06.335314"}}
{"event_type": "price_change", "event_ts": "2026-01-15T12:11:06.335314", "ingestion_ts": "2026-01-15T12:11:41.230171", "market_id": "0xcab7ba4a9133cfd407d7e73e5757e5abbace413b59421527a31113406c97815c", "raw": {"market": "0xcab7ba4a9133cfd407d7e73e5757e5abbace413b59421527a31113406c97815c", "asset_id": "20002636398944597965698652220992177552927816915094913583821579024925426590022", "price": "0.994", "size": "127.41", "side": "SELL", "timestamp": "1768475466183", "received_at": "2026-01-15T12:11:06.335314"}}
{"event_type": "price_change", "event_ts": "2026-01-15T12:11:06.335348", "ingestion_ts": "2026-01-15T12:11:41.230171", "market_id": "0xcab7ba4a9133cfd407d7e73e5757e5abbace413b59421527a31113406c97815c", "raw": {"market": "0xcab7ba4a9133cfd407d7e73e5757e5abbace413b59421527a31113406c97815c", "asset_id": "96361925776989336186111887920533578209326565663637092688733016597062311745569", "price": "0.009", "size": "812.25", "side": "BUY", "timestamp": "1768475466183", "received_at": "2026-01-15T12:11:06.335348"}}
{"event_type": "price_change", "event_ts": "2026-01-15T12:11:06.335348", "ingestion_ts": "2026-01-15T12:11:41.230171", "market_id": "0xcab7ba4a9133cfd407d7e73e5757e5abbace413b59421527a31113406c97815c", "raw": {"market": "0xcab7ba4a9133cfd407d7e73e5757e5abbace413b59421527a31113406c97815c", "asset_id": "20002636398944597965698652220992177552927816915094913583821579024925426590022", "price": "0.991", "size": "812.25", "side": "SELL", "timestamp": "1768475466183", "received_at": "2026-01-15T12:11:06.335348"}}
{"event_type": "price_change", "event_ts": "2026-01-15T12:11:07.048728", "ingestion_ts": "2026-01-15T12:11:41.230171", "market_id": "0xc0e6b917320a47228fb96e3b5ae0e5c93773a5ae2662ae4e1f37807cfe47ce98", "raw": {"market": "0xc0e6b917320a47228fb96e3b5ae0e5c93773a5ae2662ae4e1f37807cfe47ce98", "asset_id": "58656358377246279051017109359677190749228949103591068167284263961542487110215", "price": "0.017", "size": "5.4", "side": "BUY", "timestamp": "1768475466916", "received_at": "2026-01-15T12:11:07.048728"}}
{"event_type": "price_change", "event_ts": "2026-01-15T12:11:07.048728", "ingestion_ts": "2026-01-15T12:11:41.230171", "market_id": "0xc0e6b917320a47228fb96e3b5ae0e5c93773a5ae2662ae4e1f37807cfe47ce98", "raw": {"market": "0xc0e6b917320a47228fb96e3b5ae0e5c93773a5ae2662ae4e1f37807cfe47ce98", "asset_id": "81647294538046680798858716589766492074338758116170717123345952330712416337530", "price": "0.983", "size": "5.4", "side": "SELL", "timestamp": "1768475466916", "received_at": "2026-01-15T12:11:07.048728"}}
{"event_type": "price_change", "event_ts": "2026-01-15T12:11:07.230590", "ingestion_ts": "2026-01-15T12:11:41.230171", "market_id": "0xcab7ba4a9133cfd407d7e73e5757e5abbace413b59421527a31113406c97815c", "raw": {"market": "0xcab7ba4a9133cfd407d7e73e5757e5abbace413b59421527a31113406c97815c", "asset_id": "96361925776989336186111887920533578209326565663637092688733016597062311745569", "price": "0.006", "size": "136.51", "side": "BUY", "timestamp": "1768475467111", "received_at": "2026-01-15T12:11:07.230590"}}
{"event_type": "price_change", "event_ts": "2026-01-15T12:11:07.230590", "ingestion_ts": "2026-01-15T12:11:41.230171", "market_id": "0xcab7ba4a9133cfd407d7e73e5757e5abbace413b59421527a31113406c97815c", "raw": {"market": "0xcab7ba4a9133cfd407d7e73e5757e5abbace413b59421527a31113406c97815c", "asset_id": "20002636398944597965698652220992177552927816915094913583821579024925426590022", "price": "0.994", "size": "136.51", "side": "SELL", "timestamp": "1768475467111", "received_at": "2026-01-15T12:11:07.230590"}}
{"event_type": "price_change", "event_ts": "2026-01-15T12:11:07.230807", "ingestion_ts": "2026-01-15T12:11:41.230171", "market_id": "0xcab7ba4a9133cfd407d7e73e5757e5abbace413b59421527a31113406c97815c", "raw": {"market": "0xcab7ba4a9133cfd407d7e73e5757e5abbace413b59421527a31113406c97815c", "asset_id": "96361925776989336186111887920533578209326565663637092688733016597062311745569", "price": "0.009", "size": "818.33", "side": "BUY", "timestamp": "1768475467113", "received_at": "2026-01-15T12:11:07.230807"}}
{"event_type": "price_change", "event_ts": "2026-01-15T12:11:07.230807", "ingestion_ts": "2026-01-15T12:11:41.230171", "market_id": "0xcab7ba4a9133cfd407d7e73e5757e5abbace413b59421527a31113406c97815c", "raw": {"market": "0xcab7ba4a9133cfd407d7e73e5757e5abbace413b59421527a31113406c97815c", "asset_id": "20002636398944597965698652220992177552927816915094913583821579024925426590022", "price": "0.991", "size": "818.33", "side": "SELL", "timestamp": "1768475467113", "received_at": "2026-01-15T12:11:07.230807"}}
{"event_type": "price_change", "event_ts": "2026-01-15T12:11:07.437426", "ingestion_ts": "2026-01-15T12:11:41.230171", "market_id": "0xc0e6b917320a47228fb96e3b5ae0e5c93773a5ae2662ae4e1f37807cfe47ce98", "raw": {"market": "0xc0e6b917320a47228fb96e3b5ae0e5c93773a5ae2662ae4e1f37807cfe47ce98", "asset_id": "58656358377246279051017109359677190749228949103591068167284263961542487110215", "price": "0.018", "size": "8.97", "side": "BUY", "timestamp": "1768475467317", "received_at": "2026-01-15T12:11:07.437426"}}
{"event_type": "price_change", "event_ts": "2026-01-15T12:11:07.437426", "ingestion_ts": "2026-01-15T12:11:41.230171", "market_id": "0xc0e6b917320a47228fb96e3b5ae0e5c93773a5ae2662ae4e1f37807cfe47ce98", "raw": {"market": "0xc0e6b917320a47228fb96e3b5ae0e5c93773a5ae2662ae4e1f37807cfe47ce98", "asset_id": "81647294538046680798858716589766492074338758116170717123345952330712416337530", "price": "0.982", "size": "8.97", "side": "SELL", "timestamp": "1768475467317", "received_at": "2026-01-15T12:11:07.437426"}}
{"event_type": "price_change", "event_ts": "2026-01-15T12:11:09.456048", "ingestion_ts": "2026-01-15T12:11:41.230171", "market_id": "0xcab7ba4a9133cfd407d7e73e5757e5abbace413b59421527a31113406c97815c", "raw": {"market": "0xcab7ba4a9133cfd407d7e73e5757e5abbace413b59421527a31113406c97815c", "asset_id": "96361925776989336186111887920533578209326565663637092688733016597062311745569", "price": "0.006", "size": "127.41", "side": "BUY", "timestamp": "1768475469328", "received_at": "2026-01-15T12:11:09.456048"}}
{"event_type": "price_change", "event_ts": "2026-01-15T12:11:09.456048", "ingestion_ts": "2026-01-15T12:11:41.230171", "market_id": "0xcab7ba4a9133cfd407d7e73e5757e5abbace413b59421527a31113406c97815c", "raw": {"market": "0xcab7ba4a9133cfd407d7e73e5757e5abbace413b59421527a31113406c97815c", "asset_id": "20002636398944597965698652220992177552927816915094913583821579024925426590022", "price": "0.994", "size": "127.41", "side": "SELL", "timestamp": "1768475469328", "received_at": "2026-01-15T12:11:09.456048"}}
{"event_type": "price_change", "event_ts": "2026-01-15T12:11:09.456195", "ingestion_ts": "2026-01-15T12:11:41.230171", "market_id": "0xcab7ba4a9133cfd407d7e73e5757e5abbace413b59421527a31113406c97815c", "raw": {"market": "0xcab7ba4a9133cfd407d7e73e5757e5abbace413b59421527a31113406c97815c", "asset_id": "96361925776989336186111887920533578209326565663637092688733016597062311745569", "price": "0.009", "size": "812.25", "side": "BUY", "timestamp": "1768475469328", "received_at": "2026-01-15T12:11:09.456195"}}
{"event_type": "price_change", "event_ts": "2026-01-15T12:11:09.456195", "ingestion_ts": "2026-01-15T12:11:41.230171", "market_id": "0xcab7ba4a9133cfd407d7e73e5757e5abbace413b59421527a31113406c97815c", "raw": {"market": "0xcab7ba4a9133cfd407d7e73e5757e5abbace413b59421527a31113406c97815c", "asset_id": "20002636398944597965698652220992177552927816915094913583821579024925426590022", "price": "0.991", "size": "812.25", "side": "SELL", "timestamp": "1768475469328", "received_at": "2026-01-15T12:11:09.456195"}}
{"event_type": "price_change", "event_ts": "2026-01-15T12:11:09.883164", "ingestion_ts": "2026-01-15T12:11:41.230171", "market_id": "0xcab7ba4a9133cfd407d7e73e5757e5abbace413b59421527a31113406c97815c", "raw": {"market": "0xcab7ba4a9133cfd407d7e73e5757e5abbace413b59421527a31113406c97815c", "asset_id": "96361925776989336186111887920533578209326565663637092688733016597062311745569", "price": "0.006", "size": "136.51", "side": "BUY", "timestamp": "1768475469763", "received_at": "2026-01-15T12:11:09.883164"}}
{"event_type": "price_change", "event_ts": "2026-01-15T12:11:09.883164", "ingestion_ts": "2026-01-15T12:11:41.230171", "market_id": "0xcab7ba4a9133cfd407d7e73e5757e5abbace413b59421527a31113406c97815c", "raw": {"market": "0xcab7ba4a9133cfd407d7e73e5757e5abbace413b59421527a31113406c97815c", "asset_id": "20002636398944597965698652220992177552927816915094913583821579024925426590022", "price": "0.994", "size": "136.51", "side": "SELL", "timestamp": "1768475469763", "received_at": "2026-01-15T12:11:09.883164"}}
{"event_type": "price_change", "event_ts": "2026-01-15T12:11:09.884180", "ingestion_ts": "2026-01-15T12:11:41.230171", "market_id": "0xcab7ba4a9133cfd407d7e73e5757e5abbace413b59421527a31113406c97815c", "raw": {"market": "0xcab7ba4a9133cfd407d7e73e5757e5abbace413b59421527a31113406c97815c", "asset_id": "96361925776989336186111887920533578209326565663637092688733016597062311745569", "price": "0.009", "size": "818.33", "side": "BUY", "timestamp": "1768475469764", "received_at": "2026-01-15T12:11:09.884180"}}
{"event_type": "price_change", "event_ts": "2026-01-15T12:11:09.884180", "ingestion_ts": "2026-01-15T12:11:41.230171", "market_id": "0xcab7ba4a9133cfd407d7e73e5757e5abbace413b59421527a31113406c97815c", "raw": {"market": "0xcab7ba4a9133cfd407d7e73e5757e5abbace413b59421527a31113406c97815c", "asset_id": "20002636398944597965698652220992177552927816915094913583821579024925426590022", "price": "0.991", "size": "818.33", "side": "SELL", "timestamp": "1768475469764", "received_at": "2026-01-15T12:11:09.884180"}}
{"event_type": "price_change", "event_ts": "2026-01-15T12:11:10.740061", "ingestion_ts": "2026-01-15T12:11:41.230171", "market_id": "0x427bc4b40c09b3dcbc973747f0e4b079bed91b3e5a0aed5c36edd0f7591485f4", "raw": {"market": "0x427bc4b40c09b3dcbc973747f0e4b079bed91b3e5a0aed5c36edd0f7591485f4", "asset_id": "115669573443672055876643967408433138119481486650803218131873713375232186497057", "price": "0.002", "size": "63.15", "side": "BUY", "timestamp": "1768475470621", "received_at": "2026-01-15T12:11:10.740061"}}
{"event_type": "price_change", "event_ts": "2026-01-15T12:11:10.740061", "ingestion_ts": "2026-01-15T12:11:41.230171", "market_id": "0x427bc4b40c09b3dcbc973747f0e4b079bed91b3e5a0aed5c36edd0f7591485f4", "raw": {"market": "0x427bc4b40c09b3dcbc973747f0e4b079bed91b3e5a0aed5c36edd0f7591485f4", "asset_id": "86130975769502911188457673769190265049139877688522439001984850068234616395137", "price": "0.998", "size": "63.15", "side": "SELL", "timestamp": "1768475470621", "received_at": "2026-01-15T12:11:10.740061"}}
{"event_type": "price_change", "event_ts": "2026-01-15T12:11:11.080850", "ingestion_ts": "2026-01-15T12:11:41.230171", "market_id": "0x427bc4b40c09b3dcbc973747f0e4b079bed91b3e5a0aed5c36edd0f7591485f4", "raw": {"market": "0x427bc4b40c09b3dcbc973747f0e4b079bed91b3e5a0aed5c36edd0f7591485f4", "asset_id": "115669573443672055876643967408433138119481486650803218131873713375232186497057", "price": "0.003", "size": "10.15", "side": "BUY", "timestamp": "1768475470963", "received_at": "2026-01-15T12:11:11.080850"}}
{"event_type": "price_change", "event_ts": "2026-01-15T12:11:11.080850", "ingestion_ts": "2026-01-15T12:11:41.230171", "market_id": "0x427bc4b40c09b3dcbc973747f0e4b079bed91b3e5a0aed5c36edd0f7591485f4", "raw": {"market": "0x427bc4b40c09b3dcbc973747f0e4b079bed91b3e5a0aed5c36edd0f7591485f4", "asset_id": "86130975769502911188457673769190265049139877688522439001984850068234616395137", "price": "0.997", "size": "10.15", "side": "SELL", "timestamp": "1768475470963", "received_at": "2026-01-15T12:11:11.080850"}}
{"event_type": "price_change", "event_ts": "2026-01-15T12:11:11.611872", "ingestion_ts": "2026-01-15T12:11:41.230171", "market_id": "0x427bc4b40c09b3dcbc973747f0e4b079bed91b3e5a0aed5c36edd0f7591485f4", "raw": {"market": "0x427bc4b40c09b3dcbc973747f0e4b079bed91b3e5a0aed5c36edd0f7591485f4", "asset_id": "115669573443672055876643967408433138119481486650803218131873713375232186497057", "price": "0.164", "size": "7.96", "side": "SELL", "timestamp": "1768475471489", "received_at": "2026-01-15T12:11:11.611872"}}
{"event_type": "price_change", "event_ts": "2026-01-15T12:11:11.611872", "ingestion_ts": "2026-01-15T12:11:41.230171", "market_id": "0x427bc4b40c09b3dcbc973747f0e4b079bed91b3e5a0aed5c36edd0f7591485f4", "raw": {"market": "0x427bc4b40c09b3dcbc973747f0e4b079bed91b3e5a0aed5c36edd0f7591485f4", "asset_id": "86130975769502911188457673769190265049139877688522439001984850068234616395137", "price": "0.836", "size": "7.96", "side": "BUY", "timestamp": "1768475471489", "received_at": "2026-01-15T12:11:11.611872"}}
{"event_type": "price_change", "event_ts": "2026-01-15T12:11:11.862211", "ingestion_ts": "2026-01-15T12:11:41.230171", "market_id": "0xcab7ba4a9133cfd407d7e73e5757e5abbace413b59421527a31113406c97815c", "raw": {"market": "0xcab7ba4a9133cfd407d7e73e5757e5abbace413b59421527a31113406c97815c", "asset_id": "96361925776989336186111887920533578209326565663637092688733016597062311745569", "price": "0.006", "size": "127.41", "side": "BUY", "timestamp": "1768475471745", "received_at": "2026-01-15T12:11:11.862211"}}
{"event_type": "price_change", "event_ts": "2026-01-15T12:11:11.862211", "ingestion_ts": "2026-01-15T12:11:41.230171", "market_id": "0xcab7ba4a9133cfd407d7e73e5757e5abbace413b59421527a31113406c97815c", "raw": {"market": "0xcab7ba4a9133cfd407d7e73e5757e5abbace413b59421527a31113406c97815c", "asset_id": "20002636398944597965698652220992177552927816915094913583821579024925426590022", "price": "0.994", "size": "127.41", "side": "SELL", "timestamp": "1768475471745", "received_at": "2026-01-15T12:11:11.862211"}}
{"event_type": "price_change", "event_ts": "2026-01-15T12:11:11.862243", "ingestion_ts": "2026-01-15T12:11:41.230171", "market_id": "0xcab7ba4a9133cfd407d7e73e5757e5abbace413b59421527a31113406c97815c", "raw": {"market": "0xcab7ba4a9133cfd407d7e73e5757e5abbace413b59421527a31113406c97815c", "asset_id": "96361925776989336186111887920533578209326565663637092688733016597062311745569", "price": "0.009", "size": "812.25", "side": "BUY", "timestamp": "1768475471745", "received_at": "2026-01-15T12:11:11.862243"}}
{"event_type": "price_change", "event_ts": "2026-01-15T12:11:11.862243", "ingestion_ts": "2026-01-15T12:11:41.230171", "market_id": "0xcab7ba4a9133cfd407d7e73e5757e5abbace413b59421527a31113406c97815c", "raw": {"market": "0xcab7ba4a9133cfd407d7e73e5757e5abbace413b59421527a31113406c97815c", "asset_id": "20002636398944597965698652220992177552927816915094913583821579024925426590022", "price": "0.991", "size": "812.25", "side": "SELL", "timestamp": "1768475471745", "received_at": "2026-01-15T12:11:11.862243"}}
{"event_type": "price_change", "event_ts": "2026-01-15T12:11:11.989977", "ingestion_ts": "2026-01-15T12:11:41.230171", "market_id": "0x427bc4b40c09b3dcbc973747f0e4b079bed91b3e5a0aed5c36edd0f7591485f4", "raw": {"market": "0x427bc4b40c09b3dcbc973747f0e4b079bed91b3e5a0aed5c36edd0f7591485f4", "asset_id": "115669573443672055876643967408433138119481486650803218131873713375232186497057", "price": "0.163", "size": "7.96", "side": "SELL", "timestamp": "1768475471871", "received_at": "2026-01-15T12:11:11.989977"}}
{"event_type": "price_change", "event_ts": "2026-01-15T12:11:11.989977", "ingestion_ts": "2026-01-15T12:11:41.230171", "market_id": "0x427bc4b40c09b3dcbc973747f0e4b079bed91b3e5a0aed5c36edd0f7591485f4", "raw": {"market": "0x427bc4b40c09b3dcbc973747f0e4b079bed91b3e5a0aed5c36edd0f7591485f4", "asset_id": "86130975769502911188457673769190265049139877688522439001984850068234616395137", "price": "0.837", "size": "7.96", "side": "BUY", "timestamp": "1768475471871", "received_at": "2026-01-15T12:11:11.989977"}}
{"event_type": "price_change", "event_ts": "2026-01-15T12:11:12.522285", "ingestion_ts": "2026-01-15T12:11:41.230171", "market_id": "0xcab7ba4a9133cfd407d7e73e5757e5abbace413b59421527a31113406c97815c", "raw": {"market": "0xcab7ba4a9133cfd407d7e73e5757e5abbace413b59421527a31113406c97815c", "asset_id": "96361925776989336186111887920533578209326565663637092688733016597062311745569", "price": "0.006", "size": "136.51", "side": "BUY", "timestamp": "1768475472378", "received_at": "2026-01-15T12:11:12.522285"}}
{"event_type": "price_change", "event_ts": "2026-01-15T12:11:12.522285", "ingestion_ts": "2026-01-15T12:11:41.230171", "market_id": "0xcab7ba4a9133cfd407d7e73e5757e5abbace413b59421527a31113406c97815c", "raw": {"market": "0xcab7ba4a9133cfd407d7e73e5757e5abbace413b59421527a31113406c97815c", "asset_id": "20002636398944597965698652220992177552927816915094913583821579024925426590022", "price": "0.994", "size": "136.51", "side": "SELL", "timestamp": "1768475472378", "received_at": "2026-01-15T12:11:12.522285"}}
{"event_type": "price_change", "event_ts": "2026-01-15T12:11:12.522375", "ingestion_ts": "2026-01-15T12:11:41.230171", "market_id": "0xcab7ba4a9133cfd407d7e73e5757e5abbace413b59421527a31113406c97815c", "raw": {"market": "0xcab7ba4a9133cfd407d7e73e5757e5abbace413b59421527a31113406c97815c", "asset_id": "96361925776989336186111887920533578209326565663637092688733016597062311745569", "price": "0.009", "size": "818.33", "side": "BUY", "timestamp": "1768475472379", "received_at": "2026-01-15T12:11:12.522375"}}
{"event_type": "price_change", "event_ts": "2026-01-15T12:11:12.522375", "ingestion_ts": "2026-01-15T12:11:41.230171", "market_id": "0xcab7ba4a9133cfd407d7e73e5757e5abbace413b59421527a31113406c97815c", "raw": {"market": "0xcab7ba4a9133cfd407d7e73e5757e5abbace413b59421527a31113406c97815c", "asset_id": "20002636398944597965698652220992177552927816915094913583821579024925426590022", "price": "0.991", "size": "818.33", "side": "SELL", "timestamp": "1768475472379", "received_at": "2026-01-15T12:11:12.522375"}}
{"event_type": "price_change", "event_ts": "2026-01-15T12:11:13.037779", "ingestion_ts": "2026-01-15T12:11:41.230171", "market_id": "0xc0e6b917320a47228fb96e3b5ae0e5c93773a5ae2662ae4e1f37807cfe47ce98", "raw": {"market": "0xc0e6b917320a47228fb96e3b5ae0e5c93773a5ae2662ae4e1f37807cfe47ce98", "asset_id": "58656358377246279051017109359677190749228949103591068167284263961542487110215", "price": "0.001", "size": "435.5", "side": "BUY", "timestamp": "1768475472913", "received_at": "2026-01-15T12:11:13.037779"}}
{"event_type": "price_change", "event_ts": "2026-01-15T12:11:13.037779", "ingestion_ts": "2026-01-15T12:11:41.230171", "market_id": "0xc0e6b917320a47228fb96e3b5ae0e5c93773a5ae2662ae4e1f37807cfe47ce98", "raw": {"market": "0xc0e6b917320a47228fb96e3b5ae0e5c93773a5ae2662ae4e1f37807cfe47ce98", "asset_id": "81647294538046680798858716589766492074338758116170717123345952330712416337530", "price": "0.999", "size": "435.5", "side": "SELL", "timestamp": "1768475472913", "received_at": "2026-01-15T12:11:13.037779"}}
{"event_type": "price_change", "event_ts": "2026-01-15T12:11:13.037816", "ingestion_ts": "2026-01-15T12:11:41.230171", "market_id": "0xc0e6b917320a47228fb96e3b5ae0e5c93773a5ae2662ae4e1f37807cfe47ce98", "raw": {"market": "0xc0e6b917320a47228fb96e3b5ae0e5c93773a5ae2662ae4e1f37807cfe47ce98", "asset_id": "58656358377246279051017109359677190749228949103591068167284263961542487110215", "price": "0.002", "size": "3301.78", "side": "BUY", "timestamp": "1768475472913", "received_at": "2026-01-15T12:11:13.037816"}}
{"event_type": "price_change", "event_ts": "2026-01-15T12:11:13.037816", "ingestion_ts": "2026-01-15T12:11:41.230171", "market_id": "0xc0e6b917320a47228fb96e3b5ae0e5c93773a5ae2662ae4e1f37807cfe47ce98", "raw": {"market": "0xc0e6b917320a47228fb96e3b5ae0e5c93773a5ae2662ae4e1f37807cfe47ce98", "asset_id": "81647294538046680798858716589766492074338758116170717123345952330712416337530", "price": "0.998", "size": "3301.78", "side": "SELL", "timestamp": "1768475472913", "received_at": "2026-01-15T12:11:13.037816"}}
{"event_type": "price_change", "event_ts": "2026-01-15T12:11:13.037844", "ingestion_ts": "2026-01-15T12:11:41.230171", "market_id": "0xc0e6b917320a47228fb96e3b5ae0e5c93773a5ae2662ae4e1f37807cfe47ce98", "raw": {"market": "0xc0e6b917320a47228fb96e3b5ae0e5c93773a5ae2662ae4e1f37807cfe47ce98", "asset_id": "58656358377246279051017109359677190749228949103591068167284263961542487110215", "price": "0.003", "size": "404.96", "side": "BUY", "timestamp": "1768475472913", "received_at": "2026-01-15T12:11:13.037844"}}
{"event_type": "price_change", "event_ts": "2026-01-15T12:11:13.037844", "ingestion_ts": "2026-01-15T12:11:41.230171", "market_id": "0xc0e6b917320a47228fb96e3b5ae0e5c93773a5ae2662ae4e1f37807cfe47ce98", "raw": {"market": "0xc0e6b917320a47228fb96e3b5ae0e5c93773a5ae2662ae4e1f37807cfe47ce98", "asset_id": "81647294538046680798858716589766492074338758116170717123345952330712416337530", "price": "0.997", "size": "404.96", "side": "SELL", "timestamp": "1768475472913", "received_at": "2026-01-15T12:11:13.037844"}}
{"event_type": "price_change", "event_ts": "2026-01-15T12:11:13.037871", "ingestion_ts": "2026-01-15T12:11:41.230171", "market_id": "0xc0e6b917320a47228fb96e3b5ae0e5c93773a5ae2662ae4e1f37807cfe47ce98", "raw": {"market": "0xc0e6b917320a47228fb96e3b5ae0e5c93773a5ae2662ae4e1f37807cfe47ce98", "asset_id": "58656358377246279051017109359677190749228949103591068167284263961542487110215", "price": "0.018", "size": "0", "side": "BUY", "timestamp": "1768475472913", "received_at": "2026-01-15T12:11:13.037871"}}
{"event_type": "price_change", "event_ts": "2026-01-15T12:11:13.037871", "ingestion_ts": "2026-01-15T12:11:41.230171", "market_id": "0xc0e6b917320a47228fb96e3b5ae0e5c93773a5ae2662ae4e1f37807cfe47ce98", "raw": {"market": "0xc0e6b917320a47228fb96e3b5ae0e5c93773a5ae2662ae4e1f37807cfe47ce98", "asset_id": "81647294538046680798858716589766492074338758116170717123345952330712416337530", "price": "0.982", "size": "0", "side": "SELL", "timestamp": "1768475472913", "received_at": "2026-01-15T12:11:13.037871"}}
{"event_type": "price_change", "event_ts": "2026-01-15T12:11:13.436590", "ingestion_ts": "2026-01-15T12:11:41.230171", "market_id": "0xc0e6b917320a47228fb96e3b5ae0e5c93773a5ae2662ae4e1f37807cfe47ce98", "raw": {"market": "0xc0e6b917320a47228fb96e3b5ae0e5c93773a5ae2662ae4e1f37807cfe47ce98", "asset_id": "58656358377246279051017109359677190749228949103591068167284263961542487110215", "price": "0.017", "size": "12.02", "side": "BUY", "timestamp": "1768475473314", "received_at": "2026-01-15T12:11:13.436590"}}
{"event_type": "price_change", "event_ts": "2026-01-15T12:11:13.436590", "ingestion_ts": "2026-01-15T12:11:41.230171", "market_id": "0xc0e6b917320a47228fb96e3b5ae0e5c93773a5ae2662ae4e1f37807cfe47ce98", "raw": {"market": "0xc0e6b917320a47228fb96e3b5ae0e5c93773a5ae2662ae4e1f37807cfe47ce98", "asset_id": "81647294538046680798858716589766492074338758116170717123345952330712416337530", "price": "0.983", "size": "12.02", "side": "SELL", "timestamp": "1768475473314", "received_at": "2026-01-15T12:11:13.436590"}}
{"event_type": "price_change", "event_ts": "2026-01-15T12:11:13.436678", "ingestion_ts": "2026-01-15T12:11:41.230171", "market_id": "0xc0e6b917320a47228fb96e3b5ae0e5c93773a5ae2662ae4e1f37807cfe47ce98", "raw": {"market": "0xc0e6b917320a47228fb96e3b5ae0e5c93773a5ae2662ae4e1f37807cfe47ce98", "asset_id": "58656358377246279051017109359677190749228949103591068167284263961542487110215", "price": "0.017", "size": "18.64", "side": "BUY", "timestamp": "1768475473315", "received_at": "2026-01-15T12:11:13.436678"}}
{"event_type": "price_change", "event_ts": "2026-01-15T12:11:13.436678", "ingestion_ts": "2026-01-15T12:11:41.230171", "market_id": "0xc0e6b917320a47228fb96e3b5ae0e5c93773a5ae2662ae4e1f37807cfe47ce98", "raw": {"market": "0xc0e6b917320a47228fb96e3b5ae0e5c93773a5ae2662ae4e1f37807cfe47ce98", "asset_id": "81647294538046680798858716589766492074338758116170717123345952330712416337530", "price": "0.983", "size": "18.64", "side": "SELL", "timestamp": "1768475473315", "received_at": "2026-01-15T12:11:13.436678"}}
{"event_type": "price_change", "event_ts": "2026-01-15T12:11:14.678367", "ingestion_ts": "2026-01-15T12:11:41.230171", "market_id": "0xcab7ba4a9133cfd407d7e73e5757e5abbace413b59421527a31113406c97815c", "raw": {"market": "0xcab7ba4a9133cfd407d7e73e5757e5abbace413b59421527a31113406c97815c", "asset_id": "96361925776989336186111887920533578209326565663637092688733016597062311745569", "price": "0.006", "size": "127.41", "side": "BUY", "timestamp": "1768475474557", "received_at": "2026-01-15T12:11:14.678367"}}
{"event_type": "price_change", "event_ts": "2026-01-15T12:11:14.678367", "ingestion_ts": "2026-01-15T12:11:41.230171", "market_id": "0xcab7ba4a9133cfd407d7e73e5757e5abbace413b59421527a31113406c97815c", "raw": {"market": "0xcab7ba4a9133cfd407d7e73e5757e5abbace413b59421527a31113406c97815c", "asset_id": "20002636398944597965698652220992177552927816915094913583821579024925426590022", "price": "0.994", "size": "127.41", "side": "SELL", "timestamp": "1768475474557", "received_at": "2026-01-15T12:11:14.678367"}}
{"event_type": "price_change", "event_ts": "2026-01-15T12:11:14.678487", "ingestion_ts": "2026-01-15T12:11:41.230171", "market_id": "0xcab7ba4a9133cfd407d7e73e5757e5abbace413b59421527a31113406c97815c", "raw": {"market": "0xcab7ba4a9133cfd407d7e73e5757e5abbace413b59421527a31113406c97815c", "asset_id": "96361925776989336186111887920533578209326565663637092688733016597062311745569", "price": "0.009", "size": "812.25", "side": "BUY", "timestamp": "1768475474557", "received_at": "2026-01-15T12:11:14.678487"}}
{"event_type": "price_change", "event_ts": "2026-01-15T12:11:14.678487", "ingestion_ts": "2026-01-15T12:11:41.230171", "market_id": "0xcab7ba4a9133cfd407d7e73e5757e5abbace413b59421527a31113406c97815c", "raw": {"market": "0xcab7ba4a9133cfd407d7e73e5757e5abbace413b59421527a31113406c97815c", "asset_id": "20002636398944597965698652220992177552927816915094913583821579024925426590022", "price": "0.991", "size": "812.25", "side": "SELL", "timestamp": "1768475474557", "received_at": "2026-01-15T12:11:14.678487"}}
{"event_type": "price_change", "event_ts": "2026-01-15T12:11:15.528979", "ingestion_ts": "2026-01-15T12:11:41.230171", "market_id": "0xcab7ba4a9133cfd407d7e73e5757e5abbace413b59421527a31113406c97815c", "raw": {"market": "0xcab7ba4a9133cfd407d7e73e5757e5abbace413b59421527a31113406c97815c", "asset_id": "96361925776989336186111887920533578209326565663637092688733016597062311745569", "price": "0.006", "size": "136.51", "side": "BUY", "timestamp": "1768475475409", "received_at": "2026-01-15T12:11:15.528979"}}
{"event_type": "price_change", "event_ts": "2026-01-15T12:11:15.528979", "ingestion_ts": "2026-01-15T12:11:41.230171", "market_id": "0xcab7ba4a9133cfd407d7e73e5757e5abbace413b59421527a31113406c97815c", "raw": {"market": "0xcab7ba4a9133cfd407d7e73e5757e5abbace413b59421527a31113406c97815c", "asset_id": "20002636398944597965698652220992177552927816915094913583821579024925426590022", "price": "0.994", "size": "136.51", "side": "SELL", "timestamp": "1768475475409", "received_at": "2026-01-15T12:11:15.528979"}}
{"event_type": "price_change", "event_ts": "2026-01-15T12:11:15.530075", "ingestion_ts": "2026-01-15T12:11:41.230171", "market_id": "0xcab7ba4a9133cfd407d7e73e5757e5abbace413b59421527a31113406c97815c", "raw": {"market": "0xcab7ba4a9133cfd407d7e73e5757e5abbace413b59421527a31113406c97815c", "asset_id": "96361925776989336186111887920533578209326565663637092688733016597062311745569", "price": "0.009", "size": "818.33", "side": "BUY", "timestamp": "1768475475410", "received_at": "2026-01-15T12:11:15.530075"}}
{"event_type": "price_change", "event_ts": "2026-01-15T12:11:15.530075", "ingestion_ts": "2026-01-15T12:11:41.230171", "market_id": "0xcab7ba4a9133cfd407d7e73e5757e5abbace413b59421527a31113406c97815c", "raw": {"market": "0xcab7ba4a9133cfd407d7e73e5757e5abbace413b59421527a31113406c97815c", "asset_id": "20002636398944597965698652220992177552927816915094913583821579024925426590022", "price": "0.991", "size": "818.33", "side": "SELL", "timestamp": "1768475475410", "received_at": "2026-01-15T12:11:15.530075"}}
{"event_type": "price_change", "event_ts": "2026-01-15T12:11:16.102738", "ingestion_ts": "2026-01-15T12:11:41.230171", "market_id": "0x427bc4b40c09b3dcbc973747f0e4b079bed91b3e5a0aed5c36edd0f7591485f4", "raw": {"market": "0x427bc4b40c09b3dcbc973747f0e4b079bed91b3e5a0aed5c36edd0f7591485f4", "asset_id": "115669573443672055876643967408433138119481486650803218131873713375232186497057", "price": "0.003", "size": "4.03", "side": "BUY", "timestamp": "1768475475976", "received_at": "2026-01-15T12:11:16.102738"}}
{"event_type": "price_change", "event_ts": "2026-01-15T12:11:16.102738", "ingestion_ts": "2026-01-15T12:11:41.230171", "market_id": "0x427bc4b40c09b3dcbc973747f0e4b079bed91b3e5a0aed5c36edd0f7591485f4", "raw": {"market": "0x427bc4b40c09b3dcbc973747f0e4b079bed91b3e5a0aed5c36edd0f7591485f4", "asset_id": "86130975769502911188457673769190265049139877688522439001984850068234616395137", "price": "0.997", "size": "4.03", "side": "SELL", "timestamp": "1768475475976", "received_at": "2026-01-15T12:11:16.102738"}}
{"event_type": "price_change", "event_ts": "2026-01-15T12:11:16.275294", "ingestion_ts": "2026-01-15T12:11:41.230171", "market_id": "0xc0e6b917320a47228fb96e3b5ae0e5c93773a5ae2662ae4e1f37807cfe47ce98", "raw": {"market": "0xc0e6b917320a47228fb96e3b5ae0e5c93773a5ae2662ae4e1f37807cfe47ce98", "asset_id": "58656358377246279051017109359677190749228949103591068167284263961542487110215", "price": "0.017", "size": "12.02", "side": "BUY", "timestamp": "1768475476149", "received_at": "2026-01-15T12:11:16.275294"}}
{"event_type": "price_change", "event_ts": "2026-01-15T12:11:16.275294", "ingestion_ts": "2026-01-15T12:11:41.230171", "market_id": "0xc0e6b917320a47228fb96e3b5ae0e5c93773a5ae2662ae4e1f37807cfe47ce98", "raw": {"market": "0xc0e6b917320a47228fb96e3b5ae0e5c93773a5ae2662ae4e1f37807cfe47ce98", "asset_id": "81647294538046680798858716589766492074338758116170717123345952330712416337530", "price": "0.983", "size": "12.02", "side": "SELL", "timestamp": "1768475476149", "received_at": "2026-01-15T12:11:16.275294"}}
{"event_type": "price_change", "event_ts": "2026-01-15T12:11:16.430304", "ingestion_ts": "2026-01-15T12:11:41.230171", "market_id": "0x427bc4b40c09b3dcbc973747f0e4b079bed91b3e5a0aed5c36edd0f7591485f4", "raw": {"market": "0x427bc4b40c09b3dcbc973747f0e4b079bed91b3e5a0aed5c36edd0f7591485f4", "asset_id": "115669573443672055876643967408433138119481486650803218131873713375232186497057", "price": "0.002", "size": "72.33", "side": "BUY", "timestamp": "1768475476302", "received_at": "2026-01-15T12:11:16.430304"}}
{"event_type": "price_change", "event_ts": "2026-01-15T12:11:16.430304", "ingestion_ts": "2026-01-15T12:11:41.230171", "market_id": "0x427bc4b40c09b3dcbc973747f0e4b079bed91b3e5a0aed5c36edd0f7591485f4", "raw": {"market": "0x427bc4b40c09b3dcbc973747f0e4b079bed91b3e5a0aed5c36edd0f7591485f4", "asset_id": "86130975769502911188457673769190265049139877688522439001984850068234616395137", "price": "0.998", "size": "72.33", "side": "SELL", "timestamp": "1768475476302", "received_at": "2026-01-15T12:11:16.430304"}}
{"event_type": "price_change", "event_ts": "2026-01-15T12:11:16.822742", "ingestion_ts": "2026-01-15T12:11:41.230171", "market_id": "0x427bc4b40c09b3dcbc973747f0e4b079bed91b3e5a0aed5c36edd0f7591485f4", "raw": {"market": "0x427bc4b40c09b3dcbc973747f0e4b079bed91b3e5a0aed5c36edd0f7591485f4", "asset_id": "115669573443672055876643967408433138119481486650803218131873713375232186497057", "price": "0.163", "size": "0", "side": "SELL", "timestamp": "1768475476703", "received_at": "2026-01-15T12:11:16.822742"}}
{"event_type": "price_change", "event_ts": "2026-01-15T12:11:16.822742", "ingestion_ts": "2026-01-15T12:11:41.230171", "market_id": "0x427bc4b40c09b3dcbc973747f0e4b079bed91b3e5a0aed5c36edd0f7591485f4", "raw": {"market": "0x427bc4b40c09b3dcbc973747f0e4b079bed91b3e5a0aed5c36edd0f7591485f4", "asset_id": "86130975769502911188457673769190265049139877688522439001984850068234616395137", "price": "0.837", "size": "0", "side": "BUY", "timestamp": "1768475476703", "received_at": "2026-01-15T12:11:16.822742"}}
{"event_type": "price_change", "event_ts": "2026-01-15T12:11:17.012155", "ingestion_ts": "2026-01-15T12:11:41.230171", "market_id": "0xc0e6b917320a47228fb96e3b5ae0e5c93773a5ae2662ae4e1f37807cfe47ce98", "raw": {"market": "0xc0e6b917320a47228fb96e3b5ae0e5c93773a5ae2662ae4e1f37807cfe47ce98", "asset_id": "58656358377246279051017109359677190749228949103591068167284263961542487110215", "price": "0.002", "size": "3307.35", "side": "BUY", "timestamp": "1768475476893", "received_at": "2026-01-15T12:11:17.012155"}}
{"event_type": "price_change", "event_ts": "2026-01-15T12:11:17.012155", "ingestion_ts": "2026-01-15T12:11:41.230171", "market_id": "0xc0e6b917320a47228fb96e3b5ae0e5c93773a5ae2662ae4e1f37807cfe47ce98", "raw": {"market": "0xc0e6b917320a47228fb96e3b5ae0e5c93773a5ae2662ae4e1f37807cfe47ce98", "asset_id": "81647294538046680798858716589766492074338758116170717123345952330712416337530", "price": "0.998", "size": "3307.35", "side": "SELL", "timestamp": "1768475476893", "received_at": "2026-01-15T12:11:17.012155"}}
{"event_type": "price_change", "event_ts": "2026-01-15T12:11:17.019990", "ingestion_ts": "2026-01-15T12:11:41.230171", "market_id": "0xc0e6b917320a47228fb96e3b5ae0e5c93773a5ae2662ae4e1f37807cfe47ce98", "raw": {"market": "0xc0e6b917320a47228fb96e3b5ae0e5c93773a5ae2662ae4e1f37807cfe47ce98", "asset_id": "58656358377246279051017109359677190749228949103591068167284263961542487110215", "price": "0.001", "size": "440.72", "side": "BUY", "timestamp": "1768475476899", "received_at": "2026-01-15T12:11:17.019990"}}
{"event_type": "price_change", "event_ts": "2026-01-15T12:11:17.019990", "ingestion_ts": "2026-01-15T12:11:41.230171", "market_id": "0xc0e6b917320a47228fb96e3b5ae0e5c93773a5ae2662ae4e1f37807cfe47ce98", "raw": {"market": "0xc0e6b917320a47228fb96e3b5ae0e5c93773a5ae2662ae4e1f37807cfe47ce98", "asset_id": "81647294538046680798858716589766492074338758116170717123345952330712416337530", "price": "0.999", "size": "440.72", "side": "SELL", "timestamp": "1768475476899", "received_at": "2026-01-15T12:11:17.019990"}}
{"event_type": "price_change", "event_ts": "2026-01-15T12:11:17.021212", "ingestion_ts": "2026-01-15T12:11:41.230171", "market_id": "0xc0e6b917320a47228fb96e3b5ae0e5c93773a5ae2662ae4e1f37807cfe47ce98", "raw": {"market": "0xc0e6b917320a47228fb96e3b5ae0e5c93773a5ae2662ae4e1f37807cfe47ce98", "asset_id": "58656358377246279051017109359677190749228949103591068167284263961542487110215", "price": "0.002", "size": "3312.92", "side": "BUY", "timestamp": "1768475476904", "received_at": "2026-01-15T12:11:17.021212"}}
{"event_type": "price_change", "event_ts": "2026-01-15T12:11:17.021212", "ingestion_ts": "2026-01-15T12:11:41.230171", "market_id": "0xc0e6b917320a47228fb96e3b5ae0e5c93773a5ae2662ae4e1f37807cfe47ce98", "raw": {"market": "0xc0e6b917320a47228fb96e3b5ae0e5c93773a5ae2662ae4e1f37807cfe47ce98", "asset_id": "81647294538046680798858716589766492074338758116170717123345952330712416337530", "price": "0.998", "size": "3312.92", "side": "SELL", "timestamp": "1768475476904", "received_at": "2026-01-15T12:11:17.021212"}}
{"event_type": "price_change", "event_ts": "2026-01-15T12:11:17.031110", "ingestion_ts": "2026-01-15T12:11:41.230171", "market_id": "0xc0e6b917320a47228fb96e3b5ae0e5c93773a5ae2662ae4e1f37807cfe47ce98", "raw": {"market": "0xc0e6b917320a47228fb96e3b5ae0e5c93773a5ae2662ae4e1f37807cfe47ce98", "asset_id": "58656358377246279051017109359677190749228949103591068167284263961542487110215", "price": "0.003", "size": "418.26", "side": "BUY", "timestamp": "1768475476907", "received_at": "2026-01-15T12:11:17.031110"}}
{"event_type": "price_change", "event_ts": "2026-01-15T12:11:17.031110", "ingestion_ts": "2026-01-15T12:11:41.230171", "market_id": "0xc0e6b917320a47228fb96e3b5ae0e5c93773a5ae2662ae4e1f37807cfe47ce98", "raw": {"market": "0xc0e6b917320a47228fb96e3b5ae0e5c93773a5ae2662ae4e1f37807cfe47ce98", "asset_id": "81647294538046680798858716589766492074338758116170717123345952330712416337530", "price": "0.997", "size": "418.26", "side": "SELL", "timestamp": "1768475476907", "received_at": "2026-01-15T12:11:17.031110"}}
{"event_type": "price_change", "event_ts": "2026-01-15T12:11:17.039015", "ingestion_ts": "2026-01-15T12:11:41.230171", "market_id": "0xc0e6b917320a47228fb96e3b5ae0e5c93773a5ae2662ae4e1f37807cfe47ce98", "raw": {"market": "0xc0e6b917320a47228fb96e3b5ae0e5c93773a5ae2662ae4e1f37807cfe47ce98", "asset_id": "58656358377246279051017109359677190749228949103591068167284263961542487110215", "price": "0.001", "size": "445.94", "side": "BUY", "timestamp": "1768475476910", "received_at": "2026-01-15T12:11:17.039015"}}
{"event_type": "price_change", "event_ts": "2026-01-15T12:11:17.039015", "ingestion_ts": "2026-01-15T12:11:41.230171", "market_id": "0xc0e6b917320a47228fb96e3b5ae0e5c93773a5ae2662ae4e1f37807cfe47ce98", "raw": {"market": "0xc0e6b917320a47228fb96e3b5ae0e5c93773a5ae2662ae4e1f37807cfe47ce98", "asset_id": "81647294538046680798858716589766492074338758116170717123345952330712416337530", "price": "0.999", "size": "445.94", "side": "SELL", "timestamp": "1768475476910", "received_at": "2026-01-15T12:11:17.039015"}}
{"event_type": "price_change", "event_ts": "2026-01-15T12:11:17.039094", "ingestion_ts": "2026-01-15T12:11:41.230171", "market_id": "0xc0e6b917320a47228fb96e3b5ae0e5c93773a5ae2662ae4e1f37807cfe47ce98", "raw": {"market": "0xc0e6b917320a47228fb96e3b5ae0e5c93773a5ae2662ae4e1f37807cfe47ce98", "asset_id": "58656358377246279051017109359677190749228949103591068167284263961542487110215", "price": "0.003", "size": "431.56", "side": "BUY", "timestamp": "1768475476913", "received_at": "2026-01-15T12:11:17.039094"}}
{"event_type": "price_change", "event_ts": "2026-01-15T12:11:17.039094", "ingestion_ts": "2026-01-15T12:11:41.230171", "market_id": "0xc0e6b917320a47228fb96e3b5ae0e5c93773a5ae2662ae4e1f37807cfe47ce98", "raw": {"market": "0xc0e6b917320a47228fb96e3b5ae0e5c93773a5ae2662ae4e1f37807cfe47ce98", "asset_id": "81647294538046680798858716589766492074338758116170717123345952330712416337530", "price": "0.997", "size": "431.56", "side": "SELL", "timestamp": "1768475476913", "received_at": "2026-01-15T12:11:17.039094"}}
{"event_type": "price_change", "event_ts": "2026-01-15T12:11:17.195997", "ingestion_ts": "2026-01-15T12:11:41.230171", "market_id": "0x427bc4b40c09b3dcbc973747f0e4b079bed91b3e5a0aed5c36edd0f7591485f4", "raw": {"market": "0x427bc4b40c09b3dcbc973747f0e4b079bed91b3e5a0aed5c36edd0f7591485f4", "asset_id": "115669573443672055876643967408433138119481486650803218131873713375232186497057", "price": "0.164", "size": "15.92", "side": "SELL", "timestamp": "1768475477055", "received_at": "2026-01-15T12:11:17.195997"}}
{"event_type": "price_change", "event_ts": "2026-01-15T12:11:17.195997", "ingestion_ts": "2026-01-15T12:11:41.230171", "market_id": "0x427bc4b40c09b3dcbc973747f0e4b079bed91b3e5a0aed5c36edd0f7591485f4", "raw": {"market": "0x427bc4b40c09b3dcbc973747f0e4b079bed91b3e5a0aed5c36edd0f7591485f4", "asset_id": "86130975769502911188457673769190265049139877688522439001984850068234616395137", "price": "0.836", "size": "15.92", "side": "BUY", "timestamp": "1768475477055", "received_at": "2026-01-15T12:11:17.195997"}}
{"event_type": "price_change", "event_ts": "2026-01-15T12:11:17.370783", "ingestion_ts": "2026-01-15T12:11:41.230171", "market_id": "0xcab7ba4a9133cfd407d7e73e5757e5abbace413b59421527a31113406c97815c", "raw": {"market": "0xcab7ba4a9133cfd407d7e73e5757e5abbace413b59421527a31113406c97815c", "asset_id": "96361925776989336186111887920533578209326565663637092688733016597062311745569", "price": "0.006", "size": "127.41", "side": "BUY", "timestamp": "1768475477251", "received_at": "2026-01-15T12:11:17.370783"}}
{"event_type": "price_change", "event_ts": "2026-01-15T12:11:17.370783", "ingestion_ts": "2026-01-15T12:11:41.230171", "market_id": "0xcab7ba4a9133cfd407d7e73e5757e5abbace413b59421527a31113406c97815c", "raw": {"market": "0xcab7ba4a9133cfd407d7e73e5757e5abbace413b59421527a31113406c97815c", "asset_id": "20002636398944597965698652220992177552927816915094913583821579024925426590022", "price": "0.994", "size": "127.41", "side": "SELL", "timestamp": "1768475477251", "received_at": "2026-01-15T12:11:17.370783"}}
{"event_type": "price_change", "event_ts": "2026-01-15T12:11:17.372213", "ingestion_ts": "2026-01-15T12:11:41.230171", "market_id": "0xcab7ba4a9133cfd407d7e73e5757e5abbace413b59421527a31113406c97815c", "raw": {"market": "0xcab7ba4a9133cfd407d7e73e5757e5abbace413b59421527a31113406c97815c", "asset_id": "96361925776989336186111887920533578209326565663637092688733016597062311745569", "price": "0.009", "size": "812.25", "side": "BUY", "timestamp": "1768475477251", "received_at": "2026-01-15T12:11:17.372213"}}
{"event_type": "price_change", "event_ts": "2026-01-15T12:11:17.372213", "ingestion_ts": "2026-01-15T12:11:41.230171", "market_id": "0xcab7ba4a9133cfd407d7e73e5757e5abbace413b59421527a31113406c97815c", "raw": {"market": "0xcab7ba4a9133cfd407d7e73e5757e5abbace413b59421527a31113406c97815c", "asset_id": "20002636398944597965698652220992177552927816915094913583821579024925426590022", "price": "0.991", "size": "812.25", "side": "SELL", "timestamp": "1768475477251", "received_at": "2026-01-15T12:11:17.372213"}}
{"event_type": "price_change", "event_ts": "2026-01-15T12:11:17.753121", "ingestion_ts": "2026-01-15T12:11:41.230171", "market_id": "0xcab7ba4a9133cfd407d7e73e5757e5abbace413b59421527a31113406c97815c", "raw": {"market": "0xcab7ba4a9133cfd407d7e73e5757e5abbace413b59421527a31113406c97815c", "asset_id": "96361925776989336186111887920533578209326565663637092688733016597062311745569", "price": "0.009", "size": "818.33", "side": "BUY", "timestamp": "1768475477630", "received_at": "2026-01-15T12:11:17.753121"}}
{"event_type": "price_change", "event_ts": "2026-01-15T12:11:17.753121", "ingestion_ts": "2026-01-15T12:11:41.230171", "market_id": "0xcab7ba4a9133cfd407d7e73e5757e5abbace413b59421527a31113406c97815c", "raw": {"market": "0xcab7ba4a9133cfd407d7e73e5757e5abbace413b59421527a31113406c97815c", "asset_id": "20002636398944597965698652220992177552927816915094913583821579024925426590022", "price": "0.991", "size": "818.33", "side": "SELL", "timestamp": "1768475477630", "received_at": "2026-01-15T12:11:17.753121"}}
{"event_type": "price_change", "event_ts": "2026-01-15T12:11:17.753279", "ingestion_ts": "2026-01-15T12:11:41.230171", "market_id": "0xcab7ba4a9133cfd407d7e73e5757e5abbace413b59421527a31113406c97815c", "raw": {"market": "0xcab7ba4a9133cfd407d7e73e5757e5abbace413b59421527a31113406c97815c", "asset_id": "96361925776989336186111887920533578209326565663637092688733016597062311745569", "price": "0.006", "size": "136.51", "side": "BUY", "timestamp": "1768475477631", "received_at": "2026-01-15T12:11:17.753279"}}
{"event_type": "price_change", "event_ts": "2026-01-15T12:11:17.753279", "ingestion_ts": "2026-01-15T12:11:41.230171", "market_id": "0xcab7ba4a9133cfd407d7e73e5757e5abbace413b59421527a31113406c97815c", "raw": {"market": "0xcab7ba4a9133cfd407d7e73e5757e5abbace413b59421527a31113406c97815c", "asset_id": "20002636398944597965698652220992177552927816915094913583821579024925426590022", "price": "0.994", "size": "136.51", "side": "SELL", "timestamp": "1768475477631", "received_at": "2026-01-15T12:11:17.753279"}}
{"event_type": "price_change", "event_ts": "2026-01-15T12:11:19.503561", "ingestion_ts": "2026-01-15T12:11:41.230171", "market_id": "0xc0e6b917320a47228fb96e3b5ae0e5c93773a5ae2662ae4e1f37807cfe47ce98", "raw": {"market": "0xc0e6b917320a47228fb96e3b5ae0e5c93773a5ae2662ae4e1f37807cfe47ce98", "asset_id": "58656358377246279051017109359677190749228949103591068167284263961542487110215", "price": "0.001", "size": "439.8", "side": "BUY", "timestamp": "1768475479378", "received_at": "2026-01-15T12:11:19.503561"}}
{"event_type": "price_change", "event_ts": "2026-01-15T12:11:19.503561", "ingestion_ts": "2026-01-15T12:11:41.230171", "market_id": "0xc0e6b917320a47228fb96e3b5ae0e5c93773a5ae2662ae4e1f37807cfe47ce98", "raw": {"market": "0xc0e6b917320a47228fb96e3b5ae0e5c93773a5ae2662ae4e1f37807cfe47ce98", "asset_id": "81647294538046680798858716589766492074338758116170717123345952330712416337530", "price": "0.999", "size": "439.8", "side": "SELL", "timestamp": "1768475479378", "received_at": "2026-01-15T12:11:19.503561"}}
{"event_type": "price_change", "event_ts": "2026-01-15T12:11:19.503671", "ingestion_ts": "2026-01-15T12:11:41.230171", "market_id": "0xc0e6b917320a47228fb96e3b5ae0e5c93773a5ae2662ae4e1f37807cfe47ce98", "raw": {"market": "0xc0e6b917320a47228fb96e3b5ae0e5c93773a5ae2662ae4e1f37807cfe47ce98", "asset_id": "58656358377246279051017109359677190749228949103591068167284263961542487110215", "price": "0.002", "size": "3306.42", "side": "BUY", "timestamp": "1768475479378", "received_at": "2026-01-15T12:11:19.503671"}}
{"event_type": "price_change", "event_ts": "2026-01-15T12:11:19.503671", "ingestion_ts": "2026-01-15T12:11:41.230171", "market_id": "0xc0e6b917320a47228fb96e3b5ae0e5c93773a5ae2662ae4e1f37807cfe47ce98", "raw": {"market": "0xc0e6b917320a47228fb96e3b5ae0e5c93773a5ae2662ae4e1f37807cfe47ce98", "asset_id": "81647294538046680798858716589766492074338758116170717123345952330712416337530", "price": "0.998", "size": "3306.42", "side": "SELL", "timestamp": "1768475479378", "received_at": "2026-01-15T12:11:19.503671"}}
{"event_type": "price_change", "event_ts": "2026-01-15T12:11:19.503713", "ingestion_ts": "2026-01-15T12:11:41.230171", "market_id": "0xc0e6b917320a47228fb96e3b5ae0e5c93773a5ae2662ae4e1f37807cfe47ce98", "raw": {"market": "0xc0e6b917320a47228fb96e3b5ae0e5c93773a5ae2662ae4e1f37807cfe47ce98", "asset_id": "58656358377246279051017109359677190749228949103591068167284263961542487110215", "price": "0.003", "size": "417.57", "side": "BUY", "timestamp": "1768475479378", "received_at": "2026-01-15T12:11:19.503713"}}
{"event_type": "price_change", "event_ts": "2026-01-15T12:11:19.503713", "ingestion_ts": "2026-01-15T12:11:41.230171", "market_id": "0xc0e6b917320a47228fb96e3b5ae0e5c93773a5ae2662ae4e1f37807cfe47ce98", "raw": {"market": "0xc0e6b917320a47228fb96e3b5ae0e5c93773a5ae2662ae4e1f37807cfe47ce98", "asset_id": "81647294538046680798858716589766492074338758116170717123345952330712416337530", "price": "0.997", "size": "417.57", "side": "SELL", "timestamp": "1768475479378", "received_at": "2026-01-15T12:11:19.503713"}}
{"event_type": "price_change", "event_ts": "2026-01-15T12:11:19.503749", "ingestion_ts": "2026-01-15T12:11:41.230171", "market_id": "0xcab7ba4a9133cfd407d7e73e5757e5abbace413b59421527a31113406c97815c", "raw": {"market": "0xcab7ba4a9133cfd407d7e73e5757e5abbace413b59421527a31113406c97815c", "asset_id": "96361925776989336186111887920533578209326565663637092688733016597062311745569", "price": "0.006", "size": "127.41", "side": "BUY", "timestamp": "1768475479378", "received_at": "2026-01-15T12:11:19.503749"}}
{"event_type": "price_change", "event_ts": "2026-01-15T12:11:19.503749", "ingestion_ts": "2026-01-15T12:11:41.230171", "market_id": "0xcab7ba4a9133cfd407d7e73e5757e5abbace413b59421527a31113406c97815c", "raw": {"market": "0xcab7ba4a9133cfd407d7e73e5757e5abbace413b59421527a31113406c97815c", "asset_id": "20002636398944597965698652220992177552927816915094913583821579024925426590022", "price": "0.994", "size": "127.41", "side": "SELL", "timestamp": "1768475479378", "received_at": "2026-01-15T12:11:19.503749"}}
{"event_type": "price_change", "event_ts": "2026-01-15T12:11:19.503783", "ingestion_ts": "2026-01-15T12:11:41.230171", "market_id": "0xcab7ba4a9133cfd407d7e73e5757e5abbace413b59421527a31113406c97815c", "raw": {"market": "0xcab7ba4a9133cfd407d7e73e5757e5abbace413b59421527a31113406c97815c", "asset_id": "96361925776989336186111887920533578209326565663637092688733016597062311745569", "price": "0.009", "size": "812.25", "side": "BUY", "timestamp": "1768475479378", "received_at": "2026-01-15T12:11:19.503783"}}
{"event_type": "price_change", "event_ts": "2026-01-15T12:11:19.503783", "ingestion_ts": "2026-01-15T12:11:41.230171", "market_id": "0xcab7ba4a9133cfd407d7e73e5757e5abbace413b59421527a31113406c97815c", "raw": {"market": "0xcab7ba4a9133cfd407d7e73e5757e5abbace413b59421527a31113406c97815c", "asset_id": "20002636398944597965698652220992177552927816915094913583821579024925426590022", "price": "0.991", "size": "812.25", "side": "SELL", "timestamp": "1768475479378", "received_at": "2026-01-15T12:11:19.503783"}}
{"event_type": "price_change", "event_ts": "2026-01-15T12:11:19.882300", "ingestion_ts": "2026-01-15T12:11:41.230171", "market_id": "0xc0e6b917320a47228fb96e3b5ae0e5c93773a5ae2662ae4e1f37807cfe47ce98", "raw": {"market": "0xc0e6b917320a47228fb96e3b5ae0e5c93773a5ae2662ae4e1f37807cfe47ce98", "asset_id": "58656358377246279051017109359677190749228949103591068167284263961542487110215", "price": "0.001", "size": "448.3", "side": "BUY", "timestamp": "1768475479760", "received_at": "2026-01-15T12:11:19.882300"}}
{"event_type": "price_change", "event_ts": "2026-01-15T12:11:19.882300", "ingestion_ts": "2026-01-15T12:11:41.230171", "market_id": "0xc0e6b917320a47228fb96e3b5ae0e5c93773a5ae2662ae4e1f37807cfe47ce98", "raw": {"market": "0xc0e6b917320a47228fb96e3b5ae0e5c93773a5ae2662ae4e1f37807cfe47ce98", "asset_id": "81647294538046680798858716589766492074338758116170717123345952330712416337530", "price": "0.999", "size": "448.3", "side": "SELL", "timestamp": "1768475479760", "received_at": "2026-01-15T12:11:19.882300"}}
{"event_type": "price_change", "event_ts": "2026-01-15T12:11:19.882392", "ingestion_ts": "2026-01-15T12:11:41.230171", "market_id": "0xc0e6b917320a47228fb96e3b5ae0e5c93773a5ae2662ae4e1f37807cfe47ce98", "raw": {"market": "0xc0e6b917320a47228fb96e3b5ae0e5c93773a5ae2662ae4e1f37807cfe47ce98", "asset_id": "58656358377246279051017109359677190749228949103591068167284263961542487110215", "price": "0.003", "size": "423.41", "side": "BUY", "timestamp": "1768475479761", "received_at": "2026-01-15T12:11:19.882392"}}
{"event_type": "price_change", "event_ts": "2026-01-15T12:11:19.882392", "ingestion_ts": "2026-01-15T12:11:41.230171", "market_id": "0xc0e6b917320a47228fb96e3b5ae0e5c93773a5ae2662ae4e1f37807cfe47ce98", "raw": {"market": "0xc0e6b917320a47228fb96e3b5ae0e5c93773a5ae2662ae4e1f37807cfe47ce98", "asset_id": "81647294538046680798858716589766492074338758116170717123345952330712416337530", "price": "0.997", "size": "423.41", "side": "SELL", "timestamp": "1768475479761", "received_at": "2026-01-15T12:11:19.882392"}}
{"event_type": "price_change", "event_ts": "2026-01-15T12:11:19.882435", "ingestion_ts": "2026-01-15T12:11:41.230171", "market_id": "0xc0e6b917320a47228fb96e3b5ae0e5c93773a5ae2662ae4e1f37807cfe47ce98", "raw": {"market": "0xc0e6b917320a47228fb96e3b5ae0e5c93773a5ae2662ae4e1f37807cfe47ce98", "asset_id": "58656358377246279051017109359677190749228949103591068167284263961542487110215", "price": "0.003", "size": "429.25", "side": "BUY", "timestamp": "1768475479762", "received_at": "2026-01-15T12:11:19.882435"}}
{"event_type": "price_change", "event_ts": "2026-01-15T12:11:19.882435", "ingestion_ts": "2026-01-15T12:11:41.230171", "market_id": "0xc0e6b917320a47228fb96e3b5ae0e5c93773a5ae2662ae4e1f37807cfe47ce98", "raw": {"market": "0xc0e6b917320a47228fb96e3b5ae0e5c93773a5ae2662ae4e1f37807cfe47ce98", "asset_id": "81647294538046680798858716589766492074338758116170717123345952330712416337530", "price": "0.997", "size": "429.25", "side": "SELL", "timestamp": "1768475479762", "received_at": "2026-01-15T12:11:19.882435"}}
{"event_type": "price_change", "event_ts": "2026-01-15T12:11:19.882471", "ingestion_ts": "2026-01-15T12:11:41.230171", "market_id": "0xc0e6b917320a47228fb96e3b5ae0e5c93773a5ae2662ae4e1f37807cfe47ce98", "raw": {"market": "0xc0e6b917320a47228fb96e3b5ae0e5c93773a5ae2662ae4e1f37807cfe47ce98", "asset_id": "58656358377246279051017109359677190749228949103591068167284263961542487110215", "price": "0.002", "size": "3315.21", "side": "BUY", "timestamp": "1768475479763", "received_at": "2026-01-15T12:11:19.882471"}}
{"event_type": "price_change", "event_ts": "2026-01-15T12:11:19.882471", "ingestion_ts": "2026-01-15T12:11:41.230171", "market_id": "0xc0e6b917320a47228fb96e3b5ae0e5c93773a5ae2662ae4e1f37807cfe47ce98", "raw": {"market": "0xc0e6b917320a47228fb96e3b5ae0e5c93773a5ae2662ae4e1f37807cfe47ce98", "asset_id": "81647294538046680798858716589766492074338758116170717123345952330712416337530", "price": "0.998", "size": "3315.21", "side": "SELL", "timestamp": "1768475479763", "received_at": "2026-01-15T12:11:19.882471"}}
{"event_type": "price_change", "event_ts": "2026-01-15T12:11:19.913341", "ingestion_ts": "2026-01-15T12:11:41.230171", "market_id": "0xcab7ba4a9133cfd407d7e73e5757e5abbace413b59421527a31113406c97815c", "raw": {"market": "0xcab7ba4a9133cfd407d7e73e5757e5abbace413b59421527a31113406c97815c", "asset_id": "96361925776989336186111887920533578209326565663637092688733016597062311745569", "price": "0.009", "size": "818.33", "side": "BUY", "timestamp": "1768475479793", "received_at": "2026-01-15T12:11:19.913341"}}
{"event_type": "price_change", "event_ts": "2026-01-15T12:11:19.913341", "ingestion_ts": "2026-01-15T12:11:41.230171", "market_id": "0xcab7ba4a9133cfd407d7e73e5757e5abbace413b59421527a31113406c97815c", "raw": {"market": "0xcab7ba4a9133cfd407d7e73e5757e5abbace413b59421527a31113406c97815c", "asset_id": "20002636398944597965698652220992177552927816915094913583821579024925426590022", "price": "0.991", "size": "818.33", "side": "SELL", "timestamp": "1768475479793", "received_at": "2026-01-15T12:11:19.913341"}}
{"event_type": "price_change", "event_ts": "2026-01-15T12:11:19.913436", "ingestion_ts": "2026-01-15T12:11:41.230171", "market_id": "0xcab7ba4a9133cfd407d7e73e5757e5abbace413b59421527a31113406c97815c", "raw": {"market": "0xcab7ba4a9133cfd407d7e73e5757e5abbace413b59421527a31113406c97815c", "asset_id": "96361925776989336186111887920533578209326565663637092688733016597062311745569", "price": "0.006", "size": "136.51", "side": "BUY", "timestamp": "1768475479795", "received_at": "2026-01-15T12:11:19.913436"}}
{"event_type": "price_change", "event_ts": "2026-01-15T12:11:19.913436", "ingestion_ts": "2026-01-15T12:11:41.230171", "market_id": "0xcab7ba4a9133cfd407d7e73e5757e5abbace413b59421527a31113406c97815c", "raw": {"market": "0xcab7ba4a9133cfd407d7e73e5757e5abbace413b59421527a31113406c97815c", "asset_id": "20002636398944597965698652220992177552927816915094913583821579024925426590022", "price": "0.994", "size": "136.51", "side": "SELL", "timestamp": "1768475479795", "received_at": "2026-01-15T12:11:19.913436"}}
{"event_type": "price_change", "event_ts": "2026-01-15T12:11:20.101481", "ingestion_ts": "2026-01-15T12:11:41.230171", "market_id": "0x427bc4b40c09b3dcbc973747f0e4b079bed91b3e5a0aed5c36edd0f7591485f4", "raw": {"market": "0x427bc4b40c09b3dcbc973747f0e4b079bed91b3e5a0aed5c36edd0f7591485f4", "asset_id": "115669573443672055876643967408433138119481486650803218131873713375232186497057", "price": "0.002", "size": "63.15", "side": "BUY", "timestamp": "1768475479983", "received_at": "2026-01-15T12:11:20.101481"}}
{"event_type": "price_change", "event_ts": "2026-01-15T12:11:20.101481", "ingestion_ts": "2026-01-15T12:11:41.230171", "market_id": "0x427bc4b40c09b3dcbc973747f0e4b079bed91b3e5a0aed5c36edd0f7591485f4", "raw": {"market": "0x427bc4b40c09b3dcbc973747f0e4b079bed91b3e5a0aed5c36edd0f7591485f4", "asset_id": "86130975769502911188457673769190265049139877688522439001984850068234616395137", "price": "0.998", "size": "63.15", "side": "SELL", "timestamp": "1768475479983", "received_at": "2026-01-15T12:11:20.101481"}}
{"event_type": "price_change", "event_ts": "2026-01-15T12:11:20.426900", "ingestion_ts": "2026-01-15T12:11:41.230171", "market_id": "0x427bc4b40c09b3dcbc973747f0e4b079bed91b3e5a0aed5c36edd0f7591485f4", "raw": {"market": "0x427bc4b40c09b3dcbc973747f0e4b079bed91b3e5a0aed5c36edd0f7591485f4", "asset_id": "115669573443672055876643967408433138119481486650803218131873713375232186497057", "price": "0.002", "size": "72.33", "side": "BUY", "timestamp": "1768475480307", "received_at": "2026-01-15T12:11:20.426900"}}
{"event_type": "price_change", "event_ts": "2026-01-15T12:11:20.426900", "ingestion_ts": "2026-01-15T12:11:41.230171", "market_id": "0x427bc4b40c09b3dcbc973747f0e4b079bed91b3e5a0aed5c36edd0f7591485f4", "raw": {"market": "0x427bc4b40c09b3dcbc973747f0e4b079bed91b3e5a0aed5c36edd0f7591485f4", "asset_id": "86130975769502911188457673769190265049139877688522439001984850068234616395137", "price": "0.998", "size": "72.33", "side": "SELL", "timestamp": "1768475480307", "received_at": "2026-01-15T12:11:20.426900"}}
{"event_type": "price_change", "event_ts": "2026-01-15T12:11:20.958523", "ingestion_ts": "2026-01-15T12:11:41.230171", "market_id": "0x427bc4b40c09b3dcbc973747f0e4b079bed91b3e5a0aed5c36edd0f7591485f4", "raw": {"market": "0x427bc4b40c09b3dcbc973747f0e4b079bed91b3e5a0aed5c36edd0f7591485f4", "asset_id": "115669573443672055876643967408433138119481486650803218131873713375232186497057", "price": "0.164", "size": "7.96", "side": "SELL", "timestamp": "1768475480837", "received_at": "2026-01-15T12:11:20.958523"}}
{"event_type": "price_change", "event_ts": "2026-01-15T12:11:20.958523", "ingestion_ts": "2026-01-15T12:11:41.230171", "market_id": "0x427bc4b40c09b3dcbc973747f0e4b079bed91b3e5a0aed5c36edd0f7591485f4", "raw": {"market": "0x427bc4b40c09b3dcbc973747f0e4b079bed91b3e5a0aed5c36edd0f7591485f4", "asset_id": "86130975769502911188457673769190265049139877688522439001984850068234616395137", "price": "0.836", "size": "7.96", "side": "BUY", "timestamp": "1768475480837", "received_at": "2026-01-15T12:11:20.958523"}}
{"event_type": "price_change", "event_ts": "2026-01-15T12:11:21.183097", "ingestion_ts": "2026-01-15T12:11:41.230171", "market_id": "0x427bc4b40c09b3dcbc973747f0e4b079bed91b3e5a0aed5c36edd0f7591485f4", "raw": {"market": "0x427bc4b40c09b3dcbc973747f0e4b079bed91b3e5a0aed5c36edd0f7591485f4", "asset_id": "115669573443672055876643967408433138119481486650803218131873713375232186497057", "price": "0.164", "size": "15.92", "side": "SELL", "timestamp": "1768475481065", "received_at": "2026-01-15T12:11:21.183097"}}
{"event_type": "price_change", "event_ts": "2026-01-15T12:11:21.183097", "ingestion_ts": "2026-01-15T12:11:41.230171", "market_id": "0x427bc4b40c09b3dcbc973747f0e4b079bed91b3e5a0aed5c36edd0f7591485f4", "raw": {"market": "0x427bc4b40c09b3dcbc973747f0e4b079bed91b3e5a0aed5c36edd0f7591485f4", "asset_id": "86130975769502911188457673769190265049139877688522439001984850068234616395137", "price": "0.836", "size": "15.92", "side": "BUY", "timestamp": "1768475481065", "received_at": "2026-01-15T12:11:21.183097"}}
{"event_type": "price_change", "event_ts": "2026-01-15T12:11:22.801799", "ingestion_ts": "2026-01-15T12:11:41.230171", "market_id": "0xcab7ba4a9133cfd407d7e73e5757e5abbace413b59421527a31113406c97815c", "raw": {"market": "0xcab7ba4a9133cfd407d7e73e5757e5abbace413b59421527a31113406c97815c", "asset_id": "96361925776989336186111887920533578209326565663637092688733016597062311745569", "price": "0.006", "size": "127.41", "side": "BUY", "timestamp": "1768475482677", "received_at": "2026-01-15T12:11:22.801799"}}
{"event_type": "price_change", "event_ts": "2026-01-15T12:11:22.801799", "ingestion_ts": "2026-01-15T12:11:41.230171", "market_id": "0xcab7ba4a9133cfd407d7e73e5757e5abbace413b59421527a31113406c97815c", "raw": {"market": "0xcab7ba4a9133cfd407d7e73e5757e5abbace413b59421527a31113406c97815c", "asset_id": "20002636398944597965698652220992177552927816915094913583821579024925426590022", "price": "0.994", "size": "127.41", "side": "SELL", "timestamp": "1768475482677", "received_at": "2026-01-15T12:11:22.801799"}}
{"event_type": "price_change", "event_ts": "2026-01-15T12:11:22.801840", "ingestion_ts": "2026-01-15T12:11:41.230171", "market_id": "0xcab7ba4a9133cfd407d7e73e5757e5abbace413b59421527a31113406c97815c", "raw": {"market": "0xcab7ba4a9133cfd407d7e73e5757e5abbace413b59421527a31113406c97815c", "asset_id": "96361925776989336186111887920533578209326565663637092688733016597062311745569", "price": "0.009", "size": "812.25", "side": "BUY", "timestamp": "1768475482677", "received_at": "2026-01-15T12:11:22.801840"}}
{"event_type": "price_change", "event_ts": "2026-01-15T12:11:22.801840", "ingestion_ts": "2026-01-15T12:11:41.230171", "market_id": "0xcab7ba4a9133cfd407d7e73e5757e5abbace413b59421527a31113406c97815c", "raw": {"market": "0xcab7ba4a9133cfd407d7e73e5757e5abbace413b59421527a31113406c97815c", "asset_id": "20002636398944597965698652220992177552927816915094913583821579024925426590022", "price": "0.991", "size": "812.25", "side": "SELL", "timestamp": "1768475482677", "received_at": "2026-01-15T12:11:22.801840"}}
{"event_type": "price_change", "event_ts": "2026-01-15T12:11:22.901340", "ingestion_ts": "2026-01-15T12:11:41.230171", "market_id": "0xc0e6b917320a47228fb96e3b5ae0e5c93773a5ae2662ae4e1f37807cfe47ce98", "raw": {"market": "0xc0e6b917320a47228fb96e3b5ae0e5c93773a5ae2662ae4e1f37807cfe47ce98", "asset_id": "58656358377246279051017109359677190749228949103591068167284263961542487110215", "price": "0.158", "size": "0", "side": "SELL", "timestamp": "1768475482785", "received_at": "2026-01-15T12:11:22.901340"}}
{"event_type": "price_change", "event_ts": "2026-01-15T12:11:22.901340", "ingestion_ts": "2026-01-15T12:11:41.230171", "market_id": "0xc0e6b917320a47228fb96e3b5ae0e5c93773a5ae2662ae4e1f37807cfe47ce98", "raw": {"market": "0xc0e6b917320a47228fb96e3b5ae0e5c93773a5ae2662ae4e1f37807cfe47ce98", "asset_id": "81647294538046680798858716589766492074338758116170717123345952330712416337530", "price": "0.842", "size": "0", "side": "BUY", "timestamp": "1768475482785", "received_at": "2026-01-15T12:11:22.901340"}}
{"event_type": "price_change", "event_ts": "2026-01-15T12:11:23.369707", "ingestion_ts": "2026-01-15T12:11:41.230171", "market_id": "0xc0e6b917320a47228fb96e3b5ae0e5c93773a5ae2662ae4e1f37807cfe47ce98", "raw": {"market": "0xc0e6b917320a47228fb96e3b5ae0e5c93773a5ae2662ae4e1f37807cfe47ce98", "asset_id": "58656358377246279051017109359677190749228949103591068167284263961542487110215", "price": "0.157", "size": "431", "side": "SELL", "timestamp": "1768475483252", "received_at": "2026-01-15T12:11:23.369707"}}
{"event_type": "price_change", "event_ts": "2026-01-15T12:11:23.369707", "ingestion_ts": "2026-01-15T12:11:41.230171", "market_id": "0xc0e6b917320a47228fb96e3b5ae0e5c93773a5ae2662ae4e1f37807cfe47ce98", "raw": {"market": "0xc0e6b917320a47228fb96e3b5ae0e5c93773a5ae2662ae4e1f37807cfe47ce98", "asset_id": "81647294538046680798858716589766492074338758116170717123345952330712416337530", "price": "0.843", "size": "431", "side": "BUY", "timestamp": "1768475483252", "received_at": "2026-01-15T12:11:23.369707"}}
{"event_type": "price_change", "event_ts": "2026-01-15T12:11:23.396161", "ingestion_ts": "2026-01-15T12:11:41.230171", "market_id": "0xea644975be7b2ad32b536a94ae21b707ecb2f84290225b24e60ca46dd77903dd", "raw": {"market": "0xea644975be7b2ad32b536a94ae21b707ecb2f84290225b24e60ca46dd77903dd", "asset_id": "19255594762111702415265750364124818677094538461124581923455280001407159960455", "price": "0.854", "size": "0", "side": "BUY", "timestamp": "1768475483278", "received_at": "2026-01-15T12:11:23.396161"}}
{"event_type": "price_change", "event_ts": "2026-01-15T12:11:23.396161", "ingestion_ts": "2026-01-15T12:11:41.230171", "market_id": "0xea644975be7b2ad32b536a94ae21b707ecb2f84290225b24e60ca46dd77903dd", "raw": {"market": "0xea644975be7b2ad32b536a94ae21b707ecb2f84290225b24e60ca46dd77903dd", "asset_id": "110044455628775971785618539427229099821815416148768008176051068105157446559241", "price": "0.146", "size": "0", "side": "SELL", "timestamp": "1768475483278", "received_at": "2026-01-15T12:11:23.396161"}}
{"event_type": "price_change", "event_ts": "2026-01-15T12:11:23.396920", "ingestion_ts": "2026-01-15T12:11:41.230171", "market_id": "0x50e477f0b316a3d97d60486479657c63be0763834d0e2e8a30b1b86dc3c1c001", "raw": {"market": "0x50e477f0b316a3d97d60486479657c63be0763834d0e2e8a30b1b86dc3c1c001", "asset_id": "39981134260608444876865205057565852475343967395624370698967311821208058420507", "price": "0.854", "size": "0", "side": "BUY", "timestamp": "1768475483278", "received_at": "2026-01-15T12:11:23.396920"}}
{"event_type": "price_change", "event_ts": "2026-01-15T12:11:23.396920", "ingestion_ts": "2026-01-15T12:11:41.230171", "market_id": "0x50e477f0b316a3d97d60486479657c63be0763834d0e2e8a30b1b86dc3c1c001", "raw": {"market": "0x50e477f0b316a3d97d60486479657c63be0763834d0e2e8a30b1b86dc3c1c001", "asset_id": "60573178197991590327120832143415406583517170365625050489007297367895074266641", "price": "0.146", "size": "0", "side": "SELL", "timestamp": "1768475483278", "received_at": "2026-01-15T12:11:23.396920"}}
{"event_type": "price_change", "event_ts": "2026-01-15T12:11:23.397017", "ingestion_ts": "2026-01-15T12:11:41.230171", "market_id": "0xe68594f1350f5535532b24979b5b5c1948432cbfc0c363802c32a8f9ab4e6509", "raw": {"market": "0xe68594f1350f5535532b24979b5b5c1948432cbfc0c363802c32a8f9ab4e6509", "asset_id": "3074032031589250926591186368301243337494992039402397918135503567058257050088", "price": "0.854", "size": "0", "side": "BUY", "timestamp": "1768475483278", "received_at": "2026-01-15T12:11:23.397017"}}
{"event_type": "price_change", "event_ts": "2026-01-15T12:11:23.397017", "ingestion_ts": "2026-01-15T12:11:41.230171", "market_id": "0xe68594f1350f5535532b24979b5b5c1948432cbfc0c363802c32a8f9ab4e6509", "raw": {"market": "0xe68594f1350f5535532b24979b5b5c1948432cbfc0c363802c32a8f9ab4e6509", "asset_id": "47459180813047899567328389455747872955901265556145057896316155826890276004242", "price": "0.146", "size": "0", "side": "SELL", "timestamp": "1768475483278", "received_at": "2026-01-15T12:11:23.397017"}}
{"event_type": "price_change", "event_ts": "2026-01-15T12:11:23.413876", "ingestion_ts": "2026-01-15T12:11:41.230171", "market_id": "0xc0e6b917320a47228fb96e3b5ae0e5c93773a5ae2662ae4e1f37807cfe47ce98", "raw": {"market": "0xc0e6b917320a47228fb96e3b5ae0e5c93773a5ae2662ae4e1f37807cfe47ce98", "asset_id": "58656358377246279051017109359677190749228949103591068167284263961542487110215", "price": "0.001", "size": "439.8", "side": "BUY", "timestamp": "1768475483294", "received_at": "2026-01-15T12:11:23.413876"}}
{"event_type": "price_change", "event_ts": "2026-01-15T12:11:23.413876", "ingestion_ts": "2026-01-15T12:11:41.230171", "market_id": "0xc0e6b917320a47228fb96e3b5ae0e5c93773a5ae2662ae4e1f37807cfe47ce98", "raw": {"market": "0xc0e6b917320a47228fb96e3b5ae0e5c93773a5ae2662ae4e1f37807cfe47ce98", "asset_id": "81647294538046680798858716589766492074338758116170717123345952330712416337530", "price": "0.999", "size": "439.8", "side": "SELL", "timestamp": "1768475483294", "received_at": "2026-01-15T12:11:23.413876"}}
{"event_type": "price_change", "event_ts": "2026-01-15T12:11:23.414116", "ingestion_ts": "2026-01-15T12:11:41.230171", "market_id": "0xc0e6b917320a47228fb96e3b5ae0e5c93773a5ae2662ae4e1f37807cfe47ce98", "raw": {"market": "0xc0e6b917320a47228fb96e3b5ae0e5c93773a5ae2662ae4e1f37807cfe47ce98", "asset_id": "58656358377246279051017109359677190749228949103591068167284263961542487110215", "price": "0.002", "size": "3306.42", "side": "BUY", "timestamp": "1768475483294", "received_at": "2026-01-15T12:11:23.414116"}}
{"event_type": "price_change", "event_ts": "2026-01-15T12:11:23.414116", "ingestion_ts": "2026-01-15T12:11:41.230171", "market_id": "0xc0e6b917320a47228fb96e3b5ae0e5c93773a5ae2662ae4e1f37807cfe47ce98", "raw": {"market": "0xc0e6b917320a47228fb96e3b5ae0e5c93773a5ae2662ae4e1f37807cfe47ce98", "asset_id": "81647294538046680798858716589766492074338758116170717123345952330712416337530", "price": "0.998", "size": "3306.42", "side": "SELL", "timestamp": "1768475483294", "received_at": "2026-01-15T12:11:23.414116"}}
{"event_type": "price_change", "event_ts": "2026-01-15T12:11:23.414174", "ingestion_ts": "2026-01-15T12:11:41.230171", "market_id": "0xc0e6b917320a47228fb96e3b5ae0e5c93773a5ae2662ae4e1f37807cfe47ce98", "raw": {"market": "0xc0e6b917320a47228fb96e3b5ae0e5c93773a5ae2662ae4e1f37807cfe47ce98", "asset_id": "58656358377246279051017109359677190749228949103591068167284263961542487110215", "price": "0.003", "size": "415.26", "side": "BUY", "timestamp": "1768475483294", "received_at": "2026-01-15T12:11:23.414174"}}
{"event_type": "price_change", "event_ts": "2026-01-15T12:11:23.414174", "ingestion_ts": "2026-01-15T12:11:41.230171", "market_id": "0xc0e6b917320a47228fb96e3b5ae0e5c93773a5ae2662ae4e1f37807cfe47ce98", "raw": {"market": "0xc0e6b917320a47228fb96e3b5ae0e5c93773a5ae2662ae4e1f37807cfe47ce98", "asset_id": "81647294538046680798858716589766492074338758116170717123345952330712416337530", "price": "0.997", "size": "415.26", "side": "SELL", "timestamp": "1768475483294", "received_at": "2026-01-15T12:11:23.414174"}}
{"event_type": "price_change", "event_ts": "2026-01-15T12:11:23.424274", "ingestion_ts": "2026-01-15T12:11:41.230171", "market_id": "0xea644975be7b2ad32b536a94ae21b707ecb2f84290225b24e60ca46dd77903dd", "raw": {"market": "0xea644975be7b2ad32b536a94ae21b707ecb2f84290225b24e60ca46dd77903dd", "asset_id": "19255594762111702415265750364124818677094538461124581923455280001407159960455", "price": "0.854", "size": "10", "side": "BUY", "timestamp": "1768475483307", "received_at": "2026-01-15T12:11:23.424274"}}
{"event_type": "price_change", "event_ts": "2026-01-15T12:11:23.424274", "ingestion_ts": "2026-01-15T12:11:41.230171", "market_id": "0xea644975be7b2ad32b536a94ae21b707ecb2f84290225b24e60ca46dd77903dd", "raw": {"market": "0xea644975be7b2ad32b536a94ae21b707ecb2f84290225b24e60ca46dd77903dd", "asset_id": "110044455628775971785618539427229099821815416148768008176051068105157446559241", "price": "0.146", "size": "10", "side": "SELL", "timestamp": "1768475483307", "received_at": "2026-01-15T12:11:23.424274"}}
{"event_type": "price_change", "event_ts": "2026-01-15T12:11:23.426070", "ingestion_ts": "2026-01-15T12:11:41.230171", "market_id": "0x50e477f0b316a3d97d60486479657c63be0763834d0e2e8a30b1b86dc3c1c001", "raw": {"market": "0x50e477f0b316a3d97d60486479657c63be0763834d0e2e8a30b1b86dc3c1c001", "asset_id": "39981134260608444876865205057565852475343967395624370698967311821208058420507", "price": "0.854", "size": "10", "side": "BUY", "timestamp": "1768475483307", "received_at": "2026-01-15T12:11:23.426070"}}
{"event_type": "price_change", "event_ts": "2026-01-15T12:11:23.426070", "ingestion_ts": "2026-01-15T12:11:41.230171", "market_id": "0x50e477f0b316a3d97d60486479657c63be0763834d0e2e8a30b1b86dc3c1c001", "raw": {"market": "0x50e477f0b316a3d97d60486479657c63be0763834d0e2e8a30b1b86dc3c1c001", "asset_id": "60573178197991590327120832143415406583517170365625050489007297367895074266641", "price": "0.146", "size": "10", "side": "SELL", "timestamp": "1768475483307", "received_at": "2026-01-15T12:11:23.426070"}}
{"event_type": "price_change", "event_ts": "2026-01-15T12:11:23.426190", "ingestion_ts": "2026-01-15T12:11:41.230171", "market_id": "0xe68594f1350f5535532b24979b5b5c1948432cbfc0c363802c32a8f9ab4e6509", "raw": {"market": "0xe68594f1350f5535532b24979b5b5c1948432cbfc0c363802c32a8f9ab4e6509", "asset_id": "3074032031589250926591186368301243337494992039402397918135503567058257050088", "price": "0.854", "size": "10", "side": "BUY", "timestamp": "1768475483307", "received_at": "2026-01-15T12:11:23.426190"}}
{"event_type": "price_change", "event_ts": "2026-01-15T12:11:23.426190", "ingestion_ts": "2026-01-15T12:11:41.230171", "market_id": "0xe68594f1350f5535532b24979b5b5c1948432cbfc0c363802c32a8f9ab4e6509", "raw": {"market": "0xe68594f1350f5535532b24979b5b5c1948432cbfc0c363802c32a8f9ab4e6509", "asset_id": "47459180813047899567328389455747872955901265556145057896316155826890276004242", "price": "0.146", "size": "10", "side": "SELL", "timestamp": "1768475483307", "received_at": "2026-01-15T12:11:23.426190"}}
{"event_type": "price_change", "event_ts": "2026-01-15T12:11:23.497682", "ingestion_ts": "2026-01-15T12:11:41.230171", "market_id": "0xcab7ba4a9133cfd407d7e73e5757e5abbace413b59421527a31113406c97815c", "raw": {"market": "0xcab7ba4a9133cfd407d7e73e5757e5abbace413b59421527a31113406c97815c", "asset_id": "96361925776989336186111887920533578209326565663637092688733016597062311745569", "price": "0.009", "size": "818.33", "side": "BUY", "timestamp": "1768475483378", "received_at": "2026-01-15T12:11:23.497682"}}
{"event_type": "price_change", "event_ts": "2026-01-15T12:11:23.497682", "ingestion_ts": "2026-01-15T12:11:41.230171", "market_id": "0xcab7ba4a9133cfd407d7e73e5757e5abbace413b59421527a31113406c97815c", "raw": {"market": "0xcab7ba4a9133cfd407d7e73e5757e5abbace413b59421527a31113406c97815c", "asset_id": "20002636398944597965698652220992177552927816915094913583821579024925426590022", "price": "0.991", "size": "818.33", "side": "SELL", "timestamp": "1768475483378", "received_at": "2026-01-15T12:11:23.497682"}}
{"event_type": "price_change", "event_ts": "2026-01-15T12:11:23.497858", "ingestion_ts": "2026-01-15T12:11:41.230171", "market_id": "0xcab7ba4a9133cfd407d7e73e5757e5abbace413b59421527a31113406c97815c", "raw": {"market": "0xcab7ba4a9133cfd407d7e73e5757e5abbace413b59421527a31113406c97815c", "asset_id": "96361925776989336186111887920533578209326565663637092688733016597062311745569", "price": "0.006", "size": "136.51", "side": "BUY", "timestamp": "1768475483379", "received_at": "2026-01-15T12:11:23.497858"}}
{"event_type": "price_change", "event_ts": "2026-01-15T12:11:23.497858", "ingestion_ts": "2026-01-15T12:11:41.230171", "market_id": "0xcab7ba4a9133cfd407d7e73e5757e5abbace413b59421527a31113406c97815c", "raw": {"market": "0xcab7ba4a9133cfd407d7e73e5757e5abbace413b59421527a31113406c97815c", "asset_id": "20002636398944597965698652220992177552927816915094913583821579024925426590022", "price": "0.994", "size": "136.51", "side": "SELL", "timestamp": "1768475483379", "received_at": "2026-01-15T12:11:23.497858"}}
{"event_type": "price_change", "event_ts": "2026-01-15T12:11:23.804680", "ingestion_ts": "2026-01-15T12:11:41.230171", "market_id": "0xc0e6b917320a47228fb96e3b5ae0e5c93773a5ae2662ae4e1f37807cfe47ce98", "raw": {"market": "0xc0e6b917320a47228fb96e3b5ae0e5c93773a5ae2662ae4e1f37807cfe47ce98", "asset_id": "58656358377246279051017109359677190749228949103591068167284263961542487110215", "price": "0.004", "size": "8.51", "side": "BUY", "timestamp": "1768475483686", "received_at": "2026-01-15T12:11:23.804680"}}
{"event_type": "price_change", "event_ts": "2026-01-15T12:11:23.804680", "ingestion_ts": "2026-01-15T12:11:41.230171", "market_id": "0xc0e6b917320a47228fb96e3b5ae0e5c93773a5ae2662ae4e1f37807cfe47ce98", "raw": {"market": "0xc0e6b917320a47228fb96e3b5ae0e5c93773a5ae2662ae4e1f37807cfe47ce98", "asset_id": "81647294538046680798858716589766492074338758116170717123345952330712416337530", "price": "0.996", "size": "8.51", "side": "SELL", "timestamp": "1768475483686", "received_at": "2026-01-15T12:11:23.804680"}}
{"event_type": "price_change", "event_ts": "2026-01-15T12:11:23.804880", "ingestion_ts": "2026-01-15T12:11:41.230171", "market_id": "0xc0e6b917320a47228fb96e3b5ae0e5c93773a5ae2662ae4e1f37807cfe47ce98", "raw": {"market": "0xc0e6b917320a47228fb96e3b5ae0e5c93773a5ae2662ae4e1f37807cfe47ce98", "asset_id": "58656358377246279051017109359677190749228949103591068167284263961542487110215", "price": "0.004", "size": "17.02", "side": "BUY", "timestamp": "1768475483687", "received_at": "2026-01-15T12:11:23.804880"}}
{"event_type": "price_change", "event_ts": "2026-01-15T12:11:23.804880", "ingestion_ts": "2026-01-15T12:11:41.230171", "market_id": "0xc0e6b917320a47228fb96e3b5ae0e5c93773a5ae2662ae4e1f37807cfe47ce98", "raw": {"market": "0xc0e6b917320a47228fb96e3b5ae0e5c93773a5ae2662ae4e1f37807cfe47ce98", "asset_id": "81647294538046680798858716589766492074338758116170717123345952330712416337530", "price": "0.996", "size": "17.02", "side": "SELL", "timestamp": "1768475483687", "received_at": "2026-01-15T12:11:23.804880"}}
{"event_type": "price_change", "event_ts": "2026-01-15T12:11:24.156665", "ingestion_ts": "2026-01-15T12:11:41.230171", "market_id": "0x427bc4b40c09b3dcbc973747f0e4b079bed91b3e5a0aed5c36edd0f7591485f4", "raw": {"market": "0x427bc4b40c09b3dcbc973747f0e4b079bed91b3e5a0aed5c36edd0f7591485f4", "asset_id": "115669573443672055876643967408433138119481486650803218131873713375232186497057", "price": "0.002", "size": "63.15", "side": "BUY", "timestamp": "1768475484038", "received_at": "2026-01-15T12:11:24.156665"}}
{"event_type": "price_change", "event_ts": "2026-01-15T12:11:24.156665", "ingestion_ts": "2026-01-15T12:11:41.230171", "market_id": "0x427bc4b40c09b3dcbc973747f0e4b079bed91b3e5a0aed5c36edd0f7591485f4", "raw": {"market": "0x427bc4b40c09b3dcbc973747f0e4b079bed91b3e5a0aed5c36edd0f7591485f4", "asset_id": "86130975769502911188457673769190265049139877688522439001984850068234616395137", "price": "0.998", "size": "63.15", "side": "SELL", "timestamp": "1768475484038", "received_at": "2026-01-15T12:11:24.156665"}}
{"event_type": "price_change", "event_ts": "2026-01-15T12:11:24.241199", "ingestion_ts": "2026-01-15T12:11:41.230171", "market_id": "0xc0e6b917320a47228fb96e3b5ae0e5c93773a5ae2662ae4e1f37807cfe47ce98", "raw": {"market": "0xc0e6b917320a47228fb96e3b5ae0e5c93773a5ae2662ae4e1f37807cfe47ce98", "asset_id": "58656358377246279051017109359677190749228949103591068167284263961542487110215", "price": "0.157", "size": "426", "side": "SELL", "timestamp": "1768475484123", "received_at": "2026-01-15T12:11:24.241199"}}
{"event_type": "price_change", "event_ts": "2026-01-15T12:11:24.241199", "ingestion_ts": "2026-01-15T12:11:41.230171", "market_id": "0xc0e6b917320a47228fb96e3b5ae0e5c93773a5ae2662ae4e1f37807cfe47ce98", "raw": {"market": "0xc0e6b917320a47228fb96e3b5ae0e5c93773a5ae2662ae4e1f37807cfe47ce98", "asset_id": "81647294538046680798858716589766492074338758116170717123345952330712416337530", "price": "0.843", "size": "426", "side": "BUY", "timestamp": "1768475484123", "received_at": "2026-01-15T12:11:24.241199"}}
{"event_type": "price_change", "event_ts": "2026-01-15T12:11:24.400108", "ingestion_ts": "2026-01-15T12:11:41.230171", "market_id": "0x427bc4b40c09b3dcbc973747f0e4b079bed91b3e5a0aed5c36edd0f7591485f4", "raw": {"market": "0x427bc4b40c09b3dcbc973747f0e4b079bed91b3e5a0aed5c36edd0f7591485f4", "asset_id": "115669573443672055876643967408433138119481486650803218131873713375232186497057", "price": "0.002", "size": "72.33", "side": "BUY", "timestamp": "1768475484275", "received_at": "2026-01-15T12:11:24.400108"}}
{"event_type": "price_change", "event_ts": "2026-01-15T12:11:24.400108", "ingestion_ts": "2026-01-15T12:11:41.230171", "market_id": "0x427bc4b40c09b3dcbc973747f0e4b079bed91b3e5a0aed5c36edd0f7591485f4", "raw": {"market": "0x427bc4b40c09b3dcbc973747f0e4b079bed91b3e5a0aed5c36edd0f7591485f4", "asset_id": "86130975769502911188457673769190265049139877688522439001984850068234616395137", "price": "0.998", "size": "72.33", "side": "SELL", "timestamp": "1768475484275", "received_at": "2026-01-15T12:11:24.400108"}}
{"event_type": "price_change", "event_ts": "2026-01-15T12:11:24.583778", "ingestion_ts": "2026-01-15T12:11:41.230171", "market_id": "0x427bc4b40c09b3dcbc973747f0e4b079bed91b3e5a0aed5c36edd0f7591485f4", "raw": {"market": "0x427bc4b40c09b3dcbc973747f0e4b079bed91b3e5a0aed5c36edd0f7591485f4", "asset_id": "115669573443672055876643967408433138119481486650803218131873713375232186497057", "price": "0.164", "size": "7.96", "side": "SELL", "timestamp": "1768475484466", "received_at": "2026-01-15T12:11:24.583778"}}
{"event_type": "price_change", "event_ts": "2026-01-15T12:11:24.583778", "ingestion_ts": "2026-01-15T12:11:41.230171", "market_id": "0x427bc4b40c09b3dcbc973747f0e4b079bed91b3e5a0aed5c36edd0f7591485f4", "raw": {"market": "0x427bc4b40c09b3dcbc973747f0e4b079bed91b3e5a0aed5c36edd0f7591485f4", "asset_id": "86130975769502911188457673769190265049139877688522439001984850068234616395137", "price": "0.836", "size": "7.96", "side": "BUY", "timestamp": "1768475484466", "received_at": "2026-01-15T12:11:24.583778"}}
{"event_type": "price_change", "event_ts": "2026-01-15T12:11:24.904419", "ingestion_ts": "2026-01-15T12:11:41.230171", "market_id": "0x427bc4b40c09b3dcbc973747f0e4b079bed91b3e5a0aed5c36edd0f7591485f4", "raw": {"market": "0x427bc4b40c09b3dcbc973747f0e4b079bed91b3e5a0aed5c36edd0f7591485f4", "asset_id": "115669573443672055876643967408433138119481486650803218131873713375232186497057", "price": "0.164", "size": "15.92", "side": "SELL", "timestamp": "1768475484785", "received_at": "2026-01-15T12:11:24.904419"}}
{"event_type": "price_change", "event_ts": "2026-01-15T12:11:24.904419", "ingestion_ts": "2026-01-15T12:11:41.230171", "market_id": "0x427bc4b40c09b3dcbc973747f0e4b079bed91b3e5a0aed5c36edd0f7591485f4", "raw": {"market": "0x427bc4b40c09b3dcbc973747f0e4b079bed91b3e5a0aed5c36edd0f7591485f4", "asset_id": "86130975769502911188457673769190265049139877688522439001984850068234616395137", "price": "0.836", "size": "15.92", "side": "BUY", "timestamp": "1768475484785", "received_at": "2026-01-15T12:11:24.904419"}}
{"event_type": "price_change", "event_ts": "2026-01-15T12:11:24.932212", "ingestion_ts": "2026-01-15T12:11:41.230171", "market_id": "0xc0e6b917320a47228fb96e3b5ae0e5c93773a5ae2662ae4e1f37807cfe47ce98", "raw": {"market": "0xc0e6b917320a47228fb96e3b5ae0e5c93773a5ae2662ae4e1f37807cfe47ce98", "asset_id": "58656358377246279051017109359677190749228949103591068167284263961542487110215", "price": "0.156", "size": "5", "side": "SELL", "timestamp": "1768475484812", "received_at": "2026-01-15T12:11:24.932212"}}
{"event_type": "price_change", "event_ts": "2026-01-15T12:11:24.932212", "ingestion_ts": "2026-01-15T12:11:41.230171", "market_id": "0xc0e6b917320a47228fb96e3b5ae0e5c93773a5ae2662ae4e1f37807cfe47ce98", "raw": {"market": "0xc0e6b917320a47228fb96e3b5ae0e5c93773a5ae2662ae4e1f37807cfe47ce98", "asset_id": "81647294538046680798858716589766492074338758116170717123345952330712416337530", "price": "0.844", "size": "5", "side": "BUY", "timestamp": "1768475484812", "received_at": "2026-01-15T12:11:24.932212"}}
{"event_type": "price_change", "event_ts": "2026-01-15T12:11:25.663065", "ingestion_ts": "2026-01-15T12:11:41.230171", "market_id": "0xcab7ba4a9133cfd407d7e73e5757e5abbace413b59421527a31113406c97815c", "raw": {"market": "0xcab7ba4a9133cfd407d7e73e5757e5abbace413b59421527a31113406c97815c", "asset_id": "96361925776989336186111887920533578209326565663637092688733016597062311745569", "price": "0.006", "size": "127.41", "side": "BUY", "timestamp": "1768475485540", "received_at": "2026-01-15T12:11:25.663065"}}
{"event_type": "price_change", "event_ts": "2026-01-15T12:11:25.663065", "ingestion_ts": "2026-01-15T12:11:41.230171", "market_id": "0xcab7ba4a9133cfd407d7e73e5757e5abbace413b59421527a31113406c97815c", "raw": {"market": "0xcab7ba4a9133cfd407d7e73e5757e5abbace413b59421527a31113406c97815c", "asset_id": "20002636398944597965698652220992177552927816915094913583821579024925426590022", "price": "0.994", "size": "127.41", "side": "SELL", "timestamp": "1768475485540", "received_at": "2026-01-15T12:11:25.663065"}}
{"event_type": "price_change", "event_ts": "2026-01-15T12:11:25.663101", "ingestion_ts": "2026-01-15T12:11:41.230171", "market_id": "0xcab7ba4a9133cfd407d7e73e5757e5abbace413b59421527a31113406c97815c", "raw": {"market": "0xcab7ba4a9133cfd407d7e73e5757e5abbace413b59421527a31113406c97815c", "asset_id": "96361925776989336186111887920533578209326565663637092688733016597062311745569", "price": "0.009", "size": "812.25", "side": "BUY", "timestamp": "1768475485540", "received_at": "2026-01-15T12:11:25.663101"}}
{"event_type": "price_change", "event_ts": "2026-01-15T12:11:25.663101", "ingestion_ts": "2026-01-15T12:11:41.230171", "market_id": "0xcab7ba4a9133cfd407d7e73e5757e5abbace413b59421527a31113406c97815c", "raw": {"market": "0xcab7ba4a9133cfd407d7e73e5757e5abbace413b59421527a31113406c97815c", "asset_id": "20002636398944597965698652220992177552927816915094913583821579024925426590022", "price": "0.991", "size": "812.25", "side": "SELL", "timestamp": "1768475485540", "received_at": "2026-01-15T12:11:25.663101"}}
{"event_type": "price_change", "event_ts": "2026-01-15T12:11:26.062766", "ingestion_ts": "2026-01-15T12:11:41.230171", "market_id": "0xcab7ba4a9133cfd407d7e73e5757e5abbace413b59421527a31113406c97815c", "raw": {"market": "0xcab7ba4a9133cfd407d7e73e5757e5abbace413b59421527a31113406c97815c", "asset_id": "96361925776989336186111887920533578209326565663637092688733016597062311745569", "price": "0.006", "size": "136.51", "side": "BUY", "timestamp": "1768475485940", "received_at": "2026-01-15T12:11:26.062766"}}
{"event_type": "price_change", "event_ts": "2026-01-15T12:11:26.062766", "ingestion_ts": "2026-01-15T12:11:41.230171", "market_id": "0xcab7ba4a9133cfd407d7e73e5757e5abbace413b59421527a31113406c97815c", "raw": {"market": "0xcab7ba4a9133cfd407d7e73e5757e5abbace413b59421527a31113406c97815c", "asset_id": "20002636398944597965698652220992177552927816915094913583821579024925426590022", "price": "0.994", "size": "136.51", "side": "SELL", "timestamp": "1768475485940", "received_at": "2026-01-15T12:11:26.062766"}}
{"event_type": "price_change", "event_ts": "2026-01-15T12:11:26.063860", "ingestion_ts": "2026-01-15T12:11:41.230171", "market_id": "0xcab7ba4a9133cfd407d7e73e5757e5abbace413b59421527a31113406c97815c", "raw": {"market": "0xcab7ba4a9133cfd407d7e73e5757e5abbace413b59421527a31113406c97815c", "asset_id": "96361925776989336186111887920533578209326565663637092688733016597062311745569", "price": "0.009", "size": "818.33", "side": "BUY", "timestamp": "1768475485941", "received_at": "2026-01-15T12:11:26.063860"}}
{"event_type": "price_change", "event_ts": "2026-01-15T12:11:26.063860", "ingestion_ts": "2026-01-15T12:11:41.230171", "market_id": "0xcab7ba4a9133cfd407d7e73e5757e5abbace413b59421527a31113406c97815c", "raw": {"market": "0xcab7ba4a9133cfd407d7e73e5757e5abbace413b59421527a31113406c97815c", "asset_id": "20002636398944597965698652220992177552927816915094913583821579024925426590022", "price": "0.991", "size": "818.33", "side": "SELL", "timestamp": "1768475485941", "received_at": "2026-01-15T12:11:26.063860"}}
{"event_type": "price_change", "event_ts": "2026-01-15T12:11:26.379717", "ingestion_ts": "2026-01-15T12:11:41.230171", "market_id": "0xe68594f1350f5535532b24979b5b5c1948432cbfc0c363802c32a8f9ab4e6509", "raw": {"market": "0xe68594f1350f5535532b24979b5b5c1948432cbfc0c363802c32a8f9ab4e6509", "asset_id": "3074032031589250926591186368301243337494992039402397918135503567058257050088", "price": "0.854", "size": "0", "side": "BUY", "timestamp": "1768475486262", "received_at": "2026-01-15T12:11:26.379717"}}
{"event_type": "price_change", "event_ts": "2026-01-15T12:11:26.379717", "ingestion_ts": "2026-01-15T12:11:41.230171", "market_id": "0xe68594f1350f5535532b24979b5b5c1948432cbfc0c363802c32a8f9ab4e6509", "raw": {"market": "0xe68594f1350f5535532b24979b5b5c1948432cbfc0c363802c32a8f9ab4e6509", "asset_id": "47459180813047899567328389455747872955901265556145057896316155826890276004242", "price": "0.146", "size": "0", "side": "SELL", "timestamp": "1768475486262", "received_at": "2026-01-15T12:11:26.379717"}}
{"event_type": "price_change", "event_ts": "2026-01-15T12:11:26.379875", "ingestion_ts": "2026-01-15T12:11:41.230171", "market_id": "0xea644975be7b2ad32b536a94ae21b707ecb2f84290225b24e60ca46dd77903dd", "raw": {"market": "0xea644975be7b2ad32b536a94ae21b707ecb2f84290225b24e60ca46dd77903dd", "asset_id": "19255594762111702415265750364124818677094538461124581923455280001407159960455", "price": "0.854", "size": "0", "side": "BUY", "timestamp": "1768475486262", "received_at": "2026-01-15T12:11:26.379875"}}
{"event_type": "price_change", "event_ts": "2026-01-15T12:11:26.379875", "ingestion_ts": "2026-01-15T12:11:41.230171", "market_id": "0xea644975be7b2ad32b536a94ae21b707ecb2f84290225b24e60ca46dd77903dd", "raw": {"market": "0xea644975be7b2ad32b536a94ae21b707ecb2f84290225b24e60ca46dd77903dd", "asset_id": "110044455628775971785618539427229099821815416148768008176051068105157446559241", "price": "0.146", "size": "0", "side": "SELL", "timestamp": "1768475486262", "received_at": "2026-01-15T12:11:26.379875"}}
{"event_type": "price_change", "event_ts": "2026-01-15T12:11:26.379925", "ingestion_ts": "2026-01-15T12:11:41.230171", "market_id": "0x50e477f0b316a3d97d60486479657c63be0763834d0e2e8a30b1b86dc3c1c001", "raw": {"market": "0x50e477f0b316a3d97d60486479657c63be0763834d0e2e8a30b1b86dc3c1c001", "asset_id": "39981134260608444876865205057565852475343967395624370698967311821208058420507", "price": "0.854", "size": "0", "side": "BUY", "timestamp": "1768475486262", "received_at": "2026-01-15T12:11:26.379925"}}
{"event_type": "price_change", "event_ts": "2026-01-15T12:11:26.379925", "ingestion_ts": "2026-01-15T12:11:41.230171", "market_id": "0x50e477f0b316a3d97d60486479657c63be0763834d0e2e8a30b1b86dc3c1c001", "raw": {"market": "0x50e477f0b316a3d97d60486479657c63be0763834d0e2e8a30b1b86dc3c1c001", "asset_id": "60573178197991590327120832143415406583517170365625050489007297367895074266641", "price": "0.146", "size": "0", "side": "SELL", "timestamp": "1768475486262", "received_at": "2026-01-15T12:11:26.379925"}}
{"event_type": "price_change", "event_ts": "2026-01-15T12:11:27.379433", "ingestion_ts": "2026-01-15T12:11:41.230171", "market_id": "0xe68594f1350f5535532b24979b5b5c1948432cbfc0c363802c32a8f9ab4e6509", "raw": {"market": "0xe68594f1350f5535532b24979b5b5c1948432cbfc0c363802c32a8f9ab4e6509", "asset_id": "3074032031589250926591186368301243337494992039402397918135503567058257050088", "price": "0.854", "size": "5", "side": "BUY", "timestamp": "1768475487262", "received_at": "2026-01-15T12:11:27.379433"}}
{"event_type": "price_change", "event_ts": "2026-01-15T12:11:27.379433", "ingestion_ts": "2026-01-15T12:11:41.230171", "market_id": "0xe68594f1350f5535532b24979b5b5c1948432cbfc0c363802c32a8f9ab4e6509", "raw": {"market": "0xe68594f1350f5535532b24979b5b5c1948432cbfc0c363802c32a8f9ab4e6509", "asset_id": "47459180813047899567328389455747872955901265556145057896316155826890276004242", "price": "0.146", "size": "5", "side": "SELL", "timestamp": "1768475487262", "received_at": "2026-01-15T12:11:27.379433"}}
{"event_type": "price_change", "event_ts": "2026-01-15T12:11:27.382959", "ingestion_ts": "2026-01-15T12:11:41.230171", "market_id": "0x50e477f0b316a3d97d60486479657c63be0763834d0e2e8a30b1b86dc3c1c001", "raw": {"market": "0x50e477f0b316a3d97d60486479657c63be0763834d0e2e8a30b1b86dc3c1c001", "asset_id": "39981134260608444876865205057565852475343967395624370698967311821208058420507", "price": "0.854", "size": "5", "side": "BUY", "timestamp": "1768475487262", "received_at": "2026-01-15T12:11:27.382959"}}
{"event_type": "price_change", "event_ts": "2026-01-15T12:11:27.382959", "ingestion_ts": "2026-01-15T12:11:41.230171", "market_id": "0x50e477f0b316a3d97d60486479657c63be0763834d0e2e8a30b1b86dc3c1c001", "raw": {"market": "0x50e477f0b316a3d97d60486479657c63be0763834d0e2e8a30b1b86dc3c1c001", "asset_id": "60573178197991590327120832143415406583517170365625050489007297367895074266641", "price": "0.146", "size": "5", "side": "SELL", "timestamp": "1768475487262", "received_at": "2026-01-15T12:11:27.382959"}}
{"event_type": "price_change", "event_ts": "2026-01-15T12:11:27.382979", "ingestion_ts": "2026-01-15T12:11:41.230171", "market_id": "0xea644975be7b2ad32b536a94ae21b707ecb2f84290225b24e60ca46dd77903dd", "raw": {"market": "0xea644975be7b2ad32b536a94ae21b707ecb2f84290225b24e60ca46dd77903dd", "asset_id": "19255594762111702415265750364124818677094538461124581923455280001407159960455", "price": "0.856", "size": "5", "side": "BUY", "timestamp": "1768475487262", "received_at": "2026-01-15T12:11:27.382979"}}
{"event_type": "price_change", "event_ts": "2026-01-15T12:11:27.382979", "ingestion_ts": "2026-01-15T12:11:41.230171", "market_id": "0xea644975be7b2ad32b536a94ae21b707ecb2f84290225b24e60ca46dd77903dd", "raw": {"market": "0xea644975be7b2ad32b536a94ae21b707ecb2f84290225b24e60ca46dd77903dd", "asset_id": "110044455628775971785618539427229099821815416148768008176051068105157446559241", "price": "0.144", "size": "5", "side": "SELL", "timestamp": "1768475487262", "received_at": "2026-01-15T12:11:27.382979"}}
{"event_type": "price_change", "event_ts": "2026-01-15T12:11:27.458957", "ingestion_ts": "2026-01-15T12:11:41.230171", "market_id": "0xcab7ba4a9133cfd407d7e73e5757e5abbace413b59421527a31113406c97815c", "raw": {"market": "0xcab7ba4a9133cfd407d7e73e5757e5abbace413b59421527a31113406c97815c", "asset_id": "96361925776989336186111887920533578209326565663637092688733016597062311745569", "price": "0.006", "size": "127.41", "side": "BUY", "timestamp": "1768475487338", "received_at": "2026-01-15T12:11:27.458957"}}
{"event_type": "price_change", "event_ts": "2026-01-15T12:11:27.458957", "ingestion_ts": "2026-01-15T12:11:41.230171", "market_id": "0xcab7ba4a9133cfd407d7e73e5757e5abbace413b59421527a31113406c97815c", "raw": {"market": "0xcab7ba4a9133cfd407d7e73e5757e5abbace413b59421527a31113406c97815c", "asset_id": "20002636398944597965698652220992177552927816915094913583821579024925426590022", "price": "0.994", "size": "127.41", "side": "SELL", "timestamp": "1768475487338", "received_at": "2026-01-15T12:11:27.458957"}}
{"event_type": "price_change", "event_ts": "2026-01-15T12:11:27.459059", "ingestion_ts": "2026-01-15T12:11:41.230171", "market_id": "0xcab7ba4a9133cfd407d7e73e5757e5abbace413b59421527a31113406c97815c", "raw": {"market": "0xcab7ba4a9133cfd407d7e73e5757e5abbace413b59421527a31113406c97815c", "asset_id": "96361925776989336186111887920533578209326565663637092688733016597062311745569", "price": "0.009", "size": "812.25", "side": "BUY", "timestamp": "1768475487338", "received_at": "2026-01-15T12:11:27.459059"}}
{"event_type": "price_change", "event_ts": "2026-01-15T12:11:27.459059", "ingestion_ts": "2026-01-15T12:11:41.230171", "market_id": "0xcab7ba4a9133cfd407d7e73e5757e5abbace413b59421527a31113406c97815c", "raw": {"market": "0xcab7ba4a9133cfd407d7e73e5757e5abbace413b59421527a31113406c97815c", "asset_id": "20002636398944597965698652220992177552927816915094913583821579024925426590022", "price": "0.991", "size": "812.25", "side": "SELL", "timestamp": "1768475487338", "received_at": "2026-01-15T12:11:27.459059"}}
{"event_type": "price_change", "event_ts": "2026-01-15T12:11:27.908113", "ingestion_ts": "2026-01-15T12:11:41.230171", "market_id": "0xc0e6b917320a47228fb96e3b5ae0e5c93773a5ae2662ae4e1f37807cfe47ce98", "raw": {"market": "0xc0e6b917320a47228fb96e3b5ae0e5c93773a5ae2662ae4e1f37807cfe47ce98", "asset_id": "58656358377246279051017109359677190749228949103591068167284263961542487110215", "price": "0.004", "size": "8.51", "side": "BUY", "timestamp": "1768475487790", "received_at": "2026-01-15T12:11:27.908113"}}
{"event_type": "price_change", "event_ts": "2026-01-15T12:11:27.908113", "ingestion_ts": "2026-01-15T12:11:41.230171", "market_id": "0xc0e6b917320a47228fb96e3b5ae0e5c93773a5ae2662ae4e1f37807cfe47ce98", "raw": {"market": "0xc0e6b917320a47228fb96e3b5ae0e5c93773a5ae2662ae4e1f37807cfe47ce98", "asset_id": "81647294538046680798858716589766492074338758116170717123345952330712416337530", "price": "0.996", "size": "8.51", "side": "SELL", "timestamp": "1768475487790", "received_at": "2026-01-15T12:11:27.908113"}}
{"event_type": "price_change", "event_ts": "2026-01-15T12:11:27.930487", "ingestion_ts": "2026-01-15T12:11:41.230171", "market_id": "0xcab7ba4a9133cfd407d7e73e5757e5abbace413b59421527a31113406c97815c", "raw": {"market": "0xcab7ba4a9133cfd407d7e73e5757e5abbace413b59421527a31113406c97815c", "asset_id": "96361925776989336186111887920533578209326565663637092688733016597062311745569", "price": "0.009", "size": "818.33", "side": "BUY", "timestamp": "1768475487801", "received_at": "2026-01-15T12:11:27.930487"}}
{"event_type": "price_change", "event_ts": "2026-01-15T12:11:27.930487", "ingestion_ts": "2026-01-15T12:11:41.230171", "market_id": "0xcab7ba4a9133cfd407d7e73e5757e5abbace413b59421527a31113406c97815c", "raw": {"market": "0xcab7ba4a9133cfd407d7e73e5757e5abbace413b59421527a31113406c97815c", "asset_id": "20002636398944597965698652220992177552927816915094913583821579024925426590022", "price": "0.991", "size": "818.33", "side": "SELL", "timestamp": "1768475487801", "received_at": "2026-01-15T12:11:27.930487"}}
{"event_type": "price_change", "event_ts": "2026-01-15T12:11:27.930577", "ingestion_ts": "2026-01-15T12:11:41.230171", "market_id": "0xcab7ba4a9133cfd407d7e73e5757e5abbace413b59421527a31113406c97815c", "raw": {"market": "0xcab7ba4a9133cfd407d7e73e5757e5abbace413b59421527a31113406c97815c", "asset_id": "96361925776989336186111887920533578209326565663637092688733016597062311745569", "price": "0.006", "size": "136.51", "side": "BUY", "timestamp": "1768475487802", "received_at": "2026-01-15T12:11:27.930577"}}
{"event_type": "price_change", "event_ts": "2026-01-15T12:11:27.930577", "ingestion_ts": "2026-01-15T12:11:41.230171", "market_id": "0xcab7ba4a9133cfd407d7e73e5757e5abbace413b59421527a31113406c97815c", "raw": {"market": "0xcab7ba4a9133cfd407d7e73e5757e5abbace413b59421527a31113406c97815c", "asset_id": "20002636398944597965698652220992177552927816915094913583821579024925426590022", "price": "0.994", "size": "136.51", "side": "SELL", "timestamp": "1768475487802", "received_at": "2026-01-15T12:11:27.930577"}}
{"event_type": "price_change", "event_ts": "2026-01-15T12:11:28.430809", "ingestion_ts": "2026-01-15T12:11:41.230171", "market_id": "0x427bc4b40c09b3dcbc973747f0e4b079bed91b3e5a0aed5c36edd0f7591485f4", "raw": {"market": "0x427bc4b40c09b3dcbc973747f0e4b079bed91b3e5a0aed5c36edd0f7591485f4", "asset_id": "115669573443672055876643967408433138119481486650803218131873713375232186497057", "price": "0.002", "size": "63.15", "side": "BUY", "timestamp": "1768475488312", "received_at": "2026-01-15T12:11:28.430809"}}
{"event_type": "price_change", "event_ts": "2026-01-15T12:11:28.430809", "ingestion_ts": "2026-01-15T12:11:41.230171", "market_id": "0x427bc4b40c09b3dcbc973747f0e4b079bed91b3e5a0aed5c36edd0f7591485f4", "raw": {"market": "0x427bc4b40c09b3dcbc973747f0e4b079bed91b3e5a0aed5c36edd0f7591485f4", "asset_id": "86130975769502911188457673769190265049139877688522439001984850068234616395137", "price": "0.998", "size": "63.15", "side": "SELL", "timestamp": "1768475488312", "received_at": "2026-01-15T12:11:28.430809"}}
{"event_type": "price_change", "event_ts": "2026-01-15T12:11:28.465051", "ingestion_ts": "2026-01-15T12:11:41.230171", "market_id": "0xc0e6b917320a47228fb96e3b5ae0e5c93773a5ae2662ae4e1f37807cfe47ce98", "raw": {"market": "0xc0e6b917320a47228fb96e3b5ae0e5c93773a5ae2662ae4e1f37807cfe47ce98", "asset_id": "58656358377246279051017109359677190749228949103591068167284263961542487110215", "price": "0.003", "size": "420.93", "side": "BUY", "timestamp": "1768475488346", "received_at": "2026-01-15T12:11:28.465051"}}
{"event_type": "price_change", "event_ts": "2026-01-15T12:11:28.465051", "ingestion_ts": "2026-01-15T12:11:41.230171", "market_id": "0xc0e6b917320a47228fb96e3b5ae0e5c93773a5ae2662ae4e1f37807cfe47ce98", "raw": {"market": "0xc0e6b917320a47228fb96e3b5ae0e5c93773a5ae2662ae4e1f37807cfe47ce98", "asset_id": "81647294538046680798858716589766492074338758116170717123345952330712416337530", "price": "0.997", "size": "420.93", "side": "SELL", "timestamp": "1768475488346", "received_at": "2026-01-15T12:11:28.465051"}}
{"event_type": "price_change", "event_ts": "2026-01-15T12:11:28.467496", "ingestion_ts": "2026-01-15T12:11:41.230171", "market_id": "0xc0e6b917320a47228fb96e3b5ae0e5c93773a5ae2662ae4e1f37807cfe47ce98", "raw": {"market": "0xc0e6b917320a47228fb96e3b5ae0e5c93773a5ae2662ae4e1f37807cfe47ce98", "asset_id": "58656358377246279051017109359677190749228949103591068167284263961542487110215", "price": "0.003", "size": "426.6", "side": "BUY", "timestamp": "1768475488350", "received_at": "2026-01-15T12:11:28.467496"}}
{"event_type": "price_change", "event_ts": "2026-01-15T12:11:28.467496", "ingestion_ts": "2026-01-15T12:11:41.230171", "market_id": "0xc0e6b917320a47228fb96e3b5ae0e5c93773a5ae2662ae4e1f37807cfe47ce98", "raw": {"market": "0xc0e6b917320a47228fb96e3b5ae0e5c93773a5ae2662ae4e1f37807cfe47ce98", "asset_id": "81647294538046680798858716589766492074338758116170717123345952330712416337530", "price": "0.997", "size": "426.6", "side": "SELL", "timestamp": "1768475488350", "received_at": "2026-01-15T12:11:28.467496"}}
{"event_type": "price_change", "event_ts": "2026-01-15T12:11:28.917997", "ingestion_ts": "2026-01-15T12:11:41.230171", "market_id": "0x427bc4b40c09b3dcbc973747f0e4b079bed91b3e5a0aed5c36edd0f7591485f4", "raw": {"market": "0x427bc4b40c09b3dcbc973747f0e4b079bed91b3e5a0aed5c36edd0f7591485f4", "asset_id": "115669573443672055876643967408433138119481486650803218131873713375232186497057", "price": "0.002", "size": "72.33", "side": "BUY", "timestamp": "1768475488798", "received_at": "2026-01-15T12:11:28.917997"}}
{"event_type": "price_change", "event_ts": "2026-01-15T12:11:28.917997", "ingestion_ts": "2026-01-15T12:11:41.230171", "market_id": "0x427bc4b40c09b3dcbc973747f0e4b079bed91b3e5a0aed5c36edd0f7591485f4", "raw": {"market": "0x427bc4b40c09b3dcbc973747f0e4b079bed91b3e5a0aed5c36edd0f7591485f4", "asset_id": "86130975769502911188457673769190265049139877688522439001984850068234616395137", "price": "0.998", "size": "72.33", "side": "SELL", "timestamp": "1768475488798", "received_at": "2026-01-15T12:11:28.917997"}}
{"event_type": "price_change", "event_ts": "2026-01-15T12:11:29.183200", "ingestion_ts": "2026-01-15T12:11:41.230171", "market_id": "0xcab7ba4a9133cfd407d7e73e5757e5abbace413b59421527a31113406c97815c", "raw": {"market": "0xcab7ba4a9133cfd407d7e73e5757e5abbace413b59421527a31113406c97815c", "asset_id": "96361925776989336186111887920533578209326565663637092688733016597062311745569", "price": "0.006", "size": "127.41", "side": "BUY", "timestamp": "1768475489065", "received_at": "2026-01-15T12:11:29.183200"}}
{"event_type": "price_change", "event_ts": "2026-01-15T12:11:29.183200", "ingestion_ts": "2026-01-15T12:11:41.230171", "market_id": "0xcab7ba4a9133cfd407d7e73e5757e5abbace413b59421527a31113406c97815c", "raw": {"market": "0xcab7ba4a9133cfd407d7e73e5757e5abbace413b59421527a31113406c97815c", "asset_id": "20002636398944597965698652220992177552927816915094913583821579024925426590022", "price": "0.994", "size": "127.41", "side": "SELL", "timestamp": "1768475489065", "received_at": "2026-01-15T12:11:29.183200"}}
{"event_type": "price_change", "event_ts": "2026-01-15T12:11:29.183232", "ingestion_ts": "2026-01-15T12:11:41.230171", "market_id": "0xcab7ba4a9133cfd407d7e73e5757e5abbace413b59421527a31113406c97815c", "raw": {"market": "0xcab7ba4a9133cfd407d7e73e5757e5abbace413b59421527a31113406c97815c", "asset_id": "96361925776989336186111887920533578209326565663637092688733016597062311745569", "price": "0.009", "size": "812.25", "side": "BUY", "timestamp": "1768475489065", "received_at": "2026-01-15T12:11:29.183232"}}
{"event_type": "price_change", "event_ts": "2026-01-15T12:11:29.183232", "ingestion_ts": "2026-01-15T12:11:41.230171", "market_id": "0xcab7ba4a9133cfd407d7e73e5757e5abbace413b59421527a31113406c97815c", "raw": {"market": "0xcab7ba4a9133cfd407d7e73e5757e5abbace413b59421527a31113406c97815c", "asset_id": "20002636398944597965698652220992177552927816915094913583821579024925426590022", "price": "0.991", "size": "812.25", "side": "SELL", "timestamp": "1768475489065", "received_at": "2026-01-15T12:11:29.183232"}}
{"event_type": "price_change", "event_ts": "2026-01-15T12:11:29.356962", "ingestion_ts": "2026-01-15T12:11:41.230171", "market_id": "0x427bc4b40c09b3dcbc973747f0e4b079bed91b3e5a0aed5c36edd0f7591485f4", "raw": {"market": "0x427bc4b40c09b3dcbc973747f0e4b079bed91b3e5a0aed5c36edd0f7591485f4", "asset_id": "115669573443672055876643967408433138119481486650803218131873713375232186497057", "price": "0.164", "size": "7.96", "side": "SELL", "timestamp": "1768475489233", "received_at": "2026-01-15T12:11:29.356962"}}
{"event_type": "price_change", "event_ts": "2026-01-15T12:11:29.356962", "ingestion_ts": "2026-01-15T12:11:41.230171", "market_id": "0x427bc4b40c09b3dcbc973747f0e4b079bed91b3e5a0aed5c36edd0f7591485f4", "raw": {"market": "0x427bc4b40c09b3dcbc973747f0e4b079bed91b3e5a0aed5c36edd0f7591485f4", "asset_id": "86130975769502911188457673769190265049139877688522439001984850068234616395137", "price": "0.836", "size": "7.96", "side": "BUY", "timestamp": "1768475489233", "received_at": "2026-01-15T12:11:29.356962"}}
{"event_type": "price_change", "event_ts": "2026-01-15T12:11:29.619103", "ingestion_ts": "2026-01-15T12:11:41.230171", "market_id": "0xcab7ba4a9133cfd407d7e73e5757e5abbace413b59421527a31113406c97815c", "raw": {"market": "0xcab7ba4a9133cfd407d7e73e5757e5abbace413b59421527a31113406c97815c", "asset_id": "96361925776989336186111887920533578209326565663637092688733016597062311745569", "price": "0.009", "size": "818.33", "side": "BUY", "timestamp": "1768475489500", "received_at": "2026-01-15T12:11:29.619103"}}
{"event_type": "price_change", "event_ts": "2026-01-15T12:11:29.619103", "ingestion_ts": "2026-01-15T12:11:41.230171", "market_id": "0xcab7ba4a9133cfd407d7e73e5757e5abbace413b59421527a31113406c97815c", "raw": {"market": "0xcab7ba4a9133cfd407d7e73e5757e5abbace413b59421527a31113406c97815c", "asset_id": "20002636398944597965698652220992177552927816915094913583821579024925426590022", "price": "0.991", "size": "818.33", "side": "SELL", "timestamp": "1768475489500", "received_at": "2026-01-15T12:11:29.619103"}}
{"event_type": "price_change", "event_ts": "2026-01-15T12:11:29.622123", "ingestion_ts": "2026-01-15T12:11:41.230171", "market_id": "0xcab7ba4a9133cfd407d7e73e5757e5abbace413b59421527a31113406c97815c", "raw": {"market": "0xcab7ba4a9133cfd407d7e73e5757e5abbace413b59421527a31113406c97815c", "asset_id": "96361925776989336186111887920533578209326565663637092688733016597062311745569", "price": "0.006", "size": "136.51", "side": "BUY", "timestamp": "1768475489502", "received_at": "2026-01-15T12:11:29.622123"}}
{"event_type": "price_change", "event_ts": "2026-01-15T12:11:29.622123", "ingestion_ts": "2026-01-15T12:11:41.230171", "market_id": "0xcab7ba4a9133cfd407d7e73e5757e5abbace413b59421527a31113406c97815c", "raw": {"market": "0xcab7ba4a9133cfd407d7e73e5757e5abbace413b59421527a31113406c97815c", "asset_id": "20002636398944597965698652220992177552927816915094913583821579024925426590022", "price": "0.994", "size": "136.51", "side": "SELL", "timestamp": "1768475489502", "received_at": "2026-01-15T12:11:29.622123"}}
{"event_type": "price_change", "event_ts": "2026-01-15T12:11:29.786572", "ingestion_ts": "2026-01-15T12:11:41.230171", "market_id": "0x427bc4b40c09b3dcbc973747f0e4b079bed91b3e5a0aed5c36edd0f7591485f4", "raw": {"market": "0x427bc4b40c09b3dcbc973747f0e4b079bed91b3e5a0aed5c36edd0f7591485f4", "asset_id": "115669573443672055876643967408433138119481486650803218131873713375232186497057", "price": "0.164", "size": "15.92", "side": "SELL", "timestamp": "1768475489666", "received_at": "2026-01-15T12:11:29.786572"}}
{"event_type": "price_change", "event_ts": "2026-01-15T12:11:29.786572", "ingestion_ts": "2026-01-15T12:11:41.230171", "market_id": "0x427bc4b40c09b3dcbc973747f0e4b079bed91b3e5a0aed5c36edd0f7591485f4", "raw": {"market": "0x427bc4b40c09b3dcbc973747f0e4b079bed91b3e5a0aed5c36edd0f7591485f4", "asset_id": "86130975769502911188457673769190265049139877688522439001984850068234616395137", "price": "0.836", "size": "15.92", "side": "BUY", "timestamp": "1768475489666", "received_at": "2026-01-15T12:11:29.786572"}}
{"event_type": "price_change", "event_ts": "2026-01-15T12:11:31.428576", "ingestion_ts": "2026-01-15T12:11:41.230171", "market_id": "0xc0e6b917320a47228fb96e3b5ae0e5c93773a5ae2662ae4e1f37807cfe47ce98", "raw": {"market": "0xc0e6b917320a47228fb96e3b5ae0e5c93773a5ae2662ae4e1f37807cfe47ce98", "asset_id": "58656358377246279051017109359677190749228949103591068167284263961542487110215", "price": "0.003", "size": "412.73", "side": "BUY", "timestamp": "1768475491305", "received_at": "2026-01-15T12:11:31.428576"}}
{"event_type": "price_change", "event_ts": "2026-01-15T12:11:31.428576", "ingestion_ts": "2026-01-15T12:11:41.230171", "market_id": "0xc0e6b917320a47228fb96e3b5ae0e5c93773a5ae2662ae4e1f37807cfe47ce98", "raw": {"market": "0xc0e6b917320a47228fb96e3b5ae0e5c93773a5ae2662ae4e1f37807cfe47ce98", "asset_id": "81647294538046680798858716589766492074338758116170717123345952330712416337530", "price": "0.997", "size": "412.73", "side": "SELL", "timestamp": "1768475491305", "received_at": "2026-01-15T12:11:31.428576"}}
{"event_type": "price_change", "event_ts": "2026-01-15T12:11:31.428611", "ingestion_ts": "2026-01-15T12:11:41.230171", "market_id": "0xc0e6b917320a47228fb96e3b5ae0e5c93773a5ae2662ae4e1f37807cfe47ce98", "raw": {"market": "0xc0e6b917320a47228fb96e3b5ae0e5c93773a5ae2662ae4e1f37807cfe47ce98", "asset_id": "58656358377246279051017109359677190749228949103591068167284263961542487110215", "price": "0.004", "size": "0", "side": "BUY", "timestamp": "1768475491305", "received_at": "2026-01-15T12:11:31.428611"}}
{"event_type": "price_change", "event_ts": "2026-01-15T12:11:31.428611", "ingestion_ts": "2026-01-15T12:11:41.230171", "market_id": "0xc0e6b917320a47228fb96e3b5ae0e5c93773a5ae2662ae4e1f37807cfe47ce98", "raw": {"market": "0xc0e6b917320a47228fb96e3b5ae0e5c93773a5ae2662ae4e1f37807cfe47ce98", "asset_id": "81647294538046680798858716589766492074338758116170717123345952330712416337530", "price": "0.996", "size": "0", "side": "SELL", "timestamp": "1768475491305", "received_at": "2026-01-15T12:11:31.428611"}}
{"event_type": "price_change", "event_ts": "2026-01-15T12:11:31.448771", "ingestion_ts": "2026-01-15T12:11:41.230171", "market_id": "0x427bc4b40c09b3dcbc973747f0e4b079bed91b3e5a0aed5c36edd0f7591485f4", "raw": {"market": "0x427bc4b40c09b3dcbc973747f0e4b079bed91b3e5a0aed5c36edd0f7591485f4", "asset_id": "86130975769502911188457673769190265049139877688522439001984850068234616395137", "price": "0.835", "size": "0", "side": "BUY", "timestamp": "1768475491331", "received_at": "2026-01-15T12:11:31.448771"}}
{"event_type": "price_change", "event_ts": "2026-01-15T12:11:31.448771", "ingestion_ts": "2026-01-15T12:11:41.230171", "market_id": "0x427bc4b40c09b3dcbc973747f0e4b079bed91b3e5a0aed5c36edd0f7591485f4", "raw": {"market": "0x427bc4b40c09b3dcbc973747f0e4b079bed91b3e5a0aed5c36edd0f7591485f4", "asset_id": "115669573443672055876643967408433138119481486650803218131873713375232186497057", "price": "0.165", "size": "0", "side": "SELL", "timestamp": "1768475491331", "received_at": "2026-01-15T12:11:31.448771"}}
{"event_type": "price_change", "event_ts": "2026-01-15T12:11:31.568497", "ingestion_ts": "2026-01-15T12:11:41.230171", "market_id": "0x427bc4b40c09b3dcbc973747f0e4b079bed91b3e5a0aed5c36edd0f7591485f4", "raw": {"market": "0x427bc4b40c09b3dcbc973747f0e4b079bed91b3e5a0aed5c36edd0f7591485f4", "asset_id": "86130975769502911188457673769190265049139877688522439001984850068234616395137", "price": "0.846", "size": "10", "side": "BUY", "timestamp": "1768475491449", "received_at": "2026-01-15T12:11:31.568497"}}
{"event_type": "price_change", "event_ts": "2026-01-15T12:11:31.568497", "ingestion_ts": "2026-01-15T12:11:41.230171", "market_id": "0x427bc4b40c09b3dcbc973747f0e4b079bed91b3e5a0aed5c36edd0f7591485f4", "raw": {"market": "0x427bc4b40c09b3dcbc973747f0e4b079bed91b3e5a0aed5c36edd0f7591485f4", "asset_id": "115669573443672055876643967408433138119481486650803218131873713375232186497057", "price": "0.154", "size": "10", "side": "SELL", "timestamp": "1768475491449", "received_at": "2026-01-15T12:11:31.568497"}}
{"event_type": "price_change", "event_ts": "2026-01-15T12:11:31.623159", "ingestion_ts": "2026-01-15T12:11:41.230171", "market_id": "0xc0e6b917320a47228fb96e3b5ae0e5c93773a5ae2662ae4e1f37807cfe47ce98", "raw": {"market": "0xc0e6b917320a47228fb96e3b5ae0e5c93773a5ae2662ae4e1f37807cfe47ce98", "asset_id": "58656358377246279051017109359677190749228949103591068167284263961542487110215", "price": "0.005", "size": "10.54", "side": "BUY", "timestamp": "1768475491505", "received_at": "2026-01-15T12:11:31.623159"}}
{"event_type": "price_change", "event_ts": "2026-01-15T12:11:31.623159", "ingestion_ts": "2026-01-15T12:11:41.230171", "market_id": "0xc0e6b917320a47228fb96e3b5ae0e5c93773a5ae2662ae4e1f37807cfe47ce98", "raw": {"market": "0xc0e6b917320a47228fb96e3b5ae0e5c93773a5ae2662ae4e1f37807cfe47ce98", "asset_id": "81647294538046680798858716589766492074338758116170717123345952330712416337530", "price": "0.995", "size": "10.54", "side": "SELL", "timestamp": "1768475491505", "received_at": "2026-01-15T12:11:31.623159"}}
{"event_type": "price_change", "event_ts": "2026-01-15T12:11:31.626090", "ingestion_ts": "2026-01-15T12:11:41.230171", "market_id": "0xc0e6b917320a47228fb96e3b5ae0e5c93773a5ae2662ae4e1f37807cfe47ce98", "raw": {"market": "0xc0e6b917320a47228fb96e3b5ae0e5c93773a5ae2662ae4e1f37807cfe47ce98", "asset_id": "58656358377246279051017109359677190749228949103591068167284263961542487110215", "price": "0.005", "size": "18.1", "side": "BUY", "timestamp": "1768475491506", "received_at": "2026-01-15T12:11:31.626090"}}
{"event_type": "price_change", "event_ts": "2026-01-15T12:11:31.626090", "ingestion_ts": "2026-01-15T12:11:41.230171", "market_id": "0xc0e6b917320a47228fb96e3b5ae0e5c93773a5ae2662ae4e1f37807cfe47ce98", "raw": {"market": "0xc0e6b917320a47228fb96e3b5ae0e5c93773a5ae2662ae4e1f37807cfe47ce98", "asset_id": "81647294538046680798858716589766492074338758116170717123345952330712416337530", "price": "0.995", "size": "18.1", "side": "SELL", "timestamp": "1768475491506", "received_at": "2026-01-15T12:11:31.626090"}}
{"event_type": "price_change", "event_ts": "2026-01-15T12:11:31.867948", "ingestion_ts": "2026-01-15T12:11:41.230171", "market_id": "0xcab7ba4a9133cfd407d7e73e5757e5abbace413b59421527a31113406c97815c", "raw": {"market": "0xcab7ba4a9133cfd407d7e73e5757e5abbace413b59421527a31113406c97815c", "asset_id": "96361925776989336186111887920533578209326565663637092688733016597062311745569", "price": "0.006", "size": "127.41", "side": "BUY", "timestamp": "1768475491713", "received_at": "2026-01-15T12:11:31.867948"}}
{"event_type": "price_change", "event_ts": "2026-01-15T12:11:31.867948", "ingestion_ts": "2026-01-15T12:11:41.230171", "market_id": "0xcab7ba4a9133cfd407d7e73e5757e5abbace413b59421527a31113406c97815c", "raw": {"market": "0xcab7ba4a9133cfd407d7e73e5757e5abbace413b59421527a31113406c97815c", "asset_id": "20002636398944597965698652220992177552927816915094913583821579024925426590022", "price": "0.994", "size": "127.41", "side": "SELL", "timestamp": "1768475491713", "received_at": "2026-01-15T12:11:31.867948"}}
{"event_type": "price_change", "event_ts": "2026-01-15T12:11:31.868081", "ingestion_ts": "2026-01-15T12:11:41.230171", "market_id": "0xcab7ba4a9133cfd407d7e73e5757e5abbace413b59421527a31113406c97815c", "raw": {"market": "0xcab7ba4a9133cfd407d7e73e5757e5abbace413b59421527a31113406c97815c", "asset_id": "96361925776989336186111887920533578209326565663637092688733016597062311745569", "price": "0.009", "size": "812.25", "side": "BUY", "timestamp": "1768475491713", "received_at": "2026-01-15T12:11:31.868081"}}
{"event_type": "price_change", "event_ts": "2026-01-15T12:11:31.868081", "ingestion_ts": "2026-01-15T12:11:41.230171", "market_id": "0xcab7ba4a9133cfd407d7e73e5757e5abbace413b59421527a31113406c97815c", "raw": {"market": "0xcab7ba4a9133cfd407d7e73e5757e5abbace413b59421527a31113406c97815c", "asset_id": "20002636398944597965698652220992177552927816915094913583821579024925426590022", "price": "0.991", "size": "812.25", "side": "SELL", "timestamp": "1768475491713", "received_at": "2026-01-15T12:11:31.868081"}}
