{"event_type": "price_change", "event_ts": "2026-01-15T12:07:49.290741", "ingestion_ts": "2026-01-15T12:08:42.168746", "market_id": "0xc0e6b917320a47228fb96e3b5ae0e5c93773a5ae2662ae4e1f37807cfe47ce98", "raw": {"market": "0xc0e6b917320a47228fb96e3b5ae0e5c93773a5ae2662ae4e1f37807cfe47ce98", "asset_id": "81647294538046680798858716589766492074338758116170717123345952330712416337530", "price": "0.995", "size": "12.09", "side": "SELL", "timestamp": "1768475269171", "received_at": "2026-01-15T12:07:49.290741"}}
{"event_type": "price_change", "event_ts": "2026-01-15T12:07:49.489769", "ingestion_ts": "2026-01-15T12:08:42.168746", "market_id": "0xe9c127a8c35f045d37b5344b0a36711084fa20c2fc1618bf178a5386f90610be", "raw": {"market": "0xe9c127a8c35f045d37b5344b0a36711084fa20c2fc1618bf178a5386f90610be", "asset_id": "107000426448217931795450451304515386602910396776318075817601265223856116134349", "price": "0.051", "size": "0", "side": "BUY", "timestamp": "1768475269371", "received_at": "2026-01-15T12:07:49.489769"}}
{"event_type": "price_change", "event_ts": "2026-01-15T12:07:49.489769", "ingestion_ts": "2026-01-15T12:08:42.168746", "market_id": "0xe9c127a8c35f045d37b5344b0a36711084fa20c2fc1618bf178a5386f90610be", "raw": {"market": "0xe9c127a8c35f045d37b5344b0a36711084fa20c2fc1618bf178a5386f90610be", "asset_id": "80230236018433940569996058935444651347308266584430516013229815570706872276819", "price": "0.949", "size": "0", "side": "SELL", "timestamp": "1768475269371", "received_at": "2026-01-15T12:07:49.489769"}}
{"event_type": "price_change", "event_ts": "2026-01-15T12:07:49.724959", "ingestion_ts": "2026-01-15T12:08:42.168746", "market_id": "0xe9c127a8c35f045d37b5344b0a36711084fa20c2fc1618bf178a5386f90610be", "raw": {"market": "0xe9c127a8c35f045d37b5344b0a36711084fa20c2fc1618bf178a5386f90610be", "asset_id": "107000426448217931795450451304515386602910396776318075817601265223856116134349", "price": "0.051", "size": "78.43", "side": "BUY", "timestamp": "1768475269604", "received_at": "2026-01-15T12:07:49.724959"}}
{"event_type": "price_change", "event_ts": "2026-01-15T12:07:49.724959", "ingestion_ts": "2026-01-15T12:08:42.168746", "market_id": "0xe9c127a8c35f045d37b5344b0a36711084fa20c2fc1618bf178a5386f90610be", "raw": {"market": "0xe9c127a8c35f045d37b5344b0a36711084fa20c2fc1618bf178a5386f90610be", "asset_id": "80230236018433940569996058935444651347308266584430516013229815570706872276819", "price": "0.949", "size": "78.43", "side": "SELL", "timestamp": "1768475269604", "received_at": "2026-01-15T12:07:49.724959"}}
{"event_type": "price_change", "event_ts": "2026-01-15T12:07:49.910580", "ingestion_ts": "2026-01-15T12:08:42.168746", "market_id": "0xe9c127a8c35f045d37b5344b0a36711084fa20c2fc1618bf178a5386f90610be", "raw": {"market": "0xe9c127a8c35f045d37b5344b0a36711084fa20c2fc1618bf178a5386f90610be", "asset_id": "107000426448217931795450451304515386602910396776318075817601265223856116134349", "price": "0.067", "size": "0", "side": "BUY", "timestamp": "1768475269793", "received_at": "2026-01-15T12:07:49.910580"}}
{"event_type": "price_change", "event_ts": "2026-01-15T12:07:49.910580", "ingestion_ts": "2026-01-15T12:08:42.168746", "market_id": "0xe9c127a8c35f045d37b5344b0a36711084fa20c2fc1618bf178a5386f90610be", "raw": {"market": "0xe9c127a8c35f045d37b5344b0a36711084fa20c2fc1618bf178a5386f90610be", "asset_id": "80230236018433940569996058935444651347308266584430516013229815570706872276819", "price": "0.933", "size": "0", "side": "SELL", "timestamp": "1768475269793", "received_at": "2026-01-15T12:07:49.910580"}}
{"event_type": "price_change", "event_ts": "2026-01-15T12:07:50.108398", "ingestion_ts": "2026-01-15T12:08:42.168746", "market_id": "0xe9c127a8c35f045d37b5344b0a36711084fa20c2fc1618bf178a5386f90610be", "raw": {"market": "0xe9c127a8c35f045d37b5344b0a36711084fa20c2fc1618bf178a5386f90610be", "asset_id": "107000426448217931795450451304515386602910396776318075817601265223856116134349", "price": "0.067", "size": "59.7", "side": "BUY", "timestamp": "1768475269990", "received_at": "2026-01-15T12:07:50.108398"}}
{"event_type": "price_change", "event_ts": "2026-01-15T12:07:50.108398", "ingestion_ts": "2026-01-15T12:08:42.168746", "market_id": "0xe9c127a8c35f045d37b5344b0a36711084fa20c2fc1618bf178a5386f90610be", "raw": {"market": "0xe9c127a8c35f045d37b5344b0a36711084fa20c2fc1618bf178a5386f90610be", "asset_id": "80230236018433940569996058935444651347308266584430516013229815570706872276819", "price": "0.933", "size": "59.7", "side": "SELL", "timestamp": "1768475269990", "received_at": "2026-01-15T12:07:50.108398"}}
{"event_type": "price_change", "event_ts": "2026-01-15T12:07:50.293021", "ingestion_ts": "2026-01-15T12:08:42.168746", "market_id": "0xcab7ba4a9133cfd407d7e73e5757e5abbace413b59421527a31113406c97815c", "raw": {"market": "0xcab7ba4a9133cfd407d7e73e5757e5abbace413b59421527a31113406c97815c", "asset_id": "96361925776989336186111887920533578209326565663637092688733016597062311745569", "price": "0.006", "size": "127.41", "side": "BUY", "timestamp": "1768475270139", "received_at": "2026-01-15T12:07:50.293021"}}
{"event_type": "price_change", "event_ts": "2026-01-15T12:07:50.293021", "ingestion_ts": "2026-01-15T12:08:42.168746", "market_id": "0xcab7ba4a9133cfd407d7e73e5757e5abbace413b59421527a31113406c97815c", "raw": {"market": "0xcab7ba4a9133cfd407d7e73e5757e5abbace413b59421527a31113406c97815c", "asset_id": "20002636398944597965698652220992177552927816915094913583821579024925426590022", "price": "0.994", "size": "127.41", "side": "SELL", "timestamp": "1768475270139", "received_at": "2026-01-15T12:07:50.293021"}}
{"event_type": "price_change", "event_ts": "2026-01-15T12:07:50.293067", "ingestion_ts": "2026-01-15T12:08:42.168746", "market_id": "0xcab7ba4a9133cfd407d7e73e5757e5abbace413b59421527a31113406c97815c", "raw": {"market": "0xcab7ba4a9133cfd407d7e73e5757e5abbace413b59421527a31113406c97815c", "asset_id": "96361925776989336186111887920533578209326565663637092688733016597062311745569", "price": "0.009", "size": "812.25", "side": "BUY", "timestamp": "1768475270139", "received_at": "2026-01-15T12:07:50.293067"}}
{"event_type": "price_change", "event_ts": "2026-01-15T12:07:50.293067", "ingestion_ts": "2026-01-15T12:08:42.168746", "market_id": "0xcab7ba4a9133cfd407d7e73e5757e5abbace413b59421527a31113406c97815c", "raw": {"market": "0xcab7ba4a9133cfd407d7e73e5757e5abbace413b59421527a31113406c97815c", "asset_id": "20002636398944597965698652220992177552927816915094913583821579024925426590022", "price": "0.991", "size": "812.25", "side": "SELL", "timestamp": "1768475270139", "received_at": "2026-01-15T12:07:50.293067"}}
{"event_type": "price_change", "event_ts": "2026-01-15T12:07:50.358453", "ingestion_ts": "2026-01-15T12:08:42.168746", "market_id": "0xe9c127a8c35f045d37b5344b0a36711084fa20c2fc1618bf178a5386f90610be", "raw": {"market": "0xe9c127a8c35f045d37b5344b0a36711084fa20c2fc1618bf178a5386f90610be", "asset_id": "107000426448217931795450451304515386602910396776318075817601265223856116134349", "price": "0.108", "size": "37.03", "side": "BUY", "timestamp": "1768475270202", "received_at": "2026-01-15T12:07:50.358453"}}
{"event_type": "price_change", "event_ts": "2026-01-15T12:07:50.358453", "ingestion_ts": "2026-01-15T12:08:42.168746", "market_id": "0xe9c127a8c35f045d37b5344b0a36711084fa20c2fc1618bf178a5386f90610be", "raw": {"market": "0xe9c127a8c35f045d37b5344b0a36711084fa20c2fc1618bf178a5386f90610be", "asset_id": "80230236018433940569996058935444651347308266584430516013229815570706872276819", "price": "0.892", "size": "37.03", "side": "SELL", "timestamp": "1768475270202", "received_at": "2026-01-15T12:07:50.358453"}}
{"event_type": "price_change", "event_ts": "2026-01-15T12:07:50.477618", "ingestion_ts": "2026-01-15T12:08:42.168746", "market_id": "0x427bc4b40c09b3dcbc973747f0e4b079bed91b3e5a0aed5c36edd0f7591485f4", "raw": {"market": "0x427bc4b40c09b3dcbc973747f0e4b079bed91b3e5a0aed5c36edd0f7591485f4", "asset_id": "115669573443672055876643967408433138119481486650803218131873713375232186497057", "price": "0.005", "size": "16.91", "side": "BUY", "timestamp": "1768475270323", "received_at": "2026-01-15T12:07:50.477618"}}
{"event_type": "price_change", "event_ts": "2026-01-15T12:07:50.477618", "ingestion_ts": "2026-01-15T12:08:42.168746", "market_id": "0x427bc4b40c09b3dcbc973747f0e4b079bed91b3e5a0aed5c36edd0f7591485f4", "raw": {"market": "0x427bc4b40c09b3dcbc973747f0e4b079bed91b3e5a0aed5c36edd0f7591485f4", "asset_id": "86130975769502911188457673769190265049139877688522439001984850068234616395137", "price": "0.995", "size": "16.91", "side": "SELL", "timestamp": "1768475270323", "received_at": "2026-01-15T12:07:50.477618"}}
{"event_type": "price_change", "event_ts": "2026-01-15T12:07:50.514176", "ingestion_ts": "2026-01-15T12:08:42.168746", "market_id": "0xe9c127a8c35f045d37b5344b0a36711084fa20c2fc1618bf178a5386f90610be", "raw": {"market": "0xe9c127a8c35f045d37b5344b0a36711084fa20c2fc1618bf178a5386f90610be", "asset_id": "107000426448217931795450451304515386602910396776318075817601265223856116134349", "price": "0.115", "size": "0", "side": "BUY", "timestamp": "1768475270397", "received_at": "2026-01-15T12:07:50.514176"}}
{"event_type": "price_change", "event_ts": "2026-01-15T12:07:50.514176", "ingestion_ts": "2026-01-15T12:08:42.168746", "market_id": "0xe9c127a8c35f045d37b5344b0a36711084fa20c2fc1618bf178a5386f90610be", "raw": {"market": "0xe9c127a8c35f045d37b5344b0a36711084fa20c2fc1618bf178a5386f90610be", "asset_id": "80230236018433940569996058935444651347308266584430516013229815570706872276819", "price": "0.885", "size": "0", "side": "SELL", "timestamp": "1768475270397", "received_at": "2026-01-15T12:07:50.514176"}}
{"event_type": "price_change", "event_ts": "2026-01-15T12:07:50.737448", "ingestion_ts": "2026-01-15T12:08:42.168746", "market_id": "0xe9c127a8c35f045d37b5344b0a36711084fa20c2fc1618bf178a5386f90610be", "raw": {"market": "0xe9c127a8c35f045d37b5344b0a36711084fa20c2fc1618bf178a5386f90610be", "asset_id": "107000426448217931795450451304515386602910396776318075817601265223856116134349", "price": "0.115", "size": "34.78", "side": "BUY", "timestamp": "1768475270619", "received_at": "2026-01-15T12:07:50.737448"}}
{"event_type": "price_change", "event_ts": "2026-01-15T12:07:50.737448", "ingestion_ts": "2026-01-15T12:08:42.168746", "market_id": "0xe9c127a8c35f045d37b5344b0a36711084fa20c2fc1618bf178a5386f90610be", "raw": {"market": "0xe9c127a8c35f045d37b5344b0a36711084fa20c2fc1618bf178a5386f90610be", "asset_id": "80230236018433940569996058935444651347308266584430516013229815570706872276819", "price": "0.885", "size": "34.78", "side": "SELL", "timestamp": "1768475270619", "received_at": "2026-01-15T12:07:50.737448"}}
{"event_type": "price_change", "event_ts": "2026-01-15T12:07:50.813647", "ingestion_ts": "2026-01-15T12:08:42.168746", "market_id": "0x427bc4b40c09b3dcbc973747f0e4b079bed91b3e5a0aed5c36edd0f7591485f4", "raw": {"market": "0x427bc4b40c09b3dcbc973747f0e4b079bed91b3e5a0aed5c36edd0f7591485f4", "asset_id": "115669573443672055876643967408433138119481486650803218131873713375232186497057", "price": "0.002", "size": "59.2", "side": "BUY", "timestamp": "1768475270695", "received_at": "2026-01-15T12:07:50.813647"}}
{"event_type": "price_change", "event_ts": "2026-01-15T12:07:50.813647", "ingestion_ts": "2026-01-15T12:08:42.168746", "market_id": "0x427bc4b40c09b3dcbc973747f0e4b079bed91b3e5a0aed5c36edd0f7591485f4", "raw": {"market": "0x427bc4b40c09b3dcbc973747f0e4b079bed91b3e5a0aed5c36edd0f7591485f4", "asset_id": "86130975769502911188457673769190265049139877688522439001984850068234616395137", "price": "0.998", "size": "59.2", "side": "SELL", "timestamp": "1768475270695", "received_at": "2026-01-15T12:07:50.813647"}}
{"event_type": "price_change", "event_ts": "2026-01-15T12:07:50.813684", "ingestion_ts": "2026-01-15T12:08:42.168746", "market_id": "0x427bc4b40c09b3dcbc973747f0e4b079bed91b3e5a0aed5c36edd0f7591485f4", "raw": {"market": "0x427bc4b40c09b3dcbc973747f0e4b079bed91b3e5a0aed5c36edd0f7591485f4", "asset_id": "115669573443672055876643967408433138119481486650803218131873713375232186497057", "price": "0.005", "size": "24.71", "side": "BUY", "timestamp": "1768475270696", "received_at": "2026-01-15T12:07:50.813684"}}
{"event_type": "price_change", "event_ts": "2026-01-15T12:07:50.813684", "ingestion_ts": "2026-01-15T12:08:42.168746", "market_id": "0x427bc4b40c09b3dcbc973747f0e4b079bed91b3e5a0aed5c36edd0f7591485f4", "raw": {"market": "0x427bc4b40c09b3dcbc973747f0e4b079bed91b3e5a0aed5c36edd0f7591485f4", "asset_id": "86130975769502911188457673769190265049139877688522439001984850068234616395137", "price": "0.995", "size": "24.71", "side": "SELL", "timestamp": "1768475270696", "received_at": "2026-01-15T12:07:50.813684"}}
{"event_type": "price_change", "event_ts": "2026-01-15T12:07:50.937507", "ingestion_ts": "2026-01-15T12:08:42.168746", "market_id": "0xe9c127a8c35f045d37b5344b0a36711084fa20c2fc1618bf178a5386f90610be", "raw": {"market": "0xe9c127a8c35f045d37b5344b0a36711084fa20c2fc1618bf178a5386f90610be", "asset_id": "107000426448217931795450451304515386602910396776318075817601265223856116134349", "price": "0.151", "size": "0", "side": "BUY", "timestamp": "1768475270819", "received_at": "2026-01-15T12:07:50.937507"}}
{"event_type": "price_change", "event_ts": "2026-01-15T12:07:50.937507", "ingestion_ts": "2026-01-15T12:08:42.168746", "market_id": "0xe9c127a8c35f045d37b5344b0a36711084fa20c2fc1618bf178a5386f90610be", "raw": {"market": "0xe9c127a8c35f045d37b5344b0a36711084fa20c2fc1618bf178a5386f90610be", "asset_id": "80230236018433940569996058935444651347308266584430516013229815570706872276819", "price": "0.849", "size": "0", "side": "SELL", "timestamp": "1768475270819", "received_at": "2026-01-15T12:07:50.937507"}}
{"event_type": "price_change", "event_ts": "2026-01-15T12:07:51.037781", "ingestion_ts": "2026-01-15T12:08:42.168746", "market_id": "0xcab7ba4a9133cfd407d7e73e5757e5abbace413b59421527a31113406c97815c", "raw": {"market": "0xcab7ba4a9133cfd407d7e73e5757e5abbace413b59421527a31113406c97815c", "asset_id": "96361925776989336186111887920533578209326565663637092688733016597062311745569", "price": "0.006", "size": "136.51", "side": "BUY", "timestamp": "1768475270913", "received_at": "2026-01-15T12:07:51.037781"}}
{"event_type": "price_change", "event_ts": "2026-01-15T12:07:51.037781", "ingestion_ts": "2026-01-15T12:08:42.168746", "market_id": "0xcab7ba4a9133cfd407d7e73e5757e5abbace413b59421527a31113406c97815c", "raw": {"market": "0xcab7ba4a9133cfd407d7e73e5757e5abbace413b59421527a31113406c97815c", "asset_id": "20002636398944597965698652220992177552927816915094913583821579024925426590022", "price": "0.994", "size": "136.51", "side": "SELL", "timestamp": "1768475270913", "received_at": "2026-01-15T12:07:51.037781"}}
{"event_type": "price_change", "event_ts": "2026-01-15T12:07:51.039981", "ingestion_ts": "2026-01-15T12:08:42.168746", "market_id": "0xcab7ba4a9133cfd407d7e73e5757e5abbace413b59421527a31113406c97815c", "raw": {"market": "0xcab7ba4a9133cfd407d7e73e5757e5abbace413b59421527a31113406c97815c", "asset_id": "96361925776989336186111887920533578209326565663637092688733016597062311745569", "price": "0.009", "size": "818.33", "side": "BUY", "timestamp": "1768475270915", "received_at": "2026-01-15T12:07:51.039981"}}
{"event_type": "price_change", "event_ts": "2026-01-15T12:07:51.039981", "ingestion_ts": "2026-01-15T12:08:42.168746", "market_id": "0xcab7ba4a9133cfd407d7e73e5757e5abbace413b59421527a31113406c97815c", "raw": {"market": "0xcab7ba4a9133cfd407d7e73e5757e5abbace413b59421527a31113406c97815c", "asset_id": "20002636398944597965698652220992177552927816915094913583821579024925426590022", "price": "0.991", "size": "818.33", "side": "SELL", "timestamp": "1768475270915", "received_at": "2026-01-15T12:07:51.039981"}}
{"event_type": "price_change", "event_ts": "2026-01-15T12:07:51.159116", "ingestion_ts": "2026-01-15T12:08:42.168746", "market_id": "0xe9c127a8c35f045d37b5344b0a36711084fa20c2fc1618bf178a5386f90610be", "raw": {"market": "0xe9c127a8c35f045d37b5344b0a36711084fa20c2fc1618bf178a5386f90610be", "asset_id": "107000426448217931795450451304515386602910396776318075817601265223856116134349", "price": "0.151", "size": "26.49", "side": "BUY", "timestamp": "1768475271042", "received_at": "2026-01-15T12:07:51.159116"}}
{"event_type": "price_change", "event_ts": "2026-01-15T12:07:51.159116", "ingestion_ts": "2026-01-15T12:08:42.168746", "market_id": "0xe9c127a8c35f045d37b5344b0a36711084fa20c2fc1618bf178a5386f90610be", "raw": {"market": "0xe9c127a8c35f045d37b5344b0a36711084fa20c2fc1618bf178a5386f90610be", "asset_id": "80230236018433940569996058935444651347308266584430516013229815570706872276819", "price": "0.849", "size": "26.49", "side": "SELL", "timestamp": "1768475271042", "received_at": "2026-01-15T12:07:51.159116"}}
{"event_type": "price_change", "event_ts": "2026-01-15T12:07:51.353451", "ingestion_ts": "2026-01-15T12:08:42.168746", "market_id": "0xe9c127a8c35f045d37b5344b0a36711084fa20c2fc1618bf178a5386f90610be", "raw": {"market": "0xe9c127a8c35f045d37b5344b0a36711084fa20c2fc1618bf178a5386f90610be", "asset_id": "107000426448217931795450451304515386602910396776318075817601265223856116134349", "price": "0.169", "size": "0", "side": "BUY", "timestamp": "1768475271228", "received_at": "2026-01-15T12:07:51.353451"}}
{"event_type": "price_change", "event_ts": "2026-01-15T12:07:51.353451", "ingestion_ts": "2026-01-15T12:08:42.168746", "market_id": "0xe9c127a8c35f045d37b5344b0a36711084fa20c2fc1618bf178a5386f90610be", "raw": {"market": "0xe9c127a8c35f045d37b5344b0a36711084fa20c2fc1618bf178a5386f90610be", "asset_id": "80230236018433940569996058935444651347308266584430516013229815570706872276819", "price": "0.831", "size": "0", "side": "SELL", "timestamp": "1768475271228", "received_at": "2026-01-15T12:07:51.353451"}}
{"event_type": "price_change", "event_ts": "2026-01-15T12:07:51.608079", "ingestion_ts": "2026-01-15T12:08:42.168746", "market_id": "0xe9c127a8c35f045d37b5344b0a36711084fa20c2fc1618bf178a5386f90610be", "raw": {"market": "0xe9c127a8c35f045d37b5344b0a36711084fa20c2fc1618bf178a5386f90610be", "asset_id": "107000426448217931795450451304515386602910396776318075817601265223856116134349", "price": "0.169", "size": "23.66", "side": "BUY", "timestamp": "1768475271472", "received_at": "2026-01-15T12:07:51.608079"}}
{"event_type": "price_change", "event_ts": "2026-01-15T12:07:51.608079", "ingestion_ts": "2026-01-15T12:08:42.168746", "market_id": "0xe9c127a8c35f045d37b5344b0a36711084fa20c2fc1618bf178a5386f90610be", "raw": {"market": "0xe9c127a8c35f045d37b5344b0a36711084fa20c2fc1618bf178a5386f90610be", "asset_id": "80230236018433940569996058935444651347308266584430516013229815570706872276819", "price": "0.831", "size": "23.66", "side": "SELL", "timestamp": "1768475271472", "received_at": "2026-01-15T12:07:51.608079"}}
{"event_type": "price_change", "event_ts": "2026-01-15T12:07:51.801899", "ingestion_ts": "2026-01-15T12:08:42.168746", "market_id": "0xe9c127a8c35f045d37b5344b0a36711084fa20c2fc1618bf178a5386f90610be", "raw": {"market": "0xe9c127a8c35f045d37b5344b0a36711084fa20c2fc1618bf178a5386f90610be", "asset_id": "107000426448217931795450451304515386602910396776318075817601265223856116134349", "price": "0.214", "size": "0", "side": "BUY", "timestamp": "1768475271666", "received_at": "2026-01-15T12:07:51.801899"}}
{"event_type": "price_change", "event_ts": "2026-01-15T12:07:51.801899", "ingestion_ts": "2026-01-15T12:08:42.168746", "market_id": "0xe9c127a8c35f045d37b5344b0a36711084fa20c2fc1618bf178a5386f90610be", "raw": {"market": "0xe9c127a8c35f045d37b5344b0a36711084fa20c2fc1618bf178a5386f90610be", "asset_id": "80230236018433940569996058935444651347308266584430516013229815570706872276819", "price": "0.786", "size": "0", "side": "SELL", "timestamp": "1768475271666", "received_at": "2026-01-15T12:07:51.801899"}}
{"event_type": "price_change", "event_ts": "2026-01-15T12:07:51.802005", "ingestion_ts": "2026-01-15T12:08:42.168746", "market_id": "0xc0e6b917320a47228fb96e3b5ae0e5c93773a5ae2662ae4e1f37807cfe47ce98", "raw": {"market": "0xc0e6b917320a47228fb96e3b5ae0e5c93773a5ae2662ae4e1f37807cfe47ce98", "asset_id": "58656358377246279051017109359677190749228949103591068167284263961542487110215", "price": "0.004", "size": "0", "side": "BUY", "timestamp": "1768475271668", "received_at": "2026-01-15T12:07:51.802005"}}
{"event_type": "price_change", "event_ts": "2026-01-15T12:07:51.802005", "ingestion_ts": "2026-01-15T12:08:42.168746", "market_id": "0xc0e6b917320a47228fb96e3b5ae0e5c93773a5ae2662ae4e1f37807cfe47ce98", "raw": {"market": "0xc0e6b917320a47228fb96e3b5ae0e5c93773a5ae2662ae4e1f37807cfe47ce98", "asset_id": "81647294538046680798858716589766492074338758116170717123345952330712416337530", "price": "0.996", "size": "0", "side": "SELL", "timestamp": "1768475271668", "received_at": "2026-01-15T12:07:51.802005"}}
{"event_type": "price_change", "event_ts": "2026-01-15T12:07:51.802025", "ingestion_ts": "2026-01-15T12:08:42.168746", "market_id": "0xc0e6b917320a47228fb96e3b5ae0e5c93773a5ae2662ae4e1f37807cfe47ce98", "raw": {"market": "0xc0e6b917320a47228fb96e3b5ae0e5c93773a5ae2662ae4e1f37807cfe47ce98", "asset_id": "58656358377246279051017109359677190749228949103591068167284263961542487110215", "price": "0.005", "size": "2.98", "side": "BUY", "timestamp": "1768475271668", "received_at": "2026-01-15T12:07:51.802025"}}
{"event_type": "price_change", "event_ts": "2026-01-15T12:07:51.802025", "ingestion_ts": "2026-01-15T12:08:42.168746", "market_id": "0xc0e6b917320a47228fb96e3b5ae0e5c93773a5ae2662ae4e1f37807cfe47ce98", "raw": {"market": "0xc0e6b917320a47228fb96e3b5ae0e5c93773a5ae2662ae4e1f37807cfe47ce98", "asset_id": "81647294538046680798858716589766492074338758116170717123345952330712416337530", "price": "0.995", "size": "2.98", "side": "SELL", "timestamp": "1768475271668", "received_at": "2026-01-15T12:07:51.802025"}}
{"event_type": "price_change", "event_ts": "2026-01-15T12:07:52.023107", "ingestion_ts": "2026-01-15T12:08:42.168746", "market_id": "0xe9c127a8c35f045d37b5344b0a36711084fa20c2fc1618bf178a5386f90610be", "raw": {"market": "0xe9c127a8c35f045d37b5344b0a36711084fa20c2fc1618bf178a5386f90610be", "asset_id": "107000426448217931795450451304515386602910396776318075817601265223856116134349", "price": "0.214", "size": "18.69", "side": "BUY", "timestamp": "1768475271894", "received_at": "2026-01-15T12:07:52.023107"}}
{"event_type": "price_change", "event_ts": "2026-01-15T12:07:52.023107", "ingestion_ts": "2026-01-15T12:08:42.168746", "market_id": "0xe9c127a8c35f045d37b5344b0a36711084fa20c2fc1618bf178a5386f90610be", "raw": {"market": "0xe9c127a8c35f045d37b5344b0a36711084fa20c2fc1618bf178a5386f90610be", "asset_id": "80230236018433940569996058935444651347308266584430516013229815570706872276819", "price": "0.786", "size": "18.69", "side": "SELL", "timestamp": "1768475271894", "received_at": "2026-01-15T12:07:52.023107"}}
{"event_type": "price_change", "event_ts": "2026-01-15T12:07:52.306348", "ingestion_ts": "2026-01-15T12:08:42.168746", "market_id": "0xe9c127a8c35f045d37b5344b0a36711084fa20c2fc1618bf178a5386f90610be", "raw": {"market": "0xe9c127a8c35f045d37b5344b0a36711084fa20c2fc1618bf178a5386f90610be", "asset_id": "107000426448217931795450451304515386602910396776318075817601265223856116134349", "price": "0.252", "size": "15.87", "side": "BUY", "timestamp": "1768475272119", "received_at": "2026-01-15T12:07:52.306348"}}
{"event_type": "price_change", "event_ts": "2026-01-15T12:07:52.306348", "ingestion_ts": "2026-01-15T12:08:42.168746", "market_id": "0xe9c127a8c35f045d37b5344b0a36711084fa20c2fc1618bf178a5386f90610be", "raw": {"market": "0xe9c127a8c35f045d37b5344b0a36711084fa20c2fc1618bf178a5386f90610be", "asset_id": "80230236018433940569996058935444651347308266584430516013229815570706872276819", "price": "0.748", "size": "15.87", "side": "SELL", "timestamp": "1768475272119", "received_at": "2026-01-15T12:07:52.306348"}}
{"event_type": "price_change", "event_ts": "2026-01-15T12:07:52.463836", "ingestion_ts": "2026-01-15T12:08:42.168746", "market_id": "0xe9c127a8c35f045d37b5344b0a36711084fa20c2fc1618bf178a5386f90610be", "raw": {"market": "0xe9c127a8c35f045d37b5344b0a36711084fa20c2fc1618bf178a5386f90610be", "asset_id": "107000426448217931795450451304515386602910396776318075817601265223856116134349", "price": "0.38", "size": "10.52", "side": "BUY", "timestamp": "1768475272346", "received_at": "2026-01-15T12:07:52.463836"}}
{"event_type": "price_change", "event_ts": "2026-01-15T12:07:52.463836", "ingestion_ts": "2026-01-15T12:08:42.168746", "market_id": "0xe9c127a8c35f045d37b5344b0a36711084fa20c2fc1618bf178a5386f90610be", "raw": {"market": "0xe9c127a8c35f045d37b5344b0a36711084fa20c2fc1618bf178a5386f90610be", "asset_id": "80230236018433940569996058935444651347308266584430516013229815570706872276819", "price": "0.62", "size": "10.52", "side": "SELL", "timestamp": "1768475272346", "received_at": "2026-01-15T12:07:52.463836"}}
{"event_type": "price_change", "event_ts": "2026-01-15T12:07:52.680990", "ingestion_ts": "2026-01-15T12:08:42.168746", "market_id": "0xe9c127a8c35f045d37b5344b0a36711084fa20c2fc1618bf178a5386f90610be", "raw": {"market": "0xe9c127a8c35f045d37b5344b0a36711084fa20c2fc1618bf178a5386f90610be", "asset_id": "107000426448217931795450451304515386602910396776318075817601265223856116134349", "price": "0.495", "size": "0", "side": "BUY", "timestamp": "1768475272558", "received_at": "2026-01-15T12:07:52.680990"}}
{"event_type": "price_change", "event_ts": "2026-01-15T12:07:52.680990", "ingestion_ts": "2026-01-15T12:08:42.168746", "market_id": "0xe9c127a8c35f045d37b5344b0a36711084fa20c2fc1618bf178a5386f90610be", "raw": {"market": "0xe9c127a8c35f045d37b5344b0a36711084fa20c2fc1618bf178a5386f90610be", "asset_id": "80230236018433940569996058935444651347308266584430516013229815570706872276819", "price": "0.505", "size": "0", "side": "SELL", "timestamp": "1768475272558", "received_at": "2026-01-15T12:07:52.680990"}}
{"event_type": "price_change", "event_ts": "2026-01-15T12:07:52.889419", "ingestion_ts": "2026-01-15T12:08:42.168746", "market_id": "0xe9c127a8c35f045d37b5344b0a36711084fa20c2fc1618bf178a5386f90610be", "raw": {"market": "0xe9c127a8c35f045d37b5344b0a36711084fa20c2fc1618bf178a5386f90610be", "asset_id": "107000426448217931795450451304515386602910396776318075817601265223856116134349", "price": "0.495", "size": "8.08", "side": "BUY", "timestamp": "1768475272770", "received_at": "2026-01-15T12:07:52.889419"}}
{"event_type": "price_change", "event_ts": "2026-01-15T12:07:52.889419", "ingestion_ts": "2026-01-15T12:08:42.168746", "market_id": "0xe9c127a8c35f045d37b5344b0a36711084fa20c2fc1618bf178a5386f90610be", "raw": {"market": "0xe9c127a8c35f045d37b5344b0a36711084fa20c2fc1618bf178a5386f90610be", "asset_id": "80230236018433940569996058935444651347308266584430516013229815570706872276819", "price": "0.505", "size": "8.08", "side": "SELL", "timestamp": "1768475272770", "received_at": "2026-01-15T12:07:52.889419"}}
{"event_type": "price_change", "event_ts": "2026-01-15T12:07:52.930590", "ingestion_ts": "2026-01-15T12:08:42.168746", "market_id": "0xc0e6b917320a47228fb96e3b5ae0e5c93773a5ae2662ae4e1f37807cfe47ce98", "raw": {"market": "0xc0e6b917320a47228fb96e3b5ae0e5c93773a5ae2662ae4e1f37807cfe47ce98", "asset_id": "58656358377246279051017109359677190749228949103591068167284263961542487110215", "price": "0.006", "size": "8.66", "side": "BUY", "timestamp": "1768475272810", "received_at": "2026-01-15T12:07:52.930590"}}
{"event_type": "price_change", "event_ts": "2026-01-15T12:07:52.930590", "ingestion_ts": "2026-01-15T12:08:42.168746", "market_id": "0xc0e6b917320a47228fb96e3b5ae0e5c93773a5ae2662ae4e1f37807cfe47ce98", "raw": {"market": "0xc0e6b917320a47228fb96e3b5ae0e5c93773a5ae2662ae4e1f37807cfe47ce98", "asset_id": "81647294538046680798858716589766492074338758116170717123345952330712416337530", "price": "0.994", "size": "8.66", "side": "SELL", "timestamp": "1768475272810", "received_at": "2026-01-15T12:07:52.930590"}}
{"event_type": "price_change", "event_ts": "2026-01-15T12:07:52.931138", "ingestion_ts": "2026-01-15T12:08:42.168746", "market_id": "0xc0e6b917320a47228fb96e3b5ae0e5c93773a5ae2662ae4e1f37807cfe47ce98", "raw": {"market": "0xc0e6b917320a47228fb96e3b5ae0e5c93773a5ae2662ae4e1f37807cfe47ce98", "asset_id": "58656358377246279051017109359677190749228949103591068167284263961542487110215", "price": "0.005", "size": "10.81", "side": "BUY", "timestamp": "1768475272811", "received_at": "2026-01-15T12:07:52.931138"}}
{"event_type": "price_change", "event_ts": "2026-01-15T12:07:52.931138", "ingestion_ts": "2026-01-15T12:08:42.168746", "market_id": "0xc0e6b917320a47228fb96e3b5ae0e5c93773a5ae2662ae4e1f37807cfe47ce98", "raw": {"market": "0xc0e6b917320a47228fb96e3b5ae0e5c93773a5ae2662ae4e1f37807cfe47ce98", "asset_id": "81647294538046680798858716589766492074338758116170717123345952330712416337530", "price": "0.995", "size": "10.81", "side": "SELL", "timestamp": "1768475272811", "received_at": "2026-01-15T12:07:52.931138"}}
{"event_type": "price_change", "event_ts": "2026-01-15T12:07:53.419166", "ingestion_ts": "2026-01-15T12:08:42.168746", "market_id": "0xcab7ba4a9133cfd407d7e73e5757e5abbace413b59421527a31113406c97815c", "raw": {"market": "0xcab7ba4a9133cfd407d7e73e5757e5abbace413b59421527a31113406c97815c", "asset_id": "96361925776989336186111887920533578209326565663637092688733016597062311745569", "price": "0.006", "size": "127.41", "side": "BUY", "timestamp": "1768475273300", "received_at": "2026-01-15T12:07:53.419166"}}
{"event_type": "price_change", "event_ts": "2026-01-15T12:07:53.419166", "ingestion_ts": "2026-01-15T12:08:42.168746", "market_id": "0xcab7ba4a9133cfd407d7e73e5757e5abbace413b59421527a31113406c97815c", "raw": {"market": "0xcab7ba4a9133cfd407d7e73e5757e5abbace413b59421527a31113406c97815c", "asset_id": "20002636398944597965698652220992177552927816915094913583821579024925426590022", "price": "0.994", "size": "127.41", "side": "SELL", "timestamp": "1768475273300", "received_at": "2026-01-15T12:07:53.419166"}}
{"event_type": "price_change", "event_ts": "2026-01-15T12:07:53.419215", "ingestion_ts": "2026-01-15T12:08:42.168746", "market_id": "0xcab7ba4a9133cfd407d7e73e5757e5abbace413b59421527a31113406c97815c", "raw": {"market": "0xcab7ba4a9133cfd407d7e73e5757e5abbace413b59421527a31113406c97815c", "asset_id": "96361925776989336186111887920533578209326565663637092688733016597062311745569", "price": "0.009", "size": "812.25", "side": "BUY", "timestamp": "1768475273300", "received_at": "2026-01-15T12:07:53.419215"}}
{"event_type": "price_change", "event_ts": "2026-01-15T12:07:53.419215", "ingestion_ts": "2026-01-15T12:08:42.168746", "market_id": "0xcab7ba4a9133cfd407d7e73e5757e5abbace413b59421527a31113406c97815c", "raw": {"market": "0xcab7ba4a9133cfd407d7e73e5757e5abbace413b59421527a31113406c97815c", "asset_id": "20002636398944597965698652220992177552927816915094913583821579024925426590022", "price": "0.991", "size": "812.25", "side": "SELL", "timestamp": "1768475273300", "received_at": "2026-01-15T12:07:53.419215"}}
{"event_type": "price_change", "event_ts": "2026-01-15T12:07:54.079559", "ingestion_ts": "2026-01-15T12:08:42.168746", "market_id": "0xcab7ba4a9133cfd407d7e73e5757e5abbace413b59421527a31113406c97815c", "raw": {"market": "0xcab7ba4a9133cfd407d7e73e5757e5abbace413b59421527a31113406c97815c", "asset_id": "96361925776989336186111887920533578209326565663637092688733016597062311745569", "price": "0.006", "size": "136.51", "side": "BUY", "timestamp": "1768475273961", "received_at": "2026-01-15T12:07:54.079559"}}
{"event_type": "price_change", "event_ts": "2026-01-15T12:07:54.079559", "ingestion_ts": "2026-01-15T12:08:42.168746", "market_id": "0xcab7ba4a9133cfd407d7e73e5757e5abbace413b59421527a31113406c97815c", "raw": {"market": "0xcab7ba4a9133cfd407d7e73e5757e5abbace413b59421527a31113406c97815c", "asset_id": "20002636398944597965698652220992177552927816915094913583821579024925426590022", "price": "0.994", "size": "136.51", "side": "SELL", "timestamp": "1768475273961", "received_at": "2026-01-15T12:07:54.079559"}}
{"event_type": "price_change", "event_ts": "2026-01-15T12:07:54.082957", "ingestion_ts": "2026-01-15T12:08:42.168746", "market_id": "0xcab7ba4a9133cfd407d7e73e5757e5abbace413b59421527a31113406c97815c", "raw": {"market": "0xcab7ba4a9133cfd407d7e73e5757e5abbace413b59421527a31113406c97815c", "asset_id": "96361925776989336186111887920533578209326565663637092688733016597062311745569", "price": "0.009", "size": "818.33", "side": "BUY", "timestamp": "1768475273963", "received_at": "2026-01-15T12:07:54.082957"}}
{"event_type": "price_change", "event_ts": "2026-01-15T12:07:54.082957", "ingestion_ts": "2026-01-15T12:08:42.168746", "market_id": "0xcab7ba4a9133cfd407d7e73e5757e5abbace413b59421527a31113406c97815c", "raw": {"market": "0xcab7ba4a9133cfd407d7e73e5757e5abbace413b59421527a31113406c97815c", "asset_id": "20002636398944597965698652220992177552927816915094913583821579024925426590022", "price": "0.991", "size": "818.33", "side": "SELL", "timestamp": "1768475273963", "received_at": "2026-01-15T12:07:54.082957"}}
{"event_type": "price_change", "event_ts": "2026-01-15T12:07:54.843220", "ingestion_ts": "2026-01-15T12:08:42.168746", "market_id": "0xae5584fbb57f23c1c608d544b656f23d8bf12340cef70811cf31bb0cb4fc2115", "raw": {"market": "0xae5584fbb57f23c1c608d544b656f23d8bf12340cef70811cf31bb0cb4fc2115", "asset_id": "42278252558046940014991595990628759801692726198478046188873057685686228021663", "price": "0.5", "size": "11.85", "side": "BUY", "timestamp": "1768475274712", "received_at": "2026-01-15T12:07:54.843220"}}
{"event_type": "price_change", "event_ts": "2026-01-15T12:07:54.843220", "ingestion_ts": "2026-01-15T12:08:42.168746", "market_id": "0xae5584fbb57f23c1c608d544b656f23d8bf12340cef70811cf31bb0cb4fc2115", "raw": {"market": "0xae5584fbb57f23c1c608d544b656f23d8bf12340cef70811cf31bb0cb4fc2115", "asset_id": "28946595841244317705636126646676849578876740730186646421280828201004700559420", "price": "0.5", "size": "11.85", "side": "SELL", "timestamp": "1768475274712", "received_at": "2026-01-15T12:07:54.843220"}}
{"event_type": "price_change", "event_ts": "2026-01-15T12:07:55.015315", "ingestion_ts": "2026-01-15T12:08:42.168746", "market_id": "0xae5584fbb57f23c1c608d544b656f23d8bf12340cef70811cf31bb0cb4fc2115", "raw": {"market": "0xae5584fbb57f23c1c608d544b656f23d8bf12340cef70811cf31bb0cb4fc2115", "asset_id": "42278252558046940014991595990628759801692726198478046188873057685686228021663", "price": "0.352", "size": "0", "side": "BUY", "timestamp": "1768475274892", "received_at": "2026-01-15T12:07:55.015315"}}
{"event_type": "price_change", "event_ts": "2026-01-15T12:07:55.015315", "ingestion_ts": "2026-01-15T12:08:42.168746", "market_id": "0xae5584fbb57f23c1c608d544b656f23d8bf12340cef70811cf31bb0cb4fc2115", "raw": {"market": "0xae5584fbb57f23c1c608d544b656f23d8bf12340cef70811cf31bb0cb4fc2115", "asset_id": "28946595841244317705636126646676849578876740730186646421280828201004700559420", "price": "0.648", "size": "0", "side": "SELL", "timestamp": "1768475274892", "received_at": "2026-01-15T12:07:55.015315"}}
{"event_type": "price_change", "event_ts": "2026-01-15T12:07:55.145085", "ingestion_ts": "2026-01-15T12:08:42.168746", "market_id": "0x427bc4b40c09b3dcbc973747f0e4b079bed91b3e5a0aed5c36edd0f7591485f4", "raw": {"market": "0x427bc4b40c09b3dcbc973747f0e4b079bed91b3e5a0aed5c36edd0f7591485f4", "asset_id": "115669573443672055876643967408433138119481486650803218131873713375232186497057", "price": "0.002", "size": "41.05", "side": "BUY", "timestamp": "1768475275025", "received_at": "2026-01-15T12:07:55.145085"}}
{"event_type": "price_change", "event_ts": "2026-01-15T12:07:55.145085", "ingestion_ts": "2026-01-15T12:08:42.168746", "market_id": "0x427bc4b40c09b3dcbc973747f0e4b079bed91b3e5a0aed5c36edd0f7591485f4", "raw": {"market": "0x427bc4b40c09b3dcbc973747f0e4b079bed91b3e5a0aed5c36edd0f7591485f4", "asset_id": "86130975769502911188457673769190265049139877688522439001984850068234616395137", "price": "0.998", "size": "41.05", "side": "SELL", "timestamp": "1768475275025", "received_at": "2026-01-15T12:07:55.145085"}}
{"event_type": "price_change", "event_ts": "2026-01-15T12:07:55.184065", "ingestion_ts": "2026-01-15T12:08:42.168746", "market_id": "0xae5584fbb57f23c1c608d544b656f23d8bf12340cef70811cf31bb0cb4fc2115", "raw": {"market": "0xae5584fbb57f23c1c608d544b656f23d8bf12340cef70811cf31bb0cb4fc2115", "asset_id": "42278252558046940014991595990628759801692726198478046188873057685686228021663", "price": "0.021", "size": "0", "side": "BUY", "timestamp": "1768475275067", "received_at": "2026-01-15T12:07:55.184065"}}
{"event_type": "price_change", "event_ts": "2026-01-15T12:07:55.184065", "ingestion_ts": "2026-01-15T12:08:42.168746", "market_id": "0xae5584fbb57f23c1c608d544b656f23d8bf12340cef70811cf31bb0cb4fc2115", "raw": {"market": "0xae5584fbb57f23c1c608d544b656f23d8bf12340cef70811cf31bb0cb4fc2115", "asset_id": "28946595841244317705636126646676849578876740730186646421280828201004700559420", "price": "0.979", "size": "0", "side": "SELL", "timestamp": "1768475275067", "received_at": "2026-01-15T12:07:55.184065"}}
{"event_type": "price_change", "event_ts": "2026-01-15T12:07:55.419118", "ingestion_ts": "2026-01-15T12:08:42.168746", "market_id": "0xae5584fbb57f23c1c608d544b656f23d8bf12340cef70811cf31bb0cb4fc2115", "raw": {"market": "0xae5584fbb57f23c1c608d544b656f23d8bf12340cef70811cf31bb0cb4fc2115", "asset_id": "42278252558046940014991595990628759801692726198478046188873057685686228021663", "price": "0.021", "size": "175.82", "side": "BUY", "timestamp": "1768475275302", "received_at": "2026-01-15T12:07:55.419118"}}
{"event_type": "price_change", "event_ts": "2026-01-15T12:07:55.419118", "ingestion_ts": "2026-01-15T12:08:42.168746", "market_id": "0xae5584fbb57f23c1c608d544b656f23d8bf12340cef70811cf31bb0cb4fc2115", "raw": {"market": "0xae5584fbb57f23c1c608d544b656f23d8bf12340cef70811cf31bb0cb4fc2115", "asset_id": "28946595841244317705636126646676849578876740730186646421280828201004700559420", "price": "0.979", "size": "175.82", "side": "SELL", "timestamp": "1768475275302", "received_at": "2026-01-15T12:07:55.419118"}}
{"event_type": "price_change", "event_ts": "2026-01-15T12:07:55.579707", "ingestion_ts": "2026-01-15T12:08:42.168746", "market_id": "0x427bc4b40c09b3dcbc973747f0e4b079bed91b3e5a0aed5c36edd0f7591485f4", "raw": {"market": "0x427bc4b40c09b3dcbc973747f0e4b079bed91b3e5a0aed5c36edd0f7591485f4", "asset_id": "115669573443672055876643967408433138119481486650803218131873713375232186497057", "price": "0.002", "size": "59.23", "side": "BUY", "timestamp": "1768475275462", "received_at": "2026-01-15T12:07:55.579707"}}
{"event_type": "price_change", "event_ts": "2026-01-15T12:07:55.579707", "ingestion_ts": "2026-01-15T12:08:42.168746", "market_id": "0x427bc4b40c09b3dcbc973747f0e4b079bed91b3e5a0aed5c36edd0f7591485f4", "raw": {"market": "0x427bc4b40c09b3dcbc973747f0e4b079bed91b3e5a0aed5c36edd0f7591485f4", "asset_id": "86130975769502911188457673769190265049139877688522439001984850068234616395137", "price": "0.998", "size": "59.23", "side": "SELL", "timestamp": "1768475275462", "received_at": "2026-01-15T12:07:55.579707"}}
{"event_type": "price_change", "event_ts": "2026-01-15T12:07:55.623862", "ingestion_ts": "2026-01-15T12:08:42.168746", "market_id": "0xae5584fbb57f23c1c608d544b656f23d8bf12340cef70811cf31bb0cb4fc2115", "raw": {"market": "0xae5584fbb57f23c1c608d544b656f23d8bf12340cef70811cf31bb0cb4fc2115", "asset_id": "42278252558046940014991595990628759801692726198478046188873057685686228021663", "price": "0.042", "size": "0", "side": "BUY", "timestamp": "1768475275506", "received_at": "2026-01-15T12:07:55.623862"}}
{"event_type": "price_change", "event_ts": "2026-01-15T12:07:55.623862", "ingestion_ts": "2026-01-15T12:08:42.168746", "market_id": "0xae5584fbb57f23c1c608d544b656f23d8bf12340cef70811cf31bb0cb4fc2115", "raw": {"market": "0xae5584fbb57f23c1c608d544b656f23d8bf12340cef70811cf31bb0cb4fc2115", "asset_id": "28946595841244317705636126646676849578876740730186646421280828201004700559420", "price": "0.958", "size": "0", "side": "SELL", "timestamp": "1768475275506", "received_at": "2026-01-15T12:07:55.623862"}}
{"event_type": "price_change", "event_ts": "2026-01-15T12:07:55.844737", "ingestion_ts": "2026-01-15T12:08:42.168746", "market_id": "0xae5584fbb57f23c1c608d544b656f23d8bf12340cef70811cf31bb0cb4fc2115", "raw": {"market": "0xae5584fbb57f23c1c608d544b656f23d8bf12340cef70811cf31bb0cb4fc2115", "asset_id": "42278252558046940014991595990628759801692726198478046188873057685686228021663", "price": "0.042", "size": "87.91", "side": "BUY", "timestamp": "1768475275724", "received_at": "2026-01-15T12:07:55.844737"}}
{"event_type": "price_change", "event_ts": "2026-01-15T12:07:55.844737", "ingestion_ts": "2026-01-15T12:08:42.168746", "market_id": "0xae5584fbb57f23c1c608d544b656f23d8bf12340cef70811cf31bb0cb4fc2115", "raw": {"market": "0xae5584fbb57f23c1c608d544b656f23d8bf12340cef70811cf31bb0cb4fc2115", "asset_id": "28946595841244317705636126646676849578876740730186646421280828201004700559420", "price": "0.958", "size": "87.91", "side": "SELL", "timestamp": "1768475275724", "received_at": "2026-01-15T12:07:55.844737"}}
{"event_type": "price_change", "event_ts": "2026-01-15T12:07:56.061652", "ingestion_ts": "2026-01-15T12:08:42.168746", "market_id": "0xae5584fbb57f23c1c608d544b656f23d8bf12340cef70811cf31bb0cb4fc2115", "raw": {"market": "0xae5584fbb57f23c1c608d544b656f23d8bf12340cef70811cf31bb0cb4fc2115", "asset_id": "42278252558046940014991595990628759801692726198478046188873057685686228021663", "price": "0.051", "size": "0", "side": "BUY", "timestamp": "1768475275935", "received_at": "2026-01-15T12:07:56.061652"}}
{"event_type": "price_change", "event_ts": "2026-01-15T12:07:56.061652", "ingestion_ts": "2026-01-15T12:08:42.168746", "market_id": "0xae5584fbb57f23c1c608d544b656f23d8bf12340cef70811cf31bb0cb4fc2115", "raw": {"market": "0xae5584fbb57f23c1c608d544b656f23d8bf12340cef70811cf31bb0cb4fc2115", "asset_id": "28946595841244317705636126646676849578876740730186646421280828201004700559420", "price": "0.949", "size": "0", "side": "SELL", "timestamp": "1768475275935", "received_at": "2026-01-15T12:07:56.061652"}}
{"event_type": "price_change", "event_ts": "2026-01-15T12:07:56.258715", "ingestion_ts": "2026-01-15T12:08:42.168746", "market_id": "0xc0e6b917320a47228fb96e3b5ae0e5c93773a5ae2662ae4e1f37807cfe47ce98", "raw": {"market": "0xc0e6b917320a47228fb96e3b5ae0e5c93773a5ae2662ae4e1f37807cfe47ce98", "asset_id": "58656358377246279051017109359677190749228949103591068167284263961542487110215", "price": "0.005", "size": "2.98", "side": "BUY", "timestamp": "1768475276113", "received_at": "2026-01-15T12:07:56.258715"}}
{"event_type": "price_change", "event_ts": "2026-01-15T12:07:56.258715", "ingestion_ts": "2026-01-15T12:08:42.168746", "market_id": "0xc0e6b917320a47228fb96e3b5ae0e5c93773a5ae2662ae4e1f37807cfe47ce98", "raw": {"market": "0xc0e6b917320a47228fb96e3b5ae0e5c93773a5ae2662ae4e1f37807cfe47ce98", "asset_id": "81647294538046680798858716589766492074338758116170717123345952330712416337530", "price": "0.995", "size": "2.98", "side": "SELL", "timestamp": "1768475276113", "received_at": "2026-01-15T12:07:56.258715"}}
{"event_type": "price_change", "event_ts": "2026-01-15T12:07:56.258755", "ingestion_ts": "2026-01-15T12:08:42.168746", "market_id": "0xc0e6b917320a47228fb96e3b5ae0e5c93773a5ae2662ae4e1f37807cfe47ce98", "raw": {"market": "0xc0e6b917320a47228fb96e3b5ae0e5c93773a5ae2662ae4e1f37807cfe47ce98", "asset_id": "58656358377246279051017109359677190749228949103591068167284263961542487110215", "price": "0.006", "size": "0", "side": "BUY", "timestamp": "1768475276113", "received_at": "2026-01-15T12:07:56.258755"}}
{"event_type": "price_change", "event_ts": "2026-01-15T12:07:56.258755", "ingestion_ts": "2026-01-15T12:08:42.168746", "market_id": "0xc0e6b917320a47228fb96e3b5ae0e5c93773a5ae2662ae4e1f37807cfe47ce98", "raw": {"market": "0xc0e6b917320a47228fb96e3b5ae0e5c93773a5ae2662ae4e1f37807cfe47ce98", "asset_id": "81647294538046680798858716589766492074338758116170717123345952330712416337530", "price": "0.994", "size": "0", "side": "SELL", "timestamp": "1768475276113", "received_at": "2026-01-15T12:07:56.258755"}}
{"event_type": "price_change", "event_ts": "2026-01-15T12:07:56.290034", "ingestion_ts": "2026-01-15T12:08:42.168746", "market_id": "0xae5584fbb57f23c1c608d544b656f23d8bf12340cef70811cf31bb0cb4fc2115", "raw": {"market": "0xae5584fbb57f23c1c608d544b656f23d8bf12340cef70811cf31bb0cb4fc2115", "asset_id": "42278252558046940014991595990628759801692726198478046188873057685686228021663", "price": "0.051", "size": "72.39", "side": "BUY", "timestamp": "1768475276157", "received_at": "2026-01-15T12:07:56.290034"}}
{"event_type": "price_change", "event_ts": "2026-01-15T12:07:56.290034", "ingestion_ts": "2026-01-15T12:08:42.168746", "market_id": "0xae5584fbb57f23c1c608d544b656f23d8bf12340cef70811cf31bb0cb4fc2115", "raw": {"market": "0xae5584fbb57f23c1c608d544b656f23d8bf12340cef70811cf31bb0cb4fc2115", "asset_id": "28946595841244317705636126646676849578876740730186646421280828201004700559420", "price": "0.949", "size": "72.39", "side": "SELL", "timestamp": "1768475276157", "received_at": "2026-01-15T12:07:56.290034"}}
{"event_type": "price_change", "event_ts": "2026-01-15T12:07:56.483390", "ingestion_ts": "2026-01-15T12:08:42.168746", "market_id": "0xae5584fbb57f23c1c608d544b656f23d8bf12340cef70811cf31bb0cb4fc2115", "raw": {"market": "0xae5584fbb57f23c1c608d544b656f23d8bf12340cef70811cf31bb0cb4fc2115", "asset_id": "42278252558046940014991595990628759801692726198478046188873057685686228021663", "price": "0.072", "size": "0", "side": "BUY", "timestamp": "1768475276363", "received_at": "2026-01-15T12:07:56.483390"}}
{"event_type": "price_change", "event_ts": "2026-01-15T12:07:56.483390", "ingestion_ts": "2026-01-15T12:08:42.168746", "market_id": "0xae5584fbb57f23c1c608d544b656f23d8bf12340cef70811cf31bb0cb4fc2115", "raw": {"market": "0xae5584fbb57f23c1c608d544b656f23d8bf12340cef70811cf31bb0cb4fc2115", "asset_id": "28946595841244317705636126646676849578876740730186646421280828201004700559420", "price": "0.928", "size": "0", "side": "SELL", "timestamp": "1768475276363", "received_at": "2026-01-15T12:07:56.483390"}}
{"event_type": "price_change", "event_ts": "2026-01-15T12:07:56.546581", "ingestion_ts": "2026-01-15T12:08:42.168746", "market_id": "0xc0e6b917320a47228fb96e3b5ae0e5c93773a5ae2662ae4e1f37807cfe47ce98", "raw": {"market": "0xc0e6b917320a47228fb96e3b5ae0e5c93773a5ae2662ae4e1f37807cfe47ce98", "asset_id": "58656358377246279051017109359677190749228949103591068167284263961542487110215", "price": "0.007", "size": "6.38", "side": "BUY", "timestamp": "1768475276425", "received_at": "2026-01-15T12:07:56.546581"}}
{"event_type": "price_change", "event_ts": "2026-01-15T12:07:56.546581", "ingestion_ts": "2026-01-15T12:08:42.168746", "market_id": "0xc0e6b917320a47228fb96e3b5ae0e5c93773a5ae2662ae4e1f37807cfe47ce98", "raw": {"market": "0xc0e6b917320a47228fb96e3b5ae0e5c93773a5ae2662ae4e1f37807cfe47ce98", "asset_id": "81647294538046680798858716589766492074338758116170717123345952330712416337530", "price": "0.993", "size": "6.38", "side": "SELL", "timestamp": "1768475276425", "received_at": "2026-01-15T12:07:56.546581"}}
{"event_type": "price_change", "event_ts": "2026-01-15T12:07:56.548658", "ingestion_ts": "2026-01-15T12:08:42.168746", "market_id": "0xc0e6b917320a47228fb96e3b5ae0e5c93773a5ae2662ae4e1f37807cfe47ce98", "raw": {"market": "0xc0e6b917320a47228fb96e3b5ae0e5c93773a5ae2662ae4e1f37807cfe47ce98", "asset_id": "58656358377246279051017109359677190749228949103591068167284263961542487110215", "price": "0.006", "size": "7.74", "side": "BUY", "timestamp": "1768475276426", "received_at": "2026-01-15T12:07:56.548658"}}
{"event_type": "price_change", "event_ts": "2026-01-15T12:07:56.548658", "ingestion_ts": "2026-01-15T12:08:42.168746", "market_id": "0xc0e6b917320a47228fb96e3b5ae0e5c93773a5ae2662ae4e1f37807cfe47ce98", "raw": {"market": "0xc0e6b917320a47228fb96e3b5ae0e5c93773a5ae2662ae4e1f37807cfe47ce98", "asset_id": "81647294538046680798858716589766492074338758116170717123345952330712416337530", "price": "0.994", "size": "7.74", "side": "SELL", "timestamp": "1768475276426", "received_at": "2026-01-15T12:07:56.548658"}}
{"event_type": "price_change", "event_ts": "2026-01-15T12:07:56.696650", "ingestion_ts": "2026-01-15T12:08:42.168746", "market_id": "0xae5584fbb57f23c1c608d544b656f23d8bf12340cef70811cf31bb0cb4fc2115", "raw": {"market": "0xae5584fbb57f23c1c608d544b656f23d8bf12340cef70811cf31bb0cb4fc2115", "asset_id": "42278252558046940014991595990628759801692726198478046188873057685686228021663", "price": "0.072", "size": "51.28", "side": "BUY", "timestamp": "1768475276573", "received_at": "2026-01-15T12:07:56.696650"}}
{"event_type": "price_change", "event_ts": "2026-01-15T12:07:56.696650", "ingestion_ts": "2026-01-15T12:08:42.168746", "market_id": "0xae5584fbb57f23c1c608d544b656f23d8bf12340cef70811cf31bb0cb4fc2115", "raw": {"market": "0xae5584fbb57f23c1c608d544b656f23d8bf12340cef70811cf31bb0cb4fc2115", "asset_id": "28946595841244317705636126646676849578876740730186646421280828201004700559420", "price": "0.928", "size": "51.28", "side": "SELL", "timestamp": "1768475276573", "received_at": "2026-01-15T12:07:56.696650"}}
{"event_type": "price_change", "event_ts": "2026-01-15T12:07:56.896381", "ingestion_ts": "2026-01-15T12:08:42.168746", "market_id": "0xae5584fbb57f23c1c608d544b656f23d8bf12340cef70811cf31bb0cb4fc2115", "raw": {"market": "0xae5584fbb57f23c1c608d544b656f23d8bf12340cef70811cf31bb0cb4fc2115", "asset_id": "42278252558046940014991595990628759801692726198478046188873057685686228021663", "price": "0.103", "size": "0", "side": "BUY", "timestamp": "1768475276777", "received_at": "2026-01-15T12:07:56.896381"}}
{"event_type": "price_change", "event_ts": "2026-01-15T12:07:56.896381", "ingestion_ts": "2026-01-15T12:08:42.168746", "market_id": "0xae5584fbb57f23c1c608d544b656f23d8bf12340cef70811cf31bb0cb4fc2115", "raw": {"market": "0xae5584fbb57f23c1c608d544b656f23d8bf12340cef70811cf31bb0cb4fc2115", "asset_id": "28946595841244317705636126646676849578876740730186646421280828201004700559420", "price": "0.897", "size": "0", "side": "SELL", "timestamp": "1768475276777", "received_at": "2026-01-15T12:07:56.896381"}}
{"event_type": "price_change", "event_ts": "2026-01-15T12:07:57.072240", "ingestion_ts": "2026-01-15T12:08:42.168746", "market_id": "0xcab7ba4a9133cfd407d7e73e5757e5abbace413b59421527a31113406c97815c", "raw": {"market": "0xcab7ba4a9133cfd407d7e73e5757e5abbace413b59421527a31113406c97815c", "asset_id": "96361925776989336186111887920533578209326565663637092688733016597062311745569", "price": "0.006", "size": "127.41", "side": "BUY", "timestamp": "1768475276953", "received_at": "2026-01-15T12:07:57.072240"}}
{"event_type": "price_change", "event_ts": "2026-01-15T12:07:57.072240", "ingestion_ts": "2026-01-15T12:08:42.168746", "market_id": "0xcab7ba4a9133cfd407d7e73e5757e5abbace413b59421527a31113406c97815c", "raw": {"market": "0xcab7ba4a9133cfd407d7e73e5757e5abbace413b59421527a31113406c97815c", "asset_id": "20002636398944597965698652220992177552927816915094913583821579024925426590022", "price": "0.994", "size": "127.41", "side": "SELL", "timestamp": "1768475276953", "received_at": "2026-01-15T12:07:57.072240"}}
{"event_type": "price_change", "event_ts": "2026-01-15T12:07:57.072292", "ingestion_ts": "2026-01-15T12:08:42.168746", "market_id": "0xcab7ba4a9133cfd407d7e73e5757e5abbace413b59421527a31113406c97815c", "raw": {"market": "0xcab7ba4a9133cfd407d7e73e5757e5abbace413b59421527a31113406c97815c", "asset_id": "96361925776989336186111887920533578209326565663637092688733016597062311745569", "price": "0.009", "size": "812.25", "side": "BUY", "timestamp": "1768475276953", "received_at": "2026-01-15T12:07:57.072292"}}
{"event_type": "price_change", "event_ts": "2026-01-15T12:07:57.072292", "ingestion_ts": "2026-01-15T12:08:42.168746", "market_id": "0xcab7ba4a9133cfd407d7e73e5757e5abbace413b59421527a31113406c97815c", "raw": {"market": "0xcab7ba4a9133cfd407d7e73e5757e5abbace413b59421527a31113406c97815c", "asset_id": "20002636398944597965698652220992177552927816915094913583821579024925426590022", "price": "0.991", "size": "812.25", "side": "SELL", "timestamp": "1768475276953", "received_at": "2026-01-15T12:07:57.072292"}}
{"event_type": "price_change", "event_ts": "2026-01-15T12:07:57.142125", "ingestion_ts": "2026-01-15T12:08:42.168746", "market_id": "0xae5584fbb57f23c1c608d544b656f23d8bf12340cef70811cf31bb0cb4fc2115", "raw": {"market": "0xae5584fbb57f23c1c608d544b656f23d8bf12340cef70811cf31bb0cb4fc2115", "asset_id": "42278252558046940014991595990628759801692726198478046188873057685686228021663", "price": "0.103", "size": "35.84", "side": "BUY", "timestamp": "1768475277012", "received_at": "2026-01-15T12:07:57.142125"}}
{"event_type": "price_change", "event_ts": "2026-01-15T12:07:57.142125", "ingestion_ts": "2026-01-15T12:08:42.168746", "market_id": "0xae5584fbb57f23c1c608d544b656f23d8bf12340cef70811cf31bb0cb4fc2115", "raw": {"market": "0xae5584fbb57f23c1c608d544b656f23d8bf12340cef70811cf31bb0cb4fc2115", "asset_id": "28946595841244317705636126646676849578876740730186646421280828201004700559420", "price": "0.897", "size": "35.84", "side": "SELL", "timestamp": "1768475277012", "received_at": "2026-01-15T12:07:57.142125"}}
{"event_type": "price_change", "event_ts": "2026-01-15T12:07:57.355360", "ingestion_ts": "2026-01-15T12:08:42.168746", "market_id": "0xae5584fbb57f23c1c608d544b656f23d8bf12340cef70811cf31bb0cb4fc2115", "raw": {"market": "0xae5584fbb57f23c1c608d544b656f23d8bf12340cef70811cf31bb0cb4fc2115", "asset_id": "42278252558046940014991595990628759801692726198478046188873057685686228021663", "price": "0.116", "size": "0", "side": "BUY", "timestamp": "1768475277222", "received_at": "2026-01-15T12:07:57.355360"}}
{"event_type": "price_change", "event_ts": "2026-01-15T12:07:57.355360", "ingestion_ts": "2026-01-15T12:08:42.168746", "market_id": "0xae5584fbb57f23c1c608d544b656f23d8bf12340cef70811cf31bb0cb4fc2115", "raw": {"market": "0xae5584fbb57f23c1c608d544b656f23d8bf12340cef70811cf31bb0cb4fc2115", "asset_id": "28946595841244317705636126646676849578876740730186646421280828201004700559420", "price": "0.884", "size": "0", "side": "SELL", "timestamp": "1768475277222", "received_at": "2026-01-15T12:07:57.355360"}}
{"event_type": "price_change", "event_ts": "2026-01-15T12:07:57.546580", "ingestion_ts": "2026-01-15T12:08:42.168746", "market_id": "0xae5584fbb57f23c1c608d544b656f23d8bf12340cef70811cf31bb0cb4fc2115", "raw": {"market": "0xae5584fbb57f23c1c608d544b656f23d8bf12340cef70811cf31bb0cb4fc2115", "asset_id": "42278252558046940014991595990628759801692726198478046188873057685686228021663", "price": "0.116", "size": "31.83", "side": "BUY", "timestamp": "1768475277430", "received_at": "2026-01-15T12:07:57.546580"}}
{"event_type": "price_change", "event_ts": "2026-01-15T12:07:57.546580", "ingestion_ts": "2026-01-15T12:08:42.168746", "market_id": "0xae5584fbb57f23c1c608d544b656f23d8bf12340cef70811cf31bb0cb4fc2115", "raw": {"market": "0xae5584fbb57f23c1c608d544b656f23d8bf12340cef70811cf31bb0cb4fc2115", "asset_id": "28946595841244317705636126646676849578876740730186646421280828201004700559420", "price": "0.884", "size": "31.83", "side": "SELL", "timestamp": "1768475277430", "received_at": "2026-01-15T12:07:57.546580"}}
{"event_type": "price_change", "event_ts": "2026-01-15T12:07:57.765046", "ingestion_ts": "2026-01-15T12:08:42.168746", "market_id": "0xae5584fbb57f23c1c608d544b656f23d8bf12340cef70811cf31bb0cb4fc2115", "raw": {"market": "0xae5584fbb57f23c1c608d544b656f23d8bf12340cef70811cf31bb0cb4fc2115", "asset_id": "42278252558046940014991595990628759801692726198478046188873057685686228021663", "price": "0.151", "size": "0", "side": "BUY", "timestamp": "1768475277646", "received_at": "2026-01-15T12:07:57.765046"}}
{"event_type": "price_change", "event_ts": "2026-01-15T12:07:57.765046", "ingestion_ts": "2026-01-15T12:08:42.168746", "market_id": "0xae5584fbb57f23c1c608d544b656f23d8bf12340cef70811cf31bb0cb4fc2115", "raw": {"market": "0xae5584fbb57f23c1c608d544b656f23d8bf12340cef70811cf31bb0cb4fc2115", "asset_id": "28946595841244317705636126646676849578876740730186646421280828201004700559420", "price": "0.849", "size": "0", "side": "SELL", "timestamp": "1768475277646", "received_at": "2026-01-15T12:07:57.765046"}}
{"event_type": "price_change", "event_ts": "2026-01-15T12:07:58.005680", "ingestion_ts": "2026-01-15T12:08:42.168746", "market_id": "0xae5584fbb57f23c1c608d544b656f23d8bf12340cef70811cf31bb0cb4fc2115", "raw": {"market": "0xae5584fbb57f23c1c608d544b656f23d8bf12340cef70811cf31bb0cb4fc2115", "asset_id": "42278252558046940014991595990628759801692726198478046188873057685686228021663", "price": "0.151", "size": "24.45", "side": "BUY", "timestamp": "1768475277875", "received_at": "2026-01-15T12:07:58.005680"}}
{"event_type": "price_change", "event_ts": "2026-01-15T12:07:58.005680", "ingestion_ts": "2026-01-15T12:08:42.168746", "market_id": "0xae5584fbb57f23c1c608d544b656f23d8bf12340cef70811cf31bb0cb4fc2115", "raw": {"market": "0xae5584fbb57f23c1c608d544b656f23d8bf12340cef70811cf31bb0cb4fc2115", "asset_id": "28946595841244317705636126646676849578876740730186646421280828201004700559420", "price": "0.849", "size": "24.45", "side": "SELL", "timestamp": "1768475277875", "received_at": "2026-01-15T12:07:58.005680"}}
{"event_type": "price_change", "event_ts": "2026-01-15T12:07:58.005715", "ingestion_ts": "2026-01-15T12:08:42.168746", "market_id": "0xcab7ba4a9133cfd407d7e73e5757e5abbace413b59421527a31113406c97815c", "raw": {"market": "0xcab7ba4a9133cfd407d7e73e5757e5abbace413b59421527a31113406c97815c", "asset_id": "96361925776989336186111887920533578209326565663637092688733016597062311745569", "price": "0.009", "size": "818.33", "side": "BUY", "timestamp": "1768475277876", "received_at": "2026-01-15T12:07:58.005715"}}
{"event_type": "price_change", "event_ts": "2026-01-15T12:07:58.005715", "ingestion_ts": "2026-01-15T12:08:42.168746", "market_id": "0xcab7ba4a9133cfd407d7e73e5757e5abbace413b59421527a31113406c97815c", "raw": {"market": "0xcab7ba4a9133cfd407d7e73e5757e5abbace413b59421527a31113406c97815c", "asset_id": "20002636398944597965698652220992177552927816915094913583821579024925426590022", "price": "0.991", "size": "818.33", "side": "SELL", "timestamp": "1768475277876", "received_at": "2026-01-15T12:07:58.005715"}}
{"event_type": "price_change", "event_ts": "2026-01-15T12:07:58.005726", "ingestion_ts": "2026-01-15T12:08:42.168746", "market_id": "0xcab7ba4a9133cfd407d7e73e5757e5abbace413b59421527a31113406c97815c", "raw": {"market": "0xcab7ba4a9133cfd407d7e73e5757e5abbace413b59421527a31113406c97815c", "asset_id": "96361925776989336186111887920533578209326565663637092688733016597062311745569", "price": "0.006", "size": "136.51", "side": "BUY", "timestamp": "1768475277876", "received_at": "2026-01-15T12:07:58.005726"}}
{"event_type": "price_change", "event_ts": "2026-01-15T12:07:58.005726", "ingestion_ts": "2026-01-15T12:08:42.168746", "market_id": "0xcab7ba4a9133cfd407d7e73e5757e5abbace413b59421527a31113406c97815c", "raw": {"market": "0xcab7ba4a9133cfd407d7e73e5757e5abbace413b59421527a31113406c97815c", "asset_id": "20002636398944597965698652220992177552927816915094913583821579024925426590022", "price": "0.994", "size": "136.51", "side": "SELL", "timestamp": "1768475277876", "received_at": "2026-01-15T12:07:58.005726"}}
{"event_type": "price_change", "event_ts": "2026-01-15T12:07:58.188819", "ingestion_ts": "2026-01-15T12:08:42.168746", "market_id": "0xae5584fbb57f23c1c608d544b656f23d8bf12340cef70811cf31bb0cb4fc2115", "raw": {"market": "0xae5584fbb57f23c1c608d544b656f23d8bf12340cef70811cf31bb0cb4fc2115", "asset_id": "42278252558046940014991595990628759801692726198478046188873057685686228021663", "price": "0.169", "size": "0", "side": "BUY", "timestamp": "1768475278069", "received_at": "2026-01-15T12:07:58.188819"}}
{"event_type": "price_change", "event_ts": "2026-01-15T12:07:58.188819", "ingestion_ts": "2026-01-15T12:08:42.168746", "market_id": "0xae5584fbb57f23c1c608d544b656f23d8bf12340cef70811cf31bb0cb4fc2115", "raw": {"market": "0xae5584fbb57f23c1c608d544b656f23d8bf12340cef70811cf31bb0cb4fc2115", "asset_id": "28946595841244317705636126646676849578876740730186646421280828201004700559420", "price": "0.831", "size": "0", "side": "SELL", "timestamp": "1768475278069", "received_at": "2026-01-15T12:07:58.188819"}}
{"event_type": "price_change", "event_ts": "2026-01-15T12:07:58.425875", "ingestion_ts": "2026-01-15T12:08:42.168746", "market_id": "0xae5584fbb57f23c1c608d544b656f23d8bf12340cef70811cf31bb0cb4fc2115", "raw": {"market": "0xae5584fbb57f23c1c608d544b656f23d8bf12340cef70811cf31bb0cb4fc2115", "asset_id": "42278252558046940014991595990628759801692726198478046188873057685686228021663", "price": "0.169", "size": "21.84", "side": "BUY", "timestamp": "1768475278308", "received_at": "2026-01-15T12:07:58.425875"}}
{"event_type": "price_change", "event_ts": "2026-01-15T12:07:58.425875", "ingestion_ts": "2026-01-15T12:08:42.168746", "market_id": "0xae5584fbb57f23c1c608d544b656f23d8bf12340cef70811cf31bb0cb4fc2115", "raw": {"market": "0xae5584fbb57f23c1c608d544b656f23d8bf12340cef70811cf31bb0cb4fc2115", "asset_id": "28946595841244317705636126646676849578876740730186646421280828201004700559420", "price": "0.831", "size": "21.84", "side": "SELL", "timestamp": "1768475278308", "received_at": "2026-01-15T12:07:58.425875"}}
{"event_type": "price_change", "event_ts": "2026-01-15T12:07:58.653185", "ingestion_ts": "2026-01-15T12:08:42.168746", "market_id": "0xae5584fbb57f23c1c608d544b656f23d8bf12340cef70811cf31bb0cb4fc2115", "raw": {"market": "0xae5584fbb57f23c1c608d544b656f23d8bf12340cef70811cf31bb0cb4fc2115", "asset_id": "42278252558046940014991595990628759801692726198478046188873057685686228021663", "price": "0.215", "size": "0", "side": "BUY", "timestamp": "1768475278534", "received_at": "2026-01-15T12:07:58.653185"}}
{"event_type": "price_change", "event_ts": "2026-01-15T12:07:58.653185", "ingestion_ts": "2026-01-15T12:08:42.168746", "market_id": "0xae5584fbb57f23c1c608d544b656f23d8bf12340cef70811cf31bb0cb4fc2115", "raw": {"market": "0xae5584fbb57f23c1c608d544b656f23d8bf12340cef70811cf31bb0cb4fc2115", "asset_id": "28946595841244317705636126646676849578876740730186646421280828201004700559420", "price": "0.785", "size": "0", "side": "SELL", "timestamp": "1768475278534", "received_at": "2026-01-15T12:07:58.653185"}}
{"event_type": "price_change", "event_ts": "2026-01-15T12:07:58.888862", "ingestion_ts": "2026-01-15T12:08:42.168746", "market_id": "0xae5584fbb57f23c1c608d544b656f23d8bf12340cef70811cf31bb0cb4fc2115", "raw": {"market": "0xae5584fbb57f23c1c608d544b656f23d8bf12340cef70811cf31bb0cb4fc2115", "asset_id": "42278252558046940014991595990628759801692726198478046188873057685686228021663", "price": "0.215", "size": "17.17", "side": "BUY", "timestamp": "1768475278771", "received_at": "2026-01-15T12:07:58.888862"}}
{"event_type": "price_change", "event_ts": "2026-01-15T12:07:58.888862", "ingestion_ts": "2026-01-15T12:08:42.168746", "market_id": "0xae5584fbb57f23c1c608d544b656f23d8bf12340cef70811cf31bb0cb4fc2115", "raw": {"market": "0xae5584fbb57f23c1c608d544b656f23d8bf12340cef70811cf31bb0cb4fc2115", "asset_id": "28946595841244317705636126646676849578876740730186646421280828201004700559420", "price": "0.785", "size": "17.17", "side": "SELL", "timestamp": "1768475278771", "received_at": "2026-01-15T12:07:58.888862"}}
{"event_type": "price_change", "event_ts": "2026-01-15T12:07:59.079253", "ingestion_ts": "2026-01-15T12:08:42.168746", "market_id": "0xae5584fbb57f23c1c608d544b656f23d8bf12340cef70811cf31bb0cb4fc2115", "raw": {"market": "0xae5584fbb57f23c1c608d544b656f23d8bf12340cef70811cf31bb0cb4fc2115", "asset_id": "42278252558046940014991595990628759801692726198478046188873057685686228021663", "price": "0.256", "size": "0", "side": "BUY", "timestamp": "1768475278961", "received_at": "2026-01-15T12:07:59.079253"}}
{"event_type": "price_change", "event_ts": "2026-01-15T12:07:59.079253", "ingestion_ts": "2026-01-15T12:08:42.168746", "market_id": "0xae5584fbb57f23c1c608d544b656f23d8bf12340cef70811cf31bb0cb4fc2115", "raw": {"market": "0xae5584fbb57f23c1c608d544b656f23d8bf12340cef70811cf31bb0cb4fc2115", "asset_id": "28946595841244317705636126646676849578876740730186646421280828201004700559420", "price": "0.744", "size": "0", "side": "SELL", "timestamp": "1768475278961", "received_at": "2026-01-15T12:07:59.079253"}}
{"event_type": "price_change", "event_ts": "2026-01-15T12:07:59.116956", "ingestion_ts": "2026-01-15T12:08:42.168746", "market_id": "0x427bc4b40c09b3dcbc973747f0e4b079bed91b3e5a0aed5c36edd0f7591485f4", "raw": {"market": "0x427bc4b40c09b3dcbc973747f0e4b079bed91b3e5a0aed5c36edd0f7591485f4", "asset_id": "115669573443672055876643967408433138119481486650803218131873713375232186497057", "price": "0.002", "size": "41.05", "side": "BUY", "timestamp": "1768475278999", "received_at": "2026-01-15T12:07:59.116956"}}
{"event_type": "price_change", "event_ts": "2026-01-15T12:07:59.116956", "ingestion_ts": "2026-01-15T12:08:42.168746", "market_id": "0x427bc4b40c09b3dcbc973747f0e4b079bed91b3e5a0aed5c36edd0f7591485f4", "raw": {"market": "0x427bc4b40c09b3dcbc973747f0e4b079bed91b3e5a0aed5c36edd0f7591485f4", "asset_id": "86130975769502911188457673769190265049139877688522439001984850068234616395137", "price": "0.998", "size": "41.05", "side": "SELL", "timestamp": "1768475278999", "received_at": "2026-01-15T12:07:59.116956"}}
{"event_type": "price_change", "event_ts": "2026-01-15T12:07:59.285451", "ingestion_ts": "2026-01-15T12:08:42.168746", "market_id": "0xae5584fbb57f23c1c608d544b656f23d8bf12340cef70811cf31bb0cb4fc2115", "raw": {"market": "0xae5584fbb57f23c1c608d544b656f23d8bf12340cef70811cf31bb0cb4fc2115", "asset_id": "42278252558046940014991595990628759801692726198478046188873057685686228021663", "price": "0.256", "size": "14.42", "side": "BUY", "timestamp": "1768475279169", "received_at": "2026-01-15T12:07:59.285451"}}
{"event_type": "price_change", "event_ts": "2026-01-15T12:07:59.285451", "ingestion_ts": "2026-01-15T12:08:42.168746", "market_id": "0xae5584fbb57f23c1c608d544b656f23d8bf12340cef70811cf31bb0cb4fc2115", "raw": {"market": "0xae5584fbb57f23c1c608d544b656f23d8bf12340cef70811cf31bb0cb4fc2115", "asset_id": "28946595841244317705636126646676849578876740730186646421280828201004700559420", "price": "0.744", "size": "14.42", "side": "SELL", "timestamp": "1768475279169", "received_at": "2026-01-15T12:07:59.285451"}}
{"event_type": "price_change", "event_ts": "2026-01-15T12:07:59.503512", "ingestion_ts": "2026-01-15T12:08:42.168746", "market_id": "0xae5584fbb57f23c1c608d544b656f23d8bf12340cef70811cf31bb0cb4fc2115", "raw": {"market": "0xae5584fbb57f23c1c608d544b656f23d8bf12340cef70811cf31bb0cb4fc2115", "asset_id": "42278252558046940014991595990628759801692726198478046188873057685686228021663", "price": "0.3", "size": "59.91", "side": "BUY", "timestamp": "1768475279386", "received_at": "2026-01-15T12:07:59.503512"}}
{"event_type": "price_change", "event_ts": "2026-01-15T12:07:59.503512", "ingestion_ts": "2026-01-15T12:08:42.168746", "market_id": "0xae5584fbb57f23c1c608d544b656f23d8bf12340cef70811cf31bb0cb4fc2115", "raw": {"market": "0xae5584fbb57f23c1c608d544b656f23d8bf12340cef70811cf31bb0cb4fc2115", "asset_id": "28946595841244317705636126646676849578876740730186646421280828201004700559420", "price": "0.7", "size": "59.91", "side": "SELL", "timestamp": "1768475279386", "received_at": "2026-01-15T12:07:59.503512"}}
{"event_type": "price_change", "event_ts": "2026-01-15T12:07:59.520727", "ingestion_ts": "2026-01-15T12:08:42.168746", "market_id": "0x427bc4b40c09b3dcbc973747f0e4b079bed91b3e5a0aed5c36edd0f7591485f4", "raw": {"market": "0x427bc4b40c09b3dcbc973747f0e4b079bed91b3e5a0aed5c36edd0f7591485f4", "asset_id": "115669573443672055876643967408433138119481486650803218131873713375232186497057", "price": "0.002", "size": "59.23", "side": "BUY", "timestamp": "1768475279404", "received_at": "2026-01-15T12:07:59.520727"}}
{"event_type": "price_change", "event_ts": "2026-01-15T12:07:59.520727", "ingestion_ts": "2026-01-15T12:08:42.168746", "market_id": "0x427bc4b40c09b3dcbc973747f0e4b079bed91b3e5a0aed5c36edd0f7591485f4", "raw": {"market": "0x427bc4b40c09b3dcbc973747f0e4b079bed91b3e5a0aed5c36edd0f7591485f4", "asset_id": "86130975769502911188457673769190265049139877688522439001984850068234616395137", "price": "0.998", "size": "59.23", "side": "SELL", "timestamp": "1768475279404", "received_at": "2026-01-15T12:07:59.520727"}}
{"event_type": "price_change", "event_ts": "2026-01-15T12:07:59.594119", "ingestion_ts": "2026-01-15T12:08:42.168746", "market_id": "0xcab7ba4a9133cfd407d7e73e5757e5abbace413b59421527a31113406c97815c", "raw": {"market": "0xcab7ba4a9133cfd407d7e73e5757e5abbace413b59421527a31113406c97815c", "asset_id": "96361925776989336186111887920533578209326565663637092688733016597062311745569", "price": "0.006", "size": "127.41", "side": "BUY", "timestamp": "1768475279468", "received_at": "2026-01-15T12:07:59.594119"}}
{"event_type": "price_change", "event_ts": "2026-01-15T12:07:59.594119", "ingestion_ts": "2026-01-15T12:08:42.168746", "market_id": "0xcab7ba4a9133cfd407d7e73e5757e5abbace413b59421527a31113406c97815c", "raw": {"market": "0xcab7ba4a9133cfd407d7e73e5757e5abbace413b59421527a31113406c97815c", "asset_id": "20002636398944597965698652220992177552927816915094913583821579024925426590022", "price": "0.994", "size": "127.41", "side": "SELL", "timestamp": "1768475279468", "received_at": "2026-01-15T12:07:59.594119"}}
{"event_type": "price_change", "event_ts": "2026-01-15T12:07:59.594193", "ingestion_ts": "2026-01-15T12:08:42.168746", "market_id": "0xcab7ba4a9133cfd407d7e73e5757e5abbace413b59421527a31113406c97815c", "raw": {"market": "0xcab7ba4a9133cfd407d7e73e5757e5abbace413b59421527a31113406c97815c", "asset_id": "96361925776989336186111887920533578209326565663637092688733016597062311745569", "price": "0.009", "size": "812.25", "side": "BUY", "timestamp": "1768475279468", "received_at": "2026-01-15T12:07:59.594193"}}
{"event_type": "price_change", "event_ts": "2026-01-15T12:07:59.594193", "ingestion_ts": "2026-01-15T12:08:42.168746", "market_id": "0xcab7ba4a9133cfd407d7e73e5757e5abbace413b59421527a31113406c97815c", "raw": {"market": "0xcab7ba4a9133cfd407d7e73e5757e5abbace413b59421527a31113406c97815c", "asset_id": "20002636398944597965698652220992177552927816915094913583821579024925426590022", "price": "0.991", "size": "812.25", "side": "SELL", "timestamp": "1768475279468", "received_at": "2026-01-15T12:07:59.594193"}}
{"event_type": "price_change", "event_ts": "2026-01-15T12:07:59.722209", "ingestion_ts": "2026-01-15T12:08:42.168746", "market_id": "0xae5584fbb57f23c1c608d544b656f23d8bf12340cef70811cf31bb0cb4fc2115", "raw": {"market": "0xae5584fbb57f23c1c608d544b656f23d8bf12340cef70811cf31bb0cb4fc2115", "asset_id": "42278252558046940014991595990628759801692726198478046188873057685686228021663", "price": "0.4", "size": "44.94", "side": "BUY", "timestamp": "1768475279605", "received_at": "2026-01-15T12:07:59.722209"}}
{"event_type": "price_change", "event_ts": "2026-01-15T12:07:59.722209", "ingestion_ts": "2026-01-15T12:08:42.168746", "market_id": "0xae5584fbb57f23c1c608d544b656f23d8bf12340cef70811cf31bb0cb4fc2115", "raw": {"market": "0xae5584fbb57f23c1c608d544b656f23d8bf12340cef70811cf31bb0cb4fc2115", "asset_id": "28946595841244317705636126646676849578876740730186646421280828201004700559420", "price": "0.6", "size": "44.94", "side": "SELL", "timestamp": "1768475279605", "received_at": "2026-01-15T12:07:59.722209"}}
{"event_type": "price_change", "event_ts": "2026-01-15T12:07:59.953033", "ingestion_ts": "2026-01-15T12:08:42.168746", "market_id": "0xae5584fbb57f23c1c608d544b656f23d8bf12340cef70811cf31bb0cb4fc2115", "raw": {"market": "0xae5584fbb57f23c1c608d544b656f23d8bf12340cef70811cf31bb0cb4fc2115", "asset_id": "42278252558046940014991595990628759801692726198478046188873057685686228021663", "price": "0.41", "size": "9", "side": "BUY", "timestamp": "1768475279834", "received_at": "2026-01-15T12:07:59.953033"}}
{"event_type": "price_change", "event_ts": "2026-01-15T12:07:59.953033", "ingestion_ts": "2026-01-15T12:08:42.168746", "market_id": "0xae5584fbb57f23c1c608d544b656f23d8bf12340cef70811cf31bb0cb4fc2115", "raw": {"market": "0xae5584fbb57f23c1c608d544b656f23d8bf12340cef70811cf31bb0cb4fc2115", "asset_id": "28946595841244317705636126646676849578876740730186646421280828201004700559420", "price": "0.59", "size": "9", "side": "SELL", "timestamp": "1768475279834", "received_at": "2026-01-15T12:07:59.953033"}}
{"event_type": "price_change", "event_ts": "2026-01-15T12:08:00.079363", "ingestion_ts": "2026-01-15T12:08:42.168746", "market_id": "0xcab7ba4a9133cfd407d7e73e5757e5abbace413b59421527a31113406c97815c", "raw": {"market": "0xcab7ba4a9133cfd407d7e73e5757e5abbace413b59421527a31113406c97815c", "asset_id": "96361925776989336186111887920533578209326565663637092688733016597062311745569", "price": "0.009", "size": "818.33", "side": "BUY", "timestamp": "1768475279963", "received_at": "2026-01-15T12:08:00.079363"}}
{"event_type": "price_change", "event_ts": "2026-01-15T12:08:00.079363", "ingestion_ts": "2026-01-15T12:08:42.168746", "market_id": "0xcab7ba4a9133cfd407d7e73e5757e5abbace413b59421527a31113406c97815c", "raw": {"market": "0xcab7ba4a9133cfd407d7e73e5757e5abbace413b59421527a31113406c97815c", "asset_id": "20002636398944597965698652220992177552927816915094913583821579024925426590022", "price": "0.991", "size": "818.33", "side": "SELL", "timestamp": "1768475279963", "received_at": "2026-01-15T12:08:00.079363"}}
{"event_type": "price_change", "event_ts": "2026-01-15T12:08:00.589387", "ingestion_ts": "2026-01-15T12:08:42.168746", "market_id": "0xcab7ba4a9133cfd407d7e73e5757e5abbace413b59421527a31113406c97815c", "raw": {"market": "0xcab7ba4a9133cfd407d7e73e5757e5abbace413b59421527a31113406c97815c", "asset_id": "96361925776989336186111887920533578209326565663637092688733016597062311745569", "price": "0.006", "size": "136.51", "side": "BUY", "timestamp": "1768475280413", "received_at": "2026-01-15T12:08:00.589387"}}
{"event_type": "price_change", "event_ts": "2026-01-15T12:08:00.589387", "ingestion_ts": "2026-01-15T12:08:42.168746", "market_id": "0xcab7ba4a9133cfd407d7e73e5757e5abbace413b59421527a31113406c97815c", "raw": {"market": "0xcab7ba4a9133cfd407d7e73e5757e5abbace413b59421527a31113406c97815c", "asset_id": "20002636398944597965698652220992177552927816915094913583821579024925426590022", "price": "0.994", "size": "136.51", "side": "SELL", "timestamp": "1768475280413", "received_at": "2026-01-15T12:08:00.589387"}}
{"event_type": "price_change", "event_ts": "2026-01-15T12:08:01.111824", "ingestion_ts": "2026-01-15T12:08:42.168746", "market_id": "0xc0e6b917320a47228fb96e3b5ae0e5c93773a5ae2662ae4e1f37807cfe47ce98", "raw": {"market": "0xc0e6b917320a47228fb96e3b5ae0e5c93773a5ae2662ae4e1f37807cfe47ce98", "asset_id": "58656358377246279051017109359677190749228949103591068167284263961542487110215", "price": "0.006", "size": "0", "side": "BUY", "timestamp": "1768475280990", "received_at": "2026-01-15T12:08:01.111824"}}
{"event_type": "price_change", "event_ts": "2026-01-15T12:08:01.111824", "ingestion_ts": "2026-01-15T12:08:42.168746", "market_id": "0xc0e6b917320a47228fb96e3b5ae0e5c93773a5ae2662ae4e1f37807cfe47ce98", "raw": {"market": "0xc0e6b917320a47228fb96e3b5ae0e5c93773a5ae2662ae4e1f37807cfe47ce98", "asset_id": "81647294538046680798858716589766492074338758116170717123345952330712416337530", "price": "0.994", "size": "0", "side": "SELL", "timestamp": "1768475280990", "received_at": "2026-01-15T12:08:01.111824"}}
{"event_type": "price_change", "event_ts": "2026-01-15T12:08:01.111870", "ingestion_ts": "2026-01-15T12:08:42.168746", "market_id": "0xc0e6b917320a47228fb96e3b5ae0e5c93773a5ae2662ae4e1f37807cfe47ce98", "raw": {"market": "0xc0e6b917320a47228fb96e3b5ae0e5c93773a5ae2662ae4e1f37807cfe47ce98", "asset_id": "58656358377246279051017109359677190749228949103591068167284263961542487110215", "price": "0.007", "size": "0", "side": "BUY", "timestamp": "1768475280990", "received_at": "2026-01-15T12:08:01.111870"}}
{"event_type": "price_change", "event_ts": "2026-01-15T12:08:01.111870", "ingestion_ts": "2026-01-15T12:08:42.168746", "market_id": "0xc0e6b917320a47228fb96e3b5ae0e5c93773a5ae2662ae4e1f37807cfe47ce98", "raw": {"market": "0xc0e6b917320a47228fb96e3b5ae0e5c93773a5ae2662ae4e1f37807cfe47ce98", "asset_id": "81647294538046680798858716589766492074338758116170717123345952330712416337530", "price": "0.993", "size": "0", "side": "SELL", "timestamp": "1768475280990", "received_at": "2026-01-15T12:08:01.111870"}}
{"event_type": "price_change", "event_ts": "2026-01-15T12:08:01.498886", "ingestion_ts": "2026-01-15T12:08:42.168746", "market_id": "0x2393ed0b0fdc450054c7b9071907eca75cf4fc36e385adf4a0a5f99ee62243e8", "raw": {"market": "0x2393ed0b0fdc450054c7b9071907eca75cf4fc36e385adf4a0a5f99ee62243e8", "asset_id": "100074770378634056601572485653252702850363676459996771990439989989293515601975", "price": "0.044", "size": "5", "side": "BUY", "timestamp": "1768475281382", "received_at": "2026-01-15T12:08:01.498886"}}
{"event_type": "price_change", "event_ts": "2026-01-15T12:08:01.498886", "ingestion_ts": "2026-01-15T12:08:42.168746", "market_id": "0x2393ed0b0fdc450054c7b9071907eca75cf4fc36e385adf4a0a5f99ee62243e8", "raw": {"market": "0x2393ed0b0fdc450054c7b9071907eca75cf4fc36e385adf4a0a5f99ee62243e8", "asset_id": "32769749367306925959219403371425714180265458150646381231272229429098460625924", "price": "0.956", "size": "5", "side": "SELL", "timestamp": "1768475281382", "received_at": "2026-01-15T12:08:01.498886"}}
{"event_type": "price_change", "event_ts": "2026-01-15T12:08:01.684417", "ingestion_ts": "2026-01-15T12:08:42.168746", "market_id": "0x2393ed0b0fdc450054c7b9071907eca75cf4fc36e385adf4a0a5f99ee62243e8", "raw": {"market": "0x2393ed0b0fdc450054c7b9071907eca75cf4fc36e385adf4a0a5f99ee62243e8", "asset_id": "32769749367306925959219403371425714180265458150646381231272229429098460625924", "price": "0.946", "size": "10", "side": "BUY", "timestamp": "1768475281565", "received_at": "2026-01-15T12:08:01.684417"}}
{"event_type": "price_change", "event_ts": "2026-01-15T12:08:01.684417", "ingestion_ts": "2026-01-15T12:08:42.168746", "market_id": "0x2393ed0b0fdc450054c7b9071907eca75cf4fc36e385adf4a0a5f99ee62243e8", "raw": {"market": "0x2393ed0b0fdc450054c7b9071907eca75cf4fc36e385adf4a0a5f99ee62243e8", "asset_id": "100074770378634056601572485653252702850363676459996771990439989989293515601975", "price": "0.054", "size": "10", "side": "SELL", "timestamp": "1768475281565", "received_at": "2026-01-15T12:08:01.684417"}}
{"event_type": "price_change", "event_ts": "2026-01-15T12:08:01.875913", "ingestion_ts": "2026-01-15T12:08:42.168746", "market_id": "0xaf9d0e448129a9f657f851d49495ba4742055d80e0ef1166ba0ee81d4d594214", "raw": {"market": "0xaf9d0e448129a9f657f851d49495ba4742055d80e0ef1166ba0ee81d4d594214", "asset_id": "4153292802911610701832309484716814274802943278345248636922528170020319407796", "price": "0.876", "size": "17", "side": "BUY", "timestamp": "1768475281755", "received_at": "2026-01-15T12:08:01.875913"}}
{"event_type": "price_change", "event_ts": "2026-01-15T12:08:01.875913", "ingestion_ts": "2026-01-15T12:08:42.168746", "market_id": "0xaf9d0e448129a9f657f851d49495ba4742055d80e0ef1166ba0ee81d4d594214", "raw": {"market": "0xaf9d0e448129a9f657f851d49495ba4742055d80e0ef1166ba0ee81d4d594214", "asset_id": "101676997363687199724245607342877036148401850938023978421879460310389391082353", "price": "0.124", "size": "17", "side": "SELL", "timestamp": "1768475281755", "received_at": "2026-01-15T12:08:01.875913"}}
{"event_type": "price_change", "event_ts": "2026-01-15T12:08:01.893806", "ingestion_ts": "2026-01-15T12:08:42.168746", "market_id": "0xc0e6b917320a47228fb96e3b5ae0e5c93773a5ae2662ae4e1f37807cfe47ce98", "raw": {"market": "0xc0e6b917320a47228fb96e3b5ae0e5c93773a5ae2662ae4e1f37807cfe47ce98", "asset_id": "58656358377246279051017109359677190749228949103591068167284263961542487110215", "price": "0.008", "size": "5.69", "side": "BUY", "timestamp": "1768475281774", "received_at": "2026-01-15T12:08:01.893806"}}
{"event_type": "price_change", "event_ts": "2026-01-15T12:08:01.893806", "ingestion_ts": "2026-01-15T12:08:42.168746", "market_id": "0xc0e6b917320a47228fb96e3b5ae0e5c93773a5ae2662ae4e1f37807cfe47ce98", "raw": {"market": "0xc0e6b917320a47228fb96e3b5ae0e5c93773a5ae2662ae4e1f37807cfe47ce98", "asset_id": "81647294538046680798858716589766492074338758116170717123345952330712416337530", "price": "0.992", "size": "5.69", "side": "SELL", "timestamp": "1768475281774", "received_at": "2026-01-15T12:08:01.893806"}}
{"event_type": "price_change", "event_ts": "2026-01-15T12:08:01.893840", "ingestion_ts": "2026-01-15T12:08:42.168746", "market_id": "0xc0e6b917320a47228fb96e3b5ae0e5c93773a5ae2662ae4e1f37807cfe47ce98", "raw": {"market": "0xc0e6b917320a47228fb96e3b5ae0e5c93773a5ae2662ae4e1f37807cfe47ce98", "asset_id": "58656358377246279051017109359677190749228949103591068167284263961542487110215", "price": "0.008", "size": "11.38", "side": "BUY", "timestamp": "1768475281775", "received_at": "2026-01-15T12:08:01.893840"}}
{"event_type": "price_change", "event_ts": "2026-01-15T12:08:01.893840", "ingestion_ts": "2026-01-15T12:08:42.168746", "market_id": "0xc0e6b917320a47228fb96e3b5ae0e5c93773a5ae2662ae4e1f37807cfe47ce98", "raw": {"market": "0xc0e6b917320a47228fb96e3b5ae0e5c93773a5ae2662ae4e1f37807cfe47ce98", "asset_id": "81647294538046680798858716589766492074338758116170717123345952330712416337530", "price": "0.992", "size": "11.38", "side": "SELL", "timestamp": "1768475281775", "received_at": "2026-01-15T12:08:01.893840"}}
{"event_type": "price_change", "event_ts": "2026-01-15T12:08:02.049859", "ingestion_ts": "2026-01-15T12:08:42.168746", "market_id": "0xaf9d0e448129a9f657f851d49495ba4742055d80e0ef1166ba0ee81d4d594214", "raw": {"market": "0xaf9d0e448129a9f657f851d49495ba4742055d80e0ef1166ba0ee81d4d594214", "asset_id": "4153292802911610701832309484716814274802943278345248636922528170020319407796", "price": "0.876", "size": "0", "side": "BUY", "timestamp": "1768475281924", "received_at": "2026-01-15T12:08:02.049859"}}
{"event_type": "price_change", "event_ts": "2026-01-15T12:08:02.049859", "ingestion_ts": "2026-01-15T12:08:42.168746", "market_id": "0xaf9d0e448129a9f657f851d49495ba4742055d80e0ef1166ba0ee81d4d594214", "raw": {"market": "0xaf9d0e448129a9f657f851d49495ba4742055d80e0ef1166ba0ee81d4d594214", "asset_id": "101676997363687199724245607342877036148401850938023978421879460310389391082353", "price": "0.124", "size": "0", "side": "SELL", "timestamp": "1768475281924", "received_at": "2026-01-15T12:08:02.049859"}}
{"event_type": "price_change", "event_ts": "2026-01-15T12:08:02.097031", "ingestion_ts": "2026-01-15T12:08:42.168746", "market_id": "0xcab7ba4a9133cfd407d7e73e5757e5abbace413b59421527a31113406c97815c", "raw": {"market": "0xcab7ba4a9133cfd407d7e73e5757e5abbace413b59421527a31113406c97815c", "asset_id": "96361925776989336186111887920533578209326565663637092688733016597062311745569", "price": "0.006", "size": "127.41", "side": "BUY", "timestamp": "1768475281976", "received_at": "2026-01-15T12:08:02.097031"}}
{"event_type": "price_change", "event_ts": "2026-01-15T12:08:02.097031", "ingestion_ts": "2026-01-15T12:08:42.168746", "market_id": "0xcab7ba4a9133cfd407d7e73e5757e5abbace413b59421527a31113406c97815c", "raw": {"market": "0xcab7ba4a9133cfd407d7e73e5757e5abbace413b59421527a31113406c97815c", "asset_id": "20002636398944597965698652220992177552927816915094913583821579024925426590022", "price": "0.994", "size": "127.41", "side": "SELL", "timestamp": "1768475281976", "received_at": "2026-01-15T12:08:02.097031"}}
{"event_type": "price_change", "event_ts": "2026-01-15T12:08:02.097069", "ingestion_ts": "2026-01-15T12:08:42.168746", "market_id": "0xcab7ba4a9133cfd407d7e73e5757e5abbace413b59421527a31113406c97815c", "raw": {"market": "0xcab7ba4a9133cfd407d7e73e5757e5abbace413b59421527a31113406c97815c", "asset_id": "96361925776989336186111887920533578209326565663637092688733016597062311745569", "price": "0.009", "size": "812.25", "side": "BUY", "timestamp": "1768475281976", "received_at": "2026-01-15T12:08:02.097069"}}
{"event_type": "price_change", "event_ts": "2026-01-15T12:08:02.097069", "ingestion_ts": "2026-01-15T12:08:42.168746", "market_id": "0xcab7ba4a9133cfd407d7e73e5757e5abbace413b59421527a31113406c97815c", "raw": {"market": "0xcab7ba4a9133cfd407d7e73e5757e5abbace413b59421527a31113406c97815c", "asset_id": "20002636398944597965698652220992177552927816915094913583821579024925426590022", "price": "0.991", "size": "812.25", "side": "SELL", "timestamp": "1768475281976", "received_at": "2026-01-15T12:08:02.097069"}}
{"event_type": "price_change", "event_ts": "2026-01-15T12:08:02.226944", "ingestion_ts": "2026-01-15T12:08:42.168746", "market_id": "0xaf9d0e448129a9f657f851d49495ba4742055d80e0ef1166ba0ee81d4d594214", "raw": {"market": "0xaf9d0e448129a9f657f851d49495ba4742055d80e0ef1166ba0ee81d4d594214", "asset_id": "4153292802911610701832309484716814274802943278345248636922528170020319407796", "price": "0.876", "size": "19", "side": "BUY", "timestamp": "1768475282104", "received_at": "2026-01-15T12:08:02.226944"}}
{"event_type": "price_change", "event_ts": "2026-01-15T12:08:02.226944", "ingestion_ts": "2026-01-15T12:08:42.168746", "market_id": "0xaf9d0e448129a9f657f851d49495ba4742055d80e0ef1166ba0ee81d4d594214", "raw": {"market": "0xaf9d0e448129a9f657f851d49495ba4742055d80e0ef1166ba0ee81d4d594214", "asset_id": "101676997363687199724245607342877036148401850938023978421879460310389391082353", "price": "0.124", "size": "19", "side": "SELL", "timestamp": "1768475282104", "received_at": "2026-01-15T12:08:02.226944"}}
{"event_type": "price_change", "event_ts": "2026-01-15T12:08:02.226983", "ingestion_ts": "2026-01-15T12:08:42.168746", "market_id": "0xaf9d0e448129a9f657f851d49495ba4742055d80e0ef1166ba0ee81d4d594214", "raw": {"market": "0xaf9d0e448129a9f657f851d49495ba4742055d80e0ef1166ba0ee81d4d594214", "asset_id": "4153292802911610701832309484716814274802943278345248636922528170020319407796", "price": "0.876", "size": "30", "side": "BUY", "timestamp": "1768475282105", "received_at": "2026-01-15T12:08:02.226983"}}
{"event_type": "price_change", "event_ts": "2026-01-15T12:08:02.226983", "ingestion_ts": "2026-01-15T12:08:42.168746", "market_id": "0xaf9d0e448129a9f657f851d49495ba4742055d80e0ef1166ba0ee81d4d594214", "raw": {"market": "0xaf9d0e448129a9f657f851d49495ba4742055d80e0ef1166ba0ee81d4d594214", "asset_id": "101676997363687199724245607342877036148401850938023978421879460310389391082353", "price": "0.124", "size": "30", "side": "SELL", "timestamp": "1768475282105", "received_at": "2026-01-15T12:08:02.226983"}}
{"event_type": "price_change", "event_ts": "2026-01-15T12:08:02.382481", "ingestion_ts": "2026-01-15T12:08:42.168746", "market_id": "0xcab7ba4a9133cfd407d7e73e5757e5abbace413b59421527a31113406c97815c", "raw": {"market": "0xcab7ba4a9133cfd407d7e73e5757e5abbace413b59421527a31113406c97815c", "asset_id": "96361925776989336186111887920533578209326565663637092688733016597062311745569", "price": "0.009", "size": "818.33", "side": "BUY", "timestamp": "1768475282263", "received_at": "2026-01-15T12:08:02.382481"}}
{"event_type": "price_change", "event_ts": "2026-01-15T12:08:02.382481", "ingestion_ts": "2026-01-15T12:08:42.168746", "market_id": "0xcab7ba4a9133cfd407d7e73e5757e5abbace413b59421527a31113406c97815c", "raw": {"market": "0xcab7ba4a9133cfd407d7e73e5757e5abbace413b59421527a31113406c97815c", "asset_id": "20002636398944597965698652220992177552927816915094913583821579024925426590022", "price": "0.991", "size": "818.33", "side": "SELL", "timestamp": "1768475282263", "received_at": "2026-01-15T12:08:02.382481"}}
{"event_type": "price_change", "event_ts": "2026-01-15T12:08:02.382565", "ingestion_ts": "2026-01-15T12:08:42.168746", "market_id": "0xcab7ba4a9133cfd407d7e73e5757e5abbace413b59421527a31113406c97815c", "raw": {"market": "0xcab7ba4a9133cfd407d7e73e5757e5abbace413b59421527a31113406c97815c", "asset_id": "96361925776989336186111887920533578209326565663637092688733016597062311745569", "price": "0.006", "size": "136.51", "side": "BUY", "timestamp": "1768475282264", "received_at": "2026-01-15T12:08:02.382565"}}
{"event_type": "price_change", "event_ts": "2026-01-15T12:08:02.382565", "ingestion_ts": "2026-01-15T12:08:42.168746", "market_id": "0xcab7ba4a9133cfd407d7e73e5757e5abbace413b59421527a31113406c97815c", "raw": {"market": "0xcab7ba4a9133cfd407d7e73e5757e5abbace413b59421527a31113406c97815c", "asset_id": "20002636398944597965698652220992177552927816915094913583821579024925426590022", "price": "0.994", "size": "136.51", "side": "SELL", "timestamp": "1768475282264", "received_at": "2026-01-15T12:08:02.382565"}}
{"event_type": "price_change", "event_ts": "2026-01-15T12:08:02.950922", "ingestion_ts": "2026-01-15T12:08:42.168746", "market_id": "0x427bc4b40c09b3dcbc973747f0e4b079bed91b3e5a0aed5c36edd0f7591485f4", "raw": {"market": "0x427bc4b40c09b3dcbc973747f0e4b079bed91b3e5a0aed5c36edd0f7591485f4", "asset_id": "115669573443672055876643967408433138119481486650803218131873713375232186497057", "price": "0.002", "size": "41.05", "side": "BUY", "timestamp": "1768475282830", "received_at": "2026-01-15T12:08:02.950922"}}
{"event_type": "price_change", "event_ts": "2026-01-15T12:08:02.950922", "ingestion_ts": "2026-01-15T12:08:42.168746", "market_id": "0x427bc4b40c09b3dcbc973747f0e4b079bed91b3e5a0aed5c36edd0f7591485f4", "raw": {"market": "0x427bc4b40c09b3dcbc973747f0e4b079bed91b3e5a0aed5c36edd0f7591485f4", "asset_id": "86130975769502911188457673769190265049139877688522439001984850068234616395137", "price": "0.998", "size": "41.05", "side": "SELL", "timestamp": "1768475282830", "received_at": "2026-01-15T12:08:02.950922"}}
{"event_type": "price_change", "event_ts": "2026-01-15T12:08:03.269547", "ingestion_ts": "2026-01-15T12:08:42.168746", "market_id": "0x427bc4b40c09b3dcbc973747f0e4b079bed91b3e5a0aed5c36edd0f7591485f4", "raw": {"market": "0x427bc4b40c09b3dcbc973747f0e4b079bed91b3e5a0aed5c36edd0f7591485f4", "asset_id": "115669573443672055876643967408433138119481486650803218131873713375232186497057", "price": "0.003", "size": "16.15", "side": "BUY", "timestamp": "1768475283153", "received_at": "2026-01-15T12:08:03.269547"}}
{"event_type": "price_change", "event_ts": "2026-01-15T12:08:03.269547", "ingestion_ts": "2026-01-15T12:08:42.168746", "market_id": "0x427bc4b40c09b3dcbc973747f0e4b079bed91b3e5a0aed5c36edd0f7591485f4", "raw": {"market": "0x427bc4b40c09b3dcbc973747f0e4b079bed91b3e5a0aed5c36edd0f7591485f4", "asset_id": "86130975769502911188457673769190265049139877688522439001984850068234616395137", "price": "0.997", "size": "16.15", "side": "SELL", "timestamp": "1768475283153", "received_at": "2026-01-15T12:08:03.269547"}}
{"event_type": "price_change", "event_ts": "2026-01-15T12:08:04.688896", "ingestion_ts": "2026-01-15T12:08:42.168746", "market_id": "0xc0e6b917320a47228fb96e3b5ae0e5c93773a5ae2662ae4e1f37807cfe47ce98", "raw": {"market": "0xc0e6b917320a47228fb96e3b5ae0e5c93773a5ae2662ae4e1f37807cfe47ce98", "asset_id": "58656358377246279051017109359677190749228949103591068167284263961542487110215", "price": "0.008", "size": "5.69", "side": "BUY", "timestamp": "1768475284566", "received_at": "2026-01-15T12:08:04.688896"}}
{"event_type": "price_change", "event_ts": "2026-01-15T12:08:04.688896", "ingestion_ts": "2026-01-15T12:08:42.168746", "market_id": "0xc0e6b917320a47228fb96e3b5ae0e5c93773a5ae2662ae4e1f37807cfe47ce98", "raw": {"market": "0xc0e6b917320a47228fb96e3b5ae0e5c93773a5ae2662ae4e1f37807cfe47ce98", "asset_id": "81647294538046680798858716589766492074338758116170717123345952330712416337530", "price": "0.992", "size": "5.69", "side": "SELL", "timestamp": "1768475284566", "received_at": "2026-01-15T12:08:04.688896"}}
{"event_type": "price_change", "event_ts": "2026-01-15T12:08:04.691765", "ingestion_ts": "2026-01-15T12:08:42.168746", "market_id": "0xcab7ba4a9133cfd407d7e73e5757e5abbace413b59421527a31113406c97815c", "raw": {"market": "0xcab7ba4a9133cfd407d7e73e5757e5abbace413b59421527a31113406c97815c", "asset_id": "96361925776989336186111887920533578209326565663637092688733016597062311745569", "price": "0.006", "size": "127.41", "side": "BUY", "timestamp": "1768475284566", "received_at": "2026-01-15T12:08:04.691765"}}
{"event_type": "price_change", "event_ts": "2026-01-15T12:08:04.691765", "ingestion_ts": "2026-01-15T12:08:42.168746", "market_id": "0xcab7ba4a9133cfd407d7e73e5757e5abbace413b59421527a31113406c97815c", "raw": {"market": "0xcab7ba4a9133cfd407d7e73e5757e5abbace413b59421527a31113406c97815c", "asset_id": "20002636398944597965698652220992177552927816915094913583821579024925426590022", "price": "0.994", "size": "127.41", "side": "SELL", "timestamp": "1768475284566", "received_at": "2026-01-15T12:08:04.691765"}}
{"event_type": "price_change", "event_ts": "2026-01-15T12:08:04.691791", "ingestion_ts": "2026-01-15T12:08:42.168746", "market_id": "0xcab7ba4a9133cfd407d7e73e5757e5abbace413b59421527a31113406c97815c", "raw": {"market": "0xcab7ba4a9133cfd407d7e73e5757e5abbace413b59421527a31113406c97815c", "asset_id": "96361925776989336186111887920533578209326565663637092688733016597062311745569", "price": "0.009", "size": "812.25", "side": "BUY", "timestamp": "1768475284566", "received_at": "2026-01-15T12:08:04.691791"}}
{"event_type": "price_change", "event_ts": "2026-01-15T12:08:04.691791", "ingestion_ts": "2026-01-15T12:08:42.168746", "market_id": "0xcab7ba4a9133cfd407d7e73e5757e5abbace413b59421527a31113406c97815c", "raw": {"market": "0xcab7ba4a9133cfd407d7e73e5757e5abbace413b59421527a31113406c97815c", "asset_id": "20002636398944597965698652220992177552927816915094913583821579024925426590022", "price": "0.991", "size": "812.25", "side": "SELL", "timestamp": "1768475284566", "received_at": "2026-01-15T12:08:04.691791"}}
{"event_type": "price_change", "event_ts": "2026-01-15T12:08:05.446932", "ingestion_ts": "2026-01-15T12:08:42.168746", "market_id": "0xc0e6b917320a47228fb96e3b5ae0e5c93773a5ae2662ae4e1f37807cfe47ce98", "raw": {"market": "0xc0e6b917320a47228fb96e3b5ae0e5c93773a5ae2662ae4e1f37807cfe47ce98", "asset_id": "58656358377246279051017109359677190749228949103591068167284263961542487110215", "price": "0.003", "size": "437.44", "side": "BUY", "timestamp": "1768475285309", "received_at": "2026-01-15T12:08:05.446932"}}
{"event_type": "price_change", "event_ts": "2026-01-15T12:08:05.446932", "ingestion_ts": "2026-01-15T12:08:42.168746", "market_id": "0xc0e6b917320a47228fb96e3b5ae0e5c93773a5ae2662ae4e1f37807cfe47ce98", "raw": {"market": "0xc0e6b917320a47228fb96e3b5ae0e5c93773a5ae2662ae4e1f37807cfe47ce98", "asset_id": "81647294538046680798858716589766492074338758116170717123345952330712416337530", "price": "0.997", "size": "437.44", "side": "SELL", "timestamp": "1768475285309", "received_at": "2026-01-15T12:08:05.446932"}}
{"event_type": "price_change", "event_ts": "2026-01-15T12:08:05.446967", "ingestion_ts": "2026-01-15T12:08:42.168746", "market_id": "0xcab7ba4a9133cfd407d7e73e5757e5abbace413b59421527a31113406c97815c", "raw": {"market": "0xcab7ba4a9133cfd407d7e73e5757e5abbace413b59421527a31113406c97815c", "asset_id": "96361925776989336186111887920533578209326565663637092688733016597062311745569", "price": "0.009", "size": "818.33", "side": "BUY", "timestamp": "1768475285309", "received_at": "2026-01-15T12:08:05.446967"}}
{"event_type": "price_change", "event_ts": "2026-01-15T12:08:05.446967", "ingestion_ts": "2026-01-15T12:08:42.168746", "market_id": "0xcab7ba4a9133cfd407d7e73e5757e5abbace413b59421527a31113406c97815c", "raw": {"market": "0xcab7ba4a9133cfd407d7e73e5757e5abbace413b59421527a31113406c97815c", "asset_id": "20002636398944597965698652220992177552927816915094913583821579024925426590022", "price": "0.991", "size": "818.33", "side": "SELL", "timestamp": "1768475285309", "received_at": "2026-01-15T12:08:05.446967"}}
{"event_type": "price_change", "event_ts": "2026-01-15T12:08:05.446978", "ingestion_ts": "2026-01-15T12:08:42.168746", "market_id": "0xc0e6b917320a47228fb96e3b5ae0e5c93773a5ae2662ae4e1f37807cfe47ce98", "raw": {"market": "0xc0e6b917320a47228fb96e3b5ae0e5c93773a5ae2662ae4e1f37807cfe47ce98", "asset_id": "58656358377246279051017109359677190749228949103591068167284263961542487110215", "price": "0.003", "size": "445.04", "side": "BUY", "timestamp": "1768475285309", "received_at": "2026-01-15T12:08:05.446978"}}
{"event_type": "price_change", "event_ts": "2026-01-15T12:08:05.446978", "ingestion_ts": "2026-01-15T12:08:42.168746", "market_id": "0xc0e6b917320a47228fb96e3b5ae0e5c93773a5ae2662ae4e1f37807cfe47ce98", "raw": {"market": "0xc0e6b917320a47228fb96e3b5ae0e5c93773a5ae2662ae4e1f37807cfe47ce98", "asset_id": "81647294538046680798858716589766492074338758116170717123345952330712416337530", "price": "0.997", "size": "445.04", "side": "SELL", "timestamp": "1768475285309", "received_at": "2026-01-15T12:08:05.446978"}}
{"event_type": "price_change", "event_ts": "2026-01-15T12:08:05.446989", "ingestion_ts": "2026-01-15T12:08:42.168746", "market_id": "0xcab7ba4a9133cfd407d7e73e5757e5abbace413b59421527a31113406c97815c", "raw": {"market": "0xcab7ba4a9133cfd407d7e73e5757e5abbace413b59421527a31113406c97815c", "asset_id": "96361925776989336186111887920533578209326565663637092688733016597062311745569", "price": "0.006", "size": "136.51", "side": "BUY", "timestamp": "1768475285310", "received_at": "2026-01-15T12:08:05.446989"}}
{"event_type": "price_change", "event_ts": "2026-01-15T12:08:05.446989", "ingestion_ts": "2026-01-15T12:08:42.168746", "market_id": "0xcab7ba4a9133cfd407d7e73e5757e5abbace413b59421527a31113406c97815c", "raw": {"market": "0xcab7ba4a9133cfd407d7e73e5757e5abbace413b59421527a31113406c97815c", "asset_id": "20002636398944597965698652220992177552927816915094913583821579024925426590022", "price": "0.994", "size": "136.51", "side": "SELL", "timestamp": "1768475285310", "received_at": "2026-01-15T12:08:05.446989"}}
{"event_type": "price_change", "event_ts": "2026-01-15T12:08:06.332628", "ingestion_ts": "2026-01-15T12:08:42.168746", "market_id": "0x427bc4b40c09b3dcbc973747f0e4b079bed91b3e5a0aed5c36edd0f7591485f4", "raw": {"market": "0x427bc4b40c09b3dcbc973747f0e4b079bed91b3e5a0aed5c36edd0f7591485f4", "asset_id": "86130975769502911188457673769190265049139877688522439001984850068234616395137", "price": "0.833", "size": "10", "side": "BUY", "timestamp": "1768475286216", "received_at": "2026-01-15T12:08:06.332628"}}
{"event_type": "price_change", "event_ts": "2026-01-15T12:08:06.332628", "ingestion_ts": "2026-01-15T12:08:42.168746", "market_id": "0x427bc4b40c09b3dcbc973747f0e4b079bed91b3e5a0aed5c36edd0f7591485f4", "raw": {"market": "0x427bc4b40c09b3dcbc973747f0e4b079bed91b3e5a0aed5c36edd0f7591485f4", "asset_id": "115669573443672055876643967408433138119481486650803218131873713375232186497057", "price": "0.167", "size": "10", "side": "SELL", "timestamp": "1768475286216", "received_at": "2026-01-15T12:08:06.332628"}}
{"event_type": "price_change", "event_ts": "2026-01-15T12:08:06.360173", "ingestion_ts": "2026-01-15T12:08:42.168746", "market_id": "0x427bc4b40c09b3dcbc973747f0e4b079bed91b3e5a0aed5c36edd0f7591485f4", "raw": {"market": "0x427bc4b40c09b3dcbc973747f0e4b079bed91b3e5a0aed5c36edd0f7591485f4", "asset_id": "115669573443672055876643967408433138119481486650803218131873713375232186497057", "price": "0.008", "size": "0", "side": "BUY", "timestamp": "1768475286242", "received_at": "2026-01-15T12:08:06.360173"}}
{"event_type": "price_change", "event_ts": "2026-01-15T12:08:06.360173", "ingestion_ts": "2026-01-15T12:08:42.168746", "market_id": "0x427bc4b40c09b3dcbc973747f0e4b079bed91b3e5a0aed5c36edd0f7591485f4", "raw": {"market": "0x427bc4b40c09b3dcbc973747f0e4b079bed91b3e5a0aed5c36edd0f7591485f4", "asset_id": "86130975769502911188457673769190265049139877688522439001984850068234616395137", "price": "0.992", "size": "0", "side": "SELL", "timestamp": "1768475286242", "received_at": "2026-01-15T12:08:06.360173"}}
{"event_type": "price_change", "event_ts": "2026-01-15T12:08:06.389245", "ingestion_ts": "2026-01-15T12:08:42.168746", "market_id": "0x427bc4b40c09b3dcbc973747f0e4b079bed91b3e5a0aed5c36edd0f7591485f4", "raw": {"market": "0x427bc4b40c09b3dcbc973747f0e4b079bed91b3e5a0aed5c36edd0f7591485f4", "asset_id": "86130975769502911188457673769190265049139877688522439001984850068234616395137", "price": "0.34", "size": "0", "side": "BUY", "timestamp": "1768475286268", "received_at": "2026-01-15T12:08:06.389245"}}
{"event_type": "price_change", "event_ts": "2026-01-15T12:08:06.389245", "ingestion_ts": "2026-01-15T12:08:42.168746", "market_id": "0x427bc4b40c09b3dcbc973747f0e4b079bed91b3e5a0aed5c36edd0f7591485f4", "raw": {"market": "0x427bc4b40c09b3dcbc973747f0e4b079bed91b3e5a0aed5c36edd0f7591485f4", "asset_id": "115669573443672055876643967408433138119481486650803218131873713375232186497057", "price": "0.66", "size": "0", "side": "SELL", "timestamp": "1768475286268", "received_at": "2026-01-15T12:08:06.389245"}}
{"event_type": "price_change", "event_ts": "2026-01-15T12:08:06.417604", "ingestion_ts": "2026-01-15T12:08:42.168746", "market_id": "0x427bc4b40c09b3dcbc973747f0e4b079bed91b3e5a0aed5c36edd0f7591485f4", "raw": {"market": "0x427bc4b40c09b3dcbc973747f0e4b079bed91b3e5a0aed5c36edd0f7591485f4", "asset_id": "86130975769502911188457673769190265049139877688522439001984850068234616395137", "price": "0.3", "size": "0", "side": "BUY", "timestamp": "1768475286299", "received_at": "2026-01-15T12:08:06.417604"}}
{"event_type": "price_change", "event_ts": "2026-01-15T12:08:06.417604", "ingestion_ts": "2026-01-15T12:08:42.168746", "market_id": "0x427bc4b40c09b3dcbc973747f0e4b079bed91b3e5a0aed5c36edd0f7591485f4", "raw": {"market": "0x427bc4b40c09b3dcbc973747f0e4b079bed91b3e5a0aed5c36edd0f7591485f4", "asset_id": "115669573443672055876643967408433138119481486650803218131873713375232186497057", "price": "0.7", "size": "0", "side": "SELL", "timestamp": "1768475286299", "received_at": "2026-01-15T12:08:06.417604"}}
{"event_type": "price_change", "event_ts": "2026-01-15T12:08:06.447589", "ingestion_ts": "2026-01-15T12:08:42.168746", "market_id": "0x427bc4b40c09b3dcbc973747f0e4b079bed91b3e5a0aed5c36edd0f7591485f4", "raw": {"market": "0x427bc4b40c09b3dcbc973747f0e4b079bed91b3e5a0aed5c36edd0f7591485f4", "asset_id": "86130975769502911188457673769190265049139877688522439001984850068234616395137", "price": "0.25", "size": "0", "side": "BUY", "timestamp": "1768475286324", "received_at": "2026-01-15T12:08:06.447589"}}
{"event_type": "price_change", "event_ts": "2026-01-15T12:08:06.447589", "ingestion_ts": "2026-01-15T12:08:42.168746", "market_id": "0x427bc4b40c09b3dcbc973747f0e4b079bed91b3e5a0aed5c36edd0f7591485f4", "raw": {"market": "0x427bc4b40c09b3dcbc973747f0e4b079bed91b3e5a0aed5c36edd0f7591485f4", "asset_id": "115669573443672055876643967408433138119481486650803218131873713375232186497057", "price": "0.75", "size": "0", "side": "SELL", "timestamp": "1768475286324", "received_at": "2026-01-15T12:08:06.447589"}}
{"event_type": "price_change", "event_ts": "2026-01-15T12:08:06.478051", "ingestion_ts": "2026-01-15T12:08:42.168746", "market_id": "0x427bc4b40c09b3dcbc973747f0e4b079bed91b3e5a0aed5c36edd0f7591485f4", "raw": {"market": "0x427bc4b40c09b3dcbc973747f0e4b079bed91b3e5a0aed5c36edd0f7591485f4", "asset_id": "86130975769502911188457673769190265049139877688522439001984850068234616395137", "price": "0.21", "size": "0", "side": "BUY", "timestamp": "1768475286360", "received_at": "2026-01-15T12:08:06.478051"}}
{"event_type": "price_change", "event_ts": "2026-01-15T12:08:06.478051", "ingestion_ts": "2026-01-15T12:08:42.168746", "market_id": "0x427bc4b40c09b3dcbc973747f0e4b079bed91b3e5a0aed5c36edd0f7591485f4", "raw": {"market": "0x427bc4b40c09b3dcbc973747f0e4b079bed91b3e5a0aed5c36edd0f7591485f4", "asset_id": "115669573443672055876643967408433138119481486650803218131873713375232186497057", "price": "0.79", "size": "0", "side": "SELL", "timestamp": "1768475286360", "received_at": "2026-01-15T12:08:06.478051"}}
{"event_type": "price_change", "event_ts": "2026-01-15T12:08:06.503541", "ingestion_ts": "2026-01-15T12:08:42.168746", "market_id": "0x427bc4b40c09b3dcbc973747f0e4b079bed91b3e5a0aed5c36edd0f7591485f4", "raw": {"market": "0x427bc4b40c09b3dcbc973747f0e4b079bed91b3e5a0aed5c36edd0f7591485f4", "asset_id": "86130975769502911188457673769190265049139877688522439001984850068234616395137", "price": "0.17", "size": "0", "side": "BUY", "timestamp": "1768475286387", "received_at": "2026-01-15T12:08:06.503541"}}
{"event_type": "price_change", "event_ts": "2026-01-15T12:08:06.503541", "ingestion_ts": "2026-01-15T12:08:42.168746", "market_id": "0x427bc4b40c09b3dcbc973747f0e4b079bed91b3e5a0aed5c36edd0f7591485f4", "raw": {"market": "0x427bc4b40c09b3dcbc973747f0e4b079bed91b3e5a0aed5c36edd0f7591485f4", "asset_id": "115669573443672055876643967408433138119481486650803218131873713375232186497057", "price": "0.83", "size": "0", "side": "SELL", "timestamp": "1768475286387", "received_at": "2026-01-15T12:08:06.503541"}}
{"event_type": "price_change", "event_ts": "2026-01-15T12:08:06.553118", "ingestion_ts": "2026-01-15T12:08:42.168746", "market_id": "0x427bc4b40c09b3dcbc973747f0e4b079bed91b3e5a0aed5c36edd0f7591485f4", "raw": {"market": "0x427bc4b40c09b3dcbc973747f0e4b079bed91b3e5a0aed5c36edd0f7591485f4", "asset_id": "86130975769502911188457673769190265049139877688522439001984850068234616395137", "price": "0.13", "size": "0", "side": "BUY", "timestamp": "1768475286424", "received_at": "2026-01-15T12:08:06.553118"}}
{"event_type": "price_change", "event_ts": "2026-01-15T12:08:06.553118", "ingestion_ts": "2026-01-15T12:08:42.168746", "market_id": "0x427bc4b40c09b3dcbc973747f0e4b079bed91b3e5a0aed5c36edd0f7591485f4", "raw": {"market": "0x427bc4b40c09b3dcbc973747f0e4b079bed91b3e5a0aed5c36edd0f7591485f4", "asset_id": "115669573443672055876643967408433138119481486650803218131873713375232186497057", "price": "0.87", "size": "0", "side": "SELL", "timestamp": "1768475286424", "received_at": "2026-01-15T12:08:06.553118"}}
{"event_type": "price_change", "event_ts": "2026-01-15T12:08:06.666198", "ingestion_ts": "2026-01-15T12:08:42.168746", "market_id": "0x427bc4b40c09b3dcbc973747f0e4b079bed91b3e5a0aed5c36edd0f7591485f4", "raw": {"market": "0x427bc4b40c09b3dcbc973747f0e4b079bed91b3e5a0aed5c36edd0f7591485f4", "asset_id": "86130975769502911188457673769190265049139877688522439001984850068234616395137", "price": "0.08", "size": "100", "side": "BUY", "timestamp": "1768475286547", "received_at": "2026-01-15T12:08:06.666198"}}
{"event_type": "price_change", "event_ts": "2026-01-15T12:08:06.666198", "ingestion_ts": "2026-01-15T12:08:42.168746", "market_id": "0x427bc4b40c09b3dcbc973747f0e4b079bed91b3e5a0aed5c36edd0f7591485f4", "raw": {"market": "0x427bc4b40c09b3dcbc973747f0e4b079bed91b3e5a0aed5c36edd0f7591485f4", "asset_id": "115669573443672055876643967408433138119481486650803218131873713375232186497057", "price": "0.92", "size": "100", "side": "SELL", "timestamp": "1768475286547", "received_at": "2026-01-15T12:08:06.666198"}}
{"event_type": "price_change", "event_ts": "2026-01-15T12:08:06.716248", "ingestion_ts": "2026-01-15T12:08:42.168746", "market_id": "0x427bc4b40c09b3dcbc973747f0e4b079bed91b3e5a0aed5c36edd0f7591485f4", "raw": {"market": "0x427bc4b40c09b3dcbc973747f0e4b079bed91b3e5a0aed5c36edd0f7591485f4", "asset_id": "86130975769502911188457673769190265049139877688522439001984850068234616395137", "price": "0.34", "size": "42.01", "side": "BUY", "timestamp": "1768475286597", "received_at": "2026-01-15T12:08:06.716248"}}
{"event_type": "price_change", "event_ts": "2026-01-15T12:08:06.716248", "ingestion_ts": "2026-01-15T12:08:42.168746", "market_id": "0x427bc4b40c09b3dcbc973747f0e4b079bed91b3e5a0aed5c36edd0f7591485f4", "raw": {"market": "0x427bc4b40c09b3dcbc973747f0e4b079bed91b3e5a0aed5c36edd0f7591485f4", "asset_id": "115669573443672055876643967408433138119481486650803218131873713375232186497057", "price": "0.66", "size": "42.01", "side": "SELL", "timestamp": "1768475286597", "received_at": "2026-01-15T12:08:06.716248"}}
{"event_type": "price_change", "event_ts": "2026-01-15T12:08:06.780581", "ingestion_ts": "2026-01-15T12:08:42.168746", "market_id": "0x427bc4b40c09b3dcbc973747f0e4b079bed91b3e5a0aed5c36edd0f7591485f4", "raw": {"market": "0x427bc4b40c09b3dcbc973747f0e4b079bed91b3e5a0aed5c36edd0f7591485f4", "asset_id": "86130975769502911188457673769190265049139877688522439001984850068234616395137", "price": "0.3", "size": "47.61", "side": "BUY", "timestamp": "1768475286650", "received_at": "2026-01-15T12:08:06.780581"}}
{"event_type": "price_change", "event_ts": "2026-01-15T12:08:06.780581", "ingestion_ts": "2026-01-15T12:08:42.168746", "market_id": "0x427bc4b40c09b3dcbc973747f0e4b079bed91b3e5a0aed5c36edd0f7591485f4", "raw": {"market": "0x427bc4b40c09b3dcbc973747f0e4b079bed91b3e5a0aed5c36edd0f7591485f4", "asset_id": "115669573443672055876643967408433138119481486650803218131873713375232186497057", "price": "0.7", "size": "47.61", "side": "SELL", "timestamp": "1768475286650", "received_at": "2026-01-15T12:08:06.780581"}}
{"event_type": "price_change", "event_ts": "2026-01-15T12:08:06.819126", "ingestion_ts": "2026-01-15T12:08:42.168746", "market_id": "0x427bc4b40c09b3dcbc973747f0e4b079bed91b3e5a0aed5c36edd0f7591485f4", "raw": {"market": "0x427bc4b40c09b3dcbc973747f0e4b079bed91b3e5a0aed5c36edd0f7591485f4", "asset_id": "86130975769502911188457673769190265049139877688522439001984850068234616395137", "price": "0.26", "size": "54.94", "side": "BUY", "timestamp": "1768475286702", "received_at": "2026-01-15T12:08:06.819126"}}
{"event_type": "price_change", "event_ts": "2026-01-15T12:08:06.819126", "ingestion_ts": "2026-01-15T12:08:42.168746", "market_id": "0x427bc4b40c09b3dcbc973747f0e4b079bed91b3e5a0aed5c36edd0f7591485f4", "raw": {"market": "0x427bc4b40c09b3dcbc973747f0e4b079bed91b3e5a0aed5c36edd0f7591485f4", "asset_id": "115669573443672055876643967408433138119481486650803218131873713375232186497057", "price": "0.74", "size": "54.94", "side": "SELL", "timestamp": "1768475286702", "received_at": "2026-01-15T12:08:06.819126"}}
{"event_type": "price_change", "event_ts": "2026-01-15T12:08:06.876799", "ingestion_ts": "2026-01-15T12:08:42.168746", "market_id": "0x427bc4b40c09b3dcbc973747f0e4b079bed91b3e5a0aed5c36edd0f7591485f4", "raw": {"market": "0x427bc4b40c09b3dcbc973747f0e4b079bed91b3e5a0aed5c36edd0f7591485f4", "asset_id": "86130975769502911188457673769190265049139877688522439001984850068234616395137", "price": "0.21", "size": "68.02", "side": "BUY", "timestamp": "1768475286755", "received_at": "2026-01-15T12:08:06.876799"}}
{"event_type": "price_change", "event_ts": "2026-01-15T12:08:06.876799", "ingestion_ts": "2026-01-15T12:08:42.168746", "market_id": "0x427bc4b40c09b3dcbc973747f0e4b079bed91b3e5a0aed5c36edd0f7591485f4", "raw": {"market": "0x427bc4b40c09b3dcbc973747f0e4b079bed91b3e5a0aed5c36edd0f7591485f4", "asset_id": "115669573443672055876643967408433138119481486650803218131873713375232186497057", "price": "0.79", "size": "68.02", "side": "SELL", "timestamp": "1768475286755", "received_at": "2026-01-15T12:08:06.876799"}}
{"event_type": "price_change", "event_ts": "2026-01-15T12:08:06.930711", "ingestion_ts": "2026-01-15T12:08:42.168746", "market_id": "0x427bc4b40c09b3dcbc973747f0e4b079bed91b3e5a0aed5c36edd0f7591485f4", "raw": {"market": "0x427bc4b40c09b3dcbc973747f0e4b079bed91b3e5a0aed5c36edd0f7591485f4", "asset_id": "86130975769502911188457673769190265049139877688522439001984850068234616395137", "price": "0.17", "size": "84.03", "side": "BUY", "timestamp": "1768475286805", "received_at": "2026-01-15T12:08:06.930711"}}
{"event_type": "price_change", "event_ts": "2026-01-15T12:08:06.930711", "ingestion_ts": "2026-01-15T12:08:42.168746", "market_id": "0x427bc4b40c09b3dcbc973747f0e4b079bed91b3e5a0aed5c36edd0f7591485f4", "raw": {"market": "0x427bc4b40c09b3dcbc973747f0e4b079bed91b3e5a0aed5c36edd0f7591485f4", "asset_id": "115669573443672055876643967408433138119481486650803218131873713375232186497057", "price": "0.83", "size": "84.03", "side": "SELL", "timestamp": "1768475286805", "received_at": "2026-01-15T12:08:06.930711"}}
{"event_type": "price_change", "event_ts": "2026-01-15T12:08:06.975342", "ingestion_ts": "2026-01-15T12:08:42.168746", "market_id": "0x427bc4b40c09b3dcbc973747f0e4b079bed91b3e5a0aed5c36edd0f7591485f4", "raw": {"market": "0x427bc4b40c09b3dcbc973747f0e4b079bed91b3e5a0aed5c36edd0f7591485f4", "asset_id": "86130975769502911188457673769190265049139877688522439001984850068234616395137", "price": "0.13", "size": "109.89", "side": "BUY", "timestamp": "1768475286856", "received_at": "2026-01-15T12:08:06.975342"}}
{"event_type": "price_change", "event_ts": "2026-01-15T12:08:06.975342", "ingestion_ts": "2026-01-15T12:08:42.168746", "market_id": "0x427bc4b40c09b3dcbc973747f0e4b079bed91b3e5a0aed5c36edd0f7591485f4", "raw": {"market": "0x427bc4b40c09b3dcbc973747f0e4b079bed91b3e5a0aed5c36edd0f7591485f4", "asset_id": "115669573443672055876643967408433138119481486650803218131873713375232186497057", "price": "0.87", "size": "109.89", "side": "SELL", "timestamp": "1768475286856", "received_at": "2026-01-15T12:08:06.975342"}}
{"event_type": "price_change", "event_ts": "2026-01-15T12:08:07.029332", "ingestion_ts": "2026-01-15T12:08:42.168746", "market_id": "0x427bc4b40c09b3dcbc973747f0e4b079bed91b3e5a0aed5c36edd0f7591485f4", "raw": {"market": "0x427bc4b40c09b3dcbc973747f0e4b079bed91b3e5a0aed5c36edd0f7591485f4", "asset_id": "86130975769502911188457673769190265049139877688522439001984850068234616395137", "price": "0.09", "size": "158.73", "side": "BUY", "timestamp": "1768475286913", "received_at": "2026-01-15T12:08:07.029332"}}
{"event_type": "price_change", "event_ts": "2026-01-15T12:08:07.029332", "ingestion_ts": "2026-01-15T12:08:42.168746", "market_id": "0x427bc4b40c09b3dcbc973747f0e4b079bed91b3e5a0aed5c36edd0f7591485f4", "raw": {"market": "0x427bc4b40c09b3dcbc973747f0e4b079bed91b3e5a0aed5c36edd0f7591485f4", "asset_id": "115669573443672055876643967408433138119481486650803218131873713375232186497057", "price": "0.91", "size": "158.73", "side": "SELL", "timestamp": "1768475286913", "received_at": "2026-01-15T12:08:07.029332"}}
{"event_type": "price_change", "event_ts": "2026-01-15T12:08:07.610606", "ingestion_ts": "2026-01-15T12:08:42.168746", "market_id": "0x427bc4b40c09b3dcbc973747f0e4b079bed91b3e5a0aed5c36edd0f7591485f4", "raw": {"market": "0x427bc4b40c09b3dcbc973747f0e4b079bed91b3e5a0aed5c36edd0f7591485f4", "asset_id": "115669573443672055876643967408433138119481486650803218131873713375232186497057", "price": "0.003", "size": "4.03", "side": "BUY", "timestamp": "1768475287481", "received_at": "2026-01-15T12:08:07.610606"}}
{"event_type": "price_change", "event_ts": "2026-01-15T12:08:07.610606", "ingestion_ts": "2026-01-15T12:08:42.168746", "market_id": "0x427bc4b40c09b3dcbc973747f0e4b079bed91b3e5a0aed5c36edd0f7591485f4", "raw": {"market": "0x427bc4b40c09b3dcbc973747f0e4b079bed91b3e5a0aed5c36edd0f7591485f4", "asset_id": "86130975769502911188457673769190265049139877688522439001984850068234616395137", "price": "0.997", "size": "4.03", "side": "SELL", "timestamp": "1768475287481", "received_at": "2026-01-15T12:08:07.610606"}}
{"event_type": "price_change", "event_ts": "2026-01-15T12:08:08.288078", "ingestion_ts": "2026-01-15T12:08:42.168746", "market_id": "0x427bc4b40c09b3dcbc973747f0e4b079bed91b3e5a0aed5c36edd0f7591485f4", "raw": {"market": "0x427bc4b40c09b3dcbc973747f0e4b079bed91b3e5a0aed5c36edd0f7591485f4", "asset_id": "115669573443672055876643967408433138119481486650803218131873713375232186497057", "price": "0.004", "size": "37.16", "side": "BUY", "timestamp": "1768475288114", "received_at": "2026-01-15T12:08:08.288078"}}
{"event_type": "price_change", "event_ts": "2026-01-15T12:08:08.288078", "ingestion_ts": "2026-01-15T12:08:42.168746", "market_id": "0x427bc4b40c09b3dcbc973747f0e4b079bed91b3e5a0aed5c36edd0f7591485f4", "raw": {"market": "0x427bc4b40c09b3dcbc973747f0e4b079bed91b3e5a0aed5c36edd0f7591485f4", "asset_id": "86130975769502911188457673769190265049139877688522439001984850068234616395137", "price": "0.996", "size": "37.16", "side": "SELL", "timestamp": "1768475288114", "received_at": "2026-01-15T12:08:08.288078"}}
{"event_type": "price_change", "event_ts": "2026-01-15T12:08:08.749642", "ingestion_ts": "2026-01-15T12:08:42.168746", "market_id": "0x427bc4b40c09b3dcbc973747f0e4b079bed91b3e5a0aed5c36edd0f7591485f4", "raw": {"market": "0x427bc4b40c09b3dcbc973747f0e4b079bed91b3e5a0aed5c36edd0f7591485f4", "asset_id": "115669573443672055876643967408433138119481486650803218131873713375232186497057", "price": "0.177", "size": "130.61", "side": "SELL", "timestamp": "1768475288631", "received_at": "2026-01-15T12:08:08.749642"}}
{"event_type": "price_change", "event_ts": "2026-01-15T12:08:08.749642", "ingestion_ts": "2026-01-15T12:08:42.168746", "market_id": "0x427bc4b40c09b3dcbc973747f0e4b079bed91b3e5a0aed5c36edd0f7591485f4", "raw": {"market": "0x427bc4b40c09b3dcbc973747f0e4b079bed91b3e5a0aed5c36edd0f7591485f4", "asset_id": "86130975769502911188457673769190265049139877688522439001984850068234616395137", "price": "0.823", "size": "130.61", "side": "BUY", "timestamp": "1768475288631", "received_at": "2026-01-15T12:08:08.749642"}}
{"event_type": "price_change", "event_ts": "2026-01-15T12:08:08.771649", "ingestion_ts": "2026-01-15T12:08:42.168746", "market_id": "0xc0e6b917320a47228fb96e3b5ae0e5c93773a5ae2662ae4e1f37807cfe47ce98", "raw": {"market": "0xc0e6b917320a47228fb96e3b5ae0e5c93773a5ae2662ae4e1f37807cfe47ce98", "asset_id": "58656358377246279051017109359677190749228949103591068167284263961542487110215", "price": "0.008", "size": "0", "side": "BUY", "timestamp": "1768475288645", "received_at": "2026-01-15T12:08:08.771649"}}
{"event_type": "price_change", "event_ts": "2026-01-15T12:08:08.771649", "ingestion_ts": "2026-01-15T12:08:42.168746", "market_id": "0xc0e6b917320a47228fb96e3b5ae0e5c93773a5ae2662ae4e1f37807cfe47ce98", "raw": {"market": "0xc0e6b917320a47228fb96e3b5ae0e5c93773a5ae2662ae4e1f37807cfe47ce98", "asset_id": "81647294538046680798858716589766492074338758116170717123345952330712416337530", "price": "0.992", "size": "0", "side": "SELL", "timestamp": "1768475288645", "received_at": "2026-01-15T12:08:08.771649"}}
{"event_type": "price_change", "event_ts": "2026-01-15T12:08:08.771690", "ingestion_ts": "2026-01-15T12:08:42.168746", "market_id": "0xcab7ba4a9133cfd407d7e73e5757e5abbace413b59421527a31113406c97815c", "raw": {"market": "0xcab7ba4a9133cfd407d7e73e5757e5abbace413b59421527a31113406c97815c", "asset_id": "96361925776989336186111887920533578209326565663637092688733016597062311745569", "price": "0.006", "size": "127.41", "side": "BUY", "timestamp": "1768475288645", "received_at": "2026-01-15T12:08:08.771690"}}
{"event_type": "price_change", "event_ts": "2026-01-15T12:08:08.771690", "ingestion_ts": "2026-01-15T12:08:42.168746", "market_id": "0xcab7ba4a9133cfd407d7e73e5757e5abbace413b59421527a31113406c97815c", "raw": {"market": "0xcab7ba4a9133cfd407d7e73e5757e5abbace413b59421527a31113406c97815c", "asset_id": "20002636398944597965698652220992177552927816915094913583821579024925426590022", "price": "0.994", "size": "127.41", "side": "SELL", "timestamp": "1768475288645", "received_at": "2026-01-15T12:08:08.771690"}}
{"event_type": "price_change", "event_ts": "2026-01-15T12:08:08.771705", "ingestion_ts": "2026-01-15T12:08:42.168746", "market_id": "0xcab7ba4a9133cfd407d7e73e5757e5abbace413b59421527a31113406c97815c", "raw": {"market": "0xcab7ba4a9133cfd407d7e73e5757e5abbace413b59421527a31113406c97815c", "asset_id": "96361925776989336186111887920533578209326565663637092688733016597062311745569", "price": "0.009", "size": "812.25", "side": "BUY", "timestamp": "1768475288645", "received_at": "2026-01-15T12:08:08.771705"}}
{"event_type": "price_change", "event_ts": "2026-01-15T12:08:08.771705", "ingestion_ts": "2026-01-15T12:08:42.168746", "market_id": "0xcab7ba4a9133cfd407d7e73e5757e5abbace413b59421527a31113406c97815c", "raw": {"market": "0xcab7ba4a9133cfd407d7e73e5757e5abbace413b59421527a31113406c97815c", "asset_id": "20002636398944597965698652220992177552927816915094913583821579024925426590022", "price": "0.991", "size": "812.25", "side": "SELL", "timestamp": "1768475288645", "received_at": "2026-01-15T12:08:08.771705"}}
{"event_type": "price_change", "event_ts": "2026-01-15T12:08:09.063146", "ingestion_ts": "2026-01-15T12:08:42.168746", "market_id": "0x427bc4b40c09b3dcbc973747f0e4b079bed91b3e5a0aed5c36edd0f7591485f4", "raw": {"market": "0x427bc4b40c09b3dcbc973747f0e4b079bed91b3e5a0aed5c36edd0f7591485f4", "asset_id": "115669573443672055876643967408433138119481486650803218131873713375232186497057", "price": "0.176", "size": "9.78", "side": "SELL", "timestamp": "1768475288854", "received_at": "2026-01-15T12:08:09.063146"}}
{"event_type": "price_change", "event_ts": "2026-01-15T12:08:09.063146", "ingestion_ts": "2026-01-15T12:08:42.168746", "market_id": "0x427bc4b40c09b3dcbc973747f0e4b079bed91b3e5a0aed5c36edd0f7591485f4", "raw": {"market": "0x427bc4b40c09b3dcbc973747f0e4b079bed91b3e5a0aed5c36edd0f7591485f4", "asset_id": "86130975769502911188457673769190265049139877688522439001984850068234616395137", "price": "0.824", "size": "9.78", "side": "BUY", "timestamp": "1768475288854", "received_at": "2026-01-15T12:08:09.063146"}}
{"event_type": "price_change", "event_ts": "2026-01-15T12:08:09.063210", "ingestion_ts": "2026-01-15T12:08:42.168746", "market_id": "0x427bc4b40c09b3dcbc973747f0e4b079bed91b3e5a0aed5c36edd0f7591485f4", "raw": {"market": "0x427bc4b40c09b3dcbc973747f0e4b079bed91b3e5a0aed5c36edd0f7591485f4", "asset_id": "115669573443672055876643967408433138119481486650803218131873713375232186497057", "price": "0.166", "size": "6.14", "side": "SELL", "timestamp": "1768475288855", "received_at": "2026-01-15T12:08:09.063210"}}
{"event_type": "price_change", "event_ts": "2026-01-15T12:08:09.063210", "ingestion_ts": "2026-01-15T12:08:42.168746", "market_id": "0x427bc4b40c09b3dcbc973747f0e4b079bed91b3e5a0aed5c36edd0f7591485f4", "raw": {"market": "0x427bc4b40c09b3dcbc973747f0e4b079bed91b3e5a0aed5c36edd0f7591485f4", "asset_id": "86130975769502911188457673769190265049139877688522439001984850068234616395137", "price": "0.834", "size": "6.14", "side": "BUY", "timestamp": "1768475288855", "received_at": "2026-01-15T12:08:09.063210"}}
{"event_type": "price_change", "event_ts": "2026-01-15T12:08:09.454886", "ingestion_ts": "2026-01-15T12:08:42.168746", "market_id": "0xcab7ba4a9133cfd407d7e73e5757e5abbace413b59421527a31113406c97815c", "raw": {"market": "0xcab7ba4a9133cfd407d7e73e5757e5abbace413b59421527a31113406c97815c", "asset_id": "96361925776989336186111887920533578209326565663637092688733016597062311745569", "price": "0.009", "size": "818.33", "side": "BUY", "timestamp": "1768475289318", "received_at": "2026-01-15T12:08:09.454886"}}
{"event_type": "price_change", "event_ts": "2026-01-15T12:08:09.454886", "ingestion_ts": "2026-01-15T12:08:42.168746", "market_id": "0xcab7ba4a9133cfd407d7e73e5757e5abbace413b59421527a31113406c97815c", "raw": {"market": "0xcab7ba4a9133cfd407d7e73e5757e5abbace413b59421527a31113406c97815c", "asset_id": "20002636398944597965698652220992177552927816915094913583821579024925426590022", "price": "0.991", "size": "818.33", "side": "SELL", "timestamp": "1768475289318", "received_at": "2026-01-15T12:08:09.454886"}}
{"event_type": "price_change", "event_ts": "2026-01-15T12:08:09.454927", "ingestion_ts": "2026-01-15T12:08:42.168746", "market_id": "0xc0e6b917320a47228fb96e3b5ae0e5c93773a5ae2662ae4e1f37807cfe47ce98", "raw": {"market": "0xc0e6b917320a47228fb96e3b5ae0e5c93773a5ae2662ae4e1f37807cfe47ce98", "asset_id": "58656358377246279051017109359677190749228949103591068167284263961542487110215", "price": "0.009", "size": "5.05", "side": "BUY", "timestamp": "1768475289319", "received_at": "2026-01-15T12:08:09.454927"}}
{"event_type": "price_change", "event_ts": "2026-01-15T12:08:09.454927", "ingestion_ts": "2026-01-15T12:08:42.168746", "market_id": "0xc0e6b917320a47228fb96e3b5ae0e5c93773a5ae2662ae4e1f37807cfe47ce98", "raw": {"market": "0xc0e6b917320a47228fb96e3b5ae0e5c93773a5ae2662ae4e1f37807cfe47ce98", "asset_id": "81647294538046680798858716589766492074338758116170717123345952330712416337530", "price": "0.991", "size": "5.05", "side": "SELL", "timestamp": "1768475289319", "received_at": "2026-01-15T12:08:09.454927"}}
{"event_type": "price_change", "event_ts": "2026-01-15T12:08:09.454939", "ingestion_ts": "2026-01-15T12:08:42.168746", "market_id": "0xcab7ba4a9133cfd407d7e73e5757e5abbace413b59421527a31113406c97815c", "raw": {"market": "0xcab7ba4a9133cfd407d7e73e5757e5abbace413b59421527a31113406c97815c", "asset_id": "96361925776989336186111887920533578209326565663637092688733016597062311745569", "price": "0.006", "size": "136.51", "side": "BUY", "timestamp": "1768475289319", "received_at": "2026-01-15T12:08:09.454939"}}
{"event_type": "price_change", "event_ts": "2026-01-15T12:08:09.454939", "ingestion_ts": "2026-01-15T12:08:42.168746", "market_id": "0xcab7ba4a9133cfd407d7e73e5757e5abbace413b59421527a31113406c97815c", "raw": {"market": "0xcab7ba4a9133cfd407d7e73e5757e5abbace413b59421527a31113406c97815c", "asset_id": "20002636398944597965698652220992177552927816915094913583821579024925426590022", "price": "0.994", "size": "136.51", "side": "SELL", "timestamp": "1768475289319", "received_at": "2026-01-15T12:08:09.454939"}}
{"event_type": "price_change", "event_ts": "2026-01-15T12:08:11.223951", "ingestion_ts": "2026-01-15T12:08:42.168746", "market_id": "0xcab7ba4a9133cfd407d7e73e5757e5abbace413b59421527a31113406c97815c", "raw": {"market": "0xcab7ba4a9133cfd407d7e73e5757e5abbace413b59421527a31113406c97815c", "asset_id": "96361925776989336186111887920533578209326565663637092688733016597062311745569", "price": "0.006", "size": "127.41", "side": "BUY", "timestamp": "1768475291102", "received_at": "2026-01-15T12:08:11.223951"}}
{"event_type": "price_change", "event_ts": "2026-01-15T12:08:11.223951", "ingestion_ts": "2026-01-15T12:08:42.168746", "market_id": "0xcab7ba4a9133cfd407d7e73e5757e5abbace413b59421527a31113406c97815c", "raw": {"market": "0xcab7ba4a9133cfd407d7e73e5757e5abbace413b59421527a31113406c97815c", "asset_id": "20002636398944597965698652220992177552927816915094913583821579024925426590022", "price": "0.994", "size": "127.41", "side": "SELL", "timestamp": "1768475291102", "received_at": "2026-01-15T12:08:11.223951"}}
{"event_type": "price_change", "event_ts": "2026-01-15T12:08:11.224010", "ingestion_ts": "2026-01-15T12:08:42.168746", "market_id": "0xcab7ba4a9133cfd407d7e73e5757e5abbace413b59421527a31113406c97815c", "raw": {"market": "0xcab7ba4a9133cfd407d7e73e5757e5abbace413b59421527a31113406c97815c", "asset_id": "96361925776989336186111887920533578209326565663637092688733016597062311745569", "price": "0.009", "size": "812.25", "side": "BUY", "timestamp": "1768475291102", "received_at": "2026-01-15T12:08:11.224010"}}
{"event_type": "price_change", "event_ts": "2026-01-15T12:08:11.224010", "ingestion_ts": "2026-01-15T12:08:42.168746", "market_id": "0xcab7ba4a9133cfd407d7e73e5757e5abbace413b59421527a31113406c97815c", "raw": {"market": "0xcab7ba4a9133cfd407d7e73e5757e5abbace413b59421527a31113406c97815c", "asset_id": "20002636398944597965698652220992177552927816915094913583821579024925426590022", "price": "0.991", "size": "812.25", "side": "SELL", "timestamp": "1768475291102", "received_at": "2026-01-15T12:08:11.224010"}}
{"event_type": "price_change", "event_ts": "2026-01-15T12:08:11.841140", "ingestion_ts": "2026-01-15T12:08:42.168746", "market_id": "0xcab7ba4a9133cfd407d7e73e5757e5abbace413b59421527a31113406c97815c", "raw": {"market": "0xcab7ba4a9133cfd407d7e73e5757e5abbace413b59421527a31113406c97815c", "asset_id": "96361925776989336186111887920533578209326565663637092688733016597062311745569", "price": "0.009", "size": "818.33", "side": "BUY", "timestamp": "1768475291720", "received_at": "2026-01-15T12:08:11.841140"}}
{"event_type": "price_change", "event_ts": "2026-01-15T12:08:11.841140", "ingestion_ts": "2026-01-15T12:08:42.168746", "market_id": "0xcab7ba4a9133cfd407d7e73e5757e5abbace413b59421527a31113406c97815c", "raw": {"market": "0xcab7ba4a9133cfd407d7e73e5757e5abbace413b59421527a31113406c97815c", "asset_id": "20002636398944597965698652220992177552927816915094913583821579024925426590022", "price": "0.991", "size": "818.33", "side": "SELL", "timestamp": "1768475291720", "received_at": "2026-01-15T12:08:11.841140"}}
{"event_type": "price_change", "event_ts": "2026-01-15T12:08:11.841193", "ingestion_ts": "2026-01-15T12:08:42.168746", "market_id": "0xcab7ba4a9133cfd407d7e73e5757e5abbace413b59421527a31113406c97815c", "raw": {"market": "0xcab7ba4a9133cfd407d7e73e5757e5abbace413b59421527a31113406c97815c", "asset_id": "96361925776989336186111887920533578209326565663637092688733016597062311745569", "price": "0.006", "size": "136.51", "side": "BUY", "timestamp": "1768475291721", "received_at": "2026-01-15T12:08:11.841193"}}
{"event_type": "price_change", "event_ts": "2026-01-15T12:08:11.841193", "ingestion_ts": "2026-01-15T12:08:42.168746", "market_id": "0xcab7ba4a9133cfd407d7e73e5757e5abbace413b59421527a31113406c97815c", "raw": {"market": "0xcab7ba4a9133cfd407d7e73e5757e5abbace413b59421527a31113406c97815c", "asset_id": "20002636398944597965698652220992177552927816915094913583821579024925426590022", "price": "0.994", "size": "136.51", "side": "SELL", "timestamp": "1768475291721", "received_at": "2026-01-15T12:08:11.841193"}}
{"event_type": "price_change", "event_ts": "2026-01-15T12:08:12.179743", "ingestion_ts": "2026-01-15T12:08:42.168746", "market_id": "0xc0e6b917320a47228fb96e3b5ae0e5c93773a5ae2662ae4e1f37807cfe47ce98", "raw": {"market": "0xc0e6b917320a47228fb96e3b5ae0e5c93773a5ae2662ae4e1f37807cfe47ce98", "asset_id": "58656358377246279051017109359677190749228949103591068167284263961542487110215", "price": "0.009", "size": "0", "side": "BUY", "timestamp": "1768475292043", "received_at": "2026-01-15T12:08:12.179743"}}
{"event_type": "price_change", "event_ts": "2026-01-15T12:08:12.179743", "ingestion_ts": "2026-01-15T12:08:42.168746", "market_id": "0xc0e6b917320a47228fb96e3b5ae0e5c93773a5ae2662ae4e1f37807cfe47ce98", "raw": {"market": "0xc0e6b917320a47228fb96e3b5ae0e5c93773a5ae2662ae4e1f37807cfe47ce98", "asset_id": "81647294538046680798858716589766492074338758116170717123345952330712416337530", "price": "0.991", "size": "0", "side": "SELL", "timestamp": "1768475292043", "received_at": "2026-01-15T12:08:12.179743"}}
{"event_type": "price_change", "event_ts": "2026-01-15T12:08:12.240536", "ingestion_ts": "2026-01-15T12:08:42.168746", "market_id": "0xc0e6b917320a47228fb96e3b5ae0e5c93773a5ae2662ae4e1f37807cfe47ce98", "raw": {"market": "0xc0e6b917320a47228fb96e3b5ae0e5c93773a5ae2662ae4e1f37807cfe47ce98", "asset_id": "58656358377246279051017109359677190749228949103591068167284263961542487110215", "price": "0.16", "size": "0", "side": "SELL", "timestamp": "1768475292101", "received_at": "2026-01-15T12:08:12.240536"}}
{"event_type": "price_change", "event_ts": "2026-01-15T12:08:12.240536", "ingestion_ts": "2026-01-15T12:08:42.168746", "market_id": "0xc0e6b917320a47228fb96e3b5ae0e5c93773a5ae2662ae4e1f37807cfe47ce98", "raw": {"market": "0xc0e6b917320a47228fb96e3b5ae0e5c93773a5ae2662ae4e1f37807cfe47ce98", "asset_id": "81647294538046680798858716589766492074338758116170717123345952330712416337530", "price": "0.84", "size": "0", "side": "BUY", "timestamp": "1768475292101", "received_at": "2026-01-15T12:08:12.240536"}}
{"event_type": "price_change", "event_ts": "2026-01-15T12:08:12.392331", "ingestion_ts": "2026-01-15T12:08:42.168746", "market_id": "0x427bc4b40c09b3dcbc973747f0e4b079bed91b3e5a0aed5c36edd0f7591485f4", "raw": {"market": "0x427bc4b40c09b3dcbc973747f0e4b079bed91b3e5a0aed5c36edd0f7591485f4", "asset_id": "115669573443672055876643967408433138119481486650803218131873713375232186497057", "price": "0.004", "size": "28.07", "side": "BUY", "timestamp": "1768475292268", "received_at": "2026-01-15T12:08:12.392331"}}
{"event_type": "price_change", "event_ts": "2026-01-15T12:08:12.392331", "ingestion_ts": "2026-01-15T12:08:42.168746", "market_id": "0x427bc4b40c09b3dcbc973747f0e4b079bed91b3e5a0aed5c36edd0f7591485f4", "raw": {"market": "0x427bc4b40c09b3dcbc973747f0e4b079bed91b3e5a0aed5c36edd0f7591485f4", "asset_id": "86130975769502911188457673769190265049139877688522439001984850068234616395137", "price": "0.996", "size": "28.07", "side": "SELL", "timestamp": "1768475292268", "received_at": "2026-01-15T12:08:12.392331"}}
{"event_type": "price_change", "event_ts": "2026-01-15T12:08:12.392395", "ingestion_ts": "2026-01-15T12:08:42.168746", "market_id": "0x427bc4b40c09b3dcbc973747f0e4b079bed91b3e5a0aed5c36edd0f7591485f4", "raw": {"market": "0x427bc4b40c09b3dcbc973747f0e4b079bed91b3e5a0aed5c36edd0f7591485f4", "asset_id": "115669573443672055876643967408433138119481486650803218131873713375232186497057", "price": "0.005", "size": "13.09", "side": "BUY", "timestamp": "1768475292268", "received_at": "2026-01-15T12:08:12.392395"}}
{"event_type": "price_change", "event_ts": "2026-01-15T12:08:12.392395", "ingestion_ts": "2026-01-15T12:08:42.168746", "market_id": "0x427bc4b40c09b3dcbc973747f0e4b079bed91b3e5a0aed5c36edd0f7591485f4", "raw": {"market": "0x427bc4b40c09b3dcbc973747f0e4b079bed91b3e5a0aed5c36edd0f7591485f4", "asset_id": "86130975769502911188457673769190265049139877688522439001984850068234616395137", "price": "0.995", "size": "13.09", "side": "SELL", "timestamp": "1768475292268", "received_at": "2026-01-15T12:08:12.392395"}}
{"event_type": "price_change", "event_ts": "2026-01-15T12:08:12.776363", "ingestion_ts": "2026-01-15T12:08:42.168746", "market_id": "0xc0e6b917320a47228fb96e3b5ae0e5c93773a5ae2662ae4e1f37807cfe47ce98", "raw": {"market": "0xc0e6b917320a47228fb96e3b5ae0e5c93773a5ae2662ae4e1f37807cfe47ce98", "asset_id": "58656358377246279051017109359677190749228949103591068167284263961542487110215", "price": "0.159", "size": "431", "side": "SELL", "timestamp": "1768475292654", "received_at": "2026-01-15T12:08:12.776363"}}
{"event_type": "price_change", "event_ts": "2026-01-15T12:08:12.776363", "ingestion_ts": "2026-01-15T12:08:42.168746", "market_id": "0xc0e6b917320a47228fb96e3b5ae0e5c93773a5ae2662ae4e1f37807cfe47ce98", "raw": {"market": "0xc0e6b917320a47228fb96e3b5ae0e5c93773a5ae2662ae4e1f37807cfe47ce98", "asset_id": "81647294538046680798858716589766492074338758116170717123345952330712416337530", "price": "0.841", "size": "431", "side": "BUY", "timestamp": "1768475292654", "received_at": "2026-01-15T12:08:12.776363"}}
{"event_type": "price_change", "event_ts": "2026-01-15T12:08:13.081834", "ingestion_ts": "2026-01-15T12:08:42.168746", "market_id": "0x427bc4b40c09b3dcbc973747f0e4b079bed91b3e5a0aed5c36edd0f7591485f4", "raw": {"market": "0x427bc4b40c09b3dcbc973747f0e4b079bed91b3e5a0aed5c36edd0f7591485f4", "asset_id": "115669573443672055876643967408433138119481486650803218131873713375232186497057", "price": "0.002", "size": "74.73", "side": "BUY", "timestamp": "1768475292962", "received_at": "2026-01-15T12:08:13.081834"}}
{"event_type": "price_change", "event_ts": "2026-01-15T12:08:13.081834", "ingestion_ts": "2026-01-15T12:08:42.168746", "market_id": "0x427bc4b40c09b3dcbc973747f0e4b079bed91b3e5a0aed5c36edd0f7591485f4", "raw": {"market": "0x427bc4b40c09b3dcbc973747f0e4b079bed91b3e5a0aed5c36edd0f7591485f4", "asset_id": "86130975769502911188457673769190265049139877688522439001984850068234616395137", "price": "0.998", "size": "74.73", "side": "SELL", "timestamp": "1768475292962", "received_at": "2026-01-15T12:08:13.081834"}}
{"event_type": "price_change", "event_ts": "2026-01-15T12:08:13.081895", "ingestion_ts": "2026-01-15T12:08:42.168746", "market_id": "0x427bc4b40c09b3dcbc973747f0e4b079bed91b3e5a0aed5c36edd0f7591485f4", "raw": {"market": "0x427bc4b40c09b3dcbc973747f0e4b079bed91b3e5a0aed5c36edd0f7591485f4", "asset_id": "115669573443672055876643967408433138119481486650803218131873713375232186497057", "price": "0.005", "size": "18.5", "side": "BUY", "timestamp": "1768475292963", "received_at": "2026-01-15T12:08:13.081895"}}
{"event_type": "price_change", "event_ts": "2026-01-15T12:08:13.081895", "ingestion_ts": "2026-01-15T12:08:42.168746", "market_id": "0x427bc4b40c09b3dcbc973747f0e4b079bed91b3e5a0aed5c36edd0f7591485f4", "raw": {"market": "0x427bc4b40c09b3dcbc973747f0e4b079bed91b3e5a0aed5c36edd0f7591485f4", "asset_id": "86130975769502911188457673769190265049139877688522439001984850068234616395137", "price": "0.995", "size": "18.5", "side": "SELL", "timestamp": "1768475292963", "received_at": "2026-01-15T12:08:13.081895"}}
{"event_type": "price_change", "event_ts": "2026-01-15T12:08:13.353693", "ingestion_ts": "2026-01-15T12:08:42.168746", "market_id": "0xc0e6b917320a47228fb96e3b5ae0e5c93773a5ae2662ae4e1f37807cfe47ce98", "raw": {"market": "0xc0e6b917320a47228fb96e3b5ae0e5c93773a5ae2662ae4e1f37807cfe47ce98", "asset_id": "58656358377246279051017109359677190749228949103591068167284263961542487110215", "price": "0.003", "size": "452.62", "side": "BUY", "timestamp": "1768475293222", "received_at": "2026-01-15T12:08:13.353693"}}
{"event_type": "price_change", "event_ts": "2026-01-15T12:08:13.353693", "ingestion_ts": "2026-01-15T12:08:42.168746", "market_id": "0xc0e6b917320a47228fb96e3b5ae0e5c93773a5ae2662ae4e1f37807cfe47ce98", "raw": {"market": "0xc0e6b917320a47228fb96e3b5ae0e5c93773a5ae2662ae4e1f37807cfe47ce98", "asset_id": "81647294538046680798858716589766492074338758116170717123345952330712416337530", "price": "0.997", "size": "452.62", "side": "SELL", "timestamp": "1768475293222", "received_at": "2026-01-15T12:08:13.353693"}}
{"event_type": "price_change", "event_ts": "2026-01-15T12:08:13.353750", "ingestion_ts": "2026-01-15T12:08:42.168746", "market_id": "0xc0e6b917320a47228fb96e3b5ae0e5c93773a5ae2662ae4e1f37807cfe47ce98", "raw": {"market": "0xc0e6b917320a47228fb96e3b5ae0e5c93773a5ae2662ae4e1f37807cfe47ce98", "asset_id": "58656358377246279051017109359677190749228949103591068167284263961542487110215", "price": "0.003", "size": "460.2", "side": "BUY", "timestamp": "1768475293223", "received_at": "2026-01-15T12:08:13.353750"}}
{"event_type": "price_change", "event_ts": "2026-01-15T12:08:13.353750", "ingestion_ts": "2026-01-15T12:08:42.168746", "market_id": "0xc0e6b917320a47228fb96e3b5ae0e5c93773a5ae2662ae4e1f37807cfe47ce98", "raw": {"market": "0xc0e6b917320a47228fb96e3b5ae0e5c93773a5ae2662ae4e1f37807cfe47ce98", "asset_id": "81647294538046680798858716589766492074338758116170717123345952330712416337530", "price": "0.997", "size": "460.2", "side": "SELL", "timestamp": "1768475293223", "received_at": "2026-01-15T12:08:13.353750"}}
{"event_type": "price_change", "event_ts": "2026-01-15T12:08:13.392541", "ingestion_ts": "2026-01-15T12:08:42.168746", "market_id": "0xea644975be7b2ad32b536a94ae21b707ecb2f84290225b24e60ca46dd77903dd", "raw": {"market": "0xea644975be7b2ad32b536a94ae21b707ecb2f84290225b24e60ca46dd77903dd", "asset_id": "19255594762111702415265750364124818677094538461124581923455280001407159960455", "price": "0.852", "size": "0", "side": "BUY", "timestamp": "1768475293275", "received_at": "2026-01-15T12:08:13.392541"}}
{"event_type": "price_change", "event_ts": "2026-01-15T12:08:13.392541", "ingestion_ts": "2026-01-15T12:08:42.168746", "market_id": "0xea644975be7b2ad32b536a94ae21b707ecb2f84290225b24e60ca46dd77903dd", "raw": {"market": "0xea644975be7b2ad32b536a94ae21b707ecb2f84290225b24e60ca46dd77903dd", "asset_id": "110044455628775971785618539427229099821815416148768008176051068105157446559241", "price": "0.148", "size": "0", "side": "SELL", "timestamp": "1768475293275", "received_at": "2026-01-15T12:08:13.392541"}}
{"event_type": "price_change", "event_ts": "2026-01-15T12:08:13.392589", "ingestion_ts": "2026-01-15T12:08:42.168746", "market_id": "0xe68594f1350f5535532b24979b5b5c1948432cbfc0c363802c32a8f9ab4e6509", "raw": {"market": "0xe68594f1350f5535532b24979b5b5c1948432cbfc0c363802c32a8f9ab4e6509", "asset_id": "3074032031589250926591186368301243337494992039402397918135503567058257050088", "price": "0.852", "size": "0", "side": "BUY", "timestamp": "1768475293275", "received_at": "2026-01-15T12:08:13.392589"}}
{"event_type": "price_change", "event_ts": "2026-01-15T12:08:13.392589", "ingestion_ts": "2026-01-15T12:08:42.168746", "market_id": "0xe68594f1350f5535532b24979b5b5c1948432cbfc0c363802c32a8f9ab4e6509", "raw": {"market": "0xe68594f1350f5535532b24979b5b5c1948432cbfc0c363802c32a8f9ab4e6509", "asset_id": "47459180813047899567328389455747872955901265556145057896316155826890276004242", "price": "0.148", "size": "0", "side": "SELL", "timestamp": "1768475293275", "received_at": "2026-01-15T12:08:13.392589"}}
{"event_type": "price_change", "event_ts": "2026-01-15T12:08:13.392603", "ingestion_ts": "2026-01-15T12:08:42.168746", "market_id": "0x50e477f0b316a3d97d60486479657c63be0763834d0e2e8a30b1b86dc3c1c001", "raw": {"market": "0x50e477f0b316a3d97d60486479657c63be0763834d0e2e8a30b1b86dc3c1c001", "asset_id": "39981134260608444876865205057565852475343967395624370698967311821208058420507", "price": "0.851", "size": "0", "side": "BUY", "timestamp": "1768475293275", "received_at": "2026-01-15T12:08:13.392603"}}
{"event_type": "price_change", "event_ts": "2026-01-15T12:08:13.392603", "ingestion_ts": "2026-01-15T12:08:42.168746", "market_id": "0x50e477f0b316a3d97d60486479657c63be0763834d0e2e8a30b1b86dc3c1c001", "raw": {"market": "0x50e477f0b316a3d97d60486479657c63be0763834d0e2e8a30b1b86dc3c1c001", "asset_id": "60573178197991590327120832143415406583517170365625050489007297367895074266641", "price": "0.149", "size": "0", "side": "SELL", "timestamp": "1768475293275", "received_at": "2026-01-15T12:08:13.392603"}}
{"event_type": "price_change", "event_ts": "2026-01-15T12:08:13.563870", "ingestion_ts": "2026-01-15T12:08:42.168746", "market_id": "0x427bc4b40c09b3dcbc973747f0e4b079bed91b3e5a0aed5c36edd0f7591485f4", "raw": {"market": "0x427bc4b40c09b3dcbc973747f0e4b079bed91b3e5a0aed5c36edd0f7591485f4", "asset_id": "115669573443672055876643967408433138119481486650803218131873713375232186497057", "price": "0.176", "size": "0", "side": "SELL", "timestamp": "1768475293447", "received_at": "2026-01-15T12:08:13.563870"}}
{"event_type": "price_change", "event_ts": "2026-01-15T12:08:13.563870", "ingestion_ts": "2026-01-15T12:08:42.168746", "market_id": "0x427bc4b40c09b3dcbc973747f0e4b079bed91b3e5a0aed5c36edd0f7591485f4", "raw": {"market": "0x427bc4b40c09b3dcbc973747f0e4b079bed91b3e5a0aed5c36edd0f7591485f4", "asset_id": "86130975769502911188457673769190265049139877688522439001984850068234616395137", "price": "0.824", "size": "0", "side": "BUY", "timestamp": "1768475293447", "received_at": "2026-01-15T12:08:13.563870"}}
{"event_type": "price_change", "event_ts": "2026-01-15T12:08:13.893180", "ingestion_ts": "2026-01-15T12:08:42.168746", "market_id": "0x427bc4b40c09b3dcbc973747f0e4b079bed91b3e5a0aed5c36edd0f7591485f4", "raw": {"market": "0x427bc4b40c09b3dcbc973747f0e4b079bed91b3e5a0aed5c36edd0f7591485f4", "asset_id": "115669573443672055876643967408433138119481486650803218131873713375232186497057", "price": "0.175", "size": "9.78", "side": "SELL", "timestamp": "1768475293772", "received_at": "2026-01-15T12:08:13.893180"}}
{"event_type": "price_change", "event_ts": "2026-01-15T12:08:13.893180", "ingestion_ts": "2026-01-15T12:08:42.168746", "market_id": "0x427bc4b40c09b3dcbc973747f0e4b079bed91b3e5a0aed5c36edd0f7591485f4", "raw": {"market": "0x427bc4b40c09b3dcbc973747f0e4b079bed91b3e5a0aed5c36edd0f7591485f4", "asset_id": "86130975769502911188457673769190265049139877688522439001984850068234616395137", "price": "0.825", "size": "9.78", "side": "BUY", "timestamp": "1768475293772", "received_at": "2026-01-15T12:08:13.893180"}}
{"event_type": "price_change", "event_ts": "2026-01-15T12:08:14.128062", "ingestion_ts": "2026-01-15T12:08:42.168746", "market_id": "0x49686d26fb712515cd5e12c23f0a1c7e10214c7faa3cb0a730aabe0c33694082", "raw": {"market": "0x49686d26fb712515cd5e12c23f0a1c7e10214c7faa3cb0a730aabe0c33694082", "asset_id": "30442780799048074404860985387051749017905070253466005720364298335239299761065", "price": "0.006", "size": "0", "side": "BUY", "timestamp": "1768475294001", "received_at": "2026-01-15T12:08:14.128062"}}
{"event_type": "price_change", "event_ts": "2026-01-15T12:08:14.128062", "ingestion_ts": "2026-01-15T12:08:42.168746", "market_id": "0x49686d26fb712515cd5e12c23f0a1c7e10214c7faa3cb0a730aabe0c33694082", "raw": {"market": "0x49686d26fb712515cd5e12c23f0a1c7e10214c7faa3cb0a730aabe0c33694082", "asset_id": "13244681086321087932946246027856416106585284024824496763706748621681543444582", "price": "0.994", "size": "0", "side": "SELL", "timestamp": "1768475294001", "received_at": "2026-01-15T12:08:14.128062"}}
{"event_type": "price_change", "event_ts": "2026-01-15T12:08:14.188012", "ingestion_ts": "2026-01-15T12:08:42.168746", "market_id": "0xc0e6b917320a47228fb96e3b5ae0e5c93773a5ae2662ae4e1f37807cfe47ce98", "raw": {"market": "0xc0e6b917320a47228fb96e3b5ae0e5c93773a5ae2662ae4e1f37807cfe47ce98", "asset_id": "58656358377246279051017109359677190749228949103591068167284263961542487110215", "price": "0.159", "size": "426", "side": "SELL", "timestamp": "1768475294070", "received_at": "2026-01-15T12:08:14.188012"}}
{"event_type": "price_change", "event_ts": "2026-01-15T12:08:14.188012", "ingestion_ts": "2026-01-15T12:08:42.168746", "market_id": "0xc0e6b917320a47228fb96e3b5ae0e5c93773a5ae2662ae4e1f37807cfe47ce98", "raw": {"market": "0xc0e6b917320a47228fb96e3b5ae0e5c93773a5ae2662ae4e1f37807cfe47ce98", "asset_id": "81647294538046680798858716589766492074338758116170717123345952330712416337530", "price": "0.841", "size": "426", "side": "BUY", "timestamp": "1768475294070", "received_at": "2026-01-15T12:08:14.188012"}}
{"event_type": "price_change", "event_ts": "2026-01-15T12:08:14.188062", "ingestion_ts": "2026-01-15T12:08:42.168746", "market_id": "0xcab7ba4a9133cfd407d7e73e5757e5abbace413b59421527a31113406c97815c", "raw": {"market": "0xcab7ba4a9133cfd407d7e73e5757e5abbace413b59421527a31113406c97815c", "asset_id": "96361925776989336186111887920533578209326565663637092688733016597062311745569", "price": "0.006", "size": "127.41", "side": "BUY", "timestamp": "1768475294070", "received_at": "2026-01-15T12:08:14.188062"}}
{"event_type": "price_change", "event_ts": "2026-01-15T12:08:14.188062", "ingestion_ts": "2026-01-15T12:08:42.168746", "market_id": "0xcab7ba4a9133cfd407d7e73e5757e5abbace413b59421527a31113406c97815c", "raw": {"market": "0xcab7ba4a9133cfd407d7e73e5757e5abbace413b59421527a31113406c97815c", "asset_id": "20002636398944597965698652220992177552927816915094913583821579024925426590022", "price": "0.994", "size": "127.41", "side": "SELL", "timestamp": "1768475294070", "received_at": "2026-01-15T12:08:14.188062"}}
{"event_type": "price_change", "event_ts": "2026-01-15T12:08:14.188073", "ingestion_ts": "2026-01-15T12:08:42.168746", "market_id": "0xcab7ba4a9133cfd407d7e73e5757e5abbace413b59421527a31113406c97815c", "raw": {"market": "0xcab7ba4a9133cfd407d7e73e5757e5abbace413b59421527a31113406c97815c", "asset_id": "96361925776989336186111887920533578209326565663637092688733016597062311745569", "price": "0.009", "size": "812.25", "side": "BUY", "timestamp": "1768475294070", "received_at": "2026-01-15T12:08:14.188073"}}
{"event_type": "price_change", "event_ts": "2026-01-15T12:08:14.188073", "ingestion_ts": "2026-01-15T12:08:42.168746", "market_id": "0xcab7ba4a9133cfd407d7e73e5757e5abbace413b59421527a31113406c97815c", "raw": {"market": "0xcab7ba4a9133cfd407d7e73e5757e5abbace413b59421527a31113406c97815c", "asset_id": "20002636398944597965698652220992177552927816915094913583821579024925426590022", "price": "0.991", "size": "812.25", "side": "SELL", "timestamp": "1768475294070", "received_at": "2026-01-15T12:08:14.188073"}}
{"event_type": "price_change", "event_ts": "2026-01-15T12:08:14.212021", "ingestion_ts": "2026-01-15T12:08:42.168746", "market_id": "0xe68594f1350f5535532b24979b5b5c1948432cbfc0c363802c32a8f9ab4e6509", "raw": {"market": "0xe68594f1350f5535532b24979b5b5c1948432cbfc0c363802c32a8f9ab4e6509", "asset_id": "3074032031589250926591186368301243337494992039402397918135503567058257050088", "price": "0.852", "size": "10", "side": "BUY", "timestamp": "1768475294095", "received_at": "2026-01-15T12:08:14.212021"}}
{"event_type": "price_change", "event_ts": "2026-01-15T12:08:14.212021", "ingestion_ts": "2026-01-15T12:08:42.168746", "market_id": "0xe68594f1350f5535532b24979b5b5c1948432cbfc0c363802c32a8f9ab4e6509", "raw": {"market": "0xe68594f1350f5535532b24979b5b5c1948432cbfc0c363802c32a8f9ab4e6509", "asset_id": "47459180813047899567328389455747872955901265556145057896316155826890276004242", "price": "0.148", "size": "10", "side": "SELL", "timestamp": "1768475294095", "received_at": "2026-01-15T12:08:14.212021"}}
{"event_type": "price_change", "event_ts": "2026-01-15T12:08:14.212072", "ingestion_ts": "2026-01-15T12:08:42.168746", "market_id": "0xea644975be7b2ad32b536a94ae21b707ecb2f84290225b24e60ca46dd77903dd", "raw": {"market": "0xea644975be7b2ad32b536a94ae21b707ecb2f84290225b24e60ca46dd77903dd", "asset_id": "19255594762111702415265750364124818677094538461124581923455280001407159960455", "price": "0.852", "size": "10", "side": "BUY", "timestamp": "1768475294095", "received_at": "2026-01-15T12:08:14.212072"}}
{"event_type": "price_change", "event_ts": "2026-01-15T12:08:14.212072", "ingestion_ts": "2026-01-15T12:08:42.168746", "market_id": "0xea644975be7b2ad32b536a94ae21b707ecb2f84290225b24e60ca46dd77903dd", "raw": {"market": "0xea644975be7b2ad32b536a94ae21b707ecb2f84290225b24e60ca46dd77903dd", "asset_id": "110044455628775971785618539427229099821815416148768008176051068105157446559241", "price": "0.148", "size": "10", "side": "SELL", "timestamp": "1768475294095", "received_at": "2026-01-15T12:08:14.212072"}}
{"event_type": "price_change", "event_ts": "2026-01-15T12:08:14.212642", "ingestion_ts": "2026-01-15T12:08:42.168746", "market_id": "0x50e477f0b316a3d97d60486479657c63be0763834d0e2e8a30b1b86dc3c1c001", "raw": {"market": "0x50e477f0b316a3d97d60486479657c63be0763834d0e2e8a30b1b86dc3c1c001", "asset_id": "39981134260608444876865205057565852475343967395624370698967311821208058420507", "price": "0.851", "size": "10", "side": "BUY", "timestamp": "1768475294095", "received_at": "2026-01-15T12:08:14.212642"}}
{"event_type": "price_change", "event_ts": "2026-01-15T12:08:14.212642", "ingestion_ts": "2026-01-15T12:08:42.168746", "market_id": "0x50e477f0b316a3d97d60486479657c63be0763834d0e2e8a30b1b86dc3c1c001", "raw": {"market": "0x50e477f0b316a3d97d60486479657c63be0763834d0e2e8a30b1b86dc3c1c001", "asset_id": "60573178197991590327120832143415406583517170365625050489007297367895074266641", "price": "0.149", "size": "10", "side": "SELL", "timestamp": "1768475294095", "received_at": "2026-01-15T12:08:14.212642"}}
{"event_type": "price_change", "event_ts": "2026-01-15T12:08:15.285682", "ingestion_ts": "2026-01-15T12:08:42.168746", "market_id": "0xcab7ba4a9133cfd407d7e73e5757e5abbace413b59421527a31113406c97815c", "raw": {"market": "0xcab7ba4a9133cfd407d7e73e5757e5abbace413b59421527a31113406c97815c", "asset_id": "96361925776989336186111887920533578209326565663637092688733016597062311745569", "price": "0.009", "size": "818.33", "side": "BUY", "timestamp": "1768475295167", "received_at": "2026-01-15T12:08:15.285682"}}
{"event_type": "price_change", "event_ts": "2026-01-15T12:08:15.285682", "ingestion_ts": "2026-01-15T12:08:42.168746", "market_id": "0xcab7ba4a9133cfd407d7e73e5757e5abbace413b59421527a31113406c97815c", "raw": {"market": "0xcab7ba4a9133cfd407d7e73e5757e5abbace413b59421527a31113406c97815c", "asset_id": "20002636398944597965698652220992177552927816915094913583821579024925426590022", "price": "0.991", "size": "818.33", "side": "SELL", "timestamp": "1768475295167", "received_at": "2026-01-15T12:08:15.285682"}}
{"event_type": "price_change", "event_ts": "2026-01-15T12:08:15.287235", "ingestion_ts": "2026-01-15T12:08:42.168746", "market_id": "0xc0e6b917320a47228fb96e3b5ae0e5c93773a5ae2662ae4e1f37807cfe47ce98", "raw": {"market": "0xc0e6b917320a47228fb96e3b5ae0e5c93773a5ae2662ae4e1f37807cfe47ce98", "asset_id": "58656358377246279051017109359677190749228949103591068167284263961542487110215", "price": "0.158", "size": "5", "side": "SELL", "timestamp": "1768475295167", "received_at": "2026-01-15T12:08:15.287235"}}
{"event_type": "price_change", "event_ts": "2026-01-15T12:08:15.287235", "ingestion_ts": "2026-01-15T12:08:42.168746", "market_id": "0xc0e6b917320a47228fb96e3b5ae0e5c93773a5ae2662ae4e1f37807cfe47ce98", "raw": {"market": "0xc0e6b917320a47228fb96e3b5ae0e5c93773a5ae2662ae4e1f37807cfe47ce98", "asset_id": "81647294538046680798858716589766492074338758116170717123345952330712416337530", "price": "0.842", "size": "5", "side": "BUY", "timestamp": "1768475295167", "received_at": "2026-01-15T12:08:15.287235"}}
{"event_type": "price_change", "event_ts": "2026-01-15T12:08:15.300421", "ingestion_ts": "2026-01-15T12:08:42.168746", "market_id": "0xcab7ba4a9133cfd407d7e73e5757e5abbace413b59421527a31113406c97815c", "raw": {"market": "0xcab7ba4a9133cfd407d7e73e5757e5abbace413b59421527a31113406c97815c", "asset_id": "96361925776989336186111887920533578209326565663637092688733016597062311745569", "price": "0.006", "size": "136.51", "side": "BUY", "timestamp": "1768475295170", "received_at": "2026-01-15T12:08:15.300421"}}
{"event_type": "price_change", "event_ts": "2026-01-15T12:08:15.300421", "ingestion_ts": "2026-01-15T12:08:42.168746", "market_id": "0xcab7ba4a9133cfd407d7e73e5757e5abbace413b59421527a31113406c97815c", "raw": {"market": "0xcab7ba4a9133cfd407d7e73e5757e5abbace413b59421527a31113406c97815c", "asset_id": "20002636398944597965698652220992177552927816915094913583821579024925426590022", "price": "0.994", "size": "136.51", "side": "SELL", "timestamp": "1768475295170", "received_at": "2026-01-15T12:08:15.300421"}}
{"event_type": "price_change", "event_ts": "2026-01-15T12:08:17.063632", "ingestion_ts": "2026-01-15T12:08:42.168746", "market_id": "0xcab7ba4a9133cfd407d7e73e5757e5abbace413b59421527a31113406c97815c", "raw": {"market": "0xcab7ba4a9133cfd407d7e73e5757e5abbace413b59421527a31113406c97815c", "asset_id": "96361925776989336186111887920533578209326565663637092688733016597062311745569", "price": "0.006", "size": "127.41", "side": "BUY", "timestamp": "1768475296940", "received_at": "2026-01-15T12:08:17.063632"}}
{"event_type": "price_change", "event_ts": "2026-01-15T12:08:17.063632", "ingestion_ts": "2026-01-15T12:08:42.168746", "market_id": "0xcab7ba4a9133cfd407d7e73e5757e5abbace413b59421527a31113406c97815c", "raw": {"market": "0xcab7ba4a9133cfd407d7e73e5757e5abbace413b59421527a31113406c97815c", "asset_id": "20002636398944597965698652220992177552927816915094913583821579024925426590022", "price": "0.994", "size": "127.41", "side": "SELL", "timestamp": "1768475296940", "received_at": "2026-01-15T12:08:17.063632"}}
{"event_type": "price_change", "event_ts": "2026-01-15T12:08:17.063705", "ingestion_ts": "2026-01-15T12:08:42.168746", "market_id": "0xcab7ba4a9133cfd407d7e73e5757e5abbace413b59421527a31113406c97815c", "raw": {"market": "0xcab7ba4a9133cfd407d7e73e5757e5abbace413b59421527a31113406c97815c", "asset_id": "96361925776989336186111887920533578209326565663637092688733016597062311745569", "price": "0.009", "size": "812.25", "side": "BUY", "timestamp": "1768475296940", "received_at": "2026-01-15T12:08:17.063705"}}
{"event_type": "price_change", "event_ts": "2026-01-15T12:08:17.063705", "ingestion_ts": "2026-01-15T12:08:42.168746", "market_id": "0xcab7ba4a9133cfd407d7e73e5757e5abbace413b59421527a31113406c97815c", "raw": {"market": "0xcab7ba4a9133cfd407d7e73e5757e5abbace413b59421527a31113406c97815c", "asset_id": "20002636398944597965698652220992177552927816915094913583821579024925426590022", "price": "0.991", "size": "812.25", "side": "SELL", "timestamp": "1768475296940", "received_at": "2026-01-15T12:08:17.063705"}}
{"event_type": "price_change", "event_ts": "2026-01-15T12:08:18.207353", "ingestion_ts": "2026-01-15T12:08:42.168746", "market_id": "0xc0e6b917320a47228fb96e3b5ae0e5c93773a5ae2662ae4e1f37807cfe47ce98", "raw": {"market": "0xc0e6b917320a47228fb96e3b5ae0e5c93773a5ae2662ae4e1f37807cfe47ce98", "asset_id": "58656358377246279051017109359677190749228949103591068167284263961542487110215", "price": "0.003", "size": "433.58", "side": "BUY", "timestamp": "1768475298090", "received_at": "2026-01-15T12:08:18.207353"}}
{"event_type": "price_change", "event_ts": "2026-01-15T12:08:18.207353", "ingestion_ts": "2026-01-15T12:08:42.168746", "market_id": "0xc0e6b917320a47228fb96e3b5ae0e5c93773a5ae2662ae4e1f37807cfe47ce98", "raw": {"market": "0xc0e6b917320a47228fb96e3b5ae0e5c93773a5ae2662ae4e1f37807cfe47ce98", "asset_id": "81647294538046680798858716589766492074338758116170717123345952330712416337530", "price": "0.997", "size": "433.58", "side": "SELL", "timestamp": "1768475298090", "received_at": "2026-01-15T12:08:18.207353"}}
{"event_type": "price_change", "event_ts": "2026-01-15T12:08:18.287436", "ingestion_ts": "2026-01-15T12:08:42.168746", "market_id": "0xcab7ba4a9133cfd407d7e73e5757e5abbace413b59421527a31113406c97815c", "raw": {"market": "0xcab7ba4a9133cfd407d7e73e5757e5abbace413b59421527a31113406c97815c", "asset_id": "96361925776989336186111887920533578209326565663637092688733016597062311745569", "price": "0.006", "size": "136.51", "side": "BUY", "timestamp": "1768475298167", "received_at": "2026-01-15T12:08:18.287436"}}
{"event_type": "price_change", "event_ts": "2026-01-15T12:08:18.287436", "ingestion_ts": "2026-01-15T12:08:42.168746", "market_id": "0xcab7ba4a9133cfd407d7e73e5757e5abbace413b59421527a31113406c97815c", "raw": {"market": "0xcab7ba4a9133cfd407d7e73e5757e5abbace413b59421527a31113406c97815c", "asset_id": "20002636398944597965698652220992177552927816915094913583821579024925426590022", "price": "0.994", "size": "136.51", "side": "SELL", "timestamp": "1768475298167", "received_at": "2026-01-15T12:08:18.287436"}}
{"event_type": "price_change", "event_ts": "2026-01-15T12:08:18.287496", "ingestion_ts": "2026-01-15T12:08:42.168746", "market_id": "0xcab7ba4a9133cfd407d7e73e5757e5abbace413b59421527a31113406c97815c", "raw": {"market": "0xcab7ba4a9133cfd407d7e73e5757e5abbace413b59421527a31113406c97815c", "asset_id": "96361925776989336186111887920533578209326565663637092688733016597062311745569", "price": "0.009", "size": "818.33", "side": "BUY", "timestamp": "1768475298168", "received_at": "2026-01-15T12:08:18.287496"}}
{"event_type": "price_change", "event_ts": "2026-01-15T12:08:18.287496", "ingestion_ts": "2026-01-15T12:08:42.168746", "market_id": "0xcab7ba4a9133cfd407d7e73e5757e5abbace413b59421527a31113406c97815c", "raw": {"market": "0xcab7ba4a9133cfd407d7e73e5757e5abbace413b59421527a31113406c97815c", "asset_id": "20002636398944597965698652220992177552927816915094913583821579024925426590022", "price": "0.991", "size": "818.33", "side": "SELL", "timestamp": "1768475298168", "received_at": "2026-01-15T12:08:18.287496"}}
{"event_type": "price_change", "event_ts": "2026-01-15T12:08:18.684002", "ingestion_ts": "2026-01-15T12:08:42.168746", "market_id": "0xe9c127a8c35f045d37b5344b0a36711084fa20c2fc1618bf178a5386f90610be", "raw": {"market": "0xe9c127a8c35f045d37b5344b0a36711084fa20c2fc1618bf178a5386f90610be", "asset_id": "107000426448217931795450451304515386602910396776318075817601265223856116134349", "price": "0.993", "size": "15", "side": "SELL", "timestamp": "1768475298562", "received_at": "2026-01-15T12:08:18.684002"}}
{"event_type": "price_change", "event_ts": "2026-01-15T12:08:18.684002", "ingestion_ts": "2026-01-15T12:08:42.168746", "market_id": "0xe9c127a8c35f045d37b5344b0a36711084fa20c2fc1618bf178a5386f90610be", "raw": {"market": "0xe9c127a8c35f045d37b5344b0a36711084fa20c2fc1618bf178a5386f90610be", "asset_id": "80230236018433940569996058935444651347308266584430516013229815570706872276819", "price": "0.007", "size": "15", "side": "BUY", "timestamp": "1768475298562", "received_at": "2026-01-15T12:08:18.684002"}}
{"event_type": "price_change", "event_ts": "2026-01-15T12:08:18.684032", "ingestion_ts": "2026-01-15T12:08:42.168746", "market_id": "0xe9c127a8c35f045d37b5344b0a36711084fa20c2fc1618bf178a5386f90610be", "raw": {"market": "0xe9c127a8c35f045d37b5344b0a36711084fa20c2fc1618bf178a5386f90610be", "asset_id": "107000426448217931795450451304515386602910396776318075817601265223856116134349", "price": "0.992", "size": "0", "side": "SELL", "timestamp": "1768475298562", "received_at": "2026-01-15T12:08:18.684032"}}
{"event_type": "price_change", "event_ts": "2026-01-15T12:08:18.684032", "ingestion_ts": "2026-01-15T12:08:42.168746", "market_id": "0xe9c127a8c35f045d37b5344b0a36711084fa20c2fc1618bf178a5386f90610be", "raw": {"market": "0xe9c127a8c35f045d37b5344b0a36711084fa20c2fc1618bf178a5386f90610be", "asset_id": "80230236018433940569996058935444651347308266584430516013229815570706872276819", "price": "0.008", "size": "0", "side": "BUY", "timestamp": "1768475298562", "received_at": "2026-01-15T12:08:18.684032"}}
{"event_type": "price_change", "event_ts": "2026-01-15T12:08:18.705161", "ingestion_ts": "2026-01-15T12:08:42.168746", "market_id": "0xe9c127a8c35f045d37b5344b0a36711084fa20c2fc1618bf178a5386f90610be", "raw": {"market": "0xe9c127a8c35f045d37b5344b0a36711084fa20c2fc1618bf178a5386f90610be", "asset_id": "80230236018433940569996058935444651347308266584430516013229815570706872276819", "price": "0.025", "size": "10", "side": "SELL", "timestamp": "1768475298588", "received_at": "2026-01-15T12:08:18.705161"}}
{"event_type": "price_change", "event_ts": "2026-01-15T12:08:18.705161", "ingestion_ts": "2026-01-15T12:08:42.168746", "market_id": "0xe9c127a8c35f045d37b5344b0a36711084fa20c2fc1618bf178a5386f90610be", "raw": {"market": "0xe9c127a8c35f045d37b5344b0a36711084fa20c2fc1618bf178a5386f90610be", "asset_id": "107000426448217931795450451304515386602910396776318075817601265223856116134349", "price": "0.975", "size": "10", "side": "BUY", "timestamp": "1768475298588", "received_at": "2026-01-15T12:08:18.705161"}}
{"event_type": "price_change", "event_ts": "2026-01-15T12:08:18.750948", "ingestion_ts": "2026-01-15T12:08:42.168746", "market_id": "0xe9c127a8c35f045d37b5344b0a36711084fa20c2fc1618bf178a5386f90610be", "raw": {"market": "0xe9c127a8c35f045d37b5344b0a36711084fa20c2fc1618bf178a5386f90610be", "asset_id": "80230236018433940569996058935444651347308266584430516013229815570706872276819", "price": "0.025", "size": "404", "side": "SELL", "timestamp": "1768475298627", "received_at": "2026-01-15T12:08:18.750948"}}
{"event_type": "price_change", "event_ts": "2026-01-15T12:08:18.750948", "ingestion_ts": "2026-01-15T12:08:42.168746", "market_id": "0xe9c127a8c35f045d37b5344b0a36711084fa20c2fc1618bf178a5386f90610be", "raw": {"market": "0xe9c127a8c35f045d37b5344b0a36711084fa20c2fc1618bf178a5386f90610be", "asset_id": "107000426448217931795450451304515386602910396776318075817601265223856116134349", "price": "0.975", "size": "404", "side": "BUY", "timestamp": "1768475298627", "received_at": "2026-01-15T12:08:18.750948"}}
{"event_type": "price_change", "event_ts": "2026-01-15T12:08:18.834579", "ingestion_ts": "2026-01-15T12:08:42.168746", "market_id": "0xc0e6b917320a47228fb96e3b5ae0e5c93773a5ae2662ae4e1f37807cfe47ce98", "raw": {"market": "0xc0e6b917320a47228fb96e3b5ae0e5c93773a5ae2662ae4e1f37807cfe47ce98", "asset_id": "58656358377246279051017109359677190749228949103591068167284263961542487110215", "price": "0.004", "size": "9.98", "side": "BUY", "timestamp": "1768475298714", "received_at": "2026-01-15T12:08:18.834579"}}
{"event_type": "price_change", "event_ts": "2026-01-15T12:08:18.834579", "ingestion_ts": "2026-01-15T12:08:42.168746", "market_id": "0xc0e6b917320a47228fb96e3b5ae0e5c93773a5ae2662ae4e1f37807cfe47ce98", "raw": {"market": "0xc0e6b917320a47228fb96e3b5ae0e5c93773a5ae2662ae4e1f37807cfe47ce98", "asset_id": "81647294538046680798858716589766492074338758116170717123345952330712416337530", "price": "0.996", "size": "9.98", "side": "SELL", "timestamp": "1768475298714", "received_at": "2026-01-15T12:08:18.834579"}}
{"event_type": "price_change", "event_ts": "2026-01-15T12:08:18.834631", "ingestion_ts": "2026-01-15T12:08:42.168746", "market_id": "0xc0e6b917320a47228fb96e3b5ae0e5c93773a5ae2662ae4e1f37807cfe47ce98", "raw": {"market": "0xc0e6b917320a47228fb96e3b5ae0e5c93773a5ae2662ae4e1f37807cfe47ce98", "asset_id": "58656358377246279051017109359677190749228949103591068167284263961542487110215", "price": "0.004", "size": "19.96", "side": "BUY", "timestamp": "1768475298715", "received_at": "2026-01-15T12:08:18.834631"}}
{"event_type": "price_change", "event_ts": "2026-01-15T12:08:18.834631", "ingestion_ts": "2026-01-15T12:08:42.168746", "market_id": "0xc0e6b917320a47228fb96e3b5ae0e5c93773a5ae2662ae4e1f37807cfe47ce98", "raw": {"market": "0xc0e6b917320a47228fb96e3b5ae0e5c93773a5ae2662ae4e1f37807cfe47ce98", "asset_id": "81647294538046680798858716589766492074338758116170717123345952330712416337530", "price": "0.996", "size": "19.96", "side": "SELL", "timestamp": "1768475298715", "received_at": "2026-01-15T12:08:18.834631"}}
{"event_type": "price_change", "event_ts": "2026-01-15T12:08:18.950608", "ingestion_ts": "2026-01-15T12:08:42.168746", "market_id": "0x427bc4b40c09b3dcbc973747f0e4b079bed91b3e5a0aed5c36edd0f7591485f4", "raw": {"market": "0x427bc4b40c09b3dcbc973747f0e4b079bed91b3e5a0aed5c36edd0f7591485f4", "asset_id": "115669573443672055876643967408433138119481486650803218131873713375232186497057", "price": "0.002", "size": "41.05", "side": "BUY", "timestamp": "1768475298820", "received_at": "2026-01-15T12:08:18.950608"}}
{"event_type": "price_change", "event_ts": "2026-01-15T12:08:18.950608", "ingestion_ts": "2026-01-15T12:08:42.168746", "market_id": "0x427bc4b40c09b3dcbc973747f0e4b079bed91b3e5a0aed5c36edd0f7591485f4", "raw": {"market": "0x427bc4b40c09b3dcbc973747f0e4b079bed91b3e5a0aed5c36edd0f7591485f4", "asset_id": "86130975769502911188457673769190265049139877688522439001984850068234616395137", "price": "0.998", "size": "41.05", "side": "SELL", "timestamp": "1768475298820", "received_at": "2026-01-15T12:08:18.950608"}}
{"event_type": "price_change", "event_ts": "2026-01-15T12:08:19.017311", "ingestion_ts": "2026-01-15T12:08:42.168746", "market_id": "0xe9c127a8c35f045d37b5344b0a36711084fa20c2fc1618bf178a5386f90610be", "raw": {"market": "0xe9c127a8c35f045d37b5344b0a36711084fa20c2fc1618bf178a5386f90610be", "asset_id": "107000426448217931795450451304515386602910396776318075817601265223856116134349", "price": "0.994", "size": "100", "side": "SELL", "timestamp": "1768475298897", "received_at": "2026-01-15T12:08:19.017311"}}
{"event_type": "price_change", "event_ts": "2026-01-15T12:08:19.017311", "ingestion_ts": "2026-01-15T12:08:42.168746", "market_id": "0xe9c127a8c35f045d37b5344b0a36711084fa20c2fc1618bf178a5386f90610be", "raw": {"market": "0xe9c127a8c35f045d37b5344b0a36711084fa20c2fc1618bf178a5386f90610be", "asset_id": "80230236018433940569996058935444651347308266584430516013229815570706872276819", "price": "0.006", "size": "100", "side": "BUY", "timestamp": "1768475298897", "received_at": "2026-01-15T12:08:19.017311"}}
{"event_type": "price_change", "event_ts": "2026-01-15T12:08:19.017365", "ingestion_ts": "2026-01-15T12:08:42.168746", "market_id": "0xe9c127a8c35f045d37b5344b0a36711084fa20c2fc1618bf178a5386f90610be", "raw": {"market": "0xe9c127a8c35f045d37b5344b0a36711084fa20c2fc1618bf178a5386f90610be", "asset_id": "107000426448217931795450451304515386602910396776318075817601265223856116134349", "price": "0.993", "size": "31", "side": "SELL", "timestamp": "1768475298898", "received_at": "2026-01-15T12:08:19.017365"}}
{"event_type": "price_change", "event_ts": "2026-01-15T12:08:19.017365", "ingestion_ts": "2026-01-15T12:08:42.168746", "market_id": "0xe9c127a8c35f045d37b5344b0a36711084fa20c2fc1618bf178a5386f90610be", "raw": {"market": "0xe9c127a8c35f045d37b5344b0a36711084fa20c2fc1618bf178a5386f90610be", "asset_id": "80230236018433940569996058935444651347308266584430516013229815570706872276819", "price": "0.007", "size": "31", "side": "BUY", "timestamp": "1768475298898", "received_at": "2026-01-15T12:08:19.017365"}}
{"event_type": "price_change", "event_ts": "2026-01-15T12:08:19.017404", "ingestion_ts": "2026-01-15T12:08:42.168746", "market_id": "0xe9c127a8c35f045d37b5344b0a36711084fa20c2fc1618bf178a5386f90610be", "raw": {"market": "0xe9c127a8c35f045d37b5344b0a36711084fa20c2fc1618bf178a5386f90610be", "asset_id": "107000426448217931795450451304515386602910396776318075817601265223856116134349", "price": "0.995", "size": "179.44", "side": "SELL", "timestamp": "1768475298898", "received_at": "2026-01-15T12:08:19.017404"}}
{"event_type": "price_change", "event_ts": "2026-01-15T12:08:19.017404", "ingestion_ts": "2026-01-15T12:08:42.168746", "market_id": "0xe9c127a8c35f045d37b5344b0a36711084fa20c2fc1618bf178a5386f90610be", "raw": {"market": "0xe9c127a8c35f045d37b5344b0a36711084fa20c2fc1618bf178a5386f90610be", "asset_id": "80230236018433940569996058935444651347308266584430516013229815570706872276819", "price": "0.005", "size": "179.44", "side": "BUY", "timestamp": "1768475298898", "received_at": "2026-01-15T12:08:19.017404"}}
{"event_type": "price_change", "event_ts": "2026-01-15T12:08:19.208728", "ingestion_ts": "2026-01-15T12:08:42.168746", "market_id": "0x427bc4b40c09b3dcbc973747f0e4b079bed91b3e5a0aed5c36edd0f7591485f4", "raw": {"market": "0x427bc4b40c09b3dcbc973747f0e4b079bed91b3e5a0aed5c36edd0f7591485f4", "asset_id": "115669573443672055876643967408433138119481486650803218131873713375232186497057", "price": "0.003", "size": "26.5", "side": "BUY", "timestamp": "1768475299090", "received_at": "2026-01-15T12:08:19.208728"}}
{"event_type": "price_change", "event_ts": "2026-01-15T12:08:19.208728", "ingestion_ts": "2026-01-15T12:08:42.168746", "market_id": "0x427bc4b40c09b3dcbc973747f0e4b079bed91b3e5a0aed5c36edd0f7591485f4", "raw": {"market": "0x427bc4b40c09b3dcbc973747f0e4b079bed91b3e5a0aed5c36edd0f7591485f4", "asset_id": "86130975769502911188457673769190265049139877688522439001984850068234616395137", "price": "0.997", "size": "26.5", "side": "SELL", "timestamp": "1768475299090", "received_at": "2026-01-15T12:08:19.208728"}}
{"event_type": "price_change", "event_ts": "2026-01-15T12:08:19.525384", "ingestion_ts": "2026-01-15T12:08:42.168746", "market_id": "0x427bc4b40c09b3dcbc973747f0e4b079bed91b3e5a0aed5c36edd0f7591485f4", "raw": {"market": "0x427bc4b40c09b3dcbc973747f0e4b079bed91b3e5a0aed5c36edd0f7591485f4", "asset_id": "115669573443672055876643967408433138119481486650803218131873713375232186497057", "price": "0.175", "size": "0", "side": "SELL", "timestamp": "1768475299407", "received_at": "2026-01-15T12:08:19.525384"}}
{"event_type": "price_change", "event_ts": "2026-01-15T12:08:19.525384", "ingestion_ts": "2026-01-15T12:08:42.168746", "market_id": "0x427bc4b40c09b3dcbc973747f0e4b079bed91b3e5a0aed5c36edd0f7591485f4", "raw": {"market": "0x427bc4b40c09b3dcbc973747f0e4b079bed91b3e5a0aed5c36edd0f7591485f4", "asset_id": "86130975769502911188457673769190265049139877688522439001984850068234616395137", "price": "0.825", "size": "0", "side": "BUY", "timestamp": "1768475299407", "received_at": "2026-01-15T12:08:19.525384"}}
{"event_type": "price_change", "event_ts": "2026-01-15T12:08:19.853316", "ingestion_ts": "2026-01-15T12:08:42.168746", "market_id": "0x427bc4b40c09b3dcbc973747f0e4b079bed91b3e5a0aed5c36edd0f7591485f4", "raw": {"market": "0x427bc4b40c09b3dcbc973747f0e4b079bed91b3e5a0aed5c36edd0f7591485f4", "asset_id": "115669573443672055876643967408433138119481486650803218131873713375232186497057", "price": "0.174", "size": "9.78", "side": "SELL", "timestamp": "1768475299722", "received_at": "2026-01-15T12:08:19.853316"}}
{"event_type": "price_change", "event_ts": "2026-01-15T12:08:19.853316", "ingestion_ts": "2026-01-15T12:08:42.168746", "market_id": "0x427bc4b40c09b3dcbc973747f0e4b079bed91b3e5a0aed5c36edd0f7591485f4", "raw": {"market": "0x427bc4b40c09b3dcbc973747f0e4b079bed91b3e5a0aed5c36edd0f7591485f4", "asset_id": "86130975769502911188457673769190265049139877688522439001984850068234616395137", "price": "0.826", "size": "9.78", "side": "BUY", "timestamp": "1768475299722", "received_at": "2026-01-15T12:08:19.853316"}}
{"event_type": "price_change", "event_ts": "2026-01-15T12:08:20.334372", "ingestion_ts": "2026-01-15T12:08:42.168746", "market_id": "0xe9c127a8c35f045d37b5344b0a36711084fa20c2fc1618bf178a5386f90610be", "raw": {"market": "0xe9c127a8c35f045d37b5344b0a36711084fa20c2fc1618bf178a5386f90610be", "asset_id": "80230236018433940569996058935444651347308266584430516013229815570706872276819", "price": "0.025", "size": "10", "side": "SELL", "timestamp": "1768475300142", "received_at": "2026-01-15T12:08:20.334372"}}
{"event_type": "price_change", "event_ts": "2026-01-15T12:08:20.334372", "ingestion_ts": "2026-01-15T12:08:42.168746", "market_id": "0xe9c127a8c35f045d37b5344b0a36711084fa20c2fc1618bf178a5386f90610be", "raw": {"market": "0xe9c127a8c35f045d37b5344b0a36711084fa20c2fc1618bf178a5386f90610be", "asset_id": "107000426448217931795450451304515386602910396776318075817601265223856116134349", "price": "0.975", "size": "10", "side": "BUY", "timestamp": "1768475300142", "received_at": "2026-01-15T12:08:20.334372"}}
{"event_type": "price_change", "event_ts": "2026-01-15T12:08:20.349523", "ingestion_ts": "2026-01-15T12:08:42.168746", "market_id": "0xcab7ba4a9133cfd407d7e73e5757e5abbace413b59421527a31113406c97815c", "raw": {"market": "0xcab7ba4a9133cfd407d7e73e5757e5abbace413b59421527a31113406c97815c", "asset_id": "96361925776989336186111887920533578209326565663637092688733016597062311745569", "price": "0.006", "size": "127.41", "side": "BUY", "timestamp": "1768475300157", "received_at": "2026-01-15T12:08:20.349523"}}
{"event_type": "price_change", "event_ts": "2026-01-15T12:08:20.349523", "ingestion_ts": "2026-01-15T12:08:42.168746", "market_id": "0xcab7ba4a9133cfd407d7e73e5757e5abbace413b59421527a31113406c97815c", "raw": {"market": "0xcab7ba4a9133cfd407d7e73e5757e5abbace413b59421527a31113406c97815c", "asset_id": "20002636398944597965698652220992177552927816915094913583821579024925426590022", "price": "0.994", "size": "127.41", "side": "SELL", "timestamp": "1768475300157", "received_at": "2026-01-15T12:08:20.349523"}}
{"event_type": "price_change", "event_ts": "2026-01-15T12:08:20.349591", "ingestion_ts": "2026-01-15T12:08:42.168746", "market_id": "0xcab7ba4a9133cfd407d7e73e5757e5abbace413b59421527a31113406c97815c", "raw": {"market": "0xcab7ba4a9133cfd407d7e73e5757e5abbace413b59421527a31113406c97815c", "asset_id": "96361925776989336186111887920533578209326565663637092688733016597062311745569", "price": "0.009", "size": "812.25", "side": "BUY", "timestamp": "1768475300157", "received_at": "2026-01-15T12:08:20.349591"}}
{"event_type": "price_change", "event_ts": "2026-01-15T12:08:20.349591", "ingestion_ts": "2026-01-15T12:08:42.168746", "market_id": "0xcab7ba4a9133cfd407d7e73e5757e5abbace413b59421527a31113406c97815c", "raw": {"market": "0xcab7ba4a9133cfd407d7e73e5757e5abbace413b59421527a31113406c97815c", "asset_id": "20002636398944597965698652220992177552927816915094913583821579024925426590022", "price": "0.991", "size": "812.25", "side": "SELL", "timestamp": "1768475300157", "received_at": "2026-01-15T12:08:20.349591"}}
{"event_type": "price_change", "event_ts": "2026-01-15T12:08:20.349611", "ingestion_ts": "2026-01-15T12:08:42.168746", "market_id": "0xe9c127a8c35f045d37b5344b0a36711084fa20c2fc1618bf178a5386f90610be", "raw": {"market": "0xe9c127a8c35f045d37b5344b0a36711084fa20c2fc1618bf178a5386f90610be", "asset_id": "80230236018433940569996058935444651347308266584430516013229815570706872276819", "price": "0.025", "size": "388", "side": "SELL", "timestamp": "1768475300168", "received_at": "2026-01-15T12:08:20.349611"}}
{"event_type": "price_change", "event_ts": "2026-01-15T12:08:20.349611", "ingestion_ts": "2026-01-15T12:08:42.168746", "market_id": "0xe9c127a8c35f045d37b5344b0a36711084fa20c2fc1618bf178a5386f90610be", "raw": {"market": "0xe9c127a8c35f045d37b5344b0a36711084fa20c2fc1618bf178a5386f90610be", "asset_id": "107000426448217931795450451304515386602910396776318075817601265223856116134349", "price": "0.975", "size": "388", "side": "BUY", "timestamp": "1768475300168", "received_at": "2026-01-15T12:08:20.349611"}}
{"event_type": "price_change", "event_ts": "2026-01-15T12:08:22.130859", "ingestion_ts": "2026-01-15T12:08:42.168746", "market_id": "0xcab7ba4a9133cfd407d7e73e5757e5abbace413b59421527a31113406c97815c", "raw": {"market": "0xcab7ba4a9133cfd407d7e73e5757e5abbace413b59421527a31113406c97815c", "asset_id": "96361925776989336186111887920533578209326565663637092688733016597062311745569", "price": "0.009", "size": "818.33", "side": "BUY", "timestamp": "1768475302006", "received_at": "2026-01-15T12:08:22.130859"}}
{"event_type": "price_change", "event_ts": "2026-01-15T12:08:22.130859", "ingestion_ts": "2026-01-15T12:08:42.168746", "market_id": "0xcab7ba4a9133cfd407d7e73e5757e5abbace413b59421527a31113406c97815c", "raw": {"market": "0xcab7ba4a9133cfd407d7e73e5757e5abbace413b59421527a31113406c97815c", "asset_id": "20002636398944597965698652220992177552927816915094913583821579024925426590022", "price": "0.991", "size": "818.33", "side": "SELL", "timestamp": "1768475302006", "received_at": "2026-01-15T12:08:22.130859"}}
{"event_type": "price_change", "event_ts": "2026-01-15T12:08:22.132709", "ingestion_ts": "2026-01-15T12:08:42.168746", "market_id": "0xcab7ba4a9133cfd407d7e73e5757e5abbace413b59421527a31113406c97815c", "raw": {"market": "0xcab7ba4a9133cfd407d7e73e5757e5abbace413b59421527a31113406c97815c", "asset_id": "96361925776989336186111887920533578209326565663637092688733016597062311745569", "price": "0.006", "size": "136.51", "side": "BUY", "timestamp": "1768475302008", "received_at": "2026-01-15T12:08:22.132709"}}
{"event_type": "price_change", "event_ts": "2026-01-15T12:08:22.132709", "ingestion_ts": "2026-01-15T12:08:42.168746", "market_id": "0xcab7ba4a9133cfd407d7e73e5757e5abbace413b59421527a31113406c97815c", "raw": {"market": "0xcab7ba4a9133cfd407d7e73e5757e5abbace413b59421527a31113406c97815c", "asset_id": "20002636398944597965698652220992177552927816915094913583821579024925426590022", "price": "0.994", "size": "136.51", "side": "SELL", "timestamp": "1768475302008", "received_at": "2026-01-15T12:08:22.132709"}}
{"event_type": "price_change", "event_ts": "2026-01-15T12:08:23.713782", "ingestion_ts": "2026-01-15T12:08:42.168746", "market_id": "0x427bc4b40c09b3dcbc973747f0e4b079bed91b3e5a0aed5c36edd0f7591485f4", "raw": {"market": "0x427bc4b40c09b3dcbc973747f0e4b079bed91b3e5a0aed5c36edd0f7591485f4", "asset_id": "115669573443672055876643967408433138119481486650803218131873713375232186497057", "price": "0.003", "size": "4.03", "side": "BUY", "timestamp": "1768475303518", "received_at": "2026-01-15T12:08:23.713782"}}
{"event_type": "price_change", "event_ts": "2026-01-15T12:08:23.713782", "ingestion_ts": "2026-01-15T12:08:42.168746", "market_id": "0x427bc4b40c09b3dcbc973747f0e4b079bed91b3e5a0aed5c36edd0f7591485f4", "raw": {"market": "0x427bc4b40c09b3dcbc973747f0e4b079bed91b3e5a0aed5c36edd0f7591485f4", "asset_id": "86130975769502911188457673769190265049139877688522439001984850068234616395137", "price": "0.997", "size": "4.03", "side": "SELL", "timestamp": "1768475303518", "received_at": "2026-01-15T12:08:23.713782"}}
{"event_type": "price_change", "event_ts": "2026-01-15T12:08:23.842016", "ingestion_ts": "2026-01-15T12:08:42.168746", "market_id": "0xcab7ba4a9133cfd407d7e73e5757e5abbace413b59421527a31113406c97815c", "raw": {"market": "0xcab7ba4a9133cfd407d7e73e5757e5abbace413b59421527a31113406c97815c", "asset_id": "96361925776989336186111887920533578209326565663637092688733016597062311745569", "price": "0.006", "size": "127.41", "side": "BUY", "timestamp": "1768475303673", "received_at": "2026-01-15T12:08:23.842016"}}
{"event_type": "price_change", "event_ts": "2026-01-15T12:08:23.842016", "ingestion_ts": "2026-01-15T12:08:42.168746", "market_id": "0xcab7ba4a9133cfd407d7e73e5757e5abbace413b59421527a31113406c97815c", "raw": {"market": "0xcab7ba4a9133cfd407d7e73e5757e5abbace413b59421527a31113406c97815c", "asset_id": "20002636398944597965698652220992177552927816915094913583821579024925426590022", "price": "0.994", "size": "127.41", "side": "SELL", "timestamp": "1768475303673", "received_at": "2026-01-15T12:08:23.842016"}}
{"event_type": "price_change", "event_ts": "2026-01-15T12:08:23.842146", "ingestion_ts": "2026-01-15T12:08:42.168746", "market_id": "0xcab7ba4a9133cfd407d7e73e5757e5abbace413b59421527a31113406c97815c", "raw": {"market": "0xcab7ba4a9133cfd407d7e73e5757e5abbace413b59421527a31113406c97815c", "asset_id": "96361925776989336186111887920533578209326565663637092688733016597062311745569", "price": "0.009", "size": "812.25", "side": "BUY", "timestamp": "1768475303673", "received_at": "2026-01-15T12:08:23.842146"}}
{"event_type": "price_change", "event_ts": "2026-01-15T12:08:23.842146", "ingestion_ts": "2026-01-15T12:08:42.168746", "market_id": "0xcab7ba4a9133cfd407d7e73e5757e5abbace413b59421527a31113406c97815c", "raw": {"market": "0xcab7ba4a9133cfd407d7e73e5757e5abbace413b59421527a31113406c97815c", "asset_id": "20002636398944597965698652220992177552927816915094913583821579024925426590022", "price": "0.991", "size": "812.25", "side": "SELL", "timestamp": "1768475303673", "received_at": "2026-01-15T12:08:23.842146"}}
{"event_type": "price_change", "event_ts": "2026-01-15T12:08:23.949529", "ingestion_ts": "2026-01-15T12:08:42.168746", "market_id": "0x427bc4b40c09b3dcbc973747f0e4b079bed91b3e5a0aed5c36edd0f7591485f4", "raw": {"market": "0x427bc4b40c09b3dcbc973747f0e4b079bed91b3e5a0aed5c36edd0f7591485f4", "asset_id": "115669573443672055876643967408433138119481486650803218131873713375232186497057", "price": "0.004", "size": "43.63", "side": "BUY", "timestamp": "1768475303803", "received_at": "2026-01-15T12:08:23.949529"}}
{"event_type": "price_change", "event_ts": "2026-01-15T12:08:23.949529", "ingestion_ts": "2026-01-15T12:08:42.168746", "market_id": "0x427bc4b40c09b3dcbc973747f0e4b079bed91b3e5a0aed5c36edd0f7591485f4", "raw": {"market": "0x427bc4b40c09b3dcbc973747f0e4b079bed91b3e5a0aed5c36edd0f7591485f4", "asset_id": "86130975769502911188457673769190265049139877688522439001984850068234616395137", "price": "0.996", "size": "43.63", "side": "SELL", "timestamp": "1768475303803", "received_at": "2026-01-15T12:08:23.949529"}}
{"event_type": "price_change", "event_ts": "2026-01-15T12:08:23.949594", "ingestion_ts": "2026-01-15T12:08:42.168746", "market_id": "0x427bc4b40c09b3dcbc973747f0e4b079bed91b3e5a0aed5c36edd0f7591485f4", "raw": {"market": "0x427bc4b40c09b3dcbc973747f0e4b079bed91b3e5a0aed5c36edd0f7591485f4", "asset_id": "115669573443672055876643967408433138119481486650803218131873713375232186497057", "price": "0.001", "size": "767.68", "side": "BUY", "timestamp": "1768475303804", "received_at": "2026-01-15T12:08:23.949594"}}
{"event_type": "price_change", "event_ts": "2026-01-15T12:08:23.949594", "ingestion_ts": "2026-01-15T12:08:42.168746", "market_id": "0x427bc4b40c09b3dcbc973747f0e4b079bed91b3e5a0aed5c36edd0f7591485f4", "raw": {"market": "0x427bc4b40c09b3dcbc973747f0e4b079bed91b3e5a0aed5c36edd0f7591485f4", "asset_id": "86130975769502911188457673769190265049139877688522439001984850068234616395137", "price": "0.999", "size": "767.68", "side": "SELL", "timestamp": "1768475303804", "received_at": "2026-01-15T12:08:23.949594"}}
{"event_type": "price_change", "event_ts": "2026-01-15T12:08:24.172640", "ingestion_ts": "2026-01-15T12:08:42.168746", "market_id": "0x427bc4b40c09b3dcbc973747f0e4b079bed91b3e5a0aed5c36edd0f7591485f4", "raw": {"market": "0x427bc4b40c09b3dcbc973747f0e4b079bed91b3e5a0aed5c36edd0f7591485f4", "asset_id": "115669573443672055876643967408433138119481486650803218131873713375232186497057", "price": "0.174", "size": "0", "side": "SELL", "timestamp": "1768475304053", "received_at": "2026-01-15T12:08:24.172640"}}
{"event_type": "price_change", "event_ts": "2026-01-15T12:08:24.172640", "ingestion_ts": "2026-01-15T12:08:42.168746", "market_id": "0x427bc4b40c09b3dcbc973747f0e4b079bed91b3e5a0aed5c36edd0f7591485f4", "raw": {"market": "0x427bc4b40c09b3dcbc973747f0e4b079bed91b3e5a0aed5c36edd0f7591485f4", "asset_id": "86130975769502911188457673769190265049139877688522439001984850068234616395137", "price": "0.826", "size": "0", "side": "BUY", "timestamp": "1768475304053", "received_at": "2026-01-15T12:08:24.172640"}}
{"event_type": "price_change", "event_ts": "2026-01-15T12:08:24.209910", "ingestion_ts": "2026-01-15T12:08:42.168746", "market_id": "0xcab7ba4a9133cfd407d7e73e5757e5abbace413b59421527a31113406c97815c", "raw": {"market": "0xcab7ba4a9133cfd407d7e73e5757e5abbace413b59421527a31113406c97815c", "asset_id": "96361925776989336186111887920533578209326565663637092688733016597062311745569", "price": "0.006", "size": "136.51", "side": "BUY", "timestamp": "1768475304083", "received_at": "2026-01-15T12:08:24.209910"}}
{"event_type": "price_change", "event_ts": "2026-01-15T12:08:24.209910", "ingestion_ts": "2026-01-15T12:08:42.168746", "market_id": "0xcab7ba4a9133cfd407d7e73e5757e5abbace413b59421527a31113406c97815c", "raw": {"market": "0xcab7ba4a9133cfd407d7e73e5757e5abbace413b59421527a31113406c97815c", "asset_id": "20002636398944597965698652220992177552927816915094913583821579024925426590022", "price": "0.994", "size": "136.51", "side": "SELL", "timestamp": "1768475304083", "received_at": "2026-01-15T12:08:24.209910"}}
{"event_type": "price_change", "event_ts": "2026-01-15T12:08:24.210085", "ingestion_ts": "2026-01-15T12:08:42.168746", "market_id": "0xcab7ba4a9133cfd407d7e73e5757e5abbace413b59421527a31113406c97815c", "raw": {"market": "0xcab7ba4a9133cfd407d7e73e5757e5abbace413b59421527a31113406c97815c", "asset_id": "96361925776989336186111887920533578209326565663637092688733016597062311745569", "price": "0.009", "size": "818.33", "side": "BUY", "timestamp": "1768475304084", "received_at": "2026-01-15T12:08:24.210085"}}
{"event_type": "price_change", "event_ts": "2026-01-15T12:08:24.210085", "ingestion_ts": "2026-01-15T12:08:42.168746", "market_id": "0xcab7ba4a9133cfd407d7e73e5757e5abbace413b59421527a31113406c97815c", "raw": {"market": "0xcab7ba4a9133cfd407d7e73e5757e5abbace413b59421527a31113406c97815c", "asset_id": "20002636398944597965698652220992177552927816915094913583821579024925426590022", "price": "0.991", "size": "818.33", "side": "SELL", "timestamp": "1768475304084", "received_at": "2026-01-15T12:08:24.210085"}}
{"event_type": "price_change", "event_ts": "2026-01-15T12:08:24.379355", "ingestion_ts": "2026-01-15T12:08:42.168746", "market_id": "0x427bc4b40c09b3dcbc973747f0e4b079bed91b3e5a0aed5c36edd0f7591485f4", "raw": {"market": "0x427bc4b40c09b3dcbc973747f0e4b079bed91b3e5a0aed5c36edd0f7591485f4", "asset_id": "115669573443672055876643967408433138119481486650803218131873713375232186497057", "price": "0.173", "size": "9.78", "side": "SELL", "timestamp": "1768475304256", "received_at": "2026-01-15T12:08:24.379355"}}
{"event_type": "price_change", "event_ts": "2026-01-15T12:08:24.379355", "ingestion_ts": "2026-01-15T12:08:42.168746", "market_id": "0x427bc4b40c09b3dcbc973747f0e4b079bed91b3e5a0aed5c36edd0f7591485f4", "raw": {"market": "0x427bc4b40c09b3dcbc973747f0e4b079bed91b3e5a0aed5c36edd0f7591485f4", "asset_id": "86130975769502911188457673769190265049139877688522439001984850068234616395137", "price": "0.827", "size": "9.78", "side": "BUY", "timestamp": "1768475304256", "received_at": "2026-01-15T12:08:24.379355"}}
{"event_type": "price_change", "event_ts": "2026-01-15T12:08:24.931113", "ingestion_ts": "2026-01-15T12:08:42.168746", "market_id": "0xc0e6b917320a47228fb96e3b5ae0e5c93773a5ae2662ae4e1f37807cfe47ce98", "raw": {"market": "0xc0e6b917320a47228fb96e3b5ae0e5c93773a5ae2662ae4e1f37807cfe47ce98", "asset_id": "58656358377246279051017109359677190749228949103591068167284263961542487110215", "price": "0.004", "size": "9.98", "side": "BUY", "timestamp": "1768475304805", "received_at": "2026-01-15T12:08:24.931113"}}
{"event_type": "price_change", "event_ts": "2026-01-15T12:08:24.931113", "ingestion_ts": "2026-01-15T12:08:42.168746", "market_id": "0xc0e6b917320a47228fb96e3b5ae0e5c93773a5ae2662ae4e1f37807cfe47ce98", "raw": {"market": "0xc0e6b917320a47228fb96e3b5ae0e5c93773a5ae2662ae4e1f37807cfe47ce98", "asset_id": "81647294538046680798858716589766492074338758116170717123345952330712416337530", "price": "0.996", "size": "9.98", "side": "SELL", "timestamp": "1768475304805", "received_at": "2026-01-15T12:08:24.931113"}}
{"event_type": "price_change", "event_ts": "2026-01-15T12:08:24.941215", "ingestion_ts": "2026-01-15T12:08:42.168746", "market_id": "0xaf9d0e448129a9f657f851d49495ba4742055d80e0ef1166ba0ee81d4d594214", "raw": {"market": "0xaf9d0e448129a9f657f851d49495ba4742055d80e0ef1166ba0ee81d4d594214", "asset_id": "4153292802911610701832309484716814274802943278345248636922528170020319407796", "price": "0.86", "size": "750.23", "side": "BUY", "timestamp": "1768475304816", "received_at": "2026-01-15T12:08:24.941215"}}
{"event_type": "price_change", "event_ts": "2026-01-15T12:08:24.941215", "ingestion_ts": "2026-01-15T12:08:42.168746", "market_id": "0xaf9d0e448129a9f657f851d49495ba4742055d80e0ef1166ba0ee81d4d594214", "raw": {"market": "0xaf9d0e448129a9f657f851d49495ba4742055d80e0ef1166ba0ee81d4d594214", "asset_id": "101676997363687199724245607342877036148401850938023978421879460310389391082353", "price": "0.14", "size": "750.23", "side": "SELL", "timestamp": "1768475304816", "received_at": "2026-01-15T12:08:24.941215"}}
{"event_type": "price_change", "event_ts": "2026-01-15T12:08:25.400429", "ingestion_ts": "2026-01-15T12:08:42.168746", "market_id": "0xc0e6b917320a47228fb96e3b5ae0e5c93773a5ae2662ae4e1f37807cfe47ce98", "raw": {"market": "0xc0e6b917320a47228fb96e3b5ae0e5c93773a5ae2662ae4e1f37807cfe47ce98", "asset_id": "58656358377246279051017109359677190749228949103591068167284263961542487110215", "price": "0.005", "size": "10.97", "side": "BUY", "timestamp": "1768475305278", "received_at": "2026-01-15T12:08:25.400429"}}
{"event_type": "price_change", "event_ts": "2026-01-15T12:08:25.400429", "ingestion_ts": "2026-01-15T12:08:42.168746", "market_id": "0xc0e6b917320a47228fb96e3b5ae0e5c93773a5ae2662ae4e1f37807cfe47ce98", "raw": {"market": "0xc0e6b917320a47228fb96e3b5ae0e5c93773a5ae2662ae4e1f37807cfe47ce98", "asset_id": "81647294538046680798858716589766492074338758116170717123345952330712416337530", "price": "0.995", "size": "10.97", "side": "SELL", "timestamp": "1768475305278", "received_at": "2026-01-15T12:08:25.400429"}}
{"event_type": "price_change", "event_ts": "2026-01-15T12:08:26.355767", "ingestion_ts": "2026-01-15T12:08:42.168746", "market_id": "0x427bc4b40c09b3dcbc973747f0e4b079bed91b3e5a0aed5c36edd0f7591485f4", "raw": {"market": "0x427bc4b40c09b3dcbc973747f0e4b079bed91b3e5a0aed5c36edd0f7591485f4", "asset_id": "86130975769502911188457673769190265049139877688522439001984850068234616395137", "price": "0.08", "size": "0", "side": "BUY", "timestamp": "1768475306230", "received_at": "2026-01-15T12:08:26.355767"}}
{"event_type": "price_change", "event_ts": "2026-01-15T12:08:26.355767", "ingestion_ts": "2026-01-15T12:08:42.168746", "market_id": "0x427bc4b40c09b3dcbc973747f0e4b079bed91b3e5a0aed5c36edd0f7591485f4", "raw": {"market": "0x427bc4b40c09b3dcbc973747f0e4b079bed91b3e5a0aed5c36edd0f7591485f4", "asset_id": "115669573443672055876643967408433138119481486650803218131873713375232186497057", "price": "0.92", "size": "0", "side": "SELL", "timestamp": "1768475306230", "received_at": "2026-01-15T12:08:26.355767"}}
{"event_type": "price_change", "event_ts": "2026-01-15T12:08:26.640446", "ingestion_ts": "2026-01-15T12:08:42.168746", "market_id": "0x427bc4b40c09b3dcbc973747f0e4b079bed91b3e5a0aed5c36edd0f7591485f4", "raw": {"market": "0x427bc4b40c09b3dcbc973747f0e4b079bed91b3e5a0aed5c36edd0f7591485f4", "asset_id": "86130975769502911188457673769190265049139877688522439001984850068234616395137", "price": "0.09", "size": "258.73", "side": "BUY", "timestamp": "1768475306510", "received_at": "2026-01-15T12:08:26.640446"}}
{"event_type": "price_change", "event_ts": "2026-01-15T12:08:26.640446", "ingestion_ts": "2026-01-15T12:08:42.168746", "market_id": "0x427bc4b40c09b3dcbc973747f0e4b079bed91b3e5a0aed5c36edd0f7591485f4", "raw": {"market": "0x427bc4b40c09b3dcbc973747f0e4b079bed91b3e5a0aed5c36edd0f7591485f4", "asset_id": "115669573443672055876643967408433138119481486650803218131873713375232186497057", "price": "0.91", "size": "258.73", "side": "SELL", "timestamp": "1768475306510", "received_at": "2026-01-15T12:08:26.640446"}}
{"event_type": "price_change", "event_ts": "2026-01-15T12:08:27.183112", "ingestion_ts": "2026-01-15T12:08:42.168746", "market_id": "0xcab7ba4a9133cfd407d7e73e5757e5abbace413b59421527a31113406c97815c", "raw": {"market": "0xcab7ba4a9133cfd407d7e73e5757e5abbace413b59421527a31113406c97815c", "asset_id": "96361925776989336186111887920533578209326565663637092688733016597062311745569", "price": "0.006", "size": "127.41", "side": "BUY", "timestamp": "1768475307035", "received_at": "2026-01-15T12:08:27.183112"}}
{"event_type": "price_change", "event_ts": "2026-01-15T12:08:27.183112", "ingestion_ts": "2026-01-15T12:08:42.168746", "market_id": "0xcab7ba4a9133cfd407d7e73e5757e5abbace413b59421527a31113406c97815c", "raw": {"market": "0xcab7ba4a9133cfd407d7e73e5757e5abbace413b59421527a31113406c97815c", "asset_id": "20002636398944597965698652220992177552927816915094913583821579024925426590022", "price": "0.994", "size": "127.41", "side": "SELL", "timestamp": "1768475307035", "received_at": "2026-01-15T12:08:27.183112"}}
{"event_type": "price_change", "event_ts": "2026-01-15T12:08:27.183173", "ingestion_ts": "2026-01-15T12:08:42.168746", "market_id": "0xcab7ba4a9133cfd407d7e73e5757e5abbace413b59421527a31113406c97815c", "raw": {"market": "0xcab7ba4a9133cfd407d7e73e5757e5abbace413b59421527a31113406c97815c", "asset_id": "96361925776989336186111887920533578209326565663637092688733016597062311745569", "price": "0.009", "size": "812.25", "side": "BUY", "timestamp": "1768475307035", "received_at": "2026-01-15T12:08:27.183173"}}
{"event_type": "price_change", "event_ts": "2026-01-15T12:08:27.183173", "ingestion_ts": "2026-01-15T12:08:42.168746", "market_id": "0xcab7ba4a9133cfd407d7e73e5757e5abbace413b59421527a31113406c97815c", "raw": {"market": "0xcab7ba4a9133cfd407d7e73e5757e5abbace413b59421527a31113406c97815c", "asset_id": "20002636398944597965698652220992177552927816915094913583821579024925426590022", "price": "0.991", "size": "812.25", "side": "SELL", "timestamp": "1768475307035", "received_at": "2026-01-15T12:08:27.183173"}}
{"event_type": "price_change", "event_ts": "2026-01-15T12:08:27.761641", "ingestion_ts": "2026-01-15T12:08:42.168746", "market_id": "0xcab7ba4a9133cfd407d7e73e5757e5abbace413b59421527a31113406c97815c", "raw": {"market": "0xcab7ba4a9133cfd407d7e73e5757e5abbace413b59421527a31113406c97815c", "asset_id": "96361925776989336186111887920533578209326565663637092688733016597062311745569", "price": "0.009", "size": "818.33", "side": "BUY", "timestamp": "1768475307639", "received_at": "2026-01-15T12:08:27.761641"}}
{"event_type": "price_change", "event_ts": "2026-01-15T12:08:27.761641", "ingestion_ts": "2026-01-15T12:08:42.168746", "market_id": "0xcab7ba4a9133cfd407d7e73e5757e5abbace413b59421527a31113406c97815c", "raw": {"market": "0xcab7ba4a9133cfd407d7e73e5757e5abbace413b59421527a31113406c97815c", "asset_id": "20002636398944597965698652220992177552927816915094913583821579024925426590022", "price": "0.991", "size": "818.33", "side": "SELL", "timestamp": "1768475307639", "received_at": "2026-01-15T12:08:27.761641"}}
{"event_type": "price_change", "event_ts": "2026-01-15T12:08:27.761695", "ingestion_ts": "2026-01-15T12:08:42.168746", "market_id": "0xcab7ba4a9133cfd407d7e73e5757e5abbace413b59421527a31113406c97815c", "raw": {"market": "0xcab7ba4a9133cfd407d7e73e5757e5abbace413b59421527a31113406c97815c", "asset_id": "96361925776989336186111887920533578209326565663637092688733016597062311745569", "price": "0.006", "size": "136.51", "side": "BUY", "timestamp": "1768475307640", "received_at": "2026-01-15T12:08:27.761695"}}
{"event_type": "price_change", "event_ts": "2026-01-15T12:08:27.761695", "ingestion_ts": "2026-01-15T12:08:42.168746", "market_id": "0xcab7ba4a9133cfd407d7e73e5757e5abbace413b59421527a31113406c97815c", "raw": {"market": "0xcab7ba4a9133cfd407d7e73e5757e5abbace413b59421527a31113406c97815c", "asset_id": "20002636398944597965698652220992177552927816915094913583821579024925426590022", "price": "0.994", "size": "136.51", "side": "SELL", "timestamp": "1768475307640", "received_at": "2026-01-15T12:08:27.761695"}}
{"event_type": "price_change", "event_ts": "2026-01-15T12:08:27.990968", "ingestion_ts": "2026-01-15T12:08:42.168746", "market_id": "0x427bc4b40c09b3dcbc973747f0e4b079bed91b3e5a0aed5c36edd0f7591485f4", "raw": {"market": "0x427bc4b40c09b3dcbc973747f0e4b079bed91b3e5a0aed5c36edd0f7591485f4", "asset_id": "115669573443672055876643967408433138119481486650803218131873713375232186497057", "price": "0.004", "size": "28.07", "side": "BUY", "timestamp": "1768475307874", "received_at": "2026-01-15T12:08:27.990968"}}
{"event_type": "price_change", "event_ts": "2026-01-15T12:08:27.990968", "ingestion_ts": "2026-01-15T12:08:42.168746", "market_id": "0x427bc4b40c09b3dcbc973747f0e4b079bed91b3e5a0aed5c36edd0f7591485f4", "raw": {"market": "0x427bc4b40c09b3dcbc973747f0e4b079bed91b3e5a0aed5c36edd0f7591485f4", "asset_id": "86130975769502911188457673769190265049139877688522439001984850068234616395137", "price": "0.996", "size": "28.07", "side": "SELL", "timestamp": "1768475307874", "received_at": "2026-01-15T12:08:27.990968"}}
{"event_type": "price_change", "event_ts": "2026-01-15T12:08:28.266544", "ingestion_ts": "2026-01-15T12:08:42.168746", "market_id": "0x427bc4b40c09b3dcbc973747f0e4b079bed91b3e5a0aed5c36edd0f7591485f4", "raw": {"market": "0x427bc4b40c09b3dcbc973747f0e4b079bed91b3e5a0aed5c36edd0f7591485f4", "asset_id": "115669573443672055876643967408433138119481486650803218131873713375232186497057", "price": "0.002", "size": "72.18", "side": "BUY", "timestamp": "1768475308146", "received_at": "2026-01-15T12:08:28.266544"}}
{"event_type": "price_change", "event_ts": "2026-01-15T12:08:28.266544", "ingestion_ts": "2026-01-15T12:08:42.168746", "market_id": "0x427bc4b40c09b3dcbc973747f0e4b079bed91b3e5a0aed5c36edd0f7591485f4", "raw": {"market": "0x427bc4b40c09b3dcbc973747f0e4b079bed91b3e5a0aed5c36edd0f7591485f4", "asset_id": "86130975769502911188457673769190265049139877688522439001984850068234616395137", "price": "0.998", "size": "72.18", "side": "SELL", "timestamp": "1768475308146", "received_at": "2026-01-15T12:08:28.266544"}}
{"event_type": "price_change", "event_ts": "2026-01-15T12:08:28.324323", "ingestion_ts": "2026-01-15T12:08:42.168746", "market_id": "0xc0e6b917320a47228fb96e3b5ae0e5c93773a5ae2662ae4e1f37807cfe47ce98", "raw": {"market": "0xc0e6b917320a47228fb96e3b5ae0e5c93773a5ae2662ae4e1f37807cfe47ce98", "asset_id": "58656358377246279051017109359677190749228949103591068167284263961542487110215", "price": "0.004", "size": "0", "side": "BUY", "timestamp": "1768475308199", "received_at": "2026-01-15T12:08:28.324323"}}
{"event_type": "price_change", "event_ts": "2026-01-15T12:08:28.324323", "ingestion_ts": "2026-01-15T12:08:42.168746", "market_id": "0xc0e6b917320a47228fb96e3b5ae0e5c93773a5ae2662ae4e1f37807cfe47ce98", "raw": {"market": "0xc0e6b917320a47228fb96e3b5ae0e5c93773a5ae2662ae4e1f37807cfe47ce98", "asset_id": "81647294538046680798858716589766492074338758116170717123345952330712416337530", "price": "0.996", "size": "0", "side": "SELL", "timestamp": "1768475308199", "received_at": "2026-01-15T12:08:28.324323"}}
