{"event_type": "price_change", "event_ts": "2026-01-15T12:06:56.315182", "ingestion_ts": "2026-01-15T12:08:42.168746", "market_id": "0xc0e6b917320a47228fb96e3b5ae0e5c93773a5ae2662ae4e1f37807cfe47ce98", "raw": {"market": "0xc0e6b917320a47228fb96e3b5ae0e5c93773a5ae2662ae4e1f37807cfe47ce98", "asset_id": "81647294538046680798858716589766492074338758116170717123345952330712416337530", "price": "0.997", "size": "429.98", "side": "SELL", "timestamp": "1768475216185", "received_at": "2026-01-15T12:06:56.315182"}}
{"event_type": "price_change", "event_ts": "2026-01-15T12:06:56.315222", "ingestion_ts": "2026-01-15T12:08:42.168746", "market_id": "0xc0e6b917320a47228fb96e3b5ae0e5c93773a5ae2662ae4e1f37807cfe47ce98", "raw": {"market": "0xc0e6b917320a47228fb96e3b5ae0e5c93773a5ae2662ae4e1f37807cfe47ce98", "asset_id": "58656358377246279051017109359677190749228949103591068167284263961542487110215", "price": "0.003", "size": "444.33", "side": "BUY", "timestamp": "1768475216186", "received_at": "2026-01-15T12:06:56.315222"}}
{"event_type": "price_change", "event_ts": "2026-01-15T12:06:56.315222", "ingestion_ts": "2026-01-15T12:08:42.168746", "market_id": "0xc0e6b917320a47228fb96e3b5ae0e5c93773a5ae2662ae4e1f37807cfe47ce98", "raw": {"market": "0xc0e6b917320a47228fb96e3b5ae0e5c93773a5ae2662ae4e1f37807cfe47ce98", "asset_id": "81647294538046680798858716589766492074338758116170717123345952330712416337530", "price": "0.997", "size": "444.33", "side": "SELL", "timestamp": "1768475216186", "received_at": "2026-01-15T12:06:56.315222"}}
{"event_type": "price_change", "event_ts": "2026-01-15T12:06:56.436605", "ingestion_ts": "2026-01-15T12:08:42.168746", "market_id": "0xcab7ba4a9133cfd407d7e73e5757e5abbace413b59421527a31113406c97815c", "raw": {"market": "0xcab7ba4a9133cfd407d7e73e5757e5abbace413b59421527a31113406c97815c", "asset_id": "96361925776989336186111887920533578209326565663637092688733016597062311745569", "price": "0.006", "size": "127.41", "side": "BUY", "timestamp": "1768475216312", "received_at": "2026-01-15T12:06:56.436605"}}
{"event_type": "price_change", "event_ts": "2026-01-15T12:06:56.436605", "ingestion_ts": "2026-01-15T12:08:42.168746", "market_id": "0xcab7ba4a9133cfd407d7e73e5757e5abbace413b59421527a31113406c97815c", "raw": {"market": "0xcab7ba4a9133cfd407d7e73e5757e5abbace413b59421527a31113406c97815c", "asset_id": "20002636398944597965698652220992177552927816915094913583821579024925426590022", "price": "0.994", "size": "127.41", "side": "SELL", "timestamp": "1768475216312", "received_at": "2026-01-15T12:06:56.436605"}}
{"event_type": "price_change", "event_ts": "2026-01-15T12:06:56.436643", "ingestion_ts": "2026-01-15T12:08:42.168746", "market_id": "0xcab7ba4a9133cfd407d7e73e5757e5abbace413b59421527a31113406c97815c", "raw": {"market": "0xcab7ba4a9133cfd407d7e73e5757e5abbace413b59421527a31113406c97815c", "asset_id": "96361925776989336186111887920533578209326565663637092688733016597062311745569", "price": "0.009", "size": "812.25", "side": "BUY", "timestamp": "1768475216312", "received_at": "2026-01-15T12:06:56.436643"}}
{"event_type": "price_change", "event_ts": "2026-01-15T12:06:56.436643", "ingestion_ts": "2026-01-15T12:08:42.168746", "market_id": "0xcab7ba4a9133cfd407d7e73e5757e5abbace413b59421527a31113406c97815c", "raw": {"market": "0xcab7ba4a9133cfd407d7e73e5757e5abbace413b59421527a31113406c97815c", "asset_id": "20002636398944597965698652220992177552927816915094913583821579024925426590022", "price": "0.991", "size": "812.25", "side": "SELL", "timestamp": "1768475216312", "received_at": "2026-01-15T12:06:56.436643"}}
{"event_type": "price_change", "event_ts": "2026-01-15T12:06:56.873299", "ingestion_ts": "2026-01-15T12:08:42.168746", "market_id": "0xcab7ba4a9133cfd407d7e73e5757e5abbace413b59421527a31113406c97815c", "raw": {"market": "0xcab7ba4a9133cfd407d7e73e5757e5abbace413b59421527a31113406c97815c", "asset_id": "96361925776989336186111887920533578209326565663637092688733016597062311745569", "price": "0.006", "size": "136.51", "side": "BUY", "timestamp": "1768475216751", "received_at": "2026-01-15T12:06:56.873299"}}
{"event_type": "price_change", "event_ts": "2026-01-15T12:06:56.873299", "ingestion_ts": "2026-01-15T12:08:42.168746", "market_id": "0xcab7ba4a9133cfd407d7e73e5757e5abbace413b59421527a31113406c97815c", "raw": {"market": "0xcab7ba4a9133cfd407d7e73e5757e5abbace413b59421527a31113406c97815c", "asset_id": "20002636398944597965698652220992177552927816915094913583821579024925426590022", "price": "0.994", "size": "136.51", "side": "SELL", "timestamp": "1768475216751", "received_at": "2026-01-15T12:06:56.873299"}}
{"event_type": "price_change", "event_ts": "2026-01-15T12:06:56.873340", "ingestion_ts": "2026-01-15T12:08:42.168746", "market_id": "0xcab7ba4a9133cfd407d7e73e5757e5abbace413b59421527a31113406c97815c", "raw": {"market": "0xcab7ba4a9133cfd407d7e73e5757e5abbace413b59421527a31113406c97815c", "asset_id": "96361925776989336186111887920533578209326565663637092688733016597062311745569", "price": "0.009", "size": "818.33", "side": "BUY", "timestamp": "1768475216752", "received_at": "2026-01-15T12:06:56.873340"}}
{"event_type": "price_change", "event_ts": "2026-01-15T12:06:56.873340", "ingestion_ts": "2026-01-15T12:08:42.168746", "market_id": "0xcab7ba4a9133cfd407d7e73e5757e5abbace413b59421527a31113406c97815c", "raw": {"market": "0xcab7ba4a9133cfd407d7e73e5757e5abbace413b59421527a31113406c97815c", "asset_id": "20002636398944597965698652220992177552927816915094913583821579024925426590022", "price": "0.991", "size": "818.33", "side": "SELL", "timestamp": "1768475216752", "received_at": "2026-01-15T12:06:56.873340"}}
{"event_type": "price_change", "event_ts": "2026-01-15T12:06:57.994245", "ingestion_ts": "2026-01-15T12:08:42.168746", "market_id": "0xc0e6b917320a47228fb96e3b5ae0e5c93773a5ae2662ae4e1f37807cfe47ce98", "raw": {"market": "0xc0e6b917320a47228fb96e3b5ae0e5c93773a5ae2662ae4e1f37807cfe47ce98", "asset_id": "58656358377246279051017109359677190749228949103591068167284263961542487110215", "price": "0.006", "size": "0", "side": "BUY", "timestamp": "1768475217874", "received_at": "2026-01-15T12:06:57.994245"}}
{"event_type": "price_change", "event_ts": "2026-01-15T12:06:57.994245", "ingestion_ts": "2026-01-15T12:08:42.168746", "market_id": "0xc0e6b917320a47228fb96e3b5ae0e5c93773a5ae2662ae4e1f37807cfe47ce98", "raw": {"market": "0xc0e6b917320a47228fb96e3b5ae0e5c93773a5ae2662ae4e1f37807cfe47ce98", "asset_id": "81647294538046680798858716589766492074338758116170717123345952330712416337530", "price": "0.994", "size": "0", "side": "SELL", "timestamp": "1768475217874", "received_at": "2026-01-15T12:06:57.994245"}}
{"event_type": "price_change", "event_ts": "2026-01-15T12:06:58.426408", "ingestion_ts": "2026-01-15T12:08:42.168746", "market_id": "0xcab7ba4a9133cfd407d7e73e5757e5abbace413b59421527a31113406c97815c", "raw": {"market": "0xcab7ba4a9133cfd407d7e73e5757e5abbace413b59421527a31113406c97815c", "asset_id": "96361925776989336186111887920533578209326565663637092688733016597062311745569", "price": "0.006", "size": "127.41", "side": "BUY", "timestamp": "1768475218304", "received_at": "2026-01-15T12:06:58.426408"}}
{"event_type": "price_change", "event_ts": "2026-01-15T12:06:58.426408", "ingestion_ts": "2026-01-15T12:08:42.168746", "market_id": "0xcab7ba4a9133cfd407d7e73e5757e5abbace413b59421527a31113406c97815c", "raw": {"market": "0xcab7ba4a9133cfd407d7e73e5757e5abbace413b59421527a31113406c97815c", "asset_id": "20002636398944597965698652220992177552927816915094913583821579024925426590022", "price": "0.994", "size": "127.41", "side": "SELL", "timestamp": "1768475218304", "received_at": "2026-01-15T12:06:58.426408"}}
{"event_type": "price_change", "event_ts": "2026-01-15T12:06:58.426472", "ingestion_ts": "2026-01-15T12:08:42.168746", "market_id": "0xcab7ba4a9133cfd407d7e73e5757e5abbace413b59421527a31113406c97815c", "raw": {"market": "0xcab7ba4a9133cfd407d7e73e5757e5abbace413b59421527a31113406c97815c", "asset_id": "96361925776989336186111887920533578209326565663637092688733016597062311745569", "price": "0.009", "size": "812.25", "side": "BUY", "timestamp": "1768475218304", "received_at": "2026-01-15T12:06:58.426472"}}
{"event_type": "price_change", "event_ts": "2026-01-15T12:06:58.426472", "ingestion_ts": "2026-01-15T12:08:42.168746", "market_id": "0xcab7ba4a9133cfd407d7e73e5757e5abbace413b59421527a31113406c97815c", "raw": {"market": "0xcab7ba4a9133cfd407d7e73e5757e5abbace413b59421527a31113406c97815c", "asset_id": "20002636398944597965698652220992177552927816915094913583821579024925426590022", "price": "0.991", "size": "812.25", "side": "SELL", "timestamp": "1768475218304", "received_at": "2026-01-15T12:06:58.426472"}}
{"event_type": "price_change", "event_ts": "2026-01-15T12:06:58.656126", "ingestion_ts": "2026-01-15T12:08:42.168746", "market_id": "0xc0e6b917320a47228fb96e3b5ae0e5c93773a5ae2662ae4e1f37807cfe47ce98", "raw": {"market": "0xc0e6b917320a47228fb96e3b5ae0e5c93773a5ae2662ae4e1f37807cfe47ce98", "asset_id": "58656358377246279051017109359677190749228949103591068167284263961542487110215", "price": "0.007", "size": "6.8", "side": "BUY", "timestamp": "1768475218535", "received_at": "2026-01-15T12:06:58.656126"}}
{"event_type": "price_change", "event_ts": "2026-01-15T12:06:58.656126", "ingestion_ts": "2026-01-15T12:08:42.168746", "market_id": "0xc0e6b917320a47228fb96e3b5ae0e5c93773a5ae2662ae4e1f37807cfe47ce98", "raw": {"market": "0xc0e6b917320a47228fb96e3b5ae0e5c93773a5ae2662ae4e1f37807cfe47ce98", "asset_id": "81647294538046680798858716589766492074338758116170717123345952330712416337530", "price": "0.993", "size": "6.8", "side": "SELL", "timestamp": "1768475218535", "received_at": "2026-01-15T12:06:58.656126"}}
{"event_type": "price_change", "event_ts": "2026-01-15T12:06:58.905220", "ingestion_ts": "2026-01-15T12:08:42.168746", "market_id": "0xcab7ba4a9133cfd407d7e73e5757e5abbace413b59421527a31113406c97815c", "raw": {"market": "0xcab7ba4a9133cfd407d7e73e5757e5abbace413b59421527a31113406c97815c", "asset_id": "96361925776989336186111887920533578209326565663637092688733016597062311745569", "price": "0.009", "size": "818.33", "side": "BUY", "timestamp": "1768475218782", "received_at": "2026-01-15T12:06:58.905220"}}
{"event_type": "price_change", "event_ts": "2026-01-15T12:06:58.905220", "ingestion_ts": "2026-01-15T12:08:42.168746", "market_id": "0xcab7ba4a9133cfd407d7e73e5757e5abbace413b59421527a31113406c97815c", "raw": {"market": "0xcab7ba4a9133cfd407d7e73e5757e5abbace413b59421527a31113406c97815c", "asset_id": "20002636398944597965698652220992177552927816915094913583821579024925426590022", "price": "0.991", "size": "818.33", "side": "SELL", "timestamp": "1768475218782", "received_at": "2026-01-15T12:06:58.905220"}}
{"event_type": "price_change", "event_ts": "2026-01-15T12:06:58.905255", "ingestion_ts": "2026-01-15T12:08:42.168746", "market_id": "0xcab7ba4a9133cfd407d7e73e5757e5abbace413b59421527a31113406c97815c", "raw": {"market": "0xcab7ba4a9133cfd407d7e73e5757e5abbace413b59421527a31113406c97815c", "asset_id": "96361925776989336186111887920533578209326565663637092688733016597062311745569", "price": "0.006", "size": "136.51", "side": "BUY", "timestamp": "1768475218784", "received_at": "2026-01-15T12:06:58.905255"}}
{"event_type": "price_change", "event_ts": "2026-01-15T12:06:58.905255", "ingestion_ts": "2026-01-15T12:08:42.168746", "market_id": "0xcab7ba4a9133cfd407d7e73e5757e5abbace413b59421527a31113406c97815c", "raw": {"market": "0xcab7ba4a9133cfd407d7e73e5757e5abbace413b59421527a31113406c97815c", "asset_id": "20002636398944597965698652220992177552927816915094913583821579024925426590022", "price": "0.994", "size": "136.51", "side": "SELL", "timestamp": "1768475218784", "received_at": "2026-01-15T12:06:58.905255"}}
{"event_type": "price_change", "event_ts": "2026-01-15T12:07:00.581510", "ingestion_ts": "2026-01-15T12:08:42.168746", "market_id": "0xcab7ba4a9133cfd407d7e73e5757e5abbace413b59421527a31113406c97815c", "raw": {"market": "0xcab7ba4a9133cfd407d7e73e5757e5abbace413b59421527a31113406c97815c", "asset_id": "96361925776989336186111887920533578209326565663637092688733016597062311745569", "price": "0.006", "size": "127.41", "side": "BUY", "timestamp": "1768475220456", "received_at": "2026-01-15T12:07:00.581510"}}
{"event_type": "price_change", "event_ts": "2026-01-15T12:07:00.581510", "ingestion_ts": "2026-01-15T12:08:42.168746", "market_id": "0xcab7ba4a9133cfd407d7e73e5757e5abbace413b59421527a31113406c97815c", "raw": {"market": "0xcab7ba4a9133cfd407d7e73e5757e5abbace413b59421527a31113406c97815c", "asset_id": "20002636398944597965698652220992177552927816915094913583821579024925426590022", "price": "0.994", "size": "127.41", "side": "SELL", "timestamp": "1768475220456", "received_at": "2026-01-15T12:07:00.581510"}}
{"event_type": "price_change", "event_ts": "2026-01-15T12:07:00.581548", "ingestion_ts": "2026-01-15T12:08:42.168746", "market_id": "0xcab7ba4a9133cfd407d7e73e5757e5abbace413b59421527a31113406c97815c", "raw": {"market": "0xcab7ba4a9133cfd407d7e73e5757e5abbace413b59421527a31113406c97815c", "asset_id": "96361925776989336186111887920533578209326565663637092688733016597062311745569", "price": "0.009", "size": "812.25", "side": "BUY", "timestamp": "1768475220456", "received_at": "2026-01-15T12:07:00.581548"}}
{"event_type": "price_change", "event_ts": "2026-01-15T12:07:00.581548", "ingestion_ts": "2026-01-15T12:08:42.168746", "market_id": "0xcab7ba4a9133cfd407d7e73e5757e5abbace413b59421527a31113406c97815c", "raw": {"market": "0xcab7ba4a9133cfd407d7e73e5757e5abbace413b59421527a31113406c97815c", "asset_id": "20002636398944597965698652220992177552927816915094913583821579024925426590022", "price": "0.991", "size": "812.25", "side": "SELL", "timestamp": "1768475220456", "received_at": "2026-01-15T12:07:00.581548"}}
{"event_type": "price_change", "event_ts": "2026-01-15T12:07:01.181111", "ingestion_ts": "2026-01-15T12:08:42.168746", "market_id": "0xcab7ba4a9133cfd407d7e73e5757e5abbace413b59421527a31113406c97815c", "raw": {"market": "0xcab7ba4a9133cfd407d7e73e5757e5abbace413b59421527a31113406c97815c", "asset_id": "96361925776989336186111887920533578209326565663637092688733016597062311745569", "price": "0.009", "size": "818.33", "side": "BUY", "timestamp": "1768475221061", "received_at": "2026-01-15T12:07:01.181111"}}
{"event_type": "price_change", "event_ts": "2026-01-15T12:07:01.181111", "ingestion_ts": "2026-01-15T12:08:42.168746", "market_id": "0xcab7ba4a9133cfd407d7e73e5757e5abbace413b59421527a31113406c97815c", "raw": {"market": "0xcab7ba4a9133cfd407d7e73e5757e5abbace413b59421527a31113406c97815c", "asset_id": "20002636398944597965698652220992177552927816915094913583821579024925426590022", "price": "0.991", "size": "818.33", "side": "SELL", "timestamp": "1768475221061", "received_at": "2026-01-15T12:07:01.181111"}}
{"event_type": "price_change", "event_ts": "2026-01-15T12:07:01.182691", "ingestion_ts": "2026-01-15T12:08:42.168746", "market_id": "0xcab7ba4a9133cfd407d7e73e5757e5abbace413b59421527a31113406c97815c", "raw": {"market": "0xcab7ba4a9133cfd407d7e73e5757e5abbace413b59421527a31113406c97815c", "asset_id": "96361925776989336186111887920533578209326565663637092688733016597062311745569", "price": "0.006", "size": "136.51", "side": "BUY", "timestamp": "1768475221062", "received_at": "2026-01-15T12:07:01.182691"}}
{"event_type": "price_change", "event_ts": "2026-01-15T12:07:01.182691", "ingestion_ts": "2026-01-15T12:08:42.168746", "market_id": "0xcab7ba4a9133cfd407d7e73e5757e5abbace413b59421527a31113406c97815c", "raw": {"market": "0xcab7ba4a9133cfd407d7e73e5757e5abbace413b59421527a31113406c97815c", "asset_id": "20002636398944597965698652220992177552927816915094913583821579024925426590022", "price": "0.994", "size": "136.51", "side": "SELL", "timestamp": "1768475221062", "received_at": "2026-01-15T12:07:01.182691"}}
{"event_type": "price_change", "event_ts": "2026-01-15T12:07:01.462928", "ingestion_ts": "2026-01-15T12:08:42.168746", "market_id": "0xc0e6b917320a47228fb96e3b5ae0e5c93773a5ae2662ae4e1f37807cfe47ce98", "raw": {"market": "0xc0e6b917320a47228fb96e3b5ae0e5c93773a5ae2662ae4e1f37807cfe47ce98", "asset_id": "58656358377246279051017109359677190749228949103591068167284263961542487110215", "price": "0.007", "size": "0", "side": "BUY", "timestamp": "1768475221285", "received_at": "2026-01-15T12:07:01.462928"}}
{"event_type": "price_change", "event_ts": "2026-01-15T12:07:01.462928", "ingestion_ts": "2026-01-15T12:08:42.168746", "market_id": "0xc0e6b917320a47228fb96e3b5ae0e5c93773a5ae2662ae4e1f37807cfe47ce98", "raw": {"market": "0xc0e6b917320a47228fb96e3b5ae0e5c93773a5ae2662ae4e1f37807cfe47ce98", "asset_id": "81647294538046680798858716589766492074338758116170717123345952330712416337530", "price": "0.993", "size": "0", "side": "SELL", "timestamp": "1768475221285", "received_at": "2026-01-15T12:07:01.462928"}}
{"event_type": "price_change", "event_ts": "2026-01-15T12:07:02.831738", "ingestion_ts": "2026-01-15T12:08:42.168746", "market_id": "0xc0e6b917320a47228fb96e3b5ae0e5c93773a5ae2662ae4e1f37807cfe47ce98", "raw": {"market": "0xc0e6b917320a47228fb96e3b5ae0e5c93773a5ae2662ae4e1f37807cfe47ce98", "asset_id": "58656358377246279051017109359677190749228949103591068167284263961542487110215", "price": "0.003", "size": "452.27", "side": "BUY", "timestamp": "1768475222713", "received_at": "2026-01-15T12:07:02.831738"}}
{"event_type": "price_change", "event_ts": "2026-01-15T12:07:02.831738", "ingestion_ts": "2026-01-15T12:08:42.168746", "market_id": "0xc0e6b917320a47228fb96e3b5ae0e5c93773a5ae2662ae4e1f37807cfe47ce98", "raw": {"market": "0xc0e6b917320a47228fb96e3b5ae0e5c93773a5ae2662ae4e1f37807cfe47ce98", "asset_id": "81647294538046680798858716589766492074338758116170717123345952330712416337530", "price": "0.997", "size": "452.27", "side": "SELL", "timestamp": "1768475222713", "received_at": "2026-01-15T12:07:02.831738"}}
{"event_type": "price_change", "event_ts": "2026-01-15T12:07:02.850902", "ingestion_ts": "2026-01-15T12:08:42.168746", "market_id": "0xc0e6b917320a47228fb96e3b5ae0e5c93773a5ae2662ae4e1f37807cfe47ce98", "raw": {"market": "0xc0e6b917320a47228fb96e3b5ae0e5c93773a5ae2662ae4e1f37807cfe47ce98", "asset_id": "58656358377246279051017109359677190749228949103591068167284263961542487110215", "price": "0.003", "size": "460.21", "side": "BUY", "timestamp": "1768475222714", "received_at": "2026-01-15T12:07:02.850902"}}
{"event_type": "price_change", "event_ts": "2026-01-15T12:07:02.850902", "ingestion_ts": "2026-01-15T12:08:42.168746", "market_id": "0xc0e6b917320a47228fb96e3b5ae0e5c93773a5ae2662ae4e1f37807cfe47ce98", "raw": {"market": "0xc0e6b917320a47228fb96e3b5ae0e5c93773a5ae2662ae4e1f37807cfe47ce98", "asset_id": "81647294538046680798858716589766492074338758116170717123345952330712416337530", "price": "0.997", "size": "460.21", "side": "SELL", "timestamp": "1768475222714", "received_at": "2026-01-15T12:07:02.850902"}}
{"event_type": "price_change", "event_ts": "2026-01-15T12:07:03.135788", "ingestion_ts": "2026-01-15T12:08:42.168746", "market_id": "0xcab7ba4a9133cfd407d7e73e5757e5abbace413b59421527a31113406c97815c", "raw": {"market": "0xcab7ba4a9133cfd407d7e73e5757e5abbace413b59421527a31113406c97815c", "asset_id": "96361925776989336186111887920533578209326565663637092688733016597062311745569", "price": "0.006", "size": "127.41", "side": "BUY", "timestamp": "1768475223014", "received_at": "2026-01-15T12:07:03.135788"}}
{"event_type": "price_change", "event_ts": "2026-01-15T12:07:03.135788", "ingestion_ts": "2026-01-15T12:08:42.168746", "market_id": "0xcab7ba4a9133cfd407d7e73e5757e5abbace413b59421527a31113406c97815c", "raw": {"market": "0xcab7ba4a9133cfd407d7e73e5757e5abbace413b59421527a31113406c97815c", "asset_id": "20002636398944597965698652220992177552927816915094913583821579024925426590022", "price": "0.994", "size": "127.41", "side": "SELL", "timestamp": "1768475223014", "received_at": "2026-01-15T12:07:03.135788"}}
{"event_type": "price_change", "event_ts": "2026-01-15T12:07:03.135837", "ingestion_ts": "2026-01-15T12:08:42.168746", "market_id": "0xcab7ba4a9133cfd407d7e73e5757e5abbace413b59421527a31113406c97815c", "raw": {"market": "0xcab7ba4a9133cfd407d7e73e5757e5abbace413b59421527a31113406c97815c", "asset_id": "96361925776989336186111887920533578209326565663637092688733016597062311745569", "price": "0.009", "size": "812.25", "side": "BUY", "timestamp": "1768475223014", "received_at": "2026-01-15T12:07:03.135837"}}
{"event_type": "price_change", "event_ts": "2026-01-15T12:07:03.135837", "ingestion_ts": "2026-01-15T12:08:42.168746", "market_id": "0xcab7ba4a9133cfd407d7e73e5757e5abbace413b59421527a31113406c97815c", "raw": {"market": "0xcab7ba4a9133cfd407d7e73e5757e5abbace413b59421527a31113406c97815c", "asset_id": "20002636398944597965698652220992177552927816915094913583821579024925426590022", "price": "0.991", "size": "812.25", "side": "SELL", "timestamp": "1768475223014", "received_at": "2026-01-15T12:07:03.135837"}}
{"event_type": "price_change", "event_ts": "2026-01-15T12:07:03.708637", "ingestion_ts": "2026-01-15T12:08:42.168746", "market_id": "0xcab7ba4a9133cfd407d7e73e5757e5abbace413b59421527a31113406c97815c", "raw": {"market": "0xcab7ba4a9133cfd407d7e73e5757e5abbace413b59421527a31113406c97815c", "asset_id": "96361925776989336186111887920533578209326565663637092688733016597062311745569", "price": "0.006", "size": "136.51", "side": "BUY", "timestamp": "1768475223557", "received_at": "2026-01-15T12:07:03.708637"}}
{"event_type": "price_change", "event_ts": "2026-01-15T12:07:03.708637", "ingestion_ts": "2026-01-15T12:08:42.168746", "market_id": "0xcab7ba4a9133cfd407d7e73e5757e5abbace413b59421527a31113406c97815c", "raw": {"market": "0xcab7ba4a9133cfd407d7e73e5757e5abbace413b59421527a31113406c97815c", "asset_id": "20002636398944597965698652220992177552927816915094913583821579024925426590022", "price": "0.994", "size": "136.51", "side": "SELL", "timestamp": "1768475223557", "received_at": "2026-01-15T12:07:03.708637"}}
{"event_type": "price_change", "event_ts": "2026-01-15T12:07:03.708675", "ingestion_ts": "2026-01-15T12:08:42.168746", "market_id": "0xcab7ba4a9133cfd407d7e73e5757e5abbace413b59421527a31113406c97815c", "raw": {"market": "0xcab7ba4a9133cfd407d7e73e5757e5abbace413b59421527a31113406c97815c", "asset_id": "96361925776989336186111887920533578209326565663637092688733016597062311745569", "price": "0.009", "size": "818.33", "side": "BUY", "timestamp": "1768475223558", "received_at": "2026-01-15T12:07:03.708675"}}
{"event_type": "price_change", "event_ts": "2026-01-15T12:07:03.708675", "ingestion_ts": "2026-01-15T12:08:42.168746", "market_id": "0xcab7ba4a9133cfd407d7e73e5757e5abbace413b59421527a31113406c97815c", "raw": {"market": "0xcab7ba4a9133cfd407d7e73e5757e5abbace413b59421527a31113406c97815c", "asset_id": "20002636398944597965698652220992177552927816915094913583821579024925426590022", "price": "0.991", "size": "818.33", "side": "SELL", "timestamp": "1768475223558", "received_at": "2026-01-15T12:07:03.708675"}}
{"event_type": "price_change", "event_ts": "2026-01-15T12:07:04.656590", "ingestion_ts": "2026-01-15T12:08:42.168746", "market_id": "0x44f08744458b8896620cd3330bc5e1ea69df4199b02d4fc583b3fc96e5d314ce", "raw": {"market": "0x44f08744458b8896620cd3330bc5e1ea69df4199b02d4fc583b3fc96e5d314ce", "asset_id": "72327831507226612545928776794104143393438710920370371172884559893525100761096", "price": "0.402", "size": "0", "side": "BUY", "timestamp": "1768475224474", "received_at": "2026-01-15T12:07:04.656590"}}
{"event_type": "price_change", "event_ts": "2026-01-15T12:07:04.656590", "ingestion_ts": "2026-01-15T12:08:42.168746", "market_id": "0x44f08744458b8896620cd3330bc5e1ea69df4199b02d4fc583b3fc96e5d314ce", "raw": {"market": "0x44f08744458b8896620cd3330bc5e1ea69df4199b02d4fc583b3fc96e5d314ce", "asset_id": "49194009556504828848509244326501559253829462790583873936160989575507522044057", "price": "0.598", "size": "0", "side": "SELL", "timestamp": "1768475224474", "received_at": "2026-01-15T12:07:04.656590"}}
{"event_type": "price_change", "event_ts": "2026-01-15T12:07:04.694676", "ingestion_ts": "2026-01-15T12:08:42.168746", "market_id": "0x44f08744458b8896620cd3330bc5e1ea69df4199b02d4fc583b3fc96e5d314ce", "raw": {"market": "0x44f08744458b8896620cd3330bc5e1ea69df4199b02d4fc583b3fc96e5d314ce", "asset_id": "72327831507226612545928776794104143393438710920370371172884559893525100761096", "price": "0.402", "size": "5", "side": "BUY", "timestamp": "1768475224522", "received_at": "2026-01-15T12:07:04.694676"}}
{"event_type": "price_change", "event_ts": "2026-01-15T12:07:04.694676", "ingestion_ts": "2026-01-15T12:08:42.168746", "market_id": "0x44f08744458b8896620cd3330bc5e1ea69df4199b02d4fc583b3fc96e5d314ce", "raw": {"market": "0x44f08744458b8896620cd3330bc5e1ea69df4199b02d4fc583b3fc96e5d314ce", "asset_id": "49194009556504828848509244326501559253829462790583873936160989575507522044057", "price": "0.598", "size": "5", "side": "SELL", "timestamp": "1768475224522", "received_at": "2026-01-15T12:07:04.694676"}}
{"event_type": "price_change", "event_ts": "2026-01-15T12:07:05.703703", "ingestion_ts": "2026-01-15T12:08:42.168746", "market_id": "0xcab7ba4a9133cfd407d7e73e5757e5abbace413b59421527a31113406c97815c", "raw": {"market": "0xcab7ba4a9133cfd407d7e73e5757e5abbace413b59421527a31113406c97815c", "asset_id": "96361925776989336186111887920533578209326565663637092688733016597062311745569", "price": "0.006", "size": "127.41", "side": "BUY", "timestamp": "1768475225584", "received_at": "2026-01-15T12:07:05.703703"}}
{"event_type": "price_change", "event_ts": "2026-01-15T12:07:05.703703", "ingestion_ts": "2026-01-15T12:08:42.168746", "market_id": "0xcab7ba4a9133cfd407d7e73e5757e5abbace413b59421527a31113406c97815c", "raw": {"market": "0xcab7ba4a9133cfd407d7e73e5757e5abbace413b59421527a31113406c97815c", "asset_id": "20002636398944597965698652220992177552927816915094913583821579024925426590022", "price": "0.994", "size": "127.41", "side": "SELL", "timestamp": "1768475225584", "received_at": "2026-01-15T12:07:05.703703"}}
{"event_type": "price_change", "event_ts": "2026-01-15T12:07:05.703754", "ingestion_ts": "2026-01-15T12:08:42.168746", "market_id": "0xcab7ba4a9133cfd407d7e73e5757e5abbace413b59421527a31113406c97815c", "raw": {"market": "0xcab7ba4a9133cfd407d7e73e5757e5abbace413b59421527a31113406c97815c", "asset_id": "96361925776989336186111887920533578209326565663637092688733016597062311745569", "price": "0.009", "size": "812.25", "side": "BUY", "timestamp": "1768475225584", "received_at": "2026-01-15T12:07:05.703754"}}
{"event_type": "price_change", "event_ts": "2026-01-15T12:07:05.703754", "ingestion_ts": "2026-01-15T12:08:42.168746", "market_id": "0xcab7ba4a9133cfd407d7e73e5757e5abbace413b59421527a31113406c97815c", "raw": {"market": "0xcab7ba4a9133cfd407d7e73e5757e5abbace413b59421527a31113406c97815c", "asset_id": "20002636398944597965698652220992177552927816915094913583821579024925426590022", "price": "0.991", "size": "812.25", "side": "SELL", "timestamp": "1768475225584", "received_at": "2026-01-15T12:07:05.703754"}}
{"event_type": "price_change", "event_ts": "2026-01-15T12:07:06.095768", "ingestion_ts": "2026-01-15T12:08:42.168746", "market_id": "0xcab7ba4a9133cfd407d7e73e5757e5abbace413b59421527a31113406c97815c", "raw": {"market": "0xcab7ba4a9133cfd407d7e73e5757e5abbace413b59421527a31113406c97815c", "asset_id": "96361925776989336186111887920533578209326565663637092688733016597062311745569", "price": "0.006", "size": "136.51", "side": "BUY", "timestamp": "1768475225960", "received_at": "2026-01-15T12:07:06.095768"}}
{"event_type": "price_change", "event_ts": "2026-01-15T12:07:06.095768", "ingestion_ts": "2026-01-15T12:08:42.168746", "market_id": "0xcab7ba4a9133cfd407d7e73e5757e5abbace413b59421527a31113406c97815c", "raw": {"market": "0xcab7ba4a9133cfd407d7e73e5757e5abbace413b59421527a31113406c97815c", "asset_id": "20002636398944597965698652220992177552927816915094913583821579024925426590022", "price": "0.994", "size": "136.51", "side": "SELL", "timestamp": "1768475225960", "received_at": "2026-01-15T12:07:06.095768"}}
{"event_type": "price_change", "event_ts": "2026-01-15T12:07:06.095803", "ingestion_ts": "2026-01-15T12:08:42.168746", "market_id": "0xcab7ba4a9133cfd407d7e73e5757e5abbace413b59421527a31113406c97815c", "raw": {"market": "0xcab7ba4a9133cfd407d7e73e5757e5abbace413b59421527a31113406c97815c", "asset_id": "96361925776989336186111887920533578209326565663637092688733016597062311745569", "price": "0.009", "size": "818.33", "side": "BUY", "timestamp": "1768475225961", "received_at": "2026-01-15T12:07:06.095803"}}
{"event_type": "price_change", "event_ts": "2026-01-15T12:07:06.095803", "ingestion_ts": "2026-01-15T12:08:42.168746", "market_id": "0xcab7ba4a9133cfd407d7e73e5757e5abbace413b59421527a31113406c97815c", "raw": {"market": "0xcab7ba4a9133cfd407d7e73e5757e5abbace413b59421527a31113406c97815c", "asset_id": "20002636398944597965698652220992177552927816915094913583821579024925426590022", "price": "0.991", "size": "818.33", "side": "SELL", "timestamp": "1768475225961", "received_at": "2026-01-15T12:07:06.095803"}}
{"event_type": "price_change", "event_ts": "2026-01-15T12:07:06.546925", "ingestion_ts": "2026-01-15T12:08:42.168746", "market_id": "0x2393ed0b0fdc450054c7b9071907eca75cf4fc36e385adf4a0a5f99ee62243e8", "raw": {"market": "0x2393ed0b0fdc450054c7b9071907eca75cf4fc36e385adf4a0a5f99ee62243e8", "asset_id": "32769749367306925959219403371425714180265458150646381231272229429098460625924", "price": "0.916", "size": "137.22", "side": "BUY", "timestamp": "1768475226359", "received_at": "2026-01-15T12:07:06.546925"}}
{"event_type": "price_change", "event_ts": "2026-01-15T12:07:06.546925", "ingestion_ts": "2026-01-15T12:08:42.168746", "market_id": "0x2393ed0b0fdc450054c7b9071907eca75cf4fc36e385adf4a0a5f99ee62243e8", "raw": {"market": "0x2393ed0b0fdc450054c7b9071907eca75cf4fc36e385adf4a0a5f99ee62243e8", "asset_id": "100074770378634056601572485653252702850363676459996771990439989989293515601975", "price": "0.084", "size": "137.22", "side": "SELL", "timestamp": "1768475226359", "received_at": "2026-01-15T12:07:06.546925"}}
{"event_type": "price_change", "event_ts": "2026-01-15T12:07:06.701386", "ingestion_ts": "2026-01-15T12:08:42.168746", "market_id": "0xc0e6b917320a47228fb96e3b5ae0e5c93773a5ae2662ae4e1f37807cfe47ce98", "raw": {"market": "0xc0e6b917320a47228fb96e3b5ae0e5c93773a5ae2662ae4e1f37807cfe47ce98", "asset_id": "58656358377246279051017109359677190749228949103591068167284263961542487110215", "price": "0.003", "size": "418.74", "side": "BUY", "timestamp": "1768475226564", "received_at": "2026-01-15T12:07:06.701386"}}
{"event_type": "price_change", "event_ts": "2026-01-15T12:07:06.701386", "ingestion_ts": "2026-01-15T12:08:42.168746", "market_id": "0xc0e6b917320a47228fb96e3b5ae0e5c93773a5ae2662ae4e1f37807cfe47ce98", "raw": {"market": "0xc0e6b917320a47228fb96e3b5ae0e5c93773a5ae2662ae4e1f37807cfe47ce98", "asset_id": "81647294538046680798858716589766492074338758116170717123345952330712416337530", "price": "0.997", "size": "418.74", "side": "SELL", "timestamp": "1768475226564", "received_at": "2026-01-15T12:07:06.701386"}}
{"event_type": "price_change", "event_ts": "2026-01-15T12:07:07.579994", "ingestion_ts": "2026-01-15T12:08:42.168746", "market_id": "0xc0e6b917320a47228fb96e3b5ae0e5c93773a5ae2662ae4e1f37807cfe47ce98", "raw": {"market": "0xc0e6b917320a47228fb96e3b5ae0e5c93773a5ae2662ae4e1f37807cfe47ce98", "asset_id": "58656358377246279051017109359677190749228949103591068167284263961542487110215", "price": "0.004", "size": "15.55", "side": "BUY", "timestamp": "1768475227461", "received_at": "2026-01-15T12:07:07.579994"}}
{"event_type": "price_change", "event_ts": "2026-01-15T12:07:07.579994", "ingestion_ts": "2026-01-15T12:08:42.168746", "market_id": "0xc0e6b917320a47228fb96e3b5ae0e5c93773a5ae2662ae4e1f37807cfe47ce98", "raw": {"market": "0xc0e6b917320a47228fb96e3b5ae0e5c93773a5ae2662ae4e1f37807cfe47ce98", "asset_id": "81647294538046680798858716589766492074338758116170717123345952330712416337530", "price": "0.996", "size": "15.55", "side": "SELL", "timestamp": "1768475227461", "received_at": "2026-01-15T12:07:07.579994"}}
{"event_type": "price_change", "event_ts": "2026-01-15T12:07:07.581099", "ingestion_ts": "2026-01-15T12:08:42.168746", "market_id": "0xc0e6b917320a47228fb96e3b5ae0e5c93773a5ae2662ae4e1f37807cfe47ce98", "raw": {"market": "0xc0e6b917320a47228fb96e3b5ae0e5c93773a5ae2662ae4e1f37807cfe47ce98", "asset_id": "58656358377246279051017109359677190749228949103591068167284263961542487110215", "price": "0.004", "size": "31.1", "side": "BUY", "timestamp": "1768475227463", "received_at": "2026-01-15T12:07:07.581099"}}
{"event_type": "price_change", "event_ts": "2026-01-15T12:07:07.581099", "ingestion_ts": "2026-01-15T12:08:42.168746", "market_id": "0xc0e6b917320a47228fb96e3b5ae0e5c93773a5ae2662ae4e1f37807cfe47ce98", "raw": {"market": "0xc0e6b917320a47228fb96e3b5ae0e5c93773a5ae2662ae4e1f37807cfe47ce98", "asset_id": "81647294538046680798858716589766492074338758116170717123345952330712416337530", "price": "0.996", "size": "31.1", "side": "SELL", "timestamp": "1768475227463", "received_at": "2026-01-15T12:07:07.581099"}}
{"event_type": "price_change", "event_ts": "2026-01-15T12:07:07.973344", "ingestion_ts": "2026-01-15T12:08:42.168746", "market_id": "0xcab7ba4a9133cfd407d7e73e5757e5abbace413b59421527a31113406c97815c", "raw": {"market": "0xcab7ba4a9133cfd407d7e73e5757e5abbace413b59421527a31113406c97815c", "asset_id": "96361925776989336186111887920533578209326565663637092688733016597062311745569", "price": "0.006", "size": "127.41", "side": "BUY", "timestamp": "1768475227854", "received_at": "2026-01-15T12:07:07.973344"}}
{"event_type": "price_change", "event_ts": "2026-01-15T12:07:07.973344", "ingestion_ts": "2026-01-15T12:08:42.168746", "market_id": "0xcab7ba4a9133cfd407d7e73e5757e5abbace413b59421527a31113406c97815c", "raw": {"market": "0xcab7ba4a9133cfd407d7e73e5757e5abbace413b59421527a31113406c97815c", "asset_id": "20002636398944597965698652220992177552927816915094913583821579024925426590022", "price": "0.994", "size": "127.41", "side": "SELL", "timestamp": "1768475227854", "received_at": "2026-01-15T12:07:07.973344"}}
{"event_type": "price_change", "event_ts": "2026-01-15T12:07:07.974013", "ingestion_ts": "2026-01-15T12:08:42.168746", "market_id": "0xcab7ba4a9133cfd407d7e73e5757e5abbace413b59421527a31113406c97815c", "raw": {"market": "0xcab7ba4a9133cfd407d7e73e5757e5abbace413b59421527a31113406c97815c", "asset_id": "96361925776989336186111887920533578209326565663637092688733016597062311745569", "price": "0.009", "size": "812.25", "side": "BUY", "timestamp": "1768475227854", "received_at": "2026-01-15T12:07:07.974013"}}
{"event_type": "price_change", "event_ts": "2026-01-15T12:07:07.974013", "ingestion_ts": "2026-01-15T12:08:42.168746", "market_id": "0xcab7ba4a9133cfd407d7e73e5757e5abbace413b59421527a31113406c97815c", "raw": {"market": "0xcab7ba4a9133cfd407d7e73e5757e5abbace413b59421527a31113406c97815c", "asset_id": "20002636398944597965698652220992177552927816915094913583821579024925426590022", "price": "0.991", "size": "812.25", "side": "SELL", "timestamp": "1768475227854", "received_at": "2026-01-15T12:07:07.974013"}}
{"event_type": "price_change", "event_ts": "2026-01-15T12:07:08.764351", "ingestion_ts": "2026-01-15T12:08:42.168746", "market_id": "0xcab7ba4a9133cfd407d7e73e5757e5abbace413b59421527a31113406c97815c", "raw": {"market": "0xcab7ba4a9133cfd407d7e73e5757e5abbace413b59421527a31113406c97815c", "asset_id": "96361925776989336186111887920533578209326565663637092688733016597062311745569", "price": "0.009", "size": "818.33", "side": "BUY", "timestamp": "1768475228420", "received_at": "2026-01-15T12:07:08.764351"}}
{"event_type": "price_change", "event_ts": "2026-01-15T12:07:08.764351", "ingestion_ts": "2026-01-15T12:08:42.168746", "market_id": "0xcab7ba4a9133cfd407d7e73e5757e5abbace413b59421527a31113406c97815c", "raw": {"market": "0xcab7ba4a9133cfd407d7e73e5757e5abbace413b59421527a31113406c97815c", "asset_id": "20002636398944597965698652220992177552927816915094913583821579024925426590022", "price": "0.991", "size": "818.33", "side": "SELL", "timestamp": "1768475228420", "received_at": "2026-01-15T12:07:08.764351"}}
{"event_type": "price_change", "event_ts": "2026-01-15T12:07:08.764386", "ingestion_ts": "2026-01-15T12:08:42.168746", "market_id": "0xcab7ba4a9133cfd407d7e73e5757e5abbace413b59421527a31113406c97815c", "raw": {"market": "0xcab7ba4a9133cfd407d7e73e5757e5abbace413b59421527a31113406c97815c", "asset_id": "96361925776989336186111887920533578209326565663637092688733016597062311745569", "price": "0.006", "size": "136.51", "side": "BUY", "timestamp": "1768475228421", "received_at": "2026-01-15T12:07:08.764386"}}
{"event_type": "price_change", "event_ts": "2026-01-15T12:07:08.764386", "ingestion_ts": "2026-01-15T12:08:42.168746", "market_id": "0xcab7ba4a9133cfd407d7e73e5757e5abbace413b59421527a31113406c97815c", "raw": {"market": "0xcab7ba4a9133cfd407d7e73e5757e5abbace413b59421527a31113406c97815c", "asset_id": "20002636398944597965698652220992177552927816915094913583821579024925426590022", "price": "0.994", "size": "136.51", "side": "SELL", "timestamp": "1768475228421", "received_at": "2026-01-15T12:07:08.764386"}}
{"event_type": "price_change", "event_ts": "2026-01-15T12:07:10.470326", "ingestion_ts": "2026-01-15T12:08:42.168746", "market_id": "0xcab7ba4a9133cfd407d7e73e5757e5abbace413b59421527a31113406c97815c", "raw": {"market": "0xcab7ba4a9133cfd407d7e73e5757e5abbace413b59421527a31113406c97815c", "asset_id": "96361925776989336186111887920533578209326565663637092688733016597062311745569", "price": "0.006", "size": "127.41", "side": "BUY", "timestamp": "1768475230339", "received_at": "2026-01-15T12:07:10.470326"}}
{"event_type": "price_change", "event_ts": "2026-01-15T12:07:10.470326", "ingestion_ts": "2026-01-15T12:08:42.168746", "market_id": "0xcab7ba4a9133cfd407d7e73e5757e5abbace413b59421527a31113406c97815c", "raw": {"market": "0xcab7ba4a9133cfd407d7e73e5757e5abbace413b59421527a31113406c97815c", "asset_id": "20002636398944597965698652220992177552927816915094913583821579024925426590022", "price": "0.994", "size": "127.41", "side": "SELL", "timestamp": "1768475230339", "received_at": "2026-01-15T12:07:10.470326"}}
{"event_type": "price_change", "event_ts": "2026-01-15T12:07:10.470362", "ingestion_ts": "2026-01-15T12:08:42.168746", "market_id": "0xcab7ba4a9133cfd407d7e73e5757e5abbace413b59421527a31113406c97815c", "raw": {"market": "0xcab7ba4a9133cfd407d7e73e5757e5abbace413b59421527a31113406c97815c", "asset_id": "96361925776989336186111887920533578209326565663637092688733016597062311745569", "price": "0.009", "size": "812.25", "side": "BUY", "timestamp": "1768475230339", "received_at": "2026-01-15T12:07:10.470362"}}
{"event_type": "price_change", "event_ts": "2026-01-15T12:07:10.470362", "ingestion_ts": "2026-01-15T12:08:42.168746", "market_id": "0xcab7ba4a9133cfd407d7e73e5757e5abbace413b59421527a31113406c97815c", "raw": {"market": "0xcab7ba4a9133cfd407d7e73e5757e5abbace413b59421527a31113406c97815c", "asset_id": "20002636398944597965698652220992177552927816915094913583821579024925426590022", "price": "0.991", "size": "812.25", "side": "SELL", "timestamp": "1768475230339", "received_at": "2026-01-15T12:07:10.470362"}}
{"event_type": "price_change", "event_ts": "2026-01-15T12:07:11.040164", "ingestion_ts": "2026-01-15T12:08:42.168746", "market_id": "0xcab7ba4a9133cfd407d7e73e5757e5abbace413b59421527a31113406c97815c", "raw": {"market": "0xcab7ba4a9133cfd407d7e73e5757e5abbace413b59421527a31113406c97815c", "asset_id": "96361925776989336186111887920533578209326565663637092688733016597062311745569", "price": "0.006", "size": "136.51", "side": "BUY", "timestamp": "1768475230915", "received_at": "2026-01-15T12:07:11.040164"}}
{"event_type": "price_change", "event_ts": "2026-01-15T12:07:11.040164", "ingestion_ts": "2026-01-15T12:08:42.168746", "market_id": "0xcab7ba4a9133cfd407d7e73e5757e5abbace413b59421527a31113406c97815c", "raw": {"market": "0xcab7ba4a9133cfd407d7e73e5757e5abbace413b59421527a31113406c97815c", "asset_id": "20002636398944597965698652220992177552927816915094913583821579024925426590022", "price": "0.994", "size": "136.51", "side": "SELL", "timestamp": "1768475230915", "received_at": "2026-01-15T12:07:11.040164"}}
{"event_type": "price_change", "event_ts": "2026-01-15T12:07:11.042406", "ingestion_ts": "2026-01-15T12:08:42.168746", "market_id": "0xcab7ba4a9133cfd407d7e73e5757e5abbace413b59421527a31113406c97815c", "raw": {"market": "0xcab7ba4a9133cfd407d7e73e5757e5abbace413b59421527a31113406c97815c", "asset_id": "96361925776989336186111887920533578209326565663637092688733016597062311745569", "price": "0.009", "size": "818.33", "side": "BUY", "timestamp": "1768475230916", "received_at": "2026-01-15T12:07:11.042406"}}
{"event_type": "price_change", "event_ts": "2026-01-15T12:07:11.042406", "ingestion_ts": "2026-01-15T12:08:42.168746", "market_id": "0xcab7ba4a9133cfd407d7e73e5757e5abbace413b59421527a31113406c97815c", "raw": {"market": "0xcab7ba4a9133cfd407d7e73e5757e5abbace413b59421527a31113406c97815c", "asset_id": "20002636398944597965698652220992177552927816915094913583821579024925426590022", "price": "0.991", "size": "818.33", "side": "SELL", "timestamp": "1768475230916", "received_at": "2026-01-15T12:07:11.042406"}}
{"event_type": "price_change", "event_ts": "2026-01-15T12:07:11.312457", "ingestion_ts": "2026-01-15T12:08:42.168746", "market_id": "0xc0e6b917320a47228fb96e3b5ae0e5c93773a5ae2662ae4e1f37807cfe47ce98", "raw": {"market": "0xc0e6b917320a47228fb96e3b5ae0e5c93773a5ae2662ae4e1f37807cfe47ce98", "asset_id": "58656358377246279051017109359677190749228949103591068167284263961542487110215", "price": "0.004", "size": "15.55", "side": "BUY", "timestamp": "1768475231195", "received_at": "2026-01-15T12:07:11.312457"}}
{"event_type": "price_change", "event_ts": "2026-01-15T12:07:11.312457", "ingestion_ts": "2026-01-15T12:08:42.168746", "market_id": "0xc0e6b917320a47228fb96e3b5ae0e5c93773a5ae2662ae4e1f37807cfe47ce98", "raw": {"market": "0xc0e6b917320a47228fb96e3b5ae0e5c93773a5ae2662ae4e1f37807cfe47ce98", "asset_id": "81647294538046680798858716589766492074338758116170717123345952330712416337530", "price": "0.996", "size": "15.55", "side": "SELL", "timestamp": "1768475231195", "received_at": "2026-01-15T12:07:11.312457"}}
{"event_type": "price_change", "event_ts": "2026-01-15T12:07:12.121907", "ingestion_ts": "2026-01-15T12:08:42.168746", "market_id": "0xc0e6b917320a47228fb96e3b5ae0e5c93773a5ae2662ae4e1f37807cfe47ce98", "raw": {"market": "0xc0e6b917320a47228fb96e3b5ae0e5c93773a5ae2662ae4e1f37807cfe47ce98", "asset_id": "58656358377246279051017109359677190749228949103591068167284263961542487110215", "price": "0.005", "size": "12.42", "side": "BUY", "timestamp": "1768475232005", "received_at": "2026-01-15T12:07:12.121907"}}
{"event_type": "price_change", "event_ts": "2026-01-15T12:07:12.121907", "ingestion_ts": "2026-01-15T12:08:42.168746", "market_id": "0xc0e6b917320a47228fb96e3b5ae0e5c93773a5ae2662ae4e1f37807cfe47ce98", "raw": {"market": "0xc0e6b917320a47228fb96e3b5ae0e5c93773a5ae2662ae4e1f37807cfe47ce98", "asset_id": "81647294538046680798858716589766492074338758116170717123345952330712416337530", "price": "0.995", "size": "12.42", "side": "SELL", "timestamp": "1768475232005", "received_at": "2026-01-15T12:07:12.121907"}}
{"event_type": "price_change", "event_ts": "2026-01-15T12:07:12.123135", "ingestion_ts": "2026-01-15T12:08:42.168746", "market_id": "0xc0e6b917320a47228fb96e3b5ae0e5c93773a5ae2662ae4e1f37807cfe47ce98", "raw": {"market": "0xc0e6b917320a47228fb96e3b5ae0e5c93773a5ae2662ae4e1f37807cfe47ce98", "asset_id": "58656358377246279051017109359677190749228949103591068167284263961542487110215", "price": "0.003", "size": "423.74", "side": "BUY", "timestamp": "1768475232006", "received_at": "2026-01-15T12:07:12.123135"}}
{"event_type": "price_change", "event_ts": "2026-01-15T12:07:12.123135", "ingestion_ts": "2026-01-15T12:08:42.168746", "market_id": "0xc0e6b917320a47228fb96e3b5ae0e5c93773a5ae2662ae4e1f37807cfe47ce98", "raw": {"market": "0xc0e6b917320a47228fb96e3b5ae0e5c93773a5ae2662ae4e1f37807cfe47ce98", "asset_id": "81647294538046680798858716589766492074338758116170717123345952330712416337530", "price": "0.997", "size": "423.74", "side": "SELL", "timestamp": "1768475232006", "received_at": "2026-01-15T12:07:12.123135"}}
{"event_type": "price_change", "event_ts": "2026-01-15T12:07:12.740455", "ingestion_ts": "2026-01-15T12:08:42.168746", "market_id": "0xcab7ba4a9133cfd407d7e73e5757e5abbace413b59421527a31113406c97815c", "raw": {"market": "0xcab7ba4a9133cfd407d7e73e5757e5abbace413b59421527a31113406c97815c", "asset_id": "96361925776989336186111887920533578209326565663637092688733016597062311745569", "price": "0.006", "size": "127.41", "side": "BUY", "timestamp": "1768475232617", "received_at": "2026-01-15T12:07:12.740455"}}
{"event_type": "price_change", "event_ts": "2026-01-15T12:07:12.740455", "ingestion_ts": "2026-01-15T12:08:42.168746", "market_id": "0xcab7ba4a9133cfd407d7e73e5757e5abbace413b59421527a31113406c97815c", "raw": {"market": "0xcab7ba4a9133cfd407d7e73e5757e5abbace413b59421527a31113406c97815c", "asset_id": "20002636398944597965698652220992177552927816915094913583821579024925426590022", "price": "0.994", "size": "127.41", "side": "SELL", "timestamp": "1768475232617", "received_at": "2026-01-15T12:07:12.740455"}}
{"event_type": "price_change", "event_ts": "2026-01-15T12:07:12.740502", "ingestion_ts": "2026-01-15T12:08:42.168746", "market_id": "0xcab7ba4a9133cfd407d7e73e5757e5abbace413b59421527a31113406c97815c", "raw": {"market": "0xcab7ba4a9133cfd407d7e73e5757e5abbace413b59421527a31113406c97815c", "asset_id": "96361925776989336186111887920533578209326565663637092688733016597062311745569", "price": "0.009", "size": "812.25", "side": "BUY", "timestamp": "1768475232617", "received_at": "2026-01-15T12:07:12.740502"}}
{"event_type": "price_change", "event_ts": "2026-01-15T12:07:12.740502", "ingestion_ts": "2026-01-15T12:08:42.168746", "market_id": "0xcab7ba4a9133cfd407d7e73e5757e5abbace413b59421527a31113406c97815c", "raw": {"market": "0xcab7ba4a9133cfd407d7e73e5757e5abbace413b59421527a31113406c97815c", "asset_id": "20002636398944597965698652220992177552927816915094913583821579024925426590022", "price": "0.991", "size": "812.25", "side": "SELL", "timestamp": "1768475232617", "received_at": "2026-01-15T12:07:12.740502"}}
{"event_type": "price_change", "event_ts": "2026-01-15T12:07:13.062887", "ingestion_ts": "2026-01-15T12:08:42.168746", "market_id": "0xcab7ba4a9133cfd407d7e73e5757e5abbace413b59421527a31113406c97815c", "raw": {"market": "0xcab7ba4a9133cfd407d7e73e5757e5abbace413b59421527a31113406c97815c", "asset_id": "96361925776989336186111887920533578209326565663637092688733016597062311745569", "price": "0.006", "size": "136.51", "side": "BUY", "timestamp": "1768475232934", "received_at": "2026-01-15T12:07:13.062887"}}
{"event_type": "price_change", "event_ts": "2026-01-15T12:07:13.062887", "ingestion_ts": "2026-01-15T12:08:42.168746", "market_id": "0xcab7ba4a9133cfd407d7e73e5757e5abbace413b59421527a31113406c97815c", "raw": {"market": "0xcab7ba4a9133cfd407d7e73e5757e5abbace413b59421527a31113406c97815c", "asset_id": "20002636398944597965698652220992177552927816915094913583821579024925426590022", "price": "0.994", "size": "136.51", "side": "SELL", "timestamp": "1768475232934", "received_at": "2026-01-15T12:07:13.062887"}}
{"event_type": "price_change", "event_ts": "2026-01-15T12:07:13.062924", "ingestion_ts": "2026-01-15T12:08:42.168746", "market_id": "0xcab7ba4a9133cfd407d7e73e5757e5abbace413b59421527a31113406c97815c", "raw": {"market": "0xcab7ba4a9133cfd407d7e73e5757e5abbace413b59421527a31113406c97815c", "asset_id": "96361925776989336186111887920533578209326565663637092688733016597062311745569", "price": "0.009", "size": "818.33", "side": "BUY", "timestamp": "1768475232935", "received_at": "2026-01-15T12:07:13.062924"}}
{"event_type": "price_change", "event_ts": "2026-01-15T12:07:13.062924", "ingestion_ts": "2026-01-15T12:08:42.168746", "market_id": "0xcab7ba4a9133cfd407d7e73e5757e5abbace413b59421527a31113406c97815c", "raw": {"market": "0xcab7ba4a9133cfd407d7e73e5757e5abbace413b59421527a31113406c97815c", "asset_id": "20002636398944597965698652220992177552927816915094913583821579024925426590022", "price": "0.991", "size": "818.33", "side": "SELL", "timestamp": "1768475232935", "received_at": "2026-01-15T12:07:13.062924"}}
{"event_type": "price_change", "event_ts": "2026-01-15T12:07:15.922857", "ingestion_ts": "2026-01-15T12:08:42.168746", "market_id": "0xc0e6b917320a47228fb96e3b5ae0e5c93773a5ae2662ae4e1f37807cfe47ce98", "raw": {"market": "0xc0e6b917320a47228fb96e3b5ae0e5c93773a5ae2662ae4e1f37807cfe47ce98", "asset_id": "58656358377246279051017109359677190749228949103591068167284263961542487110215", "price": "0.004", "size": "0", "side": "BUY", "timestamp": "1768475235765", "received_at": "2026-01-15T12:07:15.922857"}}
{"event_type": "price_change", "event_ts": "2026-01-15T12:07:15.922857", "ingestion_ts": "2026-01-15T12:08:42.168746", "market_id": "0xc0e6b917320a47228fb96e3b5ae0e5c93773a5ae2662ae4e1f37807cfe47ce98", "raw": {"market": "0xc0e6b917320a47228fb96e3b5ae0e5c93773a5ae2662ae4e1f37807cfe47ce98", "asset_id": "81647294538046680798858716589766492074338758116170717123345952330712416337530", "price": "0.996", "size": "0", "side": "SELL", "timestamp": "1768475235765", "received_at": "2026-01-15T12:07:15.922857"}}
{"event_type": "price_change", "event_ts": "2026-01-15T12:07:15.922895", "ingestion_ts": "2026-01-15T12:08:42.168746", "market_id": "0xc0e6b917320a47228fb96e3b5ae0e5c93773a5ae2662ae4e1f37807cfe47ce98", "raw": {"market": "0xc0e6b917320a47228fb96e3b5ae0e5c93773a5ae2662ae4e1f37807cfe47ce98", "asset_id": "58656358377246279051017109359677190749228949103591068167284263961542487110215", "price": "0.005", "size": "2.98", "side": "BUY", "timestamp": "1768475235765", "received_at": "2026-01-15T12:07:15.922895"}}
{"event_type": "price_change", "event_ts": "2026-01-15T12:07:15.922895", "ingestion_ts": "2026-01-15T12:08:42.168746", "market_id": "0xc0e6b917320a47228fb96e3b5ae0e5c93773a5ae2662ae4e1f37807cfe47ce98", "raw": {"market": "0xc0e6b917320a47228fb96e3b5ae0e5c93773a5ae2662ae4e1f37807cfe47ce98", "asset_id": "81647294538046680798858716589766492074338758116170717123345952330712416337530", "price": "0.995", "size": "2.98", "side": "SELL", "timestamp": "1768475235765", "received_at": "2026-01-15T12:07:15.922895"}}
{"event_type": "price_change", "event_ts": "2026-01-15T12:07:15.922920", "ingestion_ts": "2026-01-15T12:08:42.168746", "market_id": "0xcab7ba4a9133cfd407d7e73e5757e5abbace413b59421527a31113406c97815c", "raw": {"market": "0xcab7ba4a9133cfd407d7e73e5757e5abbace413b59421527a31113406c97815c", "asset_id": "96361925776989336186111887920533578209326565663637092688733016597062311745569", "price": "0.006", "size": "127.41", "side": "BUY", "timestamp": "1768475235765", "received_at": "2026-01-15T12:07:15.922920"}}
{"event_type": "price_change", "event_ts": "2026-01-15T12:07:15.922920", "ingestion_ts": "2026-01-15T12:08:42.168746", "market_id": "0xcab7ba4a9133cfd407d7e73e5757e5abbace413b59421527a31113406c97815c", "raw": {"market": "0xcab7ba4a9133cfd407d7e73e5757e5abbace413b59421527a31113406c97815c", "asset_id": "20002636398944597965698652220992177552927816915094913583821579024925426590022", "price": "0.994", "size": "127.41", "side": "SELL", "timestamp": "1768475235765", "received_at": "2026-01-15T12:07:15.922920"}}
{"event_type": "price_change", "event_ts": "2026-01-15T12:07:15.922930", "ingestion_ts": "2026-01-15T12:08:42.168746", "market_id": "0xcab7ba4a9133cfd407d7e73e5757e5abbace413b59421527a31113406c97815c", "raw": {"market": "0xcab7ba4a9133cfd407d7e73e5757e5abbace413b59421527a31113406c97815c", "asset_id": "96361925776989336186111887920533578209326565663637092688733016597062311745569", "price": "0.009", "size": "812.25", "side": "BUY", "timestamp": "1768475235765", "received_at": "2026-01-15T12:07:15.922930"}}
{"event_type": "price_change", "event_ts": "2026-01-15T12:07:15.922930", "ingestion_ts": "2026-01-15T12:08:42.168746", "market_id": "0xcab7ba4a9133cfd407d7e73e5757e5abbace413b59421527a31113406c97815c", "raw": {"market": "0xcab7ba4a9133cfd407d7e73e5757e5abbace413b59421527a31113406c97815c", "asset_id": "20002636398944597965698652220992177552927816915094913583821579024925426590022", "price": "0.991", "size": "812.25", "side": "SELL", "timestamp": "1768475235765", "received_at": "2026-01-15T12:07:15.922930"}}
{"event_type": "price_change", "event_ts": "2026-01-15T12:07:16.319512", "ingestion_ts": "2026-01-15T12:08:42.168746", "market_id": "0xc0e6b917320a47228fb96e3b5ae0e5c93773a5ae2662ae4e1f37807cfe47ce98", "raw": {"market": "0xc0e6b917320a47228fb96e3b5ae0e5c93773a5ae2662ae4e1f37807cfe47ce98", "asset_id": "58656358377246279051017109359677190749228949103591068167284263961542487110215", "price": "0.005", "size": "8.45", "side": "BUY", "timestamp": "1768475236196", "received_at": "2026-01-15T12:07:16.319512"}}
{"event_type": "price_change", "event_ts": "2026-01-15T12:07:16.319512", "ingestion_ts": "2026-01-15T12:08:42.168746", "market_id": "0xc0e6b917320a47228fb96e3b5ae0e5c93773a5ae2662ae4e1f37807cfe47ce98", "raw": {"market": "0xc0e6b917320a47228fb96e3b5ae0e5c93773a5ae2662ae4e1f37807cfe47ce98", "asset_id": "81647294538046680798858716589766492074338758116170717123345952330712416337530", "price": "0.995", "size": "8.45", "side": "SELL", "timestamp": "1768475236196", "received_at": "2026-01-15T12:07:16.319512"}}
{"event_type": "price_change", "event_ts": "2026-01-15T12:07:16.319548", "ingestion_ts": "2026-01-15T12:08:42.168746", "market_id": "0xcab7ba4a9133cfd407d7e73e5757e5abbace413b59421527a31113406c97815c", "raw": {"market": "0xcab7ba4a9133cfd407d7e73e5757e5abbace413b59421527a31113406c97815c", "asset_id": "96361925776989336186111887920533578209326565663637092688733016597062311745569", "price": "0.009", "size": "818.33", "side": "BUY", "timestamp": "1768475236196", "received_at": "2026-01-15T12:07:16.319548"}}
{"event_type": "price_change", "event_ts": "2026-01-15T12:07:16.319548", "ingestion_ts": "2026-01-15T12:08:42.168746", "market_id": "0xcab7ba4a9133cfd407d7e73e5757e5abbace413b59421527a31113406c97815c", "raw": {"market": "0xcab7ba4a9133cfd407d7e73e5757e5abbace413b59421527a31113406c97815c", "asset_id": "20002636398944597965698652220992177552927816915094913583821579024925426590022", "price": "0.991", "size": "818.33", "side": "SELL", "timestamp": "1768475236196", "received_at": "2026-01-15T12:07:16.319548"}}
{"event_type": "price_change", "event_ts": "2026-01-15T12:07:16.319559", "ingestion_ts": "2026-01-15T12:08:42.168746", "market_id": "0xcab7ba4a9133cfd407d7e73e5757e5abbace413b59421527a31113406c97815c", "raw": {"market": "0xcab7ba4a9133cfd407d7e73e5757e5abbace413b59421527a31113406c97815c", "asset_id": "96361925776989336186111887920533578209326565663637092688733016597062311745569", "price": "0.006", "size": "136.51", "side": "BUY", "timestamp": "1768475236197", "received_at": "2026-01-15T12:07:16.319559"}}
{"event_type": "price_change", "event_ts": "2026-01-15T12:07:16.319559", "ingestion_ts": "2026-01-15T12:08:42.168746", "market_id": "0xcab7ba4a9133cfd407d7e73e5757e5abbace413b59421527a31113406c97815c", "raw": {"market": "0xcab7ba4a9133cfd407d7e73e5757e5abbace413b59421527a31113406c97815c", "asset_id": "20002636398944597965698652220992177552927816915094913583821579024925426590022", "price": "0.994", "size": "136.51", "side": "SELL", "timestamp": "1768475236197", "received_at": "2026-01-15T12:07:16.319559"}}
{"event_type": "price_change", "event_ts": "2026-01-15T12:07:16.319568", "ingestion_ts": "2026-01-15T12:08:42.168746", "market_id": "0xc0e6b917320a47228fb96e3b5ae0e5c93773a5ae2662ae4e1f37807cfe47ce98", "raw": {"market": "0xc0e6b917320a47228fb96e3b5ae0e5c93773a5ae2662ae4e1f37807cfe47ce98", "asset_id": "58656358377246279051017109359677190749228949103591068167284263961542487110215", "price": "0.006", "size": "9.11", "side": "BUY", "timestamp": "1768475236197", "received_at": "2026-01-15T12:07:16.319568"}}
{"event_type": "price_change", "event_ts": "2026-01-15T12:07:16.319568", "ingestion_ts": "2026-01-15T12:08:42.168746", "market_id": "0xc0e6b917320a47228fb96e3b5ae0e5c93773a5ae2662ae4e1f37807cfe47ce98", "raw": {"market": "0xc0e6b917320a47228fb96e3b5ae0e5c93773a5ae2662ae4e1f37807cfe47ce98", "asset_id": "81647294538046680798858716589766492074338758116170717123345952330712416337530", "price": "0.994", "size": "9.11", "side": "SELL", "timestamp": "1768475236197", "received_at": "2026-01-15T12:07:16.319568"}}
{"event_type": "price_change", "event_ts": "2026-01-15T12:07:16.319577", "ingestion_ts": "2026-01-15T12:08:42.168746", "market_id": "0xc0e6b917320a47228fb96e3b5ae0e5c93773a5ae2662ae4e1f37807cfe47ce98", "raw": {"market": "0xc0e6b917320a47228fb96e3b5ae0e5c93773a5ae2662ae4e1f37807cfe47ce98", "asset_id": "58656358377246279051017109359677190749228949103591068167284263961542487110215", "price": "0.005", "size": "13.92", "side": "BUY", "timestamp": "1768475236198", "received_at": "2026-01-15T12:07:16.319577"}}
{"event_type": "price_change", "event_ts": "2026-01-15T12:07:16.319577", "ingestion_ts": "2026-01-15T12:08:42.168746", "market_id": "0xc0e6b917320a47228fb96e3b5ae0e5c93773a5ae2662ae4e1f37807cfe47ce98", "raw": {"market": "0xc0e6b917320a47228fb96e3b5ae0e5c93773a5ae2662ae4e1f37807cfe47ce98", "asset_id": "81647294538046680798858716589766492074338758116170717123345952330712416337530", "price": "0.995", "size": "13.92", "side": "SELL", "timestamp": "1768475236198", "received_at": "2026-01-15T12:07:16.319577"}}
{"event_type": "price_change", "event_ts": "2026-01-15T12:07:17.715811", "ingestion_ts": "2026-01-15T12:08:42.168746", "market_id": "0xcab7ba4a9133cfd407d7e73e5757e5abbace413b59421527a31113406c97815c", "raw": {"market": "0xcab7ba4a9133cfd407d7e73e5757e5abbace413b59421527a31113406c97815c", "asset_id": "96361925776989336186111887920533578209326565663637092688733016597062311745569", "price": "0.006", "size": "127.41", "side": "BUY", "timestamp": "1768475237497", "received_at": "2026-01-15T12:07:17.715811"}}
{"event_type": "price_change", "event_ts": "2026-01-15T12:07:17.715811", "ingestion_ts": "2026-01-15T12:08:42.168746", "market_id": "0xcab7ba4a9133cfd407d7e73e5757e5abbace413b59421527a31113406c97815c", "raw": {"market": "0xcab7ba4a9133cfd407d7e73e5757e5abbace413b59421527a31113406c97815c", "asset_id": "20002636398944597965698652220992177552927816915094913583821579024925426590022", "price": "0.994", "size": "127.41", "side": "SELL", "timestamp": "1768475237497", "received_at": "2026-01-15T12:07:17.715811"}}
{"event_type": "price_change", "event_ts": "2026-01-15T12:07:17.715846", "ingestion_ts": "2026-01-15T12:08:42.168746", "market_id": "0xcab7ba4a9133cfd407d7e73e5757e5abbace413b59421527a31113406c97815c", "raw": {"market": "0xcab7ba4a9133cfd407d7e73e5757e5abbace413b59421527a31113406c97815c", "asset_id": "96361925776989336186111887920533578209326565663637092688733016597062311745569", "price": "0.009", "size": "812.25", "side": "BUY", "timestamp": "1768475237497", "received_at": "2026-01-15T12:07:17.715846"}}
{"event_type": "price_change", "event_ts": "2026-01-15T12:07:17.715846", "ingestion_ts": "2026-01-15T12:08:42.168746", "market_id": "0xcab7ba4a9133cfd407d7e73e5757e5abbace413b59421527a31113406c97815c", "raw": {"market": "0xcab7ba4a9133cfd407d7e73e5757e5abbace413b59421527a31113406c97815c", "asset_id": "20002636398944597965698652220992177552927816915094913583821579024925426590022", "price": "0.991", "size": "812.25", "side": "SELL", "timestamp": "1768475237497", "received_at": "2026-01-15T12:07:17.715846"}}
{"event_type": "price_change", "event_ts": "2026-01-15T12:07:18.066446", "ingestion_ts": "2026-01-15T12:08:42.168746", "market_id": "0xcab7ba4a9133cfd407d7e73e5757e5abbace413b59421527a31113406c97815c", "raw": {"market": "0xcab7ba4a9133cfd407d7e73e5757e5abbace413b59421527a31113406c97815c", "asset_id": "96361925776989336186111887920533578209326565663637092688733016597062311745569", "price": "0.009", "size": "818.33", "side": "BUY", "timestamp": "1768475237941", "received_at": "2026-01-15T12:07:18.066446"}}
{"event_type": "price_change", "event_ts": "2026-01-15T12:07:18.066446", "ingestion_ts": "2026-01-15T12:08:42.168746", "market_id": "0xcab7ba4a9133cfd407d7e73e5757e5abbace413b59421527a31113406c97815c", "raw": {"market": "0xcab7ba4a9133cfd407d7e73e5757e5abbace413b59421527a31113406c97815c", "asset_id": "20002636398944597965698652220992177552927816915094913583821579024925426590022", "price": "0.991", "size": "818.33", "side": "SELL", "timestamp": "1768475237941", "received_at": "2026-01-15T12:07:18.066446"}}
{"event_type": "price_change", "event_ts": "2026-01-15T12:07:18.066493", "ingestion_ts": "2026-01-15T12:08:42.168746", "market_id": "0xcab7ba4a9133cfd407d7e73e5757e5abbace413b59421527a31113406c97815c", "raw": {"market": "0xcab7ba4a9133cfd407d7e73e5757e5abbace413b59421527a31113406c97815c", "asset_id": "96361925776989336186111887920533578209326565663637092688733016597062311745569", "price": "0.006", "size": "136.51", "side": "BUY", "timestamp": "1768475237942", "received_at": "2026-01-15T12:07:18.066493"}}
{"event_type": "price_change", "event_ts": "2026-01-15T12:07:18.066493", "ingestion_ts": "2026-01-15T12:08:42.168746", "market_id": "0xcab7ba4a9133cfd407d7e73e5757e5abbace413b59421527a31113406c97815c", "raw": {"market": "0xcab7ba4a9133cfd407d7e73e5757e5abbace413b59421527a31113406c97815c", "asset_id": "20002636398944597965698652220992177552927816915094913583821579024925426590022", "price": "0.994", "size": "136.51", "side": "SELL", "timestamp": "1768475237942", "received_at": "2026-01-15T12:07:18.066493"}}
{"event_type": "price_change", "event_ts": "2026-01-15T12:07:18.754831", "ingestion_ts": "2026-01-15T12:08:42.168746", "market_id": "0xc0e6b917320a47228fb96e3b5ae0e5c93773a5ae2662ae4e1f37807cfe47ce98", "raw": {"market": "0xc0e6b917320a47228fb96e3b5ae0e5c93773a5ae2662ae4e1f37807cfe47ce98", "asset_id": "58656358377246279051017109359677190749228949103591068167284263961542487110215", "price": "0.005", "size": "8.45", "side": "BUY", "timestamp": "1768475238578", "received_at": "2026-01-15T12:07:18.754831"}}
{"event_type": "price_change", "event_ts": "2026-01-15T12:07:18.754831", "ingestion_ts": "2026-01-15T12:08:42.168746", "market_id": "0xc0e6b917320a47228fb96e3b5ae0e5c93773a5ae2662ae4e1f37807cfe47ce98", "raw": {"market": "0xc0e6b917320a47228fb96e3b5ae0e5c93773a5ae2662ae4e1f37807cfe47ce98", "asset_id": "81647294538046680798858716589766492074338758116170717123345952330712416337530", "price": "0.995", "size": "8.45", "side": "SELL", "timestamp": "1768475238578", "received_at": "2026-01-15T12:07:18.754831"}}
{"event_type": "price_change", "event_ts": "2026-01-15T12:07:18.755015", "ingestion_ts": "2026-01-15T12:08:42.168746", "market_id": "0xc0e6b917320a47228fb96e3b5ae0e5c93773a5ae2662ae4e1f37807cfe47ce98", "raw": {"market": "0xc0e6b917320a47228fb96e3b5ae0e5c93773a5ae2662ae4e1f37807cfe47ce98", "asset_id": "58656358377246279051017109359677190749228949103591068167284263961542487110215", "price": "0.006", "size": "0", "side": "BUY", "timestamp": "1768475238578", "received_at": "2026-01-15T12:07:18.755015"}}
{"event_type": "price_change", "event_ts": "2026-01-15T12:07:18.755015", "ingestion_ts": "2026-01-15T12:08:42.168746", "market_id": "0xc0e6b917320a47228fb96e3b5ae0e5c93773a5ae2662ae4e1f37807cfe47ce98", "raw": {"market": "0xc0e6b917320a47228fb96e3b5ae0e5c93773a5ae2662ae4e1f37807cfe47ce98", "asset_id": "81647294538046680798858716589766492074338758116170717123345952330712416337530", "price": "0.994", "size": "0", "side": "SELL", "timestamp": "1768475238578", "received_at": "2026-01-15T12:07:18.755015"}}
{"event_type": "price_change", "event_ts": "2026-01-15T12:07:19.169851", "ingestion_ts": "2026-01-15T12:08:42.168746", "market_id": "0xc0e6b917320a47228fb96e3b5ae0e5c93773a5ae2662ae4e1f37807cfe47ce98", "raw": {"market": "0xc0e6b917320a47228fb96e3b5ae0e5c93773a5ae2662ae4e1f37807cfe47ce98", "asset_id": "58656358377246279051017109359677190749228949103591068167284263961542487110215", "price": "0.006", "size": "5.96", "side": "BUY", "timestamp": "1768475239042", "received_at": "2026-01-15T12:07:19.169851"}}
{"event_type": "price_change", "event_ts": "2026-01-15T12:07:19.169851", "ingestion_ts": "2026-01-15T12:08:42.168746", "market_id": "0xc0e6b917320a47228fb96e3b5ae0e5c93773a5ae2662ae4e1f37807cfe47ce98", "raw": {"market": "0xc0e6b917320a47228fb96e3b5ae0e5c93773a5ae2662ae4e1f37807cfe47ce98", "asset_id": "81647294538046680798858716589766492074338758116170717123345952330712416337530", "price": "0.994", "size": "5.96", "side": "SELL", "timestamp": "1768475239042", "received_at": "2026-01-15T12:07:19.169851"}}
{"event_type": "price_change", "event_ts": "2026-01-15T12:07:19.173820", "ingestion_ts": "2026-01-15T12:08:42.168746", "market_id": "0xc0e6b917320a47228fb96e3b5ae0e5c93773a5ae2662ae4e1f37807cfe47ce98", "raw": {"market": "0xc0e6b917320a47228fb96e3b5ae0e5c93773a5ae2662ae4e1f37807cfe47ce98", "asset_id": "58656358377246279051017109359677190749228949103591068167284263961542487110215", "price": "0.007", "size": "6.61", "side": "BUY", "timestamp": "1768475239043", "received_at": "2026-01-15T12:07:19.173820"}}
{"event_type": "price_change", "event_ts": "2026-01-15T12:07:19.173820", "ingestion_ts": "2026-01-15T12:08:42.168746", "market_id": "0xc0e6b917320a47228fb96e3b5ae0e5c93773a5ae2662ae4e1f37807cfe47ce98", "raw": {"market": "0xc0e6b917320a47228fb96e3b5ae0e5c93773a5ae2662ae4e1f37807cfe47ce98", "asset_id": "81647294538046680798858716589766492074338758116170717123345952330712416337530", "price": "0.993", "size": "6.61", "side": "SELL", "timestamp": "1768475239043", "received_at": "2026-01-15T12:07:19.173820"}}
{"event_type": "price_change", "event_ts": "2026-01-15T12:07:19.673136", "ingestion_ts": "2026-01-15T12:08:42.168746", "market_id": "0xcab7ba4a9133cfd407d7e73e5757e5abbace413b59421527a31113406c97815c", "raw": {"market": "0xcab7ba4a9133cfd407d7e73e5757e5abbace413b59421527a31113406c97815c", "asset_id": "96361925776989336186111887920533578209326565663637092688733016597062311745569", "price": "0.006", "size": "127.41", "side": "BUY", "timestamp": "1768475239553", "received_at": "2026-01-15T12:07:19.673136"}}
{"event_type": "price_change", "event_ts": "2026-01-15T12:07:19.673136", "ingestion_ts": "2026-01-15T12:08:42.168746", "market_id": "0xcab7ba4a9133cfd407d7e73e5757e5abbace413b59421527a31113406c97815c", "raw": {"market": "0xcab7ba4a9133cfd407d7e73e5757e5abbace413b59421527a31113406c97815c", "asset_id": "20002636398944597965698652220992177552927816915094913583821579024925426590022", "price": "0.994", "size": "127.41", "side": "SELL", "timestamp": "1768475239553", "received_at": "2026-01-15T12:07:19.673136"}}
{"event_type": "price_change", "event_ts": "2026-01-15T12:07:19.673169", "ingestion_ts": "2026-01-15T12:08:42.168746", "market_id": "0xcab7ba4a9133cfd407d7e73e5757e5abbace413b59421527a31113406c97815c", "raw": {"market": "0xcab7ba4a9133cfd407d7e73e5757e5abbace413b59421527a31113406c97815c", "asset_id": "96361925776989336186111887920533578209326565663637092688733016597062311745569", "price": "0.009", "size": "812.25", "side": "BUY", "timestamp": "1768475239553", "received_at": "2026-01-15T12:07:19.673169"}}
{"event_type": "price_change", "event_ts": "2026-01-15T12:07:19.673169", "ingestion_ts": "2026-01-15T12:08:42.168746", "market_id": "0xcab7ba4a9133cfd407d7e73e5757e5abbace413b59421527a31113406c97815c", "raw": {"market": "0xcab7ba4a9133cfd407d7e73e5757e5abbace413b59421527a31113406c97815c", "asset_id": "20002636398944597965698652220992177552927816915094913583821579024925426590022", "price": "0.991", "size": "812.25", "side": "SELL", "timestamp": "1768475239553", "received_at": "2026-01-15T12:07:19.673169"}}
{"event_type": "price_change", "event_ts": "2026-01-15T12:07:20.205758", "ingestion_ts": "2026-01-15T12:08:42.168746", "market_id": "0xcab7ba4a9133cfd407d7e73e5757e5abbace413b59421527a31113406c97815c", "raw": {"market": "0xcab7ba4a9133cfd407d7e73e5757e5abbace413b59421527a31113406c97815c", "asset_id": "96361925776989336186111887920533578209326565663637092688733016597062311745569", "price": "0.009", "size": "818.33", "side": "BUY", "timestamp": "1768475240015", "received_at": "2026-01-15T12:07:20.205758"}}
{"event_type": "price_change", "event_ts": "2026-01-15T12:07:20.205758", "ingestion_ts": "2026-01-15T12:08:42.168746", "market_id": "0xcab7ba4a9133cfd407d7e73e5757e5abbace413b59421527a31113406c97815c", "raw": {"market": "0xcab7ba4a9133cfd407d7e73e5757e5abbace413b59421527a31113406c97815c", "asset_id": "20002636398944597965698652220992177552927816915094913583821579024925426590022", "price": "0.991", "size": "818.33", "side": "SELL", "timestamp": "1768475240015", "received_at": "2026-01-15T12:07:20.205758"}}
{"event_type": "price_change", "event_ts": "2026-01-15T12:07:20.205807", "ingestion_ts": "2026-01-15T12:08:42.168746", "market_id": "0xcab7ba4a9133cfd407d7e73e5757e5abbace413b59421527a31113406c97815c", "raw": {"market": "0xcab7ba4a9133cfd407d7e73e5757e5abbace413b59421527a31113406c97815c", "asset_id": "96361925776989336186111887920533578209326565663637092688733016597062311745569", "price": "0.006", "size": "136.51", "side": "BUY", "timestamp": "1768475240021", "received_at": "2026-01-15T12:07:20.205807"}}
{"event_type": "price_change", "event_ts": "2026-01-15T12:07:20.205807", "ingestion_ts": "2026-01-15T12:08:42.168746", "market_id": "0xcab7ba4a9133cfd407d7e73e5757e5abbace413b59421527a31113406c97815c", "raw": {"market": "0xcab7ba4a9133cfd407d7e73e5757e5abbace413b59421527a31113406c97815c", "asset_id": "20002636398944597965698652220992177552927816915094913583821579024925426590022", "price": "0.994", "size": "136.51", "side": "SELL", "timestamp": "1768475240021", "received_at": "2026-01-15T12:07:20.205807"}}
{"event_type": "price_change", "event_ts": "2026-01-15T12:07:21.085523", "ingestion_ts": "2026-01-15T12:08:42.168746", "market_id": "0xc0e6b917320a47228fb96e3b5ae0e5c93773a5ae2662ae4e1f37807cfe47ce98", "raw": {"market": "0xc0e6b917320a47228fb96e3b5ae0e5c93773a5ae2662ae4e1f37807cfe47ce98", "asset_id": "58656358377246279051017109359677190749228949103591068167284263961542487110215", "price": "0.005", "size": "2.98", "side": "BUY", "timestamp": "1768475240790", "received_at": "2026-01-15T12:07:21.085523"}}
{"event_type": "price_change", "event_ts": "2026-01-15T12:07:21.085523", "ingestion_ts": "2026-01-15T12:08:42.168746", "market_id": "0xc0e6b917320a47228fb96e3b5ae0e5c93773a5ae2662ae4e1f37807cfe47ce98", "raw": {"market": "0xc0e6b917320a47228fb96e3b5ae0e5c93773a5ae2662ae4e1f37807cfe47ce98", "asset_id": "81647294538046680798858716589766492074338758116170717123345952330712416337530", "price": "0.995", "size": "2.98", "side": "SELL", "timestamp": "1768475240790", "received_at": "2026-01-15T12:07:21.085523"}}
{"event_type": "price_change", "event_ts": "2026-01-15T12:07:21.085560", "ingestion_ts": "2026-01-15T12:08:42.168746", "market_id": "0xc0e6b917320a47228fb96e3b5ae0e5c93773a5ae2662ae4e1f37807cfe47ce98", "raw": {"market": "0xc0e6b917320a47228fb96e3b5ae0e5c93773a5ae2662ae4e1f37807cfe47ce98", "asset_id": "58656358377246279051017109359677190749228949103591068167284263961542487110215", "price": "0.006", "size": "0", "side": "BUY", "timestamp": "1768475240790", "received_at": "2026-01-15T12:07:21.085560"}}
{"event_type": "price_change", "event_ts": "2026-01-15T12:07:21.085560", "ingestion_ts": "2026-01-15T12:08:42.168746", "market_id": "0xc0e6b917320a47228fb96e3b5ae0e5c93773a5ae2662ae4e1f37807cfe47ce98", "raw": {"market": "0xc0e6b917320a47228fb96e3b5ae0e5c93773a5ae2662ae4e1f37807cfe47ce98", "asset_id": "81647294538046680798858716589766492074338758116170717123345952330712416337530", "price": "0.994", "size": "0", "side": "SELL", "timestamp": "1768475240790", "received_at": "2026-01-15T12:07:21.085560"}}
{"event_type": "price_change", "event_ts": "2026-01-15T12:07:21.085572", "ingestion_ts": "2026-01-15T12:08:42.168746", "market_id": "0xc0e6b917320a47228fb96e3b5ae0e5c93773a5ae2662ae4e1f37807cfe47ce98", "raw": {"market": "0xc0e6b917320a47228fb96e3b5ae0e5c93773a5ae2662ae4e1f37807cfe47ce98", "asset_id": "58656358377246279051017109359677190749228949103591068167284263961542487110215", "price": "0.007", "size": "0", "side": "BUY", "timestamp": "1768475240790", "received_at": "2026-01-15T12:07:21.085572"}}
{"event_type": "price_change", "event_ts": "2026-01-15T12:07:21.085572", "ingestion_ts": "2026-01-15T12:08:42.168746", "market_id": "0xc0e6b917320a47228fb96e3b5ae0e5c93773a5ae2662ae4e1f37807cfe47ce98", "raw": {"market": "0xc0e6b917320a47228fb96e3b5ae0e5c93773a5ae2662ae4e1f37807cfe47ce98", "asset_id": "81647294538046680798858716589766492074338758116170717123345952330712416337530", "price": "0.993", "size": "0", "side": "SELL", "timestamp": "1768475240790", "received_at": "2026-01-15T12:07:21.085572"}}
{"event_type": "price_change", "event_ts": "2026-01-15T12:07:21.648500", "ingestion_ts": "2026-01-15T12:08:42.168746", "market_id": "0xcab7ba4a9133cfd407d7e73e5757e5abbace413b59421527a31113406c97815c", "raw": {"market": "0xcab7ba4a9133cfd407d7e73e5757e5abbace413b59421527a31113406c97815c", "asset_id": "96361925776989336186111887920533578209326565663637092688733016597062311745569", "price": "0.006", "size": "127.41", "side": "BUY", "timestamp": "1768475241258", "received_at": "2026-01-15T12:07:21.648500"}}
{"event_type": "price_change", "event_ts": "2026-01-15T12:07:21.648500", "ingestion_ts": "2026-01-15T12:08:42.168746", "market_id": "0xcab7ba4a9133cfd407d7e73e5757e5abbace413b59421527a31113406c97815c", "raw": {"market": "0xcab7ba4a9133cfd407d7e73e5757e5abbace413b59421527a31113406c97815c", "asset_id": "20002636398944597965698652220992177552927816915094913583821579024925426590022", "price": "0.994", "size": "127.41", "side": "SELL", "timestamp": "1768475241258", "received_at": "2026-01-15T12:07:21.648500"}}
{"event_type": "price_change", "event_ts": "2026-01-15T12:07:21.648535", "ingestion_ts": "2026-01-15T12:08:42.168746", "market_id": "0xcab7ba4a9133cfd407d7e73e5757e5abbace413b59421527a31113406c97815c", "raw": {"market": "0xcab7ba4a9133cfd407d7e73e5757e5abbace413b59421527a31113406c97815c", "asset_id": "96361925776989336186111887920533578209326565663637092688733016597062311745569", "price": "0.009", "size": "812.25", "side": "BUY", "timestamp": "1768475241258", "received_at": "2026-01-15T12:07:21.648535"}}
{"event_type": "price_change", "event_ts": "2026-01-15T12:07:21.648535", "ingestion_ts": "2026-01-15T12:08:42.168746", "market_id": "0xcab7ba4a9133cfd407d7e73e5757e5abbace413b59421527a31113406c97815c", "raw": {"market": "0xcab7ba4a9133cfd407d7e73e5757e5abbace413b59421527a31113406c97815c", "asset_id": "20002636398944597965698652220992177552927816915094913583821579024925426590022", "price": "0.991", "size": "812.25", "side": "SELL", "timestamp": "1768475241258", "received_at": "2026-01-15T12:07:21.648535"}}
{"event_type": "price_change", "event_ts": "2026-01-15T12:07:21.689570", "ingestion_ts": "2026-01-15T12:08:42.168746", "market_id": "0xc0e6b917320a47228fb96e3b5ae0e5c93773a5ae2662ae4e1f37807cfe47ce98", "raw": {"market": "0xc0e6b917320a47228fb96e3b5ae0e5c93773a5ae2662ae4e1f37807cfe47ce98", "asset_id": "58656358377246279051017109359677190749228949103591068167284263961542487110215", "price": "0.006", "size": "8.7", "side": "BUY", "timestamp": "1768475241303", "received_at": "2026-01-15T12:07:21.689570"}}
{"event_type": "price_change", "event_ts": "2026-01-15T12:07:21.689570", "ingestion_ts": "2026-01-15T12:08:42.168746", "market_id": "0xc0e6b917320a47228fb96e3b5ae0e5c93773a5ae2662ae4e1f37807cfe47ce98", "raw": {"market": "0xc0e6b917320a47228fb96e3b5ae0e5c93773a5ae2662ae4e1f37807cfe47ce98", "asset_id": "81647294538046680798858716589766492074338758116170717123345952330712416337530", "price": "0.994", "size": "8.7", "side": "SELL", "timestamp": "1768475241303", "received_at": "2026-01-15T12:07:21.689570"}}
{"event_type": "price_change", "event_ts": "2026-01-15T12:07:21.689675", "ingestion_ts": "2026-01-15T12:08:42.168746", "market_id": "0xc0e6b917320a47228fb96e3b5ae0e5c93773a5ae2662ae4e1f37807cfe47ce98", "raw": {"market": "0xc0e6b917320a47228fb96e3b5ae0e5c93773a5ae2662ae4e1f37807cfe47ce98", "asset_id": "58656358377246279051017109359677190749228949103591068167284263961542487110215", "price": "0.008", "size": "7.14", "side": "BUY", "timestamp": "1768475241304", "received_at": "2026-01-15T12:07:21.689675"}}
{"event_type": "price_change", "event_ts": "2026-01-15T12:07:21.689675", "ingestion_ts": "2026-01-15T12:08:42.168746", "market_id": "0xc0e6b917320a47228fb96e3b5ae0e5c93773a5ae2662ae4e1f37807cfe47ce98", "raw": {"market": "0xc0e6b917320a47228fb96e3b5ae0e5c93773a5ae2662ae4e1f37807cfe47ce98", "asset_id": "81647294538046680798858716589766492074338758116170717123345952330712416337530", "price": "0.992", "size": "7.14", "side": "SELL", "timestamp": "1768475241304", "received_at": "2026-01-15T12:07:21.689675"}}
{"event_type": "price_change", "event_ts": "2026-01-15T12:07:21.997042", "ingestion_ts": "2026-01-15T12:08:42.168746", "market_id": "0xcab7ba4a9133cfd407d7e73e5757e5abbace413b59421527a31113406c97815c", "raw": {"market": "0xcab7ba4a9133cfd407d7e73e5757e5abbace413b59421527a31113406c97815c", "asset_id": "96361925776989336186111887920533578209326565663637092688733016597062311745569", "price": "0.009", "size": "818.33", "side": "BUY", "timestamp": "1768475241684", "received_at": "2026-01-15T12:07:21.997042"}}
{"event_type": "price_change", "event_ts": "2026-01-15T12:07:21.997042", "ingestion_ts": "2026-01-15T12:08:42.168746", "market_id": "0xcab7ba4a9133cfd407d7e73e5757e5abbace413b59421527a31113406c97815c", "raw": {"market": "0xcab7ba4a9133cfd407d7e73e5757e5abbace413b59421527a31113406c97815c", "asset_id": "20002636398944597965698652220992177552927816915094913583821579024925426590022", "price": "0.991", "size": "818.33", "side": "SELL", "timestamp": "1768475241684", "received_at": "2026-01-15T12:07:21.997042"}}
{"event_type": "price_change", "event_ts": "2026-01-15T12:07:21.997110", "ingestion_ts": "2026-01-15T12:08:42.168746", "market_id": "0xcab7ba4a9133cfd407d7e73e5757e5abbace413b59421527a31113406c97815c", "raw": {"market": "0xcab7ba4a9133cfd407d7e73e5757e5abbace413b59421527a31113406c97815c", "asset_id": "96361925776989336186111887920533578209326565663637092688733016597062311745569", "price": "0.006", "size": "136.51", "side": "BUY", "timestamp": "1768475241685", "received_at": "2026-01-15T12:07:21.997110"}}
{"event_type": "price_change", "event_ts": "2026-01-15T12:07:21.997110", "ingestion_ts": "2026-01-15T12:08:42.168746", "market_id": "0xcab7ba4a9133cfd407d7e73e5757e5abbace413b59421527a31113406c97815c", "raw": {"market": "0xcab7ba4a9133cfd407d7e73e5757e5abbace413b59421527a31113406c97815c", "asset_id": "20002636398944597965698652220992177552927816915094913583821579024925426590022", "price": "0.994", "size": "136.51", "side": "SELL", "timestamp": "1768475241685", "received_at": "2026-01-15T12:07:21.997110"}}
{"event_type": "price_change", "event_ts": "2026-01-15T12:07:23.198405", "ingestion_ts": "2026-01-15T12:08:42.168746", "market_id": "0x427bc4b40c09b3dcbc973747f0e4b079bed91b3e5a0aed5c36edd0f7591485f4", "raw": {"market": "0x427bc4b40c09b3dcbc973747f0e4b079bed91b3e5a0aed5c36edd0f7591485f4", "asset_id": "115669573443672055876643967408433138119481486650803218131873713375232186497057", "price": "0.004", "size": "28.07", "side": "BUY", "timestamp": "1768475243080", "received_at": "2026-01-15T12:07:23.198405"}}
{"event_type": "price_change", "event_ts": "2026-01-15T12:07:23.198405", "ingestion_ts": "2026-01-15T12:08:42.168746", "market_id": "0x427bc4b40c09b3dcbc973747f0e4b079bed91b3e5a0aed5c36edd0f7591485f4", "raw": {"market": "0x427bc4b40c09b3dcbc973747f0e4b079bed91b3e5a0aed5c36edd0f7591485f4", "asset_id": "86130975769502911188457673769190265049139877688522439001984850068234616395137", "price": "0.996", "size": "28.07", "side": "SELL", "timestamp": "1768475243080", "received_at": "2026-01-15T12:07:23.198405"}}
{"event_type": "price_change", "event_ts": "2026-01-15T12:07:23.201274", "ingestion_ts": "2026-01-15T12:08:42.168746", "market_id": "0x427bc4b40c09b3dcbc973747f0e4b079bed91b3e5a0aed5c36edd0f7591485f4", "raw": {"market": "0x427bc4b40c09b3dcbc973747f0e4b079bed91b3e5a0aed5c36edd0f7591485f4", "asset_id": "115669573443672055876643967408433138119481486650803218131873713375232186497057", "price": "0.007", "size": "0", "side": "BUY", "timestamp": "1768475243080", "received_at": "2026-01-15T12:07:23.201274"}}
{"event_type": "price_change", "event_ts": "2026-01-15T12:07:23.201274", "ingestion_ts": "2026-01-15T12:08:42.168746", "market_id": "0x427bc4b40c09b3dcbc973747f0e4b079bed91b3e5a0aed5c36edd0f7591485f4", "raw": {"market": "0x427bc4b40c09b3dcbc973747f0e4b079bed91b3e5a0aed5c36edd0f7591485f4", "asset_id": "86130975769502911188457673769190265049139877688522439001984850068234616395137", "price": "0.993", "size": "0", "side": "SELL", "timestamp": "1768475243080", "received_at": "2026-01-15T12:07:23.201274"}}
{"event_type": "price_change", "event_ts": "2026-01-15T12:07:23.540264", "ingestion_ts": "2026-01-15T12:08:42.168746", "market_id": "0x427bc4b40c09b3dcbc973747f0e4b079bed91b3e5a0aed5c36edd0f7591485f4", "raw": {"market": "0x427bc4b40c09b3dcbc973747f0e4b079bed91b3e5a0aed5c36edd0f7591485f4", "asset_id": "115669573443672055876643967408433138119481486650803218131873713375232186497057", "price": "0.005", "size": "24.01", "side": "BUY", "timestamp": "1768475243376", "received_at": "2026-01-15T12:07:23.540264"}}
{"event_type": "price_change", "event_ts": "2026-01-15T12:07:23.540264", "ingestion_ts": "2026-01-15T12:08:42.168746", "market_id": "0x427bc4b40c09b3dcbc973747f0e4b079bed91b3e5a0aed5c36edd0f7591485f4", "raw": {"market": "0x427bc4b40c09b3dcbc973747f0e4b079bed91b3e5a0aed5c36edd0f7591485f4", "asset_id": "86130975769502911188457673769190265049139877688522439001984850068234616395137", "price": "0.995", "size": "24.01", "side": "SELL", "timestamp": "1768475243376", "received_at": "2026-01-15T12:07:23.540264"}}
{"event_type": "price_change", "event_ts": "2026-01-15T12:07:23.540348", "ingestion_ts": "2026-01-15T12:08:42.168746", "market_id": "0x427bc4b40c09b3dcbc973747f0e4b079bed91b3e5a0aed5c36edd0f7591485f4", "raw": {"market": "0x427bc4b40c09b3dcbc973747f0e4b079bed91b3e5a0aed5c36edd0f7591485f4", "asset_id": "115669573443672055876643967408433138119481486650803218131873713375232186497057", "price": "0.002", "size": "60.97", "side": "BUY", "timestamp": "1768475243377", "received_at": "2026-01-15T12:07:23.540348"}}
{"event_type": "price_change", "event_ts": "2026-01-15T12:07:23.540348", "ingestion_ts": "2026-01-15T12:08:42.168746", "market_id": "0x427bc4b40c09b3dcbc973747f0e4b079bed91b3e5a0aed5c36edd0f7591485f4", "raw": {"market": "0x427bc4b40c09b3dcbc973747f0e4b079bed91b3e5a0aed5c36edd0f7591485f4", "asset_id": "86130975769502911188457673769190265049139877688522439001984850068234616395137", "price": "0.998", "size": "60.97", "side": "SELL", "timestamp": "1768475243377", "received_at": "2026-01-15T12:07:23.540348"}}
{"event_type": "price_change", "event_ts": "2026-01-15T12:07:24.884366", "ingestion_ts": "2026-01-15T12:08:42.168746", "market_id": "0xcab7ba4a9133cfd407d7e73e5757e5abbace413b59421527a31113406c97815c", "raw": {"market": "0xcab7ba4a9133cfd407d7e73e5757e5abbace413b59421527a31113406c97815c", "asset_id": "96361925776989336186111887920533578209326565663637092688733016597062311745569", "price": "0.006", "size": "127.41", "side": "BUY", "timestamp": "1768475244686", "received_at": "2026-01-15T12:07:24.884366"}}
{"event_type": "price_change", "event_ts": "2026-01-15T12:07:24.884366", "ingestion_ts": "2026-01-15T12:08:42.168746", "market_id": "0xcab7ba4a9133cfd407d7e73e5757e5abbace413b59421527a31113406c97815c", "raw": {"market": "0xcab7ba4a9133cfd407d7e73e5757e5abbace413b59421527a31113406c97815c", "asset_id": "20002636398944597965698652220992177552927816915094913583821579024925426590022", "price": "0.994", "size": "127.41", "side": "SELL", "timestamp": "1768475244686", "received_at": "2026-01-15T12:07:24.884366"}}
{"event_type": "price_change", "event_ts": "2026-01-15T12:07:24.884406", "ingestion_ts": "2026-01-15T12:08:42.168746", "market_id": "0xcab7ba4a9133cfd407d7e73e5757e5abbace413b59421527a31113406c97815c", "raw": {"market": "0xcab7ba4a9133cfd407d7e73e5757e5abbace413b59421527a31113406c97815c", "asset_id": "96361925776989336186111887920533578209326565663637092688733016597062311745569", "price": "0.009", "size": "812.25", "side": "BUY", "timestamp": "1768475244686", "received_at": "2026-01-15T12:07:24.884406"}}
{"event_type": "price_change", "event_ts": "2026-01-15T12:07:24.884406", "ingestion_ts": "2026-01-15T12:08:42.168746", "market_id": "0xcab7ba4a9133cfd407d7e73e5757e5abbace413b59421527a31113406c97815c", "raw": {"market": "0xcab7ba4a9133cfd407d7e73e5757e5abbace413b59421527a31113406c97815c", "asset_id": "20002636398944597965698652220992177552927816915094913583821579024925426590022", "price": "0.991", "size": "812.25", "side": "SELL", "timestamp": "1768475244686", "received_at": "2026-01-15T12:07:24.884406"}}
{"event_type": "price_change", "event_ts": "2026-01-15T12:07:25.294960", "ingestion_ts": "2026-01-15T12:08:42.168746", "market_id": "0xcab7ba4a9133cfd407d7e73e5757e5abbace413b59421527a31113406c97815c", "raw": {"market": "0xcab7ba4a9133cfd407d7e73e5757e5abbace413b59421527a31113406c97815c", "asset_id": "96361925776989336186111887920533578209326565663637092688733016597062311745569", "price": "0.006", "size": "136.51", "side": "BUY", "timestamp": "1768475245163", "received_at": "2026-01-15T12:07:25.294960"}}
{"event_type": "price_change", "event_ts": "2026-01-15T12:07:25.294960", "ingestion_ts": "2026-01-15T12:08:42.168746", "market_id": "0xcab7ba4a9133cfd407d7e73e5757e5abbace413b59421527a31113406c97815c", "raw": {"market": "0xcab7ba4a9133cfd407d7e73e5757e5abbace413b59421527a31113406c97815c", "asset_id": "20002636398944597965698652220992177552927816915094913583821579024925426590022", "price": "0.994", "size": "136.51", "side": "SELL", "timestamp": "1768475245163", "received_at": "2026-01-15T12:07:25.294960"}}
{"event_type": "price_change", "event_ts": "2026-01-15T12:07:25.298489", "ingestion_ts": "2026-01-15T12:08:42.168746", "market_id": "0xcab7ba4a9133cfd407d7e73e5757e5abbace413b59421527a31113406c97815c", "raw": {"market": "0xcab7ba4a9133cfd407d7e73e5757e5abbace413b59421527a31113406c97815c", "asset_id": "96361925776989336186111887920533578209326565663637092688733016597062311745569", "price": "0.009", "size": "818.33", "side": "BUY", "timestamp": "1768475245164", "received_at": "2026-01-15T12:07:25.298489"}}
{"event_type": "price_change", "event_ts": "2026-01-15T12:07:25.298489", "ingestion_ts": "2026-01-15T12:08:42.168746", "market_id": "0xcab7ba4a9133cfd407d7e73e5757e5abbace413b59421527a31113406c97815c", "raw": {"market": "0xcab7ba4a9133cfd407d7e73e5757e5abbace413b59421527a31113406c97815c", "asset_id": "20002636398944597965698652220992177552927816915094913583821579024925426590022", "price": "0.991", "size": "818.33", "side": "SELL", "timestamp": "1768475245164", "received_at": "2026-01-15T12:07:25.298489"}}
{"event_type": "price_change", "event_ts": "2026-01-15T12:07:25.440041", "ingestion_ts": "2026-01-15T12:08:42.168746", "market_id": "0xc0e6b917320a47228fb96e3b5ae0e5c93773a5ae2662ae4e1f37807cfe47ce98", "raw": {"market": "0xc0e6b917320a47228fb96e3b5ae0e5c93773a5ae2662ae4e1f37807cfe47ce98", "asset_id": "58656358377246279051017109359677190749228949103591068167284263961542487110215", "price": "0.006", "size": "0", "side": "BUY", "timestamp": "1768475245292", "received_at": "2026-01-15T12:07:25.440041"}}
{"event_type": "price_change", "event_ts": "2026-01-15T12:07:25.440041", "ingestion_ts": "2026-01-15T12:08:42.168746", "market_id": "0xc0e6b917320a47228fb96e3b5ae0e5c93773a5ae2662ae4e1f37807cfe47ce98", "raw": {"market": "0xc0e6b917320a47228fb96e3b5ae0e5c93773a5ae2662ae4e1f37807cfe47ce98", "asset_id": "81647294538046680798858716589766492074338758116170717123345952330712416337530", "price": "0.994", "size": "0", "side": "SELL", "timestamp": "1768475245292", "received_at": "2026-01-15T12:07:25.440041"}}
{"event_type": "price_change", "event_ts": "2026-01-15T12:07:25.440082", "ingestion_ts": "2026-01-15T12:08:42.168746", "market_id": "0xc0e6b917320a47228fb96e3b5ae0e5c93773a5ae2662ae4e1f37807cfe47ce98", "raw": {"market": "0xc0e6b917320a47228fb96e3b5ae0e5c93773a5ae2662ae4e1f37807cfe47ce98", "asset_id": "58656358377246279051017109359677190749228949103591068167284263961542487110215", "price": "0.008", "size": "0", "side": "BUY", "timestamp": "1768475245292", "received_at": "2026-01-15T12:07:25.440082"}}
{"event_type": "price_change", "event_ts": "2026-01-15T12:07:25.440082", "ingestion_ts": "2026-01-15T12:08:42.168746", "market_id": "0xc0e6b917320a47228fb96e3b5ae0e5c93773a5ae2662ae4e1f37807cfe47ce98", "raw": {"market": "0xc0e6b917320a47228fb96e3b5ae0e5c93773a5ae2662ae4e1f37807cfe47ce98", "asset_id": "81647294538046680798858716589766492074338758116170717123345952330712416337530", "price": "0.992", "size": "0", "side": "SELL", "timestamp": "1768475245292", "received_at": "2026-01-15T12:07:25.440082"}}
{"event_type": "price_change", "event_ts": "2026-01-15T12:07:26.322160", "ingestion_ts": "2026-01-15T12:08:42.168746", "market_id": "0xc0e6b917320a47228fb96e3b5ae0e5c93773a5ae2662ae4e1f37807cfe47ce98", "raw": {"market": "0xc0e6b917320a47228fb96e3b5ae0e5c93773a5ae2662ae4e1f37807cfe47ce98", "asset_id": "58656358377246279051017109359677190749228949103591068167284263961542487110215", "price": "0.003", "size": "441.97", "side": "BUY", "timestamp": "1768475246185", "received_at": "2026-01-15T12:07:26.322160"}}
{"event_type": "price_change", "event_ts": "2026-01-15T12:07:26.322160", "ingestion_ts": "2026-01-15T12:08:42.168746", "market_id": "0xc0e6b917320a47228fb96e3b5ae0e5c93773a5ae2662ae4e1f37807cfe47ce98", "raw": {"market": "0xc0e6b917320a47228fb96e3b5ae0e5c93773a5ae2662ae4e1f37807cfe47ce98", "asset_id": "81647294538046680798858716589766492074338758116170717123345952330712416337530", "price": "0.997", "size": "441.97", "side": "SELL", "timestamp": "1768475246185", "received_at": "2026-01-15T12:07:26.322160"}}
{"event_type": "price_change", "event_ts": "2026-01-15T12:07:26.322274", "ingestion_ts": "2026-01-15T12:08:42.168746", "market_id": "0xc0e6b917320a47228fb96e3b5ae0e5c93773a5ae2662ae4e1f37807cfe47ce98", "raw": {"market": "0xc0e6b917320a47228fb96e3b5ae0e5c93773a5ae2662ae4e1f37807cfe47ce98", "asset_id": "58656358377246279051017109359677190749228949103591068167284263961542487110215", "price": "0.003", "size": "460.2", "side": "BUY", "timestamp": "1768475246186", "received_at": "2026-01-15T12:07:26.322274"}}
{"event_type": "price_change", "event_ts": "2026-01-15T12:07:26.322274", "ingestion_ts": "2026-01-15T12:08:42.168746", "market_id": "0xc0e6b917320a47228fb96e3b5ae0e5c93773a5ae2662ae4e1f37807cfe47ce98", "raw": {"market": "0xc0e6b917320a47228fb96e3b5ae0e5c93773a5ae2662ae4e1f37807cfe47ce98", "asset_id": "81647294538046680798858716589766492074338758116170717123345952330712416337530", "price": "0.997", "size": "460.2", "side": "SELL", "timestamp": "1768475246186", "received_at": "2026-01-15T12:07:26.322274"}}
{"event_type": "price_change", "event_ts": "2026-01-15T12:07:26.697537", "ingestion_ts": "2026-01-15T12:08:42.168746", "market_id": "0xcab7ba4a9133cfd407d7e73e5757e5abbace413b59421527a31113406c97815c", "raw": {"market": "0xcab7ba4a9133cfd407d7e73e5757e5abbace413b59421527a31113406c97815c", "asset_id": "96361925776989336186111887920533578209326565663637092688733016597062311745569", "price": "0.006", "size": "127.41", "side": "BUY", "timestamp": "1768475246496", "received_at": "2026-01-15T12:07:26.697537"}}
{"event_type": "price_change", "event_ts": "2026-01-15T12:07:26.697537", "ingestion_ts": "2026-01-15T12:08:42.168746", "market_id": "0xcab7ba4a9133cfd407d7e73e5757e5abbace413b59421527a31113406c97815c", "raw": {"market": "0xcab7ba4a9133cfd407d7e73e5757e5abbace413b59421527a31113406c97815c", "asset_id": "20002636398944597965698652220992177552927816915094913583821579024925426590022", "price": "0.994", "size": "127.41", "side": "SELL", "timestamp": "1768475246496", "received_at": "2026-01-15T12:07:26.697537"}}
{"event_type": "price_change", "event_ts": "2026-01-15T12:07:26.697575", "ingestion_ts": "2026-01-15T12:08:42.168746", "market_id": "0xcab7ba4a9133cfd407d7e73e5757e5abbace413b59421527a31113406c97815c", "raw": {"market": "0xcab7ba4a9133cfd407d7e73e5757e5abbace413b59421527a31113406c97815c", "asset_id": "96361925776989336186111887920533578209326565663637092688733016597062311745569", "price": "0.009", "size": "812.25", "side": "BUY", "timestamp": "1768475246496", "received_at": "2026-01-15T12:07:26.697575"}}
{"event_type": "price_change", "event_ts": "2026-01-15T12:07:26.697575", "ingestion_ts": "2026-01-15T12:08:42.168746", "market_id": "0xcab7ba4a9133cfd407d7e73e5757e5abbace413b59421527a31113406c97815c", "raw": {"market": "0xcab7ba4a9133cfd407d7e73e5757e5abbace413b59421527a31113406c97815c", "asset_id": "20002636398944597965698652220992177552927816915094913583821579024925426590022", "price": "0.991", "size": "812.25", "side": "SELL", "timestamp": "1768475246496", "received_at": "2026-01-15T12:07:26.697575"}}
{"event_type": "price_change", "event_ts": "2026-01-15T12:07:27.155614", "ingestion_ts": "2026-01-15T12:08:42.168746", "market_id": "0xcab7ba4a9133cfd407d7e73e5757e5abbace413b59421527a31113406c97815c", "raw": {"market": "0xcab7ba4a9133cfd407d7e73e5757e5abbace413b59421527a31113406c97815c", "asset_id": "96361925776989336186111887920533578209326565663637092688733016597062311745569", "price": "0.009", "size": "818.33", "side": "BUY", "timestamp": "1768475247020", "received_at": "2026-01-15T12:07:27.155614"}}
{"event_type": "price_change", "event_ts": "2026-01-15T12:07:27.155614", "ingestion_ts": "2026-01-15T12:08:42.168746", "market_id": "0xcab7ba4a9133cfd407d7e73e5757e5abbace413b59421527a31113406c97815c", "raw": {"market": "0xcab7ba4a9133cfd407d7e73e5757e5abbace413b59421527a31113406c97815c", "asset_id": "20002636398944597965698652220992177552927816915094913583821579024925426590022", "price": "0.991", "size": "818.33", "side": "SELL", "timestamp": "1768475247020", "received_at": "2026-01-15T12:07:27.155614"}}
{"event_type": "price_change", "event_ts": "2026-01-15T12:07:27.155653", "ingestion_ts": "2026-01-15T12:08:42.168746", "market_id": "0xcab7ba4a9133cfd407d7e73e5757e5abbace413b59421527a31113406c97815c", "raw": {"market": "0xcab7ba4a9133cfd407d7e73e5757e5abbace413b59421527a31113406c97815c", "asset_id": "96361925776989336186111887920533578209326565663637092688733016597062311745569", "price": "0.006", "size": "136.51", "side": "BUY", "timestamp": "1768475247021", "received_at": "2026-01-15T12:07:27.155653"}}
{"event_type": "price_change", "event_ts": "2026-01-15T12:07:27.155653", "ingestion_ts": "2026-01-15T12:08:42.168746", "market_id": "0xcab7ba4a9133cfd407d7e73e5757e5abbace413b59421527a31113406c97815c", "raw": {"market": "0xcab7ba4a9133cfd407d7e73e5757e5abbace413b59421527a31113406c97815c", "asset_id": "20002636398944597965698652220992177552927816915094913583821579024925426590022", "price": "0.994", "size": "136.51", "side": "SELL", "timestamp": "1768475247021", "received_at": "2026-01-15T12:07:27.155653"}}
{"event_type": "price_change", "event_ts": "2026-01-15T12:07:27.789356", "ingestion_ts": "2026-01-15T12:08:42.168746", "market_id": "0x427bc4b40c09b3dcbc973747f0e4b079bed91b3e5a0aed5c36edd0f7591485f4", "raw": {"market": "0x427bc4b40c09b3dcbc973747f0e4b079bed91b3e5a0aed5c36edd0f7591485f4", "asset_id": "115669573443672055876643967408433138119481486650803218131873713375232186497057", "price": "0.002", "size": "20.4", "side": "BUY", "timestamp": "1768475247648", "received_at": "2026-01-15T12:07:27.789356"}}
{"event_type": "price_change", "event_ts": "2026-01-15T12:07:27.789356", "ingestion_ts": "2026-01-15T12:08:42.168746", "market_id": "0x427bc4b40c09b3dcbc973747f0e4b079bed91b3e5a0aed5c36edd0f7591485f4", "raw": {"market": "0x427bc4b40c09b3dcbc973747f0e4b079bed91b3e5a0aed5c36edd0f7591485f4", "asset_id": "86130975769502911188457673769190265049139877688522439001984850068234616395137", "price": "0.998", "size": "20.4", "side": "SELL", "timestamp": "1768475247648", "received_at": "2026-01-15T12:07:27.789356"}}
{"event_type": "price_change", "event_ts": "2026-01-15T12:07:28.108696", "ingestion_ts": "2026-01-15T12:08:42.168746", "market_id": "0x427bc4b40c09b3dcbc973747f0e4b079bed91b3e5a0aed5c36edd0f7591485f4", "raw": {"market": "0x427bc4b40c09b3dcbc973747f0e4b079bed91b3e5a0aed5c36edd0f7591485f4", "asset_id": "115669573443672055876643967408433138119481486650803218131873713375232186497057", "price": "0.002", "size": "60.98", "side": "BUY", "timestamp": "1768475247990", "received_at": "2026-01-15T12:07:28.108696"}}
{"event_type": "price_change", "event_ts": "2026-01-15T12:07:28.108696", "ingestion_ts": "2026-01-15T12:08:42.168746", "market_id": "0x427bc4b40c09b3dcbc973747f0e4b079bed91b3e5a0aed5c36edd0f7591485f4", "raw": {"market": "0x427bc4b40c09b3dcbc973747f0e4b079bed91b3e5a0aed5c36edd0f7591485f4", "asset_id": "86130975769502911188457673769190265049139877688522439001984850068234616395137", "price": "0.998", "size": "60.98", "side": "SELL", "timestamp": "1768475247990", "received_at": "2026-01-15T12:07:28.108696"}}
{"event_type": "price_change", "event_ts": "2026-01-15T12:07:29.712966", "ingestion_ts": "2026-01-15T12:08:42.168746", "market_id": "0xcab7ba4a9133cfd407d7e73e5757e5abbace413b59421527a31113406c97815c", "raw": {"market": "0xcab7ba4a9133cfd407d7e73e5757e5abbace413b59421527a31113406c97815c", "asset_id": "96361925776989336186111887920533578209326565663637092688733016597062311745569", "price": "0.006", "size": "127.41", "side": "BUY", "timestamp": "1768475249586", "received_at": "2026-01-15T12:07:29.712966"}}
{"event_type": "price_change", "event_ts": "2026-01-15T12:07:29.712966", "ingestion_ts": "2026-01-15T12:08:42.168746", "market_id": "0xcab7ba4a9133cfd407d7e73e5757e5abbace413b59421527a31113406c97815c", "raw": {"market": "0xcab7ba4a9133cfd407d7e73e5757e5abbace413b59421527a31113406c97815c", "asset_id": "20002636398944597965698652220992177552927816915094913583821579024925426590022", "price": "0.994", "size": "127.41", "side": "SELL", "timestamp": "1768475249586", "received_at": "2026-01-15T12:07:29.712966"}}
{"event_type": "price_change", "event_ts": "2026-01-15T12:07:29.713036", "ingestion_ts": "2026-01-15T12:08:42.168746", "market_id": "0xcab7ba4a9133cfd407d7e73e5757e5abbace413b59421527a31113406c97815c", "raw": {"market": "0xcab7ba4a9133cfd407d7e73e5757e5abbace413b59421527a31113406c97815c", "asset_id": "96361925776989336186111887920533578209326565663637092688733016597062311745569", "price": "0.009", "size": "812.25", "side": "BUY", "timestamp": "1768475249586", "received_at": "2026-01-15T12:07:29.713036"}}
{"event_type": "price_change", "event_ts": "2026-01-15T12:07:29.713036", "ingestion_ts": "2026-01-15T12:08:42.168746", "market_id": "0xcab7ba4a9133cfd407d7e73e5757e5abbace413b59421527a31113406c97815c", "raw": {"market": "0xcab7ba4a9133cfd407d7e73e5757e5abbace413b59421527a31113406c97815c", "asset_id": "20002636398944597965698652220992177552927816915094913583821579024925426590022", "price": "0.991", "size": "812.25", "side": "SELL", "timestamp": "1768475249586", "received_at": "2026-01-15T12:07:29.713036"}}
{"event_type": "price_change", "event_ts": "2026-01-15T12:07:30.312827", "ingestion_ts": "2026-01-15T12:08:42.168746", "market_id": "0xcab7ba4a9133cfd407d7e73e5757e5abbace413b59421527a31113406c97815c", "raw": {"market": "0xcab7ba4a9133cfd407d7e73e5757e5abbace413b59421527a31113406c97815c", "asset_id": "96361925776989336186111887920533578209326565663637092688733016597062311745569", "price": "0.006", "size": "136.51", "side": "BUY", "timestamp": "1768475250187", "received_at": "2026-01-15T12:07:30.312827"}}
{"event_type": "price_change", "event_ts": "2026-01-15T12:07:30.312827", "ingestion_ts": "2026-01-15T12:08:42.168746", "market_id": "0xcab7ba4a9133cfd407d7e73e5757e5abbace413b59421527a31113406c97815c", "raw": {"market": "0xcab7ba4a9133cfd407d7e73e5757e5abbace413b59421527a31113406c97815c", "asset_id": "20002636398944597965698652220992177552927816915094913583821579024925426590022", "price": "0.994", "size": "136.51", "side": "SELL", "timestamp": "1768475250187", "received_at": "2026-01-15T12:07:30.312827"}}
{"event_type": "price_change", "event_ts": "2026-01-15T12:07:30.312878", "ingestion_ts": "2026-01-15T12:08:42.168746", "market_id": "0xcab7ba4a9133cfd407d7e73e5757e5abbace413b59421527a31113406c97815c", "raw": {"market": "0xcab7ba4a9133cfd407d7e73e5757e5abbace413b59421527a31113406c97815c", "asset_id": "96361925776989336186111887920533578209326565663637092688733016597062311745569", "price": "0.009", "size": "818.33", "side": "BUY", "timestamp": "1768475250188", "received_at": "2026-01-15T12:07:30.312878"}}
{"event_type": "price_change", "event_ts": "2026-01-15T12:07:30.312878", "ingestion_ts": "2026-01-15T12:08:42.168746", "market_id": "0xcab7ba4a9133cfd407d7e73e5757e5abbace413b59421527a31113406c97815c", "raw": {"market": "0xcab7ba4a9133cfd407d7e73e5757e5abbace413b59421527a31113406c97815c", "asset_id": "20002636398944597965698652220992177552927816915094913583821579024925426590022", "price": "0.991", "size": "818.33", "side": "SELL", "timestamp": "1768475250188", "received_at": "2026-01-15T12:07:30.312878"}}
{"event_type": "price_change", "event_ts": "2026-01-15T12:07:30.915858", "ingestion_ts": "2026-01-15T12:08:42.168746", "market_id": "0xc0e6b917320a47228fb96e3b5ae0e5c93773a5ae2662ae4e1f37807cfe47ce98", "raw": {"market": "0xc0e6b917320a47228fb96e3b5ae0e5c93773a5ae2662ae4e1f37807cfe47ce98", "asset_id": "58656358377246279051017109359677190749228949103591068167284263961542487110215", "price": "0.003", "size": "422.57", "side": "BUY", "timestamp": "1768475250785", "received_at": "2026-01-15T12:07:30.915858"}}
{"event_type": "price_change", "event_ts": "2026-01-15T12:07:30.915858", "ingestion_ts": "2026-01-15T12:08:42.168746", "market_id": "0xc0e6b917320a47228fb96e3b5ae0e5c93773a5ae2662ae4e1f37807cfe47ce98", "raw": {"market": "0xc0e6b917320a47228fb96e3b5ae0e5c93773a5ae2662ae4e1f37807cfe47ce98", "asset_id": "81647294538046680798858716589766492074338758116170717123345952330712416337530", "price": "0.997", "size": "422.57", "side": "SELL", "timestamp": "1768475250785", "received_at": "2026-01-15T12:07:30.915858"}}
{"event_type": "price_change", "event_ts": "2026-01-15T12:07:31.075793", "ingestion_ts": "2026-01-15T12:08:42.168746", "market_id": "0x427bc4b40c09b3dcbc973747f0e4b079bed91b3e5a0aed5c36edd0f7591485f4", "raw": {"market": "0x427bc4b40c09b3dcbc973747f0e4b079bed91b3e5a0aed5c36edd0f7591485f4", "asset_id": "115669573443672055876643967408433138119481486650803218131873713375232186497057", "price": "0.002", "size": "20.4", "side": "BUY", "timestamp": "1768475250957", "received_at": "2026-01-15T12:07:31.075793"}}
{"event_type": "price_change", "event_ts": "2026-01-15T12:07:31.075793", "ingestion_ts": "2026-01-15T12:08:42.168746", "market_id": "0x427bc4b40c09b3dcbc973747f0e4b079bed91b3e5a0aed5c36edd0f7591485f4", "raw": {"market": "0x427bc4b40c09b3dcbc973747f0e4b079bed91b3e5a0aed5c36edd0f7591485f4", "asset_id": "86130975769502911188457673769190265049139877688522439001984850068234616395137", "price": "0.998", "size": "20.4", "side": "SELL", "timestamp": "1768475250957", "received_at": "2026-01-15T12:07:31.075793"}}
{"event_type": "price_change", "event_ts": "2026-01-15T12:07:31.421371", "ingestion_ts": "2026-01-15T12:08:42.168746", "market_id": "0xc0e6b917320a47228fb96e3b5ae0e5c93773a5ae2662ae4e1f37807cfe47ce98", "raw": {"market": "0xc0e6b917320a47228fb96e3b5ae0e5c93773a5ae2662ae4e1f37807cfe47ce98", "asset_id": "58656358377246279051017109359677190749228949103591068167284263961542487110215", "price": "0.003", "size": "441.39", "side": "BUY", "timestamp": "1768475251205", "received_at": "2026-01-15T12:07:31.421371"}}
{"event_type": "price_change", "event_ts": "2026-01-15T12:07:31.421371", "ingestion_ts": "2026-01-15T12:08:42.168746", "market_id": "0xc0e6b917320a47228fb96e3b5ae0e5c93773a5ae2662ae4e1f37807cfe47ce98", "raw": {"market": "0xc0e6b917320a47228fb96e3b5ae0e5c93773a5ae2662ae4e1f37807cfe47ce98", "asset_id": "81647294538046680798858716589766492074338758116170717123345952330712416337530", "price": "0.997", "size": "441.39", "side": "SELL", "timestamp": "1768475251205", "received_at": "2026-01-15T12:07:31.421371"}}
{"event_type": "price_change", "event_ts": "2026-01-15T12:07:31.421488", "ingestion_ts": "2026-01-15T12:08:42.168746", "market_id": "0xc0e6b917320a47228fb96e3b5ae0e5c93773a5ae2662ae4e1f37807cfe47ce98", "raw": {"market": "0xc0e6b917320a47228fb96e3b5ae0e5c93773a5ae2662ae4e1f37807cfe47ce98", "asset_id": "58656358377246279051017109359677190749228949103591068167284263961542487110215", "price": "0.003", "size": "460.21", "side": "BUY", "timestamp": "1768475251209", "received_at": "2026-01-15T12:07:31.421488"}}
{"event_type": "price_change", "event_ts": "2026-01-15T12:07:31.421488", "ingestion_ts": "2026-01-15T12:08:42.168746", "market_id": "0xc0e6b917320a47228fb96e3b5ae0e5c93773a5ae2662ae4e1f37807cfe47ce98", "raw": {"market": "0xc0e6b917320a47228fb96e3b5ae0e5c93773a5ae2662ae4e1f37807cfe47ce98", "asset_id": "81647294538046680798858716589766492074338758116170717123345952330712416337530", "price": "0.997", "size": "460.21", "side": "SELL", "timestamp": "1768475251209", "received_at": "2026-01-15T12:07:31.421488"}}
{"event_type": "price_change", "event_ts": "2026-01-15T12:07:31.444330", "ingestion_ts": "2026-01-15T12:08:42.168746", "market_id": "0xcab7ba4a9133cfd407d7e73e5757e5abbace413b59421527a31113406c97815c", "raw": {"market": "0xcab7ba4a9133cfd407d7e73e5757e5abbace413b59421527a31113406c97815c", "asset_id": "96361925776989336186111887920533578209326565663637092688733016597062311745569", "price": "0.006", "size": "127.41", "side": "BUY", "timestamp": "1768475251228", "received_at": "2026-01-15T12:07:31.444330"}}
{"event_type": "price_change", "event_ts": "2026-01-15T12:07:31.444330", "ingestion_ts": "2026-01-15T12:08:42.168746", "market_id": "0xcab7ba4a9133cfd407d7e73e5757e5abbace413b59421527a31113406c97815c", "raw": {"market": "0xcab7ba4a9133cfd407d7e73e5757e5abbace413b59421527a31113406c97815c", "asset_id": "20002636398944597965698652220992177552927816915094913583821579024925426590022", "price": "0.994", "size": "127.41", "side": "SELL", "timestamp": "1768475251228", "received_at": "2026-01-15T12:07:31.444330"}}
{"event_type": "price_change", "event_ts": "2026-01-15T12:07:31.444420", "ingestion_ts": "2026-01-15T12:08:42.168746", "market_id": "0xcab7ba4a9133cfd407d7e73e5757e5abbace413b59421527a31113406c97815c", "raw": {"market": "0xcab7ba4a9133cfd407d7e73e5757e5abbace413b59421527a31113406c97815c", "asset_id": "96361925776989336186111887920533578209326565663637092688733016597062311745569", "price": "0.009", "size": "812.25", "side": "BUY", "timestamp": "1768475251228", "received_at": "2026-01-15T12:07:31.444420"}}
{"event_type": "price_change", "event_ts": "2026-01-15T12:07:31.444420", "ingestion_ts": "2026-01-15T12:08:42.168746", "market_id": "0xcab7ba4a9133cfd407d7e73e5757e5abbace413b59421527a31113406c97815c", "raw": {"market": "0xcab7ba4a9133cfd407d7e73e5757e5abbace413b59421527a31113406c97815c", "asset_id": "20002636398944597965698652220992177552927816915094913583821579024925426590022", "price": "0.991", "size": "812.25", "side": "SELL", "timestamp": "1768475251228", "received_at": "2026-01-15T12:07:31.444420"}}
{"event_type": "price_change", "event_ts": "2026-01-15T12:07:32.112419", "ingestion_ts": "2026-01-15T12:08:42.168746", "market_id": "0xcab7ba4a9133cfd407d7e73e5757e5abbace413b59421527a31113406c97815c", "raw": {"market": "0xcab7ba4a9133cfd407d7e73e5757e5abbace413b59421527a31113406c97815c", "asset_id": "96361925776989336186111887920533578209326565663637092688733016597062311745569", "price": "0.009", "size": "818.33", "side": "BUY", "timestamp": "1768475251988", "received_at": "2026-01-15T12:07:32.112419"}}
{"event_type": "price_change", "event_ts": "2026-01-15T12:07:32.112419", "ingestion_ts": "2026-01-15T12:08:42.168746", "market_id": "0xcab7ba4a9133cfd407d7e73e5757e5abbace413b59421527a31113406c97815c", "raw": {"market": "0xcab7ba4a9133cfd407d7e73e5757e5abbace413b59421527a31113406c97815c", "asset_id": "20002636398944597965698652220992177552927816915094913583821579024925426590022", "price": "0.991", "size": "818.33", "side": "SELL", "timestamp": "1768475251988", "received_at": "2026-01-15T12:07:32.112419"}}
{"event_type": "price_change", "event_ts": "2026-01-15T12:07:32.112788", "ingestion_ts": "2026-01-15T12:08:42.168746", "market_id": "0xcab7ba4a9133cfd407d7e73e5757e5abbace413b59421527a31113406c97815c", "raw": {"market": "0xcab7ba4a9133cfd407d7e73e5757e5abbace413b59421527a31113406c97815c", "asset_id": "96361925776989336186111887920533578209326565663637092688733016597062311745569", "price": "0.006", "size": "136.51", "side": "BUY", "timestamp": "1768475251989", "received_at": "2026-01-15T12:07:32.112788"}}
{"event_type": "price_change", "event_ts": "2026-01-15T12:07:32.112788", "ingestion_ts": "2026-01-15T12:08:42.168746", "market_id": "0xcab7ba4a9133cfd407d7e73e5757e5abbace413b59421527a31113406c97815c", "raw": {"market": "0xcab7ba4a9133cfd407d7e73e5757e5abbace413b59421527a31113406c97815c", "asset_id": "20002636398944597965698652220992177552927816915094913583821579024925426590022", "price": "0.994", "size": "136.51", "side": "SELL", "timestamp": "1768475251989", "received_at": "2026-01-15T12:07:32.112788"}}
{"event_type": "price_change", "event_ts": "2026-01-15T12:07:32.222066", "ingestion_ts": "2026-01-15T12:08:42.168746", "market_id": "0x427bc4b40c09b3dcbc973747f0e4b079bed91b3e5a0aed5c36edd0f7591485f4", "raw": {"market": "0x427bc4b40c09b3dcbc973747f0e4b079bed91b3e5a0aed5c36edd0f7591485f4", "asset_id": "115669573443672055876643967408433138119481486650803218131873713375232186497057", "price": "0.002", "size": "60.98", "side": "BUY", "timestamp": "1768475252098", "received_at": "2026-01-15T12:07:32.222066"}}
{"event_type": "price_change", "event_ts": "2026-01-15T12:07:32.222066", "ingestion_ts": "2026-01-15T12:08:42.168746", "market_id": "0x427bc4b40c09b3dcbc973747f0e4b079bed91b3e5a0aed5c36edd0f7591485f4", "raw": {"market": "0x427bc4b40c09b3dcbc973747f0e4b079bed91b3e5a0aed5c36edd0f7591485f4", "asset_id": "86130975769502911188457673769190265049139877688522439001984850068234616395137", "price": "0.998", "size": "60.98", "side": "SELL", "timestamp": "1768475252098", "received_at": "2026-01-15T12:07:32.222066"}}
{"event_type": "price_change", "event_ts": "2026-01-15T12:07:33.807608", "ingestion_ts": "2026-01-15T12:08:42.168746", "market_id": "0xcab7ba4a9133cfd407d7e73e5757e5abbace413b59421527a31113406c97815c", "raw": {"market": "0xcab7ba4a9133cfd407d7e73e5757e5abbace413b59421527a31113406c97815c", "asset_id": "96361925776989336186111887920533578209326565663637092688733016597062311745569", "price": "0.006", "size": "127.41", "side": "BUY", "timestamp": "1768475253661", "received_at": "2026-01-15T12:07:33.807608"}}
{"event_type": "price_change", "event_ts": "2026-01-15T12:07:33.807608", "ingestion_ts": "2026-01-15T12:08:42.168746", "market_id": "0xcab7ba4a9133cfd407d7e73e5757e5abbace413b59421527a31113406c97815c", "raw": {"market": "0xcab7ba4a9133cfd407d7e73e5757e5abbace413b59421527a31113406c97815c", "asset_id": "20002636398944597965698652220992177552927816915094913583821579024925426590022", "price": "0.994", "size": "127.41", "side": "SELL", "timestamp": "1768475253661", "received_at": "2026-01-15T12:07:33.807608"}}
{"event_type": "price_change", "event_ts": "2026-01-15T12:07:33.807696", "ingestion_ts": "2026-01-15T12:08:42.168746", "market_id": "0xcab7ba4a9133cfd407d7e73e5757e5abbace413b59421527a31113406c97815c", "raw": {"market": "0xcab7ba4a9133cfd407d7e73e5757e5abbace413b59421527a31113406c97815c", "asset_id": "96361925776989336186111887920533578209326565663637092688733016597062311745569", "price": "0.009", "size": "812.25", "side": "BUY", "timestamp": "1768475253661", "received_at": "2026-01-15T12:07:33.807696"}}
{"event_type": "price_change", "event_ts": "2026-01-15T12:07:33.807696", "ingestion_ts": "2026-01-15T12:08:42.168746", "market_id": "0xcab7ba4a9133cfd407d7e73e5757e5abbace413b59421527a31113406c97815c", "raw": {"market": "0xcab7ba4a9133cfd407d7e73e5757e5abbace413b59421527a31113406c97815c", "asset_id": "20002636398944597965698652220992177552927816915094913583821579024925426590022", "price": "0.991", "size": "812.25", "side": "SELL", "timestamp": "1768475253661", "received_at": "2026-01-15T12:07:33.807696"}}
{"event_type": "price_change", "event_ts": "2026-01-15T12:07:34.541181", "ingestion_ts": "2026-01-15T12:08:42.168746", "market_id": "0xcab7ba4a9133cfd407d7e73e5757e5abbace413b59421527a31113406c97815c", "raw": {"market": "0xcab7ba4a9133cfd407d7e73e5757e5abbace413b59421527a31113406c97815c", "asset_id": "96361925776989336186111887920533578209326565663637092688733016597062311745569", "price": "0.006", "size": "136.51", "side": "BUY", "timestamp": "1768475254419", "received_at": "2026-01-15T12:07:34.541181"}}
{"event_type": "price_change", "event_ts": "2026-01-15T12:07:34.541181", "ingestion_ts": "2026-01-15T12:08:42.168746", "market_id": "0xcab7ba4a9133cfd407d7e73e5757e5abbace413b59421527a31113406c97815c", "raw": {"market": "0xcab7ba4a9133cfd407d7e73e5757e5abbace413b59421527a31113406c97815c", "asset_id": "20002636398944597965698652220992177552927816915094913583821579024925426590022", "price": "0.994", "size": "136.51", "side": "SELL", "timestamp": "1768475254419", "received_at": "2026-01-15T12:07:34.541181"}}
{"event_type": "price_change", "event_ts": "2026-01-15T12:07:34.542480", "ingestion_ts": "2026-01-15T12:08:42.168746", "market_id": "0xcab7ba4a9133cfd407d7e73e5757e5abbace413b59421527a31113406c97815c", "raw": {"market": "0xcab7ba4a9133cfd407d7e73e5757e5abbace413b59421527a31113406c97815c", "asset_id": "96361925776989336186111887920533578209326565663637092688733016597062311745569", "price": "0.009", "size": "818.33", "side": "BUY", "timestamp": "1768475254420", "received_at": "2026-01-15T12:07:34.542480"}}
{"event_type": "price_change", "event_ts": "2026-01-15T12:07:34.542480", "ingestion_ts": "2026-01-15T12:08:42.168746", "market_id": "0xcab7ba4a9133cfd407d7e73e5757e5abbace413b59421527a31113406c97815c", "raw": {"market": "0xcab7ba4a9133cfd407d7e73e5757e5abbace413b59421527a31113406c97815c", "asset_id": "20002636398944597965698652220992177552927816915094913583821579024925426590022", "price": "0.991", "size": "818.33", "side": "SELL", "timestamp": "1768475254420", "received_at": "2026-01-15T12:07:34.542480"}}
{"event_type": "price_change", "event_ts": "2026-01-15T12:07:34.785813", "ingestion_ts": "2026-01-15T12:08:42.168746", "market_id": "0xc0e6b917320a47228fb96e3b5ae0e5c93773a5ae2662ae4e1f37807cfe47ce98", "raw": {"market": "0xc0e6b917320a47228fb96e3b5ae0e5c93773a5ae2662ae4e1f37807cfe47ce98", "asset_id": "58656358377246279051017109359677190749228949103591068167284263961542487110215", "price": "0.003", "size": "422.94", "side": "BUY", "timestamp": "1768475254668", "received_at": "2026-01-15T12:07:34.785813"}}
{"event_type": "price_change", "event_ts": "2026-01-15T12:07:34.785813", "ingestion_ts": "2026-01-15T12:08:42.168746", "market_id": "0xc0e6b917320a47228fb96e3b5ae0e5c93773a5ae2662ae4e1f37807cfe47ce98", "raw": {"market": "0xc0e6b917320a47228fb96e3b5ae0e5c93773a5ae2662ae4e1f37807cfe47ce98", "asset_id": "81647294538046680798858716589766492074338758116170717123345952330712416337530", "price": "0.997", "size": "422.94", "side": "SELL", "timestamp": "1768475254668", "received_at": "2026-01-15T12:07:34.785813"}}
{"event_type": "price_change", "event_ts": "2026-01-15T12:07:35.241533", "ingestion_ts": "2026-01-15T12:08:42.168746", "market_id": "0xc0e6b917320a47228fb96e3b5ae0e5c93773a5ae2662ae4e1f37807cfe47ce98", "raw": {"market": "0xc0e6b917320a47228fb96e3b5ae0e5c93773a5ae2662ae4e1f37807cfe47ce98", "asset_id": "58656358377246279051017109359677190749228949103591068167284263961542487110215", "price": "0.003", "size": "441.57", "side": "BUY", "timestamp": "1768475255117", "received_at": "2026-01-15T12:07:35.241533"}}
{"event_type": "price_change", "event_ts": "2026-01-15T12:07:35.241533", "ingestion_ts": "2026-01-15T12:08:42.168746", "market_id": "0xc0e6b917320a47228fb96e3b5ae0e5c93773a5ae2662ae4e1f37807cfe47ce98", "raw": {"market": "0xc0e6b917320a47228fb96e3b5ae0e5c93773a5ae2662ae4e1f37807cfe47ce98", "asset_id": "81647294538046680798858716589766492074338758116170717123345952330712416337530", "price": "0.997", "size": "441.57", "side": "SELL", "timestamp": "1768475255117", "received_at": "2026-01-15T12:07:35.241533"}}
{"event_type": "price_change", "event_ts": "2026-01-15T12:07:35.241572", "ingestion_ts": "2026-01-15T12:08:42.168746", "market_id": "0xc0e6b917320a47228fb96e3b5ae0e5c93773a5ae2662ae4e1f37807cfe47ce98", "raw": {"market": "0xc0e6b917320a47228fb96e3b5ae0e5c93773a5ae2662ae4e1f37807cfe47ce98", "asset_id": "58656358377246279051017109359677190749228949103591068167284263961542487110215", "price": "0.003", "size": "460.2", "side": "BUY", "timestamp": "1768475255118", "received_at": "2026-01-15T12:07:35.241572"}}
{"event_type": "price_change", "event_ts": "2026-01-15T12:07:35.241572", "ingestion_ts": "2026-01-15T12:08:42.168746", "market_id": "0xc0e6b917320a47228fb96e3b5ae0e5c93773a5ae2662ae4e1f37807cfe47ce98", "raw": {"market": "0xc0e6b917320a47228fb96e3b5ae0e5c93773a5ae2662ae4e1f37807cfe47ce98", "asset_id": "81647294538046680798858716589766492074338758116170717123345952330712416337530", "price": "0.997", "size": "460.2", "side": "SELL", "timestamp": "1768475255118", "received_at": "2026-01-15T12:07:35.241572"}}
{"event_type": "price_change", "event_ts": "2026-01-15T12:07:35.714832", "ingestion_ts": "2026-01-15T12:08:42.168746", "market_id": "0xcab7ba4a9133cfd407d7e73e5757e5abbace413b59421527a31113406c97815c", "raw": {"market": "0xcab7ba4a9133cfd407d7e73e5757e5abbace413b59421527a31113406c97815c", "asset_id": "96361925776989336186111887920533578209326565663637092688733016597062311745569", "price": "0.006", "size": "127.41", "side": "BUY", "timestamp": "1768475255592", "received_at": "2026-01-15T12:07:35.714832"}}
{"event_type": "price_change", "event_ts": "2026-01-15T12:07:35.714832", "ingestion_ts": "2026-01-15T12:08:42.168746", "market_id": "0xcab7ba4a9133cfd407d7e73e5757e5abbace413b59421527a31113406c97815c", "raw": {"market": "0xcab7ba4a9133cfd407d7e73e5757e5abbace413b59421527a31113406c97815c", "asset_id": "20002636398944597965698652220992177552927816915094913583821579024925426590022", "price": "0.994", "size": "127.41", "side": "SELL", "timestamp": "1768475255592", "received_at": "2026-01-15T12:07:35.714832"}}
{"event_type": "price_change", "event_ts": "2026-01-15T12:07:35.714874", "ingestion_ts": "2026-01-15T12:08:42.168746", "market_id": "0xcab7ba4a9133cfd407d7e73e5757e5abbace413b59421527a31113406c97815c", "raw": {"market": "0xcab7ba4a9133cfd407d7e73e5757e5abbace413b59421527a31113406c97815c", "asset_id": "96361925776989336186111887920533578209326565663637092688733016597062311745569", "price": "0.009", "size": "812.25", "side": "BUY", "timestamp": "1768475255592", "received_at": "2026-01-15T12:07:35.714874"}}
{"event_type": "price_change", "event_ts": "2026-01-15T12:07:35.714874", "ingestion_ts": "2026-01-15T12:08:42.168746", "market_id": "0xcab7ba4a9133cfd407d7e73e5757e5abbace413b59421527a31113406c97815c", "raw": {"market": "0xcab7ba4a9133cfd407d7e73e5757e5abbace413b59421527a31113406c97815c", "asset_id": "20002636398944597965698652220992177552927816915094913583821579024925426590022", "price": "0.991", "size": "812.25", "side": "SELL", "timestamp": "1768475255592", "received_at": "2026-01-15T12:07:35.714874"}}
{"event_type": "price_change", "event_ts": "2026-01-15T12:07:36.323141", "ingestion_ts": "2026-01-15T12:08:42.168746", "market_id": "0xcab7ba4a9133cfd407d7e73e5757e5abbace413b59421527a31113406c97815c", "raw": {"market": "0xcab7ba4a9133cfd407d7e73e5757e5abbace413b59421527a31113406c97815c", "asset_id": "96361925776989336186111887920533578209326565663637092688733016597062311745569", "price": "0.006", "size": "136.51", "side": "BUY", "timestamp": "1768475256144", "received_at": "2026-01-15T12:07:36.323141"}}
{"event_type": "price_change", "event_ts": "2026-01-15T12:07:36.323141", "ingestion_ts": "2026-01-15T12:08:42.168746", "market_id": "0xcab7ba4a9133cfd407d7e73e5757e5abbace413b59421527a31113406c97815c", "raw": {"market": "0xcab7ba4a9133cfd407d7e73e5757e5abbace413b59421527a31113406c97815c", "asset_id": "20002636398944597965698652220992177552927816915094913583821579024925426590022", "price": "0.994", "size": "136.51", "side": "SELL", "timestamp": "1768475256144", "received_at": "2026-01-15T12:07:36.323141"}}
{"event_type": "price_change", "event_ts": "2026-01-15T12:07:36.323227", "ingestion_ts": "2026-01-15T12:08:42.168746", "market_id": "0xcab7ba4a9133cfd407d7e73e5757e5abbace413b59421527a31113406c97815c", "raw": {"market": "0xcab7ba4a9133cfd407d7e73e5757e5abbace413b59421527a31113406c97815c", "asset_id": "96361925776989336186111887920533578209326565663637092688733016597062311745569", "price": "0.009", "size": "818.33", "side": "BUY", "timestamp": "1768475256145", "received_at": "2026-01-15T12:07:36.323227"}}
{"event_type": "price_change", "event_ts": "2026-01-15T12:07:36.323227", "ingestion_ts": "2026-01-15T12:08:42.168746", "market_id": "0xcab7ba4a9133cfd407d7e73e5757e5abbace413b59421527a31113406c97815c", "raw": {"market": "0xcab7ba4a9133cfd407d7e73e5757e5abbace413b59421527a31113406c97815c", "asset_id": "20002636398944597965698652220992177552927816915094913583821579024925426590022", "price": "0.991", "size": "818.33", "side": "SELL", "timestamp": "1768475256145", "received_at": "2026-01-15T12:07:36.323227"}}
{"event_type": "price_change", "event_ts": "2026-01-15T12:07:36.705126", "ingestion_ts": "2026-01-15T12:08:42.168746", "market_id": "0x427bc4b40c09b3dcbc973747f0e4b079bed91b3e5a0aed5c36edd0f7591485f4", "raw": {"market": "0x427bc4b40c09b3dcbc973747f0e4b079bed91b3e5a0aed5c36edd0f7591485f4", "asset_id": "115669573443672055876643967408433138119481486650803218131873713375232186497057", "price": "0.002", "size": "20.4", "side": "BUY", "timestamp": "1768475256587", "received_at": "2026-01-15T12:07:36.705126"}}
{"event_type": "price_change", "event_ts": "2026-01-15T12:07:36.705126", "ingestion_ts": "2026-01-15T12:08:42.168746", "market_id": "0x427bc4b40c09b3dcbc973747f0e4b079bed91b3e5a0aed5c36edd0f7591485f4", "raw": {"market": "0x427bc4b40c09b3dcbc973747f0e4b079bed91b3e5a0aed5c36edd0f7591485f4", "asset_id": "86130975769502911188457673769190265049139877688522439001984850068234616395137", "price": "0.998", "size": "20.4", "side": "SELL", "timestamp": "1768475256587", "received_at": "2026-01-15T12:07:36.705126"}}
{"event_type": "price_change", "event_ts": "2026-01-15T12:07:37.046862", "ingestion_ts": "2026-01-15T12:08:42.168746", "market_id": "0x427bc4b40c09b3dcbc973747f0e4b079bed91b3e5a0aed5c36edd0f7591485f4", "raw": {"market": "0x427bc4b40c09b3dcbc973747f0e4b079bed91b3e5a0aed5c36edd0f7591485f4", "asset_id": "115669573443672055876643967408433138119481486650803218131873713375232186497057", "price": "0.003", "size": "31.08", "side": "BUY", "timestamp": "1768475256907", "received_at": "2026-01-15T12:07:37.046862"}}
{"event_type": "price_change", "event_ts": "2026-01-15T12:07:37.046862", "ingestion_ts": "2026-01-15T12:08:42.168746", "market_id": "0x427bc4b40c09b3dcbc973747f0e4b079bed91b3e5a0aed5c36edd0f7591485f4", "raw": {"market": "0x427bc4b40c09b3dcbc973747f0e4b079bed91b3e5a0aed5c36edd0f7591485f4", "asset_id": "86130975769502911188457673769190265049139877688522439001984850068234616395137", "price": "0.997", "size": "31.08", "side": "SELL", "timestamp": "1768475256907", "received_at": "2026-01-15T12:07:37.046862"}}
{"event_type": "price_change", "event_ts": "2026-01-15T12:07:38.015582", "ingestion_ts": "2026-01-15T12:08:42.168746", "market_id": "0xcab7ba4a9133cfd407d7e73e5757e5abbace413b59421527a31113406c97815c", "raw": {"market": "0xcab7ba4a9133cfd407d7e73e5757e5abbace413b59421527a31113406c97815c", "asset_id": "96361925776989336186111887920533578209326565663637092688733016597062311745569", "price": "0.006", "size": "127.41", "side": "BUY", "timestamp": "1768475257894", "received_at": "2026-01-15T12:07:38.015582"}}
{"event_type": "price_change", "event_ts": "2026-01-15T12:07:38.015582", "ingestion_ts": "2026-01-15T12:08:42.168746", "market_id": "0xcab7ba4a9133cfd407d7e73e5757e5abbace413b59421527a31113406c97815c", "raw": {"market": "0xcab7ba4a9133cfd407d7e73e5757e5abbace413b59421527a31113406c97815c", "asset_id": "20002636398944597965698652220992177552927816915094913583821579024925426590022", "price": "0.994", "size": "127.41", "side": "SELL", "timestamp": "1768475257894", "received_at": "2026-01-15T12:07:38.015582"}}
{"event_type": "price_change", "event_ts": "2026-01-15T12:07:38.015621", "ingestion_ts": "2026-01-15T12:08:42.168746", "market_id": "0xcab7ba4a9133cfd407d7e73e5757e5abbace413b59421527a31113406c97815c", "raw": {"market": "0xcab7ba4a9133cfd407d7e73e5757e5abbace413b59421527a31113406c97815c", "asset_id": "96361925776989336186111887920533578209326565663637092688733016597062311745569", "price": "0.009", "size": "812.25", "side": "BUY", "timestamp": "1768475257894", "received_at": "2026-01-15T12:07:38.015621"}}
{"event_type": "price_change", "event_ts": "2026-01-15T12:07:38.015621", "ingestion_ts": "2026-01-15T12:08:42.168746", "market_id": "0xcab7ba4a9133cfd407d7e73e5757e5abbace413b59421527a31113406c97815c", "raw": {"market": "0xcab7ba4a9133cfd407d7e73e5757e5abbace413b59421527a31113406c97815c", "asset_id": "20002636398944597965698652220992177552927816915094913583821579024925426590022", "price": "0.991", "size": "812.25", "side": "SELL", "timestamp": "1768475257894", "received_at": "2026-01-15T12:07:38.015621"}}
{"event_type": "price_change", "event_ts": "2026-01-15T12:07:38.434030", "ingestion_ts": "2026-01-15T12:08:42.168746", "market_id": "0xc0e6b917320a47228fb96e3b5ae0e5c93773a5ae2662ae4e1f37807cfe47ce98", "raw": {"market": "0xc0e6b917320a47228fb96e3b5ae0e5c93773a5ae2662ae4e1f37807cfe47ce98", "asset_id": "58656358377246279051017109359677190749228949103591068167284263961542487110215", "price": "0.003", "size": "429.83", "side": "BUY", "timestamp": "1768475258312", "received_at": "2026-01-15T12:07:38.434030"}}
{"event_type": "price_change", "event_ts": "2026-01-15T12:07:38.434030", "ingestion_ts": "2026-01-15T12:08:42.168746", "market_id": "0xc0e6b917320a47228fb96e3b5ae0e5c93773a5ae2662ae4e1f37807cfe47ce98", "raw": {"market": "0xc0e6b917320a47228fb96e3b5ae0e5c93773a5ae2662ae4e1f37807cfe47ce98", "asset_id": "81647294538046680798858716589766492074338758116170717123345952330712416337530", "price": "0.997", "size": "429.83", "side": "SELL", "timestamp": "1768475258312", "received_at": "2026-01-15T12:07:38.434030"}}
{"event_type": "price_change", "event_ts": "2026-01-15T12:07:38.496507", "ingestion_ts": "2026-01-15T12:08:42.168746", "market_id": "0xcab7ba4a9133cfd407d7e73e5757e5abbace413b59421527a31113406c97815c", "raw": {"market": "0xcab7ba4a9133cfd407d7e73e5757e5abbace413b59421527a31113406c97815c", "asset_id": "96361925776989336186111887920533578209326565663637092688733016597062311745569", "price": "0.009", "size": "818.33", "side": "BUY", "timestamp": "1768475258370", "received_at": "2026-01-15T12:07:38.496507"}}
{"event_type": "price_change", "event_ts": "2026-01-15T12:07:38.496507", "ingestion_ts": "2026-01-15T12:08:42.168746", "market_id": "0xcab7ba4a9133cfd407d7e73e5757e5abbace413b59421527a31113406c97815c", "raw": {"market": "0xcab7ba4a9133cfd407d7e73e5757e5abbace413b59421527a31113406c97815c", "asset_id": "20002636398944597965698652220992177552927816915094913583821579024925426590022", "price": "0.991", "size": "818.33", "side": "SELL", "timestamp": "1768475258370", "received_at": "2026-01-15T12:07:38.496507"}}
{"event_type": "price_change", "event_ts": "2026-01-15T12:07:38.496591", "ingestion_ts": "2026-01-15T12:08:42.168746", "market_id": "0xcab7ba4a9133cfd407d7e73e5757e5abbace413b59421527a31113406c97815c", "raw": {"market": "0xcab7ba4a9133cfd407d7e73e5757e5abbace413b59421527a31113406c97815c", "asset_id": "96361925776989336186111887920533578209326565663637092688733016597062311745569", "price": "0.006", "size": "136.51", "side": "BUY", "timestamp": "1768475258371", "received_at": "2026-01-15T12:07:38.496591"}}
{"event_type": "price_change", "event_ts": "2026-01-15T12:07:38.496591", "ingestion_ts": "2026-01-15T12:08:42.168746", "market_id": "0xcab7ba4a9133cfd407d7e73e5757e5abbace413b59421527a31113406c97815c", "raw": {"market": "0xcab7ba4a9133cfd407d7e73e5757e5abbace413b59421527a31113406c97815c", "asset_id": "20002636398944597965698652220992177552927816915094913583821579024925426590022", "price": "0.994", "size": "136.51", "side": "SELL", "timestamp": "1768475258371", "received_at": "2026-01-15T12:07:38.496591"}}
{"event_type": "price_change", "event_ts": "2026-01-15T12:07:39.010961", "ingestion_ts": "2026-01-15T12:08:42.168746", "market_id": "0xc0e6b917320a47228fb96e3b5ae0e5c93773a5ae2662ae4e1f37807cfe47ce98", "raw": {"market": "0xc0e6b917320a47228fb96e3b5ae0e5c93773a5ae2662ae4e1f37807cfe47ce98", "asset_id": "58656358377246279051017109359677190749228949103591068167284263961542487110215", "price": "0.003", "size": "445.02", "side": "BUY", "timestamp": "1768475258844", "received_at": "2026-01-15T12:07:39.010961"}}
{"event_type": "price_change", "event_ts": "2026-01-15T12:07:39.010961", "ingestion_ts": "2026-01-15T12:08:42.168746", "market_id": "0xc0e6b917320a47228fb96e3b5ae0e5c93773a5ae2662ae4e1f37807cfe47ce98", "raw": {"market": "0xc0e6b917320a47228fb96e3b5ae0e5c93773a5ae2662ae4e1f37807cfe47ce98", "asset_id": "81647294538046680798858716589766492074338758116170717123345952330712416337530", "price": "0.997", "size": "445.02", "side": "SELL", "timestamp": "1768475258844", "received_at": "2026-01-15T12:07:39.010961"}}
{"event_type": "price_change", "event_ts": "2026-01-15T12:07:39.017350", "ingestion_ts": "2026-01-15T12:08:42.168746", "market_id": "0xc0e6b917320a47228fb96e3b5ae0e5c93773a5ae2662ae4e1f37807cfe47ce98", "raw": {"market": "0xc0e6b917320a47228fb96e3b5ae0e5c93773a5ae2662ae4e1f37807cfe47ce98", "asset_id": "58656358377246279051017109359677190749228949103591068167284263961542487110215", "price": "0.003", "size": "460.21", "side": "BUY", "timestamp": "1768475258850", "received_at": "2026-01-15T12:07:39.017350"}}
{"event_type": "price_change", "event_ts": "2026-01-15T12:07:39.017350", "ingestion_ts": "2026-01-15T12:08:42.168746", "market_id": "0xc0e6b917320a47228fb96e3b5ae0e5c93773a5ae2662ae4e1f37807cfe47ce98", "raw": {"market": "0xc0e6b917320a47228fb96e3b5ae0e5c93773a5ae2662ae4e1f37807cfe47ce98", "asset_id": "81647294538046680798858716589766492074338758116170717123345952330712416337530", "price": "0.997", "size": "460.21", "side": "SELL", "timestamp": "1768475258850", "received_at": "2026-01-15T12:07:39.017350"}}
{"event_type": "price_change", "event_ts": "2026-01-15T12:07:40.023811", "ingestion_ts": "2026-01-15T12:08:42.168746", "market_id": "0xcab7ba4a9133cfd407d7e73e5757e5abbace413b59421527a31113406c97815c", "raw": {"market": "0xcab7ba4a9133cfd407d7e73e5757e5abbace413b59421527a31113406c97815c", "asset_id": "96361925776989336186111887920533578209326565663637092688733016597062311745569", "price": "0.006", "size": "127.41", "side": "BUY", "timestamp": "1768475259874", "received_at": "2026-01-15T12:07:40.023811"}}
{"event_type": "price_change", "event_ts": "2026-01-15T12:07:40.023811", "ingestion_ts": "2026-01-15T12:08:42.168746", "market_id": "0xcab7ba4a9133cfd407d7e73e5757e5abbace413b59421527a31113406c97815c", "raw": {"market": "0xcab7ba4a9133cfd407d7e73e5757e5abbace413b59421527a31113406c97815c", "asset_id": "20002636398944597965698652220992177552927816915094913583821579024925426590022", "price": "0.994", "size": "127.41", "side": "SELL", "timestamp": "1768475259874", "received_at": "2026-01-15T12:07:40.023811"}}
{"event_type": "price_change", "event_ts": "2026-01-15T12:07:40.023849", "ingestion_ts": "2026-01-15T12:08:42.168746", "market_id": "0xcab7ba4a9133cfd407d7e73e5757e5abbace413b59421527a31113406c97815c", "raw": {"market": "0xcab7ba4a9133cfd407d7e73e5757e5abbace413b59421527a31113406c97815c", "asset_id": "96361925776989336186111887920533578209326565663637092688733016597062311745569", "price": "0.009", "size": "812.25", "side": "BUY", "timestamp": "1768475259874", "received_at": "2026-01-15T12:07:40.023849"}}
{"event_type": "price_change", "event_ts": "2026-01-15T12:07:40.023849", "ingestion_ts": "2026-01-15T12:08:42.168746", "market_id": "0xcab7ba4a9133cfd407d7e73e5757e5abbace413b59421527a31113406c97815c", "raw": {"market": "0xcab7ba4a9133cfd407d7e73e5757e5abbace413b59421527a31113406c97815c", "asset_id": "20002636398944597965698652220992177552927816915094913583821579024925426590022", "price": "0.991", "size": "812.25", "side": "SELL", "timestamp": "1768475259874", "received_at": "2026-01-15T12:07:40.023849"}}
{"event_type": "price_change", "event_ts": "2026-01-15T12:07:40.352049", "ingestion_ts": "2026-01-15T12:08:42.168746", "market_id": "0xcab7ba4a9133cfd407d7e73e5757e5abbace413b59421527a31113406c97815c", "raw": {"market": "0xcab7ba4a9133cfd407d7e73e5757e5abbace413b59421527a31113406c97815c", "asset_id": "96361925776989336186111887920533578209326565663637092688733016597062311745569", "price": "0.009", "size": "818.33", "side": "BUY", "timestamp": "1768475260159", "received_at": "2026-01-15T12:07:40.352049"}}
{"event_type": "price_change", "event_ts": "2026-01-15T12:07:40.352049", "ingestion_ts": "2026-01-15T12:08:42.168746", "market_id": "0xcab7ba4a9133cfd407d7e73e5757e5abbace413b59421527a31113406c97815c", "raw": {"market": "0xcab7ba4a9133cfd407d7e73e5757e5abbace413b59421527a31113406c97815c", "asset_id": "20002636398944597965698652220992177552927816915094913583821579024925426590022", "price": "0.991", "size": "818.33", "side": "SELL", "timestamp": "1768475260159", "received_at": "2026-01-15T12:07:40.352049"}}
{"event_type": "price_change", "event_ts": "2026-01-15T12:07:40.352090", "ingestion_ts": "2026-01-15T12:08:42.168746", "market_id": "0xcab7ba4a9133cfd407d7e73e5757e5abbace413b59421527a31113406c97815c", "raw": {"market": "0xcab7ba4a9133cfd407d7e73e5757e5abbace413b59421527a31113406c97815c", "asset_id": "96361925776989336186111887920533578209326565663637092688733016597062311745569", "price": "0.006", "size": "136.51", "side": "BUY", "timestamp": "1768475260163", "received_at": "2026-01-15T12:07:40.352090"}}
{"event_type": "price_change", "event_ts": "2026-01-15T12:07:40.352090", "ingestion_ts": "2026-01-15T12:08:42.168746", "market_id": "0xcab7ba4a9133cfd407d7e73e5757e5abbace413b59421527a31113406c97815c", "raw": {"market": "0xcab7ba4a9133cfd407d7e73e5757e5abbace413b59421527a31113406c97815c", "asset_id": "20002636398944597965698652220992177552927816915094913583821579024925426590022", "price": "0.994", "size": "136.51", "side": "SELL", "timestamp": "1768475260163", "received_at": "2026-01-15T12:07:40.352090"}}
{"event_type": "price_change", "event_ts": "2026-01-15T12:07:41.454612", "ingestion_ts": "2026-01-15T12:08:42.168746", "market_id": "0x427bc4b40c09b3dcbc973747f0e4b079bed91b3e5a0aed5c36edd0f7591485f4", "raw": {"market": "0x427bc4b40c09b3dcbc973747f0e4b079bed91b3e5a0aed5c36edd0f7591485f4", "asset_id": "115669573443672055876643967408433138119481486650803218131873713375232186497057", "price": "0.003", "size": "4.03", "side": "BUY", "timestamp": "1768475261273", "received_at": "2026-01-15T12:07:41.454612"}}
{"event_type": "price_change", "event_ts": "2026-01-15T12:07:41.454612", "ingestion_ts": "2026-01-15T12:08:42.168746", "market_id": "0x427bc4b40c09b3dcbc973747f0e4b079bed91b3e5a0aed5c36edd0f7591485f4", "raw": {"market": "0x427bc4b40c09b3dcbc973747f0e4b079bed91b3e5a0aed5c36edd0f7591485f4", "asset_id": "86130975769502911188457673769190265049139877688522439001984850068234616395137", "price": "0.997", "size": "4.03", "side": "SELL", "timestamp": "1768475261273", "received_at": "2026-01-15T12:07:41.454612"}}
{"event_type": "price_change", "event_ts": "2026-01-15T12:07:41.641123", "ingestion_ts": "2026-01-15T12:08:42.168746", "market_id": "0x427bc4b40c09b3dcbc973747f0e4b079bed91b3e5a0aed5c36edd0f7591485f4", "raw": {"market": "0x427bc4b40c09b3dcbc973747f0e4b079bed91b3e5a0aed5c36edd0f7591485f4", "asset_id": "115669573443672055876643967408433138119481486650803218131873713375232186497057", "price": "0.002", "size": "29.58", "side": "BUY", "timestamp": "1768475261524", "received_at": "2026-01-15T12:07:41.641123"}}
{"event_type": "price_change", "event_ts": "2026-01-15T12:07:41.641123", "ingestion_ts": "2026-01-15T12:08:42.168746", "market_id": "0x427bc4b40c09b3dcbc973747f0e4b079bed91b3e5a0aed5c36edd0f7591485f4", "raw": {"market": "0x427bc4b40c09b3dcbc973747f0e4b079bed91b3e5a0aed5c36edd0f7591485f4", "asset_id": "86130975769502911188457673769190265049139877688522439001984850068234616395137", "price": "0.998", "size": "29.58", "side": "SELL", "timestamp": "1768475261524", "received_at": "2026-01-15T12:07:41.641123"}}
{"event_type": "price_change", "event_ts": "2026-01-15T12:07:41.642753", "ingestion_ts": "2026-01-15T12:08:42.168746", "market_id": "0x427bc4b40c09b3dcbc973747f0e4b079bed91b3e5a0aed5c36edd0f7591485f4", "raw": {"market": "0x427bc4b40c09b3dcbc973747f0e4b079bed91b3e5a0aed5c36edd0f7591485f4", "asset_id": "115669573443672055876643967408433138119481486650803218131873713375232186497057", "price": "0.004", "size": "43.76", "side": "BUY", "timestamp": "1768475261525", "received_at": "2026-01-15T12:07:41.642753"}}
{"event_type": "price_change", "event_ts": "2026-01-15T12:07:41.642753", "ingestion_ts": "2026-01-15T12:08:42.168746", "market_id": "0x427bc4b40c09b3dcbc973747f0e4b079bed91b3e5a0aed5c36edd0f7591485f4", "raw": {"market": "0x427bc4b40c09b3dcbc973747f0e4b079bed91b3e5a0aed5c36edd0f7591485f4", "asset_id": "86130975769502911188457673769190265049139877688522439001984850068234616395137", "price": "0.996", "size": "43.76", "side": "SELL", "timestamp": "1768475261525", "received_at": "2026-01-15T12:07:41.642753"}}
{"event_type": "price_change", "event_ts": "2026-01-15T12:07:42.042665", "ingestion_ts": "2026-01-15T12:08:42.168746", "market_id": "0xcab7ba4a9133cfd407d7e73e5757e5abbace413b59421527a31113406c97815c", "raw": {"market": "0xcab7ba4a9133cfd407d7e73e5757e5abbace413b59421527a31113406c97815c", "asset_id": "20002636398944597965698652220992177552927816915094913583821579024925426590022", "price": "0.352", "size": "0", "side": "BUY", "timestamp": "1768475261920", "received_at": "2026-01-15T12:07:42.042665"}}
{"event_type": "price_change", "event_ts": "2026-01-15T12:07:42.042665", "ingestion_ts": "2026-01-15T12:08:42.168746", "market_id": "0xcab7ba4a9133cfd407d7e73e5757e5abbace413b59421527a31113406c97815c", "raw": {"market": "0xcab7ba4a9133cfd407d7e73e5757e5abbace413b59421527a31113406c97815c", "asset_id": "96361925776989336186111887920533578209326565663637092688733016597062311745569", "price": "0.648", "size": "0", "side": "SELL", "timestamp": "1768475261920", "received_at": "2026-01-15T12:07:42.042665"}}
{"event_type": "price_change", "event_ts": "2026-01-15T12:07:42.230586", "ingestion_ts": "2026-01-15T12:08:42.168746", "market_id": "0xcab7ba4a9133cfd407d7e73e5757e5abbace413b59421527a31113406c97815c", "raw": {"market": "0xcab7ba4a9133cfd407d7e73e5757e5abbace413b59421527a31113406c97815c", "asset_id": "20002636398944597965698652220992177552927816915094913583821579024925426590022", "price": "0.041", "size": "0", "side": "BUY", "timestamp": "1768475262111", "received_at": "2026-01-15T12:07:42.230586"}}
{"event_type": "price_change", "event_ts": "2026-01-15T12:07:42.230586", "ingestion_ts": "2026-01-15T12:08:42.168746", "market_id": "0xcab7ba4a9133cfd407d7e73e5757e5abbace413b59421527a31113406c97815c", "raw": {"market": "0xcab7ba4a9133cfd407d7e73e5757e5abbace413b59421527a31113406c97815c", "asset_id": "96361925776989336186111887920533578209326565663637092688733016597062311745569", "price": "0.959", "size": "0", "side": "SELL", "timestamp": "1768475262111", "received_at": "2026-01-15T12:07:42.230586"}}
{"event_type": "price_change", "event_ts": "2026-01-15T12:07:42.437433", "ingestion_ts": "2026-01-15T12:08:42.168746", "market_id": "0xcab7ba4a9133cfd407d7e73e5757e5abbace413b59421527a31113406c97815c", "raw": {"market": "0xcab7ba4a9133cfd407d7e73e5757e5abbace413b59421527a31113406c97815c", "asset_id": "20002636398944597965698652220992177552927816915094913583821579024925426590022", "price": "0.022", "size": "0", "side": "BUY", "timestamp": "1768475262318", "received_at": "2026-01-15T12:07:42.437433"}}
{"event_type": "price_change", "event_ts": "2026-01-15T12:07:42.437433", "ingestion_ts": "2026-01-15T12:08:42.168746", "market_id": "0xcab7ba4a9133cfd407d7e73e5757e5abbace413b59421527a31113406c97815c", "raw": {"market": "0xcab7ba4a9133cfd407d7e73e5757e5abbace413b59421527a31113406c97815c", "asset_id": "96361925776989336186111887920533578209326565663637092688733016597062311745569", "price": "0.978", "size": "0", "side": "SELL", "timestamp": "1768475262318", "received_at": "2026-01-15T12:07:42.437433"}}
{"event_type": "price_change", "event_ts": "2026-01-15T12:07:42.528530", "ingestion_ts": "2026-01-15T12:08:42.168746", "market_id": "0xcab7ba4a9133cfd407d7e73e5757e5abbace413b59421527a31113406c97815c", "raw": {"market": "0xcab7ba4a9133cfd407d7e73e5757e5abbace413b59421527a31113406c97815c", "asset_id": "96361925776989336186111887920533578209326565663637092688733016597062311745569", "price": "0.006", "size": "127.41", "side": "BUY", "timestamp": "1768475262406", "received_at": "2026-01-15T12:07:42.528530"}}
{"event_type": "price_change", "event_ts": "2026-01-15T12:07:42.528530", "ingestion_ts": "2026-01-15T12:08:42.168746", "market_id": "0xcab7ba4a9133cfd407d7e73e5757e5abbace413b59421527a31113406c97815c", "raw": {"market": "0xcab7ba4a9133cfd407d7e73e5757e5abbace413b59421527a31113406c97815c", "asset_id": "20002636398944597965698652220992177552927816915094913583821579024925426590022", "price": "0.994", "size": "127.41", "side": "SELL", "timestamp": "1768475262406", "received_at": "2026-01-15T12:07:42.528530"}}
{"event_type": "price_change", "event_ts": "2026-01-15T12:07:42.528568", "ingestion_ts": "2026-01-15T12:08:42.168746", "market_id": "0xcab7ba4a9133cfd407d7e73e5757e5abbace413b59421527a31113406c97815c", "raw": {"market": "0xcab7ba4a9133cfd407d7e73e5757e5abbace413b59421527a31113406c97815c", "asset_id": "96361925776989336186111887920533578209326565663637092688733016597062311745569", "price": "0.009", "size": "812.25", "side": "BUY", "timestamp": "1768475262406", "received_at": "2026-01-15T12:07:42.528568"}}
{"event_type": "price_change", "event_ts": "2026-01-15T12:07:42.528568", "ingestion_ts": "2026-01-15T12:08:42.168746", "market_id": "0xcab7ba4a9133cfd407d7e73e5757e5abbace413b59421527a31113406c97815c", "raw": {"market": "0xcab7ba4a9133cfd407d7e73e5757e5abbace413b59421527a31113406c97815c", "asset_id": "20002636398944597965698652220992177552927816915094913583821579024925426590022", "price": "0.991", "size": "812.25", "side": "SELL", "timestamp": "1768475262406", "received_at": "2026-01-15T12:07:42.528568"}}
{"event_type": "price_change", "event_ts": "2026-01-15T12:07:42.631513", "ingestion_ts": "2026-01-15T12:08:42.168746", "market_id": "0xcab7ba4a9133cfd407d7e73e5757e5abbace413b59421527a31113406c97815c", "raw": {"market": "0xcab7ba4a9133cfd407d7e73e5757e5abbace413b59421527a31113406c97815c", "asset_id": "20002636398944597965698652220992177552927816915094913583821579024925426590022", "price": "0.022", "size": "155.84", "side": "BUY", "timestamp": "1768475262515", "received_at": "2026-01-15T12:07:42.631513"}}
{"event_type": "price_change", "event_ts": "2026-01-15T12:07:42.631513", "ingestion_ts": "2026-01-15T12:08:42.168746", "market_id": "0xcab7ba4a9133cfd407d7e73e5757e5abbace413b59421527a31113406c97815c", "raw": {"market": "0xcab7ba4a9133cfd407d7e73e5757e5abbace413b59421527a31113406c97815c", "asset_id": "96361925776989336186111887920533578209326565663637092688733016597062311745569", "price": "0.978", "size": "155.84", "side": "SELL", "timestamp": "1768475262515", "received_at": "2026-01-15T12:07:42.631513"}}
{"event_type": "price_change", "event_ts": "2026-01-15T12:07:42.871227", "ingestion_ts": "2026-01-15T12:08:42.168746", "market_id": "0xcab7ba4a9133cfd407d7e73e5757e5abbace413b59421527a31113406c97815c", "raw": {"market": "0xcab7ba4a9133cfd407d7e73e5757e5abbace413b59421527a31113406c97815c", "asset_id": "20002636398944597965698652220992177552927816915094913583821579024925426590022", "price": "0.043", "size": "79.73", "side": "BUY", "timestamp": "1768475262751", "received_at": "2026-01-15T12:07:42.871227"}}
{"event_type": "price_change", "event_ts": "2026-01-15T12:07:42.871227", "ingestion_ts": "2026-01-15T12:08:42.168746", "market_id": "0xcab7ba4a9133cfd407d7e73e5757e5abbace413b59421527a31113406c97815c", "raw": {"market": "0xcab7ba4a9133cfd407d7e73e5757e5abbace413b59421527a31113406c97815c", "asset_id": "96361925776989336186111887920533578209326565663637092688733016597062311745569", "price": "0.957", "size": "79.73", "side": "SELL", "timestamp": "1768475262751", "received_at": "2026-01-15T12:07:42.871227"}}
{"event_type": "price_change", "event_ts": "2026-01-15T12:07:43.058262", "ingestion_ts": "2026-01-15T12:08:42.168746", "market_id": "0xcab7ba4a9133cfd407d7e73e5757e5abbace413b59421527a31113406c97815c", "raw": {"market": "0xcab7ba4a9133cfd407d7e73e5757e5abbace413b59421527a31113406c97815c", "asset_id": "20002636398944597965698652220992177552927816915094913583821579024925426590022", "price": "0.063", "size": "0", "side": "BUY", "timestamp": "1768475262941", "received_at": "2026-01-15T12:07:43.058262"}}
{"event_type": "price_change", "event_ts": "2026-01-15T12:07:43.058262", "ingestion_ts": "2026-01-15T12:08:42.168746", "market_id": "0xcab7ba4a9133cfd407d7e73e5757e5abbace413b59421527a31113406c97815c", "raw": {"market": "0xcab7ba4a9133cfd407d7e73e5757e5abbace413b59421527a31113406c97815c", "asset_id": "96361925776989336186111887920533578209326565663637092688733016597062311745569", "price": "0.937", "size": "0", "side": "SELL", "timestamp": "1768475262941", "received_at": "2026-01-15T12:07:43.058262"}}
{"event_type": "price_change", "event_ts": "2026-01-15T12:07:43.153477", "ingestion_ts": "2026-01-15T12:08:42.168746", "market_id": "0xcab7ba4a9133cfd407d7e73e5757e5abbace413b59421527a31113406c97815c", "raw": {"market": "0xcab7ba4a9133cfd407d7e73e5757e5abbace413b59421527a31113406c97815c", "asset_id": "96361925776989336186111887920533578209326565663637092688733016597062311745569", "price": "0.006", "size": "136.51", "side": "BUY", "timestamp": "1768475263024", "received_at": "2026-01-15T12:07:43.153477"}}
{"event_type": "price_change", "event_ts": "2026-01-15T12:07:43.153477", "ingestion_ts": "2026-01-15T12:08:42.168746", "market_id": "0xcab7ba4a9133cfd407d7e73e5757e5abbace413b59421527a31113406c97815c", "raw": {"market": "0xcab7ba4a9133cfd407d7e73e5757e5abbace413b59421527a31113406c97815c", "asset_id": "20002636398944597965698652220992177552927816915094913583821579024925426590022", "price": "0.994", "size": "136.51", "side": "SELL", "timestamp": "1768475263024", "received_at": "2026-01-15T12:07:43.153477"}}
{"event_type": "price_change", "event_ts": "2026-01-15T12:07:43.160139", "ingestion_ts": "2026-01-15T12:08:42.168746", "market_id": "0xcab7ba4a9133cfd407d7e73e5757e5abbace413b59421527a31113406c97815c", "raw": {"market": "0xcab7ba4a9133cfd407d7e73e5757e5abbace413b59421527a31113406c97815c", "asset_id": "96361925776989336186111887920533578209326565663637092688733016597062311745569", "price": "0.009", "size": "818.33", "side": "BUY", "timestamp": "1768475263025", "received_at": "2026-01-15T12:07:43.160139"}}
{"event_type": "price_change", "event_ts": "2026-01-15T12:07:43.160139", "ingestion_ts": "2026-01-15T12:08:42.168746", "market_id": "0xcab7ba4a9133cfd407d7e73e5757e5abbace413b59421527a31113406c97815c", "raw": {"market": "0xcab7ba4a9133cfd407d7e73e5757e5abbace413b59421527a31113406c97815c", "asset_id": "20002636398944597965698652220992177552927816915094913583821579024925426590022", "price": "0.991", "size": "818.33", "side": "SELL", "timestamp": "1768475263025", "received_at": "2026-01-15T12:07:43.160139"}}
{"event_type": "price_change", "event_ts": "2026-01-15T12:07:43.262479", "ingestion_ts": "2026-01-15T12:08:42.168746", "market_id": "0xcab7ba4a9133cfd407d7e73e5757e5abbace413b59421527a31113406c97815c", "raw": {"market": "0xcab7ba4a9133cfd407d7e73e5757e5abbace413b59421527a31113406c97815c", "asset_id": "20002636398944597965698652220992177552927816915094913583821579024925426590022", "price": "0.063", "size": "54.42", "side": "BUY", "timestamp": "1768475263145", "received_at": "2026-01-15T12:07:43.262479"}}
{"event_type": "price_change", "event_ts": "2026-01-15T12:07:43.262479", "ingestion_ts": "2026-01-15T12:08:42.168746", "market_id": "0xcab7ba4a9133cfd407d7e73e5757e5abbace413b59421527a31113406c97815c", "raw": {"market": "0xcab7ba4a9133cfd407d7e73e5757e5abbace413b59421527a31113406c97815c", "asset_id": "96361925776989336186111887920533578209326565663637092688733016597062311745569", "price": "0.937", "size": "54.42", "side": "SELL", "timestamp": "1768475263145", "received_at": "2026-01-15T12:07:43.262479"}}
{"event_type": "price_change", "event_ts": "2026-01-15T12:07:43.494263", "ingestion_ts": "2026-01-15T12:08:42.168746", "market_id": "0xcab7ba4a9133cfd407d7e73e5757e5abbace413b59421527a31113406c97815c", "raw": {"market": "0xcab7ba4a9133cfd407d7e73e5757e5abbace413b59421527a31113406c97815c", "asset_id": "20002636398944597965698652220992177552927816915094913583821579024925426590022", "price": "0.104", "size": "35.5", "side": "BUY", "timestamp": "1768475263360", "received_at": "2026-01-15T12:07:43.494263"}}
{"event_type": "price_change", "event_ts": "2026-01-15T12:07:43.494263", "ingestion_ts": "2026-01-15T12:08:42.168746", "market_id": "0xcab7ba4a9133cfd407d7e73e5757e5abbace413b59421527a31113406c97815c", "raw": {"market": "0xcab7ba4a9133cfd407d7e73e5757e5abbace413b59421527a31113406c97815c", "asset_id": "96361925776989336186111887920533578209326565663637092688733016597062311745569", "price": "0.896", "size": "35.5", "side": "SELL", "timestamp": "1768475263360", "received_at": "2026-01-15T12:07:43.494263"}}
{"event_type": "price_change", "event_ts": "2026-01-15T12:07:43.495217", "ingestion_ts": "2026-01-15T12:08:42.168746", "market_id": "0xc0e6b917320a47228fb96e3b5ae0e5c93773a5ae2662ae4e1f37807cfe47ce98", "raw": {"market": "0xc0e6b917320a47228fb96e3b5ae0e5c93773a5ae2662ae4e1f37807cfe47ce98", "asset_id": "58656358377246279051017109359677190749228949103591068167284263961542487110215", "price": "0.003", "size": "429.84", "side": "BUY", "timestamp": "1768475263361", "received_at": "2026-01-15T12:07:43.495217"}}
{"event_type": "price_change", "event_ts": "2026-01-15T12:07:43.495217", "ingestion_ts": "2026-01-15T12:08:42.168746", "market_id": "0xc0e6b917320a47228fb96e3b5ae0e5c93773a5ae2662ae4e1f37807cfe47ce98", "raw": {"market": "0xc0e6b917320a47228fb96e3b5ae0e5c93773a5ae2662ae4e1f37807cfe47ce98", "asset_id": "81647294538046680798858716589766492074338758116170717123345952330712416337530", "price": "0.997", "size": "429.84", "side": "SELL", "timestamp": "1768475263361", "received_at": "2026-01-15T12:07:43.495217"}}
{"event_type": "price_change", "event_ts": "2026-01-15T12:07:43.700182", "ingestion_ts": "2026-01-15T12:08:42.168746", "market_id": "0xcab7ba4a9133cfd407d7e73e5757e5abbace413b59421527a31113406c97815c", "raw": {"market": "0xcab7ba4a9133cfd407d7e73e5757e5abbace413b59421527a31113406c97815c", "asset_id": "20002636398944597965698652220992177552927816915094913583821579024925426590022", "price": "0.104", "size": "68.46", "side": "BUY", "timestamp": "1768475263581", "received_at": "2026-01-15T12:07:43.700182"}}
{"event_type": "price_change", "event_ts": "2026-01-15T12:07:43.700182", "ingestion_ts": "2026-01-15T12:08:42.168746", "market_id": "0xcab7ba4a9133cfd407d7e73e5757e5abbace413b59421527a31113406c97815c", "raw": {"market": "0xcab7ba4a9133cfd407d7e73e5757e5abbace413b59421527a31113406c97815c", "asset_id": "96361925776989336186111887920533578209326565663637092688733016597062311745569", "price": "0.896", "size": "68.46", "side": "SELL", "timestamp": "1768475263581", "received_at": "2026-01-15T12:07:43.700182"}}
{"event_type": "price_change", "event_ts": "2026-01-15T12:07:43.926017", "ingestion_ts": "2026-01-15T12:08:42.168746", "market_id": "0xcab7ba4a9133cfd407d7e73e5757e5abbace413b59421527a31113406c97815c", "raw": {"market": "0xcab7ba4a9133cfd407d7e73e5757e5abbace413b59421527a31113406c97815c", "asset_id": "20002636398944597965698652220992177552927816915094913583821579024925426590022", "price": "0.118", "size": "0", "side": "BUY", "timestamp": "1768475263793", "received_at": "2026-01-15T12:07:43.926017"}}
{"event_type": "price_change", "event_ts": "2026-01-15T12:07:43.926017", "ingestion_ts": "2026-01-15T12:08:42.168746", "market_id": "0xcab7ba4a9133cfd407d7e73e5757e5abbace413b59421527a31113406c97815c", "raw": {"market": "0xcab7ba4a9133cfd407d7e73e5757e5abbace413b59421527a31113406c97815c", "asset_id": "96361925776989336186111887920533578209326565663637092688733016597062311745569", "price": "0.882", "size": "0", "side": "SELL", "timestamp": "1768475263793", "received_at": "2026-01-15T12:07:43.926017"}}
{"event_type": "price_change", "event_ts": "2026-01-15T12:07:44.090867", "ingestion_ts": "2026-01-15T12:08:42.168746", "market_id": "0xcab7ba4a9133cfd407d7e73e5757e5abbace413b59421527a31113406c97815c", "raw": {"market": "0xcab7ba4a9133cfd407d7e73e5757e5abbace413b59421527a31113406c97815c", "asset_id": "20002636398944597965698652220992177552927816915094913583821579024925426590022", "price": "0.118", "size": "29.05", "side": "BUY", "timestamp": "1768475263969", "received_at": "2026-01-15T12:07:44.090867"}}
{"event_type": "price_change", "event_ts": "2026-01-15T12:07:44.090867", "ingestion_ts": "2026-01-15T12:08:42.168746", "market_id": "0xcab7ba4a9133cfd407d7e73e5757e5abbace413b59421527a31113406c97815c", "raw": {"market": "0xcab7ba4a9133cfd407d7e73e5757e5abbace413b59421527a31113406c97815c", "asset_id": "96361925776989336186111887920533578209326565663637092688733016597062311745569", "price": "0.882", "size": "29.05", "side": "SELL", "timestamp": "1768475263969", "received_at": "2026-01-15T12:07:44.090867"}}
{"event_type": "price_change", "event_ts": "2026-01-15T12:07:44.284103", "ingestion_ts": "2026-01-15T12:08:42.168746", "market_id": "0xcab7ba4a9133cfd407d7e73e5757e5abbace413b59421527a31113406c97815c", "raw": {"market": "0xcab7ba4a9133cfd407d7e73e5757e5abbace413b59421527a31113406c97815c", "asset_id": "20002636398944597965698652220992177552927816915094913583821579024925426590022", "price": "0.151", "size": "0", "side": "BUY", "timestamp": "1768475264142", "received_at": "2026-01-15T12:07:44.284103"}}
{"event_type": "price_change", "event_ts": "2026-01-15T12:07:44.284103", "ingestion_ts": "2026-01-15T12:08:42.168746", "market_id": "0xcab7ba4a9133cfd407d7e73e5757e5abbace413b59421527a31113406c97815c", "raw": {"market": "0xcab7ba4a9133cfd407d7e73e5757e5abbace413b59421527a31113406c97815c", "asset_id": "96361925776989336186111887920533578209326565663637092688733016597062311745569", "price": "0.849", "size": "0", "side": "SELL", "timestamp": "1768475264142", "received_at": "2026-01-15T12:07:44.284103"}}
{"event_type": "price_change", "event_ts": "2026-01-15T12:07:44.303320", "ingestion_ts": "2026-01-15T12:08:42.168746", "market_id": "0xc0e6b917320a47228fb96e3b5ae0e5c93773a5ae2662ae4e1f37807cfe47ce98", "raw": {"market": "0xc0e6b917320a47228fb96e3b5ae0e5c93773a5ae2662ae4e1f37807cfe47ce98", "asset_id": "58656358377246279051017109359677190749228949103591068167284263961542487110215", "price": "0.004", "size": "11.39", "side": "BUY", "timestamp": "1768475264151", "received_at": "2026-01-15T12:07:44.303320"}}
{"event_type": "price_change", "event_ts": "2026-01-15T12:07:44.303320", "ingestion_ts": "2026-01-15T12:08:42.168746", "market_id": "0xc0e6b917320a47228fb96e3b5ae0e5c93773a5ae2662ae4e1f37807cfe47ce98", "raw": {"market": "0xc0e6b917320a47228fb96e3b5ae0e5c93773a5ae2662ae4e1f37807cfe47ce98", "asset_id": "81647294538046680798858716589766492074338758116170717123345952330712416337530", "price": "0.996", "size": "11.39", "side": "SELL", "timestamp": "1768475264151", "received_at": "2026-01-15T12:07:44.303320"}}
{"event_type": "price_change", "event_ts": "2026-01-15T12:07:44.303362", "ingestion_ts": "2026-01-15T12:08:42.168746", "market_id": "0xc0e6b917320a47228fb96e3b5ae0e5c93773a5ae2662ae4e1f37807cfe47ce98", "raw": {"market": "0xc0e6b917320a47228fb96e3b5ae0e5c93773a5ae2662ae4e1f37807cfe47ce98", "asset_id": "58656358377246279051017109359677190749228949103591068167284263961542487110215", "price": "0.004", "size": "22.78", "side": "BUY", "timestamp": "1768475264152", "received_at": "2026-01-15T12:07:44.303362"}}
{"event_type": "price_change", "event_ts": "2026-01-15T12:07:44.303362", "ingestion_ts": "2026-01-15T12:08:42.168746", "market_id": "0xc0e6b917320a47228fb96e3b5ae0e5c93773a5ae2662ae4e1f37807cfe47ce98", "raw": {"market": "0xc0e6b917320a47228fb96e3b5ae0e5c93773a5ae2662ae4e1f37807cfe47ce98", "asset_id": "81647294538046680798858716589766492074338758116170717123345952330712416337530", "price": "0.996", "size": "22.78", "side": "SELL", "timestamp": "1768475264152", "received_at": "2026-01-15T12:07:44.303362"}}
{"event_type": "price_change", "event_ts": "2026-01-15T12:07:44.472645", "ingestion_ts": "2026-01-15T12:08:42.168746", "market_id": "0xcab7ba4a9133cfd407d7e73e5757e5abbace413b59421527a31113406c97815c", "raw": {"market": "0xcab7ba4a9133cfd407d7e73e5757e5abbace413b59421527a31113406c97815c", "asset_id": "20002636398944597965698652220992177552927816915094913583821579024925426590022", "price": "0.151", "size": "22.7", "side": "BUY", "timestamp": "1768475264353", "received_at": "2026-01-15T12:07:44.472645"}}
{"event_type": "price_change", "event_ts": "2026-01-15T12:07:44.472645", "ingestion_ts": "2026-01-15T12:08:42.168746", "market_id": "0xcab7ba4a9133cfd407d7e73e5757e5abbace413b59421527a31113406c97815c", "raw": {"market": "0xcab7ba4a9133cfd407d7e73e5757e5abbace413b59421527a31113406c97815c", "asset_id": "96361925776989336186111887920533578209326565663637092688733016597062311745569", "price": "0.849", "size": "22.7", "side": "SELL", "timestamp": "1768475264353", "received_at": "2026-01-15T12:07:44.472645"}}
{"event_type": "price_change", "event_ts": "2026-01-15T12:07:44.590272", "ingestion_ts": "2026-01-15T12:08:42.168746", "market_id": "0xcab7ba4a9133cfd407d7e73e5757e5abbace413b59421527a31113406c97815c", "raw": {"market": "0xcab7ba4a9133cfd407d7e73e5757e5abbace413b59421527a31113406c97815c", "asset_id": "96361925776989336186111887920533578209326565663637092688733016597062311745569", "price": "0.006", "size": "127.41", "side": "BUY", "timestamp": "1768475264468", "received_at": "2026-01-15T12:07:44.590272"}}
{"event_type": "price_change", "event_ts": "2026-01-15T12:07:44.590272", "ingestion_ts": "2026-01-15T12:08:42.168746", "market_id": "0xcab7ba4a9133cfd407d7e73e5757e5abbace413b59421527a31113406c97815c", "raw": {"market": "0xcab7ba4a9133cfd407d7e73e5757e5abbace413b59421527a31113406c97815c", "asset_id": "20002636398944597965698652220992177552927816915094913583821579024925426590022", "price": "0.994", "size": "127.41", "side": "SELL", "timestamp": "1768475264468", "received_at": "2026-01-15T12:07:44.590272"}}
{"event_type": "price_change", "event_ts": "2026-01-15T12:07:44.590307", "ingestion_ts": "2026-01-15T12:08:42.168746", "market_id": "0xcab7ba4a9133cfd407d7e73e5757e5abbace413b59421527a31113406c97815c", "raw": {"market": "0xcab7ba4a9133cfd407d7e73e5757e5abbace413b59421527a31113406c97815c", "asset_id": "96361925776989336186111887920533578209326565663637092688733016597062311745569", "price": "0.009", "size": "812.25", "side": "BUY", "timestamp": "1768475264468", "received_at": "2026-01-15T12:07:44.590307"}}
{"event_type": "price_change", "event_ts": "2026-01-15T12:07:44.590307", "ingestion_ts": "2026-01-15T12:08:42.168746", "market_id": "0xcab7ba4a9133cfd407d7e73e5757e5abbace413b59421527a31113406c97815c", "raw": {"market": "0xcab7ba4a9133cfd407d7e73e5757e5abbace413b59421527a31113406c97815c", "asset_id": "20002636398944597965698652220992177552927816915094913583821579024925426590022", "price": "0.991", "size": "812.25", "side": "SELL", "timestamp": "1768475264468", "received_at": "2026-01-15T12:07:44.590307"}}
{"event_type": "price_change", "event_ts": "2026-01-15T12:07:44.653151", "ingestion_ts": "2026-01-15T12:08:42.168746", "market_id": "0xcab7ba4a9133cfd407d7e73e5757e5abbace413b59421527a31113406c97815c", "raw": {"market": "0xcab7ba4a9133cfd407d7e73e5757e5abbace413b59421527a31113406c97815c", "asset_id": "20002636398944597965698652220992177552927816915094913583821579024925426590022", "price": "0.167", "size": "0", "side": "BUY", "timestamp": "1768475264536", "received_at": "2026-01-15T12:07:44.653151"}}
{"event_type": "price_change", "event_ts": "2026-01-15T12:07:44.653151", "ingestion_ts": "2026-01-15T12:08:42.168746", "market_id": "0xcab7ba4a9133cfd407d7e73e5757e5abbace413b59421527a31113406c97815c", "raw": {"market": "0xcab7ba4a9133cfd407d7e73e5757e5abbace413b59421527a31113406c97815c", "asset_id": "96361925776989336186111887920533578209326565663637092688733016597062311745569", "price": "0.833", "size": "0", "side": "SELL", "timestamp": "1768475264536", "received_at": "2026-01-15T12:07:44.653151"}}
{"event_type": "price_change", "event_ts": "2026-01-15T12:07:44.864985", "ingestion_ts": "2026-01-15T12:08:42.168746", "market_id": "0xcab7ba4a9133cfd407d7e73e5757e5abbace413b59421527a31113406c97815c", "raw": {"market": "0xcab7ba4a9133cfd407d7e73e5757e5abbace413b59421527a31113406c97815c", "asset_id": "20002636398944597965698652220992177552927816915094913583821579024925426590022", "price": "0.167", "size": "20.53", "side": "BUY", "timestamp": "1768475264744", "received_at": "2026-01-15T12:07:44.864985"}}
{"event_type": "price_change", "event_ts": "2026-01-15T12:07:44.864985", "ingestion_ts": "2026-01-15T12:08:42.168746", "market_id": "0xcab7ba4a9133cfd407d7e73e5757e5abbace413b59421527a31113406c97815c", "raw": {"market": "0xcab7ba4a9133cfd407d7e73e5757e5abbace413b59421527a31113406c97815c", "asset_id": "96361925776989336186111887920533578209326565663637092688733016597062311745569", "price": "0.833", "size": "20.53", "side": "SELL", "timestamp": "1768475264744", "received_at": "2026-01-15T12:07:44.864985"}}
{"event_type": "price_change", "event_ts": "2026-01-15T12:07:45.083435", "ingestion_ts": "2026-01-15T12:08:42.168746", "market_id": "0xcab7ba4a9133cfd407d7e73e5757e5abbace413b59421527a31113406c97815c", "raw": {"market": "0xcab7ba4a9133cfd407d7e73e5757e5abbace413b59421527a31113406c97815c", "asset_id": "20002636398944597965698652220992177552927816915094913583821579024925426590022", "price": "0.215", "size": "0", "side": "BUY", "timestamp": "1768475264965", "received_at": "2026-01-15T12:07:45.083435"}}
{"event_type": "price_change", "event_ts": "2026-01-15T12:07:45.083435", "ingestion_ts": "2026-01-15T12:08:42.168746", "market_id": "0xcab7ba4a9133cfd407d7e73e5757e5abbace413b59421527a31113406c97815c", "raw": {"market": "0xcab7ba4a9133cfd407d7e73e5757e5abbace413b59421527a31113406c97815c", "asset_id": "96361925776989336186111887920533578209326565663637092688733016597062311745569", "price": "0.785", "size": "0", "side": "SELL", "timestamp": "1768475264965", "received_at": "2026-01-15T12:07:45.083435"}}
{"event_type": "price_change", "event_ts": "2026-01-15T12:07:45.295187", "ingestion_ts": "2026-01-15T12:08:42.168746", "market_id": "0xcab7ba4a9133cfd407d7e73e5757e5abbace413b59421527a31113406c97815c", "raw": {"market": "0xcab7ba4a9133cfd407d7e73e5757e5abbace413b59421527a31113406c97815c", "asset_id": "20002636398944597965698652220992177552927816915094913583821579024925426590022", "price": "0.215", "size": "15.94", "side": "BUY", "timestamp": "1768475265166", "received_at": "2026-01-15T12:07:45.295187"}}
{"event_type": "price_change", "event_ts": "2026-01-15T12:07:45.295187", "ingestion_ts": "2026-01-15T12:08:42.168746", "market_id": "0xcab7ba4a9133cfd407d7e73e5757e5abbace413b59421527a31113406c97815c", "raw": {"market": "0xcab7ba4a9133cfd407d7e73e5757e5abbace413b59421527a31113406c97815c", "asset_id": "96361925776989336186111887920533578209326565663637092688733016597062311745569", "price": "0.785", "size": "15.94", "side": "SELL", "timestamp": "1768475265166", "received_at": "2026-01-15T12:07:45.295187"}}
{"event_type": "price_change", "event_ts": "2026-01-15T12:07:45.295223", "ingestion_ts": "2026-01-15T12:08:42.168746", "market_id": "0xcab7ba4a9133cfd407d7e73e5757e5abbace413b59421527a31113406c97815c", "raw": {"market": "0xcab7ba4a9133cfd407d7e73e5757e5abbace413b59421527a31113406c97815c", "asset_id": "96361925776989336186111887920533578209326565663637092688733016597062311745569", "price": "0.009", "size": "818.33", "side": "BUY", "timestamp": "1768475265168", "received_at": "2026-01-15T12:07:45.295223"}}
{"event_type": "price_change", "event_ts": "2026-01-15T12:07:45.295223", "ingestion_ts": "2026-01-15T12:08:42.168746", "market_id": "0xcab7ba4a9133cfd407d7e73e5757e5abbace413b59421527a31113406c97815c", "raw": {"market": "0xcab7ba4a9133cfd407d7e73e5757e5abbace413b59421527a31113406c97815c", "asset_id": "20002636398944597965698652220992177552927816915094913583821579024925426590022", "price": "0.991", "size": "818.33", "side": "SELL", "timestamp": "1768475265168", "received_at": "2026-01-15T12:07:45.295223"}}
{"event_type": "price_change", "event_ts": "2026-01-15T12:07:45.295234", "ingestion_ts": "2026-01-15T12:08:42.168746", "market_id": "0xcab7ba4a9133cfd407d7e73e5757e5abbace413b59421527a31113406c97815c", "raw": {"market": "0xcab7ba4a9133cfd407d7e73e5757e5abbace413b59421527a31113406c97815c", "asset_id": "96361925776989336186111887920533578209326565663637092688733016597062311745569", "price": "0.006", "size": "136.51", "side": "BUY", "timestamp": "1768475265169", "received_at": "2026-01-15T12:07:45.295234"}}
{"event_type": "price_change", "event_ts": "2026-01-15T12:07:45.295234", "ingestion_ts": "2026-01-15T12:08:42.168746", "market_id": "0xcab7ba4a9133cfd407d7e73e5757e5abbace413b59421527a31113406c97815c", "raw": {"market": "0xcab7ba4a9133cfd407d7e73e5757e5abbace413b59421527a31113406c97815c", "asset_id": "20002636398944597965698652220992177552927816915094913583821579024925426590022", "price": "0.994", "size": "136.51", "side": "SELL", "timestamp": "1768475265169", "received_at": "2026-01-15T12:07:45.295234"}}
{"event_type": "price_change", "event_ts": "2026-01-15T12:07:45.437409", "ingestion_ts": "2026-01-15T12:08:42.168746", "market_id": "0x427bc4b40c09b3dcbc973747f0e4b079bed91b3e5a0aed5c36edd0f7591485f4", "raw": {"market": "0x427bc4b40c09b3dcbc973747f0e4b079bed91b3e5a0aed5c36edd0f7591485f4", "asset_id": "115669573443672055876643967408433138119481486650803218131873713375232186497057", "price": "0.004", "size": "28.07", "side": "BUY", "timestamp": "1768475265320", "received_at": "2026-01-15T12:07:45.437409"}}
{"event_type": "price_change", "event_ts": "2026-01-15T12:07:45.437409", "ingestion_ts": "2026-01-15T12:08:42.168746", "market_id": "0x427bc4b40c09b3dcbc973747f0e4b079bed91b3e5a0aed5c36edd0f7591485f4", "raw": {"market": "0x427bc4b40c09b3dcbc973747f0e4b079bed91b3e5a0aed5c36edd0f7591485f4", "asset_id": "86130975769502911188457673769190265049139877688522439001984850068234616395137", "price": "0.996", "size": "28.07", "side": "SELL", "timestamp": "1768475265320", "received_at": "2026-01-15T12:07:45.437409"}}
{"event_type": "price_change", "event_ts": "2026-01-15T12:07:45.523826", "ingestion_ts": "2026-01-15T12:08:42.168746", "market_id": "0xcab7ba4a9133cfd407d7e73e5757e5abbace413b59421527a31113406c97815c", "raw": {"market": "0xcab7ba4a9133cfd407d7e73e5757e5abbace413b59421527a31113406c97815c", "asset_id": "20002636398944597965698652220992177552927816915094913583821579024925426590022", "price": "0.224", "size": "0", "side": "BUY", "timestamp": "1768475265404", "received_at": "2026-01-15T12:07:45.523826"}}
{"event_type": "price_change", "event_ts": "2026-01-15T12:07:45.523826", "ingestion_ts": "2026-01-15T12:08:42.168746", "market_id": "0xcab7ba4a9133cfd407d7e73e5757e5abbace413b59421527a31113406c97815c", "raw": {"market": "0xcab7ba4a9133cfd407d7e73e5757e5abbace413b59421527a31113406c97815c", "asset_id": "96361925776989336186111887920533578209326565663637092688733016597062311745569", "price": "0.776", "size": "0", "side": "SELL", "timestamp": "1768475265404", "received_at": "2026-01-15T12:07:45.523826"}}
{"event_type": "price_change", "event_ts": "2026-01-15T12:07:45.750147", "ingestion_ts": "2026-01-15T12:08:42.168746", "market_id": "0xcab7ba4a9133cfd407d7e73e5757e5abbace413b59421527a31113406c97815c", "raw": {"market": "0xcab7ba4a9133cfd407d7e73e5757e5abbace413b59421527a31113406c97815c", "asset_id": "20002636398944597965698652220992177552927816915094913583821579024925426590022", "price": "0.224", "size": "15.3", "side": "BUY", "timestamp": "1768475265627", "received_at": "2026-01-15T12:07:45.750147"}}
{"event_type": "price_change", "event_ts": "2026-01-15T12:07:45.750147", "ingestion_ts": "2026-01-15T12:08:42.168746", "market_id": "0xcab7ba4a9133cfd407d7e73e5757e5abbace413b59421527a31113406c97815c", "raw": {"market": "0xcab7ba4a9133cfd407d7e73e5757e5abbace413b59421527a31113406c97815c", "asset_id": "96361925776989336186111887920533578209326565663637092688733016597062311745569", "price": "0.776", "size": "15.3", "side": "SELL", "timestamp": "1768475265627", "received_at": "2026-01-15T12:07:45.750147"}}
{"event_type": "price_change", "event_ts": "2026-01-15T12:07:45.805277", "ingestion_ts": "2026-01-15T12:08:42.168746", "market_id": "0x427bc4b40c09b3dcbc973747f0e4b079bed91b3e5a0aed5c36edd0f7591485f4", "raw": {"market": "0x427bc4b40c09b3dcbc973747f0e4b079bed91b3e5a0aed5c36edd0f7591485f4", "asset_id": "115669573443672055876643967408433138119481486650803218131873713375232186497057", "price": "0.005", "size": "29.3", "side": "BUY", "timestamp": "1768475265685", "received_at": "2026-01-15T12:07:45.805277"}}
{"event_type": "price_change", "event_ts": "2026-01-15T12:07:45.805277", "ingestion_ts": "2026-01-15T12:08:42.168746", "market_id": "0x427bc4b40c09b3dcbc973747f0e4b079bed91b3e5a0aed5c36edd0f7591485f4", "raw": {"market": "0x427bc4b40c09b3dcbc973747f0e4b079bed91b3e5a0aed5c36edd0f7591485f4", "asset_id": "86130975769502911188457673769190265049139877688522439001984850068234616395137", "price": "0.995", "size": "29.3", "side": "SELL", "timestamp": "1768475265685", "received_at": "2026-01-15T12:07:45.805277"}}
{"event_type": "price_change", "event_ts": "2026-01-15T12:07:45.805313", "ingestion_ts": "2026-01-15T12:08:42.168746", "market_id": "0x427bc4b40c09b3dcbc973747f0e4b079bed91b3e5a0aed5c36edd0f7591485f4", "raw": {"market": "0x427bc4b40c09b3dcbc973747f0e4b079bed91b3e5a0aed5c36edd0f7591485f4", "asset_id": "115669573443672055876643967408433138119481486650803218131873713375232186497057", "price": "0.002", "size": "47.73", "side": "BUY", "timestamp": "1768475265687", "received_at": "2026-01-15T12:07:45.805313"}}
{"event_type": "price_change", "event_ts": "2026-01-15T12:07:45.805313", "ingestion_ts": "2026-01-15T12:08:42.168746", "market_id": "0x427bc4b40c09b3dcbc973747f0e4b079bed91b3e5a0aed5c36edd0f7591485f4", "raw": {"market": "0x427bc4b40c09b3dcbc973747f0e4b079bed91b3e5a0aed5c36edd0f7591485f4", "asset_id": "86130975769502911188457673769190265049139877688522439001984850068234616395137", "price": "0.998", "size": "47.73", "side": "SELL", "timestamp": "1768475265687", "received_at": "2026-01-15T12:07:45.805313"}}
{"event_type": "price_change", "event_ts": "2026-01-15T12:07:45.945396", "ingestion_ts": "2026-01-15T12:08:42.168746", "market_id": "0xcab7ba4a9133cfd407d7e73e5757e5abbace413b59421527a31113406c97815c", "raw": {"market": "0xcab7ba4a9133cfd407d7e73e5757e5abbace413b59421527a31113406c97815c", "asset_id": "20002636398944597965698652220992177552927816915094913583821579024925426590022", "price": "0.252", "size": "0", "side": "BUY", "timestamp": "1768475265828", "received_at": "2026-01-15T12:07:45.945396"}}
{"event_type": "price_change", "event_ts": "2026-01-15T12:07:45.945396", "ingestion_ts": "2026-01-15T12:08:42.168746", "market_id": "0xcab7ba4a9133cfd407d7e73e5757e5abbace413b59421527a31113406c97815c", "raw": {"market": "0xcab7ba4a9133cfd407d7e73e5757e5abbace413b59421527a31113406c97815c", "asset_id": "96361925776989336186111887920533578209326565663637092688733016597062311745569", "price": "0.748", "size": "0", "side": "SELL", "timestamp": "1768475265828", "received_at": "2026-01-15T12:07:45.945396"}}
{"event_type": "price_change", "event_ts": "2026-01-15T12:07:46.091594", "ingestion_ts": "2026-01-15T12:08:42.168746", "market_id": "0x2393ed0b0fdc450054c7b9071907eca75cf4fc36e385adf4a0a5f99ee62243e8", "raw": {"market": "0x2393ed0b0fdc450054c7b9071907eca75cf4fc36e385adf4a0a5f99ee62243e8", "asset_id": "32769749367306925959219403371425714180265458150646381231272229429098460625924", "price": "0.916", "size": "0", "side": "BUY", "timestamp": "1768475265941", "received_at": "2026-01-15T12:07:46.091594"}}
{"event_type": "price_change", "event_ts": "2026-01-15T12:07:46.091594", "ingestion_ts": "2026-01-15T12:08:42.168746", "market_id": "0x2393ed0b0fdc450054c7b9071907eca75cf4fc36e385adf4a0a5f99ee62243e8", "raw": {"market": "0x2393ed0b0fdc450054c7b9071907eca75cf4fc36e385adf4a0a5f99ee62243e8", "asset_id": "100074770378634056601572485653252702850363676459996771990439989989293515601975", "price": "0.084", "size": "0", "side": "SELL", "timestamp": "1768475265941", "received_at": "2026-01-15T12:07:46.091594"}}
{"event_type": "price_change", "event_ts": "2026-01-15T12:07:46.168989", "ingestion_ts": "2026-01-15T12:08:42.168746", "market_id": "0xcab7ba4a9133cfd407d7e73e5757e5abbace413b59421527a31113406c97815c", "raw": {"market": "0xcab7ba4a9133cfd407d7e73e5757e5abbace413b59421527a31113406c97815c", "asset_id": "20002636398944597965698652220992177552927816915094913583821579024925426590022", "price": "0.252", "size": "13.6", "side": "BUY", "timestamp": "1768475266051", "received_at": "2026-01-15T12:07:46.168989"}}
{"event_type": "price_change", "event_ts": "2026-01-15T12:07:46.168989", "ingestion_ts": "2026-01-15T12:08:42.168746", "market_id": "0xcab7ba4a9133cfd407d7e73e5757e5abbace413b59421527a31113406c97815c", "raw": {"market": "0xcab7ba4a9133cfd407d7e73e5757e5abbace413b59421527a31113406c97815c", "asset_id": "96361925776989336186111887920533578209326565663637092688733016597062311745569", "price": "0.748", "size": "13.6", "side": "SELL", "timestamp": "1768475266051", "received_at": "2026-01-15T12:07:46.168989"}}
{"event_type": "price_change", "event_ts": "2026-01-15T12:07:46.383864", "ingestion_ts": "2026-01-15T12:08:42.168746", "market_id": "0xcab7ba4a9133cfd407d7e73e5757e5abbace413b59421527a31113406c97815c", "raw": {"market": "0xcab7ba4a9133cfd407d7e73e5757e5abbace413b59421527a31113406c97815c", "asset_id": "20002636398944597965698652220992177552927816915094913583821579024925426590022", "price": "0.274", "size": "0", "side": "BUY", "timestamp": "1768475266261", "received_at": "2026-01-15T12:07:46.383864"}}
{"event_type": "price_change", "event_ts": "2026-01-15T12:07:46.383864", "ingestion_ts": "2026-01-15T12:08:42.168746", "market_id": "0xcab7ba4a9133cfd407d7e73e5757e5abbace413b59421527a31113406c97815c", "raw": {"market": "0xcab7ba4a9133cfd407d7e73e5757e5abbace413b59421527a31113406c97815c", "asset_id": "96361925776989336186111887920533578209326565663637092688733016597062311745569", "price": "0.726", "size": "0", "side": "SELL", "timestamp": "1768475266261", "received_at": "2026-01-15T12:07:46.383864"}}
{"event_type": "price_change", "event_ts": "2026-01-15T12:07:46.585570", "ingestion_ts": "2026-01-15T12:08:42.168746", "market_id": "0xcab7ba4a9133cfd407d7e73e5757e5abbace413b59421527a31113406c97815c", "raw": {"market": "0xcab7ba4a9133cfd407d7e73e5757e5abbace413b59421527a31113406c97815c", "asset_id": "20002636398944597965698652220992177552927816915094913583821579024925426590022", "price": "0.274", "size": "12.51", "side": "BUY", "timestamp": "1768475266467", "received_at": "2026-01-15T12:07:46.585570"}}
{"event_type": "price_change", "event_ts": "2026-01-15T12:07:46.585570", "ingestion_ts": "2026-01-15T12:08:42.168746", "market_id": "0xcab7ba4a9133cfd407d7e73e5757e5abbace413b59421527a31113406c97815c", "raw": {"market": "0xcab7ba4a9133cfd407d7e73e5757e5abbace413b59421527a31113406c97815c", "asset_id": "96361925776989336186111887920533578209326565663637092688733016597062311745569", "price": "0.726", "size": "12.51", "side": "SELL", "timestamp": "1768475266467", "received_at": "2026-01-15T12:07:46.585570"}}
{"event_type": "price_change", "event_ts": "2026-01-15T12:07:46.734325", "ingestion_ts": "2026-01-15T12:08:42.168746", "market_id": "0xae5584fbb57f23c1c608d544b656f23d8bf12340cef70811cf31bb0cb4fc2115", "raw": {"market": "0xae5584fbb57f23c1c608d544b656f23d8bf12340cef70811cf31bb0cb4fc2115", "asset_id": "42278252558046940014991595990628759801692726198478046188873057685686228021663", "price": "0.522", "size": "0", "side": "BUY", "timestamp": "1768475266618", "received_at": "2026-01-15T12:07:46.734325"}}
{"event_type": "price_change", "event_ts": "2026-01-15T12:07:46.734325", "ingestion_ts": "2026-01-15T12:08:42.168746", "market_id": "0xae5584fbb57f23c1c608d544b656f23d8bf12340cef70811cf31bb0cb4fc2115", "raw": {"market": "0xae5584fbb57f23c1c608d544b656f23d8bf12340cef70811cf31bb0cb4fc2115", "asset_id": "28946595841244317705636126646676849578876740730186646421280828201004700559420", "price": "0.478", "size": "0", "side": "SELL", "timestamp": "1768475266618", "received_at": "2026-01-15T12:07:46.734325"}}
{"event_type": "price_change", "event_ts": "2026-01-15T12:07:46.779337", "ingestion_ts": "2026-01-15T12:08:42.168746", "market_id": "0xae5584fbb57f23c1c608d544b656f23d8bf12340cef70811cf31bb0cb4fc2115", "raw": {"market": "0xae5584fbb57f23c1c608d544b656f23d8bf12340cef70811cf31bb0cb4fc2115", "asset_id": "42278252558046940014991595990628759801692726198478046188873057685686228021663", "price": "0.522", "size": "5", "side": "BUY", "timestamp": "1768475266663", "received_at": "2026-01-15T12:07:46.779337"}}
{"event_type": "price_change", "event_ts": "2026-01-15T12:07:46.779337", "ingestion_ts": "2026-01-15T12:08:42.168746", "market_id": "0xae5584fbb57f23c1c608d544b656f23d8bf12340cef70811cf31bb0cb4fc2115", "raw": {"market": "0xae5584fbb57f23c1c608d544b656f23d8bf12340cef70811cf31bb0cb4fc2115", "asset_id": "28946595841244317705636126646676849578876740730186646421280828201004700559420", "price": "0.478", "size": "5", "side": "SELL", "timestamp": "1768475266663", "received_at": "2026-01-15T12:07:46.779337"}}
{"event_type": "price_change", "event_ts": "2026-01-15T12:07:46.804093", "ingestion_ts": "2026-01-15T12:08:42.168746", "market_id": "0xcab7ba4a9133cfd407d7e73e5757e5abbace413b59421527a31113406c97815c", "raw": {"market": "0xcab7ba4a9133cfd407d7e73e5757e5abbace413b59421527a31113406c97815c", "asset_id": "20002636398944597965698652220992177552927816915094913583821579024925426590022", "price": "0.3", "size": "59.03", "side": "BUY", "timestamp": "1768475266688", "received_at": "2026-01-15T12:07:46.804093"}}
{"event_type": "price_change", "event_ts": "2026-01-15T12:07:46.804093", "ingestion_ts": "2026-01-15T12:08:42.168746", "market_id": "0xcab7ba4a9133cfd407d7e73e5757e5abbace413b59421527a31113406c97815c", "raw": {"market": "0xcab7ba4a9133cfd407d7e73e5757e5abbace413b59421527a31113406c97815c", "asset_id": "96361925776989336186111887920533578209326565663637092688733016597062311745569", "price": "0.7", "size": "59.03", "side": "SELL", "timestamp": "1768475266688", "received_at": "2026-01-15T12:07:46.804093"}}
{"event_type": "price_change", "event_ts": "2026-01-15T12:07:47.037990", "ingestion_ts": "2026-01-15T12:08:42.168746", "market_id": "0xcab7ba4a9133cfd407d7e73e5757e5abbace413b59421527a31113406c97815c", "raw": {"market": "0xcab7ba4a9133cfd407d7e73e5757e5abbace413b59421527a31113406c97815c", "asset_id": "20002636398944597965698652220992177552927816915094913583821579024925426590022", "price": "0.4", "size": "44.28", "side": "BUY", "timestamp": "1768475266892", "received_at": "2026-01-15T12:07:47.037990"}}
{"event_type": "price_change", "event_ts": "2026-01-15T12:07:47.037990", "ingestion_ts": "2026-01-15T12:08:42.168746", "market_id": "0xcab7ba4a9133cfd407d7e73e5757e5abbace413b59421527a31113406c97815c", "raw": {"market": "0xcab7ba4a9133cfd407d7e73e5757e5abbace413b59421527a31113406c97815c", "asset_id": "96361925776989336186111887920533578209326565663637092688733016597062311745569", "price": "0.6", "size": "44.28", "side": "SELL", "timestamp": "1768475266892", "received_at": "2026-01-15T12:07:47.037990"}}
{"event_type": "price_change", "event_ts": "2026-01-15T12:07:47.208524", "ingestion_ts": "2026-01-15T12:08:42.168746", "market_id": "0xcab7ba4a9133cfd407d7e73e5757e5abbace413b59421527a31113406c97815c", "raw": {"market": "0xcab7ba4a9133cfd407d7e73e5757e5abbace413b59421527a31113406c97815c", "asset_id": "20002636398944597965698652220992177552927816915094913583821579024925426590022", "price": "0.489", "size": "0", "side": "BUY", "timestamp": "1768475267084", "received_at": "2026-01-15T12:07:47.208524"}}
{"event_type": "price_change", "event_ts": "2026-01-15T12:07:47.208524", "ingestion_ts": "2026-01-15T12:08:42.168746", "market_id": "0xcab7ba4a9133cfd407d7e73e5757e5abbace413b59421527a31113406c97815c", "raw": {"market": "0xcab7ba4a9133cfd407d7e73e5757e5abbace413b59421527a31113406c97815c", "asset_id": "96361925776989336186111887920533578209326565663637092688733016597062311745569", "price": "0.511", "size": "0", "side": "SELL", "timestamp": "1768475267084", "received_at": "2026-01-15T12:07:47.208524"}}
{"event_type": "price_change", "event_ts": "2026-01-15T12:07:47.421250", "ingestion_ts": "2026-01-15T12:08:42.168746", "market_id": "0xcab7ba4a9133cfd407d7e73e5757e5abbace413b59421527a31113406c97815c", "raw": {"market": "0xcab7ba4a9133cfd407d7e73e5757e5abbace413b59421527a31113406c97815c", "asset_id": "20002636398944597965698652220992177552927816915094913583821579024925426590022", "price": "0.489", "size": "7.01", "side": "BUY", "timestamp": "1768475267304", "received_at": "2026-01-15T12:07:47.421250"}}
{"event_type": "price_change", "event_ts": "2026-01-15T12:07:47.421250", "ingestion_ts": "2026-01-15T12:08:42.168746", "market_id": "0xcab7ba4a9133cfd407d7e73e5757e5abbace413b59421527a31113406c97815c", "raw": {"market": "0xcab7ba4a9133cfd407d7e73e5757e5abbace413b59421527a31113406c97815c", "asset_id": "96361925776989336186111887920533578209326565663637092688733016597062311745569", "price": "0.511", "size": "7.01", "side": "SELL", "timestamp": "1768475267304", "received_at": "2026-01-15T12:07:47.421250"}}
{"event_type": "price_change", "event_ts": "2026-01-15T12:07:47.601398", "ingestion_ts": "2026-01-15T12:08:42.168746", "market_id": "0xe9c127a8c35f045d37b5344b0a36711084fa20c2fc1618bf178a5386f90610be", "raw": {"market": "0xe9c127a8c35f045d37b5344b0a36711084fa20c2fc1618bf178a5386f90610be", "asset_id": "107000426448217931795450451304515386602910396776318075817601265223856116134349", "price": "0.4", "size": "35.71", "side": "BUY", "timestamp": "1768475267482", "received_at": "2026-01-15T12:07:47.601398"}}
{"event_type": "price_change", "event_ts": "2026-01-15T12:07:47.601398", "ingestion_ts": "2026-01-15T12:08:42.168746", "market_id": "0xe9c127a8c35f045d37b5344b0a36711084fa20c2fc1618bf178a5386f90610be", "raw": {"market": "0xe9c127a8c35f045d37b5344b0a36711084fa20c2fc1618bf178a5386f90610be", "asset_id": "80230236018433940569996058935444651347308266584430516013229815570706872276819", "price": "0.6", "size": "35.71", "side": "SELL", "timestamp": "1768475267482", "received_at": "2026-01-15T12:07:47.601398"}}
{"event_type": "price_change", "event_ts": "2026-01-15T12:07:47.629266", "ingestion_ts": "2026-01-15T12:08:42.168746", "market_id": "0xe9c127a8c35f045d37b5344b0a36711084fa20c2fc1618bf178a5386f90610be", "raw": {"market": "0xe9c127a8c35f045d37b5344b0a36711084fa20c2fc1618bf178a5386f90610be", "asset_id": "80230236018433940569996058935444651347308266584430516013229815570706872276819", "price": "0.025", "size": "10", "side": "SELL", "timestamp": "1768475267510", "received_at": "2026-01-15T12:07:47.629266"}}
{"event_type": "price_change", "event_ts": "2026-01-15T12:07:47.629266", "ingestion_ts": "2026-01-15T12:08:42.168746", "market_id": "0xe9c127a8c35f045d37b5344b0a36711084fa20c2fc1618bf178a5386f90610be", "raw": {"market": "0xe9c127a8c35f045d37b5344b0a36711084fa20c2fc1618bf178a5386f90610be", "asset_id": "107000426448217931795450451304515386602910396776318075817601265223856116134349", "price": "0.975", "size": "10", "side": "BUY", "timestamp": "1768475267510", "received_at": "2026-01-15T12:07:47.629266"}}
{"event_type": "price_change", "event_ts": "2026-01-15T12:07:47.658139", "ingestion_ts": "2026-01-15T12:08:42.168746", "market_id": "0xe9c127a8c35f045d37b5344b0a36711084fa20c2fc1618bf178a5386f90610be", "raw": {"market": "0xe9c127a8c35f045d37b5344b0a36711084fa20c2fc1618bf178a5386f90610be", "asset_id": "80230236018433940569996058935444651347308266584430516013229815570706872276819", "price": "0.025", "size": "388", "side": "SELL", "timestamp": "1768475267542", "received_at": "2026-01-15T12:07:47.658139"}}
{"event_type": "price_change", "event_ts": "2026-01-15T12:07:47.658139", "ingestion_ts": "2026-01-15T12:08:42.168746", "market_id": "0xe9c127a8c35f045d37b5344b0a36711084fa20c2fc1618bf178a5386f90610be", "raw": {"market": "0xe9c127a8c35f045d37b5344b0a36711084fa20c2fc1618bf178a5386f90610be", "asset_id": "107000426448217931795450451304515386602910396776318075817601265223856116134349", "price": "0.975", "size": "388", "side": "BUY", "timestamp": "1768475267542", "received_at": "2026-01-15T12:07:47.658139"}}
{"event_type": "price_change", "event_ts": "2026-01-15T12:07:47.830037", "ingestion_ts": "2026-01-15T12:08:42.168746", "market_id": "0xe9c127a8c35f045d37b5344b0a36711084fa20c2fc1618bf178a5386f90610be", "raw": {"market": "0xe9c127a8c35f045d37b5344b0a36711084fa20c2fc1618bf178a5386f90610be", "asset_id": "107000426448217931795450451304515386602910396776318075817601265223856116134349", "price": "0.3", "size": "47.61", "side": "BUY", "timestamp": "1768475267712", "received_at": "2026-01-15T12:07:47.830037"}}
{"event_type": "price_change", "event_ts": "2026-01-15T12:07:47.830037", "ingestion_ts": "2026-01-15T12:08:42.168746", "market_id": "0xe9c127a8c35f045d37b5344b0a36711084fa20c2fc1618bf178a5386f90610be", "raw": {"market": "0xe9c127a8c35f045d37b5344b0a36711084fa20c2fc1618bf178a5386f90610be", "asset_id": "80230236018433940569996058935444651347308266584430516013229815570706872276819", "price": "0.7", "size": "47.61", "side": "SELL", "timestamp": "1768475267712", "received_at": "2026-01-15T12:07:47.830037"}}
{"event_type": "price_change", "event_ts": "2026-01-15T12:07:48.011588", "ingestion_ts": "2026-01-15T12:08:42.168746", "market_id": "0xe9c127a8c35f045d37b5344b0a36711084fa20c2fc1618bf178a5386f90610be", "raw": {"market": "0xe9c127a8c35f045d37b5344b0a36711084fa20c2fc1618bf178a5386f90610be", "asset_id": "107000426448217931795450451304515386602910396776318075817601265223856116134349", "price": "0.258", "size": "0", "side": "BUY", "timestamp": "1768475267893", "received_at": "2026-01-15T12:07:48.011588"}}
{"event_type": "price_change", "event_ts": "2026-01-15T12:07:48.011588", "ingestion_ts": "2026-01-15T12:08:42.168746", "market_id": "0xe9c127a8c35f045d37b5344b0a36711084fa20c2fc1618bf178a5386f90610be", "raw": {"market": "0xe9c127a8c35f045d37b5344b0a36711084fa20c2fc1618bf178a5386f90610be", "asset_id": "80230236018433940569996058935444651347308266584430516013229815570706872276819", "price": "0.742", "size": "0", "side": "SELL", "timestamp": "1768475267893", "received_at": "2026-01-15T12:07:48.011588"}}
{"event_type": "price_change", "event_ts": "2026-01-15T12:07:48.075306", "ingestion_ts": "2026-01-15T12:08:42.168746", "market_id": "0xcab7ba4a9133cfd407d7e73e5757e5abbace413b59421527a31113406c97815c", "raw": {"market": "0xcab7ba4a9133cfd407d7e73e5757e5abbace413b59421527a31113406c97815c", "asset_id": "96361925776989336186111887920533578209326565663637092688733016597062311745569", "price": "0.006", "size": "127.41", "side": "BUY", "timestamp": "1768475267942", "received_at": "2026-01-15T12:07:48.075306"}}
{"event_type": "price_change", "event_ts": "2026-01-15T12:07:48.075306", "ingestion_ts": "2026-01-15T12:08:42.168746", "market_id": "0xcab7ba4a9133cfd407d7e73e5757e5abbace413b59421527a31113406c97815c", "raw": {"market": "0xcab7ba4a9133cfd407d7e73e5757e5abbace413b59421527a31113406c97815c", "asset_id": "20002636398944597965698652220992177552927816915094913583821579024925426590022", "price": "0.994", "size": "127.41", "side": "SELL", "timestamp": "1768475267942", "received_at": "2026-01-15T12:07:48.075306"}}
{"event_type": "price_change", "event_ts": "2026-01-15T12:07:48.075341", "ingestion_ts": "2026-01-15T12:08:42.168746", "market_id": "0xcab7ba4a9133cfd407d7e73e5757e5abbace413b59421527a31113406c97815c", "raw": {"market": "0xcab7ba4a9133cfd407d7e73e5757e5abbace413b59421527a31113406c97815c", "asset_id": "96361925776989336186111887920533578209326565663637092688733016597062311745569", "price": "0.009", "size": "812.25", "side": "BUY", "timestamp": "1768475267942", "received_at": "2026-01-15T12:07:48.075341"}}
{"event_type": "price_change", "event_ts": "2026-01-15T12:07:48.075341", "ingestion_ts": "2026-01-15T12:08:42.168746", "market_id": "0xcab7ba4a9133cfd407d7e73e5757e5abbace413b59421527a31113406c97815c", "raw": {"market": "0xcab7ba4a9133cfd407d7e73e5757e5abbace413b59421527a31113406c97815c", "asset_id": "20002636398944597965698652220992177552927816915094913583821579024925426590022", "price": "0.991", "size": "812.25", "side": "SELL", "timestamp": "1768475267942", "received_at": "2026-01-15T12:07:48.075341"}}
{"event_type": "price_change", "event_ts": "2026-01-15T12:07:48.214867", "ingestion_ts": "2026-01-15T12:08:42.168746", "market_id": "0xe9c127a8c35f045d37b5344b0a36711084fa20c2fc1618bf178a5386f90610be", "raw": {"market": "0xe9c127a8c35f045d37b5344b0a36711084fa20c2fc1618bf178a5386f90610be", "asset_id": "107000426448217931795450451304515386602910396776318075817601265223856116134349", "price": "0.257", "size": "14.36", "side": "BUY", "timestamp": "1768475268097", "received_at": "2026-01-15T12:07:48.214867"}}
{"event_type": "price_change", "event_ts": "2026-01-15T12:07:48.214867", "ingestion_ts": "2026-01-15T12:08:42.168746", "market_id": "0xe9c127a8c35f045d37b5344b0a36711084fa20c2fc1618bf178a5386f90610be", "raw": {"market": "0xe9c127a8c35f045d37b5344b0a36711084fa20c2fc1618bf178a5386f90610be", "asset_id": "80230236018433940569996058935444651347308266584430516013229815570706872276819", "price": "0.743", "size": "14.36", "side": "SELL", "timestamp": "1768475268097", "received_at": "2026-01-15T12:07:48.214867"}}
{"event_type": "price_change", "event_ts": "2026-01-15T12:07:48.375033", "ingestion_ts": "2026-01-15T12:08:42.168746", "market_id": "0xcab7ba4a9133cfd407d7e73e5757e5abbace413b59421527a31113406c97815c", "raw": {"market": "0xcab7ba4a9133cfd407d7e73e5757e5abbace413b59421527a31113406c97815c", "asset_id": "96361925776989336186111887920533578209326565663637092688733016597062311745569", "price": "0.009", "size": "818.33", "side": "BUY", "timestamp": "1768475268257", "received_at": "2026-01-15T12:07:48.375033"}}
{"event_type": "price_change", "event_ts": "2026-01-15T12:07:48.375033", "ingestion_ts": "2026-01-15T12:08:42.168746", "market_id": "0xcab7ba4a9133cfd407d7e73e5757e5abbace413b59421527a31113406c97815c", "raw": {"market": "0xcab7ba4a9133cfd407d7e73e5757e5abbace413b59421527a31113406c97815c", "asset_id": "20002636398944597965698652220992177552927816915094913583821579024925426590022", "price": "0.991", "size": "818.33", "side": "SELL", "timestamp": "1768475268257", "received_at": "2026-01-15T12:07:48.375033"}}
{"event_type": "price_change", "event_ts": "2026-01-15T12:07:48.375906", "ingestion_ts": "2026-01-15T12:08:42.168746", "market_id": "0xcab7ba4a9133cfd407d7e73e5757e5abbace413b59421527a31113406c97815c", "raw": {"market": "0xcab7ba4a9133cfd407d7e73e5757e5abbace413b59421527a31113406c97815c", "asset_id": "96361925776989336186111887920533578209326565663637092688733016597062311745569", "price": "0.006", "size": "136.51", "side": "BUY", "timestamp": "1768475268258", "received_at": "2026-01-15T12:07:48.375906"}}
{"event_type": "price_change", "event_ts": "2026-01-15T12:07:48.375906", "ingestion_ts": "2026-01-15T12:08:42.168746", "market_id": "0xcab7ba4a9133cfd407d7e73e5757e5abbace413b59421527a31113406c97815c", "raw": {"market": "0xcab7ba4a9133cfd407d7e73e5757e5abbace413b59421527a31113406c97815c", "asset_id": "20002636398944597965698652220992177552927816915094913583821579024925426590022", "price": "0.994", "size": "136.51", "side": "SELL", "timestamp": "1768475268258", "received_at": "2026-01-15T12:07:48.375906"}}
{"event_type": "price_change", "event_ts": "2026-01-15T12:07:48.419239", "ingestion_ts": "2026-01-15T12:08:42.168746", "market_id": "0xe9c127a8c35f045d37b5344b0a36711084fa20c2fc1618bf178a5386f90610be", "raw": {"market": "0xe9c127a8c35f045d37b5344b0a36711084fa20c2fc1618bf178a5386f90610be", "asset_id": "107000426448217931795450451304515386602910396776318075817601265223856116134349", "price": "0.106", "size": "0", "side": "BUY", "timestamp": "1768475268301", "received_at": "2026-01-15T12:07:48.419239"}}
{"event_type": "price_change", "event_ts": "2026-01-15T12:07:48.419239", "ingestion_ts": "2026-01-15T12:08:42.168746", "market_id": "0xe9c127a8c35f045d37b5344b0a36711084fa20c2fc1618bf178a5386f90610be", "raw": {"market": "0xe9c127a8c35f045d37b5344b0a36711084fa20c2fc1618bf178a5386f90610be", "asset_id": "80230236018433940569996058935444651347308266584430516013229815570706872276819", "price": "0.894", "size": "0", "side": "SELL", "timestamp": "1768475268301", "received_at": "2026-01-15T12:07:48.419239"}}
{"event_type": "price_change", "event_ts": "2026-01-15T12:07:48.617524", "ingestion_ts": "2026-01-15T12:08:42.168746", "market_id": "0xe9c127a8c35f045d37b5344b0a36711084fa20c2fc1618bf178a5386f90610be", "raw": {"market": "0xe9c127a8c35f045d37b5344b0a36711084fa20c2fc1618bf178a5386f90610be", "asset_id": "107000426448217931795450451304515386602910396776318075817601265223856116134349", "price": "0.04", "size": "0", "side": "BUY", "timestamp": "1768475268495", "received_at": "2026-01-15T12:07:48.617524"}}
{"event_type": "price_change", "event_ts": "2026-01-15T12:07:48.617524", "ingestion_ts": "2026-01-15T12:08:42.168746", "market_id": "0xe9c127a8c35f045d37b5344b0a36711084fa20c2fc1618bf178a5386f90610be", "raw": {"market": "0xe9c127a8c35f045d37b5344b0a36711084fa20c2fc1618bf178a5386f90610be", "asset_id": "80230236018433940569996058935444651347308266584430516013229815570706872276819", "price": "0.96", "size": "0", "side": "SELL", "timestamp": "1768475268495", "received_at": "2026-01-15T12:07:48.617524"}}
{"event_type": "price_change", "event_ts": "2026-01-15T12:07:48.797813", "ingestion_ts": "2026-01-15T12:08:42.168746", "market_id": "0xe9c127a8c35f045d37b5344b0a36711084fa20c2fc1618bf178a5386f90610be", "raw": {"market": "0xe9c127a8c35f045d37b5344b0a36711084fa20c2fc1618bf178a5386f90610be", "asset_id": "107000426448217931795450451304515386602910396776318075817601265223856116134349", "price": "0.022", "size": "0", "side": "BUY", "timestamp": "1768475268680", "received_at": "2026-01-15T12:07:48.797813"}}
{"event_type": "price_change", "event_ts": "2026-01-15T12:07:48.797813", "ingestion_ts": "2026-01-15T12:08:42.168746", "market_id": "0xe9c127a8c35f045d37b5344b0a36711084fa20c2fc1618bf178a5386f90610be", "raw": {"market": "0xe9c127a8c35f045d37b5344b0a36711084fa20c2fc1618bf178a5386f90610be", "asset_id": "80230236018433940569996058935444651347308266584430516013229815570706872276819", "price": "0.978", "size": "0", "side": "SELL", "timestamp": "1768475268680", "received_at": "2026-01-15T12:07:48.797813"}}
{"event_type": "price_change", "event_ts": "2026-01-15T12:07:48.925252", "ingestion_ts": "2026-01-15T12:08:42.168746", "market_id": "0xc0e6b917320a47228fb96e3b5ae0e5c93773a5ae2662ae4e1f37807cfe47ce98", "raw": {"market": "0xc0e6b917320a47228fb96e3b5ae0e5c93773a5ae2662ae4e1f37807cfe47ce98", "asset_id": "58656358377246279051017109359677190749228949103591068167284263961542487110215", "price": "0.004", "size": "11.39", "side": "BUY", "timestamp": "1768475268806", "received_at": "2026-01-15T12:07:48.925252"}}
{"event_type": "price_change", "event_ts": "2026-01-15T12:07:48.925252", "ingestion_ts": "2026-01-15T12:08:42.168746", "market_id": "0xc0e6b917320a47228fb96e3b5ae0e5c93773a5ae2662ae4e1f37807cfe47ce98", "raw": {"market": "0xc0e6b917320a47228fb96e3b5ae0e5c93773a5ae2662ae4e1f37807cfe47ce98", "asset_id": "81647294538046680798858716589766492074338758116170717123345952330712416337530", "price": "0.996", "size": "11.39", "side": "SELL", "timestamp": "1768475268806", "received_at": "2026-01-15T12:07:48.925252"}}
{"event_type": "price_change", "event_ts": "2026-01-15T12:07:49.022294", "ingestion_ts": "2026-01-15T12:08:42.168746", "market_id": "0xe9c127a8c35f045d37b5344b0a36711084fa20c2fc1618bf178a5386f90610be", "raw": {"market": "0xe9c127a8c35f045d37b5344b0a36711084fa20c2fc1618bf178a5386f90610be", "asset_id": "107000426448217931795450451304515386602910396776318075817601265223856116134349", "price": "0.022", "size": "181.81", "side": "BUY", "timestamp": "1768475268898", "received_at": "2026-01-15T12:07:49.022294"}}
{"event_type": "price_change", "event_ts": "2026-01-15T12:07:49.022294", "ingestion_ts": "2026-01-15T12:08:42.168746", "market_id": "0xe9c127a8c35f045d37b5344b0a36711084fa20c2fc1618bf178a5386f90610be", "raw": {"market": "0xe9c127a8c35f045d37b5344b0a36711084fa20c2fc1618bf178a5386f90610be", "asset_id": "80230236018433940569996058935444651347308266584430516013229815570706872276819", "price": "0.978", "size": "181.81", "side": "SELL", "timestamp": "1768475268898", "received_at": "2026-01-15T12:07:49.022294"}}
{"event_type": "price_change", "event_ts": "2026-01-15T12:07:49.255884", "ingestion_ts": "2026-01-15T12:08:42.168746", "market_id": "0xe9c127a8c35f045d37b5344b0a36711084fa20c2fc1618bf178a5386f90610be", "raw": {"market": "0xe9c127a8c35f045d37b5344b0a36711084fa20c2fc1618bf178a5386f90610be", "asset_id": "107000426448217931795450451304515386602910396776318075817601265223856116134349", "price": "0.042", "size": "95.23", "side": "BUY", "timestamp": "1768475269137", "received_at": "2026-01-15T12:07:49.255884"}}
{"event_type": "price_change", "event_ts": "2026-01-15T12:07:49.255884", "ingestion_ts": "2026-01-15T12:08:42.168746", "market_id": "0xe9c127a8c35f045d37b5344b0a36711084fa20c2fc1618bf178a5386f90610be", "raw": {"market": "0xe9c127a8c35f045d37b5344b0a36711084fa20c2fc1618bf178a5386f90610be", "asset_id": "80230236018433940569996058935444651347308266584430516013229815570706872276819", "price": "0.958", "size": "95.23", "side": "SELL", "timestamp": "1768475269137", "received_at": "2026-01-15T12:07:49.255884"}}
{"event_type": "price_change", "event_ts": "2026-01-15T12:07:49.290741", "ingestion_ts": "2026-01-15T12:08:42.168746", "market_id": "0xc0e6b917320a47228fb96e3b5ae0e5c93773a5ae2662ae4e1f37807cfe47ce98", "raw": {"market": "0xc0e6b917320a47228fb96e3b5ae0e5c93773a5ae2662ae4e1f37807cfe47ce98", "asset_id": "58656358377246279051017109359677190749228949103591068167284263961542487110215", "price": "0.005", "size": "12.09", "side": "BUY", "timestamp": "1768475269171", "received_at": "2026-01-15T12:07:49.290741"}}
