{"event_type": "price_change", "event_ts": "2026-01-15T12:04:40.440290", "ingestion_ts": "2026-01-15T12:08:42.168746", "market_id": "0xcab7ba4a9133cfd407d7e73e5757e5abbace413b59421527a31113406c97815c", "raw": {"market": "0xcab7ba4a9133cfd407d7e73e5757e5abbace413b59421527a31113406c97815c", "asset_id": "96361925776989336186111887920533578209326565663637092688733016597062311745569", "price": "0.006", "size": "136.13", "side": "BUY", "timestamp": "1768475080321", "received_at": "2026-01-15T12:04:40.440290"}}
{"event_type": "price_change", "event_ts": "2026-01-15T12:04:40.440290", "ingestion_ts": "2026-01-15T12:08:42.168746", "market_id": "0xcab7ba4a9133cfd407d7e73e5757e5abbace413b59421527a31113406c97815c", "raw": {"market": "0xcab7ba4a9133cfd407d7e73e5757e5abbace413b59421527a31113406c97815c", "asset_id": "20002636398944597965698652220992177552927816915094913583821579024925426590022", "price": "0.994", "size": "136.13", "side": "SELL", "timestamp": "1768475080321", "received_at": "2026-01-15T12:04:40.440290"}}
{"event_type": "price_change", "event_ts": "2026-01-15T12:04:40.440334", "ingestion_ts": "2026-01-15T12:08:42.168746", "market_id": "0xcab7ba4a9133cfd407d7e73e5757e5abbace413b59421527a31113406c97815c", "raw": {"market": "0xcab7ba4a9133cfd407d7e73e5757e5abbace413b59421527a31113406c97815c", "asset_id": "96361925776989336186111887920533578209326565663637092688733016597062311745569", "price": "0.008", "size": "631.87", "side": "BUY", "timestamp": "1768475080322", "received_at": "2026-01-15T12:04:40.440334"}}
{"event_type": "price_change", "event_ts": "2026-01-15T12:04:40.440334", "ingestion_ts": "2026-01-15T12:08:42.168746", "market_id": "0xcab7ba4a9133cfd407d7e73e5757e5abbace413b59421527a31113406c97815c", "raw": {"market": "0xcab7ba4a9133cfd407d7e73e5757e5abbace413b59421527a31113406c97815c", "asset_id": "20002636398944597965698652220992177552927816915094913583821579024925426590022", "price": "0.992", "size": "631.87", "side": "SELL", "timestamp": "1768475080322", "received_at": "2026-01-15T12:04:40.440334"}}
{"event_type": "price_change", "event_ts": "2026-01-15T12:04:40.834591", "ingestion_ts": "2026-01-15T12:08:42.168746", "market_id": "0xc0e6b917320a47228fb96e3b5ae0e5c93773a5ae2662ae4e1f37807cfe47ce98", "raw": {"market": "0xc0e6b917320a47228fb96e3b5ae0e5c93773a5ae2662ae4e1f37807cfe47ce98", "asset_id": "58656358377246279051017109359677190749228949103591068167284263961542487110215", "price": "0.003", "size": "457.97", "side": "BUY", "timestamp": "1768475080715", "received_at": "2026-01-15T12:04:40.834591"}}
{"event_type": "price_change", "event_ts": "2026-01-15T12:04:40.834591", "ingestion_ts": "2026-01-15T12:08:42.168746", "market_id": "0xc0e6b917320a47228fb96e3b5ae0e5c93773a5ae2662ae4e1f37807cfe47ce98", "raw": {"market": "0xc0e6b917320a47228fb96e3b5ae0e5c93773a5ae2662ae4e1f37807cfe47ce98", "asset_id": "81647294538046680798858716589766492074338758116170717123345952330712416337530", "price": "0.997", "size": "457.97", "side": "SELL", "timestamp": "1768475080715", "received_at": "2026-01-15T12:04:40.834591"}}
{"event_type": "price_change", "event_ts": "2026-01-15T12:04:41.913460", "ingestion_ts": "2026-01-15T12:08:42.168746", "market_id": "0xcab7ba4a9133cfd407d7e73e5757e5abbace413b59421527a31113406c97815c", "raw": {"market": "0xcab7ba4a9133cfd407d7e73e5757e5abbace413b59421527a31113406c97815c", "asset_id": "96361925776989336186111887920533578209326565663637092688733016597062311745569", "price": "0.006", "size": "127.41", "side": "BUY", "timestamp": "1768475081789", "received_at": "2026-01-15T12:04:41.913460"}}
{"event_type": "price_change", "event_ts": "2026-01-15T12:04:41.913460", "ingestion_ts": "2026-01-15T12:08:42.168746", "market_id": "0xcab7ba4a9133cfd407d7e73e5757e5abbace413b59421527a31113406c97815c", "raw": {"market": "0xcab7ba4a9133cfd407d7e73e5757e5abbace413b59421527a31113406c97815c", "asset_id": "20002636398944597965698652220992177552927816915094913583821579024925426590022", "price": "0.994", "size": "127.41", "side": "SELL", "timestamp": "1768475081789", "received_at": "2026-01-15T12:04:41.913460"}}
{"event_type": "price_change", "event_ts": "2026-01-15T12:04:41.913558", "ingestion_ts": "2026-01-15T12:08:42.168746", "market_id": "0xcab7ba4a9133cfd407d7e73e5757e5abbace413b59421527a31113406c97815c", "raw": {"market": "0xcab7ba4a9133cfd407d7e73e5757e5abbace413b59421527a31113406c97815c", "asset_id": "96361925776989336186111887920533578209326565663637092688733016597062311745569", "price": "0.008", "size": "619.71", "side": "BUY", "timestamp": "1768475081789", "received_at": "2026-01-15T12:04:41.913558"}}
{"event_type": "price_change", "event_ts": "2026-01-15T12:04:41.913558", "ingestion_ts": "2026-01-15T12:08:42.168746", "market_id": "0xcab7ba4a9133cfd407d7e73e5757e5abbace413b59421527a31113406c97815c", "raw": {"market": "0xcab7ba4a9133cfd407d7e73e5757e5abbace413b59421527a31113406c97815c", "asset_id": "20002636398944597965698652220992177552927816915094913583821579024925426590022", "price": "0.992", "size": "619.71", "side": "SELL", "timestamp": "1768475081789", "received_at": "2026-01-15T12:04:41.913558"}}
{"event_type": "price_change", "event_ts": "2026-01-15T12:04:42.414517", "ingestion_ts": "2026-01-15T12:08:42.168746", "market_id": "0xcab7ba4a9133cfd407d7e73e5757e5abbace413b59421527a31113406c97815c", "raw": {"market": "0xcab7ba4a9133cfd407d7e73e5757e5abbace413b59421527a31113406c97815c", "asset_id": "96361925776989336186111887920533578209326565663637092688733016597062311745569", "price": "0.006", "size": "136.13", "side": "BUY", "timestamp": "1768475082288", "received_at": "2026-01-15T12:04:42.414517"}}
{"event_type": "price_change", "event_ts": "2026-01-15T12:04:42.414517", "ingestion_ts": "2026-01-15T12:08:42.168746", "market_id": "0xcab7ba4a9133cfd407d7e73e5757e5abbace413b59421527a31113406c97815c", "raw": {"market": "0xcab7ba4a9133cfd407d7e73e5757e5abbace413b59421527a31113406c97815c", "asset_id": "20002636398944597965698652220992177552927816915094913583821579024925426590022", "price": "0.994", "size": "136.13", "side": "SELL", "timestamp": "1768475082288", "received_at": "2026-01-15T12:04:42.414517"}}
{"event_type": "price_change", "event_ts": "2026-01-15T12:04:42.415873", "ingestion_ts": "2026-01-15T12:08:42.168746", "market_id": "0xcab7ba4a9133cfd407d7e73e5757e5abbace413b59421527a31113406c97815c", "raw": {"market": "0xcab7ba4a9133cfd407d7e73e5757e5abbace413b59421527a31113406c97815c", "asset_id": "96361925776989336186111887920533578209326565663637092688733016597062311745569", "price": "0.008", "size": "631.87", "side": "BUY", "timestamp": "1768475082289", "received_at": "2026-01-15T12:04:42.415873"}}
{"event_type": "price_change", "event_ts": "2026-01-15T12:04:42.415873", "ingestion_ts": "2026-01-15T12:08:42.168746", "market_id": "0xcab7ba4a9133cfd407d7e73e5757e5abbace413b59421527a31113406c97815c", "raw": {"market": "0xcab7ba4a9133cfd407d7e73e5757e5abbace413b59421527a31113406c97815c", "asset_id": "20002636398944597965698652220992177552927816915094913583821579024925426590022", "price": "0.992", "size": "631.87", "side": "SELL", "timestamp": "1768475082289", "received_at": "2026-01-15T12:04:42.415873"}}
{"event_type": "price_change", "event_ts": "2026-01-15T12:04:44.755748", "ingestion_ts": "2026-01-15T12:08:42.168746", "market_id": "0xc0e6b917320a47228fb96e3b5ae0e5c93773a5ae2662ae4e1f37807cfe47ce98", "raw": {"market": "0xc0e6b917320a47228fb96e3b5ae0e5c93773a5ae2662ae4e1f37807cfe47ce98", "asset_id": "58656358377246279051017109359677190749228949103591068167284263961542487110215", "price": "0.003", "size": "300.37", "side": "BUY", "timestamp": "1768475084631", "received_at": "2026-01-15T12:04:44.755748"}}
{"event_type": "price_change", "event_ts": "2026-01-15T12:04:44.755748", "ingestion_ts": "2026-01-15T12:08:42.168746", "market_id": "0xc0e6b917320a47228fb96e3b5ae0e5c93773a5ae2662ae4e1f37807cfe47ce98", "raw": {"market": "0xc0e6b917320a47228fb96e3b5ae0e5c93773a5ae2662ae4e1f37807cfe47ce98", "asset_id": "81647294538046680798858716589766492074338758116170717123345952330712416337530", "price": "0.997", "size": "300.37", "side": "SELL", "timestamp": "1768475084631", "received_at": "2026-01-15T12:04:44.755748"}}
{"event_type": "price_change", "event_ts": "2026-01-15T12:04:44.755842", "ingestion_ts": "2026-01-15T12:08:42.168746", "market_id": "0xcab7ba4a9133cfd407d7e73e5757e5abbace413b59421527a31113406c97815c", "raw": {"market": "0xcab7ba4a9133cfd407d7e73e5757e5abbace413b59421527a31113406c97815c", "asset_id": "96361925776989336186111887920533578209326565663637092688733016597062311745569", "price": "0.006", "size": "127.41", "side": "BUY", "timestamp": "1768475084631", "received_at": "2026-01-15T12:04:44.755842"}}
{"event_type": "price_change", "event_ts": "2026-01-15T12:04:44.755842", "ingestion_ts": "2026-01-15T12:08:42.168746", "market_id": "0xcab7ba4a9133cfd407d7e73e5757e5abbace413b59421527a31113406c97815c", "raw": {"market": "0xcab7ba4a9133cfd407d7e73e5757e5abbace413b59421527a31113406c97815c", "asset_id": "20002636398944597965698652220992177552927816915094913583821579024925426590022", "price": "0.994", "size": "127.41", "side": "SELL", "timestamp": "1768475084631", "received_at": "2026-01-15T12:04:44.755842"}}
{"event_type": "price_change", "event_ts": "2026-01-15T12:04:44.755883", "ingestion_ts": "2026-01-15T12:08:42.168746", "market_id": "0xcab7ba4a9133cfd407d7e73e5757e5abbace413b59421527a31113406c97815c", "raw": {"market": "0xcab7ba4a9133cfd407d7e73e5757e5abbace413b59421527a31113406c97815c", "asset_id": "96361925776989336186111887920533578209326565663637092688733016597062311745569", "price": "0.008", "size": "619.71", "side": "BUY", "timestamp": "1768475084631", "received_at": "2026-01-15T12:04:44.755883"}}
{"event_type": "price_change", "event_ts": "2026-01-15T12:04:44.755883", "ingestion_ts": "2026-01-15T12:08:42.168746", "market_id": "0xcab7ba4a9133cfd407d7e73e5757e5abbace413b59421527a31113406c97815c", "raw": {"market": "0xcab7ba4a9133cfd407d7e73e5757e5abbace413b59421527a31113406c97815c", "asset_id": "20002636398944597965698652220992177552927816915094913583821579024925426590022", "price": "0.992", "size": "619.71", "side": "SELL", "timestamp": "1768475084631", "received_at": "2026-01-15T12:04:44.755883"}}
{"event_type": "price_change", "event_ts": "2026-01-15T12:04:45.447224", "ingestion_ts": "2026-01-15T12:08:42.168746", "market_id": "0xcab7ba4a9133cfd407d7e73e5757e5abbace413b59421527a31113406c97815c", "raw": {"market": "0xcab7ba4a9133cfd407d7e73e5757e5abbace413b59421527a31113406c97815c", "asset_id": "96361925776989336186111887920533578209326565663637092688733016597062311745569", "price": "0.006", "size": "136.13", "side": "BUY", "timestamp": "1768475085326", "received_at": "2026-01-15T12:04:45.447224"}}
{"event_type": "price_change", "event_ts": "2026-01-15T12:04:45.447224", "ingestion_ts": "2026-01-15T12:08:42.168746", "market_id": "0xcab7ba4a9133cfd407d7e73e5757e5abbace413b59421527a31113406c97815c", "raw": {"market": "0xcab7ba4a9133cfd407d7e73e5757e5abbace413b59421527a31113406c97815c", "asset_id": "20002636398944597965698652220992177552927816915094913583821579024925426590022", "price": "0.994", "size": "136.13", "side": "SELL", "timestamp": "1768475085326", "received_at": "2026-01-15T12:04:45.447224"}}
{"event_type": "price_change", "event_ts": "2026-01-15T12:04:45.448495", "ingestion_ts": "2026-01-15T12:08:42.168746", "market_id": "0xc0e6b917320a47228fb96e3b5ae0e5c93773a5ae2662ae4e1f37807cfe47ce98", "raw": {"market": "0xc0e6b917320a47228fb96e3b5ae0e5c93773a5ae2662ae4e1f37807cfe47ce98", "asset_id": "58656358377246279051017109359677190749228949103591068167284263961542487110215", "price": "0.004", "size": "118.2", "side": "BUY", "timestamp": "1768475085327", "received_at": "2026-01-15T12:04:45.448495"}}
{"event_type": "price_change", "event_ts": "2026-01-15T12:04:45.448495", "ingestion_ts": "2026-01-15T12:08:42.168746", "market_id": "0xc0e6b917320a47228fb96e3b5ae0e5c93773a5ae2662ae4e1f37807cfe47ce98", "raw": {"market": "0xc0e6b917320a47228fb96e3b5ae0e5c93773a5ae2662ae4e1f37807cfe47ce98", "asset_id": "81647294538046680798858716589766492074338758116170717123345952330712416337530", "price": "0.996", "size": "118.2", "side": "SELL", "timestamp": "1768475085327", "received_at": "2026-01-15T12:04:45.448495"}}
{"event_type": "price_change", "event_ts": "2026-01-15T12:04:45.448584", "ingestion_ts": "2026-01-15T12:08:42.168746", "market_id": "0xcab7ba4a9133cfd407d7e73e5757e5abbace413b59421527a31113406c97815c", "raw": {"market": "0xcab7ba4a9133cfd407d7e73e5757e5abbace413b59421527a31113406c97815c", "asset_id": "96361925776989336186111887920533578209326565663637092688733016597062311745569", "price": "0.008", "size": "631.87", "side": "BUY", "timestamp": "1768475085328", "received_at": "2026-01-15T12:04:45.448584"}}
{"event_type": "price_change", "event_ts": "2026-01-15T12:04:45.448584", "ingestion_ts": "2026-01-15T12:08:42.168746", "market_id": "0xcab7ba4a9133cfd407d7e73e5757e5abbace413b59421527a31113406c97815c", "raw": {"market": "0xcab7ba4a9133cfd407d7e73e5757e5abbace413b59421527a31113406c97815c", "asset_id": "20002636398944597965698652220992177552927816915094913583821579024925426590022", "price": "0.992", "size": "631.87", "side": "SELL", "timestamp": "1768475085328", "received_at": "2026-01-15T12:04:45.448584"}}
{"event_type": "price_change", "event_ts": "2026-01-15T12:04:46.502282", "ingestion_ts": "2026-01-15T12:08:42.168746", "market_id": "0xcab7ba4a9133cfd407d7e73e5757e5abbace413b59421527a31113406c97815c", "raw": {"market": "0xcab7ba4a9133cfd407d7e73e5757e5abbace413b59421527a31113406c97815c", "asset_id": "96361925776989336186111887920533578209326565663637092688733016597062311745569", "price": "0.006", "size": "127.41", "side": "BUY", "timestamp": "1768475086380", "received_at": "2026-01-15T12:04:46.502282"}}
{"event_type": "price_change", "event_ts": "2026-01-15T12:04:46.502282", "ingestion_ts": "2026-01-15T12:08:42.168746", "market_id": "0xcab7ba4a9133cfd407d7e73e5757e5abbace413b59421527a31113406c97815c", "raw": {"market": "0xcab7ba4a9133cfd407d7e73e5757e5abbace413b59421527a31113406c97815c", "asset_id": "20002636398944597965698652220992177552927816915094913583821579024925426590022", "price": "0.994", "size": "127.41", "side": "SELL", "timestamp": "1768475086380", "received_at": "2026-01-15T12:04:46.502282"}}
{"event_type": "price_change", "event_ts": "2026-01-15T12:04:46.502411", "ingestion_ts": "2026-01-15T12:08:42.168746", "market_id": "0xcab7ba4a9133cfd407d7e73e5757e5abbace413b59421527a31113406c97815c", "raw": {"market": "0xcab7ba4a9133cfd407d7e73e5757e5abbace413b59421527a31113406c97815c", "asset_id": "96361925776989336186111887920533578209326565663637092688733016597062311745569", "price": "0.008", "size": "619.71", "side": "BUY", "timestamp": "1768475086380", "received_at": "2026-01-15T12:04:46.502411"}}
{"event_type": "price_change", "event_ts": "2026-01-15T12:04:46.502411", "ingestion_ts": "2026-01-15T12:08:42.168746", "market_id": "0xcab7ba4a9133cfd407d7e73e5757e5abbace413b59421527a31113406c97815c", "raw": {"market": "0xcab7ba4a9133cfd407d7e73e5757e5abbace413b59421527a31113406c97815c", "asset_id": "20002636398944597965698652220992177552927816915094913583821579024925426590022", "price": "0.992", "size": "619.71", "side": "SELL", "timestamp": "1768475086380", "received_at": "2026-01-15T12:04:46.502411"}}
{"event_type": "price_change", "event_ts": "2026-01-15T12:04:47.040539", "ingestion_ts": "2026-01-15T12:08:42.168746", "market_id": "0xcab7ba4a9133cfd407d7e73e5757e5abbace413b59421527a31113406c97815c", "raw": {"market": "0xcab7ba4a9133cfd407d7e73e5757e5abbace413b59421527a31113406c97815c", "asset_id": "96361925776989336186111887920533578209326565663637092688733016597062311745569", "price": "0.006", "size": "136.13", "side": "BUY", "timestamp": "1768475086922", "received_at": "2026-01-15T12:04:47.040539"}}
{"event_type": "price_change", "event_ts": "2026-01-15T12:04:47.040539", "ingestion_ts": "2026-01-15T12:08:42.168746", "market_id": "0xcab7ba4a9133cfd407d7e73e5757e5abbace413b59421527a31113406c97815c", "raw": {"market": "0xcab7ba4a9133cfd407d7e73e5757e5abbace413b59421527a31113406c97815c", "asset_id": "20002636398944597965698652220992177552927816915094913583821579024925426590022", "price": "0.994", "size": "136.13", "side": "SELL", "timestamp": "1768475086922", "received_at": "2026-01-15T12:04:47.040539"}}
{"event_type": "price_change", "event_ts": "2026-01-15T12:04:47.042233", "ingestion_ts": "2026-01-15T12:08:42.168746", "market_id": "0xcab7ba4a9133cfd407d7e73e5757e5abbace413b59421527a31113406c97815c", "raw": {"market": "0xcab7ba4a9133cfd407d7e73e5757e5abbace413b59421527a31113406c97815c", "asset_id": "96361925776989336186111887920533578209326565663637092688733016597062311745569", "price": "0.008", "size": "631.87", "side": "BUY", "timestamp": "1768475086923", "received_at": "2026-01-15T12:04:47.042233"}}
{"event_type": "price_change", "event_ts": "2026-01-15T12:04:47.042233", "ingestion_ts": "2026-01-15T12:08:42.168746", "market_id": "0xcab7ba4a9133cfd407d7e73e5757e5abbace413b59421527a31113406c97815c", "raw": {"market": "0xcab7ba4a9133cfd407d7e73e5757e5abbace413b59421527a31113406c97815c", "asset_id": "20002636398944597965698652220992177552927816915094913583821579024925426590022", "price": "0.992", "size": "631.87", "side": "SELL", "timestamp": "1768475086923", "received_at": "2026-01-15T12:04:47.042233"}}
{"event_type": "price_change", "event_ts": "2026-01-15T12:04:47.421288", "ingestion_ts": "2026-01-15T12:08:42.168746", "market_id": "0xc0e6b917320a47228fb96e3b5ae0e5c93773a5ae2662ae4e1f37807cfe47ce98", "raw": {"market": "0xc0e6b917320a47228fb96e3b5ae0e5c93773a5ae2662ae4e1f37807cfe47ce98", "asset_id": "58656358377246279051017109359677190749228949103591068167284263961542487110215", "price": "0.004", "size": "0", "side": "BUY", "timestamp": "1768475087303", "received_at": "2026-01-15T12:04:47.421288"}}
{"event_type": "price_change", "event_ts": "2026-01-15T12:04:47.421288", "ingestion_ts": "2026-01-15T12:08:42.168746", "market_id": "0xc0e6b917320a47228fb96e3b5ae0e5c93773a5ae2662ae4e1f37807cfe47ce98", "raw": {"market": "0xc0e6b917320a47228fb96e3b5ae0e5c93773a5ae2662ae4e1f37807cfe47ce98", "asset_id": "81647294538046680798858716589766492074338758116170717123345952330712416337530", "price": "0.996", "size": "0", "side": "SELL", "timestamp": "1768475087303", "received_at": "2026-01-15T12:04:47.421288"}}
{"event_type": "price_change", "event_ts": "2026-01-15T12:04:47.826106", "ingestion_ts": "2026-01-15T12:08:42.168746", "market_id": "0xc0e6b917320a47228fb96e3b5ae0e5c93773a5ae2662ae4e1f37807cfe47ce98", "raw": {"market": "0xc0e6b917320a47228fb96e3b5ae0e5c93773a5ae2662ae4e1f37807cfe47ce98", "asset_id": "58656358377246279051017109359677190749228949103591068167284263961542487110215", "price": "0.005", "size": "97.54", "side": "BUY", "timestamp": "1768475087707", "received_at": "2026-01-15T12:04:47.826106"}}
{"event_type": "price_change", "event_ts": "2026-01-15T12:04:47.826106", "ingestion_ts": "2026-01-15T12:08:42.168746", "market_id": "0xc0e6b917320a47228fb96e3b5ae0e5c93773a5ae2662ae4e1f37807cfe47ce98", "raw": {"market": "0xc0e6b917320a47228fb96e3b5ae0e5c93773a5ae2662ae4e1f37807cfe47ce98", "asset_id": "81647294538046680798858716589766492074338758116170717123345952330712416337530", "price": "0.995", "size": "97.54", "side": "SELL", "timestamp": "1768475087707", "received_at": "2026-01-15T12:04:47.826106"}}
{"event_type": "price_change", "event_ts": "2026-01-15T12:04:48.733391", "ingestion_ts": "2026-01-15T12:08:42.168746", "market_id": "0xcab7ba4a9133cfd407d7e73e5757e5abbace413b59421527a31113406c97815c", "raw": {"market": "0xcab7ba4a9133cfd407d7e73e5757e5abbace413b59421527a31113406c97815c", "asset_id": "96361925776989336186111887920533578209326565663637092688733016597062311745569", "price": "0.006", "size": "127.41", "side": "BUY", "timestamp": "1768475088608", "received_at": "2026-01-15T12:04:48.733391"}}
{"event_type": "price_change", "event_ts": "2026-01-15T12:04:48.733391", "ingestion_ts": "2026-01-15T12:08:42.168746", "market_id": "0xcab7ba4a9133cfd407d7e73e5757e5abbace413b59421527a31113406c97815c", "raw": {"market": "0xcab7ba4a9133cfd407d7e73e5757e5abbace413b59421527a31113406c97815c", "asset_id": "20002636398944597965698652220992177552927816915094913583821579024925426590022", "price": "0.994", "size": "127.41", "side": "SELL", "timestamp": "1768475088608", "received_at": "2026-01-15T12:04:48.733391"}}
{"event_type": "price_change", "event_ts": "2026-01-15T12:04:48.733478", "ingestion_ts": "2026-01-15T12:08:42.168746", "market_id": "0xcab7ba4a9133cfd407d7e73e5757e5abbace413b59421527a31113406c97815c", "raw": {"market": "0xcab7ba4a9133cfd407d7e73e5757e5abbace413b59421527a31113406c97815c", "asset_id": "96361925776989336186111887920533578209326565663637092688733016597062311745569", "price": "0.008", "size": "619.71", "side": "BUY", "timestamp": "1768475088608", "received_at": "2026-01-15T12:04:48.733478"}}
{"event_type": "price_change", "event_ts": "2026-01-15T12:04:48.733478", "ingestion_ts": "2026-01-15T12:08:42.168746", "market_id": "0xcab7ba4a9133cfd407d7e73e5757e5abbace413b59421527a31113406c97815c", "raw": {"market": "0xcab7ba4a9133cfd407d7e73e5757e5abbace413b59421527a31113406c97815c", "asset_id": "20002636398944597965698652220992177552927816915094913583821579024925426590022", "price": "0.992", "size": "619.71", "side": "SELL", "timestamp": "1768475088608", "received_at": "2026-01-15T12:04:48.733478"}}
{"event_type": "price_change", "event_ts": "2026-01-15T12:04:49.362376", "ingestion_ts": "2026-01-15T12:08:42.168746", "market_id": "0xcab7ba4a9133cfd407d7e73e5757e5abbace413b59421527a31113406c97815c", "raw": {"market": "0xcab7ba4a9133cfd407d7e73e5757e5abbace413b59421527a31113406c97815c", "asset_id": "96361925776989336186111887920533578209326565663637092688733016597062311745569", "price": "0.008", "size": "631.87", "side": "BUY", "timestamp": "1768475089237", "received_at": "2026-01-15T12:04:49.362376"}}
{"event_type": "price_change", "event_ts": "2026-01-15T12:04:49.362376", "ingestion_ts": "2026-01-15T12:08:42.168746", "market_id": "0xcab7ba4a9133cfd407d7e73e5757e5abbace413b59421527a31113406c97815c", "raw": {"market": "0xcab7ba4a9133cfd407d7e73e5757e5abbace413b59421527a31113406c97815c", "asset_id": "20002636398944597965698652220992177552927816915094913583821579024925426590022", "price": "0.992", "size": "631.87", "side": "SELL", "timestamp": "1768475089237", "received_at": "2026-01-15T12:04:49.362376"}}
{"event_type": "price_change", "event_ts": "2026-01-15T12:04:49.362471", "ingestion_ts": "2026-01-15T12:08:42.168746", "market_id": "0xcab7ba4a9133cfd407d7e73e5757e5abbace413b59421527a31113406c97815c", "raw": {"market": "0xcab7ba4a9133cfd407d7e73e5757e5abbace413b59421527a31113406c97815c", "asset_id": "96361925776989336186111887920533578209326565663637092688733016597062311745569", "price": "0.006", "size": "136.13", "side": "BUY", "timestamp": "1768475089238", "received_at": "2026-01-15T12:04:49.362471"}}
{"event_type": "price_change", "event_ts": "2026-01-15T12:04:49.362471", "ingestion_ts": "2026-01-15T12:08:42.168746", "market_id": "0xcab7ba4a9133cfd407d7e73e5757e5abbace413b59421527a31113406c97815c", "raw": {"market": "0xcab7ba4a9133cfd407d7e73e5757e5abbace413b59421527a31113406c97815c", "asset_id": "20002636398944597965698652220992177552927816915094913583821579024925426590022", "price": "0.994", "size": "136.13", "side": "SELL", "timestamp": "1768475089238", "received_at": "2026-01-15T12:04:49.362471"}}
{"event_type": "price_change", "event_ts": "2026-01-15T12:04:50.118685", "ingestion_ts": "2026-01-15T12:08:42.168746", "market_id": "0xc0e6b917320a47228fb96e3b5ae0e5c93773a5ae2662ae4e1f37807cfe47ce98", "raw": {"market": "0xc0e6b917320a47228fb96e3b5ae0e5c93773a5ae2662ae4e1f37807cfe47ce98", "asset_id": "58656358377246279051017109359677190749228949103591068167284263961542487110215", "price": "0.003", "size": "287.91", "side": "BUY", "timestamp": "1768475090000", "received_at": "2026-01-15T12:04:50.118685"}}
{"event_type": "price_change", "event_ts": "2026-01-15T12:04:50.118685", "ingestion_ts": "2026-01-15T12:08:42.168746", "market_id": "0xc0e6b917320a47228fb96e3b5ae0e5c93773a5ae2662ae4e1f37807cfe47ce98", "raw": {"market": "0xc0e6b917320a47228fb96e3b5ae0e5c93773a5ae2662ae4e1f37807cfe47ce98", "asset_id": "81647294538046680798858716589766492074338758116170717123345952330712416337530", "price": "0.997", "size": "287.91", "side": "SELL", "timestamp": "1768475090000", "received_at": "2026-01-15T12:04:50.118685"}}
{"event_type": "price_change", "event_ts": "2026-01-15T12:04:50.125687", "ingestion_ts": "2026-01-15T12:08:42.168746", "market_id": "0xc0e6b917320a47228fb96e3b5ae0e5c93773a5ae2662ae4e1f37807cfe47ce98", "raw": {"market": "0xc0e6b917320a47228fb96e3b5ae0e5c93773a5ae2662ae4e1f37807cfe47ce98", "asset_id": "58656358377246279051017109359677190749228949103591068167284263961542487110215", "price": "0.003", "size": "287.91", "side": "BUY", "timestamp": "1768475090000", "received_at": "2026-01-15T12:04:50.125687"}}
{"event_type": "price_change", "event_ts": "2026-01-15T12:04:50.125687", "ingestion_ts": "2026-01-15T12:08:42.168746", "market_id": "0xc0e6b917320a47228fb96e3b5ae0e5c93773a5ae2662ae4e1f37807cfe47ce98", "raw": {"market": "0xc0e6b917320a47228fb96e3b5ae0e5c93773a5ae2662ae4e1f37807cfe47ce98", "asset_id": "81647294538046680798858716589766492074338758116170717123345952330712416337530", "price": "0.997", "size": "287.91", "side": "SELL", "timestamp": "1768475090000", "received_at": "2026-01-15T12:04:50.125687"}}
{"event_type": "price_change", "event_ts": "2026-01-15T12:04:50.214759", "ingestion_ts": "2026-01-15T12:08:42.168746", "market_id": "0x50c669f178da4e5bbea7f1be25041fd278914712fa87a6a6f8e57d5923d88dee", "raw": {"market": "0x50c669f178da4e5bbea7f1be25041fd278914712fa87a6a6f8e57d5923d88dee", "asset_id": "74040420326294854165772767082819937451857852955603897473157746262672057685461", "price": "0.469", "size": "0", "side": "BUY", "timestamp": "1768475090096", "received_at": "2026-01-15T12:04:50.214759"}}
{"event_type": "price_change", "event_ts": "2026-01-15T12:04:50.214759", "ingestion_ts": "2026-01-15T12:08:42.168746", "market_id": "0x50c669f178da4e5bbea7f1be25041fd278914712fa87a6a6f8e57d5923d88dee", "raw": {"market": "0x50c669f178da4e5bbea7f1be25041fd278914712fa87a6a6f8e57d5923d88dee", "asset_id": "24682525479474221428144937281315825971983904267399062415430320764754931667953", "price": "0.531", "size": "0", "side": "SELL", "timestamp": "1768475090096", "received_at": "2026-01-15T12:04:50.214759"}}
{"event_type": "price_change", "event_ts": "2026-01-15T12:04:50.267686", "ingestion_ts": "2026-01-15T12:08:42.168746", "market_id": "0x50c669f178da4e5bbea7f1be25041fd278914712fa87a6a6f8e57d5923d88dee", "raw": {"market": "0x50c669f178da4e5bbea7f1be25041fd278914712fa87a6a6f8e57d5923d88dee", "asset_id": "74040420326294854165772767082819937451857852955603897473157746262672057685461", "price": "0.469", "size": "5", "side": "BUY", "timestamp": "1768475090149", "received_at": "2026-01-15T12:04:50.267686"}}
{"event_type": "price_change", "event_ts": "2026-01-15T12:04:50.267686", "ingestion_ts": "2026-01-15T12:08:42.168746", "market_id": "0x50c669f178da4e5bbea7f1be25041fd278914712fa87a6a6f8e57d5923d88dee", "raw": {"market": "0x50c669f178da4e5bbea7f1be25041fd278914712fa87a6a6f8e57d5923d88dee", "asset_id": "24682525479474221428144937281315825971983904267399062415430320764754931667953", "price": "0.531", "size": "5", "side": "SELL", "timestamp": "1768475090149", "received_at": "2026-01-15T12:04:50.267686"}}
{"event_type": "price_change", "event_ts": "2026-01-15T12:04:51.446528", "ingestion_ts": "2026-01-15T12:08:42.168746", "market_id": "0xc0e6b917320a47228fb96e3b5ae0e5c93773a5ae2662ae4e1f37807cfe47ce98", "raw": {"market": "0xc0e6b917320a47228fb96e3b5ae0e5c93773a5ae2662ae4e1f37807cfe47ce98", "asset_id": "58656358377246279051017109359677190749228949103591068167284263961542487110215", "price": "0.005", "size": "2.98", "side": "BUY", "timestamp": "1768475091315", "received_at": "2026-01-15T12:04:51.446528"}}
{"event_type": "price_change", "event_ts": "2026-01-15T12:04:51.446528", "ingestion_ts": "2026-01-15T12:08:42.168746", "market_id": "0xc0e6b917320a47228fb96e3b5ae0e5c93773a5ae2662ae4e1f37807cfe47ce98", "raw": {"market": "0xc0e6b917320a47228fb96e3b5ae0e5c93773a5ae2662ae4e1f37807cfe47ce98", "asset_id": "81647294538046680798858716589766492074338758116170717123345952330712416337530", "price": "0.995", "size": "2.98", "side": "SELL", "timestamp": "1768475091315", "received_at": "2026-01-15T12:04:51.446528"}}
{"event_type": "price_change", "event_ts": "2026-01-15T12:04:51.446627", "ingestion_ts": "2026-01-15T12:08:42.168746", "market_id": "0xcab7ba4a9133cfd407d7e73e5757e5abbace413b59421527a31113406c97815c", "raw": {"market": "0xcab7ba4a9133cfd407d7e73e5757e5abbace413b59421527a31113406c97815c", "asset_id": "96361925776989336186111887920533578209326565663637092688733016597062311745569", "price": "0.006", "size": "127.41", "side": "BUY", "timestamp": "1768475091315", "received_at": "2026-01-15T12:04:51.446627"}}
{"event_type": "price_change", "event_ts": "2026-01-15T12:04:51.446627", "ingestion_ts": "2026-01-15T12:08:42.168746", "market_id": "0xcab7ba4a9133cfd407d7e73e5757e5abbace413b59421527a31113406c97815c", "raw": {"market": "0xcab7ba4a9133cfd407d7e73e5757e5abbace413b59421527a31113406c97815c", "asset_id": "20002636398944597965698652220992177552927816915094913583821579024925426590022", "price": "0.994", "size": "127.41", "side": "SELL", "timestamp": "1768475091315", "received_at": "2026-01-15T12:04:51.446627"}}
{"event_type": "price_change", "event_ts": "2026-01-15T12:04:51.446667", "ingestion_ts": "2026-01-15T12:08:42.168746", "market_id": "0xcab7ba4a9133cfd407d7e73e5757e5abbace413b59421527a31113406c97815c", "raw": {"market": "0xcab7ba4a9133cfd407d7e73e5757e5abbace413b59421527a31113406c97815c", "asset_id": "96361925776989336186111887920533578209326565663637092688733016597062311745569", "price": "0.008", "size": "619.71", "side": "BUY", "timestamp": "1768475091315", "received_at": "2026-01-15T12:04:51.446667"}}
{"event_type": "price_change", "event_ts": "2026-01-15T12:04:51.446667", "ingestion_ts": "2026-01-15T12:08:42.168746", "market_id": "0xcab7ba4a9133cfd407d7e73e5757e5abbace413b59421527a31113406c97815c", "raw": {"market": "0xcab7ba4a9133cfd407d7e73e5757e5abbace413b59421527a31113406c97815c", "asset_id": "20002636398944597965698652220992177552927816915094913583821579024925426590022", "price": "0.992", "size": "619.71", "side": "SELL", "timestamp": "1768475091315", "received_at": "2026-01-15T12:04:51.446667"}}
{"event_type": "price_change", "event_ts": "2026-01-15T12:04:52.050948", "ingestion_ts": "2026-01-15T12:08:42.168746", "market_id": "0xc0e6b917320a47228fb96e3b5ae0e5c93773a5ae2662ae4e1f37807cfe47ce98", "raw": {"market": "0xc0e6b917320a47228fb96e3b5ae0e5c93773a5ae2662ae4e1f37807cfe47ce98", "asset_id": "58656358377246279051017109359677190749228949103591068167284263961542487110215", "price": "0.003", "size": "457.97", "side": "BUY", "timestamp": "1768475091929", "received_at": "2026-01-15T12:04:52.050948"}}
{"event_type": "price_change", "event_ts": "2026-01-15T12:04:52.050948", "ingestion_ts": "2026-01-15T12:08:42.168746", "market_id": "0xc0e6b917320a47228fb96e3b5ae0e5c93773a5ae2662ae4e1f37807cfe47ce98", "raw": {"market": "0xc0e6b917320a47228fb96e3b5ae0e5c93773a5ae2662ae4e1f37807cfe47ce98", "asset_id": "81647294538046680798858716589766492074338758116170717123345952330712416337530", "price": "0.997", "size": "457.97", "side": "SELL", "timestamp": "1768475091929", "received_at": "2026-01-15T12:04:52.050948"}}
{"event_type": "price_change", "event_ts": "2026-01-15T12:04:52.054335", "ingestion_ts": "2026-01-15T12:08:42.168746", "market_id": "0xcab7ba4a9133cfd407d7e73e5757e5abbace413b59421527a31113406c97815c", "raw": {"market": "0xcab7ba4a9133cfd407d7e73e5757e5abbace413b59421527a31113406c97815c", "asset_id": "96361925776989336186111887920533578209326565663637092688733016597062311745569", "price": "0.008", "size": "631.87", "side": "BUY", "timestamp": "1768475091929", "received_at": "2026-01-15T12:04:52.054335"}}
{"event_type": "price_change", "event_ts": "2026-01-15T12:04:52.054335", "ingestion_ts": "2026-01-15T12:08:42.168746", "market_id": "0xcab7ba4a9133cfd407d7e73e5757e5abbace413b59421527a31113406c97815c", "raw": {"market": "0xcab7ba4a9133cfd407d7e73e5757e5abbace413b59421527a31113406c97815c", "asset_id": "20002636398944597965698652220992177552927816915094913583821579024925426590022", "price": "0.992", "size": "631.87", "side": "SELL", "timestamp": "1768475091929", "received_at": "2026-01-15T12:04:52.054335"}}
{"event_type": "price_change", "event_ts": "2026-01-15T12:04:52.054423", "ingestion_ts": "2026-01-15T12:08:42.168746", "market_id": "0xcab7ba4a9133cfd407d7e73e5757e5abbace413b59421527a31113406c97815c", "raw": {"market": "0xcab7ba4a9133cfd407d7e73e5757e5abbace413b59421527a31113406c97815c", "asset_id": "96361925776989336186111887920533578209326565663637092688733016597062311745569", "price": "0.006", "size": "136.13", "side": "BUY", "timestamp": "1768475091930", "received_at": "2026-01-15T12:04:52.054423"}}
{"event_type": "price_change", "event_ts": "2026-01-15T12:04:52.054423", "ingestion_ts": "2026-01-15T12:08:42.168746", "market_id": "0xcab7ba4a9133cfd407d7e73e5757e5abbace413b59421527a31113406c97815c", "raw": {"market": "0xcab7ba4a9133cfd407d7e73e5757e5abbace413b59421527a31113406c97815c", "asset_id": "20002636398944597965698652220992177552927816915094913583821579024925426590022", "price": "0.994", "size": "136.13", "side": "SELL", "timestamp": "1768475091930", "received_at": "2026-01-15T12:04:52.054423"}}
{"event_type": "price_change", "event_ts": "2026-01-15T12:04:52.412951", "ingestion_ts": "2026-01-15T12:08:42.168746", "market_id": "0x50e477f0b316a3d97d60486479657c63be0763834d0e2e8a30b1b86dc3c1c001", "raw": {"market": "0x50e477f0b316a3d97d60486479657c63be0763834d0e2e8a30b1b86dc3c1c001", "asset_id": "39981134260608444876865205057565852475343967395624370698967311821208058420507", "price": "0.353", "size": "0", "side": "BUY", "timestamp": "1768475092295", "received_at": "2026-01-15T12:04:52.412951"}}
{"event_type": "price_change", "event_ts": "2026-01-15T12:04:52.412951", "ingestion_ts": "2026-01-15T12:08:42.168746", "market_id": "0x50e477f0b316a3d97d60486479657c63be0763834d0e2e8a30b1b86dc3c1c001", "raw": {"market": "0x50e477f0b316a3d97d60486479657c63be0763834d0e2e8a30b1b86dc3c1c001", "asset_id": "60573178197991590327120832143415406583517170365625050489007297367895074266641", "price": "0.647", "size": "0", "side": "SELL", "timestamp": "1768475092295", "received_at": "2026-01-15T12:04:52.412951"}}
{"event_type": "price_change", "event_ts": "2026-01-15T12:04:52.460082", "ingestion_ts": "2026-01-15T12:08:42.168746", "market_id": "0x50e477f0b316a3d97d60486479657c63be0763834d0e2e8a30b1b86dc3c1c001", "raw": {"market": "0x50e477f0b316a3d97d60486479657c63be0763834d0e2e8a30b1b86dc3c1c001", "asset_id": "39981134260608444876865205057565852475343967395624370698967311821208058420507", "price": "0.353", "size": "5", "side": "BUY", "timestamp": "1768475092343", "received_at": "2026-01-15T12:04:52.460082"}}
{"event_type": "price_change", "event_ts": "2026-01-15T12:04:52.460082", "ingestion_ts": "2026-01-15T12:08:42.168746", "market_id": "0x50e477f0b316a3d97d60486479657c63be0763834d0e2e8a30b1b86dc3c1c001", "raw": {"market": "0x50e477f0b316a3d97d60486479657c63be0763834d0e2e8a30b1b86dc3c1c001", "asset_id": "60573178197991590327120832143415406583517170365625050489007297367895074266641", "price": "0.647", "size": "5", "side": "SELL", "timestamp": "1768475092343", "received_at": "2026-01-15T12:04:52.460082"}}
{"event_type": "price_change", "event_ts": "2026-01-15T12:04:55.317133", "ingestion_ts": "2026-01-15T12:08:42.168746", "market_id": "0xcab7ba4a9133cfd407d7e73e5757e5abbace413b59421527a31113406c97815c", "raw": {"market": "0xcab7ba4a9133cfd407d7e73e5757e5abbace413b59421527a31113406c97815c", "asset_id": "96361925776989336186111887920533578209326565663637092688733016597062311745569", "price": "0.006", "size": "127.41", "side": "BUY", "timestamp": "1768475095188", "received_at": "2026-01-15T12:04:55.317133"}}
{"event_type": "price_change", "event_ts": "2026-01-15T12:04:55.317133", "ingestion_ts": "2026-01-15T12:08:42.168746", "market_id": "0xcab7ba4a9133cfd407d7e73e5757e5abbace413b59421527a31113406c97815c", "raw": {"market": "0xcab7ba4a9133cfd407d7e73e5757e5abbace413b59421527a31113406c97815c", "asset_id": "20002636398944597965698652220992177552927816915094913583821579024925426590022", "price": "0.994", "size": "127.41", "side": "SELL", "timestamp": "1768475095188", "received_at": "2026-01-15T12:04:55.317133"}}
{"event_type": "price_change", "event_ts": "2026-01-15T12:04:55.317239", "ingestion_ts": "2026-01-15T12:08:42.168746", "market_id": "0xcab7ba4a9133cfd407d7e73e5757e5abbace413b59421527a31113406c97815c", "raw": {"market": "0xcab7ba4a9133cfd407d7e73e5757e5abbace413b59421527a31113406c97815c", "asset_id": "96361925776989336186111887920533578209326565663637092688733016597062311745569", "price": "0.008", "size": "619.71", "side": "BUY", "timestamp": "1768475095188", "received_at": "2026-01-15T12:04:55.317239"}}
{"event_type": "price_change", "event_ts": "2026-01-15T12:04:55.317239", "ingestion_ts": "2026-01-15T12:08:42.168746", "market_id": "0xcab7ba4a9133cfd407d7e73e5757e5abbace413b59421527a31113406c97815c", "raw": {"market": "0xcab7ba4a9133cfd407d7e73e5757e5abbace413b59421527a31113406c97815c", "asset_id": "20002636398944597965698652220992177552927816915094913583821579024925426590022", "price": "0.992", "size": "619.71", "side": "SELL", "timestamp": "1768475095188", "received_at": "2026-01-15T12:04:55.317239"}}
{"event_type": "price_change", "event_ts": "2026-01-15T12:04:55.759123", "ingestion_ts": "2026-01-15T12:08:42.168746", "market_id": "0xc0e6b917320a47228fb96e3b5ae0e5c93773a5ae2662ae4e1f37807cfe47ce98", "raw": {"market": "0xc0e6b917320a47228fb96e3b5ae0e5c93773a5ae2662ae4e1f37807cfe47ce98", "asset_id": "58656358377246279051017109359677190749228949103591068167284263961542487110215", "price": "0.003", "size": "287.91", "side": "BUY", "timestamp": "1768475095639", "received_at": "2026-01-15T12:04:55.759123"}}
{"event_type": "price_change", "event_ts": "2026-01-15T12:04:55.759123", "ingestion_ts": "2026-01-15T12:08:42.168746", "market_id": "0xc0e6b917320a47228fb96e3b5ae0e5c93773a5ae2662ae4e1f37807cfe47ce98", "raw": {"market": "0xc0e6b917320a47228fb96e3b5ae0e5c93773a5ae2662ae4e1f37807cfe47ce98", "asset_id": "81647294538046680798858716589766492074338758116170717123345952330712416337530", "price": "0.997", "size": "287.91", "side": "SELL", "timestamp": "1768475095639", "received_at": "2026-01-15T12:04:55.759123"}}
{"event_type": "price_change", "event_ts": "2026-01-15T12:04:55.797193", "ingestion_ts": "2026-01-15T12:08:42.168746", "market_id": "0xcab7ba4a9133cfd407d7e73e5757e5abbace413b59421527a31113406c97815c", "raw": {"market": "0xcab7ba4a9133cfd407d7e73e5757e5abbace413b59421527a31113406c97815c", "asset_id": "96361925776989336186111887920533578209326565663637092688733016597062311745569", "price": "0.006", "size": "136.13", "side": "BUY", "timestamp": "1768475095673", "received_at": "2026-01-15T12:04:55.797193"}}
{"event_type": "price_change", "event_ts": "2026-01-15T12:04:55.797193", "ingestion_ts": "2026-01-15T12:08:42.168746", "market_id": "0xcab7ba4a9133cfd407d7e73e5757e5abbace413b59421527a31113406c97815c", "raw": {"market": "0xcab7ba4a9133cfd407d7e73e5757e5abbace413b59421527a31113406c97815c", "asset_id": "20002636398944597965698652220992177552927816915094913583821579024925426590022", "price": "0.994", "size": "136.13", "side": "SELL", "timestamp": "1768475095673", "received_at": "2026-01-15T12:04:55.797193"}}
{"event_type": "price_change", "event_ts": "2026-01-15T12:04:55.797288", "ingestion_ts": "2026-01-15T12:08:42.168746", "market_id": "0xcab7ba4a9133cfd407d7e73e5757e5abbace413b59421527a31113406c97815c", "raw": {"market": "0xcab7ba4a9133cfd407d7e73e5757e5abbace413b59421527a31113406c97815c", "asset_id": "96361925776989336186111887920533578209326565663637092688733016597062311745569", "price": "0.008", "size": "631.87", "side": "BUY", "timestamp": "1768475095674", "received_at": "2026-01-15T12:04:55.797288"}}
{"event_type": "price_change", "event_ts": "2026-01-15T12:04:55.797288", "ingestion_ts": "2026-01-15T12:08:42.168746", "market_id": "0xcab7ba4a9133cfd407d7e73e5757e5abbace413b59421527a31113406c97815c", "raw": {"market": "0xcab7ba4a9133cfd407d7e73e5757e5abbace413b59421527a31113406c97815c", "asset_id": "20002636398944597965698652220992177552927816915094913583821579024925426590022", "price": "0.992", "size": "631.87", "side": "SELL", "timestamp": "1768475095674", "received_at": "2026-01-15T12:04:55.797288"}}
{"event_type": "price_change", "event_ts": "2026-01-15T12:04:56.158989", "ingestion_ts": "2026-01-15T12:08:42.168746", "market_id": "0xc0e6b917320a47228fb96e3b5ae0e5c93773a5ae2662ae4e1f37807cfe47ce98", "raw": {"market": "0xc0e6b917320a47228fb96e3b5ae0e5c93773a5ae2662ae4e1f37807cfe47ce98", "asset_id": "58656358377246279051017109359677190749228949103591068167284263961542487110215", "price": "0.004", "size": "127.55", "side": "BUY", "timestamp": "1768475096035", "received_at": "2026-01-15T12:04:56.158989"}}
{"event_type": "price_change", "event_ts": "2026-01-15T12:04:56.158989", "ingestion_ts": "2026-01-15T12:08:42.168746", "market_id": "0xc0e6b917320a47228fb96e3b5ae0e5c93773a5ae2662ae4e1f37807cfe47ce98", "raw": {"market": "0xc0e6b917320a47228fb96e3b5ae0e5c93773a5ae2662ae4e1f37807cfe47ce98", "asset_id": "81647294538046680798858716589766492074338758116170717123345952330712416337530", "price": "0.996", "size": "127.55", "side": "SELL", "timestamp": "1768475096035", "received_at": "2026-01-15T12:04:56.158989"}}
{"event_type": "price_change", "event_ts": "2026-01-15T12:04:57.120592", "ingestion_ts": "2026-01-15T12:08:42.168746", "market_id": "0xcab7ba4a9133cfd407d7e73e5757e5abbace413b59421527a31113406c97815c", "raw": {"market": "0xcab7ba4a9133cfd407d7e73e5757e5abbace413b59421527a31113406c97815c", "asset_id": "96361925776989336186111887920533578209326565663637092688733016597062311745569", "price": "0.006", "size": "127.41", "side": "BUY", "timestamp": "1768475096985", "received_at": "2026-01-15T12:04:57.120592"}}
{"event_type": "price_change", "event_ts": "2026-01-15T12:04:57.120592", "ingestion_ts": "2026-01-15T12:08:42.168746", "market_id": "0xcab7ba4a9133cfd407d7e73e5757e5abbace413b59421527a31113406c97815c", "raw": {"market": "0xcab7ba4a9133cfd407d7e73e5757e5abbace413b59421527a31113406c97815c", "asset_id": "20002636398944597965698652220992177552927816915094913583821579024925426590022", "price": "0.994", "size": "127.41", "side": "SELL", "timestamp": "1768475096985", "received_at": "2026-01-15T12:04:57.120592"}}
{"event_type": "price_change", "event_ts": "2026-01-15T12:04:57.120675", "ingestion_ts": "2026-01-15T12:08:42.168746", "market_id": "0xcab7ba4a9133cfd407d7e73e5757e5abbace413b59421527a31113406c97815c", "raw": {"market": "0xcab7ba4a9133cfd407d7e73e5757e5abbace413b59421527a31113406c97815c", "asset_id": "96361925776989336186111887920533578209326565663637092688733016597062311745569", "price": "0.008", "size": "619.71", "side": "BUY", "timestamp": "1768475096985", "received_at": "2026-01-15T12:04:57.120675"}}
{"event_type": "price_change", "event_ts": "2026-01-15T12:04:57.120675", "ingestion_ts": "2026-01-15T12:08:42.168746", "market_id": "0xcab7ba4a9133cfd407d7e73e5757e5abbace413b59421527a31113406c97815c", "raw": {"market": "0xcab7ba4a9133cfd407d7e73e5757e5abbace413b59421527a31113406c97815c", "asset_id": "20002636398944597965698652220992177552927816915094913583821579024925426590022", "price": "0.992", "size": "619.71", "side": "SELL", "timestamp": "1768475096985", "received_at": "2026-01-15T12:04:57.120675"}}
{"event_type": "price_change", "event_ts": "2026-01-15T12:04:57.499496", "ingestion_ts": "2026-01-15T12:08:42.168746", "market_id": "0xcab7ba4a9133cfd407d7e73e5757e5abbace413b59421527a31113406c97815c", "raw": {"market": "0xcab7ba4a9133cfd407d7e73e5757e5abbace413b59421527a31113406c97815c", "asset_id": "96361925776989336186111887920533578209326565663637092688733016597062311745569", "price": "0.006", "size": "136.13", "side": "BUY", "timestamp": "1768475097380", "received_at": "2026-01-15T12:04:57.499496"}}
{"event_type": "price_change", "event_ts": "2026-01-15T12:04:57.499496", "ingestion_ts": "2026-01-15T12:08:42.168746", "market_id": "0xcab7ba4a9133cfd407d7e73e5757e5abbace413b59421527a31113406c97815c", "raw": {"market": "0xcab7ba4a9133cfd407d7e73e5757e5abbace413b59421527a31113406c97815c", "asset_id": "20002636398944597965698652220992177552927816915094913583821579024925426590022", "price": "0.994", "size": "136.13", "side": "SELL", "timestamp": "1768475097380", "received_at": "2026-01-15T12:04:57.499496"}}
{"event_type": "price_change", "event_ts": "2026-01-15T12:04:57.504587", "ingestion_ts": "2026-01-15T12:08:42.168746", "market_id": "0xcab7ba4a9133cfd407d7e73e5757e5abbace413b59421527a31113406c97815c", "raw": {"market": "0xcab7ba4a9133cfd407d7e73e5757e5abbace413b59421527a31113406c97815c", "asset_id": "96361925776989336186111887920533578209326565663637092688733016597062311745569", "price": "0.008", "size": "631.87", "side": "BUY", "timestamp": "1768475097385", "received_at": "2026-01-15T12:04:57.504587"}}
{"event_type": "price_change", "event_ts": "2026-01-15T12:04:57.504587", "ingestion_ts": "2026-01-15T12:08:42.168746", "market_id": "0xcab7ba4a9133cfd407d7e73e5757e5abbace413b59421527a31113406c97815c", "raw": {"market": "0xcab7ba4a9133cfd407d7e73e5757e5abbace413b59421527a31113406c97815c", "asset_id": "20002636398944597965698652220992177552927816915094913583821579024925426590022", "price": "0.992", "size": "631.87", "side": "SELL", "timestamp": "1768475097385", "received_at": "2026-01-15T12:04:57.504587"}}
{"event_type": "price_change", "event_ts": "2026-01-15T12:04:58.804046", "ingestion_ts": "2026-01-15T12:08:42.168746", "market_id": "0xc0e6b917320a47228fb96e3b5ae0e5c93773a5ae2662ae4e1f37807cfe47ce98", "raw": {"market": "0xc0e6b917320a47228fb96e3b5ae0e5c93773a5ae2662ae4e1f37807cfe47ce98", "asset_id": "58656358377246279051017109359677190749228949103591068167284263961542487110215", "price": "0.004", "size": "0", "side": "BUY", "timestamp": "1768475098685", "received_at": "2026-01-15T12:04:58.804046"}}
{"event_type": "price_change", "event_ts": "2026-01-15T12:04:58.804046", "ingestion_ts": "2026-01-15T12:08:42.168746", "market_id": "0xc0e6b917320a47228fb96e3b5ae0e5c93773a5ae2662ae4e1f37807cfe47ce98", "raw": {"market": "0xc0e6b917320a47228fb96e3b5ae0e5c93773a5ae2662ae4e1f37807cfe47ce98", "asset_id": "81647294538046680798858716589766492074338758116170717123345952330712416337530", "price": "0.996", "size": "0", "side": "SELL", "timestamp": "1768475098685", "received_at": "2026-01-15T12:04:58.804046"}}
{"event_type": "price_change", "event_ts": "2026-01-15T12:04:59.124223", "ingestion_ts": "2026-01-15T12:08:42.168746", "market_id": "0xc0e6b917320a47228fb96e3b5ae0e5c93773a5ae2662ae4e1f37807cfe47ce98", "raw": {"market": "0xc0e6b917320a47228fb96e3b5ae0e5c93773a5ae2662ae4e1f37807cfe47ce98", "asset_id": "58656358377246279051017109359677190749228949103591068167284263961542487110215", "price": "0.005", "size": "105.02", "side": "BUY", "timestamp": "1768475098984", "received_at": "2026-01-15T12:04:59.124223"}}
{"event_type": "price_change", "event_ts": "2026-01-15T12:04:59.124223", "ingestion_ts": "2026-01-15T12:08:42.168746", "market_id": "0xc0e6b917320a47228fb96e3b5ae0e5c93773a5ae2662ae4e1f37807cfe47ce98", "raw": {"market": "0xc0e6b917320a47228fb96e3b5ae0e5c93773a5ae2662ae4e1f37807cfe47ce98", "asset_id": "81647294538046680798858716589766492074338758116170717123345952330712416337530", "price": "0.995", "size": "105.02", "side": "SELL", "timestamp": "1768475098984", "received_at": "2026-01-15T12:04:59.124223"}}
{"event_type": "price_change", "event_ts": "2026-01-15T12:05:00.320912", "ingestion_ts": "2026-01-15T12:08:42.168746", "market_id": "0xcab7ba4a9133cfd407d7e73e5757e5abbace413b59421527a31113406c97815c", "raw": {"market": "0xcab7ba4a9133cfd407d7e73e5757e5abbace413b59421527a31113406c97815c", "asset_id": "96361925776989336186111887920533578209326565663637092688733016597062311745569", "price": "0.006", "size": "127.41", "side": "BUY", "timestamp": "1768475100197", "received_at": "2026-01-15T12:05:00.320912"}}
{"event_type": "price_change", "event_ts": "2026-01-15T12:05:00.320912", "ingestion_ts": "2026-01-15T12:08:42.168746", "market_id": "0xcab7ba4a9133cfd407d7e73e5757e5abbace413b59421527a31113406c97815c", "raw": {"market": "0xcab7ba4a9133cfd407d7e73e5757e5abbace413b59421527a31113406c97815c", "asset_id": "20002636398944597965698652220992177552927816915094913583821579024925426590022", "price": "0.994", "size": "127.41", "side": "SELL", "timestamp": "1768475100197", "received_at": "2026-01-15T12:05:00.320912"}}
{"event_type": "price_change", "event_ts": "2026-01-15T12:05:00.321005", "ingestion_ts": "2026-01-15T12:08:42.168746", "market_id": "0xcab7ba4a9133cfd407d7e73e5757e5abbace413b59421527a31113406c97815c", "raw": {"market": "0xcab7ba4a9133cfd407d7e73e5757e5abbace413b59421527a31113406c97815c", "asset_id": "96361925776989336186111887920533578209326565663637092688733016597062311745569", "price": "0.008", "size": "619.71", "side": "BUY", "timestamp": "1768475100197", "received_at": "2026-01-15T12:05:00.321005"}}
{"event_type": "price_change", "event_ts": "2026-01-15T12:05:00.321005", "ingestion_ts": "2026-01-15T12:08:42.168746", "market_id": "0xcab7ba4a9133cfd407d7e73e5757e5abbace413b59421527a31113406c97815c", "raw": {"market": "0xcab7ba4a9133cfd407d7e73e5757e5abbace413b59421527a31113406c97815c", "asset_id": "20002636398944597965698652220992177552927816915094913583821579024925426590022", "price": "0.992", "size": "619.71", "side": "SELL", "timestamp": "1768475100197", "received_at": "2026-01-15T12:05:00.321005"}}
{"event_type": "price_change", "event_ts": "2026-01-15T12:05:00.786376", "ingestion_ts": "2026-01-15T12:08:42.168746", "market_id": "0xcab7ba4a9133cfd407d7e73e5757e5abbace413b59421527a31113406c97815c", "raw": {"market": "0xcab7ba4a9133cfd407d7e73e5757e5abbace413b59421527a31113406c97815c", "asset_id": "96361925776989336186111887920533578209326565663637092688733016597062311745569", "price": "0.006", "size": "136.13", "side": "BUY", "timestamp": "1768475100646", "received_at": "2026-01-15T12:05:00.786376"}}
{"event_type": "price_change", "event_ts": "2026-01-15T12:05:00.786376", "ingestion_ts": "2026-01-15T12:08:42.168746", "market_id": "0xcab7ba4a9133cfd407d7e73e5757e5abbace413b59421527a31113406c97815c", "raw": {"market": "0xcab7ba4a9133cfd407d7e73e5757e5abbace413b59421527a31113406c97815c", "asset_id": "20002636398944597965698652220992177552927816915094913583821579024925426590022", "price": "0.994", "size": "136.13", "side": "SELL", "timestamp": "1768475100646", "received_at": "2026-01-15T12:05:00.786376"}}
{"event_type": "price_change", "event_ts": "2026-01-15T12:05:00.786416", "ingestion_ts": "2026-01-15T12:08:42.168746", "market_id": "0xcab7ba4a9133cfd407d7e73e5757e5abbace413b59421527a31113406c97815c", "raw": {"market": "0xcab7ba4a9133cfd407d7e73e5757e5abbace413b59421527a31113406c97815c", "asset_id": "96361925776989336186111887920533578209326565663637092688733016597062311745569", "price": "0.008", "size": "631.87", "side": "BUY", "timestamp": "1768475100648", "received_at": "2026-01-15T12:05:00.786416"}}
{"event_type": "price_change", "event_ts": "2026-01-15T12:05:00.786416", "ingestion_ts": "2026-01-15T12:08:42.168746", "market_id": "0xcab7ba4a9133cfd407d7e73e5757e5abbace413b59421527a31113406c97815c", "raw": {"market": "0xcab7ba4a9133cfd407d7e73e5757e5abbace413b59421527a31113406c97815c", "asset_id": "20002636398944597965698652220992177552927816915094913583821579024925426590022", "price": "0.992", "size": "631.87", "side": "SELL", "timestamp": "1768475100648", "received_at": "2026-01-15T12:05:00.786416"}}
{"event_type": "price_change", "event_ts": "2026-01-15T12:05:03.252961", "ingestion_ts": "2026-01-15T12:08:42.168746", "market_id": "0xcab7ba4a9133cfd407d7e73e5757e5abbace413b59421527a31113406c97815c", "raw": {"market": "0xcab7ba4a9133cfd407d7e73e5757e5abbace413b59421527a31113406c97815c", "asset_id": "96361925776989336186111887920533578209326565663637092688733016597062311745569", "price": "0.006", "size": "127.41", "side": "BUY", "timestamp": "1768475103129", "received_at": "2026-01-15T12:05:03.252961"}}
{"event_type": "price_change", "event_ts": "2026-01-15T12:05:03.252961", "ingestion_ts": "2026-01-15T12:08:42.168746", "market_id": "0xcab7ba4a9133cfd407d7e73e5757e5abbace413b59421527a31113406c97815c", "raw": {"market": "0xcab7ba4a9133cfd407d7e73e5757e5abbace413b59421527a31113406c97815c", "asset_id": "20002636398944597965698652220992177552927816915094913583821579024925426590022", "price": "0.994", "size": "127.41", "side": "SELL", "timestamp": "1768475103129", "received_at": "2026-01-15T12:05:03.252961"}}
{"event_type": "price_change", "event_ts": "2026-01-15T12:05:03.253071", "ingestion_ts": "2026-01-15T12:08:42.168746", "market_id": "0xcab7ba4a9133cfd407d7e73e5757e5abbace413b59421527a31113406c97815c", "raw": {"market": "0xcab7ba4a9133cfd407d7e73e5757e5abbace413b59421527a31113406c97815c", "asset_id": "96361925776989336186111887920533578209326565663637092688733016597062311745569", "price": "0.008", "size": "619.71", "side": "BUY", "timestamp": "1768475103129", "received_at": "2026-01-15T12:05:03.253071"}}
{"event_type": "price_change", "event_ts": "2026-01-15T12:05:03.253071", "ingestion_ts": "2026-01-15T12:08:42.168746", "market_id": "0xcab7ba4a9133cfd407d7e73e5757e5abbace413b59421527a31113406c97815c", "raw": {"market": "0xcab7ba4a9133cfd407d7e73e5757e5abbace413b59421527a31113406c97815c", "asset_id": "20002636398944597965698652220992177552927816915094913583821579024925426590022", "price": "0.992", "size": "619.71", "side": "SELL", "timestamp": "1768475103129", "received_at": "2026-01-15T12:05:03.253071"}}
{"event_type": "price_change", "event_ts": "2026-01-15T12:05:03.875560", "ingestion_ts": "2026-01-15T12:08:42.168746", "market_id": "0xc0e6b917320a47228fb96e3b5ae0e5c93773a5ae2662ae4e1f37807cfe47ce98", "raw": {"market": "0xc0e6b917320a47228fb96e3b5ae0e5c93773a5ae2662ae4e1f37807cfe47ce98", "asset_id": "58656358377246279051017109359677190749228949103591068167284263961542487110215", "price": "0.005", "size": "2.98", "side": "BUY", "timestamp": "1768475103754", "received_at": "2026-01-15T12:05:03.875560"}}
{"event_type": "price_change", "event_ts": "2026-01-15T12:05:03.875560", "ingestion_ts": "2026-01-15T12:08:42.168746", "market_id": "0xc0e6b917320a47228fb96e3b5ae0e5c93773a5ae2662ae4e1f37807cfe47ce98", "raw": {"market": "0xc0e6b917320a47228fb96e3b5ae0e5c93773a5ae2662ae4e1f37807cfe47ce98", "asset_id": "81647294538046680798858716589766492074338758116170717123345952330712416337530", "price": "0.995", "size": "2.98", "side": "SELL", "timestamp": "1768475103754", "received_at": "2026-01-15T12:05:03.875560"}}
{"event_type": "price_change", "event_ts": "2026-01-15T12:05:04.092624", "ingestion_ts": "2026-01-15T12:08:42.168746", "market_id": "0xcab7ba4a9133cfd407d7e73e5757e5abbace413b59421527a31113406c97815c", "raw": {"market": "0xcab7ba4a9133cfd407d7e73e5757e5abbace413b59421527a31113406c97815c", "asset_id": "96361925776989336186111887920533578209326565663637092688733016597062311745569", "price": "0.006", "size": "136.13", "side": "BUY", "timestamp": "1768475103972", "received_at": "2026-01-15T12:05:04.092624"}}
{"event_type": "price_change", "event_ts": "2026-01-15T12:05:04.092624", "ingestion_ts": "2026-01-15T12:08:42.168746", "market_id": "0xcab7ba4a9133cfd407d7e73e5757e5abbace413b59421527a31113406c97815c", "raw": {"market": "0xcab7ba4a9133cfd407d7e73e5757e5abbace413b59421527a31113406c97815c", "asset_id": "20002636398944597965698652220992177552927816915094913583821579024925426590022", "price": "0.994", "size": "136.13", "side": "SELL", "timestamp": "1768475103972", "received_at": "2026-01-15T12:05:04.092624"}}
{"event_type": "price_change", "event_ts": "2026-01-15T12:05:04.092676", "ingestion_ts": "2026-01-15T12:08:42.168746", "market_id": "0xcab7ba4a9133cfd407d7e73e5757e5abbace413b59421527a31113406c97815c", "raw": {"market": "0xcab7ba4a9133cfd407d7e73e5757e5abbace413b59421527a31113406c97815c", "asset_id": "96361925776989336186111887920533578209326565663637092688733016597062311745569", "price": "0.008", "size": "631.87", "side": "BUY", "timestamp": "1768475103973", "received_at": "2026-01-15T12:05:04.092676"}}
{"event_type": "price_change", "event_ts": "2026-01-15T12:05:04.092676", "ingestion_ts": "2026-01-15T12:08:42.168746", "market_id": "0xcab7ba4a9133cfd407d7e73e5757e5abbace413b59421527a31113406c97815c", "raw": {"market": "0xcab7ba4a9133cfd407d7e73e5757e5abbace413b59421527a31113406c97815c", "asset_id": "20002636398944597965698652220992177552927816915094913583821579024925426590022", "price": "0.992", "size": "631.87", "side": "SELL", "timestamp": "1768475103973", "received_at": "2026-01-15T12:05:04.092676"}}
{"event_type": "price_change", "event_ts": "2026-01-15T12:05:04.124735", "ingestion_ts": "2026-01-15T12:08:42.168746", "market_id": "0xc0e6b917320a47228fb96e3b5ae0e5c93773a5ae2662ae4e1f37807cfe47ce98", "raw": {"market": "0xc0e6b917320a47228fb96e3b5ae0e5c93773a5ae2662ae4e1f37807cfe47ce98", "asset_id": "58656358377246279051017109359677190749228949103591068167284263961542487110215", "price": "0.003", "size": "275.43", "side": "BUY", "timestamp": "1768475104000", "received_at": "2026-01-15T12:05:04.124735"}}
{"event_type": "price_change", "event_ts": "2026-01-15T12:05:04.124735", "ingestion_ts": "2026-01-15T12:08:42.168746", "market_id": "0xc0e6b917320a47228fb96e3b5ae0e5c93773a5ae2662ae4e1f37807cfe47ce98", "raw": {"market": "0xc0e6b917320a47228fb96e3b5ae0e5c93773a5ae2662ae4e1f37807cfe47ce98", "asset_id": "81647294538046680798858716589766492074338758116170717123345952330712416337530", "price": "0.997", "size": "275.43", "side": "SELL", "timestamp": "1768475104000", "received_at": "2026-01-15T12:05:04.124735"}}
{"event_type": "price_change", "event_ts": "2026-01-15T12:05:04.134440", "ingestion_ts": "2026-01-15T12:08:42.168746", "market_id": "0xc0e6b917320a47228fb96e3b5ae0e5c93773a5ae2662ae4e1f37807cfe47ce98", "raw": {"market": "0xc0e6b917320a47228fb96e3b5ae0e5c93773a5ae2662ae4e1f37807cfe47ce98", "asset_id": "58656358377246279051017109359677190749228949103591068167284263961542487110215", "price": "0.003", "size": "275.43", "side": "BUY", "timestamp": "1768475104001", "received_at": "2026-01-15T12:05:04.134440"}}
{"event_type": "price_change", "event_ts": "2026-01-15T12:05:04.134440", "ingestion_ts": "2026-01-15T12:08:42.168746", "market_id": "0xc0e6b917320a47228fb96e3b5ae0e5c93773a5ae2662ae4e1f37807cfe47ce98", "raw": {"market": "0xc0e6b917320a47228fb96e3b5ae0e5c93773a5ae2662ae4e1f37807cfe47ce98", "asset_id": "81647294538046680798858716589766492074338758116170717123345952330712416337530", "price": "0.997", "size": "275.43", "side": "SELL", "timestamp": "1768475104001", "received_at": "2026-01-15T12:05:04.134440"}}
{"event_type": "price_change", "event_ts": "2026-01-15T12:05:04.316400", "ingestion_ts": "2026-01-15T12:08:42.168746", "market_id": "0xc0e6b917320a47228fb96e3b5ae0e5c93773a5ae2662ae4e1f37807cfe47ce98", "raw": {"market": "0xc0e6b917320a47228fb96e3b5ae0e5c93773a5ae2662ae4e1f37807cfe47ce98", "asset_id": "58656358377246279051017109359677190749228949103591068167284263961542487110215", "price": "0.006", "size": "85.03", "side": "BUY", "timestamp": "1768475104188", "received_at": "2026-01-15T12:05:04.316400"}}
{"event_type": "price_change", "event_ts": "2026-01-15T12:05:04.316400", "ingestion_ts": "2026-01-15T12:08:42.168746", "market_id": "0xc0e6b917320a47228fb96e3b5ae0e5c93773a5ae2662ae4e1f37807cfe47ce98", "raw": {"market": "0xc0e6b917320a47228fb96e3b5ae0e5c93773a5ae2662ae4e1f37807cfe47ce98", "asset_id": "81647294538046680798858716589766492074338758116170717123345952330712416337530", "price": "0.994", "size": "85.03", "side": "SELL", "timestamp": "1768475104188", "received_at": "2026-01-15T12:05:04.316400"}}
{"event_type": "price_change", "event_ts": "2026-01-15T12:05:05.391729", "ingestion_ts": "2026-01-15T12:08:42.168746", "market_id": "0xcab7ba4a9133cfd407d7e73e5757e5abbace413b59421527a31113406c97815c", "raw": {"market": "0xcab7ba4a9133cfd407d7e73e5757e5abbace413b59421527a31113406c97815c", "asset_id": "96361925776989336186111887920533578209326565663637092688733016597062311745569", "price": "0.006", "size": "127.41", "side": "BUY", "timestamp": "1768475105266", "received_at": "2026-01-15T12:05:05.391729"}}
{"event_type": "price_change", "event_ts": "2026-01-15T12:05:05.391729", "ingestion_ts": "2026-01-15T12:08:42.168746", "market_id": "0xcab7ba4a9133cfd407d7e73e5757e5abbace413b59421527a31113406c97815c", "raw": {"market": "0xcab7ba4a9133cfd407d7e73e5757e5abbace413b59421527a31113406c97815c", "asset_id": "20002636398944597965698652220992177552927816915094913583821579024925426590022", "price": "0.994", "size": "127.41", "side": "SELL", "timestamp": "1768475105266", "received_at": "2026-01-15T12:05:05.391729"}}
{"event_type": "price_change", "event_ts": "2026-01-15T12:05:05.391832", "ingestion_ts": "2026-01-15T12:08:42.168746", "market_id": "0xcab7ba4a9133cfd407d7e73e5757e5abbace413b59421527a31113406c97815c", "raw": {"market": "0xcab7ba4a9133cfd407d7e73e5757e5abbace413b59421527a31113406c97815c", "asset_id": "96361925776989336186111887920533578209326565663637092688733016597062311745569", "price": "0.008", "size": "619.71", "side": "BUY", "timestamp": "1768475105266", "received_at": "2026-01-15T12:05:05.391832"}}
{"event_type": "price_change", "event_ts": "2026-01-15T12:05:05.391832", "ingestion_ts": "2026-01-15T12:08:42.168746", "market_id": "0xcab7ba4a9133cfd407d7e73e5757e5abbace413b59421527a31113406c97815c", "raw": {"market": "0xcab7ba4a9133cfd407d7e73e5757e5abbace413b59421527a31113406c97815c", "asset_id": "20002636398944597965698652220992177552927816915094913583821579024925426590022", "price": "0.992", "size": "619.71", "side": "SELL", "timestamp": "1768475105266", "received_at": "2026-01-15T12:05:05.391832"}}
{"event_type": "price_change", "event_ts": "2026-01-15T12:05:05.786558", "ingestion_ts": "2026-01-15T12:08:42.168746", "market_id": "0x49686d26fb712515cd5e12c23f0a1c7e10214c7faa3cb0a730aabe0c33694082", "raw": {"market": "0x49686d26fb712515cd5e12c23f0a1c7e10214c7faa3cb0a730aabe0c33694082", "asset_id": "13244681086321087932946246027856416106585284024824496763706748621681543444582", "price": "0.295", "size": "0", "side": "BUY", "timestamp": "1768475105651", "received_at": "2026-01-15T12:05:05.786558"}}
{"event_type": "price_change", "event_ts": "2026-01-15T12:05:05.786558", "ingestion_ts": "2026-01-15T12:08:42.168746", "market_id": "0x49686d26fb712515cd5e12c23f0a1c7e10214c7faa3cb0a730aabe0c33694082", "raw": {"market": "0x49686d26fb712515cd5e12c23f0a1c7e10214c7faa3cb0a730aabe0c33694082", "asset_id": "30442780799048074404860985387051749017905070253466005720364298335239299761065", "price": "0.705", "size": "0", "side": "SELL", "timestamp": "1768475105651", "received_at": "2026-01-15T12:05:05.786558"}}
{"event_type": "price_change", "event_ts": "2026-01-15T12:05:06.019737", "ingestion_ts": "2026-01-15T12:08:42.168746", "market_id": "0x2393ed0b0fdc450054c7b9071907eca75cf4fc36e385adf4a0a5f99ee62243e8", "raw": {"market": "0x2393ed0b0fdc450054c7b9071907eca75cf4fc36e385adf4a0a5f99ee62243e8", "asset_id": "32769749367306925959219403371425714180265458150646381231272229429098460625924", "price": "0.859", "size": "0", "side": "BUY", "timestamp": "1768475105708", "received_at": "2026-01-15T12:05:06.019737"}}
{"event_type": "price_change", "event_ts": "2026-01-15T12:05:06.019737", "ingestion_ts": "2026-01-15T12:08:42.168746", "market_id": "0x2393ed0b0fdc450054c7b9071907eca75cf4fc36e385adf4a0a5f99ee62243e8", "raw": {"market": "0x2393ed0b0fdc450054c7b9071907eca75cf4fc36e385adf4a0a5f99ee62243e8", "asset_id": "100074770378634056601572485653252702850363676459996771990439989989293515601975", "price": "0.141", "size": "0", "side": "SELL", "timestamp": "1768475105708", "received_at": "2026-01-15T12:05:06.019737"}}
{"event_type": "price_change", "event_ts": "2026-01-15T12:05:06.185324", "ingestion_ts": "2026-01-15T12:08:42.168746", "market_id": "0xcab7ba4a9133cfd407d7e73e5757e5abbace413b59421527a31113406c97815c", "raw": {"market": "0xcab7ba4a9133cfd407d7e73e5757e5abbace413b59421527a31113406c97815c", "asset_id": "96361925776989336186111887920533578209326565663637092688733016597062311745569", "price": "0.006", "size": "136.13", "side": "BUY", "timestamp": "1768475106017", "received_at": "2026-01-15T12:05:06.185324"}}
{"event_type": "price_change", "event_ts": "2026-01-15T12:05:06.185324", "ingestion_ts": "2026-01-15T12:08:42.168746", "market_id": "0xcab7ba4a9133cfd407d7e73e5757e5abbace413b59421527a31113406c97815c", "raw": {"market": "0xcab7ba4a9133cfd407d7e73e5757e5abbace413b59421527a31113406c97815c", "asset_id": "20002636398944597965698652220992177552927816915094913583821579024925426590022", "price": "0.994", "size": "136.13", "side": "SELL", "timestamp": "1768475106017", "received_at": "2026-01-15T12:05:06.185324"}}
{"event_type": "price_change", "event_ts": "2026-01-15T12:05:06.187432", "ingestion_ts": "2026-01-15T12:08:42.168746", "market_id": "0xcab7ba4a9133cfd407d7e73e5757e5abbace413b59421527a31113406c97815c", "raw": {"market": "0xcab7ba4a9133cfd407d7e73e5757e5abbace413b59421527a31113406c97815c", "asset_id": "96361925776989336186111887920533578209326565663637092688733016597062311745569", "price": "0.008", "size": "631.87", "side": "BUY", "timestamp": "1768475106019", "received_at": "2026-01-15T12:05:06.187432"}}
{"event_type": "price_change", "event_ts": "2026-01-15T12:05:06.187432", "ingestion_ts": "2026-01-15T12:08:42.168746", "market_id": "0xcab7ba4a9133cfd407d7e73e5757e5abbace413b59421527a31113406c97815c", "raw": {"market": "0xcab7ba4a9133cfd407d7e73e5757e5abbace413b59421527a31113406c97815c", "asset_id": "20002636398944597965698652220992177552927816915094913583821579024925426590022", "price": "0.992", "size": "631.87", "side": "SELL", "timestamp": "1768475106019", "received_at": "2026-01-15T12:05:06.187432"}}
{"event_type": "price_change", "event_ts": "2026-01-15T12:05:06.257859", "ingestion_ts": "2026-01-15T12:08:42.168746", "market_id": "0x2393ed0b0fdc450054c7b9071907eca75cf4fc36e385adf4a0a5f99ee62243e8", "raw": {"market": "0x2393ed0b0fdc450054c7b9071907eca75cf4fc36e385adf4a0a5f99ee62243e8", "asset_id": "32769749367306925959219403371425714180265458150646381231272229429098460625924", "price": "0.862", "size": "25", "side": "BUY", "timestamp": "1768475106137", "received_at": "2026-01-15T12:05:06.257859"}}
{"event_type": "price_change", "event_ts": "2026-01-15T12:05:06.257859", "ingestion_ts": "2026-01-15T12:08:42.168746", "market_id": "0x2393ed0b0fdc450054c7b9071907eca75cf4fc36e385adf4a0a5f99ee62243e8", "raw": {"market": "0x2393ed0b0fdc450054c7b9071907eca75cf4fc36e385adf4a0a5f99ee62243e8", "asset_id": "100074770378634056601572485653252702850363676459996771990439989989293515601975", "price": "0.138", "size": "25", "side": "SELL", "timestamp": "1768475106137", "received_at": "2026-01-15T12:05:06.257859"}}
{"event_type": "price_change", "event_ts": "2026-01-15T12:05:06.418105", "ingestion_ts": "2026-01-15T12:08:42.168746", "market_id": "0x44f08744458b8896620cd3330bc5e1ea69df4199b02d4fc583b3fc96e5d314ce", "raw": {"market": "0x44f08744458b8896620cd3330bc5e1ea69df4199b02d4fc583b3fc96e5d314ce", "asset_id": "72327831507226612545928776794104143393438710920370371172884559893525100761096", "price": "0.91", "size": "0", "side": "BUY", "timestamp": "1768475106294", "received_at": "2026-01-15T12:05:06.418105"}}
{"event_type": "price_change", "event_ts": "2026-01-15T12:05:06.418105", "ingestion_ts": "2026-01-15T12:08:42.168746", "market_id": "0x44f08744458b8896620cd3330bc5e1ea69df4199b02d4fc583b3fc96e5d314ce", "raw": {"market": "0x44f08744458b8896620cd3330bc5e1ea69df4199b02d4fc583b3fc96e5d314ce", "asset_id": "49194009556504828848509244326501559253829462790583873936160989575507522044057", "price": "0.09", "size": "0", "side": "SELL", "timestamp": "1768475106294", "received_at": "2026-01-15T12:05:06.418105"}}
{"event_type": "price_change", "event_ts": "2026-01-15T12:05:06.917998", "ingestion_ts": "2026-01-15T12:08:42.168746", "market_id": "0x44f08744458b8896620cd3330bc5e1ea69df4199b02d4fc583b3fc96e5d314ce", "raw": {"market": "0x44f08744458b8896620cd3330bc5e1ea69df4199b02d4fc583b3fc96e5d314ce", "asset_id": "72327831507226612545928776794104143393438710920370371172884559893525100761096", "price": "0.911", "size": "0", "side": "BUY", "timestamp": "1768475106794", "received_at": "2026-01-15T12:05:06.917998"}}
{"event_type": "price_change", "event_ts": "2026-01-15T12:05:06.917998", "ingestion_ts": "2026-01-15T12:08:42.168746", "market_id": "0x44f08744458b8896620cd3330bc5e1ea69df4199b02d4fc583b3fc96e5d314ce", "raw": {"market": "0x44f08744458b8896620cd3330bc5e1ea69df4199b02d4fc583b3fc96e5d314ce", "asset_id": "49194009556504828848509244326501559253829462790583873936160989575507522044057", "price": "0.089", "size": "0", "side": "SELL", "timestamp": "1768475106794", "received_at": "2026-01-15T12:05:06.917998"}}
{"event_type": "price_change", "event_ts": "2026-01-15T12:05:06.918036", "ingestion_ts": "2026-01-15T12:08:42.168746", "market_id": "0x2393ed0b0fdc450054c7b9071907eca75cf4fc36e385adf4a0a5f99ee62243e8", "raw": {"market": "0x2393ed0b0fdc450054c7b9071907eca75cf4fc36e385adf4a0a5f99ee62243e8", "asset_id": "32769749367306925959219403371425714180265458150646381231272229429098460625924", "price": "0.861", "size": "0", "side": "BUY", "timestamp": "1768475106794", "received_at": "2026-01-15T12:05:06.918036"}}
{"event_type": "price_change", "event_ts": "2026-01-15T12:05:06.918036", "ingestion_ts": "2026-01-15T12:08:42.168746", "market_id": "0x2393ed0b0fdc450054c7b9071907eca75cf4fc36e385adf4a0a5f99ee62243e8", "raw": {"market": "0x2393ed0b0fdc450054c7b9071907eca75cf4fc36e385adf4a0a5f99ee62243e8", "asset_id": "100074770378634056601572485653252702850363676459996771990439989989293515601975", "price": "0.139", "size": "0", "side": "SELL", "timestamp": "1768475106794", "received_at": "2026-01-15T12:05:06.918036"}}
{"event_type": "price_change", "event_ts": "2026-01-15T12:05:06.951472", "ingestion_ts": "2026-01-15T12:08:42.168746", "market_id": "0x2393ed0b0fdc450054c7b9071907eca75cf4fc36e385adf4a0a5f99ee62243e8", "raw": {"market": "0x2393ed0b0fdc450054c7b9071907eca75cf4fc36e385adf4a0a5f99ee62243e8", "asset_id": "32769749367306925959219403371425714180265458150646381231272229429098460625924", "price": "0.863", "size": "5", "side": "BUY", "timestamp": "1768475106824", "received_at": "2026-01-15T12:05:06.951472"}}
{"event_type": "price_change", "event_ts": "2026-01-15T12:05:06.951472", "ingestion_ts": "2026-01-15T12:08:42.168746", "market_id": "0x2393ed0b0fdc450054c7b9071907eca75cf4fc36e385adf4a0a5f99ee62243e8", "raw": {"market": "0x2393ed0b0fdc450054c7b9071907eca75cf4fc36e385adf4a0a5f99ee62243e8", "asset_id": "100074770378634056601572485653252702850363676459996771990439989989293515601975", "price": "0.137", "size": "5", "side": "SELL", "timestamp": "1768475106824", "received_at": "2026-01-15T12:05:06.951472"}}
{"event_type": "price_change", "event_ts": "2026-01-15T12:05:06.952071", "ingestion_ts": "2026-01-15T12:08:42.168746", "market_id": "0x44f08744458b8896620cd3330bc5e1ea69df4199b02d4fc583b3fc96e5d314ce", "raw": {"market": "0x44f08744458b8896620cd3330bc5e1ea69df4199b02d4fc583b3fc96e5d314ce", "asset_id": "72327831507226612545928776794104143393438710920370371172884559893525100761096", "price": "0.908", "size": "5", "side": "BUY", "timestamp": "1768475106824", "received_at": "2026-01-15T12:05:06.952071"}}
{"event_type": "price_change", "event_ts": "2026-01-15T12:05:06.952071", "ingestion_ts": "2026-01-15T12:08:42.168746", "market_id": "0x44f08744458b8896620cd3330bc5e1ea69df4199b02d4fc583b3fc96e5d314ce", "raw": {"market": "0x44f08744458b8896620cd3330bc5e1ea69df4199b02d4fc583b3fc96e5d314ce", "asset_id": "49194009556504828848509244326501559253829462790583873936160989575507522044057", "price": "0.092", "size": "5", "side": "SELL", "timestamp": "1768475106824", "received_at": "2026-01-15T12:05:06.952071"}}
{"event_type": "price_change", "event_ts": "2026-01-15T12:05:07.088488", "ingestion_ts": "2026-01-15T12:08:42.168746", "market_id": "0x9472be65457510b7fc3477b20ba90910e99d92eac8421a14bf4b7b7a08ef31dc", "raw": {"market": "0x9472be65457510b7fc3477b20ba90910e99d92eac8421a14bf4b7b7a08ef31dc", "asset_id": "43311793366960417907757893276427136943959788721376762326430771171648759300146", "price": "0.883", "size": "0", "side": "BUY", "timestamp": "1768475106966", "received_at": "2026-01-15T12:05:07.088488"}}
{"event_type": "price_change", "event_ts": "2026-01-15T12:05:07.088488", "ingestion_ts": "2026-01-15T12:08:42.168746", "market_id": "0x9472be65457510b7fc3477b20ba90910e99d92eac8421a14bf4b7b7a08ef31dc", "raw": {"market": "0x9472be65457510b7fc3477b20ba90910e99d92eac8421a14bf4b7b7a08ef31dc", "asset_id": "73414222381656326204771753454630063673548497164758947581648273905027617570612", "price": "0.117", "size": "0", "side": "SELL", "timestamp": "1768475106966", "received_at": "2026-01-15T12:05:07.088488"}}
{"event_type": "price_change", "event_ts": "2026-01-15T12:05:07.121020", "ingestion_ts": "2026-01-15T12:08:42.168746", "market_id": "0xc0e6b917320a47228fb96e3b5ae0e5c93773a5ae2662ae4e1f37807cfe47ce98", "raw": {"market": "0xc0e6b917320a47228fb96e3b5ae0e5c93773a5ae2662ae4e1f37807cfe47ce98", "asset_id": "58656358377246279051017109359677190749228949103591068167284263961542487110215", "price": "0.003", "size": "262.97", "side": "BUY", "timestamp": "1768475107000", "received_at": "2026-01-15T12:05:07.121020"}}
{"event_type": "price_change", "event_ts": "2026-01-15T12:05:07.121020", "ingestion_ts": "2026-01-15T12:08:42.168746", "market_id": "0xc0e6b917320a47228fb96e3b5ae0e5c93773a5ae2662ae4e1f37807cfe47ce98", "raw": {"market": "0xc0e6b917320a47228fb96e3b5ae0e5c93773a5ae2662ae4e1f37807cfe47ce98", "asset_id": "81647294538046680798858716589766492074338758116170717123345952330712416337530", "price": "0.997", "size": "262.97", "side": "SELL", "timestamp": "1768475107000", "received_at": "2026-01-15T12:05:07.121020"}}
{"event_type": "price_change", "event_ts": "2026-01-15T12:05:07.124281", "ingestion_ts": "2026-01-15T12:08:42.168746", "market_id": "0xc0e6b917320a47228fb96e3b5ae0e5c93773a5ae2662ae4e1f37807cfe47ce98", "raw": {"market": "0xc0e6b917320a47228fb96e3b5ae0e5c93773a5ae2662ae4e1f37807cfe47ce98", "asset_id": "58656358377246279051017109359677190749228949103591068167284263961542487110215", "price": "0.003", "size": "262.97", "side": "BUY", "timestamp": "1768475107001", "received_at": "2026-01-15T12:05:07.124281"}}
{"event_type": "price_change", "event_ts": "2026-01-15T12:05:07.124281", "ingestion_ts": "2026-01-15T12:08:42.168746", "market_id": "0xc0e6b917320a47228fb96e3b5ae0e5c93773a5ae2662ae4e1f37807cfe47ce98", "raw": {"market": "0xc0e6b917320a47228fb96e3b5ae0e5c93773a5ae2662ae4e1f37807cfe47ce98", "asset_id": "81647294538046680798858716589766492074338758116170717123345952330712416337530", "price": "0.997", "size": "262.97", "side": "SELL", "timestamp": "1768475107001", "received_at": "2026-01-15T12:05:07.124281"}}
{"event_type": "price_change", "event_ts": "2026-01-15T12:05:07.261492", "ingestion_ts": "2026-01-15T12:08:42.168746", "market_id": "0xb9bbdd34304344dcc45803780a34c97d73a00133a5ecf70f63e1008b8abb2fca", "raw": {"market": "0xb9bbdd34304344dcc45803780a34c97d73a00133a5ecf70f63e1008b8abb2fca", "asset_id": "8682484153073832526711485265636767086525069344085206423986003504588877767339", "price": "0.872", "size": "0", "side": "BUY", "timestamp": "1768475107141", "received_at": "2026-01-15T12:05:07.261492"}}
{"event_type": "price_change", "event_ts": "2026-01-15T12:05:07.261492", "ingestion_ts": "2026-01-15T12:08:42.168746", "market_id": "0xb9bbdd34304344dcc45803780a34c97d73a00133a5ecf70f63e1008b8abb2fca", "raw": {"market": "0xb9bbdd34304344dcc45803780a34c97d73a00133a5ecf70f63e1008b8abb2fca", "asset_id": "72012724360700510767037780555710363830014634797787940282136454146828040926557", "price": "0.128", "size": "0", "side": "SELL", "timestamp": "1768475107141", "received_at": "2026-01-15T12:05:07.261492"}}
{"event_type": "price_change", "event_ts": "2026-01-15T12:05:07.605644", "ingestion_ts": "2026-01-15T12:08:42.168746", "market_id": "0xcab7ba4a9133cfd407d7e73e5757e5abbace413b59421527a31113406c97815c", "raw": {"market": "0xcab7ba4a9133cfd407d7e73e5757e5abbace413b59421527a31113406c97815c", "asset_id": "96361925776989336186111887920533578209326565663637092688733016597062311745569", "price": "0.006", "size": "127.41", "side": "BUY", "timestamp": "1768475107485", "received_at": "2026-01-15T12:05:07.605644"}}
{"event_type": "price_change", "event_ts": "2026-01-15T12:05:07.605644", "ingestion_ts": "2026-01-15T12:08:42.168746", "market_id": "0xcab7ba4a9133cfd407d7e73e5757e5abbace413b59421527a31113406c97815c", "raw": {"market": "0xcab7ba4a9133cfd407d7e73e5757e5abbace413b59421527a31113406c97815c", "asset_id": "20002636398944597965698652220992177552927816915094913583821579024925426590022", "price": "0.994", "size": "127.41", "side": "SELL", "timestamp": "1768475107485", "received_at": "2026-01-15T12:05:07.605644"}}
{"event_type": "price_change", "event_ts": "2026-01-15T12:05:07.605681", "ingestion_ts": "2026-01-15T12:08:42.168746", "market_id": "0xcab7ba4a9133cfd407d7e73e5757e5abbace413b59421527a31113406c97815c", "raw": {"market": "0xcab7ba4a9133cfd407d7e73e5757e5abbace413b59421527a31113406c97815c", "asset_id": "96361925776989336186111887920533578209326565663637092688733016597062311745569", "price": "0.008", "size": "619.71", "side": "BUY", "timestamp": "1768475107485", "received_at": "2026-01-15T12:05:07.605681"}}
{"event_type": "price_change", "event_ts": "2026-01-15T12:05:07.605681", "ingestion_ts": "2026-01-15T12:08:42.168746", "market_id": "0xcab7ba4a9133cfd407d7e73e5757e5abbace413b59421527a31113406c97815c", "raw": {"market": "0xcab7ba4a9133cfd407d7e73e5757e5abbace413b59421527a31113406c97815c", "asset_id": "20002636398944597965698652220992177552927816915094913583821579024925426590022", "price": "0.992", "size": "619.71", "side": "SELL", "timestamp": "1768475107485", "received_at": "2026-01-15T12:05:07.605681"}}
{"event_type": "price_change", "event_ts": "2026-01-15T12:05:08.142959", "ingestion_ts": "2026-01-15T12:08:42.168746", "market_id": "0xcab7ba4a9133cfd407d7e73e5757e5abbace413b59421527a31113406c97815c", "raw": {"market": "0xcab7ba4a9133cfd407d7e73e5757e5abbace413b59421527a31113406c97815c", "asset_id": "96361925776989336186111887920533578209326565663637092688733016597062311745569", "price": "0.008", "size": "631.87", "side": "BUY", "timestamp": "1768475108004", "received_at": "2026-01-15T12:05:08.142959"}}
{"event_type": "price_change", "event_ts": "2026-01-15T12:05:08.142959", "ingestion_ts": "2026-01-15T12:08:42.168746", "market_id": "0xcab7ba4a9133cfd407d7e73e5757e5abbace413b59421527a31113406c97815c", "raw": {"market": "0xcab7ba4a9133cfd407d7e73e5757e5abbace413b59421527a31113406c97815c", "asset_id": "20002636398944597965698652220992177552927816915094913583821579024925426590022", "price": "0.992", "size": "631.87", "side": "SELL", "timestamp": "1768475108004", "received_at": "2026-01-15T12:05:08.142959"}}
{"event_type": "price_change", "event_ts": "2026-01-15T12:05:08.145825", "ingestion_ts": "2026-01-15T12:08:42.168746", "market_id": "0xcab7ba4a9133cfd407d7e73e5757e5abbace413b59421527a31113406c97815c", "raw": {"market": "0xcab7ba4a9133cfd407d7e73e5757e5abbace413b59421527a31113406c97815c", "asset_id": "96361925776989336186111887920533578209326565663637092688733016597062311745569", "price": "0.006", "size": "136.13", "side": "BUY", "timestamp": "1768475108005", "received_at": "2026-01-15T12:05:08.145825"}}
{"event_type": "price_change", "event_ts": "2026-01-15T12:05:08.145825", "ingestion_ts": "2026-01-15T12:08:42.168746", "market_id": "0xcab7ba4a9133cfd407d7e73e5757e5abbace413b59421527a31113406c97815c", "raw": {"market": "0xcab7ba4a9133cfd407d7e73e5757e5abbace413b59421527a31113406c97815c", "asset_id": "20002636398944597965698652220992177552927816915094913583821579024925426590022", "price": "0.994", "size": "136.13", "side": "SELL", "timestamp": "1768475108005", "received_at": "2026-01-15T12:05:08.145825"}}
{"event_type": "price_change", "event_ts": "2026-01-15T12:05:08.505757", "ingestion_ts": "2026-01-15T12:08:42.168746", "market_id": "0xc0e6b917320a47228fb96e3b5ae0e5c93773a5ae2662ae4e1f37807cfe47ce98", "raw": {"market": "0xc0e6b917320a47228fb96e3b5ae0e5c93773a5ae2662ae4e1f37807cfe47ce98", "asset_id": "58656358377246279051017109359677190749228949103591068167284263961542487110215", "price": "0.006", "size": "0", "side": "BUY", "timestamp": "1768475108379", "received_at": "2026-01-15T12:05:08.505757"}}
{"event_type": "price_change", "event_ts": "2026-01-15T12:05:08.505757", "ingestion_ts": "2026-01-15T12:08:42.168746", "market_id": "0xc0e6b917320a47228fb96e3b5ae0e5c93773a5ae2662ae4e1f37807cfe47ce98", "raw": {"market": "0xc0e6b917320a47228fb96e3b5ae0e5c93773a5ae2662ae4e1f37807cfe47ce98", "asset_id": "81647294538046680798858716589766492074338758116170717123345952330712416337530", "price": "0.994", "size": "0", "side": "SELL", "timestamp": "1768475108379", "received_at": "2026-01-15T12:05:08.505757"}}
{"event_type": "price_change", "event_ts": "2026-01-15T12:05:09.624978", "ingestion_ts": "2026-01-15T12:08:42.168746", "market_id": "0xc0e6b917320a47228fb96e3b5ae0e5c93773a5ae2662ae4e1f37807cfe47ce98", "raw": {"market": "0xc0e6b917320a47228fb96e3b5ae0e5c93773a5ae2662ae4e1f37807cfe47ce98", "asset_id": "58656358377246279051017109359677190749228949103591068167284263961542487110215", "price": "0.003", "size": "276.84", "side": "BUY", "timestamp": "1768475109499", "received_at": "2026-01-15T12:05:09.624978"}}
{"event_type": "price_change", "event_ts": "2026-01-15T12:05:09.624978", "ingestion_ts": "2026-01-15T12:08:42.168746", "market_id": "0xc0e6b917320a47228fb96e3b5ae0e5c93773a5ae2662ae4e1f37807cfe47ce98", "raw": {"market": "0xc0e6b917320a47228fb96e3b5ae0e5c93773a5ae2662ae4e1f37807cfe47ce98", "asset_id": "81647294538046680798858716589766492074338758116170717123345952330712416337530", "price": "0.997", "size": "276.84", "side": "SELL", "timestamp": "1768475109499", "received_at": "2026-01-15T12:05:09.624978"}}
{"event_type": "price_change", "event_ts": "2026-01-15T12:05:09.625026", "ingestion_ts": "2026-01-15T12:08:42.168746", "market_id": "0xc0e6b917320a47228fb96e3b5ae0e5c93773a5ae2662ae4e1f37807cfe47ce98", "raw": {"market": "0xc0e6b917320a47228fb96e3b5ae0e5c93773a5ae2662ae4e1f37807cfe47ce98", "asset_id": "58656358377246279051017109359677190749228949103591068167284263961542487110215", "price": "0.007", "size": "77.62", "side": "BUY", "timestamp": "1768475109500", "received_at": "2026-01-15T12:05:09.625026"}}
{"event_type": "price_change", "event_ts": "2026-01-15T12:05:09.625026", "ingestion_ts": "2026-01-15T12:08:42.168746", "market_id": "0xc0e6b917320a47228fb96e3b5ae0e5c93773a5ae2662ae4e1f37807cfe47ce98", "raw": {"market": "0xc0e6b917320a47228fb96e3b5ae0e5c93773a5ae2662ae4e1f37807cfe47ce98", "asset_id": "81647294538046680798858716589766492074338758116170717123345952330712416337530", "price": "0.993", "size": "77.62", "side": "SELL", "timestamp": "1768475109500", "received_at": "2026-01-15T12:05:09.625026"}}
{"event_type": "price_change", "event_ts": "2026-01-15T12:05:10.179752", "ingestion_ts": "2026-01-15T12:08:42.168746", "market_id": "0x9472be65457510b7fc3477b20ba90910e99d92eac8421a14bf4b7b7a08ef31dc", "raw": {"market": "0x9472be65457510b7fc3477b20ba90910e99d92eac8421a14bf4b7b7a08ef31dc", "asset_id": "43311793366960417907757893276427136943959788721376762326430771171648759300146", "price": "0.884", "size": "0", "side": "BUY", "timestamp": "1768475110058", "received_at": "2026-01-15T12:05:10.179752"}}
{"event_type": "price_change", "event_ts": "2026-01-15T12:05:10.179752", "ingestion_ts": "2026-01-15T12:08:42.168746", "market_id": "0x9472be65457510b7fc3477b20ba90910e99d92eac8421a14bf4b7b7a08ef31dc", "raw": {"market": "0x9472be65457510b7fc3477b20ba90910e99d92eac8421a14bf4b7b7a08ef31dc", "asset_id": "73414222381656326204771753454630063673548497164758947581648273905027617570612", "price": "0.116", "size": "0", "side": "SELL", "timestamp": "1768475110058", "received_at": "2026-01-15T12:05:10.179752"}}
{"event_type": "price_change", "event_ts": "2026-01-15T12:05:10.179846", "ingestion_ts": "2026-01-15T12:08:42.168746", "market_id": "0xb9bbdd34304344dcc45803780a34c97d73a00133a5ecf70f63e1008b8abb2fca", "raw": {"market": "0xb9bbdd34304344dcc45803780a34c97d73a00133a5ecf70f63e1008b8abb2fca", "asset_id": "8682484153073832526711485265636767086525069344085206423986003504588877767339", "price": "0.873", "size": "0", "side": "BUY", "timestamp": "1768475110058", "received_at": "2026-01-15T12:05:10.179846"}}
{"event_type": "price_change", "event_ts": "2026-01-15T12:05:10.179846", "ingestion_ts": "2026-01-15T12:08:42.168746", "market_id": "0xb9bbdd34304344dcc45803780a34c97d73a00133a5ecf70f63e1008b8abb2fca", "raw": {"market": "0xb9bbdd34304344dcc45803780a34c97d73a00133a5ecf70f63e1008b8abb2fca", "asset_id": "72012724360700510767037780555710363830014634797787940282136454146828040926557", "price": "0.127", "size": "0", "side": "SELL", "timestamp": "1768475110058", "received_at": "2026-01-15T12:05:10.179846"}}
{"event_type": "price_change", "event_ts": "2026-01-15T12:05:10.216360", "ingestion_ts": "2026-01-15T12:08:42.168746", "market_id": "0x9472be65457510b7fc3477b20ba90910e99d92eac8421a14bf4b7b7a08ef31dc", "raw": {"market": "0x9472be65457510b7fc3477b20ba90910e99d92eac8421a14bf4b7b7a08ef31dc", "asset_id": "43311793366960417907757893276427136943959788721376762326430771171648759300146", "price": "0.826", "size": "5", "side": "BUY", "timestamp": "1768475110088", "received_at": "2026-01-15T12:05:10.216360"}}
{"event_type": "price_change", "event_ts": "2026-01-15T12:05:10.216360", "ingestion_ts": "2026-01-15T12:08:42.168746", "market_id": "0x9472be65457510b7fc3477b20ba90910e99d92eac8421a14bf4b7b7a08ef31dc", "raw": {"market": "0x9472be65457510b7fc3477b20ba90910e99d92eac8421a14bf4b7b7a08ef31dc", "asset_id": "73414222381656326204771753454630063673548497164758947581648273905027617570612", "price": "0.174", "size": "5", "side": "SELL", "timestamp": "1768475110088", "received_at": "2026-01-15T12:05:10.216360"}}
{"event_type": "price_change", "event_ts": "2026-01-15T12:05:10.216398", "ingestion_ts": "2026-01-15T12:08:42.168746", "market_id": "0xb9bbdd34304344dcc45803780a34c97d73a00133a5ecf70f63e1008b8abb2fca", "raw": {"market": "0xb9bbdd34304344dcc45803780a34c97d73a00133a5ecf70f63e1008b8abb2fca", "asset_id": "8682484153073832526711485265636767086525069344085206423986003504588877767339", "price": "0.869", "size": "5", "side": "BUY", "timestamp": "1768475110088", "received_at": "2026-01-15T12:05:10.216398"}}
{"event_type": "price_change", "event_ts": "2026-01-15T12:05:10.216398", "ingestion_ts": "2026-01-15T12:08:42.168746", "market_id": "0xb9bbdd34304344dcc45803780a34c97d73a00133a5ecf70f63e1008b8abb2fca", "raw": {"market": "0xb9bbdd34304344dcc45803780a34c97d73a00133a5ecf70f63e1008b8abb2fca", "asset_id": "72012724360700510767037780555710363830014634797787940282136454146828040926557", "price": "0.131", "size": "5", "side": "SELL", "timestamp": "1768475110088", "received_at": "2026-01-15T12:05:10.216398"}}
{"event_type": "price_change", "event_ts": "2026-01-15T12:05:10.328979", "ingestion_ts": "2026-01-15T12:08:42.168746", "market_id": "0x49a20c7523c271099008f3ef9a31521263b24d637959852a391e6b4697b1a437", "raw": {"market": "0x49a20c7523c271099008f3ef9a31521263b24d637959852a391e6b4697b1a437", "asset_id": "55881023621710858558280545117465775643848233756850602339827152783696837905531", "price": "0.928", "size": "0", "side": "BUY", "timestamp": "1768475110198", "received_at": "2026-01-15T12:05:10.328979"}}
{"event_type": "price_change", "event_ts": "2026-01-15T12:05:10.328979", "ingestion_ts": "2026-01-15T12:08:42.168746", "market_id": "0x49a20c7523c271099008f3ef9a31521263b24d637959852a391e6b4697b1a437", "raw": {"market": "0x49a20c7523c271099008f3ef9a31521263b24d637959852a391e6b4697b1a437", "asset_id": "13018971792603393862521629014128024641178044618205296260525674415067194037856", "price": "0.072", "size": "0", "side": "SELL", "timestamp": "1768475110198", "received_at": "2026-01-15T12:05:10.328979"}}
{"event_type": "price_change", "event_ts": "2026-01-15T12:05:10.329018", "ingestion_ts": "2026-01-15T12:08:42.168746", "market_id": "0x49a20c7523c271099008f3ef9a31521263b24d637959852a391e6b4697b1a437", "raw": {"market": "0x49a20c7523c271099008f3ef9a31521263b24d637959852a391e6b4697b1a437", "asset_id": "55881023621710858558280545117465775643848233756850602339827152783696837905531", "price": "0.866", "size": "0", "side": "BUY", "timestamp": "1768475110198", "received_at": "2026-01-15T12:05:10.329018"}}
{"event_type": "price_change", "event_ts": "2026-01-15T12:05:10.329018", "ingestion_ts": "2026-01-15T12:08:42.168746", "market_id": "0x49a20c7523c271099008f3ef9a31521263b24d637959852a391e6b4697b1a437", "raw": {"market": "0x49a20c7523c271099008f3ef9a31521263b24d637959852a391e6b4697b1a437", "asset_id": "13018971792603393862521629014128024641178044618205296260525674415067194037856", "price": "0.134", "size": "0", "side": "SELL", "timestamp": "1768475110198", "received_at": "2026-01-15T12:05:10.329018"}}
{"event_type": "price_change", "event_ts": "2026-01-15T12:05:10.364122", "ingestion_ts": "2026-01-15T12:08:42.168746", "market_id": "0x49a20c7523c271099008f3ef9a31521263b24d637959852a391e6b4697b1a437", "raw": {"market": "0x49a20c7523c271099008f3ef9a31521263b24d637959852a391e6b4697b1a437", "asset_id": "55881023621710858558280545117465775643848233756850602339827152783696837905531", "price": "0.868", "size": "10", "side": "BUY", "timestamp": "1768475110246", "received_at": "2026-01-15T12:05:10.364122"}}
{"event_type": "price_change", "event_ts": "2026-01-15T12:05:10.364122", "ingestion_ts": "2026-01-15T12:08:42.168746", "market_id": "0x49a20c7523c271099008f3ef9a31521263b24d637959852a391e6b4697b1a437", "raw": {"market": "0x49a20c7523c271099008f3ef9a31521263b24d637959852a391e6b4697b1a437", "asset_id": "13018971792603393862521629014128024641178044618205296260525674415067194037856", "price": "0.132", "size": "10", "side": "SELL", "timestamp": "1768475110246", "received_at": "2026-01-15T12:05:10.364122"}}
{"event_type": "price_change", "event_ts": "2026-01-15T12:05:10.364160", "ingestion_ts": "2026-01-15T12:08:42.168746", "market_id": "0x49a20c7523c271099008f3ef9a31521263b24d637959852a391e6b4697b1a437", "raw": {"market": "0x49a20c7523c271099008f3ef9a31521263b24d637959852a391e6b4697b1a437", "asset_id": "55881023621710858558280545117465775643848233756850602339827152783696837905531", "price": "0.928", "size": "20", "side": "BUY", "timestamp": "1768475110247", "received_at": "2026-01-15T12:05:10.364160"}}
{"event_type": "price_change", "event_ts": "2026-01-15T12:05:10.364160", "ingestion_ts": "2026-01-15T12:08:42.168746", "market_id": "0x49a20c7523c271099008f3ef9a31521263b24d637959852a391e6b4697b1a437", "raw": {"market": "0x49a20c7523c271099008f3ef9a31521263b24d637959852a391e6b4697b1a437", "asset_id": "13018971792603393862521629014128024641178044618205296260525674415067194037856", "price": "0.072", "size": "20", "side": "SELL", "timestamp": "1768475110247", "received_at": "2026-01-15T12:05:10.364160"}}
{"event_type": "price_change", "event_ts": "2026-01-15T12:05:10.486829", "ingestion_ts": "2026-01-15T12:08:42.168746", "market_id": "0xc55db914f0fd1fee18997706712c0dfd8d0369cdbef93a9fef12bd001914ca77", "raw": {"market": "0xc55db914f0fd1fee18997706712c0dfd8d0369cdbef93a9fef12bd001914ca77", "asset_id": "114600293444080540179603459515770723592661967180480327891296353898330242622833", "price": "0.931", "size": "0", "side": "BUY", "timestamp": "1768475110367", "received_at": "2026-01-15T12:05:10.486829"}}
{"event_type": "price_change", "event_ts": "2026-01-15T12:05:10.486829", "ingestion_ts": "2026-01-15T12:08:42.168746", "market_id": "0xc55db914f0fd1fee18997706712c0dfd8d0369cdbef93a9fef12bd001914ca77", "raw": {"market": "0xc55db914f0fd1fee18997706712c0dfd8d0369cdbef93a9fef12bd001914ca77", "asset_id": "72354723612769247426741660426331235762851940382312402276325808095604519806766", "price": "0.069", "size": "0", "side": "SELL", "timestamp": "1768475110367", "received_at": "2026-01-15T12:05:10.486829"}}
{"event_type": "price_change", "event_ts": "2026-01-15T12:05:10.997613", "ingestion_ts": "2026-01-15T12:08:42.168746", "market_id": "0xcab7ba4a9133cfd407d7e73e5757e5abbace413b59421527a31113406c97815c", "raw": {"market": "0xcab7ba4a9133cfd407d7e73e5757e5abbace413b59421527a31113406c97815c", "asset_id": "96361925776989336186111887920533578209326565663637092688733016597062311745569", "price": "0.006", "size": "127.41", "side": "BUY", "timestamp": "1768475110861", "received_at": "2026-01-15T12:05:10.997613"}}
{"event_type": "price_change", "event_ts": "2026-01-15T12:05:10.997613", "ingestion_ts": "2026-01-15T12:08:42.168746", "market_id": "0xcab7ba4a9133cfd407d7e73e5757e5abbace413b59421527a31113406c97815c", "raw": {"market": "0xcab7ba4a9133cfd407d7e73e5757e5abbace413b59421527a31113406c97815c", "asset_id": "20002636398944597965698652220992177552927816915094913583821579024925426590022", "price": "0.994", "size": "127.41", "side": "SELL", "timestamp": "1768475110861", "received_at": "2026-01-15T12:05:10.997613"}}
{"event_type": "price_change", "event_ts": "2026-01-15T12:05:10.997708", "ingestion_ts": "2026-01-15T12:08:42.168746", "market_id": "0xcab7ba4a9133cfd407d7e73e5757e5abbace413b59421527a31113406c97815c", "raw": {"market": "0xcab7ba4a9133cfd407d7e73e5757e5abbace413b59421527a31113406c97815c", "asset_id": "96361925776989336186111887920533578209326565663637092688733016597062311745569", "price": "0.008", "size": "619.71", "side": "BUY", "timestamp": "1768475110861", "received_at": "2026-01-15T12:05:10.997708"}}
{"event_type": "price_change", "event_ts": "2026-01-15T12:05:10.997708", "ingestion_ts": "2026-01-15T12:08:42.168746", "market_id": "0xcab7ba4a9133cfd407d7e73e5757e5abbace413b59421527a31113406c97815c", "raw": {"market": "0xcab7ba4a9133cfd407d7e73e5757e5abbace413b59421527a31113406c97815c", "asset_id": "20002636398944597965698652220992177552927816915094913583821579024925426590022", "price": "0.992", "size": "619.71", "side": "SELL", "timestamp": "1768475110861", "received_at": "2026-01-15T12:05:10.997708"}}
{"event_type": "price_change", "event_ts": "2026-01-15T12:05:11.460970", "ingestion_ts": "2026-01-15T12:08:42.168746", "market_id": "0xcab7ba4a9133cfd407d7e73e5757e5abbace413b59421527a31113406c97815c", "raw": {"market": "0xcab7ba4a9133cfd407d7e73e5757e5abbace413b59421527a31113406c97815c", "asset_id": "96361925776989336186111887920533578209326565663637092688733016597062311745569", "price": "0.006", "size": "136.13", "side": "BUY", "timestamp": "1768475111342", "received_at": "2026-01-15T12:05:11.460970"}}
{"event_type": "price_change", "event_ts": "2026-01-15T12:05:11.460970", "ingestion_ts": "2026-01-15T12:08:42.168746", "market_id": "0xcab7ba4a9133cfd407d7e73e5757e5abbace413b59421527a31113406c97815c", "raw": {"market": "0xcab7ba4a9133cfd407d7e73e5757e5abbace413b59421527a31113406c97815c", "asset_id": "20002636398944597965698652220992177552927816915094913583821579024925426590022", "price": "0.994", "size": "136.13", "side": "SELL", "timestamp": "1768475111342", "received_at": "2026-01-15T12:05:11.460970"}}
{"event_type": "price_change", "event_ts": "2026-01-15T12:05:11.465878", "ingestion_ts": "2026-01-15T12:08:42.168746", "market_id": "0xcab7ba4a9133cfd407d7e73e5757e5abbace413b59421527a31113406c97815c", "raw": {"market": "0xcab7ba4a9133cfd407d7e73e5757e5abbace413b59421527a31113406c97815c", "asset_id": "96361925776989336186111887920533578209326565663637092688733016597062311745569", "price": "0.008", "size": "631.87", "side": "BUY", "timestamp": "1768475111343", "received_at": "2026-01-15T12:05:11.465878"}}
{"event_type": "price_change", "event_ts": "2026-01-15T12:05:11.465878", "ingestion_ts": "2026-01-15T12:08:42.168746", "market_id": "0xcab7ba4a9133cfd407d7e73e5757e5abbace413b59421527a31113406c97815c", "raw": {"market": "0xcab7ba4a9133cfd407d7e73e5757e5abbace413b59421527a31113406c97815c", "asset_id": "20002636398944597965698652220992177552927816915094913583821579024925426590022", "price": "0.992", "size": "631.87", "side": "SELL", "timestamp": "1768475111343", "received_at": "2026-01-15T12:05:11.465878"}}
{"event_type": "price_change", "event_ts": "2026-01-15T12:05:12.946265", "ingestion_ts": "2026-01-15T12:08:42.168746", "market_id": "0xcab7ba4a9133cfd407d7e73e5757e5abbace413b59421527a31113406c97815c", "raw": {"market": "0xcab7ba4a9133cfd407d7e73e5757e5abbace413b59421527a31113406c97815c", "asset_id": "96361925776989336186111887920533578209326565663637092688733016597062311745569", "price": "0.006", "size": "127.41", "side": "BUY", "timestamp": "1768475112823", "received_at": "2026-01-15T12:05:12.946265"}}
{"event_type": "price_change", "event_ts": "2026-01-15T12:05:12.946265", "ingestion_ts": "2026-01-15T12:08:42.168746", "market_id": "0xcab7ba4a9133cfd407d7e73e5757e5abbace413b59421527a31113406c97815c", "raw": {"market": "0xcab7ba4a9133cfd407d7e73e5757e5abbace413b59421527a31113406c97815c", "asset_id": "20002636398944597965698652220992177552927816915094913583821579024925426590022", "price": "0.994", "size": "127.41", "side": "SELL", "timestamp": "1768475112823", "received_at": "2026-01-15T12:05:12.946265"}}
{"event_type": "price_change", "event_ts": "2026-01-15T12:05:12.946301", "ingestion_ts": "2026-01-15T12:08:42.168746", "market_id": "0xcab7ba4a9133cfd407d7e73e5757e5abbace413b59421527a31113406c97815c", "raw": {"market": "0xcab7ba4a9133cfd407d7e73e5757e5abbace413b59421527a31113406c97815c", "asset_id": "96361925776989336186111887920533578209326565663637092688733016597062311745569", "price": "0.008", "size": "619.71", "side": "BUY", "timestamp": "1768475112823", "received_at": "2026-01-15T12:05:12.946301"}}
{"event_type": "price_change", "event_ts": "2026-01-15T12:05:12.946301", "ingestion_ts": "2026-01-15T12:08:42.168746", "market_id": "0xcab7ba4a9133cfd407d7e73e5757e5abbace413b59421527a31113406c97815c", "raw": {"market": "0xcab7ba4a9133cfd407d7e73e5757e5abbace413b59421527a31113406c97815c", "asset_id": "20002636398944597965698652220992177552927816915094913583821579024925426590022", "price": "0.992", "size": "619.71", "side": "SELL", "timestamp": "1768475112823", "received_at": "2026-01-15T12:05:12.946301"}}
{"event_type": "price_change", "event_ts": "2026-01-15T12:05:13.512673", "ingestion_ts": "2026-01-15T12:08:42.168746", "market_id": "0xcab7ba4a9133cfd407d7e73e5757e5abbace413b59421527a31113406c97815c", "raw": {"market": "0xcab7ba4a9133cfd407d7e73e5757e5abbace413b59421527a31113406c97815c", "asset_id": "96361925776989336186111887920533578209326565663637092688733016597062311745569", "price": "0.006", "size": "136.13", "side": "BUY", "timestamp": "1768475113392", "received_at": "2026-01-15T12:05:13.512673"}}
{"event_type": "price_change", "event_ts": "2026-01-15T12:05:13.512673", "ingestion_ts": "2026-01-15T12:08:42.168746", "market_id": "0xcab7ba4a9133cfd407d7e73e5757e5abbace413b59421527a31113406c97815c", "raw": {"market": "0xcab7ba4a9133cfd407d7e73e5757e5abbace413b59421527a31113406c97815c", "asset_id": "20002636398944597965698652220992177552927816915094913583821579024925426590022", "price": "0.994", "size": "136.13", "side": "SELL", "timestamp": "1768475113392", "received_at": "2026-01-15T12:05:13.512673"}}
{"event_type": "price_change", "event_ts": "2026-01-15T12:05:13.517423", "ingestion_ts": "2026-01-15T12:08:42.168746", "market_id": "0xcab7ba4a9133cfd407d7e73e5757e5abbace413b59421527a31113406c97815c", "raw": {"market": "0xcab7ba4a9133cfd407d7e73e5757e5abbace413b59421527a31113406c97815c", "asset_id": "96361925776989336186111887920533578209326565663637092688733016597062311745569", "price": "0.008", "size": "631.87", "side": "BUY", "timestamp": "1768475113397", "received_at": "2026-01-15T12:05:13.517423"}}
{"event_type": "price_change", "event_ts": "2026-01-15T12:05:13.517423", "ingestion_ts": "2026-01-15T12:08:42.168746", "market_id": "0xcab7ba4a9133cfd407d7e73e5757e5abbace413b59421527a31113406c97815c", "raw": {"market": "0xcab7ba4a9133cfd407d7e73e5757e5abbace413b59421527a31113406c97815c", "asset_id": "20002636398944597965698652220992177552927816915094913583821579024925426590022", "price": "0.992", "size": "631.87", "side": "SELL", "timestamp": "1768475113397", "received_at": "2026-01-15T12:05:13.517423"}}
{"event_type": "price_change", "event_ts": "2026-01-15T12:05:13.882731", "ingestion_ts": "2026-01-15T12:08:42.168746", "market_id": "0x49a20c7523c271099008f3ef9a31521263b24d637959852a391e6b4697b1a437", "raw": {"market": "0x49a20c7523c271099008f3ef9a31521263b24d637959852a391e6b4697b1a437", "asset_id": "55881023621710858558280545117465775643848233756850602339827152783696837905531", "price": "0.867", "size": "0", "side": "BUY", "timestamp": "1768475113763", "received_at": "2026-01-15T12:05:13.882731"}}
{"event_type": "price_change", "event_ts": "2026-01-15T12:05:13.882731", "ingestion_ts": "2026-01-15T12:08:42.168746", "market_id": "0x49a20c7523c271099008f3ef9a31521263b24d637959852a391e6b4697b1a437", "raw": {"market": "0x49a20c7523c271099008f3ef9a31521263b24d637959852a391e6b4697b1a437", "asset_id": "13018971792603393862521629014128024641178044618205296260525674415067194037856", "price": "0.133", "size": "0", "side": "SELL", "timestamp": "1768475113763", "received_at": "2026-01-15T12:05:13.882731"}}
{"event_type": "price_change", "event_ts": "2026-01-15T12:05:13.917354", "ingestion_ts": "2026-01-15T12:08:42.168746", "market_id": "0x49a20c7523c271099008f3ef9a31521263b24d637959852a391e6b4697b1a437", "raw": {"market": "0x49a20c7523c271099008f3ef9a31521263b24d637959852a391e6b4697b1a437", "asset_id": "55881023621710858558280545117465775643848233756850602339827152783696837905531", "price": "0.869", "size": "5", "side": "BUY", "timestamp": "1768475113799", "received_at": "2026-01-15T12:05:13.917354"}}
{"event_type": "price_change", "event_ts": "2026-01-15T12:05:13.917354", "ingestion_ts": "2026-01-15T12:08:42.168746", "market_id": "0x49a20c7523c271099008f3ef9a31521263b24d637959852a391e6b4697b1a437", "raw": {"market": "0x49a20c7523c271099008f3ef9a31521263b24d637959852a391e6b4697b1a437", "asset_id": "13018971792603393862521629014128024641178044618205296260525674415067194037856", "price": "0.131", "size": "5", "side": "SELL", "timestamp": "1768475113799", "received_at": "2026-01-15T12:05:13.917354"}}
{"event_type": "price_change", "event_ts": "2026-01-15T12:05:14.062620", "ingestion_ts": "2026-01-15T12:08:42.168746", "market_id": "0x2393ed0b0fdc450054c7b9071907eca75cf4fc36e385adf4a0a5f99ee62243e8", "raw": {"market": "0x2393ed0b0fdc450054c7b9071907eca75cf4fc36e385adf4a0a5f99ee62243e8", "asset_id": "32769749367306925959219403371425714180265458150646381231272229429098460625924", "price": "0.892", "size": "0", "side": "BUY", "timestamp": "1768475113943", "received_at": "2026-01-15T12:05:14.062620"}}
{"event_type": "price_change", "event_ts": "2026-01-15T12:05:14.062620", "ingestion_ts": "2026-01-15T12:08:42.168746", "market_id": "0x2393ed0b0fdc450054c7b9071907eca75cf4fc36e385adf4a0a5f99ee62243e8", "raw": {"market": "0x2393ed0b0fdc450054c7b9071907eca75cf4fc36e385adf4a0a5f99ee62243e8", "asset_id": "100074770378634056601572485653252702850363676459996771990439989989293515601975", "price": "0.108", "size": "0", "side": "SELL", "timestamp": "1768475113943", "received_at": "2026-01-15T12:05:14.062620"}}
{"event_type": "price_change", "event_ts": "2026-01-15T12:05:14.152358", "ingestion_ts": "2026-01-15T12:08:42.168746", "market_id": "0xc0e6b917320a47228fb96e3b5ae0e5c93773a5ae2662ae4e1f37807cfe47ce98", "raw": {"market": "0xc0e6b917320a47228fb96e3b5ae0e5c93773a5ae2662ae4e1f37807cfe47ce98", "asset_id": "58656358377246279051017109359677190749228949103591068167284263961542487110215", "price": "0.007", "size": "0", "side": "BUY", "timestamp": "1768475114006", "received_at": "2026-01-15T12:05:14.152358"}}
{"event_type": "price_change", "event_ts": "2026-01-15T12:05:14.152358", "ingestion_ts": "2026-01-15T12:08:42.168746", "market_id": "0xc0e6b917320a47228fb96e3b5ae0e5c93773a5ae2662ae4e1f37807cfe47ce98", "raw": {"market": "0xc0e6b917320a47228fb96e3b5ae0e5c93773a5ae2662ae4e1f37807cfe47ce98", "asset_id": "81647294538046680798858716589766492074338758116170717123345952330712416337530", "price": "0.993", "size": "0", "side": "SELL", "timestamp": "1768475114006", "received_at": "2026-01-15T12:05:14.152358"}}
{"event_type": "price_change", "event_ts": "2026-01-15T12:05:14.225402", "ingestion_ts": "2026-01-15T12:08:42.168746", "market_id": "0xc55db914f0fd1fee18997706712c0dfd8d0369cdbef93a9fef12bd001914ca77", "raw": {"market": "0xc55db914f0fd1fee18997706712c0dfd8d0369cdbef93a9fef12bd001914ca77", "asset_id": "114600293444080540179603459515770723592661967180480327891296353898330242622833", "price": "0.874", "size": "0", "side": "BUY", "timestamp": "1768475114107", "received_at": "2026-01-15T12:05:14.225402"}}
{"event_type": "price_change", "event_ts": "2026-01-15T12:05:14.225402", "ingestion_ts": "2026-01-15T12:08:42.168746", "market_id": "0xc55db914f0fd1fee18997706712c0dfd8d0369cdbef93a9fef12bd001914ca77", "raw": {"market": "0xc55db914f0fd1fee18997706712c0dfd8d0369cdbef93a9fef12bd001914ca77", "asset_id": "72354723612769247426741660426331235762851940382312402276325808095604519806766", "price": "0.126", "size": "0", "side": "SELL", "timestamp": "1768475114107", "received_at": "2026-01-15T12:05:14.225402"}}
{"event_type": "price_change", "event_ts": "2026-01-15T12:05:14.277605", "ingestion_ts": "2026-01-15T12:08:42.168746", "market_id": "0xc55db914f0fd1fee18997706712c0dfd8d0369cdbef93a9fef12bd001914ca77", "raw": {"market": "0xc55db914f0fd1fee18997706712c0dfd8d0369cdbef93a9fef12bd001914ca77", "asset_id": "114600293444080540179603459515770723592661967180480327891296353898330242622833", "price": "0.931", "size": "20", "side": "BUY", "timestamp": "1768475114160", "received_at": "2026-01-15T12:05:14.277605"}}
{"event_type": "price_change", "event_ts": "2026-01-15T12:05:14.277605", "ingestion_ts": "2026-01-15T12:08:42.168746", "market_id": "0xc55db914f0fd1fee18997706712c0dfd8d0369cdbef93a9fef12bd001914ca77", "raw": {"market": "0xc55db914f0fd1fee18997706712c0dfd8d0369cdbef93a9fef12bd001914ca77", "asset_id": "72354723612769247426741660426331235762851940382312402276325808095604519806766", "price": "0.069", "size": "20", "side": "SELL", "timestamp": "1768475114160", "received_at": "2026-01-15T12:05:14.277605"}}
{"event_type": "price_change", "event_ts": "2026-01-15T12:05:14.278641", "ingestion_ts": "2026-01-15T12:08:42.168746", "market_id": "0x2393ed0b0fdc450054c7b9071907eca75cf4fc36e385adf4a0a5f99ee62243e8", "raw": {"market": "0x2393ed0b0fdc450054c7b9071907eca75cf4fc36e385adf4a0a5f99ee62243e8", "asset_id": "32769749367306925959219403371425714180265458150646381231272229429098460625924", "price": "0.892", "size": "30", "side": "BUY", "timestamp": "1768475114160", "received_at": "2026-01-15T12:05:14.278641"}}
{"event_type": "price_change", "event_ts": "2026-01-15T12:05:14.278641", "ingestion_ts": "2026-01-15T12:08:42.168746", "market_id": "0x2393ed0b0fdc450054c7b9071907eca75cf4fc36e385adf4a0a5f99ee62243e8", "raw": {"market": "0x2393ed0b0fdc450054c7b9071907eca75cf4fc36e385adf4a0a5f99ee62243e8", "asset_id": "100074770378634056601572485653252702850363676459996771990439989989293515601975", "price": "0.108", "size": "30", "side": "SELL", "timestamp": "1768475114160", "received_at": "2026-01-15T12:05:14.278641"}}
{"event_type": "price_change", "event_ts": "2026-01-15T12:05:14.281368", "ingestion_ts": "2026-01-15T12:08:42.168746", "market_id": "0x2393ed0b0fdc450054c7b9071907eca75cf4fc36e385adf4a0a5f99ee62243e8", "raw": {"market": "0x2393ed0b0fdc450054c7b9071907eca75cf4fc36e385adf4a0a5f99ee62243e8", "asset_id": "32769749367306925959219403371425714180265458150646381231272229429098460625924", "price": "0.463", "size": "444", "side": "BUY", "timestamp": "1768475114161", "received_at": "2026-01-15T12:05:14.281368"}}
{"event_type": "price_change", "event_ts": "2026-01-15T12:05:14.281368", "ingestion_ts": "2026-01-15T12:08:42.168746", "market_id": "0x2393ed0b0fdc450054c7b9071907eca75cf4fc36e385adf4a0a5f99ee62243e8", "raw": {"market": "0x2393ed0b0fdc450054c7b9071907eca75cf4fc36e385adf4a0a5f99ee62243e8", "asset_id": "100074770378634056601572485653252702850363676459996771990439989989293515601975", "price": "0.537", "size": "444", "side": "SELL", "timestamp": "1768475114161", "received_at": "2026-01-15T12:05:14.281368"}}
{"event_type": "price_change", "event_ts": "2026-01-15T12:05:14.281435", "ingestion_ts": "2026-01-15T12:08:42.168746", "market_id": "0xc55db914f0fd1fee18997706712c0dfd8d0369cdbef93a9fef12bd001914ca77", "raw": {"market": "0xc55db914f0fd1fee18997706712c0dfd8d0369cdbef93a9fef12bd001914ca77", "asset_id": "114600293444080540179603459515770723592661967180480327891296353898330242622833", "price": "0.876", "size": "10", "side": "BUY", "timestamp": "1768475114161", "received_at": "2026-01-15T12:05:14.281435"}}
{"event_type": "price_change", "event_ts": "2026-01-15T12:05:14.281435", "ingestion_ts": "2026-01-15T12:08:42.168746", "market_id": "0xc55db914f0fd1fee18997706712c0dfd8d0369cdbef93a9fef12bd001914ca77", "raw": {"market": "0xc55db914f0fd1fee18997706712c0dfd8d0369cdbef93a9fef12bd001914ca77", "asset_id": "72354723612769247426741660426331235762851940382312402276325808095604519806766", "price": "0.124", "size": "10", "side": "SELL", "timestamp": "1768475114161", "received_at": "2026-01-15T12:05:14.281435"}}
{"event_type": "price_change", "event_ts": "2026-01-15T12:05:14.406458", "ingestion_ts": "2026-01-15T12:08:42.168746", "market_id": "0x9472be65457510b7fc3477b20ba90910e99d92eac8421a14bf4b7b7a08ef31dc", "raw": {"market": "0x9472be65457510b7fc3477b20ba90910e99d92eac8421a14bf4b7b7a08ef31dc", "asset_id": "43311793366960417907757893276427136943959788721376762326430771171648759300146", "price": "0.927", "size": "0", "side": "BUY", "timestamp": "1768475114284", "received_at": "2026-01-15T12:05:14.406458"}}
{"event_type": "price_change", "event_ts": "2026-01-15T12:05:14.406458", "ingestion_ts": "2026-01-15T12:08:42.168746", "market_id": "0x9472be65457510b7fc3477b20ba90910e99d92eac8421a14bf4b7b7a08ef31dc", "raw": {"market": "0x9472be65457510b7fc3477b20ba90910e99d92eac8421a14bf4b7b7a08ef31dc", "asset_id": "73414222381656326204771753454630063673548497164758947581648273905027617570612", "price": "0.073", "size": "0", "side": "SELL", "timestamp": "1768475114284", "received_at": "2026-01-15T12:05:14.406458"}}
{"event_type": "price_change", "event_ts": "2026-01-15T12:05:14.569140", "ingestion_ts": "2026-01-15T12:08:42.168746", "market_id": "0x9472be65457510b7fc3477b20ba90910e99d92eac8421a14bf4b7b7a08ef31dc", "raw": {"market": "0x9472be65457510b7fc3477b20ba90910e99d92eac8421a14bf4b7b7a08ef31dc", "asset_id": "43311793366960417907757893276427136943959788721376762326430771171648759300146", "price": "0.927", "size": "20", "side": "BUY", "timestamp": "1768475114449", "received_at": "2026-01-15T12:05:14.569140"}}
{"event_type": "price_change", "event_ts": "2026-01-15T12:05:14.569140", "ingestion_ts": "2026-01-15T12:08:42.168746", "market_id": "0x9472be65457510b7fc3477b20ba90910e99d92eac8421a14bf4b7b7a08ef31dc", "raw": {"market": "0x9472be65457510b7fc3477b20ba90910e99d92eac8421a14bf4b7b7a08ef31dc", "asset_id": "73414222381656326204771753454630063673548497164758947581648273905027617570612", "price": "0.073", "size": "20", "side": "SELL", "timestamp": "1768475114449", "received_at": "2026-01-15T12:05:14.569140"}}
{"event_type": "price_change", "event_ts": "2026-01-15T12:05:14.569248", "ingestion_ts": "2026-01-15T12:08:42.168746", "market_id": "0x9472be65457510b7fc3477b20ba90910e99d92eac8421a14bf4b7b7a08ef31dc", "raw": {"market": "0x9472be65457510b7fc3477b20ba90910e99d92eac8421a14bf4b7b7a08ef31dc", "asset_id": "43311793366960417907757893276427136943959788721376762326430771171648759300146", "price": "0.827", "size": "10", "side": "BUY", "timestamp": "1768475114450", "received_at": "2026-01-15T12:05:14.569248"}}
{"event_type": "price_change", "event_ts": "2026-01-15T12:05:14.569248", "ingestion_ts": "2026-01-15T12:08:42.168746", "market_id": "0x9472be65457510b7fc3477b20ba90910e99d92eac8421a14bf4b7b7a08ef31dc", "raw": {"market": "0x9472be65457510b7fc3477b20ba90910e99d92eac8421a14bf4b7b7a08ef31dc", "asset_id": "73414222381656326204771753454630063673548497164758947581648273905027617570612", "price": "0.173", "size": "10", "side": "SELL", "timestamp": "1768475114450", "received_at": "2026-01-15T12:05:14.569248"}}
{"event_type": "price_change", "event_ts": "2026-01-15T12:05:14.841641", "ingestion_ts": "2026-01-15T12:08:42.168746", "market_id": "0xc0e6b917320a47228fb96e3b5ae0e5c93773a5ae2662ae4e1f37807cfe47ce98", "raw": {"market": "0xc0e6b917320a47228fb96e3b5ae0e5c93773a5ae2662ae4e1f37807cfe47ce98", "asset_id": "58656358377246279051017109359677190749228949103591068167284263961542487110215", "price": "0.008", "size": "67.92", "side": "BUY", "timestamp": "1768475114719", "received_at": "2026-01-15T12:05:14.841641"}}
{"event_type": "price_change", "event_ts": "2026-01-15T12:05:14.841641", "ingestion_ts": "2026-01-15T12:08:42.168746", "market_id": "0xc0e6b917320a47228fb96e3b5ae0e5c93773a5ae2662ae4e1f37807cfe47ce98", "raw": {"market": "0xc0e6b917320a47228fb96e3b5ae0e5c93773a5ae2662ae4e1f37807cfe47ce98", "asset_id": "81647294538046680798858716589766492074338758116170717123345952330712416337530", "price": "0.992", "size": "67.92", "side": "SELL", "timestamp": "1768475114719", "received_at": "2026-01-15T12:05:14.841641"}}
{"event_type": "price_change", "event_ts": "2026-01-15T12:05:15.497913", "ingestion_ts": "2026-01-15T12:08:42.168746", "market_id": "0xc55db914f0fd1fee18997706712c0dfd8d0369cdbef93a9fef12bd001914ca77", "raw": {"market": "0xc55db914f0fd1fee18997706712c0dfd8d0369cdbef93a9fef12bd001914ca77", "asset_id": "114600293444080540179603459515770723592661967180480327891296353898330242622833", "price": "0.875", "size": "0", "side": "BUY", "timestamp": "1768475115379", "received_at": "2026-01-15T12:05:15.497913"}}
{"event_type": "price_change", "event_ts": "2026-01-15T12:05:15.497913", "ingestion_ts": "2026-01-15T12:08:42.168746", "market_id": "0xc55db914f0fd1fee18997706712c0dfd8d0369cdbef93a9fef12bd001914ca77", "raw": {"market": "0xc55db914f0fd1fee18997706712c0dfd8d0369cdbef93a9fef12bd001914ca77", "asset_id": "72354723612769247426741660426331235762851940382312402276325808095604519806766", "price": "0.125", "size": "0", "side": "SELL", "timestamp": "1768475115379", "received_at": "2026-01-15T12:05:15.497913"}}
{"event_type": "price_change", "event_ts": "2026-01-15T12:05:15.498129", "ingestion_ts": "2026-01-15T12:08:42.168746", "market_id": "0x9472be65457510b7fc3477b20ba90910e99d92eac8421a14bf4b7b7a08ef31dc", "raw": {"market": "0x9472be65457510b7fc3477b20ba90910e99d92eac8421a14bf4b7b7a08ef31dc", "asset_id": "43311793366960417907757893276427136943959788721376762326430771171648759300146", "price": "0.826", "size": "0", "side": "BUY", "timestamp": "1768475115379", "received_at": "2026-01-15T12:05:15.498129"}}
{"event_type": "price_change", "event_ts": "2026-01-15T12:05:15.498129", "ingestion_ts": "2026-01-15T12:08:42.168746", "market_id": "0x9472be65457510b7fc3477b20ba90910e99d92eac8421a14bf4b7b7a08ef31dc", "raw": {"market": "0x9472be65457510b7fc3477b20ba90910e99d92eac8421a14bf4b7b7a08ef31dc", "asset_id": "73414222381656326204771753454630063673548497164758947581648273905027617570612", "price": "0.174", "size": "0", "side": "SELL", "timestamp": "1768475115379", "received_at": "2026-01-15T12:05:15.498129"}}
{"event_type": "price_change", "event_ts": "2026-01-15T12:05:15.525854", "ingestion_ts": "2026-01-15T12:08:42.168746", "market_id": "0xc55db914f0fd1fee18997706712c0dfd8d0369cdbef93a9fef12bd001914ca77", "raw": {"market": "0xc55db914f0fd1fee18997706712c0dfd8d0369cdbef93a9fef12bd001914ca77", "asset_id": "114600293444080540179603459515770723592661967180480327891296353898330242622833", "price": "0.877", "size": "5", "side": "BUY", "timestamp": "1768475115407", "received_at": "2026-01-15T12:05:15.525854"}}
{"event_type": "price_change", "event_ts": "2026-01-15T12:05:15.525854", "ingestion_ts": "2026-01-15T12:08:42.168746", "market_id": "0xc55db914f0fd1fee18997706712c0dfd8d0369cdbef93a9fef12bd001914ca77", "raw": {"market": "0xc55db914f0fd1fee18997706712c0dfd8d0369cdbef93a9fef12bd001914ca77", "asset_id": "72354723612769247426741660426331235762851940382312402276325808095604519806766", "price": "0.123", "size": "5", "side": "SELL", "timestamp": "1768475115407", "received_at": "2026-01-15T12:05:15.525854"}}
{"event_type": "price_change", "event_ts": "2026-01-15T12:05:15.526056", "ingestion_ts": "2026-01-15T12:08:42.168746", "market_id": "0x9472be65457510b7fc3477b20ba90910e99d92eac8421a14bf4b7b7a08ef31dc", "raw": {"market": "0x9472be65457510b7fc3477b20ba90910e99d92eac8421a14bf4b7b7a08ef31dc", "asset_id": "43311793366960417907757893276427136943959788721376762326430771171648759300146", "price": "0.828", "size": "5", "side": "BUY", "timestamp": "1768475115407", "received_at": "2026-01-15T12:05:15.526056"}}
{"event_type": "price_change", "event_ts": "2026-01-15T12:05:15.526056", "ingestion_ts": "2026-01-15T12:08:42.168746", "market_id": "0x9472be65457510b7fc3477b20ba90910e99d92eac8421a14bf4b7b7a08ef31dc", "raw": {"market": "0x9472be65457510b7fc3477b20ba90910e99d92eac8421a14bf4b7b7a08ef31dc", "asset_id": "73414222381656326204771753454630063673548497164758947581648273905027617570612", "price": "0.172", "size": "5", "side": "SELL", "timestamp": "1768475115407", "received_at": "2026-01-15T12:05:15.526056"}}
{"event_type": "price_change", "event_ts": "2026-01-15T12:05:15.781339", "ingestion_ts": "2026-01-15T12:08:42.168746", "market_id": "0x50c669f178da4e5bbea7f1be25041fd278914712fa87a6a6f8e57d5923d88dee", "raw": {"market": "0x50c669f178da4e5bbea7f1be25041fd278914712fa87a6a6f8e57d5923d88dee", "asset_id": "74040420326294854165772767082819937451857852955603897473157746262672057685461", "price": "0.867", "size": "0", "side": "BUY", "timestamp": "1768475115640", "received_at": "2026-01-15T12:05:15.781339"}}
{"event_type": "price_change", "event_ts": "2026-01-15T12:05:15.781339", "ingestion_ts": "2026-01-15T12:08:42.168746", "market_id": "0x50c669f178da4e5bbea7f1be25041fd278914712fa87a6a6f8e57d5923d88dee", "raw": {"market": "0x50c669f178da4e5bbea7f1be25041fd278914712fa87a6a6f8e57d5923d88dee", "asset_id": "24682525479474221428144937281315825971983904267399062415430320764754931667953", "price": "0.133", "size": "0", "side": "SELL", "timestamp": "1768475115640", "received_at": "2026-01-15T12:05:15.781339"}}
{"event_type": "price_change", "event_ts": "2026-01-15T12:05:15.951079", "ingestion_ts": "2026-01-15T12:08:42.168746", "market_id": "0xcab7ba4a9133cfd407d7e73e5757e5abbace413b59421527a31113406c97815c", "raw": {"market": "0xcab7ba4a9133cfd407d7e73e5757e5abbace413b59421527a31113406c97815c", "asset_id": "96361925776989336186111887920533578209326565663637092688733016597062311745569", "price": "0.006", "size": "127.41", "side": "BUY", "timestamp": "1768475115830", "received_at": "2026-01-15T12:05:15.951079"}}
{"event_type": "price_change", "event_ts": "2026-01-15T12:05:15.951079", "ingestion_ts": "2026-01-15T12:08:42.168746", "market_id": "0xcab7ba4a9133cfd407d7e73e5757e5abbace413b59421527a31113406c97815c", "raw": {"market": "0xcab7ba4a9133cfd407d7e73e5757e5abbace413b59421527a31113406c97815c", "asset_id": "20002636398944597965698652220992177552927816915094913583821579024925426590022", "price": "0.994", "size": "127.41", "side": "SELL", "timestamp": "1768475115830", "received_at": "2026-01-15T12:05:15.951079"}}
{"event_type": "price_change", "event_ts": "2026-01-15T12:05:15.952329", "ingestion_ts": "2026-01-15T12:08:42.168746", "market_id": "0xcab7ba4a9133cfd407d7e73e5757e5abbace413b59421527a31113406c97815c", "raw": {"market": "0xcab7ba4a9133cfd407d7e73e5757e5abbace413b59421527a31113406c97815c", "asset_id": "96361925776989336186111887920533578209326565663637092688733016597062311745569", "price": "0.008", "size": "619.71", "side": "BUY", "timestamp": "1768475115830", "received_at": "2026-01-15T12:05:15.952329"}}
{"event_type": "price_change", "event_ts": "2026-01-15T12:05:15.952329", "ingestion_ts": "2026-01-15T12:08:42.168746", "market_id": "0xcab7ba4a9133cfd407d7e73e5757e5abbace413b59421527a31113406c97815c", "raw": {"market": "0xcab7ba4a9133cfd407d7e73e5757e5abbace413b59421527a31113406c97815c", "asset_id": "20002636398944597965698652220992177552927816915094913583821579024925426590022", "price": "0.992", "size": "619.71", "side": "SELL", "timestamp": "1768475115830", "received_at": "2026-01-15T12:05:15.952329"}}
{"event_type": "price_change", "event_ts": "2026-01-15T12:05:16.436144", "ingestion_ts": "2026-01-15T12:08:42.168746", "market_id": "0xcab7ba4a9133cfd407d7e73e5757e5abbace413b59421527a31113406c97815c", "raw": {"market": "0xcab7ba4a9133cfd407d7e73e5757e5abbace413b59421527a31113406c97815c", "asset_id": "96361925776989336186111887920533578209326565663637092688733016597062311745569", "price": "0.008", "size": "631.87", "side": "BUY", "timestamp": "1768475116310", "received_at": "2026-01-15T12:05:16.436144"}}
{"event_type": "price_change", "event_ts": "2026-01-15T12:05:16.436144", "ingestion_ts": "2026-01-15T12:08:42.168746", "market_id": "0xcab7ba4a9133cfd407d7e73e5757e5abbace413b59421527a31113406c97815c", "raw": {"market": "0xcab7ba4a9133cfd407d7e73e5757e5abbace413b59421527a31113406c97815c", "asset_id": "20002636398944597965698652220992177552927816915094913583821579024925426590022", "price": "0.992", "size": "631.87", "side": "SELL", "timestamp": "1768475116310", "received_at": "2026-01-15T12:05:16.436144"}}
{"event_type": "price_change", "event_ts": "2026-01-15T12:05:16.436232", "ingestion_ts": "2026-01-15T12:08:42.168746", "market_id": "0xcab7ba4a9133cfd407d7e73e5757e5abbace413b59421527a31113406c97815c", "raw": {"market": "0xcab7ba4a9133cfd407d7e73e5757e5abbace413b59421527a31113406c97815c", "asset_id": "96361925776989336186111887920533578209326565663637092688733016597062311745569", "price": "0.006", "size": "136.13", "side": "BUY", "timestamp": "1768475116311", "received_at": "2026-01-15T12:05:16.436232"}}
{"event_type": "price_change", "event_ts": "2026-01-15T12:05:16.436232", "ingestion_ts": "2026-01-15T12:08:42.168746", "market_id": "0xcab7ba4a9133cfd407d7e73e5757e5abbace413b59421527a31113406c97815c", "raw": {"market": "0xcab7ba4a9133cfd407d7e73e5757e5abbace413b59421527a31113406c97815c", "asset_id": "20002636398944597965698652220992177552927816915094913583821579024925426590022", "price": "0.994", "size": "136.13", "side": "SELL", "timestamp": "1768475116311", "received_at": "2026-01-15T12:05:16.436232"}}
{"event_type": "price_change", "event_ts": "2026-01-15T12:05:16.729167", "ingestion_ts": "2026-01-15T12:08:42.168746", "market_id": "0x2393ed0b0fdc450054c7b9071907eca75cf4fc36e385adf4a0a5f99ee62243e8", "raw": {"market": "0x2393ed0b0fdc450054c7b9071907eca75cf4fc36e385adf4a0a5f99ee62243e8", "asset_id": "32769749367306925959219403371425714180265458150646381231272229429098460625924", "price": "0.922", "size": "0", "side": "BUY", "timestamp": "1768475116571", "received_at": "2026-01-15T12:05:16.729167"}}
{"event_type": "price_change", "event_ts": "2026-01-15T12:05:16.729167", "ingestion_ts": "2026-01-15T12:08:42.168746", "market_id": "0x2393ed0b0fdc450054c7b9071907eca75cf4fc36e385adf4a0a5f99ee62243e8", "raw": {"market": "0x2393ed0b0fdc450054c7b9071907eca75cf4fc36e385adf4a0a5f99ee62243e8", "asset_id": "100074770378634056601572485653252702850363676459996771990439989989293515601975", "price": "0.078", "size": "0", "side": "SELL", "timestamp": "1768475116571", "received_at": "2026-01-15T12:05:16.729167"}}
{"event_type": "price_change", "event_ts": "2026-01-15T12:05:17.398715", "ingestion_ts": "2026-01-15T12:08:42.168746", "market_id": "0xcab7ba4a9133cfd407d7e73e5757e5abbace413b59421527a31113406c97815c", "raw": {"market": "0xcab7ba4a9133cfd407d7e73e5757e5abbace413b59421527a31113406c97815c", "asset_id": "96361925776989336186111887920533578209326565663637092688733016597062311745569", "price": "0.006", "size": "127.41", "side": "BUY", "timestamp": "1768475117270", "received_at": "2026-01-15T12:05:17.398715"}}
{"event_type": "price_change", "event_ts": "2026-01-15T12:05:17.398715", "ingestion_ts": "2026-01-15T12:08:42.168746", "market_id": "0xcab7ba4a9133cfd407d7e73e5757e5abbace413b59421527a31113406c97815c", "raw": {"market": "0xcab7ba4a9133cfd407d7e73e5757e5abbace413b59421527a31113406c97815c", "asset_id": "20002636398944597965698652220992177552927816915094913583821579024925426590022", "price": "0.994", "size": "127.41", "side": "SELL", "timestamp": "1768475117270", "received_at": "2026-01-15T12:05:17.398715"}}
{"event_type": "price_change", "event_ts": "2026-01-15T12:05:17.398807", "ingestion_ts": "2026-01-15T12:08:42.168746", "market_id": "0xcab7ba4a9133cfd407d7e73e5757e5abbace413b59421527a31113406c97815c", "raw": {"market": "0xcab7ba4a9133cfd407d7e73e5757e5abbace413b59421527a31113406c97815c", "asset_id": "96361925776989336186111887920533578209326565663637092688733016597062311745569", "price": "0.008", "size": "619.71", "side": "BUY", "timestamp": "1768475117270", "received_at": "2026-01-15T12:05:17.398807"}}
{"event_type": "price_change", "event_ts": "2026-01-15T12:05:17.398807", "ingestion_ts": "2026-01-15T12:08:42.168746", "market_id": "0xcab7ba4a9133cfd407d7e73e5757e5abbace413b59421527a31113406c97815c", "raw": {"market": "0xcab7ba4a9133cfd407d7e73e5757e5abbace413b59421527a31113406c97815c", "asset_id": "20002636398944597965698652220992177552927816915094913583821579024925426590022", "price": "0.992", "size": "619.71", "side": "SELL", "timestamp": "1768475117270", "received_at": "2026-01-15T12:05:17.398807"}}
{"event_type": "price_change", "event_ts": "2026-01-15T12:05:18.227815", "ingestion_ts": "2026-01-15T12:08:42.168746", "market_id": "0xcab7ba4a9133cfd407d7e73e5757e5abbace413b59421527a31113406c97815c", "raw": {"market": "0xcab7ba4a9133cfd407d7e73e5757e5abbace413b59421527a31113406c97815c", "asset_id": "96361925776989336186111887920533578209326565663637092688733016597062311745569", "price": "0.008", "size": "625.79", "side": "BUY", "timestamp": "1768475118038", "received_at": "2026-01-15T12:05:18.227815"}}
{"event_type": "price_change", "event_ts": "2026-01-15T12:05:18.227815", "ingestion_ts": "2026-01-15T12:08:42.168746", "market_id": "0xcab7ba4a9133cfd407d7e73e5757e5abbace413b59421527a31113406c97815c", "raw": {"market": "0xcab7ba4a9133cfd407d7e73e5757e5abbace413b59421527a31113406c97815c", "asset_id": "20002636398944597965698652220992177552927816915094913583821579024925426590022", "price": "0.992", "size": "625.79", "side": "SELL", "timestamp": "1768475118038", "received_at": "2026-01-15T12:05:18.227815"}}
{"event_type": "price_change", "event_ts": "2026-01-15T12:05:18.229299", "ingestion_ts": "2026-01-15T12:08:42.168746", "market_id": "0xcab7ba4a9133cfd407d7e73e5757e5abbace413b59421527a31113406c97815c", "raw": {"market": "0xcab7ba4a9133cfd407d7e73e5757e5abbace413b59421527a31113406c97815c", "asset_id": "96361925776989336186111887920533578209326565663637092688733016597062311745569", "price": "0.008", "size": "631.87", "side": "BUY", "timestamp": "1768475118039", "received_at": "2026-01-15T12:05:18.229299"}}
{"event_type": "price_change", "event_ts": "2026-01-15T12:05:18.229299", "ingestion_ts": "2026-01-15T12:08:42.168746", "market_id": "0xcab7ba4a9133cfd407d7e73e5757e5abbace413b59421527a31113406c97815c", "raw": {"market": "0xcab7ba4a9133cfd407d7e73e5757e5abbace413b59421527a31113406c97815c", "asset_id": "20002636398944597965698652220992177552927816915094913583821579024925426590022", "price": "0.992", "size": "631.87", "side": "SELL", "timestamp": "1768475118039", "received_at": "2026-01-15T12:05:18.229299"}}
{"event_type": "price_change", "event_ts": "2026-01-15T12:05:18.231601", "ingestion_ts": "2026-01-15T12:08:42.168746", "market_id": "0xcab7ba4a9133cfd407d7e73e5757e5abbace413b59421527a31113406c97815c", "raw": {"market": "0xcab7ba4a9133cfd407d7e73e5757e5abbace413b59421527a31113406c97815c", "asset_id": "96361925776989336186111887920533578209326565663637092688733016597062311745569", "price": "0.006", "size": "136.13", "side": "BUY", "timestamp": "1768475118040", "received_at": "2026-01-15T12:05:18.231601"}}
{"event_type": "price_change", "event_ts": "2026-01-15T12:05:18.231601", "ingestion_ts": "2026-01-15T12:08:42.168746", "market_id": "0xcab7ba4a9133cfd407d7e73e5757e5abbace413b59421527a31113406c97815c", "raw": {"market": "0xcab7ba4a9133cfd407d7e73e5757e5abbace413b59421527a31113406c97815c", "asset_id": "20002636398944597965698652220992177552927816915094913583821579024925426590022", "price": "0.994", "size": "136.13", "side": "SELL", "timestamp": "1768475118040", "received_at": "2026-01-15T12:05:18.231601"}}
{"event_type": "price_change", "event_ts": "2026-01-15T12:05:19.282446", "ingestion_ts": "2026-01-15T12:08:42.168746", "market_id": "0x50c669f178da4e5bbea7f1be25041fd278914712fa87a6a6f8e57d5923d88dee", "raw": {"market": "0x50c669f178da4e5bbea7f1be25041fd278914712fa87a6a6f8e57d5923d88dee", "asset_id": "74040420326294854165772767082819937451857852955603897473157746262672057685461", "price": "0.868", "size": "0", "side": "BUY", "timestamp": "1768475119164", "received_at": "2026-01-15T12:05:19.282446"}}
{"event_type": "price_change", "event_ts": "2026-01-15T12:05:19.282446", "ingestion_ts": "2026-01-15T12:08:42.168746", "market_id": "0x50c669f178da4e5bbea7f1be25041fd278914712fa87a6a6f8e57d5923d88dee", "raw": {"market": "0x50c669f178da4e5bbea7f1be25041fd278914712fa87a6a6f8e57d5923d88dee", "asset_id": "24682525479474221428144937281315825971983904267399062415430320764754931667953", "price": "0.132", "size": "0", "side": "SELL", "timestamp": "1768475119164", "received_at": "2026-01-15T12:05:19.282446"}}
{"event_type": "price_change", "event_ts": "2026-01-15T12:05:19.316409", "ingestion_ts": "2026-01-15T12:08:42.168746", "market_id": "0x50c669f178da4e5bbea7f1be25041fd278914712fa87a6a6f8e57d5923d88dee", "raw": {"market": "0x50c669f178da4e5bbea7f1be25041fd278914712fa87a6a6f8e57d5923d88dee", "asset_id": "74040420326294854165772767082819937451857852955603897473157746262672057685461", "price": "0.864", "size": "5", "side": "BUY", "timestamp": "1768475119193", "received_at": "2026-01-15T12:05:19.316409"}}
{"event_type": "price_change", "event_ts": "2026-01-15T12:05:19.316409", "ingestion_ts": "2026-01-15T12:08:42.168746", "market_id": "0x50c669f178da4e5bbea7f1be25041fd278914712fa87a6a6f8e57d5923d88dee", "raw": {"market": "0x50c669f178da4e5bbea7f1be25041fd278914712fa87a6a6f8e57d5923d88dee", "asset_id": "24682525479474221428144937281315825971983904267399062415430320764754931667953", "price": "0.136", "size": "5", "side": "SELL", "timestamp": "1768475119193", "received_at": "2026-01-15T12:05:19.316409"}}
{"event_type": "price_change", "event_ts": "2026-01-15T12:05:19.335978", "ingestion_ts": "2026-01-15T12:08:42.168746", "market_id": "0x44f08744458b8896620cd3330bc5e1ea69df4199b02d4fc583b3fc96e5d314ce", "raw": {"market": "0x44f08744458b8896620cd3330bc5e1ea69df4199b02d4fc583b3fc96e5d314ce", "asset_id": "72327831507226612545928776794104143393438710920370371172884559893525100761096", "price": "0.905", "size": "0", "side": "BUY", "timestamp": "1768475119217", "received_at": "2026-01-15T12:05:19.335978"}}
{"event_type": "price_change", "event_ts": "2026-01-15T12:05:19.335978", "ingestion_ts": "2026-01-15T12:08:42.168746", "market_id": "0x44f08744458b8896620cd3330bc5e1ea69df4199b02d4fc583b3fc96e5d314ce", "raw": {"market": "0x44f08744458b8896620cd3330bc5e1ea69df4199b02d4fc583b3fc96e5d314ce", "asset_id": "49194009556504828848509244326501559253829462790583873936160989575507522044057", "price": "0.095", "size": "0", "side": "SELL", "timestamp": "1768475119217", "received_at": "2026-01-15T12:05:19.335978"}}
{"event_type": "price_change", "event_ts": "2026-01-15T12:05:19.746957", "ingestion_ts": "2026-01-15T12:08:42.168746", "market_id": "0x2393ed0b0fdc450054c7b9071907eca75cf4fc36e385adf4a0a5f99ee62243e8", "raw": {"market": "0x2393ed0b0fdc450054c7b9071907eca75cf4fc36e385adf4a0a5f99ee62243e8", "asset_id": "32769749367306925959219403371425714180265458150646381231272229429098460625924", "price": "0.922", "size": "11.24", "side": "BUY", "timestamp": "1768475119628", "received_at": "2026-01-15T12:05:19.746957"}}
{"event_type": "price_change", "event_ts": "2026-01-15T12:05:19.746957", "ingestion_ts": "2026-01-15T12:08:42.168746", "market_id": "0x2393ed0b0fdc450054c7b9071907eca75cf4fc36e385adf4a0a5f99ee62243e8", "raw": {"market": "0x2393ed0b0fdc450054c7b9071907eca75cf4fc36e385adf4a0a5f99ee62243e8", "asset_id": "100074770378634056601572485653252702850363676459996771990439989989293515601975", "price": "0.078", "size": "11.24", "side": "SELL", "timestamp": "1768475119628", "received_at": "2026-01-15T12:05:19.746957"}}
{"event_type": "price_change", "event_ts": "2026-01-15T12:05:20.020109", "ingestion_ts": "2026-01-15T12:08:42.168746", "market_id": "0xc0e6b917320a47228fb96e3b5ae0e5c93773a5ae2662ae4e1f37807cfe47ce98", "raw": {"market": "0xc0e6b917320a47228fb96e3b5ae0e5c93773a5ae2662ae4e1f37807cfe47ce98", "asset_id": "58656358377246279051017109359677190749228949103591068167284263961542487110215", "price": "0.008", "size": "0", "side": "BUY", "timestamp": "1768475119897", "received_at": "2026-01-15T12:05:20.020109"}}
{"event_type": "price_change", "event_ts": "2026-01-15T12:05:20.020109", "ingestion_ts": "2026-01-15T12:08:42.168746", "market_id": "0xc0e6b917320a47228fb96e3b5ae0e5c93773a5ae2662ae4e1f37807cfe47ce98", "raw": {"market": "0xc0e6b917320a47228fb96e3b5ae0e5c93773a5ae2662ae4e1f37807cfe47ce98", "asset_id": "81647294538046680798858716589766492074338758116170717123345952330712416337530", "price": "0.992", "size": "0", "side": "SELL", "timestamp": "1768475119897", "received_at": "2026-01-15T12:05:20.020109"}}
{"event_type": "price_change", "event_ts": "2026-01-15T12:05:20.351897", "ingestion_ts": "2026-01-15T12:08:42.168746", "market_id": "0xc0e6b917320a47228fb96e3b5ae0e5c93773a5ae2662ae4e1f37807cfe47ce98", "raw": {"market": "0xc0e6b917320a47228fb96e3b5ae0e5c93773a5ae2662ae4e1f37807cfe47ce98", "asset_id": "58656358377246279051017109359677190749228949103591068167284263961542487110215", "price": "0.009", "size": "60.37", "side": "BUY", "timestamp": "1768475120231", "received_at": "2026-01-15T12:05:20.351897"}}
{"event_type": "price_change", "event_ts": "2026-01-15T12:05:20.351897", "ingestion_ts": "2026-01-15T12:08:42.168746", "market_id": "0xc0e6b917320a47228fb96e3b5ae0e5c93773a5ae2662ae4e1f37807cfe47ce98", "raw": {"market": "0xc0e6b917320a47228fb96e3b5ae0e5c93773a5ae2662ae4e1f37807cfe47ce98", "asset_id": "81647294538046680798858716589766492074338758116170717123345952330712416337530", "price": "0.991", "size": "60.37", "side": "SELL", "timestamp": "1768475120231", "received_at": "2026-01-15T12:05:20.351897"}}
{"event_type": "price_change", "event_ts": "2026-01-15T12:05:21.140017", "ingestion_ts": "2026-01-15T12:08:42.168746", "market_id": "0xc0e6b917320a47228fb96e3b5ae0e5c93773a5ae2662ae4e1f37807cfe47ce98", "raw": {"market": "0xc0e6b917320a47228fb96e3b5ae0e5c93773a5ae2662ae4e1f37807cfe47ce98", "asset_id": "58656358377246279051017109359677190749228949103591068167284263961542487110215", "price": "0.003", "size": "264.38", "side": "BUY", "timestamp": "1768475121000", "received_at": "2026-01-15T12:05:21.140017"}}
{"event_type": "price_change", "event_ts": "2026-01-15T12:05:21.140017", "ingestion_ts": "2026-01-15T12:08:42.168746", "market_id": "0xc0e6b917320a47228fb96e3b5ae0e5c93773a5ae2662ae4e1f37807cfe47ce98", "raw": {"market": "0xc0e6b917320a47228fb96e3b5ae0e5c93773a5ae2662ae4e1f37807cfe47ce98", "asset_id": "81647294538046680798858716589766492074338758116170717123345952330712416337530", "price": "0.997", "size": "264.38", "side": "SELL", "timestamp": "1768475121000", "received_at": "2026-01-15T12:05:21.140017"}}
{"event_type": "price_change", "event_ts": "2026-01-15T12:05:21.140150", "ingestion_ts": "2026-01-15T12:08:42.168746", "market_id": "0xc0e6b917320a47228fb96e3b5ae0e5c93773a5ae2662ae4e1f37807cfe47ce98", "raw": {"market": "0xc0e6b917320a47228fb96e3b5ae0e5c93773a5ae2662ae4e1f37807cfe47ce98", "asset_id": "58656358377246279051017109359677190749228949103591068167284263961542487110215", "price": "0.003", "size": "264.38", "side": "BUY", "timestamp": "1768475121001", "received_at": "2026-01-15T12:05:21.140150"}}
{"event_type": "price_change", "event_ts": "2026-01-15T12:05:21.140150", "ingestion_ts": "2026-01-15T12:08:42.168746", "market_id": "0xc0e6b917320a47228fb96e3b5ae0e5c93773a5ae2662ae4e1f37807cfe47ce98", "raw": {"market": "0xc0e6b917320a47228fb96e3b5ae0e5c93773a5ae2662ae4e1f37807cfe47ce98", "asset_id": "81647294538046680798858716589766492074338758116170717123345952330712416337530", "price": "0.997", "size": "264.38", "side": "SELL", "timestamp": "1768475121001", "received_at": "2026-01-15T12:05:21.140150"}}
{"event_type": "price_change", "event_ts": "2026-01-15T12:05:21.310531", "ingestion_ts": "2026-01-15T12:08:42.168746", "market_id": "0xcab7ba4a9133cfd407d7e73e5757e5abbace413b59421527a31113406c97815c", "raw": {"market": "0xcab7ba4a9133cfd407d7e73e5757e5abbace413b59421527a31113406c97815c", "asset_id": "96361925776989336186111887920533578209326565663637092688733016597062311745569", "price": "0.006", "size": "127.41", "side": "BUY", "timestamp": "1768475121176", "received_at": "2026-01-15T12:05:21.310531"}}
{"event_type": "price_change", "event_ts": "2026-01-15T12:05:21.310531", "ingestion_ts": "2026-01-15T12:08:42.168746", "market_id": "0xcab7ba4a9133cfd407d7e73e5757e5abbace413b59421527a31113406c97815c", "raw": {"market": "0xcab7ba4a9133cfd407d7e73e5757e5abbace413b59421527a31113406c97815c", "asset_id": "20002636398944597965698652220992177552927816915094913583821579024925426590022", "price": "0.994", "size": "127.41", "side": "SELL", "timestamp": "1768475121176", "received_at": "2026-01-15T12:05:21.310531"}}
{"event_type": "price_change", "event_ts": "2026-01-15T12:05:21.310621", "ingestion_ts": "2026-01-15T12:08:42.168746", "market_id": "0xcab7ba4a9133cfd407d7e73e5757e5abbace413b59421527a31113406c97815c", "raw": {"market": "0xcab7ba4a9133cfd407d7e73e5757e5abbace413b59421527a31113406c97815c", "asset_id": "96361925776989336186111887920533578209326565663637092688733016597062311745569", "price": "0.008", "size": "625.79", "side": "BUY", "timestamp": "1768475121176", "received_at": "2026-01-15T12:05:21.310621"}}
{"event_type": "price_change", "event_ts": "2026-01-15T12:05:21.310621", "ingestion_ts": "2026-01-15T12:08:42.168746", "market_id": "0xcab7ba4a9133cfd407d7e73e5757e5abbace413b59421527a31113406c97815c", "raw": {"market": "0xcab7ba4a9133cfd407d7e73e5757e5abbace413b59421527a31113406c97815c", "asset_id": "20002636398944597965698652220992177552927816915094913583821579024925426590022", "price": "0.992", "size": "625.79", "side": "SELL", "timestamp": "1768475121176", "received_at": "2026-01-15T12:05:21.310621"}}
{"event_type": "price_change", "event_ts": "2026-01-15T12:05:21.877561", "ingestion_ts": "2026-01-15T12:08:42.168746", "market_id": "0xcab7ba4a9133cfd407d7e73e5757e5abbace413b59421527a31113406c97815c", "raw": {"market": "0xcab7ba4a9133cfd407d7e73e5757e5abbace413b59421527a31113406c97815c", "asset_id": "96361925776989336186111887920533578209326565663637092688733016597062311745569", "price": "0.006", "size": "135.83", "side": "BUY", "timestamp": "1768475121755", "received_at": "2026-01-15T12:05:21.877561"}}
{"event_type": "price_change", "event_ts": "2026-01-15T12:05:21.877561", "ingestion_ts": "2026-01-15T12:08:42.168746", "market_id": "0xcab7ba4a9133cfd407d7e73e5757e5abbace413b59421527a31113406c97815c", "raw": {"market": "0xcab7ba4a9133cfd407d7e73e5757e5abbace413b59421527a31113406c97815c", "asset_id": "20002636398944597965698652220992177552927816915094913583821579024925426590022", "price": "0.994", "size": "135.83", "side": "SELL", "timestamp": "1768475121755", "received_at": "2026-01-15T12:05:21.877561"}}
{"event_type": "price_change", "event_ts": "2026-01-15T12:05:21.877680", "ingestion_ts": "2026-01-15T12:08:42.168746", "market_id": "0xcab7ba4a9133cfd407d7e73e5757e5abbace413b59421527a31113406c97815c", "raw": {"market": "0xcab7ba4a9133cfd407d7e73e5757e5abbace413b59421527a31113406c97815c", "asset_id": "96361925776989336186111887920533578209326565663637092688733016597062311745569", "price": "0.006", "size": "144.25", "side": "BUY", "timestamp": "1768475121756", "received_at": "2026-01-15T12:05:21.877680"}}
{"event_type": "price_change", "event_ts": "2026-01-15T12:05:21.877680", "ingestion_ts": "2026-01-15T12:08:42.168746", "market_id": "0xcab7ba4a9133cfd407d7e73e5757e5abbace413b59421527a31113406c97815c", "raw": {"market": "0xcab7ba4a9133cfd407d7e73e5757e5abbace413b59421527a31113406c97815c", "asset_id": "20002636398944597965698652220992177552927816915094913583821579024925426590022", "price": "0.994", "size": "144.25", "side": "SELL", "timestamp": "1768475121756", "received_at": "2026-01-15T12:05:21.877680"}}
{"event_type": "price_change", "event_ts": "2026-01-15T12:05:24.339303", "ingestion_ts": "2026-01-15T12:08:42.168746", "market_id": "0xc0e6b917320a47228fb96e3b5ae0e5c93773a5ae2662ae4e1f37807cfe47ce98", "raw": {"market": "0xc0e6b917320a47228fb96e3b5ae0e5c93773a5ae2662ae4e1f37807cfe47ce98", "asset_id": "58656358377246279051017109359677190749228949103591068167284263961542487110215", "price": "0.009", "size": "0", "side": "BUY", "timestamp": "1768475124216", "received_at": "2026-01-15T12:05:24.339303"}}
{"event_type": "price_change", "event_ts": "2026-01-15T12:05:24.339303", "ingestion_ts": "2026-01-15T12:08:42.168746", "market_id": "0xc0e6b917320a47228fb96e3b5ae0e5c93773a5ae2662ae4e1f37807cfe47ce98", "raw": {"market": "0xc0e6b917320a47228fb96e3b5ae0e5c93773a5ae2662ae4e1f37807cfe47ce98", "asset_id": "81647294538046680798858716589766492074338758116170717123345952330712416337530", "price": "0.991", "size": "0", "side": "SELL", "timestamp": "1768475124216", "received_at": "2026-01-15T12:05:24.339303"}}
{"event_type": "price_change", "event_ts": "2026-01-15T12:05:24.339386", "ingestion_ts": "2026-01-15T12:08:42.168746", "market_id": "0xcab7ba4a9133cfd407d7e73e5757e5abbace413b59421527a31113406c97815c", "raw": {"market": "0xcab7ba4a9133cfd407d7e73e5757e5abbace413b59421527a31113406c97815c", "asset_id": "96361925776989336186111887920533578209326565663637092688733016597062311745569", "price": "0.006", "size": "135.83", "side": "BUY", "timestamp": "1768475124216", "received_at": "2026-01-15T12:05:24.339386"}}
{"event_type": "price_change", "event_ts": "2026-01-15T12:05:24.339386", "ingestion_ts": "2026-01-15T12:08:42.168746", "market_id": "0xcab7ba4a9133cfd407d7e73e5757e5abbace413b59421527a31113406c97815c", "raw": {"market": "0xcab7ba4a9133cfd407d7e73e5757e5abbace413b59421527a31113406c97815c", "asset_id": "20002636398944597965698652220992177552927816915094913583821579024925426590022", "price": "0.994", "size": "135.83", "side": "SELL", "timestamp": "1768475124216", "received_at": "2026-01-15T12:05:24.339386"}}
{"event_type": "price_change", "event_ts": "2026-01-15T12:05:24.339424", "ingestion_ts": "2026-01-15T12:08:42.168746", "market_id": "0xcab7ba4a9133cfd407d7e73e5757e5abbace413b59421527a31113406c97815c", "raw": {"market": "0xcab7ba4a9133cfd407d7e73e5757e5abbace413b59421527a31113406c97815c", "asset_id": "96361925776989336186111887920533578209326565663637092688733016597062311745569", "price": "0.008", "size": "619.71", "side": "BUY", "timestamp": "1768475124216", "received_at": "2026-01-15T12:05:24.339424"}}
{"event_type": "price_change", "event_ts": "2026-01-15T12:05:24.339424", "ingestion_ts": "2026-01-15T12:08:42.168746", "market_id": "0xcab7ba4a9133cfd407d7e73e5757e5abbace413b59421527a31113406c97815c", "raw": {"market": "0xcab7ba4a9133cfd407d7e73e5757e5abbace413b59421527a31113406c97815c", "asset_id": "20002636398944597965698652220992177552927816915094913583821579024925426590022", "price": "0.992", "size": "619.71", "side": "SELL", "timestamp": "1768475124216", "received_at": "2026-01-15T12:05:24.339424"}}
{"event_type": "price_change", "event_ts": "2026-01-15T12:05:25.018422", "ingestion_ts": "2026-01-15T12:08:42.168746", "market_id": "0xcab7ba4a9133cfd407d7e73e5757e5abbace413b59421527a31113406c97815c", "raw": {"market": "0xcab7ba4a9133cfd407d7e73e5757e5abbace413b59421527a31113406c97815c", "asset_id": "96361925776989336186111887920533578209326565663637092688733016597062311745569", "price": "0.008", "size": "625.9", "side": "BUY", "timestamp": "1768475124837", "received_at": "2026-01-15T12:05:25.018422"}}
{"event_type": "price_change", "event_ts": "2026-01-15T12:05:25.018422", "ingestion_ts": "2026-01-15T12:08:42.168746", "market_id": "0xcab7ba4a9133cfd407d7e73e5757e5abbace413b59421527a31113406c97815c", "raw": {"market": "0xcab7ba4a9133cfd407d7e73e5757e5abbace413b59421527a31113406c97815c", "asset_id": "20002636398944597965698652220992177552927816915094913583821579024925426590022", "price": "0.992", "size": "625.9", "side": "SELL", "timestamp": "1768475124837", "received_at": "2026-01-15T12:05:25.018422"}}
{"event_type": "price_change", "event_ts": "2026-01-15T12:05:25.018517", "ingestion_ts": "2026-01-15T12:08:42.168746", "market_id": "0xc0e6b917320a47228fb96e3b5ae0e5c93773a5ae2662ae4e1f37807cfe47ce98", "raw": {"market": "0xc0e6b917320a47228fb96e3b5ae0e5c93773a5ae2662ae4e1f37807cfe47ce98", "asset_id": "58656358377246279051017109359677190749228949103591068167284263961542487110215", "price": "0.01", "size": "58.07", "side": "BUY", "timestamp": "1768475124837", "received_at": "2026-01-15T12:05:25.018517"}}
{"event_type": "price_change", "event_ts": "2026-01-15T12:05:25.018517", "ingestion_ts": "2026-01-15T12:08:42.168746", "market_id": "0xc0e6b917320a47228fb96e3b5ae0e5c93773a5ae2662ae4e1f37807cfe47ce98", "raw": {"market": "0xc0e6b917320a47228fb96e3b5ae0e5c93773a5ae2662ae4e1f37807cfe47ce98", "asset_id": "81647294538046680798858716589766492074338758116170717123345952330712416337530", "price": "0.99", "size": "58.07", "side": "SELL", "timestamp": "1768475124837", "received_at": "2026-01-15T12:05:25.018517"}}
{"event_type": "price_change", "event_ts": "2026-01-15T12:05:25.021325", "ingestion_ts": "2026-01-15T12:08:42.168746", "market_id": "0xcab7ba4a9133cfd407d7e73e5757e5abbace413b59421527a31113406c97815c", "raw": {"market": "0xcab7ba4a9133cfd407d7e73e5757e5abbace413b59421527a31113406c97815c", "asset_id": "96361925776989336186111887920533578209326565663637092688733016597062311745569", "price": "0.008", "size": "632.09", "side": "BUY", "timestamp": "1768475124839", "received_at": "2026-01-15T12:05:25.021325"}}
{"event_type": "price_change", "event_ts": "2026-01-15T12:05:25.021325", "ingestion_ts": "2026-01-15T12:08:42.168746", "market_id": "0xcab7ba4a9133cfd407d7e73e5757e5abbace413b59421527a31113406c97815c", "raw": {"market": "0xcab7ba4a9133cfd407d7e73e5757e5abbace413b59421527a31113406c97815c", "asset_id": "20002636398944597965698652220992177552927816915094913583821579024925426590022", "price": "0.992", "size": "632.09", "side": "SELL", "timestamp": "1768475124839", "received_at": "2026-01-15T12:05:25.021325"}}
{"event_type": "price_change", "event_ts": "2026-01-15T12:05:27.779351", "ingestion_ts": "2026-01-15T12:08:42.168746", "market_id": "0xcab7ba4a9133cfd407d7e73e5757e5abbace413b59421527a31113406c97815c", "raw": {"market": "0xcab7ba4a9133cfd407d7e73e5757e5abbace413b59421527a31113406c97815c", "asset_id": "96361925776989336186111887920533578209326565663637092688733016597062311745569", "price": "0.006", "size": "127.41", "side": "BUY", "timestamp": "1768475127658", "received_at": "2026-01-15T12:05:27.779351"}}
{"event_type": "price_change", "event_ts": "2026-01-15T12:05:27.779351", "ingestion_ts": "2026-01-15T12:08:42.168746", "market_id": "0xcab7ba4a9133cfd407d7e73e5757e5abbace413b59421527a31113406c97815c", "raw": {"market": "0xcab7ba4a9133cfd407d7e73e5757e5abbace413b59421527a31113406c97815c", "asset_id": "20002636398944597965698652220992177552927816915094913583821579024925426590022", "price": "0.994", "size": "127.41", "side": "SELL", "timestamp": "1768475127658", "received_at": "2026-01-15T12:05:27.779351"}}
{"event_type": "price_change", "event_ts": "2026-01-15T12:05:27.779391", "ingestion_ts": "2026-01-15T12:08:42.168746", "market_id": "0xcab7ba4a9133cfd407d7e73e5757e5abbace413b59421527a31113406c97815c", "raw": {"market": "0xcab7ba4a9133cfd407d7e73e5757e5abbace413b59421527a31113406c97815c", "asset_id": "96361925776989336186111887920533578209326565663637092688733016597062311745569", "price": "0.008", "size": "625.9", "side": "BUY", "timestamp": "1768475127658", "received_at": "2026-01-15T12:05:27.779391"}}
{"event_type": "price_change", "event_ts": "2026-01-15T12:05:27.779391", "ingestion_ts": "2026-01-15T12:08:42.168746", "market_id": "0xcab7ba4a9133cfd407d7e73e5757e5abbace413b59421527a31113406c97815c", "raw": {"market": "0xcab7ba4a9133cfd407d7e73e5757e5abbace413b59421527a31113406c97815c", "asset_id": "20002636398944597965698652220992177552927816915094913583821579024925426590022", "price": "0.992", "size": "625.9", "side": "SELL", "timestamp": "1768475127658", "received_at": "2026-01-15T12:05:27.779391"}}
{"event_type": "price_change", "event_ts": "2026-01-15T12:05:28.245191", "ingestion_ts": "2026-01-15T12:08:42.168746", "market_id": "0xcab7ba4a9133cfd407d7e73e5757e5abbace413b59421527a31113406c97815c", "raw": {"market": "0xcab7ba4a9133cfd407d7e73e5757e5abbace413b59421527a31113406c97815c", "asset_id": "96361925776989336186111887920533578209326565663637092688733016597062311745569", "price": "0.006", "size": "135.75", "side": "BUY", "timestamp": "1768475128080", "received_at": "2026-01-15T12:05:28.245191"}}
{"event_type": "price_change", "event_ts": "2026-01-15T12:05:28.245191", "ingestion_ts": "2026-01-15T12:08:42.168746", "market_id": "0xcab7ba4a9133cfd407d7e73e5757e5abbace413b59421527a31113406c97815c", "raw": {"market": "0xcab7ba4a9133cfd407d7e73e5757e5abbace413b59421527a31113406c97815c", "asset_id": "20002636398944597965698652220992177552927816915094913583821579024925426590022", "price": "0.994", "size": "135.75", "side": "SELL", "timestamp": "1768475128080", "received_at": "2026-01-15T12:05:28.245191"}}
{"event_type": "price_change", "event_ts": "2026-01-15T12:05:28.246790", "ingestion_ts": "2026-01-15T12:08:42.168746", "market_id": "0xcab7ba4a9133cfd407d7e73e5757e5abbace413b59421527a31113406c97815c", "raw": {"market": "0xcab7ba4a9133cfd407d7e73e5757e5abbace413b59421527a31113406c97815c", "asset_id": "96361925776989336186111887920533578209326565663637092688733016597062311745569", "price": "0.006", "size": "144.09", "side": "BUY", "timestamp": "1768475128081", "received_at": "2026-01-15T12:05:28.246790"}}
{"event_type": "price_change", "event_ts": "2026-01-15T12:05:28.246790", "ingestion_ts": "2026-01-15T12:08:42.168746", "market_id": "0xcab7ba4a9133cfd407d7e73e5757e5abbace413b59421527a31113406c97815c", "raw": {"market": "0xcab7ba4a9133cfd407d7e73e5757e5abbace413b59421527a31113406c97815c", "asset_id": "20002636398944597965698652220992177552927816915094913583821579024925426590022", "price": "0.994", "size": "144.09", "side": "SELL", "timestamp": "1768475128081", "received_at": "2026-01-15T12:05:28.246790"}}
{"event_type": "price_change", "event_ts": "2026-01-15T12:05:28.468253", "ingestion_ts": "2026-01-15T12:08:42.168746", "market_id": "0x49686d26fb712515cd5e12c23f0a1c7e10214c7faa3cb0a730aabe0c33694082", "raw": {"market": "0x49686d26fb712515cd5e12c23f0a1c7e10214c7faa3cb0a730aabe0c33694082", "asset_id": "13244681086321087932946246027856416106585284024824496763706748621681543444582", "price": "0.297", "size": "1010", "side": "BUY", "timestamp": "1768475128349", "received_at": "2026-01-15T12:05:28.468253"}}
{"event_type": "price_change", "event_ts": "2026-01-15T12:05:28.468253", "ingestion_ts": "2026-01-15T12:08:42.168746", "market_id": "0x49686d26fb712515cd5e12c23f0a1c7e10214c7faa3cb0a730aabe0c33694082", "raw": {"market": "0x49686d26fb712515cd5e12c23f0a1c7e10214c7faa3cb0a730aabe0c33694082", "asset_id": "30442780799048074404860985387051749017905070253466005720364298335239299761065", "price": "0.703", "size": "1010", "side": "SELL", "timestamp": "1768475128349", "received_at": "2026-01-15T12:05:28.468253"}}
{"event_type": "price_change", "event_ts": "2026-01-15T12:05:28.705616", "ingestion_ts": "2026-01-15T12:08:42.168746", "market_id": "0x50c669f178da4e5bbea7f1be25041fd278914712fa87a6a6f8e57d5923d88dee", "raw": {"market": "0x50c669f178da4e5bbea7f1be25041fd278914712fa87a6a6f8e57d5923d88dee", "asset_id": "74040420326294854165772767082819937451857852955603897473157746262672057685461", "price": "0.932", "size": "0", "side": "BUY", "timestamp": "1768475128588", "received_at": "2026-01-15T12:05:28.705616"}}
{"event_type": "price_change", "event_ts": "2026-01-15T12:05:28.705616", "ingestion_ts": "2026-01-15T12:08:42.168746", "market_id": "0x50c669f178da4e5bbea7f1be25041fd278914712fa87a6a6f8e57d5923d88dee", "raw": {"market": "0x50c669f178da4e5bbea7f1be25041fd278914712fa87a6a6f8e57d5923d88dee", "asset_id": "24682525479474221428144937281315825971983904267399062415430320764754931667953", "price": "0.068", "size": "0", "side": "SELL", "timestamp": "1768475128588", "received_at": "2026-01-15T12:05:28.705616"}}
{"event_type": "price_change", "event_ts": "2026-01-15T12:05:29.004924", "ingestion_ts": "2026-01-15T12:08:42.168746", "market_id": "0x50c669f178da4e5bbea7f1be25041fd278914712fa87a6a6f8e57d5923d88dee", "raw": {"market": "0x50c669f178da4e5bbea7f1be25041fd278914712fa87a6a6f8e57d5923d88dee", "asset_id": "74040420326294854165772767082819937451857852955603897473157746262672057685461", "price": "0.865", "size": "10", "side": "BUY", "timestamp": "1768475128884", "received_at": "2026-01-15T12:05:29.004924"}}
{"event_type": "price_change", "event_ts": "2026-01-15T12:05:29.004924", "ingestion_ts": "2026-01-15T12:08:42.168746", "market_id": "0x50c669f178da4e5bbea7f1be25041fd278914712fa87a6a6f8e57d5923d88dee", "raw": {"market": "0x50c669f178da4e5bbea7f1be25041fd278914712fa87a6a6f8e57d5923d88dee", "asset_id": "24682525479474221428144937281315825971983904267399062415430320764754931667953", "price": "0.135", "size": "10", "side": "SELL", "timestamp": "1768475128884", "received_at": "2026-01-15T12:05:29.004924"}}
{"event_type": "price_change", "event_ts": "2026-01-15T12:05:29.005091", "ingestion_ts": "2026-01-15T12:08:42.168746", "market_id": "0x50c669f178da4e5bbea7f1be25041fd278914712fa87a6a6f8e57d5923d88dee", "raw": {"market": "0x50c669f178da4e5bbea7f1be25041fd278914712fa87a6a6f8e57d5923d88dee", "asset_id": "74040420326294854165772767082819937451857852955603897473157746262672057685461", "price": "0.931", "size": "876", "side": "BUY", "timestamp": "1768475128885", "received_at": "2026-01-15T12:05:29.005091"}}
{"event_type": "price_change", "event_ts": "2026-01-15T12:05:29.005091", "ingestion_ts": "2026-01-15T12:08:42.168746", "market_id": "0x50c669f178da4e5bbea7f1be25041fd278914712fa87a6a6f8e57d5923d88dee", "raw": {"market": "0x50c669f178da4e5bbea7f1be25041fd278914712fa87a6a6f8e57d5923d88dee", "asset_id": "24682525479474221428144937281315825971983904267399062415430320764754931667953", "price": "0.069", "size": "876", "side": "SELL", "timestamp": "1768475128885", "received_at": "2026-01-15T12:05:29.005091"}}
{"event_type": "price_change", "event_ts": "2026-01-15T12:05:29.213696", "ingestion_ts": "2026-01-15T12:08:42.168746", "market_id": "0xc0e6b917320a47228fb96e3b5ae0e5c93773a5ae2662ae4e1f37807cfe47ce98", "raw": {"market": "0xc0e6b917320a47228fb96e3b5ae0e5c93773a5ae2662ae4e1f37807cfe47ce98", "asset_id": "58656358377246279051017109359677190749228949103591068167284263961542487110215", "price": "0.01", "size": "0", "side": "BUY", "timestamp": "1768475129097", "received_at": "2026-01-15T12:05:29.213696"}}
{"event_type": "price_change", "event_ts": "2026-01-15T12:05:29.213696", "ingestion_ts": "2026-01-15T12:08:42.168746", "market_id": "0xc0e6b917320a47228fb96e3b5ae0e5c93773a5ae2662ae4e1f37807cfe47ce98", "raw": {"market": "0xc0e6b917320a47228fb96e3b5ae0e5c93773a5ae2662ae4e1f37807cfe47ce98", "asset_id": "81647294538046680798858716589766492074338758116170717123345952330712416337530", "price": "0.99", "size": "0", "side": "SELL", "timestamp": "1768475129097", "received_at": "2026-01-15T12:05:29.213696"}}
{"event_type": "price_change", "event_ts": "2026-01-15T12:05:30.039416", "ingestion_ts": "2026-01-15T12:08:42.168746", "market_id": "0x49686d26fb712515cd5e12c23f0a1c7e10214c7faa3cb0a730aabe0c33694082", "raw": {"market": "0x49686d26fb712515cd5e12c23f0a1c7e10214c7faa3cb0a730aabe0c33694082", "asset_id": "13244681086321087932946246027856416106585284024824496763706748621681543444582", "price": "0.91", "size": "108", "side": "SELL", "timestamp": "1768475129802", "received_at": "2026-01-15T12:05:30.039416"}}
{"event_type": "price_change", "event_ts": "2026-01-15T12:05:30.039416", "ingestion_ts": "2026-01-15T12:08:42.168746", "market_id": "0x49686d26fb712515cd5e12c23f0a1c7e10214c7faa3cb0a730aabe0c33694082", "raw": {"market": "0x49686d26fb712515cd5e12c23f0a1c7e10214c7faa3cb0a730aabe0c33694082", "asset_id": "30442780799048074404860985387051749017905070253466005720364298335239299761065", "price": "0.09", "size": "108", "side": "BUY", "timestamp": "1768475129802", "received_at": "2026-01-15T12:05:30.039416"}}
{"event_type": "price_change", "event_ts": "2026-01-15T12:05:30.650747", "ingestion_ts": "2026-01-15T12:08:42.168746", "market_id": "0xcab7ba4a9133cfd407d7e73e5757e5abbace413b59421527a31113406c97815c", "raw": {"market": "0xcab7ba4a9133cfd407d7e73e5757e5abbace413b59421527a31113406c97815c", "asset_id": "96361925776989336186111887920533578209326565663637092688733016597062311745569", "price": "0.006", "size": "135.75", "side": "BUY", "timestamp": "1768475130317", "received_at": "2026-01-15T12:05:30.650747"}}
{"event_type": "price_change", "event_ts": "2026-01-15T12:05:30.650747", "ingestion_ts": "2026-01-15T12:08:42.168746", "market_id": "0xcab7ba4a9133cfd407d7e73e5757e5abbace413b59421527a31113406c97815c", "raw": {"market": "0xcab7ba4a9133cfd407d7e73e5757e5abbace413b59421527a31113406c97815c", "asset_id": "20002636398944597965698652220992177552927816915094913583821579024925426590022", "price": "0.994", "size": "135.75", "side": "SELL", "timestamp": "1768475130317", "received_at": "2026-01-15T12:05:30.650747"}}
{"event_type": "price_change", "event_ts": "2026-01-15T12:05:30.650854", "ingestion_ts": "2026-01-15T12:08:42.168746", "market_id": "0xcab7ba4a9133cfd407d7e73e5757e5abbace413b59421527a31113406c97815c", "raw": {"market": "0xcab7ba4a9133cfd407d7e73e5757e5abbace413b59421527a31113406c97815c", "asset_id": "96361925776989336186111887920533578209326565663637092688733016597062311745569", "price": "0.008", "size": "619.71", "side": "BUY", "timestamp": "1768475130317", "received_at": "2026-01-15T12:05:30.650854"}}
{"event_type": "price_change", "event_ts": "2026-01-15T12:05:30.650854", "ingestion_ts": "2026-01-15T12:08:42.168746", "market_id": "0xcab7ba4a9133cfd407d7e73e5757e5abbace413b59421527a31113406c97815c", "raw": {"market": "0xcab7ba4a9133cfd407d7e73e5757e5abbace413b59421527a31113406c97815c", "asset_id": "20002636398944597965698652220992177552927816915094913583821579024925426590022", "price": "0.992", "size": "619.71", "side": "SELL", "timestamp": "1768475130317", "received_at": "2026-01-15T12:05:30.650854"}}
{"event_type": "price_change", "event_ts": "2026-01-15T12:05:30.773547", "ingestion_ts": "2026-01-15T12:08:42.168746", "market_id": "0xc0e6b917320a47228fb96e3b5ae0e5c93773a5ae2662ae4e1f37807cfe47ce98", "raw": {"market": "0xc0e6b917320a47228fb96e3b5ae0e5c93773a5ae2662ae4e1f37807cfe47ce98", "asset_id": "58656358377246279051017109359677190749228949103591068167284263961542487110215", "price": "0.003", "size": "305.85", "side": "BUY", "timestamp": "1768475130428", "received_at": "2026-01-15T12:05:30.773547"}}
{"event_type": "price_change", "event_ts": "2026-01-15T12:05:30.773547", "ingestion_ts": "2026-01-15T12:08:42.168746", "market_id": "0xc0e6b917320a47228fb96e3b5ae0e5c93773a5ae2662ae4e1f37807cfe47ce98", "raw": {"market": "0xc0e6b917320a47228fb96e3b5ae0e5c93773a5ae2662ae4e1f37807cfe47ce98", "asset_id": "81647294538046680798858716589766492074338758116170717123345952330712416337530", "price": "0.997", "size": "305.85", "side": "SELL", "timestamp": "1768475130428", "received_at": "2026-01-15T12:05:30.773547"}}
{"event_type": "price_change", "event_ts": "2026-01-15T12:05:30.774566", "ingestion_ts": "2026-01-15T12:08:42.168746", "market_id": "0xc0e6b917320a47228fb96e3b5ae0e5c93773a5ae2662ae4e1f37807cfe47ce98", "raw": {"market": "0xc0e6b917320a47228fb96e3b5ae0e5c93773a5ae2662ae4e1f37807cfe47ce98", "asset_id": "58656358377246279051017109359677190749228949103591068167284263961542487110215", "price": "0.011", "size": "41.48", "side": "BUY", "timestamp": "1768475130429", "received_at": "2026-01-15T12:05:30.774566"}}
{"event_type": "price_change", "event_ts": "2026-01-15T12:05:30.774566", "ingestion_ts": "2026-01-15T12:08:42.168746", "market_id": "0xc0e6b917320a47228fb96e3b5ae0e5c93773a5ae2662ae4e1f37807cfe47ce98", "raw": {"market": "0xc0e6b917320a47228fb96e3b5ae0e5c93773a5ae2662ae4e1f37807cfe47ce98", "asset_id": "81647294538046680798858716589766492074338758116170717123345952330712416337530", "price": "0.989", "size": "41.48", "side": "SELL", "timestamp": "1768475130429", "received_at": "2026-01-15T12:05:30.774566"}}
{"event_type": "price_change", "event_ts": "2026-01-15T12:05:31.124793", "ingestion_ts": "2026-01-15T12:08:42.168746", "market_id": "0x49686d26fb712515cd5e12c23f0a1c7e10214c7faa3cb0a730aabe0c33694082", "raw": {"market": "0x49686d26fb712515cd5e12c23f0a1c7e10214c7faa3cb0a730aabe0c33694082", "asset_id": "30442780799048074404860985387051749017905070253466005720364298335239299761065", "price": "0.089", "size": "0", "side": "BUY", "timestamp": "1768475130967", "received_at": "2026-01-15T12:05:31.124793"}}
{"event_type": "price_change", "event_ts": "2026-01-15T12:05:31.124793", "ingestion_ts": "2026-01-15T12:08:42.168746", "market_id": "0x49686d26fb712515cd5e12c23f0a1c7e10214c7faa3cb0a730aabe0c33694082", "raw": {"market": "0x49686d26fb712515cd5e12c23f0a1c7e10214c7faa3cb0a730aabe0c33694082", "asset_id": "13244681086321087932946246027856416106585284024824496763706748621681543444582", "price": "0.911", "size": "0", "side": "SELL", "timestamp": "1768475130967", "received_at": "2026-01-15T12:05:31.124793"}}
{"event_type": "price_change", "event_ts": "2026-01-15T12:05:31.178582", "ingestion_ts": "2026-01-15T12:08:42.168746", "market_id": "0xcab7ba4a9133cfd407d7e73e5757e5abbace413b59421527a31113406c97815c", "raw": {"market": "0xcab7ba4a9133cfd407d7e73e5757e5abbace413b59421527a31113406c97815c", "asset_id": "96361925776989336186111887920533578209326565663637092688733016597062311745569", "price": "0.008", "size": "625.93", "side": "BUY", "timestamp": "1768475131031", "received_at": "2026-01-15T12:05:31.178582"}}
{"event_type": "price_change", "event_ts": "2026-01-15T12:05:31.178582", "ingestion_ts": "2026-01-15T12:08:42.168746", "market_id": "0xcab7ba4a9133cfd407d7e73e5757e5abbace413b59421527a31113406c97815c", "raw": {"market": "0xcab7ba4a9133cfd407d7e73e5757e5abbace413b59421527a31113406c97815c", "asset_id": "20002636398944597965698652220992177552927816915094913583821579024925426590022", "price": "0.992", "size": "625.93", "side": "SELL", "timestamp": "1768475131031", "received_at": "2026-01-15T12:05:31.178582"}}
{"event_type": "price_change", "event_ts": "2026-01-15T12:05:31.180309", "ingestion_ts": "2026-01-15T12:08:42.168746", "market_id": "0xcab7ba4a9133cfd407d7e73e5757e5abbace413b59421527a31113406c97815c", "raw": {"market": "0xcab7ba4a9133cfd407d7e73e5757e5abbace413b59421527a31113406c97815c", "asset_id": "96361925776989336186111887920533578209326565663637092688733016597062311745569", "price": "0.008", "size": "632.15", "side": "BUY", "timestamp": "1768475131033", "received_at": "2026-01-15T12:05:31.180309"}}
{"event_type": "price_change", "event_ts": "2026-01-15T12:05:31.180309", "ingestion_ts": "2026-01-15T12:08:42.168746", "market_id": "0xcab7ba4a9133cfd407d7e73e5757e5abbace413b59421527a31113406c97815c", "raw": {"market": "0xcab7ba4a9133cfd407d7e73e5757e5abbace413b59421527a31113406c97815c", "asset_id": "20002636398944597965698652220992177552927816915094913583821579024925426590022", "price": "0.992", "size": "632.15", "side": "SELL", "timestamp": "1768475131033", "received_at": "2026-01-15T12:05:31.180309"}}
{"event_type": "price_change", "event_ts": "2026-01-15T12:05:31.203832", "ingestion_ts": "2026-01-15T12:08:42.168746", "market_id": "0x49686d26fb712515cd5e12c23f0a1c7e10214c7faa3cb0a730aabe0c33694082", "raw": {"market": "0x49686d26fb712515cd5e12c23f0a1c7e10214c7faa3cb0a730aabe0c33694082", "asset_id": "30442780799048074404860985387051749017905070253466005720364298335239299761065", "price": "0.091", "size": "22.73", "side": "BUY", "timestamp": "1768475131071", "received_at": "2026-01-15T12:05:31.203832"}}
{"event_type": "price_change", "event_ts": "2026-01-15T12:05:31.203832", "ingestion_ts": "2026-01-15T12:08:42.168746", "market_id": "0x49686d26fb712515cd5e12c23f0a1c7e10214c7faa3cb0a730aabe0c33694082", "raw": {"market": "0x49686d26fb712515cd5e12c23f0a1c7e10214c7faa3cb0a730aabe0c33694082", "asset_id": "13244681086321087932946246027856416106585284024824496763706748621681543444582", "price": "0.909", "size": "22.73", "side": "SELL", "timestamp": "1768475131071", "received_at": "2026-01-15T12:05:31.203832"}}
{"event_type": "price_change", "event_ts": "2026-01-15T12:05:31.220313", "ingestion_ts": "2026-01-15T12:08:42.168746", "market_id": "0x49686d26fb712515cd5e12c23f0a1c7e10214c7faa3cb0a730aabe0c33694082", "raw": {"market": "0x49686d26fb712515cd5e12c23f0a1c7e10214c7faa3cb0a730aabe0c33694082", "asset_id": "13244681086321087932946246027856416106585284024824496763706748621681543444582", "price": "0.91", "size": "0", "side": "SELL", "timestamp": "1768475131098", "received_at": "2026-01-15T12:05:31.220313"}}
{"event_type": "price_change", "event_ts": "2026-01-15T12:05:31.220313", "ingestion_ts": "2026-01-15T12:08:42.168746", "market_id": "0x49686d26fb712515cd5e12c23f0a1c7e10214c7faa3cb0a730aabe0c33694082", "raw": {"market": "0x49686d26fb712515cd5e12c23f0a1c7e10214c7faa3cb0a730aabe0c33694082", "asset_id": "30442780799048074404860985387051749017905070253466005720364298335239299761065", "price": "0.09", "size": "0", "side": "BUY", "timestamp": "1768475131098", "received_at": "2026-01-15T12:05:31.220313"}}
{"event_type": "price_change", "event_ts": "2026-01-15T12:05:31.249582", "ingestion_ts": "2026-01-15T12:08:42.168746", "market_id": "0x49686d26fb712515cd5e12c23f0a1c7e10214c7faa3cb0a730aabe0c33694082", "raw": {"market": "0x49686d26fb712515cd5e12c23f0a1c7e10214c7faa3cb0a730aabe0c33694082", "asset_id": "13244681086321087932946246027856416106585284024824496763706748621681543444582", "price": "0.908", "size": "108", "side": "SELL", "timestamp": "1768475131130", "received_at": "2026-01-15T12:05:31.249582"}}
{"event_type": "price_change", "event_ts": "2026-01-15T12:05:31.249582", "ingestion_ts": "2026-01-15T12:08:42.168746", "market_id": "0x49686d26fb712515cd5e12c23f0a1c7e10214c7faa3cb0a730aabe0c33694082", "raw": {"market": "0x49686d26fb712515cd5e12c23f0a1c7e10214c7faa3cb0a730aabe0c33694082", "asset_id": "30442780799048074404860985387051749017905070253466005720364298335239299761065", "price": "0.092", "size": "108", "side": "BUY", "timestamp": "1768475131130", "received_at": "2026-01-15T12:05:31.249582"}}
{"event_type": "price_change", "event_ts": "2026-01-15T12:05:31.905385", "ingestion_ts": "2026-01-15T12:08:42.168746", "market_id": "0x49686d26fb712515cd5e12c23f0a1c7e10214c7faa3cb0a730aabe0c33694082", "raw": {"market": "0x49686d26fb712515cd5e12c23f0a1c7e10214c7faa3cb0a730aabe0c33694082", "asset_id": "30442780799048074404860985387051749017905070253466005720364298335239299761065", "price": "0.091", "size": "0", "side": "BUY", "timestamp": "1768475131784", "received_at": "2026-01-15T12:05:31.905385"}}
{"event_type": "price_change", "event_ts": "2026-01-15T12:05:31.905385", "ingestion_ts": "2026-01-15T12:08:42.168746", "market_id": "0x49686d26fb712515cd5e12c23f0a1c7e10214c7faa3cb0a730aabe0c33694082", "raw": {"market": "0x49686d26fb712515cd5e12c23f0a1c7e10214c7faa3cb0a730aabe0c33694082", "asset_id": "13244681086321087932946246027856416106585284024824496763706748621681543444582", "price": "0.909", "size": "0", "side": "SELL", "timestamp": "1768475131784", "received_at": "2026-01-15T12:05:31.905385"}}
{"event_type": "price_change", "event_ts": "2026-01-15T12:05:31.969594", "ingestion_ts": "2026-01-15T12:08:42.168746", "market_id": "0x49686d26fb712515cd5e12c23f0a1c7e10214c7faa3cb0a730aabe0c33694082", "raw": {"market": "0x49686d26fb712515cd5e12c23f0a1c7e10214c7faa3cb0a730aabe0c33694082", "asset_id": "30442780799048074404860985387051749017905070253466005720364298335239299761065", "price": "0.093", "size": "22.73", "side": "BUY", "timestamp": "1768475131837", "received_at": "2026-01-15T12:05:31.969594"}}
{"event_type": "price_change", "event_ts": "2026-01-15T12:05:31.969594", "ingestion_ts": "2026-01-15T12:08:42.168746", "market_id": "0x49686d26fb712515cd5e12c23f0a1c7e10214c7faa3cb0a730aabe0c33694082", "raw": {"market": "0x49686d26fb712515cd5e12c23f0a1c7e10214c7faa3cb0a730aabe0c33694082", "asset_id": "13244681086321087932946246027856416106585284024824496763706748621681543444582", "price": "0.907", "size": "22.73", "side": "SELL", "timestamp": "1768475131837", "received_at": "2026-01-15T12:05:31.969594"}}
{"event_type": "price_change", "event_ts": "2026-01-15T12:05:32.422172", "ingestion_ts": "2026-01-15T12:08:42.168746", "market_id": "0x49686d26fb712515cd5e12c23f0a1c7e10214c7faa3cb0a730aabe0c33694082", "raw": {"market": "0x49686d26fb712515cd5e12c23f0a1c7e10214c7faa3cb0a730aabe0c33694082", "asset_id": "13244681086321087932946246027856416106585284024824496763706748621681543444582", "price": "0.908", "size": "0", "side": "SELL", "timestamp": "1768475132299", "received_at": "2026-01-15T12:05:32.422172"}}
{"event_type": "price_change", "event_ts": "2026-01-15T12:05:32.422172", "ingestion_ts": "2026-01-15T12:08:42.168746", "market_id": "0x49686d26fb712515cd5e12c23f0a1c7e10214c7faa3cb0a730aabe0c33694082", "raw": {"market": "0x49686d26fb712515cd5e12c23f0a1c7e10214c7faa3cb0a730aabe0c33694082", "asset_id": "30442780799048074404860985387051749017905070253466005720364298335239299761065", "price": "0.092", "size": "0", "side": "BUY", "timestamp": "1768475132299", "received_at": "2026-01-15T12:05:32.422172"}}
{"event_type": "price_change", "event_ts": "2026-01-15T12:05:32.460995", "ingestion_ts": "2026-01-15T12:08:42.168746", "market_id": "0x49686d26fb712515cd5e12c23f0a1c7e10214c7faa3cb0a730aabe0c33694082", "raw": {"market": "0x49686d26fb712515cd5e12c23f0a1c7e10214c7faa3cb0a730aabe0c33694082", "asset_id": "13244681086321087932946246027856416106585284024824496763706748621681543444582", "price": "0.906", "size": "112", "side": "SELL", "timestamp": "1768475132335", "received_at": "2026-01-15T12:05:32.460995"}}
{"event_type": "price_change", "event_ts": "2026-01-15T12:05:32.460995", "ingestion_ts": "2026-01-15T12:08:42.168746", "market_id": "0x49686d26fb712515cd5e12c23f0a1c7e10214c7faa3cb0a730aabe0c33694082", "raw": {"market": "0x49686d26fb712515cd5e12c23f0a1c7e10214c7faa3cb0a730aabe0c33694082", "asset_id": "30442780799048074404860985387051749017905070253466005720364298335239299761065", "price": "0.094", "size": "112", "side": "BUY", "timestamp": "1768475132335", "received_at": "2026-01-15T12:05:32.460995"}}
{"event_type": "price_change", "event_ts": "2026-01-15T12:05:32.671425", "ingestion_ts": "2026-01-15T12:08:42.168746", "market_id": "0xb9bbdd34304344dcc45803780a34c97d73a00133a5ecf70f63e1008b8abb2fca", "raw": {"market": "0xb9bbdd34304344dcc45803780a34c97d73a00133a5ecf70f63e1008b8abb2fca", "asset_id": "8682484153073832526711485265636767086525069344085206423986003504588877767339", "price": "0.928", "size": "0", "side": "BUY", "timestamp": "1768475132525", "received_at": "2026-01-15T12:05:32.671425"}}
{"event_type": "price_change", "event_ts": "2026-01-15T12:05:32.671425", "ingestion_ts": "2026-01-15T12:08:42.168746", "market_id": "0xb9bbdd34304344dcc45803780a34c97d73a00133a5ecf70f63e1008b8abb2fca", "raw": {"market": "0xb9bbdd34304344dcc45803780a34c97d73a00133a5ecf70f63e1008b8abb2fca", "asset_id": "72012724360700510767037780555710363830014634797787940282136454146828040926557", "price": "0.072", "size": "0", "side": "SELL", "timestamp": "1768475132525", "received_at": "2026-01-15T12:05:32.671425"}}
{"event_type": "price_change", "event_ts": "2026-01-15T12:05:32.688072", "ingestion_ts": "2026-01-15T12:08:42.168746", "market_id": "0x50c669f178da4e5bbea7f1be25041fd278914712fa87a6a6f8e57d5923d88dee", "raw": {"market": "0x50c669f178da4e5bbea7f1be25041fd278914712fa87a6a6f8e57d5923d88dee", "asset_id": "74040420326294854165772767082819937451857852955603897473157746262672057685461", "price": "0.864", "size": "0", "side": "BUY", "timestamp": "1768475132570", "received_at": "2026-01-15T12:05:32.688072"}}
{"event_type": "price_change", "event_ts": "2026-01-15T12:05:32.688072", "ingestion_ts": "2026-01-15T12:08:42.168746", "market_id": "0x50c669f178da4e5bbea7f1be25041fd278914712fa87a6a6f8e57d5923d88dee", "raw": {"market": "0x50c669f178da4e5bbea7f1be25041fd278914712fa87a6a6f8e57d5923d88dee", "asset_id": "24682525479474221428144937281315825971983904267399062415430320764754931667953", "price": "0.136", "size": "0", "side": "SELL", "timestamp": "1768475132570", "received_at": "2026-01-15T12:05:32.688072"}}
{"event_type": "price_change", "event_ts": "2026-01-15T12:05:32.715898", "ingestion_ts": "2026-01-15T12:08:42.168746", "market_id": "0x50c669f178da4e5bbea7f1be25041fd278914712fa87a6a6f8e57d5923d88dee", "raw": {"market": "0x50c669f178da4e5bbea7f1be25041fd278914712fa87a6a6f8e57d5923d88dee", "asset_id": "74040420326294854165772767082819937451857852955603897473157746262672057685461", "price": "0.866", "size": "5", "side": "BUY", "timestamp": "1768475132595", "received_at": "2026-01-15T12:05:32.715898"}}
{"event_type": "price_change", "event_ts": "2026-01-15T12:05:32.715898", "ingestion_ts": "2026-01-15T12:08:42.168746", "market_id": "0x50c669f178da4e5bbea7f1be25041fd278914712fa87a6a6f8e57d5923d88dee", "raw": {"market": "0x50c669f178da4e5bbea7f1be25041fd278914712fa87a6a6f8e57d5923d88dee", "asset_id": "24682525479474221428144937281315825971983904267399062415430320764754931667953", "price": "0.134", "size": "5", "side": "SELL", "timestamp": "1768475132595", "received_at": "2026-01-15T12:05:32.715898"}}
{"event_type": "price_change", "event_ts": "2026-01-15T12:05:32.805278", "ingestion_ts": "2026-01-15T12:08:42.168746", "market_id": "0xb9bbdd34304344dcc45803780a34c97d73a00133a5ecf70f63e1008b8abb2fca", "raw": {"market": "0xb9bbdd34304344dcc45803780a34c97d73a00133a5ecf70f63e1008b8abb2fca", "asset_id": "8682484153073832526711485265636767086525069344085206423986003504588877767339", "price": "0.87", "size": "10", "side": "BUY", "timestamp": "1768475132651", "received_at": "2026-01-15T12:05:32.805278"}}
{"event_type": "price_change", "event_ts": "2026-01-15T12:05:32.805278", "ingestion_ts": "2026-01-15T12:08:42.168746", "market_id": "0xb9bbdd34304344dcc45803780a34c97d73a00133a5ecf70f63e1008b8abb2fca", "raw": {"market": "0xb9bbdd34304344dcc45803780a34c97d73a00133a5ecf70f63e1008b8abb2fca", "asset_id": "72012724360700510767037780555710363830014634797787940282136454146828040926557", "price": "0.13", "size": "10", "side": "SELL", "timestamp": "1768475132651", "received_at": "2026-01-15T12:05:32.805278"}}
{"event_type": "price_change", "event_ts": "2026-01-15T12:05:32.805448", "ingestion_ts": "2026-01-15T12:08:42.168746", "market_id": "0xb9bbdd34304344dcc45803780a34c97d73a00133a5ecf70f63e1008b8abb2fca", "raw": {"market": "0xb9bbdd34304344dcc45803780a34c97d73a00133a5ecf70f63e1008b8abb2fca", "asset_id": "8682484153073832526711485265636767086525069344085206423986003504588877767339", "price": "0.928", "size": "20", "side": "BUY", "timestamp": "1768475132652", "received_at": "2026-01-15T12:05:32.805448"}}
{"event_type": "price_change", "event_ts": "2026-01-15T12:05:32.805448", "ingestion_ts": "2026-01-15T12:08:42.168746", "market_id": "0xb9bbdd34304344dcc45803780a34c97d73a00133a5ecf70f63e1008b8abb2fca", "raw": {"market": "0xb9bbdd34304344dcc45803780a34c97d73a00133a5ecf70f63e1008b8abb2fca", "asset_id": "72012724360700510767037780555710363830014634797787940282136454146828040926557", "price": "0.072", "size": "20", "side": "SELL", "timestamp": "1768475132652", "received_at": "2026-01-15T12:05:32.805448"}}
{"event_type": "price_change", "event_ts": "2026-01-15T12:05:32.837468", "ingestion_ts": "2026-01-15T12:08:42.168746", "market_id": "0xcab7ba4a9133cfd407d7e73e5757e5abbace413b59421527a31113406c97815c", "raw": {"market": "0xcab7ba4a9133cfd407d7e73e5757e5abbace413b59421527a31113406c97815c", "asset_id": "96361925776989336186111887920533578209326565663637092688733016597062311745569", "price": "0.006", "size": "127.41", "side": "BUY", "timestamp": "1768475132712", "received_at": "2026-01-15T12:05:32.837468"}}
{"event_type": "price_change", "event_ts": "2026-01-15T12:05:32.837468", "ingestion_ts": "2026-01-15T12:08:42.168746", "market_id": "0xcab7ba4a9133cfd407d7e73e5757e5abbace413b59421527a31113406c97815c", "raw": {"market": "0xcab7ba4a9133cfd407d7e73e5757e5abbace413b59421527a31113406c97815c", "asset_id": "20002636398944597965698652220992177552927816915094913583821579024925426590022", "price": "0.994", "size": "127.41", "side": "SELL", "timestamp": "1768475132712", "received_at": "2026-01-15T12:05:32.837468"}}
{"event_type": "price_change", "event_ts": "2026-01-15T12:05:32.837569", "ingestion_ts": "2026-01-15T12:08:42.168746", "market_id": "0xcab7ba4a9133cfd407d7e73e5757e5abbace413b59421527a31113406c97815c", "raw": {"market": "0xcab7ba4a9133cfd407d7e73e5757e5abbace413b59421527a31113406c97815c", "asset_id": "96361925776989336186111887920533578209326565663637092688733016597062311745569", "price": "0.008", "size": "625.93", "side": "BUY", "timestamp": "1768475132712", "received_at": "2026-01-15T12:05:32.837569"}}
{"event_type": "price_change", "event_ts": "2026-01-15T12:05:32.837569", "ingestion_ts": "2026-01-15T12:08:42.168746", "market_id": "0xcab7ba4a9133cfd407d7e73e5757e5abbace413b59421527a31113406c97815c", "raw": {"market": "0xcab7ba4a9133cfd407d7e73e5757e5abbace413b59421527a31113406c97815c", "asset_id": "20002636398944597965698652220992177552927816915094913583821579024925426590022", "price": "0.992", "size": "625.93", "side": "SELL", "timestamp": "1768475132712", "received_at": "2026-01-15T12:05:32.837569"}}
{"event_type": "price_change", "event_ts": "2026-01-15T12:05:33.639998", "ingestion_ts": "2026-01-15T12:08:42.168746", "market_id": "0xcab7ba4a9133cfd407d7e73e5757e5abbace413b59421527a31113406c97815c", "raw": {"market": "0xcab7ba4a9133cfd407d7e73e5757e5abbace413b59421527a31113406c97815c", "asset_id": "96361925776989336186111887920533578209326565663637092688733016597062311745569", "price": "0.006", "size": "135.73", "side": "BUY", "timestamp": "1768475133505", "received_at": "2026-01-15T12:05:33.639998"}}
{"event_type": "price_change", "event_ts": "2026-01-15T12:05:33.639998", "ingestion_ts": "2026-01-15T12:08:42.168746", "market_id": "0xcab7ba4a9133cfd407d7e73e5757e5abbace413b59421527a31113406c97815c", "raw": {"market": "0xcab7ba4a9133cfd407d7e73e5757e5abbace413b59421527a31113406c97815c", "asset_id": "20002636398944597965698652220992177552927816915094913583821579024925426590022", "price": "0.994", "size": "135.73", "side": "SELL", "timestamp": "1768475133505", "received_at": "2026-01-15T12:05:33.639998"}}
{"event_type": "price_change", "event_ts": "2026-01-15T12:05:33.640035", "ingestion_ts": "2026-01-15T12:08:42.168746", "market_id": "0xcab7ba4a9133cfd407d7e73e5757e5abbace413b59421527a31113406c97815c", "raw": {"market": "0xcab7ba4a9133cfd407d7e73e5757e5abbace413b59421527a31113406c97815c", "asset_id": "96361925776989336186111887920533578209326565663637092688733016597062311745569", "price": "0.006", "size": "144.05", "side": "BUY", "timestamp": "1768475133506", "received_at": "2026-01-15T12:05:33.640035"}}
{"event_type": "price_change", "event_ts": "2026-01-15T12:05:33.640035", "ingestion_ts": "2026-01-15T12:08:42.168746", "market_id": "0xcab7ba4a9133cfd407d7e73e5757e5abbace413b59421527a31113406c97815c", "raw": {"market": "0xcab7ba4a9133cfd407d7e73e5757e5abbace413b59421527a31113406c97815c", "asset_id": "20002636398944597965698652220992177552927816915094913583821579024925426590022", "price": "0.994", "size": "144.05", "side": "SELL", "timestamp": "1768475133506", "received_at": "2026-01-15T12:05:33.640035"}}
{"event_type": "price_change", "event_ts": "2026-01-15T12:05:33.648872", "ingestion_ts": "2026-01-15T12:08:42.168746", "market_id": "0x49686d26fb712515cd5e12c23f0a1c7e10214c7faa3cb0a730aabe0c33694082", "raw": {"market": "0x49686d26fb712515cd5e12c23f0a1c7e10214c7faa3cb0a730aabe0c33694082", "asset_id": "30442780799048074404860985387051749017905070253466005720364298335239299761065", "price": "0.093", "size": "0", "side": "BUY", "timestamp": "1768475133532", "received_at": "2026-01-15T12:05:33.648872"}}
{"event_type": "price_change", "event_ts": "2026-01-15T12:05:33.648872", "ingestion_ts": "2026-01-15T12:08:42.168746", "market_id": "0x49686d26fb712515cd5e12c23f0a1c7e10214c7faa3cb0a730aabe0c33694082", "raw": {"market": "0x49686d26fb712515cd5e12c23f0a1c7e10214c7faa3cb0a730aabe0c33694082", "asset_id": "13244681086321087932946246027856416106585284024824496763706748621681543444582", "price": "0.907", "size": "0", "side": "SELL", "timestamp": "1768475133532", "received_at": "2026-01-15T12:05:33.648872"}}
{"event_type": "price_change", "event_ts": "2026-01-15T12:05:33.691469", "ingestion_ts": "2026-01-15T12:08:42.168746", "market_id": "0x49686d26fb712515cd5e12c23f0a1c7e10214c7faa3cb0a730aabe0c33694082", "raw": {"market": "0x49686d26fb712515cd5e12c23f0a1c7e10214c7faa3cb0a730aabe0c33694082", "asset_id": "30442780799048074404860985387051749017905070253466005720364298335239299761065", "price": "0.095", "size": "22.73", "side": "BUY", "timestamp": "1768475133572", "received_at": "2026-01-15T12:05:33.691469"}}
{"event_type": "price_change", "event_ts": "2026-01-15T12:05:33.691469", "ingestion_ts": "2026-01-15T12:08:42.168746", "market_id": "0x49686d26fb712515cd5e12c23f0a1c7e10214c7faa3cb0a730aabe0c33694082", "raw": {"market": "0x49686d26fb712515cd5e12c23f0a1c7e10214c7faa3cb0a730aabe0c33694082", "asset_id": "13244681086321087932946246027856416106585284024824496763706748621681543444582", "price": "0.905", "size": "22.73", "side": "SELL", "timestamp": "1768475133572", "received_at": "2026-01-15T12:05:33.691469"}}
{"event_type": "price_change", "event_ts": "2026-01-15T12:05:33.762488", "ingestion_ts": "2026-01-15T12:08:42.168746", "market_id": "0x49686d26fb712515cd5e12c23f0a1c7e10214c7faa3cb0a730aabe0c33694082", "raw": {"market": "0x49686d26fb712515cd5e12c23f0a1c7e10214c7faa3cb0a730aabe0c33694082", "asset_id": "13244681086321087932946246027856416106585284024824496763706748621681543444582", "price": "0.906", "size": "0", "side": "SELL", "timestamp": "1768475133603", "received_at": "2026-01-15T12:05:33.762488"}}
{"event_type": "price_change", "event_ts": "2026-01-15T12:05:33.762488", "ingestion_ts": "2026-01-15T12:08:42.168746", "market_id": "0x49686d26fb712515cd5e12c23f0a1c7e10214c7faa3cb0a730aabe0c33694082", "raw": {"market": "0x49686d26fb712515cd5e12c23f0a1c7e10214c7faa3cb0a730aabe0c33694082", "asset_id": "30442780799048074404860985387051749017905070253466005720364298335239299761065", "price": "0.094", "size": "0", "side": "BUY", "timestamp": "1768475133603", "received_at": "2026-01-15T12:05:33.762488"}}
{"event_type": "price_change", "event_ts": "2026-01-15T12:05:33.762574", "ingestion_ts": "2026-01-15T12:08:42.168746", "market_id": "0x49686d26fb712515cd5e12c23f0a1c7e10214c7faa3cb0a730aabe0c33694082", "raw": {"market": "0x49686d26fb712515cd5e12c23f0a1c7e10214c7faa3cb0a730aabe0c33694082", "asset_id": "13244681086321087932946246027856416106585284024824496763706748621681543444582", "price": "0.905", "size": "130.73", "side": "SELL", "timestamp": "1768475133634", "received_at": "2026-01-15T12:05:33.762574"}}
{"event_type": "price_change", "event_ts": "2026-01-15T12:05:33.762574", "ingestion_ts": "2026-01-15T12:08:42.168746", "market_id": "0x49686d26fb712515cd5e12c23f0a1c7e10214c7faa3cb0a730aabe0c33694082", "raw": {"market": "0x49686d26fb712515cd5e12c23f0a1c7e10214c7faa3cb0a730aabe0c33694082", "asset_id": "30442780799048074404860985387051749017905070253466005720364298335239299761065", "price": "0.095", "size": "130.73", "side": "BUY", "timestamp": "1768475133634", "received_at": "2026-01-15T12:05:33.762574"}}
{"event_type": "price_change", "event_ts": "2026-01-15T12:05:34.120606", "ingestion_ts": "2026-01-15T12:08:42.168746", "market_id": "0xc0e6b917320a47228fb96e3b5ae0e5c93773a5ae2662ae4e1f37807cfe47ce98", "raw": {"market": "0xc0e6b917320a47228fb96e3b5ae0e5c93773a5ae2662ae4e1f37807cfe47ce98", "asset_id": "58656358377246279051017109359677190749228949103591068167284263961542487110215", "price": "0.003", "size": "295.07", "side": "BUY", "timestamp": "1768475134000", "received_at": "2026-01-15T12:05:34.120606"}}
{"event_type": "price_change", "event_ts": "2026-01-15T12:05:34.120606", "ingestion_ts": "2026-01-15T12:08:42.168746", "market_id": "0xc0e6b917320a47228fb96e3b5ae0e5c93773a5ae2662ae4e1f37807cfe47ce98", "raw": {"market": "0xc0e6b917320a47228fb96e3b5ae0e5c93773a5ae2662ae4e1f37807cfe47ce98", "asset_id": "81647294538046680798858716589766492074338758116170717123345952330712416337530", "price": "0.997", "size": "295.07", "side": "SELL", "timestamp": "1768475134000", "received_at": "2026-01-15T12:05:34.120606"}}
{"event_type": "price_change", "event_ts": "2026-01-15T12:05:34.120697", "ingestion_ts": "2026-01-15T12:08:42.168746", "market_id": "0xc0e6b917320a47228fb96e3b5ae0e5c93773a5ae2662ae4e1f37807cfe47ce98", "raw": {"market": "0xc0e6b917320a47228fb96e3b5ae0e5c93773a5ae2662ae4e1f37807cfe47ce98", "asset_id": "58656358377246279051017109359677190749228949103591068167284263961542487110215", "price": "0.003", "size": "295.07", "side": "BUY", "timestamp": "1768475134000", "received_at": "2026-01-15T12:05:34.120697"}}
{"event_type": "price_change", "event_ts": "2026-01-15T12:05:34.120697", "ingestion_ts": "2026-01-15T12:08:42.168746", "market_id": "0xc0e6b917320a47228fb96e3b5ae0e5c93773a5ae2662ae4e1f37807cfe47ce98", "raw": {"market": "0xc0e6b917320a47228fb96e3b5ae0e5c93773a5ae2662ae4e1f37807cfe47ce98", "asset_id": "81647294538046680798858716589766492074338758116170717123345952330712416337530", "price": "0.997", "size": "295.07", "side": "SELL", "timestamp": "1768475134000", "received_at": "2026-01-15T12:05:34.120697"}}
{"event_type": "price_change", "event_ts": "2026-01-15T12:05:34.481437", "ingestion_ts": "2026-01-15T12:08:42.168746", "market_id": "0xc0e6b917320a47228fb96e3b5ae0e5c93773a5ae2662ae4e1f37807cfe47ce98", "raw": {"market": "0xc0e6b917320a47228fb96e3b5ae0e5c93773a5ae2662ae4e1f37807cfe47ce98", "asset_id": "58656358377246279051017109359677190749228949103591068167284263961542487110215", "price": "0.011", "size": "0", "side": "BUY", "timestamp": "1768475134332", "received_at": "2026-01-15T12:05:34.481437"}}
{"event_type": "price_change", "event_ts": "2026-01-15T12:05:34.481437", "ingestion_ts": "2026-01-15T12:08:42.168746", "market_id": "0xc0e6b917320a47228fb96e3b5ae0e5c93773a5ae2662ae4e1f37807cfe47ce98", "raw": {"market": "0xc0e6b917320a47228fb96e3b5ae0e5c93773a5ae2662ae4e1f37807cfe47ce98", "asset_id": "81647294538046680798858716589766492074338758116170717123345952330712416337530", "price": "0.989", "size": "0", "side": "SELL", "timestamp": "1768475134332", "received_at": "2026-01-15T12:05:34.481437"}}
{"event_type": "price_change", "event_ts": "2026-01-15T12:05:34.481539", "ingestion_ts": "2026-01-15T12:08:42.168746", "market_id": "0xcab7ba4a9133cfd407d7e73e5757e5abbace413b59421527a31113406c97815c", "raw": {"market": "0xcab7ba4a9133cfd407d7e73e5757e5abbace413b59421527a31113406c97815c", "asset_id": "96361925776989336186111887920533578209326565663637092688733016597062311745569", "price": "0.006", "size": "135.73", "side": "BUY", "timestamp": "1768475134332", "received_at": "2026-01-15T12:05:34.481539"}}
{"event_type": "price_change", "event_ts": "2026-01-15T12:05:34.481539", "ingestion_ts": "2026-01-15T12:08:42.168746", "market_id": "0xcab7ba4a9133cfd407d7e73e5757e5abbace413b59421527a31113406c97815c", "raw": {"market": "0xcab7ba4a9133cfd407d7e73e5757e5abbace413b59421527a31113406c97815c", "asset_id": "20002636398944597965698652220992177552927816915094913583821579024925426590022", "price": "0.994", "size": "135.73", "side": "SELL", "timestamp": "1768475134332", "received_at": "2026-01-15T12:05:34.481539"}}
{"event_type": "price_change", "event_ts": "2026-01-15T12:05:34.481580", "ingestion_ts": "2026-01-15T12:08:42.168746", "market_id": "0xcab7ba4a9133cfd407d7e73e5757e5abbace413b59421527a31113406c97815c", "raw": {"market": "0xcab7ba4a9133cfd407d7e73e5757e5abbace413b59421527a31113406c97815c", "asset_id": "96361925776989336186111887920533578209326565663637092688733016597062311745569", "price": "0.008", "size": "619.71", "side": "BUY", "timestamp": "1768475134332", "received_at": "2026-01-15T12:05:34.481580"}}
{"event_type": "price_change", "event_ts": "2026-01-15T12:05:34.481580", "ingestion_ts": "2026-01-15T12:08:42.168746", "market_id": "0xcab7ba4a9133cfd407d7e73e5757e5abbace413b59421527a31113406c97815c", "raw": {"market": "0xcab7ba4a9133cfd407d7e73e5757e5abbace413b59421527a31113406c97815c", "asset_id": "20002636398944597965698652220992177552927816915094913583821579024925426590022", "price": "0.992", "size": "619.71", "side": "SELL", "timestamp": "1768475134332", "received_at": "2026-01-15T12:05:34.481580"}}
{"event_type": "price_change", "event_ts": "2026-01-15T12:05:35.023257", "ingestion_ts": "2026-01-15T12:08:42.168746", "market_id": "0xcab7ba4a9133cfd407d7e73e5757e5abbace413b59421527a31113406c97815c", "raw": {"market": "0xcab7ba4a9133cfd407d7e73e5757e5abbace413b59421527a31113406c97815c", "asset_id": "96361925776989336186111887920533578209326565663637092688733016597062311745569", "price": "0.008", "size": "625.94", "side": "BUY", "timestamp": "1768475134902", "received_at": "2026-01-15T12:05:35.023257"}}
{"event_type": "price_change", "event_ts": "2026-01-15T12:05:35.023257", "ingestion_ts": "2026-01-15T12:08:42.168746", "market_id": "0xcab7ba4a9133cfd407d7e73e5757e5abbace413b59421527a31113406c97815c", "raw": {"market": "0xcab7ba4a9133cfd407d7e73e5757e5abbace413b59421527a31113406c97815c", "asset_id": "20002636398944597965698652220992177552927816915094913583821579024925426590022", "price": "0.992", "size": "625.94", "side": "SELL", "timestamp": "1768475134902", "received_at": "2026-01-15T12:05:35.023257"}}
{"event_type": "price_change", "event_ts": "2026-01-15T12:05:35.023951", "ingestion_ts": "2026-01-15T12:08:42.168746", "market_id": "0xcab7ba4a9133cfd407d7e73e5757e5abbace413b59421527a31113406c97815c", "raw": {"market": "0xcab7ba4a9133cfd407d7e73e5757e5abbace413b59421527a31113406c97815c", "asset_id": "96361925776989336186111887920533578209326565663637092688733016597062311745569", "price": "0.008", "size": "632.17", "side": "BUY", "timestamp": "1768475134903", "received_at": "2026-01-15T12:05:35.023951"}}
{"event_type": "price_change", "event_ts": "2026-01-15T12:05:35.023951", "ingestion_ts": "2026-01-15T12:08:42.168746", "market_id": "0xcab7ba4a9133cfd407d7e73e5757e5abbace413b59421527a31113406c97815c", "raw": {"market": "0xcab7ba4a9133cfd407d7e73e5757e5abbace413b59421527a31113406c97815c", "asset_id": "20002636398944597965698652220992177552927816915094913583821579024925426590022", "price": "0.992", "size": "632.17", "side": "SELL", "timestamp": "1768475134903", "received_at": "2026-01-15T12:05:35.023951"}}
{"event_type": "price_change", "event_ts": "2026-01-15T12:05:35.032879", "ingestion_ts": "2026-01-15T12:08:42.168746", "market_id": "0xc0e6b917320a47228fb96e3b5ae0e5c93773a5ae2662ae4e1f37807cfe47ce98", "raw": {"market": "0xc0e6b917320a47228fb96e3b5ae0e5c93773a5ae2662ae4e1f37807cfe47ce98", "asset_id": "58656358377246279051017109359677190749228949103591068167284263961542487110215", "price": "0.003", "size": "332.7", "side": "BUY", "timestamp": "1768475134916", "received_at": "2026-01-15T12:05:35.032879"}}
{"event_type": "price_change", "event_ts": "2026-01-15T12:05:35.032879", "ingestion_ts": "2026-01-15T12:08:42.168746", "market_id": "0xc0e6b917320a47228fb96e3b5ae0e5c93773a5ae2662ae4e1f37807cfe47ce98", "raw": {"market": "0xc0e6b917320a47228fb96e3b5ae0e5c93773a5ae2662ae4e1f37807cfe47ce98", "asset_id": "81647294538046680798858716589766492074338758116170717123345952330712416337530", "price": "0.997", "size": "332.7", "side": "SELL", "timestamp": "1768475134916", "received_at": "2026-01-15T12:05:35.032879"}}
{"event_type": "price_change", "event_ts": "2026-01-15T12:05:35.034430", "ingestion_ts": "2026-01-15T12:08:42.168746", "market_id": "0xc0e6b917320a47228fb96e3b5ae0e5c93773a5ae2662ae4e1f37807cfe47ce98", "raw": {"market": "0xc0e6b917320a47228fb96e3b5ae0e5c93773a5ae2662ae4e1f37807cfe47ce98", "asset_id": "58656358377246279051017109359677190749228949103591068167284263961542487110215", "price": "0.004", "size": "8.72", "side": "BUY", "timestamp": "1768475134917", "received_at": "2026-01-15T12:05:35.034430"}}
{"event_type": "price_change", "event_ts": "2026-01-15T12:05:35.034430", "ingestion_ts": "2026-01-15T12:08:42.168746", "market_id": "0xc0e6b917320a47228fb96e3b5ae0e5c93773a5ae2662ae4e1f37807cfe47ce98", "raw": {"market": "0xc0e6b917320a47228fb96e3b5ae0e5c93773a5ae2662ae4e1f37807cfe47ce98", "asset_id": "81647294538046680798858716589766492074338758116170717123345952330712416337530", "price": "0.996", "size": "8.72", "side": "SELL", "timestamp": "1768475134917", "received_at": "2026-01-15T12:05:35.034430"}}
{"event_type": "price_change", "event_ts": "2026-01-15T12:05:35.035151", "ingestion_ts": "2026-01-15T12:08:42.168746", "market_id": "0xc0e6b917320a47228fb96e3b5ae0e5c93773a5ae2662ae4e1f37807cfe47ce98", "raw": {"market": "0xc0e6b917320a47228fb96e3b5ae0e5c93773a5ae2662ae4e1f37807cfe47ce98", "asset_id": "58656358377246279051017109359677190749228949103591068167284263961542487110215", "price": "0.012", "size": "28.4", "side": "BUY", "timestamp": "1768475134918", "received_at": "2026-01-15T12:05:35.035151"}}
{"event_type": "price_change", "event_ts": "2026-01-15T12:05:35.035151", "ingestion_ts": "2026-01-15T12:08:42.168746", "market_id": "0xc0e6b917320a47228fb96e3b5ae0e5c93773a5ae2662ae4e1f37807cfe47ce98", "raw": {"market": "0xc0e6b917320a47228fb96e3b5ae0e5c93773a5ae2662ae4e1f37807cfe47ce98", "asset_id": "81647294538046680798858716589766492074338758116170717123345952330712416337530", "price": "0.988", "size": "28.4", "side": "SELL", "timestamp": "1768475134918", "received_at": "2026-01-15T12:05:35.035151"}}
{"event_type": "price_change", "event_ts": "2026-01-15T12:05:35.623681", "ingestion_ts": "2026-01-15T12:08:42.168746", "market_id": "0xb9bbdd34304344dcc45803780a34c97d73a00133a5ecf70f63e1008b8abb2fca", "raw": {"market": "0xb9bbdd34304344dcc45803780a34c97d73a00133a5ecf70f63e1008b8abb2fca", "asset_id": "8682484153073832526711485265636767086525069344085206423986003504588877767339", "price": "0.869", "size": "0", "side": "BUY", "timestamp": "1768475135489", "received_at": "2026-01-15T12:05:35.623681"}}
{"event_type": "price_change", "event_ts": "2026-01-15T12:05:35.623681", "ingestion_ts": "2026-01-15T12:08:42.168746", "market_id": "0xb9bbdd34304344dcc45803780a34c97d73a00133a5ecf70f63e1008b8abb2fca", "raw": {"market": "0xb9bbdd34304344dcc45803780a34c97d73a00133a5ecf70f63e1008b8abb2fca", "asset_id": "72012724360700510767037780555710363830014634797787940282136454146828040926557", "price": "0.131", "size": "0", "side": "SELL", "timestamp": "1768475135489", "received_at": "2026-01-15T12:05:35.623681"}}
{"event_type": "price_change", "event_ts": "2026-01-15T12:05:35.639336", "ingestion_ts": "2026-01-15T12:08:42.168746", "market_id": "0xb9bbdd34304344dcc45803780a34c97d73a00133a5ecf70f63e1008b8abb2fca", "raw": {"market": "0xb9bbdd34304344dcc45803780a34c97d73a00133a5ecf70f63e1008b8abb2fca", "asset_id": "8682484153073832526711485265636767086525069344085206423986003504588877767339", "price": "0.871", "size": "5", "side": "BUY", "timestamp": "1768475135516", "received_at": "2026-01-15T12:05:35.639336"}}
{"event_type": "price_change", "event_ts": "2026-01-15T12:05:35.639336", "ingestion_ts": "2026-01-15T12:08:42.168746", "market_id": "0xb9bbdd34304344dcc45803780a34c97d73a00133a5ecf70f63e1008b8abb2fca", "raw": {"market": "0xb9bbdd34304344dcc45803780a34c97d73a00133a5ecf70f63e1008b8abb2fca", "asset_id": "72012724360700510767037780555710363830014634797787940282136454146828040926557", "price": "0.129", "size": "5", "side": "SELL", "timestamp": "1768475135516", "received_at": "2026-01-15T12:05:35.639336"}}
{"event_type": "price_change", "event_ts": "2026-01-15T12:05:37.348437", "ingestion_ts": "2026-01-15T12:08:42.168746", "market_id": "0xcab7ba4a9133cfd407d7e73e5757e5abbace413b59421527a31113406c97815c", "raw": {"market": "0xcab7ba4a9133cfd407d7e73e5757e5abbace413b59421527a31113406c97815c", "asset_id": "96361925776989336186111887920533578209326565663637092688733016597062311745569", "price": "0.006", "size": "127.41", "side": "BUY", "timestamp": "1768475137149", "received_at": "2026-01-15T12:05:37.348437"}}
{"event_type": "price_change", "event_ts": "2026-01-15T12:05:37.348437", "ingestion_ts": "2026-01-15T12:08:42.168746", "market_id": "0xcab7ba4a9133cfd407d7e73e5757e5abbace413b59421527a31113406c97815c", "raw": {"market": "0xcab7ba4a9133cfd407d7e73e5757e5abbace413b59421527a31113406c97815c", "asset_id": "20002636398944597965698652220992177552927816915094913583821579024925426590022", "price": "0.994", "size": "127.41", "side": "SELL", "timestamp": "1768475137149", "received_at": "2026-01-15T12:05:37.348437"}}
{"event_type": "price_change", "event_ts": "2026-01-15T12:05:37.348525", "ingestion_ts": "2026-01-15T12:08:42.168746", "market_id": "0xcab7ba4a9133cfd407d7e73e5757e5abbace413b59421527a31113406c97815c", "raw": {"market": "0xcab7ba4a9133cfd407d7e73e5757e5abbace413b59421527a31113406c97815c", "asset_id": "96361925776989336186111887920533578209326565663637092688733016597062311745569", "price": "0.008", "size": "625.94", "side": "BUY", "timestamp": "1768475137149", "received_at": "2026-01-15T12:05:37.348525"}}
{"event_type": "price_change", "event_ts": "2026-01-15T12:05:37.348525", "ingestion_ts": "2026-01-15T12:08:42.168746", "market_id": "0xcab7ba4a9133cfd407d7e73e5757e5abbace413b59421527a31113406c97815c", "raw": {"market": "0xcab7ba4a9133cfd407d7e73e5757e5abbace413b59421527a31113406c97815c", "asset_id": "20002636398944597965698652220992177552927816915094913583821579024925426590022", "price": "0.992", "size": "625.94", "side": "SELL", "timestamp": "1768475137149", "received_at": "2026-01-15T12:05:37.348525"}}
{"event_type": "price_change", "event_ts": "2026-01-15T12:05:38.900692", "ingestion_ts": "2026-01-15T12:08:42.168746", "market_id": "0xcab7ba4a9133cfd407d7e73e5757e5abbace413b59421527a31113406c97815c", "raw": {"market": "0xcab7ba4a9133cfd407d7e73e5757e5abbace413b59421527a31113406c97815c", "asset_id": "96361925776989336186111887920533578209326565663637092688733016597062311745569", "price": "0.006", "size": "135.73", "side": "BUY", "timestamp": "1768475138781", "received_at": "2026-01-15T12:05:38.900692"}}
