{"event_type": "price_change", "event_ts": "2026-01-15T12:08:28.324377", "ingestion_ts": "2026-01-15T12:08:42.168746", "market_id": "0xc0e6b917320a47228fb96e3b5ae0e5c93773a5ae2662ae4e1f37807cfe47ce98", "raw": {"market": "0xc0e6b917320a47228fb96e3b5ae0e5c93773a5ae2662ae4e1f37807cfe47ce98", "asset_id": "58656358377246279051017109359677190749228949103591068167284263961542487110215", "price": "0.005", "size": "2.98", "side": "BUY", "timestamp": "1768475308199", "received_at": "2026-01-15T12:08:28.324377"}}
{"event_type": "price_change", "event_ts": "2026-01-15T12:08:28.324377", "ingestion_ts": "2026-01-15T12:08:42.168746", "market_id": "0xc0e6b917320a47228fb96e3b5ae0e5c93773a5ae2662ae4e1f37807cfe47ce98", "raw": {"market": "0xc0e6b917320a47228fb96e3b5ae0e5c93773a5ae2662ae4e1f37807cfe47ce98", "asset_id": "81647294538046680798858716589766492074338758116170717123345952330712416337530", "price": "0.995", "size": "2.98", "side": "SELL", "timestamp": "1768475308199", "received_at": "2026-01-15T12:08:28.324377"}}
{"event_type": "price_change", "event_ts": "2026-01-15T12:08:28.506175", "ingestion_ts": "2026-01-15T12:08:42.168746", "market_id": "0x427bc4b40c09b3dcbc973747f0e4b079bed91b3e5a0aed5c36edd0f7591485f4", "raw": {"market": "0x427bc4b40c09b3dcbc973747f0e4b079bed91b3e5a0aed5c36edd0f7591485f4", "asset_id": "115669573443672055876643967408433138119481486650803218131873713375232186497057", "price": "0.173", "size": "0", "side": "SELL", "timestamp": "1768475308388", "received_at": "2026-01-15T12:08:28.506175"}}
{"event_type": "price_change", "event_ts": "2026-01-15T12:08:28.506175", "ingestion_ts": "2026-01-15T12:08:42.168746", "market_id": "0x427bc4b40c09b3dcbc973747f0e4b079bed91b3e5a0aed5c36edd0f7591485f4", "raw": {"market": "0x427bc4b40c09b3dcbc973747f0e4b079bed91b3e5a0aed5c36edd0f7591485f4", "asset_id": "86130975769502911188457673769190265049139877688522439001984850068234616395137", "price": "0.827", "size": "0", "side": "BUY", "timestamp": "1768475308388", "received_at": "2026-01-15T12:08:28.506175"}}
{"event_type": "price_change", "event_ts": "2026-01-15T12:08:28.722274", "ingestion_ts": "2026-01-15T12:08:42.168746", "market_id": "0xc0e6b917320a47228fb96e3b5ae0e5c93773a5ae2662ae4e1f37807cfe47ce98", "raw": {"market": "0xc0e6b917320a47228fb96e3b5ae0e5c93773a5ae2662ae4e1f37807cfe47ce98", "asset_id": "58656358377246279051017109359677190749228949103591068167284263961542487110215", "price": "0.003", "size": "446.89", "side": "BUY", "timestamp": "1768475308579", "received_at": "2026-01-15T12:08:28.722274"}}
{"event_type": "price_change", "event_ts": "2026-01-15T12:08:28.722274", "ingestion_ts": "2026-01-15T12:08:42.168746", "market_id": "0xc0e6b917320a47228fb96e3b5ae0e5c93773a5ae2662ae4e1f37807cfe47ce98", "raw": {"market": "0xc0e6b917320a47228fb96e3b5ae0e5c93773a5ae2662ae4e1f37807cfe47ce98", "asset_id": "81647294538046680798858716589766492074338758116170717123345952330712416337530", "price": "0.997", "size": "446.89", "side": "SELL", "timestamp": "1768475308579", "received_at": "2026-01-15T12:08:28.722274"}}
{"event_type": "price_change", "event_ts": "2026-01-15T12:08:28.722337", "ingestion_ts": "2026-01-15T12:08:42.168746", "market_id": "0xc0e6b917320a47228fb96e3b5ae0e5c93773a5ae2662ae4e1f37807cfe47ce98", "raw": {"market": "0xc0e6b917320a47228fb96e3b5ae0e5c93773a5ae2662ae4e1f37807cfe47ce98", "asset_id": "58656358377246279051017109359677190749228949103591068167284263961542487110215", "price": "0.003", "size": "460.2", "side": "BUY", "timestamp": "1768475308580", "received_at": "2026-01-15T12:08:28.722337"}}
{"event_type": "price_change", "event_ts": "2026-01-15T12:08:28.722337", "ingestion_ts": "2026-01-15T12:08:42.168746", "market_id": "0xc0e6b917320a47228fb96e3b5ae0e5c93773a5ae2662ae4e1f37807cfe47ce98", "raw": {"market": "0xc0e6b917320a47228fb96e3b5ae0e5c93773a5ae2662ae4e1f37807cfe47ce98", "asset_id": "81647294538046680798858716589766492074338758116170717123345952330712416337530", "price": "0.997", "size": "460.2", "side": "SELL", "timestamp": "1768475308580", "received_at": "2026-01-15T12:08:28.722337"}}
{"event_type": "price_change", "event_ts": "2026-01-15T12:08:28.764809", "ingestion_ts": "2026-01-15T12:08:42.168746", "market_id": "0xcab7ba4a9133cfd407d7e73e5757e5abbace413b59421527a31113406c97815c", "raw": {"market": "0xcab7ba4a9133cfd407d7e73e5757e5abbace413b59421527a31113406c97815c", "asset_id": "96361925776989336186111887920533578209326565663637092688733016597062311745569", "price": "0.006", "size": "127.41", "side": "BUY", "timestamp": "1768475308625", "received_at": "2026-01-15T12:08:28.764809"}}
{"event_type": "price_change", "event_ts": "2026-01-15T12:08:28.764809", "ingestion_ts": "2026-01-15T12:08:42.168746", "market_id": "0xcab7ba4a9133cfd407d7e73e5757e5abbace413b59421527a31113406c97815c", "raw": {"market": "0xcab7ba4a9133cfd407d7e73e5757e5abbace413b59421527a31113406c97815c", "asset_id": "20002636398944597965698652220992177552927816915094913583821579024925426590022", "price": "0.994", "size": "127.41", "side": "SELL", "timestamp": "1768475308625", "received_at": "2026-01-15T12:08:28.764809"}}
{"event_type": "price_change", "event_ts": "2026-01-15T12:08:28.764869", "ingestion_ts": "2026-01-15T12:08:42.168746", "market_id": "0xcab7ba4a9133cfd407d7e73e5757e5abbace413b59421527a31113406c97815c", "raw": {"market": "0xcab7ba4a9133cfd407d7e73e5757e5abbace413b59421527a31113406c97815c", "asset_id": "96361925776989336186111887920533578209326565663637092688733016597062311745569", "price": "0.009", "size": "812.25", "side": "BUY", "timestamp": "1768475308625", "received_at": "2026-01-15T12:08:28.764869"}}
{"event_type": "price_change", "event_ts": "2026-01-15T12:08:28.764869", "ingestion_ts": "2026-01-15T12:08:42.168746", "market_id": "0xcab7ba4a9133cfd407d7e73e5757e5abbace413b59421527a31113406c97815c", "raw": {"market": "0xcab7ba4a9133cfd407d7e73e5757e5abbace413b59421527a31113406c97815c", "asset_id": "20002636398944597965698652220992177552927816915094913583821579024925426590022", "price": "0.991", "size": "812.25", "side": "SELL", "timestamp": "1768475308625", "received_at": "2026-01-15T12:08:28.764869"}}
{"event_type": "price_change", "event_ts": "2026-01-15T12:08:28.858154", "ingestion_ts": "2026-01-15T12:08:42.168746", "market_id": "0x427bc4b40c09b3dcbc973747f0e4b079bed91b3e5a0aed5c36edd0f7591485f4", "raw": {"market": "0x427bc4b40c09b3dcbc973747f0e4b079bed91b3e5a0aed5c36edd0f7591485f4", "asset_id": "115669573443672055876643967408433138119481486650803218131873713375232186497057", "price": "0.166", "size": "15.92", "side": "SELL", "timestamp": "1768475308728", "received_at": "2026-01-15T12:08:28.858154"}}
{"event_type": "price_change", "event_ts": "2026-01-15T12:08:28.858154", "ingestion_ts": "2026-01-15T12:08:42.168746", "market_id": "0x427bc4b40c09b3dcbc973747f0e4b079bed91b3e5a0aed5c36edd0f7591485f4", "raw": {"market": "0x427bc4b40c09b3dcbc973747f0e4b079bed91b3e5a0aed5c36edd0f7591485f4", "asset_id": "86130975769502911188457673769190265049139877688522439001984850068234616395137", "price": "0.834", "size": "15.92", "side": "BUY", "timestamp": "1768475308728", "received_at": "2026-01-15T12:08:28.858154"}}
{"event_type": "price_change", "event_ts": "2026-01-15T12:08:29.172334", "ingestion_ts": "2026-01-15T12:08:42.168746", "market_id": "0xcab7ba4a9133cfd407d7e73e5757e5abbace413b59421527a31113406c97815c", "raw": {"market": "0xcab7ba4a9133cfd407d7e73e5757e5abbace413b59421527a31113406c97815c", "asset_id": "96361925776989336186111887920533578209326565663637092688733016597062311745569", "price": "0.009", "size": "818.33", "side": "BUY", "timestamp": "1768475309014", "received_at": "2026-01-15T12:08:29.172334"}}
{"event_type": "price_change", "event_ts": "2026-01-15T12:08:29.172334", "ingestion_ts": "2026-01-15T12:08:42.168746", "market_id": "0xcab7ba4a9133cfd407d7e73e5757e5abbace413b59421527a31113406c97815c", "raw": {"market": "0xcab7ba4a9133cfd407d7e73e5757e5abbace413b59421527a31113406c97815c", "asset_id": "20002636398944597965698652220992177552927816915094913583821579024925426590022", "price": "0.991", "size": "818.33", "side": "SELL", "timestamp": "1768475309014", "received_at": "2026-01-15T12:08:29.172334"}}
{"event_type": "price_change", "event_ts": "2026-01-15T12:08:29.172406", "ingestion_ts": "2026-01-15T12:08:42.168746", "market_id": "0xcab7ba4a9133cfd407d7e73e5757e5abbace413b59421527a31113406c97815c", "raw": {"market": "0xcab7ba4a9133cfd407d7e73e5757e5abbace413b59421527a31113406c97815c", "asset_id": "96361925776989336186111887920533578209326565663637092688733016597062311745569", "price": "0.006", "size": "136.51", "side": "BUY", "timestamp": "1768475309015", "received_at": "2026-01-15T12:08:29.172406"}}
{"event_type": "price_change", "event_ts": "2026-01-15T12:08:29.172406", "ingestion_ts": "2026-01-15T12:08:42.168746", "market_id": "0xcab7ba4a9133cfd407d7e73e5757e5abbace413b59421527a31113406c97815c", "raw": {"market": "0xcab7ba4a9133cfd407d7e73e5757e5abbace413b59421527a31113406c97815c", "asset_id": "20002636398944597965698652220992177552927816915094913583821579024925426590022", "price": "0.994", "size": "136.51", "side": "SELL", "timestamp": "1768475309015", "received_at": "2026-01-15T12:08:29.172406"}}
{"event_type": "price_change", "event_ts": "2026-01-15T12:08:31.436495", "ingestion_ts": "2026-01-15T12:08:42.168746", "market_id": "0xcab7ba4a9133cfd407d7e73e5757e5abbace413b59421527a31113406c97815c", "raw": {"market": "0xcab7ba4a9133cfd407d7e73e5757e5abbace413b59421527a31113406c97815c", "asset_id": "96361925776989336186111887920533578209326565663637092688733016597062311745569", "price": "0.006", "size": "127.41", "side": "BUY", "timestamp": "1768475311296", "received_at": "2026-01-15T12:08:31.436495"}}
{"event_type": "price_change", "event_ts": "2026-01-15T12:08:31.436495", "ingestion_ts": "2026-01-15T12:08:42.168746", "market_id": "0xcab7ba4a9133cfd407d7e73e5757e5abbace413b59421527a31113406c97815c", "raw": {"market": "0xcab7ba4a9133cfd407d7e73e5757e5abbace413b59421527a31113406c97815c", "asset_id": "20002636398944597965698652220992177552927816915094913583821579024925426590022", "price": "0.994", "size": "127.41", "side": "SELL", "timestamp": "1768475311296", "received_at": "2026-01-15T12:08:31.436495"}}
{"event_type": "price_change", "event_ts": "2026-01-15T12:08:31.436573", "ingestion_ts": "2026-01-15T12:08:42.168746", "market_id": "0xcab7ba4a9133cfd407d7e73e5757e5abbace413b59421527a31113406c97815c", "raw": {"market": "0xcab7ba4a9133cfd407d7e73e5757e5abbace413b59421527a31113406c97815c", "asset_id": "96361925776989336186111887920533578209326565663637092688733016597062311745569", "price": "0.009", "size": "812.25", "side": "BUY", "timestamp": "1768475311296", "received_at": "2026-01-15T12:08:31.436573"}}
{"event_type": "price_change", "event_ts": "2026-01-15T12:08:31.436573", "ingestion_ts": "2026-01-15T12:08:42.168746", "market_id": "0xcab7ba4a9133cfd407d7e73e5757e5abbace413b59421527a31113406c97815c", "raw": {"market": "0xcab7ba4a9133cfd407d7e73e5757e5abbace413b59421527a31113406c97815c", "asset_id": "20002636398944597965698652220992177552927816915094913583821579024925426590022", "price": "0.991", "size": "812.25", "side": "SELL", "timestamp": "1768475311296", "received_at": "2026-01-15T12:08:31.436573"}}
{"event_type": "price_change", "event_ts": "2026-01-15T12:08:32.081120", "ingestion_ts": "2026-01-15T12:08:42.168746", "market_id": "0xcab7ba4a9133cfd407d7e73e5757e5abbace413b59421527a31113406c97815c", "raw": {"market": "0xcab7ba4a9133cfd407d7e73e5757e5abbace413b59421527a31113406c97815c", "asset_id": "96361925776989336186111887920533578209326565663637092688733016597062311745569", "price": "0.009", "size": "818.33", "side": "BUY", "timestamp": "1768475311963", "received_at": "2026-01-15T12:08:32.081120"}}
{"event_type": "price_change", "event_ts": "2026-01-15T12:08:32.081120", "ingestion_ts": "2026-01-15T12:08:42.168746", "market_id": "0xcab7ba4a9133cfd407d7e73e5757e5abbace413b59421527a31113406c97815c", "raw": {"market": "0xcab7ba4a9133cfd407d7e73e5757e5abbace413b59421527a31113406c97815c", "asset_id": "20002636398944597965698652220992177552927816915094913583821579024925426590022", "price": "0.991", "size": "818.33", "side": "SELL", "timestamp": "1768475311963", "received_at": "2026-01-15T12:08:32.081120"}}
{"event_type": "price_change", "event_ts": "2026-01-15T12:08:32.087372", "ingestion_ts": "2026-01-15T12:08:42.168746", "market_id": "0xcab7ba4a9133cfd407d7e73e5757e5abbace413b59421527a31113406c97815c", "raw": {"market": "0xcab7ba4a9133cfd407d7e73e5757e5abbace413b59421527a31113406c97815c", "asset_id": "96361925776989336186111887920533578209326565663637092688733016597062311745569", "price": "0.006", "size": "136.51", "side": "BUY", "timestamp": "1768475311964", "received_at": "2026-01-15T12:08:32.087372"}}
{"event_type": "price_change", "event_ts": "2026-01-15T12:08:32.087372", "ingestion_ts": "2026-01-15T12:08:42.168746", "market_id": "0xcab7ba4a9133cfd407d7e73e5757e5abbace413b59421527a31113406c97815c", "raw": {"market": "0xcab7ba4a9133cfd407d7e73e5757e5abbace413b59421527a31113406c97815c", "asset_id": "20002636398944597965698652220992177552927816915094913583821579024925426590022", "price": "0.994", "size": "136.51", "side": "SELL", "timestamp": "1768475311964", "received_at": "2026-01-15T12:08:32.087372"}}
{"event_type": "price_change", "event_ts": "2026-01-15T12:08:32.529373", "ingestion_ts": "2026-01-15T12:08:42.168746", "market_id": "0xc0e6b917320a47228fb96e3b5ae0e5c93773a5ae2662ae4e1f37807cfe47ce98", "raw": {"market": "0xc0e6b917320a47228fb96e3b5ae0e5c93773a5ae2662ae4e1f37807cfe47ce98", "asset_id": "58656358377246279051017109359677190749228949103591068167284263961542487110215", "price": "0.003", "size": "441.26", "side": "BUY", "timestamp": "1768475312409", "received_at": "2026-01-15T12:08:32.529373"}}
{"event_type": "price_change", "event_ts": "2026-01-15T12:08:32.529373", "ingestion_ts": "2026-01-15T12:08:42.168746", "market_id": "0xc0e6b917320a47228fb96e3b5ae0e5c93773a5ae2662ae4e1f37807cfe47ce98", "raw": {"market": "0xc0e6b917320a47228fb96e3b5ae0e5c93773a5ae2662ae4e1f37807cfe47ce98", "asset_id": "81647294538046680798858716589766492074338758116170717123345952330712416337530", "price": "0.997", "size": "441.26", "side": "SELL", "timestamp": "1768475312409", "received_at": "2026-01-15T12:08:32.529373"}}
{"event_type": "price_change", "event_ts": "2026-01-15T12:08:32.994958", "ingestion_ts": "2026-01-15T12:08:42.168746", "market_id": "0xcab7ba4a9133cfd407d7e73e5757e5abbace413b59421527a31113406c97815c", "raw": {"market": "0xcab7ba4a9133cfd407d7e73e5757e5abbace413b59421527a31113406c97815c", "asset_id": "96361925776989336186111887920533578209326565663637092688733016597062311745569", "price": "0.006", "size": "127.41", "side": "BUY", "timestamp": "1768475312856", "received_at": "2026-01-15T12:08:32.994958"}}
{"event_type": "price_change", "event_ts": "2026-01-15T12:08:32.994958", "ingestion_ts": "2026-01-15T12:08:42.168746", "market_id": "0xcab7ba4a9133cfd407d7e73e5757e5abbace413b59421527a31113406c97815c", "raw": {"market": "0xcab7ba4a9133cfd407d7e73e5757e5abbace413b59421527a31113406c97815c", "asset_id": "20002636398944597965698652220992177552927816915094913583821579024925426590022", "price": "0.994", "size": "127.41", "side": "SELL", "timestamp": "1768475312856", "received_at": "2026-01-15T12:08:32.994958"}}
{"event_type": "price_change", "event_ts": "2026-01-15T12:08:32.995014", "ingestion_ts": "2026-01-15T12:08:42.168746", "market_id": "0xcab7ba4a9133cfd407d7e73e5757e5abbace413b59421527a31113406c97815c", "raw": {"market": "0xcab7ba4a9133cfd407d7e73e5757e5abbace413b59421527a31113406c97815c", "asset_id": "96361925776989336186111887920533578209326565663637092688733016597062311745569", "price": "0.009", "size": "812.25", "side": "BUY", "timestamp": "1768475312856", "received_at": "2026-01-15T12:08:32.995014"}}
{"event_type": "price_change", "event_ts": "2026-01-15T12:08:32.995014", "ingestion_ts": "2026-01-15T12:08:42.168746", "market_id": "0xcab7ba4a9133cfd407d7e73e5757e5abbace413b59421527a31113406c97815c", "raw": {"market": "0xcab7ba4a9133cfd407d7e73e5757e5abbace413b59421527a31113406c97815c", "asset_id": "20002636398944597965698652220992177552927816915094913583821579024925426590022", "price": "0.991", "size": "812.25", "side": "SELL", "timestamp": "1768475312856", "received_at": "2026-01-15T12:08:32.995014"}}
{"event_type": "price_change", "event_ts": "2026-01-15T12:08:33.022465", "ingestion_ts": "2026-01-15T12:08:42.168746", "market_id": "0xc0e6b917320a47228fb96e3b5ae0e5c93773a5ae2662ae4e1f37807cfe47ce98", "raw": {"market": "0xc0e6b917320a47228fb96e3b5ae0e5c93773a5ae2662ae4e1f37807cfe47ce98", "asset_id": "58656358377246279051017109359677190749228949103591068167284263961542487110215", "price": "0.003", "size": "450.73", "side": "BUY", "timestamp": "1768475312905", "received_at": "2026-01-15T12:08:33.022465"}}
{"event_type": "price_change", "event_ts": "2026-01-15T12:08:33.022465", "ingestion_ts": "2026-01-15T12:08:42.168746", "market_id": "0xc0e6b917320a47228fb96e3b5ae0e5c93773a5ae2662ae4e1f37807cfe47ce98", "raw": {"market": "0xc0e6b917320a47228fb96e3b5ae0e5c93773a5ae2662ae4e1f37807cfe47ce98", "asset_id": "81647294538046680798858716589766492074338758116170717123345952330712416337530", "price": "0.997", "size": "450.73", "side": "SELL", "timestamp": "1768475312905", "received_at": "2026-01-15T12:08:33.022465"}}
{"event_type": "price_change", "event_ts": "2026-01-15T12:08:33.029737", "ingestion_ts": "2026-01-15T12:08:42.168746", "market_id": "0xc0e6b917320a47228fb96e3b5ae0e5c93773a5ae2662ae4e1f37807cfe47ce98", "raw": {"market": "0xc0e6b917320a47228fb96e3b5ae0e5c93773a5ae2662ae4e1f37807cfe47ce98", "asset_id": "58656358377246279051017109359677190749228949103591068167284263961542487110215", "price": "0.003", "size": "460.2", "side": "BUY", "timestamp": "1768475312907", "received_at": "2026-01-15T12:08:33.029737"}}
{"event_type": "price_change", "event_ts": "2026-01-15T12:08:33.029737", "ingestion_ts": "2026-01-15T12:08:42.168746", "market_id": "0xc0e6b917320a47228fb96e3b5ae0e5c93773a5ae2662ae4e1f37807cfe47ce98", "raw": {"market": "0xc0e6b917320a47228fb96e3b5ae0e5c93773a5ae2662ae4e1f37807cfe47ce98", "asset_id": "81647294538046680798858716589766492074338758116170717123345952330712416337530", "price": "0.997", "size": "460.2", "side": "SELL", "timestamp": "1768475312907", "received_at": "2026-01-15T12:08:33.029737"}}
{"event_type": "price_change", "event_ts": "2026-01-15T12:08:33.521269", "ingestion_ts": "2026-01-15T12:08:42.168746", "market_id": "0xcab7ba4a9133cfd407d7e73e5757e5abbace413b59421527a31113406c97815c", "raw": {"market": "0xcab7ba4a9133cfd407d7e73e5757e5abbace413b59421527a31113406c97815c", "asset_id": "96361925776989336186111887920533578209326565663637092688733016597062311745569", "price": "0.009", "size": "818.33", "side": "BUY", "timestamp": "1768475313403", "received_at": "2026-01-15T12:08:33.521269"}}
{"event_type": "price_change", "event_ts": "2026-01-15T12:08:33.521269", "ingestion_ts": "2026-01-15T12:08:42.168746", "market_id": "0xcab7ba4a9133cfd407d7e73e5757e5abbace413b59421527a31113406c97815c", "raw": {"market": "0xcab7ba4a9133cfd407d7e73e5757e5abbace413b59421527a31113406c97815c", "asset_id": "20002636398944597965698652220992177552927816915094913583821579024925426590022", "price": "0.991", "size": "818.33", "side": "SELL", "timestamp": "1768475313403", "received_at": "2026-01-15T12:08:33.521269"}}
{"event_type": "price_change", "event_ts": "2026-01-15T12:08:33.523543", "ingestion_ts": "2026-01-15T12:08:42.168746", "market_id": "0xcab7ba4a9133cfd407d7e73e5757e5abbace413b59421527a31113406c97815c", "raw": {"market": "0xcab7ba4a9133cfd407d7e73e5757e5abbace413b59421527a31113406c97815c", "asset_id": "96361925776989336186111887920533578209326565663637092688733016597062311745569", "price": "0.006", "size": "136.51", "side": "BUY", "timestamp": "1768475313404", "received_at": "2026-01-15T12:08:33.523543"}}
{"event_type": "price_change", "event_ts": "2026-01-15T12:08:33.523543", "ingestion_ts": "2026-01-15T12:08:42.168746", "market_id": "0xcab7ba4a9133cfd407d7e73e5757e5abbace413b59421527a31113406c97815c", "raw": {"market": "0xcab7ba4a9133cfd407d7e73e5757e5abbace413b59421527a31113406c97815c", "asset_id": "20002636398944597965698652220992177552927816915094913583821579024925426590022", "price": "0.994", "size": "136.51", "side": "SELL", "timestamp": "1768475313404", "received_at": "2026-01-15T12:08:33.523543"}}
{"event_type": "price_change", "event_ts": "2026-01-15T12:08:35.075664", "ingestion_ts": "2026-01-15T12:08:42.168746", "market_id": "0x427bc4b40c09b3dcbc973747f0e4b079bed91b3e5a0aed5c36edd0f7591485f4", "raw": {"market": "0x427bc4b40c09b3dcbc973747f0e4b079bed91b3e5a0aed5c36edd0f7591485f4", "asset_id": "115669573443672055876643967408433138119481486650803218131873713375232186497057", "price": "0.002", "size": "41.05", "side": "BUY", "timestamp": "1768475314953", "received_at": "2026-01-15T12:08:35.075664"}}
{"event_type": "price_change", "event_ts": "2026-01-15T12:08:35.075664", "ingestion_ts": "2026-01-15T12:08:42.168746", "market_id": "0x427bc4b40c09b3dcbc973747f0e4b079bed91b3e5a0aed5c36edd0f7591485f4", "raw": {"market": "0x427bc4b40c09b3dcbc973747f0e4b079bed91b3e5a0aed5c36edd0f7591485f4", "asset_id": "86130975769502911188457673769190265049139877688522439001984850068234616395137", "price": "0.998", "size": "41.05", "side": "SELL", "timestamp": "1768475314953", "received_at": "2026-01-15T12:08:35.075664"}}
{"event_type": "price_change", "event_ts": "2026-01-15T12:08:35.293324", "ingestion_ts": "2026-01-15T12:08:42.168746", "market_id": "0x427bc4b40c09b3dcbc973747f0e4b079bed91b3e5a0aed5c36edd0f7591485f4", "raw": {"market": "0x427bc4b40c09b3dcbc973747f0e4b079bed91b3e5a0aed5c36edd0f7591485f4", "asset_id": "115669573443672055876643967408433138119481486650803218131873713375232186497057", "price": "0.002", "size": "72.18", "side": "BUY", "timestamp": "1768475315176", "received_at": "2026-01-15T12:08:35.293324"}}
{"event_type": "price_change", "event_ts": "2026-01-15T12:08:35.293324", "ingestion_ts": "2026-01-15T12:08:42.168746", "market_id": "0x427bc4b40c09b3dcbc973747f0e4b079bed91b3e5a0aed5c36edd0f7591485f4", "raw": {"market": "0x427bc4b40c09b3dcbc973747f0e4b079bed91b3e5a0aed5c36edd0f7591485f4", "asset_id": "86130975769502911188457673769190265049139877688522439001984850068234616395137", "price": "0.998", "size": "72.18", "side": "SELL", "timestamp": "1768475315176", "received_at": "2026-01-15T12:08:35.293324"}}
{"event_type": "price_change", "event_ts": "2026-01-15T12:08:36.078815", "ingestion_ts": "2026-01-15T12:08:42.168746", "market_id": "0x427bc4b40c09b3dcbc973747f0e4b079bed91b3e5a0aed5c36edd0f7591485f4", "raw": {"market": "0x427bc4b40c09b3dcbc973747f0e4b079bed91b3e5a0aed5c36edd0f7591485f4", "asset_id": "115669573443672055876643967408433138119481486650803218131873713375232186497057", "price": "0.166", "size": "6.14", "side": "SELL", "timestamp": "1768475315962", "received_at": "2026-01-15T12:08:36.078815"}}
{"event_type": "price_change", "event_ts": "2026-01-15T12:08:36.078815", "ingestion_ts": "2026-01-15T12:08:42.168746", "market_id": "0x427bc4b40c09b3dcbc973747f0e4b079bed91b3e5a0aed5c36edd0f7591485f4", "raw": {"market": "0x427bc4b40c09b3dcbc973747f0e4b079bed91b3e5a0aed5c36edd0f7591485f4", "asset_id": "86130975769502911188457673769190265049139877688522439001984850068234616395137", "price": "0.834", "size": "6.14", "side": "BUY", "timestamp": "1768475315962", "received_at": "2026-01-15T12:08:36.078815"}}
{"event_type": "price_change", "event_ts": "2026-01-15T12:08:36.141920", "ingestion_ts": "2026-01-15T12:08:42.168746", "market_id": "0x427bc4b40c09b3dcbc973747f0e4b079bed91b3e5a0aed5c36edd0f7591485f4", "raw": {"market": "0x427bc4b40c09b3dcbc973747f0e4b079bed91b3e5a0aed5c36edd0f7591485f4", "asset_id": "115669573443672055876643967408433138119481486650803218131873713375232186497057", "price": "0.001", "size": "762.3", "side": "BUY", "timestamp": "1768475316000", "received_at": "2026-01-15T12:08:36.141920"}}
{"event_type": "price_change", "event_ts": "2026-01-15T12:08:36.141920", "ingestion_ts": "2026-01-15T12:08:42.168746", "market_id": "0x427bc4b40c09b3dcbc973747f0e4b079bed91b3e5a0aed5c36edd0f7591485f4", "raw": {"market": "0x427bc4b40c09b3dcbc973747f0e4b079bed91b3e5a0aed5c36edd0f7591485f4", "asset_id": "86130975769502911188457673769190265049139877688522439001984850068234616395137", "price": "0.999", "size": "762.3", "side": "SELL", "timestamp": "1768475316000", "received_at": "2026-01-15T12:08:36.141920"}}
{"event_type": "price_change", "event_ts": "2026-01-15T12:08:36.142068", "ingestion_ts": "2026-01-15T12:08:42.168746", "market_id": "0xe9c127a8c35f045d37b5344b0a36711084fa20c2fc1618bf178a5386f90610be", "raw": {"market": "0xe9c127a8c35f045d37b5344b0a36711084fa20c2fc1618bf178a5386f90610be", "asset_id": "80230236018433940569996058935444651347308266584430516013229815570706872276819", "price": "0.001", "size": "5708.9", "side": "BUY", "timestamp": "1768475316000", "received_at": "2026-01-15T12:08:36.142068"}}
{"event_type": "price_change", "event_ts": "2026-01-15T12:08:36.142068", "ingestion_ts": "2026-01-15T12:08:42.168746", "market_id": "0xe9c127a8c35f045d37b5344b0a36711084fa20c2fc1618bf178a5386f90610be", "raw": {"market": "0xe9c127a8c35f045d37b5344b0a36711084fa20c2fc1618bf178a5386f90610be", "asset_id": "107000426448217931795450451304515386602910396776318075817601265223856116134349", "price": "0.999", "size": "5708.9", "side": "SELL", "timestamp": "1768475316000", "received_at": "2026-01-15T12:08:36.142068"}}
{"event_type": "price_change", "event_ts": "2026-01-15T12:08:36.167538", "ingestion_ts": "2026-01-15T12:08:42.168746", "market_id": "0xe9c127a8c35f045d37b5344b0a36711084fa20c2fc1618bf178a5386f90610be", "raw": {"market": "0xe9c127a8c35f045d37b5344b0a36711084fa20c2fc1618bf178a5386f90610be", "asset_id": "80230236018433940569996058935444651347308266584430516013229815570706872276819", "price": "0.025", "size": "10", "side": "SELL", "timestamp": "1768475316037", "received_at": "2026-01-15T12:08:36.167538"}}
{"event_type": "price_change", "event_ts": "2026-01-15T12:08:36.167538", "ingestion_ts": "2026-01-15T12:08:42.168746", "market_id": "0xe9c127a8c35f045d37b5344b0a36711084fa20c2fc1618bf178a5386f90610be", "raw": {"market": "0xe9c127a8c35f045d37b5344b0a36711084fa20c2fc1618bf178a5386f90610be", "asset_id": "107000426448217931795450451304515386602910396776318075817601265223856116134349", "price": "0.975", "size": "10", "side": "BUY", "timestamp": "1768475316037", "received_at": "2026-01-15T12:08:36.167538"}}
{"event_type": "price_change", "event_ts": "2026-01-15T12:08:36.179341", "ingestion_ts": "2026-01-15T12:08:42.168746", "market_id": "0xe9c127a8c35f045d37b5344b0a36711084fa20c2fc1618bf178a5386f90610be", "raw": {"market": "0xe9c127a8c35f045d37b5344b0a36711084fa20c2fc1618bf178a5386f90610be", "asset_id": "80230236018433940569996058935444651347308266584430516013229815570706872276819", "price": "0.025", "size": "386", "side": "SELL", "timestamp": "1768475316063", "received_at": "2026-01-15T12:08:36.179341"}}
{"event_type": "price_change", "event_ts": "2026-01-15T12:08:36.179341", "ingestion_ts": "2026-01-15T12:08:42.168746", "market_id": "0xe9c127a8c35f045d37b5344b0a36711084fa20c2fc1618bf178a5386f90610be", "raw": {"market": "0xe9c127a8c35f045d37b5344b0a36711084fa20c2fc1618bf178a5386f90610be", "asset_id": "107000426448217931795450451304515386602910396776318075817601265223856116134349", "price": "0.975", "size": "386", "side": "BUY", "timestamp": "1768475316063", "received_at": "2026-01-15T12:08:36.179341"}}
{"event_type": "price_change", "event_ts": "2026-01-15T12:08:36.338210", "ingestion_ts": "2026-01-15T12:08:42.168746", "market_id": "0x427bc4b40c09b3dcbc973747f0e4b079bed91b3e5a0aed5c36edd0f7591485f4", "raw": {"market": "0x427bc4b40c09b3dcbc973747f0e4b079bed91b3e5a0aed5c36edd0f7591485f4", "asset_id": "115669573443672055876643967408433138119481486650803218131873713375232186497057", "price": "0.165", "size": "9.78", "side": "SELL", "timestamp": "1768475316217", "received_at": "2026-01-15T12:08:36.338210"}}
{"event_type": "price_change", "event_ts": "2026-01-15T12:08:36.338210", "ingestion_ts": "2026-01-15T12:08:42.168746", "market_id": "0x427bc4b40c09b3dcbc973747f0e4b079bed91b3e5a0aed5c36edd0f7591485f4", "raw": {"market": "0x427bc4b40c09b3dcbc973747f0e4b079bed91b3e5a0aed5c36edd0f7591485f4", "asset_id": "86130975769502911188457673769190265049139877688522439001984850068234616395137", "price": "0.835", "size": "9.78", "side": "BUY", "timestamp": "1768475316217", "received_at": "2026-01-15T12:08:36.338210"}}
{"event_type": "price_change", "event_ts": "2026-01-15T12:08:36.632070", "ingestion_ts": "2026-01-15T12:08:42.168746", "market_id": "0xcab7ba4a9133cfd407d7e73e5757e5abbace413b59421527a31113406c97815c", "raw": {"market": "0xcab7ba4a9133cfd407d7e73e5757e5abbace413b59421527a31113406c97815c", "asset_id": "96361925776989336186111887920533578209326565663637092688733016597062311745569", "price": "0.006", "size": "127.41", "side": "BUY", "timestamp": "1768475316514", "received_at": "2026-01-15T12:08:36.632070"}}
{"event_type": "price_change", "event_ts": "2026-01-15T12:08:36.632070", "ingestion_ts": "2026-01-15T12:08:42.168746", "market_id": "0xcab7ba4a9133cfd407d7e73e5757e5abbace413b59421527a31113406c97815c", "raw": {"market": "0xcab7ba4a9133cfd407d7e73e5757e5abbace413b59421527a31113406c97815c", "asset_id": "20002636398944597965698652220992177552927816915094913583821579024925426590022", "price": "0.994", "size": "127.41", "side": "SELL", "timestamp": "1768475316514", "received_at": "2026-01-15T12:08:36.632070"}}
{"event_type": "price_change", "event_ts": "2026-01-15T12:08:36.632127", "ingestion_ts": "2026-01-15T12:08:42.168746", "market_id": "0xcab7ba4a9133cfd407d7e73e5757e5abbace413b59421527a31113406c97815c", "raw": {"market": "0xcab7ba4a9133cfd407d7e73e5757e5abbace413b59421527a31113406c97815c", "asset_id": "96361925776989336186111887920533578209326565663637092688733016597062311745569", "price": "0.009", "size": "812.25", "side": "BUY", "timestamp": "1768475316514", "received_at": "2026-01-15T12:08:36.632127"}}
{"event_type": "price_change", "event_ts": "2026-01-15T12:08:36.632127", "ingestion_ts": "2026-01-15T12:08:42.168746", "market_id": "0xcab7ba4a9133cfd407d7e73e5757e5abbace413b59421527a31113406c97815c", "raw": {"market": "0xcab7ba4a9133cfd407d7e73e5757e5abbace413b59421527a31113406c97815c", "asset_id": "20002636398944597965698652220992177552927816915094913583821579024925426590022", "price": "0.991", "size": "812.25", "side": "SELL", "timestamp": "1768475316514", "received_at": "2026-01-15T12:08:36.632127"}}
{"event_type": "price_change", "event_ts": "2026-01-15T12:08:37.000829", "ingestion_ts": "2026-01-15T12:08:42.168746", "market_id": "0xcab7ba4a9133cfd407d7e73e5757e5abbace413b59421527a31113406c97815c", "raw": {"market": "0xcab7ba4a9133cfd407d7e73e5757e5abbace413b59421527a31113406c97815c", "asset_id": "96361925776989336186111887920533578209326565663637092688733016597062311745569", "price": "0.006", "size": "136.51", "side": "BUY", "timestamp": "1768475316870", "received_at": "2026-01-15T12:08:37.000829"}}
{"event_type": "price_change", "event_ts": "2026-01-15T12:08:37.000829", "ingestion_ts": "2026-01-15T12:08:42.168746", "market_id": "0xcab7ba4a9133cfd407d7e73e5757e5abbace413b59421527a31113406c97815c", "raw": {"market": "0xcab7ba4a9133cfd407d7e73e5757e5abbace413b59421527a31113406c97815c", "asset_id": "20002636398944597965698652220992177552927816915094913583821579024925426590022", "price": "0.994", "size": "136.51", "side": "SELL", "timestamp": "1768475316870", "received_at": "2026-01-15T12:08:37.000829"}}
{"event_type": "price_change", "event_ts": "2026-01-15T12:08:37.000914", "ingestion_ts": "2026-01-15T12:08:42.168746", "market_id": "0xcab7ba4a9133cfd407d7e73e5757e5abbace413b59421527a31113406c97815c", "raw": {"market": "0xcab7ba4a9133cfd407d7e73e5757e5abbace413b59421527a31113406c97815c", "asset_id": "96361925776989336186111887920533578209326565663637092688733016597062311745569", "price": "0.009", "size": "818.33", "side": "BUY", "timestamp": "1768475316871", "received_at": "2026-01-15T12:08:37.000914"}}
{"event_type": "price_change", "event_ts": "2026-01-15T12:08:37.000914", "ingestion_ts": "2026-01-15T12:08:42.168746", "market_id": "0xcab7ba4a9133cfd407d7e73e5757e5abbace413b59421527a31113406c97815c", "raw": {"market": "0xcab7ba4a9133cfd407d7e73e5757e5abbace413b59421527a31113406c97815c", "asset_id": "20002636398944597965698652220992177552927816915094913583821579024925426590022", "price": "0.991", "size": "818.33", "side": "SELL", "timestamp": "1768475316871", "received_at": "2026-01-15T12:08:37.000914"}}
{"event_type": "price_change", "event_ts": "2026-01-15T12:08:37.258958", "ingestion_ts": "2026-01-15T12:08:42.168746", "market_id": "0xc0e6b917320a47228fb96e3b5ae0e5c93773a5ae2662ae4e1f37807cfe47ce98", "raw": {"market": "0xc0e6b917320a47228fb96e3b5ae0e5c93773a5ae2662ae4e1f37807cfe47ce98", "asset_id": "58656358377246279051017109359677190749228949103591068167284263961542487110215", "price": "0.003", "size": "441.38", "side": "BUY", "timestamp": "1768475317124", "received_at": "2026-01-15T12:08:37.258958"}}
{"event_type": "price_change", "event_ts": "2026-01-15T12:08:37.258958", "ingestion_ts": "2026-01-15T12:08:42.168746", "market_id": "0xc0e6b917320a47228fb96e3b5ae0e5c93773a5ae2662ae4e1f37807cfe47ce98", "raw": {"market": "0xc0e6b917320a47228fb96e3b5ae0e5c93773a5ae2662ae4e1f37807cfe47ce98", "asset_id": "81647294538046680798858716589766492074338758116170717123345952330712416337530", "price": "0.997", "size": "441.38", "side": "SELL", "timestamp": "1768475317124", "received_at": "2026-01-15T12:08:37.258958"}}
{"event_type": "price_change", "event_ts": "2026-01-15T12:08:37.684421", "ingestion_ts": "2026-01-15T12:08:42.168746", "market_id": "0xc0e6b917320a47228fb96e3b5ae0e5c93773a5ae2662ae4e1f37807cfe47ce98", "raw": {"market": "0xc0e6b917320a47228fb96e3b5ae0e5c93773a5ae2662ae4e1f37807cfe47ce98", "asset_id": "58656358377246279051017109359677190749228949103591068167284263961542487110215", "price": "0.004", "size": "7.06", "side": "BUY", "timestamp": "1768475317567", "received_at": "2026-01-15T12:08:37.684421"}}
{"event_type": "price_change", "event_ts": "2026-01-15T12:08:37.684421", "ingestion_ts": "2026-01-15T12:08:42.168746", "market_id": "0xc0e6b917320a47228fb96e3b5ae0e5c93773a5ae2662ae4e1f37807cfe47ce98", "raw": {"market": "0xc0e6b917320a47228fb96e3b5ae0e5c93773a5ae2662ae4e1f37807cfe47ce98", "asset_id": "81647294538046680798858716589766492074338758116170717123345952330712416337530", "price": "0.996", "size": "7.06", "side": "SELL", "timestamp": "1768475317567", "received_at": "2026-01-15T12:08:37.684421"}}
{"event_type": "price_change", "event_ts": "2026-01-15T12:08:37.685245", "ingestion_ts": "2026-01-15T12:08:42.168746", "market_id": "0xc0e6b917320a47228fb96e3b5ae0e5c93773a5ae2662ae4e1f37807cfe47ce98", "raw": {"market": "0xc0e6b917320a47228fb96e3b5ae0e5c93773a5ae2662ae4e1f37807cfe47ce98", "asset_id": "58656358377246279051017109359677190749228949103591068167284263961542487110215", "price": "0.004", "size": "14.12", "side": "BUY", "timestamp": "1768475317568", "received_at": "2026-01-15T12:08:37.685245"}}
{"event_type": "price_change", "event_ts": "2026-01-15T12:08:37.685245", "ingestion_ts": "2026-01-15T12:08:42.168746", "market_id": "0xc0e6b917320a47228fb96e3b5ae0e5c93773a5ae2662ae4e1f37807cfe47ce98", "raw": {"market": "0xc0e6b917320a47228fb96e3b5ae0e5c93773a5ae2662ae4e1f37807cfe47ce98", "asset_id": "81647294538046680798858716589766492074338758116170717123345952330712416337530", "price": "0.996", "size": "14.12", "side": "SELL", "timestamp": "1768475317568", "received_at": "2026-01-15T12:08:37.685245"}}
{"event_type": "price_change", "event_ts": "2026-01-15T12:08:40.506287", "ingestion_ts": "2026-01-15T12:08:42.168746", "market_id": "0xe68594f1350f5535532b24979b5b5c1948432cbfc0c363802c32a8f9ab4e6509", "raw": {"market": "0xe68594f1350f5535532b24979b5b5c1948432cbfc0c363802c32a8f9ab4e6509", "asset_id": "3074032031589250926591186368301243337494992039402397918135503567058257050088", "price": "0.852", "size": "0", "side": "BUY", "timestamp": "1768475320261", "received_at": "2026-01-15T12:08:40.506287"}}
{"event_type": "price_change", "event_ts": "2026-01-15T12:08:40.506287", "ingestion_ts": "2026-01-15T12:08:42.168746", "market_id": "0xe68594f1350f5535532b24979b5b5c1948432cbfc0c363802c32a8f9ab4e6509", "raw": {"market": "0xe68594f1350f5535532b24979b5b5c1948432cbfc0c363802c32a8f9ab4e6509", "asset_id": "47459180813047899567328389455747872955901265556145057896316155826890276004242", "price": "0.148", "size": "0", "side": "SELL", "timestamp": "1768475320261", "received_at": "2026-01-15T12:08:40.506287"}}
{"event_type": "price_change", "event_ts": "2026-01-15T12:08:40.506328", "ingestion_ts": "2026-01-15T12:08:42.168746", "market_id": "0x50e477f0b316a3d97d60486479657c63be0763834d0e2e8a30b1b86dc3c1c001", "raw": {"market": "0x50e477f0b316a3d97d60486479657c63be0763834d0e2e8a30b1b86dc3c1c001", "asset_id": "39981134260608444876865205057565852475343967395624370698967311821208058420507", "price": "0.851", "size": "0", "side": "BUY", "timestamp": "1768475320261", "received_at": "2026-01-15T12:08:40.506328"}}
{"event_type": "price_change", "event_ts": "2026-01-15T12:08:40.506328", "ingestion_ts": "2026-01-15T12:08:42.168746", "market_id": "0x50e477f0b316a3d97d60486479657c63be0763834d0e2e8a30b1b86dc3c1c001", "raw": {"market": "0x50e477f0b316a3d97d60486479657c63be0763834d0e2e8a30b1b86dc3c1c001", "asset_id": "60573178197991590327120832143415406583517170365625050489007297367895074266641", "price": "0.149", "size": "0", "side": "SELL", "timestamp": "1768475320261", "received_at": "2026-01-15T12:08:40.506328"}}
{"event_type": "price_change", "event_ts": "2026-01-15T12:08:40.506727", "ingestion_ts": "2026-01-15T12:08:42.168746", "market_id": "0xea644975be7b2ad32b536a94ae21b707ecb2f84290225b24e60ca46dd77903dd", "raw": {"market": "0xea644975be7b2ad32b536a94ae21b707ecb2f84290225b24e60ca46dd77903dd", "asset_id": "19255594762111702415265750364124818677094538461124581923455280001407159960455", "price": "0.852", "size": "0", "side": "BUY", "timestamp": "1768475320261", "received_at": "2026-01-15T12:08:40.506727"}}
{"event_type": "price_change", "event_ts": "2026-01-15T12:08:40.506727", "ingestion_ts": "2026-01-15T12:08:42.168746", "market_id": "0xea644975be7b2ad32b536a94ae21b707ecb2f84290225b24e60ca46dd77903dd", "raw": {"market": "0xea644975be7b2ad32b536a94ae21b707ecb2f84290225b24e60ca46dd77903dd", "asset_id": "110044455628775971785618539427229099821815416148768008176051068105157446559241", "price": "0.148", "size": "0", "side": "SELL", "timestamp": "1768475320261", "received_at": "2026-01-15T12:08:40.506727"}}
{"event_type": "price_change", "event_ts": "2026-01-15T12:08:40.671499", "ingestion_ts": "2026-01-15T12:08:42.168746", "market_id": "0xe68594f1350f5535532b24979b5b5c1948432cbfc0c363802c32a8f9ab4e6509", "raw": {"market": "0xe68594f1350f5535532b24979b5b5c1948432cbfc0c363802c32a8f9ab4e6509", "asset_id": "3074032031589250926591186368301243337494992039402397918135503567058257050088", "price": "0.852", "size": "5", "side": "BUY", "timestamp": "1768475320445", "received_at": "2026-01-15T12:08:40.671499"}}
{"event_type": "price_change", "event_ts": "2026-01-15T12:08:40.671499", "ingestion_ts": "2026-01-15T12:08:42.168746", "market_id": "0xe68594f1350f5535532b24979b5b5c1948432cbfc0c363802c32a8f9ab4e6509", "raw": {"market": "0xe68594f1350f5535532b24979b5b5c1948432cbfc0c363802c32a8f9ab4e6509", "asset_id": "47459180813047899567328389455747872955901265556145057896316155826890276004242", "price": "0.148", "size": "5", "side": "SELL", "timestamp": "1768475320445", "received_at": "2026-01-15T12:08:40.671499"}}
{"event_type": "price_change", "event_ts": "2026-01-15T12:08:40.671539", "ingestion_ts": "2026-01-15T12:08:42.168746", "market_id": "0x50e477f0b316a3d97d60486479657c63be0763834d0e2e8a30b1b86dc3c1c001", "raw": {"market": "0x50e477f0b316a3d97d60486479657c63be0763834d0e2e8a30b1b86dc3c1c001", "asset_id": "39981134260608444876865205057565852475343967395624370698967311821208058420507", "price": "0.852", "size": "5", "side": "BUY", "timestamp": "1768475320445", "received_at": "2026-01-15T12:08:40.671539"}}
{"event_type": "price_change", "event_ts": "2026-01-15T12:08:40.671539", "ingestion_ts": "2026-01-15T12:08:42.168746", "market_id": "0x50e477f0b316a3d97d60486479657c63be0763834d0e2e8a30b1b86dc3c1c001", "raw": {"market": "0x50e477f0b316a3d97d60486479657c63be0763834d0e2e8a30b1b86dc3c1c001", "asset_id": "60573178197991590327120832143415406583517170365625050489007297367895074266641", "price": "0.148", "size": "5", "side": "SELL", "timestamp": "1768475320445", "received_at": "2026-01-15T12:08:40.671539"}}
{"event_type": "price_change", "event_ts": "2026-01-15T12:08:40.671551", "ingestion_ts": "2026-01-15T12:08:42.168746", "market_id": "0xea644975be7b2ad32b536a94ae21b707ecb2f84290225b24e60ca46dd77903dd", "raw": {"market": "0xea644975be7b2ad32b536a94ae21b707ecb2f84290225b24e60ca46dd77903dd", "asset_id": "19255594762111702415265750364124818677094538461124581923455280001407159960455", "price": "0.854", "size": "5", "side": "BUY", "timestamp": "1768475320445", "received_at": "2026-01-15T12:08:40.671551"}}
{"event_type": "price_change", "event_ts": "2026-01-15T12:08:40.671551", "ingestion_ts": "2026-01-15T12:08:42.168746", "market_id": "0xea644975be7b2ad32b536a94ae21b707ecb2f84290225b24e60ca46dd77903dd", "raw": {"market": "0xea644975be7b2ad32b536a94ae21b707ecb2f84290225b24e60ca46dd77903dd", "asset_id": "110044455628775971785618539427229099821815416148768008176051068105157446559241", "price": "0.146", "size": "5", "side": "SELL", "timestamp": "1768475320445", "received_at": "2026-01-15T12:08:40.671551"}}
{"event_type": "price_change", "event_ts": "2026-01-15T12:08:41.215666", "ingestion_ts": "2026-01-15T12:08:42.168746", "market_id": "0xcab7ba4a9133cfd407d7e73e5757e5abbace413b59421527a31113406c97815c", "raw": {"market": "0xcab7ba4a9133cfd407d7e73e5757e5abbace413b59421527a31113406c97815c", "asset_id": "96361925776989336186111887920533578209326565663637092688733016597062311745569", "price": "0.006", "size": "127.41", "side": "BUY", "timestamp": "1768475321098", "received_at": "2026-01-15T12:08:41.215666"}}
{"event_type": "price_change", "event_ts": "2026-01-15T12:08:41.215666", "ingestion_ts": "2026-01-15T12:08:42.168746", "market_id": "0xcab7ba4a9133cfd407d7e73e5757e5abbace413b59421527a31113406c97815c", "raw": {"market": "0xcab7ba4a9133cfd407d7e73e5757e5abbace413b59421527a31113406c97815c", "asset_id": "20002636398944597965698652220992177552927816915094913583821579024925426590022", "price": "0.994", "size": "127.41", "side": "SELL", "timestamp": "1768475321098", "received_at": "2026-01-15T12:08:41.215666"}}
{"event_type": "price_change", "event_ts": "2026-01-15T12:08:41.216112", "ingestion_ts": "2026-01-15T12:08:42.168746", "market_id": "0xcab7ba4a9133cfd407d7e73e5757e5abbace413b59421527a31113406c97815c", "raw": {"market": "0xcab7ba4a9133cfd407d7e73e5757e5abbace413b59421527a31113406c97815c", "asset_id": "96361925776989336186111887920533578209326565663637092688733016597062311745569", "price": "0.009", "size": "812.25", "side": "BUY", "timestamp": "1768475321098", "received_at": "2026-01-15T12:08:41.216112"}}
{"event_type": "price_change", "event_ts": "2026-01-15T12:08:41.216112", "ingestion_ts": "2026-01-15T12:08:42.168746", "market_id": "0xcab7ba4a9133cfd407d7e73e5757e5abbace413b59421527a31113406c97815c", "raw": {"market": "0xcab7ba4a9133cfd407d7e73e5757e5abbace413b59421527a31113406c97815c", "asset_id": "20002636398944597965698652220992177552927816915094913583821579024925426590022", "price": "0.991", "size": "812.25", "side": "SELL", "timestamp": "1768475321098", "received_at": "2026-01-15T12:08:41.216112"}}
{"event_type": "price_change", "event_ts": "2026-01-15T12:08:41.582724", "ingestion_ts": "2026-01-15T12:08:42.168746", "market_id": "0xcab7ba4a9133cfd407d7e73e5757e5abbace413b59421527a31113406c97815c", "raw": {"market": "0xcab7ba4a9133cfd407d7e73e5757e5abbace413b59421527a31113406c97815c", "asset_id": "96361925776989336186111887920533578209326565663637092688733016597062311745569", "price": "0.006", "size": "136.51", "side": "BUY", "timestamp": "1768475321466", "received_at": "2026-01-15T12:08:41.582724"}}
{"event_type": "price_change", "event_ts": "2026-01-15T12:08:41.582724", "ingestion_ts": "2026-01-15T12:08:42.168746", "market_id": "0xcab7ba4a9133cfd407d7e73e5757e5abbace413b59421527a31113406c97815c", "raw": {"market": "0xcab7ba4a9133cfd407d7e73e5757e5abbace413b59421527a31113406c97815c", "asset_id": "20002636398944597965698652220992177552927816915094913583821579024925426590022", "price": "0.994", "size": "136.51", "side": "SELL", "timestamp": "1768475321466", "received_at": "2026-01-15T12:08:41.582724"}}
{"event_type": "price_change", "event_ts": "2026-01-15T12:08:41.583613", "ingestion_ts": "2026-01-15T12:08:42.168746", "market_id": "0xcab7ba4a9133cfd407d7e73e5757e5abbace413b59421527a31113406c97815c", "raw": {"market": "0xcab7ba4a9133cfd407d7e73e5757e5abbace413b59421527a31113406c97815c", "asset_id": "96361925776989336186111887920533578209326565663637092688733016597062311745569", "price": "0.009", "size": "818.33", "side": "BUY", "timestamp": "1768475321467", "received_at": "2026-01-15T12:08:41.583613"}}
{"event_type": "price_change", "event_ts": "2026-01-15T12:08:41.583613", "ingestion_ts": "2026-01-15T12:08:42.168746", "market_id": "0xcab7ba4a9133cfd407d7e73e5757e5abbace413b59421527a31113406c97815c", "raw": {"market": "0xcab7ba4a9133cfd407d7e73e5757e5abbace413b59421527a31113406c97815c", "asset_id": "20002636398944597965698652220992177552927816915094913583821579024925426590022", "price": "0.991", "size": "818.33", "side": "SELL", "timestamp": "1768475321467", "received_at": "2026-01-15T12:08:41.583613"}}
{"event_type": "price_change", "event_ts": "2026-01-15T12:08:41.702009", "ingestion_ts": "2026-01-15T12:08:42.168746", "market_id": "0xc0e6b917320a47228fb96e3b5ae0e5c93773a5ae2662ae4e1f37807cfe47ce98", "raw": {"market": "0xc0e6b917320a47228fb96e3b5ae0e5c93773a5ae2662ae4e1f37807cfe47ce98", "asset_id": "58656358377246279051017109359677190749228949103591068167284263961542487110215", "price": "0.004", "size": "7.06", "side": "BUY", "timestamp": "1768475321581", "received_at": "2026-01-15T12:08:41.702009"}}
{"event_type": "price_change", "event_ts": "2026-01-15T12:08:41.702009", "ingestion_ts": "2026-01-15T12:08:42.168746", "market_id": "0xc0e6b917320a47228fb96e3b5ae0e5c93773a5ae2662ae4e1f37807cfe47ce98", "raw": {"market": "0xc0e6b917320a47228fb96e3b5ae0e5c93773a5ae2662ae4e1f37807cfe47ce98", "asset_id": "81647294538046680798858716589766492074338758116170717123345952330712416337530", "price": "0.996", "size": "7.06", "side": "SELL", "timestamp": "1768475321581", "received_at": "2026-01-15T12:08:41.702009"}}
{"event_type": "price_change", "event_ts": "2026-01-15T12:08:41.788221", "ingestion_ts": "2026-01-15T12:08:42.168746", "market_id": "0x49686d26fb712515cd5e12c23f0a1c7e10214c7faa3cb0a730aabe0c33694082", "raw": {"market": "0x49686d26fb712515cd5e12c23f0a1c7e10214c7faa3cb0a730aabe0c33694082", "asset_id": "30442780799048074404860985387051749017905070253466005720364298335239299761065", "price": "0.006", "size": "5.17", "side": "BUY", "timestamp": "1768475321665", "received_at": "2026-01-15T12:08:41.788221"}}
{"event_type": "price_change", "event_ts": "2026-01-15T12:08:41.788221", "ingestion_ts": "2026-01-15T12:08:42.168746", "market_id": "0x49686d26fb712515cd5e12c23f0a1c7e10214c7faa3cb0a730aabe0c33694082", "raw": {"market": "0x49686d26fb712515cd5e12c23f0a1c7e10214c7faa3cb0a730aabe0c33694082", "asset_id": "13244681086321087932946246027856416106585284024824496763706748621681543444582", "price": "0.994", "size": "5.17", "side": "SELL", "timestamp": "1768475321665", "received_at": "2026-01-15T12:08:41.788221"}}
{"event_type": "price_change", "event_ts": "2026-01-15T12:08:42.114108", "ingestion_ts": "2026-01-15T12:08:42.168746", "market_id": "0xc0e6b917320a47228fb96e3b5ae0e5c93773a5ae2662ae4e1f37807cfe47ce98", "raw": {"market": "0xc0e6b917320a47228fb96e3b5ae0e5c93773a5ae2662ae4e1f37807cfe47ce98", "asset_id": "58656358377246279051017109359677190749228949103591068167284263961542487110215", "price": "0.005", "size": "8.63", "side": "BUY", "timestamp": "1768475321974", "received_at": "2026-01-15T12:08:42.114108"}}
{"event_type": "price_change", "event_ts": "2026-01-15T12:08:42.114108", "ingestion_ts": "2026-01-15T12:08:42.168746", "market_id": "0xc0e6b917320a47228fb96e3b5ae0e5c93773a5ae2662ae4e1f37807cfe47ce98", "raw": {"market": "0xc0e6b917320a47228fb96e3b5ae0e5c93773a5ae2662ae4e1f37807cfe47ce98", "asset_id": "81647294538046680798858716589766492074338758116170717123345952330712416337530", "price": "0.995", "size": "8.63", "side": "SELL", "timestamp": "1768475321974", "received_at": "2026-01-15T12:08:42.114108"}}
{"event_type": "new_market", "event_ts": "2026-01-15T12:05:24.853251", "ingestion_ts": "2026-01-15T12:08:42.168746", "market_id": "1189329", "raw": {"id": "1189329", "question": "CA River Plate vs. Gimnasia y Esgrima de La Plata: O/U 2.5", "market": "0x1d6e85dbd387b16cf826340937fce148efc3929c8d13aec3eaaa81e6b7ba581d", "slug": "arg-riv-gim-2026-01-28-total-2pt5", "description": "In the upcoming Primera División Argentina game between CA River Plate and Gimnasia y Esgrima de La Plata, scheduled for January 28 at 6:00 PM ET:\n\nThis market will resolve to \"Over\" if CA River Plate and Gimnasia y Esgrima de La Plata combine to score 3 or more goals in this game.\n\nIf the combined total is less than 3, this market will resolve to \"Under\".\n\nIf the game is postponed, this market will remain open until the game has been completed. If the game is canceled entirely, with no make-up game, this market will resolve 50–50.\n\nIf the game is started but not completed, this market will resolve according to the official final score published on ligaprofesional.ar. This market refers only to the outcome within the first 90 minutes of regular play plus stoppage time.", "assets_ids": ["15959547836296922045426578168346241167597546123762348648466654287695875541042", "80104504651751897109976827615637289175704595738686663643384016863044528753284"], "outcomes": ["Over", "Under"], "timestamp": "1768475124733", "received_at": "2026-01-15T12:05:24.853251"}}
{"event_type": "new_market", "event_ts": "2026-01-15T12:05:26.828837", "ingestion_ts": "2026-01-15T12:08:42.168746", "market_id": "1189328", "raw": {"id": "1189328", "question": "CA River Plate vs. Gimnasia y Esgrima de La Plata: O/U 1.5", "market": "0x71008a98fa7dd3eebdcf279febc951894ebb728efdb2748ee96c125ed4a8933f", "slug": "arg-riv-gim-2026-01-28-total-1pt5", "description": "In the upcoming Primera División Argentina game between CA River Plate and Gimnasia y Esgrima de La Plata, scheduled for January 28 at 6:00 PM ET:\n\nThis market will resolve to \"Over\" if CA River Plate and Gimnasia y Esgrima de La Plata combine to score 2 or more goals in this game.\n\nIf the combined total is less than 2, this market will resolve to \"Under\".\n\nIf the game is postponed, this market will remain open until the game has been completed. If the game is canceled entirely, with no make-up game, this market will resolve 50–50.\n\nIf the game is started but not completed, this market will resolve according to the official final score published on ligaprofesional.ar. This market refers only to the outcome within the first 90 minutes of regular play plus stoppage time.", "assets_ids": ["32105933203500604408259434453669260949628709323065588500489111946620444515336", "106238726087857835662025452949229695893614600215482089949221795068389810484050"], "outcomes": ["Over", "Under"], "timestamp": "1768475126682", "received_at": "2026-01-15T12:05:26.828837"}}
{"event_type": "new_market", "event_ts": "2026-01-15T12:05:27.084265", "ingestion_ts": "2026-01-15T12:08:42.168746", "market_id": "1189330", "raw": {"id": "1189330", "question": "CA River Plate vs. Gimnasia y Esgrima de La Plata: O/U 3.5", "market": "0x9915188c97c08c25793ae8d05fc555d047508a36097e3dfb7e235df239cc29a8", "slug": "arg-riv-gim-2026-01-28-total-3pt5", "description": "In the upcoming Primera División Argentina game between CA River Plate and Gimnasia y Esgrima de La Plata, scheduled for January 28 at 6:00 PM ET:\n\nThis market will resolve to \"Over\" if CA River Plate and Gimnasia y Esgrima de La Plata combine to score 4 or more goals in this game.\n\nIf the combined total is less than 4, this market will resolve to \"Under\".\n\nIf the game is postponed, this market will remain open until the game has been completed. If the game is canceled entirely, with no make-up game, this market will resolve 50–50.\n\nIf the game is started but not completed, this market will resolve according to the official final score published on ligaprofesional.ar. This market refers only to the outcome within the first 90 minutes of regular play plus stoppage time.", "assets_ids": ["55411899930088570067470110649429180830907728637084328708004029859345776962995", "89952363749787490604753642566845308054497655642374366200118056471766622427900"], "outcomes": ["Over", "Under"], "timestamp": "1768475126936", "received_at": "2026-01-15T12:05:27.084265"}}
{"event_type": "new_market", "event_ts": "2026-01-15T12:05:27.309793", "ingestion_ts": "2026-01-15T12:08:42.168746", "market_id": "1189331", "raw": {"id": "1189331", "question": "CA River Plate vs. Gimnasia y Esgrima de La Plata: O/U 4.5", "market": "0x1eb9df578fc9d76913939c662c2a76cb0bfd71d3e073718e4ad2300593a23b4d", "slug": "arg-riv-gim-2026-01-28-total-4pt5", "description": "In the upcoming Primera División Argentina game between CA River Plate and Gimnasia y Esgrima de La Plata, scheduled for January 28 at 6:00 PM ET:\n\nThis market will resolve to \"Over\" if CA River Plate and Gimnasia y Esgrima de La Plata combine to score 5 or more goals in this game.\n\nIf the combined total is less than 5, this market will resolve to \"Under\".\n\nIf the game is postponed, this market will remain open until the game has been completed. If the game is canceled entirely, with no make-up game, this market will resolve 50–50.\n\nIf the game is started but not completed, this market will resolve according to the official final score published on ligaprofesional.ar. This market refers only to the outcome within the first 90 minutes of regular play plus stoppage time.", "assets_ids": ["22087788613599558801712703369423248970922199426581585525754227160072582625265", "8219193169239638318951192529166878635535635341727236790074476550153924622753"], "outcomes": ["Over", "Under"], "timestamp": "1768475127189", "received_at": "2026-01-15T12:05:27.309793"}}
{"event_type": "new_market", "event_ts": "2026-01-15T12:05:27.566333", "ingestion_ts": "2026-01-15T12:08:42.168746", "market_id": "1189332", "raw": {"id": "1189332", "question": "CA River Plate vs. Gimnasia y Esgrima de La Plata: Both Teams to Score", "market": "0xf69bfaac0a69516d1aed90fc1b275ed600af05314ba3409b7a5c4937f2ec23e0", "slug": "arg-riv-gim-2026-01-28-btts", "description": "In the upcoming Primera División Argentina game between CA River Plate and Gimnasia y Esgrima de La Plata, scheduled for January 28 at 6:00 PM ET:\n\nThis market will resolve to \"Yes\" if both CA River Plate and Gimnasia y Esgrima de La Plata each score at least one goal during the game.\n\nThis market will resolve to \"No\" if either team fails to score (i.e., if one or both teams finish with zero goals).\n\nIf the game is postponed, this market will remain open until the game has been completed. If the game is canceled entirely, with no make-up game, this market will resolve 50–50.\n\nIf the game is started but not completed, this market will resolve according to the official final score published on ligaprofesional.ar. This market refers only to the outcome within the first 90 minutes of regular play plus stoppage time.", "assets_ids": ["15051417552737700541417947925513124005804862833368574352661633762229109747037", "18997942889146920606813683415027172591099587430516153035983168876844846262750"], "outcomes": ["Yes", "No"], "timestamp": "1768475127446", "received_at": "2026-01-15T12:05:27.566333"}}
{"event_type": "new_market", "event_ts": "2026-01-15T12:05:28.960562", "ingestion_ts": "2026-01-15T12:08:42.168746", "market_id": "1189342", "raw": {"id": "1189342", "question": "Racing Club vs. CA Rosario Central: Both Teams to Score", "market": "0xc63b43a2ff890a37b393148e28f102115db34b7f628f74c094b2fbcd85046d3f", "slug": "arg-rac-ros-2026-01-28-btts", "description": "In the upcoming Primera División Argentina game between Racing Club and CA Rosario Central, scheduled for January 28 at 4:00 PM ET:\n\nThis market will resolve to \"Yes\" if both Racing Club and CA Rosario Central each score at least one goal during the game.\n\nThis market will resolve to \"No\" if either team fails to score (i.e., if one or both teams finish with zero goals).\n\nIf the game is postponed, this market will remain open until the game has been completed. If the game is canceled entirely, with no make-up game, this market will resolve 50–50.\n\nIf the game is started but not completed, this market will resolve according to the official final score published on ligaprofesional.ar. This market refers only to the outcome within the first 90 minutes of regular play plus stoppage time.", "assets_ids": ["15150201159284286682643112880992701287151808991972030144638233218225996491759", "49703137961456797251534319723139734999628563125611596952276788225277170816329"], "outcomes": ["Yes", "No"], "timestamp": "1768475128840", "received_at": "2026-01-15T12:05:28.960562"}}
{"event_type": "new_market", "event_ts": "2026-01-15T12:05:29.213254", "ingestion_ts": "2026-01-15T12:08:42.168746", "market_id": "1189338", "raw": {"id": "1189338", "question": "Racing Club vs. CA Rosario Central: O/U 3.5", "market": "0xd6dad75ca2b6631524f117ac2ba96e21688cba5c0cd462218a8116be518edb98", "slug": "arg-rac-ros-2026-01-28-total-3pt5", "description": "In the upcoming Primera División Argentina game between Racing Club and CA Rosario Central, scheduled for January 28 at 4:00 PM ET:\n\nThis market will resolve to \"Over\" if Racing Club and CA Rosario Central combine to score 4 or more goals in this game.\n\nIf the combined total is less than 4, this market will resolve to \"Under\".\n\nIf the game is postponed, this market will remain open until the game has been completed. If the game is canceled entirely, with no make-up game, this market will resolve 50–50.\n\nIf the game is started but not completed, this market will resolve according to the official final score published on ligaprofesional.ar. This market refers only to the outcome within the first 90 minutes of regular play plus stoppage time.", "assets_ids": ["42498677192330617321710189539615569622819819161246892649784511055270749662846", "36273902733651815367661258035817185322385551073127183309734555360851541998545"], "outcomes": ["Over", "Under"], "timestamp": "1768475129094", "received_at": "2026-01-15T12:05:29.213254"}}
{"event_type": "new_market", "event_ts": "2026-01-15T12:05:29.496177", "ingestion_ts": "2026-01-15T12:08:42.168746", "market_id": "1189336", "raw": {"id": "1189336", "question": "Racing Club vs. CA Rosario Central: O/U 2.5", "market": "0xb69c382879ccef5add42d01ed9281f44ff08d0b0ef58da72c9075c6f28e0cf93", "slug": "arg-rac-ros-2026-01-28-total-2pt5", "description": "In the upcoming Primera División Argentina game between Racing Club and CA Rosario Central, scheduled for January 28 at 4:00 PM ET:\n\nThis market will resolve to \"Over\" if Racing Club and CA Rosario Central combine to score 3 or more goals in this game.\n\nIf the combined total is less than 3, this market will resolve to \"Under\".\n\nIf the game is postponed, this market will remain open until the game has been completed. If the game is canceled entirely, with no make-up game, this market will resolve 50–50.\n\nIf the game is started but not completed, this market will resolve according to the official final score published on ligaprofesional.ar. This market refers only to the outcome within the first 90 minutes of regular play plus stoppage time.", "assets_ids": ["35422079466485138129556576612370179666164300773681816408434307459776121384645", "96791456739933333271639923824956685875942785840388694225355749218647341100891"], "outcomes": ["Over", "Under"], "timestamp": "1768475129347", "received_at": "2026-01-15T12:05:29.496177"}}
{"event_type": "new_market", "event_ts": "2026-01-15T12:05:29.778570", "ingestion_ts": "2026-01-15T12:08:42.168746", "market_id": "1189334", "raw": {"id": "1189334", "question": "Racing Club vs. CA Rosario Central: O/U 1.5", "market": "0xbeb683b7b0cfb0a2d7c50fc865e2494dea436d9674f380d582ef2c863a8acba7", "slug": "arg-rac-ros-2026-01-28-total-1pt5", "description": "In the upcoming Primera División Argentina game between Racing Club and CA Rosario Central, scheduled for January 28 at 4:00 PM ET:\n\nThis market will resolve to \"Over\" if Racing Club and CA Rosario Central combine to score 2 or more goals in this game.\n\nIf the combined total is less than 2, this market will resolve to \"Under\".\n\nIf the game is postponed, this market will remain open until the game has been completed. If the game is canceled entirely, with no make-up game, this market will resolve 50–50.\n\nIf the game is started but not completed, this market will resolve according to the official final score published on ligaprofesional.ar. This market refers only to the outcome within the first 90 minutes of regular play plus stoppage time.", "assets_ids": ["46338570497933900814619172127499155783195600499322452321725505915699579241596", "79277445837563180535105425225005010190360953254554420989026325708743676713696"], "outcomes": ["Over", "Under"], "timestamp": "1768475129605", "received_at": "2026-01-15T12:05:29.778570"}}
{"event_type": "new_market", "event_ts": "2026-01-15T12:05:31.080466", "ingestion_ts": "2026-01-15T12:08:42.168746", "market_id": "1189347", "raw": {"id": "1189347", "question": "CA Aldosivi vs. CA Barracas Central: O/U 3.5", "market": "0x06174417ad483f065d7659c36aabd9f0e29dc17a8c3421a3c0ec716df41db05e", "slug": "arg-ald-bar-2026-01-28-total-3pt5", "description": "In the upcoming Primera División Argentina game between CA Aldosivi and CA Barracas Central, scheduled for January 28 at 3:00 PM ET:\n\nThis market will resolve to \"Over\" if CA Aldosivi and CA Barracas Central combine to score 4 or more goals in this game.\n\nIf the combined total is less than 4, this market will resolve to \"Under\".\n\nIf the game is postponed, this market will remain open until the game has been completed. If the game is canceled entirely, with no make-up game, this market will resolve 50–50.\n\nIf the game is started but not completed, this market will resolve according to the official final score published on ligaprofesional.ar. This market refers only to the outcome within the first 90 minutes of regular play plus stoppage time.", "assets_ids": ["26332281255737466354693189241098986395469814877518513932108676229565623383485", "18099895558284363745575067142450218885528443481174701636949592584960895264624"], "outcomes": ["Over", "Under"], "timestamp": "1768475130897", "received_at": "2026-01-15T12:05:31.080466"}}
{"event_type": "new_market", "event_ts": "2026-01-15T12:05:31.268813", "ingestion_ts": "2026-01-15T12:08:42.168746", "market_id": "1189340", "raw": {"id": "1189340", "question": "Racing Club vs. CA Rosario Central: O/U 4.5", "market": "0xea4bf035f2e2b7b0f0fd880097bff72a2132a67d48e88d666f3ca524e6c99cfa", "slug": "arg-rac-ros-2026-01-28-total-4pt5", "description": "In the upcoming Primera División Argentina game between Racing Club and CA Rosario Central, scheduled for January 28 at 4:00 PM ET:\n\nThis market will resolve to \"Over\" if Racing Club and CA Rosario Central combine to score 5 or more goals in this game.\n\nIf the combined total is less than 5, this market will resolve to \"Under\".\n\nIf the game is postponed, this market will remain open until the game has been completed. If the game is canceled entirely, with no make-up game, this market will resolve 50–50.\n\nIf the game is started but not completed, this market will resolve according to the official final score published on ligaprofesional.ar. This market refers only to the outcome within the first 90 minutes of regular play plus stoppage time.", "assets_ids": ["23910001925854374751237612034388577574653141630159997617813699407390135357665", "65977372496747834281539703408466307030653703231664348514486715438178290329646"], "outcomes": ["Over", "Under"], "timestamp": "1768475131152", "received_at": "2026-01-15T12:05:31.268813"}}
{"event_type": "new_market", "event_ts": "2026-01-15T12:05:31.523297", "ingestion_ts": "2026-01-15T12:08:42.168746", "market_id": "1189348", "raw": {"id": "1189348", "question": "CA Aldosivi vs. CA Barracas Central: O/U 4.5", "market": "0xc25cf927c371e05a621d84b8b7aa9431f91961616680fa8881eff2ab423dc00b", "slug": "arg-ald-bar-2026-01-28-total-4pt5", "description": "In the upcoming Primera División Argentina game between CA Aldosivi and CA Barracas Central, scheduled for January 28 at 3:00 PM ET:\n\nThis market will resolve to \"Over\" if CA Aldosivi and CA Barracas Central combine to score 5 or more goals in this game.\n\nIf the combined total is less than 5, this market will resolve to \"Under\".\n\nIf the game is postponed, this market will remain open until the game has been completed. If the game is canceled entirely, with no make-up game, this market will resolve 50–50.\n\nIf the game is started but not completed, this market will resolve according to the official final score published on ligaprofesional.ar. This market refers only to the outcome within the first 90 minutes of regular play plus stoppage time.", "assets_ids": ["113332388812221146374423696960505687834049822100331386584599701008815162733464", "11430289049759303014174533085485511351721079530123361699271713824667877918487"], "outcomes": ["Over", "Under"], "timestamp": "1768475131406", "received_at": "2026-01-15T12:05:31.523297"}}
{"event_type": "new_market", "event_ts": "2026-01-15T12:05:31.781156", "ingestion_ts": "2026-01-15T12:08:42.168746", "market_id": "1189346", "raw": {"id": "1189346", "question": "CA Aldosivi vs. CA Barracas Central: O/U 2.5", "market": "0xf3bbd723c1e5fc504776a5d8d6546c7400831fa9f86029a48e84e621d9f17530", "slug": "arg-ald-bar-2026-01-28-total-2pt5", "description": "In the upcoming Primera División Argentina game between CA Aldosivi and CA Barracas Central, scheduled for January 28 at 3:00 PM ET:\n\nThis market will resolve to \"Over\" if CA Aldosivi and CA Barracas Central combine to score 3 or more goals in this game.\n\nIf the combined total is less than 3, this market will resolve to \"Under\".\n\nIf the game is postponed, this market will remain open until the game has been completed. If the game is canceled entirely, with no make-up game, this market will resolve 50–50.\n\nIf the game is started but not completed, this market will resolve according to the official final score published on ligaprofesional.ar. This market refers only to the outcome within the first 90 minutes of regular play plus stoppage time.", "assets_ids": ["8469007216441200425829943730729467963181116358622244980409683948178701320316", "51221845176367715896875758131608057630454342285854025698027818341706287109976"], "outcomes": ["Over", "Under"], "timestamp": "1768475131661", "received_at": "2026-01-15T12:05:31.781156"}}
{"event_type": "new_market", "event_ts": "2026-01-15T12:05:32.029347", "ingestion_ts": "2026-01-15T12:08:42.168746", "market_id": "1189349", "raw": {"id": "1189349", "question": "CA Aldosivi vs. CA Barracas Central: Both Teams to Score", "market": "0x148ba02fa0808af3a5a476bbcd4733de1371c4d6376ea6e1c273596c01a51ae2", "slug": "arg-ald-bar-2026-01-28-btts", "description": "In the upcoming Primera División Argentina game between CA Aldosivi and CA Barracas Central, scheduled for January 28 at 3:00 PM ET:\n\nThis market will resolve to \"Yes\" if both CA Aldosivi and CA Barracas Central each score at least one goal during the game.\n\nThis market will resolve to \"No\" if either team fails to score (i.e., if one or both teams finish with zero goals).\n\nIf the game is postponed, this market will remain open until the game has been completed. If the game is canceled entirely, with no make-up game, this market will resolve 50–50.\n\nIf the game is started but not completed, this market will resolve according to the official final score published on ligaprofesional.ar. This market refers only to the outcome within the first 90 minutes of regular play plus stoppage time.", "assets_ids": ["108650155838401519686118001392006656339605908570030190213782786396167660492351", "93824376681265802671921175942596766808113717830057422573077151180071826733452"], "outcomes": ["Yes", "No"], "timestamp": "1768475131913", "received_at": "2026-01-15T12:05:32.029347"}}
{"event_type": "new_market", "event_ts": "2026-01-15T12:05:33.228767", "ingestion_ts": "2026-01-15T12:08:42.168746", "market_id": "1189345", "raw": {"id": "1189345", "question": "CA Aldosivi vs. CA Barracas Central: O/U 1.5", "market": "0x60dc9ac980e807b8f892d4dd551c079d3e74f149e6fcfdf71ecf5369e910b053", "slug": "arg-ald-bar-2026-01-28-total-1pt5", "description": "In the upcoming Primera División Argentina game between CA Aldosivi and CA Barracas Central, scheduled for January 28 at 3:00 PM ET:\n\nThis market will resolve to \"Over\" if CA Aldosivi and CA Barracas Central combine to score 2 or more goals in this game.\n\nIf the combined total is less than 2, this market will resolve to \"Under\".\n\nIf the game is postponed, this market will remain open until the game has been completed. If the game is canceled entirely, with no make-up game, this market will resolve 50–50.\n\nIf the game is started but not completed, this market will resolve according to the official final score published on ligaprofesional.ar. This market refers only to the outcome within the first 90 minutes of regular play plus stoppage time.", "assets_ids": ["90226723536418759655580992953977577673934988120925659404719146052953006982231", "55004233060952359114549227664477821433175751648049274517540992823514588548244"], "outcomes": ["Over", "Under"], "timestamp": "1768475133112", "received_at": "2026-01-15T12:05:33.228767"}}
