{"event_type": "price_change", "event_ts": "2026-01-15T12:05:38.900692", "ingestion_ts": "2026-01-15T12:08:42.168746", "market_id": "0xcab7ba4a9133cfd407d7e73e5757e5abbace413b59421527a31113406c97815c", "raw": {"market": "0xcab7ba4a9133cfd407d7e73e5757e5abbace413b59421527a31113406c97815c", "asset_id": "20002636398944597965698652220992177552927816915094913583821579024925426590022", "price": "0.994", "size": "135.73", "side": "SELL", "timestamp": "1768475138781", "received_at": "2026-01-15T12:05:38.900692"}}
{"event_type": "price_change", "event_ts": "2026-01-15T12:05:38.901456", "ingestion_ts": "2026-01-15T12:08:42.168746", "market_id": "0xcab7ba4a9133cfd407d7e73e5757e5abbace413b59421527a31113406c97815c", "raw": {"market": "0xcab7ba4a9133cfd407d7e73e5757e5abbace413b59421527a31113406c97815c", "asset_id": "96361925776989336186111887920533578209326565663637092688733016597062311745569", "price": "0.006", "size": "144.05", "side": "BUY", "timestamp": "1768475138782", "received_at": "2026-01-15T12:05:38.901456"}}
{"event_type": "price_change", "event_ts": "2026-01-15T12:05:38.901456", "ingestion_ts": "2026-01-15T12:08:42.168746", "market_id": "0xcab7ba4a9133cfd407d7e73e5757e5abbace413b59421527a31113406c97815c", "raw": {"market": "0xcab7ba4a9133cfd407d7e73e5757e5abbace413b59421527a31113406c97815c", "asset_id": "20002636398944597965698652220992177552927816915094913583821579024925426590022", "price": "0.994", "size": "144.05", "side": "SELL", "timestamp": "1768475138782", "received_at": "2026-01-15T12:05:38.901456"}}
{"event_type": "price_change", "event_ts": "2026-01-15T12:05:39.256548", "ingestion_ts": "2026-01-15T12:08:42.168746", "market_id": "0xc0e6b917320a47228fb96e3b5ae0e5c93773a5ae2662ae4e1f37807cfe47ce98", "raw": {"market": "0xc0e6b917320a47228fb96e3b5ae0e5c93773a5ae2662ae4e1f37807cfe47ce98", "asset_id": "58656358377246279051017109359677190749228949103591068167284263961542487110215", "price": "0.004", "size": "0", "side": "BUY", "timestamp": "1768475139136", "received_at": "2026-01-15T12:05:39.256548"}}
{"event_type": "price_change", "event_ts": "2026-01-15T12:05:39.256548", "ingestion_ts": "2026-01-15T12:08:42.168746", "market_id": "0xc0e6b917320a47228fb96e3b5ae0e5c93773a5ae2662ae4e1f37807cfe47ce98", "raw": {"market": "0xc0e6b917320a47228fb96e3b5ae0e5c93773a5ae2662ae4e1f37807cfe47ce98", "asset_id": "81647294538046680798858716589766492074338758116170717123345952330712416337530", "price": "0.996", "size": "0", "side": "SELL", "timestamp": "1768475139136", "received_at": "2026-01-15T12:05:39.256548"}}
{"event_type": "price_change", "event_ts": "2026-01-15T12:05:39.256584", "ingestion_ts": "2026-01-15T12:08:42.168746", "market_id": "0xc0e6b917320a47228fb96e3b5ae0e5c93773a5ae2662ae4e1f37807cfe47ce98", "raw": {"market": "0xc0e6b917320a47228fb96e3b5ae0e5c93773a5ae2662ae4e1f37807cfe47ce98", "asset_id": "58656358377246279051017109359677190749228949103591068167284263961542487110215", "price": "0.012", "size": "0", "side": "BUY", "timestamp": "1768475139136", "received_at": "2026-01-15T12:05:39.256584"}}
{"event_type": "price_change", "event_ts": "2026-01-15T12:05:39.256584", "ingestion_ts": "2026-01-15T12:08:42.168746", "market_id": "0xc0e6b917320a47228fb96e3b5ae0e5c93773a5ae2662ae4e1f37807cfe47ce98", "raw": {"market": "0xc0e6b917320a47228fb96e3b5ae0e5c93773a5ae2662ae4e1f37807cfe47ce98", "asset_id": "81647294538046680798858716589766492074338758116170717123345952330712416337530", "price": "0.988", "size": "0", "side": "SELL", "timestamp": "1768475139136", "received_at": "2026-01-15T12:05:39.256584"}}
{"event_type": "price_change", "event_ts": "2026-01-15T12:05:39.486034", "ingestion_ts": "2026-01-15T12:08:42.168746", "market_id": "0xc0e6b917320a47228fb96e3b5ae0e5c93773a5ae2662ae4e1f37807cfe47ce98", "raw": {"market": "0xc0e6b917320a47228fb96e3b5ae0e5c93773a5ae2662ae4e1f37807cfe47ce98", "asset_id": "58656358377246279051017109359677190749228949103591068167284263961542487110215", "price": "0.013", "size": "27.34", "side": "BUY", "timestamp": "1768475139368", "received_at": "2026-01-15T12:05:39.486034"}}
{"event_type": "price_change", "event_ts": "2026-01-15T12:05:39.486034", "ingestion_ts": "2026-01-15T12:08:42.168746", "market_id": "0xc0e6b917320a47228fb96e3b5ae0e5c93773a5ae2662ae4e1f37807cfe47ce98", "raw": {"market": "0xc0e6b917320a47228fb96e3b5ae0e5c93773a5ae2662ae4e1f37807cfe47ce98", "asset_id": "81647294538046680798858716589766492074338758116170717123345952330712416337530", "price": "0.987", "size": "27.34", "side": "SELL", "timestamp": "1768475139368", "received_at": "2026-01-15T12:05:39.486034"}}
{"event_type": "price_change", "event_ts": "2026-01-15T12:05:39.486958", "ingestion_ts": "2026-01-15T12:08:42.168746", "market_id": "0xc0e6b917320a47228fb96e3b5ae0e5c93773a5ae2662ae4e1f37807cfe47ce98", "raw": {"market": "0xc0e6b917320a47228fb96e3b5ae0e5c93773a5ae2662ae4e1f37807cfe47ce98", "asset_id": "58656358377246279051017109359677190749228949103591068167284263961542487110215", "price": "0.003", "size": "369.97", "side": "BUY", "timestamp": "1768475139369", "received_at": "2026-01-15T12:05:39.486958"}}
{"event_type": "price_change", "event_ts": "2026-01-15T12:05:39.486958", "ingestion_ts": "2026-01-15T12:08:42.168746", "market_id": "0xc0e6b917320a47228fb96e3b5ae0e5c93773a5ae2662ae4e1f37807cfe47ce98", "raw": {"market": "0xc0e6b917320a47228fb96e3b5ae0e5c93773a5ae2662ae4e1f37807cfe47ce98", "asset_id": "81647294538046680798858716589766492074338758116170717123345952330712416337530", "price": "0.997", "size": "369.97", "side": "SELL", "timestamp": "1768475139369", "received_at": "2026-01-15T12:05:39.486958"}}
{"event_type": "price_change", "event_ts": "2026-01-15T12:05:39.494203", "ingestion_ts": "2026-01-15T12:08:42.168746", "market_id": "0xc0e6b917320a47228fb96e3b5ae0e5c93773a5ae2662ae4e1f37807cfe47ce98", "raw": {"market": "0xc0e6b917320a47228fb96e3b5ae0e5c93773a5ae2662ae4e1f37807cfe47ce98", "asset_id": "58656358377246279051017109359677190749228949103591068167284263961542487110215", "price": "0.005", "size": "10.68", "side": "BUY", "timestamp": "1768475139370", "received_at": "2026-01-15T12:05:39.494203"}}
{"event_type": "price_change", "event_ts": "2026-01-15T12:05:39.494203", "ingestion_ts": "2026-01-15T12:08:42.168746", "market_id": "0xc0e6b917320a47228fb96e3b5ae0e5c93773a5ae2662ae4e1f37807cfe47ce98", "raw": {"market": "0xc0e6b917320a47228fb96e3b5ae0e5c93773a5ae2662ae4e1f37807cfe47ce98", "asset_id": "81647294538046680798858716589766492074338758116170717123345952330712416337530", "price": "0.995", "size": "10.68", "side": "SELL", "timestamp": "1768475139370", "received_at": "2026-01-15T12:05:39.494203"}}
{"event_type": "price_change", "event_ts": "2026-01-15T12:05:40.118799", "ingestion_ts": "2026-01-15T12:08:42.168746", "market_id": "0xcab7ba4a9133cfd407d7e73e5757e5abbace413b59421527a31113406c97815c", "raw": {"market": "0xcab7ba4a9133cfd407d7e73e5757e5abbace413b59421527a31113406c97815c", "asset_id": "96361925776989336186111887920533578209326565663637092688733016597062311745569", "price": "0.007", "size": "189.12", "side": "BUY", "timestamp": "1768475139998", "received_at": "2026-01-15T12:05:40.118799"}}
{"event_type": "price_change", "event_ts": "2026-01-15T12:05:40.118799", "ingestion_ts": "2026-01-15T12:08:42.168746", "market_id": "0xcab7ba4a9133cfd407d7e73e5757e5abbace413b59421527a31113406c97815c", "raw": {"market": "0xcab7ba4a9133cfd407d7e73e5757e5abbace413b59421527a31113406c97815c", "asset_id": "20002636398944597965698652220992177552927816915094913583821579024925426590022", "price": "0.993", "size": "189.12", "side": "SELL", "timestamp": "1768475139998", "received_at": "2026-01-15T12:05:40.118799"}}
{"event_type": "price_change", "event_ts": "2026-01-15T12:05:40.118836", "ingestion_ts": "2026-01-15T12:08:42.168746", "market_id": "0xcab7ba4a9133cfd407d7e73e5757e5abbace413b59421527a31113406c97815c", "raw": {"market": "0xcab7ba4a9133cfd407d7e73e5757e5abbace413b59421527a31113406c97815c", "asset_id": "96361925776989336186111887920533578209326565663637092688733016597062311745569", "price": "0.008", "size": "619.71", "side": "BUY", "timestamp": "1768475139998", "received_at": "2026-01-15T12:05:40.118836"}}
{"event_type": "price_change", "event_ts": "2026-01-15T12:05:40.118836", "ingestion_ts": "2026-01-15T12:08:42.168746", "market_id": "0xcab7ba4a9133cfd407d7e73e5757e5abbace413b59421527a31113406c97815c", "raw": {"market": "0xcab7ba4a9133cfd407d7e73e5757e5abbace413b59421527a31113406c97815c", "asset_id": "20002636398944597965698652220992177552927816915094913583821579024925426590022", "price": "0.992", "size": "619.71", "side": "SELL", "timestamp": "1768475139998", "received_at": "2026-01-15T12:05:40.118836"}}
{"event_type": "price_change", "event_ts": "2026-01-15T12:05:40.987441", "ingestion_ts": "2026-01-15T12:08:42.168746", "market_id": "0xcab7ba4a9133cfd407d7e73e5757e5abbace413b59421527a31113406c97815c", "raw": {"market": "0xcab7ba4a9133cfd407d7e73e5757e5abbace413b59421527a31113406c97815c", "asset_id": "96361925776989336186111887920533578209326565663637092688733016597062311745569", "price": "0.007", "size": "197.75", "side": "BUY", "timestamp": "1768475140868", "received_at": "2026-01-15T12:05:40.987441"}}
{"event_type": "price_change", "event_ts": "2026-01-15T12:05:40.987441", "ingestion_ts": "2026-01-15T12:08:42.168746", "market_id": "0xcab7ba4a9133cfd407d7e73e5757e5abbace413b59421527a31113406c97815c", "raw": {"market": "0xcab7ba4a9133cfd407d7e73e5757e5abbace413b59421527a31113406c97815c", "asset_id": "20002636398944597965698652220992177552927816915094913583821579024925426590022", "price": "0.993", "size": "197.75", "side": "SELL", "timestamp": "1768475140868", "received_at": "2026-01-15T12:05:40.987441"}}
{"event_type": "price_change", "event_ts": "2026-01-15T12:05:40.988232", "ingestion_ts": "2026-01-15T12:08:42.168746", "market_id": "0xcab7ba4a9133cfd407d7e73e5757e5abbace413b59421527a31113406c97815c", "raw": {"market": "0xcab7ba4a9133cfd407d7e73e5757e5abbace413b59421527a31113406c97815c", "asset_id": "96361925776989336186111887920533578209326565663637092688733016597062311745569", "price": "0.007", "size": "206.38", "side": "BUY", "timestamp": "1768475140869", "received_at": "2026-01-15T12:05:40.988232"}}
{"event_type": "price_change", "event_ts": "2026-01-15T12:05:40.988232", "ingestion_ts": "2026-01-15T12:08:42.168746", "market_id": "0xcab7ba4a9133cfd407d7e73e5757e5abbace413b59421527a31113406c97815c", "raw": {"market": "0xcab7ba4a9133cfd407d7e73e5757e5abbace413b59421527a31113406c97815c", "asset_id": "20002636398944597965698652220992177552927816915094913583821579024925426590022", "price": "0.993", "size": "206.38", "side": "SELL", "timestamp": "1768475140869", "received_at": "2026-01-15T12:05:40.988232"}}
{"event_type": "price_change", "event_ts": "2026-01-15T12:05:43.211306", "ingestion_ts": "2026-01-15T12:08:42.168746", "market_id": "0xcab7ba4a9133cfd407d7e73e5757e5abbace413b59421527a31113406c97815c", "raw": {"market": "0xcab7ba4a9133cfd407d7e73e5757e5abbace413b59421527a31113406c97815c", "asset_id": "96361925776989336186111887920533578209326565663637092688733016597062311745569", "price": "0.006", "size": "135.73", "side": "BUY", "timestamp": "1768475143081", "received_at": "2026-01-15T12:05:43.211306"}}
{"event_type": "price_change", "event_ts": "2026-01-15T12:05:43.211306", "ingestion_ts": "2026-01-15T12:08:42.168746", "market_id": "0xcab7ba4a9133cfd407d7e73e5757e5abbace413b59421527a31113406c97815c", "raw": {"market": "0xcab7ba4a9133cfd407d7e73e5757e5abbace413b59421527a31113406c97815c", "asset_id": "20002636398944597965698652220992177552927816915094913583821579024925426590022", "price": "0.994", "size": "135.73", "side": "SELL", "timestamp": "1768475143081", "received_at": "2026-01-15T12:05:43.211306"}}
{"event_type": "price_change", "event_ts": "2026-01-15T12:05:43.211343", "ingestion_ts": "2026-01-15T12:08:42.168746", "market_id": "0xcab7ba4a9133cfd407d7e73e5757e5abbace413b59421527a31113406c97815c", "raw": {"market": "0xcab7ba4a9133cfd407d7e73e5757e5abbace413b59421527a31113406c97815c", "asset_id": "96361925776989336186111887920533578209326565663637092688733016597062311745569", "price": "0.007", "size": "197.75", "side": "BUY", "timestamp": "1768475143081", "received_at": "2026-01-15T12:05:43.211343"}}
{"event_type": "price_change", "event_ts": "2026-01-15T12:05:43.211343", "ingestion_ts": "2026-01-15T12:08:42.168746", "market_id": "0xcab7ba4a9133cfd407d7e73e5757e5abbace413b59421527a31113406c97815c", "raw": {"market": "0xcab7ba4a9133cfd407d7e73e5757e5abbace413b59421527a31113406c97815c", "asset_id": "20002636398944597965698652220992177552927816915094913583821579024925426590022", "price": "0.993", "size": "197.75", "side": "SELL", "timestamp": "1768475143081", "received_at": "2026-01-15T12:05:43.211343"}}
{"event_type": "price_change", "event_ts": "2026-01-15T12:05:43.955719", "ingestion_ts": "2026-01-15T12:08:42.168746", "market_id": "0xcab7ba4a9133cfd407d7e73e5757e5abbace413b59421527a31113406c97815c", "raw": {"market": "0xcab7ba4a9133cfd407d7e73e5757e5abbace413b59421527a31113406c97815c", "asset_id": "96361925776989336186111887920533578209326565663637092688733016597062311745569", "price": "0.007", "size": "202.89", "side": "BUY", "timestamp": "1768475143836", "received_at": "2026-01-15T12:05:43.955719"}}
{"event_type": "price_change", "event_ts": "2026-01-15T12:05:43.955719", "ingestion_ts": "2026-01-15T12:08:42.168746", "market_id": "0xcab7ba4a9133cfd407d7e73e5757e5abbace413b59421527a31113406c97815c", "raw": {"market": "0xcab7ba4a9133cfd407d7e73e5757e5abbace413b59421527a31113406c97815c", "asset_id": "20002636398944597965698652220992177552927816915094913583821579024925426590022", "price": "0.993", "size": "202.89", "side": "SELL", "timestamp": "1768475143836", "received_at": "2026-01-15T12:05:43.955719"}}
{"event_type": "price_change", "event_ts": "2026-01-15T12:05:43.957159", "ingestion_ts": "2026-01-15T12:08:42.168746", "market_id": "0xcab7ba4a9133cfd407d7e73e5757e5abbace413b59421527a31113406c97815c", "raw": {"market": "0xcab7ba4a9133cfd407d7e73e5757e5abbace413b59421527a31113406c97815c", "asset_id": "96361925776989336186111887920533578209326565663637092688733016597062311745569", "price": "0.008", "size": "629", "side": "BUY", "timestamp": "1768475143837", "received_at": "2026-01-15T12:05:43.957159"}}
{"event_type": "price_change", "event_ts": "2026-01-15T12:05:43.957159", "ingestion_ts": "2026-01-15T12:08:42.168746", "market_id": "0xcab7ba4a9133cfd407d7e73e5757e5abbace413b59421527a31113406c97815c", "raw": {"market": "0xcab7ba4a9133cfd407d7e73e5757e5abbace413b59421527a31113406c97815c", "asset_id": "20002636398944597965698652220992177552927816915094913583821579024925426590022", "price": "0.992", "size": "629", "side": "SELL", "timestamp": "1768475143837", "received_at": "2026-01-15T12:05:43.957159"}}
{"event_type": "price_change", "event_ts": "2026-01-15T12:05:45.143537", "ingestion_ts": "2026-01-15T12:08:42.168746", "market_id": "0xc0e6b917320a47228fb96e3b5ae0e5c93773a5ae2662ae4e1f37807cfe47ce98", "raw": {"market": "0xc0e6b917320a47228fb96e3b5ae0e5c93773a5ae2662ae4e1f37807cfe47ce98", "asset_id": "58656358377246279051017109359677190749228949103591068167284263961542487110215", "price": "0.003", "size": "359.19", "side": "BUY", "timestamp": "1768475145000", "received_at": "2026-01-15T12:05:45.143537"}}
{"event_type": "price_change", "event_ts": "2026-01-15T12:05:45.143537", "ingestion_ts": "2026-01-15T12:08:42.168746", "market_id": "0xc0e6b917320a47228fb96e3b5ae0e5c93773a5ae2662ae4e1f37807cfe47ce98", "raw": {"market": "0xc0e6b917320a47228fb96e3b5ae0e5c93773a5ae2662ae4e1f37807cfe47ce98", "asset_id": "81647294538046680798858716589766492074338758116170717123345952330712416337530", "price": "0.997", "size": "359.19", "side": "SELL", "timestamp": "1768475145000", "received_at": "2026-01-15T12:05:45.143537"}}
{"event_type": "price_change", "event_ts": "2026-01-15T12:05:45.143635", "ingestion_ts": "2026-01-15T12:08:42.168746", "market_id": "0xc0e6b917320a47228fb96e3b5ae0e5c93773a5ae2662ae4e1f37807cfe47ce98", "raw": {"market": "0xc0e6b917320a47228fb96e3b5ae0e5c93773a5ae2662ae4e1f37807cfe47ce98", "asset_id": "58656358377246279051017109359677190749228949103591068167284263961542487110215", "price": "0.003", "size": "359.19", "side": "BUY", "timestamp": "1768475145001", "received_at": "2026-01-15T12:05:45.143635"}}
{"event_type": "price_change", "event_ts": "2026-01-15T12:05:45.143635", "ingestion_ts": "2026-01-15T12:08:42.168746", "market_id": "0xc0e6b917320a47228fb96e3b5ae0e5c93773a5ae2662ae4e1f37807cfe47ce98", "raw": {"market": "0xc0e6b917320a47228fb96e3b5ae0e5c93773a5ae2662ae4e1f37807cfe47ce98", "asset_id": "81647294538046680798858716589766492074338758116170717123345952330712416337530", "price": "0.997", "size": "359.19", "side": "SELL", "timestamp": "1768475145001", "received_at": "2026-01-15T12:05:45.143635"}}
{"event_type": "price_change", "event_ts": "2026-01-15T12:05:45.343144", "ingestion_ts": "2026-01-15T12:08:42.168746", "market_id": "0xc0e6b917320a47228fb96e3b5ae0e5c93773a5ae2662ae4e1f37807cfe47ce98", "raw": {"market": "0xc0e6b917320a47228fb96e3b5ae0e5c93773a5ae2662ae4e1f37807cfe47ce98", "asset_id": "58656358377246279051017109359677190749228949103591068167284263961542487110215", "price": "0.005", "size": "2.98", "side": "BUY", "timestamp": "1768475145217", "received_at": "2026-01-15T12:05:45.343144"}}
{"event_type": "price_change", "event_ts": "2026-01-15T12:05:45.343144", "ingestion_ts": "2026-01-15T12:08:42.168746", "market_id": "0xc0e6b917320a47228fb96e3b5ae0e5c93773a5ae2662ae4e1f37807cfe47ce98", "raw": {"market": "0xc0e6b917320a47228fb96e3b5ae0e5c93773a5ae2662ae4e1f37807cfe47ce98", "asset_id": "81647294538046680798858716589766492074338758116170717123345952330712416337530", "price": "0.995", "size": "2.98", "side": "SELL", "timestamp": "1768475145217", "received_at": "2026-01-15T12:05:45.343144"}}
{"event_type": "price_change", "event_ts": "2026-01-15T12:05:45.343235", "ingestion_ts": "2026-01-15T12:08:42.168746", "market_id": "0xc0e6b917320a47228fb96e3b5ae0e5c93773a5ae2662ae4e1f37807cfe47ce98", "raw": {"market": "0xc0e6b917320a47228fb96e3b5ae0e5c93773a5ae2662ae4e1f37807cfe47ce98", "asset_id": "58656358377246279051017109359677190749228949103591068167284263961542487110215", "price": "0.013", "size": "10", "side": "BUY", "timestamp": "1768475145217", "received_at": "2026-01-15T12:05:45.343235"}}
{"event_type": "price_change", "event_ts": "2026-01-15T12:05:45.343235", "ingestion_ts": "2026-01-15T12:08:42.168746", "market_id": "0xc0e6b917320a47228fb96e3b5ae0e5c93773a5ae2662ae4e1f37807cfe47ce98", "raw": {"market": "0xc0e6b917320a47228fb96e3b5ae0e5c93773a5ae2662ae4e1f37807cfe47ce98", "asset_id": "81647294538046680798858716589766492074338758116170717123345952330712416337530", "price": "0.987", "size": "10", "side": "SELL", "timestamp": "1768475145217", "received_at": "2026-01-15T12:05:45.343235"}}
{"event_type": "price_change", "event_ts": "2026-01-15T12:05:45.344882", "ingestion_ts": "2026-01-15T12:08:42.168746", "market_id": "0xcab7ba4a9133cfd407d7e73e5757e5abbace413b59421527a31113406c97815c", "raw": {"market": "0xcab7ba4a9133cfd407d7e73e5757e5abbace413b59421527a31113406c97815c", "asset_id": "96361925776989336186111887920533578209326565663637092688733016597062311745569", "price": "0.006", "size": "127.41", "side": "BUY", "timestamp": "1768475145218", "received_at": "2026-01-15T12:05:45.344882"}}
{"event_type": "price_change", "event_ts": "2026-01-15T12:05:45.344882", "ingestion_ts": "2026-01-15T12:08:42.168746", "market_id": "0xcab7ba4a9133cfd407d7e73e5757e5abbace413b59421527a31113406c97815c", "raw": {"market": "0xcab7ba4a9133cfd407d7e73e5757e5abbace413b59421527a31113406c97815c", "asset_id": "20002636398944597965698652220992177552927816915094913583821579024925426590022", "price": "0.994", "size": "127.41", "side": "SELL", "timestamp": "1768475145218", "received_at": "2026-01-15T12:05:45.344882"}}
{"event_type": "price_change", "event_ts": "2026-01-15T12:05:45.344957", "ingestion_ts": "2026-01-15T12:08:42.168746", "market_id": "0xcab7ba4a9133cfd407d7e73e5757e5abbace413b59421527a31113406c97815c", "raw": {"market": "0xcab7ba4a9133cfd407d7e73e5757e5abbace413b59421527a31113406c97815c", "asset_id": "96361925776989336186111887920533578209326565663637092688733016597062311745569", "price": "0.007", "size": "194.26", "side": "BUY", "timestamp": "1768475145218", "received_at": "2026-01-15T12:05:45.344957"}}
{"event_type": "price_change", "event_ts": "2026-01-15T12:05:45.344957", "ingestion_ts": "2026-01-15T12:08:42.168746", "market_id": "0xcab7ba4a9133cfd407d7e73e5757e5abbace413b59421527a31113406c97815c", "raw": {"market": "0xcab7ba4a9133cfd407d7e73e5757e5abbace413b59421527a31113406c97815c", "asset_id": "20002636398944597965698652220992177552927816915094913583821579024925426590022", "price": "0.993", "size": "194.26", "side": "SELL", "timestamp": "1768475145218", "received_at": "2026-01-15T12:05:45.344957"}}
{"event_type": "price_change", "event_ts": "2026-01-15T12:05:45.345126", "ingestion_ts": "2026-01-15T12:08:42.168746", "market_id": "0xcab7ba4a9133cfd407d7e73e5757e5abbace413b59421527a31113406c97815c", "raw": {"market": "0xcab7ba4a9133cfd407d7e73e5757e5abbace413b59421527a31113406c97815c", "asset_id": "96361925776989336186111887920533578209326565663637092688733016597062311745569", "price": "0.008", "size": "619.71", "side": "BUY", "timestamp": "1768475145218", "received_at": "2026-01-15T12:05:45.345126"}}
{"event_type": "price_change", "event_ts": "2026-01-15T12:05:45.345126", "ingestion_ts": "2026-01-15T12:08:42.168746", "market_id": "0xcab7ba4a9133cfd407d7e73e5757e5abbace413b59421527a31113406c97815c", "raw": {"market": "0xcab7ba4a9133cfd407d7e73e5757e5abbace413b59421527a31113406c97815c", "asset_id": "20002636398944597965698652220992177552927816915094913583821579024925426590022", "price": "0.992", "size": "619.71", "side": "SELL", "timestamp": "1768475145218", "received_at": "2026-01-15T12:05:45.345126"}}
{"event_type": "price_change", "event_ts": "2026-01-15T12:05:46.145802", "ingestion_ts": "2026-01-15T12:08:42.168746", "market_id": "0xc0e6b917320a47228fb96e3b5ae0e5c93773a5ae2662ae4e1f37807cfe47ce98", "raw": {"market": "0xc0e6b917320a47228fb96e3b5ae0e5c93773a5ae2662ae4e1f37807cfe47ce98", "asset_id": "58656358377246279051017109359677190749228949103591068167284263961542487110215", "price": "0.014", "size": "17.16", "side": "BUY", "timestamp": "1768475145998", "received_at": "2026-01-15T12:05:46.145802"}}
{"event_type": "price_change", "event_ts": "2026-01-15T12:05:46.145802", "ingestion_ts": "2026-01-15T12:08:42.168746", "market_id": "0xc0e6b917320a47228fb96e3b5ae0e5c93773a5ae2662ae4e1f37807cfe47ce98", "raw": {"market": "0xc0e6b917320a47228fb96e3b5ae0e5c93773a5ae2662ae4e1f37807cfe47ce98", "asset_id": "81647294538046680798858716589766492074338758116170717123345952330712416337530", "price": "0.986", "size": "17.16", "side": "SELL", "timestamp": "1768475145998", "received_at": "2026-01-15T12:05:46.145802"}}
{"event_type": "price_change", "event_ts": "2026-01-15T12:05:46.146127", "ingestion_ts": "2026-01-15T12:08:42.168746", "market_id": "0xcab7ba4a9133cfd407d7e73e5757e5abbace413b59421527a31113406c97815c", "raw": {"market": "0xcab7ba4a9133cfd407d7e73e5757e5abbace413b59421527a31113406c97815c", "asset_id": "96361925776989336186111887920533578209326565663637092688733016597062311745569", "price": "0.006", "size": "133.12", "side": "BUY", "timestamp": "1768475145998", "received_at": "2026-01-15T12:05:46.146127"}}
{"event_type": "price_change", "event_ts": "2026-01-15T12:05:46.146127", "ingestion_ts": "2026-01-15T12:08:42.168746", "market_id": "0xcab7ba4a9133cfd407d7e73e5757e5abbace413b59421527a31113406c97815c", "raw": {"market": "0xcab7ba4a9133cfd407d7e73e5757e5abbace413b59421527a31113406c97815c", "asset_id": "20002636398944597965698652220992177552927816915094913583821579024925426590022", "price": "0.994", "size": "133.12", "side": "SELL", "timestamp": "1768475145998", "received_at": "2026-01-15T12:05:46.146127"}}
{"event_type": "price_change", "event_ts": "2026-01-15T12:05:46.146190", "ingestion_ts": "2026-01-15T12:08:42.168746", "market_id": "0xc0e6b917320a47228fb96e3b5ae0e5c93773a5ae2662ae4e1f37807cfe47ce98", "raw": {"market": "0xc0e6b917320a47228fb96e3b5ae0e5c93773a5ae2662ae4e1f37807cfe47ce98", "asset_id": "58656358377246279051017109359677190749228949103591068167284263961542487110215", "price": "0.006", "size": "11.61", "side": "BUY", "timestamp": "1768475145999", "received_at": "2026-01-15T12:05:46.146190"}}
{"event_type": "price_change", "event_ts": "2026-01-15T12:05:46.146190", "ingestion_ts": "2026-01-15T12:08:42.168746", "market_id": "0xc0e6b917320a47228fb96e3b5ae0e5c93773a5ae2662ae4e1f37807cfe47ce98", "raw": {"market": "0xc0e6b917320a47228fb96e3b5ae0e5c93773a5ae2662ae4e1f37807cfe47ce98", "asset_id": "81647294538046680798858716589766492074338758116170717123345952330712416337530", "price": "0.994", "size": "11.61", "side": "SELL", "timestamp": "1768475145999", "received_at": "2026-01-15T12:05:46.146190"}}
{"event_type": "price_change", "event_ts": "2026-01-15T12:05:46.146233", "ingestion_ts": "2026-01-15T12:08:42.168746", "market_id": "0xcab7ba4a9133cfd407d7e73e5757e5abbace413b59421527a31113406c97815c", "raw": {"market": "0xcab7ba4a9133cfd407d7e73e5757e5abbace413b59421527a31113406c97815c", "asset_id": "96361925776989336186111887920533578209326565663637092688733016597062311745569", "price": "0.007", "size": "200.44", "side": "BUY", "timestamp": "1768475146000", "received_at": "2026-01-15T12:05:46.146233"}}
{"event_type": "price_change", "event_ts": "2026-01-15T12:05:46.146233", "ingestion_ts": "2026-01-15T12:08:42.168746", "market_id": "0xcab7ba4a9133cfd407d7e73e5757e5abbace413b59421527a31113406c97815c", "raw": {"market": "0xcab7ba4a9133cfd407d7e73e5757e5abbace413b59421527a31113406c97815c", "asset_id": "20002636398944597965698652220992177552927816915094913583821579024925426590022", "price": "0.993", "size": "200.44", "side": "SELL", "timestamp": "1768475146000", "received_at": "2026-01-15T12:05:46.146233"}}
{"event_type": "price_change", "event_ts": "2026-01-15T12:05:46.153886", "ingestion_ts": "2026-01-15T12:08:42.168746", "market_id": "0xc0e6b917320a47228fb96e3b5ae0e5c93773a5ae2662ae4e1f37807cfe47ce98", "raw": {"market": "0xc0e6b917320a47228fb96e3b5ae0e5c93773a5ae2662ae4e1f37807cfe47ce98", "asset_id": "58656358377246279051017109359677190749228949103591068167284263961542487110215", "price": "0.003", "size": "409.15", "side": "BUY", "timestamp": "1768475146001", "received_at": "2026-01-15T12:05:46.153886"}}
{"event_type": "price_change", "event_ts": "2026-01-15T12:05:46.153886", "ingestion_ts": "2026-01-15T12:08:42.168746", "market_id": "0xc0e6b917320a47228fb96e3b5ae0e5c93773a5ae2662ae4e1f37807cfe47ce98", "raw": {"market": "0xc0e6b917320a47228fb96e3b5ae0e5c93773a5ae2662ae4e1f37807cfe47ce98", "asset_id": "81647294538046680798858716589766492074338758116170717123345952330712416337530", "price": "0.997", "size": "409.15", "side": "SELL", "timestamp": "1768475146001", "received_at": "2026-01-15T12:05:46.153886"}}
{"event_type": "price_change", "event_ts": "2026-01-15T12:05:46.160509", "ingestion_ts": "2026-01-15T12:08:42.168746", "market_id": "0xcab7ba4a9133cfd407d7e73e5757e5abbace413b59421527a31113406c97815c", "raw": {"market": "0xcab7ba4a9133cfd407d7e73e5757e5abbace413b59421527a31113406c97815c", "asset_id": "96361925776989336186111887920533578209326565663637092688733016597062311745569", "price": "0.007", "size": "206.62", "side": "BUY", "timestamp": "1768475146003", "received_at": "2026-01-15T12:05:46.160509"}}
{"event_type": "price_change", "event_ts": "2026-01-15T12:05:46.160509", "ingestion_ts": "2026-01-15T12:08:42.168746", "market_id": "0xcab7ba4a9133cfd407d7e73e5757e5abbace413b59421527a31113406c97815c", "raw": {"market": "0xcab7ba4a9133cfd407d7e73e5757e5abbace413b59421527a31113406c97815c", "asset_id": "20002636398944597965698652220992177552927816915094913583821579024925426590022", "price": "0.993", "size": "206.62", "side": "SELL", "timestamp": "1768475146003", "received_at": "2026-01-15T12:05:46.160509"}}
{"event_type": "price_change", "event_ts": "2026-01-15T12:05:46.163304", "ingestion_ts": "2026-01-15T12:08:42.168746", "market_id": "0xcab7ba4a9133cfd407d7e73e5757e5abbace413b59421527a31113406c97815c", "raw": {"market": "0xcab7ba4a9133cfd407d7e73e5757e5abbace413b59421527a31113406c97815c", "asset_id": "96361925776989336186111887920533578209326565663637092688733016597062311745569", "price": "0.008", "size": "627.68", "side": "BUY", "timestamp": "1768475146004", "received_at": "2026-01-15T12:05:46.163304"}}
{"event_type": "price_change", "event_ts": "2026-01-15T12:05:46.163304", "ingestion_ts": "2026-01-15T12:08:42.168746", "market_id": "0xcab7ba4a9133cfd407d7e73e5757e5abbace413b59421527a31113406c97815c", "raw": {"market": "0xcab7ba4a9133cfd407d7e73e5757e5abbace413b59421527a31113406c97815c", "asset_id": "20002636398944597965698652220992177552927816915094913583821579024925426590022", "price": "0.992", "size": "627.68", "side": "SELL", "timestamp": "1768475146004", "received_at": "2026-01-15T12:05:46.163304"}}
{"event_type": "price_change", "event_ts": "2026-01-15T12:05:48.118285", "ingestion_ts": "2026-01-15T12:08:42.168746", "market_id": "0xcab7ba4a9133cfd407d7e73e5757e5abbace413b59421527a31113406c97815c", "raw": {"market": "0xcab7ba4a9133cfd407d7e73e5757e5abbace413b59421527a31113406c97815c", "asset_id": "96361925776989336186111887920533578209326565663637092688733016597062311745569", "price": "0.006", "size": "127.41", "side": "BUY", "timestamp": "1768475147979", "received_at": "2026-01-15T12:05:48.118285"}}
{"event_type": "price_change", "event_ts": "2026-01-15T12:05:48.118285", "ingestion_ts": "2026-01-15T12:08:42.168746", "market_id": "0xcab7ba4a9133cfd407d7e73e5757e5abbace413b59421527a31113406c97815c", "raw": {"market": "0xcab7ba4a9133cfd407d7e73e5757e5abbace413b59421527a31113406c97815c", "asset_id": "20002636398944597965698652220992177552927816915094913583821579024925426590022", "price": "0.994", "size": "127.41", "side": "SELL", "timestamp": "1768475147979", "received_at": "2026-01-15T12:05:48.118285"}}
{"event_type": "price_change", "event_ts": "2026-01-15T12:05:48.118326", "ingestion_ts": "2026-01-15T12:08:42.168746", "market_id": "0xcab7ba4a9133cfd407d7e73e5757e5abbace413b59421527a31113406c97815c", "raw": {"market": "0xcab7ba4a9133cfd407d7e73e5757e5abbace413b59421527a31113406c97815c", "asset_id": "96361925776989336186111887920533578209326565663637092688733016597062311745569", "price": "0.007", "size": "200.44", "side": "BUY", "timestamp": "1768475147979", "received_at": "2026-01-15T12:05:48.118326"}}
{"event_type": "price_change", "event_ts": "2026-01-15T12:05:48.118326", "ingestion_ts": "2026-01-15T12:08:42.168746", "market_id": "0xcab7ba4a9133cfd407d7e73e5757e5abbace413b59421527a31113406c97815c", "raw": {"market": "0xcab7ba4a9133cfd407d7e73e5757e5abbace413b59421527a31113406c97815c", "asset_id": "20002636398944597965698652220992177552927816915094913583821579024925426590022", "price": "0.993", "size": "200.44", "side": "SELL", "timestamp": "1768475147979", "received_at": "2026-01-15T12:05:48.118326"}}
{"event_type": "price_change", "event_ts": "2026-01-15T12:05:48.118337", "ingestion_ts": "2026-01-15T12:08:42.168746", "market_id": "0xcab7ba4a9133cfd407d7e73e5757e5abbace413b59421527a31113406c97815c", "raw": {"market": "0xcab7ba4a9133cfd407d7e73e5757e5abbace413b59421527a31113406c97815c", "asset_id": "96361925776989336186111887920533578209326565663637092688733016597062311745569", "price": "0.008", "size": "619.71", "side": "BUY", "timestamp": "1768475147979", "received_at": "2026-01-15T12:05:48.118337"}}
{"event_type": "price_change", "event_ts": "2026-01-15T12:05:48.118337", "ingestion_ts": "2026-01-15T12:08:42.168746", "market_id": "0xcab7ba4a9133cfd407d7e73e5757e5abbace413b59421527a31113406c97815c", "raw": {"market": "0xcab7ba4a9133cfd407d7e73e5757e5abbace413b59421527a31113406c97815c", "asset_id": "20002636398944597965698652220992177552927816915094913583821579024925426590022", "price": "0.992", "size": "619.71", "side": "SELL", "timestamp": "1768475147979", "received_at": "2026-01-15T12:05:48.118337"}}
{"event_type": "price_change", "event_ts": "2026-01-15T12:05:48.575979", "ingestion_ts": "2026-01-15T12:08:42.168746", "market_id": "0xcab7ba4a9133cfd407d7e73e5757e5abbace413b59421527a31113406c97815c", "raw": {"market": "0xcab7ba4a9133cfd407d7e73e5757e5abbace413b59421527a31113406c97815c", "asset_id": "96361925776989336186111887920533578209326565663637092688733016597062311745569", "price": "0.008", "size": "625.45", "side": "BUY", "timestamp": "1768475148454", "received_at": "2026-01-15T12:05:48.575979"}}
{"event_type": "price_change", "event_ts": "2026-01-15T12:05:48.575979", "ingestion_ts": "2026-01-15T12:08:42.168746", "market_id": "0xcab7ba4a9133cfd407d7e73e5757e5abbace413b59421527a31113406c97815c", "raw": {"market": "0xcab7ba4a9133cfd407d7e73e5757e5abbace413b59421527a31113406c97815c", "asset_id": "20002636398944597965698652220992177552927816915094913583821579024925426590022", "price": "0.992", "size": "625.45", "side": "SELL", "timestamp": "1768475148454", "received_at": "2026-01-15T12:05:48.575979"}}
{"event_type": "price_change", "event_ts": "2026-01-15T12:05:48.576926", "ingestion_ts": "2026-01-15T12:08:42.168746", "market_id": "0xcab7ba4a9133cfd407d7e73e5757e5abbace413b59421527a31113406c97815c", "raw": {"market": "0xcab7ba4a9133cfd407d7e73e5757e5abbace413b59421527a31113406c97815c", "asset_id": "96361925776989336186111887920533578209326565663637092688733016597062311745569", "price": "0.006", "size": "135.65", "side": "BUY", "timestamp": "1768475148455", "received_at": "2026-01-15T12:05:48.576926"}}
{"event_type": "price_change", "event_ts": "2026-01-15T12:05:48.576926", "ingestion_ts": "2026-01-15T12:08:42.168746", "market_id": "0xcab7ba4a9133cfd407d7e73e5757e5abbace413b59421527a31113406c97815c", "raw": {"market": "0xcab7ba4a9133cfd407d7e73e5757e5abbace413b59421527a31113406c97815c", "asset_id": "20002636398944597965698652220992177552927816915094913583821579024925426590022", "price": "0.994", "size": "135.65", "side": "SELL", "timestamp": "1768475148455", "received_at": "2026-01-15T12:05:48.576926"}}
{"event_type": "price_change", "event_ts": "2026-01-15T12:05:48.576981", "ingestion_ts": "2026-01-15T12:08:42.168746", "market_id": "0xcab7ba4a9133cfd407d7e73e5757e5abbace413b59421527a31113406c97815c", "raw": {"market": "0xcab7ba4a9133cfd407d7e73e5757e5abbace413b59421527a31113406c97815c", "asset_id": "96361925776989336186111887920533578209326565663637092688733016597062311745569", "price": "0.008", "size": "631.19", "side": "BUY", "timestamp": "1768475148457", "received_at": "2026-01-15T12:05:48.576981"}}
{"event_type": "price_change", "event_ts": "2026-01-15T12:05:48.576981", "ingestion_ts": "2026-01-15T12:08:42.168746", "market_id": "0xcab7ba4a9133cfd407d7e73e5757e5abbace413b59421527a31113406c97815c", "raw": {"market": "0xcab7ba4a9133cfd407d7e73e5757e5abbace413b59421527a31113406c97815c", "asset_id": "20002636398944597965698652220992177552927816915094913583821579024925426590022", "price": "0.992", "size": "631.19", "side": "SELL", "timestamp": "1768475148457", "received_at": "2026-01-15T12:05:48.576981"}}
{"event_type": "price_change", "event_ts": "2026-01-15T12:05:48.754640", "ingestion_ts": "2026-01-15T12:08:42.168746", "market_id": "0xc0e6b917320a47228fb96e3b5ae0e5c93773a5ae2662ae4e1f37807cfe47ce98", "raw": {"market": "0xc0e6b917320a47228fb96e3b5ae0e5c93773a5ae2662ae4e1f37807cfe47ce98", "asset_id": "58656358377246279051017109359677190749228949103591068167284263961542487110215", "price": "0.006", "size": "0", "side": "BUY", "timestamp": "1768475148627", "received_at": "2026-01-15T12:05:48.754640"}}
{"event_type": "price_change", "event_ts": "2026-01-15T12:05:48.754640", "ingestion_ts": "2026-01-15T12:08:42.168746", "market_id": "0xc0e6b917320a47228fb96e3b5ae0e5c93773a5ae2662ae4e1f37807cfe47ce98", "raw": {"market": "0xc0e6b917320a47228fb96e3b5ae0e5c93773a5ae2662ae4e1f37807cfe47ce98", "asset_id": "81647294538046680798858716589766492074338758116170717123345952330712416337530", "price": "0.994", "size": "0", "side": "SELL", "timestamp": "1768475148627", "received_at": "2026-01-15T12:05:48.754640"}}
{"event_type": "price_change", "event_ts": "2026-01-15T12:05:48.754875", "ingestion_ts": "2026-01-15T12:08:42.168746", "market_id": "0xc0e6b917320a47228fb96e3b5ae0e5c93773a5ae2662ae4e1f37807cfe47ce98", "raw": {"market": "0xc0e6b917320a47228fb96e3b5ae0e5c93773a5ae2662ae4e1f37807cfe47ce98", "asset_id": "58656358377246279051017109359677190749228949103591068167284263961542487110215", "price": "0.014", "size": "11.2", "side": "BUY", "timestamp": "1768475148627", "received_at": "2026-01-15T12:05:48.754875"}}
{"event_type": "price_change", "event_ts": "2026-01-15T12:05:48.754875", "ingestion_ts": "2026-01-15T12:08:42.168746", "market_id": "0xc0e6b917320a47228fb96e3b5ae0e5c93773a5ae2662ae4e1f37807cfe47ce98", "raw": {"market": "0xc0e6b917320a47228fb96e3b5ae0e5c93773a5ae2662ae4e1f37807cfe47ce98", "asset_id": "81647294538046680798858716589766492074338758116170717123345952330712416337530", "price": "0.986", "size": "11.2", "side": "SELL", "timestamp": "1768475148627", "received_at": "2026-01-15T12:05:48.754875"}}
{"event_type": "price_change", "event_ts": "2026-01-15T12:05:49.219226", "ingestion_ts": "2026-01-15T12:08:42.168746", "market_id": "0xc0e6b917320a47228fb96e3b5ae0e5c93773a5ae2662ae4e1f37807cfe47ce98", "raw": {"market": "0xc0e6b917320a47228fb96e3b5ae0e5c93773a5ae2662ae4e1f37807cfe47ce98", "asset_id": "58656358377246279051017109359677190749228949103591068167284263961542487110215", "price": "0.007", "size": "9.95", "side": "BUY", "timestamp": "1768475149097", "received_at": "2026-01-15T12:05:49.219226"}}
{"event_type": "price_change", "event_ts": "2026-01-15T12:05:49.219226", "ingestion_ts": "2026-01-15T12:08:42.168746", "market_id": "0xc0e6b917320a47228fb96e3b5ae0e5c93773a5ae2662ae4e1f37807cfe47ce98", "raw": {"market": "0xc0e6b917320a47228fb96e3b5ae0e5c93773a5ae2662ae4e1f37807cfe47ce98", "asset_id": "81647294538046680798858716589766492074338758116170717123345952330712416337530", "price": "0.993", "size": "9.95", "side": "SELL", "timestamp": "1768475149097", "received_at": "2026-01-15T12:05:49.219226"}}
{"event_type": "price_change", "event_ts": "2026-01-15T12:05:49.220648", "ingestion_ts": "2026-01-15T12:08:42.168746", "market_id": "0xc0e6b917320a47228fb96e3b5ae0e5c93773a5ae2662ae4e1f37807cfe47ce98", "raw": {"market": "0xc0e6b917320a47228fb96e3b5ae0e5c93773a5ae2662ae4e1f37807cfe47ce98", "asset_id": "58656358377246279051017109359677190749228949103591068167284263961542487110215", "price": "0.015", "size": "50.55", "side": "BUY", "timestamp": "1768475149099", "received_at": "2026-01-15T12:05:49.220648"}}
{"event_type": "price_change", "event_ts": "2026-01-15T12:05:49.220648", "ingestion_ts": "2026-01-15T12:08:42.168746", "market_id": "0xc0e6b917320a47228fb96e3b5ae0e5c93773a5ae2662ae4e1f37807cfe47ce98", "raw": {"market": "0xc0e6b917320a47228fb96e3b5ae0e5c93773a5ae2662ae4e1f37807cfe47ce98", "asset_id": "81647294538046680798858716589766492074338758116170717123345952330712416337530", "price": "0.985", "size": "50.55", "side": "SELL", "timestamp": "1768475149099", "received_at": "2026-01-15T12:05:49.220648"}}
{"event_type": "price_change", "event_ts": "2026-01-15T12:05:50.219585", "ingestion_ts": "2026-01-15T12:08:42.168746", "market_id": "0xcab7ba4a9133cfd407d7e73e5757e5abbace413b59421527a31113406c97815c", "raw": {"market": "0xcab7ba4a9133cfd407d7e73e5757e5abbace413b59421527a31113406c97815c", "asset_id": "96361925776989336186111887920533578209326565663637092688733016597062311745569", "price": "0.006", "size": "127.41", "side": "BUY", "timestamp": "1768475150097", "received_at": "2026-01-15T12:05:50.219585"}}
{"event_type": "price_change", "event_ts": "2026-01-15T12:05:50.219585", "ingestion_ts": "2026-01-15T12:08:42.168746", "market_id": "0xcab7ba4a9133cfd407d7e73e5757e5abbace413b59421527a31113406c97815c", "raw": {"market": "0xcab7ba4a9133cfd407d7e73e5757e5abbace413b59421527a31113406c97815c", "asset_id": "20002636398944597965698652220992177552927816915094913583821579024925426590022", "price": "0.994", "size": "127.41", "side": "SELL", "timestamp": "1768475150097", "received_at": "2026-01-15T12:05:50.219585"}}
{"event_type": "price_change", "event_ts": "2026-01-15T12:05:50.219631", "ingestion_ts": "2026-01-15T12:08:42.168746", "market_id": "0xcab7ba4a9133cfd407d7e73e5757e5abbace413b59421527a31113406c97815c", "raw": {"market": "0xcab7ba4a9133cfd407d7e73e5757e5abbace413b59421527a31113406c97815c", "asset_id": "96361925776989336186111887920533578209326565663637092688733016597062311745569", "price": "0.008", "size": "625.45", "side": "BUY", "timestamp": "1768475150097", "received_at": "2026-01-15T12:05:50.219631"}}
{"event_type": "price_change", "event_ts": "2026-01-15T12:05:50.219631", "ingestion_ts": "2026-01-15T12:08:42.168746", "market_id": "0xcab7ba4a9133cfd407d7e73e5757e5abbace413b59421527a31113406c97815c", "raw": {"market": "0xcab7ba4a9133cfd407d7e73e5757e5abbace413b59421527a31113406c97815c", "asset_id": "20002636398944597965698652220992177552927816915094913583821579024925426590022", "price": "0.992", "size": "625.45", "side": "SELL", "timestamp": "1768475150097", "received_at": "2026-01-15T12:05:50.219631"}}
{"event_type": "price_change", "event_ts": "2026-01-15T12:05:50.616907", "ingestion_ts": "2026-01-15T12:08:42.168746", "market_id": "0xcab7ba4a9133cfd407d7e73e5757e5abbace413b59421527a31113406c97815c", "raw": {"market": "0xcab7ba4a9133cfd407d7e73e5757e5abbace413b59421527a31113406c97815c", "asset_id": "96361925776989336186111887920533578209326565663637092688733016597062311745569", "price": "0.006", "size": "135.36", "side": "BUY", "timestamp": "1768475150471", "received_at": "2026-01-15T12:05:50.616907"}}
{"event_type": "price_change", "event_ts": "2026-01-15T12:05:50.616907", "ingestion_ts": "2026-01-15T12:08:42.168746", "market_id": "0xcab7ba4a9133cfd407d7e73e5757e5abbace413b59421527a31113406c97815c", "raw": {"market": "0xcab7ba4a9133cfd407d7e73e5757e5abbace413b59421527a31113406c97815c", "asset_id": "20002636398944597965698652220992177552927816915094913583821579024925426590022", "price": "0.994", "size": "135.36", "side": "SELL", "timestamp": "1768475150471", "received_at": "2026-01-15T12:05:50.616907"}}
{"event_type": "price_change", "event_ts": "2026-01-15T12:05:50.635478", "ingestion_ts": "2026-01-15T12:08:42.168746", "market_id": "0xcab7ba4a9133cfd407d7e73e5757e5abbace413b59421527a31113406c97815c", "raw": {"market": "0xcab7ba4a9133cfd407d7e73e5757e5abbace413b59421527a31113406c97815c", "asset_id": "96361925776989336186111887920533578209326565663637092688733016597062311745569", "price": "0.006", "size": "143.31", "side": "BUY", "timestamp": "1768475150476", "received_at": "2026-01-15T12:05:50.635478"}}
{"event_type": "price_change", "event_ts": "2026-01-15T12:05:50.635478", "ingestion_ts": "2026-01-15T12:08:42.168746", "market_id": "0xcab7ba4a9133cfd407d7e73e5757e5abbace413b59421527a31113406c97815c", "raw": {"market": "0xcab7ba4a9133cfd407d7e73e5757e5abbace413b59421527a31113406c97815c", "asset_id": "20002636398944597965698652220992177552927816915094913583821579024925426590022", "price": "0.994", "size": "143.31", "side": "SELL", "timestamp": "1768475150476", "received_at": "2026-01-15T12:05:50.635478"}}
{"event_type": "price_change", "event_ts": "2026-01-15T12:05:52.726540", "ingestion_ts": "2026-01-15T12:08:42.168746", "market_id": "0xc0e6b917320a47228fb96e3b5ae0e5c93773a5ae2662ae4e1f37807cfe47ce98", "raw": {"market": "0xc0e6b917320a47228fb96e3b5ae0e5c93773a5ae2662ae4e1f37807cfe47ce98", "asset_id": "58656358377246279051017109359677190749228949103591068167284263961542487110215", "price": "0.007", "size": "0", "side": "BUY", "timestamp": "1768475152601", "received_at": "2026-01-15T12:05:52.726540"}}
{"event_type": "price_change", "event_ts": "2026-01-15T12:05:52.726540", "ingestion_ts": "2026-01-15T12:08:42.168746", "market_id": "0xc0e6b917320a47228fb96e3b5ae0e5c93773a5ae2662ae4e1f37807cfe47ce98", "raw": {"market": "0xc0e6b917320a47228fb96e3b5ae0e5c93773a5ae2662ae4e1f37807cfe47ce98", "asset_id": "81647294538046680798858716589766492074338758116170717123345952330712416337530", "price": "0.993", "size": "0", "side": "SELL", "timestamp": "1768475152601", "received_at": "2026-01-15T12:05:52.726540"}}
{"event_type": "price_change", "event_ts": "2026-01-15T12:05:52.726578", "ingestion_ts": "2026-01-15T12:08:42.168746", "market_id": "0xc0e6b917320a47228fb96e3b5ae0e5c93773a5ae2662ae4e1f37807cfe47ce98", "raw": {"market": "0xc0e6b917320a47228fb96e3b5ae0e5c93773a5ae2662ae4e1f37807cfe47ce98", "asset_id": "58656358377246279051017109359677190749228949103591068167284263961542487110215", "price": "0.015", "size": "44.99", "side": "BUY", "timestamp": "1768475152601", "received_at": "2026-01-15T12:05:52.726578"}}
{"event_type": "price_change", "event_ts": "2026-01-15T12:05:52.726578", "ingestion_ts": "2026-01-15T12:08:42.168746", "market_id": "0xc0e6b917320a47228fb96e3b5ae0e5c93773a5ae2662ae4e1f37807cfe47ce98", "raw": {"market": "0xc0e6b917320a47228fb96e3b5ae0e5c93773a5ae2662ae4e1f37807cfe47ce98", "asset_id": "81647294538046680798858716589766492074338758116170717123345952330712416337530", "price": "0.985", "size": "44.99", "side": "SELL", "timestamp": "1768475152601", "received_at": "2026-01-15T12:05:52.726578"}}
{"event_type": "price_change", "event_ts": "2026-01-15T12:05:53.293368", "ingestion_ts": "2026-01-15T12:08:42.168746", "market_id": "0xc0e6b917320a47228fb96e3b5ae0e5c93773a5ae2662ae4e1f37807cfe47ce98", "raw": {"market": "0xc0e6b917320a47228fb96e3b5ae0e5c93773a5ae2662ae4e1f37807cfe47ce98", "asset_id": "58656358377246279051017109359677190749228949103591068167284263961542487110215", "price": "0.008", "size": "12.04", "side": "BUY", "timestamp": "1768475153169", "received_at": "2026-01-15T12:05:53.293368"}}
{"event_type": "price_change", "event_ts": "2026-01-15T12:05:53.293368", "ingestion_ts": "2026-01-15T12:08:42.168746", "market_id": "0xc0e6b917320a47228fb96e3b5ae0e5c93773a5ae2662ae4e1f37807cfe47ce98", "raw": {"market": "0xc0e6b917320a47228fb96e3b5ae0e5c93773a5ae2662ae4e1f37807cfe47ce98", "asset_id": "81647294538046680798858716589766492074338758116170717123345952330712416337530", "price": "0.992", "size": "12.04", "side": "SELL", "timestamp": "1768475153169", "received_at": "2026-01-15T12:05:53.293368"}}
{"event_type": "price_change", "event_ts": "2026-01-15T12:05:53.293510", "ingestion_ts": "2026-01-15T12:08:42.168746", "market_id": "0xc0e6b917320a47228fb96e3b5ae0e5c93773a5ae2662ae4e1f37807cfe47ce98", "raw": {"market": "0xc0e6b917320a47228fb96e3b5ae0e5c93773a5ae2662ae4e1f37807cfe47ce98", "asset_id": "58656358377246279051017109359677190749228949103591068167284263961542487110215", "price": "0.003", "size": "428.09", "side": "BUY", "timestamp": "1768475153170", "received_at": "2026-01-15T12:05:53.293510"}}
{"event_type": "price_change", "event_ts": "2026-01-15T12:05:53.293510", "ingestion_ts": "2026-01-15T12:08:42.168746", "market_id": "0xc0e6b917320a47228fb96e3b5ae0e5c93773a5ae2662ae4e1f37807cfe47ce98", "raw": {"market": "0xc0e6b917320a47228fb96e3b5ae0e5c93773a5ae2662ae4e1f37807cfe47ce98", "asset_id": "81647294538046680798858716589766492074338758116170717123345952330712416337530", "price": "0.997", "size": "428.09", "side": "SELL", "timestamp": "1768475153170", "received_at": "2026-01-15T12:05:53.293510"}}
{"event_type": "price_change", "event_ts": "2026-01-15T12:05:54.235441", "ingestion_ts": "2026-01-15T12:08:42.168746", "market_id": "0xcab7ba4a9133cfd407d7e73e5757e5abbace413b59421527a31113406c97815c", "raw": {"market": "0xcab7ba4a9133cfd407d7e73e5757e5abbace413b59421527a31113406c97815c", "asset_id": "96361925776989336186111887920533578209326565663637092688733016597062311745569", "price": "0.006", "size": "135.36", "side": "BUY", "timestamp": "1768475154113", "received_at": "2026-01-15T12:05:54.235441"}}
{"event_type": "price_change", "event_ts": "2026-01-15T12:05:54.235441", "ingestion_ts": "2026-01-15T12:08:42.168746", "market_id": "0xcab7ba4a9133cfd407d7e73e5757e5abbace413b59421527a31113406c97815c", "raw": {"market": "0xcab7ba4a9133cfd407d7e73e5757e5abbace413b59421527a31113406c97815c", "asset_id": "20002636398944597965698652220992177552927816915094913583821579024925426590022", "price": "0.994", "size": "135.36", "side": "SELL", "timestamp": "1768475154113", "received_at": "2026-01-15T12:05:54.235441"}}
{"event_type": "price_change", "event_ts": "2026-01-15T12:05:54.571086", "ingestion_ts": "2026-01-15T12:08:42.168746", "market_id": "0xcab7ba4a9133cfd407d7e73e5757e5abbace413b59421527a31113406c97815c", "raw": {"market": "0xcab7ba4a9133cfd407d7e73e5757e5abbace413b59421527a31113406c97815c", "asset_id": "96361925776989336186111887920533578209326565663637092688733016597062311745569", "price": "0.009", "size": "819.1", "side": "BUY", "timestamp": "1768475154451", "received_at": "2026-01-15T12:05:54.571086"}}
{"event_type": "price_change", "event_ts": "2026-01-15T12:05:54.571086", "ingestion_ts": "2026-01-15T12:08:42.168746", "market_id": "0xcab7ba4a9133cfd407d7e73e5757e5abbace413b59421527a31113406c97815c", "raw": {"market": "0xcab7ba4a9133cfd407d7e73e5757e5abbace413b59421527a31113406c97815c", "asset_id": "20002636398944597965698652220992177552927816915094913583821579024925426590022", "price": "0.991", "size": "819.1", "side": "SELL", "timestamp": "1768475154451", "received_at": "2026-01-15T12:05:54.571086"}}
{"event_type": "price_change", "event_ts": "2026-01-15T12:05:56.773839", "ingestion_ts": "2026-01-15T12:08:42.168746", "market_id": "0xc0e6b917320a47228fb96e3b5ae0e5c93773a5ae2662ae4e1f37807cfe47ce98", "raw": {"market": "0xc0e6b917320a47228fb96e3b5ae0e5c93773a5ae2662ae4e1f37807cfe47ce98", "asset_id": "58656358377246279051017109359677190749228949103591068167284263961542487110215", "price": "0.008", "size": "0", "side": "BUY", "timestamp": "1768475156644", "received_at": "2026-01-15T12:05:56.773839"}}
{"event_type": "price_change", "event_ts": "2026-01-15T12:05:56.773839", "ingestion_ts": "2026-01-15T12:08:42.168746", "market_id": "0xc0e6b917320a47228fb96e3b5ae0e5c93773a5ae2662ae4e1f37807cfe47ce98", "raw": {"market": "0xc0e6b917320a47228fb96e3b5ae0e5c93773a5ae2662ae4e1f37807cfe47ce98", "asset_id": "81647294538046680798858716589766492074338758116170717123345952330712416337530", "price": "0.992", "size": "0", "side": "SELL", "timestamp": "1768475156644", "received_at": "2026-01-15T12:05:56.773839"}}
{"event_type": "price_change", "event_ts": "2026-01-15T12:05:56.773878", "ingestion_ts": "2026-01-15T12:08:42.168746", "market_id": "0xcab7ba4a9133cfd407d7e73e5757e5abbace413b59421527a31113406c97815c", "raw": {"market": "0xcab7ba4a9133cfd407d7e73e5757e5abbace413b59421527a31113406c97815c", "asset_id": "96361925776989336186111887920533578209326565663637092688733016597062311745569", "price": "0.006", "size": "127.41", "side": "BUY", "timestamp": "1768475156644", "received_at": "2026-01-15T12:05:56.773878"}}
{"event_type": "price_change", "event_ts": "2026-01-15T12:05:56.773878", "ingestion_ts": "2026-01-15T12:08:42.168746", "market_id": "0xcab7ba4a9133cfd407d7e73e5757e5abbace413b59421527a31113406c97815c", "raw": {"market": "0xcab7ba4a9133cfd407d7e73e5757e5abbace413b59421527a31113406c97815c", "asset_id": "20002636398944597965698652220992177552927816915094913583821579024925426590022", "price": "0.994", "size": "127.41", "side": "SELL", "timestamp": "1768475156644", "received_at": "2026-01-15T12:05:56.773878"}}
{"event_type": "price_change", "event_ts": "2026-01-15T12:05:56.773891", "ingestion_ts": "2026-01-15T12:08:42.168746", "market_id": "0xcab7ba4a9133cfd407d7e73e5757e5abbace413b59421527a31113406c97815c", "raw": {"market": "0xcab7ba4a9133cfd407d7e73e5757e5abbace413b59421527a31113406c97815c", "asset_id": "96361925776989336186111887920533578209326565663637092688733016597062311745569", "price": "0.009", "size": "812.25", "side": "BUY", "timestamp": "1768475156644", "received_at": "2026-01-15T12:05:56.773891"}}
{"event_type": "price_change", "event_ts": "2026-01-15T12:05:56.773891", "ingestion_ts": "2026-01-15T12:08:42.168746", "market_id": "0xcab7ba4a9133cfd407d7e73e5757e5abbace413b59421527a31113406c97815c", "raw": {"market": "0xcab7ba4a9133cfd407d7e73e5757e5abbace413b59421527a31113406c97815c", "asset_id": "20002636398944597965698652220992177552927816915094913583821579024925426590022", "price": "0.991", "size": "812.25", "side": "SELL", "timestamp": "1768475156644", "received_at": "2026-01-15T12:05:56.773891"}}
{"event_type": "price_change", "event_ts": "2026-01-15T12:05:57.180073", "ingestion_ts": "2026-01-15T12:08:42.168746", "market_id": "0xc0e6b917320a47228fb96e3b5ae0e5c93773a5ae2662ae4e1f37807cfe47ce98", "raw": {"market": "0xc0e6b917320a47228fb96e3b5ae0e5c93773a5ae2662ae4e1f37807cfe47ce98", "asset_id": "58656358377246279051017109359677190749228949103591068167284263961542487110215", "price": "0.009", "size": "10.7", "side": "BUY", "timestamp": "1768475157061", "received_at": "2026-01-15T12:05:57.180073"}}
{"event_type": "price_change", "event_ts": "2026-01-15T12:05:57.180073", "ingestion_ts": "2026-01-15T12:08:42.168746", "market_id": "0xc0e6b917320a47228fb96e3b5ae0e5c93773a5ae2662ae4e1f37807cfe47ce98", "raw": {"market": "0xc0e6b917320a47228fb96e3b5ae0e5c93773a5ae2662ae4e1f37807cfe47ce98", "asset_id": "81647294538046680798858716589766492074338758116170717123345952330712416337530", "price": "0.991", "size": "10.7", "side": "SELL", "timestamp": "1768475157061", "received_at": "2026-01-15T12:05:57.180073"}}
{"event_type": "price_change", "event_ts": "2026-01-15T12:05:57.397719", "ingestion_ts": "2026-01-15T12:08:42.168746", "market_id": "0xcab7ba4a9133cfd407d7e73e5757e5abbace413b59421527a31113406c97815c", "raw": {"market": "0xcab7ba4a9133cfd407d7e73e5757e5abbace413b59421527a31113406c97815c", "asset_id": "96361925776989336186111887920533578209326565663637092688733016597062311745569", "price": "0.006", "size": "136.51", "side": "BUY", "timestamp": "1768475157265", "received_at": "2026-01-15T12:05:57.397719"}}
{"event_type": "price_change", "event_ts": "2026-01-15T12:05:57.397719", "ingestion_ts": "2026-01-15T12:08:42.168746", "market_id": "0xcab7ba4a9133cfd407d7e73e5757e5abbace413b59421527a31113406c97815c", "raw": {"market": "0xcab7ba4a9133cfd407d7e73e5757e5abbace413b59421527a31113406c97815c", "asset_id": "20002636398944597965698652220992177552927816915094913583821579024925426590022", "price": "0.994", "size": "136.51", "side": "SELL", "timestamp": "1768475157265", "received_at": "2026-01-15T12:05:57.397719"}}
{"event_type": "price_change", "event_ts": "2026-01-15T12:05:57.397781", "ingestion_ts": "2026-01-15T12:08:42.168746", "market_id": "0xcab7ba4a9133cfd407d7e73e5757e5abbace413b59421527a31113406c97815c", "raw": {"market": "0xcab7ba4a9133cfd407d7e73e5757e5abbace413b59421527a31113406c97815c", "asset_id": "96361925776989336186111887920533578209326565663637092688733016597062311745569", "price": "0.009", "size": "818.33", "side": "BUY", "timestamp": "1768475157266", "received_at": "2026-01-15T12:05:57.397781"}}
{"event_type": "price_change", "event_ts": "2026-01-15T12:05:57.397781", "ingestion_ts": "2026-01-15T12:08:42.168746", "market_id": "0xcab7ba4a9133cfd407d7e73e5757e5abbace413b59421527a31113406c97815c", "raw": {"market": "0xcab7ba4a9133cfd407d7e73e5757e5abbace413b59421527a31113406c97815c", "asset_id": "20002636398944597965698652220992177552927816915094913583821579024925426590022", "price": "0.991", "size": "818.33", "side": "SELL", "timestamp": "1768475157266", "received_at": "2026-01-15T12:05:57.397781"}}
{"event_type": "price_change", "event_ts": "2026-01-15T12:05:58.121490", "ingestion_ts": "2026-01-15T12:08:42.168746", "market_id": "0xc0e6b917320a47228fb96e3b5ae0e5c93773a5ae2662ae4e1f37807cfe47ce98", "raw": {"market": "0xc0e6b917320a47228fb96e3b5ae0e5c93773a5ae2662ae4e1f37807cfe47ce98", "asset_id": "58656358377246279051017109359677190749228949103591068167284263961542487110215", "price": "0.003", "size": "417.33", "side": "BUY", "timestamp": "1768475158000", "received_at": "2026-01-15T12:05:58.121490"}}
{"event_type": "price_change", "event_ts": "2026-01-15T12:05:58.121490", "ingestion_ts": "2026-01-15T12:08:42.168746", "market_id": "0xc0e6b917320a47228fb96e3b5ae0e5c93773a5ae2662ae4e1f37807cfe47ce98", "raw": {"market": "0xc0e6b917320a47228fb96e3b5ae0e5c93773a5ae2662ae4e1f37807cfe47ce98", "asset_id": "81647294538046680798858716589766492074338758116170717123345952330712416337530", "price": "0.997", "size": "417.33", "side": "SELL", "timestamp": "1768475158000", "received_at": "2026-01-15T12:05:58.121490"}}
{"event_type": "price_change", "event_ts": "2026-01-15T12:05:58.127361", "ingestion_ts": "2026-01-15T12:08:42.168746", "market_id": "0xc0e6b917320a47228fb96e3b5ae0e5c93773a5ae2662ae4e1f37807cfe47ce98", "raw": {"market": "0xc0e6b917320a47228fb96e3b5ae0e5c93773a5ae2662ae4e1f37807cfe47ce98", "asset_id": "58656358377246279051017109359677190749228949103591068167284263961542487110215", "price": "0.003", "size": "417.33", "side": "BUY", "timestamp": "1768475158000", "received_at": "2026-01-15T12:05:58.127361"}}
{"event_type": "price_change", "event_ts": "2026-01-15T12:05:58.127361", "ingestion_ts": "2026-01-15T12:08:42.168746", "market_id": "0xc0e6b917320a47228fb96e3b5ae0e5c93773a5ae2662ae4e1f37807cfe47ce98", "raw": {"market": "0xc0e6b917320a47228fb96e3b5ae0e5c93773a5ae2662ae4e1f37807cfe47ce98", "asset_id": "81647294538046680798858716589766492074338758116170717123345952330712416337530", "price": "0.997", "size": "417.33", "side": "SELL", "timestamp": "1768475158000", "received_at": "2026-01-15T12:05:58.127361"}}
{"event_type": "price_change", "event_ts": "2026-01-15T12:05:59.595112", "ingestion_ts": "2026-01-15T12:08:42.168746", "market_id": "0xcab7ba4a9133cfd407d7e73e5757e5abbace413b59421527a31113406c97815c", "raw": {"market": "0xcab7ba4a9133cfd407d7e73e5757e5abbace413b59421527a31113406c97815c", "asset_id": "96361925776989336186111887920533578209326565663637092688733016597062311745569", "price": "0.006", "size": "127.41", "side": "BUY", "timestamp": "1768475159472", "received_at": "2026-01-15T12:05:59.595112"}}
{"event_type": "price_change", "event_ts": "2026-01-15T12:05:59.595112", "ingestion_ts": "2026-01-15T12:08:42.168746", "market_id": "0xcab7ba4a9133cfd407d7e73e5757e5abbace413b59421527a31113406c97815c", "raw": {"market": "0xcab7ba4a9133cfd407d7e73e5757e5abbace413b59421527a31113406c97815c", "asset_id": "20002636398944597965698652220992177552927816915094913583821579024925426590022", "price": "0.994", "size": "127.41", "side": "SELL", "timestamp": "1768475159472", "received_at": "2026-01-15T12:05:59.595112"}}
{"event_type": "price_change", "event_ts": "2026-01-15T12:05:59.595192", "ingestion_ts": "2026-01-15T12:08:42.168746", "market_id": "0xcab7ba4a9133cfd407d7e73e5757e5abbace413b59421527a31113406c97815c", "raw": {"market": "0xcab7ba4a9133cfd407d7e73e5757e5abbace413b59421527a31113406c97815c", "asset_id": "96361925776989336186111887920533578209326565663637092688733016597062311745569", "price": "0.009", "size": "812.25", "side": "BUY", "timestamp": "1768475159472", "received_at": "2026-01-15T12:05:59.595192"}}
{"event_type": "price_change", "event_ts": "2026-01-15T12:05:59.595192", "ingestion_ts": "2026-01-15T12:08:42.168746", "market_id": "0xcab7ba4a9133cfd407d7e73e5757e5abbace413b59421527a31113406c97815c", "raw": {"market": "0xcab7ba4a9133cfd407d7e73e5757e5abbace413b59421527a31113406c97815c", "asset_id": "20002636398944597965698652220992177552927816915094913583821579024925426590022", "price": "0.991", "size": "812.25", "side": "SELL", "timestamp": "1768475159472", "received_at": "2026-01-15T12:05:59.595192"}}
{"event_type": "price_change", "event_ts": "2026-01-15T12:06:00.050804", "ingestion_ts": "2026-01-15T12:08:42.168746", "market_id": "0xcab7ba4a9133cfd407d7e73e5757e5abbace413b59421527a31113406c97815c", "raw": {"market": "0xcab7ba4a9133cfd407d7e73e5757e5abbace413b59421527a31113406c97815c", "asset_id": "96361925776989336186111887920533578209326565663637092688733016597062311745569", "price": "0.006", "size": "136.51", "side": "BUY", "timestamp": "1768475159934", "received_at": "2026-01-15T12:06:00.050804"}}
{"event_type": "price_change", "event_ts": "2026-01-15T12:06:00.050804", "ingestion_ts": "2026-01-15T12:08:42.168746", "market_id": "0xcab7ba4a9133cfd407d7e73e5757e5abbace413b59421527a31113406c97815c", "raw": {"market": "0xcab7ba4a9133cfd407d7e73e5757e5abbace413b59421527a31113406c97815c", "asset_id": "20002636398944597965698652220992177552927816915094913583821579024925426590022", "price": "0.994", "size": "136.51", "side": "SELL", "timestamp": "1768475159934", "received_at": "2026-01-15T12:06:00.050804"}}
{"event_type": "price_change", "event_ts": "2026-01-15T12:06:00.059197", "ingestion_ts": "2026-01-15T12:08:42.168746", "market_id": "0xcab7ba4a9133cfd407d7e73e5757e5abbace413b59421527a31113406c97815c", "raw": {"market": "0xcab7ba4a9133cfd407d7e73e5757e5abbace413b59421527a31113406c97815c", "asset_id": "96361925776989336186111887920533578209326565663637092688733016597062311745569", "price": "0.009", "size": "818.33", "side": "BUY", "timestamp": "1768475159935", "received_at": "2026-01-15T12:06:00.059197"}}
{"event_type": "price_change", "event_ts": "2026-01-15T12:06:00.059197", "ingestion_ts": "2026-01-15T12:08:42.168746", "market_id": "0xcab7ba4a9133cfd407d7e73e5757e5abbace413b59421527a31113406c97815c", "raw": {"market": "0xcab7ba4a9133cfd407d7e73e5757e5abbace413b59421527a31113406c97815c", "asset_id": "20002636398944597965698652220992177552927816915094913583821579024925426590022", "price": "0.991", "size": "818.33", "side": "SELL", "timestamp": "1768475159935", "received_at": "2026-01-15T12:06:00.059197"}}
{"event_type": "price_change", "event_ts": "2026-01-15T12:06:01.071186", "ingestion_ts": "2026-01-15T12:08:42.168746", "market_id": "0xc0e6b917320a47228fb96e3b5ae0e5c93773a5ae2662ae4e1f37807cfe47ce98", "raw": {"market": "0xc0e6b917320a47228fb96e3b5ae0e5c93773a5ae2662ae4e1f37807cfe47ce98", "asset_id": "58656358377246279051017109359677190749228949103591068167284263961542487110215", "price": "0.009", "size": "0", "side": "BUY", "timestamp": "1768475160943", "received_at": "2026-01-15T12:06:01.071186"}}
{"event_type": "price_change", "event_ts": "2026-01-15T12:06:01.071186", "ingestion_ts": "2026-01-15T12:08:42.168746", "market_id": "0xc0e6b917320a47228fb96e3b5ae0e5c93773a5ae2662ae4e1f37807cfe47ce98", "raw": {"market": "0xc0e6b917320a47228fb96e3b5ae0e5c93773a5ae2662ae4e1f37807cfe47ce98", "asset_id": "81647294538046680798858716589766492074338758116170717123345952330712416337530", "price": "0.991", "size": "0", "side": "SELL", "timestamp": "1768475160943", "received_at": "2026-01-15T12:06:01.071186"}}
{"event_type": "price_change", "event_ts": "2026-01-15T12:06:01.940740", "ingestion_ts": "2026-01-15T12:08:42.168746", "market_id": "0xc0e6b917320a47228fb96e3b5ae0e5c93773a5ae2662ae4e1f37807cfe47ce98", "raw": {"market": "0xc0e6b917320a47228fb96e3b5ae0e5c93773a5ae2662ae4e1f37807cfe47ce98", "asset_id": "58656358377246279051017109359677190749228949103591068167284263961542487110215", "price": "0.01", "size": "12.86", "side": "BUY", "timestamp": "1768475161815", "received_at": "2026-01-15T12:06:01.940740"}}
{"event_type": "price_change", "event_ts": "2026-01-15T12:06:01.940740", "ingestion_ts": "2026-01-15T12:08:42.168746", "market_id": "0xc0e6b917320a47228fb96e3b5ae0e5c93773a5ae2662ae4e1f37807cfe47ce98", "raw": {"market": "0xc0e6b917320a47228fb96e3b5ae0e5c93773a5ae2662ae4e1f37807cfe47ce98", "asset_id": "81647294538046680798858716589766492074338758116170717123345952330712416337530", "price": "0.99", "size": "12.86", "side": "SELL", "timestamp": "1768475161815", "received_at": "2026-01-15T12:06:01.940740"}}
{"event_type": "price_change", "event_ts": "2026-01-15T12:06:02.381423", "ingestion_ts": "2026-01-15T12:08:42.168746", "market_id": "0xcab7ba4a9133cfd407d7e73e5757e5abbace413b59421527a31113406c97815c", "raw": {"market": "0xcab7ba4a9133cfd407d7e73e5757e5abbace413b59421527a31113406c97815c", "asset_id": "96361925776989336186111887920533578209326565663637092688733016597062311745569", "price": "0.006", "size": "127.41", "side": "BUY", "timestamp": "1768475162262", "received_at": "2026-01-15T12:06:02.381423"}}
{"event_type": "price_change", "event_ts": "2026-01-15T12:06:02.381423", "ingestion_ts": "2026-01-15T12:08:42.168746", "market_id": "0xcab7ba4a9133cfd407d7e73e5757e5abbace413b59421527a31113406c97815c", "raw": {"market": "0xcab7ba4a9133cfd407d7e73e5757e5abbace413b59421527a31113406c97815c", "asset_id": "20002636398944597965698652220992177552927816915094913583821579024925426590022", "price": "0.994", "size": "127.41", "side": "SELL", "timestamp": "1768475162262", "received_at": "2026-01-15T12:06:02.381423"}}
{"event_type": "price_change", "event_ts": "2026-01-15T12:06:02.381464", "ingestion_ts": "2026-01-15T12:08:42.168746", "market_id": "0xcab7ba4a9133cfd407d7e73e5757e5abbace413b59421527a31113406c97815c", "raw": {"market": "0xcab7ba4a9133cfd407d7e73e5757e5abbace413b59421527a31113406c97815c", "asset_id": "96361925776989336186111887920533578209326565663637092688733016597062311745569", "price": "0.009", "size": "812.25", "side": "BUY", "timestamp": "1768475162262", "received_at": "2026-01-15T12:06:02.381464"}}
{"event_type": "price_change", "event_ts": "2026-01-15T12:06:02.381464", "ingestion_ts": "2026-01-15T12:08:42.168746", "market_id": "0xcab7ba4a9133cfd407d7e73e5757e5abbace413b59421527a31113406c97815c", "raw": {"market": "0xcab7ba4a9133cfd407d7e73e5757e5abbace413b59421527a31113406c97815c", "asset_id": "20002636398944597965698652220992177552927816915094913583821579024925426590022", "price": "0.991", "size": "812.25", "side": "SELL", "timestamp": "1768475162262", "received_at": "2026-01-15T12:06:02.381464"}}
{"event_type": "price_change", "event_ts": "2026-01-15T12:06:02.900481", "ingestion_ts": "2026-01-15T12:08:42.168746", "market_id": "0xcab7ba4a9133cfd407d7e73e5757e5abbace413b59421527a31113406c97815c", "raw": {"market": "0xcab7ba4a9133cfd407d7e73e5757e5abbace413b59421527a31113406c97815c", "asset_id": "96361925776989336186111887920533578209326565663637092688733016597062311745569", "price": "0.009", "size": "818.33", "side": "BUY", "timestamp": "1768475162781", "received_at": "2026-01-15T12:06:02.900481"}}
{"event_type": "price_change", "event_ts": "2026-01-15T12:06:02.900481", "ingestion_ts": "2026-01-15T12:08:42.168746", "market_id": "0xcab7ba4a9133cfd407d7e73e5757e5abbace413b59421527a31113406c97815c", "raw": {"market": "0xcab7ba4a9133cfd407d7e73e5757e5abbace413b59421527a31113406c97815c", "asset_id": "20002636398944597965698652220992177552927816915094913583821579024925426590022", "price": "0.991", "size": "818.33", "side": "SELL", "timestamp": "1768475162781", "received_at": "2026-01-15T12:06:02.900481"}}
{"event_type": "price_change", "event_ts": "2026-01-15T12:06:02.901259", "ingestion_ts": "2026-01-15T12:08:42.168746", "market_id": "0xcab7ba4a9133cfd407d7e73e5757e5abbace413b59421527a31113406c97815c", "raw": {"market": "0xcab7ba4a9133cfd407d7e73e5757e5abbace413b59421527a31113406c97815c", "asset_id": "96361925776989336186111887920533578209326565663637092688733016597062311745569", "price": "0.006", "size": "136.51", "side": "BUY", "timestamp": "1768475162782", "received_at": "2026-01-15T12:06:02.901259"}}
{"event_type": "price_change", "event_ts": "2026-01-15T12:06:02.901259", "ingestion_ts": "2026-01-15T12:08:42.168746", "market_id": "0xcab7ba4a9133cfd407d7e73e5757e5abbace413b59421527a31113406c97815c", "raw": {"market": "0xcab7ba4a9133cfd407d7e73e5757e5abbace413b59421527a31113406c97815c", "asset_id": "20002636398944597965698652220992177552927816915094913583821579024925426590022", "price": "0.994", "size": "136.51", "side": "SELL", "timestamp": "1768475162782", "received_at": "2026-01-15T12:06:02.901259"}}
{"event_type": "price_change", "event_ts": "2026-01-15T12:06:03.784119", "ingestion_ts": "2026-01-15T12:08:42.168746", "market_id": "0xcab7ba4a9133cfd407d7e73e5757e5abbace413b59421527a31113406c97815c", "raw": {"market": "0xcab7ba4a9133cfd407d7e73e5757e5abbace413b59421527a31113406c97815c", "asset_id": "96361925776989336186111887920533578209326565663637092688733016597062311745569", "price": "0.006", "size": "127.41", "side": "BUY", "timestamp": "1768475163666", "received_at": "2026-01-15T12:06:03.784119"}}
{"event_type": "price_change", "event_ts": "2026-01-15T12:06:03.784119", "ingestion_ts": "2026-01-15T12:08:42.168746", "market_id": "0xcab7ba4a9133cfd407d7e73e5757e5abbace413b59421527a31113406c97815c", "raw": {"market": "0xcab7ba4a9133cfd407d7e73e5757e5abbace413b59421527a31113406c97815c", "asset_id": "20002636398944597965698652220992177552927816915094913583821579024925426590022", "price": "0.994", "size": "127.41", "side": "SELL", "timestamp": "1768475163666", "received_at": "2026-01-15T12:06:03.784119"}}
{"event_type": "price_change", "event_ts": "2026-01-15T12:06:03.785731", "ingestion_ts": "2026-01-15T12:08:42.168746", "market_id": "0xcab7ba4a9133cfd407d7e73e5757e5abbace413b59421527a31113406c97815c", "raw": {"market": "0xcab7ba4a9133cfd407d7e73e5757e5abbace413b59421527a31113406c97815c", "asset_id": "96361925776989336186111887920533578209326565663637092688733016597062311745569", "price": "0.009", "size": "812.25", "side": "BUY", "timestamp": "1768475163666", "received_at": "2026-01-15T12:06:03.785731"}}
{"event_type": "price_change", "event_ts": "2026-01-15T12:06:03.785731", "ingestion_ts": "2026-01-15T12:08:42.168746", "market_id": "0xcab7ba4a9133cfd407d7e73e5757e5abbace413b59421527a31113406c97815c", "raw": {"market": "0xcab7ba4a9133cfd407d7e73e5757e5abbace413b59421527a31113406c97815c", "asset_id": "20002636398944597965698652220992177552927816915094913583821579024925426590022", "price": "0.991", "size": "812.25", "side": "SELL", "timestamp": "1768475163666", "received_at": "2026-01-15T12:06:03.785731"}}
{"event_type": "price_change", "event_ts": "2026-01-15T12:06:04.356557", "ingestion_ts": "2026-01-15T12:08:42.168746", "market_id": "0xcab7ba4a9133cfd407d7e73e5757e5abbace413b59421527a31113406c97815c", "raw": {"market": "0xcab7ba4a9133cfd407d7e73e5757e5abbace413b59421527a31113406c97815c", "asset_id": "96361925776989336186111887920533578209326565663637092688733016597062311745569", "price": "0.009", "size": "818.33", "side": "BUY", "timestamp": "1768475164233", "received_at": "2026-01-15T12:06:04.356557"}}
{"event_type": "price_change", "event_ts": "2026-01-15T12:06:04.356557", "ingestion_ts": "2026-01-15T12:08:42.168746", "market_id": "0xcab7ba4a9133cfd407d7e73e5757e5abbace413b59421527a31113406c97815c", "raw": {"market": "0xcab7ba4a9133cfd407d7e73e5757e5abbace413b59421527a31113406c97815c", "asset_id": "20002636398944597965698652220992177552927816915094913583821579024925426590022", "price": "0.991", "size": "818.33", "side": "SELL", "timestamp": "1768475164233", "received_at": "2026-01-15T12:06:04.356557"}}
{"event_type": "price_change", "event_ts": "2026-01-15T12:06:04.357891", "ingestion_ts": "2026-01-15T12:08:42.168746", "market_id": "0xcab7ba4a9133cfd407d7e73e5757e5abbace413b59421527a31113406c97815c", "raw": {"market": "0xcab7ba4a9133cfd407d7e73e5757e5abbace413b59421527a31113406c97815c", "asset_id": "96361925776989336186111887920533578209326565663637092688733016597062311745569", "price": "0.006", "size": "136.51", "side": "BUY", "timestamp": "1768475164238", "received_at": "2026-01-15T12:06:04.357891"}}
{"event_type": "price_change", "event_ts": "2026-01-15T12:06:04.357891", "ingestion_ts": "2026-01-15T12:08:42.168746", "market_id": "0xcab7ba4a9133cfd407d7e73e5757e5abbace413b59421527a31113406c97815c", "raw": {"market": "0xcab7ba4a9133cfd407d7e73e5757e5abbace413b59421527a31113406c97815c", "asset_id": "20002636398944597965698652220992177552927816915094913583821579024925426590022", "price": "0.994", "size": "136.51", "side": "SELL", "timestamp": "1768475164238", "received_at": "2026-01-15T12:06:04.357891"}}
{"event_type": "price_change", "event_ts": "2026-01-15T12:06:04.570750", "ingestion_ts": "2026-01-15T12:08:42.168746", "market_id": "0xc0e6b917320a47228fb96e3b5ae0e5c93773a5ae2662ae4e1f37807cfe47ce98", "raw": {"market": "0xc0e6b917320a47228fb96e3b5ae0e5c93773a5ae2662ae4e1f37807cfe47ce98", "asset_id": "58656358377246279051017109359677190749228949103591068167284263961542487110215", "price": "0.01", "size": "0", "side": "BUY", "timestamp": "1768475164443", "received_at": "2026-01-15T12:06:04.570750"}}
{"event_type": "price_change", "event_ts": "2026-01-15T12:06:04.570750", "ingestion_ts": "2026-01-15T12:08:42.168746", "market_id": "0xc0e6b917320a47228fb96e3b5ae0e5c93773a5ae2662ae4e1f37807cfe47ce98", "raw": {"market": "0xc0e6b917320a47228fb96e3b5ae0e5c93773a5ae2662ae4e1f37807cfe47ce98", "asset_id": "81647294538046680798858716589766492074338758116170717123345952330712416337530", "price": "0.99", "size": "0", "side": "SELL", "timestamp": "1768475164443", "received_at": "2026-01-15T12:06:04.570750"}}
{"event_type": "price_change", "event_ts": "2026-01-15T12:06:05.007578", "ingestion_ts": "2026-01-15T12:08:42.168746", "market_id": "0xc0e6b917320a47228fb96e3b5ae0e5c93773a5ae2662ae4e1f37807cfe47ce98", "raw": {"market": "0xc0e6b917320a47228fb96e3b5ae0e5c93773a5ae2662ae4e1f37807cfe47ce98", "asset_id": "58656358377246279051017109359677190749228949103591068167284263961542487110215", "price": "0.011", "size": "11.69", "side": "BUY", "timestamp": "1768475164889", "received_at": "2026-01-15T12:06:05.007578"}}
{"event_type": "price_change", "event_ts": "2026-01-15T12:06:05.007578", "ingestion_ts": "2026-01-15T12:08:42.168746", "market_id": "0xc0e6b917320a47228fb96e3b5ae0e5c93773a5ae2662ae4e1f37807cfe47ce98", "raw": {"market": "0xc0e6b917320a47228fb96e3b5ae0e5c93773a5ae2662ae4e1f37807cfe47ce98", "asset_id": "81647294538046680798858716589766492074338758116170717123345952330712416337530", "price": "0.989", "size": "11.69", "side": "SELL", "timestamp": "1768475164889", "received_at": "2026-01-15T12:06:05.007578"}}
{"event_type": "price_change", "event_ts": "2026-01-15T12:06:07.195543", "ingestion_ts": "2026-01-15T12:08:42.168746", "market_id": "0xcab7ba4a9133cfd407d7e73e5757e5abbace413b59421527a31113406c97815c", "raw": {"market": "0xcab7ba4a9133cfd407d7e73e5757e5abbace413b59421527a31113406c97815c", "asset_id": "96361925776989336186111887920533578209326565663637092688733016597062311745569", "price": "0.006", "size": "127.41", "side": "BUY", "timestamp": "1768475167045", "received_at": "2026-01-15T12:06:07.195543"}}
{"event_type": "price_change", "event_ts": "2026-01-15T12:06:07.195543", "ingestion_ts": "2026-01-15T12:08:42.168746", "market_id": "0xcab7ba4a9133cfd407d7e73e5757e5abbace413b59421527a31113406c97815c", "raw": {"market": "0xcab7ba4a9133cfd407d7e73e5757e5abbace413b59421527a31113406c97815c", "asset_id": "20002636398944597965698652220992177552927816915094913583821579024925426590022", "price": "0.994", "size": "127.41", "side": "SELL", "timestamp": "1768475167045", "received_at": "2026-01-15T12:06:07.195543"}}
{"event_type": "price_change", "event_ts": "2026-01-15T12:06:07.195591", "ingestion_ts": "2026-01-15T12:08:42.168746", "market_id": "0xcab7ba4a9133cfd407d7e73e5757e5abbace413b59421527a31113406c97815c", "raw": {"market": "0xcab7ba4a9133cfd407d7e73e5757e5abbace413b59421527a31113406c97815c", "asset_id": "96361925776989336186111887920533578209326565663637092688733016597062311745569", "price": "0.009", "size": "812.25", "side": "BUY", "timestamp": "1768475167045", "received_at": "2026-01-15T12:06:07.195591"}}
{"event_type": "price_change", "event_ts": "2026-01-15T12:06:07.195591", "ingestion_ts": "2026-01-15T12:08:42.168746", "market_id": "0xcab7ba4a9133cfd407d7e73e5757e5abbace413b59421527a31113406c97815c", "raw": {"market": "0xcab7ba4a9133cfd407d7e73e5757e5abbace413b59421527a31113406c97815c", "asset_id": "20002636398944597965698652220992177552927816915094913583821579024925426590022", "price": "0.991", "size": "812.25", "side": "SELL", "timestamp": "1768475167045", "received_at": "2026-01-15T12:06:07.195591"}}
{"event_type": "price_change", "event_ts": "2026-01-15T12:06:08.002291", "ingestion_ts": "2026-01-15T12:08:42.168746", "market_id": "0xc0e6b917320a47228fb96e3b5ae0e5c93773a5ae2662ae4e1f37807cfe47ce98", "raw": {"market": "0xc0e6b917320a47228fb96e3b5ae0e5c93773a5ae2662ae4e1f37807cfe47ce98", "asset_id": "58656358377246279051017109359677190749228949103591068167284263961542487110215", "price": "0.011", "size": "0", "side": "BUY", "timestamp": "1768475167884", "received_at": "2026-01-15T12:06:08.002291"}}
{"event_type": "price_change", "event_ts": "2026-01-15T12:06:08.002291", "ingestion_ts": "2026-01-15T12:08:42.168746", "market_id": "0xc0e6b917320a47228fb96e3b5ae0e5c93773a5ae2662ae4e1f37807cfe47ce98", "raw": {"market": "0xc0e6b917320a47228fb96e3b5ae0e5c93773a5ae2662ae4e1f37807cfe47ce98", "asset_id": "81647294538046680798858716589766492074338758116170717123345952330712416337530", "price": "0.989", "size": "0", "side": "SELL", "timestamp": "1768475167884", "received_at": "2026-01-15T12:06:08.002291"}}
{"event_type": "price_change", "event_ts": "2026-01-15T12:06:08.151397", "ingestion_ts": "2026-01-15T12:08:42.168746", "market_id": "0xcab7ba4a9133cfd407d7e73e5757e5abbace413b59421527a31113406c97815c", "raw": {"market": "0xcab7ba4a9133cfd407d7e73e5757e5abbace413b59421527a31113406c97815c", "asset_id": "96361925776989336186111887920533578209326565663637092688733016597062311745569", "price": "0.009", "size": "818.33", "side": "BUY", "timestamp": "1768475168004", "received_at": "2026-01-15T12:06:08.151397"}}
{"event_type": "price_change", "event_ts": "2026-01-15T12:06:08.151397", "ingestion_ts": "2026-01-15T12:08:42.168746", "market_id": "0xcab7ba4a9133cfd407d7e73e5757e5abbace413b59421527a31113406c97815c", "raw": {"market": "0xcab7ba4a9133cfd407d7e73e5757e5abbace413b59421527a31113406c97815c", "asset_id": "20002636398944597965698652220992177552927816915094913583821579024925426590022", "price": "0.991", "size": "818.33", "side": "SELL", "timestamp": "1768475168004", "received_at": "2026-01-15T12:06:08.151397"}}
{"event_type": "price_change", "event_ts": "2026-01-15T12:06:08.151434", "ingestion_ts": "2026-01-15T12:08:42.168746", "market_id": "0xcab7ba4a9133cfd407d7e73e5757e5abbace413b59421527a31113406c97815c", "raw": {"market": "0xcab7ba4a9133cfd407d7e73e5757e5abbace413b59421527a31113406c97815c", "asset_id": "96361925776989336186111887920533578209326565663637092688733016597062311745569", "price": "0.006", "size": "136.51", "side": "BUY", "timestamp": "1768475168005", "received_at": "2026-01-15T12:06:08.151434"}}
{"event_type": "price_change", "event_ts": "2026-01-15T12:06:08.151434", "ingestion_ts": "2026-01-15T12:08:42.168746", "market_id": "0xcab7ba4a9133cfd407d7e73e5757e5abbace413b59421527a31113406c97815c", "raw": {"market": "0xcab7ba4a9133cfd407d7e73e5757e5abbace413b59421527a31113406c97815c", "asset_id": "20002636398944597965698652220992177552927816915094913583821579024925426590022", "price": "0.994", "size": "136.51", "side": "SELL", "timestamp": "1768475168005", "received_at": "2026-01-15T12:06:08.151434"}}
{"event_type": "price_change", "event_ts": "2026-01-15T12:06:08.480132", "ingestion_ts": "2026-01-15T12:08:42.168746", "market_id": "0xc0e6b917320a47228fb96e3b5ae0e5c93773a5ae2662ae4e1f37807cfe47ce98", "raw": {"market": "0xc0e6b917320a47228fb96e3b5ae0e5c93773a5ae2662ae4e1f37807cfe47ce98", "asset_id": "58656358377246279051017109359677190749228949103591068167284263961542487110215", "price": "0.003", "size": "460.21", "side": "BUY", "timestamp": "1768475168316", "received_at": "2026-01-15T12:06:08.480132"}}
{"event_type": "price_change", "event_ts": "2026-01-15T12:06:08.480132", "ingestion_ts": "2026-01-15T12:08:42.168746", "market_id": "0xc0e6b917320a47228fb96e3b5ae0e5c93773a5ae2662ae4e1f37807cfe47ce98", "raw": {"market": "0xc0e6b917320a47228fb96e3b5ae0e5c93773a5ae2662ae4e1f37807cfe47ce98", "asset_id": "81647294538046680798858716589766492074338758116170717123345952330712416337530", "price": "0.997", "size": "460.21", "side": "SELL", "timestamp": "1768475168316", "received_at": "2026-01-15T12:06:08.480132"}}
{"event_type": "price_change", "event_ts": "2026-01-15T12:06:09.129985", "ingestion_ts": "2026-01-15T12:08:42.168746", "market_id": "0xc0e6b917320a47228fb96e3b5ae0e5c93773a5ae2662ae4e1f37807cfe47ce98", "raw": {"market": "0xc0e6b917320a47228fb96e3b5ae0e5c93773a5ae2662ae4e1f37807cfe47ce98", "asset_id": "58656358377246279051017109359677190749228949103591068167284263961542487110215", "price": "0.003", "size": "449.43", "side": "BUY", "timestamp": "1768475169000", "received_at": "2026-01-15T12:06:09.129985"}}
{"event_type": "price_change", "event_ts": "2026-01-15T12:06:09.129985", "ingestion_ts": "2026-01-15T12:08:42.168746", "market_id": "0xc0e6b917320a47228fb96e3b5ae0e5c93773a5ae2662ae4e1f37807cfe47ce98", "raw": {"market": "0xc0e6b917320a47228fb96e3b5ae0e5c93773a5ae2662ae4e1f37807cfe47ce98", "asset_id": "81647294538046680798858716589766492074338758116170717123345952330712416337530", "price": "0.997", "size": "449.43", "side": "SELL", "timestamp": "1768475169000", "received_at": "2026-01-15T12:06:09.129985"}}
{"event_type": "price_change", "event_ts": "2026-01-15T12:06:09.131212", "ingestion_ts": "2026-01-15T12:08:42.168746", "market_id": "0xc0e6b917320a47228fb96e3b5ae0e5c93773a5ae2662ae4e1f37807cfe47ce98", "raw": {"market": "0xc0e6b917320a47228fb96e3b5ae0e5c93773a5ae2662ae4e1f37807cfe47ce98", "asset_id": "58656358377246279051017109359677190749228949103591068167284263961542487110215", "price": "0.003", "size": "449.43", "side": "BUY", "timestamp": "1768475169001", "received_at": "2026-01-15T12:06:09.131212"}}
{"event_type": "price_change", "event_ts": "2026-01-15T12:06:09.131212", "ingestion_ts": "2026-01-15T12:08:42.168746", "market_id": "0xc0e6b917320a47228fb96e3b5ae0e5c93773a5ae2662ae4e1f37807cfe47ce98", "raw": {"market": "0xc0e6b917320a47228fb96e3b5ae0e5c93773a5ae2662ae4e1f37807cfe47ce98", "asset_id": "81647294538046680798858716589766492074338758116170717123345952330712416337530", "price": "0.997", "size": "449.43", "side": "SELL", "timestamp": "1768475169001", "received_at": "2026-01-15T12:06:09.131212"}}
{"event_type": "price_change", "event_ts": "2026-01-15T12:06:10.067106", "ingestion_ts": "2026-01-15T12:08:42.168746", "market_id": "0xcab7ba4a9133cfd407d7e73e5757e5abbace413b59421527a31113406c97815c", "raw": {"market": "0xcab7ba4a9133cfd407d7e73e5757e5abbace413b59421527a31113406c97815c", "asset_id": "96361925776989336186111887920533578209326565663637092688733016597062311745569", "price": "0.006", "size": "127.41", "side": "BUY", "timestamp": "1768475169937", "received_at": "2026-01-15T12:06:10.067106"}}
{"event_type": "price_change", "event_ts": "2026-01-15T12:06:10.067106", "ingestion_ts": "2026-01-15T12:08:42.168746", "market_id": "0xcab7ba4a9133cfd407d7e73e5757e5abbace413b59421527a31113406c97815c", "raw": {"market": "0xcab7ba4a9133cfd407d7e73e5757e5abbace413b59421527a31113406c97815c", "asset_id": "20002636398944597965698652220992177552927816915094913583821579024925426590022", "price": "0.994", "size": "127.41", "side": "SELL", "timestamp": "1768475169937", "received_at": "2026-01-15T12:06:10.067106"}}
{"event_type": "price_change", "event_ts": "2026-01-15T12:06:10.067207", "ingestion_ts": "2026-01-15T12:08:42.168746", "market_id": "0xcab7ba4a9133cfd407d7e73e5757e5abbace413b59421527a31113406c97815c", "raw": {"market": "0xcab7ba4a9133cfd407d7e73e5757e5abbace413b59421527a31113406c97815c", "asset_id": "96361925776989336186111887920533578209326565663637092688733016597062311745569", "price": "0.009", "size": "812.25", "side": "BUY", "timestamp": "1768475169937", "received_at": "2026-01-15T12:06:10.067207"}}
{"event_type": "price_change", "event_ts": "2026-01-15T12:06:10.067207", "ingestion_ts": "2026-01-15T12:08:42.168746", "market_id": "0xcab7ba4a9133cfd407d7e73e5757e5abbace413b59421527a31113406c97815c", "raw": {"market": "0xcab7ba4a9133cfd407d7e73e5757e5abbace413b59421527a31113406c97815c", "asset_id": "20002636398944597965698652220992177552927816915094913583821579024925426590022", "price": "0.991", "size": "812.25", "side": "SELL", "timestamp": "1768475169937", "received_at": "2026-01-15T12:06:10.067207"}}
{"event_type": "price_change", "event_ts": "2026-01-15T12:06:10.756776", "ingestion_ts": "2026-01-15T12:08:42.168746", "market_id": "0xcab7ba4a9133cfd407d7e73e5757e5abbace413b59421527a31113406c97815c", "raw": {"market": "0xcab7ba4a9133cfd407d7e73e5757e5abbace413b59421527a31113406c97815c", "asset_id": "96361925776989336186111887920533578209326565663637092688733016597062311745569", "price": "0.009", "size": "818.33", "side": "BUY", "timestamp": "1768475170636", "received_at": "2026-01-15T12:06:10.756776"}}
{"event_type": "price_change", "event_ts": "2026-01-15T12:06:10.756776", "ingestion_ts": "2026-01-15T12:08:42.168746", "market_id": "0xcab7ba4a9133cfd407d7e73e5757e5abbace413b59421527a31113406c97815c", "raw": {"market": "0xcab7ba4a9133cfd407d7e73e5757e5abbace413b59421527a31113406c97815c", "asset_id": "20002636398944597965698652220992177552927816915094913583821579024925426590022", "price": "0.991", "size": "818.33", "side": "SELL", "timestamp": "1768475170636", "received_at": "2026-01-15T12:06:10.756776"}}
{"event_type": "price_change", "event_ts": "2026-01-15T12:06:10.758063", "ingestion_ts": "2026-01-15T12:08:42.168746", "market_id": "0xcab7ba4a9133cfd407d7e73e5757e5abbace413b59421527a31113406c97815c", "raw": {"market": "0xcab7ba4a9133cfd407d7e73e5757e5abbace413b59421527a31113406c97815c", "asset_id": "96361925776989336186111887920533578209326565663637092688733016597062311745569", "price": "0.006", "size": "136.51", "side": "BUY", "timestamp": "1768475170637", "received_at": "2026-01-15T12:06:10.758063"}}
{"event_type": "price_change", "event_ts": "2026-01-15T12:06:10.758063", "ingestion_ts": "2026-01-15T12:08:42.168746", "market_id": "0xcab7ba4a9133cfd407d7e73e5757e5abbace413b59421527a31113406c97815c", "raw": {"market": "0xcab7ba4a9133cfd407d7e73e5757e5abbace413b59421527a31113406c97815c", "asset_id": "20002636398944597965698652220992177552927816915094913583821579024925426590022", "price": "0.994", "size": "136.51", "side": "SELL", "timestamp": "1768475170637", "received_at": "2026-01-15T12:06:10.758063"}}
{"event_type": "price_change", "event_ts": "2026-01-15T12:06:12.670463", "ingestion_ts": "2026-01-15T12:08:42.168746", "market_id": "0xc0e6b917320a47228fb96e3b5ae0e5c93773a5ae2662ae4e1f37807cfe47ce98", "raw": {"market": "0xc0e6b917320a47228fb96e3b5ae0e5c93773a5ae2662ae4e1f37807cfe47ce98", "asset_id": "58656358377246279051017109359677190749228949103591068167284263961542487110215", "price": "0.003", "size": "399.47", "side": "BUY", "timestamp": "1768475172403", "received_at": "2026-01-15T12:06:12.670463"}}
{"event_type": "price_change", "event_ts": "2026-01-15T12:06:12.670463", "ingestion_ts": "2026-01-15T12:08:42.168746", "market_id": "0xc0e6b917320a47228fb96e3b5ae0e5c93773a5ae2662ae4e1f37807cfe47ce98", "raw": {"market": "0xc0e6b917320a47228fb96e3b5ae0e5c93773a5ae2662ae4e1f37807cfe47ce98", "asset_id": "81647294538046680798858716589766492074338758116170717123345952330712416337530", "price": "0.997", "size": "399.47", "side": "SELL", "timestamp": "1768475172403", "received_at": "2026-01-15T12:06:12.670463"}}
{"event_type": "price_change", "event_ts": "2026-01-15T12:06:13.156521", "ingestion_ts": "2026-01-15T12:08:42.168746", "market_id": "0xc0e6b917320a47228fb96e3b5ae0e5c93773a5ae2662ae4e1f37807cfe47ce98", "raw": {"market": "0xc0e6b917320a47228fb96e3b5ae0e5c93773a5ae2662ae4e1f37807cfe47ce98", "asset_id": "58656358377246279051017109359677190749228949103591068167284263961542487110215", "price": "0.004", "size": "45.55", "side": "BUY", "timestamp": "1768475173008", "received_at": "2026-01-15T12:06:13.156521"}}
{"event_type": "price_change", "event_ts": "2026-01-15T12:06:13.156521", "ingestion_ts": "2026-01-15T12:08:42.168746", "market_id": "0xc0e6b917320a47228fb96e3b5ae0e5c93773a5ae2662ae4e1f37807cfe47ce98", "raw": {"market": "0xc0e6b917320a47228fb96e3b5ae0e5c93773a5ae2662ae4e1f37807cfe47ce98", "asset_id": "81647294538046680798858716589766492074338758116170717123345952330712416337530", "price": "0.996", "size": "45.55", "side": "SELL", "timestamp": "1768475173008", "received_at": "2026-01-15T12:06:13.156521"}}
{"event_type": "price_change", "event_ts": "2026-01-15T12:06:13.649792", "ingestion_ts": "2026-01-15T12:08:42.168746", "market_id": "0xcab7ba4a9133cfd407d7e73e5757e5abbace413b59421527a31113406c97815c", "raw": {"market": "0xcab7ba4a9133cfd407d7e73e5757e5abbace413b59421527a31113406c97815c", "asset_id": "96361925776989336186111887920533578209326565663637092688733016597062311745569", "price": "0.006", "size": "127.41", "side": "BUY", "timestamp": "1768475173532", "received_at": "2026-01-15T12:06:13.649792"}}
{"event_type": "price_change", "event_ts": "2026-01-15T12:06:13.649792", "ingestion_ts": "2026-01-15T12:08:42.168746", "market_id": "0xcab7ba4a9133cfd407d7e73e5757e5abbace413b59421527a31113406c97815c", "raw": {"market": "0xcab7ba4a9133cfd407d7e73e5757e5abbace413b59421527a31113406c97815c", "asset_id": "20002636398944597965698652220992177552927816915094913583821579024925426590022", "price": "0.994", "size": "127.41", "side": "SELL", "timestamp": "1768475173532", "received_at": "2026-01-15T12:06:13.649792"}}
{"event_type": "price_change", "event_ts": "2026-01-15T12:06:13.651033", "ingestion_ts": "2026-01-15T12:08:42.168746", "market_id": "0xcab7ba4a9133cfd407d7e73e5757e5abbace413b59421527a31113406c97815c", "raw": {"market": "0xcab7ba4a9133cfd407d7e73e5757e5abbace413b59421527a31113406c97815c", "asset_id": "96361925776989336186111887920533578209326565663637092688733016597062311745569", "price": "0.009", "size": "812.25", "side": "BUY", "timestamp": "1768475173532", "received_at": "2026-01-15T12:06:13.651033"}}
{"event_type": "price_change", "event_ts": "2026-01-15T12:06:13.651033", "ingestion_ts": "2026-01-15T12:08:42.168746", "market_id": "0xcab7ba4a9133cfd407d7e73e5757e5abbace413b59421527a31113406c97815c", "raw": {"market": "0xcab7ba4a9133cfd407d7e73e5757e5abbace413b59421527a31113406c97815c", "asset_id": "20002636398944597965698652220992177552927816915094913583821579024925426590022", "price": "0.991", "size": "812.25", "side": "SELL", "timestamp": "1768475173532", "received_at": "2026-01-15T12:06:13.651033"}}
{"event_type": "price_change", "event_ts": "2026-01-15T12:06:14.213174", "ingestion_ts": "2026-01-15T12:08:42.168746", "market_id": "0xcab7ba4a9133cfd407d7e73e5757e5abbace413b59421527a31113406c97815c", "raw": {"market": "0xcab7ba4a9133cfd407d7e73e5757e5abbace413b59421527a31113406c97815c", "asset_id": "96361925776989336186111887920533578209326565663637092688733016597062311745569", "price": "0.006", "size": "136.51", "side": "BUY", "timestamp": "1768475174095", "received_at": "2026-01-15T12:06:14.213174"}}
{"event_type": "price_change", "event_ts": "2026-01-15T12:06:14.213174", "ingestion_ts": "2026-01-15T12:08:42.168746", "market_id": "0xcab7ba4a9133cfd407d7e73e5757e5abbace413b59421527a31113406c97815c", "raw": {"market": "0xcab7ba4a9133cfd407d7e73e5757e5abbace413b59421527a31113406c97815c", "asset_id": "20002636398944597965698652220992177552927816915094913583821579024925426590022", "price": "0.994", "size": "136.51", "side": "SELL", "timestamp": "1768475174095", "received_at": "2026-01-15T12:06:14.213174"}}
{"event_type": "price_change", "event_ts": "2026-01-15T12:06:14.213698", "ingestion_ts": "2026-01-15T12:08:42.168746", "market_id": "0xcab7ba4a9133cfd407d7e73e5757e5abbace413b59421527a31113406c97815c", "raw": {"market": "0xcab7ba4a9133cfd407d7e73e5757e5abbace413b59421527a31113406c97815c", "asset_id": "96361925776989336186111887920533578209326565663637092688733016597062311745569", "price": "0.009", "size": "818.33", "side": "BUY", "timestamp": "1768475174096", "received_at": "2026-01-15T12:06:14.213698"}}
{"event_type": "price_change", "event_ts": "2026-01-15T12:06:14.213698", "ingestion_ts": "2026-01-15T12:08:42.168746", "market_id": "0xcab7ba4a9133cfd407d7e73e5757e5abbace413b59421527a31113406c97815c", "raw": {"market": "0xcab7ba4a9133cfd407d7e73e5757e5abbace413b59421527a31113406c97815c", "asset_id": "20002636398944597965698652220992177552927816915094913583821579024925426590022", "price": "0.991", "size": "818.33", "side": "SELL", "timestamp": "1768475174096", "received_at": "2026-01-15T12:06:14.213698"}}
{"event_type": "price_change", "event_ts": "2026-01-15T12:06:16.374009", "ingestion_ts": "2026-01-15T12:08:42.168746", "market_id": "0xcab7ba4a9133cfd407d7e73e5757e5abbace413b59421527a31113406c97815c", "raw": {"market": "0xcab7ba4a9133cfd407d7e73e5757e5abbace413b59421527a31113406c97815c", "asset_id": "96361925776989336186111887920533578209326565663637092688733016597062311745569", "price": "0.006", "size": "127.41", "side": "BUY", "timestamp": "1768475176246", "received_at": "2026-01-15T12:06:16.374009"}}
{"event_type": "price_change", "event_ts": "2026-01-15T12:06:16.374009", "ingestion_ts": "2026-01-15T12:08:42.168746", "market_id": "0xcab7ba4a9133cfd407d7e73e5757e5abbace413b59421527a31113406c97815c", "raw": {"market": "0xcab7ba4a9133cfd407d7e73e5757e5abbace413b59421527a31113406c97815c", "asset_id": "20002636398944597965698652220992177552927816915094913583821579024925426590022", "price": "0.994", "size": "127.41", "side": "SELL", "timestamp": "1768475176246", "received_at": "2026-01-15T12:06:16.374009"}}
{"event_type": "price_change", "event_ts": "2026-01-15T12:06:16.374073", "ingestion_ts": "2026-01-15T12:08:42.168746", "market_id": "0xcab7ba4a9133cfd407d7e73e5757e5abbace413b59421527a31113406c97815c", "raw": {"market": "0xcab7ba4a9133cfd407d7e73e5757e5abbace413b59421527a31113406c97815c", "asset_id": "96361925776989336186111887920533578209326565663637092688733016597062311745569", "price": "0.009", "size": "812.25", "side": "BUY", "timestamp": "1768475176246", "received_at": "2026-01-15T12:06:16.374073"}}
{"event_type": "price_change", "event_ts": "2026-01-15T12:06:16.374073", "ingestion_ts": "2026-01-15T12:08:42.168746", "market_id": "0xcab7ba4a9133cfd407d7e73e5757e5abbace413b59421527a31113406c97815c", "raw": {"market": "0xcab7ba4a9133cfd407d7e73e5757e5abbace413b59421527a31113406c97815c", "asset_id": "20002636398944597965698652220992177552927816915094913583821579024925426590022", "price": "0.991", "size": "812.25", "side": "SELL", "timestamp": "1768475176246", "received_at": "2026-01-15T12:06:16.374073"}}
{"event_type": "price_change", "event_ts": "2026-01-15T12:06:16.923509", "ingestion_ts": "2026-01-15T12:08:42.168746", "market_id": "0xc0e6b917320a47228fb96e3b5ae0e5c93773a5ae2662ae4e1f37807cfe47ce98", "raw": {"market": "0xc0e6b917320a47228fb96e3b5ae0e5c93773a5ae2662ae4e1f37807cfe47ce98", "asset_id": "58656358377246279051017109359677190749228949103591068167284263961542487110215", "price": "0.004", "size": "0", "side": "BUY", "timestamp": "1768475176798", "received_at": "2026-01-15T12:06:16.923509"}}
{"event_type": "price_change", "event_ts": "2026-01-15T12:06:16.923509", "ingestion_ts": "2026-01-15T12:08:42.168746", "market_id": "0xc0e6b917320a47228fb96e3b5ae0e5c93773a5ae2662ae4e1f37807cfe47ce98", "raw": {"market": "0xc0e6b917320a47228fb96e3b5ae0e5c93773a5ae2662ae4e1f37807cfe47ce98", "asset_id": "81647294538046680798858716589766492074338758116170717123345952330712416337530", "price": "0.996", "size": "0", "side": "SELL", "timestamp": "1768475176798", "received_at": "2026-01-15T12:06:16.923509"}}
{"event_type": "price_change", "event_ts": "2026-01-15T12:06:17.329732", "ingestion_ts": "2026-01-15T12:08:42.168746", "market_id": "0xcab7ba4a9133cfd407d7e73e5757e5abbace413b59421527a31113406c97815c", "raw": {"market": "0xcab7ba4a9133cfd407d7e73e5757e5abbace413b59421527a31113406c97815c", "asset_id": "96361925776989336186111887920533578209326565663637092688733016597062311745569", "price": "0.006", "size": "136.51", "side": "BUY", "timestamp": "1768475177206", "received_at": "2026-01-15T12:06:17.329732"}}
{"event_type": "price_change", "event_ts": "2026-01-15T12:06:17.329732", "ingestion_ts": "2026-01-15T12:08:42.168746", "market_id": "0xcab7ba4a9133cfd407d7e73e5757e5abbace413b59421527a31113406c97815c", "raw": {"market": "0xcab7ba4a9133cfd407d7e73e5757e5abbace413b59421527a31113406c97815c", "asset_id": "20002636398944597965698652220992177552927816915094913583821579024925426590022", "price": "0.994", "size": "136.51", "side": "SELL", "timestamp": "1768475177206", "received_at": "2026-01-15T12:06:17.329732"}}
{"event_type": "price_change", "event_ts": "2026-01-15T12:06:17.329770", "ingestion_ts": "2026-01-15T12:08:42.168746", "market_id": "0xcab7ba4a9133cfd407d7e73e5757e5abbace413b59421527a31113406c97815c", "raw": {"market": "0xcab7ba4a9133cfd407d7e73e5757e5abbace413b59421527a31113406c97815c", "asset_id": "96361925776989336186111887920533578209326565663637092688733016597062311745569", "price": "0.009", "size": "818.33", "side": "BUY", "timestamp": "1768475177207", "received_at": "2026-01-15T12:06:17.329770"}}
{"event_type": "price_change", "event_ts": "2026-01-15T12:06:17.329770", "ingestion_ts": "2026-01-15T12:08:42.168746", "market_id": "0xcab7ba4a9133cfd407d7e73e5757e5abbace413b59421527a31113406c97815c", "raw": {"market": "0xcab7ba4a9133cfd407d7e73e5757e5abbace413b59421527a31113406c97815c", "asset_id": "20002636398944597965698652220992177552927816915094913583821579024925426590022", "price": "0.991", "size": "818.33", "side": "SELL", "timestamp": "1768475177207", "received_at": "2026-01-15T12:06:17.329770"}}
{"event_type": "price_change", "event_ts": "2026-01-15T12:06:17.523799", "ingestion_ts": "2026-01-15T12:08:42.168746", "market_id": "0xc0e6b917320a47228fb96e3b5ae0e5c93773a5ae2662ae4e1f37807cfe47ce98", "raw": {"market": "0xc0e6b917320a47228fb96e3b5ae0e5c93773a5ae2662ae4e1f37807cfe47ce98", "asset_id": "58656358377246279051017109359677190749228949103591068167284263961542487110215", "price": "0.005", "size": "39.42", "side": "BUY", "timestamp": "1768475177403", "received_at": "2026-01-15T12:06:17.523799"}}
{"event_type": "price_change", "event_ts": "2026-01-15T12:06:17.523799", "ingestion_ts": "2026-01-15T12:08:42.168746", "market_id": "0xc0e6b917320a47228fb96e3b5ae0e5c93773a5ae2662ae4e1f37807cfe47ce98", "raw": {"market": "0xc0e6b917320a47228fb96e3b5ae0e5c93773a5ae2662ae4e1f37807cfe47ce98", "asset_id": "81647294538046680798858716589766492074338758116170717123345952330712416337530", "price": "0.995", "size": "39.42", "side": "SELL", "timestamp": "1768475177403", "received_at": "2026-01-15T12:06:17.523799"}}
{"event_type": "price_change", "event_ts": "2026-01-15T12:06:21.266999", "ingestion_ts": "2026-01-15T12:08:42.168746", "market_id": "0xcab7ba4a9133cfd407d7e73e5757e5abbace413b59421527a31113406c97815c", "raw": {"market": "0xcab7ba4a9133cfd407d7e73e5757e5abbace413b59421527a31113406c97815c", "asset_id": "96361925776989336186111887920533578209326565663637092688733016597062311745569", "price": "0.006", "size": "127.41", "side": "BUY", "timestamp": "1768475181139", "received_at": "2026-01-15T12:06:21.266999"}}
{"event_type": "price_change", "event_ts": "2026-01-15T12:06:21.266999", "ingestion_ts": "2026-01-15T12:08:42.168746", "market_id": "0xcab7ba4a9133cfd407d7e73e5757e5abbace413b59421527a31113406c97815c", "raw": {"market": "0xcab7ba4a9133cfd407d7e73e5757e5abbace413b59421527a31113406c97815c", "asset_id": "20002636398944597965698652220992177552927816915094913583821579024925426590022", "price": "0.994", "size": "127.41", "side": "SELL", "timestamp": "1768475181139", "received_at": "2026-01-15T12:06:21.266999"}}
{"event_type": "price_change", "event_ts": "2026-01-15T12:06:21.267045", "ingestion_ts": "2026-01-15T12:08:42.168746", "market_id": "0xcab7ba4a9133cfd407d7e73e5757e5abbace413b59421527a31113406c97815c", "raw": {"market": "0xcab7ba4a9133cfd407d7e73e5757e5abbace413b59421527a31113406c97815c", "asset_id": "96361925776989336186111887920533578209326565663637092688733016597062311745569", "price": "0.009", "size": "812.25", "side": "BUY", "timestamp": "1768475181139", "received_at": "2026-01-15T12:06:21.267045"}}
{"event_type": "price_change", "event_ts": "2026-01-15T12:06:21.267045", "ingestion_ts": "2026-01-15T12:08:42.168746", "market_id": "0xcab7ba4a9133cfd407d7e73e5757e5abbace413b59421527a31113406c97815c", "raw": {"market": "0xcab7ba4a9133cfd407d7e73e5757e5abbace413b59421527a31113406c97815c", "asset_id": "20002636398944597965698652220992177552927816915094913583821579024925426590022", "price": "0.991", "size": "812.25", "side": "SELL", "timestamp": "1768475181139", "received_at": "2026-01-15T12:06:21.267045"}}
{"event_type": "price_change", "event_ts": "2026-01-15T12:06:22.015317", "ingestion_ts": "2026-01-15T12:08:42.168746", "market_id": "0xcab7ba4a9133cfd407d7e73e5757e5abbace413b59421527a31113406c97815c", "raw": {"market": "0xcab7ba4a9133cfd407d7e73e5757e5abbace413b59421527a31113406c97815c", "asset_id": "96361925776989336186111887920533578209326565663637092688733016597062311745569", "price": "0.006", "size": "136.51", "side": "BUY", "timestamp": "1768475181897", "received_at": "2026-01-15T12:06:22.015317"}}
{"event_type": "price_change", "event_ts": "2026-01-15T12:06:22.015317", "ingestion_ts": "2026-01-15T12:08:42.168746", "market_id": "0xcab7ba4a9133cfd407d7e73e5757e5abbace413b59421527a31113406c97815c", "raw": {"market": "0xcab7ba4a9133cfd407d7e73e5757e5abbace413b59421527a31113406c97815c", "asset_id": "20002636398944597965698652220992177552927816915094913583821579024925426590022", "price": "0.994", "size": "136.51", "side": "SELL", "timestamp": "1768475181897", "received_at": "2026-01-15T12:06:22.015317"}}
{"event_type": "price_change", "event_ts": "2026-01-15T12:06:22.016465", "ingestion_ts": "2026-01-15T12:08:42.168746", "market_id": "0xcab7ba4a9133cfd407d7e73e5757e5abbace413b59421527a31113406c97815c", "raw": {"market": "0xcab7ba4a9133cfd407d7e73e5757e5abbace413b59421527a31113406c97815c", "asset_id": "96361925776989336186111887920533578209326565663637092688733016597062311745569", "price": "0.009", "size": "818.33", "side": "BUY", "timestamp": "1768475181898", "received_at": "2026-01-15T12:06:22.016465"}}
{"event_type": "price_change", "event_ts": "2026-01-15T12:06:22.016465", "ingestion_ts": "2026-01-15T12:08:42.168746", "market_id": "0xcab7ba4a9133cfd407d7e73e5757e5abbace413b59421527a31113406c97815c", "raw": {"market": "0xcab7ba4a9133cfd407d7e73e5757e5abbace413b59421527a31113406c97815c", "asset_id": "20002636398944597965698652220992177552927816915094913583821579024925426590022", "price": "0.991", "size": "818.33", "side": "SELL", "timestamp": "1768475181898", "received_at": "2026-01-15T12:06:22.016465"}}
{"event_type": "price_change", "event_ts": "2026-01-15T12:06:22.132562", "ingestion_ts": "2026-01-15T12:08:42.168746", "market_id": "0x427bc4b40c09b3dcbc973747f0e4b079bed91b3e5a0aed5c36edd0f7591485f4", "raw": {"market": "0x427bc4b40c09b3dcbc973747f0e4b079bed91b3e5a0aed5c36edd0f7591485f4", "asset_id": "115669573443672055876643967408433138119481486650803218131873713375232186497057", "price": "0.005", "size": "11.62", "side": "BUY", "timestamp": "1768475182001", "received_at": "2026-01-15T12:06:22.132562"}}
{"event_type": "price_change", "event_ts": "2026-01-15T12:06:22.132562", "ingestion_ts": "2026-01-15T12:08:42.168746", "market_id": "0x427bc4b40c09b3dcbc973747f0e4b079bed91b3e5a0aed5c36edd0f7591485f4", "raw": {"market": "0x427bc4b40c09b3dcbc973747f0e4b079bed91b3e5a0aed5c36edd0f7591485f4", "asset_id": "86130975769502911188457673769190265049139877688522439001984850068234616395137", "price": "0.995", "size": "11.62", "side": "SELL", "timestamp": "1768475182001", "received_at": "2026-01-15T12:06:22.132562"}}
{"event_type": "price_change", "event_ts": "2026-01-15T12:06:23.411089", "ingestion_ts": "2026-01-15T12:08:42.168746", "market_id": "0xc0e6b917320a47228fb96e3b5ae0e5c93773a5ae2662ae4e1f37807cfe47ce98", "raw": {"market": "0xc0e6b917320a47228fb96e3b5ae0e5c93773a5ae2662ae4e1f37807cfe47ce98", "asset_id": "58656358377246279051017109359677190749228949103591068167284263961542487110215", "price": "0.005", "size": "2.98", "side": "BUY", "timestamp": "1768475183292", "received_at": "2026-01-15T12:06:23.411089"}}
{"event_type": "price_change", "event_ts": "2026-01-15T12:06:23.411089", "ingestion_ts": "2026-01-15T12:08:42.168746", "market_id": "0xc0e6b917320a47228fb96e3b5ae0e5c93773a5ae2662ae4e1f37807cfe47ce98", "raw": {"market": "0xc0e6b917320a47228fb96e3b5ae0e5c93773a5ae2662ae4e1f37807cfe47ce98", "asset_id": "81647294538046680798858716589766492074338758116170717123345952330712416337530", "price": "0.995", "size": "2.98", "side": "SELL", "timestamp": "1768475183292", "received_at": "2026-01-15T12:06:23.411089"}}
{"event_type": "price_change", "event_ts": "2026-01-15T12:06:24.063039", "ingestion_ts": "2026-01-15T12:08:42.168746", "market_id": "0xc0e6b917320a47228fb96e3b5ae0e5c93773a5ae2662ae4e1f37807cfe47ce98", "raw": {"market": "0xc0e6b917320a47228fb96e3b5ae0e5c93773a5ae2662ae4e1f37807cfe47ce98", "asset_id": "58656358377246279051017109359677190749228949103591068167284263961542487110215", "price": "0.003", "size": "429.84", "side": "BUY", "timestamp": "1768475183945", "received_at": "2026-01-15T12:06:24.063039"}}
{"event_type": "price_change", "event_ts": "2026-01-15T12:06:24.063039", "ingestion_ts": "2026-01-15T12:08:42.168746", "market_id": "0xc0e6b917320a47228fb96e3b5ae0e5c93773a5ae2662ae4e1f37807cfe47ce98", "raw": {"market": "0xc0e6b917320a47228fb96e3b5ae0e5c93773a5ae2662ae4e1f37807cfe47ce98", "asset_id": "81647294538046680798858716589766492074338758116170717123345952330712416337530", "price": "0.997", "size": "429.84", "side": "SELL", "timestamp": "1768475183945", "received_at": "2026-01-15T12:06:24.063039"}}
{"event_type": "price_change", "event_ts": "2026-01-15T12:06:24.461431", "ingestion_ts": "2026-01-15T12:08:42.168746", "market_id": "0xc0e6b917320a47228fb96e3b5ae0e5c93773a5ae2662ae4e1f37807cfe47ce98", "raw": {"market": "0xc0e6b917320a47228fb96e3b5ae0e5c93773a5ae2662ae4e1f37807cfe47ce98", "asset_id": "58656358377246279051017109359677190749228949103591068167284263961542487110215", "price": "0.003", "size": "460.21", "side": "BUY", "timestamp": "1768475184343", "received_at": "2026-01-15T12:06:24.461431"}}
{"event_type": "price_change", "event_ts": "2026-01-15T12:06:24.461431", "ingestion_ts": "2026-01-15T12:08:42.168746", "market_id": "0xc0e6b917320a47228fb96e3b5ae0e5c93773a5ae2662ae4e1f37807cfe47ce98", "raw": {"market": "0xc0e6b917320a47228fb96e3b5ae0e5c93773a5ae2662ae4e1f37807cfe47ce98", "asset_id": "81647294538046680798858716589766492074338758116170717123345952330712416337530", "price": "0.997", "size": "460.21", "side": "SELL", "timestamp": "1768475184343", "received_at": "2026-01-15T12:06:24.461431"}}
{"event_type": "price_change", "event_ts": "2026-01-15T12:06:25.116835", "ingestion_ts": "2026-01-15T12:08:42.168746", "market_id": "0xcab7ba4a9133cfd407d7e73e5757e5abbace413b59421527a31113406c97815c", "raw": {"market": "0xcab7ba4a9133cfd407d7e73e5757e5abbace413b59421527a31113406c97815c", "asset_id": "96361925776989336186111887920533578209326565663637092688733016597062311745569", "price": "0.006", "size": "127.41", "side": "BUY", "timestamp": "1768475184988", "received_at": "2026-01-15T12:06:25.116835"}}
{"event_type": "price_change", "event_ts": "2026-01-15T12:06:25.116835", "ingestion_ts": "2026-01-15T12:08:42.168746", "market_id": "0xcab7ba4a9133cfd407d7e73e5757e5abbace413b59421527a31113406c97815c", "raw": {"market": "0xcab7ba4a9133cfd407d7e73e5757e5abbace413b59421527a31113406c97815c", "asset_id": "20002636398944597965698652220992177552927816915094913583821579024925426590022", "price": "0.994", "size": "127.41", "side": "SELL", "timestamp": "1768475184988", "received_at": "2026-01-15T12:06:25.116835"}}
{"event_type": "price_change", "event_ts": "2026-01-15T12:06:25.116871", "ingestion_ts": "2026-01-15T12:08:42.168746", "market_id": "0xcab7ba4a9133cfd407d7e73e5757e5abbace413b59421527a31113406c97815c", "raw": {"market": "0xcab7ba4a9133cfd407d7e73e5757e5abbace413b59421527a31113406c97815c", "asset_id": "96361925776989336186111887920533578209326565663637092688733016597062311745569", "price": "0.009", "size": "812.25", "side": "BUY", "timestamp": "1768475184988", "received_at": "2026-01-15T12:06:25.116871"}}
{"event_type": "price_change", "event_ts": "2026-01-15T12:06:25.116871", "ingestion_ts": "2026-01-15T12:08:42.168746", "market_id": "0xcab7ba4a9133cfd407d7e73e5757e5abbace413b59421527a31113406c97815c", "raw": {"market": "0xcab7ba4a9133cfd407d7e73e5757e5abbace413b59421527a31113406c97815c", "asset_id": "20002636398944597965698652220992177552927816915094913583821579024925426590022", "price": "0.991", "size": "812.25", "side": "SELL", "timestamp": "1768475184988", "received_at": "2026-01-15T12:06:25.116871"}}
{"event_type": "price_change", "event_ts": "2026-01-15T12:06:25.815810", "ingestion_ts": "2026-01-15T12:08:42.168746", "market_id": "0xcab7ba4a9133cfd407d7e73e5757e5abbace413b59421527a31113406c97815c", "raw": {"market": "0xcab7ba4a9133cfd407d7e73e5757e5abbace413b59421527a31113406c97815c", "asset_id": "96361925776989336186111887920533578209326565663637092688733016597062311745569", "price": "0.009", "size": "818.33", "side": "BUY", "timestamp": "1768475185660", "received_at": "2026-01-15T12:06:25.815810"}}
{"event_type": "price_change", "event_ts": "2026-01-15T12:06:25.815810", "ingestion_ts": "2026-01-15T12:08:42.168746", "market_id": "0xcab7ba4a9133cfd407d7e73e5757e5abbace413b59421527a31113406c97815c", "raw": {"market": "0xcab7ba4a9133cfd407d7e73e5757e5abbace413b59421527a31113406c97815c", "asset_id": "20002636398944597965698652220992177552927816915094913583821579024925426590022", "price": "0.991", "size": "818.33", "side": "SELL", "timestamp": "1768475185660", "received_at": "2026-01-15T12:06:25.815810"}}
{"event_type": "price_change", "event_ts": "2026-01-15T12:06:25.817677", "ingestion_ts": "2026-01-15T12:08:42.168746", "market_id": "0xcab7ba4a9133cfd407d7e73e5757e5abbace413b59421527a31113406c97815c", "raw": {"market": "0xcab7ba4a9133cfd407d7e73e5757e5abbace413b59421527a31113406c97815c", "asset_id": "96361925776989336186111887920533578209326565663637092688733016597062311745569", "price": "0.006", "size": "136.51", "side": "BUY", "timestamp": "1768475185661", "received_at": "2026-01-15T12:06:25.817677"}}
{"event_type": "price_change", "event_ts": "2026-01-15T12:06:25.817677", "ingestion_ts": "2026-01-15T12:08:42.168746", "market_id": "0xcab7ba4a9133cfd407d7e73e5757e5abbace413b59421527a31113406c97815c", "raw": {"market": "0xcab7ba4a9133cfd407d7e73e5757e5abbace413b59421527a31113406c97815c", "asset_id": "20002636398944597965698652220992177552927816915094913583821579024925426590022", "price": "0.994", "size": "136.51", "side": "SELL", "timestamp": "1768475185661", "received_at": "2026-01-15T12:06:25.817677"}}
{"event_type": "price_change", "event_ts": "2026-01-15T12:06:27.046874", "ingestion_ts": "2026-01-15T12:08:42.168746", "market_id": "0xcab7ba4a9133cfd407d7e73e5757e5abbace413b59421527a31113406c97815c", "raw": {"market": "0xcab7ba4a9133cfd407d7e73e5757e5abbace413b59421527a31113406c97815c", "asset_id": "96361925776989336186111887920533578209326565663637092688733016597062311745569", "price": "0.006", "size": "127.41", "side": "BUY", "timestamp": "1768475186885", "received_at": "2026-01-15T12:06:27.046874"}}
{"event_type": "price_change", "event_ts": "2026-01-15T12:06:27.046874", "ingestion_ts": "2026-01-15T12:08:42.168746", "market_id": "0xcab7ba4a9133cfd407d7e73e5757e5abbace413b59421527a31113406c97815c", "raw": {"market": "0xcab7ba4a9133cfd407d7e73e5757e5abbace413b59421527a31113406c97815c", "asset_id": "20002636398944597965698652220992177552927816915094913583821579024925426590022", "price": "0.994", "size": "127.41", "side": "SELL", "timestamp": "1768475186885", "received_at": "2026-01-15T12:06:27.046874"}}
{"event_type": "price_change", "event_ts": "2026-01-15T12:06:27.046910", "ingestion_ts": "2026-01-15T12:08:42.168746", "market_id": "0xcab7ba4a9133cfd407d7e73e5757e5abbace413b59421527a31113406c97815c", "raw": {"market": "0xcab7ba4a9133cfd407d7e73e5757e5abbace413b59421527a31113406c97815c", "asset_id": "96361925776989336186111887920533578209326565663637092688733016597062311745569", "price": "0.009", "size": "812.25", "side": "BUY", "timestamp": "1768475186885", "received_at": "2026-01-15T12:06:27.046910"}}
{"event_type": "price_change", "event_ts": "2026-01-15T12:06:27.046910", "ingestion_ts": "2026-01-15T12:08:42.168746", "market_id": "0xcab7ba4a9133cfd407d7e73e5757e5abbace413b59421527a31113406c97815c", "raw": {"market": "0xcab7ba4a9133cfd407d7e73e5757e5abbace413b59421527a31113406c97815c", "asset_id": "20002636398944597965698652220992177552927816915094913583821579024925426590022", "price": "0.991", "size": "812.25", "side": "SELL", "timestamp": "1768475186885", "received_at": "2026-01-15T12:06:27.046910"}}
{"event_type": "price_change", "event_ts": "2026-01-15T12:06:27.455961", "ingestion_ts": "2026-01-15T12:08:42.168746", "market_id": "0xcab7ba4a9133cfd407d7e73e5757e5abbace413b59421527a31113406c97815c", "raw": {"market": "0xcab7ba4a9133cfd407d7e73e5757e5abbace413b59421527a31113406c97815c", "asset_id": "96361925776989336186111887920533578209326565663637092688733016597062311745569", "price": "0.006", "size": "136.51", "side": "BUY", "timestamp": "1768475187330", "received_at": "2026-01-15T12:06:27.455961"}}
{"event_type": "price_change", "event_ts": "2026-01-15T12:06:27.455961", "ingestion_ts": "2026-01-15T12:08:42.168746", "market_id": "0xcab7ba4a9133cfd407d7e73e5757e5abbace413b59421527a31113406c97815c", "raw": {"market": "0xcab7ba4a9133cfd407d7e73e5757e5abbace413b59421527a31113406c97815c", "asset_id": "20002636398944597965698652220992177552927816915094913583821579024925426590022", "price": "0.994", "size": "136.51", "side": "SELL", "timestamp": "1768475187330", "received_at": "2026-01-15T12:06:27.455961"}}
{"event_type": "price_change", "event_ts": "2026-01-15T12:06:27.460221", "ingestion_ts": "2026-01-15T12:08:42.168746", "market_id": "0xcab7ba4a9133cfd407d7e73e5757e5abbace413b59421527a31113406c97815c", "raw": {"market": "0xcab7ba4a9133cfd407d7e73e5757e5abbace413b59421527a31113406c97815c", "asset_id": "96361925776989336186111887920533578209326565663637092688733016597062311745569", "price": "0.009", "size": "818.33", "side": "BUY", "timestamp": "1768475187336", "received_at": "2026-01-15T12:06:27.460221"}}
{"event_type": "price_change", "event_ts": "2026-01-15T12:06:27.460221", "ingestion_ts": "2026-01-15T12:08:42.168746", "market_id": "0xcab7ba4a9133cfd407d7e73e5757e5abbace413b59421527a31113406c97815c", "raw": {"market": "0xcab7ba4a9133cfd407d7e73e5757e5abbace413b59421527a31113406c97815c", "asset_id": "20002636398944597965698652220992177552927816915094913583821579024925426590022", "price": "0.991", "size": "818.33", "side": "SELL", "timestamp": "1768475187336", "received_at": "2026-01-15T12:06:27.460221"}}
{"event_type": "price_change", "event_ts": "2026-01-15T12:06:28.815508", "ingestion_ts": "2026-01-15T12:08:42.168746", "market_id": "0xc0e6b917320a47228fb96e3b5ae0e5c93773a5ae2662ae4e1f37807cfe47ce98", "raw": {"market": "0xc0e6b917320a47228fb96e3b5ae0e5c93773a5ae2662ae4e1f37807cfe47ce98", "asset_id": "58656358377246279051017109359677190749228949103591068167284263961542487110215", "price": "0.003", "size": "417.33", "side": "BUY", "timestamp": "1768475188618", "received_at": "2026-01-15T12:06:28.815508"}}
{"event_type": "price_change", "event_ts": "2026-01-15T12:06:28.815508", "ingestion_ts": "2026-01-15T12:08:42.168746", "market_id": "0xc0e6b917320a47228fb96e3b5ae0e5c93773a5ae2662ae4e1f37807cfe47ce98", "raw": {"market": "0xc0e6b917320a47228fb96e3b5ae0e5c93773a5ae2662ae4e1f37807cfe47ce98", "asset_id": "81647294538046680798858716589766492074338758116170717123345952330712416337530", "price": "0.997", "size": "417.33", "side": "SELL", "timestamp": "1768475188618", "received_at": "2026-01-15T12:06:28.815508"}}
{"event_type": "price_change", "event_ts": "2026-01-15T12:06:29.506075", "ingestion_ts": "2026-01-15T12:08:42.168746", "market_id": "0xc0e6b917320a47228fb96e3b5ae0e5c93773a5ae2662ae4e1f37807cfe47ce98", "raw": {"market": "0xc0e6b917320a47228fb96e3b5ae0e5c93773a5ae2662ae4e1f37807cfe47ce98", "asset_id": "58656358377246279051017109359677190749228949103591068167284263961542487110215", "price": "0.004", "size": "16.08", "side": "BUY", "timestamp": "1768475189343", "received_at": "2026-01-15T12:06:29.506075"}}
{"event_type": "price_change", "event_ts": "2026-01-15T12:06:29.506075", "ingestion_ts": "2026-01-15T12:08:42.168746", "market_id": "0xc0e6b917320a47228fb96e3b5ae0e5c93773a5ae2662ae4e1f37807cfe47ce98", "raw": {"market": "0xc0e6b917320a47228fb96e3b5ae0e5c93773a5ae2662ae4e1f37807cfe47ce98", "asset_id": "81647294538046680798858716589766492074338758116170717123345952330712416337530", "price": "0.996", "size": "16.08", "side": "SELL", "timestamp": "1768475189343", "received_at": "2026-01-15T12:06:29.506075"}}
{"event_type": "price_change", "event_ts": "2026-01-15T12:06:29.506113", "ingestion_ts": "2026-01-15T12:08:42.168746", "market_id": "0xc0e6b917320a47228fb96e3b5ae0e5c93773a5ae2662ae4e1f37807cfe47ce98", "raw": {"market": "0xc0e6b917320a47228fb96e3b5ae0e5c93773a5ae2662ae4e1f37807cfe47ce98", "asset_id": "58656358377246279051017109359677190749228949103591068167284263961542487110215", "price": "0.004", "size": "32.16", "side": "BUY", "timestamp": "1768475189344", "received_at": "2026-01-15T12:06:29.506113"}}
{"event_type": "price_change", "event_ts": "2026-01-15T12:06:29.506113", "ingestion_ts": "2026-01-15T12:08:42.168746", "market_id": "0xc0e6b917320a47228fb96e3b5ae0e5c93773a5ae2662ae4e1f37807cfe47ce98", "raw": {"market": "0xc0e6b917320a47228fb96e3b5ae0e5c93773a5ae2662ae4e1f37807cfe47ce98", "asset_id": "81647294538046680798858716589766492074338758116170717123345952330712416337530", "price": "0.996", "size": "32.16", "side": "SELL", "timestamp": "1768475189344", "received_at": "2026-01-15T12:06:29.506113"}}
{"event_type": "price_change", "event_ts": "2026-01-15T12:06:29.924284", "ingestion_ts": "2026-01-15T12:08:42.168746", "market_id": "0xcab7ba4a9133cfd407d7e73e5757e5abbace413b59421527a31113406c97815c", "raw": {"market": "0xcab7ba4a9133cfd407d7e73e5757e5abbace413b59421527a31113406c97815c", "asset_id": "96361925776989336186111887920533578209326565663637092688733016597062311745569", "price": "0.006", "size": "127.41", "side": "BUY", "timestamp": "1768475189798", "received_at": "2026-01-15T12:06:29.924284"}}
{"event_type": "price_change", "event_ts": "2026-01-15T12:06:29.924284", "ingestion_ts": "2026-01-15T12:08:42.168746", "market_id": "0xcab7ba4a9133cfd407d7e73e5757e5abbace413b59421527a31113406c97815c", "raw": {"market": "0xcab7ba4a9133cfd407d7e73e5757e5abbace413b59421527a31113406c97815c", "asset_id": "20002636398944597965698652220992177552927816915094913583821579024925426590022", "price": "0.994", "size": "127.41", "side": "SELL", "timestamp": "1768475189798", "received_at": "2026-01-15T12:06:29.924284"}}
{"event_type": "price_change", "event_ts": "2026-01-15T12:06:29.924374", "ingestion_ts": "2026-01-15T12:08:42.168746", "market_id": "0xcab7ba4a9133cfd407d7e73e5757e5abbace413b59421527a31113406c97815c", "raw": {"market": "0xcab7ba4a9133cfd407d7e73e5757e5abbace413b59421527a31113406c97815c", "asset_id": "96361925776989336186111887920533578209326565663637092688733016597062311745569", "price": "0.009", "size": "812.25", "side": "BUY", "timestamp": "1768475189798", "received_at": "2026-01-15T12:06:29.924374"}}
{"event_type": "price_change", "event_ts": "2026-01-15T12:06:29.924374", "ingestion_ts": "2026-01-15T12:08:42.168746", "market_id": "0xcab7ba4a9133cfd407d7e73e5757e5abbace413b59421527a31113406c97815c", "raw": {"market": "0xcab7ba4a9133cfd407d7e73e5757e5abbace413b59421527a31113406c97815c", "asset_id": "20002636398944597965698652220992177552927816915094913583821579024925426590022", "price": "0.991", "size": "812.25", "side": "SELL", "timestamp": "1768475189798", "received_at": "2026-01-15T12:06:29.924374"}}
{"event_type": "price_change", "event_ts": "2026-01-15T12:06:31.100774", "ingestion_ts": "2026-01-15T12:08:42.168746", "market_id": "0xcab7ba4a9133cfd407d7e73e5757e5abbace413b59421527a31113406c97815c", "raw": {"market": "0xcab7ba4a9133cfd407d7e73e5757e5abbace413b59421527a31113406c97815c", "asset_id": "96361925776989336186111887920533578209326565663637092688733016597062311745569", "price": "0.009", "size": "818.33", "side": "BUY", "timestamp": "1768475190977", "received_at": "2026-01-15T12:06:31.100774"}}
{"event_type": "price_change", "event_ts": "2026-01-15T12:06:31.100774", "ingestion_ts": "2026-01-15T12:08:42.168746", "market_id": "0xcab7ba4a9133cfd407d7e73e5757e5abbace413b59421527a31113406c97815c", "raw": {"market": "0xcab7ba4a9133cfd407d7e73e5757e5abbace413b59421527a31113406c97815c", "asset_id": "20002636398944597965698652220992177552927816915094913583821579024925426590022", "price": "0.991", "size": "818.33", "side": "SELL", "timestamp": "1768475190977", "received_at": "2026-01-15T12:06:31.100774"}}
{"event_type": "price_change", "event_ts": "2026-01-15T12:06:31.100810", "ingestion_ts": "2026-01-15T12:08:42.168746", "market_id": "0xcab7ba4a9133cfd407d7e73e5757e5abbace413b59421527a31113406c97815c", "raw": {"market": "0xcab7ba4a9133cfd407d7e73e5757e5abbace413b59421527a31113406c97815c", "asset_id": "96361925776989336186111887920533578209326565663637092688733016597062311745569", "price": "0.006", "size": "136.51", "side": "BUY", "timestamp": "1768475190978", "received_at": "2026-01-15T12:06:31.100810"}}
{"event_type": "price_change", "event_ts": "2026-01-15T12:06:31.100810", "ingestion_ts": "2026-01-15T12:08:42.168746", "market_id": "0xcab7ba4a9133cfd407d7e73e5757e5abbace413b59421527a31113406c97815c", "raw": {"market": "0xcab7ba4a9133cfd407d7e73e5757e5abbace413b59421527a31113406c97815c", "asset_id": "20002636398944597965698652220992177552927816915094913583821579024925426590022", "price": "0.994", "size": "136.51", "side": "SELL", "timestamp": "1768475190978", "received_at": "2026-01-15T12:06:31.100810"}}
{"event_type": "price_change", "event_ts": "2026-01-15T12:06:31.502968", "ingestion_ts": "2026-01-15T12:08:42.168746", "market_id": "0xc0e6b917320a47228fb96e3b5ae0e5c93773a5ae2662ae4e1f37807cfe47ce98", "raw": {"market": "0xc0e6b917320a47228fb96e3b5ae0e5c93773a5ae2662ae4e1f37807cfe47ce98", "asset_id": "58656358377246279051017109359677190749228949103591068167284263961542487110215", "price": "0.161", "size": "0", "side": "SELL", "timestamp": "1768475191339", "received_at": "2026-01-15T12:06:31.502968"}}
{"event_type": "price_change", "event_ts": "2026-01-15T12:06:31.502968", "ingestion_ts": "2026-01-15T12:08:42.168746", "market_id": "0xc0e6b917320a47228fb96e3b5ae0e5c93773a5ae2662ae4e1f37807cfe47ce98", "raw": {"market": "0xc0e6b917320a47228fb96e3b5ae0e5c93773a5ae2662ae4e1f37807cfe47ce98", "asset_id": "81647294538046680798858716589766492074338758116170717123345952330712416337530", "price": "0.839", "size": "0", "side": "BUY", "timestamp": "1768475191339", "received_at": "2026-01-15T12:06:31.502968"}}
{"event_type": "price_change", "event_ts": "2026-01-15T12:06:31.948069", "ingestion_ts": "2026-01-15T12:08:42.168746", "market_id": "0xc0e6b917320a47228fb96e3b5ae0e5c93773a5ae2662ae4e1f37807cfe47ce98", "raw": {"market": "0xc0e6b917320a47228fb96e3b5ae0e5c93773a5ae2662ae4e1f37807cfe47ce98", "asset_id": "58656358377246279051017109359677190749228949103591068167284263961542487110215", "price": "0.16", "size": "431", "side": "SELL", "timestamp": "1768475191828", "received_at": "2026-01-15T12:06:31.948069"}}
{"event_type": "price_change", "event_ts": "2026-01-15T12:06:31.948069", "ingestion_ts": "2026-01-15T12:08:42.168746", "market_id": "0xc0e6b917320a47228fb96e3b5ae0e5c93773a5ae2662ae4e1f37807cfe47ce98", "raw": {"market": "0xc0e6b917320a47228fb96e3b5ae0e5c93773a5ae2662ae4e1f37807cfe47ce98", "asset_id": "81647294538046680798858716589766492074338758116170717123345952330712416337530", "price": "0.84", "size": "431", "side": "BUY", "timestamp": "1768475191828", "received_at": "2026-01-15T12:06:31.948069"}}
{"event_type": "price_change", "event_ts": "2026-01-15T12:06:32.779650", "ingestion_ts": "2026-01-15T12:08:42.168746", "market_id": "0xcab7ba4a9133cfd407d7e73e5757e5abbace413b59421527a31113406c97815c", "raw": {"market": "0xcab7ba4a9133cfd407d7e73e5757e5abbace413b59421527a31113406c97815c", "asset_id": "96361925776989336186111887920533578209326565663637092688733016597062311745569", "price": "0.006", "size": "127.41", "side": "BUY", "timestamp": "1768475192659", "received_at": "2026-01-15T12:06:32.779650"}}
{"event_type": "price_change", "event_ts": "2026-01-15T12:06:32.779650", "ingestion_ts": "2026-01-15T12:08:42.168746", "market_id": "0xcab7ba4a9133cfd407d7e73e5757e5abbace413b59421527a31113406c97815c", "raw": {"market": "0xcab7ba4a9133cfd407d7e73e5757e5abbace413b59421527a31113406c97815c", "asset_id": "20002636398944597965698652220992177552927816915094913583821579024925426590022", "price": "0.994", "size": "127.41", "side": "SELL", "timestamp": "1768475192659", "received_at": "2026-01-15T12:06:32.779650"}}
{"event_type": "price_change", "event_ts": "2026-01-15T12:06:32.779687", "ingestion_ts": "2026-01-15T12:08:42.168746", "market_id": "0xcab7ba4a9133cfd407d7e73e5757e5abbace413b59421527a31113406c97815c", "raw": {"market": "0xcab7ba4a9133cfd407d7e73e5757e5abbace413b59421527a31113406c97815c", "asset_id": "96361925776989336186111887920533578209326565663637092688733016597062311745569", "price": "0.009", "size": "812.25", "side": "BUY", "timestamp": "1768475192659", "received_at": "2026-01-15T12:06:32.779687"}}
{"event_type": "price_change", "event_ts": "2026-01-15T12:06:32.779687", "ingestion_ts": "2026-01-15T12:08:42.168746", "market_id": "0xcab7ba4a9133cfd407d7e73e5757e5abbace413b59421527a31113406c97815c", "raw": {"market": "0xcab7ba4a9133cfd407d7e73e5757e5abbace413b59421527a31113406c97815c", "asset_id": "20002636398944597965698652220992177552927816915094913583821579024925426590022", "price": "0.991", "size": "812.25", "side": "SELL", "timestamp": "1768475192659", "received_at": "2026-01-15T12:06:32.779687"}}
{"event_type": "price_change", "event_ts": "2026-01-15T12:06:33.172323", "ingestion_ts": "2026-01-15T12:08:42.168746", "market_id": "0xcab7ba4a9133cfd407d7e73e5757e5abbace413b59421527a31113406c97815c", "raw": {"market": "0xcab7ba4a9133cfd407d7e73e5757e5abbace413b59421527a31113406c97815c", "asset_id": "96361925776989336186111887920533578209326565663637092688733016597062311745569", "price": "0.006", "size": "136.51", "side": "BUY", "timestamp": "1768475193051", "received_at": "2026-01-15T12:06:33.172323"}}
{"event_type": "price_change", "event_ts": "2026-01-15T12:06:33.172323", "ingestion_ts": "2026-01-15T12:08:42.168746", "market_id": "0xcab7ba4a9133cfd407d7e73e5757e5abbace413b59421527a31113406c97815c", "raw": {"market": "0xcab7ba4a9133cfd407d7e73e5757e5abbace413b59421527a31113406c97815c", "asset_id": "20002636398944597965698652220992177552927816915094913583821579024925426590022", "price": "0.994", "size": "136.51", "side": "SELL", "timestamp": "1768475193051", "received_at": "2026-01-15T12:06:33.172323"}}
{"event_type": "price_change", "event_ts": "2026-01-15T12:06:33.172401", "ingestion_ts": "2026-01-15T12:08:42.168746", "market_id": "0xcab7ba4a9133cfd407d7e73e5757e5abbace413b59421527a31113406c97815c", "raw": {"market": "0xcab7ba4a9133cfd407d7e73e5757e5abbace413b59421527a31113406c97815c", "asset_id": "96361925776989336186111887920533578209326565663637092688733016597062311745569", "price": "0.009", "size": "818.33", "side": "BUY", "timestamp": "1768475193052", "received_at": "2026-01-15T12:06:33.172401"}}
{"event_type": "price_change", "event_ts": "2026-01-15T12:06:33.172401", "ingestion_ts": "2026-01-15T12:08:42.168746", "market_id": "0xcab7ba4a9133cfd407d7e73e5757e5abbace413b59421527a31113406c97815c", "raw": {"market": "0xcab7ba4a9133cfd407d7e73e5757e5abbace413b59421527a31113406c97815c", "asset_id": "20002636398944597965698652220992177552927816915094913583821579024925426590022", "price": "0.991", "size": "818.33", "side": "SELL", "timestamp": "1768475193052", "received_at": "2026-01-15T12:06:33.172401"}}
{"event_type": "price_change", "event_ts": "2026-01-15T12:06:33.662225", "ingestion_ts": "2026-01-15T12:08:42.168746", "market_id": "0xc0e6b917320a47228fb96e3b5ae0e5c93773a5ae2662ae4e1f37807cfe47ce98", "raw": {"market": "0xc0e6b917320a47228fb96e3b5ae0e5c93773a5ae2662ae4e1f37807cfe47ce98", "asset_id": "58656358377246279051017109359677190749228949103591068167284263961542487110215", "price": "0.004", "size": "16.08", "side": "BUY", "timestamp": "1768475193528", "received_at": "2026-01-15T12:06:33.662225"}}
{"event_type": "price_change", "event_ts": "2026-01-15T12:06:33.662225", "ingestion_ts": "2026-01-15T12:08:42.168746", "market_id": "0xc0e6b917320a47228fb96e3b5ae0e5c93773a5ae2662ae4e1f37807cfe47ce98", "raw": {"market": "0xc0e6b917320a47228fb96e3b5ae0e5c93773a5ae2662ae4e1f37807cfe47ce98", "asset_id": "81647294538046680798858716589766492074338758116170717123345952330712416337530", "price": "0.996", "size": "16.08", "side": "SELL", "timestamp": "1768475193528", "received_at": "2026-01-15T12:06:33.662225"}}
{"event_type": "price_change", "event_ts": "2026-01-15T12:06:33.694768", "ingestion_ts": "2026-01-15T12:08:42.168746", "market_id": "0xea644975be7b2ad32b536a94ae21b707ecb2f84290225b24e60ca46dd77903dd", "raw": {"market": "0xea644975be7b2ad32b536a94ae21b707ecb2f84290225b24e60ca46dd77903dd", "asset_id": "19255594762111702415265750364124818677094538461124581923455280001407159960455", "price": "0.851", "size": "0", "side": "BUY", "timestamp": "1768475193577", "received_at": "2026-01-15T12:06:33.694768"}}
{"event_type": "price_change", "event_ts": "2026-01-15T12:06:33.694768", "ingestion_ts": "2026-01-15T12:08:42.168746", "market_id": "0xea644975be7b2ad32b536a94ae21b707ecb2f84290225b24e60ca46dd77903dd", "raw": {"market": "0xea644975be7b2ad32b536a94ae21b707ecb2f84290225b24e60ca46dd77903dd", "asset_id": "110044455628775971785618539427229099821815416148768008176051068105157446559241", "price": "0.149", "size": "0", "side": "SELL", "timestamp": "1768475193577", "received_at": "2026-01-15T12:06:33.694768"}}
{"event_type": "price_change", "event_ts": "2026-01-15T12:06:33.694804", "ingestion_ts": "2026-01-15T12:08:42.168746", "market_id": "0xe68594f1350f5535532b24979b5b5c1948432cbfc0c363802c32a8f9ab4e6509", "raw": {"market": "0xe68594f1350f5535532b24979b5b5c1948432cbfc0c363802c32a8f9ab4e6509", "asset_id": "3074032031589250926591186368301243337494992039402397918135503567058257050088", "price": "0.851", "size": "0", "side": "BUY", "timestamp": "1768475193577", "received_at": "2026-01-15T12:06:33.694804"}}
{"event_type": "price_change", "event_ts": "2026-01-15T12:06:33.694804", "ingestion_ts": "2026-01-15T12:08:42.168746", "market_id": "0xe68594f1350f5535532b24979b5b5c1948432cbfc0c363802c32a8f9ab4e6509", "raw": {"market": "0xe68594f1350f5535532b24979b5b5c1948432cbfc0c363802c32a8f9ab4e6509", "asset_id": "47459180813047899567328389455747872955901265556145057896316155826890276004242", "price": "0.149", "size": "0", "side": "SELL", "timestamp": "1768475193577", "received_at": "2026-01-15T12:06:33.694804"}}
{"event_type": "price_change", "event_ts": "2026-01-15T12:06:33.694817", "ingestion_ts": "2026-01-15T12:08:42.168746", "market_id": "0x50e477f0b316a3d97d60486479657c63be0763834d0e2e8a30b1b86dc3c1c001", "raw": {"market": "0x50e477f0b316a3d97d60486479657c63be0763834d0e2e8a30b1b86dc3c1c001", "asset_id": "39981134260608444876865205057565852475343967395624370698967311821208058420507", "price": "0.851", "size": "0", "side": "BUY", "timestamp": "1768475193577", "received_at": "2026-01-15T12:06:33.694817"}}
{"event_type": "price_change", "event_ts": "2026-01-15T12:06:33.694817", "ingestion_ts": "2026-01-15T12:08:42.168746", "market_id": "0x50e477f0b316a3d97d60486479657c63be0763834d0e2e8a30b1b86dc3c1c001", "raw": {"market": "0x50e477f0b316a3d97d60486479657c63be0763834d0e2e8a30b1b86dc3c1c001", "asset_id": "60573178197991590327120832143415406583517170365625050489007297367895074266641", "price": "0.149", "size": "0", "side": "SELL", "timestamp": "1768475193577", "received_at": "2026-01-15T12:06:33.694817"}}
{"event_type": "price_change", "event_ts": "2026-01-15T12:06:34.383085", "ingestion_ts": "2026-01-15T12:08:42.168746", "market_id": "0xea644975be7b2ad32b536a94ae21b707ecb2f84290225b24e60ca46dd77903dd", "raw": {"market": "0xea644975be7b2ad32b536a94ae21b707ecb2f84290225b24e60ca46dd77903dd", "asset_id": "19255594762111702415265750364124818677094538461124581923455280001407159960455", "price": "0.851", "size": "10", "side": "BUY", "timestamp": "1768475194263", "received_at": "2026-01-15T12:06:34.383085"}}
{"event_type": "price_change", "event_ts": "2026-01-15T12:06:34.383085", "ingestion_ts": "2026-01-15T12:08:42.168746", "market_id": "0xea644975be7b2ad32b536a94ae21b707ecb2f84290225b24e60ca46dd77903dd", "raw": {"market": "0xea644975be7b2ad32b536a94ae21b707ecb2f84290225b24e60ca46dd77903dd", "asset_id": "110044455628775971785618539427229099821815416148768008176051068105157446559241", "price": "0.149", "size": "10", "side": "SELL", "timestamp": "1768475194263", "received_at": "2026-01-15T12:06:34.383085"}}
{"event_type": "price_change", "event_ts": "2026-01-15T12:06:34.383121", "ingestion_ts": "2026-01-15T12:08:42.168746", "market_id": "0xe68594f1350f5535532b24979b5b5c1948432cbfc0c363802c32a8f9ab4e6509", "raw": {"market": "0xe68594f1350f5535532b24979b5b5c1948432cbfc0c363802c32a8f9ab4e6509", "asset_id": "3074032031589250926591186368301243337494992039402397918135503567058257050088", "price": "0.851", "size": "10", "side": "BUY", "timestamp": "1768475194263", "received_at": "2026-01-15T12:06:34.383121"}}
{"event_type": "price_change", "event_ts": "2026-01-15T12:06:34.383121", "ingestion_ts": "2026-01-15T12:08:42.168746", "market_id": "0xe68594f1350f5535532b24979b5b5c1948432cbfc0c363802c32a8f9ab4e6509", "raw": {"market": "0xe68594f1350f5535532b24979b5b5c1948432cbfc0c363802c32a8f9ab4e6509", "asset_id": "47459180813047899567328389455747872955901265556145057896316155826890276004242", "price": "0.149", "size": "10", "side": "SELL", "timestamp": "1768475194263", "received_at": "2026-01-15T12:06:34.383121"}}
{"event_type": "price_change", "event_ts": "2026-01-15T12:06:34.383133", "ingestion_ts": "2026-01-15T12:08:42.168746", "market_id": "0x50e477f0b316a3d97d60486479657c63be0763834d0e2e8a30b1b86dc3c1c001", "raw": {"market": "0x50e477f0b316a3d97d60486479657c63be0763834d0e2e8a30b1b86dc3c1c001", "asset_id": "39981134260608444876865205057565852475343967395624370698967311821208058420507", "price": "0.851", "size": "10", "side": "BUY", "timestamp": "1768475194264", "received_at": "2026-01-15T12:06:34.383133"}}
{"event_type": "price_change", "event_ts": "2026-01-15T12:06:34.383133", "ingestion_ts": "2026-01-15T12:08:42.168746", "market_id": "0x50e477f0b316a3d97d60486479657c63be0763834d0e2e8a30b1b86dc3c1c001", "raw": {"market": "0x50e477f0b316a3d97d60486479657c63be0763834d0e2e8a30b1b86dc3c1c001", "asset_id": "60573178197991590327120832143415406583517170365625050489007297367895074266641", "price": "0.149", "size": "10", "side": "SELL", "timestamp": "1768475194264", "received_at": "2026-01-15T12:06:34.383133"}}
{"event_type": "price_change", "event_ts": "2026-01-15T12:06:34.864166", "ingestion_ts": "2026-01-15T12:08:42.168746", "market_id": "0xc0e6b917320a47228fb96e3b5ae0e5c93773a5ae2662ae4e1f37807cfe47ce98", "raw": {"market": "0xc0e6b917320a47228fb96e3b5ae0e5c93773a5ae2662ae4e1f37807cfe47ce98", "asset_id": "58656358377246279051017109359677190749228949103591068167284263961542487110215", "price": "0.005", "size": "12.58", "side": "BUY", "timestamp": "1768475194746", "received_at": "2026-01-15T12:06:34.864166"}}
{"event_type": "price_change", "event_ts": "2026-01-15T12:06:34.864166", "ingestion_ts": "2026-01-15T12:08:42.168746", "market_id": "0xc0e6b917320a47228fb96e3b5ae0e5c93773a5ae2662ae4e1f37807cfe47ce98", "raw": {"market": "0xc0e6b917320a47228fb96e3b5ae0e5c93773a5ae2662ae4e1f37807cfe47ce98", "asset_id": "81647294538046680798858716589766492074338758116170717123345952330712416337530", "price": "0.995", "size": "12.58", "side": "SELL", "timestamp": "1768475194746", "received_at": "2026-01-15T12:06:34.864166"}}
{"event_type": "price_change", "event_ts": "2026-01-15T12:06:34.868933", "ingestion_ts": "2026-01-15T12:08:42.168746", "market_id": "0xc0e6b917320a47228fb96e3b5ae0e5c93773a5ae2662ae4e1f37807cfe47ce98", "raw": {"market": "0xc0e6b917320a47228fb96e3b5ae0e5c93773a5ae2662ae4e1f37807cfe47ce98", "asset_id": "58656358377246279051017109359677190749228949103591068167284263961542487110215", "price": "0.003", "size": "422.77", "side": "BUY", "timestamp": "1768475194747", "received_at": "2026-01-15T12:06:34.868933"}}
{"event_type": "price_change", "event_ts": "2026-01-15T12:06:34.868933", "ingestion_ts": "2026-01-15T12:08:42.168746", "market_id": "0xc0e6b917320a47228fb96e3b5ae0e5c93773a5ae2662ae4e1f37807cfe47ce98", "raw": {"market": "0xc0e6b917320a47228fb96e3b5ae0e5c93773a5ae2662ae4e1f37807cfe47ce98", "asset_id": "81647294538046680798858716589766492074338758116170717123345952330712416337530", "price": "0.997", "size": "422.77", "side": "SELL", "timestamp": "1768475194747", "received_at": "2026-01-15T12:06:34.868933"}}
{"event_type": "price_change", "event_ts": "2026-01-15T12:06:35.870918", "ingestion_ts": "2026-01-15T12:08:42.168746", "market_id": "0xc0e6b917320a47228fb96e3b5ae0e5c93773a5ae2662ae4e1f37807cfe47ce98", "raw": {"market": "0xc0e6b917320a47228fb96e3b5ae0e5c93773a5ae2662ae4e1f37807cfe47ce98", "asset_id": "58656358377246279051017109359677190749228949103591068167284263961542487110215", "price": "0.16", "size": "426", "side": "SELL", "timestamp": "1768475195746", "received_at": "2026-01-15T12:06:35.870918"}}
{"event_type": "price_change", "event_ts": "2026-01-15T12:06:35.870918", "ingestion_ts": "2026-01-15T12:08:42.168746", "market_id": "0xc0e6b917320a47228fb96e3b5ae0e5c93773a5ae2662ae4e1f37807cfe47ce98", "raw": {"market": "0xc0e6b917320a47228fb96e3b5ae0e5c93773a5ae2662ae4e1f37807cfe47ce98", "asset_id": "81647294538046680798858716589766492074338758116170717123345952330712416337530", "price": "0.84", "size": "426", "side": "BUY", "timestamp": "1768475195746", "received_at": "2026-01-15T12:06:35.870918"}}
{"event_type": "price_change", "event_ts": "2026-01-15T12:06:36.302014", "ingestion_ts": "2026-01-15T12:08:42.168746", "market_id": "0xcab7ba4a9133cfd407d7e73e5757e5abbace413b59421527a31113406c97815c", "raw": {"market": "0xcab7ba4a9133cfd407d7e73e5757e5abbace413b59421527a31113406c97815c", "asset_id": "96361925776989336186111887920533578209326565663637092688733016597062311745569", "price": "0.006", "size": "127.41", "side": "BUY", "timestamp": "1768475196175", "received_at": "2026-01-15T12:06:36.302014"}}
{"event_type": "price_change", "event_ts": "2026-01-15T12:06:36.302014", "ingestion_ts": "2026-01-15T12:08:42.168746", "market_id": "0xcab7ba4a9133cfd407d7e73e5757e5abbace413b59421527a31113406c97815c", "raw": {"market": "0xcab7ba4a9133cfd407d7e73e5757e5abbace413b59421527a31113406c97815c", "asset_id": "20002636398944597965698652220992177552927816915094913583821579024925426590022", "price": "0.994", "size": "127.41", "side": "SELL", "timestamp": "1768475196175", "received_at": "2026-01-15T12:06:36.302014"}}
{"event_type": "price_change", "event_ts": "2026-01-15T12:06:36.302051", "ingestion_ts": "2026-01-15T12:08:42.168746", "market_id": "0xcab7ba4a9133cfd407d7e73e5757e5abbace413b59421527a31113406c97815c", "raw": {"market": "0xcab7ba4a9133cfd407d7e73e5757e5abbace413b59421527a31113406c97815c", "asset_id": "96361925776989336186111887920533578209326565663637092688733016597062311745569", "price": "0.009", "size": "812.25", "side": "BUY", "timestamp": "1768475196175", "received_at": "2026-01-15T12:06:36.302051"}}
{"event_type": "price_change", "event_ts": "2026-01-15T12:06:36.302051", "ingestion_ts": "2026-01-15T12:08:42.168746", "market_id": "0xcab7ba4a9133cfd407d7e73e5757e5abbace413b59421527a31113406c97815c", "raw": {"market": "0xcab7ba4a9133cfd407d7e73e5757e5abbace413b59421527a31113406c97815c", "asset_id": "20002636398944597965698652220992177552927816915094913583821579024925426590022", "price": "0.991", "size": "812.25", "side": "SELL", "timestamp": "1768475196175", "received_at": "2026-01-15T12:06:36.302051"}}
{"event_type": "price_change", "event_ts": "2026-01-15T12:06:36.470217", "ingestion_ts": "2026-01-15T12:08:42.168746", "market_id": "0xc0e6b917320a47228fb96e3b5ae0e5c93773a5ae2662ae4e1f37807cfe47ce98", "raw": {"market": "0xc0e6b917320a47228fb96e3b5ae0e5c93773a5ae2662ae4e1f37807cfe47ce98", "asset_id": "58656358377246279051017109359677190749228949103591068167284263961542487110215", "price": "0.159", "size": "5", "side": "SELL", "timestamp": "1768475196351", "received_at": "2026-01-15T12:06:36.470217"}}
{"event_type": "price_change", "event_ts": "2026-01-15T12:06:36.470217", "ingestion_ts": "2026-01-15T12:08:42.168746", "market_id": "0xc0e6b917320a47228fb96e3b5ae0e5c93773a5ae2662ae4e1f37807cfe47ce98", "raw": {"market": "0xc0e6b917320a47228fb96e3b5ae0e5c93773a5ae2662ae4e1f37807cfe47ce98", "asset_id": "81647294538046680798858716589766492074338758116170717123345952330712416337530", "price": "0.841", "size": "5", "side": "BUY", "timestamp": "1768475196351", "received_at": "2026-01-15T12:06:36.470217"}}
{"event_type": "price_change", "event_ts": "2026-01-15T12:06:36.822440", "ingestion_ts": "2026-01-15T12:08:42.168746", "market_id": "0xcab7ba4a9133cfd407d7e73e5757e5abbace413b59421527a31113406c97815c", "raw": {"market": "0xcab7ba4a9133cfd407d7e73e5757e5abbace413b59421527a31113406c97815c", "asset_id": "96361925776989336186111887920533578209326565663637092688733016597062311745569", "price": "0.009", "size": "818.33", "side": "BUY", "timestamp": "1768475196704", "received_at": "2026-01-15T12:06:36.822440"}}
{"event_type": "price_change", "event_ts": "2026-01-15T12:06:36.822440", "ingestion_ts": "2026-01-15T12:08:42.168746", "market_id": "0xcab7ba4a9133cfd407d7e73e5757e5abbace413b59421527a31113406c97815c", "raw": {"market": "0xcab7ba4a9133cfd407d7e73e5757e5abbace413b59421527a31113406c97815c", "asset_id": "20002636398944597965698652220992177552927816915094913583821579024925426590022", "price": "0.991", "size": "818.33", "side": "SELL", "timestamp": "1768475196704", "received_at": "2026-01-15T12:06:36.822440"}}
{"event_type": "price_change", "event_ts": "2026-01-15T12:06:36.822496", "ingestion_ts": "2026-01-15T12:08:42.168746", "market_id": "0xcab7ba4a9133cfd407d7e73e5757e5abbace413b59421527a31113406c97815c", "raw": {"market": "0xcab7ba4a9133cfd407d7e73e5757e5abbace413b59421527a31113406c97815c", "asset_id": "96361925776989336186111887920533578209326565663637092688733016597062311745569", "price": "0.006", "size": "136.51", "side": "BUY", "timestamp": "1768475196705", "received_at": "2026-01-15T12:06:36.822496"}}
{"event_type": "price_change", "event_ts": "2026-01-15T12:06:36.822496", "ingestion_ts": "2026-01-15T12:08:42.168746", "market_id": "0xcab7ba4a9133cfd407d7e73e5757e5abbace413b59421527a31113406c97815c", "raw": {"market": "0xcab7ba4a9133cfd407d7e73e5757e5abbace413b59421527a31113406c97815c", "asset_id": "20002636398944597965698652220992177552927816915094913583821579024925426590022", "price": "0.994", "size": "136.51", "side": "SELL", "timestamp": "1768475196705", "received_at": "2026-01-15T12:06:36.822496"}}
{"event_type": "price_change", "event_ts": "2026-01-15T12:06:38.088029", "ingestion_ts": "2026-01-15T12:08:42.168746", "market_id": "0xc0e6b917320a47228fb96e3b5ae0e5c93773a5ae2662ae4e1f37807cfe47ce98", "raw": {"market": "0xc0e6b917320a47228fb96e3b5ae0e5c93773a5ae2662ae4e1f37807cfe47ce98", "asset_id": "58656358377246279051017109359677190749228949103591068167284263961542487110215", "price": "0.004", "size": "0", "side": "BUY", "timestamp": "1768475197969", "received_at": "2026-01-15T12:06:38.088029"}}
{"event_type": "price_change", "event_ts": "2026-01-15T12:06:38.088029", "ingestion_ts": "2026-01-15T12:08:42.168746", "market_id": "0xc0e6b917320a47228fb96e3b5ae0e5c93773a5ae2662ae4e1f37807cfe47ce98", "raw": {"market": "0xc0e6b917320a47228fb96e3b5ae0e5c93773a5ae2662ae4e1f37807cfe47ce98", "asset_id": "81647294538046680798858716589766492074338758116170717123345952330712416337530", "price": "0.996", "size": "0", "side": "SELL", "timestamp": "1768475197969", "received_at": "2026-01-15T12:06:38.088029"}}
{"event_type": "price_change", "event_ts": "2026-01-15T12:06:38.088064", "ingestion_ts": "2026-01-15T12:08:42.168746", "market_id": "0xc0e6b917320a47228fb96e3b5ae0e5c93773a5ae2662ae4e1f37807cfe47ce98", "raw": {"market": "0xc0e6b917320a47228fb96e3b5ae0e5c93773a5ae2662ae4e1f37807cfe47ce98", "asset_id": "58656358377246279051017109359677190749228949103591068167284263961542487110215", "price": "0.005", "size": "2.98", "side": "BUY", "timestamp": "1768475197969", "received_at": "2026-01-15T12:06:38.088064"}}
{"event_type": "price_change", "event_ts": "2026-01-15T12:06:38.088064", "ingestion_ts": "2026-01-15T12:08:42.168746", "market_id": "0xc0e6b917320a47228fb96e3b5ae0e5c93773a5ae2662ae4e1f37807cfe47ce98", "raw": {"market": "0xc0e6b917320a47228fb96e3b5ae0e5c93773a5ae2662ae4e1f37807cfe47ce98", "asset_id": "81647294538046680798858716589766492074338758116170717123345952330712416337530", "price": "0.995", "size": "2.98", "side": "SELL", "timestamp": "1768475197969", "received_at": "2026-01-15T12:06:38.088064"}}
{"event_type": "price_change", "event_ts": "2026-01-15T12:06:38.103738", "ingestion_ts": "2026-01-15T12:08:42.168746", "market_id": "0xcab7ba4a9133cfd407d7e73e5757e5abbace413b59421527a31113406c97815c", "raw": {"market": "0xcab7ba4a9133cfd407d7e73e5757e5abbace413b59421527a31113406c97815c", "asset_id": "96361925776989336186111887920533578209326565663637092688733016597062311745569", "price": "0.006", "size": "127.41", "side": "BUY", "timestamp": "1768475197969", "received_at": "2026-01-15T12:06:38.103738"}}
{"event_type": "price_change", "event_ts": "2026-01-15T12:06:38.103738", "ingestion_ts": "2026-01-15T12:08:42.168746", "market_id": "0xcab7ba4a9133cfd407d7e73e5757e5abbace413b59421527a31113406c97815c", "raw": {"market": "0xcab7ba4a9133cfd407d7e73e5757e5abbace413b59421527a31113406c97815c", "asset_id": "20002636398944597965698652220992177552927816915094913583821579024925426590022", "price": "0.994", "size": "127.41", "side": "SELL", "timestamp": "1768475197969", "received_at": "2026-01-15T12:06:38.103738"}}
{"event_type": "price_change", "event_ts": "2026-01-15T12:06:38.103775", "ingestion_ts": "2026-01-15T12:08:42.168746", "market_id": "0xcab7ba4a9133cfd407d7e73e5757e5abbace413b59421527a31113406c97815c", "raw": {"market": "0xcab7ba4a9133cfd407d7e73e5757e5abbace413b59421527a31113406c97815c", "asset_id": "96361925776989336186111887920533578209326565663637092688733016597062311745569", "price": "0.009", "size": "812.25", "side": "BUY", "timestamp": "1768475197969", "received_at": "2026-01-15T12:06:38.103775"}}
{"event_type": "price_change", "event_ts": "2026-01-15T12:06:38.103775", "ingestion_ts": "2026-01-15T12:08:42.168746", "market_id": "0xcab7ba4a9133cfd407d7e73e5757e5abbace413b59421527a31113406c97815c", "raw": {"market": "0xcab7ba4a9133cfd407d7e73e5757e5abbace413b59421527a31113406c97815c", "asset_id": "20002636398944597965698652220992177552927816915094913583821579024925426590022", "price": "0.991", "size": "812.25", "side": "SELL", "timestamp": "1768475197969", "received_at": "2026-01-15T12:06:38.103775"}}
{"event_type": "price_change", "event_ts": "2026-01-15T12:06:38.791294", "ingestion_ts": "2026-01-15T12:08:42.168746", "market_id": "0xc0e6b917320a47228fb96e3b5ae0e5c93773a5ae2662ae4e1f37807cfe47ce98", "raw": {"market": "0xc0e6b917320a47228fb96e3b5ae0e5c93773a5ae2662ae4e1f37807cfe47ce98", "asset_id": "58656358377246279051017109359677190749228949103591068167284263961542487110215", "price": "0.005", "size": "8.65", "side": "BUY", "timestamp": "1768475198665", "received_at": "2026-01-15T12:06:38.791294"}}
{"event_type": "price_change", "event_ts": "2026-01-15T12:06:38.791294", "ingestion_ts": "2026-01-15T12:08:42.168746", "market_id": "0xc0e6b917320a47228fb96e3b5ae0e5c93773a5ae2662ae4e1f37807cfe47ce98", "raw": {"market": "0xc0e6b917320a47228fb96e3b5ae0e5c93773a5ae2662ae4e1f37807cfe47ce98", "asset_id": "81647294538046680798858716589766492074338758116170717123345952330712416337530", "price": "0.995", "size": "8.65", "side": "SELL", "timestamp": "1768475198665", "received_at": "2026-01-15T12:06:38.791294"}}
{"event_type": "price_change", "event_ts": "2026-01-15T12:06:38.791386", "ingestion_ts": "2026-01-15T12:08:42.168746", "market_id": "0xcab7ba4a9133cfd407d7e73e5757e5abbace413b59421527a31113406c97815c", "raw": {"market": "0xcab7ba4a9133cfd407d7e73e5757e5abbace413b59421527a31113406c97815c", "asset_id": "96361925776989336186111887920533578209326565663637092688733016597062311745569", "price": "0.009", "size": "818.33", "side": "BUY", "timestamp": "1768475198665", "received_at": "2026-01-15T12:06:38.791386"}}
{"event_type": "price_change", "event_ts": "2026-01-15T12:06:38.791386", "ingestion_ts": "2026-01-15T12:08:42.168746", "market_id": "0xcab7ba4a9133cfd407d7e73e5757e5abbace413b59421527a31113406c97815c", "raw": {"market": "0xcab7ba4a9133cfd407d7e73e5757e5abbace413b59421527a31113406c97815c", "asset_id": "20002636398944597965698652220992177552927816915094913583821579024925426590022", "price": "0.991", "size": "818.33", "side": "SELL", "timestamp": "1768475198665", "received_at": "2026-01-15T12:06:38.791386"}}
{"event_type": "price_change", "event_ts": "2026-01-15T12:06:38.791422", "ingestion_ts": "2026-01-15T12:08:42.168746", "market_id": "0xcab7ba4a9133cfd407d7e73e5757e5abbace413b59421527a31113406c97815c", "raw": {"market": "0xcab7ba4a9133cfd407d7e73e5757e5abbace413b59421527a31113406c97815c", "asset_id": "96361925776989336186111887920533578209326565663637092688733016597062311745569", "price": "0.006", "size": "136.51", "side": "BUY", "timestamp": "1768475198666", "received_at": "2026-01-15T12:06:38.791422"}}
{"event_type": "price_change", "event_ts": "2026-01-15T12:06:38.791422", "ingestion_ts": "2026-01-15T12:08:42.168746", "market_id": "0xcab7ba4a9133cfd407d7e73e5757e5abbace413b59421527a31113406c97815c", "raw": {"market": "0xcab7ba4a9133cfd407d7e73e5757e5abbace413b59421527a31113406c97815c", "asset_id": "20002636398944597965698652220992177552927816915094913583821579024925426590022", "price": "0.994", "size": "136.51", "side": "SELL", "timestamp": "1768475198666", "received_at": "2026-01-15T12:06:38.791422"}}
{"event_type": "price_change", "event_ts": "2026-01-15T12:06:38.792660", "ingestion_ts": "2026-01-15T12:08:42.168746", "market_id": "0xc0e6b917320a47228fb96e3b5ae0e5c93773a5ae2662ae4e1f37807cfe47ce98", "raw": {"market": "0xc0e6b917320a47228fb96e3b5ae0e5c93773a5ae2662ae4e1f37807cfe47ce98", "asset_id": "58656358377246279051017109359677190749228949103591068167284263961542487110215", "price": "0.005", "size": "14.32", "side": "BUY", "timestamp": "1768475198666", "received_at": "2026-01-15T12:06:38.792660"}}
{"event_type": "price_change", "event_ts": "2026-01-15T12:06:38.792660", "ingestion_ts": "2026-01-15T12:08:42.168746", "market_id": "0xc0e6b917320a47228fb96e3b5ae0e5c93773a5ae2662ae4e1f37807cfe47ce98", "raw": {"market": "0xc0e6b917320a47228fb96e3b5ae0e5c93773a5ae2662ae4e1f37807cfe47ce98", "asset_id": "81647294538046680798858716589766492074338758116170717123345952330712416337530", "price": "0.995", "size": "14.32", "side": "SELL", "timestamp": "1768475198666", "received_at": "2026-01-15T12:06:38.792660"}}
{"event_type": "price_change", "event_ts": "2026-01-15T12:06:38.796753", "ingestion_ts": "2026-01-15T12:08:42.168746", "market_id": "0xc0e6b917320a47228fb96e3b5ae0e5c93773a5ae2662ae4e1f37807cfe47ce98", "raw": {"market": "0xc0e6b917320a47228fb96e3b5ae0e5c93773a5ae2662ae4e1f37807cfe47ce98", "asset_id": "58656358377246279051017109359677190749228949103591068167284263961542487110215", "price": "0.006", "size": "9.25", "side": "BUY", "timestamp": "1768475198667", "received_at": "2026-01-15T12:06:38.796753"}}
{"event_type": "price_change", "event_ts": "2026-01-15T12:06:38.796753", "ingestion_ts": "2026-01-15T12:08:42.168746", "market_id": "0xc0e6b917320a47228fb96e3b5ae0e5c93773a5ae2662ae4e1f37807cfe47ce98", "raw": {"market": "0xc0e6b917320a47228fb96e3b5ae0e5c93773a5ae2662ae4e1f37807cfe47ce98", "asset_id": "81647294538046680798858716589766492074338758116170717123345952330712416337530", "price": "0.994", "size": "9.25", "side": "SELL", "timestamp": "1768475198667", "received_at": "2026-01-15T12:06:38.796753"}}
{"event_type": "price_change", "event_ts": "2026-01-15T12:06:41.902835", "ingestion_ts": "2026-01-15T12:08:42.168746", "market_id": "0xcab7ba4a9133cfd407d7e73e5757e5abbace413b59421527a31113406c97815c", "raw": {"market": "0xcab7ba4a9133cfd407d7e73e5757e5abbace413b59421527a31113406c97815c", "asset_id": "96361925776989336186111887920533578209326565663637092688733016597062311745569", "price": "0.006", "size": "127.41", "side": "BUY", "timestamp": "1768475201776", "received_at": "2026-01-15T12:06:41.902835"}}
{"event_type": "price_change", "event_ts": "2026-01-15T12:06:41.902835", "ingestion_ts": "2026-01-15T12:08:42.168746", "market_id": "0xcab7ba4a9133cfd407d7e73e5757e5abbace413b59421527a31113406c97815c", "raw": {"market": "0xcab7ba4a9133cfd407d7e73e5757e5abbace413b59421527a31113406c97815c", "asset_id": "20002636398944597965698652220992177552927816915094913583821579024925426590022", "price": "0.994", "size": "127.41", "side": "SELL", "timestamp": "1768475201776", "received_at": "2026-01-15T12:06:41.902835"}}
{"event_type": "price_change", "event_ts": "2026-01-15T12:06:41.902935", "ingestion_ts": "2026-01-15T12:08:42.168746", "market_id": "0xcab7ba4a9133cfd407d7e73e5757e5abbace413b59421527a31113406c97815c", "raw": {"market": "0xcab7ba4a9133cfd407d7e73e5757e5abbace413b59421527a31113406c97815c", "asset_id": "96361925776989336186111887920533578209326565663637092688733016597062311745569", "price": "0.009", "size": "812.25", "side": "BUY", "timestamp": "1768475201776", "received_at": "2026-01-15T12:06:41.902935"}}
{"event_type": "price_change", "event_ts": "2026-01-15T12:06:41.902935", "ingestion_ts": "2026-01-15T12:08:42.168746", "market_id": "0xcab7ba4a9133cfd407d7e73e5757e5abbace413b59421527a31113406c97815c", "raw": {"market": "0xcab7ba4a9133cfd407d7e73e5757e5abbace413b59421527a31113406c97815c", "asset_id": "20002636398944597965698652220992177552927816915094913583821579024925426590022", "price": "0.991", "size": "812.25", "side": "SELL", "timestamp": "1768475201776", "received_at": "2026-01-15T12:06:41.902935"}}
{"event_type": "price_change", "event_ts": "2026-01-15T12:06:42.424635", "ingestion_ts": "2026-01-15T12:08:42.168746", "market_id": "0xcab7ba4a9133cfd407d7e73e5757e5abbace413b59421527a31113406c97815c", "raw": {"market": "0xcab7ba4a9133cfd407d7e73e5757e5abbace413b59421527a31113406c97815c", "asset_id": "96361925776989336186111887920533578209326565663637092688733016597062311745569", "price": "0.009", "size": "818.33", "side": "BUY", "timestamp": "1768475202306", "received_at": "2026-01-15T12:06:42.424635"}}
{"event_type": "price_change", "event_ts": "2026-01-15T12:06:42.424635", "ingestion_ts": "2026-01-15T12:08:42.168746", "market_id": "0xcab7ba4a9133cfd407d7e73e5757e5abbace413b59421527a31113406c97815c", "raw": {"market": "0xcab7ba4a9133cfd407d7e73e5757e5abbace413b59421527a31113406c97815c", "asset_id": "20002636398944597965698652220992177552927816915094913583821579024925426590022", "price": "0.991", "size": "818.33", "side": "SELL", "timestamp": "1768475202306", "received_at": "2026-01-15T12:06:42.424635"}}
{"event_type": "price_change", "event_ts": "2026-01-15T12:06:42.424676", "ingestion_ts": "2026-01-15T12:08:42.168746", "market_id": "0xcab7ba4a9133cfd407d7e73e5757e5abbace413b59421527a31113406c97815c", "raw": {"market": "0xcab7ba4a9133cfd407d7e73e5757e5abbace413b59421527a31113406c97815c", "asset_id": "96361925776989336186111887920533578209326565663637092688733016597062311745569", "price": "0.006", "size": "136.51", "side": "BUY", "timestamp": "1768475202307", "received_at": "2026-01-15T12:06:42.424676"}}
{"event_type": "price_change", "event_ts": "2026-01-15T12:06:42.424676", "ingestion_ts": "2026-01-15T12:08:42.168746", "market_id": "0xcab7ba4a9133cfd407d7e73e5757e5abbace413b59421527a31113406c97815c", "raw": {"market": "0xcab7ba4a9133cfd407d7e73e5757e5abbace413b59421527a31113406c97815c", "asset_id": "20002636398944597965698652220992177552927816915094913583821579024925426590022", "price": "0.994", "size": "136.51", "side": "SELL", "timestamp": "1768475202307", "received_at": "2026-01-15T12:06:42.424676"}}
{"event_type": "price_change", "event_ts": "2026-01-15T12:06:42.943015", "ingestion_ts": "2026-01-15T12:08:42.168746", "market_id": "0xc0e6b917320a47228fb96e3b5ae0e5c93773a5ae2662ae4e1f37807cfe47ce98", "raw": {"market": "0xc0e6b917320a47228fb96e3b5ae0e5c93773a5ae2662ae4e1f37807cfe47ce98", "asset_id": "58656358377246279051017109359677190749228949103591068167284263961542487110215", "price": "0.005", "size": "8.65", "side": "BUY", "timestamp": "1768475202763", "received_at": "2026-01-15T12:06:42.943015"}}
{"event_type": "price_change", "event_ts": "2026-01-15T12:06:42.943015", "ingestion_ts": "2026-01-15T12:08:42.168746", "market_id": "0xc0e6b917320a47228fb96e3b5ae0e5c93773a5ae2662ae4e1f37807cfe47ce98", "raw": {"market": "0xc0e6b917320a47228fb96e3b5ae0e5c93773a5ae2662ae4e1f37807cfe47ce98", "asset_id": "81647294538046680798858716589766492074338758116170717123345952330712416337530", "price": "0.995", "size": "8.65", "side": "SELL", "timestamp": "1768475202763", "received_at": "2026-01-15T12:06:42.943015"}}
{"event_type": "price_change", "event_ts": "2026-01-15T12:06:42.943126", "ingestion_ts": "2026-01-15T12:08:42.168746", "market_id": "0xc0e6b917320a47228fb96e3b5ae0e5c93773a5ae2662ae4e1f37807cfe47ce98", "raw": {"market": "0xc0e6b917320a47228fb96e3b5ae0e5c93773a5ae2662ae4e1f37807cfe47ce98", "asset_id": "58656358377246279051017109359677190749228949103591068167284263961542487110215", "price": "0.006", "size": "0", "side": "BUY", "timestamp": "1768475202763", "received_at": "2026-01-15T12:06:42.943126"}}
{"event_type": "price_change", "event_ts": "2026-01-15T12:06:42.943126", "ingestion_ts": "2026-01-15T12:08:42.168746", "market_id": "0xc0e6b917320a47228fb96e3b5ae0e5c93773a5ae2662ae4e1f37807cfe47ce98", "raw": {"market": "0xc0e6b917320a47228fb96e3b5ae0e5c93773a5ae2662ae4e1f37807cfe47ce98", "asset_id": "81647294538046680798858716589766492074338758116170717123345952330712416337530", "price": "0.994", "size": "0", "side": "SELL", "timestamp": "1768475202763", "received_at": "2026-01-15T12:06:42.943126"}}
{"event_type": "price_change", "event_ts": "2026-01-15T12:06:43.008751", "ingestion_ts": "2026-01-15T12:08:42.168746", "market_id": "0x50e477f0b316a3d97d60486479657c63be0763834d0e2e8a30b1b86dc3c1c001", "raw": {"market": "0x50e477f0b316a3d97d60486479657c63be0763834d0e2e8a30b1b86dc3c1c001", "asset_id": "39981134260608444876865205057565852475343967395624370698967311821208058420507", "price": "0.851", "size": "0", "side": "BUY", "timestamp": "1768475202853", "received_at": "2026-01-15T12:06:43.008751"}}
{"event_type": "price_change", "event_ts": "2026-01-15T12:06:43.008751", "ingestion_ts": "2026-01-15T12:08:42.168746", "market_id": "0x50e477f0b316a3d97d60486479657c63be0763834d0e2e8a30b1b86dc3c1c001", "raw": {"market": "0x50e477f0b316a3d97d60486479657c63be0763834d0e2e8a30b1b86dc3c1c001", "asset_id": "60573178197991590327120832143415406583517170365625050489007297367895074266641", "price": "0.149", "size": "0", "side": "SELL", "timestamp": "1768475202853", "received_at": "2026-01-15T12:06:43.008751"}}
{"event_type": "price_change", "event_ts": "2026-01-15T12:06:43.008842", "ingestion_ts": "2026-01-15T12:08:42.168746", "market_id": "0xea644975be7b2ad32b536a94ae21b707ecb2f84290225b24e60ca46dd77903dd", "raw": {"market": "0xea644975be7b2ad32b536a94ae21b707ecb2f84290225b24e60ca46dd77903dd", "asset_id": "19255594762111702415265750364124818677094538461124581923455280001407159960455", "price": "0.851", "size": "0", "side": "BUY", "timestamp": "1768475202853", "received_at": "2026-01-15T12:06:43.008842"}}
{"event_type": "price_change", "event_ts": "2026-01-15T12:06:43.008842", "ingestion_ts": "2026-01-15T12:08:42.168746", "market_id": "0xea644975be7b2ad32b536a94ae21b707ecb2f84290225b24e60ca46dd77903dd", "raw": {"market": "0xea644975be7b2ad32b536a94ae21b707ecb2f84290225b24e60ca46dd77903dd", "asset_id": "110044455628775971785618539427229099821815416148768008176051068105157446559241", "price": "0.149", "size": "0", "side": "SELL", "timestamp": "1768475202853", "received_at": "2026-01-15T12:06:43.008842"}}
{"event_type": "price_change", "event_ts": "2026-01-15T12:06:43.008883", "ingestion_ts": "2026-01-15T12:08:42.168746", "market_id": "0xe68594f1350f5535532b24979b5b5c1948432cbfc0c363802c32a8f9ab4e6509", "raw": {"market": "0xe68594f1350f5535532b24979b5b5c1948432cbfc0c363802c32a8f9ab4e6509", "asset_id": "3074032031589250926591186368301243337494992039402397918135503567058257050088", "price": "0.851", "size": "0", "side": "BUY", "timestamp": "1768475202853", "received_at": "2026-01-15T12:06:43.008883"}}
{"event_type": "price_change", "event_ts": "2026-01-15T12:06:43.008883", "ingestion_ts": "2026-01-15T12:08:42.168746", "market_id": "0xe68594f1350f5535532b24979b5b5c1948432cbfc0c363802c32a8f9ab4e6509", "raw": {"market": "0xe68594f1350f5535532b24979b5b5c1948432cbfc0c363802c32a8f9ab4e6509", "asset_id": "47459180813047899567328389455747872955901265556145057896316155826890276004242", "price": "0.149", "size": "0", "side": "SELL", "timestamp": "1768475202853", "received_at": "2026-01-15T12:06:43.008883"}}
{"event_type": "price_change", "event_ts": "2026-01-15T12:06:43.052284", "ingestion_ts": "2026-01-15T12:08:42.168746", "market_id": "0xe68594f1350f5535532b24979b5b5c1948432cbfc0c363802c32a8f9ab4e6509", "raw": {"market": "0xe68594f1350f5535532b24979b5b5c1948432cbfc0c363802c32a8f9ab4e6509", "asset_id": "3074032031589250926591186368301243337494992039402397918135503567058257050088", "price": "0.852", "size": "5", "side": "BUY", "timestamp": "1768475202925", "received_at": "2026-01-15T12:06:43.052284"}}
{"event_type": "price_change", "event_ts": "2026-01-15T12:06:43.052284", "ingestion_ts": "2026-01-15T12:08:42.168746", "market_id": "0xe68594f1350f5535532b24979b5b5c1948432cbfc0c363802c32a8f9ab4e6509", "raw": {"market": "0xe68594f1350f5535532b24979b5b5c1948432cbfc0c363802c32a8f9ab4e6509", "asset_id": "47459180813047899567328389455747872955901265556145057896316155826890276004242", "price": "0.148", "size": "5", "side": "SELL", "timestamp": "1768475202925", "received_at": "2026-01-15T12:06:43.052284"}}
{"event_type": "price_change", "event_ts": "2026-01-15T12:06:43.052449", "ingestion_ts": "2026-01-15T12:08:42.168746", "market_id": "0xea644975be7b2ad32b536a94ae21b707ecb2f84290225b24e60ca46dd77903dd", "raw": {"market": "0xea644975be7b2ad32b536a94ae21b707ecb2f84290225b24e60ca46dd77903dd", "asset_id": "19255594762111702415265750364124818677094538461124581923455280001407159960455", "price": "0.852", "size": "5", "side": "BUY", "timestamp": "1768475202925", "received_at": "2026-01-15T12:06:43.052449"}}
{"event_type": "price_change", "event_ts": "2026-01-15T12:06:43.052449", "ingestion_ts": "2026-01-15T12:08:42.168746", "market_id": "0xea644975be7b2ad32b536a94ae21b707ecb2f84290225b24e60ca46dd77903dd", "raw": {"market": "0xea644975be7b2ad32b536a94ae21b707ecb2f84290225b24e60ca46dd77903dd", "asset_id": "110044455628775971785618539427229099821815416148768008176051068105157446559241", "price": "0.148", "size": "5", "side": "SELL", "timestamp": "1768475202925", "received_at": "2026-01-15T12:06:43.052449"}}
{"event_type": "price_change", "event_ts": "2026-01-15T12:06:43.052502", "ingestion_ts": "2026-01-15T12:08:42.168746", "market_id": "0x50e477f0b316a3d97d60486479657c63be0763834d0e2e8a30b1b86dc3c1c001", "raw": {"market": "0x50e477f0b316a3d97d60486479657c63be0763834d0e2e8a30b1b86dc3c1c001", "asset_id": "39981134260608444876865205057565852475343967395624370698967311821208058420507", "price": "0.851", "size": "5", "side": "BUY", "timestamp": "1768475202925", "received_at": "2026-01-15T12:06:43.052502"}}
{"event_type": "price_change", "event_ts": "2026-01-15T12:06:43.052502", "ingestion_ts": "2026-01-15T12:08:42.168746", "market_id": "0x50e477f0b316a3d97d60486479657c63be0763834d0e2e8a30b1b86dc3c1c001", "raw": {"market": "0x50e477f0b316a3d97d60486479657c63be0763834d0e2e8a30b1b86dc3c1c001", "asset_id": "60573178197991590327120832143415406583517170365625050489007297367895074266641", "price": "0.149", "size": "5", "side": "SELL", "timestamp": "1768475202925", "received_at": "2026-01-15T12:06:43.052502"}}
{"event_type": "price_change", "event_ts": "2026-01-15T12:06:43.399598", "ingestion_ts": "2026-01-15T12:08:42.168746", "market_id": "0xc0e6b917320a47228fb96e3b5ae0e5c93773a5ae2662ae4e1f37807cfe47ce98", "raw": {"market": "0xc0e6b917320a47228fb96e3b5ae0e5c93773a5ae2662ae4e1f37807cfe47ce98", "asset_id": "58656358377246279051017109359677190749228949103591068167284263961542487110215", "price": "0.003", "size": "436.76", "side": "BUY", "timestamp": "1768475203275", "received_at": "2026-01-15T12:06:43.399598"}}
{"event_type": "price_change", "event_ts": "2026-01-15T12:06:43.399598", "ingestion_ts": "2026-01-15T12:08:42.168746", "market_id": "0xc0e6b917320a47228fb96e3b5ae0e5c93773a5ae2662ae4e1f37807cfe47ce98", "raw": {"market": "0xc0e6b917320a47228fb96e3b5ae0e5c93773a5ae2662ae4e1f37807cfe47ce98", "asset_id": "81647294538046680798858716589766492074338758116170717123345952330712416337530", "price": "0.997", "size": "436.76", "side": "SELL", "timestamp": "1768475203275", "received_at": "2026-01-15T12:06:43.399598"}}
{"event_type": "price_change", "event_ts": "2026-01-15T12:06:43.399693", "ingestion_ts": "2026-01-15T12:08:42.168746", "market_id": "0xc0e6b917320a47228fb96e3b5ae0e5c93773a5ae2662ae4e1f37807cfe47ce98", "raw": {"market": "0xc0e6b917320a47228fb96e3b5ae0e5c93773a5ae2662ae4e1f37807cfe47ce98", "asset_id": "58656358377246279051017109359677190749228949103591068167284263961542487110215", "price": "0.003", "size": "450.75", "side": "BUY", "timestamp": "1768475203276", "received_at": "2026-01-15T12:06:43.399693"}}
{"event_type": "price_change", "event_ts": "2026-01-15T12:06:43.399693", "ingestion_ts": "2026-01-15T12:08:42.168746", "market_id": "0xc0e6b917320a47228fb96e3b5ae0e5c93773a5ae2662ae4e1f37807cfe47ce98", "raw": {"market": "0xc0e6b917320a47228fb96e3b5ae0e5c93773a5ae2662ae4e1f37807cfe47ce98", "asset_id": "81647294538046680798858716589766492074338758116170717123345952330712416337530", "price": "0.997", "size": "450.75", "side": "SELL", "timestamp": "1768475203276", "received_at": "2026-01-15T12:06:43.399693"}}
{"event_type": "price_change", "event_ts": "2026-01-15T12:06:43.891401", "ingestion_ts": "2026-01-15T12:08:42.168746", "market_id": "0xcab7ba4a9133cfd407d7e73e5757e5abbace413b59421527a31113406c97815c", "raw": {"market": "0xcab7ba4a9133cfd407d7e73e5757e5abbace413b59421527a31113406c97815c", "asset_id": "96361925776989336186111887920533578209326565663637092688733016597062311745569", "price": "0.006", "size": "127.41", "side": "BUY", "timestamp": "1768475203772", "received_at": "2026-01-15T12:06:43.891401"}}
{"event_type": "price_change", "event_ts": "2026-01-15T12:06:43.891401", "ingestion_ts": "2026-01-15T12:08:42.168746", "market_id": "0xcab7ba4a9133cfd407d7e73e5757e5abbace413b59421527a31113406c97815c", "raw": {"market": "0xcab7ba4a9133cfd407d7e73e5757e5abbace413b59421527a31113406c97815c", "asset_id": "20002636398944597965698652220992177552927816915094913583821579024925426590022", "price": "0.994", "size": "127.41", "side": "SELL", "timestamp": "1768475203772", "received_at": "2026-01-15T12:06:43.891401"}}
{"event_type": "price_change", "event_ts": "2026-01-15T12:06:43.892065", "ingestion_ts": "2026-01-15T12:08:42.168746", "market_id": "0xcab7ba4a9133cfd407d7e73e5757e5abbace413b59421527a31113406c97815c", "raw": {"market": "0xcab7ba4a9133cfd407d7e73e5757e5abbace413b59421527a31113406c97815c", "asset_id": "96361925776989336186111887920533578209326565663637092688733016597062311745569", "price": "0.009", "size": "812.25", "side": "BUY", "timestamp": "1768475203772", "received_at": "2026-01-15T12:06:43.892065"}}
{"event_type": "price_change", "event_ts": "2026-01-15T12:06:43.892065", "ingestion_ts": "2026-01-15T12:08:42.168746", "market_id": "0xcab7ba4a9133cfd407d7e73e5757e5abbace413b59421527a31113406c97815c", "raw": {"market": "0xcab7ba4a9133cfd407d7e73e5757e5abbace413b59421527a31113406c97815c", "asset_id": "20002636398944597965698652220992177552927816915094913583821579024925426590022", "price": "0.991", "size": "812.25", "side": "SELL", "timestamp": "1768475203772", "received_at": "2026-01-15T12:06:43.892065"}}
{"event_type": "price_change", "event_ts": "2026-01-15T12:06:44.323608", "ingestion_ts": "2026-01-15T12:08:42.168746", "market_id": "0xcab7ba4a9133cfd407d7e73e5757e5abbace413b59421527a31113406c97815c", "raw": {"market": "0xcab7ba4a9133cfd407d7e73e5757e5abbace413b59421527a31113406c97815c", "asset_id": "96361925776989336186111887920533578209326565663637092688733016597062311745569", "price": "0.009", "size": "818.33", "side": "BUY", "timestamp": "1768475204197", "received_at": "2026-01-15T12:06:44.323608"}}
{"event_type": "price_change", "event_ts": "2026-01-15T12:06:44.323608", "ingestion_ts": "2026-01-15T12:08:42.168746", "market_id": "0xcab7ba4a9133cfd407d7e73e5757e5abbace413b59421527a31113406c97815c", "raw": {"market": "0xcab7ba4a9133cfd407d7e73e5757e5abbace413b59421527a31113406c97815c", "asset_id": "20002636398944597965698652220992177552927816915094913583821579024925426590022", "price": "0.991", "size": "818.33", "side": "SELL", "timestamp": "1768475204197", "received_at": "2026-01-15T12:06:44.323608"}}
{"event_type": "price_change", "event_ts": "2026-01-15T12:06:44.323648", "ingestion_ts": "2026-01-15T12:08:42.168746", "market_id": "0xcab7ba4a9133cfd407d7e73e5757e5abbace413b59421527a31113406c97815c", "raw": {"market": "0xcab7ba4a9133cfd407d7e73e5757e5abbace413b59421527a31113406c97815c", "asset_id": "96361925776989336186111887920533578209326565663637092688733016597062311745569", "price": "0.006", "size": "136.51", "side": "BUY", "timestamp": "1768475204198", "received_at": "2026-01-15T12:06:44.323648"}}
{"event_type": "price_change", "event_ts": "2026-01-15T12:06:44.323648", "ingestion_ts": "2026-01-15T12:08:42.168746", "market_id": "0xcab7ba4a9133cfd407d7e73e5757e5abbace413b59421527a31113406c97815c", "raw": {"market": "0xcab7ba4a9133cfd407d7e73e5757e5abbace413b59421527a31113406c97815c", "asset_id": "20002636398944597965698652220992177552927816915094913583821579024925426590022", "price": "0.994", "size": "136.51", "side": "SELL", "timestamp": "1768475204198", "received_at": "2026-01-15T12:06:44.323648"}}
{"event_type": "price_change", "event_ts": "2026-01-15T12:06:46.385727", "ingestion_ts": "2026-01-15T12:08:42.168746", "market_id": "0xc0e6b917320a47228fb96e3b5ae0e5c93773a5ae2662ae4e1f37807cfe47ce98", "raw": {"market": "0xc0e6b917320a47228fb96e3b5ae0e5c93773a5ae2662ae4e1f37807cfe47ce98", "asset_id": "58656358377246279051017109359677190749228949103591068167284263961542487110215", "price": "0.003", "size": "409.11", "side": "BUY", "timestamp": "1768475206257", "received_at": "2026-01-15T12:06:46.385727"}}
{"event_type": "price_change", "event_ts": "2026-01-15T12:06:46.385727", "ingestion_ts": "2026-01-15T12:08:42.168746", "market_id": "0xc0e6b917320a47228fb96e3b5ae0e5c93773a5ae2662ae4e1f37807cfe47ce98", "raw": {"market": "0xc0e6b917320a47228fb96e3b5ae0e5c93773a5ae2662ae4e1f37807cfe47ce98", "asset_id": "81647294538046680798858716589766492074338758116170717123345952330712416337530", "price": "0.997", "size": "409.11", "side": "SELL", "timestamp": "1768475206257", "received_at": "2026-01-15T12:06:46.385727"}}
{"event_type": "price_change", "event_ts": "2026-01-15T12:06:46.385825", "ingestion_ts": "2026-01-15T12:08:42.168746", "market_id": "0xc0e6b917320a47228fb96e3b5ae0e5c93773a5ae2662ae4e1f37807cfe47ce98", "raw": {"market": "0xc0e6b917320a47228fb96e3b5ae0e5c93773a5ae2662ae4e1f37807cfe47ce98", "asset_id": "58656358377246279051017109359677190749228949103591068167284263961542487110215", "price": "0.005", "size": "2.98", "side": "BUY", "timestamp": "1768475206257", "received_at": "2026-01-15T12:06:46.385825"}}
{"event_type": "price_change", "event_ts": "2026-01-15T12:06:46.385825", "ingestion_ts": "2026-01-15T12:08:42.168746", "market_id": "0xc0e6b917320a47228fb96e3b5ae0e5c93773a5ae2662ae4e1f37807cfe47ce98", "raw": {"market": "0xc0e6b917320a47228fb96e3b5ae0e5c93773a5ae2662ae4e1f37807cfe47ce98", "asset_id": "81647294538046680798858716589766492074338758116170717123345952330712416337530", "price": "0.995", "size": "2.98", "side": "SELL", "timestamp": "1768475206257", "received_at": "2026-01-15T12:06:46.385825"}}
{"event_type": "price_change", "event_ts": "2026-01-15T12:06:47.308268", "ingestion_ts": "2026-01-15T12:08:42.168746", "market_id": "0xc0e6b917320a47228fb96e3b5ae0e5c93773a5ae2662ae4e1f37807cfe47ce98", "raw": {"market": "0xc0e6b917320a47228fb96e3b5ae0e5c93773a5ae2662ae4e1f37807cfe47ce98", "asset_id": "58656358377246279051017109359677190749228949103591068167284263961542487110215", "price": "0.006", "size": "6.57", "side": "BUY", "timestamp": "1768475207190", "received_at": "2026-01-15T12:06:47.308268"}}
{"event_type": "price_change", "event_ts": "2026-01-15T12:06:47.308268", "ingestion_ts": "2026-01-15T12:08:42.168746", "market_id": "0xc0e6b917320a47228fb96e3b5ae0e5c93773a5ae2662ae4e1f37807cfe47ce98", "raw": {"market": "0xc0e6b917320a47228fb96e3b5ae0e5c93773a5ae2662ae4e1f37807cfe47ce98", "asset_id": "81647294538046680798858716589766492074338758116170717123345952330712416337530", "price": "0.994", "size": "6.57", "side": "SELL", "timestamp": "1768475207190", "received_at": "2026-01-15T12:06:47.308268"}}
{"event_type": "price_change", "event_ts": "2026-01-15T12:06:47.310940", "ingestion_ts": "2026-01-15T12:08:42.168746", "market_id": "0xc0e6b917320a47228fb96e3b5ae0e5c93773a5ae2662ae4e1f37807cfe47ce98", "raw": {"market": "0xc0e6b917320a47228fb96e3b5ae0e5c93773a5ae2662ae4e1f37807cfe47ce98", "asset_id": "58656358377246279051017109359677190749228949103591068167284263961542487110215", "price": "0.004", "size": "14.23", "side": "BUY", "timestamp": "1768475207191", "received_at": "2026-01-15T12:06:47.310940"}}
{"event_type": "price_change", "event_ts": "2026-01-15T12:06:47.310940", "ingestion_ts": "2026-01-15T12:08:42.168746", "market_id": "0xc0e6b917320a47228fb96e3b5ae0e5c93773a5ae2662ae4e1f37807cfe47ce98", "raw": {"market": "0xc0e6b917320a47228fb96e3b5ae0e5c93773a5ae2662ae4e1f37807cfe47ce98", "asset_id": "81647294538046680798858716589766492074338758116170717123345952330712416337530", "price": "0.996", "size": "14.23", "side": "SELL", "timestamp": "1768475207191", "received_at": "2026-01-15T12:06:47.310940"}}
{"event_type": "price_change", "event_ts": "2026-01-15T12:06:47.311009", "ingestion_ts": "2026-01-15T12:08:42.168746", "market_id": "0xc0e6b917320a47228fb96e3b5ae0e5c93773a5ae2662ae4e1f37807cfe47ce98", "raw": {"market": "0xc0e6b917320a47228fb96e3b5ae0e5c93773a5ae2662ae4e1f37807cfe47ce98", "asset_id": "58656358377246279051017109359677190749228949103591068167284263961542487110215", "price": "0.004", "size": "28.46", "side": "BUY", "timestamp": "1768475207192", "received_at": "2026-01-15T12:06:47.311009"}}
{"event_type": "price_change", "event_ts": "2026-01-15T12:06:47.311009", "ingestion_ts": "2026-01-15T12:08:42.168746", "market_id": "0xc0e6b917320a47228fb96e3b5ae0e5c93773a5ae2662ae4e1f37807cfe47ce98", "raw": {"market": "0xc0e6b917320a47228fb96e3b5ae0e5c93773a5ae2662ae4e1f37807cfe47ce98", "asset_id": "81647294538046680798858716589766492074338758116170717123345952330712416337530", "price": "0.996", "size": "28.46", "side": "SELL", "timestamp": "1768475207192", "received_at": "2026-01-15T12:06:47.311009"}}
{"event_type": "price_change", "event_ts": "2026-01-15T12:06:47.437808", "ingestion_ts": "2026-01-15T12:08:42.168746", "market_id": "0xcab7ba4a9133cfd407d7e73e5757e5abbace413b59421527a31113406c97815c", "raw": {"market": "0xcab7ba4a9133cfd407d7e73e5757e5abbace413b59421527a31113406c97815c", "asset_id": "96361925776989336186111887920533578209326565663637092688733016597062311745569", "price": "0.006", "size": "127.41", "side": "BUY", "timestamp": "1768475207310", "received_at": "2026-01-15T12:06:47.437808"}}
{"event_type": "price_change", "event_ts": "2026-01-15T12:06:47.437808", "ingestion_ts": "2026-01-15T12:08:42.168746", "market_id": "0xcab7ba4a9133cfd407d7e73e5757e5abbace413b59421527a31113406c97815c", "raw": {"market": "0xcab7ba4a9133cfd407d7e73e5757e5abbace413b59421527a31113406c97815c", "asset_id": "20002636398944597965698652220992177552927816915094913583821579024925426590022", "price": "0.994", "size": "127.41", "side": "SELL", "timestamp": "1768475207310", "received_at": "2026-01-15T12:06:47.437808"}}
{"event_type": "price_change", "event_ts": "2026-01-15T12:06:47.438059", "ingestion_ts": "2026-01-15T12:08:42.168746", "market_id": "0xcab7ba4a9133cfd407d7e73e5757e5abbace413b59421527a31113406c97815c", "raw": {"market": "0xcab7ba4a9133cfd407d7e73e5757e5abbace413b59421527a31113406c97815c", "asset_id": "96361925776989336186111887920533578209326565663637092688733016597062311745569", "price": "0.009", "size": "812.25", "side": "BUY", "timestamp": "1768475207310", "received_at": "2026-01-15T12:06:47.438059"}}
{"event_type": "price_change", "event_ts": "2026-01-15T12:06:47.438059", "ingestion_ts": "2026-01-15T12:08:42.168746", "market_id": "0xcab7ba4a9133cfd407d7e73e5757e5abbace413b59421527a31113406c97815c", "raw": {"market": "0xcab7ba4a9133cfd407d7e73e5757e5abbace413b59421527a31113406c97815c", "asset_id": "20002636398944597965698652220992177552927816915094913583821579024925426590022", "price": "0.991", "size": "812.25", "side": "SELL", "timestamp": "1768475207310", "received_at": "2026-01-15T12:06:47.438059"}}
{"event_type": "price_change", "event_ts": "2026-01-15T12:06:47.920078", "ingestion_ts": "2026-01-15T12:08:42.168746", "market_id": "0xcab7ba4a9133cfd407d7e73e5757e5abbace413b59421527a31113406c97815c", "raw": {"market": "0xcab7ba4a9133cfd407d7e73e5757e5abbace413b59421527a31113406c97815c", "asset_id": "96361925776989336186111887920533578209326565663637092688733016597062311745569", "price": "0.009", "size": "818.33", "side": "BUY", "timestamp": "1768475207796", "received_at": "2026-01-15T12:06:47.920078"}}
{"event_type": "price_change", "event_ts": "2026-01-15T12:06:47.920078", "ingestion_ts": "2026-01-15T12:08:42.168746", "market_id": "0xcab7ba4a9133cfd407d7e73e5757e5abbace413b59421527a31113406c97815c", "raw": {"market": "0xcab7ba4a9133cfd407d7e73e5757e5abbace413b59421527a31113406c97815c", "asset_id": "20002636398944597965698652220992177552927816915094913583821579024925426590022", "price": "0.991", "size": "818.33", "side": "SELL", "timestamp": "1768475207796", "received_at": "2026-01-15T12:06:47.920078"}}
{"event_type": "price_change", "event_ts": "2026-01-15T12:06:47.920117", "ingestion_ts": "2026-01-15T12:08:42.168746", "market_id": "0xcab7ba4a9133cfd407d7e73e5757e5abbace413b59421527a31113406c97815c", "raw": {"market": "0xcab7ba4a9133cfd407d7e73e5757e5abbace413b59421527a31113406c97815c", "asset_id": "96361925776989336186111887920533578209326565663637092688733016597062311745569", "price": "0.006", "size": "136.51", "side": "BUY", "timestamp": "1768475207797", "received_at": "2026-01-15T12:06:47.920117"}}
{"event_type": "price_change", "event_ts": "2026-01-15T12:06:47.920117", "ingestion_ts": "2026-01-15T12:08:42.168746", "market_id": "0xcab7ba4a9133cfd407d7e73e5757e5abbace413b59421527a31113406c97815c", "raw": {"market": "0xcab7ba4a9133cfd407d7e73e5757e5abbace413b59421527a31113406c97815c", "asset_id": "20002636398944597965698652220992177552927816915094913583821579024925426590022", "price": "0.994", "size": "136.51", "side": "SELL", "timestamp": "1768475207797", "received_at": "2026-01-15T12:06:47.920117"}}
{"event_type": "price_change", "event_ts": "2026-01-15T12:06:49.333701", "ingestion_ts": "2026-01-15T12:08:42.168746", "market_id": "0xc0e6b917320a47228fb96e3b5ae0e5c93773a5ae2662ae4e1f37807cfe47ce98", "raw": {"market": "0xc0e6b917320a47228fb96e3b5ae0e5c93773a5ae2662ae4e1f37807cfe47ce98", "asset_id": "58656358377246279051017109359677190749228949103591068167284263961542487110215", "price": "0.004", "size": "14.23", "side": "BUY", "timestamp": "1768475209200", "received_at": "2026-01-15T12:06:49.333701"}}
{"event_type": "price_change", "event_ts": "2026-01-15T12:06:49.333701", "ingestion_ts": "2026-01-15T12:08:42.168746", "market_id": "0xc0e6b917320a47228fb96e3b5ae0e5c93773a5ae2662ae4e1f37807cfe47ce98", "raw": {"market": "0xc0e6b917320a47228fb96e3b5ae0e5c93773a5ae2662ae4e1f37807cfe47ce98", "asset_id": "81647294538046680798858716589766492074338758116170717123345952330712416337530", "price": "0.996", "size": "14.23", "side": "SELL", "timestamp": "1768475209200", "received_at": "2026-01-15T12:06:49.333701"}}
{"event_type": "price_change", "event_ts": "2026-01-15T12:06:49.333739", "ingestion_ts": "2026-01-15T12:08:42.168746", "market_id": "0xc0e6b917320a47228fb96e3b5ae0e5c93773a5ae2662ae4e1f37807cfe47ce98", "raw": {"market": "0xc0e6b917320a47228fb96e3b5ae0e5c93773a5ae2662ae4e1f37807cfe47ce98", "asset_id": "58656358377246279051017109359677190749228949103591068167284263961542487110215", "price": "0.006", "size": "0", "side": "BUY", "timestamp": "1768475209200", "received_at": "2026-01-15T12:06:49.333739"}}
{"event_type": "price_change", "event_ts": "2026-01-15T12:06:49.333739", "ingestion_ts": "2026-01-15T12:08:42.168746", "market_id": "0xc0e6b917320a47228fb96e3b5ae0e5c93773a5ae2662ae4e1f37807cfe47ce98", "raw": {"market": "0xc0e6b917320a47228fb96e3b5ae0e5c93773a5ae2662ae4e1f37807cfe47ce98", "asset_id": "81647294538046680798858716589766492074338758116170717123345952330712416337530", "price": "0.994", "size": "0", "side": "SELL", "timestamp": "1768475209200", "received_at": "2026-01-15T12:06:49.333739"}}
{"event_type": "price_change", "event_ts": "2026-01-15T12:06:49.801746", "ingestion_ts": "2026-01-15T12:08:42.168746", "market_id": "0xc0e6b917320a47228fb96e3b5ae0e5c93773a5ae2662ae4e1f37807cfe47ce98", "raw": {"market": "0xc0e6b917320a47228fb96e3b5ae0e5c93773a5ae2662ae4e1f37807cfe47ce98", "asset_id": "58656358377246279051017109359677190749228949103591068167284263961542487110215", "price": "0.003", "size": "415.63", "side": "BUY", "timestamp": "1768475209682", "received_at": "2026-01-15T12:06:49.801746"}}
{"event_type": "price_change", "event_ts": "2026-01-15T12:06:49.801746", "ingestion_ts": "2026-01-15T12:08:42.168746", "market_id": "0xc0e6b917320a47228fb96e3b5ae0e5c93773a5ae2662ae4e1f37807cfe47ce98", "raw": {"market": "0xc0e6b917320a47228fb96e3b5ae0e5c93773a5ae2662ae4e1f37807cfe47ce98", "asset_id": "81647294538046680798858716589766492074338758116170717123345952330712416337530", "price": "0.997", "size": "415.63", "side": "SELL", "timestamp": "1768475209682", "received_at": "2026-01-15T12:06:49.801746"}}
{"event_type": "price_change", "event_ts": "2026-01-15T12:06:49.801785", "ingestion_ts": "2026-01-15T12:08:42.168746", "market_id": "0xc0e6b917320a47228fb96e3b5ae0e5c93773a5ae2662ae4e1f37807cfe47ce98", "raw": {"market": "0xc0e6b917320a47228fb96e3b5ae0e5c93773a5ae2662ae4e1f37807cfe47ce98", "asset_id": "58656358377246279051017109359677190749228949103591068167284263961542487110215", "price": "0.005", "size": "10.66", "side": "BUY", "timestamp": "1768475209684", "received_at": "2026-01-15T12:06:49.801785"}}
{"event_type": "price_change", "event_ts": "2026-01-15T12:06:49.801785", "ingestion_ts": "2026-01-15T12:08:42.168746", "market_id": "0xc0e6b917320a47228fb96e3b5ae0e5c93773a5ae2662ae4e1f37807cfe47ce98", "raw": {"market": "0xc0e6b917320a47228fb96e3b5ae0e5c93773a5ae2662ae4e1f37807cfe47ce98", "asset_id": "81647294538046680798858716589766492074338758116170717123345952330712416337530", "price": "0.995", "size": "10.66", "side": "SELL", "timestamp": "1768475209684", "received_at": "2026-01-15T12:06:49.801785"}}
{"event_type": "price_change", "event_ts": "2026-01-15T12:06:49.807064", "ingestion_ts": "2026-01-15T12:08:42.168746", "market_id": "0xc0e6b917320a47228fb96e3b5ae0e5c93773a5ae2662ae4e1f37807cfe47ce98", "raw": {"market": "0xc0e6b917320a47228fb96e3b5ae0e5c93773a5ae2662ae4e1f37807cfe47ce98", "asset_id": "58656358377246279051017109359677190749228949103591068167284263961542487110215", "price": "0.005", "size": "18.34", "side": "BUY", "timestamp": "1768475209685", "received_at": "2026-01-15T12:06:49.807064"}}
{"event_type": "price_change", "event_ts": "2026-01-15T12:06:49.807064", "ingestion_ts": "2026-01-15T12:08:42.168746", "market_id": "0xc0e6b917320a47228fb96e3b5ae0e5c93773a5ae2662ae4e1f37807cfe47ce98", "raw": {"market": "0xc0e6b917320a47228fb96e3b5ae0e5c93773a5ae2662ae4e1f37807cfe47ce98", "asset_id": "81647294538046680798858716589766492074338758116170717123345952330712416337530", "price": "0.995", "size": "18.34", "side": "SELL", "timestamp": "1768475209685", "received_at": "2026-01-15T12:06:49.807064"}}
{"event_type": "price_change", "event_ts": "2026-01-15T12:06:50.280019", "ingestion_ts": "2026-01-15T12:08:42.168746", "market_id": "0xcab7ba4a9133cfd407d7e73e5757e5abbace413b59421527a31113406c97815c", "raw": {"market": "0xcab7ba4a9133cfd407d7e73e5757e5abbace413b59421527a31113406c97815c", "asset_id": "96361925776989336186111887920533578209326565663637092688733016597062311745569", "price": "0.006", "size": "127.41", "side": "BUY", "timestamp": "1768475210162", "received_at": "2026-01-15T12:06:50.280019"}}
{"event_type": "price_change", "event_ts": "2026-01-15T12:06:50.280019", "ingestion_ts": "2026-01-15T12:08:42.168746", "market_id": "0xcab7ba4a9133cfd407d7e73e5757e5abbace413b59421527a31113406c97815c", "raw": {"market": "0xcab7ba4a9133cfd407d7e73e5757e5abbace413b59421527a31113406c97815c", "asset_id": "20002636398944597965698652220992177552927816915094913583821579024925426590022", "price": "0.994", "size": "127.41", "side": "SELL", "timestamp": "1768475210162", "received_at": "2026-01-15T12:06:50.280019"}}
{"event_type": "price_change", "event_ts": "2026-01-15T12:06:50.280056", "ingestion_ts": "2026-01-15T12:08:42.168746", "market_id": "0xcab7ba4a9133cfd407d7e73e5757e5abbace413b59421527a31113406c97815c", "raw": {"market": "0xcab7ba4a9133cfd407d7e73e5757e5abbace413b59421527a31113406c97815c", "asset_id": "96361925776989336186111887920533578209326565663637092688733016597062311745569", "price": "0.009", "size": "812.25", "side": "BUY", "timestamp": "1768475210162", "received_at": "2026-01-15T12:06:50.280056"}}
{"event_type": "price_change", "event_ts": "2026-01-15T12:06:50.280056", "ingestion_ts": "2026-01-15T12:08:42.168746", "market_id": "0xcab7ba4a9133cfd407d7e73e5757e5abbace413b59421527a31113406c97815c", "raw": {"market": "0xcab7ba4a9133cfd407d7e73e5757e5abbace413b59421527a31113406c97815c", "asset_id": "20002636398944597965698652220992177552927816915094913583821579024925426590022", "price": "0.991", "size": "812.25", "side": "SELL", "timestamp": "1768475210162", "received_at": "2026-01-15T12:06:50.280056"}}
{"event_type": "price_change", "event_ts": "2026-01-15T12:06:50.962610", "ingestion_ts": "2026-01-15T12:08:42.168746", "market_id": "0xcab7ba4a9133cfd407d7e73e5757e5abbace413b59421527a31113406c97815c", "raw": {"market": "0xcab7ba4a9133cfd407d7e73e5757e5abbace413b59421527a31113406c97815c", "asset_id": "96361925776989336186111887920533578209326565663637092688733016597062311745569", "price": "0.006", "size": "136.51", "side": "BUY", "timestamp": "1768475210839", "received_at": "2026-01-15T12:06:50.962610"}}
{"event_type": "price_change", "event_ts": "2026-01-15T12:06:50.962610", "ingestion_ts": "2026-01-15T12:08:42.168746", "market_id": "0xcab7ba4a9133cfd407d7e73e5757e5abbace413b59421527a31113406c97815c", "raw": {"market": "0xcab7ba4a9133cfd407d7e73e5757e5abbace413b59421527a31113406c97815c", "asset_id": "20002636398944597965698652220992177552927816915094913583821579024925426590022", "price": "0.994", "size": "136.51", "side": "SELL", "timestamp": "1768475210839", "received_at": "2026-01-15T12:06:50.962610"}}
{"event_type": "price_change", "event_ts": "2026-01-15T12:06:50.965630", "ingestion_ts": "2026-01-15T12:08:42.168746", "market_id": "0xcab7ba4a9133cfd407d7e73e5757e5abbace413b59421527a31113406c97815c", "raw": {"market": "0xcab7ba4a9133cfd407d7e73e5757e5abbace413b59421527a31113406c97815c", "asset_id": "96361925776989336186111887920533578209326565663637092688733016597062311745569", "price": "0.009", "size": "818.33", "side": "BUY", "timestamp": "1768475210840", "received_at": "2026-01-15T12:06:50.965630"}}
{"event_type": "price_change", "event_ts": "2026-01-15T12:06:50.965630", "ingestion_ts": "2026-01-15T12:08:42.168746", "market_id": "0xcab7ba4a9133cfd407d7e73e5757e5abbace413b59421527a31113406c97815c", "raw": {"market": "0xcab7ba4a9133cfd407d7e73e5757e5abbace413b59421527a31113406c97815c", "asset_id": "20002636398944597965698652220992177552927816915094913583821579024925426590022", "price": "0.991", "size": "818.33", "side": "SELL", "timestamp": "1768475210840", "received_at": "2026-01-15T12:06:50.965630"}}
{"event_type": "price_change", "event_ts": "2026-01-15T12:06:53.291360", "ingestion_ts": "2026-01-15T12:08:42.168746", "market_id": "0xc0e6b917320a47228fb96e3b5ae0e5c93773a5ae2662ae4e1f37807cfe47ce98", "raw": {"market": "0xc0e6b917320a47228fb96e3b5ae0e5c93773a5ae2662ae4e1f37807cfe47ce98", "asset_id": "58656358377246279051017109359677190749228949103591068167284263961542487110215", "price": "0.004", "size": "0", "side": "BUY", "timestamp": "1768475213174", "received_at": "2026-01-15T12:06:53.291360"}}
{"event_type": "price_change", "event_ts": "2026-01-15T12:06:53.291360", "ingestion_ts": "2026-01-15T12:08:42.168746", "market_id": "0xc0e6b917320a47228fb96e3b5ae0e5c93773a5ae2662ae4e1f37807cfe47ce98", "raw": {"market": "0xc0e6b917320a47228fb96e3b5ae0e5c93773a5ae2662ae4e1f37807cfe47ce98", "asset_id": "81647294538046680798858716589766492074338758116170717123345952330712416337530", "price": "0.996", "size": "0", "side": "SELL", "timestamp": "1768475213174", "received_at": "2026-01-15T12:06:53.291360"}}
{"event_type": "price_change", "event_ts": "2026-01-15T12:06:53.292409", "ingestion_ts": "2026-01-15T12:08:42.168746", "market_id": "0xc0e6b917320a47228fb96e3b5ae0e5c93773a5ae2662ae4e1f37807cfe47ce98", "raw": {"market": "0xc0e6b917320a47228fb96e3b5ae0e5c93773a5ae2662ae4e1f37807cfe47ce98", "asset_id": "58656358377246279051017109359677190749228949103591068167284263961542487110215", "price": "0.005", "size": "10.66", "side": "BUY", "timestamp": "1768475213174", "received_at": "2026-01-15T12:06:53.292409"}}
{"event_type": "price_change", "event_ts": "2026-01-15T12:06:53.292409", "ingestion_ts": "2026-01-15T12:08:42.168746", "market_id": "0xc0e6b917320a47228fb96e3b5ae0e5c93773a5ae2662ae4e1f37807cfe47ce98", "raw": {"market": "0xc0e6b917320a47228fb96e3b5ae0e5c93773a5ae2662ae4e1f37807cfe47ce98", "asset_id": "81647294538046680798858716589766492074338758116170717123345952330712416337530", "price": "0.995", "size": "10.66", "side": "SELL", "timestamp": "1768475213174", "received_at": "2026-01-15T12:06:53.292409"}}
{"event_type": "price_change", "event_ts": "2026-01-15T12:06:53.914273", "ingestion_ts": "2026-01-15T12:08:42.168746", "market_id": "0xc0e6b917320a47228fb96e3b5ae0e5c93773a5ae2662ae4e1f37807cfe47ce98", "raw": {"market": "0xc0e6b917320a47228fb96e3b5ae0e5c93773a5ae2662ae4e1f37807cfe47ce98", "asset_id": "58656358377246279051017109359677190749228949103591068167284263961542487110215", "price": "0.006", "size": "7.94", "side": "BUY", "timestamp": "1768475213796", "received_at": "2026-01-15T12:06:53.914273"}}
{"event_type": "price_change", "event_ts": "2026-01-15T12:06:53.914273", "ingestion_ts": "2026-01-15T12:08:42.168746", "market_id": "0xc0e6b917320a47228fb96e3b5ae0e5c93773a5ae2662ae4e1f37807cfe47ce98", "raw": {"market": "0xc0e6b917320a47228fb96e3b5ae0e5c93773a5ae2662ae4e1f37807cfe47ce98", "asset_id": "81647294538046680798858716589766492074338758116170717123345952330712416337530", "price": "0.994", "size": "7.94", "side": "SELL", "timestamp": "1768475213796", "received_at": "2026-01-15T12:06:53.914273"}}
{"event_type": "price_change", "event_ts": "2026-01-15T12:06:53.916735", "ingestion_ts": "2026-01-15T12:08:42.168746", "market_id": "0xc0e6b917320a47228fb96e3b5ae0e5c93773a5ae2662ae4e1f37807cfe47ce98", "raw": {"market": "0xc0e6b917320a47228fb96e3b5ae0e5c93773a5ae2662ae4e1f37807cfe47ce98", "asset_id": "58656358377246279051017109359677190749228949103591068167284263961542487110215", "price": "0.006", "size": "15.88", "side": "BUY", "timestamp": "1768475213799", "received_at": "2026-01-15T12:06:53.916735"}}
{"event_type": "price_change", "event_ts": "2026-01-15T12:06:53.916735", "ingestion_ts": "2026-01-15T12:08:42.168746", "market_id": "0xc0e6b917320a47228fb96e3b5ae0e5c93773a5ae2662ae4e1f37807cfe47ce98", "raw": {"market": "0xc0e6b917320a47228fb96e3b5ae0e5c93773a5ae2662ae4e1f37807cfe47ce98", "asset_id": "81647294538046680798858716589766492074338758116170717123345952330712416337530", "price": "0.994", "size": "15.88", "side": "SELL", "timestamp": "1768475213799", "received_at": "2026-01-15T12:06:53.916735"}}
{"event_type": "price_change", "event_ts": "2026-01-15T12:06:54.245117", "ingestion_ts": "2026-01-15T12:08:42.168746", "market_id": "0xcab7ba4a9133cfd407d7e73e5757e5abbace413b59421527a31113406c97815c", "raw": {"market": "0xcab7ba4a9133cfd407d7e73e5757e5abbace413b59421527a31113406c97815c", "asset_id": "96361925776989336186111887920533578209326565663637092688733016597062311745569", "price": "0.006", "size": "127.41", "side": "BUY", "timestamp": "1768475214128", "received_at": "2026-01-15T12:06:54.245117"}}
{"event_type": "price_change", "event_ts": "2026-01-15T12:06:54.245117", "ingestion_ts": "2026-01-15T12:08:42.168746", "market_id": "0xcab7ba4a9133cfd407d7e73e5757e5abbace413b59421527a31113406c97815c", "raw": {"market": "0xcab7ba4a9133cfd407d7e73e5757e5abbace413b59421527a31113406c97815c", "asset_id": "20002636398944597965698652220992177552927816915094913583821579024925426590022", "price": "0.994", "size": "127.41", "side": "SELL", "timestamp": "1768475214128", "received_at": "2026-01-15T12:06:54.245117"}}
{"event_type": "price_change", "event_ts": "2026-01-15T12:06:54.247211", "ingestion_ts": "2026-01-15T12:08:42.168746", "market_id": "0xcab7ba4a9133cfd407d7e73e5757e5abbace413b59421527a31113406c97815c", "raw": {"market": "0xcab7ba4a9133cfd407d7e73e5757e5abbace413b59421527a31113406c97815c", "asset_id": "96361925776989336186111887920533578209326565663637092688733016597062311745569", "price": "0.009", "size": "812.25", "side": "BUY", "timestamp": "1768475214128", "received_at": "2026-01-15T12:06:54.247211"}}
{"event_type": "price_change", "event_ts": "2026-01-15T12:06:54.247211", "ingestion_ts": "2026-01-15T12:08:42.168746", "market_id": "0xcab7ba4a9133cfd407d7e73e5757e5abbace413b59421527a31113406c97815c", "raw": {"market": "0xcab7ba4a9133cfd407d7e73e5757e5abbace413b59421527a31113406c97815c", "asset_id": "20002636398944597965698652220992177552927816915094913583821579024925426590022", "price": "0.991", "size": "812.25", "side": "SELL", "timestamp": "1768475214128", "received_at": "2026-01-15T12:06:54.247211"}}
{"event_type": "price_change", "event_ts": "2026-01-15T12:06:54.455678", "ingestion_ts": "2026-01-15T12:08:42.168746", "market_id": "0xcab7ba4a9133cfd407d7e73e5757e5abbace413b59421527a31113406c97815c", "raw": {"market": "0xcab7ba4a9133cfd407d7e73e5757e5abbace413b59421527a31113406c97815c", "asset_id": "96361925776989336186111887920533578209326565663637092688733016597062311745569", "price": "0.006", "size": "136.51", "side": "BUY", "timestamp": "1768475214318", "received_at": "2026-01-15T12:06:54.455678"}}
{"event_type": "price_change", "event_ts": "2026-01-15T12:06:54.455678", "ingestion_ts": "2026-01-15T12:08:42.168746", "market_id": "0xcab7ba4a9133cfd407d7e73e5757e5abbace413b59421527a31113406c97815c", "raw": {"market": "0xcab7ba4a9133cfd407d7e73e5757e5abbace413b59421527a31113406c97815c", "asset_id": "20002636398944597965698652220992177552927816915094913583821579024925426590022", "price": "0.994", "size": "136.51", "side": "SELL", "timestamp": "1768475214318", "received_at": "2026-01-15T12:06:54.455678"}}
{"event_type": "price_change", "event_ts": "2026-01-15T12:06:54.455717", "ingestion_ts": "2026-01-15T12:08:42.168746", "market_id": "0xcab7ba4a9133cfd407d7e73e5757e5abbace413b59421527a31113406c97815c", "raw": {"market": "0xcab7ba4a9133cfd407d7e73e5757e5abbace413b59421527a31113406c97815c", "asset_id": "96361925776989336186111887920533578209326565663637092688733016597062311745569", "price": "0.009", "size": "818.33", "side": "BUY", "timestamp": "1768475214321", "received_at": "2026-01-15T12:06:54.455717"}}
{"event_type": "price_change", "event_ts": "2026-01-15T12:06:54.455717", "ingestion_ts": "2026-01-15T12:08:42.168746", "market_id": "0xcab7ba4a9133cfd407d7e73e5757e5abbace413b59421527a31113406c97815c", "raw": {"market": "0xcab7ba4a9133cfd407d7e73e5757e5abbace413b59421527a31113406c97815c", "asset_id": "20002636398944597965698652220992177552927816915094913583821579024925426590022", "price": "0.991", "size": "818.33", "side": "SELL", "timestamp": "1768475214321", "received_at": "2026-01-15T12:06:54.455717"}}
{"event_type": "price_change", "event_ts": "2026-01-15T12:06:55.688411", "ingestion_ts": "2026-01-15T12:08:42.168746", "market_id": "0xc0e6b917320a47228fb96e3b5ae0e5c93773a5ae2662ae4e1f37807cfe47ce98", "raw": {"market": "0xc0e6b917320a47228fb96e3b5ae0e5c93773a5ae2662ae4e1f37807cfe47ce98", "asset_id": "58656358377246279051017109359677190749228949103591068167284263961542487110215", "price": "0.005", "size": "2.98", "side": "BUY", "timestamp": "1768475215563", "received_at": "2026-01-15T12:06:55.688411"}}
{"event_type": "price_change", "event_ts": "2026-01-15T12:06:55.688411", "ingestion_ts": "2026-01-15T12:08:42.168746", "market_id": "0xc0e6b917320a47228fb96e3b5ae0e5c93773a5ae2662ae4e1f37807cfe47ce98", "raw": {"market": "0xc0e6b917320a47228fb96e3b5ae0e5c93773a5ae2662ae4e1f37807cfe47ce98", "asset_id": "81647294538046680798858716589766492074338758116170717123345952330712416337530", "price": "0.995", "size": "2.98", "side": "SELL", "timestamp": "1768475215563", "received_at": "2026-01-15T12:06:55.688411"}}
{"event_type": "price_change", "event_ts": "2026-01-15T12:06:55.688486", "ingestion_ts": "2026-01-15T12:08:42.168746", "market_id": "0xc0e6b917320a47228fb96e3b5ae0e5c93773a5ae2662ae4e1f37807cfe47ce98", "raw": {"market": "0xc0e6b917320a47228fb96e3b5ae0e5c93773a5ae2662ae4e1f37807cfe47ce98", "asset_id": "58656358377246279051017109359677190749228949103591068167284263961542487110215", "price": "0.006", "size": "7.94", "side": "BUY", "timestamp": "1768475215563", "received_at": "2026-01-15T12:06:55.688486"}}
{"event_type": "price_change", "event_ts": "2026-01-15T12:06:55.688486", "ingestion_ts": "2026-01-15T12:08:42.168746", "market_id": "0xc0e6b917320a47228fb96e3b5ae0e5c93773a5ae2662ae4e1f37807cfe47ce98", "raw": {"market": "0xc0e6b917320a47228fb96e3b5ae0e5c93773a5ae2662ae4e1f37807cfe47ce98", "asset_id": "81647294538046680798858716589766492074338758116170717123345952330712416337530", "price": "0.994", "size": "7.94", "side": "SELL", "timestamp": "1768475215563", "received_at": "2026-01-15T12:06:55.688486"}}
{"event_type": "price_change", "event_ts": "2026-01-15T12:06:56.315182", "ingestion_ts": "2026-01-15T12:08:42.168746", "market_id": "0xc0e6b917320a47228fb96e3b5ae0e5c93773a5ae2662ae4e1f37807cfe47ce98", "raw": {"market": "0xc0e6b917320a47228fb96e3b5ae0e5c93773a5ae2662ae4e1f37807cfe47ce98", "asset_id": "58656358377246279051017109359677190749228949103591068167284263961542487110215", "price": "0.003", "size": "429.98", "side": "BUY", "timestamp": "1768475216185", "received_at": "2026-01-15T12:06:56.315182"}}
