{"event_type": "price_change", "event_ts": "2026-01-15T12:11:32.362785", "ingestion_ts": "2026-01-15T12:11:41.230171", "market_id": "0xcab7ba4a9133cfd407d7e73e5757e5abbace413b59421527a31113406c97815c", "raw": {"market": "0xcab7ba4a9133cfd407d7e73e5757e5abbace413b59421527a31113406c97815c", "asset_id": "96361925776989336186111887920533578209326565663637092688733016597062311745569", "price": "0.009", "size": "818.33", "side": "BUY", "timestamp": "1768475492231", "received_at": "2026-01-15T12:11:32.362785"}}
{"event_type": "price_change", "event_ts": "2026-01-15T12:11:32.362785", "ingestion_ts": "2026-01-15T12:11:41.230171", "market_id": "0xcab7ba4a9133cfd407d7e73e5757e5abbace413b59421527a31113406c97815c", "raw": {"market": "0xcab7ba4a9133cfd407d7e73e5757e5abbace413b59421527a31113406c97815c", "asset_id": "20002636398944597965698652220992177552927816915094913583821579024925426590022", "price": "0.991", "size": "818.33", "side": "SELL", "timestamp": "1768475492231", "received_at": "2026-01-15T12:11:32.362785"}}
{"event_type": "price_change", "event_ts": "2026-01-15T12:11:32.362865", "ingestion_ts": "2026-01-15T12:11:41.230171", "market_id": "0xcab7ba4a9133cfd407d7e73e5757e5abbace413b59421527a31113406c97815c", "raw": {"market": "0xcab7ba4a9133cfd407d7e73e5757e5abbace413b59421527a31113406c97815c", "asset_id": "96361925776989336186111887920533578209326565663637092688733016597062311745569", "price": "0.006", "size": "136.51", "side": "BUY", "timestamp": "1768475492232", "received_at": "2026-01-15T12:11:32.362865"}}
{"event_type": "price_change", "event_ts": "2026-01-15T12:11:32.362865", "ingestion_ts": "2026-01-15T12:11:41.230171", "market_id": "0xcab7ba4a9133cfd407d7e73e5757e5abbace413b59421527a31113406c97815c", "raw": {"market": "0xcab7ba4a9133cfd407d7e73e5757e5abbace413b59421527a31113406c97815c", "asset_id": "20002636398944597965698652220992177552927816915094913583821579024925426590022", "price": "0.994", "size": "136.51", "side": "SELL", "timestamp": "1768475492232", "received_at": "2026-01-15T12:11:32.362865"}}
{"event_type": "price_change", "event_ts": "2026-01-15T12:11:33.533221", "ingestion_ts": "2026-01-15T12:11:41.230171", "market_id": "0x427bc4b40c09b3dcbc973747f0e4b079bed91b3e5a0aed5c36edd0f7591485f4", "raw": {"market": "0x427bc4b40c09b3dcbc973747f0e4b079bed91b3e5a0aed5c36edd0f7591485f4", "asset_id": "115669573443672055876643967408433138119481486650803218131873713375232186497057", "price": "0.002", "size": "63.15", "side": "BUY", "timestamp": "1768475493410", "received_at": "2026-01-15T12:11:33.533221"}}
{"event_type": "price_change", "event_ts": "2026-01-15T12:11:33.533221", "ingestion_ts": "2026-01-15T12:11:41.230171", "market_id": "0x427bc4b40c09b3dcbc973747f0e4b079bed91b3e5a0aed5c36edd0f7591485f4", "raw": {"market": "0x427bc4b40c09b3dcbc973747f0e4b079bed91b3e5a0aed5c36edd0f7591485f4", "asset_id": "86130975769502911188457673769190265049139877688522439001984850068234616395137", "price": "0.998", "size": "63.15", "side": "SELL", "timestamp": "1768475493410", "received_at": "2026-01-15T12:11:33.533221"}}
{"event_type": "price_change", "event_ts": "2026-01-15T12:11:33.859300", "ingestion_ts": "2026-01-15T12:11:41.230171", "market_id": "0x427bc4b40c09b3dcbc973747f0e4b079bed91b3e5a0aed5c36edd0f7591485f4", "raw": {"market": "0x427bc4b40c09b3dcbc973747f0e4b079bed91b3e5a0aed5c36edd0f7591485f4", "asset_id": "115669573443672055876643967408433138119481486650803218131873713375232186497057", "price": "0.002", "size": "72.33", "side": "BUY", "timestamp": "1768475493736", "received_at": "2026-01-15T12:11:33.859300"}}
{"event_type": "price_change", "event_ts": "2026-01-15T12:11:33.859300", "ingestion_ts": "2026-01-15T12:11:41.230171", "market_id": "0x427bc4b40c09b3dcbc973747f0e4b079bed91b3e5a0aed5c36edd0f7591485f4", "raw": {"market": "0x427bc4b40c09b3dcbc973747f0e4b079bed91b3e5a0aed5c36edd0f7591485f4", "asset_id": "86130975769502911188457673769190265049139877688522439001984850068234616395137", "price": "0.998", "size": "72.33", "side": "SELL", "timestamp": "1768475493736", "received_at": "2026-01-15T12:11:33.859300"}}
{"event_type": "price_change", "event_ts": "2026-01-15T12:11:33.875200", "ingestion_ts": "2026-01-15T12:11:41.230171", "market_id": "0xc0e6b917320a47228fb96e3b5ae0e5c93773a5ae2662ae4e1f37807cfe47ce98", "raw": {"market": "0xc0e6b917320a47228fb96e3b5ae0e5c93773a5ae2662ae4e1f37807cfe47ce98", "asset_id": "58656358377246279051017109359677190749228949103591068167284263961542487110215", "price": "0.005", "size": "10.54", "side": "BUY", "timestamp": "1768475493751", "received_at": "2026-01-15T12:11:33.875200"}}
{"event_type": "price_change", "event_ts": "2026-01-15T12:11:33.875200", "ingestion_ts": "2026-01-15T12:11:41.230171", "market_id": "0xc0e6b917320a47228fb96e3b5ae0e5c93773a5ae2662ae4e1f37807cfe47ce98", "raw": {"market": "0xc0e6b917320a47228fb96e3b5ae0e5c93773a5ae2662ae4e1f37807cfe47ce98", "asset_id": "81647294538046680798858716589766492074338758116170717123345952330712416337530", "price": "0.995", "size": "10.54", "side": "SELL", "timestamp": "1768475493751", "received_at": "2026-01-15T12:11:33.875200"}}
{"event_type": "price_change", "event_ts": "2026-01-15T12:11:33.875360", "ingestion_ts": "2026-01-15T12:11:41.230171", "market_id": "0xcab7ba4a9133cfd407d7e73e5757e5abbace413b59421527a31113406c97815c", "raw": {"market": "0xcab7ba4a9133cfd407d7e73e5757e5abbace413b59421527a31113406c97815c", "asset_id": "96361925776989336186111887920533578209326565663637092688733016597062311745569", "price": "0.006", "size": "127.41", "side": "BUY", "timestamp": "1768475493751", "received_at": "2026-01-15T12:11:33.875360"}}
{"event_type": "price_change", "event_ts": "2026-01-15T12:11:33.875360", "ingestion_ts": "2026-01-15T12:11:41.230171", "market_id": "0xcab7ba4a9133cfd407d7e73e5757e5abbace413b59421527a31113406c97815c", "raw": {"market": "0xcab7ba4a9133cfd407d7e73e5757e5abbace413b59421527a31113406c97815c", "asset_id": "20002636398944597965698652220992177552927816915094913583821579024925426590022", "price": "0.994", "size": "127.41", "side": "SELL", "timestamp": "1768475493751", "received_at": "2026-01-15T12:11:33.875360"}}
{"event_type": "price_change", "event_ts": "2026-01-15T12:11:33.875625", "ingestion_ts": "2026-01-15T12:11:41.230171", "market_id": "0xcab7ba4a9133cfd407d7e73e5757e5abbace413b59421527a31113406c97815c", "raw": {"market": "0xcab7ba4a9133cfd407d7e73e5757e5abbace413b59421527a31113406c97815c", "asset_id": "96361925776989336186111887920533578209326565663637092688733016597062311745569", "price": "0.009", "size": "812.25", "side": "BUY", "timestamp": "1768475493751", "received_at": "2026-01-15T12:11:33.875625"}}
{"event_type": "price_change", "event_ts": "2026-01-15T12:11:33.875625", "ingestion_ts": "2026-01-15T12:11:41.230171", "market_id": "0xcab7ba4a9133cfd407d7e73e5757e5abbace413b59421527a31113406c97815c", "raw": {"market": "0xcab7ba4a9133cfd407d7e73e5757e5abbace413b59421527a31113406c97815c", "asset_id": "20002636398944597965698652220992177552927816915094913583821579024925426590022", "price": "0.991", "size": "812.25", "side": "SELL", "timestamp": "1768475493751", "received_at": "2026-01-15T12:11:33.875625"}}
{"event_type": "price_change", "event_ts": "2026-01-15T12:11:34.007135", "ingestion_ts": "2026-01-15T12:11:41.230171", "market_id": "0x427bc4b40c09b3dcbc973747f0e4b079bed91b3e5a0aed5c36edd0f7591485f4", "raw": {"market": "0x427bc4b40c09b3dcbc973747f0e4b079bed91b3e5a0aed5c36edd0f7591485f4", "asset_id": "115669573443672055876643967408433138119481486650803218131873713375232186497057", "price": "0.164", "size": "7.96", "side": "SELL", "timestamp": "1768475493890", "received_at": "2026-01-15T12:11:34.007135"}}
{"event_type": "price_change", "event_ts": "2026-01-15T12:11:34.007135", "ingestion_ts": "2026-01-15T12:11:41.230171", "market_id": "0x427bc4b40c09b3dcbc973747f0e4b079bed91b3e5a0aed5c36edd0f7591485f4", "raw": {"market": "0x427bc4b40c09b3dcbc973747f0e4b079bed91b3e5a0aed5c36edd0f7591485f4", "asset_id": "86130975769502911188457673769190265049139877688522439001984850068234616395137", "price": "0.836", "size": "7.96", "side": "BUY", "timestamp": "1768475493890", "received_at": "2026-01-15T12:11:34.007135"}}
{"event_type": "price_change", "event_ts": "2026-01-15T12:11:34.258237", "ingestion_ts": "2026-01-15T12:11:41.230171", "market_id": "0x427bc4b40c09b3dcbc973747f0e4b079bed91b3e5a0aed5c36edd0f7591485f4", "raw": {"market": "0x427bc4b40c09b3dcbc973747f0e4b079bed91b3e5a0aed5c36edd0f7591485f4", "asset_id": "115669573443672055876643967408433138119481486650803218131873713375232186497057", "price": "0.153", "size": "7.96", "side": "SELL", "timestamp": "1768475494136", "received_at": "2026-01-15T12:11:34.258237"}}
{"event_type": "price_change", "event_ts": "2026-01-15T12:11:34.258237", "ingestion_ts": "2026-01-15T12:11:41.230171", "market_id": "0x427bc4b40c09b3dcbc973747f0e4b079bed91b3e5a0aed5c36edd0f7591485f4", "raw": {"market": "0x427bc4b40c09b3dcbc973747f0e4b079bed91b3e5a0aed5c36edd0f7591485f4", "asset_id": "86130975769502911188457673769190265049139877688522439001984850068234616395137", "price": "0.847", "size": "7.96", "side": "BUY", "timestamp": "1768475494136", "received_at": "2026-01-15T12:11:34.258237"}}
{"event_type": "price_change", "event_ts": "2026-01-15T12:11:34.344642", "ingestion_ts": "2026-01-15T12:11:41.230171", "market_id": "0xc0e6b917320a47228fb96e3b5ae0e5c93773a5ae2662ae4e1f37807cfe47ce98", "raw": {"market": "0xc0e6b917320a47228fb96e3b5ae0e5c93773a5ae2662ae4e1f37807cfe47ce98", "asset_id": "58656358377246279051017109359677190749228949103591068167284263961542487110215", "price": "0.006", "size": "6.31", "side": "BUY", "timestamp": "1768475494226", "received_at": "2026-01-15T12:11:34.344642"}}
{"event_type": "price_change", "event_ts": "2026-01-15T12:11:34.344642", "ingestion_ts": "2026-01-15T12:11:41.230171", "market_id": "0xc0e6b917320a47228fb96e3b5ae0e5c93773a5ae2662ae4e1f37807cfe47ce98", "raw": {"market": "0xc0e6b917320a47228fb96e3b5ae0e5c93773a5ae2662ae4e1f37807cfe47ce98", "asset_id": "81647294538046680798858716589766492074338758116170717123345952330712416337530", "price": "0.994", "size": "6.31", "side": "SELL", "timestamp": "1768475494226", "received_at": "2026-01-15T12:11:34.344642"}}
{"event_type": "price_change", "event_ts": "2026-01-15T12:11:34.344736", "ingestion_ts": "2026-01-15T12:11:41.230171", "market_id": "0xcab7ba4a9133cfd407d7e73e5757e5abbace413b59421527a31113406c97815c", "raw": {"market": "0xcab7ba4a9133cfd407d7e73e5757e5abbace413b59421527a31113406c97815c", "asset_id": "96361925776989336186111887920533578209326565663637092688733016597062311745569", "price": "0.009", "size": "818.33", "side": "BUY", "timestamp": "1768475494226", "received_at": "2026-01-15T12:11:34.344736"}}
{"event_type": "price_change", "event_ts": "2026-01-15T12:11:34.344736", "ingestion_ts": "2026-01-15T12:11:41.230171", "market_id": "0xcab7ba4a9133cfd407d7e73e5757e5abbace413b59421527a31113406c97815c", "raw": {"market": "0xcab7ba4a9133cfd407d7e73e5757e5abbace413b59421527a31113406c97815c", "asset_id": "20002636398944597965698652220992177552927816915094913583821579024925426590022", "price": "0.991", "size": "818.33", "side": "SELL", "timestamp": "1768475494226", "received_at": "2026-01-15T12:11:34.344736"}}
{"event_type": "price_change", "event_ts": "2026-01-15T12:11:34.346934", "ingestion_ts": "2026-01-15T12:11:41.230171", "market_id": "0xcab7ba4a9133cfd407d7e73e5757e5abbace413b59421527a31113406c97815c", "raw": {"market": "0xcab7ba4a9133cfd407d7e73e5757e5abbace413b59421527a31113406c97815c", "asset_id": "96361925776989336186111887920533578209326565663637092688733016597062311745569", "price": "0.006", "size": "136.51", "side": "BUY", "timestamp": "1768475494227", "received_at": "2026-01-15T12:11:34.346934"}}
{"event_type": "price_change", "event_ts": "2026-01-15T12:11:34.346934", "ingestion_ts": "2026-01-15T12:11:41.230171", "market_id": "0xcab7ba4a9133cfd407d7e73e5757e5abbace413b59421527a31113406c97815c", "raw": {"market": "0xcab7ba4a9133cfd407d7e73e5757e5abbace413b59421527a31113406c97815c", "asset_id": "20002636398944597965698652220992177552927816915094913583821579024925426590022", "price": "0.994", "size": "136.51", "side": "SELL", "timestamp": "1768475494227", "received_at": "2026-01-15T12:11:34.346934"}}
{"event_type": "price_change", "event_ts": "2026-01-15T12:11:35.674698", "ingestion_ts": "2026-01-15T12:11:41.230171", "market_id": "0xc0e6b917320a47228fb96e3b5ae0e5c93773a5ae2662ae4e1f37807cfe47ce98", "raw": {"market": "0xc0e6b917320a47228fb96e3b5ae0e5c93773a5ae2662ae4e1f37807cfe47ce98", "asset_id": "58656358377246279051017109359677190749228949103591068167284263961542487110215", "price": "0.005", "size": "2.98", "side": "BUY", "timestamp": "1768475495551", "received_at": "2026-01-15T12:11:35.674698"}}
{"event_type": "price_change", "event_ts": "2026-01-15T12:11:35.674698", "ingestion_ts": "2026-01-15T12:11:41.230171", "market_id": "0xc0e6b917320a47228fb96e3b5ae0e5c93773a5ae2662ae4e1f37807cfe47ce98", "raw": {"market": "0xc0e6b917320a47228fb96e3b5ae0e5c93773a5ae2662ae4e1f37807cfe47ce98", "asset_id": "81647294538046680798858716589766492074338758116170717123345952330712416337530", "price": "0.995", "size": "2.98", "side": "SELL", "timestamp": "1768475495551", "received_at": "2026-01-15T12:11:35.674698"}}
{"event_type": "price_change", "event_ts": "2026-01-15T12:11:35.674732", "ingestion_ts": "2026-01-15T12:11:41.230171", "market_id": "0xc0e6b917320a47228fb96e3b5ae0e5c93773a5ae2662ae4e1f37807cfe47ce98", "raw": {"market": "0xc0e6b917320a47228fb96e3b5ae0e5c93773a5ae2662ae4e1f37807cfe47ce98", "asset_id": "58656358377246279051017109359677190749228949103591068167284263961542487110215", "price": "0.006", "size": "0", "side": "BUY", "timestamp": "1768475495551", "received_at": "2026-01-15T12:11:35.674732"}}
{"event_type": "price_change", "event_ts": "2026-01-15T12:11:35.674732", "ingestion_ts": "2026-01-15T12:11:41.230171", "market_id": "0xc0e6b917320a47228fb96e3b5ae0e5c93773a5ae2662ae4e1f37807cfe47ce98", "raw": {"market": "0xc0e6b917320a47228fb96e3b5ae0e5c93773a5ae2662ae4e1f37807cfe47ce98", "asset_id": "81647294538046680798858716589766492074338758116170717123345952330712416337530", "price": "0.994", "size": "0", "side": "SELL", "timestamp": "1768475495551", "received_at": "2026-01-15T12:11:35.674732"}}
{"event_type": "price_change", "event_ts": "2026-01-15T12:11:36.218034", "ingestion_ts": "2026-01-15T12:11:41.230171", "market_id": "0xcab7ba4a9133cfd407d7e73e5757e5abbace413b59421527a31113406c97815c", "raw": {"market": "0xcab7ba4a9133cfd407d7e73e5757e5abbace413b59421527a31113406c97815c", "asset_id": "96361925776989336186111887920533578209326565663637092688733016597062311745569", "price": "0.006", "size": "127.41", "side": "BUY", "timestamp": "1768475496074", "received_at": "2026-01-15T12:11:36.218034"}}
{"event_type": "price_change", "event_ts": "2026-01-15T12:11:36.218034", "ingestion_ts": "2026-01-15T12:11:41.230171", "market_id": "0xcab7ba4a9133cfd407d7e73e5757e5abbace413b59421527a31113406c97815c", "raw": {"market": "0xcab7ba4a9133cfd407d7e73e5757e5abbace413b59421527a31113406c97815c", "asset_id": "20002636398944597965698652220992177552927816915094913583821579024925426590022", "price": "0.994", "size": "127.41", "side": "SELL", "timestamp": "1768475496074", "received_at": "2026-01-15T12:11:36.218034"}}
{"event_type": "price_change", "event_ts": "2026-01-15T12:11:36.218083", "ingestion_ts": "2026-01-15T12:11:41.230171", "market_id": "0xcab7ba4a9133cfd407d7e73e5757e5abbace413b59421527a31113406c97815c", "raw": {"market": "0xcab7ba4a9133cfd407d7e73e5757e5abbace413b59421527a31113406c97815c", "asset_id": "96361925776989336186111887920533578209326565663637092688733016597062311745569", "price": "0.009", "size": "812.25", "side": "BUY", "timestamp": "1768475496074", "received_at": "2026-01-15T12:11:36.218083"}}
{"event_type": "price_change", "event_ts": "2026-01-15T12:11:36.218083", "ingestion_ts": "2026-01-15T12:11:41.230171", "market_id": "0xcab7ba4a9133cfd407d7e73e5757e5abbace413b59421527a31113406c97815c", "raw": {"market": "0xcab7ba4a9133cfd407d7e73e5757e5abbace413b59421527a31113406c97815c", "asset_id": "20002636398944597965698652220992177552927816915094913583821579024925426590022", "price": "0.991", "size": "812.25", "side": "SELL", "timestamp": "1768475496074", "received_at": "2026-01-15T12:11:36.218083"}}
{"event_type": "price_change", "event_ts": "2026-01-15T12:11:36.237817", "ingestion_ts": "2026-01-15T12:11:41.230171", "market_id": "0x427bc4b40c09b3dcbc973747f0e4b079bed91b3e5a0aed5c36edd0f7591485f4", "raw": {"market": "0x427bc4b40c09b3dcbc973747f0e4b079bed91b3e5a0aed5c36edd0f7591485f4", "asset_id": "115669573443672055876643967408433138119481486650803218131873713375232186497057", "price": "0.002", "size": "63.15", "side": "BUY", "timestamp": "1768475496094", "received_at": "2026-01-15T12:11:36.237817"}}
{"event_type": "price_change", "event_ts": "2026-01-15T12:11:36.237817", "ingestion_ts": "2026-01-15T12:11:41.230171", "market_id": "0x427bc4b40c09b3dcbc973747f0e4b079bed91b3e5a0aed5c36edd0f7591485f4", "raw": {"market": "0x427bc4b40c09b3dcbc973747f0e4b079bed91b3e5a0aed5c36edd0f7591485f4", "asset_id": "86130975769502911188457673769190265049139877688522439001984850068234616395137", "price": "0.998", "size": "63.15", "side": "SELL", "timestamp": "1768475496094", "received_at": "2026-01-15T12:11:36.237817"}}
{"event_type": "price_change", "event_ts": "2026-01-15T12:11:36.321769", "ingestion_ts": "2026-01-15T12:11:41.230171", "market_id": "0xc0e6b917320a47228fb96e3b5ae0e5c93773a5ae2662ae4e1f37807cfe47ce98", "raw": {"market": "0xc0e6b917320a47228fb96e3b5ae0e5c93773a5ae2662ae4e1f37807cfe47ce98", "asset_id": "58656358377246279051017109359677190749228949103591068167284263961542487110215", "price": "0.006", "size": "6.3", "side": "BUY", "timestamp": "1768475496194", "received_at": "2026-01-15T12:11:36.321769"}}
{"event_type": "price_change", "event_ts": "2026-01-15T12:11:36.321769", "ingestion_ts": "2026-01-15T12:11:41.230171", "market_id": "0xc0e6b917320a47228fb96e3b5ae0e5c93773a5ae2662ae4e1f37807cfe47ce98", "raw": {"market": "0xc0e6b917320a47228fb96e3b5ae0e5c93773a5ae2662ae4e1f37807cfe47ce98", "asset_id": "81647294538046680798858716589766492074338758116170717123345952330712416337530", "price": "0.994", "size": "6.3", "side": "SELL", "timestamp": "1768475496194", "received_at": "2026-01-15T12:11:36.321769"}}
{"event_type": "price_change", "event_ts": "2026-01-15T12:11:36.321901", "ingestion_ts": "2026-01-15T12:11:41.230171", "market_id": "0xc0e6b917320a47228fb96e3b5ae0e5c93773a5ae2662ae4e1f37807cfe47ce98", "raw": {"market": "0xc0e6b917320a47228fb96e3b5ae0e5c93773a5ae2662ae4e1f37807cfe47ce98", "asset_id": "58656358377246279051017109359677190749228949103591068167284263961542487110215", "price": "0.006", "size": "12.6", "side": "BUY", "timestamp": "1768475496197", "received_at": "2026-01-15T12:11:36.321901"}}
{"event_type": "price_change", "event_ts": "2026-01-15T12:11:36.321901", "ingestion_ts": "2026-01-15T12:11:41.230171", "market_id": "0xc0e6b917320a47228fb96e3b5ae0e5c93773a5ae2662ae4e1f37807cfe47ce98", "raw": {"market": "0xc0e6b917320a47228fb96e3b5ae0e5c93773a5ae2662ae4e1f37807cfe47ce98", "asset_id": "81647294538046680798858716589766492074338758116170717123345952330712416337530", "price": "0.994", "size": "12.6", "side": "SELL", "timestamp": "1768475496197", "received_at": "2026-01-15T12:11:36.321901"}}
{"event_type": "price_change", "event_ts": "2026-01-15T12:11:36.460626", "ingestion_ts": "2026-01-15T12:11:41.230171", "market_id": "0x427bc4b40c09b3dcbc973747f0e4b079bed91b3e5a0aed5c36edd0f7591485f4", "raw": {"market": "0x427bc4b40c09b3dcbc973747f0e4b079bed91b3e5a0aed5c36edd0f7591485f4", "asset_id": "115669573443672055876643967408433138119481486650803218131873713375232186497057", "price": "0.002", "size": "72.33", "side": "BUY", "timestamp": "1768475496339", "received_at": "2026-01-15T12:11:36.460626"}}
{"event_type": "price_change", "event_ts": "2026-01-15T12:11:36.460626", "ingestion_ts": "2026-01-15T12:11:41.230171", "market_id": "0x427bc4b40c09b3dcbc973747f0e4b079bed91b3e5a0aed5c36edd0f7591485f4", "raw": {"market": "0x427bc4b40c09b3dcbc973747f0e4b079bed91b3e5a0aed5c36edd0f7591485f4", "asset_id": "86130975769502911188457673769190265049139877688522439001984850068234616395137", "price": "0.998", "size": "72.33", "side": "SELL", "timestamp": "1768475496339", "received_at": "2026-01-15T12:11:36.460626"}}
{"event_type": "price_change", "event_ts": "2026-01-15T12:11:36.597487", "ingestion_ts": "2026-01-15T12:11:41.230171", "market_id": "0xcab7ba4a9133cfd407d7e73e5757e5abbace413b59421527a31113406c97815c", "raw": {"market": "0xcab7ba4a9133cfd407d7e73e5757e5abbace413b59421527a31113406c97815c", "asset_id": "96361925776989336186111887920533578209326565663637092688733016597062311745569", "price": "0.009", "size": "818.33", "side": "BUY", "timestamp": "1768475496478", "received_at": "2026-01-15T12:11:36.597487"}}
{"event_type": "price_change", "event_ts": "2026-01-15T12:11:36.597487", "ingestion_ts": "2026-01-15T12:11:41.230171", "market_id": "0xcab7ba4a9133cfd407d7e73e5757e5abbace413b59421527a31113406c97815c", "raw": {"market": "0xcab7ba4a9133cfd407d7e73e5757e5abbace413b59421527a31113406c97815c", "asset_id": "20002636398944597965698652220992177552927816915094913583821579024925426590022", "price": "0.991", "size": "818.33", "side": "SELL", "timestamp": "1768475496478", "received_at": "2026-01-15T12:11:36.597487"}}
{"event_type": "price_change", "event_ts": "2026-01-15T12:11:36.600652", "ingestion_ts": "2026-01-15T12:11:41.230171", "market_id": "0xcab7ba4a9133cfd407d7e73e5757e5abbace413b59421527a31113406c97815c", "raw": {"market": "0xcab7ba4a9133cfd407d7e73e5757e5abbace413b59421527a31113406c97815c", "asset_id": "96361925776989336186111887920533578209326565663637092688733016597062311745569", "price": "0.006", "size": "136.51", "side": "BUY", "timestamp": "1768475496481", "received_at": "2026-01-15T12:11:36.600652"}}
{"event_type": "price_change", "event_ts": "2026-01-15T12:11:36.600652", "ingestion_ts": "2026-01-15T12:11:41.230171", "market_id": "0xcab7ba4a9133cfd407d7e73e5757e5abbace413b59421527a31113406c97815c", "raw": {"market": "0xcab7ba4a9133cfd407d7e73e5757e5abbace413b59421527a31113406c97815c", "asset_id": "20002636398944597965698652220992177552927816915094913583821579024925426590022", "price": "0.994", "size": "136.51", "side": "SELL", "timestamp": "1768475496481", "received_at": "2026-01-15T12:11:36.600652"}}
{"event_type": "price_change", "event_ts": "2026-01-15T12:11:36.630714", "ingestion_ts": "2026-01-15T12:11:41.230171", "market_id": "0x427bc4b40c09b3dcbc973747f0e4b079bed91b3e5a0aed5c36edd0f7591485f4", "raw": {"market": "0x427bc4b40c09b3dcbc973747f0e4b079bed91b3e5a0aed5c36edd0f7591485f4", "asset_id": "115669573443672055876643967408433138119481486650803218131873713375232186497057", "price": "0.164", "size": "0", "side": "SELL", "timestamp": "1768475496513", "received_at": "2026-01-15T12:11:36.630714"}}
{"event_type": "price_change", "event_ts": "2026-01-15T12:11:36.630714", "ingestion_ts": "2026-01-15T12:11:41.230171", "market_id": "0x427bc4b40c09b3dcbc973747f0e4b079bed91b3e5a0aed5c36edd0f7591485f4", "raw": {"market": "0x427bc4b40c09b3dcbc973747f0e4b079bed91b3e5a0aed5c36edd0f7591485f4", "asset_id": "86130975769502911188457673769190265049139877688522439001984850068234616395137", "price": "0.836", "size": "0", "side": "BUY", "timestamp": "1768475496513", "received_at": "2026-01-15T12:11:36.630714"}}
{"event_type": "price_change", "event_ts": "2026-01-15T12:11:36.920066", "ingestion_ts": "2026-01-15T12:11:41.230171", "market_id": "0x427bc4b40c09b3dcbc973747f0e4b079bed91b3e5a0aed5c36edd0f7591485f4", "raw": {"market": "0x427bc4b40c09b3dcbc973747f0e4b079bed91b3e5a0aed5c36edd0f7591485f4", "asset_id": "115669573443672055876643967408433138119481486650803218131873713375232186497057", "price": "0.153", "size": "15.92", "side": "SELL", "timestamp": "1768475496798", "received_at": "2026-01-15T12:11:36.920066"}}
{"event_type": "price_change", "event_ts": "2026-01-15T12:11:36.920066", "ingestion_ts": "2026-01-15T12:11:41.230171", "market_id": "0x427bc4b40c09b3dcbc973747f0e4b079bed91b3e5a0aed5c36edd0f7591485f4", "raw": {"market": "0x427bc4b40c09b3dcbc973747f0e4b079bed91b3e5a0aed5c36edd0f7591485f4", "asset_id": "86130975769502911188457673769190265049139877688522439001984850068234616395137", "price": "0.847", "size": "15.92", "side": "BUY", "timestamp": "1768475496798", "received_at": "2026-01-15T12:11:36.920066"}}
{"event_type": "price_change", "event_ts": "2026-01-15T12:11:38.266805", "ingestion_ts": "2026-01-15T12:11:41.230171", "market_id": "0xcab7ba4a9133cfd407d7e73e5757e5abbace413b59421527a31113406c97815c", "raw": {"market": "0xcab7ba4a9133cfd407d7e73e5757e5abbace413b59421527a31113406c97815c", "asset_id": "96361925776989336186111887920533578209326565663637092688733016597062311745569", "price": "0.006", "size": "127.41", "side": "BUY", "timestamp": "1768475498146", "received_at": "2026-01-15T12:11:38.266805"}}
{"event_type": "price_change", "event_ts": "2026-01-15T12:11:38.266805", "ingestion_ts": "2026-01-15T12:11:41.230171", "market_id": "0xcab7ba4a9133cfd407d7e73e5757e5abbace413b59421527a31113406c97815c", "raw": {"market": "0xcab7ba4a9133cfd407d7e73e5757e5abbace413b59421527a31113406c97815c", "asset_id": "20002636398944597965698652220992177552927816915094913583821579024925426590022", "price": "0.994", "size": "127.41", "side": "SELL", "timestamp": "1768475498146", "received_at": "2026-01-15T12:11:38.266805"}}
{"event_type": "price_change", "event_ts": "2026-01-15T12:11:38.266840", "ingestion_ts": "2026-01-15T12:11:41.230171", "market_id": "0xcab7ba4a9133cfd407d7e73e5757e5abbace413b59421527a31113406c97815c", "raw": {"market": "0xcab7ba4a9133cfd407d7e73e5757e5abbace413b59421527a31113406c97815c", "asset_id": "96361925776989336186111887920533578209326565663637092688733016597062311745569", "price": "0.009", "size": "812.25", "side": "BUY", "timestamp": "1768475498146", "received_at": "2026-01-15T12:11:38.266840"}}
{"event_type": "price_change", "event_ts": "2026-01-15T12:11:38.266840", "ingestion_ts": "2026-01-15T12:11:41.230171", "market_id": "0xcab7ba4a9133cfd407d7e73e5757e5abbace413b59421527a31113406c97815c", "raw": {"market": "0xcab7ba4a9133cfd407d7e73e5757e5abbace413b59421527a31113406c97815c", "asset_id": "20002636398944597965698652220992177552927816915094913583821579024925426590022", "price": "0.991", "size": "812.25", "side": "SELL", "timestamp": "1768475498146", "received_at": "2026-01-15T12:11:38.266840"}}
{"event_type": "price_change", "event_ts": "2026-01-15T12:11:38.462709", "ingestion_ts": "2026-01-15T12:11:41.230171", "market_id": "0xcab7ba4a9133cfd407d7e73e5757e5abbace413b59421527a31113406c97815c", "raw": {"market": "0xcab7ba4a9133cfd407d7e73e5757e5abbace413b59421527a31113406c97815c", "asset_id": "96361925776989336186111887920533578209326565663637092688733016597062311745569", "price": "0.006", "size": "136.51", "side": "BUY", "timestamp": "1768475498346", "received_at": "2026-01-15T12:11:38.462709"}}
{"event_type": "price_change", "event_ts": "2026-01-15T12:11:38.462709", "ingestion_ts": "2026-01-15T12:11:41.230171", "market_id": "0xcab7ba4a9133cfd407d7e73e5757e5abbace413b59421527a31113406c97815c", "raw": {"market": "0xcab7ba4a9133cfd407d7e73e5757e5abbace413b59421527a31113406c97815c", "asset_id": "20002636398944597965698652220992177552927816915094913583821579024925426590022", "price": "0.994", "size": "136.51", "side": "SELL", "timestamp": "1768475498346", "received_at": "2026-01-15T12:11:38.462709"}}
{"event_type": "price_change", "event_ts": "2026-01-15T12:11:38.464281", "ingestion_ts": "2026-01-15T12:11:41.230171", "market_id": "0xcab7ba4a9133cfd407d7e73e5757e5abbace413b59421527a31113406c97815c", "raw": {"market": "0xcab7ba4a9133cfd407d7e73e5757e5abbace413b59421527a31113406c97815c", "asset_id": "96361925776989336186111887920533578209326565663637092688733016597062311745569", "price": "0.009", "size": "818.33", "side": "BUY", "timestamp": "1768475498347", "received_at": "2026-01-15T12:11:38.464281"}}
{"event_type": "price_change", "event_ts": "2026-01-15T12:11:38.464281", "ingestion_ts": "2026-01-15T12:11:41.230171", "market_id": "0xcab7ba4a9133cfd407d7e73e5757e5abbace413b59421527a31113406c97815c", "raw": {"market": "0xcab7ba4a9133cfd407d7e73e5757e5abbace413b59421527a31113406c97815c", "asset_id": "20002636398944597965698652220992177552927816915094913583821579024925426590022", "price": "0.991", "size": "818.33", "side": "SELL", "timestamp": "1768475498347", "received_at": "2026-01-15T12:11:38.464281"}}
{"event_type": "price_change", "event_ts": "2026-01-15T12:11:39.410448", "ingestion_ts": "2026-01-15T12:11:41.230171", "market_id": "0xc0e6b917320a47228fb96e3b5ae0e5c93773a5ae2662ae4e1f37807cfe47ce98", "raw": {"market": "0xc0e6b917320a47228fb96e3b5ae0e5c93773a5ae2662ae4e1f37807cfe47ce98", "asset_id": "58656358377246279051017109359677190749228949103591068167284263961542487110215", "price": "0.006", "size": "6.3", "side": "BUY", "timestamp": "1768475499291", "received_at": "2026-01-15T12:11:39.410448"}}
{"event_type": "price_change", "event_ts": "2026-01-15T12:11:39.410448", "ingestion_ts": "2026-01-15T12:11:41.230171", "market_id": "0xc0e6b917320a47228fb96e3b5ae0e5c93773a5ae2662ae4e1f37807cfe47ce98", "raw": {"market": "0xc0e6b917320a47228fb96e3b5ae0e5c93773a5ae2662ae4e1f37807cfe47ce98", "asset_id": "81647294538046680798858716589766492074338758116170717123345952330712416337530", "price": "0.994", "size": "6.3", "side": "SELL", "timestamp": "1768475499291", "received_at": "2026-01-15T12:11:39.410448"}}
{"event_type": "price_change", "event_ts": "2026-01-15T12:11:39.747291", "ingestion_ts": "2026-01-15T12:11:41.230171", "market_id": "0xc0e6b917320a47228fb96e3b5ae0e5c93773a5ae2662ae4e1f37807cfe47ce98", "raw": {"market": "0xc0e6b917320a47228fb96e3b5ae0e5c93773a5ae2662ae4e1f37807cfe47ce98", "asset_id": "58656358377246279051017109359677190749228949103591068167284263961542487110215", "price": "0.002", "size": "3313.14", "side": "BUY", "timestamp": "1768475499625", "received_at": "2026-01-15T12:11:39.747291"}}
{"event_type": "price_change", "event_ts": "2026-01-15T12:11:39.747291", "ingestion_ts": "2026-01-15T12:11:41.230171", "market_id": "0xc0e6b917320a47228fb96e3b5ae0e5c93773a5ae2662ae4e1f37807cfe47ce98", "raw": {"market": "0xc0e6b917320a47228fb96e3b5ae0e5c93773a5ae2662ae4e1f37807cfe47ce98", "asset_id": "81647294538046680798858716589766492074338758116170717123345952330712416337530", "price": "0.998", "size": "3313.14", "side": "SELL", "timestamp": "1768475499625", "received_at": "2026-01-15T12:11:39.747291"}}
{"event_type": "price_change", "event_ts": "2026-01-15T12:11:39.747379", "ingestion_ts": "2026-01-15T12:11:41.230171", "market_id": "0xc0e6b917320a47228fb96e3b5ae0e5c93773a5ae2662ae4e1f37807cfe47ce98", "raw": {"market": "0xc0e6b917320a47228fb96e3b5ae0e5c93773a5ae2662ae4e1f37807cfe47ce98", "asset_id": "58656358377246279051017109359677190749228949103591068167284263961542487110215", "price": "0.001", "size": "445.29", "side": "BUY", "timestamp": "1768475499626", "received_at": "2026-01-15T12:11:39.747379"}}
{"event_type": "price_change", "event_ts": "2026-01-15T12:11:39.747379", "ingestion_ts": "2026-01-15T12:11:41.230171", "market_id": "0xc0e6b917320a47228fb96e3b5ae0e5c93773a5ae2662ae4e1f37807cfe47ce98", "raw": {"market": "0xc0e6b917320a47228fb96e3b5ae0e5c93773a5ae2662ae4e1f37807cfe47ce98", "asset_id": "81647294538046680798858716589766492074338758116170717123345952330712416337530", "price": "0.999", "size": "445.29", "side": "SELL", "timestamp": "1768475499626", "received_at": "2026-01-15T12:11:39.747379"}}
{"event_type": "price_change", "event_ts": "2026-01-15T12:11:39.747418", "ingestion_ts": "2026-01-15T12:11:41.230171", "market_id": "0xc0e6b917320a47228fb96e3b5ae0e5c93773a5ae2662ae4e1f37807cfe47ce98", "raw": {"market": "0xc0e6b917320a47228fb96e3b5ae0e5c93773a5ae2662ae4e1f37807cfe47ce98", "asset_id": "58656358377246279051017109359677190749228949103591068167284263961542487110215", "price": "0.002", "size": "3319.86", "side": "BUY", "timestamp": "1768475499627", "received_at": "2026-01-15T12:11:39.747418"}}
{"event_type": "price_change", "event_ts": "2026-01-15T12:11:39.747418", "ingestion_ts": "2026-01-15T12:11:41.230171", "market_id": "0xc0e6b917320a47228fb96e3b5ae0e5c93773a5ae2662ae4e1f37807cfe47ce98", "raw": {"market": "0xc0e6b917320a47228fb96e3b5ae0e5c93773a5ae2662ae4e1f37807cfe47ce98", "asset_id": "81647294538046680798858716589766492074338758116170717123345952330712416337530", "price": "0.998", "size": "3319.86", "side": "SELL", "timestamp": "1768475499627", "received_at": "2026-01-15T12:11:39.747418"}}
{"event_type": "price_change", "event_ts": "2026-01-15T12:11:39.747450", "ingestion_ts": "2026-01-15T12:11:41.230171", "market_id": "0xc0e6b917320a47228fb96e3b5ae0e5c93773a5ae2662ae4e1f37807cfe47ce98", "raw": {"market": "0xc0e6b917320a47228fb96e3b5ae0e5c93773a5ae2662ae4e1f37807cfe47ce98", "asset_id": "58656358377246279051017109359677190749228949103591068167284263961542487110215", "price": "0.001", "size": "450.78", "side": "BUY", "timestamp": "1768475499627", "received_at": "2026-01-15T12:11:39.747450"}}
{"event_type": "price_change", "event_ts": "2026-01-15T12:11:39.747450", "ingestion_ts": "2026-01-15T12:11:41.230171", "market_id": "0xc0e6b917320a47228fb96e3b5ae0e5c93773a5ae2662ae4e1f37807cfe47ce98", "raw": {"market": "0xc0e6b917320a47228fb96e3b5ae0e5c93773a5ae2662ae4e1f37807cfe47ce98", "asset_id": "81647294538046680798858716589766492074338758116170717123345952330712416337530", "price": "0.999", "size": "450.78", "side": "SELL", "timestamp": "1768475499627", "received_at": "2026-01-15T12:11:39.747450"}}
{"event_type": "price_change", "event_ts": "2026-01-15T12:11:40.558627", "ingestion_ts": "2026-01-15T12:11:41.230171", "market_id": "0xcab7ba4a9133cfd407d7e73e5757e5abbace413b59421527a31113406c97815c", "raw": {"market": "0xcab7ba4a9133cfd407d7e73e5757e5abbace413b59421527a31113406c97815c", "asset_id": "96361925776989336186111887920533578209326565663637092688733016597062311745569", "price": "0.006", "size": "127.41", "side": "BUY", "timestamp": "1768475500367", "received_at": "2026-01-15T12:11:40.558627"}}
{"event_type": "price_change", "event_ts": "2026-01-15T12:11:40.558627", "ingestion_ts": "2026-01-15T12:11:41.230171", "market_id": "0xcab7ba4a9133cfd407d7e73e5757e5abbace413b59421527a31113406c97815c", "raw": {"market": "0xcab7ba4a9133cfd407d7e73e5757e5abbace413b59421527a31113406c97815c", "asset_id": "20002636398944597965698652220992177552927816915094913583821579024925426590022", "price": "0.994", "size": "127.41", "side": "SELL", "timestamp": "1768475500367", "received_at": "2026-01-15T12:11:40.558627"}}
{"event_type": "price_change", "event_ts": "2026-01-15T12:11:40.558790", "ingestion_ts": "2026-01-15T12:11:41.230171", "market_id": "0xcab7ba4a9133cfd407d7e73e5757e5abbace413b59421527a31113406c97815c", "raw": {"market": "0xcab7ba4a9133cfd407d7e73e5757e5abbace413b59421527a31113406c97815c", "asset_id": "96361925776989336186111887920533578209326565663637092688733016597062311745569", "price": "0.009", "size": "812.25", "side": "BUY", "timestamp": "1768475500367", "received_at": "2026-01-15T12:11:40.558790"}}
{"event_type": "price_change", "event_ts": "2026-01-15T12:11:40.558790", "ingestion_ts": "2026-01-15T12:11:41.230171", "market_id": "0xcab7ba4a9133cfd407d7e73e5757e5abbace413b59421527a31113406c97815c", "raw": {"market": "0xcab7ba4a9133cfd407d7e73e5757e5abbace413b59421527a31113406c97815c", "asset_id": "20002636398944597965698652220992177552927816915094913583821579024925426590022", "price": "0.991", "size": "812.25", "side": "SELL", "timestamp": "1768475500367", "received_at": "2026-01-15T12:11:40.558790"}}
{"event_type": "price_change", "event_ts": "2026-01-15T12:11:41.197012", "ingestion_ts": "2026-01-15T12:11:41.230171", "market_id": "0xcab7ba4a9133cfd407d7e73e5757e5abbace413b59421527a31113406c97815c", "raw": {"market": "0xcab7ba4a9133cfd407d7e73e5757e5abbace413b59421527a31113406c97815c", "asset_id": "96361925776989336186111887920533578209326565663637092688733016597062311745569", "price": "0.009", "size": "818.33", "side": "BUY", "timestamp": "1768475501076", "received_at": "2026-01-15T12:11:41.197012"}}
{"event_type": "price_change", "event_ts": "2026-01-15T12:11:41.197012", "ingestion_ts": "2026-01-15T12:11:41.230171", "market_id": "0xcab7ba4a9133cfd407d7e73e5757e5abbace413b59421527a31113406c97815c", "raw": {"market": "0xcab7ba4a9133cfd407d7e73e5757e5abbace413b59421527a31113406c97815c", "asset_id": "20002636398944597965698652220992177552927816915094913583821579024925426590022", "price": "0.991", "size": "818.33", "side": "SELL", "timestamp": "1768475501076", "received_at": "2026-01-15T12:11:41.197012"}}
